{"rx_ns": 13975992087400, "kind": "rest", "req": {"method": "GET", "url": "https://data-api.binance.vision/api/v3/depth?symbol=BTCUSDT&limit=1000", "limit": 1000, "weight": 50, "sent_ns": 13974392748000, "status": 200, "used_weight_1m": "150", "recv_ns": 13975959202300}, "frame": {"lastUpdateId":99118683459,"bids":[["79864.33000000","2.06249000"],["79864.32000000","0.00076000"],["79864.31000000","0.00013000"],["79863.05000000","0.00975000"],["79862.90000000","0.00007000"],["79862.75000000","0.00400000"],["79862.45000000","0.00863000"],["79862.10000000","0.00007000"],["79861.85000000","0.00007000"],["79861.79000000","0.00007000"],["79861.78000000","0.60866000"],["79861.77000000","0.36906000"],["79861.69000000","0.00007000"],["79861.68000000","0.05260000"],["79861.67000000","0.00007000"],["79861.66000000","0.31340000"],["79861.65000000","0.22691000"],["79861.32000000","0.00014000"],["79861.30000000","0.00007000"],["79861.29000000","0.08007000"],["79861.17000000","0.01403000"],["79861.05000000","0.00007000"],["79861.04000000","0.47730000"],["79860.86000000","0.00161000"],["79860.72000000","0.00008000"],["79860.49000000","0.00007000"],["79860.45000000","0.00013000"],["79860.44000000","0.00007000"],["79860.43000000","0.26197000"],["79860.18000000","0.00400000"],["79860.01000000","0.04042000"],["79859.89000000","0.01691000"],["79859.25000000","0.00007000"],["79859.24000000","0.49725000"],["79859.23000000","1.04939000"],["79859.21000000","0.33247000"],["79859.00000000","0.00007000"],["79858.66000000","0.00079000"],["79858.61000000","0.01684000"],["79858.41000000","0.00007000"],["79858.35000000","0.00013000"],["79858.18000000","0.00626000"],["79858.17000000","0.02100000"],["79858.16000000","0.00126000"],["79858.15000000","0.03358000"],["79858.04000000","0.00902000"],["79858.00000000","0.02400000"],["79857.54000000","0.00026000"],["79857.50000000","0.00400000"],["79857.45000000","0.00014000"],["79857.44000000","0.00250000"],["79857.43000000","0.02600000"],["79857.31000000","0.00069000"],["79857.22000000","0.00626000"],["79857.21000000","0.00400000"],["79856.94000000","0.00690000"],["79856.92000000","0.02703000"],["79856.69000000","0.02200000"],["79856.64000000","0.02000000"],["79856.62000000","0.02400000"],["79856.39000000","0.03000000"],["79856.34000000","0.00051000"],["79856.28000000","0.00094000"],["79856.00000000","0.02407000"],["79855.65000000","0.00250000"],["79855.12000000","0.01200000"],["79855.11000000","0.00400000"],["79855.10000000","1.32452000"],["79855.09000000","1.87677000"],["79855.00000000","0.00400000"],["79854.97000000","0.02254000"],["79854.72000000","0.00007000"],["79854.69000000","1.04939000"],["79854.67000000","0.12522000"],["79854.34000000","0.00028000"],["79854.31000000","0.02400000"],["79854.28000000","0.00007000"],["79854.26000000","0.00007000"],["79854.14000000","1.20229000"],["79854.05000000","0.00688000"],["79854.00000000","0.02400000"],["79853.64000000","0.00010000"],["79853.58000000","0.00014000"],["79853.52000000","0.00400000"],["79853.15000000","0.00923000"],["79853.01000000","0.00007000"],["79852.82000000","0.00007000"],["79852.75000000","0.03224000"],["79852.65000000","0.00008000"],["79852.61000000","0.02800000"],["79852.19000000","0.00007000"],["79852.07000000","0.00400000"],["79852.00000000","0.02400000"],["79851.77000000","0.02000000"],["79851.74000000","0.08566000"],["79851.71000000","0.12573000"],["79851.58000000","0.00705000"],["79851.53000000","0.00007000"],["79851.04000000","0.00400000"],["79850.75000000","0.33821000"],["79850.40000000","0.00007000"],["79850.25000000","0.99435000"],["79850.24000000","1.87677000"],["79850.20000000","1.04939000"],["79850.11000000","0.00007000"],["79850.02000000","0.00007000"],["79850.01000000","0.00052000"],["79850.00000000","0.12811000"],["79849.94000000","0.12523000"],["79849.71000000","0.33836000"],["79849.52000000","0.00026000"],["79849.28000000","0.00400000"],["79849.21000000","0.00007000"],["79848.93000000","0.20250000"],["79848.61000000","0.02200000"],["79848.60000000","0.02400000"],["79848.36000000","0.00008000"],["79848.35000000","0.00036000"],["79848.34000000","0.00007000"],["79848.11000000","0.02200000"],["79848.03000000","0.00014000"],["79848.00000000","0.02407000"],["79847.86000000","0.00059000"],["79847.83000000","0.02000000"],["79847.82000000","0.02000000"],["79847.77000000","0.00906000"],["79847.72000000","0.04400000"],["79847.70000000","0.00007000"],["79847.64000000","0.00400000"],["79847.58000000","0.00400000"],["79847.57000000","1.04222000"],["79847.26000000","0.00007000"],["79846.88000000","0.04000000"],["79846.52000000","0.00007000"],["79846.42000000","0.01161000"],["79846.27000000","0.00400000"],["79846.13000000","0.09373000"],["79846.00000000","0.02400000"],["79845.84000000","0.00014000"],["79845.66000000","0.00010000"],["79845.63000000","0.00012000"],["79845.35000000","0.36586000"],["79845.34000000","1.04939000"],["79845.02000000","1.87677000"],["79844.58000000","0.00008000"],["79844.36000000","0.00008000"],["79844.13000000","0.10306000"],["79844.10000000","0.33824000"],["79844.01000000","0.00007000"],["79844.00000000","0.02400000"],["79843.97000000","0.37582000"],["79843.88000000","0.00007000"],["79843.83000000","0.02499000"],["79843.63000000","0.50924000"],["79843.26000000","0.00400000"],["79843.22000000","0.03224000"],["79843.21000000","0.33824000"],["79842.82000000","0.00125000"],["79842.80000000","0.00192000"],["79842.65000000","0.00626000"],["79842.64000000","0.00007000"],["79842.51000000","0.88181000"],["79842.50000000","0.30458000"],["79842.49000000","0.12524000"],["79842.03000000","0.00007000"],["79842.01000000","0.00007000"],["79842.00000000","0.02400000"],["79841.99000000","0.00007000"],["79841.97000000","0.00014000"],["79841.48000000","0.00026000"],["79841.01000000","0.00400000"],["79840.54000000","0.33826000"],["79840.37000000","0.00044000"],["79840.03000000","1.87677000"],["79840.00000000","0.28024000"],["79839.85000000","0.76416000"],["79839.84000000","1.04939000"],["79839.78000000","0.00910000"],["79839.73000000","0.00007000"],["79838.76000000","0.00400000"],["79838.42000000","0.00007000"],["79838.10000000","0.00014000"],["79838.00000000","0.02400000"],["79837.91000000","0.62625000"],["79837.68000000","0.00010000"],["79837.65000000","0.00007000"],["79837.40000000","0.02600000"],["79836.66000000","0.02200000"],["79836.61000000","0.02000000"],["79836.59000000","0.02400000"],["79836.57000000","0.00400000"],["79836.51000000","0.00008000"],["79836.38000000","0.00008000"],["79836.35000000","0.42961000"],["79836.34000000","0.37587000"],["79836.08000000","0.00007000"],["79836.01000000","0.00007000"],["79836.00000000","0.02400000"],["79835.58000000","0.00007000"],["79835.14000000","0.51108000"],["79834.88000000","0.00007000"],["79834.29000000","1.14744000"],["79834.28000000","1.90077000"],["79834.23000000","0.00014000"],["79834.03000000","0.00007000"],["79834.00000000","0.02400000"],["79833.80000000","0.00200000"],["79833.62000000","1.04939000"],["79833.60000000","0.00400000"],["79833.50000000","0.00007000"],["79833.38000000","0.00026000"],["79833.36000000","0.09496000"],["79832.83000000","0.04480000"],["79832.38000000","0.00044000"],["79832.24000000","0.36586000"],["79832.08000000","0.00007000"],["79832.00000000","0.02800000"],["79831.80000000","0.20250000"],["79831.79000000","0.02000000"],["79831.75000000","0.00750000"],["79831.69000000","0.00072000"],["79831.43000000","0.00007000"],["79830.36000000","0.00014000"],["79830.21000000","0.00400000"],["79830.03000000","0.00400000"],["79830.00000000","0.07187000"],["79829.82000000","0.00007000"],["79829.70000000","0.00010000"],["79829.35000000","0.00007000"],["79829.29000000","0.92661000"],["79829.28000000","0.12897000"],["79828.78000000","1.87677000"],["79828.61000000","0.02400000"],["79828.44000000","0.00008000"],["79828.39000000","0.00008000"],["79828.28000000","1.05439000"],["79828.00000000","0.02400000"],["79827.84000000","0.02000000"],["79827.83000000","0.20631000"],["79827.80000000","0.00125000"],["79827.73000000","0.00070000"],["79827.28000000","0.00007000"],["79827.12000000","0.00007000"],["79826.49000000","0.00014000"],["79826.33000000","0.00010000"],["79826.32000000","0.00132000"],["79826.30000000","0.00052000"],["79826.00000000","0.02400000"],["79825.39000000","0.00026000"],["79825.34000000","0.36172000"],["79825.33000000","0.05104000"],["79825.20000000","0.00007000"],["79824.50000000","0.03224000"],["79824.40000000","0.00008000"],["79824.39000000","0.07962000"],["79824.20000000","0.01153000"],["79824.11000000","0.36881000"],["79824.00000000","0.03407000"],["79823.94000000","0.62654000"],["79823.87000000","1.56761000"],["79823.86000000","1.04939000"],["79823.84000000","2.24263000"],["79823.73000000","0.62879000"],["79823.16000000","0.00007000"],["79823.13000000","0.00007000"],["79822.16000000","0.20250000"],["79822.00000000","0.02400000"],["79821.72000000","0.00010000"],["79821.05000000","0.00007000"],["79820.92000000","0.00007000"],["79820.68000000","0.00014000"],["79820.37000000","0.00008000"],["79820.10000000","0.00007000"],["79820.09000000","0.50983000"],["79820.00000000","0.02400000"],["79819.99000000","0.00007000"],["79819.81000000","0.62658000"],["79819.36000000","0.00007000"],["79818.61000000","1.02263000"],["79818.60000000","1.87677000"],["79818.06000000","0.00007000"],["79818.00000000","0.02400000"],["79817.89000000","1.04939000"],["79817.67000000","0.02541000"],["79817.50000000","0.03224000"],["79817.34000000","0.83239000"],["79817.28000000","0.02000000"],["79817.15000000","0.00026000"],["79816.90000000","0.00007000"],["79816.44000000","0.02541000"],["79816.35000000","0.00007000"],["79816.02000000","0.00012000"],["79816.00000000","0.02400000"],["79815.99000000","0.34821000"],["79815.73000000","0.00654000"],["79815.51000000","0.71709000"],["79815.50000000","0.36586000"],["79814.82000000","0.00007000"],["79814.27000000","0.00007000"],["79814.06000000","0.02800000"],["79814.02000000","0.20250000"],["79814.01000000","0.00007000"],["79814.00000000","0.02400000"],["79813.74000000","0.00010000"],["79812.98000000","0.00010000"],["79812.75000000","1.87684000"],["79812.30000000","0.00008000"],["79812.00000000","0.02400000"],["79811.61000000","0.00621000"],["79811.60000000","0.00007000"],["79811.30000000","0.20631000"],["79811.24000000","0.02000000"],["79811.20000000","1.30337000"],["79810.87000000","0.02400000"],["79810.67000000","0.00007000"],["79810.43000000","0.00100000"],["79810.38000000","0.00007000"],["79810.28000000","0.00007000"],["79810.19000000","0.81756000"],["79810.00000000","0.02400000"],["79809.79000000","0.00433000"],["79809.62000000","0.02200000"],["79809.55000000","2.29018000"],["79809.36000000","0.00427000"],["79809.25000000","0.02000000"],["79809.22000000","0.02200000"],["79809.21000000","0.02200000"],["79809.16000000","0.00026000"],["79808.00000000","0.02407000"],["79807.83000000","0.02400000"],["79807.68000000","0.02541000"],["79807.39000000","0.00335000"],["79807.23000000","0.79339000"],["79807.21000000","0.02000000"],["79807.19000000","0.00007000"],["79807.02000000","1.24080000"],["79806.96000000","0.04696000"],["79806.61000000","0.36711000"],["79806.60000000","0.06139000"],["79806.52000000","0.00007000"],["79806.44000000","0.00013000"],["79806.01000000","0.20250000"],["79806.00000000","0.02400000"],["79805.76000000","0.00010000"],["79804.97000000","0.02600000"],["79804.45000000","0.00007000"],["79804.23000000","0.00008000"],["79804.12000000","0.00007000"],["79804.10000000","0.02000000"],["79804.07000000","0.82537000"],["79804.02000000","0.00007000"],["79804.00000000","0.02400000"],["79803.93000000","0.02400000"],["79803.86000000","0.02200000"],["79803.84000000","0.00007000"],["79803.52000000","2.39001000"],["79803.51000000","1.87677000"],["79803.49000000","1.04939000"],["79802.37000000","0.00007000"],["79802.09000000","0.00007000"],["79802.00000000","0.02400000"],["79801.88000000","0.00431000"],["79800.92000000","0.00007000"],["79800.86000000","0.00026000"],["79800.56000000","3.40038000"],["79800.32000000","0.80000000"],["79800.30000000","0.00007000"],["79800.12000000","0.00390000"],["79800.00000000","0.82870000"],["79799.04000000","1.24093000"],["79798.65000000","1.48440000"],["79798.64000000","1.87677000"],["79798.62000000","1.04939000"],["79798.23000000","0.00007000"],["79798.06000000","0.00007000"],["79798.05000000","0.36586000"],["79798.00000000","0.02400000"],["79797.99000000","0.00200000"],["79797.90000000","0.00007000"],["79797.78000000","0.00010000"],["79797.44000000","0.00312000"],["79797.43000000","0.20250000"],["79797.29000000","0.02200000"],["79796.80000000","0.00313000"],["79796.79000000","0.00537000"],["79796.43000000","2.32243000"],["79796.16000000","0.00008000"],["79796.08000000","0.00007000"],["79796.05000000","0.00007000"],["79796.00000000","0.02400000"],["79795.39000000","0.00110000"],["79795.08000000","0.00312000"],["79795.07000000","0.00253000"],["79794.59000000","0.03224000"],["79794.46000000","0.01716000"],["79794.07000000","0.02800000"],["79794.03000000","0.00007000"],["79794.00000000","0.02400000"],["79793.96000000","1.04939000"],["79792.96000000","0.11982000"],["79792.66000000","0.00026000"],["79792.23000000","0.00413000"],["79792.03000000","0.00007000"],["79792.00000000","0.02414000"],["79791.03000000","0.00014000"],["79790.96000000","0.08703000"],["79790.58000000","0.00270000"],["79790.52000000","0.04644000"],["79790.29000000","0.00400000"],["79790.00000000","0.02400000"],["79789.80000000","0.00010000"],["79789.63000000","0.02200000"],["79789.44000000","0.20250000"],["79789.27000000","0.02000000"],["79789.23000000","0.02200000"],["79789.22000000","0.02200000"],["79789.05000000","1.87677000"],["79788.77000000","0.00011000"],["79788.59000000","0.36586000"],["79788.53000000","0.00007000"],["79788.32000000","0.00007000"],["79788.23000000","1.04939000"],["79788.14000000","0.00007000"],["79788.09000000","0.00008000"],["79788.01000000","0.01444000"],["79788.00000000","0.02400000"],["79787.85000000","0.00007000"],["79786.12000000","0.00014000"],["79786.00000000","0.02400000"],["79785.32000000","0.00008000"],["79784.04000000","0.00007000"],["79784.00000000","0.02400000"],["79783.70000000","0.00007000"],["79782.80000000","0.00007000"],["79782.00000000","0.02426000"],["79781.82000000","0.00010000"],["79781.80000000","0.03224000"],["79781.45000000","0.20250000"],["79780.99000000","0.00014000"],["79780.81000000","0.62589000"],["79780.57000000","0.00007000"],["79780.56000000","0.00007000"],["79780.48000000","0.36586000"],["79780.02000000","0.00008000"],["79780.00000000","0.02400000"],["79778.96000000","1.04939000"],["79778.86000000","0.00100000"],["79778.18000000","0.00067000"],["79778.16000000","0.00007000"],["79778.00000000","0.02400000"],["79777.94000000","0.05682000"],["79777.84000000","0.01282000"],["79777.06000000","0.03224000"],["79777.00000000","0.00012000"],["79776.11000000","0.00007000"],["79776.00000000","0.02407000"],["79775.70000000","1.99604000"],["79775.41000000","0.00007000"],["79774.00000000","0.02400000"],["79773.97000000","0.00026000"],["79773.84000000","0.00010000"],["79773.61000000","0.00010000"],["79773.46000000","0.20250000"],["79773.13000000","0.00007000"],["79772.80000000","0.00007000"],["79772.69000000","0.00020000"],["79772.16000000","0.00007000"],["79772.00000000","0.02400000"],["79771.59000000","0.04613000"],["79771.26000000","0.00007000"],["79770.99000000","0.00007000"],["79770.39000000","0.36586000"],["79770.15000000","0.00007000"],["79770.00000000","0.02917000"],["79769.41000000","0.03224000"],["79769.18000000","3.76184000"],["79769.12000000","0.00010000"],["79768.85000000","0.00007000"],["79768.00000000","0.02400000"],["79766.71000000","0.00007000"],["79766.66000000","0.00016000"],["79766.00000000","0.02482000"],["79765.99000000","0.00026000"],["79765.86000000","0.00010000"],["79765.47000000","0.20250000"],["79765.25000000","0.01253000"],["79765.04000000","0.00014000"],["79764.70000000","0.00541000"],["79764.51000000","0.00007000"],["79764.00000000","0.02400000"],["79763.88000000","0.00008000"],["79763.72000000","0.00025000"],["79762.96000000","0.00007000"],["79762.26000000","0.36586000"],["79762.12000000","0.00007000"],["79762.00000000","0.02400000"],["79761.89000000","0.00200000"],["79761.88000000","0.00008000"],["79760.08000000","0.00007000"],["79760.00000000","0.02625000"],["79758.36000000","0.00400000"],["79758.00000000","0.02400000"],["79757.99000000","0.00007000"],["79757.88000000","0.00010000"],["79757.62000000","0.00007000"],["79757.52000000","0.00026000"],["79757.48000000","0.20250000"],["79757.41000000","0.00231000"],["79757.38000000","0.00034000"],["79757.28000000","0.00007000"],["79756.79000000","0.03224000"],["79756.43000000","0.00501000"],["79756.18000000","0.00007000"],["79756.00000000","0.02400000"],["79755.93000000","0.00007000"],["79755.00000000","0.09659000"],["79754.67000000","0.00007000"],["79754.20000000","0.00126000"],["79754.18000000","0.00007000"],["79754.00000000","0.02400000"],["79752.24000000","0.00014000"],["79752.06000000","0.00007000"],["79752.00000000","0.02400000"],["79751.91000000","0.00394000"],["79751.41000000","0.00270000"],["79750.52000000","0.00007000"],["79750.00000000","0.02799000"],["79749.49000000","0.20250000"],["79749.37000000","0.00026000"],["79748.08000000","0.00007000"],["79748.00000000","0.02400000"],["79747.89000000","0.02692000"],["79747.88000000","0.36586000"],["79747.84000000","0.00088000"],["79747.74000000","0.00008000"],["79746.89000000","0.00160000"],["79746.37000000","0.00007000"],["79746.04000000","0.08730000"],["79746.00000000","0.02400000"],["79745.46000000","0.00016000"],["79744.74000000","0.00007000"],["79744.00000000","0.02407000"],["79743.94000000","0.00752000"],["79743.28000000","0.25000000"],["79742.19000000","0.00007000"],["79742.00000000","0.02400000"],["79741.50000000","0.20250000"],["79740.15000000","0.00026000"],["79740.00000000","0.05014000"],["79739.48000000","0.00007000"],["79738.93000000","0.00100000"],["79738.83000000","0.00016000"],["79738.21000000","0.00007000"],["79738.00000000","0.02400000"],["79737.27000000","0.12897000"],["79736.72000000","0.07529000"],["79736.67000000","0.00007000"],["79736.47000000","0.00376000"],["79736.04000000","0.00007000"],["79736.01000000","0.00007000"],["79736.00000000","0.02400000"],["79735.60000000","0.00012000"],["79734.24000000","0.00010000"],["79734.16000000","0.04910000"],["79734.00000000","0.02407000"],["79733.69000000","0.00007000"],["79733.50000000","0.36586000"],["79732.48000000","0.00059000"],["79732.00000000","0.02400000"],["79731.98000000","0.00026000"],["79731.70000000","0.00007000"],["79731.60000000","0.00008000"],["79730.76000000","0.00035000"],["79730.48000000","0.00012000"],["79730.00000000","0.03474000"],["79729.79000000","0.00007000"],["79729.72000000","0.00111000"],["79729.70000000","0.00007000"],["79729.09000000","0.01961000"],["79729.04000000","0.00042000"],["79728.65000000","0.00012000"],["79728.64000000","0.00007000"],["79728.57000000","0.00020000"],["79728.40000000","0.00413000"],["79728.30000000","0.03032000"],["79728.00000000","0.02400000"],["79727.14000000","0.00009000"],["79727.11000000","0.00048000"],["79727.00000000","0.00251000"],["79726.86000000","0.00007000"],["79726.69000000","3.76373000"],["79726.00000000","0.02400000"],["79725.64000000","0.00007000"],["79724.62000000","0.00020000"],["79724.07000000","0.00007000"],["79724.01000000","0.00125000"],["79724.00000000","0.02426000"],["79723.98000000","0.00260000"],["79723.52000000","0.00010000"],["79723.40000000","0.00009000"],["79722.91000000","0.09362000"],["79722.24000000","0.00007000"],["79722.00000000","0.02400000"],["79721.94000000","0.00007000"],["79721.64000000","0.00007000"],["79721.57000000","0.00007000"],["79721.30000000","0.03224000"],["79720.00000000","0.02550000"],["79719.42000000","0.00007000"],["79719.12000000","0.36586000"],["79718.74000000","0.00654000"],["79718.52000000","0.00007000"],["79718.16000000","0.00009000"],["79718.00000000","0.02400000"],["79717.58000000","0.00023000"],["79717.43000000","0.00170000"],["79717.34000000","0.00007000"],["79716.79000000","0.00125000"],["79716.78000000","0.00062000"],["79716.66000000","0.00010000"],["79716.45000000","0.00007000"],["79716.03000000","0.00008000"],["79716.00000000","0.02400000"],["79715.91000000","0.00026000"],["79715.53000000","0.00017000"],["79715.46000000","0.00008000"],["79715.28000000","0.00007000"],["79714.36000000","0.00007000"],["79714.29000000","0.00125000"],["79714.28000000","0.00013000"],["79714.25000000","0.06000000"],["79714.20000000","0.00016000"],["79714.00000000","0.02400000"],["79713.90000000","0.00165000"],["79713.76000000","0.00010000"],["79713.68000000","1.50049000"],["79713.56000000","0.00007000"],["79713.45000000","0.00014000"],["79712.53000000","0.00008000"],["79712.00000000","0.02407000"],["79711.26000000","0.00035000"],["79711.23000000","0.05082000"],["79711.00000000","0.00270000"],["79710.76000000","0.00011000"],["79710.75000000","0.00030000"],["79710.72000000","0.00007000"],["79710.54000000","0.00007000"],["79710.46000000","0.00400000"],["79710.00000000","0.02467000"],["79709.77000000","0.03499000"],["79709.57000000","0.00007000"],["79709.06000000","0.00007000"],["79708.33000000","0.00007000"],["79708.00000000","0.02400000"],["79707.66000000","0.00015000"],["79707.50000000","0.00026000"],["79707.44000000","0.00021000"],["79706.59000000","0.03224000"],["79706.27000000","0.00007000"],["79706.00000000","0.02400000"],["79705.88000000","0.00959000"],["79705.59000000","0.00007000"],["79705.45000000","0.00022000"],["79705.00000000","0.00010000"],["79704.92000000","0.00007000"],["79704.88000000","0.00007000"],["79704.74000000","0.36586000"],["79704.27000000","0.00008000"],["79704.00000000","0.02462000"],["79703.75000000","0.00013000"],["79703.74000000","0.00091000"],["79703.71000000","0.00021000"],["79703.56000000","0.00023000"],["79703.52000000","0.00123000"],["79703.38000000","0.00007000"],["79703.19000000","0.00044000"],["79702.92000000","0.00008000"],["79702.82000000","0.00015000"],["79702.64000000","0.00007000"],["79702.54000000","0.00024000"],["79702.00000000","0.02424000"],["79701.79000000","0.00008000"],["79701.66000000","0.00013000"],["79701.60000000","0.00007000"],["79701.33000000","0.00010000"],["79701.32000000","0.00034000"],["79700.91000000","0.00023000"],["79700.90000000","0.01267000"],["79700.89000000","0.00024000"],["79700.88000000","0.00010000"],["79700.85000000","0.00109000"],["79700.51000000","0.00033000"],["79700.48000000","0.00016000"],["79700.29000000","0.00013000"],["79700.28000000","0.05082000"],["79700.15000000","0.00093000"],["79700.10000000","0.00012000"],["79700.00000000","1.18142000"],["79699.86000000","0.00079000"],["79699.77000000","0.00010000"],["79699.72000000","0.00012000"],["79699.59000000","0.00043000"],["79699.51000000","0.00026000"],["79699.39000000","0.00007000"],["79699.32000000","0.00008000"],["79699.20000000","0.00007000"],["79699.02000000","0.00015000"],["79699.00000000","0.13279000"],["79698.79000000","0.00013000"],["79698.70000000","0.00007000"],["79698.63000000","0.00008000"],["79698.48000000","0.00007000"],["79697.89000000","0.00007000"],["79697.86000000","0.00012000"],["79697.56000000","0.00007000"],["79697.09000000","0.00010000"],["79696.96000000","0.00010000"],["79696.93000000","1.20000000"],["79696.91000000","0.00007000"],["79696.86000000","0.00013000"],["79696.59000000","0.00015000"],["79696.55000000","0.00380000"],["79696.39000000","0.00032000"],["79696.10000000","0.00007000"],["79695.64000000","0.00012000"],["79695.39000000","0.00011000"],["79695.21000000","0.03224000"],["79695.12000000","0.00010000"],["79694.87000000","0.00010000"],["79694.84000000","0.00134000"],["79694.71000000","0.00009000"],["79694.66000000","0.00007000"],["79694.44000000","0.00031000"],["79694.34000000","0.00035000"],["79694.22000000","0.00048000"],["79694.05000000","0.00050000"],["79694.00000000","0.00087000"],["79693.69000000","0.00012000"],["79693.58000000","0.00020000"],["79693.43000000","0.00118000"],["79693.33000000","0.00019000"],["79693.13000000","0.00072000"],["79692.59000000","0.00025000"],["79692.48000000","0.00007000"],["79692.41000000","0.00007000"],["79692.32000000","0.00951000"],["79692.30000000","0.00056000"],["79692.22000000","0.00028000"],["79692.07000000","0.00530000"],["79691.34000000","0.00009000"],["79691.01000000","0.00100000"],["79690.79000000","0.00020000"],["79690.52000000","0.00159000"],["79690.50000000","0.00022000"],["79690.37000000","0.00008000"],["79690.31000000","0.00009000"],["79690.30000000","0.00007000"],["79690.00000000","0.00050000"],["79689.80000000","0.00026000"],["79689.65000000","0.00007000"],["79689.59000000","0.00030000"],["79689.44000000","0.00026000"],["79689.35000000","0.00007000"],["79689.19000000","0.00028000"],["79689.16000000","0.00122000"],["79689.00000000","0.00125000"],["79688.88000000","0.00013000"],["79688.76000000","0.00012000"],["79688.63000000","0.00098000"],["79688.40000000","0.00019000"],["79688.34000000","0.00007000"],["79688.20000000","3.76555000"],["79687.85000000","0.00009000"],["79687.77000000","0.00023000"],["79687.55000000","0.00007000"],["79687.50000000","0.00685000"],["79687.44000000","0.00007000"],["79687.36000000","0.00023000"],["79687.12000000","0.00012000"],["79687.03000000","0.00010000"],["79686.99000000","0.00023000"],["79686.89000000","0.01000000"],["79686.72000000","0.00014000"],["79686.66000000","4.59860000"],["79685.71000000","0.00008000"],["79685.56000000","0.00013000"],["79685.36000000","0.00007000"],["79685.35000000","0.00863000"],["79684.94000000","0.00045000"],["79684.66000000","0.00025000"],["79684.65000000","0.00501000"],["79684.56000000","0.00007000"],["79684.21000000","0.00457000"],["79684.15000000","0.00013000"],["79683.74000000","0.00007000"],["79683.66000000","0.11607000"],["79683.58000000","0.00021000"],["79683.54000000","0.00007000"],["79683.48000000","0.00023000"],["79683.18000000","0.00008000"],["79683.15000000","0.00374000"],["79683.07000000","0.00008000"],["79682.96000000","0.00007000"],["79682.75000000","0.00020000"],["79682.72000000","0.00007000"],["79682.12000000","0.00007000"],["79681.92000000","0.00007000"],["79681.81000000","0.00010000"],["79681.62000000","0.00025000"],["79681.51000000","0.00132000"],["79681.46000000","0.00026000"],["79681.39000000","0.00011000"],["79680.97000000","0.00010000"],["79680.88000000","0.00014000"],["79680.85000000","0.00007000"],["79680.82000000","0.00010000"],["79680.56000000","0.00007000"],["79680.38000000","0.00023000"],["79680.36000000","0.00148000"],["79680.32000000","0.00050000"],["79680.11000000","0.00019000"],["79680.00000000","0.02056000"],["79679.90000000","0.00144000"],["79679.89000000","0.00033000"],["79679.17000000","0.00010000"],["79679.06000000","0.00010000"],["79679.02000000","0.00009000"],["79678.57000000","0.00028000"],["79678.55000000","0.00007000"],["79678.27000000","0.00048000"],["79678.17000000","0.00007000"],["79677.97000000","0.00010000"],["79677.58000000","0.00012000"],["79677.53000000","0.00009000"],["79677.47000000","0.00454000"],["79677.41000000","0.00130000"],["79677.21000000","0.00011000"],["79677.06000000","0.00007000"],["79676.94000000","0.01389000"],["79676.89000000","0.00245000"],["79676.76000000","0.00039000"],["79676.60000000","0.00190000"],["79676.47000000","0.00653000"],["79676.40000000","0.00091000"],["79676.19000000","0.00007000"],["79675.91000000","0.00007000"],["79675.86000000","0.00053000"],["79675.78000000","0.00021000"],["79675.70000000","0.00008000"],["79675.67000000","0.00156000"],["79675.66000000","3.40571000"],["79675.00000000","0.00012000"],["79674.66000000","0.00014000"],["79674.64000000","0.01572000"],["79674.47000000","0.00060000"],["79674.41000000","0.00094000"],["79674.33000000","0.00007000"],["79674.14000000","0.00057000"],["79673.70000000","0.00013000"],["79673.64000000","0.00007000"],["79673.37000000","0.00026000"],["79673.33000000","0.00025000"],["79673.20000000","0.00020000"],["79673.14000000","0.00008000"],["79672.84000000","0.00062000"],["79672.78000000","0.00007000"],["79672.69000000","0.00012000"],["79672.31000000","0.00010000"],["79672.01000000","0.00270000"],["79671.91000000","0.00007000"],["79671.90000000","0.00200000"],["79671.39000000","0.00010000"],["79670.91000000","0.11607000"],["79670.66000000","0.00007000"],["79670.58000000","0.00031000"],["79670.26000000","0.00012000"],["79670.14000000","0.00016000"],["79670.01000000","0.00013000"],["79670.00000000","0.00067000"],["79669.97000000","0.00008000"],["79669.86000000","0.00013000"],["79669.78000000","0.00078000"],["79669.77000000","0.00125000"],["79669.70000000","0.00007000"],["79669.48000000","0.00105000"],["79668.89000000","0.00368000"],["79668.85000000","0.00007000"],["79668.59000000","0.00044000"],["79668.58000000","0.00065000"],["79668.49000000","0.00010000"],["79668.13000000","0.00864000"],["79668.00000000","0.03000000"],["79667.95000000","0.00088000"],["79667.46000000","0.00009000"],["79667.45000000","0.00043000"],["79667.27000000","0.00269000"],["79667.26000000","2.32631000"],["79667.17000000","0.00008000"],["79667.09000000","0.03229000"],["79667.04000000","0.00008000"],["79667.03000000","0.00029000"],["79666.66000000","0.03573000"],["79666.60000000","0.00011000"],["79666.55000000","0.00124000"],["79666.52000000","0.00034000"],["79666.40000000","0.00010000"],["79666.28000000","0.00137000"],["79666.19000000","0.00602000"],["79666.10000000","0.00007000"],["79666.00000000","0.00215000"],["79665.88000000","0.00281000"],["79665.61000000","0.00007000"],["79665.36000000","0.00038000"],["79665.35000000","0.00011000"],["79665.25000000","0.01255000"],["79665.22000000","0.00007000"],["79664.86000000","0.00007000"],["79664.73000000","0.00009000"],["79664.62000000","0.00414000"],["79664.39000000","0.00055000"],["79664.16000000","0.00007000"],["79664.12000000","3.76684000"],["79664.01000000","0.00055000"],["79663.85000000","0.00048000"],["79663.55000000","0.00011000"],["79663.45000000","0.00062000"],["79663.37000000","0.00007000"],["79663.24000000","0.00022000"],["79663.14000000","0.00012000"],["79663.08000000","0.00020000"],["79663.03000000","0.00007000"],["79662.85000000","0.00183000"],["79662.83000000","0.00007000"],["79662.56000000","0.00007000"],["79662.33000000","0.00031000"],["79662.03000000","0.00031000"],["79661.66000000","0.00014000"],["79661.65000000","0.00012000"],["79661.30000000","0.00413000"],["79661.26000000","0.00007000"],["79661.19000000","0.00023000"],["79661.18000000","0.00007000"],["79661.15000000","0.00070000"],["79661.11000000","0.00011000"],["79660.69000000","0.00008000"],["79660.60000000","0.23795000"],["79660.56000000","0.00007000"],["79660.00000000","0.00390000"],["79659.82000000","0.00010000"],["79659.78000000","0.00012000"],["79659.77000000","0.00010000"],["79659.75000000","0.00011000"],["79659.53000000","0.00008000"],["79659.36000000","0.00007000"],["79659.09000000","0.00075000"],["79658.95000000","0.11607000"],["79658.92000000","0.00023000"],["79658.70000000","0.00036000"],["79658.36000000","0.00007000"],["79658.26000000","0.00065000"],["79658.01000000","0.00087000"],["79657.99000000","0.00010000"],["79657.87000000","0.00010000"],["79657.78000000","0.00007000"],["79657.44000000","0.00011000"],["79657.35000000","0.00026000"],["79657.14000000","0.00134000"],["79656.71000000","0.00016000"],["79656.64000000","0.00065000"],["79656.61000000","0.00007000"],["79656.50000000","0.00048000"],["79656.49000000","0.00008000"],["79656.43000000","0.00009000"],["79656.25000000","0.00023000"],["79656.22000000","0.00752000"],["79655.94000000","0.01762000"],["79655.50000000","0.00010000"],["79655.44000000","0.00014000"],["79655.17000000","0.00122000"],["79654.94000000","0.00017000"],["79654.67000000","0.00080000"],["79654.59000000","0.00007000"],["79654.56000000","0.00080000"],["79654.47000000","0.00007000"],["79654.27000000","0.00012000"],["79654.11000000","0.00008000"],["79653.84000000","0.00090000"],["79653.57000000","0.00044000"],["79652.73000000","0.00028000"],["79652.70000000","0.00280000"],["79652.52000000","0.00007000"],["79652.38000000","0.00007000"],["79652.36000000","0.00013000"],["79652.25000000","0.00007000"],["79652.15000000","0.00178000"],["79651.98000000","0.00181000"],["79651.21000000","0.00023000"],["79651.20000000","0.00010000"],["79651.15000000","0.00116000"],["79650.98000000","0.00009000"]],"asks":[["79864.34000000","1.43907000"],["79864.35000000","0.00712000"],["79864.36000000","0.00013000"],["79864.53000000","0.00007000"],["79864.54000000","0.00007000"],["79864.55000000","0.07184000"],["79864.59000000","0.00007000"],["79864.94000000","0.00007000"],["79864.95000000","0.11827000"],["79865.19000000","0.00014000"],["79865.57000000","0.00007000"],["79865.58000000","0.06152000"],["79865.61000000","0.00007000"],["79865.62000000","0.01761000"],["79865.99000000","0.00007000"],["79866.09000000","0.00007000"],["79866.19000000","0.00007000"],["79866.20000000","0.06159000"],["79866.71000000","0.00007000"],["79866.78000000","0.00007000"],["79866.81000000","0.00007000"],["79866.82000000","0.06152000"],["79866.89000000","0.00007000"],["79866.90000000","0.02100000"],["79867.06000000","0.00007000"],["79867.07000000","0.06138000"],["79867.15000000","0.00063000"],["79867.26000000","0.00007000"],["79867.27000000","0.04779000"],["79867.39000000","0.00007000"],["79867.57000000","0.00007000"],["79867.99000000","0.06138000"],["79868.00000000","0.02414000"],["79868.17000000","0.11424000"],["79868.18000000","0.02086000"],["79868.42000000","0.00007000"],["79868.68000000","0.06145000"],["79868.79000000","0.00007000"],["79869.06000000","0.00014000"],["79869.30000000","0.06145000"],["79869.80000000","0.00007000"],["79869.83000000","0.00010000"],["79869.91000000","0.00007000"],["79869.92000000","0.06138000"],["79870.00000000","0.02407000"],["79870.32000000","0.00013000"],["79870.54000000","0.06138000"],["79870.74000000","0.00007000"],["79870.86000000","0.00007000"],["79871.14000000","0.00334000"],["79871.16000000","0.06138000"],["79871.66000000","0.00017000"],["79871.67000000","0.00007000"],["79871.78000000","0.06138000"],["79871.99000000","0.00626000"],["79872.00000000","0.02407000"],["79872.03000000","0.00400000"],["79872.26000000","0.00932000"],["79872.33000000","0.00008000"],["79872.40000000","0.06138000"],["79872.93000000","0.00014000"],["79872.94000000","0.00007000"],["79873.02000000","0.06138000"],["79873.10000000","0.00007000"],["79873.28000000","0.00048000"],["79873.36000000","0.00400000"],["79873.40000000","0.00250000"],["79873.64000000","0.06138000"],["79873.68000000","0.00007000"],["79873.94000000","0.00400000"],["79873.95000000","0.01200000"],["79873.96000000","0.95566000"],["79873.97000000","1.87677000"],["79874.00000000","0.02400000"],["79874.01000000","0.34254000"],["79874.18000000","0.00026000"],["79874.25000000","0.00400000"],["79874.26000000","0.35288000"],["79874.41000000","0.00718000"],["79874.44000000","0.14772000"],["79874.74000000","0.00007000"],["79874.83000000","0.00250000"],["79875.02000000","0.00007000"],["79875.19000000","0.00007000"],["79875.20000000","0.20250000"],["79875.84000000","0.00400000"],["79875.93000000","1.04939000"],["79875.94000000","0.90444000"],["79876.00000000","0.02400000"],["79876.01000000","0.65851000"],["79876.29000000","0.00007000"],["79876.40000000","0.08576000"],["79876.45000000","0.00701000"],["79876.61000000","0.00915000"],["79876.76000000","0.00007000"],["79876.80000000","0.00014000"],["79876.86000000","0.00008000"],["79877.09000000","0.00007000"],["79877.56000000","0.00007000"],["79877.60000000","0.00400000"],["79877.81000000","0.00010000"],["79878.00000000","0.02400000"],["79878.07000000","0.36586000"],["79878.89000000","0.02000000"],["79879.01000000","1.87677000"],["79879.17000000","0.00007000"],["79879.18000000","0.00150000"],["79879.54000000","0.00187000"],["79879.70000000","0.02000000"],["79879.80000000","0.00400000"],["79880.00000000","0.02407000"],["79880.31000000","0.00008000"],["79880.35000000","0.62998000"],["79880.36000000","1.04939000"],["79880.61000000","0.00903000"],["79880.67000000","0.00014000"],["79880.75000000","0.00007000"],["79880.80000000","0.35043000"],["79881.25000000","0.00007000"],["79881.44000000","0.00007000"],["79881.56000000","0.09400000"],["79881.94000000","0.00007000"],["79882.00000000","0.02400000"],["79882.12000000","0.02000000"],["79882.18000000","0.00026000"],["79882.24000000","0.00400000"],["79882.74000000","0.02000000"],["79882.89000000","0.02000000"],["79883.31000000","0.12518000"],["79883.32000000","0.00007000"],["79883.36000000","0.02000000"],["79883.44000000","0.02000000"],["79883.52000000","0.02000000"],["79883.53000000","0.00400000"],["79883.55000000","0.12342000"],["79883.70000000","0.02000000"],["79883.74000000","0.19019000"],["79883.75000000","0.04000000"],["79883.95000000","1.29736000"],["79883.96000000","1.87677000"],["79884.00000000","0.43288000"],["79884.03000000","0.00007000"],["79884.09000000","0.00400000"],["79884.31000000","0.00008000"],["79884.54000000","0.00014000"],["79884.60000000","1.04939000"],["79884.63000000","0.00250000"],["79884.93000000","0.00008000"],["79885.32000000","0.00007000"],["79885.40000000","0.00007000"],["79885.58000000","0.33806000"],["79885.79000000","0.00010000"],["79885.98000000","0.00928000"],["79886.00000000","0.02400000"],["79886.25000000","0.36586000"],["79886.50000000","0.02000000"],["79886.62000000","0.00007000"],["79887.06000000","0.00400000"],["79887.48000000","0.33813000"],["79888.00000000","0.02407000"],["79888.03000000","0.00200000"],["79888.30000000","0.00008000"],["79888.41000000","0.00014000"],["79888.50000000","0.00400000"],["79889.19000000","0.00626000"],["79889.20000000","0.00007000"],["79889.56000000","0.00007000"],["79889.71000000","0.00007000"],["79889.72000000","0.46445000"],["79889.73000000","0.38402000"],["79889.75000000","0.02000000"],["79890.00000000","0.07201000"],["79890.03000000","0.00400000"],["79890.46000000","0.03000000"],["79890.57000000","0.02000000"],["79890.65000000","0.12517000"],["79891.22000000","0.00026000"],["79891.37000000","0.04613000"],["79891.41000000","1.04939000"],["79891.63000000","0.00007000"],["79891.97000000","0.62632000"],["79891.99000000","1.52655000"],["79892.00000000","0.02400000"],["79892.28000000","0.00014000"],["79892.29000000","0.00008000"],["79892.31000000","0.02480000"],["79893.00000000","0.34211000"],["79893.19000000","0.00012000"],["79893.22000000","0.01270000"],["79893.53000000","0.33803000"],["79893.71000000","0.00007000"],["79893.77000000","0.00010000"],["79893.96000000","0.00400000"],["79893.99000000","0.00007000"],["79894.00000000","0.22650000"],["79894.26000000","0.12000000"],["79894.64000000","1.87677000"],["79895.20000000","0.00400000"],["79895.39000000","0.00125000"],["79895.50000000","1.04939000"],["79895.79000000","0.00007000"],["79896.00000000","0.02400000"],["79896.15000000","0.00014000"],["79896.29000000","0.00008000"],["79896.60000000","0.00400000"],["79896.96000000","0.00007000"],["79896.99000000","1.34646000"],["79897.69000000","0.00007000"],["79897.86000000","0.00007000"],["79897.89000000","0.00300000"],["79897.91000000","0.00007000"],["79897.92000000","0.62596000"],["79898.00000000","0.02800000"],["79898.58000000","0.36586000"],["79898.76000000","0.20631000"],["79898.78000000","0.49768000"],["79898.96000000","0.02000000"],["79899.24000000","0.62820000"],["79899.40000000","0.00026000"],["79899.44000000","1.87677000"],["79899.75000000","0.00400000"],["79899.93000000","0.42954000"],["79899.94000000","0.00007000"],["79899.98000000","0.82415000"],["79899.99000000","1.04939000"],["79900.00000000","0.07657000"],["79900.02000000","0.00014000"],["79900.12000000","0.33800000"],["79900.16000000","0.09389000"],["79900.28000000","0.00015000"],["79900.53000000","0.03224000"],["79900.93000000","0.20631000"],["79901.07000000","0.00008000"],["79901.75000000","0.00010000"],["79901.99000000","0.20250000"],["79902.00000000","0.72400000"],["79902.02000000","0.00007000"],["79902.14000000","0.00400000"],["79902.15000000","0.00190000"],["79902.19000000","0.02000000"],["79902.27000000","0.00012000"],["79902.96000000","0.02000000"],["79903.43000000","0.02000000"],["79903.67000000","0.62591000"],["79903.69000000","0.10000000"],["79903.77000000","0.02000000"],["79903.82000000","0.04000000"],["79903.89000000","0.00014000"],["79903.97000000","0.00007000"],["79904.00000000","0.02407000"],["79904.10000000","0.00007000"],["79904.27000000","0.00008000"],["79904.47000000","1.68224000"],["79904.48000000","1.87677000"],["79904.50000000","1.04939000"],["79904.72000000","0.00007000"],["79904.76000000","0.00400000"],["79905.00000000","0.01000000"],["79905.07000000","0.00060000"],["79905.37000000","1.20229000"],["79905.99000000","0.00007000"],["79906.00000000","0.02400000"],["79906.17000000","0.00007000"],["79906.33000000","0.02480000"],["79906.49000000","0.25000000"],["79906.58000000","0.36586000"],["79906.66000000","0.02000000"],["79907.62000000","1.23924000"],["79907.75000000","0.00026000"],["79907.81000000","1.02439000"],["79907.99000000","0.00007000"],["79908.00000000","0.02400000"],["79908.25000000","0.00007000"],["79908.61000000","1.04939000"],["79908.62000000","0.20631000"],["79908.67000000","0.02000000"],["79909.14000000","0.00008000"],["79909.45000000","0.02000000"],["79909.54000000","1.87677000"],["79909.73000000","0.00010000"],["79909.98000000","0.20250000"],["79909.99000000","0.00007000"],["79910.00000000","0.02973000"],["79910.33000000","0.00007000"],["79910.81000000","0.00235000"],["79911.94000000","0.01270000"],["79911.99000000","1.72219000"],["79912.00000000","0.02400000"],["79912.41000000","0.00007000"],["79912.48000000","0.00007000"],["79912.72000000","1.04939000"],["79912.73000000","0.02000000"],["79912.81000000","0.00629000"],["79912.82000000","0.81651000"],["79913.11000000","0.00427000"],["79913.33000000","0.02000000"],["79913.45000000","0.02000000"],["79913.49000000","0.02000000"],["79913.50000000","0.83139000"],["79913.58000000","0.00100000"],["79913.88000000","0.00007000"],["79914.00000000","0.02400000"],["79914.06000000","0.00427000"],["79914.48000000","0.00007000"],["79915.01000000","1.87677000"],["79915.07000000","0.00007000"],["79915.57000000","0.34702000"],["79915.73000000","0.00431000"],["79915.84000000","0.00026000"],["79915.98000000","0.00007000"],["79916.00000000","0.02400000"],["79916.06000000","1.23912000"],["79916.15000000","0.75769000"],["79916.56000000","0.00007000"],["79916.73000000","0.03224000"],["79916.97000000","1.04939000"],["79917.21000000","0.00008000"],["79917.44000000","0.20631000"],["79917.71000000","0.00010000"],["79917.81000000","0.00007000"],["79918.00000000","0.02400000"],["79918.64000000","0.00007000"],["79918.81000000","0.20250000"],["79919.70000000","0.51612000"],["79919.93000000","1.50371000"],["79919.94000000","1.87677000"],["79919.95000000","0.36586000"],["79920.00000000","1.01576000"],["79920.24000000","0.00007000"],["79920.72000000","0.00007000"],["79920.79000000","0.00007000"],["79920.95000000","0.00075000"],["79921.06000000","0.00007000"],["79921.73000000","1.04939000"],["79921.88000000","0.00884000"],["79922.00000000","0.02400000"],["79922.01000000","0.01876000"],["79922.42000000","0.00413000"],["79922.75000000","1.01890000"],["79923.38000000","0.02000000"],["79923.88000000","0.00026000"],["79924.00000000","0.02400000"],["79924.05000000","0.00200000"],["79924.06000000","1.45779000"],["79924.60000000","0.00007000"],["79924.73000000","0.02000000"],["79924.86000000","0.02000000"],["79924.87000000","0.00007000"],["79925.14000000","0.03456000"],["79925.28000000","0.00008000"],["79925.69000000","0.00010000"],["79925.77000000","1.04939000"],["79925.79000000","1.87677000"],["79926.00000000","0.02400000"],["79926.80000000","0.20250000"],["79926.86000000","1.23897000"],["79926.95000000","0.00007000"],["79926.98000000","0.00007000"],["79927.05000000","0.02000000"],["79927.37000000","0.02000000"],["79927.53000000","0.00218000"],["79927.83000000","0.02000000"],["79927.99000000","0.16360000"],["79928.00000000","0.02407000"],["79928.16000000","0.02000000"],["79928.23000000","0.02000000"],["79928.24000000","0.02000000"],["79928.51000000","0.36586000"],["79929.44000000","0.02000000"],["79929.85000000","0.00007000"],["79929.90000000","0.00007000"],["79930.00000000","0.02400000"],["79930.32000000","0.00625000"],["79931.59000000","0.00311000"],["79931.60000000","0.03224000"],["79931.61000000","0.00007000"],["79931.76000000","1.23887000"],["79931.94000000","0.89330000"],["79931.96000000","0.00007000"],["79931.97000000","0.00007000"],["79931.99000000","0.00312000"],["79932.00000000","0.02400000"],["79932.09000000","0.00026000"],["79932.71000000","0.02000000"],["79933.19000000","0.00007000"],["79933.32000000","0.02000000"],["79933.35000000","0.00008000"],["79933.44000000","0.02000000"],["79933.48000000","0.02000000"],["79933.60000000","1.04939000"],["79933.66000000","0.01132000"],["79933.67000000","0.00010000"],["79933.92000000","0.00400000"],["79933.98000000","0.00007000"],["79934.00000000","0.02400000"],["79934.71000000","1.87677000"],["79935.15000000","0.00010000"],["79935.37000000","0.00070000"],["79935.52000000","0.01270000"],["79935.76000000","0.00007000"],["79935.99000000","0.00007000"],["79936.00000000","0.02407000"],["79936.45000000","0.04695000"],["79936.84000000","0.01713000"],["79937.02000000","0.73766000"],["79937.03000000","0.82399000"],["79937.08000000","0.36586000"],["79938.00000000","0.02400000"],["79938.01000000","0.20250000"],["79938.07000000","0.00007000"],["79938.18000000","1.04939000"],["79939.13000000","0.00535000"],["79939.42000000","0.00007000"],["79939.78000000","0.85077000"],["79939.79000000","1.87677000"],["79939.99000000","0.00047000"],["79940.00000000","0.24051000"],["79941.06000000","0.00007000"],["79941.11000000","0.00026000"],["79941.37000000","0.00111000"],["79941.42000000","0.00008000"],["79941.65000000","0.00010000"],["79942.00000000","0.02400000"],["79943.20000000","0.00200000"],["79943.52000000","0.00007000"],["79943.58000000","0.00007000"],["79943.64000000","0.00007000"],["79943.65000000","0.00007000"],["79943.84000000","0.03224000"],["79944.00000000","0.02400000"],["79945.22000000","0.12338000"],["79945.23000000","0.36586000"],["79945.67000000","0.00008000"],["79945.68000000","0.00021000"],["79945.82000000","0.00007000"],["79945.89000000","0.00100000"],["79945.99000000","0.00007000"],["79946.00000000","0.02400000"],["79946.19000000","0.00014000"],["79947.63000000","0.97151000"],["79947.64000000","1.04939000"],["79947.74000000","0.00007000"],["79947.94000000","0.00007000"],["79948.00000000","0.22650000"],["79949.32000000","0.00007000"],["79949.33000000","0.00026000"],["79949.49000000","0.00008000"],["79949.63000000","0.00010000"],["79949.99000000","0.00270000"],["79950.00000000","0.03129000"],["79951.28000000","0.00007000"],["79951.52000000","1.87677000"],["79951.56000000","0.03456000"],["79952.00000000","0.02400000"],["79952.56000000","2.04668000"],["79952.57000000","3.75321000"],["79953.16000000","0.00007000"],["79953.97000000","0.00007000"],["79954.00000000","0.02400000"],["79954.41000000","0.36586000"],["79954.88000000","2.31235000"],["79955.00000000","0.00011000"],["79955.15000000","0.00007000"],["79955.45000000","0.00012000"],["79955.51000000","0.40000000"],["79955.57000000","0.00070000"],["79955.64000000","0.12231000"],["79956.00000000","0.02400000"],["79956.44000000","0.99299000"],["79956.45000000","1.04939000"],["79957.15000000","0.00007000"],["79957.28000000","0.03224000"],["79957.39000000","0.00026000"],["79957.56000000","0.00008000"],["79957.61000000","0.00010000"],["79958.00000000","0.02400000"],["79958.13000000","0.00007000"],["79958.33000000","0.09823000"],["79958.40000000","0.00239000"],["79958.54000000","0.00500000"],["79958.89000000","1.87677000"],["79959.04000000","0.00007000"],["79959.18000000","0.20250000"],["79959.19000000","0.09322000"],["79959.21000000","0.00197000"],["79959.22000000","0.00491000"],["79959.42000000","0.00007000"],["79959.88000000","1.67735000"],["79959.96000000","0.00390000"],["79960.00000000","1.02515000"],["79960.29000000","0.00200000"],["79960.31000000","1.95361000"],["79960.96000000","0.00010000"],["79961.00000000","0.00202000"],["79961.44000000","0.00007000"],["79961.65000000","3.43863000"],["79961.72000000","1.04939000"],["79961.79000000","0.00007000"],["79962.00000000","0.02400000"],["79963.38000000","0.00025000"],["79963.65000000","0.00007000"],["79963.75000000","1.17139000"],["79963.76000000","1.87677000"],["79963.92000000","0.00007000"],["79964.00000000","0.02400000"],["79964.13000000","0.00078000"],["79964.37000000","0.00007000"],["79964.78000000","0.00018000"],["79964.80000000","1.99149000"],["79964.96000000","0.00007000"],["79965.16000000","0.00070000"],["79965.33000000","0.00380000"],["79965.59000000","0.00036000"],["79965.63000000","0.00008000"],["79965.87000000","0.00088000"],["79965.93000000","0.00400000"],["79966.00000000","0.02400000"],["79966.04000000","0.00032000"],["79966.29000000","0.00018000"],["79966.60000000","0.00012000"],["79966.80000000","0.00014000"],["79967.46000000","0.00007000"],["79967.51000000","0.00016000"],["79967.61000000","0.00025000"],["79967.75000000","0.13066000"],["79967.82000000","0.01662000"],["79967.83000000","0.36586000"],["79967.99000000","0.00556000"],["79968.00000000","0.02420000"],["79968.01000000","0.00151000"],["79968.15000000","0.00007000"],["79969.87000000","0.00176000"],["79970.00000000","0.02450000"],["79970.02000000","0.00011000"],["79970.50000000","0.00375000"],["79970.57000000","0.00010000"],["79970.58000000","0.00009000"],["79970.60000000","0.00053000"],["79971.08000000","0.00049000"],["79971.44000000","0.00007000"],["79972.00000000","0.02400000"],["79972.72000000","0.20250000"],["79972.95000000","0.85507000"],["79972.96000000","1.87677000"],["79972.98000000","0.03224000"],["79973.25000000","0.00007000"],["79973.56000000","0.00007000"],["79973.57000000","0.00010000"],["79973.70000000","0.00008000"],["79973.73000000","0.02804000"],["79974.00000000","0.02400000"],["79974.29000000","0.92475000"],["79974.34000000","0.00026000"],["79974.52000000","0.00010000"],["79974.56000000","0.00007000"],["79975.00000000","0.00024000"],["79975.99000000","0.01616000"],["79976.00000000","0.02400000"],["79976.12000000","0.00007000"],["79976.15000000","0.00007000"],["79976.26000000","0.00016000"],["79977.76000000","0.00007000"],["79977.90000000","0.00011000"],["79978.00000000","0.02400000"],["79978.27000000","0.00104000"],["79978.47000000","0.00007000"],["79979.11000000","0.00055000"],["79979.90000000","0.00007000"],["79979.99000000","1.04860000"],["79980.00000000","1.02719000"],["79980.46000000","0.04600000"],["79980.70000000","0.20250000"],["79981.00000000","0.00019000"],["79981.55000000","0.00010000"],["79981.62000000","0.01162000"],["79981.81000000","0.01580000"],["79982.00000000","0.02400000"],["79982.21000000","0.36586000"],["79982.32000000","0.00007000"],["79982.38000000","0.00020000"],["79982.41000000","0.00026000"],["79982.45000000","0.00007000"],["79982.55000000","1.87677000"],["79983.55000000","0.00117000"],["79983.69000000","0.00018000"],["79983.99000000","0.93606000"],["79984.00000000","0.02400000"],["79984.98000000","0.00014000"],["79985.16000000","0.00007000"],["79985.34000000","0.00007000"],["79985.44000000","0.00040000"],["79985.45000000","0.00029000"],["79985.71000000","0.00013000"],["79985.82000000","0.00100000"],["79986.00000000","0.02400000"],["79986.02000000","0.00375000"],["79986.41000000","0.00412000"],["79987.53000000","3.75154000"],["79987.54000000","0.09017000"],["79987.86000000","0.00031000"],["79988.00000000","0.02400000"],["79988.17000000","0.03224000"],["79988.68000000","0.20250000"],["79989.32000000","0.00007000"],["79989.53000000","0.00010000"],["79989.84000000","0.00008000"],["79989.96000000","0.00035000"],["79989.99000000","0.00270000"],["79990.00000000","0.02817000"],["79990.08000000","0.00007000"],["79990.65000000","0.00026000"],["79991.97000000","0.02071000"],["79992.00000000","0.02400000"],["79992.11000000","0.00160000"],["79992.16000000","0.00016000"],["79992.85000000","0.00394000"],["79992.87000000","0.00007000"],["79993.73000000","0.00007000"],["79994.00000000","0.02400000"],["79994.02000000","0.00375000"],["79994.15000000","0.00007000"],["79994.28000000","0.00011000"],["79994.55000000","0.00036000"],["79994.94000000","0.00007000"],["79995.56000000","0.00007000"],["79995.88000000","0.00007000"],["79996.00000000","0.02400000"],["79996.06000000","0.00038000"],["79996.18000000","0.18857000"],["79996.59000000","0.36586000"],["79996.66000000","0.20250000"],["79996.85000000","0.00007000"],["79997.44000000","0.00069000"],["79997.51000000","0.00010000"],["79997.62000000","0.00041000"],["79998.00000000","0.02400000"],["79998.36000000","0.00378000"],["79998.83000000","0.00026000"],["79999.00000000","0.00461000"],["79999.01000000","0.01307000"],["79999.03000000","0.01059000"],["79999.10000000","0.00010000"],["79999.17000000","0.00007000"],["79999.38000000","0.00007000"],["79999.55000000","0.00022000"],["79999.60000000","0.00136000"],["79999.85000000","0.00010000"],["79999.90000000","1.02096000"],["79999.94000000","0.00010000"],["80000.00000000","3.41279000"],["80000.17000000","0.04451000"],["80001.80000000","0.00007000"],["80001.83000000","0.00010000"],["80002.12000000","0.00008000"],["80002.42000000","0.00007000"],["80002.51000000","0.00007000"],["80003.61000000","0.00124000"],["80003.99000000","0.00409000"],["80004.15000000","0.00020000"],["80004.63000000","0.17095000"],["80004.64000000","0.20250000"],["80004.85000000","0.00268000"],["80005.00000000","0.00025000"],["80005.04000000","0.00007000"],["80005.46000000","0.36586000"],["80005.54000000","0.00017000"],["80005.95000000","0.00009000"],["80005.98000000","0.00008000"],["80006.05000000","0.00007000"],["80006.59000000","0.00033000"],["80006.85000000","0.00026000"],["80007.19000000","0.00018000"],["80007.44000000","0.00010000"],["80008.00000000","0.00087000"],["80008.04000000","0.00007000"],["80008.52000000","0.00022000"],["80008.56000000","0.00016000"],["80009.02000000","0.00007000"],["80009.70000000","0.00007000"],["80010.00000000","0.00057000"],["80010.03000000","0.00065000"],["80011.58000000","0.00125000"],["80011.59000000","0.00025000"],["80011.99000000","0.00125000"],["80012.00000000","0.30955000"],["80012.23000000","0.00007000"],["80012.46000000","0.03224000"],["80012.61000000","0.00023000"],["80012.62000000","0.20250000"],["80012.68000000","0.00008000"],["80012.85000000","0.80000000"],["80013.36000000","0.00007000"],["80013.42000000","0.00007000"],["80013.72000000","0.00011000"],["80013.89000000","0.00010000"],["80013.94000000","0.00011000"],["80014.31000000","0.00010000"],["80014.71000000","0.00055000"],["80014.90000000","0.00026000"],["80015.29000000","0.00045000"],["80015.37000000","0.00008000"],["80015.74000000","1.54613000"],["80016.06000000","0.00007000"],["80016.21000000","0.00007000"],["80016.66000000","0.00010000"],["80016.74000000","0.00400000"],["80017.14000000","0.04644000"],["80017.15000000","0.00076000"],["80017.16000000","1.50049000"],["80017.64000000","0.00027000"],["80018.81000000","0.00007000"],["80018.82000000","0.00007000"],["80019.08000000","0.36586000"],["80019.10000000","3.74998000"],["80019.33000000","0.00010000"],["80019.50000000","0.07720000"],["80019.99000000","0.00869000"],["80020.00000000","0.00078000"],["80020.60000000","0.20250000"],["80021.13000000","0.03224000"],["80021.19000000","0.00007000"],["80021.34000000","0.00007000"],["80021.42000000","0.00030000"],["80021.57000000","0.00024000"],["80021.85000000","0.00007000"],["80022.12000000","0.00008000"],["80022.22000000","0.00055000"],["80022.76000000","0.00014000"],["80023.13000000","0.00007000"],["80023.25000000","0.00094000"],["80023.28000000","0.00011000"],["80023.30000000","0.00026000"],["80023.52000000","0.00030000"],["80023.74000000","0.02000000"],["80023.77000000","0.00014000"],["80024.70000000","0.00011000"],["80024.83000000","0.00023000"],["80025.00000000","0.00043000"],["80025.16000000","0.00013000"],["80025.53000000","0.00008000"],["80025.67000000","0.00007000"],["80025.83000000","0.00007000"],["80026.29000000","0.00041000"],["80026.63000000","0.00007000"],["80026.98000000","0.05818000"],["80027.39000000","0.00008000"],["80027.71000000","0.00226000"],["80028.29000000","0.06617000"],["80028.44000000","0.00039000"],["80028.57000000","0.00015000"],["80028.58000000","0.20250000"],["80029.22000000","0.00007000"],["80029.37000000","0.00011000"],["80029.38000000","0.00008000"],["80029.41000000","0.00156000"],["80029.98000000","0.00270000"],["80030.00000000","0.01142000"],["80030.01000000","0.00077000"],["80030.07000000","0.00013000"],["80030.10000000","0.00009000"],["80030.30000000","0.00010000"],["80031.25000000","0.00007000"],["80031.31000000","0.00026000"],["80031.35000000","0.00122000"],["80031.41000000","0.00007000"],["80031.91000000","0.00007000"],["80032.00000000","0.00007000"],["80032.10000000","0.00160000"],["80032.15000000","0.12905000"],["80032.16000000","0.06930000"],["80032.69000000","0.00008000"],["80033.06000000","0.00010000"],["80033.17000000","0.00010000"],["80033.31000000","0.00265000"],["80033.33000000","0.00077000"],["80033.42000000","0.00139000"],["80033.52000000","0.00025000"],["80033.74000000","0.00100000"],["80034.28000000","0.00053000"],["80034.88000000","0.36586000"],["80034.90000000","0.00007000"],["80035.45000000","0.00007000"],["80035.46000000","0.00088000"],["80035.57000000","0.17543000"],["80035.58000000","0.34723000"],["80035.76000000","0.02000000"],["80036.03000000","0.00012000"],["80036.56000000","0.20250000"],["80036.64000000","0.00007000"],["80037.03000000","0.00043000"],["80037.19000000","0.00007000"],["80037.22000000","0.00015000"],["80037.44000000","0.00126000"],["80037.53000000","0.00007000"],["80037.64000000","0.00010000"],["80037.68000000","0.00041000"],["80038.18000000","0.00187000"],["80038.26000000","0.00008000"],["80038.52000000","0.03224000"],["80038.85000000","0.00072000"],["80038.93000000","0.00040000"],["80039.79000000","0.00007000"],["80039.81000000","0.00050000"],["80039.84000000","0.00026000"],["80040.00000000","0.00195000"],["80040.01000000","0.00052000"],["80040.24000000","0.00009000"],["80040.55000000","0.00150000"],["80040.78000000","0.01602000"],["80040.80000000","0.00010000"],["80040.93000000","0.00313000"],["80041.22000000","0.00016000"],["80041.64000000","0.00007000"],["80041.77000000","0.00014000"],["80042.15000000","0.00050000"],["80042.47000000","0.00007000"],["80042.73000000","0.00109000"],["80042.85000000","0.00007000"],["80043.25000000","0.00010000"],["80043.46000000","0.00010000"],["80043.78000000","0.00007000"],["80044.17000000","0.00012000"],["80044.53000000","0.08419000"],["80044.54000000","0.20250000"],["80044.63000000","0.00028000"],["80045.29000000","0.00010000"],["80045.39000000","0.00007000"],["80045.42000000","0.00008000"],["80045.63000000","0.00007000"],["80045.72000000","0.03134000"],["80045.95000000","0.00044000"],["80047.05000000","0.00031000"],["80047.75000000","0.00045000"],["80047.77000000","0.00007000"],["80047.88000000","0.00026000"],["80048.04000000","0.00007000"],["80049.06000000","0.00007000"],["80049.25000000","0.44309000"],["80049.26000000","0.36586000"],["80049.66000000","0.00125000"],["80049.87000000","0.00020000"],["80050.00000000","1.00087000"],["80050.28000000","0.00007000"],["80050.53000000","0.11607000"],["80051.13000000","0.00007000"],["80051.50000000","0.09345000"],["80051.51000000","0.10010000"],["80051.58000000","0.00007000"],["80051.76000000","0.00007000"],["80051.92000000","0.00007000"],["80051.99000000","0.00007000"],["80052.13000000","0.00012000"],["80052.44000000","0.00011000"],["80052.52000000","0.20250000"],["80052.98000000","0.00040000"],["80053.04000000","0.00007000"],["80053.26000000","0.00010000"],["80053.50000000","0.00129000"],["80053.52000000","0.00018000"],["80053.58000000","0.00007000"],["80053.64000000","0.00057000"],["80053.81000000","0.00007000"],["80054.31000000","0.00010000"],["80054.40000000","0.00058000"],["80054.46000000","0.00237000"],["80055.00000000","0.00007000"],["80055.26000000","0.00007000"],["80055.92000000","0.00053000"],["80056.01000000","0.01234000"],["80056.19000000","4.55669000"],["80056.27000000","0.00026000"],["80056.60000000","0.00025000"],["80056.73000000","0.00007000"],["80056.74000000","0.00164000"],["80057.14000000","0.00048000"],["80057.25000000","0.00074000"],["80057.49000000","0.00256000"],["80057.59000000","0.00028000"],["80057.61000000","0.00007000"],["80058.32000000","0.00007000"],["80058.82000000","0.00025000"],["80059.11000000","0.00042000"],["80059.43000000","0.00007000"],["80059.92000000","0.00007000"],["80060.00000000","0.00176000"],["80060.17000000","0.01961000"],["80060.24000000","0.00013000"],["80060.40000000","0.00034000"],["80060.49000000","0.20463000"],["80060.50000000","0.20250000"],["80060.52000000","0.00007000"],["80060.58000000","0.00029000"],["80061.53000000","0.00046000"],["80062.10000000","0.00007000"],["80062.54000000","0.11607000"],["80062.56000000","0.00014000"],["80062.78000000","0.36586000"],["80062.82000000","0.00007000"],["80063.61000000","0.00007000"],["80063.82000000","0.00009000"],["80064.00000000","0.00007000"],["80064.15000000","0.00017000"],["80064.72000000","0.00026000"],["80064.91000000","3.74793000"],["80065.00000000","0.00018000"],["80065.13000000","3.74783000"],["80065.15000000","0.00032000"],["80065.65000000","0.02105000"],["80066.09000000","0.00007000"],["80066.66000000","0.00058000"],["80066.84000000","0.00381000"],["80067.46000000","0.00007000"],["80067.99000000","0.00007000"],["80068.00000000","0.00025000"],["80068.75000000","0.00019000"],["80068.89000000","0.00007000"],["80068.90000000","0.00007000"],["80069.18000000","0.00223000"],["80069.99000000","0.00269000"],["80070.00000000","0.00057000"],["80071.26000000","0.00007000"],["80071.42000000","0.00017000"],["80072.13000000","0.00008000"],["80072.21000000","0.00107000"],["80073.03000000","0.00008000"],["80073.12000000","0.00056000"],["80073.18000000","0.00026000"],["80073.58000000","0.00007000"],["80073.59000000","0.00007000"],["80073.64000000","0.00012000"],["80074.10000000","0.00374000"],["80074.16000000","0.00021000"],["80074.17000000","0.00007000"],["80074.39000000","0.01253000"],["80074.55000000","0.11607000"],["80074.67000000","0.00056000"],["80074.73000000","0.00007000"],["80075.00000000","0.00033000"],["80075.18000000","0.00013000"],["80076.46000000","0.20250000"],["80076.50000000","0.00023000"],["80076.60000000","0.00045000"],["80076.70000000","0.00023000"],["80076.73000000","0.00021000"],["80076.80000000","0.00010000"],["80076.81000000","0.00007000"],["80076.92000000","0.00007000"],["80077.16000000","0.36586000"],["80077.39000000","0.00007000"],["80077.58000000","0.00026000"],["80077.62000000","0.00049000"],["80077.87000000","0.00007000"],["80079.13000000","0.00011000"],["80079.30000000","0.00026000"],["80079.31000000","0.00018000"],["80079.33000000","0.00009000"],["80079.46000000","0.00007000"],["80079.76000000","0.00010000"],["80079.84000000","0.00260000"],["80080.00000000","0.00090000"],["80080.39000000","0.00016000"],["80080.50000000","0.00007000"],["80080.83000000","0.00007000"],["80081.25000000","0.00012000"],["80081.50000000","0.00026000"],["80081.65000000","0.00007000"],["80082.11000000","0.00374000"],["80082.19000000","0.00016000"],["80082.30000000","0.00067000"],["80082.35000000","0.00007000"],["80082.43000000","0.11196000"],["80083.20000000","0.00007000"],["80083.24000000","0.01961000"],["80083.33000000","0.00007000"],["80083.43000000","0.00007000"],["80083.76000000","0.00008000"],["80083.83000000","0.00007000"],["80083.96000000","0.00010000"],["80084.02000000","0.01262000"],["80084.40000000","0.00007000"],["80084.74000000","0.00007000"],["80085.42000000","0.00027000"],["80085.63000000","0.00011000"],["80085.77000000","0.00400000"],["80086.27000000","0.00672000"],["80086.28000000","0.00013000"],["80086.37000000","0.00019000"],["80086.57000000","0.11607000"],["80086.68000000","0.00008000"],["80086.76000000","0.00007000"],["80087.57000000","0.00008000"],["80087.62000000","0.00011000"],["80087.68000000","0.00250000"],["80088.23000000","0.00010000"],["80088.88000000","0.00202000"],["80088.94000000","0.00240000"],["80089.13000000","0.00008000"],["80089.32000000","0.00190000"],["80089.55000000","0.00007000"],["80089.70000000","0.00026000"]]}}
{"rx_ns": 13975992087400, "frame": {"stream":"btcusdt@depth@100ms","data":{"e":"depthUpdate","E":1787650971214,"s":"BTCUSDT","U":99118683509,"u":99118683516,"b":[["79864.33000000","1.87945000"],["79857.22000000","0.00000000"],["79856.95000000","0.00626000"],["71877.90000000","0.00432000"],["63891.47000000","0.00000000"]],"a":[["79864.34000000","1.43906000"],["79873.77000000","0.00000000"]]}}}
{"rx_ns": 13976091847500, "frame": {"stream":"btcusdt@depth@100ms","data":{"e":"depthUpdate","E":1787650971314,"s":"BTCUSDT","U":99118683517,"u":99118683530,"b":[["79861.77000000","0.32906000"],["71877.90000000","0.00416000"],["63891.46000000","0.00000000"],["63891.00000000","0.00000000"]],"a":[]}}}
{"rx_ns": 13976194417200, "frame": {"stream":"btcusdt@depth@100ms","data":{"e":"depthUpdate","E":1787650971414,"s":"BTCUSDT","U":99118683531,"u":99118683540,"b":[["79864.33000000","1.97166000"],["79795.03000000","0.02087000"],["71877.90000000","0.00400000"],["63891.46000000","0.00000000"]],"a":[["79877.12000000","0.12528000"]]}}}
{"rx_ns": 13976294641700, "frame": {"stream":"btcusdt@depth@100ms","data":{"e":"depthUpdate","E":1787650971516,"s":"BTCUSDT","U":99118683541,"u":99118683544,"b":[["79795.03000000","0.00000000"],["71877.90000000","0.00416000"],["63891.47000000","0.00031000"]],"a":[["79877.12000000","0.00000000"]]}}}
{"rx_ns": 13976391627600, "frame": {"stream":"btcusdt@depth@100ms","data":{"e":"depthUpdate","E":1787650971614,"s":"BTCUSDT","U":99118683545,"u":99118683553,"b":[["78666.36000000","0.00030000"],["71877.90000000","0.00416000"],["63891.47000000","0.00000000"]],"a":[["81062.31000000","0.00030000"]]}}}
{"rx_ns": 13976492778600, "frame": {"stream":"btcusdt@depth@100ms","data":{"e":"depthUpdate","E":1787650971714,"s":"BTCUSDT","U":99118683554,"u":99118683560,"b":[["79864.33000000","1.96628000"],["79849.12000000","0.00007000"],["71877.90000000","0.00416000"],["71877.89000000","0.00008000"]],"a":[["79881.08000000","0.00007000"]]}}}
{"rx_ns": 13976592096800, "frame": {"stream":"btcusdt@depth@100ms","data":{"e":"depthUpdate","E":1787650971814,"s":"BTCUSDT","U":99118683561,"u":99118683563,"b":[["73475.20000000","0.00009000"],["71877.90000000","0.00416000"]],"a":[]}}}
{"rx_ns": 13976691890300, "frame": {"stream":"btcusdt@depth@100ms","data":{"e":"depthUpdate","E":1787650971914,"s":"BTCUSDT","U":99118683564,"u":99118683570,"b":[["71877.90000000","0.00432000"]],"a":[["79867.13000000","0.00063000"],["79867.15000000","0.00000000"],["79876.97000000","0.00000000"]]}}}
{"rx_ns": 13976803606600, "frame": {"stream":"btcusdt@depth20","data":{"lastUpdateId":99118683583,"bids":[["79864.33000000","1.96776000"],["79864.32000000","0.00076000"],["79864.31000000","0.00013000"],["79863.05000000","0.00975000"],["79862.90000000","0.00007000"],["79862.75000000","0.00400000"],["79862.45000000","0.00863000"],["79862.10000000","0.00007000"],["79861.85000000","0.00007000"],["79861.79000000","0.00007000"],["79861.78000000","0.60866000"],["79861.77000000","0.32906000"],["79861.69000000","0.00007000"],["79861.68000000","0.05260000"],["79861.67000000","0.00007000"],["79861.66000000","0.31340000"],["79861.65000000","0.22691000"],["79861.32000000","0.00014000"],["79861.30000000","0.00007000"],["79861.29000000","0.08007000"]],"asks":[["79864.34000000","1.43906000"],["79864.35000000","0.00712000"],["79864.36000000","0.00013000"],["79864.53000000","0.00007000"],["79864.54000000","0.00007000"],["79864.55000000","0.07184000"],["79864.59000000","0.00007000"],["79864.94000000","0.00007000"],["79864.95000000","0.11827000"],["79865.19000000","0.00014000"],["79865.57000000","0.00007000"],["79865.58000000","0.06152000"],["79865.61000000","0.00007000"],["79865.62000000","0.01761000"],["79865.99000000","0.00007000"],["79866.09000000","0.00007000"],["79866.19000000","0.00007000"],["79866.20000000","0.06159000"],["79866.71000000","0.00007000"],["79866.78000000","0.00007000"]]}}}
{"rx_ns": 13976803710600, "frame": {"stream":"btcusdt@depth@100ms","data":{"e":"depthUpdate","E":1787650972015,"s":"BTCUSDT","U":99118683571,"u":99118683583,"b":[["79864.33000000","1.96776000"],["79856.34000000","0.00423000"],["79848.35000000","0.00000000"],["79840.37000000","0.00008000"],["79832.38000000","0.00008000"],["79795.03000000","0.02087000"],["71877.90000000","0.00416000"],["63891.47000000","0.00031000"]],"a":[]}}}
{"rx_ns": 13976891799100, "frame": {"stream":"btcusdt@depth@100ms","data":{"e":"depthUpdate","E":1787650972114,"s":"BTCUSDT","U":99118683584,"u":99118683590,"b":[["79848.35000000","0.00408000"],["79840.37000000","0.00416000"],["79832.38000000","0.00416000"],["71877.90000000","0.00432000"],["71877.00000000","0.00000000"]],"a":[["80260.59000000","0.00000000"]]}}}
{"rx_ns": 13977000780100, "frame": {"stream":"btcusdt@depth@100ms","data":{"e":"depthUpdate","E":1787650972215,"s":"BTCUSDT","U":99118683591,"u":99118683595,"b":[["79795.03000000","0.00000000"],["71877.90000000","0.00416000"],["63891.47000000","0.00000000"]],"a":[]}}}
{"rx_ns": 13977092170300, "frame": {"stream":"btcusdt@depth@100ms","data":{"e":"depthUpdate","E":1787650972314,"s":"BTCUSDT","U":99118683596,"u":99118683602,"b":[["71877.90000000","0.00432000"],["63891.46000000","0.00000000"],["63891.00000000","0.00000000"]],"a":[]}}}
{"rx_ns": 13977191670000, "frame": {"stream":"btcusdt@depth@100ms","data":{"e":"depthUpdate","E":1787650972414,"s":"BTCUSDT","U":99118683603,"u":99118683605,"b":[["71877.90000000","0.00416000"],["63891.46000000","0.00000000"]],"a":[]}}}
{"rx_ns": 13977295666200, "frame": {"stream":"btcusdt@depth@100ms","data":{"e":"depthUpdate","E":1787650972514,"s":"BTCUSDT","U":99118683606,"u":99118683611,"b":[["73475.18000000","0.00014000"],["71877.90000000","0.00432000"],["63891.47000000","0.00031000"]],"a":[["79864.34000000","1.38906000"]]}}}
{"rx_ns": 13977391868200, "frame": {"stream":"btcusdt@depth@100ms","data":{"e":"depthUpdate","E":1787650972614,"s":"BTCUSDT","U":99118683612,"u":99118683627,"b":[["79864.33000000","1.95224000"],["79795.03000000","0.02087000"],["79650.00000000","1.07934000"],["78666.36000000","0.00030000"],["71877.90000000","0.00416000"],["71877.89000000","0.00000000"],["71877.88000000","0.00008000"],["63891.47000000","0.00000000"]],"a":[["79904.00000000","0.02807000"],["79904.76000000","0.00000000"],["81062.31000000","0.00030000"]]}}}
{"rx_ns": 13977491431700, "frame": {"stream":"btcusdt@depth@100ms","data":{"e":"depthUpdate","E":1787650972714,"s":"BTCUSDT","U":99118683628,"u":99118683634,"b":[["79849.12000000","0.00007000"],["79795.03000000","0.00000000"],["71877.90000000","0.00416000"]],"a":[["79864.34000000","1.38898000"],["79881.08000000","0.00007000"]]}}}
{"rx_ns": 13977592519000, "frame": {"stream":"btcusdt@depth@100ms","data":{"e":"depthUpdate","E":1787650972814,"s":"BTCUSDT","U":99118683635,"u":99118683637,"b":[["79795.03000000","0.02087000"],["71877.90000000","0.00416000"]],"a":[]}}}
{"rx_ns": 13977700491000, "frame": {"stream":"btcusdt@depth@100ms","data":{"e":"depthUpdate","E":1787650972914,"s":"BTCUSDT","U":99118683638,"u":99118683644,"b":[["79795.03000000","0.00000000"],["71877.90000000","0.00416000"]],"a":[["79864.34000000","1.38833000"]]}}}
{"rx_ns": 13977798540900, "frame": {"stream":"btcusdt@depth20","data":{"lastUpdateId":99118683649,"bids":[["79864.33000000","1.85224000"],["79864.32000000","0.00076000"],["79864.31000000","0.00013000"],["79863.05000000","0.00975000"],["79862.90000000","0.00007000"],["79862.75000000","0.00400000"],["79862.45000000","0.00863000"],["79862.10000000","0.00007000"],["79861.85000000","0.00007000"],["79861.79000000","0.00007000"],["79861.78000000","0.60866000"],["79861.77000000","0.32906000"],["79861.69000000","0.00007000"],["79861.68000000","0.05260000"],["79861.67000000","0.00007000"],["79861.66000000","0.31340000"],["79861.65000000","0.22691000"],["79861.32000000","0.00014000"],["79861.30000000","0.00007000"],["79861.29000000","0.08007000"]],"asks":[["79864.34000000","1.38833000"],["79864.35000000","0.00712000"],["79864.36000000","0.00013000"],["79864.53000000","0.00007000"],["79864.54000000","0.00007000"],["79864.55000000","0.07184000"],["79864.59000000","0.00007000"],["79864.94000000","0.00007000"],["79864.95000000","0.11827000"],["79865.19000000","0.00014000"],["79865.57000000","0.00007000"],["79865.58000000","0.06152000"],["79865.61000000","0.00007000"],["79865.62000000","0.01761000"],["79865.99000000","0.00007000"],["79866.09000000","0.00007000"],["79866.19000000","0.00007000"],["79866.20000000","0.06159000"],["79866.71000000","0.00007000"],["79866.78000000","0.00007000"]]}}}
{"rx_ns": 13977798644800, "frame": {"stream":"btcusdt@depth@100ms","data":{"e":"depthUpdate","E":1787650973014,"s":"BTCUSDT","U":99118683645,"u":99118683649,"b":[["79864.33000000","1.85224000"],["79795.03000000","0.02087000"],["71877.90000000","0.00400000"],["63891.47000000","0.00031000"]],"a":[["79877.09000000","0.12535000"]]}}}
{"rx_ns": 13977894392600, "frame": {"stream":"btcusdt@depth@100ms","data":{"e":"depthUpdate","E":1787650973114,"s":"BTCUSDT","U":99118683650,"u":99118683658,"b":[["79864.33000000","1.87115000"],["79795.03000000","0.00000000"],["73475.18000000","0.00000000"],["71877.90000000","0.00416000"],["71877.00000000","0.00000000"]],"a":[["79877.09000000","0.00007000"]]}}}
{"rx_ns": 13978003268800, "frame": {"stream":"btcusdt@depth@100ms","data":{"e":"depthUpdate","E":1787650973214,"s":"BTCUSDT","U":99118683659,"u":99118683669,"b":[["79864.33000000","1.96959000"],["79795.03000000","0.02087000"],["71877.90000000","0.00416000"],["63891.47000000","0.00000000"]],"a":[]}}}
{"rx_ns": 13978091927500, "frame": {"stream":"btcusdt@depth@100ms","data":{"e":"depthUpdate","E":1787650973314,"s":"BTCUSDT","U":99118683670,"u":99118683680,"b":[["79795.03000000","0.00000000"],["71877.90000000","0.00416000"],["71877.88000000","0.00000000"],["63891.46000000","0.00000000"],["63891.00000000","0.00000000"]],"a":[["79864.34000000","1.38807000"]]}}}
{"rx_ns": 13978191598300, "frame": {"stream":"btcusdt@depth@100ms","data":{"e":"depthUpdate","E":1787650973414,"s":"BTCUSDT","U":99118683681,"u":99118683685,"b":[["71877.90000000","0.00432000"],["63891.46000000","0.00000000"]],"a":[["79876.86000000","0.00008000"]]}}}
{"rx_ns": 13978292167100, "frame": {"stream":"btcusdt@depth@100ms","data":{"e":"depthUpdate","E":1787650973514,"s":"BTCUSDT","U":99118683686,"u":99118683689,"b":[["71877.90000000","0.00416000"],["63891.47000000","0.00031000"]],"a":[]}}}
{"rx_ns": 13978391392300, "frame": {"stream":"btcusdt@depth@100ms","data":{"e":"depthUpdate","E":1787650973614,"s":"BTCUSDT","U":99118683690,"u":99118683701,"b":[["79843.06000000","0.04427000"],["79832.83000000","0.00000000"],["78666.36000000","0.00030000"],["71877.90000000","0.00432000"],["63891.47000000","0.00000000"],["63891.00000000","0.00000000"]],"a":[["81062.31000000","0.00030000"]]}}}
{"rx_ns": 13978492873100, "frame": {"stream":"btcusdt@depth@100ms","data":{"e":"depthUpdate","E":1787650973715,"s":"BTCUSDT","U":99118683702,"u":99118683706,"b":[["79849.12000000","0.00007000"],["71877.90000000","0.00416000"]],"a":[["79877.03000000","0.12528000"],["79881.08000000","0.00007000"]]}}}
{"rx_ns": 13978591815400, "frame": {"stream":"btcusdt@depth@100ms","data":{"e":"depthUpdate","E":1787650973814,"s":"BTCUSDT","U":99118683707,"u":99118683714,"b":[["79864.33000000","1.96930000"],["73475.20000000","0.00000000"],["71877.90000000","0.00432000"]],"a":[["79877.03000000","0.00000000"]]}}}
{"rx_ns": 13978707493500, "frame": {"stream":"btcusdt@depth@100ms","data":{"e":"depthUpdate","E":1787650973914,"s":"BTCUSDT","U":99118683715,"u":99118683724,"b":[["79864.33000000","1.95050000"],["71877.90000000","0.00416000"],["63891.00000000","0.00200000"]],"a":[["79872.00000000","0.02807000"],["79877.07000000","0.12528000"],["79902.00000000","0.02800000"],["79902.14000000","0.00000000"],["79904.00000000","0.02407000"]]}}}
{"rx_ns": 13978801448400, "frame": {"stream":"btcusdt@depth20","data":{"lastUpdateId":99118684118,"bids":[["79864.33000000","0.62656000"],["79864.32000000","0.00076000"],["79864.31000000","0.00013000"],["79863.05000000","0.00975000"],["79862.90000000","0.00007000"],["79862.45000000","0.00870000"],["79862.29000000","0.00007000"],["79862.28000000","0.02000000"],["79862.10000000","0.00007000"],["79861.78000000","0.00014000"],["79861.77000000","0.00028000"],["79861.69000000","0.00007000"],["79861.68000000","0.05260000"],["79861.67000000","0.00007000"],["79861.66000000","0.31333000"],["79861.65000000","0.00746000"],["79861.32000000","0.00007000"],["79861.29000000","0.00021000"],["79861.17000000","0.01403000"],["79861.04000000","0.00007000"]],"asks":[["79864.34000000","3.40796000"],["79864.35000000","0.00663000"],["79864.36000000","0.00013000"],["79864.53000000","0.00007000"],["79864.55000000","0.07191000"],["79864.59000000","0.00007000"],["79864.91000000","0.00026000"],["79864.95000000","0.11827000"],["79865.19000000","0.00014000"],["79865.45000000","0.00063000"],["79865.58000000","0.00014000"],["79865.62000000","0.01761000"],["79865.99000000","0.00007000"],["79866.00000000","0.00400000"],["79866.09000000","0.00007000"],["79866.20000000","0.00014000"],["79866.47000000","0.04000000"],["79866.71000000","0.00007000"],["79866.78000000","0.00007000"],["79866.82000000","0.00014000"]]}}}
{"rx_ns": 13978801559600, "frame": {"stream":"btcusdt@depth@100ms","data":{"e":"depthUpdate","E":1787650974014,"s":"BTCUSDT","U":99118683725,"u":99118684118,"b":[["79864.33000000","0.62656000"],["79862.75000000","0.00000000"],["79862.45000000","0.00870000"],["79862.29000000","0.00007000"],["79862.28000000","0.02000000"],["79861.85000000","0.00000000"],["79861.79000000","0.00000000"],["79861.78000000","0.00014000"],["79861.77000000","0.00028000"],["79861.66000000","0.31333000"],["79861.65000000","0.00746000"],["79861.32000000","0.00007000"],["79861.30000000","0.00000000"],["79861.29000000","0.00021000"],["79861.17000000","0.01403000"],["79861.05000000","0.00000000"],["79861.04000000","0.00007000"],["79860.86000000","0.00000000"],["79860.72000000","0.00000000"],["79860.45000000","0.00000000"],["79860.44000000","0.00000000"],["79860.43000000","0.00021000"],["79860.19000000","0.00000000"],["79860.18000000","0.00000000"],["79860.02000000","0.00007000"],["79859.89000000","0.01684000"],["79859.25000000","0.00000000"],["79859.24000000","0.00000000"],["79859.23000000","0.00000000"],["79859.22000000","0.00007000"],["79859.21000000","0.12931000"],["79859.00000000","0.00000000"],["79858.61000000","0.01691000"],["79858.42000000","0.00000000"],["79858.18000000","0.00000000"],["79858.17000000","0.00000000"],["79858.15000000","0.00134000"],["79858.04000000","0.00909000"],["79858.00000000","0.02407000"],["79857.55000000","0.00000000"],["79857.54000000","0.00000000"],["79857.50000000","0.00000000"],["79857.45000000","0.00007000"],["79857.44000000","0.00000000"],["79857.43000000","0.00000000"],["79857.21000000","0.00000000"],["79856.95000000","0.00000000"],["79856.92000000","0.00000000"],["79856.69000000","0.00000000"],["79856.64000000","0.00000000"],["79856.62000000","0.00000000"],["79856.59000000","0.00000000"],["79856.39000000","0.00000000"],["79856.01000000","0.00000000"],["79855.13000000","0.00000000"],["79855.12000000","0.00000000"],["79855.11000000","0.00000000"],["79855.10000000","0.00000000"],["79855.09000000","0.00000000"],["79854.69000000","0.00000000"],["79854.68000000","0.05612000"],["79854.31000000","0.00000000"],["79854.15000000","0.06104000"],["79854.06000000","0.00000000"],["79853.58000000","0.00007000"],["79853.16000000","0.00016000"],["79852.99000000","0.00000000"],["79852.75000000","0.00000000"],["79852.69000000","0.00000000"],["79852.07000000","0.00000000"],["79852.04000000","0.00160000"],["79851.74000000","0.00000000"],["79851.58000000","0.01705000"],["79851.48000000","0.02000000"],["79851.38000000","0.08000000"],["79851.05000000","0.00000000"],["79850.75000000","0.00000000"],["79850.41000000","0.00000000"],["79850.25000000","0.45161000"],["79850.24000000","0.08566000"],["79850.00000000","0.03418000"],["79849.71000000","0.00007000"],["79848.37000000","0.00626000"],["79847.65000000","0.00626000"],["79847.58000000","0.00000000"],["79845.36000000","0.01200000"],["79845.35000000","0.00000000"],["79844.10000000","0.00000000"],["79843.97000000","0.00000000"],["79843.83000000","0.00000000"],["79843.63000000","0.00000000"],["79843.06000000","0.00000000"],["79842.50000000","0.00000000"],["79840.00000000","0.27773000"],["79837.41000000","0.41113000"],["79835.46000000","0.33828000"],["79835.23000000","0.04584000"],["79835.14000000","0.00000000"],["79830.00000000","0.07438000"],["79829.78000000","0.33830000"],["79828.00000000","0.02800000"],["79826.00000000","0.02800000"],["79822.62000000","0.00007000"],["79820.00000000","0.02800000"],["79818.75000000","0.00007000"],["79807.39000000","0.00000000"],["79797.44000000","0.00000000"],["79792.96000000","0.00000000"],["79791.90000000","0.00000000"],["79791.44000000","0.00000000"],["79791.24000000","0.00000000"],["79791.18000000","1.48843000"],["79791.17000000","1.24105000"],["79790.75000000","0.00000000"],["79789.98000000","0.00000000"],["79789.70000000","0.00000000"],["79789.50000000","0.12077000"],["79780.81000000","0.00000000"],["79779.46000000","1.87677000"],["79778.17000000","0.62589000"],["79762.27000000","0.11701000"],["79726.70000000","0.55248000"],["79724.01000000","0.00000000"],["71877.90000000","0.00432000"],["71877.89000000","0.00008000"],["63891.47000000","0.00031000"],["63891.00000000","0.00000000"]],"a":[["79864.34000000","3.40796000"],["79864.35000000","0.00663000"],["79864.54000000","0.00000000"],["79864.55000000","0.07191000"],["79864.91000000","0.00026000"],["79864.94000000","0.00000000"],["79865.01000000","0.00000000"],["79865.18000000","0.00000000"],["79865.45000000","0.00063000"],["79865.57000000","0.00000000"],["79865.58000000","0.00014000"],["79865.61000000","0.00000000"],["79865.68000000","0.00000000"],["79865.98000000","0.00000000"],["79866.00000000","0.00400000"],["79866.19000000","0.00000000"],["79866.20000000","0.00014000"],["79866.47000000","0.04000000"],["79866.81000000","0.00000000"],["79866.82000000","0.00014000"],["79866.89000000","0.00000000"],["79867.06000000","0.00000000"],["79867.07000000","0.00000000"],["79867.13000000","0.00000000"],["79867.26000000","0.00000000"],["79867.34000000","0.00000000"],["79867.62000000","0.00400000"],["79867.99000000","0.00000000"],["79868.00000000","0.02814000"],["79868.17000000","0.67313000"],["79868.23000000","0.00400000"],["79868.41000000","0.00000000"],["79868.68000000","0.00007000"],["79868.79000000","0.00015000"],["79869.17000000","1.87677000"],["79869.19000000","0.00000000"],["79869.30000000","0.00007000"],["79869.92000000","0.00000000"],["79870.00000000","0.02963000"],["79870.33000000","0.00000000"],["79870.54000000","0.00000000"],["79870.59000000","0.00000000"],["79871.16000000","0.00000000"],["79871.66000000","0.00000000"],["79871.78000000","0.00000000"],["79871.79000000","0.00000000"],["79871.91000000","1.04939000"],["79871.99000000","0.00000000"],["79872.03000000","0.00000000"],["79872.05000000","0.00719000"],["79872.40000000","0.00000000"],["79872.55000000","0.03224000"],["79873.02000000","0.00000000"],["79873.28000000","0.00000000"],["79873.40000000","0.00000000"],["79873.64000000","0.00000000"],["79873.96000000","0.89428000"],["79874.25000000","0.00000000"],["79874.73000000","0.00000000"],["79874.90000000","0.08576000"],["79875.65000000","0.00000000"],["79875.92000000","1.38380000"],["79875.94000000","0.00000000"],["79876.40000000","0.00000000"],["79877.07000000","0.00000000"],["79877.14000000","0.12528000"],["79878.85000000","0.02000000"],["79879.15000000","0.00000000"],["79879.18000000","0.00000000"],["79879.38000000","0.33809000"],["79880.00000000","0.11797000"],["79880.30000000","0.33809000"],["79881.56000000","0.12400000"],["79882.51000000","0.03224000"],["79886.00000000","0.02800000"],["79886.50000000","0.00000000"],["79886.97000000","0.62604000"],["79890.00000000","0.07452000"],["79890.46000000","0.00000000"],["79890.65000000","0.00000000"],["79891.99000000","1.10030000"],["79893.00000000","0.00408000"],["79893.53000000","0.00000000"],["79896.60000000","0.00000000"],["79898.00000000","0.02400000"],["79899.75000000","0.00000000"],["79900.12000000","0.00000000"],["79902.00000000","0.02400000"],["79906.33000000","0.00000000"],["79931.76000000","0.00000000"],["79962.89000000","0.00556000"],["79967.99000000","0.00000000"]]}}}
{"rx_ns": 13978895851000, "frame": {"stream":"btcusdt@depth@100ms","data":{"e":"depthUpdate","E":1787650974114,"s":"BTCUSDT","U":99118684119,"u":99118684317,"b":[["79864.33000000","0.37911000"],["79864.32000000","0.00076000"],["79863.05000000","0.00968000"],["79862.45000000","0.00863000"],["79862.28000000","0.02014000"],["79861.78000000","0.00000000"],["79861.77000000","0.00014000"],["79861.67000000","0.00000000"],["79861.66000000","0.00021000"],["79861.65000000","0.00746000"],["79861.29000000","0.00007000"],["79861.18000000","0.00007000"],["79861.17000000","0.01417000"],["79860.01000000","0.04258000"],["79859.90000000","0.00007000"],["79859.89000000","0.01691000"],["79859.70000000","0.00007000"],["79859.69000000","0.33818000"],["79859.22000000","0.00000000"],["79859.21000000","0.00725000"],["79859.00000000","0.12529000"],["79858.13000000","0.06138000"],["79858.00000000","0.02414000"],["79857.56000000","0.00026000"],["79857.52000000","0.00007000"],["79857.51000000","0.06138000"],["79857.45000000","0.00014000"],["79856.90000000","0.00007000"],["79856.89000000","0.06138000"],["79856.28000000","0.00101000"],["79856.27000000","0.06138000"],["79855.66000000","0.00007000"],["79855.65000000","0.06388000"],["79855.04000000","0.00000000"],["79855.03000000","0.06138000"],["79855.00000000","0.00000000"],["79854.92000000","0.31314000"],["79854.69000000","0.00000000"],["79854.68000000","0.05605000"],["79854.60000000","0.00048000"],["79854.58000000","0.00069000"],["79854.29000000","0.00000000"],["79854.17000000","0.06138000"],["79854.16000000","0.40655000"],["79854.15000000","0.00000000"],["79853.58000000","0.00014000"],["79853.39000000","0.00048000"],["79853.16000000","0.00000000"],["79852.57000000","0.02480000"],["79850.27000000","0.00250000"],["79850.25000000","0.45787000"],["79850.18000000","0.00189000"],["79849.72000000","0.00626000"],["79849.71000000","0.00014000"],["79849.32000000","0.00400000"],["79848.37000000","0.00000000"],["79847.65000000","0.00000000"],["79845.35000000","0.01200000"],["79843.21000000","0.00000000"],["79837.00000000","0.00000000"],["79824.00000000","0.03807000"],["79795.03000000","0.02087000"],["79789.50000000","0.00000000"],["79789.15000000","0.00000000"],["79788.75000000","0.00000000"],["79778.17000000","0.00000000"],["79734.16000000","0.00000000"],["79686.66000000","0.00000000"],["79546.58000000","0.00000000"],["71877.90000000","0.00416000"]],"a":[["79864.34000000","3.40763000"],["79864.35000000","0.00649000"],["79864.53000000","0.00000000"],["79864.55000000","0.07184000"],["79864.91000000","0.00000000"],["79864.95000000","0.04831000"],["79865.43000000","0.00000000"],["79865.44000000","0.00250000"],["79865.58000000","0.00000000"],["79865.62000000","0.01761000"],["79866.15000000","0.00930000"],["79866.20000000","0.00000000"],["79866.47000000","0.04014000"],["79866.82000000","0.00000000"],["79866.90000000","0.02093000"],["79867.27000000","0.04786000"],["79867.99000000","0.00000000"],["79868.00000000","0.02835000"],["79868.16000000","0.36586000"],["79868.18000000","0.02079000"],["79868.68000000","0.00000000"],["79869.30000000","0.00000000"],["79870.00000000","0.02956000"],["79871.90000000","1.35133000"],["79873.09000000","0.02253000"],["79873.38000000","0.33812000"],["79873.96000000","0.00000000"],["79873.99000000","0.00250000"],["79874.44000000","0.12519000"],["79874.83000000","0.00000000"],["79879.54000000","0.00000000"],["79900.00000000","0.07406000"],["79901.07000000","0.02442000"],["79973.73000000","0.00000000"],["80056.19000000","0.00000000"],["80143.10000000","0.00000000"]]}}}
{"rx_ns": 13978991993000, "frame": {"stream":"btcusdt@depth@100ms","data":{"e":"depthUpdate","E":1787650974214,"s":"BTCUSDT","U":99118684318,"u":99118684409,"b":[["79864.33000000","0.38068000"],["79864.32000000","0.00076000"],["79863.05000000","0.00021000"],["79861.68000000","0.05260000"],["79861.66000000","0.00007000"],["79861.65000000","0.00028000"],["79861.17000000","0.01424000"],["79860.50000000","0.00007000"],["79860.02000000","0.00000000"],["79860.01000000","0.00216000"],["79860.00000000","0.00007000"],["79859.99000000","0.06138000"],["79859.89000000","0.01712000"],["79859.71000000","0.00007000"],["79859.70000000","0.06145000"],["79859.21000000","0.00027000"],["79859.01000000","0.00000000"],["79859.00000000","0.00000000"],["79858.61000000","0.01698000"],["79858.14000000","0.00007000"],["79856.28000000","0.00094000"],["79855.66000000","0.00000000"],["79854.98000000","0.06138000"],["79854.94000000","0.87540000"],["79854.93000000","1.04939000"],["79854.68000000","0.00000000"],["79854.17000000","0.00000000"],["79854.16000000","0.00000000"],["79851.39000000","0.00626000"],["79850.25000000","0.98955000"],["79850.21000000","1.87677000"],["79849.72000000","0.00000000"],["79795.03000000","0.00000000"],["79724.67000000","0.04534000"],["79537.81000000","0.00039000"],["71877.90000000","0.00432000"],["63891.47000000","0.00000000"]],"a":[["79864.34000000","3.40144000"],["79864.35000000","0.01258000"],["79864.54000000","0.00007000"],["79864.94000000","0.00007000"],["79864.95000000","0.04838000"],["79865.43000000","0.00626000"],["79865.61000000","0.00007000"],["79865.62000000","0.01761000"],["79866.15000000","0.00944000"],["79866.46000000","0.00007000"],["79866.89000000","0.00007000"],["79867.26000000","0.00007000"],["79867.99000000","0.00007000"],["79868.00000000","0.02828000"],["79868.15000000","0.01607000"],["79873.94000000","0.00000000"],["79873.95000000","0.00000000"],["79964.21000000","0.02804000"],["80134.27000000","0.00025000"]]}}}
{"rx_ns": 13979096450200, "frame": {"stream":"btcusdt@depth@100ms","data":{"e":"depthUpdate","E":1787650974314,"s":"BTCUSDT","U":99118684410,"u":99118684483,"b":[["79864.33000000","0.38082000"],["79863.05000000","0.00007000"],["79861.68000000","0.05260000"],["79861.65000000","0.00014000"],["79861.17000000","0.01424000"],["79860.01000000","0.00202000"],["79859.99000000","0.06152000"],["79859.89000000","0.01712000"],["79859.70000000","0.06159000"],["79855.04000000","0.01600000"],["79854.53000000","0.02188000"],["79845.36000000","0.00800000"],["79845.35000000","0.00000000"],["79839.79000000","0.51800000"],["79834.30000000","0.62645000"],["79831.45000000","0.33829000"],["79830.21000000","0.00000000"],["79827.31000000","0.00400000"],["79823.12000000","0.33833000"],["79815.84000000","1.02846000"],["79807.23000000","0.46895000"],["79807.02000000","0.00000000"],["79790.29000000","0.00000000"],["79788.14000000","0.12261000"],["79787.39000000","0.00400000"],["79758.36000000","0.00000000"],["79755.46000000","0.00400000"],["79710.46000000","0.00000000"],["79707.56000000","0.00400000"],["79681.93000000","4.39167000"],["79638.61000000","0.00000000"],["79635.72000000","0.00400000"],["63891.46000000","0.00000000"],["63891.00000000","0.00000000"]],"a":[["79864.34000000","3.41386000"],["79864.95000000","0.04838000"],["79865.43000000","0.00014000"],["79866.70000000","0.00626000"],["79867.27000000","0.04779000"],["79867.75000000","0.00705000"],["79873.38000000","0.00000000"],["79893.32000000","0.33803000"],["80049.44000000","4.51187000"]]}}}
{"rx_ns": 13979196762300, "frame": {"stream":"btcusdt@depth@100ms","data":{"e":"depthUpdate","E":1787650974414,"s":"BTCUSDT","U":99118684484,"u":99118684549,"b":[["79864.33000000","0.38089000"],["79862.53000000","0.00007000"],["79862.52000000","0.02480000"],["79859.71000000","0.00007000"],["79859.70000000","0.06159000"],["79858.14000000","0.00007000"],["79857.52000000","0.00000000"],["79856.90000000","0.00000000"],["79854.03000000","0.00007000"],["79852.57000000","0.00000000"],["79851.12000000","0.00250000"],["79850.27000000","0.00000000"],["79827.31000000","0.00000000"],["79827.11000000","0.00400000"],["79818.75000000","0.00000000"],["79755.46000000","0.00000000"],["79755.26000000","0.00400000"],["79707.56000000","0.00000000"],["79707.36000000","0.00400000"],["79641.60000000","0.00000000"],["79599.03000000","0.00771000"],["71877.90000000","0.00432000"],["71877.00000000","0.00000000"],["63891.46000000","0.00000000"]],"a":[["79864.95000000","0.04831000"],["79865.43000000","0.00000000"],["79865.44000000","0.00000000"],["79866.47000000","0.04021000"],["79866.70000000","0.00640000"],["79867.08000000","0.00250000"],["79867.26000000","0.00000000"],["79867.99000000","0.00000000"],["79868.14000000","0.00000000"],["79868.15000000","0.00000000"],["79871.66000000","0.01600000"]]}}}
{"rx_ns": 13979293166400, "frame": {"stream":"btcusdt@depth@100ms","data":{"e":"depthUpdate","E":1787650974514,"s":"BTCUSDT","U":99118684550,"u":99118684580,"b":[["79864.33000000","0.38096000"],["79864.32000000","0.00083000"],["79855.05000000","0.01600000"],["79855.04000000","0.00000000"],["79852.68000000","0.00000000"],["79852.66000000","0.00400000"],["79849.32000000","0.00000000"],["79827.11000000","0.00000000"],["79827.04000000","0.00400000"],["71877.90000000","0.00432000"],["63891.47000000","0.00031000"]],"a":[["79867.26000000","0.00007000"],["79867.99000000","0.00007000"],["79868.00000000","0.02821000"],["79868.15000000","0.00007000"]]}}}
{"rx_ns": 13979396653500, "frame": {"stream":"btcusdt@depth@100ms","data":{"e":"depthUpdate","E":1787650974614,"s":"BTCUSDT","U":99118684581,"u":99118684619,"b":[["79864.33000000","0.38096000"],["79855.06000000","0.01600000"],["79855.05000000","0.00000000"],["79852.72000000","0.00000000"],["79852.66000000","0.00000000"],["79852.62000000","0.00000000"],["79827.04000000","0.00400000"],["78666.36000000","0.00030000"],["71877.90000000","0.00416000"],["63891.47000000","0.00000000"]],"a":[["81062.31000000","0.00030000"]]}}}
{"rx_ns": 13979497850800, "frame": {"stream":"btcusdt@depth@100ms","data":{"e":"depthUpdate","E":1787650974714,"s":"BTCUSDT","U":99118684620,"u":99118684696,"b":[["79864.33000000","0.38249000"],["79862.90000000","0.00000000"],["79862.52000000","0.02494000"],["79859.69000000","0.33825000"],["79858.96000000","0.00000000"],["79858.85000000","0.00007000"],["79858.84000000","0.00000000"],["79856.34000000","0.00583000"],["79855.07000000","0.01200000"],["79855.06000000","0.00400000"],["79852.72000000","0.00000000"],["79852.71000000","0.00000000"],["79852.61000000","0.03200000"],["79852.56000000","0.00000000"],["79849.12000000","0.00000000"],["79848.35000000","0.00568000"],["79840.37000000","0.00008000"],["79832.38000000","0.00008000"],["79827.04000000","0.00400000"],["79818.75000000","0.00007000"],["71877.90000000","0.00432000"],["66786.00000000","0.01524000"]],"a":[["79864.34000000","3.50759000"],["79881.08000000","0.00000000"],["79881.25000000","0.02007000"],["79882.06000000","0.02000000"],["79897.00000000","0.70000000"],["79929.44000000","0.00000000"]]}}}
{"rx_ns": 13979598778400, "frame": {"stream":"btcusdt@depth@100ms","data":{"e":"depthUpdate","E":1787650974814,"s":"BTCUSDT","U":99118684697,"u":99118684711,"b":[["79864.33000000","0.38242000"],["79859.69000000","0.33818000"],["79858.85000000","0.00000000"],["79849.12000000","0.00007000"],["79840.37000000","0.00576000"],["79832.38000000","0.00576000"],["79832.00000000","0.72800000"],["79827.04000000","0.00000000"],["79827.01000000","0.00400000"],["79788.34000000","0.02087000"],["71877.90000000","0.00432000"]],"a":[["79881.08000000","0.00007000"]]}}}
{"rx_ns": 13979691659500, "frame": {"stream":"btcusdt@depth@100ms","data":{"e":"depthUpdate","E":1787650974914,"s":"BTCUSDT","U":99118684712,"u":99118684720,"b":[["79788.34000000","0.00000000"],["79784.98000000","0.02600000"],["79784.12000000","0.02000000"],["71877.90000000","0.00432000"]],"a":[["79889.75000000","0.00000000"],["79890.57000000","0.00000000"],["79985.36000000","0.01961000"],["80060.17000000","0.00000000"]]}}}
{"rx_ns": 13979794884300, "frame": {"stream":"btcusdt@depth20","data":{"lastUpdateId":99118684732,"bids":[["79864.33000000","0.38249000"],["79864.32000000","0.00083000"],["79864.31000000","0.00013000"],["79863.05000000","0.00007000"],["79862.53000000","0.00007000"],["79862.52000000","0.02494000"],["79862.45000000","0.00863000"],["79862.29000000","0.00007000"],["79862.28000000","0.02014000"],["79862.10000000","0.00007000"],["79861.77000000","0.00014000"],["79861.69000000","0.00007000"],["79861.68000000","0.05260000"],["79861.66000000","0.00007000"],["79861.65000000","0.00014000"],["79861.32000000","0.00007000"],["79861.29000000","0.00007000"],["79861.18000000","0.00007000"],["79861.17000000","0.01424000"],["79861.04000000","0.00007000"]],"asks":[["79864.34000000","3.50759000"],["79864.35000000","0.01258000"],["79864.36000000","0.00013000"],["79864.54000000","0.00007000"],["79864.55000000","0.07184000"],["79864.59000000","0.00007000"],["79864.94000000","0.00007000"],["79864.95000000","0.04831000"],["79865.19000000","0.00014000"],["79865.45000000","0.00063000"],["79865.61000000","0.00007000"],["79865.62000000","0.01761000"],["79865.99000000","0.00007000"],["79866.00000000","0.00400000"],["79866.09000000","0.00007000"],["79866.15000000","0.00944000"],["79866.46000000","0.00007000"],["79866.47000000","0.04021000"],["79866.70000000","0.00640000"],["79866.71000000","0.00007000"]]}}}
{"rx_ns": 13979795051700, "frame": {"stream":"btcusdt@depth@100ms","data":{"e":"depthUpdate","E":1787650975014,"s":"BTCUSDT","U":99118684721,"u":99118684732,"b":[["79864.33000000","0.38249000"],["79859.69000000","0.33825000"],["79858.63000000","0.00007000"],["79858.62000000","0.12529000"],["79854.53000000","0.00000000"],["79790.88000000","0.02400000"],["79783.94000000","0.02400000"],["71877.90000000","0.00432000"],["71877.00000000","0.00010000"],["63891.47000000","0.00031000"]],"a":[["79880.27000000","0.09194000"]]}}}
{"rx_ns": 13979896383500, "frame": {"stream":"btcusdt@depth@100ms","data":{"e":"depthUpdate","E":1787650975114,"s":"BTCUSDT","U":99118684733,"u":99118684744,"b":[["79864.33000000","0.38242000"],["79859.69000000","0.33818000"],["79858.63000000","0.00000000"],["79858.62000000","0.00000000"],["79783.88000000","0.02200000"],["71877.90000000","0.00448000"],["71877.00000000","0.00010000"]],"a":[["79865.45000000","0.00000000"],["79889.09000000","0.12517000"]]}}}
{"rx_ns": 13979992083200, "frame": {"stream":"btcusdt@depth@100ms","data":{"e":"depthUpdate","E":1787650975214,"s":"BTCUSDT","U":99118684745,"u":99118684895,"b":[["79864.33000000","1.25806000"],["79864.32000000","0.00111000"],["79862.54000000","0.00007000"],["79862.53000000","0.00007000"],["79862.28000000","0.02021000"],["79861.86000000","0.00007000"],["79861.85000000","0.06138000"],["79861.68000000","0.05267000"],["79861.24000000","0.00007000"],["79861.23000000","0.06138000"],["79861.18000000","0.00000000"],["79861.17000000","0.01431000"],["79861.07000000","0.00007000"],["79861.06000000","0.31312000"],["79860.62000000","0.00000000"],["79860.61000000","0.00000000"],["79860.01000000","0.00000000"],["79860.00000000","0.00007000"],["79859.90000000","0.00000000"],["79859.72000000","0.00007000"],["79859.71000000","1.04939000"],["79859.70000000","0.00014000"],["79859.69000000","0.00000000"],["79858.75000000","0.00000000"],["79858.61000000","0.01691000"],["79858.48000000","0.12529000"],["79858.38000000","0.00000000"],["79858.14000000","0.00000000"],["79858.13000000","0.00000000"],["79858.00000000","0.02400000"],["79857.51000000","0.00000000"],["79857.20000000","0.00400000"],["79856.89000000","0.00000000"],["79856.27000000","0.00000000"],["79856.01000000","0.00626000"],["79855.65000000","0.00250000"],["79855.09000000","1.34972000"],["79855.08000000","1.87677000"],["79855.03000000","0.00000000"],["79854.98000000","0.00000000"],["79854.94000000","0.00000000"],["79854.92000000","0.00000000"],["79854.58000000","0.00000000"],["79854.13000000","0.03224000"],["79853.65000000","0.00626000"],["79853.40000000","0.00250000"],["79853.02000000","0.00000000"],["79852.61000000","0.02800000"],["79851.39000000","0.00000000"],["79851.12000000","0.00000000"],["79850.25000000","0.98329000"],["79843.64000000","0.37583000"],["79841.06000000","0.33825000"],["79840.33000000","0.02436000"],["79834.30000000","0.00000000"],["79833.36000000","0.00000000"],["79832.73000000","0.09426000"],["79823.12000000","0.00000000"],["79818.75000000","0.00000000"],["79788.34000000","0.02087000"],["71877.90000000","0.00432000"],["71877.00000000","0.00000000"],["63891.47000000","0.00000000"]],"a":[["79864.34000000","1.63223000"],["79864.35000000","0.01265000"],["79864.53000000","0.00007000"],["79864.54000000","0.08487000"],["79864.94000000","0.00000000"],["79864.95000000","0.00014000"],["79866.70000000","0.00014000"],["79867.08000000","0.00000000"],["79867.25000000","0.00007000"],["79867.26000000","0.00007000"],["79867.27000000","0.04786000"],["79867.43000000","0.00007000"],["79867.44000000","0.06138000"],["79867.56000000","0.00009000"],["79867.62000000","0.00000000"],["79867.75000000","0.00712000"],["79867.98000000","0.00007000"],["79867.99000000","0.06138000"],["79868.00000000","0.02828000"],["79868.14000000","0.15289000"],["79868.15000000","0.06138000"],["79868.17000000","0.00000000"],["79868.22000000","0.00000000"],["79868.23000000","0.00000000"],["79869.17000000","0.00000000"],["79869.36000000","0.00250000"],["79869.86000000","0.00000000"],["79870.31000000","0.00000000"],["79870.33000000","0.00000000"],["79871.06000000","0.00400000"],["79871.57000000","0.00400000"],["79871.78000000","0.06138000"],["79871.88000000","0.06138000"],["79871.89000000","0.19019000"],["79872.04000000","0.00626000"],["79872.55000000","0.00000000"],["79883.74000000","0.00000000"],["79901.00000000","0.00000000"]]}}}
{"rx_ns": 13980094447200, "frame": {"stream":"btcusdt@depth@100ms","data":{"e":"depthUpdate","E":1787650975314,"s":"BTCUSDT","U":99118684896,"u":99118685002,"b":[["79864.33000000","1.14740000"],["79864.32000000","0.00097000"],["79862.54000000","0.00000000"],["79862.28000000","0.02021000"],["79861.85000000","0.06152000"],["79861.68000000","0.05267000"],["79861.23000000","0.06152000"],["79861.17000000","0.01431000"],["79861.06000000","0.31326000"],["79860.43000000","0.00014000"],["79860.00000000","0.00007000"],["79859.99000000","0.06138000"],["79859.89000000","0.01691000"],["79859.73000000","0.00007000"],["79859.72000000","0.34404000"],["79859.70000000","0.00000000"],["79858.61000000","0.01691000"],["79858.49000000","0.00000000"],["79858.48000000","0.00000000"],["79850.62000000","0.02023000"],["79822.08000000","0.00400000"],["79820.00000000","0.02400000"],["79788.34000000","0.00000000"],["71877.90000000","0.00448000"],["71877.89000000","0.00000000"],["71877.88000000","0.00008000"],["71877.00000000","0.00010000"],["63891.46000000","0.00000000"],["63891.00000000","0.00000000"]],"a":[["79864.34000000","1.63223000"],["79864.35000000","0.01265000"],["79864.54000000","0.08501000"],["79864.55000000","0.07177000"],["79864.95000000","0.00000000"],["79866.47000000","0.04014000"],["79866.70000000","0.00000000"],["79867.26000000","0.00007000"],["79867.27000000","0.04800000"],["79867.43000000","0.00007000"],["79867.98000000","0.00007000"]]}}}
{"rx_ns": 13980195385700, "frame": {"stream":"btcusdt@depth@100ms","data":{"e":"depthUpdate","E":1787650975414,"s":"BTCUSDT","U":99118685003,"u":99118685023,"b":[["79864.33000000","1.14747000"],["79861.32000000","0.00014000"],["79854.23000000","0.00250000"],["79853.40000000","0.00000000"],["79751.91000000","0.00000000"],["79744.11000000","0.00394000"],["71877.90000000","0.00432000"],["71877.00000000","0.00000000"],["63891.46000000","0.00000000"]],"a":[["79864.34000000","1.68218000"],["79869.36000000","0.00000000"],["79870.19000000","0.00250000"]]}}}
{"rx_ns": 13980291746300, "frame": {"stream":"btcusdt@depth@100ms","data":{"e":"depthUpdate","E":1787650975514,"s":"BTCUSDT","U":99118685024,"u":99118685030,"b":[["79864.33000000","1.14949000"],["71877.90000000","0.00448000"],["63891.47000000","0.00031000"]],"a":[["79864.34000000","1.68231000"]]}}}
{"rx_ns": 13980391751900, "frame": {"stream":"btcusdt@depth@100ms","data":{"e":"depthUpdate","E":1787650975614,"s":"BTCUSDT","U":99118685031,"u":99118685044,"b":[["79836.66000000","0.00000000"],["79832.00000000","0.02800000"],["79803.86000000","0.00000000"],["79783.88000000","0.00000000"],["79778.17000000","0.62589000"],["79726.70000000","0.00000000"],["79685.35000000","0.00456000"],["78666.36000000","0.00030000"],["71877.90000000","0.00432000"],["63891.47000000","0.00000000"]],"a":[["79864.34000000","1.68905000"],["79883.44000000","0.00000000"],["79913.33000000","0.00000000"],["79933.32000000","0.00000000"],["80047.54000000","0.01942000"],["80183.44000000","0.00000000"],["81062.31000000","0.00030000"]]}}}
{"rx_ns": 13980491773200, "frame": {"stream":"btcusdt@depth@100ms","data":{"e":"depthUpdate","E":1787650975714,"s":"BTCUSDT","U":99118685045,"u":99118685075,"b":[["79864.33000000","0.94685000"],["79864.32000000","0.00090000"],["79861.17000000","0.01424000"],["79860.00000000","0.00000000"],["79859.99000000","0.00000000"],["79859.72000000","0.03073000"],["79859.71000000","0.00000000"],["79856.89000000","0.06138000"],["79856.27000000","0.06138000"],["79855.65000000","0.06388000"],["79855.10000000","0.06138000"],["79793.97000000","0.29835000"],["79638.43000000","0.00771000"],["79599.03000000","0.00000000"],["71877.90000000","0.00448000"],["71877.00000000","0.00000000"]],"a":[["79864.34000000","1.70993000"],["79870.54000000","0.06138000"],["79871.16000000","0.06138000"],["79897.00000000","0.00000000"],["79929.44000000","0.02000000"]]}}}
{"rx_ns": 13980596464000, "frame": {"stream":"btcusdt@depth@100ms","data":{"e":"depthUpdate","E":1787650975814,"s":"BTCUSDT","U":99118685076,"u":99118685110,"b":[["79864.33000000","0.94381000"],["79861.06000000","0.31326000"],["79859.72000000","0.09595000"],["79858.61000000","0.01698000"],["79858.14000000","0.00007000"],["79858.13000000","0.06138000"],["79857.52000000","0.00007000"],["79857.51000000","0.06138000"],["79856.90000000","0.00007000"],["79856.28000000","0.00094000"],["79849.12000000","0.00007000"],["71877.90000000","0.00432000"],["71877.88000000","0.00000000"],["71877.00000000","0.00000000"]],"a":[["79867.26000000","0.00007000"],["79867.43000000","0.00007000"],["79867.98000000","0.00007000"],["79881.08000000","0.00007000"],["79985.36000000","0.00000000"],["79993.37000000","0.01961000"]]}}}
{"rx_ns": 13980701458500, "frame": {"stream":"btcusdt@depth@100ms","data":{"e":"depthUpdate","E":1787650975914,"s":"BTCUSDT","U":99118685111,"u":99118685140,"b":[["79864.33000000","0.93728000"],["79861.85000000","0.00014000"],["79861.32000000","0.00007000"],["79861.23000000","0.00014000"],["79859.53000000","0.00711000"],["79858.13000000","0.00000000"],["79857.20000000","0.00000000"],["79855.47000000","0.00000000"],["79855.11000000","0.01200000"],["79855.08000000","0.00000000"],["79855.07000000","0.00000000"],["79854.42000000","0.00400000"],["79854.23000000","0.00000000"],["79788.34000000","0.02087000"],["71877.90000000","0.00432000"],["71877.00000000","0.00010000"]],"a":[["79865.58000000","0.06138000"],["79866.20000000","0.06138000"],["79866.82000000","0.06138000"],["79869.30000000","0.06138000"],["79869.92000000","0.06138000"],["79870.19000000","0.00000000"]]}}}
{"rx_ns": 13980796803100, "frame": {"stream":"btcusdt@depth20","data":{"lastUpdateId":99118685241,"bids":[["79864.33000000","0.85234000"],["79864.32000000","0.00076000"],["79864.31000000","0.00013000"],["79863.05000000","0.00007000"],["79862.53000000","0.00007000"],["79862.52000000","0.02494000"],["79862.45000000","0.00863000"],["79862.29000000","0.00007000"],["79862.28000000","0.02014000"],["79862.10000000","0.00007000"],["79861.77000000","0.00014000"],["79861.69000000","0.00007000"],["79861.68000000","0.05260000"],["79861.66000000","0.00007000"],["79861.65000000","0.00014000"],["79861.32000000","0.00007000"],["79861.29000000","0.00007000"],["79861.18000000","0.00007000"],["79861.17000000","0.01424000"],["79861.07000000","0.00007000"]],"asks":[["79864.34000000","1.72585000"],["79864.35000000","0.01265000"],["79864.36000000","0.00013000"],["79864.53000000","0.00007000"],["79864.54000000","0.12837000"],["79864.55000000","0.07184000"],["79864.59000000","0.00007000"],["79865.19000000","0.00014000"],["79865.57000000","0.00007000"],["79865.58000000","0.06152000"],["79865.61000000","0.00007000"],["79865.62000000","0.01761000"],["79865.99000000","0.00007000"],["79866.00000000","0.00400000"],["79866.09000000","0.00007000"],["79866.15000000","0.00951000"],["79866.19000000","0.00007000"],["79866.20000000","0.06152000"],["79866.46000000","0.00007000"],["79866.47000000","0.04021000"]]}}}
{"rx_ns": 13980796900800, "frame": {"stream":"btcusdt@depth@100ms","data":{"e":"depthUpdate","E":1787650976014,"s":"BTCUSDT","U":99118685141,"u":99118685241,"b":[["79864.33000000","0.85234000"],["79864.32000000","0.00076000"],["79862.28000000","0.02014000"],["79861.86000000","0.00000000"],["79861.85000000","0.00000000"],["79861.68000000","0.05260000"],["79861.24000000","0.00000000"],["79861.23000000","0.00000000"],["79861.18000000","0.00007000"],["79859.89000000","0.01705000"],["79859.72000000","0.00021000"],["79859.53000000","0.00711000"],["79858.97000000","0.00000000"],["79858.96000000","0.00000000"],["79858.61000000","0.01691000"],["79858.14000000","0.00000000"],["79857.52000000","0.00007000"],["79856.90000000","0.00007000"],["79856.28000000","0.00101000"],["79856.01000000","0.00000000"],["79855.09000000","0.75989000"],["79854.73000000","0.00626000"],["79853.22000000","0.00250000"],["79788.34000000","0.00000000"],["71877.90000000","0.00432000"],["71877.00000000","0.00010000"],["63891.47000000","0.00031000"]],"a":[["79864.34000000","1.72585000"],["79864.54000000","0.12837000"],["79864.55000000","0.07184000"],["79865.57000000","0.00007000"],["79865.58000000","0.06152000"],["79866.15000000","0.00951000"],["79866.19000000","0.00007000"],["79866.20000000","0.06152000"],["79866.46000000","0.00007000"],["79866.47000000","0.04021000"],["79866.81000000","0.00007000"],["79866.89000000","0.00000000"],["79866.90000000","0.02079000"],["79867.26000000","0.00007000"],["79867.27000000","0.04786000"],["79867.43000000","0.00000000"],["79867.98000000","0.00000000"],["79868.14000000","0.22307000"],["79868.18000000","0.02086000"],["79869.19000000","0.00250000"]]}}}
{"rx_ns": 13980891456500, "frame": {"stream":"btcusdt@depth@100ms","data":{"e":"depthUpdate","E":1787650976114,"s":"BTCUSDT","U":99118685242,"u":99118685270,"b":[["79864.33000000","0.85234000"],["79859.89000000","0.01698000"],["79859.73000000","0.00000000"],["79859.72000000","0.00000000"],["79859.53000000","0.00014000"],["79858.01000000","0.00007000"],["79858.00000000","0.02407000"],["79844.36000000","0.02208000"],["79804.38000000","0.02200000"],["71877.90000000","0.00432000"],["71877.00000000","0.00000000"]],"a":[["79864.34000000","1.72593000"],["79879.28000000","0.02000000"],["79899.27000000","0.02000000"],["79919.25000000","0.02000000"]]}}}
{"rx_ns": 13980998748600, "frame": {"stream":"btcusdt@depth@100ms","data":{"e":"depthUpdate","E":1787650976214,"s":"BTCUSDT","U":99118685271,"u":99118685287,"b":[["79864.33000000","0.85172000"],["79859.89000000","0.01705000"],["79859.53000000","0.00000000"],["79858.80000000","0.00007000"],["79858.79000000","0.12529000"],["79858.61000000","0.01705000"],["79858.01000000","0.00000000"],["79855.29000000","0.00070000"],["71877.90000000","0.00416000"],["63891.47000000","0.00000000"]],"a":[]}}}
{"rx_ns": 13981091448600, "frame": {"stream":"btcusdt@depth@100ms","data":{"e":"depthUpdate","E":1787650976314,"s":"BTCUSDT","U":99118685288,"u":99118685321,"b":[["79864.33000000","0.85111000"],["79864.32000000","0.00090000"],["79862.75000000","0.00202000"],["79861.68000000","0.05267000"],["79861.63000000","0.00007000"],["79861.62000000","0.33818000"],["79861.18000000","0.00000000"],["79859.89000000","0.01705000"],["79858.79000000","0.12543000"],["79858.61000000","0.01691000"],["79855.29000000","0.00000000"],["79853.22000000","0.00000000"],["79852.36000000","0.00250000"],["71877.90000000","0.00432000"],["71877.89000000","0.00008000"],["63891.46000000","0.00000000"],["63891.00000000","0.00000000"]],"a":[["79868.32000000","0.00250000"],["79869.19000000","0.00000000"]]}}}
{"rx_ns": 13981191734400, "frame": {"stream":"btcusdt@depth@100ms","data":{"e":"depthUpdate","E":1787650976414,"s":"BTCUSDT","U":99118685322,"u":99118685349,"b":[["79864.33000000","0.85180000"],["79861.68000000","0.05267000"],["79861.62000000","0.33832000"],["79858.79000000","0.12529000"],["79855.31000000","0.00000000"],["79855.11000000","0.00000000"],["79855.06000000","0.00000000"],["79853.19000000","0.00250000"],["79852.36000000","0.00000000"],["79850.26000000","0.01600000"],["71877.90000000","0.00448000"],["63891.46000000","0.00000000"]],"a":[["79868.32000000","0.00000000"],["79869.15000000","0.00250000"]]}}}
{"rx_ns": 13981292520100, "frame": {"stream":"btcusdt@depth@100ms","data":{"e":"depthUpdate","E":1787650976514,"s":"BTCUSDT","U":99118685350,"u":99118685366,"b":[["79864.33000000","0.85165000"],["79859.89000000","0.01698000"],["79858.80000000","0.00000000"],["79858.79000000","0.00000000"],["79855.66000000","0.00007000"],["79836.59000000","0.00000000"],["79803.93000000","0.00000000"],["79783.94000000","0.00000000"],["71877.90000000","0.00416000"],["71877.00000000","0.00000000"],["63891.47000000","0.00031000"]],"a":[["79864.34000000","1.69147000"],["79868.18000000","0.02079000"],["79869.30000000","0.00000000"],["79883.52000000","0.00000000"],["79896.00000000","0.72400000"],["79913.45000000","0.00000000"],["79933.44000000","0.00000000"]]}}}
{"rx_ns": 13981396209600, "frame": {"stream":"btcusdt@depth@100ms","data":{"e":"depthUpdate","E":1787650976614,"s":"BTCUSDT","U":99118685367,"u":99118685388,"b":[["79864.33000000","0.85032000"],["79859.89000000","0.01698000"],["79855.11000000","0.01600000"],["79850.26000000","0.00000000"],["78666.36000000","0.00030000"],["71877.90000000","0.00448000"],["63891.47000000","0.00000000"]],"a":[["79884.57000000","0.04409000"],["79891.37000000","0.00000000"],["81062.31000000","0.00030000"]]}}}
{"rx_ns": 13981495563100, "frame": {"stream":"btcusdt@depth@100ms","data":{"e":"depthUpdate","E":1787650976715,"s":"BTCUSDT","U":99118685389,"u":99118685401,"b":[["79864.33000000","0.33108000"],["79854.73000000","0.00000000"],["79854.42000000","0.00000000"],["79853.40000000","0.00626000"],["79852.63000000","0.00400000"],["71877.90000000","0.00432000"]],"a":[["79864.35000000","0.01272000"],["79864.53000000","0.06145000"],["79865.61000000","0.00000000"],["79866.89000000","0.00626000"],["79867.02000000","0.00400000"],["79871.57000000","0.00000000"],["79872.04000000","0.00000000"]]}}}
{"rx_ns": 13981596628600, "frame": {"stream":"btcusdt@depth@100ms","data":{"e":"depthUpdate","E":1787650976814,"s":"BTCUSDT","U":99118685402,"u":99118685420,"b":[["79849.12000000","0.00007000"],["71877.90000000","0.00448000"]],"a":[["79864.34000000","1.69139000"],["79864.35000000","0.01272000"],["79864.52000000","0.00007000"],["79864.53000000","0.06159000"],["79866.47000000","0.04007000"],["79866.82000000","0.06145000"],["79881.08000000","0.00007000"]]}}}
{"rx_ns": 13981694966400, "frame": {"stream":"btcusdt@depth@100ms","data":{"e":"depthUpdate","E":1787650976914,"s":"BTCUSDT","U":99118685421,"u":99118685450,"b":[["79864.33000000","0.33115000"],["79862.75000000","0.00000000"],["79861.62000000","0.00014000"],["79858.61000000","0.01698000"],["79858.14000000","0.00007000"],["79858.13000000","0.06138000"],["79857.56000000","0.00000000"],["79855.66000000","0.00000000"],["79853.19000000","0.00000000"],["79850.92000000","0.00250000"],["79818.75000000","0.00007000"],["71877.90000000","0.00432000"]],"a":[["79864.34000000","3.56810000"],["79864.53000000","0.00021000"],["79865.58000000","0.00040000"],["79866.20000000","0.00014000"],["79866.82000000","0.00007000"],["79867.44000000","0.00000000"],["79867.99000000","0.00000000"],["79868.15000000","0.00000000"],["79869.15000000","0.00000000"],["79869.92000000","0.00000000"],["79870.54000000","0.00000000"],["79871.16000000","0.00000000"],["79871.78000000","0.00000000"],["79871.88000000","0.00000000"]]}}}
{"rx_ns": 13981798380600, "frame": {"stream":"btcusdt@depth20","data":{"lastUpdateId":99118685531,"bids":[["79864.33000000","0.32991000"],["79864.32000000","0.00076000"],["79864.31000000","0.00013000"],["79863.05000000","0.00007000"],["79862.53000000","0.00007000"],["79862.52000000","0.02494000"],["79862.45000000","0.00863000"],["79862.29000000","0.00007000"],["79862.28000000","0.02014000"],["79862.10000000","0.00007000"],["79861.77000000","0.00014000"],["79861.69000000","0.00007000"],["79861.68000000","0.05260000"],["79861.66000000","0.00007000"],["79861.65000000","0.00014000"],["79861.32000000","0.00007000"],["79861.29000000","0.00007000"],["79861.18000000","0.00007000"],["79861.17000000","0.01424000"],["79861.07000000","0.00007000"]],"asks":[["79864.34000000","3.56810000"],["79864.35000000","0.01272000"],["79864.36000000","0.00013000"],["79864.53000000","0.00007000"],["79864.54000000","0.07648000"],["79864.55000000","0.07184000"],["79864.59000000","0.00007000"],["79865.19000000","0.00014000"],["79865.61000000","0.00007000"],["79865.62000000","0.01761000"],["79865.99000000","0.00007000"],["79866.00000000","0.00400000"],["79866.08000000","0.00250000"],["79866.09000000","0.00007000"],["79866.15000000","0.00944000"],["79866.46000000","0.00007000"],["79866.47000000","0.04021000"],["79866.71000000","0.00007000"],["79866.78000000","0.00007000"],["79866.82000000","0.00007000"]]}}}
{"rx_ns": 13981798494600, "frame": {"stream":"btcusdt@depth@100ms","data":{"e":"depthUpdate","E":1787650977014,"s":"BTCUSDT","U":99118685451,"u":99118685531,"b":[["79864.33000000","0.32991000"],["79864.32000000","0.00076000"],["79861.68000000","0.05260000"],["79861.63000000","0.00000000"],["79861.62000000","0.00000000"],["79861.18000000","0.00007000"],["79859.89000000","0.01705000"],["79858.76000000","0.00007000"],["79858.75000000","0.06138000"],["79858.61000000","0.01712000"],["79857.58000000","0.00026000"],["79855.26000000","0.00047000"],["79854.03000000","0.00077000"],["79844.41000000","0.02400000"],["79804.44000000","0.02400000"],["79778.17000000","0.00000000"],["71877.90000000","0.00448000"],["63891.47000000","0.00031000"]],"a":[["79864.34000000","3.56810000"],["79864.35000000","0.01272000"],["79864.52000000","0.00000000"],["79864.53000000","0.00007000"],["79864.54000000","0.07648000"],["79864.55000000","0.07184000"],["79865.57000000","0.00000000"],["79865.58000000","0.00000000"],["79865.61000000","0.00007000"],["79866.08000000","0.00250000"],["79866.15000000","0.00944000"],["79866.19000000","0.00000000"],["79866.20000000","0.00000000"],["79866.47000000","0.04021000"],["79866.81000000","0.00000000"],["79866.89000000","0.00647000"],["79866.90000000","0.02093000"],["79867.25000000","0.00000000"],["79867.27000000","0.04779000"],["79867.75000000","0.00705000"],["79867.99000000","0.00007000"],["79868.00000000","0.02821000"],["79868.13000000","0.00007000"],["79868.14000000","0.15289000"],["79879.35000000","0.02000000"],["79899.33000000","0.02000000"],["79904.51000000","0.00425000"],["79914.06000000","0.00000000"],["79919.32000000","0.02000000"],["79955.03000000","1.95361000"],["79960.31000000","0.00000000"]]}}}
{"rx_ns": 13981896605200, "frame": {"stream":"btcusdt@depth@100ms","data":{"e":"depthUpdate","E":1787650977114,"s":"BTCUSDT","U":99118685532,"u":99118685550,"b":[["79859.89000000","0.01705000"],["79858.75000000","0.06152000"],["79858.61000000","0.01698000"],["79830.00000000","0.77438000"],["79784.40000000","0.02200000"],["72247.84000000","0.00000000"],["71877.90000000","0.00432000"]],"a":[["79864.55000000","0.07177000"],["79903.10000000","0.00634000"],["79905.82000000","0.00433000"],["79912.81000000","0.00000000"],["79915.73000000","0.00000000"]]}}}
{"rx_ns": 13982003956300, "frame": {"stream":"btcusdt@depth@100ms","data":{"e":"depthUpdate","E":1787650977214,"s":"BTCUSDT","U":99118685551,"u":99118685600,"b":[["79864.33000000","0.25970000"],["79859.89000000","0.01712000"],["79859.38000000","0.00007000"],["79859.37000000","0.06138000"],["79857.52000000","0.00007000"],["79856.90000000","0.00000000"],["79856.28000000","0.00094000"],["79855.12000000","0.01200000"],["79855.11000000","0.00400000"],["79854.93000000","0.00000000"],["79854.13000000","0.00000000"],["79853.40000000","0.00000000"],["79852.63000000","0.00000000"],["79852.20000000","0.00626000"],["79850.21000000","0.00000000"],["79835.23000000","0.00000000"],["79832.73000000","0.00000000"],["79827.53000000","0.04543000"],["79788.14000000","0.00007000"],["71877.90000000","0.00448000"],["63891.47000000","0.00000000"]],"a":[["79864.34000000","3.60012000"],["79866.08000000","0.00000000"],["79866.11000000","0.00250000"],["79866.81000000","0.00400000"],["79867.02000000","0.00000000"],["79867.26000000","0.00007000"],["79867.56000000","0.00000000"],["79867.99000000","0.00000000"],["79868.13000000","0.00000000"],["79871.06000000","0.00000000"],["79872.35000000","0.03224000"],["80013.52000000","0.00400000"],["80016.74000000","0.00000000"]]}}}
{"rx_ns": 13982091737400, "frame": {"stream":"btcusdt@depth@100ms","data":{"e":"depthUpdate","E":1787650977314,"s":"BTCUSDT","U":99118685601,"u":99118685649,"b":[["79859.89000000","0.01712000"],["79859.37000000","0.06152000"],["79858.75000000","0.06138000"],["79855.13000000","1.04939000"],["79855.12000000","0.00000000"],["79855.11000000","0.00000000"],["79855.09000000","0.00000000"],["79854.68000000","0.06138000"],["79854.15000000","0.06138000"],["79853.65000000","0.00000000"],["79852.20000000","0.00000000"],["79852.05000000","0.00626000"],["79851.05000000","0.00626000"],["79850.26000000","0.01200000"],["79850.25000000","0.45161000"],["79815.99000000","0.00000000"],["79799.05000000","1.43056000"],["79798.65000000","0.00000000"],["79796.43000000","0.00000000"],["79769.19000000","0.77634000"],["79667.26000000","0.00000000"],["71877.90000000","0.00432000"],["71877.89000000","0.00000000"],["71877.88000000","0.00008000"],["63891.00000000","0.00000000"]],"a":[["79864.34000000","3.59992000"],["79867.26000000","0.00000000"],["79915.57000000","0.00000000"],["79954.88000000","0.00000000"],["80101.00000000","0.00000000"]]}}}
{"rx_ns": 13982193127200, "frame": {"stream":"btcusdt@depth@100ms","data":{"e":"depthUpdate","E":1787650977414,"s":"BTCUSDT","U":99118685650,"u":99118685687,"b":[["79864.33000000","0.28757000"],["79864.32000000","0.00083000"],["79861.17000000","0.01431000"],["79861.08000000","0.00007000"],["79861.07000000","0.06145000"],["79855.14000000","0.80947000"],["79855.10000000","0.00000000"],["79854.68000000","0.00000000"],["79854.15000000","0.00000000"],["79850.26000000","0.00000000"],["79847.58000000","0.01200000"],["79840.55000000","0.36586000"],["79818.75000000","0.00000000"],["79685.35000000","0.00000000"],["79667.74000000","0.00433000"],["71877.90000000","0.00432000"],["63891.46000000","0.00000000"]],"a":[["79864.34000000","3.59953000"],["79866.11000000","0.00000000"],["79866.17000000","0.00250000"],["79867.26000000","0.00007000"],["79867.99000000","0.00007000"],["79868.13000000","0.00007000"],["80047.54000000","0.00000000"],["80165.72000000","0.00998000"]]}}}
{"rx_ns": 13982292118700, "frame": {"stream":"btcusdt@depth@100ms","data":{"e":"depthUpdate","E":1787650977514,"s":"BTCUSDT","U":99118685688,"u":99118685709,"b":[["79861.17000000","0.01431000"],["79861.07000000","0.06159000"],["79859.37000000","0.06138000"],["79855.15000000","0.01200000"],["79847.58000000","0.00000000"],["79836.61000000","0.00000000"],["79804.10000000","0.00000000"],["79784.12000000","0.00000000"],["71877.00000000","0.00000000"],["63891.47000000","0.00031000"],["63891.46000000","0.00000000"]],"a":[["79866.17000000","0.00000000"],["79866.20000000","0.00250000"],["79883.55000000","0.10342000"],["79913.49000000","0.00000000"],["79933.48000000","0.00000000"]]}}}
{"rx_ns": 13982392291200, "frame": {"stream":"btcusdt@depth@100ms","data":{"e":"depthUpdate","E":1787650977614,"s":"BTCUSDT","U":99118685710,"u":99118685726,"b":[["79822.32000000","0.00400000"],["79822.08000000","0.00000000"],["79818.75000000","0.00007000"],["79638.43000000","0.00000000"],["79637.50000000","0.00799000"],["79500.00000000","10.25823000"],["78666.36000000","0.00030000"],["71877.90000000","0.00432000"],["63891.47000000","0.00000000"]],"a":[["79866.20000000","0.00000000"],["79866.23000000","0.00250000"],["79922.75000000","0.00000000"],["81062.31000000","0.00030000"]]}}}
{"rx_ns": 13982492110700, "frame": {"stream":"btcusdt@depth@100ms","data":{"e":"depthUpdate","E":1787650977714,"s":"BTCUSDT","U":99118685727,"u":99118685731,"b":[["79832.63000000","0.09399000"],["79787.41000000","0.12090000"],["71877.90000000","0.00432000"]],"a":[["79864.34000000","3.59968000"]]}}}
{"rx_ns": 13982595694500, "frame": {"stream":"btcusdt@depth@100ms","data":{"e":"depthUpdate","E":1787650977816,"s":"BTCUSDT","U":99118685732,"u":99118685747,"b":[["79864.33000000","0.28607000"],["79855.15000000","0.00000000"],["79849.12000000","0.00000000"],["79846.14000000","0.00400000"],["79788.34000000","0.02087000"],["79638.42000000","0.00000000"],["79629.93000000","0.01961000"],["71877.90000000","0.00416000"]],"a":[["79867.99000000","0.00007000"],["79868.13000000","0.00007000"],["79881.08000000","0.00000000"]]}}}
{"rx_ns": 13982691614800, "frame": {"stream":"btcusdt@depth@100ms","data":{"e":"depthUpdate","E":1787650977914,"s":"BTCUSDT","U":99118685748,"u":99118685759,"b":[["79849.33000000","0.02600000"],["79849.12000000","0.00007000"],["79848.54000000","0.02000000"],["79808.57000000","0.02000000"],["79788.34000000","0.00000000"],["71877.90000000","0.00448000"]],"a":[["79873.47000000","0.02000000"],["79874.28000000","0.02000000"],["79881.08000000","0.00007000"],["79894.27000000","0.02000000"],["79914.25000000","0.02000000"]]}}}
{"rx_ns": 13982795159100, "frame": {"stream":"btcusdt@depth20","data":{"lastUpdateId":99118685771,"bids":[["79864.33000000","0.28607000"],["79864.32000000","0.00083000"],["79864.31000000","0.00013000"],["79863.05000000","0.00007000"],["79862.53000000","0.00007000"],["79862.52000000","0.02494000"],["79862.45000000","0.00863000"],["79862.29000000","0.00007000"],["79862.28000000","0.02014000"],["79862.10000000","0.00007000"],["79861.77000000","0.00014000"],["79861.69000000","0.00007000"],["79861.68000000","0.05260000"],["79861.66000000","0.00007000"],["79861.65000000","0.00014000"],["79861.32000000","0.00007000"],["79861.29000000","0.00007000"],["79861.18000000","0.00007000"],["79861.17000000","0.01431000"],["79861.08000000","0.00007000"]],"asks":[["79864.34000000","3.59968000"],["79864.35000000","0.01272000"],["79864.36000000","0.00013000"],["79864.53000000","0.00007000"],["79864.54000000","0.07648000"],["79864.55000000","0.07177000"],["79864.59000000","0.00007000"],["79865.19000000","0.00014000"],["79865.61000000","0.00007000"],["79865.62000000","0.01761000"],["79865.99000000","0.00007000"],["79866.00000000","0.00400000"],["79866.09000000","0.00007000"],["79866.15000000","0.00944000"],["79866.23000000","0.00250000"],["79866.46000000","0.00007000"],["79866.47000000","0.04021000"],["79866.71000000","0.00007000"],["79866.78000000","0.00007000"],["79866.81000000","0.00400000"]]}}}
{"rx_ns": 13982795273600, "frame": {"stream":"btcusdt@depth@100ms","data":{"e":"depthUpdate","E":1787650978014,"s":"BTCUSDT","U":99118685760,"u":99118685771,"b":[["79846.19000000","0.02400000"],["79837.40000000","0.00000000"],["79790.88000000","0.00000000"],["79784.98000000","0.00000000"],["79784.45000000","0.02400000"],["71877.90000000","0.00432000"],["63891.47000000","0.00031000"]],"a":[["79882.74000000","0.00000000"],["79890.21000000","0.49303000"],["79932.71000000","0.00000000"]]}}}
{"rx_ns": 13982891650600, "frame": {"stream":"btcusdt@depth@100ms","data":{"e":"depthUpdate","E":1787650978114,"s":"BTCUSDT","U":99118685772,"u":99118685775,"b":[["79834.28000000","1.87677000"],["73475.18000000","0.00014000"],["71877.90000000","0.00432000"]],"a":[]}}}
{"rx_ns": 13982991175200, "frame": {"stream":"btcusdt@depth@100ms","data":{"e":"depthUpdate","E":1787650978214,"s":"BTCUSDT","U":99118685776,"u":99118685785,"b":[["79864.33000000","0.25942000"],["71877.90000000","0.00432000"],["71877.88000000","0.00000000"],["63891.47000000","0.00000000"]],"a":[["79864.34000000","3.59868000"],["79867.99000000","0.00000000"],["79868.13000000","0.00000000"]]}}}
{"rx_ns": 13983097425900, "frame": {"stream":"btcusdt@depth@100ms","data":{"e":"depthUpdate","E":1787650978315,"s":"BTCUSDT","U":99118685786,"u":99118685794,"b":[["79775.53000000","0.62589000"],["71877.90000000","0.00448000"],["63891.00000000","0.00000000"]],"a":[["79864.34000000","3.59719000"],["79867.99000000","0.00007000"],["79868.13000000","0.00007000"]]}}}
{"rx_ns": 13983191429900, "frame": {"stream":"btcusdt@depth@100ms","data":{"e":"depthUpdate","E":1787650978414,"s":"BTCUSDT","U":99118685795,"u":99118685802,"b":[["79858.39000000","0.12529000"],["79814.12000000","0.34825000"],["79777.04000000","2.32279000"],["79628.52000000","2.32712000"],["71877.90000000","0.00416000"],["63891.46000000","0.00000000"]],"a":[]}}}
{"rx_ns": 13983293214200, "frame": {"stream":"btcusdt@depth@100ms","data":{"e":"depthUpdate","E":1787650978515,"s":"BTCUSDT","U":99118685803,"u":99118685834,"b":[["79864.33000000","0.25942000"],["79859.38000000","0.00007000"],["79858.76000000","0.00007000"],["79858.40000000","0.00000000"],["79858.39000000","0.00000000"],["79858.14000000","0.00007000"],["79857.52000000","0.00000000"],["79849.33000000","0.00000000"],["79804.97000000","0.00000000"],["71877.90000000","0.00432000"],["63891.47000000","0.00031000"],["63891.46000000","0.00000000"]],"a":[["79867.26000000","0.00007000"],["79867.99000000","0.00007000"],["79868.13000000","0.00007000"],["79873.47000000","0.00000000"],["79912.73000000","0.00000000"],["80677.00000000","0.03851000"]]}}}
{"rx_ns": 13983392766200, "frame": {"stream":"btcusdt@depth@100ms","data":{"e":"depthUpdate","E":1787650978614,"s":"BTCUSDT","U":99118685835,"u":99118685845,"b":[["78666.36000000","0.00030000"],["73475.18000000","0.00000000"],["71877.90000000","0.00416000"],["71877.00000000","0.00000000"],["63891.47000000","0.00000000"]],"a":[["81062.31000000","0.00030000"]]}}}
{"rx_ns": 13983491671700, "frame": {"stream":"btcusdt@depth@100ms","data":{"e":"depthUpdate","E":1787650978714,"s":"BTCUSDT","U":99118685846,"u":99118685854,"b":[["79864.33000000","0.28582000"],["79861.68000000","0.05267000"],["79861.24000000","0.00007000"],["79861.23000000","0.06138000"],["79855.15000000","0.00400000"],["79846.14000000","0.00000000"],["71877.90000000","0.00432000"]],"a":[]}}}
{"rx_ns": 13983598972700, "frame": {"stream":"btcusdt@depth@100ms","data":{"e":"depthUpdate","E":1787650978814,"s":"BTCUSDT","U":99118685855,"u":99118685985,"b":[["79864.33000000","0.25060000"],["79864.32000000","0.00076000"],["79861.68000000","0.05267000"],["79861.24000000","0.00000000"],["79861.23000000","0.00014000"],["79861.08000000","0.00000000"],["79861.07000000","0.00014000"],["79861.06000000","0.00014000"],["79859.90000000","0.00007000"],["79859.89000000","0.01691000"],["79859.38000000","0.00000000"],["79859.37000000","0.00000000"],["79858.96000000","0.00202000"],["79858.76000000","0.00000000"],["79858.75000000","0.00000000"],["79858.65000000","0.00007000"],["79858.64000000","0.33818000"],["79858.61000000","0.01691000"],["79858.14000000","0.00000000"],["79858.13000000","0.00000000"],["79858.01000000","0.00007000"],["79858.00000000","0.02400000"],["79857.51000000","0.00000000"],["79857.45000000","0.00007000"],["79856.89000000","0.00000000"],["79856.27000000","0.05699000"],["79855.65000000","0.06388000"],["79855.16000000","0.00007000"],["79855.15000000","0.06138000"],["79855.14000000","0.00000000"],["79855.13000000","0.00000000"],["79854.68000000","0.06138000"],["79854.15000000","0.06138000"],["79853.81000000","0.31315000"],["79852.05000000","0.00000000"],["79851.58000000","0.00705000"],["79851.48000000","0.00000000"],["79851.38000000","0.00000000"],["79851.05000000","0.00000000"],["79850.92000000","0.00000000"],["79849.53000000","0.00626000"],["79849.18000000","0.03000000"],["79849.08000000","0.08000000"],["79848.62000000","0.00626000"],["79848.48000000","0.00250000"],["79846.01000000","0.00000000"],["79845.35000000","0.00400000"],["79843.64000000","0.00000000"],["79841.06000000","0.00000000"],["79840.55000000","0.00000000"],["79840.54000000","0.00000000"],["79832.63000000","0.00000000"],["79826.41000000","0.33832000"],["79820.57000000","0.33834000"],["79815.85000000","1.16562000"],["79815.51000000","0.00000000"],["79809.36000000","0.00000000"],["79788.01000000","0.34225000"],["79787.66000000","1.24110000"],["79787.41000000","0.00000000"],["71877.90000000","0.00416000"],["71877.89000000","0.00008000"]],"a":[["79864.34000000","3.60325000"],["79864.35000000","0.01265000"],["79864.44000000","0.00250000"],["79864.53000000","0.00000000"],["79864.54000000","0.07641000"],["79865.61000000","0.00000000"],["79866.20000000","0.00000000"],["79866.23000000","0.00000000"],["79866.46000000","0.00000000"],["79866.82000000","0.00007000"],["79866.89000000","0.00014000"],["79867.26000000","0.00000000"],["79867.27000000","0.04786000"],["79867.44000000","0.00000000"],["79867.75000000","0.00712000"],["79867.99000000","0.06138000"],["79868.00000000","0.02828000"],["79868.13000000","0.00000000"],["79868.18000000","0.02086000"],["79869.92000000","0.00000000"],["79870.00000000","0.02963000"],["79870.54000000","0.06138000"],["79871.16000000","0.06138000"],["79871.78000000","0.06138000"],["79871.88000000","0.06138000"],["79895.04000000","0.00400000"],["79895.20000000","0.00000000"]]}}}
{"rx_ns": 13983692052500, "frame": {"stream":"btcusdt@depth@100ms","data":{"e":"depthUpdate","E":1787650978914,"s":"BTCUSDT","U":99118685986,"u":99118686085,"b":[["79864.33000000","0.25081000"],["79864.32000000","0.00083000"],["79861.68000000","0.05260000"],["79861.23000000","0.00000000"],["79861.17000000","0.01417000"],["79861.07000000","0.00000000"],["79861.06000000","0.00000000"],["79859.89000000","0.01719000"],["79859.38000000","0.00007000"],["79859.37000000","0.06138000"],["79858.76000000","0.00007000"],["79858.75000000","0.06145000"],["79858.66000000","0.00086000"],["79858.65000000","0.06145000"],["79858.64000000","0.00014000"],["79858.61000000","0.01705000"],["79858.01000000","0.00000000"],["79856.90000000","0.00007000"],["79856.89000000","0.06138000"],["79856.28000000","0.00094000"],["79855.66000000","0.00000000"],["79855.16000000","0.00000000"],["79853.52000000","0.00000000"],["79852.04000000","0.00000000"],["79849.12000000","0.00007000"],["79848.48000000","0.00000000"],["79846.29000000","0.02600000"],["79841.80000000","0.00160000"],["79818.28000000","0.00400000"],["79816.26000000","0.00000000"],["79806.32000000","0.02600000"],["79797.18000000","0.00431000"],["79788.58000000","0.02000000"],["79786.48000000","0.00000000"],["79786.27000000","0.00000000"],["79786.10000000","0.00000000"],["79785.99000000","0.00000000"],["79785.84000000","0.12052000"],["79775.53000000","0.00000000"],["71877.90000000","0.00416000"]],"a":[["79864.44000000","0.00000000"],["79866.15000000","0.00951000"],["79866.41000000","0.03224000"],["79866.47000000","0.04014000"],["79866.82000000","0.00000000"],["79866.89000000","0.00000000"],["79867.27000000","0.04793000"],["79867.75000000","0.00705000"],["79867.99000000","0.00000000"],["79868.00000000","0.02821000"],["79868.18000000","0.02079000"],["79870.00000000","0.02963000"],["79870.54000000","0.00000000"],["79871.16000000","0.00007000"],["79871.88000000","0.00000000"],["79873.47000000","0.02000000"],["79881.08000000","0.00007000"],["79893.46000000","0.02000000"],["79913.44000000","0.02000000"]]}}}
{"rx_ns": 13983791788000, "frame": {"stream":"btcusdt@depth20","data":{"lastUpdateId":99118686132,"bids":[["79864.33000000","0.25081000"],["79864.32000000","0.00090000"],["79864.31000000","0.00013000"],["79863.05000000","0.00007000"],["79862.53000000","0.00007000"],["79862.52000000","0.02494000"],["79862.45000000","0.00863000"],["79862.29000000","0.00007000"],["79862.28000000","0.02014000"],["79862.10000000","0.00007000"],["79861.77000000","0.00014000"],["79861.69000000","0.00007000"],["79861.68000000","0.05260000"],["79861.66000000","0.00007000"],["79861.65000000","0.00014000"],["79861.32000000","0.00007000"],["79861.29000000","0.00007000"],["79861.18000000","0.00007000"],["79861.17000000","0.01424000"],["79861.04000000","0.00007000"]],"asks":[["79864.34000000","3.60588000"],["79864.35000000","0.01265000"],["79864.36000000","0.00013000"],["79864.54000000","0.07641000"],["79864.55000000","0.07177000"],["79864.59000000","0.00007000"],["79865.19000000","0.00014000"],["79865.62000000","0.01761000"],["79865.99000000","0.00007000"],["79866.00000000","0.00400000"],["79866.09000000","0.00007000"],["79866.15000000","0.00951000"],["79866.41000000","0.03238000"],["79866.47000000","0.04014000"],["79866.71000000","0.00007000"],["79866.78000000","0.00007000"],["79866.81000000","0.00400000"],["79866.90000000","0.02093000"],["79867.27000000","0.04779000"],["79867.39000000","0.00007000"]]}}}
{"rx_ns": 13983791914800, "frame": {"stream":"btcusdt@depth@100ms","data":{"e":"depthUpdate","E":1787650979014,"s":"BTCUSDT","U":99118686086,"u":99118686132,"b":[["79864.33000000","0.25081000"],["79864.32000000","0.00090000"],["79861.17000000","0.01424000"],["79860.00000000","0.00007000"],["79859.99000000","0.05589000"],["79859.89000000","0.01712000"],["79859.37000000","0.06152000"],["79858.75000000","0.06159000"],["79858.65000000","0.06138000"],["79858.64000000","0.00000000"],["79858.61000000","0.01691000"],["79858.01000000","0.00007000"],["79857.51000000","0.06138000"],["79856.90000000","0.00000000"],["79853.81000000","0.00000000"],["79848.60000000","0.02650000"],["79848.59000000","0.00000000"],["79833.95000000","0.62645000"],["79820.57000000","0.00000000"],["79790.88000000","0.02400000"],["79788.01000000","0.01444000"],["79787.66000000","0.00000000"],["71877.90000000","0.00416000"],["63891.47000000","0.00031000"]],"a":[["79864.34000000","3.60588000"],["79866.15000000","0.00951000"],["79866.41000000","0.03238000"],["79867.27000000","0.04779000"],["87850.77000000","0.00000000"]]}}}
{"rx_ns": 13983891450600, "frame": {"stream":"btcusdt@depth@100ms","data":{"e":"depthUpdate","E":1787650979114,"s":"BTCUSDT","U":99118686133,"u":99118686165,"b":[["79864.33000000","0.25050000"],["79864.32000000","0.00097000"],["79861.17000000","0.01431000"],["79860.50000000","0.00014000"],["79860.49000000","0.31319000"],["79859.99000000","0.05603000"],["79859.90000000","0.00000000"],["79858.75000000","0.06145000"],["79858.61000000","0.01698000"],["79858.29000000","0.33818000"],["79858.01000000","0.00000000"],["79850.26000000","0.00400000"],["79845.85000000","0.00000000"],["79845.35000000","0.00000000"],["79843.14000000","0.33824000"],["79783.74000000","0.02087000"],["71877.90000000","0.00416000"]],"a":[["79871.78000000","0.00000000"],["79993.37000000","0.00000000"],["80011.41000000","0.01961000"],["80260.59000000","0.00018000"]]}}}
{"rx_ns": 13983992225000, "frame": {"stream":"btcusdt@depth@100ms","data":{"e":"depthUpdate","E":1787650979215,"s":"BTCUSDT","U":99118686166,"u":99118686183,"b":[["79861.17000000","0.01431000"],["79860.49000000","0.31333000"],["79859.37000000","0.06138000"],["79850.26000000","0.00000000"],["79846.01000000","0.00400000"],["79783.74000000","0.00000000"],["79637.50000000","0.00028000"],["79629.94000000","0.00771000"],["71877.90000000","0.00432000"],["63891.47000000","0.00000000"]],"a":[["80011.41000000","0.00000000"],["80054.16000000","0.01961000"]]}}}
{"rx_ns": 13984092854500, "frame": {"stream":"btcusdt@depth@100ms","data":{"e":"depthUpdate","E":1787650979314,"s":"BTCUSDT","U":99118686184,"u":99118686192,"b":[["79831.57000000","0.09554000"],["79772.89000000","0.62589000"],["71877.90000000","0.00416000"],["63891.00000000","0.00000000"]],"a":[["79864.34000000","3.60338000"],["79864.35000000","0.01515000"]]}}}
{"rx_ns": 13984193752100, "frame": {"stream":"btcusdt@depth@100ms","data":{"e":"depthUpdate","E":1787650979414,"s":"BTCUSDT","U":99118686193,"u":99118686204,"b":[["71877.90000000","0.00432000"],["63891.46000000","0.00000000"]],"a":[["79864.35000000","0.01265000"],["79864.37000000","0.00000000"],["79864.39000000","0.00250000"],["79906.87000000","0.34702000"],["79945.22000000","0.79131000"],["79946.18000000","2.31238000"],["80094.70000000","2.30809000"]]}}}
{"rx_ns": 13984291433800, "frame": {"stream":"btcusdt@depth@100ms","data":{"e":"depthUpdate","E":1787650979514,"s":"BTCUSDT","U":99118686205,"u":99118686216,"b":[["71877.90000000","0.00416000"],["63891.47000000","0.00031000"],["63891.46000000","0.00000000"]],"a":[["79864.34000000","3.65325000"],["79864.39000000","0.00000000"],["79864.40000000","0.00250000"],["79895.00000000","0.70000000"],["79896.00000000","0.02400000"]]}}}
{"rx_ns": 13984395911400, "frame": {"stream":"btcusdt@depth@100ms","data":{"e":"depthUpdate","E":1787650979614,"s":"BTCUSDT","U":99118686217,"u":99118686231,"b":[["79864.33000000","0.24925000"],["78666.36000000","0.00030000"],["71877.90000000","0.00432000"],["71877.89000000","0.00000000"],["71877.88000000","0.00008000"],["63891.47000000","0.00000000"],["63891.00000000","0.00000000"]],"a":[["79864.34000000","3.65192000"],["79864.40000000","0.00000000"],["79864.42000000","0.00250000"],["81062.31000000","0.00030000"]]}}}
{"rx_ns": 13984503576300, "frame": {"stream":"btcusdt@depth@100ms","data":{"e":"depthUpdate","E":1787650979714,"s":"BTCUSDT","U":99118686232,"u":99118686256,"b":[["79864.33000000","0.24932000"],["79864.32000000","0.00104000"],["79861.17000000","0.01438000"],["79860.62000000","0.00007000"],["79860.61000000","0.06138000"],["79843.91000000","0.37582000"],["79840.89000000","0.33825000"],["79833.95000000","0.00000000"],["79826.41000000","0.00000000"],["79819.08000000","0.00400000"],["79818.28000000","0.00000000"],["71877.90000000","0.00400000"],["71877.00000000","0.00000000"]],"a":[["79864.34000000","3.59542000"],["79864.53000000","0.00007000"],["79864.54000000","0.07648000"],["79865.61000000","0.00007000"],["79866.40000000","0.00007000"],["79866.46000000","0.00007000"],["79866.89000000","0.00007000"],["79867.26000000","0.00007000"],["79867.99000000","0.00007000"]]}}}
{"rx_ns": 13984592547100, "frame": {"stream":"btcusdt@depth@100ms","data":{"e":"depthUpdate","E":1787650979815,"s":"BTCUSDT","U":99118686257,"u":99118686285,"b":[["79864.33000000","0.24925000"],["79864.32000000","0.00097000"],["79861.17000000","0.01438000"],["79860.61000000","0.06152000"],["79860.00000000","0.00000000"],["79859.99000000","0.00014000"],["79859.89000000","0.01698000"],["79857.51000000","0.00000000"],["71877.90000000","0.00432000"],["63891.00000000","0.00000000"]],"a":[["79864.42000000","0.00000000"],["79864.46000000","0.00250000"],["79864.54000000","0.29975000"],["79864.55000000","0.07184000"],["79864.80000000","0.78000000"],["79865.61000000","0.00000000"],["79866.40000000","0.00000000"],["79866.46000000","0.00000000"],["79866.89000000","0.00000000"],["79867.26000000","0.00000000"],["79867.99000000","0.00000000"]]}}}
{"rx_ns": 13984691803600, "frame": {"stream":"btcusdt@depth@100ms","data":{"e":"depthUpdate","E":1787650979914,"s":"BTCUSDT","U":99118686286,"u":99118686314,"b":[["79861.17000000","0.01431000"],["79860.49000000","0.31333000"],["79859.99000000","0.00000000"],["79859.89000000","0.01712000"],["79849.78000000","0.00160000"],["79849.12000000","0.00007000"],["79846.14000000","0.00400000"],["79841.80000000","0.00000000"],["79786.33000000","0.02600000"],["71877.90000000","0.00416000"]],"a":[["79864.34000000","3.59550000"],["79864.46000000","0.00000000"],["79864.55000000","0.07184000"],["79864.80000000","0.78014000"],["79866.90000000","0.02079000"],["79881.08000000","0.00007000"]]}}}
{"rx_ns": 13984805606200, "frame": {"stream":"btcusdt@depth20","data":{"lastUpdateId":99118686333,"bids":[["79864.33000000","0.24925000"],["79864.32000000","0.00097000"],["79864.31000000","0.00013000"],["79863.05000000","0.00007000"],["79862.53000000","0.00007000"],["79862.52000000","0.02494000"],["79862.45000000","0.00863000"],["79862.29000000","0.00007000"],["79862.28000000","0.02014000"],["79862.10000000","0.00007000"],["79861.77000000","0.00014000"],["79861.69000000","0.00007000"],["79861.68000000","0.05260000"],["79861.66000000","0.00007000"],["79861.65000000","0.00014000"],["79861.32000000","0.00007000"],["79861.29000000","0.00007000"],["79861.18000000","0.00007000"],["79861.17000000","0.01431000"],["79861.04000000","0.00007000"]],"asks":[["79864.34000000","3.59550000"],["79864.35000000","0.01265000"],["79864.36000000","0.00013000"],["79864.51000000","0.00250000"],["79864.53000000","0.00007000"],["79864.54000000","0.29975000"],["79864.55000000","0.07184000"],["79864.59000000","0.00007000"],["79864.80000000","0.78014000"],["79865.19000000","0.00014000"],["79865.62000000","0.01761000"],["79865.99000000","0.00007000"],["79866.00000000","0.00400000"],["79866.09000000","0.00007000"],["79866.15000000","0.00951000"],["79866.41000000","0.03238000"],["79866.47000000","0.04014000"],["79866.71000000","0.00007000"],["79866.78000000","0.00007000"],["79866.81000000","0.00400000"]]}}}
{"rx_ns": 13984805719200, "frame": {"stream":"btcusdt@depth@100ms","data":{"e":"depthUpdate","E":1787650980014,"s":"BTCUSDT","U":99118686315,"u":99118686333,"b":[["79842.65000000","0.00000000"],["79838.77000000","0.00626000"],["79837.92000000","0.36514000"],["79837.91000000","0.00000000"],["79837.41000000","0.00000000"],["79836.36000000","0.00000000"],["79835.47000000","0.62628000"],["79792.24000000","0.00312000"],["79712.01000000","0.00125000"],["71877.90000000","0.00416000"],["63891.47000000","0.00031000"]],"a":[["79864.49000000","0.00000000"],["79864.51000000","0.00250000"],["79877.55000000","0.00626000"],["79878.06000000","0.34577000"],["79880.79000000","0.62628000"],["79887.99000000","0.42960000"],["79889.19000000","0.00000000"],["79889.73000000","0.00000000"],["79891.97000000","0.00007000"],["79899.93000000","0.00000000"],["79927.04000000","0.00190000"],["80006.84000000","0.00076000"],["86422.88000000","0.18910000"]]}}}
{"rx_ns": 13984891886700, "frame": {"stream":"btcusdt@depth@100ms","data":{"e":"depthUpdate","E":1787650980114,"s":"BTCUSDT","U":99118686334,"u":99118686346,"b":[["79837.92000000","0.00000000"],["79836.36000000","0.54464000"],["79825.34000000","0.25050000"],["79824.11000000","0.00000000"],["71877.90000000","0.00416000"],["71877.00000000","0.00010000"]],"a":[["79864.51000000","0.00000000"],["79864.53000000","0.00257000"],["79945.22000000","0.73942000"],["86422.88000000","0.20801000"]]}}}
{"rx_ns": 13984992285600, "frame": {"stream":"btcusdt@depth@100ms","data":{"e":"depthUpdate","E":1787650980214,"s":"BTCUSDT","U":99118686347,"u":99118686377,"b":[["79864.33000000","0.23476000"],["79864.32000000","0.00083000"],["79860.62000000","0.00000000"],["79860.61000000","0.00014000"],["79859.89000000","0.01705000"],["79859.38000000","0.00000000"],["79859.37000000","0.00000000"],["79858.75000000","0.06138000"],["79858.66000000","0.00079000"],["79858.65000000","0.00000000"],["79858.30000000","0.00007000"],["79856.90000000","0.00007000"],["79856.28000000","0.00101000"],["79835.47000000","0.00000000"],["79834.30000000","0.62628000"],["79806.96000000","0.00000000"],["79797.64000000","0.04696000"],["71877.90000000","0.00432000"],["71877.00000000","0.00000000"],["63891.47000000","0.00000000"]],"a":[["79864.53000000","0.00007000"],["79864.56000000","0.00250000"],["79949.75000000","1.95361000"],["79952.56000000","0.00000000"],["79955.03000000","0.00000000"]]}}}
{"rx_ns": 13985096109900, "frame": {"stream":"btcusdt@depth@100ms","data":{"e":"depthUpdate","E":1787650980314,"s":"BTCUSDT","U":99118686378,"u":99118686488,"b":[["79864.33000000","0.12346000"],["79862.29000000","0.00000000"],["79862.28000000","0.00014000"],["79861.17000000","0.01424000"],["79860.61000000","0.00000000"],["79860.49000000","0.00021000"],["79859.89000000","0.01705000"],["79858.96000000","0.00000000"],["79858.76000000","0.00000000"],["79858.75000000","0.00014000"],["79858.29000000","0.00000000"],["79858.04000000","0.00007000"],["79857.39000000","0.00000000"],["79856.96000000","0.02000000"],["79856.94000000","0.00000000"],["79856.89000000","0.00000000"],["79856.28000000","0.05629000"],["79856.27000000","0.00000000"],["79855.66000000","0.05552000"],["79855.65000000","0.00250000"],["79855.16000000","0.06145000"],["79855.15000000","0.00000000"],["79854.69000000","0.06138000"],["79854.68000000","0.00000000"],["79854.16000000","0.05666000"],["79854.15000000","0.00000000"],["79854.14000000","1.51544000"],["79854.05000000","0.00000000"],["79850.26000000","0.00000000"],["79848.60000000","0.02400000"],["79848.23000000","0.00250000"],["79846.14000000","0.00000000"],["79846.01000000","0.00400000"],["79845.85000000","0.00400000"],["79845.67000000","0.00000000"],["79845.64000000","0.00000000"],["79845.36000000","0.00000000"],["79845.35000000","0.00400000"],["79845.02000000","0.00000000"],["79843.91000000","0.00000000"],["79843.14000000","0.00000000"],["79840.89000000","0.00000000"],["79838.77000000","0.00000000"],["79836.58000000","0.00626000"],["79831.57000000","0.00000000"],["79829.98000000","0.09401000"],["79822.67000000","0.33833000"],["79817.34000000","0.00000000"],["79789.08000000","1.24108000"],["79785.84000000","0.00000000"],["79784.49000000","0.11998000"],["71877.90000000","0.00416000"],["71877.88000000","0.00000000"],["71877.00000000","0.00010000"],["65000.00000000","82.39543000"],["63891.00000000","0.00000000"]],"a":[["79864.34000000","3.59806000"],["79864.53000000","0.00000000"],["79864.54000000","0.29968000"],["79864.56000000","0.00000000"],["79868.18000000","0.02086000"],["79868.76000000","0.02000000"],["79872.75000000","0.33812000"],["79877.15000000","0.12000000"],["79878.85000000","0.00000000"],["79893.32000000","0.00000000"],["79894.26000000","0.00000000"],["79900.16000000","0.00000000"],["79913.50000000","0.00000000"],["80083.24000000","0.00000000"],["84202.54000000","0.00884000"]]}}}
{"rx_ns": 13985198241900, "frame": {"stream":"btcusdt@depth@100ms","data":{"e":"depthUpdate","E":1787650980414,"s":"BTCUSDT","U":99118686489,"u":99118686599,"b":[["79864.33000000","0.12339000"],["79864.32000000","0.00076000"],["79862.45000000","0.00856000"],["79862.28000000","0.00000000"],["79861.17000000","0.01424000"],["79860.50000000","0.00007000"],["79860.49000000","0.00007000"],["79859.90000000","0.00007000"],["79859.89000000","0.01705000"],["79858.76000000","0.00007000"],["79858.75000000","0.06138000"],["79858.62000000","0.00007000"],["79858.61000000","0.01712000"],["79858.30000000","0.00000000"],["79858.14000000","0.00007000"],["79858.13000000","0.06138000"],["79858.01000000","0.00007000"],["79858.00000000","0.02428000"],["79857.78000000","0.00000000"],["79857.77000000","0.00007000"],["79857.52000000","0.00007000"],["79857.51000000","0.06138000"],["79856.97000000","0.00000000"],["79856.96000000","0.02021000"],["79856.90000000","0.00000000"],["79856.89000000","0.06138000"],["79856.29000000","0.00007000"],["79856.28000000","0.05622000"],["79856.01000000","0.00000000"],["79855.66000000","0.05545000"],["79855.16000000","0.06138000"],["79851.78000000","0.00000000"],["79850.26000000","0.00000000"],["79850.24000000","0.00000000"],["79849.03000000","0.08566000"],["79848.23000000","0.00000000"],["79847.57000000","0.93788000"],["79847.53000000","0.00250000"],["79846.01000000","0.00000000"],["79845.67000000","0.00400000"],["79845.35000000","1.88077000"],["79840.33000000","0.00000000"],["79814.88000000","0.00007000"],["71877.90000000","0.00416000"],["71877.00000000","0.00000000"],["63891.46000000","0.00000000"]],"a":[["79864.34000000","3.59180000"],["79866.15000000","0.00958000"],["79866.40000000","0.00626000"],["79873.69000000","0.08576000"],["79874.90000000","0.00000000"],["79903.07000000","0.00433000"],["79911.99000000","1.14520000"],["79913.11000000","0.00000000"],["79955.24000000","0.00556000"],["79962.89000000","0.00000000"],["80071.39000000","0.01961000"]]}}}
{"rx_ns": 13985294465200, "frame": {"stream":"btcusdt@depth@100ms","data":{"e":"depthUpdate","E":1787650980514,"s":"BTCUSDT","U":99118686600,"u":99118686633,"b":[["79859.89000000","0.01705000"],["79858.75000000","0.06152000"],["79858.61000000","0.01712000"],["79858.13000000","0.06152000"],["79858.00000000","0.02414000"],["79856.96000000","0.02007000"],["79847.54000000","0.00250000"],["79847.53000000","0.00000000"],["79830.00000000","0.07438000"],["71877.90000000","0.00416000"],["63891.47000000","0.00031000"],["63891.46000000","0.00000000"]],"a":[["79864.34000000","3.59806000"],["79864.55000000","0.07885000"],["79866.15000000","0.00958000"],["79866.40000000","0.00014000"],["79866.47000000","0.04000000"]]}}}
{"rx_ns": 13985392210000, "frame": {"stream":"btcusdt@depth@100ms","data":{"e":"depthUpdate","E":1787650980614,"s":"BTCUSDT","U":99118686634,"u":99118686669,"b":[["79850.62000000","0.00000000"],["79850.01000000","0.00000000"],["79847.54000000","0.00000000"],["79847.53000000","0.00250000"],["79845.36000000","0.00800000"],["79839.79000000","0.00000000"],["79809.93000000","0.83247000"],["78666.36000000","0.00000000"],["71877.90000000","0.00416000"],["63891.47000000","0.00000000"]],"a":[["79864.34000000","3.59743000"],["79866.15000000","0.00951000"],["79866.40000000","0.00000000"],["79866.47000000","0.04014000"],["79870.00000000","0.12354000"],["79880.00000000","0.12048000"],["79880.27000000","0.00000000"],["79887.98000000","0.51223000"],["79888.75000000","0.00189000"],["79889.72000000","0.00000000"],["79890.21000000","0.00000000"],["79891.56000000","0.00060000"],["79902.15000000","0.00000000"],["79905.07000000","0.00000000"],["79906.09000000","0.83147000"],["81062.31000000","0.00000000"]]}}}
{"rx_ns": 13985492004800, "frame": {"stream":"btcusdt@depth@100ms","data":{"e":"depthUpdate","E":1787650980714,"s":"BTCUSDT","U":99118686670,"u":99118686696,"b":[["79864.33000000","0.12353000"],["79864.32000000","0.00090000"],["79861.17000000","0.01431000"],["79860.00000000","0.00007000"],["79859.99000000","0.06138000"],["79859.89000000","0.01712000"],["79859.38000000","0.00007000"],["79859.37000000","0.06138000"],["79858.62000000","0.00000000"],["79856.29000000","0.00000000"],["79852.20000000","0.00007000"],["79847.53000000","0.00000000"],["79847.52000000","0.00250000"],["79845.36000000","0.01200000"],["79780.94000000","0.00000000"],["78666.36000000","0.00030000"],["71877.90000000","0.00432000"],["71877.00000000","0.00000000"]],"a":[["79927.04000000","0.00000000"],["80006.84000000","0.00000000"],["81062.31000000","0.00030000"]]}}}
{"rx_ns": 13985591788100, "frame": {"stream":"btcusdt@depth@100ms","data":{"e":"depthUpdate","E":1787650980814,"s":"BTCUSDT","U":99118686697,"u":99118686737,"b":[["79864.33000000","0.12312000"],["79863.70000000","0.00007000"],["79861.17000000","0.01431000"],["79859.99000000","0.06152000"],["79859.89000000","0.01712000"],["79859.37000000","0.06152000"],["79858.61000000","0.01698000"],["79858.13000000","0.06138000"],["79856.96000000","0.02000000"],["79855.07000000","0.33818000"],["79853.58000000","0.00007000"],["79847.52000000","0.00000000"],["79846.50000000","0.00250000"],["79819.60000000","0.00400000"],["79819.08000000","0.00000000"],["79815.85000000","0.00000000"],["79815.84000000","0.00000000"],["79779.47000000","0.54241000"],["71877.90000000","0.00416000"],["71877.00000000","0.00000000"]],"a":[["79864.34000000","3.59735000"],["79891.74000000","0.09410000"],["79898.78000000","0.00000000"],["79927.04000000","0.00190000"],["79947.11000000","1.95361000"],["79949.75000000","0.00000000"],["79952.56000000","1.35811000"],["80006.84000000","0.00076000"]]}}}
{"rx_ns": 13985711952300, "frame": {"stream":"btcusdt@depth@100ms","data":{"e":"depthUpdate","E":1787650980914,"s":"BTCUSDT","U":99118686738,"u":99118686748,"b":[["79849.12000000","0.00000000"],["79846.50000000","0.00000000"],["79835.62000000","0.49442000"],["79811.67000000","0.97261000"],["71877.90000000","0.00432000"]],"a":[["79877.63000000","0.17962000"],["79881.08000000","0.00000000"],["79886.17000000","0.49358000"],["79890.00000000","0.77452000"],["79910.13000000","0.97751000"]]}}}
