{"captured_at": "2026-08-24T20:24:17.662805+00:00", "url": "wss://data-stream.binance.vision/ws/btcusdt@depth@100ms", "venue": "binance", "symbol": "BTCUSDT", "streams": ["depth@100ms"], "combined": false, "rest_url": "https://data-api.binance.vision/api/v3/depth?symbol=BTCUSDT&limit=100", "rest_limit": 100, "rest_weight_per_fetch": 5, "snapshot_every_s": 10.0, "tool_version": "0.1.0", "clock": "perf_counter_ns", "capture_mode": "reconnect", "cycles": 2, "origin_sent": null, "handshake_status": "HTTP/1.1 101 Switching Protocols"}
{"rx_ns": 1253772300, "frame": {"e":"depthUpdate","E":1787603058714,"s":"BTCUSDT","U":99076612006,"u":99076612015,"b":[["78752.21000000","0.12705000"],["78629.57000000","0.00000000"],["76000.00000000","44.09177000"],["70882.20000000","0.00432000"]],"a":[["78758.00000000","0.94668000"],["78758.59000000","0.20201000"],["78759.20000000","0.00331000"],["78760.77000000","0.00334000"],["78865.82000000","0.00000000"]]}}
{"rx_ns": 1362935400, "frame": {"e":"depthUpdate","E":1787603058814,"s":"BTCUSDT","U":99076612016,"u":99076612073,"b":[["78757.99000000","3.60703000"],["78753.32000000","0.37160000"],["78752.21000000","0.00000000"],["78704.12000000","0.00413000"],["78634.89000000","0.04471000"],["78364.20000000","0.01000000"],["77972.37000000","0.01000000"],["77582.51000000","0.01012000"],["77194.60000000","0.01000000"],["76808.63000000","0.01000000"],["76424.58000000","0.01000000"],["76042.46000000","0.01000000"],["75662.25000000","0.01000000"],["75283.94000000","0.01000000"],["74907.52000000","0.01000000"],["74532.98000000","0.01000000"],["74160.31000000","0.01000000"],["73789.51000000","0.01000000"],["73420.57000000","0.01000000"],["73053.46000000","0.01000000"],["70882.20000000","0.00441000"],["63006.00000000","0.09804000"]],"a":[["78758.00000000","0.94705000"],["78758.01000000","0.00090000"],["78758.58000000","0.00007000"],["78761.52000000","0.00000000"],["78762.00000000","0.02400000"],["78771.71000000","0.00000000"],["78783.35000000","0.63472000"],["78871.16000000","0.02789000"],["79151.79000000","0.01000000"],["79547.55000000","0.01000000"],["79945.29000000","0.01000000"],["80345.02000000","0.01000000"],["80746.74000000","0.01000000"],["81150.48000000","0.01000000"],["81556.23000000","0.01000000"],["81964.01000000","0.01000000"],["82373.83000000","0.01000000"],["82785.70000000","0.01000000"],["83199.63000000","0.01000000"],["83615.63000000","0.01000000"],["84033.70000000","0.01000000"],["84453.87000000","0.01000000"],["84876.14000000","0.01000000"]]}}
{"rx_ns": 1453136100, "frame": {"e":"depthUpdate","E":1787603058914,"s":"BTCUSDT","U":99076612074,"u":99076612096,"b":[["78757.99000000","3.60687000"],["78755.98000000","0.36238000"],["78755.02000000","0.00000000"],["78753.51000000","0.00000000"],["78753.32000000","0.37153000"],["78752.23000000","0.00000000"],["78701.92000000","0.00342000"],["70882.20000000","0.00425000"],["70882.00000000","0.00020000"],["50000.00000000","517.89831000"]],"a":[["78758.00000000","0.94685000"],["78758.59000000","0.20208000"],["78759.19000000","0.00000000"],["78759.98000000","0.00007000"],["78880.39000000","0.00000000"],["78931.56000000","0.00028000"]]}}
{"rx_ns": 1554052400, "frame": {"e":"depthUpdate","E":1787603059015,"s":"BTCUSDT","U":99076612097,"u":99076612105,"b":[["78625.38000000","0.00406000"],["70882.20000000","0.00441000"],["70882.00000000","0.00000000"],["63006.40000000","0.00031000"],["63006.00000000","0.09804000"]],"a":[["78767.27000000","0.00000000"],["78767.74000000","0.31747000"]]}}
{"rx_ns": 1653561800, "frame": {"e":"depthUpdate","E":1787603059114,"s":"BTCUSDT","U":99076612106,"u":99076612110,"b":[["78757.99000000","3.60043000"],["78755.32000000","0.00324000"],["70882.20000000","0.00425000"]],"a":[["78760.77000000","0.00327000"]]}}
{"rx_ns": 1755101400, "frame": {"e":"depthUpdate","E":1787603059214,"s":"BTCUSDT","U":99076612111,"u":99076612121,"b":[["78753.32000000","0.37160000"],["78753.24000000","0.00007000"],["78752.72000000","0.00000000"],["78645.21000000","0.00000000"],["70882.20000000","0.00441000"],["63006.40000000","0.00000000"]],"a":[["78758.00000000","0.94593000"]]}}
{"rx_ns": 1872577800, "frame": {"e":"depthUpdate","E":1787603059314,"s":"BTCUSDT","U":99076612122,"u":99076612173,"b":[["78757.26000000","0.20829000"],["78757.25000000","0.00204000"],["78753.32000000","0.37153000"],["78734.32000000","0.00007000"],["78677.35000000","0.02115000"],["78364.20000000","0.00000000"],["77972.37000000","0.00000000"],["77582.51000000","0.00012000"],["77194.60000000","0.00000000"],["76808.63000000","0.00000000"],["76424.58000000","0.00000000"],["76042.46000000","0.00000000"],["75662.25000000","0.00000000"],["75283.94000000","0.00000000"],["74907.52000000","0.00000000"],["74532.98000000","0.00000000"],["74160.31000000","0.00000000"],["73789.51000000","0.00000000"],["73420.57000000","0.00000000"],["73053.46000000","0.00000000"],["70882.20000000","0.00425000"],["63006.00000000","0.09804000"],["41465.30000000","0.00000000"]],"a":[["78758.00000000","0.72754000"],["78763.36000000","0.00000000"],["78763.40000000","0.00000000"],["78765.25000000","0.00253000"],["78765.99000000","0.00253000"],["78766.03000000","0.00007000"],["78767.74000000","0.00000000"],["78767.99000000","0.31747000"],["78781.58000000","0.00007000"],["79151.79000000","0.00000000"],["79547.55000000","0.00000000"],["79945.29000000","0.00000000"],["80345.02000000","0.00000000"],["80746.74000000","0.00000000"],["81150.48000000","0.00000000"],["81556.23000000","0.00000000"],["81964.01000000","0.00000000"],["82373.83000000","0.00000000"],["82785.70000000","0.00000000"],["83199.63000000","0.00000000"],["83615.63000000","0.00000000"],["84033.70000000","0.00000000"],["84453.87000000","0.00000000"],["84876.14000000","0.00000000"]]}}
{"rx_ns": 1967162700, "frame": {"e":"depthUpdate","E":1787603059414,"s":"BTCUSDT","U":99076612174,"u":99076612200,"b":[["78757.99000000","3.91796000"],["78757.98000000","0.00090000"],["78757.79000000","0.10231000"],["78757.72000000","0.01970000"],["78756.65000000","0.00000000"],["78752.09000000","0.12705000"],["78750.83000000","0.00400000"],["78740.85000000","0.38104000"],["78732.02000000","0.00318000"],["70882.20000000","0.00409000"],["70882.00000000","0.00010000"]],"a":[["78758.00000000","0.72740000"],["78758.58000000","0.00014000"],["78761.92000000","0.00007000"],["78765.25000000","0.00000000"],["78765.98000000","0.00253000"],["78771.82000000","0.00400000"],["78779.01000000","0.00000000"],["78861.82000000","0.00316000"]]}}
{"rx_ns": 2053436300, "frame": {"e":"depthUpdate","E":1787603059514,"s":"BTCUSDT","U":99076612201,"u":99076612221,"b":[["78756.84000000","0.00007000"],["78753.32000000","0.37160000"],["78752.09000000","0.00000000"],["78751.79000000","0.12705000"],["70882.20000000","0.00425000"],["70882.00000000","0.00000000"],["63006.40000000","0.00031000"],["63006.39000000","0.00000000"]],"a":[["78758.00000000","0.72733000"],["78758.01000000","0.00083000"],["78760.44000000","0.05239000"],["78761.53000000","0.03698000"],["78761.92000000","0.00000000"],["78762.00000000","0.02407000"],["79247.61000000","0.00339000"]]}}
{"rx_ns": 2153835200, "kind": "rest", "req": {"method": "GET", "url": "https://data-api.binance.vision/api/v3/depth?symbol=BTCUSDT&limit=100", "limit": 100, "weight": 5, "sent_ns": 1132069400, "status": 200, "used_weight_1m": "5", "recv_ns": 2126102400}, "frame": {"lastUpdateId":99076612221,"bids":[["78757.99000000","3.91796000"],["78757.98000000","0.00090000"],["78757.97000000","0.02534000"],["78757.80000000","0.00014000"],["78757.79000000","0.10231000"],["78757.73000000","0.00014000"],["78757.72000000","0.01970000"],["78757.32000000","0.00014000"],["78757.26000000","0.20829000"],["78757.25000000","0.00204000"],["78756.84000000","0.00007000"],["78756.68000000","0.00014000"],["78756.67000000","0.05327000"],["78756.64000000","0.04013000"],["78756.45000000","0.03279000"],["78755.99000000","0.00007000"],["78755.98000000","0.36238000"],["78755.60000000","0.00008000"],["78755.32000000","0.00324000"],["78755.28000000","0.00400000"],["78755.19000000","0.03926000"],["78755.18000000","0.00007000"],["78754.93000000","0.04926000"],["78754.50000000","0.00014000"],["78754.49000000","0.00007000"],["78754.01000000","0.30000000"],["78754.00000000","0.63080000"],["78753.99000000","0.30007000"],["78753.98000000","1.23044000"],["78753.93000000","0.03926000"],["78753.32000000","0.37160000"],["78753.27000000","0.00657000"],["78753.24000000","0.00007000"],["78752.97000000","0.00253000"],["78752.89000000","0.00400000"],["78752.45000000","0.03224000"],["78752.00000000","0.01400000"],["78751.79000000","0.12705000"],["78751.31000000","0.12698000"],["78751.19000000","0.00007000"],["78750.83000000","0.00400000"],["78750.82000000","1.90515000"],["78750.81000000","0.04640000"],["78750.80000000","0.77358000"],["78750.79000000","0.00007000"],["78750.70000000","0.02000000"],["78750.63000000","0.00014000"],["78750.62000000","0.00359000"],["78750.50000000","0.00400000"],["78750.11000000","0.21930000"],["78750.02000000","0.00152000"],["78750.00000000","0.01907000"],["78749.99000000","0.00010000"],["78749.54000000","1.18593000"],["78749.29000000","0.01268000"],["78749.28000000","0.02285000"],["78749.15000000","0.00007000"],["78748.79000000","0.12000000"],["78748.66000000","0.00007000"],["78748.58000000","0.00317000"],["78748.48000000","0.00007000"],["78748.11000000","0.00400000"],["78748.00000000","0.02400000"],["78747.97000000","0.00007000"],["78747.90000000","0.00008000"],["78747.76000000","0.08576000"],["78747.43000000","0.00329000"],["78747.30000000","0.36224000"],["78747.29000000","1.21875000"],["78747.10000000","0.00007000"],["78746.84000000","0.02400000"],["78746.79000000","0.02600000"],["78746.76000000","0.00014000"],["78746.29000000","0.00400000"],["78746.06000000","0.02200000"],["78746.01000000","0.02800000"],["78746.00000000","0.02400000"],["78745.99000000","0.02800000"],["78745.55000000","1.21952000"],["78745.51000000","0.00007000"],["78745.29000000","0.03000000"],["78745.07000000","0.00326000"],["78745.05000000","0.00007000"],["78744.93000000","0.12699000"],["78744.63000000","0.00007000"],["78744.60000000","0.00007000"],["78744.45000000","1.90515000"],["78744.35000000","0.03224000"],["78744.30000000","0.00400000"],["78744.00000000","0.02400000"],["78743.70000000","0.02400000"],["78743.50000000","0.00406000"],["78743.00000000","0.00014000"],["78742.94000000","0.02000000"],["78742.92000000","0.02400000"],["78742.89000000","0.00014000"],["78742.45000000","0.00007000"],["78742.43000000","0.00007000"],["78742.36000000","0.00007000"],["78742.31000000","0.00400000"]],"asks":[["78758.00000000","0.72733000"],["78758.01000000","0.00083000"],["78758.02000000","0.00013000"],["78758.37000000","0.00014000"],["78758.58000000","0.00014000"],["78758.59000000","0.20208000"],["78758.99000000","0.00014000"],["78759.00000000","0.01852000"],["78759.20000000","0.00331000"],["78759.98000000","0.00007000"],["78759.99000000","0.00014000"],["78760.00000000","0.02407000"],["78760.12000000","0.00007000"],["78760.26000000","0.00014000"],["78760.27000000","0.03083000"],["78760.43000000","0.00014000"],["78760.44000000","0.05239000"],["78760.77000000","0.00327000"],["78761.01000000","0.01007000"],["78761.42000000","0.00007000"],["78761.53000000","0.03698000"],["78762.00000000","0.02407000"],["78762.24000000","0.00014000"],["78762.78000000","0.00332000"],["78762.79000000","0.03691000"],["78763.30000000","0.00008000"],["78763.47000000","0.00007000"],["78763.69000000","0.00324000"],["78764.00000000","0.02414000"],["78764.43000000","0.00007000"],["78764.75000000","0.03007000"],["78765.26000000","0.13027000"],["78765.52000000","0.00007000"],["78765.98000000","0.00253000"],["78765.99000000","0.00253000"],["78766.00000000","0.02400000"],["78766.03000000","0.00007000"],["78766.11000000","0.00014000"],["78766.26000000","0.00995000"],["78766.96000000","0.02000000"],["78767.24000000","0.00007000"],["78767.28000000","0.00400000"],["78767.56000000","0.00320000"],["78767.57000000","0.00007000"],["78767.58000000","0.00007000"],["78767.75000000","0.02000000"],["78767.76000000","0.02000000"],["78767.88000000","0.00007000"],["78767.99000000","0.31747000"],["78768.00000000","0.02400000"],["78768.09000000","0.00334000"],["78768.16000000","0.25395000"],["78768.62000000","0.00027000"],["78768.74000000","0.02161000"],["78768.75000000","0.04000000"],["78768.84000000","0.21930000"],["78769.35000000","0.08000000"],["78769.58000000","0.00007000"],["78769.61000000","0.00007000"],["78769.67000000","0.00320000"],["78769.92000000","0.00400000"],["78769.94000000","0.00047000"],["78769.98000000","0.00014000"],["78770.00000000","0.02400000"],["78770.01000000","0.01193000"],["78770.53000000","0.00047000"],["78770.73000000","0.00007000"],["78770.81000000","0.00188000"],["78771.00000000","0.00015000"],["78771.66000000","0.00007000"],["78771.76000000","0.00007000"],["78771.82000000","0.00400000"],["78771.83000000","0.00007000"],["78772.00000000","0.02400000"],["78772.11000000","0.00400000"],["78772.14000000","1.21952000"],["78772.39000000","0.00137000"],["78772.41000000","0.02000000"],["78772.94000000","0.38091000"],["78772.97000000","0.02000000"],["78773.12000000","0.00634000"],["78773.16000000","0.02000000"],["78773.18000000","0.02328000"],["78773.71000000","0.00007000"],["78773.76000000","0.11010000"],["78773.83000000","0.00007000"],["78773.85000000","0.00014000"],["78774.00000000","0.02400000"],["78774.01000000","0.02173000"],["78774.19000000","0.00010000"],["78774.30000000","0.00400000"],["78774.81000000","0.04857000"],["78774.84000000","0.00634000"],["78775.56000000","0.02000000"],["78775.64000000","0.00007000"],["78775.76000000","0.00007000"],["78775.83000000","0.00007000"],["78776.00000000","0.02400000"],["78776.19000000","1.21952000"],["78776.20000000","0.12694000"]]}}
{"rx_ns": 2153835200, "frame": {"e":"depthUpdate","E":1787603059614,"s":"BTCUSDT","U":99076612222,"u":99076612231,"b":[["78677.35000000","0.00000000"],["70882.20000000","0.00425000"],["63006.40000000","0.00000000"]],"a":[["78777.96000000","0.06584000"],["78779.93000000","0.07607000"],["78818.78000000","0.00007000"],["80203.37000000","0.00084000"]]}}
{"rx_ns": 2253251300, "frame": {"e":"depthUpdate","E":1787603059714,"s":"BTCUSDT","U":99076612232,"u":99076612241,"b":[["78757.99000000","3.72448000"],["78753.32000000","0.37160000"],["78751.79000000","0.00000000"],["78751.34000000","0.12705000"],["70882.20000000","0.00409000"]],"a":[["78758.00000000","0.94650000"],["80363.78000000","0.00034000"]]}}
{"rx_ns": 2361599800, "frame": {"e":"depthUpdate","E":1787603059814,"s":"BTCUSDT","U":99076612242,"u":99076612293,"b":[["78757.99000000","3.72476000"],["78753.32000000","0.37160000"],["78677.35000000","0.02115000"],["78568.76000000","0.00778000"],["78565.62000000","0.00000000"],["78364.20000000","0.01000000"],["77972.37000000","0.01000000"],["77582.51000000","0.01012000"],["77194.60000000","0.01000000"],["76808.63000000","0.01000000"],["76424.58000000","0.01000000"],["76042.46000000","0.01000000"],["75662.25000000","0.01000000"],["75283.94000000","0.01000000"],["74907.52000000","0.01000000"],["74532.98000000","0.01000000"],["74160.31000000","0.01000000"],["73789.51000000","0.01000000"],["73420.57000000","0.01000000"],["73053.46000000","0.01000000"],["70882.20000000","0.00425000"],["52500.00000000","35.82499000"]],"a":[["78758.00000000","0.94656000"],["78760.71000000","0.00027000"],["78764.74000000","0.00506000"],["78765.98000000","0.00000000"],["78765.99000000","0.00000000"],["78766.25000000","0.31747000"],["78767.27000000","0.00000000"],["78767.99000000","0.00000000"],["79151.79000000","0.01000000"],["79547.55000000","0.01000000"],["79945.29000000","0.01000000"],["80345.02000000","0.01000000"],["80524.51000000","0.00049000"],["80685.56000000","0.00045000"],["80746.74000000","0.01000000"],["80846.94000000","0.00052000"],["81150.48000000","0.01000000"],["81556.23000000","0.01000000"],["81964.01000000","0.01000000"],["82373.83000000","0.01000000"],["82785.70000000","0.01000000"],["83199.63000000","0.01000000"],["83615.63000000","0.01000000"],["84033.70000000","0.01000000"],["84453.87000000","0.01000000"],["84876.14000000","0.01000000"]]}}
{"rx_ns": 2453359900, "frame": {"e":"depthUpdate","E":1787603059914,"s":"BTCUSDT","U":99076612294,"u":99076612314,"b":[["78757.99000000","3.52273000"],["78757.98000000","0.00083000"],["78757.79000000","0.10224000"],["78757.26000000","0.00000000"],["78750.83000000","0.00000000"],["78750.81000000","0.00007000"],["78750.70000000","0.00000000"],["78748.10000000","0.02000000"],["78747.76000000","0.08765000"],["78747.31000000","0.00400000"],["78654.97000000","0.00000000"],["70882.20000000","0.00441000"]],"a":[["78758.00000000","0.94642000"],["78765.26000000","0.13034000"],["78766.25000000","0.00000000"],["78766.95000000","0.31747000"]]}}
{"rx_ns": 2555330600, "frame": {"e":"depthUpdate","E":1787603060014,"s":"BTCUSDT","U":99076612315,"u":99076613159,"b":[["78757.99000000","0.00000000"],["78757.98000000","0.00000000"],["78757.97000000","0.00000000"],["78757.80000000","0.00000000"],["78757.79000000","0.00000000"],["78757.73000000","0.00000000"],["78757.72000000","0.00000000"],["78757.32000000","0.00000000"],["78757.25000000","0.00000000"],["78756.84000000","0.00000000"],["78756.68000000","0.00000000"],["78756.67000000","0.00000000"],["78756.65000000","0.00000000"],["78756.64000000","0.04142000"],["78756.63000000","0.00049000"],["78756.46000000","0.00014000"],["78756.06000000","0.00007000"],["78755.99000000","0.00007000"],["78755.98000000","0.00014000"],["78755.60000000","0.00000000"],["78755.32000000","0.00000000"],["78755.28000000","0.00000000"],["78755.20000000","0.00014000"],["78755.19000000","0.03933000"],["78755.18000000","0.00000000"],["78754.94000000","0.00014000"],["78754.93000000","0.00007000"],["78754.50000000","0.00007000"],["78754.48000000","0.00000000"],["78754.02000000","0.00000000"],["78754.01000000","0.00021000"],["78754.00000000","0.06100000"],["78753.99000000","0.00014000"],["78753.98000000","0.00014000"],["78753.94000000","0.00007000"],["78753.62000000","0.00000000"],["78753.32000000","0.00007000"],["78753.27000000","0.00007000"],["78752.97000000","0.00000000"],["78752.89000000","0.00000000"],["78752.45000000","0.00000000"],["78751.34000000","0.00000000"],["78751.31000000","0.00000000"],["78750.82000000","0.00000000"],["78750.80000000","0.00014000"],["78750.79000000","0.00000000"],["78750.63000000","0.00007000"],["78750.62000000","0.00000000"],["78750.50000000","0.12706000"],["78750.11000000","0.00000000"],["78749.54000000","0.00000000"],["78749.29000000","0.00000000"],["78749.05000000","0.00000000"],["78748.79000000","0.00000000"],["78748.58000000","0.00000000"],["78748.10000000","0.00000000"],["78747.76000000","0.00189000"],["78747.43000000","0.00000000"],["78747.31000000","0.00000000"],["78747.30000000","0.00000000"],["78747.29000000","0.00000000"],["78746.79000000","0.00000000"],["78746.76000000","0.00007000"],["78746.06000000","0.00000000"],["78746.01000000","0.00000000"],["78745.99000000","0.00000000"],["78745.55000000","0.00000000"],["78745.29000000","0.00000000"],["78744.72000000","0.08576000"],["78744.46000000","0.00000000"],["78744.45000000","0.00000000"],["78744.35000000","0.00000000"],["78743.70000000","0.00000000"],["78743.69000000","0.00000000"],["78743.01000000","0.00000000"],["78742.94000000","0.00000000"],["78742.92000000","0.00000000"],["78742.89000000","0.00007000"],["78742.49000000","0.00000000"],["78742.14000000","0.00000000"],["78742.13000000","0.00027000"],["78742.06000000","0.00000000"],["78742.05000000","0.00000000"],["78740.85000000","0.00000000"],["78740.44000000","0.34629000"],["78740.00000000","0.02400000"],["78739.64000000","0.00000000"],["78739.04000000","0.00000000"],["78739.03000000","0.00635000"],["78739.02000000","0.00007000"],["78738.49000000","0.03000000"],["78738.09000000","0.02000000"],["78737.69000000","0.00000000"],["78737.59000000","0.04000000"],["78737.41000000","0.00635000"],["78737.40000000","0.00000000"],["78737.09000000","0.08000000"],["78736.29000000","1.90515000"],["78736.07000000","0.00000000"],["78736.05000000","0.00254000"],["78735.99000000","0.00007000"],["78735.97000000","0.00000000"],["78735.77000000","0.36224000"],["78735.15000000","0.00007000"],["78733.80000000","0.00000000"],["78732.02000000","0.00000000"],["78731.28000000","0.00007000"],["78731.19000000","0.00000000"],["78731.12000000","0.00000000"],["78730.99000000","0.00000000"],["78730.90000000","3.12720000"],["78729.88000000","0.00000000"],["78728.92000000","0.00000000"],["78728.12000000","0.00000000"],["78727.41000000","0.00007000"],["78726.90000000","0.00000000"],["78725.85000000","0.38111000"],["78724.01000000","0.00634000"],["78723.88000000","0.13239000"],["78723.87000000","0.00000000"],["78723.54000000","0.00007000"],["78721.78000000","0.00320000"],["78720.29000000","0.34302000"],["78720.16000000","0.00400000"],["78719.72000000","0.00000000"],["78719.51000000","0.00000000"],["78719.40000000","0.00000000"],["78718.95000000","0.00000000"],["78718.51000000","0.00010000"],["78718.00000000","0.02600000"],["78717.00000000","0.01000000"],["78715.95000000","0.00000000"],["78715.80000000","0.00007000"],["78715.08000000","0.00000000"],["78711.93000000","0.00007000"],["78711.75000000","0.28447000"],["78710.24000000","0.00400000"],["78709.90000000","0.34307000"],["78708.34000000","0.63532000"],["78708.06000000","0.00007000"],["78705.28000000","0.00400000"],["78704.91000000","0.00007000"],["78704.19000000","0.00007000"],["78701.92000000","0.00007000"],["78700.32000000","0.00007000"],["78691.90000000","0.00000000"],["78687.61000000","1.25828000"],["78682.01000000","0.00000000"],["78664.01000000","1.90515000"],["78616.67000000","0.00000000"],["78593.44000000","1.52082000"],["78462.41000000","0.00250000"],["78364.20000000","0.00000000"],["78355.80000000","0.00007000"],["77972.37000000","0.00000000"],["77582.51000000","0.00012000"],["77194.60000000","0.00000000"],["76808.63000000","0.00000000"],["76424.58000000","0.00000000"],["76042.46000000","0.00000000"],["75662.25000000","0.00000000"],["75283.94000000","0.00000000"],["74907.52000000","0.00000000"],["74532.98000000","0.00000000"],["74160.31000000","0.00000000"],["73789.51000000","0.00000000"],["73420.57000000","0.00000000"],["73053.46000000","0.00000000"],["70882.20000000","0.00000000"],["70882.19000000","0.00041000"],["70882.00000000","0.00000000"],["70880.98000000","0.00016000"],["63005.32000000","0.00046000"]],"a":[["78756.65000000","2.84513000"],["78756.66000000","0.03872000"],["78756.67000000","0.07513000"],["78756.68000000","0.00000000"],["78756.69000000","0.00000000"],["78756.84000000","0.00000000"],["78756.85000000","0.10287000"],["78756.86000000","0.00000000"],["78756.87000000","0.00000000"],["78757.21000000","0.00000000"],["78757.25000000","0.07500000"],["78757.26000000","0.13846000"],["78757.32000000","0.00227000"],["78757.33000000","0.21436000"],["78757.34000000","0.00000000"],["78757.35000000","0.00000000"],["78757.36000000","0.00400000"],["78757.72000000","0.00000000"],["78757.73000000","0.00021000"],["78757.74000000","0.00000000"],["78757.79000000","0.00634000"],["78757.80000000","0.21777000"],["78757.81000000","0.23135000"],["78757.97000000","0.36224000"],["78757.98000000","0.25752000"],["78757.99000000","0.07682000"],["78758.00000000","0.47130000"],["78758.01000000","0.00000000"],["78758.02000000","0.00000000"],["78758.58000000","0.00000000"],["78758.59000000","0.20215000"],["78758.66000000","0.02000000"],["78758.99000000","0.00000000"],["78759.00000000","0.01845000"],["78759.19000000","0.00000000"],["78759.36000000","0.00000000"],["78759.51000000","0.05232000"],["78759.84000000","0.00400000"],["78759.85000000","0.25402000"],["78759.97000000","0.00000000"],["78759.98000000","0.00000000"],["78759.99000000","0.00000000"],["78760.00000000","0.02400000"],["78760.21000000","0.01269000"],["78760.25000000","0.06345000"],["78760.26000000","0.00000000"],["78760.27000000","0.03076000"],["78760.43000000","0.00000000"],["78760.44000000","0.00007000"],["78761.01000000","0.01000000"],["78761.53000000","0.03691000"],["78762.00000000","0.02400000"],["78762.23000000","0.00000000"],["78762.32000000","0.00400000"],["78762.77000000","0.00000000"],["78763.91000000","0.38092000"],["78764.07000000","0.00000000"],["78764.16000000","0.00000000"],["78764.73000000","0.00000000"],["78764.74000000","0.00000000"],["78764.80000000","0.00400000"],["78765.25000000","0.02161000"],["78765.26000000","0.13027000"],["78766.35000000","0.00000000"],["78766.49000000","1.90515000"],["78766.94000000","1.21952000"],["78766.95000000","0.00000000"],["78767.23000000","0.00000000"],["78767.75000000","0.02162000"],["78768.16000000","0.00000000"],["78768.40000000","0.00007000"],["78770.17000000","0.34280000"],["78770.87000000","0.00000000"],["78770.98000000","0.34280000"],["78771.76000000","0.04864000"],["78771.82000000","0.00000000"],["78771.94000000","0.12694000"],["78771.99000000","0.36224000"],["78772.13000000","1.90515000"],["78772.39000000","0.00000000"],["78772.41000000","0.11343000"],["78772.94000000","0.00000000"],["78772.97000000","0.00000000"],["78773.02000000","0.63480000"],["78773.12000000","0.00000000"],["78773.70000000","0.43566000"],["78773.76000000","0.00007000"],["78774.81000000","0.00000000"],["78774.84000000","0.00000000"],["78776.26000000","0.00000000"],["78779.45000000","0.02514000"],["78780.68000000","1.90515000"],["78782.75000000","0.00000000"],["78785.54000000","0.00000000"],["78785.57000000","0.00000000"],["78790.53000000","0.00000000"],["78791.77000000","0.00000000"],["78791.82000000","0.00000000"],["78791.84000000","0.00000000"],["78793.22000000","1.25659000"],["78793.51000000","0.00000000"],["78795.91000000","0.00000000"],["78797.07000000","0.00000000"],["78797.91000000","0.00000000"],["78798.30000000","0.00000000"],["78800.69000000","0.00000000"],["78803.08000000","0.00000000"],["78811.76000000","0.00010000"],["78822.01000000","0.00000000"],["78823.94000000","0.00000000"],["78833.93000000","0.00000000"],["78843.58000000","0.00000000"],["78856.70000000","0.00315000"],["78859.35000000","0.00000000"],["78861.82000000","0.00000000"],["78892.66000000","1.52082000"],["78944.50000000","3.80057000"],["78950.94000000","0.00013000"],["79078.09000000","0.00000000"],["79273.61000000","0.00250000"],["79531.48000000","0.00400000"],["79532.46000000","0.00000000"],["82685.41000000","0.00000000"],["82695.62000000","0.00010000"],["82695.90000000","0.00010000"]]}}
{"rx_ns": 2791308900, "frame": {"e":"depthUpdate","E":1787603060114,"s":"BTCUSDT","U":99076613160,"u":99076614320,"b":[["78756.64000000","0.00000000"],["78756.63000000","0.00000000"],["78756.46000000","0.00000000"],["78756.45000000","0.00000000"],["78756.44000000","0.00000000"],["78756.06000000","0.00000000"],["78755.99000000","0.00000000"],["78755.98000000","0.00000000"],["78755.20000000","0.00000000"],["78755.19000000","0.00000000"],["78754.94000000","0.00000000"],["78754.93000000","0.00000000"],["78754.50000000","0.00000000"],["78754.49000000","0.00000000"],["78754.01000000","0.00000000"],["78754.00000000","0.00000000"],["78753.99000000","0.00000000"],["78753.98000000","0.00000000"],["78753.94000000","0.00000000"],["78753.93000000","0.00000000"],["78753.32000000","0.00000000"],["78753.27000000","0.00000000"],["78753.24000000","0.00000000"],["78752.65000000","0.00000000"],["78752.64000000","0.00000000"],["78752.35000000","0.00000000"],["78752.01000000","0.00000000"],["78752.00000000","0.00000000"],["78751.99000000","0.00000000"],["78751.19000000","0.00000000"],["78751.17000000","0.00000000"],["78751.16000000","0.00028000"],["78751.15000000","0.00093000"],["78751.14000000","0.00007000"],["78750.81000000","0.00007000"],["78750.80000000","0.00000000"],["78750.63000000","0.00028000"],["78750.62000000","0.00007000"],["78750.51000000","0.00000000"],["78750.50000000","0.00007000"],["78750.02000000","0.00000000"],["78750.01000000","0.00014000"],["78750.00000000","0.01907000"],["78749.28000000","0.00007000"],["78749.17000000","0.00000000"],["78748.85000000","0.00000000"],["78748.66000000","0.00000000"],["78748.32000000","0.04927000"],["78748.11000000","0.00000000"],["78748.02000000","0.00000000"],["78748.01000000","0.00014000"],["78748.00000000","0.02407000"],["78747.90000000","0.00000000"],["78747.76000000","0.00000000"],["78747.44000000","0.00000000"],["78747.15000000","0.00000000"],["78746.88000000","0.00000000"],["78746.84000000","0.00007000"],["78746.29000000","0.00000000"],["78746.01000000","0.00014000"],["78746.00000000","0.02407000"],["78745.07000000","0.00000000"],["78744.94000000","0.00014000"],["78744.93000000","0.12713000"],["78744.73000000","0.00007000"],["78744.72000000","0.00007000"],["78744.63000000","0.00000000"],["78744.30000000","0.00000000"],["78743.45000000","0.00000000"],["78743.32000000","0.00000000"],["78742.43000000","0.31759000"],["78742.14000000","0.08576000"],["78741.98000000","0.00000000"],["78741.85000000","0.00000000"],["78741.48000000","0.00152000"],["78740.79000000","0.00000000"],["78740.66000000","0.00000000"],["78740.61000000","0.00000000"],["78740.44000000","0.00000000"],["78739.85000000","0.00048000"],["78739.51000000","0.00330000"],["78739.46000000","0.20829000"],["78739.21000000","0.00007000"],["78739.03000000","0.00000000"],["78739.02000000","0.00007000"],["78738.70000000","0.00204000"],["78738.49000000","0.00000000"],["78738.09000000","0.00000000"],["78737.59000000","0.00000000"],["78737.09000000","0.00000000"],["78736.91000000","0.00000000"],["78736.34000000","0.00187000"],["78736.30000000","1.21952000"],["78735.77000000","0.00000000"],["78735.57000000","0.00323000"],["78735.48000000","0.07000000"],["78735.46000000","0.00000000"],["78735.19000000","0.02000000"],["78735.15000000","0.00014000"],["78734.94000000","0.00000000"],["78734.26000000","0.00635000"],["78733.34000000","0.02286000"],["78732.97000000","0.00000000"],["78732.57000000","0.00000000"],["78732.13000000","0.00000000"],["78732.12000000","0.00000000"],["78731.63000000","0.00328000"],["78731.28000000","0.00014000"],["78730.90000000","3.12467000"],["78730.89000000","0.00000000"],["78730.60000000","0.00000000"],["78730.00000000","0.02400000"],["78729.79000000","0.00000000"],["78729.18000000","0.08000000"],["78729.00000000","0.00007000"],["78727.69000000","0.00330000"],["78727.67000000","1.21903000"],["78727.41000000","0.00014000"],["78725.85000000","0.00000000"],["78724.00000000","0.02400000"],["78723.54000000","0.00014000"],["78717.85000000","0.00000000"],["78717.68000000","0.00000000"],["78717.00000000","0.00000000"],["78716.32000000","0.00000000"],["78715.92000000","0.00000000"],["78715.80000000","0.00014000"],["78715.33000000","0.00000000"],["78715.00000000","0.00000000"],["78714.23000000","0.00000000"],["78714.00000000","0.02400000"],["78713.95000000","0.00000000"],["78712.00000000","0.03400000"],["78711.93000000","0.00014000"],["78708.83000000","0.00000000"],["78708.61000000","0.00000000"],["78707.76000000","0.00400000"],["78703.77000000","0.00000000"],["78703.27000000","0.00000000"],["78702.80000000","0.00400000"],["78701.88000000","0.00000000"],["78701.22000000","0.02406000"],["78700.35000000","0.21930000"],["78700.32000000","0.00407000"],["78698.44000000","0.00000000"],["78692.25000000","0.00617000"],["78690.79000000","0.00436000"],["78685.45000000","0.00642000"],["78677.35000000","0.00000000"],["78049.17000000","0.00000000"],["70880.98000000","0.00000000"],["70880.00000000","0.00081000"],["70878.60000000","0.00000000"],["70877.00000000","0.00222000"]],"a":[["78751.17000000","1.73829000"],["78751.18000000","0.00020000"],["78751.19000000","0.00013000"],["78751.20000000","0.00000000"],["78752.00000000","0.45458000"],["78752.01000000","0.67692000"],["78752.02000000","0.00014000"],["78752.03000000","0.00000000"],["78752.05000000","0.00000000"],["78753.25000000","0.00000000"],["78753.27000000","0.00014000"],["78753.28000000","0.00000000"],["78753.32000000","0.00014000"],["78753.33000000","0.00920000"],["78753.48000000","0.00000000"],["78753.76000000","0.00000000"],["78753.83000000","0.05246000"],["78753.84000000","0.00014000"],["78753.94000000","0.00000000"],["78753.95000000","0.00000000"],["78753.99000000","0.00000000"],["78754.00000000","0.39267000"],["78754.01000000","0.13835000"],["78754.02000000","0.02161000"],["78754.03000000","0.00000000"],["78754.50000000","0.00014000"],["78754.51000000","0.00000000"],["78754.68000000","0.00000000"],["78754.88000000","0.00400000"],["78755.19000000","0.00000000"],["78755.20000000","0.92364000"],["78755.21000000","0.00000000"],["78755.22000000","0.00000000"],["78755.99000000","0.00000000"],["78756.00000000","0.00558000"],["78756.06000000","0.00227000"],["78756.07000000","0.00007000"],["78756.44000000","0.00000000"],["78756.45000000","0.07500000"],["78756.46000000","0.66888000"],["78756.47000000","0.00000000"],["78756.48000000","0.00000000"],["78756.63000000","0.00000000"],["78756.64000000","1.22127000"],["78756.65000000","0.24473000"],["78756.66000000","0.03859000"],["78756.67000000","0.00000000"],["78756.75000000","0.00000000"],["78756.84000000","0.00000000"],["78756.85000000","0.10287000"],["78757.00000000","0.00007000"],["78757.24000000","1.90515000"],["78757.25000000","0.00000000"],["78757.26000000","0.00007000"],["78757.32000000","0.00000000"],["78757.33000000","0.00007000"],["78757.73000000","0.00014000"],["78757.80000000","0.00007000"],["78757.81000000","0.00007000"],["78757.86000000","0.00000000"],["78757.96000000","0.00000000"],["78757.98000000","0.25745000"],["78757.99000000","0.00007000"],["78758.00000000","0.25277000"],["78758.59000000","0.20208000"],["78759.00000000","0.00000000"],["78759.51000000","0.00000000"],["78759.54000000","0.00162000"],["78760.27000000","0.00000000"],["78760.44000000","0.00000000"],["78761.28000000","0.00007000"],["78761.48000000","0.02285000"],["78761.53000000","0.00000000"],["78762.08000000","0.00253000"],["78762.79000000","0.00000000"],["78763.48000000","0.34283000"],["78763.83000000","0.00007000"],["78763.90000000","0.00000000"],["78764.75000000","0.00000000"],["78766.26000000","0.00000000"],["78767.75000000","0.02000000"],["78768.21000000","0.00000000"],["78768.40000000","0.00000000"],["78768.75000000","0.00000000"],["78769.18000000","0.04857000"],["78769.35000000","0.00000000"],["78769.67000000","0.00000000"],["78769.77000000","0.10994000"],["78769.94000000","0.00000000"],["78770.00000000","0.11922000"],["78770.01000000","0.00000000"],["78770.53000000","0.00000000"],["78770.73000000","0.00000000"],["78770.81000000","0.00000000"],["78771.34000000","0.06584000"],["78771.76000000","0.00007000"],["78771.94000000","0.00000000"],["78772.41000000","0.02000000"],["78773.31000000","0.07607000"],["78776.13000000","0.09579000"],["78777.26000000","0.00000000"],["78777.96000000","0.00000000"],["78778.11000000","0.00000000"],["78779.43000000","0.00000000"],["78779.93000000","0.00000000"],["78784.18000000","0.00405000"],["78784.40000000","0.00000000"],["78789.22000000","0.00436000"],["78789.60000000","0.00400000"],["78789.98000000","0.02463000"],["78790.07000000","0.00000000"],["78790.80000000","0.00617000"],["78790.84000000","0.00000000"],["78793.20000000","0.00000000"],["78793.52000000","0.00000000"],["78795.10000000","0.00427000"],["78796.00000000","0.03400000"],["78796.39000000","0.00434000"],["78798.00000000","0.02400000"],["78800.00000000","0.04372000"],["78803.72000000","0.00000000"],["78805.97000000","0.00000000"],["78806.03000000","0.00000000"],["78810.57000000","0.00000000"],["78811.02000000","0.00000000"],["78814.09000000","0.00000000"],["78818.78000000","0.00000000"],["78823.58000000","0.00405000"],["78823.95000000","0.00000000"],["78827.83000000","0.00000000"],["78830.24000000","0.00000000"],["78830.72000000","0.09172000"],["78835.71000000","0.00000000"],["78843.59000000","0.00000000"],["78844.99000000","0.04637000"],["78848.60000000","0.00000000"],["78851.47000000","0.00000000"],["78851.58000000","0.00319000"],["78855.09000000","0.00405000"],["78856.70000000","0.00000000"],["78861.76000000","0.00000000"],["78868.94000000","0.00000000"],["78902.36000000","0.00405000"],["78909.01000000","0.00000000"],["78973.27000000","0.00405000"],["78979.94000000","0.00000000"],["78987.90000000","0.00000000"],["79240.00000000","0.00635000"],["79531.48000000","0.00000000"],["79531.97000000","0.00000000"],["79532.11000000","0.00000000"],["79532.25000000","0.00000000"]]}}
{"rx_ns": 2791603700, "frame": {"e":"depthUpdate","E":1787603060214,"s":"BTCUSDT","U":99076614321,"u":99076615387,"b":[["78751.16000000","0.00000000"],["78751.15000000","0.00000000"],["78751.14000000","0.00000000"],["78750.81000000","0.00000000"],["78750.63000000","0.00000000"],["78750.62000000","0.00000000"],["78750.50000000","0.00000000"],["78750.01000000","0.00000000"],["78750.00000000","0.00000000"],["78749.99000000","0.00000000"],["78749.28000000","0.00000000"],["78749.15000000","0.00000000"],["78748.48000000","0.00000000"],["78748.33000000","0.00000000"],["78748.32000000","0.00000000"],["78748.01000000","0.00000000"],["78748.00000000","0.00000000"],["78747.97000000","0.00000000"],["78747.10000000","0.00000000"],["78747.09000000","0.00000000"],["78746.84000000","0.00000000"],["78746.76000000","0.00000000"],["78746.01000000","0.00000000"],["78746.00000000","0.01734000"],["78745.99000000","0.00035000"],["78745.51000000","0.00000000"],["78745.23000000","0.00014000"],["78745.22000000","0.03179000"],["78745.05000000","0.00000000"],["78744.94000000","0.00000000"],["78744.93000000","0.00014000"],["78744.73000000","0.00000000"],["78744.72000000","0.00000000"],["78744.23000000","0.00000000"],["78744.22000000","0.00000000"],["78744.01000000","0.00014000"],["78744.00000000","0.02407000"],["78743.97000000","0.00014000"],["78743.96000000","0.03816000"],["78743.50000000","0.00000000"],["78743.13000000","0.00014000"],["78743.12000000","0.04854000"],["78743.00000000","0.00007000"],["78742.71000000","0.00007000"],["78742.70000000","0.03816000"],["78742.44000000","0.00000000"],["78742.43000000","0.00028000"],["78742.36000000","0.00000000"],["78742.31000000","0.00000000"],["78742.14000000","0.00007000"],["78742.13000000","0.00000000"],["78742.01000000","0.00007000"],["78742.00000000","0.02407000"],["78741.59000000","0.00000000"],["78741.48000000","0.00000000"],["78741.00000000","0.00000000"],["78740.99000000","0.00007000"],["78740.50000000","0.00007000"],["78740.46000000","0.00000000"],["78740.37000000","0.00000000"],["78740.09000000","0.00000000"],["78740.01000000","0.00000000"],["78739.51000000","0.00000000"],["78739.46000000","0.00000000"],["78739.17000000","0.00000000"],["78739.16000000","0.00014000"],["78738.70000000","0.00000000"],["78738.06000000","0.00406000"],["78737.88000000","0.00000000"],["78737.41000000","0.00000000"],["78736.88000000","0.00000000"],["78736.77000000","0.00639000"],["78736.31000000","0.00007000"],["78736.30000000","0.00000000"],["78736.29000000","0.00000000"],["78736.06000000","0.00007000"],["78736.05000000","0.00000000"],["78735.48000000","0.00000000"],["78735.19000000","0.00000000"],["78735.15000000","0.31762000"],["78734.26000000","0.00000000"],["78733.73000000","0.08576000"],["78733.49000000","0.00000000"],["78733.38000000","0.00000000"],["78733.10000000","0.00152000"],["78733.08000000","0.20829000"],["78733.06000000","0.00204000"],["78732.91000000","0.00007000"],["78731.98000000","0.00000000"],["78731.28000000","0.00014000"],["78730.91000000","1.21952000"],["78730.90000000","0.00000000"],["78730.56000000","0.00000000"],["78730.49000000","0.00000000"],["78729.98000000","0.00000000"],["78729.91000000","0.02514000"],["78729.82000000","0.00000000"],["78729.18000000","0.00000000"],["78729.08000000","0.00007000"],["78728.32000000","0.00635000"],["78728.08000000","0.00000000"],["78728.04000000","0.00000000"],["78727.86000000","0.00000000"],["78727.78000000","0.01000000"],["78727.41000000","0.00014000"],["78727.28000000","0.14000000"],["78726.78000000","0.00000000"],["78726.75000000","1.90515000"],["78726.67000000","1.21952000"],["78726.08000000","0.02000000"],["78725.61000000","0.06588000"],["78724.53000000","0.36224000"],["78724.36000000","0.00000000"],["78724.09000000","0.02400000"],["78724.01000000","0.00000000"],["78723.88000000","0.00000000"],["78723.64000000","0.07612000"],["78723.39000000","0.00000000"],["78722.38000000","0.00126000"],["78721.87000000","0.00000000"],["78721.78000000","0.00000000"],["78720.29000000","0.00000000"],["78720.00000000","0.02400000"],["78719.56000000","0.00254000"],["78718.91000000","0.13487000"],["78717.47000000","0.13240000"],["78716.96000000","0.00000000"],["78716.90000000","0.00000000"],["78715.72000000","0.00000000"],["78713.42000000","0.00000000"],["78713.26000000","0.00000000"],["78713.03000000","0.00000000"],["78712.00000000","0.02400000"],["78711.00000000","0.00000000"],["78710.10000000","0.00000000"],["78710.00000000","0.11929000"],["78709.85000000","0.00000000"],["78709.11000000","0.04552000"],["78708.06000000","0.00014000"],["78707.70000000","0.00000000"],["78707.45000000","0.00000000"],["78707.43000000","0.00000000"],["78706.83000000","0.09406000"],["78706.00000000","0.03400000"],["78705.86000000","0.50402000"],["78704.91000000","0.00000000"],["78704.12000000","0.00007000"],["78703.56000000","0.00000000"],["78703.23000000","0.00000000"],["78703.13000000","0.00000000"],["78702.92000000","0.00000000"],["78702.58000000","0.00000000"],["78702.46000000","0.00000000"],["78702.31000000","0.00000000"],["78701.22000000","0.00000000"],["78700.86000000","0.00000000"],["78700.79000000","0.00000000"],["78700.63000000","0.00000000"],["78700.43000000","0.00000000"],["78700.06000000","0.00000000"],["78700.00000000","0.11937000"],["78699.14000000","0.00000000"],["78698.93000000","0.00000000"],["78698.10000000","0.00000000"],["78697.84000000","0.00400000"],["78697.70000000","0.00000000"],["78697.60000000","0.00000000"],["78697.16000000","0.00000000"],["78697.04000000","0.00000000"],["78696.91000000","0.00000000"],["78696.45000000","0.00007000"],["78696.40000000","0.02835000"],["78695.36000000","0.00400000"],["78695.27000000","0.00000000"],["78695.02000000","0.00000000"],["78694.51000000","0.02394000"],["78692.88000000","0.00400000"],["78684.51000000","0.00430000"],["78683.48000000","0.00434000"],["78679.26000000","0.86850000"],["78676.34000000","0.01162000"],["78672.63000000","0.00000000"],["78672.57000000","0.00000000"],["78662.69000000","0.00000000"],["78659.92000000","0.00000000"],["78658.35000000","0.00000000"],["78656.94000000","0.00000000"],["78654.55000000","1.90515000"],["78653.06000000","0.00000000"],["78650.13000000","0.00000000"],["78634.89000000","0.00000000"],["78626.51000000","0.00000000"],["78626.05000000","0.00000000"],["78625.38000000","0.00000000"],["78623.75000000","0.04605000"],["78623.66000000","0.00000000"],["78618.29000000","0.04091000"],["78612.01000000","0.00000000"],["78604.02000000","0.00127000"],["78591.71000000","0.00000000"],["78582.26000000","0.00127000"],["78554.69000000","0.00000000"],["78554.51000000","0.00000000"],["78545.29000000","0.00007000"],["78541.36000000","0.00007000"],["78540.00000000","0.00565000"],["78520.82000000","2.88169000"],["78423.68000000","7.65162000"],["78423.64000000","0.00000000"],["78355.80000000","0.00014000"],["70880.00000000","0.00071000"],["70877.00000000","0.00212000"],["70876.05000000","0.00000000"],["70876.00000000","0.00010000"],["63005.32000000","0.00015000"]],"a":[["78746.01000000","3.20116000"],["78746.02000000","0.20039000"],["78746.03000000","0.00013000"],["78746.76000000","0.00014000"],["78746.77000000","0.00000000"],["78747.09000000","0.00000000"],["78747.10000000","0.00014000"],["78747.11000000","0.54312000"],["78747.12000000","0.00000000"],["78747.13000000","0.00000000"],["78747.14000000","0.03000000"],["78747.44000000","0.00400000"],["78747.76000000","0.01901000"],["78747.96000000","0.00000000"],["78747.97000000","0.00000000"],["78747.98000000","0.03014000"],["78748.00000000","0.00000000"],["78748.01000000","0.00014000"],["78748.02000000","0.00000000"],["78748.03000000","0.00000000"],["78748.32000000","0.00000000"],["78748.33000000","0.00007000"],["78748.43000000","0.00000000"],["78748.49000000","0.00000000"],["78748.62000000","0.00014000"],["78748.63000000","0.05307000"],["78748.82000000","0.00000000"],["78748.83000000","0.00014000"],["78749.02000000","0.03169000"],["78749.04000000","0.00000000"],["78749.16000000","0.02161000"],["78749.73000000","0.00007000"],["78749.83000000","0.00000000"],["78749.92000000","0.00400000"],["78750.00000000","0.00007000"],["78750.01000000","0.00007000"],["78750.02000000","0.00000000"],["78750.22000000","0.00000000"],["78750.25000000","0.02000000"],["78750.27000000","0.00000000"],["78750.28000000","0.03803000"],["78750.35000000","0.00000000"],["78750.51000000","0.00000000"],["78750.59000000","0.00000000"],["78750.63000000","0.00014000"],["78750.64000000","0.21944000"],["78750.82000000","0.00007000"],["78750.99000000","0.00000000"],["78751.00000000","0.00000000"],["78751.09000000","0.00000000"],["78751.15000000","0.00000000"],["78751.16000000","3.39432000"],["78751.17000000","0.46819000"],["78751.18000000","0.00000000"],["78751.19000000","0.00000000"],["78751.52000000","0.00162000"],["78751.54000000","0.03803000"],["78751.99000000","0.00000000"],["78752.00000000","0.07500000"],["78752.01000000","0.28858000"],["78752.02000000","0.00007000"],["78752.60000000","0.00027000"],["78753.27000000","0.00000000"],["78753.32000000","0.00000000"],["78753.33000000","0.00920000"],["78753.82000000","0.00000000"],["78753.83000000","0.00007000"],["78753.84000000","0.00007000"],["78754.00000000","0.07500000"],["78754.01000000","0.01060000"],["78754.02000000","0.02161000"],["78754.98000000","0.00007000"],["78755.20000000","0.73693000"],["78755.28000000","0.00007000"],["78755.60000000","0.00008000"],["78755.83000000","0.00007000"],["78756.07000000","0.00000000"],["78756.17000000","0.34286000"],["78756.21000000","0.12697000"],["78756.24000000","0.00007000"],["78756.45000000","0.00000000"],["78756.46000000","0.65764000"],["78756.64000000","1.21952000"],["78756.65000000","0.00000000"],["78756.66000000","0.00000000"],["78756.85000000","0.00000000"],["78757.26000000","0.00000000"],["78757.33000000","0.00000000"],["78757.73000000","0.00000000"],["78757.79000000","0.00000000"],["78757.80000000","0.00000000"],["78757.81000000","0.00000000"],["78757.98000000","0.25638000"],["78757.99000000","0.00000000"],["78758.00000000","0.03333000"],["78758.13000000","0.00007000"],["78758.59000000","0.00000000"],["78758.66000000","0.00000000"],["78759.54000000","0.00000000"],["78759.85000000","0.00000000"],["78760.00000000","0.11923000"],["78760.77000000","0.05184000"],["78760.99000000","0.00007000"],["78761.76000000","0.10951000"],["78761.94000000","0.63489000"],["78764.43000000","0.00000000"],["78764.79000000","0.04674000"],["78766.20000000","0.00000000"],["78766.32000000","0.00010000"],["78766.93000000","0.00000000"],["78766.97000000","0.06585000"],["78767.56000000","0.00000000"],["78767.58000000","0.00000000"],["78768.94000000","0.07608000"],["78769.18000000","0.00000000"],["78769.77000000","0.00000000"],["78770.98000000","0.00000000"],["78771.00000000","0.00008000"],["78771.34000000","0.00000000"],["78771.52000000","0.63482000"],["78773.31000000","0.00000000"],["78775.64000000","0.00000000"],["78776.20000000","0.00000000"],["78776.67000000","1.21903000"],["78778.26000000","0.00000000"],["78779.11000000","0.02834000"],["78782.25000000","0.02507000"],["78783.07000000","0.00000000"],["78783.35000000","0.00000000"],["78784.18000000","0.00000000"],["78784.45000000","0.00000000"],["78785.46000000","0.00000000"],["78785.80000000","0.00000000"],["78786.50000000","0.00000000"],["78788.42000000","0.00000000"],["78789.33000000","0.00000000"],["78789.60000000","0.00000000"],["78789.98000000","0.00000000"],["78792.00000000","0.02407000"],["78795.94000000","0.00000000"],["78796.00000000","0.02400000"],["78796.38000000","0.00316000"],["78799.10000000","0.86718000"],["78799.36000000","0.00000000"],["78799.73000000","0.88660000"],["78800.32000000","0.01151000"],["78800.70000000","0.31621000"],["78802.67000000","0.51293000"],["78806.94000000","0.00000000"],["78809.43000000","0.00000000"],["78810.58000000","0.00000000"],["78813.39000000","0.00000000"],["78813.97000000","0.00000000"],["78814.27000000","0.00000000"],["78818.33000000","0.00317000"],["78819.95000000","0.00000000"],["78821.77000000","0.00008000"],["78821.86000000","0.00000000"],["78823.58000000","0.00000000"],["78827.97000000","0.00000000"],["78828.81000000","0.00000000"],["78851.58000000","0.00000000"],["78853.87000000","0.00000000"],["78854.51000000","0.02789000"],["78855.09000000","0.00000000"],["78862.63000000","0.00000000"],["78868.77000000","0.00000000"],["78871.16000000","0.00000000"],["78872.96000000","0.00000000"],["78874.87000000","0.00000000"],["78880.40000000","0.00000000"],["78902.36000000","0.00000000"],["78955.39000000","2.62348000"],["78973.27000000","0.00000000"],["78978.94000000","0.00000000"],["78982.10000000","0.00000000"],["78989.54000000","0.00000000"],["79011.79000000","0.00000000"]]}}
{"rx_ns": 2890346800, "frame": {"e":"depthUpdate","E":1787603060314,"s":"BTCUSDT","U":99076615388,"u":99076616261,"b":[["78746.00000000","0.00000000"],["78745.99000000","0.00000000"],["78745.23000000","0.00000000"],["78745.22000000","0.00000000"],["78745.21000000","0.00000000"],["78745.20000000","0.00000000"],["78744.93000000","0.00000000"],["78744.60000000","0.00000000"],["78744.01000000","0.00000000"],["78744.00000000","0.00000000"],["78743.99000000","0.00000000"],["78743.97000000","0.00000000"],["78743.96000000","0.00000000"],["78743.48000000","0.00000000"],["78743.13000000","0.00000000"],["78743.12000000","0.00000000"],["78743.00000000","0.00000000"],["78742.89000000","0.00000000"],["78742.71000000","0.00000000"],["78742.70000000","0.00000000"],["78742.45000000","0.00000000"],["78742.43000000","0.00000000"],["78742.35000000","0.00000000"],["78742.34000000","0.00000000"],["78742.14000000","0.00000000"],["78742.12000000","0.00000000"],["78742.01000000","0.00000000"],["78742.00000000","0.02115000"],["78741.99000000","0.00042000"],["78741.13000000","0.00014000"],["78741.12000000","0.00000000"],["78740.99000000","0.00000000"],["78740.96000000","0.00000000"],["78740.50000000","0.00000000"],["78740.20000000","0.00000000"],["78740.01000000","0.00014000"],["78740.00000000","0.02407000"],["78739.85000000","0.00000000"],["78739.37000000","0.00000000"],["78739.21000000","0.00000000"],["78739.12000000","0.04854000"],["78738.01000000","0.00014000"],["78738.00000000","0.02407000"],["78736.77000000","0.00007000"],["78736.38000000","0.00000000"],["78736.34000000","0.00000000"],["78736.01000000","0.00014000"],["78736.00000000","0.02614000"],["78735.57000000","0.00000000"],["78735.24000000","0.00000000"],["78735.16000000","0.00007000"],["78734.32000000","0.00000000"],["78734.14000000","0.12707000"],["78734.10000000","0.00000000"],["78733.73000000","0.00007000"],["78733.39000000","0.00000000"],["78733.34000000","0.00000000"],["78733.30000000","0.00000000"],["78733.08000000","0.00000000"],["78733.06000000","0.00000000"],["78732.93000000","0.00000000"],["78732.85000000","0.00329000"],["78731.68000000","0.08576000"],["78731.63000000","0.00000000"],["78731.36000000","0.00000000"],["78731.28000000","0.21162000"],["78731.18000000","0.00204000"],["78729.85000000","0.00048000"],["78729.76000000","0.00007000"],["78729.20000000","0.50488000"],["78728.32000000","0.00000000"],["78727.68000000","0.00800000"],["78727.28000000","0.06000000"],["78726.52000000","0.02200000"],["78726.13000000","0.00188000"],["78725.98000000","0.00000000"],["78725.61000000","0.00000000"],["78725.51000000","0.00320000"],["78723.64000000","0.00000000"],["78723.43000000","0.00000000"],["78722.93000000","0.02000000"],["78722.67000000","0.00000000"],["78721.86000000","0.00253000"],["78720.00000000","0.02424000"],["78719.88000000","0.08000000"],["78718.52000000","0.00000000"],["78717.63000000","0.00331000"],["78717.34000000","0.02286000"],["78714.47000000","0.00190000"],["78711.70000000","0.00059000"],["78710.40000000","0.00012000"],["78709.75000000","0.00321000"],["78709.34000000","0.34307000"],["78706.83000000","0.00000000"],["78706.00000000","0.02400000"],["78705.97000000","0.00000000"],["78705.50000000","0.00000000"],["78705.48000000","0.63535000"],["78705.30000000","0.00000000"],["78705.00000000","0.00000000"],["78704.57000000","0.00000000"],["78704.53000000","0.99297000"],["78704.19000000","0.00014000"],["78704.17000000","0.00000000"],["78704.00000000","0.02400000"],["78702.36000000","0.34310000"],["78702.00000000","0.39624000"],["78701.87000000","0.00321000"],["78701.58000000","0.68285000"],["78696.40000000","0.00000000"],["78695.76000000","0.00000000"],["78695.61000000","0.00000000"],["78695.06000000","0.00000000"],["78694.96000000","0.00000000"],["78694.79000000","0.00000000"],["78694.51000000","0.00000000"],["78694.44000000","0.00000000"],["78694.27000000","0.00000000"],["78693.87000000","0.00000000"],["78693.72000000","0.00000000"],["78693.64000000","0.00000000"],["78693.30000000","0.00000000"],["78693.17000000","0.00000000"],["78693.07000000","0.00000000"],["78692.90000000","0.00000000"],["78692.58000000","0.00007000"],["78692.44000000","0.00000000"],["78692.25000000","0.00000000"],["78691.75000000","0.00000000"],["78691.41000000","0.00000000"],["78690.79000000","0.00000000"],["78690.40000000","0.00400000"],["78688.19000000","0.88785000"],["78687.01000000","0.00000000"],["78682.01000000","0.00314000"],["78679.26000000","0.00000000"],["78678.47000000","0.00427000"],["78675.35000000","0.00000000"],["78674.02000000","0.00000000"],["78670.58000000","1.25855000"],["78668.06000000","0.00000000"],["78666.01000000","0.00000000"],["78664.45000000","0.02000000"],["78660.27000000","0.00313000"],["78618.29000000","0.08531000"],["78547.44000000","0.00007000"],["78543.05000000","3.81999000"],["78535.65000000","0.00007000"],["78452.95000000","0.00000000"],["78437.41000000","0.00000000"],["78413.77000000","0.00033000"],["78403.41000000","1.76683000"],["70882.19000000","0.00032000"],["70869.60000000","0.00000000"],["70867.80000000","0.00016000"],["63006.00000000","0.09804000"]],"a":[["78742.01000000","1.77806000"],["78742.02000000","0.00020000"],["78742.03000000","0.00013000"],["78742.35000000","0.00000000"],["78742.48000000","0.00400000"],["78742.71000000","0.00000000"],["78742.89000000","0.00014000"],["78743.01000000","0.00000000"],["78743.13000000","0.01350000"],["78743.14000000","0.00000000"],["78743.97000000","0.00007000"],["78743.98000000","0.00000000"],["78744.00000000","0.45142000"],["78744.01000000","0.30852000"],["78744.02000000","0.00000000"],["78744.03000000","0.00000000"],["78744.61000000","0.00000000"],["78744.63000000","0.05307000"],["78744.94000000","0.00007000"],["78744.96000000","0.00400000"],["78745.20000000","0.00014000"],["78745.21000000","0.07514000"],["78745.22000000","0.47547000"],["78745.23000000","0.51676000"],["78745.24000000","0.00000000"],["78745.25000000","0.00000000"],["78745.99000000","0.00000000"],["78746.00000000","0.02336000"],["78746.01000000","0.36079000"],["78746.02000000","0.20033000"],["78746.03000000","0.00000000"],["78746.63000000","0.00000000"],["78747.10000000","1.21952000"],["78747.11000000","0.33476000"],["78747.14000000","0.00007000"],["78747.76000000","0.00000000"],["78747.85000000","0.00000000"],["78747.90000000","0.00008000"],["78747.98000000","0.03658000"],["78748.01000000","0.00000000"],["78748.33000000","0.00000000"],["78748.62000000","0.00000000"],["78748.63000000","0.00000000"],["78748.83000000","0.00000000"],["78749.02000000","0.00000000"],["78750.01000000","0.00000000"],["78750.28000000","0.00000000"],["78750.63000000","0.00014000"],["78750.64000000","0.21937000"],["78750.82000000","0.00000000"],["78751.16000000","3.31750000"],["78751.17000000","0.21375000"],["78751.54000000","0.00000000"],["78751.83000000","0.00007000"],["78752.00000000","0.00000000"],["78752.01000000","0.00353000"],["78752.40000000","0.00400000"],["78753.33000000","0.00000000"],["78753.83000000","0.00007000"],["78754.00000000","0.00000000"],["78754.01000000","0.00664000"],["78755.20000000","0.00000000"],["78756.00000000","0.00000000"],["78756.46000000","0.04036000"],["78757.32000000","0.34286000"],["78758.00000000","0.03320000"],["78758.45000000","0.00010000"],["78758.72000000","0.04857000"],["78759.05000000","0.21930000"],["78759.76000000","0.10314000"],["78760.77000000","0.00327000"],["78761.01000000","0.00000000"],["78761.28000000","0.00000000"],["78761.76000000","0.00000000"],["78762.11000000","0.02514000"],["78762.75000000","0.06585000"],["78762.78000000","0.00000000"],["78764.72000000","0.07608000"],["78765.26000000","0.12695000"],["78766.89000000","0.00060000"],["78766.97000000","0.00000000"],["78767.20000000","0.02600000"],["78767.54000000","0.09356000"],["78768.24000000","0.00126000"],["78768.94000000","0.00000000"],["78769.87000000","0.00190000"],["78776.13000000","0.00000000"],["78776.78000000","0.00000000"],["78777.41000000","0.02334000"],["78779.00000000","0.00429000"],["78779.45000000","0.00000000"],["78780.01000000","0.00000000"],["78780.79000000","0.00629000"],["78780.84000000","0.00000000"],["78781.58000000","0.00000000"],["78781.59000000","0.00000000"],["78782.12000000","0.68215000"],["78782.49000000","0.00014000"],["78782.62000000","0.00000000"],["78784.20000000","0.00000000"],["78784.23000000","0.00424000"],["78784.29000000","0.00000000"],["78785.34000000","1.25672000"],["78785.50000000","0.00427000"],["78786.00000000","0.02407000"],["78787.34000000","0.01157000"],["78789.22000000","0.00000000"],["78790.00000000","0.72400000"],["78790.80000000","0.00000000"],["78791.00000000","0.00000000"],["78791.98000000","0.00000000"],["78792.24000000","0.00000000"],["78795.10000000","0.00000000"],["78795.40000000","0.00000000"],["78795.55000000","0.00634000"],["78795.69000000","0.00000000"],["78796.39000000","0.00000000"],["78799.10000000","0.00000000"],["78803.73000000","1.90515000"],["78804.56000000","0.00111000"],["78805.22000000","0.00532000"],["78806.56000000","0.00000000"],["78806.61000000","0.00000000"],["78807.18000000","0.01693000"],["78808.53000000","0.00000000"],["78810.08000000","0.00000000"],["78818.53000000","0.00000000"],["78819.93000000","0.00000000"],["78819.95000000","0.21930000"],["78821.88000000","0.00000000"],["78827.83000000","0.00000000"],["78843.25000000","0.04641000"],["78976.83000000","0.00000000"],["78999.84000000","0.00145000"],["79119.97000000","0.54998000"],["79151.79000000","0.00000000"],["79158.14000000","0.00000000"],["79547.55000000","0.00000000"],["79945.29000000","0.00000000"],["80345.02000000","0.00000000"],["80746.74000000","0.00000000"],["81150.48000000","0.00000000"],["81556.23000000","0.00000000"],["81964.01000000","0.00000000"],["82373.83000000","0.00000000"],["82785.70000000","0.00000000"],["83199.63000000","0.00000000"],["83615.63000000","0.00000000"],["84033.70000000","0.00000000"],["84453.87000000","0.00000000"],["84876.14000000","0.00000000"]]}}
{"rx_ns": 2956851900, "frame": {"e":"depthUpdate","E":1787603060414,"s":"BTCUSDT","U":99076616262,"u":99076616655,"b":[["78742.00000000","0.00000000"],["78741.99000000","0.00000000"],["78741.22000000","0.00000000"],["78741.21000000","0.01987000"],["78741.20000000","0.00035000"],["78741.13000000","0.00000000"],["78740.00000000","0.02407000"],["78739.96000000","0.00014000"],["78739.95000000","0.03133000"],["78739.13000000","0.00000000"],["78739.12000000","0.00007000"],["78738.70000000","0.00014000"],["78738.69000000","0.03760000"],["78738.34000000","0.00014000"],["78738.33000000","0.04854000"],["78738.00000000","0.02407000"],["78737.43000000","0.03760000"],["78736.77000000","0.00000000"],["78736.01000000","0.00000000"],["78735.16000000","0.00000000"],["78735.15000000","0.00014000"],["78734.66000000","0.00000000"],["78734.15000000","0.00000000"],["78734.14000000","0.12721000"],["78734.00000000","0.02407000"],["78733.10000000","0.00000000"],["78732.85000000","0.00000000"],["78732.84000000","0.00000000"],["78732.72000000","0.00327000"],["78732.69000000","0.00000000"],["78732.56000000","0.00007000"],["78731.68000000","0.00000000"],["78731.29000000","0.00000000"],["78731.28000000","0.00014000"],["78731.27000000","0.00000000"],["78731.18000000","0.00102000"],["78731.15000000","0.00324000"],["78730.04000000","0.00007000"],["78729.91000000","0.00000000"],["78729.75000000","0.00102000"],["78729.24000000","0.08576000"],["78729.20000000","0.00000000"],["78728.68000000","0.31758000"],["78727.68000000","0.00400000"],["78727.12000000","0.00400000"],["78726.52000000","0.00000000"],["78726.08000000","0.00000000"],["78724.90000000","0.00152000"],["78724.72000000","0.00007000"],["78724.38000000","0.02000000"],["78724.09000000","0.00000000"],["78722.93000000","0.00000000"],["78722.03000000","0.01200000"],["78721.86000000","0.00000000"],["78720.87000000","0.00253000"],["78719.04000000","0.00000000"],["78718.45000000","0.00000000"],["78718.33000000","0.00007000"],["78717.47000000","0.00000000"],["78716.39000000","0.06589000"],["78714.42000000","0.07613000"],["78712.31000000","0.13241000"],["78703.77000000","0.00000000"],["78703.10000000","0.00000000"],["78702.00000000","0.38624000"],["78701.00000000","0.01000000"],["78692.96000000","0.00000000"],["78692.39000000","0.00000000"],["78691.07000000","0.00000000"],["78690.50000000","0.00000000"],["78687.92000000","0.00400000"],["78685.36000000","0.00000000"],["78679.53000000","0.00619000"],["78675.85000000","0.00000000"],["78664.45000000","0.00000000"],["78659.01000000","0.01740000"],["78658.74000000","0.00543000"],["78657.85000000","0.00112000"],["78619.95000000","0.00406000"],["78618.29000000","0.00000000"],["78617.34000000","0.00000000"],["78617.07000000","0.00000000"],["78605.54000000","0.00000000"],["78593.44000000","0.00000000"],["78578.37000000","1.52082000"],["78423.60000000","0.21930000"],["70876.00000000","0.00000000"],["70867.80000000","0.00000000"]],"a":[["78741.22000000","2.11748000"],["78741.23000000","0.00020000"],["78741.24000000","0.00013000"],["78741.99000000","0.00014000"],["78742.00000000","0.47438000"],["78742.01000000","0.00956000"],["78742.02000000","0.00000000"],["78742.03000000","0.00000000"],["78742.48000000","0.00400000"],["78742.49000000","0.01929000"],["78743.12000000","0.00000000"],["78743.13000000","0.01357000"],["78743.74000000","0.00014000"],["78743.75000000","0.03216000"],["78743.83000000","0.00014000"],["78743.84000000","0.05307000"],["78743.97000000","0.00000000"],["78743.99000000","0.00000000"],["78744.00000000","0.07528000"],["78744.01000000","0.24625000"],["78744.62000000","0.00027000"],["78744.63000000","0.00007000"],["78745.01000000","0.03859000"],["78745.19000000","0.00000000"],["78745.20000000","1.90515000"],["78745.21000000","0.07507000"],["78745.22000000","0.40033000"],["78745.23000000","0.51676000"],["78745.99000000","0.00000000"],["78746.00000000","0.02161000"],["78746.01000000","0.35572000"],["78746.02000000","0.20026000"],["78746.27000000","0.03859000"],["78747.09000000","0.36224000"],["78747.11000000","0.33469000"],["78747.14000000","0.00000000"],["78752.01000000","0.00007000"],["78752.02000000","0.00000000"],["78753.84000000","0.00000000"],["78754.01000000","0.00657000"],["78756.27000000","0.04857000"],["78756.97000000","0.11010000"],["78757.08000000","0.00000000"],["78757.76000000","0.00000000"],["78758.10000000","0.06585000"],["78758.72000000","0.00000000"],["78758.90000000","0.00007000"],["78759.76000000","0.00000000"],["78760.07000000","0.07609000"],["78760.77000000","0.00000000"],["78762.75000000","0.00000000"],["78764.72000000","0.00000000"],["78765.59000000","0.00007000"],["78769.72000000","0.39818000"],["78773.18000000","0.02000000"],["78777.83000000","0.00000000"],["78782.00000000","0.03400000"],["78785.00000000","0.00000000"],["78803.73000000","0.00000000"],["78804.24000000","0.91101000"],["78819.02000000","0.00000000"],["78830.69000000","0.00529000"],["78842.53000000","0.02801000"],["78854.51000000","0.00000000"],["78855.78000000","0.00012000"],["78861.92000000","0.00019000"],["78868.02000000","0.00031000"],["78877.53000000","1.52082000"],["78892.66000000","0.00000000"],["78972.90000000","0.00000000"]]}}
{"rx_ns": 3055826000, "frame": {"e":"depthUpdate","E":1787603060514,"s":"BTCUSDT","U":99076616656,"u":99076617599,"b":[["78741.21000000","0.00000000"],["78741.20000000","0.00000000"],["78740.72000000","0.00000000"],["78740.01000000","0.00000000"],["78740.00000000","0.00000000"],["78739.99000000","0.00000000"],["78739.96000000","0.00000000"],["78739.95000000","0.00000000"],["78739.16000000","0.00000000"],["78739.12000000","0.00000000"],["78739.02000000","0.00000000"],["78738.91000000","0.00000000"],["78738.70000000","0.00000000"],["78738.69000000","0.00000000"],["78738.68000000","0.00000000"],["78738.34000000","0.00000000"],["78738.33000000","0.00000000"],["78738.06000000","0.00379000"],["78738.05000000","0.00055000"],["78738.04000000","0.00013000"],["78738.00000000","0.02407000"],["78737.44000000","0.00014000"],["78737.43000000","0.03767000"],["78737.13000000","0.00000000"],["78737.12000000","0.00000000"],["78736.86000000","0.00000000"],["78736.28000000","0.00000000"],["78736.06000000","0.00000000"],["78736.01000000","0.00014000"],["78736.00000000","0.02614000"],["78735.81000000","0.00000000"],["78735.18000000","0.04849000"],["78735.15000000","0.00007000"],["78734.25000000","0.00010000"],["78734.16000000","0.00000000"],["78734.15000000","0.00000000"],["78734.14000000","0.00021000"],["78734.01000000","0.00014000"],["78734.00000000","0.02407000"],["78733.76000000","0.00000000"],["78733.66000000","0.00000000"],["78733.31000000","0.00000000"],["78732.72000000","0.00000000"],["78732.56000000","0.00000000"],["78732.50000000","0.00000000"],["78732.01000000","0.00007000"],["78732.00000000","0.02407000"],["78731.99000000","0.00749000"],["78731.77000000","0.00000000"],["78731.18000000","0.00000000"],["78731.15000000","0.00000000"],["78730.92000000","0.00000000"],["78730.91000000","0.00000000"],["78730.41000000","0.00000000"],["78729.76000000","0.12708000"],["78729.75000000","0.00000000"],["78729.64000000","0.00000000"],["78729.24000000","0.00000000"],["78728.77000000","0.00000000"],["78728.68000000","0.31765000"],["78728.31000000","0.00104000"],["78727.78000000","0.00000000"],["78727.69000000","0.00000000"],["78727.68000000","0.00000000"],["78727.57000000","0.00000000"],["78727.56000000","0.00000000"],["78727.50000000","0.00000000"],["78727.41000000","0.00007000"],["78727.33000000","0.00000000"],["78727.31000000","0.20829000"],["78727.28000000","0.00000000"],["78727.12000000","0.00000000"],["78726.76000000","1.90515000"],["78726.75000000","0.00000000"],["78726.69000000","0.00000000"],["78726.68000000","0.00204000"],["78726.61000000","0.00007000"],["78725.94000000","0.00328000"],["78725.82000000","0.08576000"],["78725.31000000","0.00000000"],["78724.66000000","0.00000000"],["78724.65000000","0.00000000"],["78724.64000000","0.00000000"],["78724.53000000","0.00000000"],["78724.38000000","0.00000000"],["78723.98000000","0.00000000"],["78723.63000000","0.00323000"],["78723.31000000","0.00000000"],["78722.75000000","0.00000000"],["78722.48000000","0.00000000"],["78722.03000000","0.00000000"],["78721.20000000","0.00000000"],["78720.98000000","0.00000000"],["78720.87000000","0.00000000"],["78720.62000000","0.00000000"],["78720.18000000","0.01000000"],["78719.93000000","0.00000000"],["78719.88000000","0.00000000"],["78719.78000000","0.02000000"],["78719.69000000","0.00324000"],["78719.18000000","0.00000000"],["78718.91000000","0.13234000"],["78718.70000000","0.02514000"],["78718.52000000","0.00400000"],["78718.48000000","0.04000000"],["78718.34000000","0.00000000"],["78718.28000000","0.00000000"],["78718.23000000","0.00000000"],["78718.18000000","0.36224000"],["78718.02000000","0.00000000"],["78717.95000000","0.00000000"],["78717.29000000","0.00253000"],["78716.58000000","0.02000000"],["78716.40000000","0.00000000"],["78716.08000000","0.00000000"],["78715.78000000","0.00000000"],["78715.75000000","0.00318000"],["78714.18000000","0.08000000"],["78711.81000000","0.00326000"],["78711.75000000","0.00000000"],["78710.04000000","0.36224000"],["78709.90000000","0.00000000"],["78709.34000000","0.00000000"],["78709.11000000","0.00000000"],["78705.48000000","0.00000000"],["78704.53000000","0.00000000"],["78702.93000000","0.00000000"],["78702.50000000","0.00000000"],["78701.70000000","0.00008000"],["78701.43000000","0.00000000"],["78701.00000000","0.00000000"],["78700.32000000","0.00414000"],["78700.00000000","0.11937000"],["78699.81000000","0.04636000"],["78699.00000000","0.00000000"],["78698.72000000","0.00000000"],["78698.51000000","0.02000000"],["78698.00000000","0.03400000"],["78697.62000000","0.00000000"],["78692.20000000","0.00000000"],["78691.77000000","0.00000000"],["78691.37000000","0.00000000"],["78690.69000000","0.00000000"],["78690.46000000","0.00000000"],["78690.31000000","0.00000000"],["78689.88000000","0.00000000"],["78689.48000000","0.00000000"],["78689.22000000","0.00000000"],["78689.00000000","0.00000000"],["78688.80000000","0.00000000"],["78688.71000000","0.00007000"],["78688.57000000","0.00000000"],["78688.27000000","0.00000000"],["78687.95000000","0.00000000"],["78687.33000000","0.00000000"],["78687.19000000","0.00000000"],["78687.15000000","0.00000000"],["78685.37000000","0.00000000"],["78685.26000000","0.00000000"],["78683.58000000","0.00400000"],["78682.01000000","0.00000000"],["78680.79000000","0.00400000"],["78676.50000000","0.00316000"],["78667.96000000","0.86863000"],["78660.27000000","0.00000000"],["78659.39000000","1.89811000"],["78654.56000000","0.00315000"],["78645.09000000","1.90515000"],["78632.08000000","0.00007000"],["78627.52000000","2.14236000"],["78612.33000000","0.80000000"],["78606.35000000","0.04091000"],["78592.01000000","0.01989000"],["78538.29000000","0.00007000"],["78530.43000000","0.00007000"],["78413.77000000","0.00000000"],["70867.09000000","0.00000000"],["70867.00000000","0.00022000"],["62992.97000000","0.00000000"],["62990.45000000","0.00031000"]],"a":[["78738.07000000","2.25768000"],["78738.08000000","0.00020000"],["78738.09000000","0.00013000"],["78738.32000000","0.00014000"],["78738.33000000","0.00021000"],["78738.34000000","0.00014000"],["78738.35000000","0.14825000"],["78738.36000000","0.00000000"],["78738.68000000","0.00014000"],["78738.69000000","0.07514000"],["78738.70000000","0.77582000"],["78738.71000000","0.05259000"],["78738.72000000","0.00000000"],["78738.92000000","0.00000000"],["78739.01000000","0.00000000"],["78739.02000000","0.00014000"],["78739.03000000","0.00007000"],["78739.13000000","0.00000000"],["78739.16000000","0.00000000"],["78739.17000000","0.11069000"],["78739.18000000","0.00000000"],["78739.95000000","0.00000000"],["78739.96000000","0.00021000"],["78739.97000000","0.00000000"],["78739.98000000","0.00000000"],["78740.00000000","0.07500000"],["78740.01000000","0.32731000"],["78740.02000000","0.00014000"],["78740.03000000","0.00000000"],["78740.20000000","0.00008000"],["78740.69000000","0.05312000"],["78740.72000000","0.00000000"],["78740.73000000","0.00007000"],["78741.20000000","0.00000000"],["78741.21000000","0.07675000"],["78741.22000000","0.46084000"],["78741.23000000","0.00000000"],["78741.24000000","0.00000000"],["78741.32000000","0.00000000"],["78741.79000000","0.00000000"],["78741.94000000","0.00000000"],["78741.95000000","0.02000000"],["78741.99000000","0.00000000"],["78742.00000000","0.02175000"],["78742.01000000","0.00345000"],["78742.48000000","0.00400000"],["78742.49000000","0.01929000"],["78742.62000000","0.00000000"],["78742.63000000","0.00000000"],["78743.00000000","0.00007000"],["78743.13000000","0.01350000"],["78743.74000000","0.00000000"],["78743.75000000","0.03216000"],["78743.83000000","0.00000000"],["78743.84000000","0.00000000"],["78743.99000000","0.00000000"],["78744.00000000","0.00007000"],["78744.01000000","0.24604000"],["78744.63000000","0.00000000"],["78745.21000000","0.00000000"],["78745.22000000","0.02996000"],["78745.23000000","0.06229000"],["78745.51000000","0.12699000"],["78745.99000000","0.00000000"],["78746.01000000","0.08899000"],["78746.02000000","0.20026000"],["78746.31000000","0.25395000"],["78747.08000000","0.36224000"],["78747.09000000","0.00000000"],["78747.11000000","0.00007000"],["78747.89000000","0.00007000"],["78747.98000000","0.00651000"],["78748.48000000","0.00007000"],["78748.68000000","0.00007000"],["78748.84000000","0.34290000"],["78749.73000000","0.00000000"],["78750.00000000","0.09531000"],["78750.25000000","0.00000000"],["78750.64000000","0.00000000"],["78751.16000000","3.12467000"],["78751.17000000","0.00340000"],["78752.01000000","0.00000000"],["78752.11000000","0.63497000"],["78752.85000000","0.04857000"],["78753.83000000","0.00000000"],["78755.76000000","0.11348000"],["78756.27000000","0.00000000"],["78756.97000000","0.00000000"],["78758.00000000","0.03000000"],["78758.13000000","0.00000000"],["78761.53000000","0.00012000"],["78763.48000000","0.00000000"],["78763.91000000","0.00000000"],["78765.26000000","0.00000000"],["78770.17000000","0.00000000"],["78777.72000000","0.00000000"],["78781.00000000","0.01000000"],["78781.71000000","0.00000000"],["78782.00000000","0.02400000"],["78782.25000000","0.00000000"],["78783.22000000","0.00000000"],["78786.31000000","0.00000000"],["78787.79000000","0.86731000"],["78802.26000000","0.00000000"],["78804.44000000","0.00000000"],["78827.83000000","0.21930000"],["78828.27000000","2.13690000"],["78834.79000000","3.41916000"],["78835.71000000","0.21930000"],["78868.43000000","0.00000000"],["78870.01000000","0.00000000"],["78893.00000000","0.03189000"],["78933.51000000","0.00000000"],["78963.79000000","0.00000000"],["78964.04000000","0.00007000"],["78967.72000000","0.00000000"],["78970.22000000","0.00000000"],["79002.00000000","0.00008000"],["82674.06000000","0.00000000"],["82677.01000000","0.00010000"]]}}
{"rx_ns": 3157937200, "frame": {"e":"depthUpdate","E":1787603060614,"s":"BTCUSDT","U":99076617600,"u":99076617861,"b":[["78738.06000000","0.00000000"],["78738.05000000","0.00000000"],["78738.04000000","0.00000000"],["78738.01000000","0.00000000"],["78738.00000000","0.02485000"],["78737.99000000","0.00041000"],["78737.98000000","0.00013000"],["78737.97000000","0.00007000"],["78737.44000000","0.00000000"],["78737.43000000","0.00007000"],["78736.00000000","0.02607000"],["78735.19000000","0.00014000"],["78735.18000000","0.04856000"],["78734.14000000","0.00007000"],["78733.86000000","0.00027000"],["78732.01000000","0.00014000"],["78732.00000000","0.02407000"],["78731.99000000","0.00756000"],["78730.01000000","0.00007000"],["78730.00000000","0.02407000"],["78729.76000000","0.12715000"],["78726.12000000","0.00000000"],["78718.74000000","0.00400000"],["78716.39000000","0.00000000"],["78715.00000000","0.00007000"],["78714.42000000","0.00000000"],["78712.31000000","0.00000000"],["78711.19000000","0.00253000"],["78705.45000000","0.13242000"],["78701.58000000","0.00000000"],["78697.58000000","0.00000000"],["78686.80000000","0.00000000"],["78686.49000000","0.00000000"],["78686.06000000","0.02816000"],["78684.91000000","0.00000000"],["78684.60000000","0.00000000"],["78684.51000000","0.00000000"],["78683.48000000","0.00000000"],["78675.21000000","0.00400000"],["78672.15000000","0.00724000"],["78670.81000000","0.00430000"],["78665.45000000","0.91262000"],["78606.35000000","0.00000000"],["78602.98000000","0.08808000"],["78592.01000000","0.00000000"],["78577.31000000","0.01989000"],["78549.28000000","0.00000000"],["78530.43000000","0.00000000"],["78402.91000000","0.00032000"],["70867.00000000","0.00012000"],["70864.20000000","0.00016000"],["70864.00000000","0.00010000"],["62990.45000000","0.00000000"],["41465.30000000","0.00036000"]],"a":[["78738.01000000","4.08661000"],["78738.02000000","0.00020000"],["78738.03000000","0.00013000"],["78738.05000000","0.00000000"],["78738.06000000","0.00014000"],["78738.07000000","0.58962000"],["78738.08000000","0.00000000"],["78738.09000000","0.00000000"],["78738.32000000","0.00000000"],["78738.33000000","0.00007000"],["78738.34000000","0.00021000"],["78738.35000000","0.14846000"],["78738.68000000","0.36238000"],["78738.69000000","0.07521000"],["78738.70000000","0.77534000"],["78738.71000000","0.05266000"],["78739.16000000","0.00000000"],["78739.17000000","0.11069000"],["78739.96000000","0.00670000"],["78740.00000000","0.07507000"],["78740.01000000","0.05808000"],["78740.02000000","0.00007000"],["78740.73000000","0.00000000"],["78741.21000000","0.00000000"],["78741.22000000","0.07024000"],["78742.00000000","0.02168000"],["78742.01000000","0.00338000"],["78742.49000000","0.00000000"],["78743.37000000","0.00162000"],["78743.75000000","0.00000000"],["78745.01000000","0.00000000"],["78746.01000000","0.00336000"],["78746.02000000","0.20019000"],["78746.27000000","0.00000000"],["78747.11000000","0.00000000"],["78751.18000000","0.00007000"],["78751.52000000","0.00000000"],["78753.76000000","0.09992000"],["78753.81000000","0.06586000"],["78754.01000000","0.00328000"],["78755.76000000","0.00000000"],["78755.78000000","0.07609000"],["78758.10000000","0.00000000"],["78760.07000000","0.00000000"],["78767.54000000","0.00000000"],["78768.09000000","0.00000000"],["78773.17000000","0.68223000"],["78773.43000000","0.02498000"],["78778.00000000","0.03407000"],["78780.00000000","0.02400000"],["78781.00000000","0.00000000"],["78782.12000000","0.00000000"],["78786.56000000","0.88675000"],["78799.73000000","0.00000000"],["78802.39000000","0.00000000"],["78806.00000000","0.02400000"],["78813.67000000","0.09284000"],["78819.11000000","0.00405000"],["78830.72000000","0.00000000"],["78835.71000000","0.00000000"],["78839.15000000","0.02789000"],["78842.53000000","0.00012000"],["78957.71000000","0.00000000"],["78967.91000000","0.00007000"],["78971.84000000","0.00000000"],["78999.84000000","0.00108000"]]}}
{"rx_ns": 3253691100, "frame": {"e":"depthUpdate","E":1787603060714,"s":"BTCUSDT","U":99076617862,"u":99076618132,"b":[["78738.00000000","0.00000000"],["78737.99000000","0.00000000"],["78737.98000000","0.00000000"],["78737.97000000","0.00000000"],["78737.43000000","0.00000000"],["78736.84000000","0.00000000"],["78736.52000000","0.00000000"],["78736.31000000","0.00000000"],["78736.01000000","0.00000000"],["78736.00000000","0.02693000"],["78735.99000000","0.00056000"],["78735.19000000","0.00000000"],["78735.18000000","0.00007000"],["78734.82000000","0.00000000"],["78734.25000000","0.00000000"],["78734.20000000","0.00014000"],["78734.19000000","0.01715000"],["78733.86000000","0.00000000"],["78733.13000000","0.00014000"],["78733.12000000","0.04849000"],["78732.94000000","0.00014000"],["78732.93000000","0.02859000"],["78732.91000000","0.00000000"],["78732.77000000","0.00000000"],["78731.99000000","0.00007000"],["78731.67000000","0.03431000"],["78731.51000000","0.00000000"],["78730.41000000","0.03431000"],["78730.01000000","0.00000000"],["78729.77000000","0.00000000"],["78728.68000000","0.31765000"],["78728.00000000","0.02534000"],["78727.31000000","0.00007000"],["78726.68000000","0.00000000"],["78725.94000000","0.00000000"],["78725.82000000","0.00007000"],["78725.51000000","0.00000000"],["78724.99000000","0.00333000"],["78724.19000000","0.08780000"],["78723.91000000","0.20829000"],["78723.63000000","0.00000000"],["78723.46000000","0.00007000"],["78723.41000000","0.00329000"],["78719.78000000","0.00000000"],["78719.58000000","0.00000000"],["78718.91000000","0.00000000"],["78718.48000000","0.00000000"],["78717.30000000","0.00000000"],["78717.29000000","0.00000000"],["78716.08000000","0.02000000"],["78715.22000000","0.00000000"],["78714.18000000","0.12000000"],["78710.00000000","0.02400000"],["78707.03000000","0.53552000"],["78698.00000000","0.02400000"],["78696.00000000","0.04701000"],["78694.10000000","0.00000000"],["78693.84000000","0.00000000"],["78686.06000000","0.00000000"],["78685.45000000","0.00007000"],["78684.84000000","0.00007000"],["78684.17000000","0.00000000"],["78681.67000000","1.08420000"],["78681.47000000","0.02791000"],["78672.70000000","0.01135000"],["78662.95000000","0.00000000"],["78653.08000000","0.00000000"],["78628.87000000","2.77079000"],["78608.36000000","0.00000000"],["78581.19000000","0.00000000"],["78578.37000000","0.00000000"],["78576.92000000","0.09330000"],["78562.79000000","1.20000000"],["78530.71000000","0.00007000"],["78526.78000000","0.00000000"],["78516.33000000","0.00000000"],["78500.03000000","3.36997000"],["78473.79000000","0.00000000"],["70864.20000000","0.00000000"],["70864.00000000","0.00000000"]],"a":[["78736.01000000","2.10996000"],["78736.02000000","0.00020000"],["78736.03000000","0.00013000"],["78736.84000000","0.00014000"],["78736.85000000","0.12103000"],["78737.27000000","0.03490000"],["78737.44000000","0.00000000"],["78737.98000000","0.00000000"],["78737.99000000","0.00014000"],["78738.00000000","0.07514000"],["78738.01000000","1.36360000"],["78738.02000000","0.00000000"],["78738.03000000","0.00000000"],["78738.07000000","0.58462000"],["78738.34000000","0.00007000"],["78738.35000000","0.14853000"],["78738.53000000","0.04188000"],["78738.63000000","0.05312000"],["78738.68000000","0.36231000"],["78738.69000000","0.07507000"],["78738.70000000","0.34775000"],["78739.17000000","0.10765000"],["78739.79000000","0.04188000"],["78740.00000000","0.07500000"],["78740.01000000","0.05801000"],["78740.69000000","0.00000000"],["78744.01000000","0.02674000"],["78745.23000000","0.00014000"],["78745.53000000","0.00007000"],["78745.83000000","0.00007000"],["78746.01000000","0.00329000"],["78746.02000000","0.20012000"],["78746.58000000","0.21930000"],["78751.17000000","0.00333000"],["78751.22000000","0.04857000"],["78751.76000000","0.09334000"],["78752.85000000","0.00000000"],["78753.69000000","0.00007000"],["78753.76000000","0.00000000"],["78754.98000000","0.00000000"],["78758.00000000","0.05000000"],["78759.20000000","0.09800000"],["78777.41000000","0.00000000"],["78778.00000000","0.02407000"],["78787.48000000","0.02438000"],["78795.55000000","0.00000000"],["78842.61000000","0.00012000"],["78855.78000000","0.00000000"],["78861.92000000","0.00000000"],["78868.02000000","0.00000000"],["78877.53000000","0.00000000"],["78964.04000000","0.00000000"],["78967.91000000","0.00000000"],["78988.90000000","0.00037000"],["79006.29000000","2.50000000"],["79131.60000000","0.00000000"]]}}
{"rx_ns": 3362854300, "frame": {"e":"depthUpdate","E":1787603060823,"s":"BTCUSDT","U":99076618133,"u":99076618249,"b":[["78736.00000000","0.02700000"],["78735.99000000","0.00063000"],["78735.18000000","0.00000000"],["78734.19000000","0.01722000"],["78734.00000000","0.02407000"],["78733.12000000","0.04856000"],["78732.93000000","0.02866000"],["78732.00000000","0.02407000"],["78731.99000000","0.00000000"],["78731.67000000","0.03438000"],["78730.41000000","0.03438000"],["78729.76000000","0.12708000"],["78728.68000000","0.31758000"],["78728.00000000","0.02527000"],["78720.18000000","0.00000000"],["78719.55000000","0.00400000"],["78719.54000000","0.00000000"],["78719.08000000","0.00000000"],["78718.74000000","0.00000000"],["78718.70000000","0.00000000"],["78718.08000000","0.01000000"],["78716.18000000","0.02600000"],["78715.39000000","0.02800000"],["78715.34000000","0.02800000"],["78714.18000000","0.04000000"],["78711.28000000","0.08000000"],["78711.19000000","0.13501000"],["78707.03000000","0.00000000"],["78704.11000000","0.00000000"],["78703.39000000","0.00000000"],["78690.00000000","0.11932000"],["78676.80000000","0.02400000"],["78664.70000000","0.02600000"],["78664.08000000","0.02800000"],["78663.98000000","0.02800000"],["78656.34000000","3.36337000"],["78604.02000000","0.00000000"],["78593.74000000","0.00127000"],["78582.26000000","0.00000000"],["78573.49000000","0.00127000"],["78500.03000000","0.00000000"],["78489.70000000","0.09946000"],["78409.72000000","0.02743000"],["78342.32000000","0.01000000"],["77950.60000000","0.01000000"],["77560.85000000","0.01000000"],["77173.05000000","0.01000000"],["76787.18000000","0.01000000"],["76403.24000000","0.01000000"],["76021.23000000","0.01000000"],["75641.12000000","0.01000000"],["75262.92000000","0.01000000"],["74886.60000000","0.01000000"],["74512.17000000","0.01000000"],["74139.61000000","0.01000000"],["73768.91000000","0.01000000"],["73400.07000000","0.01000000"],["73033.07000000","0.01000000"],["70862.40000000","0.00016000"]],"a":[["78736.01000000","2.11503000"],["78736.85000000","0.12110000"],["78737.27000000","0.03497000"],["78738.00000000","0.07521000"],["78738.01000000","0.97658000"],["78738.07000000","0.36532000"],["78738.35000000","0.14853000"],["78738.53000000","0.04195000"],["78738.68000000","0.36224000"],["78738.69000000","0.07500000"],["78738.70000000","0.34768000"],["78738.71000000","0.05259000"],["78739.17000000","0.10758000"],["78742.82000000","0.02000000"],["78744.78000000","0.02000000"],["78745.23000000","0.00007000"],["78745.56000000","0.02000000"],["78745.57000000","0.02000000"],["78750.41000000","0.02514000"],["78762.11000000","0.00000000"],["78776.00000000","0.03400000"],["78785.27000000","0.00317000"],["78796.38000000","0.00000000"],["78806.94000000","0.00316000"],["78818.33000000","0.00000000"],["78835.71000000","0.21930000"],["78885.86000000","0.00127000"],["78897.89000000","0.00405000"],["78912.12000000","0.00000000"],["79129.70000000","0.01000000"],["79525.34000000","0.01000000"],["79922.97000000","0.01000000"],["80322.59000000","0.01000000"],["80724.20000000","0.01000000"],["81127.82000000","0.01000000"],["81533.46000000","0.01000000"],["81941.13000000","0.01000000"],["82350.83000000","0.01000000"],["82762.58000000","0.01000000"],["83176.40000000","0.01000000"],["83592.28000000","0.01000000"],["84010.24000000","0.01000000"],["84430.29000000","0.01000000"],["84852.44000000","0.01000000"]]}}
{"rx_ns": 3453355100, "frame": {"e":"depthUpdate","E":1787603060914,"s":"BTCUSDT","U":99076618250,"u":99076618287,"b":[["78732.47000000","0.00007000"],["78729.60000000","0.00723000"],["78721.59000000","0.02514000"],["78721.32000000","0.00007000"],["78715.42000000","0.02200000"],["78711.43000000","0.02000000"],["78703.49000000","0.00000000"],["78684.84000000","0.00000000"],["78673.67000000","0.02400000"],["78672.86000000","0.00335000"],["78672.09000000","0.02000000"],["78664.21000000","0.02200000"],["78664.08000000","0.00000000"],["78660.57000000","0.00000000"],["78528.94000000","0.00027000"],["78498.88000000","0.01989000"],["70862.40000000","0.00048000"],["55000.00000000","448.03987000"]],"a":[["78736.01000000","2.30302000"],["78738.01000000","0.75472000"],["78743.59000000","0.02000000"],["78744.60000000","0.00007000"],["78745.97000000","0.02000000"],["78747.53000000","0.02000000"],["78747.60000000","0.02000000"],["78767.88000000","0.00000000"],["78809.46000000","0.00000000"],["78847.24000000","0.00000000"],["78848.74000000","0.00019000"],["78854.84000000","0.00031000"]]}}
{"rx_ns": 3554286600, "frame": {"e":"depthUpdate","E":1787603061014,"s":"BTCUSDT","U":99076618288,"u":99076618338,"b":[["78730.62000000","0.00000000"],["78727.67000000","0.00000000"],["78724.72000000","0.00000000"],["78720.04000000","0.12703000"],["78719.58000000","0.00400000"],["78719.55000000","0.00000000"],["78711.50000000","0.02000000"],["78703.62000000","0.00000000"],["78701.49000000","0.00000000"],["78701.47000000","1.21904000"],["78700.36000000","0.00635000"],["78672.89000000","0.02000000"],["78672.03000000","0.02200000"],["78664.76000000","0.04761000"],["78664.21000000","0.00000000"],["78660.58000000","0.02000000"],["78568.76000000","0.00000000"],["78520.83000000","0.00778000"],["62988.80000000","0.00031000"]],"a":[["78736.01000000","3.01325000"],["78736.80000000","0.38092000"],["78739.01000000","0.00635000"],["78745.19000000","0.00227000"],["78745.22000000","0.02989000"],["78745.23000000","0.00000000"],["78746.31000000","0.00000000"],["78746.73000000","0.02000000"],["78747.55000000","0.02600000"],["78747.59000000","0.02000000"],["78751.53000000","0.12698000"],["78754.22000000","0.00007000"],["78755.27000000","0.43576000"],["78756.06000000","0.00000000"],["78760.21000000","0.00000000"],["78760.25000000","0.00000000"],["78766.03000000","0.00000000"],["78773.70000000","0.00000000"],["78829.21000000","0.00000000"],["78855.70000000","0.00000000"],["78968.80000000","0.00405000"]]}}
{"rx_ns": 3654609200, "frame": {"e":"depthUpdate","E":1787603061114,"s":"BTCUSDT","U":99076618339,"u":99076618397,"b":[["78736.00000000","0.01693000"],["78735.99000000","0.00056000"],["78731.28000000","0.00007000"],["78730.04000000","0.00000000"],["78729.85000000","0.00000000"],["78729.76000000","0.12715000"],["78729.60000000","0.00000000"],["78728.68000000","0.00000000"],["78727.31000000","0.00000000"],["78725.82000000","0.00000000"],["78724.68000000","0.00000000"],["78724.19000000","0.08787000"],["78721.59000000","0.00000000"],["78720.81000000","0.31761000"],["78720.32000000","0.00047000"],["78699.99000000","0.00000000"],["78699.98000000","0.00000000"],["78698.79000000","0.34311000"],["78698.38000000","0.54075000"],["78697.40000000","0.63541000"],["78694.65000000","0.34313000"],["78690.18000000","0.00000000"],["78687.61000000","0.00000000"],["78684.84000000","0.00007000"],["78679.59000000","1.25841000"],["78672.86000000","0.00000000"],["78667.18000000","1.25861000"],["78642.29000000","0.00000000"],["78620.13000000","0.04551000"],["78415.72000000","0.21930000"],["78027.38000000","0.00010000"],["70862.40000000","0.00080000"]],"a":[["78736.01000000","3.21369000"],["78736.79000000","0.00014000"],["78738.06000000","0.00000000"],["78743.16000000","0.02285000"],["78743.51000000","0.00253000"],["78744.01000000","0.02667000"],["78744.94000000","0.00000000"],["78746.02000000","0.00000000"],["78749.86000000","0.34289000"],["78757.98000000","0.02161000"],["78761.48000000","0.00000000"],["78762.08000000","0.00000000"],["78808.34000000","0.00000000"],["78827.47000000","0.02000000"],["78855.65000000","0.00000000"]]}}
{"rx_ns": 3753928800, "frame": {"e":"depthUpdate","E":1787603061214,"s":"BTCUSDT","U":99076618398,"u":99076618783,"b":[["78736.00000000","0.00000000"],["78735.99000000","0.00000000"],["78735.15000000","0.00000000"],["78734.20000000","0.00000000"],["78734.19000000","0.00000000"],["78734.18000000","0.00000000"],["78734.14000000","0.00000000"],["78734.04000000","0.00000000"],["78734.01000000","0.00000000"],["78734.00000000","0.02513000"],["78733.99000000","0.00055000"],["78733.98000000","0.00013000"],["78733.79000000","0.00000000"],["78733.13000000","0.00000000"],["78733.12000000","0.00007000"],["78732.94000000","0.00000000"],["78732.93000000","0.00007000"],["78731.68000000","0.00000000"],["78731.67000000","0.00007000"],["78731.32000000","0.00014000"],["78731.31000000","0.04849000"],["78730.42000000","0.00000000"],["78730.41000000","0.00007000"],["78730.01000000","0.00014000"],["78729.77000000","0.00014000"],["78729.76000000","0.12715000"],["78728.01000000","0.00007000"],["78728.00000000","0.02534000"],["78726.76000000","0.00000000"],["78726.13000000","0.00000000"],["78724.19000000","0.00007000"],["78723.91000000","0.00007000"],["78723.54000000","0.00007000"],["78722.87000000","0.08583000"],["78720.31000000","0.00007000"],["78717.57000000","0.02514000"],["78716.08000000","0.00000000"],["78715.08000000","0.02000000"],["78712.33000000","0.02400000"],["78710.61000000","0.12704000"],["78698.69000000","0.00406000"],["78696.45000000","0.00014000"],["78696.00000000","0.03701000"],["78694.00000000","0.03415000"],["78693.21000000","0.00000000"],["78693.11000000","0.00000000"],["78681.47000000","0.00000000"],["78681.19000000","0.00000000"],["78681.07000000","0.02779000"],["78674.46000000","0.00015000"],["78670.90000000","0.00008000"],["78662.41000000","0.00000000"],["78662.32000000","0.00000000"],["78659.93000000","0.00000000"],["78654.56000000","0.00000000"],["78650.13000000","0.00315000"],["78612.33000000","0.00000000"],["78609.62000000","0.80000000"],["78602.98000000","0.00000000"],["78533.15000000","0.00007000"],["78525.29000000","0.00000000"],["78342.32000000","0.00000000"],["77950.60000000","0.00000000"],["77560.85000000","0.00000000"],["77173.05000000","0.00000000"],["76787.18000000","0.00000000"],["76403.24000000","0.00000000"],["76021.23000000","0.00000000"],["75641.12000000","0.00000000"],["75262.92000000","0.00000000"],["74886.60000000","0.00000000"],["74512.17000000","0.00000000"],["74139.61000000","0.00000000"],["73768.91000000","0.00000000"],["73400.07000000","0.00000000"],["73033.07000000","0.00000000"],["70862.40000000","0.00009000"],["70862.00000000","0.00000000"],["70860.78000000","0.00011000"],["70860.60000000","0.00016000"],["62988.80000000","0.00000000"]],"a":[["78734.01000000","2.25557000"],["78734.02000000","0.07488000"],["78734.03000000","0.00013000"],["78734.15000000","0.00000000"],["78734.19000000","0.62876000"],["78734.20000000","0.98075000"],["78734.21000000","0.00000000"],["78734.22000000","0.00000000"],["78735.15000000","0.00014000"],["78735.16000000","0.00000000"],["78735.99000000","0.00014000"],["78736.00000000","0.07521000"],["78736.01000000","0.47717000"],["78736.02000000","0.00000000"],["78736.03000000","0.00000000"],["78736.80000000","0.38099000"],["78736.82000000","0.05313000"],["78736.84000000","0.00000000"],["78737.27000000","0.00007000"],["78737.99000000","0.00000000"],["78738.00000000","0.07514000"],["78738.35000000","0.14832000"],["78738.53000000","0.00000000"],["78738.63000000","0.00000000"],["78738.68000000","0.00000000"],["78738.69000000","0.00000000"],["78739.79000000","0.00000000"],["78739.96000000","0.00663000"],["78740.00000000","0.00000000"],["78741.22000000","0.01024000"],["78742.38000000","0.00007000"],["78744.01000000","0.00653000"],["78745.19000000","0.36451000"],["78745.22000000","0.00000000"],["78746.77000000","0.02000000"],["78747.08000000","0.00000000"],["78747.09000000","0.00007000"],["78749.90000000","0.04857000"],["78749.95000000","0.10796000"],["78751.22000000","0.00000000"],["78751.76000000","0.00000000"],["78751.83000000","0.00000000"],["78752.36000000","0.00007000"],["78756.46000000","0.00000000"],["78762.06000000","0.39818000"],["78773.85000000","0.00000000"],["78774.00000000","0.03400000"],["78776.00000000","0.02400000"],["78780.75000000","0.00000000"],["78782.54000000","0.00634000"],["78798.99000000","0.00274000"],["78809.27000000","0.00000000"],["78826.70000000","0.00000000"],["78833.63000000","0.00052000"],["78838.09000000","0.00000000"],["78847.18000000","0.00000000"]]}}
{"rx_ns": 3854695900, "frame": {"e":"depthUpdate","E":1787603061314,"s":"BTCUSDT","U":99076618784,"u":99076618936,"b":[["78734.00000000","0.01525000"],["78733.99000000","0.00083000"],["78733.12000000","0.00000000"],["78732.93000000","0.00000000"],["78732.20000000","0.00014000"],["78732.19000000","0.01715000"],["78732.00000000","0.02407000"],["78731.67000000","0.00000000"],["78731.31000000","0.04856000"],["78730.94000000","0.00007000"],["78730.93000000","0.02859000"],["78730.41000000","0.00000000"],["78729.77000000","0.00000000"],["78729.76000000","0.00014000"],["78729.67000000","0.03431000"],["78728.41000000","0.03431000"],["78728.20000000","0.00722000"],["78728.01000000","0.00000000"],["78728.00000000","0.02534000"],["78726.67000000","1.21959000"],["78726.00000000","0.02407000"],["78724.99000000","0.00000000"],["78724.00000000","0.02407000"],["78723.41000000","0.00000000"],["78719.58000000","0.00000000"],["78718.19000000","0.00400000"],["78718.08000000","0.00000000"],["78717.57000000","0.00000000"],["78717.28000000","0.01000000"],["78715.78000000","0.00189000"],["78715.45000000","0.02200000"],["78711.87000000","0.02000000"],["78703.86000000","0.00000000"],["78699.34000000","0.00000000"],["78692.00000000","0.72400000"],["78691.24000000","0.09603000"],["78681.07000000","0.00000000"],["78668.07000000","0.00000000"],["78664.45000000","0.02000000"],["78660.72000000","0.02413000"],["78598.99000000","0.04092000"],["62987.00000000","0.00000000"]],"a":[["78734.01000000","2.64281000"],["78734.02000000","0.07502000"],["78734.18000000","0.00014000"],["78734.19000000","0.02182000"],["78734.20000000","0.97833000"],["78735.27000000","0.03490000"],["78735.99000000","0.00007000"],["78736.00000000","0.07528000"],["78736.01000000","0.28433000"],["78736.53000000","0.04188000"],["78736.79000000","0.00000000"],["78736.80000000","0.38106000"],["78736.82000000","0.05320000"],["78736.85000000","0.12103000"],["78737.27000000","0.00000000"],["78737.79000000","0.04188000"],["78738.00000000","0.07500000"],["78738.01000000","0.15465000"],["78738.07000000","0.36525000"],["78738.35000000","0.14825000"],["78743.60000000","0.02000000"],["78743.83000000","0.00007000"],["78747.23000000","0.02600000"],["78751.53000000","0.00000000"],["78754.00000000","0.00500000"],["78756.00000000","0.00500000"],["78758.00000000","0.04000000"],["78769.72000000","0.00000000"],["78770.28000000","0.00628000"],["78780.79000000","0.00000000"],["78834.44000000","0.00000000"],["78842.55000000","0.00000000"],["78845.59000000","0.00000000"],["78959.77000000","0.00000000"],["79129.70000000","0.00000000"],["79525.34000000","0.00000000"],["79922.97000000","0.00000000"],["80322.59000000","0.00000000"],["80724.20000000","0.00000000"],["81127.82000000","0.00000000"],["81533.46000000","0.00000000"],["81941.13000000","0.00000000"],["82350.83000000","0.00000000"],["82762.58000000","0.00000000"],["83176.40000000","0.00000000"],["83592.28000000","0.00000000"],["84010.24000000","0.00000000"],["84430.29000000","0.00000000"],["84852.44000000","0.00000000"]]}}
{"rx_ns": 3953194500, "frame": {"e":"depthUpdate","E":1787603061414,"s":"BTCUSDT","U":99076618937,"u":99076618998,"b":[["78734.00000000","0.01532000"],["78733.99000000","0.00083000"],["78732.47000000","0.00000000"],["78732.19000000","0.01722000"],["78731.31000000","0.04856000"],["78730.94000000","0.00014000"],["78730.93000000","0.02866000"],["78730.90000000","0.00007000"],["78730.00000000","0.02407000"],["78729.76000000","0.00007000"],["78729.67000000","0.03438000"],["78728.41000000","0.03438000"],["78728.20000000","0.00729000"],["78728.00000000","0.02527000"],["78726.67000000","1.21952000"],["78726.00000000","0.02400000"],["78724.92000000","0.00323000"],["78724.00000000","0.02400000"],["78723.34000000","0.00320000"],["78719.40000000","0.02514000"],["78718.33000000","0.00000000"],["78718.19000000","0.00000000"],["78717.94000000","0.00000000"],["78717.77000000","0.00400000"],["78717.74000000","0.00000000"],["78717.73000000","0.00000000"],["78717.71000000","0.00000000"],["78710.34000000","0.00007000"],["78707.48000000","0.00000000"],["78667.96000000","0.00000000"],["78667.19000000","0.00406000"],["78659.80000000","0.86872000"],["78637.25000000","0.00000000"],["78613.14000000","0.05808000"],["70860.60000000","0.00048000"]],"a":[["78734.01000000","2.64288000"],["78734.20000000","0.38384000"],["78735.27000000","0.03497000"],["78736.00000000","0.07521000"],["78736.01000000","0.28426000"],["78736.82000000","0.05313000"],["78757.59000000","0.00007000"],["78765.59000000","0.00000000"],["78780.06000000","0.86739000"],["78787.79000000","0.00000000"],["78838.05000000","0.00000000"]]}}
{"rx_ns": 4061543200, "frame": {"e":"depthUpdate","E":1787603061514,"s":"BTCUSDT","U":99076618999,"u":99076619022,"b":[["78734.00000000","0.01546000"],["78733.99000000","0.00090000"],["78730.44000000","0.00649000"],["78729.35000000","0.00000000"],["78728.20000000","0.00007000"],["78725.85000000","0.12702000"],["78718.82000000","0.00007000"],["78718.25000000","0.00007000"],["78695.50000000","0.34313000"],["78156.60000000","0.00000000"],["78046.85000000","0.01526000"],["70860.60000000","0.00064000"],["62987.20000000","0.00031000"],["41465.30000000","0.00000000"]],"a":[["78735.26000000","0.00007000"],["78735.99000000","0.00000000"],["78736.00000000","0.00021000"],["78763.40000000","0.34283000"],["78847.25000000","0.00000000"]]}}
{"rx_ns": 4153524500, "frame": {"e":"depthUpdate","E":1787603061614,"s":"BTCUSDT","U":99076619023,"u":99076619061,"b":[["78734.00000000","0.02246000"],["78733.99000000","0.00090000"],["78732.08000000","0.00860000"],["78730.93000000","0.02866000"],["78730.44000000","0.00000000"],["78728.41000000","0.03431000"],["78728.20000000","0.00000000"],["78723.54000000","0.00014000"],["78720.82000000","0.00635000"],["78718.83000000","0.00635000"],["78692.74000000","0.28460000"],["78644.05000000","0.02115000"],["70860.60000000","0.00096000"],["62987.20000000","0.00000000"]],"a":[["78734.01000000","2.64425000"],["78735.26000000","0.00642000"],["78735.27000000","0.03497000"],["78736.00000000","0.00014000"],["78736.01000000","0.28433000"],["78736.53000000","0.04195000"],["78736.82000000","0.05320000"],["78738.00000000","0.08000000"],["78740.00000000","0.00500000"],["78742.00000000","0.02668000"],["78744.00000000","0.00500000"],["78746.00000000","0.02661000"],["78748.00000000","0.00500000"],["78749.14000000","0.00007000"],["78750.00000000","0.10031000"],["78752.00000000","0.00500000"],["78779.72000000","0.00405000"],["78841.18000000","0.00000000"]]}}
{"rx_ns": 4255712700, "frame": {"e":"depthUpdate","E":1787603061714,"s":"BTCUSDT","U":99076619062,"u":99076619455,"b":[["78734.00000000","0.00000000"],["78733.99000000","0.00000000"],["78733.98000000","0.00000000"],["78733.73000000","0.00000000"],["78732.96000000","0.00000000"],["78732.20000000","0.00000000"],["78732.19000000","0.00000000"],["78732.09000000","0.00000000"],["78732.08000000","0.00000000"],["78732.01000000","0.00000000"],["78732.00000000","0.00000000"],["78731.32000000","0.00000000"],["78731.31000000","0.00000000"],["78731.28000000","0.00000000"],["78730.94000000","0.00000000"],["78730.93000000","0.00000000"],["78730.90000000","0.00000000"],["78730.72000000","0.00000000"],["78730.01000000","0.00000000"],["78730.00000000","0.00000000"],["78729.76000000","0.00000000"],["78729.67000000","0.38857000"],["78729.66000000","0.00042000"],["78729.00000000","0.00000000"],["78728.91000000","0.00000000"],["78728.67000000","0.00000000"],["78728.42000000","0.00000000"],["78728.41000000","0.00007000"],["78728.01000000","0.00014000"],["78728.00000000","0.02534000"],["78727.46000000","0.00000000"],["78726.78000000","0.00014000"],["78726.77000000","0.04808000"],["78726.68000000","0.00014000"],["78726.67000000","1.21959000"],["78726.61000000","0.00000000"],["78726.17000000","0.00000000"],["78726.00000000","0.02407000"],["78725.86000000","0.00000000"],["78725.85000000","0.00007000"],["78723.59000000","0.00014000"],["78723.58000000","0.20829000"],["78723.11000000","0.00204000"],["78722.88000000","0.00000000"],["78722.87000000","0.00007000"],["78722.38000000","0.00000000"],["78722.03000000","0.00007000"],["78720.81000000","0.31761000"],["78720.04000000","0.00000000"],["78719.25000000","0.00000000"],["78718.99000000","0.08576000"],["78718.83000000","0.00000000"],["78717.77000000","0.00000000"],["78717.16000000","0.00007000"],["78716.19000000","0.00635000"],["78715.81000000","0.00000000"],["78706.05000000","0.00126000"],["78694.00000000","0.02415000"],["78692.58000000","0.00014000"],["78691.84000000","0.02538000"],["78691.24000000","0.00000000"],["78690.35000000","0.00000000"],["78690.00000000","0.12932000"],["78684.84000000","0.00000000"],["78678.91000000","0.02741000"],["78676.50000000","0.00000000"],["78669.96000000","0.00335000"],["78667.20000000","0.00316000"],["78666.00000000","0.02407000"],["78660.72000000","0.00000000"],["78644.05000000","0.00000000"],["78624.32000000","0.00007000"],["78527.28000000","0.00007000"],["78523.35000000","0.00053000"],["78507.56000000","0.00000000"],["78492.54000000","0.00007000"],["78465.37000000","0.03176000"],["70860.60000000","0.00000000"]],"a":[["78729.68000000","1.65072000"],["78729.69000000","0.00020000"],["78729.70000000","0.00013000"],["78729.77000000","0.00000000"],["78730.01000000","0.00014000"],["78730.94000000","0.00000000"],["78731.28000000","0.00014000"],["78731.29000000","0.00000000"],["78731.31000000","0.00000000"],["78731.32000000","0.00014000"],["78731.92000000","0.00014000"],["78731.93000000","0.25402000"],["78732.01000000","0.00007000"],["78732.09000000","0.00000000"],["78732.19000000","0.00014000"],["78732.20000000","0.10635000"],["78732.21000000","0.00000000"],["78732.27000000","0.00014000"],["78732.28000000","0.05361000"],["78732.97000000","0.00000000"],["78733.74000000","0.00000000"],["78733.99000000","0.00000000"],["78734.00000000","0.00021000"],["78734.01000000","0.73233000"],["78734.02000000","0.00014000"],["78734.03000000","0.00000000"],["78734.18000000","0.00000000"],["78734.19000000","0.02168000"],["78734.20000000","0.00014000"],["78735.26000000","0.00642000"],["78735.27000000","0.00000000"],["78736.00000000","0.00014000"],["78736.01000000","0.03031000"],["78736.19000000","0.00027000"],["78736.53000000","0.00000000"],["78736.79000000","0.00007000"],["78736.80000000","0.38092000"],["78736.82000000","0.00000000"],["78737.79000000","0.00000000"],["78738.07000000","0.26386000"],["78739.23000000","0.00007000"],["78739.50000000","0.00007000"],["78740.01000000","0.02801000"],["78740.72000000","0.00007000"],["78741.22000000","0.01017000"],["78742.00000000","0.02661000"],["78742.01000000","0.00331000"],["78744.00000000","0.00727000"],["78745.19000000","0.36224000"],["78745.43000000","0.09447000"],["78746.02000000","0.04857000"],["78748.68000000","0.00000000"],["78749.90000000","0.00000000"],["78749.95000000","0.00000000"],["78757.00000000","0.00000000"],["78757.58000000","0.39834000"],["78760.12000000","0.00000000"],["78769.98000000","0.00000000"],["78770.00000000","0.12922000"],["78774.00000000","0.02400000"],["78774.01000000","0.00012000"],["78794.19000000","0.00000000"],["78798.29000000","0.00000000"],["78838.60000000","0.00012000"],["78842.61000000","0.00000000"],["78848.74000000","0.00000000"],["78854.84000000","0.00000000"],["78864.88000000","0.00000000"],["78955.84000000","0.00000000"],["79028.85000000","1.19998000"],["79061.30000000","0.00000000"]]}}
{"rx_ns": 4355923000, "frame": {"e":"depthUpdate","E":1787603061814,"s":"BTCUSDT","U":99076619456,"u":99076619544,"b":[["78729.67000000","0.04716000"],["78729.66000000","0.00042000"],["78728.41000000","0.00000000"],["78728.00000000","0.02534000"],["78727.14000000","0.00014000"],["78727.13000000","0.01598000"],["78726.77000000","0.04815000"],["78726.00000000","0.02407000"],["78725.87000000","0.02664000"],["78725.85000000","0.00000000"],["78724.61000000","0.03196000"],["78724.00000000","0.02407000"],["78723.58000000","0.20836000"],["78723.35000000","0.03196000"],["78723.15000000","0.00000000"],["78723.14000000","0.00000000"],["78722.17000000","0.02207000"],["78722.03000000","0.00000000"],["78722.02000000","3.12474000"],["78720.82000000","0.00000000"],["78718.26000000","0.00635000"],["78669.96000000","0.00000000"],["78664.08000000","0.02800000"],["70856.71000000","0.00032000"]],"a":[["78729.68000000","1.81829000"],["78729.69000000","0.00157000"],["78730.01000000","0.00000000"],["78730.93000000","0.00014000"],["78730.94000000","0.03686000"],["78731.32000000","0.00000000"],["78731.93000000","0.25409000"],["78732.01000000","0.00000000"],["78732.20000000","0.04438000"],["78732.28000000","0.05368000"],["78733.45000000","0.00007000"],["78733.46000000","0.04424000"],["78734.00000000","0.00014000"],["78734.01000000","0.50158000"],["78734.02000000","0.00007000"],["78734.19000000","0.02168000"],["78734.20000000","0.00007000"],["78735.26000000","0.00642000"],["78736.79000000","0.00000000"],["78737.56000000","0.21930000"],["78738.07000000","0.26373000"],["78758.00000000","0.74000000"],["78762.06000000","0.00000000"],["78850.63000000","0.00405000"],["78952.43000000","0.00000000"]]}}
{"rx_ns": 4454593300, "frame": {"e":"depthUpdate","E":1787603061914,"s":"BTCUSDT","U":99076619545,"u":99076619608,"b":[["78729.67000000","0.04473000"],["78729.66000000","0.00049000"],["78728.00000000","0.02534000"],["78727.13000000","0.01605000"],["78726.00000000","0.02407000"],["78725.87000000","0.02671000"],["78724.61000000","0.03203000"],["78723.58000000","0.20829000"],["78722.17000000","0.02200000"],["78722.02000000","3.12467000"],["78684.84000000","0.00007000"],["78664.21000000","0.02200000"],["78660.57000000","0.02000000"],["78336.02000000","0.01000000"],["77944.34000000","0.01000000"],["77554.61000000","0.01000000"],["77166.84000000","0.01000000"],["76781.01000000","0.01000000"],["76397.10000000","0.01000000"],["76015.12000000","0.01000000"],["75635.04000000","0.01000000"],["75256.87000000","0.01000000"],["74880.58000000","0.01000000"],["74506.18000000","0.01000000"],["74133.65000000","0.01000000"],["73762.98000000","0.01000000"],["73394.16000000","0.01000000"],["73027.19000000","0.01000000"],["70856.71000000","0.00048000"]],"a":[["78729.68000000","2.21866000"],["78729.69000000","0.00020000"],["78730.94000000","0.03693000"],["78732.28000000","0.05361000"],["78734.01000000","0.49983000"],["78736.85000000","0.12110000"],["78750.65000000","0.00175000"],["78844.74000000","0.00019000"],["78850.83000000","0.00031000"],["79123.33000000","0.01000000"],["79518.95000000","0.01000000"],["79916.54000000","0.01077000"],["80316.13000000","0.01000000"],["80717.71000000","0.01000000"],["81121.30000000","0.01000000"],["81526.90000000","0.01125000"],["81934.54000000","0.01000000"],["82344.21000000","0.01000000"],["82755.93000000","0.01000000"],["83169.71000000","0.01000000"],["83585.56000000","0.01000000"],["84003.49000000","0.01000000"],["84423.50000000","0.01000000"],["84845.62000000","0.01000000"]]}}
{"rx_ns": 4554780500, "frame": {"e":"depthUpdate","E":1787603062014,"s":"BTCUSDT","U":99076619609,"u":99076619700,"b":[["78729.67000000","0.00000000"],["78729.66000000","0.00063000"],["78725.46000000","0.00000000"],["78724.90000000","0.00000000"],["78723.54000000","0.00007000"],["78722.31000000","0.12702000"],["78718.26000000","0.00000000"],["78717.28000000","0.00000000"],["78716.19000000","0.00000000"],["78715.46000000","0.00000000"],["78715.08000000","0.00000000"],["78714.48000000","0.00635000"],["78714.18000000","0.00000000"],["78713.57000000","0.00635000"],["78713.56000000","0.00007000"],["78711.28000000","0.00000000"],["78709.08000000","0.12000000"],["78708.34000000","0.00000000"],["78702.36000000","0.00000000"],["78698.69000000","0.00000000"],["78693.21000000","0.63545000"],["78690.45000000","0.09365000"],["78678.91000000","0.00000000"],["78678.57000000","0.00000000"],["78667.19000000","0.00000000"],["78660.10000000","0.00000000"],["78659.76000000","0.00000000"],["78619.95000000","0.00000000"],["78549.08000000","0.00000000"],["70856.71000000","0.00064000"],["62983.74000000","0.00031000"],["57500.00000000","135.22382000"]],"a":[["78729.67000000","2.08325000"],["78729.68000000","0.96740000"],["78729.72000000","0.01270000"],["78729.76000000","0.06350000"],["78730.92000000","0.00000000"],["78730.93000000","0.31762000"],["78732.19000000","0.00000000"],["78732.27000000","0.00000000"],["78732.28000000","0.05368000"],["78732.45000000","0.00000000"],["78732.46000000","0.00007000"],["78733.45000000","0.00000000"],["78734.00000000","0.00007000"],["78734.01000000","0.18223000"],["78735.26000000","0.00007000"],["78736.79000000","1.90515000"],["78738.05000000","0.12700000"],["78741.95000000","0.00000000"],["78779.72000000","0.00000000"],["78797.95000000","0.00000000"],["78819.11000000","0.00000000"],["78850.63000000","0.00000000"],["78897.89000000","0.00000000"],["78968.80000000","0.00000000"],["79065.47000000","0.00000000"]]}}
{"rx_ns": 4655648800, "frame": {"e":"depthUpdate","E":1787603062114,"s":"BTCUSDT","U":99076619701,"u":99076620894,"b":[["78729.66000000","0.00000000"],["78729.65000000","0.00000000"],["78729.08000000","0.00000000"],["78728.31000000","0.00000000"],["78728.30000000","0.00000000"],["78728.01000000","0.00000000"],["78728.00000000","0.00000000"],["78727.99000000","0.00000000"],["78727.41000000","0.00000000"],["78727.14000000","0.00000000"],["78727.13000000","0.00000000"],["78726.78000000","0.00000000"],["78726.77000000","0.00000000"],["78726.68000000","0.00000000"],["78726.67000000","0.00000000"],["78726.38000000","0.00000000"],["78726.23000000","0.00000000"],["78726.00000000","0.00000000"],["78725.87000000","0.00000000"],["78725.41000000","0.00000000"],["78725.20000000","0.00000000"],["78724.92000000","0.00000000"],["78724.80000000","0.00000000"],["78724.61000000","0.00000000"],["78724.60000000","0.00000000"],["78724.59000000","0.00000000"],["78724.58000000","0.00000000"],["78724.19000000","0.00000000"],["78724.01000000","0.00000000"],["78724.00000000","0.01998000"],["78723.93000000","0.00000000"],["78723.59000000","0.00000000"],["78723.58000000","0.00014000"],["78723.46000000","0.00000000"],["78723.36000000","0.00000000"],["78723.35000000","0.00007000"],["78723.34000000","0.00000000"],["78723.11000000","0.00000000"],["78722.94000000","0.00000000"],["78722.53000000","0.00000000"],["78722.32000000","0.00000000"],["78722.31000000","0.00007000"],["78722.17000000","0.00007000"],["78722.02000000","0.00007000"],["78722.01000000","0.00014000"],["78722.00000000","0.02414000"],["78721.69000000","0.00014000"],["78721.68000000","0.04767000"],["78720.81000000","0.00007000"],["78720.32000000","0.00000000"],["78720.31000000","0.00000000"],["78720.17000000","0.00000000"],["78720.16000000","0.00000000"],["78720.01000000","0.00014000"],["78719.69000000","0.00000000"],["78719.67000000","0.00007000"],["78719.56000000","0.00000000"],["78719.40000000","0.00000000"],["78719.03000000","0.00000000"],["78718.99000000","0.00000000"],["78718.52000000","0.00000000"],["78718.35000000","0.00000000"],["78718.34000000","0.00000000"],["78718.22000000","0.00000000"],["78718.18000000","0.00000000"],["78718.02000000","0.00000000"],["78718.01000000","0.00007000"],["78717.63000000","0.00000000"],["78717.46000000","0.00000000"],["78717.38000000","0.00000000"],["78717.34000000","0.00000000"],["78717.25000000","0.00000000"],["78717.10000000","0.00000000"],["78716.73000000","0.00000000"],["78716.58000000","0.00000000"],["78716.18000000","0.00000000"],["78716.13000000","0.00000000"],["78716.12000000","0.00000000"],["78716.11000000","0.00000000"],["78715.80000000","0.00007000"],["78715.75000000","0.00000000"],["78715.45000000","0.00000000"],["78715.42000000","0.00000000"],["78715.39000000","0.00000000"],["78715.38000000","0.00152000"],["78715.34000000","0.00000000"],["78715.20000000","0.00000000"],["78714.93000000","0.00000000"],["78714.92000000","0.00329000"],["78714.48000000","0.00000000"],["78714.47000000","0.00000000"],["78714.01000000","0.00007000"],["78713.58000000","0.00000000"],["78713.57000000","0.00000000"],["78713.39000000","0.00000000"],["78713.22000000","0.00048000"],["78712.95000000","0.31764000"],["78712.81000000","0.00000000"],["78712.58000000","0.00000000"],["78712.33000000","0.00000000"],["78712.10000000","0.08576000"],["78711.93000000","0.00007000"],["78711.87000000","0.00000000"],["78711.70000000","0.00000000"],["78711.51000000","0.00000000"],["78711.50000000","0.00000000"],["78711.47000000","0.00000000"],["78711.43000000","0.00000000"],["78711.39000000","1.90515000"],["78711.19000000","0.00000000"],["78710.86000000","0.00007000"],["78710.41000000","0.00635000"],["78710.40000000","0.00000000"],["78710.38000000","0.00000000"],["78710.05000000","0.36224000"],["78710.04000000","0.00000000"],["78709.37000000","0.02000000"],["78709.09000000","0.00000000"],["78709.08000000","0.00000000"],["78708.42000000","0.00000000"],["78708.08000000","0.00000000"],["78708.06000000","0.00014000"],["78707.82000000","0.00000000"],["78707.77000000","0.00000000"],["78707.64000000","0.00000000"],["78706.85000000","0.00000000"],["78706.18000000","0.00635000"],["78705.86000000","0.00000000"],["78705.68000000","0.00000000"],["78705.45000000","0.00000000"],["78704.19000000","0.00014000"],["78704.01000000","0.00400000"],["78703.54000000","0.00254000"],["78701.87000000","0.15321000"],["78701.52000000","0.02287000"],["78701.09000000","0.00000000"],["78701.00000000","0.00007000"],["78700.36000000","0.00000000"],["78700.32000000","0.00414000"],["78700.00000000","0.02407000"],["78699.81000000","0.00000000"],["78699.61000000","0.13502000"],["78698.79000000","0.00000000"],["78696.46000000","0.00000000"],["78696.45000000","0.00014000"],["78695.63000000","0.00190000"],["78695.50000000","0.00000000"],["78694.65000000","0.00000000"],["78693.21000000","0.00000000"],["78693.12000000","0.00060000"],["78693.04000000","0.00635000"],["78691.84000000","0.00000000"],["78691.74000000","0.00012000"],["78691.50000000","0.04445000"],["78690.45000000","0.00000000"],["78690.41000000","0.13245000"],["78690.09000000","0.00000000"],["78690.00000000","0.11932000"],["78689.37000000","0.00000000"],["78688.76000000","0.50426000"],["78688.71000000","0.00014000"],["78688.19000000","0.00000000"],["78688.00000000","0.03001000"],["78687.99000000","0.34316000"],["78687.65000000","0.68297000"],["78686.00000000","0.02400000"],["78685.96000000","0.00000000"],["78685.73000000","0.34317000"],["78685.00000000","0.01000000"],["78684.09000000","0.00000000"],["78683.68000000","0.00000000"],["78683.61000000","0.00000000"],["78683.51000000","0.00000000"],["78682.14000000","0.00000000"],["78681.34000000","0.00000000"],["78680.97000000","0.00007000"],["78680.00000000","0.08942000"],["78679.59000000","0.00000000"],["78679.53000000","0.00000000"],["78678.47000000","0.00000000"],["78678.43000000","0.00000000"],["78677.43000000","0.00000000"],["78677.10000000","0.00007000"],["78676.34000000","0.00000000"],["78675.70000000","0.00000000"],["78674.46000000","0.00015000"],["78673.72000000","0.00000000"],["78673.36000000","0.00000000"],["78673.23000000","0.00007000"],["78672.45000000","0.00000000"],["78672.36000000","0.00000000"],["78672.15000000","0.00300000"],["78671.02000000","0.00000000"],["78670.81000000","0.00000000"],["78670.60000000","0.00400000"],["78669.15000000","0.02815000"],["78669.05000000","0.88807000"],["78667.65000000","0.00400000"],["78663.63000000","0.00618000"],["78662.47000000","0.00429000"],["78661.75000000","0.00400000"],["78660.37000000","1.21952000"],["78659.80000000","0.00000000"],["78659.51000000","0.00000000"],["78658.74000000","0.00000000"],["78658.58000000","0.00000000"],["78658.21000000","1.25882000"],["78657.85000000","0.00000000"],["78655.66000000","0.00000000"],["78654.91000000","0.00000000"],["78654.56000000","0.00000000"],["78653.64000000","0.00000000"],["78653.56000000","0.00000000"],["78652.24000000","0.00000000"],["78650.34000000","0.02418000"],["78650.13000000","1.21952000"],["78644.01000000","0.00315000"],["78641.67000000","0.00530000"],["78635.64000000","1.90515000"],["78628.87000000","0.00000000"],["78627.52000000","0.00000000"],["78609.62000000","0.00000000"],["78600.61000000","0.00000000"],["78598.99000000","0.00000000"],["78519.77000000","0.00007000"],["78515.84000000","0.00000000"],["78503.29000000","0.00000000"],["78443.12000000","0.11559000"],["78407.84000000","0.21930000"],["78407.47000000","7.65320000"],["78402.91000000","0.00000000"],["78393.25000000","0.00036000"],["78336.02000000","0.00000000"],["77944.34000000","0.00000000"],["77554.61000000","0.00000000"],["77166.84000000","0.00000000"],["76781.01000000","0.00000000"],["76397.10000000","0.00000000"],["76015.12000000","0.00000000"],["75635.04000000","0.00000000"],["75256.87000000","0.00000000"],["74880.58000000","0.00000000"],["74506.18000000","0.00000000"],["74133.65000000","0.00000000"],["73762.98000000","0.00000000"],["73394.16000000","0.00000000"],["73027.19000000","0.00000000"],["72486.80000000","0.00014000"],["70862.40000000","0.00000000"],["70862.39000000","0.00009000"],["70856.71000000","0.00000000"],["70852.15000000","0.00000000"]],"a":[["78724.01000000","0.75110000"],["78724.20000000","0.40000000"],["78724.60000000","0.40000000"],["78724.61000000","3.55369000"],["78724.62000000","0.38798000"],["78724.63000000","0.00013000"],["78724.64000000","0.00000000"],["78724.73000000","0.00000000"],["78724.81000000","0.00000000"],["78724.93000000","0.00000000"],["78725.21000000","0.00000000"],["78725.86000000","0.00014000"],["78725.87000000","0.02175000"],["78725.88000000","0.42787000"],["78726.00000000","0.00000000"],["78726.01000000","0.00007000"],["78726.23000000","0.00000000"],["78726.24000000","0.00007000"],["78726.65000000","0.00400000"],["78726.67000000","0.00000000"],["78726.68000000","0.00007000"],["78726.77000000","0.00000000"],["78726.78000000","0.00007000"],["78727.12000000","0.00014000"],["78727.13000000","0.07507000"],["78727.14000000","0.00007000"],["78727.18000000","0.00007000"],["78727.19000000","0.05403000"],["78727.41000000","0.00014000"],["78727.42000000","0.00007000"],["78728.00000000","0.36224000"],["78728.01000000","0.07819000"],["78728.02000000","0.00007000"],["78728.03000000","0.00000000"],["78728.31000000","0.07500000"],["78728.32000000","0.16719000"],["78728.33000000","0.00000000"],["78728.34000000","0.00000000"],["78728.80000000","0.38099000"],["78729.00000000","0.00007000"],["78729.09000000","0.00000000"],["78729.60000000","0.00400000"],["78729.66000000","3.12642000"],["78729.67000000","0.12495000"],["78729.68000000","0.33908000"],["78729.69000000","0.00000000"],["78729.70000000","0.00000000"],["78729.72000000","0.01277000"],["78729.76000000","0.06357000"],["78730.92000000","0.00000000"],["78730.93000000","0.00000000"],["78730.94000000","0.00000000"],["78731.27000000","0.00227000"],["78731.92000000","0.00000000"],["78731.93000000","0.25402000"],["78732.20000000","0.00007000"],["78732.28000000","0.00007000"],["78732.50000000","0.00008000"],["78732.54000000","0.02000000"],["78732.55000000","0.00400000"],["78732.93000000","0.00007000"],["78733.46000000","0.00000000"],["78733.94000000","0.00000000"],["78734.01000000","0.00359000"],["78734.19000000","0.02161000"],["78734.20000000","0.00327000"],["78734.71000000","0.00157000"],["78735.25000000","0.00000000"],["78735.26000000","0.00000000"],["78736.00000000","0.00007000"],["78736.01000000","0.00010000"],["78736.08000000","0.00007000"],["78736.78000000","1.58176000"],["78736.80000000","0.00000000"],["78736.84000000","0.00007000"],["78736.85000000","0.12096000"],["78737.95000000","0.00325000"],["78738.00000000","0.00500000"],["78738.01000000","0.15458000"],["78738.07000000","0.26352000"],["78738.33000000","0.00000000"],["78738.34000000","0.00000000"],["78738.45000000","0.00400000"],["78738.71000000","0.00000000"],["78739.01000000","0.00000000"],["78739.03000000","0.00000000"],["78739.13000000","0.04857000"],["78739.17000000","0.00000000"],["78739.96000000","0.00656000"],["78740.00000000","0.07047000"],["78740.01000000","0.02000000"],["78740.02000000","0.00000000"],["78740.36000000","0.10887000"],["78740.42000000","0.00000000"],["78741.22000000","0.00000000"],["78741.26000000","0.34293000"],["78741.74000000","0.06587000"],["78742.27000000","0.34293000"],["78742.29000000","0.63505000"],["78742.38000000","0.00000000"],["78743.13000000","0.00000000"],["78743.37000000","0.00000000"],["78743.71000000","0.07610000"],["78743.76000000","0.00000000"],["78744.00000000","0.00500000"],["78745.43000000","0.00000000"],["78745.53000000","0.00000000"],["78746.01000000","0.00000000"],["78746.02000000","0.00000000"],["78747.98000000","0.00326000"],["78748.78000000","0.00000000"],["78749.03000000","0.00060000"],["78750.58000000","0.00010000"],["78750.65000000","0.09634000"],["78750.75000000","0.00000000"],["78751.17000000","0.00007000"],["78751.75000000","0.00190000"],["78751.94000000","0.00126000"],["78752.26000000","0.00000000"],["78752.52000000","0.39834000"],["78752.53000000","1.21906000"],["78753.81000000","0.00000000"],["78755.78000000","0.00000000"],["78756.21000000","0.00000000"],["78757.32000000","0.00000000"],["78759.20000000","0.00000000"],["78761.10000000","0.68234000"],["78761.53000000","0.00000000"],["78761.72000000","0.02757000"],["78762.80000000","1.25708000"],["78763.39000000","0.00431000"],["78763.40000000","0.00000000"],["78763.69000000","0.00000000"],["78766.11000000","0.00000000"],["78766.89000000","0.00000000"],["78768.24000000","0.00000000"],["78768.74000000","0.00000000"],["78768.97000000","0.00433000"],["78769.87000000","0.00000000"],["78770.27000000","0.00426000"],["78771.52000000","0.00000000"],["78772.11000000","0.00000000"],["78773.17000000","0.00000000"],["78773.43000000","0.00000000"],["78774.30000000","0.00000000"],["78774.49000000","0.88688000"],["78776.49000000","0.00000000"],["78776.67000000","0.00000000"],["78778.29000000","0.00000000"],["78778.80000000","0.00350000"],["78779.00000000","0.00000000"],["78779.11000000","0.00000000"],["78780.06000000","0.00000000"],["78781.50000000","0.00000000"],["78784.03000000","0.51317000"],["78784.23000000","0.00000000"],["78785.50000000","0.00000000"],["78786.41000000","0.00111000"],["78786.56000000","0.00000000"],["78787.65000000","0.00539000"],["78787.87000000","0.91120000"],["78789.87000000","0.01713000"],["78791.87000000","0.00000000"],["78792.14000000","0.00000000"],["78797.25000000","0.00000000"],["78799.68000000","0.00000000"],["78800.70000000","0.00000000"],["78802.67000000","0.00000000"],["78804.24000000","0.00000000"],["78804.56000000","0.00000000"],["78805.22000000","0.00000000"],["78807.18000000","0.00000000"],["78813.00000000","0.00000000"],["78815.76000000","0.00000000"],["78818.01000000","0.04651000"],["78827.83000000","0.00000000"],["78828.75000000","0.00000000"],["78831.52000000","0.00000000"],["78835.71000000","0.00000000"],["78839.15000000","0.00000000"],["78844.50000000","0.00000000"],["78844.99000000","0.00000000"],["78847.28000000","0.00000000"],["78860.25000000","0.00000000"],["78863.04000000","0.00000000"],["78876.00000000","0.02407000"],["78878.80000000","0.00008000"],["78891.75000000","0.00000000"],["78894.56000000","0.00000000"],["78907.50000000","0.00000000"],["78910.32000000","0.00000000"],["78923.25000000","0.00000000"],["78926.08000000","0.00000000"],["78939.00000000","0.00000000"],["78948.12000000","0.00000000"],["78954.75000000","0.00000000"],["78970.50000000","0.00000000"],["78979.17000000","0.00033000"],["78986.25000000","0.00000000"],["78988.90000000","0.00000000"],["79049.26000000","0.00000000"]]}}
{"rx_ns": 4754885200, "frame": {"e":"depthUpdate","E":1787603062214,"s":"BTCUSDT","U":99076620895,"u":99076621203,"b":[["78724.00000000","0.02070000"],["78723.99000000","0.00035000"],["78723.91000000","0.00000000"],["78723.58000000","0.00000000"],["78723.35000000","0.00000000"],["78722.87000000","0.00000000"],["78722.31000000","0.00000000"],["78722.17000000","0.00000000"],["78722.02000000","0.00000000"],["78722.00000000","0.02407000"],["78721.69000000","0.00000000"],["78721.68000000","0.00007000"],["78721.08000000","0.00014000"],["78721.07000000","0.04767000"],["78720.81000000","0.00000000"],["78720.61000000","0.00014000"],["78720.60000000","0.01459000"],["78720.00000000","0.02431000"],["78719.35000000","0.00007000"],["78719.34000000","0.02432000"],["78718.94000000","0.00041000"],["78718.08000000","0.02919000"],["78718.01000000","0.00000000"],["78718.00000000","0.02607000"],["78717.38000000","0.00027000"],["78716.82000000","0.02919000"],["78716.01000000","0.00000000"],["78716.00000000","0.02407000"],["78715.78000000","0.00000000"],["78714.92000000","0.00000000"],["78714.01000000","0.00007000"],["78714.00000000","0.02407000"],["78713.39000000","0.00007000"],["78712.95000000","0.31778000"],["78712.24000000","0.00000000"],["78712.23000000","0.00000000"],["78712.10000000","0.08583000"],["78711.93000000","0.00007000"],["78708.33000000","0.02514000"],["78704.64000000","0.00187000"],["78701.21000000","0.02400000"],["78692.00000000","0.02400000"],["78685.00000000","0.00000000"],["78684.84000000","0.00014000"],["78684.00000000","0.03400000"],["78680.21000000","0.09594000"],["78673.23000000","0.00000000"],["78669.15000000","0.00000000"],["78668.86000000","0.00000000"],["78668.58000000","0.00000000"],["78668.46000000","0.02839000"],["78659.01000000","0.00000000"],["78658.20000000","0.00426000"],["78656.98000000","0.00428000"],["78650.34000000","0.00000000"],["78650.05000000","0.00000000"],["78649.86000000","0.01137000"],["78649.77000000","0.00000000"],["78649.66000000","0.02371000"],["78642.73000000","0.01711000"],["78640.67000000","0.00112000"],["78623.75000000","0.00000000"],["78602.24000000","0.00000000"],["78598.70000000","0.00000000"],["78598.34000000","0.04559000"],["78590.35000000","0.04092000"],["78556.93000000","0.00000000"],["78548.36000000","0.00663000"],["78489.70000000","0.00000000"],["70851.60000000","0.00032000"],["62983.74000000","0.00000000"]],"a":[["78724.01000000","3.63096000"],["78724.02000000","0.00020000"],["78724.03000000","0.00013000"],["78724.19000000","0.00000000"],["78724.20000000","0.00014000"],["78724.59000000","0.00000000"],["78724.60000000","0.00021000"],["78724.61000000","0.36852000"],["78724.62000000","0.38567000"],["78724.63000000","0.00000000"],["78725.26000000","0.00014000"],["78725.27000000","0.03918000"],["78725.86000000","0.00000000"],["78725.87000000","0.02168000"],["78725.88000000","0.00035000"],["78726.52000000","0.00007000"],["78726.53000000","0.04702000"],["78726.57000000","0.00014000"],["78726.58000000","0.05396000"],["78727.12000000","0.00000000"],["78727.18000000","0.00000000"],["78727.19000000","0.00007000"],["78727.79000000","0.04702000"],["78728.01000000","0.07812000"],["78728.32000000","0.16712000"],["78729.66000000","3.12467000"],["78729.67000000","0.12488000"],["78729.68000000","0.16289000"],["78729.72000000","0.01270000"],["78729.76000000","0.06350000"],["78734.01000000","0.00345000"],["78734.02000000","0.00000000"],["78738.35000000","0.00000000"],["78740.95000000","0.00007000"],["78741.69000000","0.00007000"],["78746.40000000","0.00012000"],["78757.58000000","0.00000000"],["78760.46000000","0.02462000"],["78760.60000000","0.00631000"],["78764.00000000","0.03414000"],["78770.00000000","0.02400000"],["78770.28000000","0.00000000"],["78819.95000000","0.00000000"],["78826.49000000","0.02789000"],["78828.58000000","0.00406000"],["78932.00000000","0.00000000"],["78949.18000000","0.00000000"],["78994.70000000","0.07611000"]]}}
{"rx_ns": 4853809700, "frame": {"e":"depthUpdate","E":1787603062314,"s":"BTCUSDT","U":99076621204,"u":99076621267,"b":[["78724.00000000","0.02070000"],["78722.00000000","0.02407000"],["78721.68000000","0.00000000"],["78721.07000000","0.04774000"],["78720.60000000","0.01466000"],["78720.00000000","0.02431000"],["78719.34000000","0.02439000"],["78718.08000000","0.02926000"],["78718.00000000","0.02607000"],["78716.82000000","0.02926000"],["78716.00000000","0.02400000"],["78714.00000000","0.02400000"],["78713.75000000","0.00334000"],["78712.95000000","0.31771000"],["78712.10000000","0.08576000"],["78711.93000000","0.00014000"],["78705.80000000","0.00007000"],["78704.34000000","0.02200000"],["78700.75000000","0.02000000"],["78664.95000000","0.02200000"],["78644.75000000","0.02000000"],["78590.35000000","0.00000000"],["78483.33000000","0.09957000"],["62979.00000000","0.00000000"]],"a":[["78724.01000000","3.63096000"],["78724.20000000","0.00007000"],["78724.60000000","0.00014000"],["78724.61000000","0.14922000"],["78724.62000000","0.16637000"],["78725.27000000","0.03925000"],["78725.86000000","0.00007000"],["78725.87000000","0.02168000"],["78725.88000000","0.00028000"],["78726.16000000","0.00007000"],["78726.53000000","0.04709000"],["78726.57000000","0.00007000"],["78726.58000000","0.05403000"],["78731.93000000","0.25395000"],["78732.20000000","0.00000000"],["78732.28000000","0.00000000"],["78734.00000000","0.00000000"],["78734.80000000","0.02000000"],["78736.99000000","0.02514000"],["78738.44000000","0.02600000"],["78747.23000000","0.00000000"],["78750.41000000","0.00000000"],["78774.47000000","0.01148000"],["78800.32000000","0.00000000"],["78814.73000000","0.00000000"],["78819.95000000","0.21930000"],["78827.83000000","0.21930000"]]}}
{"rx_ns": 4956089900, "frame": {"e":"depthUpdate","E":1787603062414,"s":"BTCUSDT","U":99076621268,"u":99076621326,"b":[["78724.00000000","0.01179000"],["78715.24000000","0.00000000"],["78715.21000000","0.00406000"],["78714.62000000","0.00000000"],["78710.60000000","0.26053000"],["78710.34000000","0.00000000"],["78700.34000000","0.00007000"],["78667.20000000","0.00000000"],["78662.01000000","0.00317000"],["78649.69000000","0.86883000"],["78644.75000000","0.00000000"],["78644.01000000","0.00000000"],["78640.68000000","0.00317000"],["78618.43000000","2.77137000"],["78609.17000000","2.14286000"],["78593.74000000","0.00000000"],["78588.88000000","0.04092000"],["78582.26000000","0.00127000"],["78573.49000000","0.00000000"],["78560.78000000","0.00127000"],["78557.09000000","0.00102000"],["78556.75000000","0.00102000"],["70862.39000000","0.00000000"],["70851.60000000","0.00064000"],["70851.00000000","0.00020000"]],"a":[["78724.01000000","3.89656000"],["78729.67000000","0.11988000"],["78732.96000000","0.00007000"],["78743.60000000","0.00000000"],["78747.58000000","0.00007000"],["78752.36000000","0.00000000"],["78757.59000000","0.00000000"],["78769.75000000","0.86751000"],["78773.15000000","0.00317000"],["78785.27000000","0.00000000"],["78795.99000000","0.00314000"],["78806.94000000","0.00000000"],["78828.58000000","0.00418000"],["78838.60000000","0.00000000"],["78844.74000000","0.00000000"],["78850.83000000","0.00000000"],["78851.99000000","0.00127000"],["78857.12000000","0.00000000"],["78865.43000000","0.00102000"],["78865.72000000","0.00102000"],["78873.99000000","0.00127000"],["78882.34000000","0.00000000"],["78885.86000000","0.00000000"],["79123.33000000","0.00000000"],["79518.95000000","0.00000000"],["79916.54000000","0.00077000"],["80316.13000000","0.00000000"],["80717.71000000","0.00000000"],["81121.30000000","0.00000000"],["81526.90000000","0.00125000"],["81934.54000000","0.00000000"],["82344.21000000","0.00000000"],["82755.93000000","0.00000000"],["83169.71000000","0.00000000"],["83585.56000000","0.00000000"],["84003.49000000","0.00000000"],["84423.50000000","0.00000000"],["84845.62000000","0.00000000"]]}}
{"rx_ns": 5056824100, "frame": {"e":"depthUpdate","E":1787603062514,"s":"BTCUSDT","U":99076621327,"u":99076621343,"b":[["78715.88000000","0.12703000"],["78684.06000000","0.34318000"],["78672.23000000","0.34323000"],["78599.73000000","0.80000000"],["70851.60000000","0.00080000"],["70851.00000000","0.00000000"],["62979.20000000","0.00031000"]],"a":[["78724.01000000","4.15058000"],["78727.74000000","0.00007000"],["78731.93000000","0.00000000"],["78732.46000000","0.00000000"],["78834.72000000","0.00019000"]]}}
{"rx_ns": 5154662500, "frame": {"e":"depthUpdate","E":1787603062614,"s":"BTCUSDT","U":99076621344,"u":99076621671,"b":[["78724.00000000","0.00000000"],["78723.99000000","0.00000000"],["78723.54000000","0.00000000"],["78723.26000000","0.00000000"],["78722.01000000","0.00000000"],["78722.00000000","0.00092000"],["78721.99000000","0.00041000"],["78721.98000000","0.00013000"],["78721.08000000","0.00000000"],["78721.07000000","0.00007000"],["78720.61000000","0.00000000"],["78720.60000000","0.00007000"],["78719.35000000","0.00000000"],["78719.34000000","0.00007000"],["78719.08000000","0.00014000"],["78719.07000000","0.04767000"],["78718.94000000","0.00000000"],["78718.82000000","0.00000000"],["78718.50000000","0.00000000"],["78718.09000000","0.00000000"],["78718.08000000","0.00007000"],["78718.01000000","0.00014000"],["78716.82000000","0.00007000"],["78716.01000000","0.00014000"],["78716.00000000","0.02407000"],["78715.89000000","0.00007000"],["78713.75000000","0.00000000"],["78712.95000000","0.00007000"],["78712.10000000","0.00007000"],["78711.93000000","0.00007000"],["78711.81000000","0.00000000"],["78711.39000000","0.00000000"],["78710.61000000","0.00007000"],["78710.41000000","0.00000000"],["78710.21000000","0.08576000"],["78709.73000000","0.00000000"],["78709.37000000","0.00000000"],["78709.23000000","0.00000000"],["78708.64000000","0.00323000"],["78706.17000000","0.02007000"],["78706.00000000","0.15105000"],["78705.91000000","0.31767000"],["78705.79000000","0.00332000"],["78705.44000000","0.00000000"],["78702.75000000","0.00000000"],["78701.87000000","0.03321000"],["78701.85000000","0.00321000"],["78701.07000000","0.04000000"],["78698.47000000","0.08000000"],["78697.91000000","0.00324000"],["78697.40000000","0.00000000"],["78693.97000000","0.00332000"],["78687.99000000","0.00000000"],["78685.86000000","0.63551000"],["78684.00000000","0.02400000"],["78682.00000000","0.03400000"],["78680.21000000","0.00000000"],["78673.43000000","0.00007000"],["78673.23000000","0.00007000"],["78668.46000000","0.00000000"],["78649.66000000","0.00000000"],["78644.36000000","0.00406000"],["78632.75000000","0.02115000"],["78626.19000000","1.90515000"],["78517.61000000","0.00007000"],["78513.68000000","0.00000000"],["70851.60000000","0.00000000"],["70849.80000000","0.00009000"],["62979.20000000","0.00000000"]],"a":[["78722.01000000","3.03235000"],["78722.02000000","0.00020000"],["78722.03000000","0.00013000"],["78723.54000000","0.00014000"],["78723.55000000","0.00007000"],["78723.99000000","0.00000000"],["78724.00000000","0.00196000"],["78724.01000000","1.12757000"],["78724.02000000","0.00000000"],["78724.03000000","0.00000000"],["78724.20000000","0.00000000"],["78724.36000000","0.02000000"],["78724.57000000","0.00014000"],["78724.58000000","0.05396000"],["78724.60000000","0.00014000"],["78724.61000000","0.08486000"],["78724.62000000","0.17280000"],["78725.26000000","0.00000000"],["78725.27000000","0.00007000"],["78725.86000000","0.00000000"],["78726.52000000","0.00000000"],["78726.53000000","0.00007000"],["78726.57000000","0.00000000"],["78726.58000000","0.00007000"],["78727.13000000","0.07514000"],["78727.79000000","0.00000000"],["78728.56000000","0.00327000"],["78729.67000000","0.08988000"],["78729.68000000","0.16282000"],["78731.83000000","0.00007000"],["78732.54000000","0.00000000"],["78733.53000000","0.34296000"],["78736.51000000","0.00007000"],["78737.24000000","0.04857000"],["78737.76000000","0.10246000"],["78738.07000000","0.18201000"],["78739.13000000","0.00000000"],["78740.01000000","0.01000000"],["78740.36000000","0.00000000"],["78742.01000000","0.00000000"],["78744.01000000","0.00334000"],["78753.44000000","1.25723000"],["78754.01000000","0.00000000"],["78754.22000000","0.00000000"],["78756.17000000","0.00000000"],["78762.00000000","0.03400000"],["78762.24000000","0.00000000"],["78762.80000000","0.00000000"],["78764.00000000","0.02414000"],["78765.25000000","0.00000000"],["78779.23000000","0.31635000"],["78788.05000000","0.00000000"],["78801.99000000","0.00007000"],["78822.38000000","2.10788000"],["78840.82000000","0.00031000"],["78904.12000000","3.80251000"],["78945.08000000","0.00000000"],["78946.23000000","0.00000000"],["78999.98000000","0.00000000"]]}}
{"rx_ns": 5262353700, "frame": {"e":"depthUpdate","E":1787603062714,"s":"BTCUSDT","U":99076621672,"u":99076622000,"b":[["78722.00000000","0.00000000"],["78721.99000000","0.00000000"],["78721.98000000","0.00000000"],["78721.32000000","0.00000000"],["78721.07000000","0.00000000"],["78720.60000000","0.00000000"],["78720.49000000","0.00000000"],["78720.01000000","0.00000000"],["78720.00000000","0.00842000"],["78719.99000000","0.00056000"],["78719.34000000","0.00000000"],["78719.08000000","0.00000000"],["78719.07000000","0.00007000"],["78718.51000000","0.00000000"],["78718.44000000","0.00000000"],["78718.25000000","0.00000000"],["78718.08000000","0.00000000"],["78718.00000000","0.02607000"],["78717.38000000","0.00000000"],["78717.16000000","0.00000000"],["78717.08000000","0.00021000"],["78717.07000000","0.04774000"],["78716.82000000","0.00000000"],["78716.61000000","0.00014000"],["78716.60000000","0.01459000"],["78715.89000000","0.00000000"],["78715.88000000","0.00007000"],["78715.38000000","0.00000000"],["78715.35000000","0.00007000"],["78715.34000000","0.02433000"],["78714.94000000","0.00000000"],["78714.08000000","0.02919000"],["78714.01000000","0.00007000"],["78714.00000000","0.02407000"],["78712.82000000","0.02919000"],["78712.01000000","0.00000000"],["78710.60000000","0.00007000"],["78710.24000000","0.00000000"],["78710.21000000","0.00007000"],["78710.05000000","0.00007000"],["78708.33000000","0.00000000"],["78708.09000000","0.08576000"],["78707.71000000","0.00007000"],["78707.38000000","0.00152000"],["78702.00000000","0.02400000"],["78701.07000000","0.00000000"],["78699.87000000","0.04000000"],["78699.83000000","0.36224000"],["78698.47000000","0.00000000"],["78698.38000000","0.00000000"],["78697.44000000","0.06591000"],["78697.27000000","0.08000000"],["78695.47000000","0.07615000"],["78691.50000000","0.00000000"],["78687.65000000","0.00000000"],["78682.00000000","0.02400000"],["78681.53000000","0.04453000"],["78680.97000000","0.00014000"],["78680.00000000","0.09942000"],["78677.87000000","0.00000000"],["78677.08000000","0.09673000"],["78666.46000000","0.00381000"],["78665.99000000","0.00000000"],["78665.66000000","0.00000000"],["78665.45000000","0.00000000"],["78656.35000000","1.21952000"],["78652.80000000","0.00400000"],["78647.66000000","0.00000000"],["78647.19000000","0.00000000"],["78646.86000000","0.00000000"],["78632.75000000","0.00000000"],["78618.43000000","0.00000000"],["78599.73000000","0.00000000"],["78597.03000000","0.00000000"],["78588.88000000","0.08809000"],["78511.73000000","0.00007000"],["78507.80000000","0.00000000"],["78317.01000000","0.00007000"],["72486.80000000","0.00000000"],["70849.80000000","0.00009000"],["70848.00000000","0.00016000"]],"a":[["78720.01000000","3.18067000"],["78720.02000000","0.00020000"],["78720.03000000","0.00013000"],["78720.61000000","0.00000000"],["78721.08000000","0.00000000"],["78721.26000000","0.00007000"],["78721.27000000","0.03918000"],["78721.33000000","0.00000000"],["78721.99000000","0.00014000"],["78722.00000000","0.02350000"],["78722.01000000","1.09388000"],["78722.02000000","0.00000000"],["78722.03000000","0.00000000"],["78722.53000000","0.04702000"],["78722.58000000","0.00014000"],["78722.59000000","0.05396000"],["78723.79000000","0.04702000"],["78724.00000000","3.12488000"],["78724.01000000","0.56204000"],["78724.36000000","0.02007000"],["78724.57000000","0.00000000"],["78724.58000000","0.00007000"],["78724.60000000","0.00000000"],["78724.61000000","0.08472000"],["78724.62000000","0.17280000"],["78724.80000000","0.00008000"],["78725.27000000","0.00000000"],["78725.87000000","0.02168000"],["78725.88000000","0.00021000"],["78726.15000000","0.02286000"],["78726.33000000","0.00254000"],["78726.53000000","0.00000000"],["78726.58000000","0.00000000"],["78727.13000000","0.07521000"],["78727.89000000","0.21930000"],["78728.00000000","0.36224000"],["78728.32000000","0.13712000"],["78729.08000000","0.00007000"],["78729.67000000","0.08981000"],["78729.68000000","0.12136000"],["78729.78000000","0.00007000"],["78729.83000000","0.00007000"],["78734.01000000","0.00338000"],["78735.12000000","0.04857000"],["78735.76000000","0.09404000"],["78737.24000000","0.00000000"],["78737.76000000","0.00000000"],["78738.01000000","0.00000000"],["78738.34000000","0.06587000"],["78739.01000000","0.43585000"],["78739.23000000","0.00000000"],["78739.26000000","0.00000000"],["78739.96000000","0.00332000"],["78740.01000000","0.00000000"],["78740.31000000","0.07611000"],["78741.74000000","0.00000000"],["78742.21000000","0.04640000"],["78743.16000000","0.00000000"],["78743.51000000","0.00000000"],["78743.71000000","0.00000000"],["78755.27000000","0.00000000"],["78762.00000000","0.02400000"],["78764.79000000","0.00000000"],["78786.32000000","0.00000000"],["78786.33000000","0.00000000"],["78787.34000000","0.00000000"],["78828.27000000","0.00000000"],["78944.25000000","0.00000000"]]}}
{"rx_ns": 5353762600, "frame": {"e":"depthUpdate","E":1787603062814,"s":"BTCUSDT","U":99076622001,"u":99076622077,"b":[["78720.00000000","0.00849000"],["78719.99000000","0.00063000"],["78719.07000000","0.00000000"],["78718.00000000","0.02607000"],["78717.07000000","0.04781000"],["78716.60000000","0.01466000"],["78716.00000000","0.02407000"],["78715.99000000","0.00211000"],["78715.88000000","0.00000000"],["78715.34000000","0.02440000"],["78714.08000000","0.02926000"],["78714.00000000","0.02407000"],["78712.82000000","0.02926000"],["78703.25000000","0.02514000"],["78702.23000000","0.02600000"],["78701.43000000","0.02800000"],["78701.34000000","0.02800000"],["78682.00000000","0.72400000"],["78645.01000000","0.02600000"],["78644.38000000","0.02800000"],["78644.29000000","0.02800000"],["78590.25000000","0.00000000"],["78515.45000000","0.00007000"],["78511.73000000","0.00000000"],["70848.00000000","0.00032000"]],"a":[["78720.01000000","3.37799000"],["78721.26000000","0.00014000"],["78721.27000000","0.03925000"],["78722.00000000","0.02182000"],["78722.01000000","0.73229000"],["78722.52000000","0.00007000"],["78722.53000000","0.04709000"],["78722.59000000","0.05403000"],["78723.99000000","0.00000000"],["78724.00000000","3.12467000"],["78724.01000000","0.33470000"],["78724.36000000","0.02000000"],["78724.58000000","0.00000000"],["78724.61000000","0.08465000"],["78724.62000000","0.17273000"],["78725.87000000","0.02161000"],["78725.90000000","0.00157000"],["78727.13000000","0.07514000"],["78728.24000000","0.02000000"],["78728.32000000","0.13705000"],["78728.80000000","0.38092000"],["78728.95000000","0.02000000"],["78729.02000000","0.02000000"],["78729.68000000","0.12122000"],["78734.71000000","0.00000000"],["78760.00000000","0.12923000"],["78764.92000000","0.01155000"],["78875.83000000","0.00406000"],["78951.38000000","0.11369000"],["78999.79000000","0.00000000"]]}}
{"rx_ns": 5453509600, "frame": {"e":"depthUpdate","E":1787603062914,"s":"BTCUSDT","U":99076622078,"u":99076622164,"b":[["78719.88000000","0.00007000"],["78718.37000000","0.00000000"],["78717.51000000","0.00038000"],["78715.99000000","0.00169000"],["78701.43000000","0.05000000"],["78697.43000000","0.02000000"],["78692.98000000","0.38127000"],["78688.87000000","0.51640000"],["78674.98000000","0.63559000"],["78657.10000000","0.02400000"],["78653.97000000","0.02400000"],["78652.39000000","0.02000000"],["78644.52000000","0.02200000"],["78644.38000000","0.00000000"],["78640.87000000","0.00000000"],["78498.88000000","0.00000000"],["78326.40000000","0.01000000"],["77934.76000000","0.01000000"],["77545.09000000","0.01000000"],["77157.36000000","0.01000000"],["76771.58000000","0.01000000"],["76387.72000000","0.01000000"],["76005.78000000","0.05000000"],["75625.75000000","0.01000000"],["75247.62000000","0.01000000"],["74871.38000000","0.01000000"],["74497.03000000","0.01000000"],["74124.54000000","0.01000000"],["73753.92000000","0.01000000"],["73385.15000000","0.01000000"],["73018.22000000","0.01000000"],["70848.00000000","0.00048000"]],"a":[["78720.01000000","2.93743000"],["78721.25000000","0.00007000"],["78721.26000000","0.31780000"],["78722.52000000","0.00000000"],["78724.00000000","1.90515000"],["78724.61000000","0.07830000"],["78726.16000000","0.00000000"],["78728.11000000","0.02000000"],["78728.88000000","0.02000000"],["78729.65000000","0.00227000"],["78731.27000000","0.00000000"],["78731.28000000","0.02014000"],["78732.85000000","0.02000000"],["78732.90000000","0.02000000"],["78737.95000000","0.00000000"],["78739.01000000","0.00000000"],["78739.99000000","0.43584000"],["78747.98000000","0.00000000"],["78785.31000000","0.00000000"],["78790.94000000","1.21952000"],["78818.38000000","0.04789000"],["78824.58000000","0.00012000"],["78826.49000000","0.00000000"],["78827.53000000","0.00000000"],["78828.58000000","0.00406000"],["78830.72000000","0.00019000"],["78834.72000000","0.00000000"],["78840.82000000","0.00000000"],["79113.62000000","0.01000000"],["79509.18000000","0.01000000"],["79906.73000000","0.01000000"],["80306.26000000","0.01000000"],["80707.79000000","0.01000000"],["81111.33000000","0.01000000"],["81516.89000000","0.01000000"],["81924.47000000","0.01000000"],["82334.10000000","0.01000000"],["82745.77000000","0.01000000"],["83159.50000000","0.01000000"],["83575.29000000","0.01000000"],["83993.17000000","0.01000000"],["84413.14000000","0.01000000"],["84835.20000000","0.01000000"]]}}
{"rx_ns": 5554148400, "frame": {"e":"depthUpdate","E":1787603063014,"s":"BTCUSDT","U":99076622165,"u":99076622215,"b":[["78720.00000000","0.00894000"],["78717.51000000","0.00000000"],["78706.19000000","0.00635000"],["78706.18000000","0.00000000"],["78704.65000000","0.00635000"],["78697.50000000","0.02000000"],["78693.04000000","0.00000000"],["78692.74000000","0.00000000"],["78686.48000000","0.00635000"],["78653.20000000","0.02000000"],["78652.33000000","0.02200000"],["78644.52000000","0.00000000"],["78640.89000000","0.02000000"],["78520.83000000","0.00000000"],["78510.34000000","0.00778000"],["70849.80000000","0.00000000"],["70849.79000000","0.00009000"],["70848.00000000","0.00064000"],["62976.00000000","0.00031000"]],"a":[["78720.01000000","2.94530000"],["78721.24000000","0.00635000"],["78721.26000000","0.31787000"],["78723.79000000","0.04709000"],["78723.99000000","1.21952000"],["78724.01000000","0.33463000"],["78724.35000000","0.00635000"],["78726.00000000","0.00703000"],["78728.00000000","0.36924000"],["78730.00000000","0.00700000"],["78732.00000000","0.00700000"],["78732.08000000","0.02000000"],["78732.86000000","0.02600000"],["78732.90000000","0.04000000"],["78742.82000000","0.00000000"],["78743.59000000","0.00000000"],["78745.97000000","0.00000000"],["78747.53000000","0.00000000"],["78747.59000000","0.00000000"],["78790.94000000","0.00000000"],["78808.29000000","2.13744000"],["78809.50000000","0.00008000"],["78836.82000000","0.00031000"],["78840.30000000","0.00000000"],["78946.71000000","0.00406000"],["78967.68000000","3.41333000"],["79055.28000000","0.00000000"],["79058.73000000","0.00000000"]]}}
{"rx_ns": 5653264700, "frame": {"e":"depthUpdate","E":1787603063114,"s":"BTCUSDT","U":99076622216,"u":99076622249,"b":[["78720.00000000","0.00901000"],["78712.11000000","0.12704000"],["78692.52000000","0.28465000"],["78645.01000000","0.00000000"],["78640.89000000","0.00000000"],["78631.80000000","0.00663000"],["78533.91000000","4.41894000"],["78027.38000000","0.00000000"],["70848.00000000","0.00096000"]],"a":[["78720.01000000","2.94537000"],["78723.79000000","0.04702000"],["78727.74000000","0.00000000"],["78727.85000000","0.12701000"],["78728.32000000","0.13698000"],["78734.00000000","0.00700000"],["78736.00000000","0.00707000"],["78736.01000000","0.00000000"],["78738.00000000","0.01200000"],["78740.00000000","0.07747000"],["78742.00000000","0.03361000"],["78744.00000000","0.01200000"],["78746.00000000","0.03361000"],["78747.55000000","0.00000000"],["78747.60000000","0.00000000"],["78748.00000000","0.01200000"],["78750.00000000","0.10731000"],["78752.00000000","0.01200000"],["78754.00000000","0.01200000"],["78756.00000000","0.01200000"],["78758.00000000","0.74700000"],["78784.49000000","0.00000000"],["78817.61000000","0.00025000"],["78833.63000000","0.00027000"]]}}
{"rx_ns": 5753537500, "frame": {"e":"depthUpdate","E":1787603063214,"s":"BTCUSDT","U":99076622250,"u":99076622274,"b":[["78716.13000000","0.00045000"],["78712.82000000","0.02919000"],["78692.52000000","0.00000000"],["78681.67000000","0.00274000"],["78665.26000000","0.02787000"],["78658.96000000","0.02400000"],["78656.00000000","0.02800000"],["78652.80000000","0.00000000"],["78646.46000000","0.02363000"],["78644.29000000","0.00000000"],["62976.00000000","0.00000000"]],"a":[["78720.01000000","2.94424000"],["78721.24000000","0.00642000"],["78724.00000000","1.91215000"],["78726.00000000","0.01403000"],["78728.00000000","0.37624000"],["78730.00000000","0.01400000"],["78732.00000000","0.01400000"],["78732.10000000","0.02000000"],["78734.00000000","0.01400000"],["78736.85000000","0.12103000"],["78746.73000000","0.00000000"],["78757.69000000","0.00406000"],["78785.28000000","0.00000000"],["78818.38000000","0.02789000"]]}}
{"rx_ns": 5853570800, "frame": {"e":"depthUpdate","E":1787603063314,"s":"BTCUSDT","U":99076622275,"u":99076622294,"b":[["78629.16000000","0.02115000"],["70848.00000000","0.00128000"],["62987.00000000","0.00000000"],["41465.30000000","0.00036000"]],"a":[["78736.00000000","0.01407000"],["78738.00000000","0.01900000"],["78740.00000000","0.08447000"],["78742.00000000","0.04061000"],["78744.00000000","0.01900000"],["78746.00000000","0.04061000"],["78746.77000000","0.00000000"],["78748.00000000","0.01900000"],["78750.00000000","0.11431000"],["78752.00000000","0.01900000"],["78754.00000000","0.01900000"],["78756.00000000","0.01900000"],["78758.00000000","0.75400000"],["78792.86000000","0.02000000"]]}}
{"rx_ns": 5955618900, "frame": {"e":"depthUpdate","E":1787603063414,"s":"BTCUSDT","U":99076622295,"u":99076622333,"b":[["78720.00000000","0.00908000"],["78700.34000000","0.00000000"],["78526.29000000","0.00413000"],["78326.40000000","0.00000000"],["77934.76000000","0.00000000"],["77545.09000000","0.00000000"],["77157.36000000","0.00000000"],["76771.58000000","0.00000000"],["76387.72000000","0.00000000"],["76005.78000000","0.04000000"],["75625.75000000","0.00000000"],["75247.62000000","0.00000000"],["74871.38000000","0.00000000"],["74497.03000000","0.00000000"],["74124.54000000","0.00000000"],["73753.92000000","0.00000000"],["73385.15000000","0.00000000"],["73018.22000000","0.00000000"],["70848.00000000","0.00144000"]],"a":[["78720.01000000","3.27995000"],["78729.72000000","0.00000000"],["78729.76000000","0.00000000"],["78746.00000000","0.74061000"],["78747.58000000","0.00000000"],["79113.62000000","0.00000000"],["79509.18000000","0.00000000"],["79906.73000000","0.00000000"],["80306.26000000","0.00000000"],["80707.79000000","0.00000000"],["81111.33000000","0.00000000"],["81516.89000000","0.00000000"],["81924.47000000","0.00000000"],["82334.10000000","0.00000000"],["82745.77000000","0.00000000"],["83159.50000000","0.00000000"],["83575.29000000","0.00000000"],["83993.17000000","0.00000000"],["84413.14000000","0.00000000"],["84835.20000000","0.00000000"]]}}
{"rx_ns": 6052907400, "frame": {"e":"depthUpdate","E":1787603063514,"s":"BTCUSDT","U":99076622334,"u":99076622357,"b":[["78696.34000000","0.00007000"],["78679.29000000","0.34320000"],["78629.16000000","0.00000000"],["70848.00000000","0.00160000"],["62976.00000000","0.00031000"]],"a":[["78720.01000000","2.94437000"],["78721.45000000","0.00007000"],["78743.58000000","0.00007000"],["78746.00000000","0.74561000"],["78748.00000000","0.02400000"],["78750.00000000","0.11931000"],["78752.00000000","0.02400000"],["78754.00000000","0.02400000"],["78756.00000000","0.02400000"],["78758.00000000","0.72400000"]]}}
{"rx_ns": 6153190100, "frame": {"e":"depthUpdate","E":1787603063614,"s":"BTCUSDT","U":99076622358,"u":99076622367,"b":[["78720.00000000","0.00914000"],["78719.99000000","0.00076000"],["78719.98000000","0.00013000"],["78696.45000000","0.12721000"],["78683.00000000","0.70000000"],["78659.48000000","1.03354000"],["62976.00000000","0.00000000"]],"a":[["78738.90000000","0.00007000"],["78797.07000000","0.00406000"]]}}
{"rx_ns": 6254913900, "frame": {"e":"depthUpdate","E":1787603063714,"s":"BTCUSDT","U":99076622368,"u":99076622741,"b":[["78720.00000000","0.00000000"],["78719.99000000","0.00000000"],["78719.98000000","0.00000000"],["78719.88000000","0.00000000"],["78719.67000000","0.00000000"],["78718.01000000","0.00000000"],["78718.00000000","0.00000000"],["78717.44000000","0.00000000"],["78717.08000000","0.00000000"],["78717.07000000","0.00000000"],["78716.61000000","0.00000000"],["78716.60000000","0.00000000"],["78716.13000000","0.00000000"],["78716.01000000","0.00000000"],["78716.00000000","0.00000000"],["78715.99000000","0.00000000"],["78715.80000000","0.00000000"],["78715.35000000","0.00000000"],["78715.34000000","0.00000000"],["78715.21000000","0.00000000"],["78715.00000000","0.00000000"],["78714.35000000","0.00000000"],["78714.08000000","0.00000000"],["78714.01000000","0.00000000"],["78714.00000000","0.42023000"],["78713.99000000","0.00468000"],["78713.82000000","0.00007000"],["78713.22000000","0.00000000"],["78712.83000000","0.00000000"],["78712.82000000","0.00007000"],["78712.80000000","0.00000000"],["78712.12000000","0.00000000"],["78712.11000000","0.00007000"],["78712.01000000","0.00014000"],["78712.00000000","0.02407000"],["78711.06000000","0.00014000"],["78711.05000000","0.04727000"],["78710.86000000","0.00000000"],["78710.17000000","0.00000000"],["78710.04000000","0.00014000"],["78710.03000000","1.21959000"],["78708.24000000","0.00014000"],["78708.23000000","0.21944000"],["78708.09000000","0.00007000"],["78706.67000000","0.00007000"],["78706.56000000","0.26053000"],["78706.19000000","0.00000000"],["78706.17000000","0.00007000"],["78706.00000000","0.15112000"],["78704.66000000","0.00635000"],["78704.65000000","0.00000000"],["78704.56000000","0.00007000"],["78704.31000000","0.00048000"],["78703.44000000","0.08576000"],["78702.46000000","0.00635000"],["78701.41000000","0.00007000"],["78699.61000000","0.00000000"],["78699.17000000","0.02000000"],["78697.44000000","0.00000000"],["78695.47000000","0.00000000"],["78681.53000000","0.00000000"],["78680.00000000","0.08942000"],["78677.51000000","0.04452000"],["78677.10000000","0.00014000"],["78677.08000000","0.00000000"],["78674.00000000","0.03400000"],["78672.65000000","0.68310000"],["78665.26000000","0.00000000"],["78664.45000000","0.04841000"],["78662.01000000","0.00000000"],["78655.50000000","0.00015000"],["78652.01000000","0.00317000"],["78646.46000000","0.00000000"],["78645.89000000","0.91285000"],["78640.68000000","0.00000000"],["78630.01000000","0.00315000"],["78608.80000000","0.00007000"],["78581.77000000","0.02541000"],["78562.79000000","0.00000000"],["78540.83000000","1.20000000"],["78511.61000000","0.00079000"],["78507.68000000","0.00007000"],["78383.63000000","0.05082000"],["78232.00000000","0.00015000"],["70848.00000000","0.00000000"],["70842.60000000","0.00032000"],["64089.97000000","0.00000000"]],"a":[["78714.01000000","2.04735000"],["78714.02000000","0.00020000"],["78714.03000000","0.00013000"],["78714.09000000","0.00000000"],["78715.22000000","0.00000000"],["78715.35000000","0.00000000"],["78715.80000000","0.00014000"],["78716.00000000","0.00000000"],["78716.01000000","0.00000000"],["78716.02000000","0.00000000"],["78716.56000000","0.00522000"],["78716.57000000","0.05452000"],["78716.61000000","0.00000000"],["78717.08000000","0.00000000"],["78717.86000000","0.00027000"],["78718.01000000","0.00000000"],["78718.02000000","0.00000000"],["78719.54000000","0.00014000"],["78719.55000000","0.31780000"],["78719.56000000","0.25402000"],["78719.67000000","0.00014000"],["78719.68000000","0.00000000"],["78719.89000000","0.00000000"],["78719.99000000","0.00014000"],["78720.00000000","0.26093000"],["78720.01000000","0.40070000"],["78720.02000000","0.00000000"],["78720.03000000","0.00000000"],["78721.25000000","0.00000000"],["78721.26000000","0.00014000"],["78721.27000000","0.00007000"],["78721.91000000","0.12702000"],["78721.98000000","0.00137000"],["78721.99000000","0.00000000"],["78722.00000000","0.02175000"],["78722.01000000","0.70229000"],["78722.53000000","0.00007000"],["78722.58000000","0.00000000"],["78722.59000000","0.00007000"],["78723.48000000","0.00007000"],["78723.79000000","0.00000000"],["78723.83000000","0.00007000"],["78724.00000000","1.91715000"],["78724.01000000","0.05068000"],["78724.62000000","0.07134000"],["78725.20000000","0.00007000"],["78725.88000000","0.00014000"],["78726.24000000","0.00000000"],["78726.63000000","0.00007000"],["78726.68000000","0.00000000"],["78726.78000000","0.00000000"],["78727.13000000","0.07500000"],["78727.14000000","0.00000000"],["78727.19000000","0.00000000"],["78727.42000000","0.00000000"],["78727.76000000","0.00007000"],["78727.84000000","0.00227000"],["78728.02000000","0.00000000"],["78729.65000000","0.00000000"],["78729.76000000","0.11206000"],["78730.47000000","0.04857000"],["78732.93000000","0.00000000"],["78733.37000000","0.06588000"],["78735.12000000","0.00000000"],["78735.34000000","0.07611000"],["78735.76000000","0.00000000"],["78736.08000000","0.00000000"],["78738.34000000","0.00000000"],["78740.31000000","0.00000000"],["78742.53000000","0.39822000"],["78743.00000000","0.00000000"],["78744.60000000","0.00000000"],["78745.51000000","0.00000000"],["78752.73000000","0.68241000"],["78754.50000000","0.00000000"],["78758.37000000","0.00000000"],["78761.10000000","0.00000000"],["78781.90000000","0.00000000"],["78783.95000000","0.00000000"],["78827.83000000","0.00000000"],["78942.11000000","0.00000000"]]}}
{"rx_ns": 6353176800, "frame": {"e":"depthUpdate","E":1787603063814,"s":"BTCUSDT","U":99076622742,"u":99076622834,"b":[["78714.00000000","0.42092000"],["78713.99000000","0.00475000"],["78713.82000000","0.00000000"],["78712.82000000","0.00000000"],["78712.11000000","0.00000000"],["78712.00000000","0.02407000"],["78711.05000000","0.04734000"],["78710.00000000","0.02407000"],["78709.81000000","0.01332000"],["78708.55000000","0.02220000"],["78708.23000000","0.21951000"],["78708.00000000","0.02414000"],["78707.29000000","0.02664000"],["78706.66000000","1.90522000"],["78706.56000000","0.26060000"],["78706.03000000","0.02664000"],["78688.03000000","0.13492000"],["78597.13000000","0.00406000"],["78588.88000000","0.00000000"],["78582.27000000","0.08810000"],["78503.75000000","0.00023000"],["78499.82000000","0.00000000"],["70842.60000000","0.00048000"]],"a":[["78714.01000000","2.07714000"],["78715.26000000","0.00014000"],["78715.27000000","0.04131000"],["78716.52000000","0.00007000"],["78716.53000000","0.04958000"],["78716.56000000","0.00529000"],["78716.57000000","0.05459000"],["78717.79000000","0.04958000"],["78719.55000000","0.31773000"],["78719.56000000","0.25409000"],["78719.99000000","0.00000000"],["78720.00000000","0.00007000"],["78720.01000000","0.17640000"],["78720.75000000","0.38092000"],["78721.24000000","0.00635000"],["78721.26000000","0.00007000"],["78721.27000000","0.00000000"],["78722.00000000","0.02168000"],["78722.01000000","0.70222000"],["78722.53000000","0.00000000"],["78722.59000000","0.00000000"],["78725.88000000","0.00007000"],["78726.00000000","0.01903000"],["78726.01000000","0.00000000"],["78728.00000000","0.38124000"],["78728.80000000","0.00000000"],["78730.00000000","0.01900000"],["78732.00000000","0.01900000"],["78734.00000000","0.01900000"],["78736.00000000","0.01907000"],["78738.00000000","0.02400000"],["78740.00000000","0.08947000"],["78742.00000000","0.04561000"],["78744.00000000","0.02400000"],["78752.52000000","0.00000000"],["78754.00000000","0.03400000"],["78760.00000000","0.11923000"],["78935.31000000","0.00000000"],["78938.18000000","0.00000000"]]}}
{"rx_ns": 6459196400, "frame": {"e":"depthUpdate","E":1787603063914,"s":"BTCUSDT","U":99076622835,"u":99076622920,"b":[["78710.00000000","0.02407000"],["78709.81000000","0.01339000"],["78708.55000000","0.02227000"],["78708.06000000","0.00007000"],["78708.00000000","0.02414000"],["78706.66000000","1.90515000"],["78706.56000000","0.26053000"],["78669.36000000","0.00007000"],["78666.12000000","0.00007000"],["78506.51000000","0.01990000"],["78320.43000000","0.01000000"],["77928.82000000","0.01000000"],["77539.18000000","0.01000000"],["77151.48000000","0.01000000"],["76765.73000000","0.01000000"],["76381.90000000","0.01000000"],["75999.99000000","0.01000000"],["75619.99000000","0.01000000"],["75241.89000000","0.01000000"],["74865.68000000","0.01000000"],["74491.35000000","0.01000000"],["74118.89000000","0.01000000"],["73748.30000000","0.01000000"],["73379.56000000","0.01000000"],["73012.66000000","0.01000000"],["70842.60000000","0.00064000"],["64169.97000000","0.00744000"]],"a":[["78714.01000000","2.07814000"],["78715.27000000","0.04138000"],["78716.52000000","0.00014000"],["78716.53000000","0.04965000"],["78716.57000000","0.05459000"],["78717.78000000","0.00014000"],["78717.79000000","0.04965000"],["78719.56000000","0.25395000"],["78720.00000000","0.00000000"],["78720.01000000","0.17533000"],["78721.36000000","0.00192000"],["78747.91000000","0.02000000"],["78748.68000000","0.02000000"],["78751.08000000","0.02000000"],["78752.64000000","0.02000000"],["78752.70000000","0.02000000"],["78792.88000000","0.02000000"],["78796.88000000","0.00000000"],["78818.57000000","0.00012000"],["78824.58000000","0.00000000"],["78824.71000000","0.00019000"],["78830.72000000","0.00000000"],["78836.82000000","0.00000000"],["78849.33000000","0.01990000"],["78957.12000000","0.11388000"],["78959.21000000","0.00000000"],["78989.96000000","0.02396000"],["78990.31000000","0.00489000"],["79007.02000000","0.00000000"],["79045.06000000","0.00000000"],["79045.94000000","0.00000000"],["79107.59000000","0.01000000"],["79503.12000000","0.01000000"],["79900.64000000","0.01000000"],["80300.14000000","0.01000000"],["80701.64000000","0.01000000"],["81105.15000000","0.01000000"],["81510.68000000","0.01000000"],["81918.23000000","0.01000000"],["82327.82000000","0.01000000"],["82739.46000000","0.01000000"],["83153.16000000","0.01000000"],["83568.92000000","0.01000000"],["83986.77000000","0.01000000"],["84406.70000000","0.01000000"],["84828.73000000","0.01000000"]]}}
{"rx_ns": 6554294500, "frame": {"e":"depthUpdate","E":1787603064014,"s":"BTCUSDT","U":99076622921,"u":99076622958,"b":[["78704.66000000","0.00000000"],["78703.58000000","0.00635000"],["78698.26000000","0.00007000"],["78698.04000000","0.00007000"],["78675.85000000","0.00000000"],["78644.36000000","0.00000000"],["78597.13000000","0.00000000"],["78582.26000000","0.00000000"],["78571.48000000","0.00127000"],["78560.78000000","0.00000000"],["78551.73000000","0.00127000"],["78526.29000000","0.00007000"],["70842.60000000","0.00080000"],["62971.20000000","0.00031000"]],"a":[["78714.01000000","2.08006000"],["78715.94000000","0.00007000"],["78716.57000000","0.05466000"],["78717.76000000","0.00137000"],["78717.77000000","0.00649000"],["78717.78000000","0.31781000"],["78719.54000000","0.00000000"],["78719.55000000","0.00007000"],["78721.24000000","0.00000000"],["78721.36000000","0.00000000"],["78721.45000000","0.00000000"],["78721.98000000","0.00000000"],["78751.87000000","0.02000000"],["78752.64000000","0.04600000"],["78752.69000000","0.02000000"],["78757.69000000","0.00000000"],["78763.38000000","0.00316000"],["78773.15000000","0.00000000"],["78785.33000000","0.00315000"],["78792.88000000","0.00000000"],["78795.99000000","0.00000000"],["78797.07000000","0.00000000"],["78828.58000000","0.00000000"],["78830.81000000","0.00031000"],["78841.99000000","0.00127000"],["78851.99000000","0.00000000"],["78863.62000000","0.00127000"],["78873.99000000","0.00000000"],["78875.83000000","0.00000000"],["78946.71000000","0.00000000"]]}}
{"rx_ns": 6652955100, "frame": {"e":"depthUpdate","E":1787603064114,"s":"BTCUSDT","U":99076622959,"u":99076622991,"b":[["78714.00000000","0.42092000"],["78713.99000000","0.00468000"],["78708.64000000","0.00000000"],["78708.58000000","0.00327000"],["78691.29000000","0.12707000"],["78005.57000000","0.00010000"],["70842.60000000","0.00112000"],["62500.00000000","32.44062000"],["60000.00000000","176.66940000"]],"a":[["78714.01000000","2.09293000"],["78714.04000000","0.00014000"],["78714.05000000","0.06350000"],["78714.08000000","0.00323000"],["78716.57000000","0.05459000"],["78717.77000000","0.00656000"],["78717.78000000","0.31774000"],["78717.79000000","0.04958000"],["78718.02000000","0.00328000"],["78719.55000000","0.00000000"],["78720.00000000","0.00400000"],["78725.88000000","0.00000000"],["78729.68000000","0.11793000"],["78734.01000000","0.00007000"],["78769.92000000","0.00000000"],["78806.95000000","0.00000000"]]}}
{"rx_ns": 6753779100, "frame": {"e":"depthUpdate","E":1787603064214,"s":"BTCUSDT","U":99076622992,"u":99076623017,"b":[["78714.00000000","0.42099000"],["78676.15000000","0.00000000"],["78675.83000000","0.00000000"],["78675.65000000","0.00000000"],["78671.62000000","0.09447000"],["78645.64000000","0.02396000"],["78610.60000000","2.77171000"],["70842.60000000","0.00128000"],["62971.20000000","0.00000000"],["41465.30000000","0.00000000"]],"a":[["78714.01000000","2.09323000"],["78724.62000000","0.07127000"],["78742.50000000","0.09645000"],["78750.65000000","0.00000000"],["78751.88000000","0.02000000"],["78796.03000000","0.02000000"],["78806.14000000","0.00000000"],["78827.47000000","0.00000000"]]}}
{"rx_ns": 6853485100, "frame": {"e":"depthUpdate","E":1787603064314,"s":"BTCUSDT","U":99076623018,"u":99076623038,"b":[["78708.98000000","0.00000000"],["70842.60000000","0.00144000"],["62979.00000000","0.00000000"],["62971.00000000","0.00000000"]],"a":[["78720.01000000","0.13394000"],["78732.76000000","0.00007000"],["78742.50000000","0.00000000"],["78744.01000000","0.00000000"],["78777.98000000","0.09660000"],["78780.01000000","0.00000000"],["78796.03000000","0.00000000"],["78822.84000000","0.00000000"],["78825.89000000","0.00000000"]]}}
{"rx_ns": 6956637100, "frame": {"e":"depthUpdate","E":1787603064414,"s":"BTCUSDT","U":99076623039,"u":99076623077,"b":[["78629.16000000","0.00000000"],["78582.27000000","0.00000000"],["78320.43000000","0.00000000"],["77928.82000000","0.00000000"],["77539.18000000","0.00000000"],["77151.48000000","0.00000000"],["76765.73000000","0.00000000"],["76381.90000000","0.00000000"],["75999.99000000","0.00000000"],["75619.99000000","0.00000000"],["75241.89000000","0.00000000"],["74865.68000000","0.00000000"],["74491.35000000","0.00000000"],["74118.89000000","0.00000000"],["73748.30000000","0.00000000"],["73379.56000000","0.00000000"],["73012.66000000","0.00000000"],["70842.60000000","0.00160000"],["70842.00000000","0.00235000"]],"a":[["78714.01000000","2.09641000"],["78777.98000000","0.00000000"],["79107.59000000","0.00000000"],["79503.12000000","0.00000000"],["79900.64000000","0.00000000"],["80300.14000000","0.00000000"],["80701.64000000","0.00000000"],["81105.15000000","0.00000000"],["81510.68000000","0.00000000"],["81918.23000000","0.00000000"],["82327.82000000","0.00000000"],["82739.46000000","0.00000000"],["83153.16000000","0.00000000"],["83568.92000000","0.00000000"],["83986.77000000","0.00000000"],["84406.70000000","0.00000000"],["84828.73000000","0.00000000"]]}}
{"rx_ns": 7063154400, "frame": {"e":"depthUpdate","E":1787603064514,"s":"BTCUSDT","U":99076623078,"u":99076623237,"b":[["78714.00000000","3.62735000"],["78713.99000000","0.00433000"],["78713.27000000","0.31764000"],["78713.11000000","0.03224000"],["78710.04000000","0.36238000"],["78708.24000000","0.00000000"],["78708.06000000","0.00014000"],["78707.97000000","0.00000000"],["78707.36000000","0.03224000"],["78706.67000000","0.00000000"],["78706.56000000","0.00000000"],["78706.37000000","0.02000000"],["78705.91000000","0.00000000"],["78704.65000000","0.00635000"],["78703.58000000","0.00000000"],["78702.46000000","0.00000000"],["78701.35000000","0.00000000"],["78699.17000000","0.00000000"],["78696.34000000","0.00000000"],["78690.34000000","0.00007000"],["78679.43000000","0.02488000"],["78673.34000000","0.34323000"],["78669.36000000","0.00000000"],["78666.12000000","0.00014000"],["78594.41000000","0.80000000"],["78584.87000000","0.04474000"],["78317.01000000","0.00000000"],["70842.60000000","0.00144000"],["70842.00000000","0.00225000"],["62971.20000000","0.00031000"]],"a":[["78714.01000000","1.38216000"],["78714.05000000","0.00007000"],["78714.08000000","0.00000000"],["78715.41000000","0.00000000"],["78716.00000000","0.00237000"],["78716.56000000","0.00021000"],["78716.57000000","0.05466000"],["78717.75000000","0.00000000"],["78717.76000000","0.00000000"],["78717.77000000","0.00007000"],["78717.78000000","0.00014000"],["78717.79000000","0.04965000"],["78717.86000000","0.00000000"],["78718.00000000","0.00500000"],["78718.02000000","0.00000000"],["78719.54000000","0.00000000"],["78719.55000000","0.00000000"],["78719.56000000","0.00000000"],["78720.00000000","0.00900000"],["78720.01000000","0.10077000"],["78720.03000000","0.12000000"],["78720.74000000","0.00000000"],["78721.25000000","0.00000000"],["78721.90000000","0.00000000"],["78722.00000000","0.00007000"],["78722.01000000","0.22222000"],["78723.47000000","0.00645000"],["78723.98000000","0.00000000"],["78723.99000000","0.00000000"],["78724.00000000","0.01200000"],["78724.35000000","0.00000000"],["78724.36000000","0.00000000"],["78724.60000000","0.31767000"],["78725.96000000","0.02000000"],["78727.84000000","0.00000000"],["78728.00000000","0.01900000"],["78728.30000000","0.00635000"],["78729.07000000","0.00635000"],["78729.66000000","0.00000000"],["78732.84000000","1.21952000"],["78733.53000000","0.00000000"],["78735.33000000","0.00227000"],["78737.58000000","0.00007000"],["78743.58000000","0.00000000"],["78757.20000000","0.34286000"],["78769.50000000","0.09457000"],["78790.66000000","1.90515000"],["78790.94000000","1.21952000"],["78800.64000000","1.90515000"],["78827.54000000","0.00000000"],["78827.83000000","0.21930000"]]}}
{"rx_ns": 7155282200, "frame": {"e":"depthUpdate","E":1787603064614,"s":"BTCUSDT","U":99076623238,"u":99076623339,"b":[["78714.00000000","3.64809000"],["78713.99000000","0.00460000"],["78713.98000000","0.00013000"],["78713.28000000","0.00014000"],["78713.27000000","0.31778000"],["78713.12000000","0.00000000"],["78713.11000000","0.00007000"],["78711.93000000","0.00014000"],["78711.05000000","0.04734000"],["78710.05000000","0.00021000"],["78710.04000000","0.36231000"],["78708.55000000","0.02220000"],["78708.23000000","0.21937000"],["78708.00000000","0.02407000"],["78706.00000000","0.15105000"],["78704.31000000","0.00000000"],["78673.23000000","0.00000000"],["78659.20000000","0.00400000"],["78656.00000000","0.02400000"],["78584.87000000","0.04717000"],["70842.60000000","0.00176000"],["70842.00000000","0.00245000"],["62971.20000000","0.00000000"]],"a":[["78714.01000000","1.60086000"],["78714.04000000","0.00000000"],["78714.05000000","0.00000000"],["78716.53000000","0.04965000"],["78716.56000000","0.00014000"],["78716.57000000","0.05452000"],["78717.77000000","0.00000000"],["78717.78000000","0.00014000"],["78717.79000000","0.04965000"],["78718.00000000","0.00507000"],["78719.86000000","0.00027000"],["78720.00000000","0.00914000"],["78720.01000000","0.10091000"],["78720.03000000","0.12007000"],["78722.00000000","0.00507000"],["78724.00000000","0.01700000"],["78724.01000000","0.05075000"],["78725.96000000","0.00000000"],["78726.00000000","0.02403000"],["78726.51000000","0.00048000"],["78727.76000000","0.02007000"],["78728.00000000","0.02400000"],["78730.00000000","0.02400000"],["78730.71000000","0.00007000"],["78732.00000000","0.02400000"],["78732.01000000","0.00192000"],["78734.00000000","0.02400000"],["78736.00000000","0.02407000"],["78818.38000000","0.00000000"]]}}
{"rx_ns": 7254648800, "frame": {"e":"depthUpdate","E":1787603064714,"s":"BTCUSDT","U":99076623340,"u":99076623375,"b":[["78714.00000000","3.64850000"],["78713.99000000","0.00453000"],["78713.27000000","0.31778000"],["78713.11000000","0.00000000"],["78710.68000000","0.00325000"],["78710.04000000","0.36238000"],["78708.23000000","0.00007000"],["78704.64000000","0.00000000"],["78698.99000000","0.00406000"],["78649.52000000","0.00000000"],["78646.78000000","0.00107000"],["78570.72000000","0.00000000"],["78568.07000000","0.00134000"],["78491.93000000","0.00000000"],["78489.36000000","0.00134000"],["78413.14000000","0.00000000"],["78410.65000000","0.00134000"],["78331.94000000","0.00134000"],["70842.60000000","0.00176000"],["70842.00000000","0.00225000"]],"a":[["78714.01000000","1.38156000"],["78717.02000000","0.23200000"],["78722.01000000","0.22229000"],["78722.26000000","0.38092000"],["78739.93000000","0.00406000"],["78744.00000000","0.72400000"],["78746.00000000","0.04561000"],["78772.72000000","0.00107000"],["78779.30000000","0.00406000"],["78820.13000000","0.02789000"],["78851.43000000","0.00134000"],["78930.14000000","0.00134000"],["79008.85000000","0.00134000"],["79087.56000000","0.00134000"]]}}
{"rx_ns": 7355753600, "frame": {"e":"depthUpdate","E":1787603064814,"s":"BTCUSDT","U":99076623376,"u":99076623390,"b":[["78714.00000000","3.64405000"],["78711.07000000","0.00635000"],["78628.16000000","0.00406000"],["70842.60000000","0.00176000"]],"a":[["78716.57000000","0.05459000"],["78717.01000000","0.00014000"],["78717.02000000","0.23207000"],["78720.00000000","0.00907000"],["78720.01000000","0.09903000"],["78720.03000000","0.12000000"],["78730.70000000","0.00191000"]]}}
{"rx_ns": 7464472800, "frame": {"e":"depthUpdate","E":1787603064914,"s":"BTCUSDT","U":99076623391,"u":99076623435,"b":[["78712.00000000","0.02407000"],["78710.68000000","0.00000000"],["78520.83000000","0.00778000"],["78510.34000000","0.00000000"],["78320.43000000","0.01000000"],["77928.82000000","0.01000000"],["77606.60000000","0.00000000"],["77539.18000000","0.01000000"],["77151.48000000","0.01000000"],["76900.00000000","4.18743000"],["76765.73000000","0.01000000"],["76381.90000000","0.01000000"],["75999.99000000","0.01000000"],["75619.99000000","0.01000000"],["75241.89000000","0.01000000"],["74865.68000000","0.01000000"],["74491.35000000","0.01000000"],["74118.89000000","0.01000000"],["73748.30000000","0.01000000"],["73379.56000000","0.01000000"],["73012.66000000","0.01000000"],["70842.60000000","0.00192000"]],"a":[["78714.01000000","1.60203000"],["78720.01000000","0.09896000"],["78720.75000000","0.00000000"],["78744.00000000","0.02400000"],["79107.59000000","0.01000000"],["79387.87000000","0.00300000"],["79503.12000000","0.01000000"],["79900.64000000","0.01000000"],["80300.14000000","0.01000000"],["80701.64000000","0.01000000"],["81105.15000000","0.01000000"],["81510.68000000","0.01000000"],["81918.23000000","0.01000000"],["82327.82000000","0.01000000"],["82739.46000000","0.01000000"],["83153.16000000","0.01000000"],["83568.92000000","0.01000000"],["83986.77000000","0.01000000"],["84406.70000000","0.01000000"],["84828.73000000","0.01000000"]]}}
{"rx_ns": 7553577200, "frame": {"e":"depthUpdate","E":1787603065014,"s":"BTCUSDT","U":99076623436,"u":99076623460,"b":[["78714.00000000","3.64405000"],["78713.99000000","0.00453000"],["78710.67000000","0.00324000"],["78708.24000000","0.00635000"],["78704.65000000","0.00000000"],["70849.79000000","0.00000000"],["70842.60000000","0.00208000"],["62971.20000000","0.00031000"]],"a":[["78714.01000000","1.59930000"],["78717.01000000","0.00000000"],["78717.02000000","0.00007000"],["78720.00000000","0.00914000"],["78721.25000000","0.00508000"],["78723.46000000","0.00000000"],["78723.47000000","0.00137000"],["78723.99000000","0.31765000"],["78724.60000000","0.00000000"],["78858.04000000","0.00406000"],["78938.05000000","0.01990000"],["78975.25000000","0.00000000"]]}}
{"rx_ns": 7656861100, "frame": {"e":"depthUpdate","E":1787603065114,"s":"BTCUSDT","U":99076623461,"u":99076623495,"b":[["78629.16000000","0.02116000"],["70842.60000000","0.00208000"],["70842.00000000","0.00245000"]],"a":[["78714.01000000","1.59991000"],["78714.02000000","0.00069000"],["78716.57000000","0.05452000"],["78717.02000000","0.00000000"],["78720.03000000","0.12007000"],["78722.26000000","0.38099000"],["78724.01000000","0.05068000"],["78811.61000000","0.00025000"],["78817.61000000","0.00000000"]]}}
{"rx_ns": 7753292500, "frame": {"e":"depthUpdate","E":1787603065214,"s":"BTCUSDT","U":99076623496,"u":99076623504,"b":[["78684.00000000","0.72400000"],["78629.16000000","0.00000000"],["78510.11000000","0.00406000"],["70842.60000000","0.00224000"],["70842.00000000","0.00235000"],["62971.20000000","0.00000000"]],"a":[["78714.01000000","1.59891000"],["78719.98000000","0.00321000"]]}}
{"rx_ns": 7853654700, "frame": {"e":"depthUpdate","E":1787603065314,"s":"BTCUSDT","U":99076623505,"u":99076623517,"b":[["70842.60000000","0.00224000"],["70842.00000000","0.00225000"],["62971.00000000","0.00000000"]],"a":[["78714.01000000","1.59828000"],["78714.02000000","0.00076000"],["78723.90000000","0.38092000"],["78734.81000000","0.00007000"],["78751.38000000","0.10000000"]]}}
{"rx_ns": 7953470900, "frame": {"e":"depthUpdate","E":1787603065414,"s":"BTCUSDT","U":99076623518,"u":99076623564,"b":[["78710.04000000","0.36238000"],["78709.87000000","0.00000000"],["78664.96000000","0.00400000"],["78661.94000000","0.00400000"],["78661.75000000","0.00000000"],["78659.64000000","0.00406000"],["78659.20000000","0.00000000"],["78320.43000000","0.00000000"],["77928.82000000","0.00000000"],["77539.18000000","0.00000000"],["77151.48000000","0.00000000"],["76765.73000000","0.00000000"],["76381.90000000","0.00000000"],["75999.99000000","0.00000000"],["75619.99000000","0.00000000"],["75241.89000000","0.00000000"],["74865.68000000","0.00000000"],["74491.35000000","0.00000000"],["74118.89000000","0.00000000"],["73748.30000000","0.00000000"],["73379.56000000","0.00000000"],["73012.66000000","0.00000000"],["70842.60000000","0.00240000"],["41465.30000000","0.00036000"]],"a":[["78722.26000000","0.38106000"],["78727.84000000","1.21952000"],["78790.94000000","0.00000000"],["78915.52000000","0.00011000"],["79107.59000000","0.00000000"],["79503.12000000","0.00000000"],["79900.64000000","0.00000000"],["80300.14000000","0.00000000"],["80701.64000000","0.00000000"],["81105.15000000","0.00000000"],["81510.68000000","0.00000000"],["81918.23000000","0.00000000"],["82327.82000000","0.00000000"],["82739.46000000","0.00000000"],["83153.16000000","0.00000000"],["83568.92000000","0.00000000"],["83986.77000000","0.00000000"],["84406.70000000","0.00000000"],["84828.73000000","0.00000000"]]}}
{"rx_ns": 8054712300, "frame": {"e":"depthUpdate","E":1787603065514,"s":"BTCUSDT","U":99076623565,"u":99076623579,"b":[["78714.00000000","3.64215000"],["78713.27000000","0.31785000"],["78710.67000000","0.00014000"],["78710.66000000","0.26053000"],["78710.04000000","0.36231000"],["78703.28000000","0.00187000"],["78690.34000000","0.00007000"],["70842.00000000","0.00235000"],["62971.20000000","0.00031000"]],"a":[["78721.90000000","0.02161000"],["78737.58000000","0.00007000"],["79231.51000000","0.00087000"]]}}
{"rx_ns": 8155256100, "frame": {"e":"depthUpdate","E":1787603065614,"s":"BTCUSDT","U":99076623580,"u":99076623603,"b":[["78711.07000000","0.00642000"],["78711.05000000","0.04734000"],["78709.81000000","0.01332000"],["78701.43000000","0.02800000"],["78683.92000000","0.00000000"],["78683.00000000","0.00000000"],["78664.21000000","0.00000000"],["70842.60000000","0.00256000"],["70842.00000000","0.00235000"],["62971.20000000","0.00000000"]],"a":[["78714.01000000","1.59835000"],["78715.83000000","0.00014000"],["78715.84000000","0.21816000"],["78720.00000000","0.00907000"],["78728.66000000","0.00007000"],["78728.88000000","0.00000000"],["78748.68000000","0.00000000"],["78773.18000000","0.00000000"],["78928.91000000","0.00406000"],["80187.08000000","0.00034000"]]}}
{"rx_ns": 8253870400, "frame": {"e":"depthUpdate","E":1787603065714,"s":"BTCUSDT","U":99076623604,"u":99076623640,"b":[["78714.00000000","3.23126000"],["78710.66000000","0.26060000"],["78708.58000000","0.00000000"],["78708.36000000","0.00318000"],["78629.16000000","0.02116000"],["78581.77000000","0.00000000"],["78399.96000000","0.21930000"],["70842.60000000","0.00281000"],["70842.00000000","0.00225000"]],"a":[["78714.01000000","1.59801000"],["78714.02000000","0.00083000"],["78714.79000000","0.00014000"],["78714.80000000","0.17623000"],["78715.27000000","0.04138000"],["78715.83000000","0.00000000"],["78715.84000000","0.00007000"],["78720.03000000","0.12000000"],["78724.79000000","0.00635000"],["78729.07000000","0.00000000"],["78862.29000000","0.00000000"],["80347.46000000","0.00014000"]]}}
{"rx_ns": 8354835900, "frame": {"e":"depthUpdate","E":1787603065814,"s":"BTCUSDT","U":99076623641,"u":99076623658,"b":[["78714.00000000","3.23139000"],["78709.75000000","0.00000000"],["78709.67000000","0.00319000"],["78708.36000000","0.00000000"],["78708.11000000","0.00324000"],["78629.16000000","0.00000000"],["78580.94000000","0.00406000"],["64169.97000000","0.00000000"]],"a":[["78714.01000000","1.59801000"],["78714.80000000","0.17630000"],["78715.27000000","0.04131000"],["78715.84000000","0.00000000"],["78748.00000000","0.72400000"],["78807.74000000","0.00529000"],["78830.69000000","0.00000000"]]}}
{"rx_ns": 8455516100, "frame": {"e":"depthUpdate","E":1787603065914,"s":"BTCUSDT","U":99076623659,"u":99076623702,"b":[["78714.00000000","3.23114000"],["78710.04000000","0.36238000"],["78708.93000000","0.00000000"],["78701.77000000","0.02200000"],["78662.37000000","0.02200000"],["78320.43000000","0.01000000"],["77928.82000000","0.01000000"],["77539.18000000","0.01000000"],["77151.48000000","0.01000000"],["76765.73000000","0.01000000"],["76381.90000000","0.01000000"],["75999.99000000","0.01000000"],["75619.99000000","0.01000000"],["75241.89000000","0.01000000"],["74865.68000000","0.01000000"],["74491.35000000","0.01000000"],["74118.89000000","0.01000000"],["73748.30000000","0.01000000"],["73379.56000000","0.01000000"],["73012.66000000","0.01000000"],["70842.60000000","0.00297000"]],"a":[["78714.01000000","1.59794000"],["78715.27000000","0.04138000"],["78729.07000000","0.02000000"],["78748.77000000","0.02000000"],["78768.47000000","0.02000000"],["79107.59000000","0.01000000"],["79503.12000000","0.01000000"],["79900.64000000","0.01000000"],["80300.14000000","0.01000000"],["80701.64000000","0.01000000"],["81105.15000000","0.01000000"],["81510.68000000","0.01000000"],["81918.23000000","0.01000000"],["82327.82000000","0.01000000"],["82739.46000000","0.01000000"],["83153.16000000","0.01000000"],["83568.92000000","0.01000000"],["83986.77000000","0.01000000"],["84406.70000000","0.01000000"],["84828.73000000","0.01000000"]]}}
{"rx_ns": 8553876100, "frame": {"e":"depthUpdate","E":1787603066014,"s":"BTCUSDT","U":99076623703,"u":99076623714,"b":[["78710.04000000","0.36231000"],["78683.26000000","0.28464000"],["70842.60000000","0.00297000"],["62971.20000000","0.00031000"]],"a":[["78724.79000000","0.00000000"],["78726.32000000","0.00635000"],["78769.50000000","0.00000000"],["78808.94000000","0.93647000"],["78810.80000000","0.00406000"],["78853.31000000","0.00000000"],["78977.12000000","2.10412000"],["80508.16000000","0.00016000"]]}}
{"rx_ns": 8653151500, "frame": {"e":"depthUpdate","E":1787603066114,"s":"BTCUSDT","U":99076623715,"u":99076623724,"b":[["70842.60000000","0.00297000"]],"a":[["78714.01000000","1.59808000"],["78716.57000000","0.05459000"],["78719.69000000","0.01270000"],["78719.73000000","0.06350000"],["78726.00000000","0.05200000"],["80669.18000000","0.00019000"]]}}
{"rx_ns": 8753203100, "frame": {"e":"depthUpdate","E":1787603066214,"s":"BTCUSDT","U":99076623725,"u":99076623733,"b":[["70842.60000000","0.00313000"],["62971.20000000","0.00000000"]],"a":[["78718.00000000","0.00507000"],["78719.69000000","0.01277000"],["78719.73000000","0.06357000"],["78720.00000000","0.00900000"],["78720.01000000","0.09889000"],["80830.52000000","0.00021000"]]}}
{"rx_ns": 8854284500, "frame": {"e":"depthUpdate","E":1787603066315,"s":"BTCUSDT","U":99076623734,"u":99076623749,"b":[["78710.04000000","0.36238000"],["78708.48000000","0.12712000"],["78708.24000000","0.00000000"],["78706.67000000","0.00635000"],["70842.60000000","0.00329000"],["62971.00000000","0.00000000"]],"a":[["78714.01000000","2.06928000"],["78718.00000000","0.01207000"],["78720.00000000","0.01600000"],["78722.00000000","0.01207000"],["78742.99000000","0.00007000"]]}}
{"rx_ns": 8954995800, "frame": {"e":"depthUpdate","E":1787603066414,"s":"BTCUSDT","U":99076623750,"u":99076623786,"b":[["78710.04000000","0.36231000"],["78708.48000000","0.00000000"],["78320.43000000","0.00000000"],["77928.82000000","0.00000000"],["77539.18000000","0.00000000"],["77151.48000000","0.00000000"],["76765.73000000","0.00000000"],["76381.90000000","0.00000000"],["75999.99000000","0.00000000"],["75619.99000000","0.00000000"],["75241.89000000","0.00000000"],["74865.68000000","0.00000000"],["74491.35000000","0.00000000"],["74118.89000000","0.00000000"],["73748.30000000","0.00000000"],["73379.56000000","0.00000000"],["73012.66000000","0.00000000"],["70842.60000000","0.00313000"],["41465.30000000","0.00000000"]],"a":[["78714.01000000","1.59808000"],["78884.00000000","0.02400000"],["79107.59000000","0.00000000"],["79503.12000000","0.00000000"],["79900.64000000","0.00000000"],["80300.14000000","0.00000000"],["80701.64000000","0.00000000"],["81105.15000000","0.00000000"],["81510.68000000","0.00000000"],["81918.23000000","0.00000000"],["82327.82000000","0.00000000"],["82739.46000000","0.00000000"],["83153.16000000","0.00000000"],["83568.92000000","0.00000000"],["83986.77000000","0.00000000"],["84406.70000000","0.00000000"],["84828.73000000","0.00000000"]]}}
{"rx_ns": 9055889900, "frame": {"e":"depthUpdate","E":1787603066514,"s":"BTCUSDT","U":99076623787,"u":99076623802,"b":[["78710.04000000","0.36238000"],["78708.49000000","0.00000000"],["78708.39000000","0.00000000"],["78701.34000000","0.00000000"],["78690.34000000","0.00007000"],["78683.78000000","0.00000000"],["78664.08000000","0.00000000"],["77000.00000000","69.38203000"],["70842.60000000","0.00345000"],["62971.20000000","0.00031000"]],"a":[["78728.95000000","0.00000000"],["78737.58000000","0.00007000"],["78745.56000000","0.00000000"],["78755.64000000","0.09443000"],["78767.76000000","0.00000000"]]}}
{"rx_ns": 9156755100, "frame": {"e":"depthUpdate","E":1787603066614,"s":"BTCUSDT","U":99076623803,"u":99076624053,"b":[["78714.00000000","3.36713000"],["78713.99000000","0.00439000"],["78713.95000000","0.05000000"],["78713.28000000","0.00414000"],["78712.96000000","0.00000000"],["78712.79000000","0.03224000"],["78712.54000000","0.00326000"],["78712.01000000","0.00000000"],["78711.07000000","0.00007000"],["78711.06000000","0.00000000"],["78710.67000000","0.00000000"],["78710.66000000","0.00007000"],["78710.26000000","0.00400000"],["78710.05000000","0.00007000"],["78710.04000000","0.36231000"],["78707.38000000","0.00000000"],["78706.67000000","0.00000000"],["78706.37000000","0.00000000"],["78705.44000000","0.08576000"],["78703.44000000","0.00000000"],["78703.28000000","0.00000000"],["78701.34000000","0.38123000"],["78700.40000000","0.00000000"],["78694.83000000","0.34313000"],["78693.45000000","0.34314000"],["78691.29000000","0.00000000"],["78673.34000000","0.00000000"],["78672.23000000","0.00000000"],["78667.98000000","0.00400000"],["78667.65000000","0.00000000"],["78664.96000000","0.00000000"],["78661.94000000","0.00000000"],["78423.68000000","0.00000000"],["70842.60000000","0.00336000"],["70842.59000000","0.00009000"],["62971.20000000","0.00000000"]],"a":[["78714.01000000","0.13125000"],["78714.02000000","0.00076000"],["78714.79000000","0.00000000"],["78714.80000000","0.00007000"],["78715.80000000","0.00007000"],["78716.57000000","0.05466000"],["78717.99000000","0.00007000"],["78719.67000000","0.00007000"],["78719.69000000","0.00007000"],["78719.73000000","0.00007000"],["78719.86000000","0.00000000"],["78719.98000000","0.00000000"],["78720.00000000","0.01200000"],["78720.01000000","0.00041000"],["78720.03000000","0.00000000"],["78720.73000000","0.00000000"],["78721.25000000","0.00000000"],["78721.26000000","0.00000000"],["78721.90000000","0.00000000"],["78721.91000000","0.00000000"],["78722.01000000","0.00021000"],["78722.26000000","0.00000000"],["78722.43000000","0.00000000"],["78723.46000000","0.00000000"],["78723.47000000","0.00000000"],["78723.54000000","0.00007000"],["78723.90000000","0.00000000"],["78723.99000000","0.00000000"],["78724.01000000","0.00007000"],["78724.61000000","0.02064000"],["78724.62000000","0.02782000"],["78725.23000000","0.00007000"],["78725.40000000","0.00000000"],["78725.86000000","0.00000000"],["78725.87000000","0.00000000"],["78725.90000000","0.00000000"],["78725.99000000","0.00000000"],["78726.32000000","0.00000000"],["78726.62000000","0.00007000"],["78726.65000000","0.00000000"],["78727.13000000","0.01000000"],["78727.23000000","0.00000000"],["78727.40000000","0.00137000"],["78727.75000000","0.00000000"],["78727.76000000","0.00007000"],["78727.83000000","0.00000000"],["78727.84000000","0.00000000"],["78727.93000000","0.00000000"],["78727.97000000","0.00000000"],["78728.01000000","0.04782000"],["78728.13000000","0.02000000"],["78728.30000000","0.00000000"],["78728.31000000","0.00000000"],["78728.32000000","0.09414000"],["78729.48000000","0.00000000"],["78729.58000000","0.00254000"],["78729.59000000","0.00254000"],["78729.67000000","0.00000000"],["78729.93000000","0.00000000"],["78730.33000000","0.08000000"],["78730.47000000","0.00000000"],["78730.83000000","0.04000000"],["78731.28000000","0.02014000"],["78731.82000000","0.00000000"],["78731.89000000","0.00000000"],["78731.99000000","0.31765000"],["78732.47000000","0.04857000"],["78732.84000000","0.00635000"],["78733.99000000","0.00635000"],["78735.33000000","0.00000000"],["78736.14000000","0.00157000"],["78736.69000000","0.02000000"],["78736.77000000","0.00400000"],["78736.78000000","0.00000000"],["78736.79000000","0.00000000"],["78736.99000000","0.00000000"],["78739.74000000","0.04482000"],["78739.98000000","0.00227000"],["78739.99000000","0.00000000"],["78740.00000000","0.02400000"],["78741.26000000","0.00000000"],["78741.50000000","0.00000000"],["78742.21000000","0.00000000"],["78742.27000000","0.00000000"],["78742.28000000","0.00000000"],["78742.29000000","0.00000000"],["78743.58000000","0.00000000"],["78745.12000000","0.00000000"],["78745.19000000","0.00000000"],["78745.80000000","0.00000000"],["78749.85000000","0.43579000"],["78752.53000000","0.00000000"],["78753.44000000","0.00000000"],["78754.50000000","0.00007000"],["78755.64000000","0.00000000"],["78758.37000000","0.00007000"],["78759.06000000","0.34285000"],["78762.24000000","0.00007000"],["78764.63000000","1.25705000"],["78765.83000000","0.34282000"],["78773.68000000","0.00400000"],["78778.69000000","0.00000000"],["78779.72000000","0.00400000"],["78789.93000000","1.21962000"],["78800.17000000","1.21952000"],["78808.28000000","3.12467000"],["78808.94000000","0.00000000"],["78923.44000000","0.00000000"],["79027.65000000","7.59315000"]]}}
