{"rx_ns": 22252552300, "kind": "rest", "req": {"method": "GET", "url": "https://data-api.binance.vision/api/v3/depth?symbol=BTCUSDT&limit=100", "limit": 100, "weight": 5, "sent_ns": 21160541500, "status": 200, "used_weight_1m": "15", "recv_ns": 22179639600}, "frame": {"lastUpdateId":99076631380,"bids":[["78705.01000000","3.38285000"],["78705.00000000","0.00069000"],["78704.99000000","0.00013000"],["78704.95000000","0.00007000"],["78704.19000000","0.00014000"],["78704.01000000","0.00014000"],["78704.00000000","0.02407000"],["78703.71000000","0.00602000"],["78703.70000000","0.00014000"],["78703.69000000","0.26063000"],["78703.61000000","0.00414000"],["78703.60000000","1.90522000"],["78703.58000000","0.00014000"],["78703.57000000","1.21959000"],["78703.54000000","0.00254000"],["78703.37000000","0.00014000"],["78703.36000000","0.31789000"],["78702.77000000","0.00010000"],["78702.00000000","0.02407000"],["78701.92000000","0.00007000"],["78701.79000000","0.02807000"],["78701.73000000","0.02200000"],["78701.70000000","0.00008000"],["78701.59000000","0.00321000"],["78701.52000000","0.02287000"],["78701.43000000","0.00007000"],["78701.14000000","0.00334000"],["78701.08000000","0.00027000"],["78701.00000000","0.00007000"],["78700.70000000","0.00152000"],["78700.54000000","0.12713000"],["78700.46000000","0.00007000"],["78700.35000000","0.00007000"],["78700.32000000","0.00414000"],["78700.28000000","0.01245000"],["78700.17000000","0.00007000"],["78700.02000000","0.00007000"],["78700.00000000","0.02407000"],["78699.97000000","0.02515000"],["78699.56000000","0.00326000"],["78699.37000000","1.21952000"],["78699.02000000","0.02075000"],["78698.85000000","0.36224000"],["78698.57000000","0.02000000"],["78698.52000000","0.00635000"],["78698.28000000","1.90515000"],["78698.26000000","0.00014000"],["78698.17000000","0.00007000"],["78698.04000000","0.00007000"],["78698.00000000","0.02400000"],["78697.98000000","0.00007000"],["78697.92000000","0.03224000"],["78697.84000000","0.00400000"],["78697.76000000","0.02490000"],["78697.66000000","0.00762000"],["78697.43000000","0.00317000"],["78697.37000000","0.11000000"],["78696.50000000","0.02490000"],["78696.45000000","0.12721000"],["78696.04000000","0.00007000"],["78696.00000000","0.03701000"],["78695.93000000","0.00007000"],["78695.63000000","0.00190000"],["78695.37000000","0.00635000"],["78695.36000000","0.00400000"],["78695.35000000","0.00400000"],["78695.34000000","1.21952000"],["78695.26000000","0.08576000"],["78695.11000000","0.00007000"],["78695.07000000","0.04000000"],["78694.90000000","0.02410000"],["78694.86000000","0.02600000"],["78694.16000000","0.00007000"],["78694.08000000","1.21956000"],["78694.07000000","0.02800000"],["78694.00000000","0.02415000"],["78693.88000000","0.00007000"],["78693.49000000","0.00321000"],["78693.26000000","0.00326000"],["78693.12000000","0.00060000"],["78693.03000000","0.00027000"],["78692.88000000","0.00400000"],["78692.58000000","0.00014000"],["78692.00000000","0.02400000"],["78691.96000000","0.00007000"],["78691.77000000","0.02400000"],["78691.74000000","0.00012000"],["78691.55000000","1.90515000"],["78691.36000000","0.00007000"],["78691.10000000","0.00007000"],["78691.00000000","0.02400000"],["78690.98000000","0.02000000"],["78690.63000000","0.36224000"],["78690.40000000","0.00400000"],["78690.28000000","0.00007000"],["78690.19000000","0.02000000"],["78690.18000000","0.02000000"],["78690.12000000","0.14708000"],["78690.11000000","0.02200000"],["78690.04000000","1.21952000"]],"asks":[["78705.02000000","1.63314000"],["78705.03000000","0.00076000"],["78705.04000000","0.00013000"],["78706.27000000","0.00014000"],["78706.28000000","0.04284000"],["78706.50000000","0.00007000"],["78706.54000000","0.00014000"],["78706.55000000","0.04032000"],["78707.29000000","0.00007000"],["78707.53000000","0.00014000"],["78707.54000000","0.05139000"],["78707.57000000","0.00014000"],["78707.58000000","0.05454000"],["78707.67000000","0.00322000"],["78708.00000000","0.00507000"],["78708.06000000","0.00014000"],["78708.20000000","0.00007000"],["78708.79000000","0.00014000"],["78708.80000000","0.05139000"],["78708.87000000","0.00007000"],["78710.00000000","0.01707000"],["78710.24000000","0.00007000"],["78710.43000000","0.00027000"],["78711.17000000","0.00324000"],["78711.92000000","0.00515000"],["78711.93000000","0.00014000"],["78712.00000000","0.04053000"],["78712.01000000","0.07436000"],["78712.09000000","0.00400000"],["78712.29000000","0.00007000"],["78713.32000000","0.12000000"],["78713.56000000","0.00007000"],["78714.00000000","0.01707000"],["78714.01000000","0.11617000"],["78714.03000000","0.00007000"],["78714.06000000","0.00007000"],["78714.15000000","0.00317000"],["78714.34000000","0.00007000"],["78714.56000000","0.00137000"],["78714.84000000","0.00007000"],["78714.90000000","0.31768000"],["78714.91000000","0.00330000"],["78715.00000000","0.00007000"],["78715.80000000","0.00014000"],["78716.00000000","0.02800000"],["78716.38000000","0.00007000"],["78716.48000000","0.00329000"],["78717.09000000","0.00635000"],["78717.10000000","0.00008000"],["78717.18000000","0.12710000"],["78717.44000000","0.00007000"],["78717.47000000","0.00400000"],["78717.92000000","0.00635000"],["78717.96000000","0.22736000"],["78717.99000000","0.30000000"],["78718.00000000","0.25355000"],["78718.43000000","0.00007000"],["78718.50000000","0.01270000"],["78718.54000000","0.06350000"],["78718.67000000","0.02318000"],["78718.77000000","0.00007000"],["78719.26000000","0.00230000"],["78719.42000000","0.04161000"],["78719.67000000","0.00014000"],["78719.83000000","0.03000000"],["78719.89000000","0.21930000"],["78720.00000000","0.02400000"],["78720.10000000","0.00184000"],["78720.20000000","0.00400000"],["78720.33000000","0.00007000"],["78720.48000000","0.00007000"],["78720.76000000","0.00007000"],["78720.77000000","0.11276000"],["78721.31000000","0.00227000"],["78721.32000000","0.00342000"],["78721.82000000","0.02000000"],["78721.83000000","0.02007000"],["78721.94000000","0.12702000"],["78722.00000000","0.02407000"],["78722.28000000","0.04857000"],["78722.52000000","0.00007000"],["78722.58000000","0.02000000"],["78722.60000000","0.02000000"],["78722.94000000","0.00400000"],["78723.08000000","0.25410000"],["78723.30000000","1.21952000"],["78723.34000000","0.02600000"],["78723.39000000","0.02000000"],["78723.42000000","0.02000000"],["78723.43000000","0.02000000"],["78723.54000000","0.00014000"],["78723.87000000","0.38116000"],["78723.97000000","0.00007000"],["78724.00000000","0.02400000"],["78724.10000000","0.02000000"],["78724.57000000","0.00007000"],["78724.60000000","0.02161000"],["78724.61000000","0.02057000"],["78724.62000000","0.02782000"],["78724.80000000","0.00008000"]]}}
{"rx_ns": 22252552300, "frame": {"e":"depthUpdate","E":1787603079714,"s":"BTCUSDT","U":99076631381,"u":99076631408,"b":[["78705.01000000","3.22841000"],["78703.36000000","0.31796000"],["78702.75000000","0.00000000"],["78702.70000000","0.00000000"],["78700.60000000","0.00000000"],["78700.54000000","0.00000000"],["78699.89000000","0.12713000"],["78626.36000000","0.00000000"],["70834.51000000","0.00240000"],["70834.00000000","0.00000000"]],"a":[["78705.02000000","1.63306000"],["78741.89000000","0.00000000"]]}}
{"rx_ns": 22354792300, "frame": {"e":"depthUpdate","E":1787603079814,"s":"BTCUSDT","U":99076631409,"u":99076631452,"b":[["78703.36000000","0.31796000"],["78699.96000000","0.12713000"],["78699.89000000","0.00000000"],["78685.61000000","0.00000000"],["78645.34000000","0.00406000"],["78644.80000000","0.00007000"],["78518.36000000","0.00000000"],["78510.34000000","0.00778000"],["78311.48000000","0.00000000"],["77919.92000000","0.00000000"],["77530.32000000","0.00000000"],["77142.67000000","0.00000000"],["76756.96000000","0.00000000"],["76373.17000000","0.00000000"],["75991.31000000","0.00000000"],["75611.35000000","0.00000000"],["75233.29000000","0.00000000"],["74857.13000000","0.00000000"],["74482.84000000","0.00000000"],["74110.43000000","0.00000000"],["73739.88000000","0.00000000"],["73371.18000000","0.00000000"],["73004.32000000","0.00000000"],["70834.51000000","0.00240000"],["62964.01000000","0.00000000"]],"a":[["79098.55000000","0.00000000"],["79494.04000000","0.00000000"],["79891.51000000","0.00008000"],["80290.97000000","0.00000000"],["80692.43000000","0.00000000"],["81095.89000000","0.00000000"],["81501.37000000","0.00000000"],["81908.87000000","0.00000000"],["82318.42000000","0.00000000"],["82730.01000000","0.00000000"],["83143.66000000","0.00000000"],["83559.38000000","0.00000000"],["83977.18000000","0.00000000"],["84397.06000000","0.00000000"],["84819.05000000","0.00000000"]]}}
{"rx_ns": 22453021400, "frame": {"e":"depthUpdate","E":1787603079914,"s":"BTCUSDT","U":99076631453,"u":99076631467,"b":[["78702.85000000","0.05000000"],["78702.80000000","0.05000000"],["78700.33000000","0.00000000"],["78700.24000000","0.00000000"],["78700.14000000","0.12713000"],["78699.96000000","0.00000000"],["78699.87000000","0.00000000"],["78681.36000000","0.00007000"],["77157.67000000","0.00025000"],["70834.51000000","0.00256000"]],"a":[["78728.59000000","0.00007000"]]}}
{"rx_ns": 22554009000, "frame": {"e":"depthUpdate","E":1787603080014,"s":"BTCUSDT","U":99076631468,"u":99076631499,"b":[["78705.01000000","3.22855000"],["78703.36000000","0.31796000"],["78702.85000000","0.05014000"],["78702.80000000","0.00007000"],["78702.00000000","0.02400000"],["78701.79000000","0.02800000"],["78701.04000000","0.00000000"],["78700.64000000","0.00000000"],["78700.51000000","0.00000000"],["78700.14000000","0.00000000"],["77003.35000000","0.00014000"],["70834.51000000","0.00272000"],["62964.01000000","0.00031000"]],"a":[["78705.02000000","2.15081000"],["78713.31000000","0.31768000"],["78714.90000000","0.00000000"],["78716.52000000","0.00007000"],["78801.62000000","0.00406000"]]}}
{"rx_ns": 22653030000, "frame": {"e":"depthUpdate","E":1787603080114,"s":"BTCUSDT","U":99076631500,"u":99076631525,"b":[["78705.01000000","3.22848000"],["78703.63000000","0.00326000"],["78702.90000000","0.00000000"],["78702.85000000","0.00007000"],["78702.80000000","0.00000000"],["78702.00000000","0.02407000"],["78700.14000000","0.12713000"],["78694.17000000","0.00400000"],["70834.51000000","0.00256000"],["70834.00000000","0.00020000"]],"a":[["78705.02000000","1.63313000"],["78712.01000000","0.07436000"],["78713.31000000","0.00000000"],["78713.32000000","0.12007000"],["78713.99000000","0.31769000"],["78714.01000000","0.11610000"]]}}
{"rx_ns": 22752891600, "frame": {"e":"depthUpdate","E":1787603080214,"s":"BTCUSDT","U":99076631526,"u":99076631548,"b":[["78705.01000000","3.22841000"],["78703.36000000","0.31796000"],["78702.85000000","0.00000000"],["78702.55000000","0.05000000"],["78702.50000000","0.00000000"],["78701.79000000","0.02807000"],["78700.14000000","0.00000000"],["78700.04000000","0.12713000"],["78694.17000000","0.00800000"],["78613.87000000","0.00406000"],["78518.36000000","0.00778000"],["78510.34000000","0.00000000"],["70834.51000000","0.00288000"],["70834.00000000","0.00010000"],["62964.01000000","0.00000000"]],"a":[["78731.64000000","0.09715000"]]}}
{"rx_ns": 22854098500, "frame": {"e":"depthUpdate","E":1787603080315,"s":"BTCUSDT","U":99076631549,"u":99076631597,"b":[["78703.36000000","0.31803000"],["78702.55000000","0.00007000"],["78701.79000000","0.02800000"],["78700.12000000","0.00000000"],["78700.04000000","0.00000000"],["78699.78000000","0.12713000"],["78694.17000000","0.01200000"],["78607.99000000","2.77224000"],["78311.48000000","0.01000000"],["77919.92000000","0.01000000"],["77530.32000000","0.01000000"],["77142.67000000","0.01000000"],["76756.96000000","0.01000000"],["76373.17000000","0.01000000"],["75991.31000000","0.01000000"],["75611.35000000","0.01000000"],["75233.29000000","0.01000000"],["74857.13000000","0.01000000"],["74482.84000000","0.01000000"],["74110.43000000","0.01000000"],["73739.88000000","0.01000000"],["73371.18000000","0.01000000"],["73004.32000000","0.01000000"],["70834.51000000","0.00288000"],["70834.00000000","0.00000000"],["62964.00000000","0.00000000"]],"a":[["79098.55000000","0.01000000"],["79494.04000000","0.01000000"],["79891.51000000","0.01008000"],["80290.97000000","0.01000000"],["80692.43000000","0.01000000"],["81095.89000000","0.01000000"],["81501.37000000","0.01000000"],["81908.87000000","0.01000000"],["82318.42000000","0.01000000"],["82730.01000000","0.01000000"],["83143.66000000","0.01000000"],["83559.38000000","0.01000000"],["83977.18000000","0.01000000"],["84397.06000000","0.01000000"],["84819.05000000","0.01000000"]]}}
{"rx_ns": 22954122400, "frame": {"e":"depthUpdate","E":1787603080414,"s":"BTCUSDT","U":99076631598,"u":99076631616,"b":[["78703.36000000","0.31796000"],["78702.55000000","0.00000000"],["78701.79000000","0.02807000"],["78700.98000000","0.00400000"],["78699.78000000","0.00000000"],["78699.71000000","0.00000000"],["78673.23000000","0.00414000"],["78671.76000000","0.00000000"],["78658.29000000","0.00000000"],["70834.51000000","0.00288000"]],"a":[["78718.50000000","0.00000000"],["78718.54000000","0.00000000"],["78770.13000000","0.00406000"]]}}
{"rx_ns": 23053495300, "frame": {"e":"depthUpdate","E":1787603080514,"s":"BTCUSDT","U":99076631617,"u":99076631638,"b":[["78703.36000000","0.31796000"],["78700.67000000","0.00000000"],["78699.92000000","0.00000000"],["78699.78000000","0.00000000"],["78699.53000000","0.00000000"],["78699.18000000","0.00000000"],["78671.54000000","0.09607000"],["78642.75000000","0.00007000"],["70834.51000000","0.00320000"],["70834.00000000","0.00010000"],["62964.01000000","0.00031000"]],"a":[["78731.64000000","0.00000000"],["78731.74000000","0.09567000"]]}}
{"rx_ns": 23153286200, "frame": {"e":"depthUpdate","E":1787603080614,"s":"BTCUSDT","U":99076631639,"u":99076631660,"b":[["78703.36000000","0.31789000"],["78701.08000000","0.00027000"],["78701.01000000","0.12713000"],["78699.89000000","0.00000000"],["78699.82000000","0.00000000"],["78699.25000000","0.00400000"],["78518.36000000","0.00000000"],["78510.34000000","0.00778000"],["76849.34000000","0.00016000"],["76695.64000000","0.00029000"],["70834.51000000","0.00320000"],["70834.00000000","0.00010000"],["62964.01000000","0.00000000"]],"a":[["78713.43000000","0.00400000"]]}}
{"rx_ns": 23254392100, "frame": {"e":"depthUpdate","E":1787603080715,"s":"BTCUSDT","U":99076631661,"u":99076631679,"b":[["78703.36000000","0.31789000"],["78702.90000000","0.05000000"],["78702.85000000","0.05000000"],["78701.01000000","0.00000000"],["78700.08000000","0.00000000"],["78632.92000000","0.00000000"],["78626.36000000","0.00000000"],["78597.45000000","0.00400000"],["76542.24000000","0.00025000"],["70834.51000000","0.00416000"],["70834.00000000","0.00000000"]],"a":[]}}
{"rx_ns": 23357203300, "frame": {"e":"depthUpdate","E":1787603080814,"s":"BTCUSDT","U":99076631680,"u":99076631855,"b":[["78705.01000000","3.27060000"],["78705.00000000","0.00027000"],["78704.05000000","0.03224000"],["78703.36000000","0.31796000"],["78702.97000000","0.00000000"],["78702.90000000","0.00014000"],["78702.85000000","0.00007000"],["78702.00000000","0.02400000"],["78701.79000000","0.02800000"],["78700.46000000","0.00007000"],["78698.57000000","0.00000000"],["78698.52000000","0.00000000"],["78693.51000000","0.38126000"],["78692.54000000","0.34314000"],["78686.28000000","0.00400000"],["78669.81000000","0.00000000"],["78667.18000000","0.00000000"],["78661.00000000","0.00000000"],["78648.88000000","0.00007000"],["78311.48000000","0.00000000"],["77919.92000000","0.00000000"],["77530.32000000","0.00000000"],["77142.67000000","0.00000000"],["76756.96000000","0.00000000"],["76373.17000000","0.00000000"],["75991.31000000","0.00000000"],["75611.35000000","0.00000000"],["75233.29000000","0.00000000"],["74857.13000000","0.00000000"],["74482.84000000","0.00000000"],["74110.43000000","0.00000000"],["73739.88000000","0.00000000"],["73371.18000000","0.00000000"],["73004.32000000","0.00000000"],["70834.51000000","0.00336000"],["70834.00000000","0.00000000"],["62964.01000000","0.00000000"]],"a":[["78705.02000000","0.10131000"],["78707.67000000","0.00000000"],["78708.06000000","0.00007000"],["78708.80000000","0.05146000"],["78709.89000000","0.26056000"],["78710.00000000","0.02407000"],["78710.43000000","0.00000000"],["78711.17000000","0.00000000"],["78711.92000000","0.00007000"],["78712.00000000","0.02592000"],["78712.01000000","0.00136000"],["78712.15000000","0.00027000"],["78713.32000000","0.12000000"],["78713.43000000","0.00000000"],["78713.98000000","0.00000000"],["78713.99000000","0.00000000"],["78714.33000000","0.00000000"],["78714.56000000","0.00000000"],["78715.79000000","0.00508000"],["78716.47000000","0.00000000"],["78716.97000000","0.00000000"],["78717.09000000","0.00000000"],["78717.40000000","0.00000000"],["78717.43000000","0.00137000"],["78717.46000000","0.00000000"],["78717.92000000","0.00000000"],["78718.66000000","0.31768000"],["78718.92000000","0.00400000"],["78719.12000000","0.00000000"],["78719.16000000","0.00000000"],["78721.31000000","0.00000000"],["78721.93000000","0.00000000"],["78722.27000000","0.01270000"],["78723.07000000","0.00400000"],["78723.08000000","0.00000000"],["78723.30000000","0.00000000"],["78723.87000000","0.00000000"],["78726.04000000","0.00000000"],["78726.61000000","0.00227000"],["78726.72000000","0.25411000"],["78727.51000000","0.38116000"],["78727.80000000","1.21952000"],["78730.00000000","0.02400000"],["78732.13000000","1.90515000"],["78732.54000000","0.00000000"],["78733.45000000","0.00000000"],["78740.94000000","0.43584000"],["78746.00000000","0.04561000"],["78746.76000000","0.00007000"],["78747.92000000","0.34290000"],["78749.00000000","0.00000000"],["78753.97000000","0.00000000"],["78780.67000000","1.21952000"],["78797.83000000","3.80764000"],["79098.55000000","0.00000000"],["79494.04000000","0.00000000"],["79891.51000000","0.00008000"],["80290.97000000","0.00000000"],["80692.43000000","0.00000000"],["81095.89000000","0.00000000"],["81501.37000000","0.00000000"],["81908.87000000","0.00000000"],["82318.42000000","0.00000000"],["82730.01000000","0.00000000"],["83143.66000000","0.00000000"],["83559.38000000","0.00000000"],["83977.18000000","0.00000000"],["84397.06000000","0.00000000"],["84819.05000000","0.00000000"]]}}
{"rx_ns": 23452772400, "frame": {"e":"depthUpdate","E":1787603080914,"s":"BTCUSDT","U":99076631856,"u":99076631895,"b":[["78705.01000000","3.27702000"],["78704.55000000","0.00400000"],["78704.05000000","0.03231000"],["78703.36000000","0.31789000"],["78702.90000000","0.00000000"],["78702.85000000","0.05000000"],["78702.80000000","0.05000000"],["78695.37000000","0.00000000"],["78690.00000000","0.11932000"],["78681.36000000","0.00000000"],["78663.75000000","0.00000000"],["78626.36000000","0.02116000"],["70834.51000000","0.00352000"]],"a":[["78705.02000000","0.10062000"],["78705.03000000","0.00076000"],["78708.80000000","0.05146000"],["78709.89000000","0.26063000"],["78710.00000000","0.02407000"],["78711.92000000","0.00000000"],["78712.01000000","0.00089000"],["78712.09000000","0.00000000"],["78714.00000000","0.02407000"],["78714.78000000","0.00048000"],["78715.61000000","0.00069000"],["78722.41000000","0.00047000"],["78723.94000000","0.00191000"],["78728.59000000","0.00000000"],["78741.00000000","0.00000000"],["78759.36000000","0.00400000"]]}}
{"rx_ns": 23560877700, "frame": {"e":"depthUpdate","E":1787603081014,"s":"BTCUSDT","U":99076631896,"u":99076631924,"b":[["78703.37000000","0.00007000"],["78703.36000000","0.31789000"],["78702.85000000","0.00000000"],["78702.80000000","0.00000000"],["78684.69000000","0.00000000"],["78681.36000000","0.00007000"],["78649.12000000","0.00406000"],["78645.34000000","0.00000000"],["78626.36000000","0.00000000"],["78613.87000000","0.00000000"],["78566.66000000","0.00007000"],["78499.61000000","0.00406000"],["78495.84000000","0.00000000"],["70834.51000000","0.00352000"],["62964.01000000","0.00031000"]],"a":[["78706.54000000","0.00000000"],["78706.55000000","0.00007000"],["78709.88000000","0.00007000"],["78712.56000000","0.18084000"],["78728.59000000","0.00007000"],["78730.76000000","0.00000000"],["78770.13000000","0.00000000"],["78773.90000000","0.00406000"],["78801.62000000","0.00000000"],["78848.86000000","0.00000000"],["78919.72000000","0.00000000"]]}}
{"rx_ns": 23653809400, "frame": {"e":"depthUpdate","E":1787603081114,"s":"BTCUSDT","U":99076631925,"u":99076631955,"b":[["78705.01000000","3.27060000"],["78704.06000000","0.00014000"],["78703.36000000","0.31789000"],["78702.50000000","0.00000000"],["78702.01000000","0.00635000"],["78702.00000000","0.02407000"],["78701.40000000","0.00000000"],["78637.50000000","0.00000000"],["78626.36000000","0.02116000"],["70840.79000000","0.00000000"],["70834.51000000","0.00368000"]],"a":[["78705.02000000","0.56987000"],["78705.03000000","0.00069000"],["78705.72000000","0.00007000"],["78706.28000000","0.04284000"],["78706.55000000","0.00000000"],["78707.29000000","0.00000000"],["78709.89000000","0.26070000"],["78712.00000000","0.02599000"],["78717.17000000","0.31767000"],["78718.66000000","0.00000000"]]}}
{"rx_ns": 23752659900, "frame": {"e":"depthUpdate","E":1787603081214,"s":"BTCUSDT","U":99076631956,"u":99076631976,"b":[["78703.36000000","0.31789000"],["78702.65000000","0.05000000"],["78702.60000000","0.05000000"],["78702.01000000","0.00642000"],["78702.00000000","0.02400000"],["78626.36000000","0.00000000"],["70834.51000000","0.00368000"],["62964.01000000","0.00000000"]],"a":[["78705.02000000","0.09933000"],["78714.15000000","0.00000000"],["78724.10000000","0.00000000"],["78729.04000000","0.02000000"],["78732.14000000","0.00000000"],["78754.03000000","1.25722000"],["78852.64000000","0.00406000"]]}}
{"rx_ns": 23853241200, "frame": {"e":"depthUpdate","E":1787603081314,"s":"BTCUSDT","U":99076631977,"u":99076632018,"b":[["78703.36000000","0.31796000"],["78702.65000000","0.00007000"],["78702.01000000","0.00635000"],["78311.48000000","0.01000000"],["77919.92000000","0.01000000"],["77530.32000000","0.01000000"],["77142.67000000","0.01000000"],["76756.96000000","0.01000000"],["76373.17000000","0.01000000"],["75991.31000000","0.01000000"],["75611.35000000","0.01000000"],["75233.29000000","0.01000000"],["74857.13000000","0.01000000"],["74482.84000000","0.01000000"],["74110.43000000","0.01000000"],["73739.88000000","0.01000000"],["73371.18000000","0.01000000"],["73004.32000000","0.01000000"],["70834.51000000","0.00384000"],["62964.00000000","0.00000000"]],"a":[["78714.06000000","0.00000000"],["79098.55000000","0.01000000"],["79494.04000000","0.01000000"],["79891.51000000","0.01008000"],["80290.97000000","0.01000000"],["80692.43000000","0.01000000"],["81095.89000000","0.01000000"],["81501.37000000","0.01000000"],["81908.87000000","0.01000000"],["82318.42000000","0.01000000"],["82730.01000000","0.01000000"],["83143.66000000","0.01000000"],["83559.38000000","0.01000000"],["83977.18000000","0.01000000"],["84397.06000000","0.01000000"],["84819.05000000","0.01000000"]]}}
{"rx_ns": 23953144300, "frame": {"e":"depthUpdate","E":1787603081414,"s":"BTCUSDT","U":99076632019,"u":99076632026,"b":[["78703.36000000","0.31796000"],["78702.65000000","0.00000000"],["78702.60000000","0.00007000"],["78570.43000000","0.00406000"]],"a":[]}}
{"rx_ns": 24053511900, "frame": {"e":"depthUpdate","E":1787603081514,"s":"BTCUSDT","U":99076632027,"u":99076632345,"b":[["78706.27000000","5.09992000"],["78706.26000000","1.90542000"],["78706.25000000","0.00013000"],["78705.71000000","0.00000000"],["78705.03000000","0.00007000"],["78705.02000000","0.43466000"],["78705.01000000","0.21960000"],["78705.00000000","0.00007000"],["78704.99000000","0.00000000"],["78704.06000000","0.00000000"],["78704.01000000","0.00000000"],["78703.70000000","0.00000000"],["78703.69000000","0.00007000"],["78703.61000000","0.00400000"],["78703.60000000","0.00007000"],["78703.58000000","0.00000000"],["78703.36000000","0.00014000"],["78702.60000000","0.00000000"],["78702.01000000","0.00000000"],["78701.38000000","0.12706000"],["78700.70000000","0.00000000"],["78691.80000000","0.34315000"],["78691.39000000","0.00000000"],["78690.12000000","0.02000000"],["78687.00000000","0.73238000"],["78685.64000000","0.12708000"],["78681.58000000","0.00000000"],["78676.55000000","0.00000000"],["78670.58000000","0.00320000"],["78665.46000000","0.00000000"],["78640.71000000","0.00000000"],["78534.05000000","0.00000000"],["78494.00000000","0.00007000"],["70834.51000000","0.00009000"],["62964.01000000","0.00031000"]],"a":[["78705.02000000","0.00000000"],["78705.03000000","0.00000000"],["78705.04000000","0.00000000"],["78705.72000000","0.00000000"],["78706.27000000","0.00000000"],["78706.28000000","0.11049000"],["78706.29000000","0.00056000"],["78707.54000000","0.05146000"],["78707.58000000","0.00021000"],["78708.85000000","0.05421000"],["78709.88000000","0.00014000"],["78709.89000000","0.00014000"],["78709.99000000","0.00007000"],["78711.93000000","0.00007000"],["78712.00000000","0.02407000"],["78712.15000000","0.00000000"],["78712.56000000","0.00007000"],["78713.32000000","0.00000000"],["78714.01000000","0.00000000"],["78714.84000000","0.00000000"],["78714.91000000","0.00000000"],["78715.25000000","0.00331000"],["78715.79000000","0.26056000"],["78715.80000000","0.00007000"],["78716.00000000","0.02400000"],["78716.48000000","0.00000000"],["78717.17000000","0.00000000"],["78717.42000000","0.00000000"],["78717.43000000","0.00000000"],["78717.47000000","0.00000000"],["78717.96000000","0.00000000"],["78718.00000000","0.02400000"],["78718.07000000","0.00000000"],["78718.23000000","0.04000000"],["78718.42000000","0.00254000"],["78718.66000000","0.00000000"],["78718.92000000","0.00000000"],["78719.42000000","0.02000000"],["78719.83000000","0.11000000"],["78719.95000000","0.00000000"],["78720.10000000","0.00027000"],["78720.76000000","0.31774000"],["78720.77000000","0.00000000"],["78721.31000000","0.00137000"],["78721.81000000","0.00254000"],["78721.94000000","0.00000000"],["78722.03000000","0.05642000"],["78722.42000000","0.00000000"],["78722.54000000","0.00000000"],["78723.07000000","0.00000000"],["78723.99000000","0.00000000"],["78725.28000000","0.00400000"],["78726.61000000","0.00000000"],["78726.72000000","0.00000000"],["78727.51000000","0.00000000"],["78727.80000000","0.00000000"],["78728.25000000","0.00192000"],["78728.83000000","0.00000000"],["78729.54000000","0.00160000"],["78731.74000000","0.00000000"],["78731.79000000","0.00000000"],["78732.12000000","1.22179000"],["78732.13000000","0.00000000"],["78732.83000000","0.00000000"],["78732.96000000","0.00007000"],["78736.77000000","0.00000000"],["78737.51000000","1.90515000"],["78737.52000000","0.00000000"],["78737.55000000","0.00000000"],["78740.93000000","0.00000000"],["78740.94000000","0.00000000"],["78744.80000000","0.02516000"],["78745.00000000","0.00000000"],["78746.00000000","0.05561000"],["78746.75000000","0.43580000"],["78750.63000000","0.00007000"],["78754.50000000","0.00007000"],["78756.75000000","0.00400000"],["78764.58000000","0.00400000"],["78790.64000000","1.21952000"],["78795.26000000","0.00000000"],["78797.82000000","1.90515000"],["78800.09000000","0.00000000"],["78800.38000000","0.00320000"],["78921.71000000","0.00007000"],["78925.64000000","0.00007000"],["79098.55000000","0.00000000"],["79494.04000000","0.00000000"],["79891.51000000","0.00008000"],["80290.97000000","0.00000000"],["80692.43000000","0.00000000"],["81095.89000000","0.00000000"],["81501.37000000","0.00000000"],["81908.87000000","0.00000000"],["82318.42000000","0.00000000"],["82730.01000000","0.00000000"],["83143.66000000","0.00000000"],["83559.38000000","0.00000000"],["83977.18000000","0.00000000"],["84397.06000000","0.00000000"],["84819.05000000","0.00000000"]]}}
{"rx_ns": 24153733600, "frame": {"e":"depthUpdate","E":1787603081614,"s":"BTCUSDT","U":99076632346,"u":99076632943,"b":[["78709.99000000","6.58136000"],["78709.98000000","0.00020000"],["78709.97000000","0.00013000"],["78709.77000000","0.00400000"],["78708.85000000","0.07507000"],["78708.84000000","0.00000000"],["78708.83000000","0.00000000"],["78708.79000000","2.45824000"],["78708.78000000","1.58176000"],["78708.77000000","0.00000000"],["78708.06000000","0.00014000"],["78707.99000000","0.00000000"],["78707.57000000","0.00000000"],["78707.54000000","0.39266000"],["78707.53000000","0.60239000"],["78707.52000000","0.00000000"],["78707.51000000","0.00000000"],["78707.16000000","0.00400000"],["78706.49000000","0.21930000"],["78706.29000000","0.00000000"],["78706.28000000","0.41370000"],["78706.27000000","1.11682000"],["78706.26000000","0.00346000"],["78706.25000000","0.00000000"],["78705.03000000","0.00000000"],["78705.02000000","0.04206000"],["78705.01000000","0.21555000"],["78705.00000000","0.00000000"],["78704.95000000","0.00000000"],["78704.00000000","0.02400000"],["78703.71000000","0.00595000"],["78703.69000000","0.00000000"],["78703.60000000","0.00000000"],["78703.57000000","1.21952000"],["78703.36000000","0.00007000"],["78702.00000000","0.02400000"],["78701.41000000","0.00007000"],["78701.38000000","0.12713000"],["78700.61000000","0.38123000"],["78700.59000000","0.08576000"],["78700.46000000","0.00000000"],["78700.35000000","0.00000000"],["78700.28000000","0.00000000"],["78699.02000000","0.00000000"],["78698.80000000","0.00000000"],["78697.76000000","0.00000000"],["78696.50000000","0.00000000"],["78695.26000000","0.00000000"],["78692.65000000","0.01300000"],["78691.96000000","0.00000000"],["78689.55000000","0.00000000"],["78685.86000000","0.00000000"],["78684.17000000","0.13251000"],["78669.36000000","0.00000000"],["78668.14000000","0.00000000"],["78667.59000000","0.00000000"],["78666.36000000","0.00000000"],["78666.12000000","0.00014000"],["78666.00000000","0.03407000"],["78665.00000000","0.00000000"],["78644.80000000","0.00000000"],["78617.65000000","0.00406000"],["78407.54000000","7.65320000"],["78402.65000000","0.00000000"],["70839.00000000","0.00016000"],["66960.06000000","0.00017000"],["66903.50000000","0.00017000"],["62964.01000000","0.00000000"],["58000.00000000","134.37636000"]],"a":[["78706.28000000","0.00000000"],["78706.29000000","0.00000000"],["78706.50000000","0.00000000"],["78707.53000000","0.00000000"],["78707.54000000","0.00000000"],["78707.55000000","0.00000000"],["78707.57000000","0.00000000"],["78707.58000000","0.00000000"],["78708.00000000","0.00000000"],["78708.06000000","0.00000000"],["78708.20000000","0.00000000"],["78708.79000000","0.00000000"],["78708.80000000","0.00000000"],["78708.84000000","0.00000000"],["78708.85000000","0.00000000"],["78708.87000000","0.00000000"],["78709.88000000","0.00000000"],["78709.89000000","0.00000000"],["78709.99000000","0.00000000"],["78710.00000000","0.02500000"],["78710.01000000","0.00056000"],["78710.10000000","0.00000000"],["78710.11000000","0.00000000"],["78710.24000000","0.00000000"],["78710.44000000","0.00007000"],["78711.37000000","0.00000000"],["78711.99000000","0.00014000"],["78712.00000000","0.02407000"],["78712.01000000","0.00027000"],["78712.56000000","0.00014000"],["78712.57000000","0.05421000"],["78713.99000000","0.00014000"],["78714.00000000","0.02407000"],["78714.03000000","0.00000000"],["78714.78000000","0.00000000"],["78715.25000000","0.00000000"],["78715.47000000","0.00321000"],["78715.79000000","0.00014000"],["78715.99000000","0.00014000"],["78716.00000000","0.02407000"],["78717.10000000","0.00000000"],["78717.17000000","0.00007000"],["78717.18000000","0.12731000"],["78717.56000000","0.26056000"],["78717.99000000","0.30014000"],["78718.00000000","0.02407000"],["78718.23000000","0.00007000"],["78718.42000000","0.00000000"],["78718.67000000","0.00318000"],["78719.42000000","0.00000000"],["78719.54000000","0.00047000"],["78719.83000000","0.03000000"],["78720.13000000","0.04000000"],["78720.20000000","0.00000000"],["78720.76000000","0.00007000"],["78721.31000000","0.00000000"],["78721.81000000","0.00508000"],["78721.82000000","0.00000000"],["78722.03000000","0.08000000"],["78722.27000000","0.00000000"],["78722.28000000","0.00000000"],["78722.58000000","0.00000000"],["78722.60000000","0.00000000"],["78723.34000000","0.00000000"],["78723.39000000","0.00000000"],["78723.42000000","0.00000000"],["78723.43000000","0.00000000"],["78723.48000000","0.00007000"],["78723.99000000","0.31767000"],["78724.56000000","0.00137000"],["78725.28000000","0.01035000"],["78725.50000000","0.00048000"],["78725.83000000","0.00000000"],["78727.40000000","0.00000000"],["78727.62000000","0.04857000"],["78727.83000000","0.00635000"],["78728.25000000","0.00000000"],["78728.65000000","0.00000000"],["78729.04000000","0.00000000"],["78729.07000000","0.00000000"],["78732.12000000","1.21952000"],["78732.95000000","0.02000000"],["78733.46000000","0.00000000"],["78734.17000000","0.00000000"],["78735.06000000","0.00000000"],["78735.27000000","0.00000000"],["78735.68000000","0.09521000"],["78736.18000000","0.00227000"],["78741.62000000","0.36224000"],["78744.28000000","0.00192000"],["78744.93000000","0.00000000"],["78746.00000000","0.04561000"],["78746.76000000","0.00014000"],["78747.00000000","0.00000000"],["78747.78000000","0.34290000"],["78749.00000000","0.00000000"],["78749.91000000","0.00000000"],["78750.00000000","0.12931000"],["78754.87000000","0.00000000"],["78759.04000000","0.00317000"],["78760.57000000","0.00624000"],["78761.97000000","0.00400000"],["78775.67000000","0.00000000"],["78778.79000000","0.00315000"],["78803.72000000","0.00000000"],["78832.97000000","0.00000000"],["78837.93000000","0.00127000"],["78838.01000000","0.00000000"],["78847.62000000","0.01990000"],["78925.64000000","0.00000000"]]}}
{"rx_ns": 24259317100, "frame": {"e":"depthUpdate","E":1787603081714,"s":"BTCUSDT","U":99076632944,"u":99076633019,"b":[["78709.99000000","6.43872000"],["78708.85000000","0.07514000"],["78708.79000000","2.45831000"],["78708.78000000","1.58183000"],["78707.54000000","0.39273000"],["78707.53000000","0.60239000"],["78706.27000000","0.50907000"],["78706.26000000","0.00339000"],["78706.06000000","0.01373000"],["78705.02000000","0.04199000"],["78705.01000000","0.21541000"],["78704.80000000","0.02289000"],["78704.05000000","0.03224000"],["78703.54000000","0.03001000"],["78703.37000000","0.00000000"],["78703.36000000","0.00000000"],["78702.28000000","0.02747000"],["78701.43000000","0.00000000"],["78684.17000000","0.13505000"],["78680.31000000","0.00000000"],["78670.00000000","0.12212000"],["78668.00000000","0.02400000"],["78666.00000000","0.02407000"],["78576.60000000","0.00000000"],["78528.58000000","4.38794000"],["70839.00000000","0.00032000"]],"a":[["78710.00000000","0.04930000"],["78710.01000000","0.00049000"],["78711.25000000","0.00014000"],["78711.26000000","0.04063000"],["78712.00000000","0.02407000"],["78712.01000000","0.00034000"],["78712.51000000","0.00014000"],["78712.52000000","0.04875000"],["78712.57000000","0.05428000"],["78713.77000000","0.00007000"],["78713.78000000","0.04875000"],["78713.99000000","0.00007000"],["78714.00000000","0.02407000"],["78715.79000000","0.00007000"],["78715.99000000","0.00000000"],["78716.08000000","0.19398000"],["78717.17000000","0.00000000"],["78717.18000000","0.12731000"],["78717.56000000","0.26063000"],["78718.00000000","0.02407000"],["78718.23000000","0.00000000"],["78727.82000000","0.00400000"],["78727.88000000","1.21952000"],["78729.94000000","0.25411000"],["78730.73000000","0.38116000"],["78733.90000000","0.00000000"],["78737.93000000","0.04496000"],["78790.64000000","0.00000000"],["78816.75000000","0.00000000"]]}}
{"rx_ns": 24354715100, "frame": {"e":"depthUpdate","E":1787603081814,"s":"BTCUSDT","U":99076633020,"u":99076633082,"b":[["78708.86000000","0.00014000"],["78708.80000000","0.00014000"],["78708.79000000","2.13692000"],["78707.55000000","0.00014000"],["78707.53000000","0.22382000"],["78706.49000000","0.00000000"],["78706.27000000","0.50807000"],["78695.20000000","0.00007000"],["78585.72000000","0.04092000"],["78520.83000000","0.00778000"],["78510.34000000","0.00000000"],["78311.48000000","0.00000000"],["77919.92000000","0.00000000"],["77530.32000000","0.00000000"],["77142.67000000","0.00000000"],["76756.96000000","0.00000000"],["76373.17000000","0.00000000"],["75991.31000000","0.00000000"],["75611.35000000","0.00000000"],["75233.29000000","0.00000000"],["74857.13000000","0.00000000"],["74482.84000000","0.00000000"],["74110.43000000","0.00000000"],["73739.88000000","0.00000000"],["73371.18000000","0.00000000"],["73004.32000000","0.00000000"],["70839.00000000","0.00048000"],["62967.99000000","0.00000000"]],"a":[["78710.00000000","0.05037000"],["78710.01000000","0.00056000"],["78711.26000000","0.04070000"],["78712.00000000","0.02407000"],["78712.52000000","0.04882000"],["78712.57000000","0.05435000"],["78713.78000000","0.04882000"],["78716.00000000","0.02407000"],["78716.08000000","0.19405000"],["78717.18000000","0.12724000"],["78717.56000000","0.26056000"],["78717.99000000","0.30007000"],["78718.00000000","0.02400000"],["78724.11000000","0.25411000"],["78729.94000000","0.00000000"],["78734.53000000","0.00406000"],["78738.07000000","0.18201000"],["78821.84000000","0.02789000"]]}}
{"rx_ns": 24455008500, "frame": {"e":"depthUpdate","E":1787603081914,"s":"BTCUSDT","U":99076633083,"u":99076633123,"b":[["78709.99000000","6.46388000"],["78708.05000000","0.05000000"],["78708.00000000","0.05000000"],["78707.53000000","0.22382000"],["78706.27000000","0.50807000"],["78705.18000000","0.00000000"],["78705.03000000","0.00000000"],["78705.01000000","0.21548000"],["78704.66000000","0.05037000"],["78704.58000000","0.00000000"],["78702.07000000","0.00007000"],["78699.97000000","0.00000000"],["70839.00000000","0.00080000"]],"a":[["78710.00000000","0.05051000"],["78710.01000000","0.00070000"],["78715.80000000","0.00014000"],["78716.08000000","0.00007000"],["78728.61000000","0.02000000"],["78731.76000000","0.02000000"],["78733.33000000","0.02000000"],["78733.40000000","0.02000000"],["78792.09000000","0.02000000"],["78792.10000000","0.02000000"],["78795.25000000","0.02000000"],["78796.82000000","0.02000000"],["78809.58000000","0.00000000"],["78814.56000000","0.00012000"],["78815.72000000","0.00000000"],["78821.81000000","0.00000000"]]}}
{"rx_ns": 24575943300, "frame": {"e":"depthUpdate","E":1787603082014,"s":"BTCUSDT","U":99076633124,"u":99076633162,"b":[["78708.78000000","1.58183000"],["78708.05000000","0.00000000"],["78708.00000000","0.00000000"],["78707.40000000","0.05000000"],["78707.35000000","0.05000000"],["78706.26000000","0.00661000"],["78691.01000000","0.04474000"],["78688.47000000","0.00406000"],["78686.33000000","0.00007000"],["78681.36000000","0.00000000"],["78666.82000000","0.00000000"],["70839.00000000","0.00096000"],["70838.00000000","0.00008000"],["62968.00000000","0.00041000"]],"a":[["78710.00000000","0.05051000"],["78710.01000000","0.00063000"],["78712.57000000","0.05428000"],["78715.47000000","0.00000000"],["78716.00000000","0.02407000"],["78716.08000000","0.00000000"],["78717.17000000","0.02161000"],["78717.18000000","0.12731000"],["78728.59000000","0.00000000"],["78729.38000000","0.02000000"],["78732.53000000","0.02000000"],["78733.32000000","0.02600000"],["78733.38000000","0.02000000"],["78733.57000000","0.00007000"],["78788.16000000","0.00000000"],["78791.26000000","0.02000000"],["78792.09000000","0.00000000"],["78796.82000000","0.04600000"],["78796.86000000","0.02000000"],["78808.94000000","0.93647000"],["78820.70000000","0.00019000"]]}}
{"rx_ns": 24654540300, "frame": {"e":"depthUpdate","E":1787603082115,"s":"BTCUSDT","U":99076633163,"u":99076633180,"b":[["78708.78000000","1.58183000"],["78707.75000000","0.05000000"],["78707.53000000","0.22382000"],["78707.40000000","0.00000000"],["78707.35000000","0.00000000"],["77996.66000000","0.00000000"],["70839.00000000","0.00112000"]],"a":[["78716.00000000","0.02407000"],["78717.17000000","0.02168000"],["78717.18000000","0.12717000"],["78717.56000000","0.00000000"],["78754.50000000","0.00000000"],["78826.07000000","0.00000000"],["78826.80000000","0.00031000"]]}}
{"rx_ns": 24756182000, "frame": {"e":"depthUpdate","E":1787603082214,"s":"BTCUSDT","U":99076633181,"u":99076633204,"b":[["78708.85000000","0.07521000"],["78708.78000000","1.58183000"],["78707.75000000","0.00007000"],["78707.70000000","0.00000000"],["78707.65000000","0.05000000"],["78707.53000000","0.22375000"],["78706.00000000","0.00500000"],["78701.38000000","0.12706000"],["77500.00000000","13.67981000"],["70839.00000000","0.00144000"],["62968.00000000","0.00010000"]],"a":[["78710.00000000","0.04907000"],["78710.44000000","0.00000000"],["78713.58000000","0.00007000"],["78732.53000000","0.04000000"],["78791.26000000","0.00000000"],["78791.27000000","0.02000000"],["78796.82000000","0.00000000"],["78923.50000000","0.00406000"]]}}
{"rx_ns": 24854005500, "frame": {"e":"depthUpdate","E":1787603082315,"s":"BTCUSDT","U":99076633205,"u":99076633272,"b":[["78709.99000000","6.44388000"],["78708.85000000","0.07521000"],["78708.78000000","1.58183000"],["78707.75000000","0.00000000"],["78707.65000000","0.00007000"],["78707.53000000","0.22382000"],["78700.49000000","0.02200000"],["78696.89000000","0.02000000"],["78693.00000000","0.70000000"],["78645.25000000","0.00000000"],["78583.01000000","0.02541000"],["78316.44000000","0.01010000"],["77924.85000000","0.01000000"],["77535.23000000","0.01000000"],["77147.55000000","0.01000000"],["76761.81000000","0.01000000"],["76378.01000000","0.01000000"],["75996.12000000","0.01000000"],["75616.13000000","0.01000000"],["75238.05000000","0.01000000"],["74861.86000000","0.01000000"],["74487.55000000","0.01000000"],["74115.12000000","0.01000000"],["73744.54000000","0.01000000"],["73375.82000000","0.01000000"],["73008.94000000","0.01000000"],["70839.00000000","0.00144000"],["62968.00000000","0.00010000"]],"a":[["78710.00000000","0.04927000"],["78710.44000000","0.00007000"],["78712.57000000","0.05435000"],["78715.72000000","0.19469000"],["78716.82000000","0.00000000"],["78717.99000000","0.00007000"],["78791.27000000","0.00000000"],["78792.10000000","0.00000000"],["78795.25000000","0.00000000"],["79103.55000000","0.01000000"],["79499.07000000","0.01000000"],["79896.57000000","0.01027000"],["80296.05000000","0.01000000"],["80697.53000000","0.01000000"],["81101.02000000","0.01000000"],["81506.52000000","0.01000000"],["81914.06000000","0.01000000"],["82323.63000000","0.01000000"],["82735.24000000","0.01000000"],["83148.92000000","0.01000000"],["83564.67000000","0.01000000"],["83982.49000000","0.01000000"],["84402.40000000","0.01000000"],["84824.41000000","0.01000000"]]}}
{"rx_ns": 24960571100, "frame": {"e":"depthUpdate","E":1787603082414,"s":"BTCUSDT","U":99076633273,"u":99076633311,"b":[["78709.99000000","6.44388000"],["78708.85000000","0.07514000"],["78708.78000000","1.58183000"],["78707.65000000","0.00000000"],["78706.27000000","0.50814000"],["78689.30000000","0.00007000"],["78688.47000000","0.00000000"],["78687.77000000","0.00000000"],["78684.15000000","0.00000000"],["78649.12000000","0.00000000"],["78644.75000000","0.00000000"],["78617.65000000","0.00000000"],["78570.43000000","0.00000000"],["78499.61000000","0.00000000"],["70839.00000000","0.00160000"]],"a":[["78710.00000000","0.04927000"],["78710.01000000","0.00070000"],["78712.57000000","0.05435000"],["78714.00000000","0.02407000"],["78715.72000000","0.19476000"],["78717.17000000","0.02161000"],["78734.53000000","0.00000000"],["78751.00000000","0.70000000"],["78773.90000000","0.00000000"],["78797.81000000","1.90515000"],["78797.82000000","0.00000000"],["78805.40000000","0.00000000"],["78852.64000000","0.00000000"],["78923.50000000","0.00000000"]]}}
{"rx_ns": 25062900200, "frame": {"e":"depthUpdate","E":1787603082514,"s":"BTCUSDT","U":99076633312,"u":99076633322,"b":[["78693.88000000","0.00014000"],["70839.00000000","0.00160000"],["62968.00000000","0.00041000"]],"a":[["78710.00000000","0.04903000"],["78716.26000000","0.00325000"],["78732.11000000","1.90515000"],["78790.00000000","0.02424000"],["78796.86000000","0.00000000"],["78797.81000000","0.00000000"]]}}
{"rx_ns": 25157846200, "frame": {"e":"depthUpdate","E":1787603082614,"s":"BTCUSDT","U":99076633323,"u":99076633346,"b":[["78635.44000000","0.02541000"],["78626.36000000","0.02116000"],["78620.85000000","0.00406000"],["78583.01000000","0.00000000"],["75000.00000000","111.15672000"],["70839.00000000","0.00176000"],["62968.00000000","0.00010000"],["59000.00000000","47.47735000"]],"a":[["78710.00000000","0.35583000"],["78710.01000000","0.00083000"],["78710.02000000","0.00013000"],["78712.01000000","0.00027000"],["78712.57000000","0.05442000"],["78714.22000000","0.18713000"],["78715.72000000","0.00007000"],["78734.75000000","0.12700000"]]}}
{"rx_ns": 25256010200, "frame": {"e":"depthUpdate","E":1787603082714,"s":"BTCUSDT","U":99076633347,"u":99076633363,"b":[["78709.99000000","6.43753000"],["78707.17000000","0.00635000"],["78706.27000000","0.46819000"],["78700.61000000","0.00000000"],["78673.18000000","1.25851000"],["78626.36000000","0.00000000"]],"a":[["78710.00000000","0.46247000"],["78712.57000000","0.05435000"],["78714.00000000","0.02407000"],["78714.22000000","0.18720000"],["78715.72000000","0.00000000"],["78924.18000000","0.00007000"],["78928.11000000","0.00007000"]]}}
{"rx_ns": 25363282800, "frame": {"e":"depthUpdate","E":1787603082814,"s":"BTCUSDT","U":99076633364,"u":99076633411,"b":[["78707.53000000","0.22382000"],["78316.44000000","0.00010000"],["77924.85000000","0.00000000"],["77535.23000000","0.00000000"],["77147.55000000","0.00000000"],["76761.81000000","0.00000000"],["76378.01000000","0.00000000"],["75996.12000000","0.00000000"],["75616.13000000","0.00000000"],["75238.05000000","0.00000000"],["74861.86000000","0.00000000"],["74487.55000000","0.00000000"],["74115.12000000","0.00000000"],["73744.54000000","0.00000000"],["73375.82000000","0.00000000"],["73008.94000000","0.00000000"],["70839.00000000","0.00192000"],["62968.00000000","0.00010000"],["62967.99000000","0.00000000"]],"a":[["78710.44000000","0.00000000"],["78721.20000000","0.01270000"],["78721.24000000","0.06350000"],["78808.61000000","0.00406000"],["78928.11000000","0.00000000"],["79103.55000000","0.00000000"],["79499.07000000","0.00000000"],["79896.57000000","0.00027000"],["80296.05000000","0.00000000"],["80697.53000000","0.00000000"],["81101.02000000","0.00000000"],["81506.52000000","0.00000000"],["81914.06000000","0.00000000"],["82323.63000000","0.00000000"],["82735.24000000","0.00000000"],["83148.92000000","0.00000000"],["83564.67000000","0.00000000"],["83982.49000000","0.00000000"],["84402.40000000","0.00000000"],["84824.41000000","0.00000000"]]}}
{"rx_ns": 25452753400, "frame": {"e":"depthUpdate","E":1787603082914,"s":"BTCUSDT","U":99076633412,"u":99076633419,"b":[["78707.70000000","0.05000000"],["78707.65000000","0.05000000"],["78704.12000000","0.00007000"],["70839.00000000","0.00192000"]],"a":[["78710.00000000","0.45673000"],["78735.41000000","0.34296000"],["78747.92000000","0.00000000"]]}}
{"rx_ns": 25552933600, "frame": {"e":"depthUpdate","E":1787603083014,"s":"BTCUSDT","U":99076633420,"u":99076633439,"b":[["78708.78000000","1.58183000"],["78707.70000000","0.00007000"],["78707.65000000","0.00007000"],["78706.28000000","0.41363000"],["78706.27000000","0.46812000"],["78686.33000000","0.00007000"],["78652.33000000","0.02606000"],["78626.36000000","0.02116000"],["78528.59000000","0.00778000"],["78520.83000000","0.00000000"],["70839.00000000","0.00208000"],["62968.00000000","0.00041000"]],"a":[["78733.57000000","0.00007000"],["78750.00000000","0.82931000"],["78751.00000000","0.00000000"]]}}
{"rx_ns": 25660409000, "frame": {"e":"depthUpdate","E":1787603083114,"s":"BTCUSDT","U":99076633440,"u":99076633460,"b":[["78709.99000000","6.43769000"],["78708.78000000","1.58183000"],["78707.80000000","0.00000000"],["78707.75000000","0.00000000"],["78707.70000000","0.00000000"],["78707.65000000","0.00000000"],["78707.17000000","0.00642000"],["78706.28000000","0.41370000"],["78626.36000000","0.00000000"],["78001.60000000","0.00010000"],["70839.00000000","0.00208000"],["70838.00000000","0.00008000"]],"a":[["78710.00000000","0.45683000"],["78802.60000000","0.00000000"],["78807.59000000","0.00025000"]]}}
{"rx_ns": 25755323100, "frame": {"e":"depthUpdate","E":1787603083215,"s":"BTCUSDT","U":99076633461,"u":99076633477,"b":[["78709.99000000","6.43980000"],["78707.70000000","0.00000000"],["78707.56000000","0.00635000"],["78707.17000000","0.00007000"],["78648.01000000","0.00317000"],["78642.74000000","0.00000000"],["78626.20000000","0.00316000"],["78621.27000000","0.00000000"],["78568.76000000","0.00127000"],["78564.04000000","0.00000000"],["78547.76000000","0.00127000"],["78543.06000000","0.00000000"],["78502.81000000","0.00406000"],["70839.00000000","0.00224000"],["62968.00000000","0.00010000"]],"a":[["78721.99000000","0.00137000"],["78724.56000000","0.00000000"],["78778.79000000","0.00000000"],["78780.66000000","0.00317000"],["78855.28000000","0.00000000"],["78859.99000000","0.00127000"]]}}
{"rx_ns": 25853222500, "frame": {"e":"depthUpdate","E":1787603083314,"s":"BTCUSDT","U":99076633478,"u":99076633525,"b":[["78708.85000000","0.07521000"],["78708.78000000","1.58183000"],["78707.56000000","0.00642000"],["78707.55000000","0.00014000"],["78707.53000000","0.22382000"],["78707.50000000","0.00000000"],["78707.17000000","0.00000000"],["78645.25000000","0.02200000"],["78644.76000000","0.02000000"],["78316.44000000","0.01010000"],["78000.00000000","21.09242000"],["77924.85000000","0.01000000"],["77535.23000000","0.01000000"],["77147.55000000","0.01000000"],["76761.81000000","0.01000000"],["76378.01000000","0.01000000"],["75996.12000000","0.01000000"],["75616.13000000","0.01000000"],["75238.05000000","0.01000000"],["74861.86000000","0.01000000"],["74487.55000000","0.01000000"],["74115.12000000","0.01000000"],["73744.54000000","0.01000000"],["73375.82000000","0.01000000"],["73008.94000000","0.01000000"],["70839.00000000","0.00208000"],["62964.00000000","0.00000000"]],"a":[["78805.19000000","0.00529000"],["79103.55000000","0.01000000"],["79499.07000000","0.01000000"],["79896.57000000","0.01027000"],["80296.05000000","0.01000000"],["80697.53000000","0.01000000"],["81101.02000000","0.01000000"],["81506.52000000","0.01000000"],["81914.06000000","0.01000000"],["82323.63000000","0.01000000"],["82735.24000000","0.01000000"],["83148.92000000","0.01000000"],["83564.67000000","0.01000000"],["83982.49000000","0.01000000"],["84402.40000000","0.01000000"],["84824.41000000","0.01000000"]]}}
{"rx_ns": 25952625300, "frame": {"e":"depthUpdate","E":1787603083414,"s":"BTCUSDT","U":99076633526,"u":99076633528,"b":[["70839.00000000","0.00240000"]],"a":[["78737.74000000","0.00406000"]]}}
{"rx_ns": 26052940300, "frame": {"e":"depthUpdate","E":1787603083514,"s":"BTCUSDT","U":99076633529,"u":99076633552,"b":[["78709.99000000","6.44311000"],["78693.49000000","0.00000000"],["78691.84000000","0.00007000"],["78689.80000000","0.63547000"],["78407.54000000","0.00000000"],["70839.00000000","0.00256000"],["62968.00000000","0.00041000"]],"a":[["78710.00000000","0.04352000"],["78710.01000000","0.00076000"],["78714.22000000","0.00007000"],["78716.26000000","0.00000000"],["78718.67000000","0.00000000"],["78719.56000000","0.00331000"],["78721.99000000","0.00000000"],["78722.93000000","0.00137000"],["78723.50000000","0.00320000"],["78725.28000000","0.00400000"],["78725.89000000","0.00635000"],["78727.44000000","0.00330000"],["78731.38000000","0.00328000"],["78735.32000000","0.00327000"],["79084.32000000","0.01517000"],["79163.41000000","0.00000000"]]}}
{"rx_ns": 26154756600, "frame": {"e":"depthUpdate","E":1787603083615,"s":"BTCUSDT","U":99076633553,"u":99076633560,"b":[["70839.00000000","0.00240000"],["62968.00000000","0.00010000"]],"a":[["78712.57000000","0.05428000"],["78714.00000000","0.02407000"],["78714.22000000","0.00000000"],["78717.17000000","0.02168000"],["78855.85000000","0.00406000"]]}}
{"rx_ns": 26255479200, "frame": {"e":"depthUpdate","E":1787603083715,"s":"BTCUSDT","U":99076633561,"u":99076633652,"b":[["78709.99000000","4.93314000"],["78708.87000000","0.00000000"],["78708.86000000","0.00000000"],["78708.85000000","0.00021000"],["78708.79000000","1.97795000"],["78707.74000000","0.00000000"],["78707.56000000","0.00007000"],["78707.54000000","0.31773000"],["78707.53000000","0.19382000"],["78707.17000000","0.00000000"],["78706.47000000","0.02000000"],["78706.29000000","0.00000000"],["78706.28000000","0.30028000"],["78705.87000000","0.00400000"],["78705.03000000","0.00635000"],["78704.81000000","0.00635000"],["78703.61000000","0.00000000"],["78703.58000000","0.00407000"],["78700.98000000","0.00000000"],["78700.60000000","0.00000000"],["78700.01000000","0.01200000"],["78699.25000000","0.00000000"],["78695.35000000","0.00000000"],["78694.17000000","0.00400000"],["78689.80000000","0.00000000"],["78673.18000000","0.00000000"],["78669.00000000","1.25858000"],["78613.21000000","2.77206000"],["78607.99000000","0.00000000"],["78402.43000000","7.65370000"],["70839.00000000","0.00272000"],["70834.51000000","0.00000000"],["70834.50000000","0.00009000"]],"a":[["78710.00000000","1.12501000"],["78710.01000000","0.00083000"],["78711.93000000","0.00014000"],["78712.15000000","0.00027000"],["78712.57000000","0.05428000"],["78713.88000000","0.00000000"],["78713.99000000","0.00000000"],["78717.98000000","0.00254000"],["78719.25000000","0.00254000"],["78719.54000000","0.00000000"],["78720.63000000","0.00192000"],["78721.81000000","0.00000000"],["78721.99000000","0.31764000"],["78723.99000000","0.00000000"],["78724.96000000","0.02000000"],["78732.10000000","0.36224000"],["78732.95000000","0.00000000"],["78744.28000000","0.00000000"],["78750.63000000","0.00000000"]]}}
{"rx_ns": 26353041300, "frame": {"e":"depthUpdate","E":1787603083814,"s":"BTCUSDT","U":99076633653,"u":99076633710,"b":[["78709.99000000","4.93321000"],["78708.85000000","0.00014000"],["78708.78000000","1.58183000"],["78707.56000000","0.00000000"],["78707.53000000","0.19382000"],["78706.47000000","0.02007000"],["78691.68000000","0.00406000"],["78626.36000000","0.02116000"],["78613.21000000","0.00000000"],["78316.44000000","0.00010000"],["77924.85000000","0.00000000"],["77535.23000000","0.00000000"],["77147.55000000","0.00000000"],["76761.81000000","0.00000000"],["76378.01000000","0.00000000"],["75996.12000000","0.00000000"],["75616.13000000","0.00000000"],["75238.05000000","0.00000000"],["74861.86000000","0.00000000"],["74487.55000000","0.00000000"],["74115.12000000","0.00000000"],["73744.54000000","0.00000000"],["73375.82000000","0.00000000"],["73008.94000000","0.00000000"],["70839.00000000","0.00272000"],["62967.99000000","0.00000000"]],"a":[["78710.00000000","1.12700000"],["78715.23000000","0.00322000"],["78715.61000000","0.00000000"],["78716.80000000","0.00319000"],["79103.55000000","0.00000000"],["79499.07000000","0.00000000"],["79896.57000000","0.00027000"],["80296.05000000","0.00000000"],["80697.53000000","0.00000000"],["81101.02000000","0.00000000"],["81506.52000000","0.00000000"],["81914.06000000","0.00000000"],["82323.63000000","0.00000000"],["82735.24000000","0.00000000"],["83148.92000000","0.00000000"],["83564.67000000","0.00000000"],["83982.49000000","0.00000000"],["84402.40000000","0.00000000"],["84824.41000000","0.00000000"]]}}
{"rx_ns": 26452890900, "frame": {"e":"depthUpdate","E":1787603083914,"s":"BTCUSDT","U":99076633711,"u":99076633725,"b":[["78709.99000000","4.53321000"],["78707.25000000","0.05000000"],["78707.20000000","0.05000000"],["78706.16000000","0.00007000"],["78666.12000000","0.00007000"],["78626.36000000","0.00000000"],["70839.00000000","0.00288000"],["62967.99000000","0.00000000"]],"a":[["78727.62000000","0.05257000"],["78735.68000000","0.00000000"],["78736.29000000","0.09413000"],["78764.58000000","0.00000000"]]}}
{"rx_ns": 26556296100, "frame": {"e":"depthUpdate","E":1787603084014,"s":"BTCUSDT","U":99076633726,"u":99076633741,"b":[["78707.53000000","0.19382000"],["78707.25000000","0.00000000"],["78707.20000000","0.00000000"],["78686.33000000","0.00007000"],["78669.36000000","0.00007000"],["78573.64000000","0.00406000"],["62968.00000000","0.00041000"]],"a":[["78710.00000000","1.38750000"],["78719.24000000","0.00137000"],["78719.55000000","0.31766000"],["78719.88000000","0.00635000"],["78721.99000000","0.00000000"],["78722.93000000","0.00000000"],["78725.89000000","0.00000000"],["78733.57000000","0.00007000"]]}}
{"rx_ns": 26653460900, "frame": {"e":"depthUpdate","E":1787603084114,"s":"BTCUSDT","U":99076633742,"u":99076633762,"b":[["78708.06000000","0.00007000"],["78707.53000000","0.19382000"],["78707.15000000","0.05000000"],["78707.10000000","0.00000000"],["78706.00000000","0.01200000"],["78705.88000000","0.00635000"],["78705.03000000","0.00000000"],["78626.36000000","0.02116000"],["70839.00000000","0.00288000"],["70838.00000000","0.00028000"]],"a":[["78710.00000000","1.38743000"],["78710.01000000","0.00083000"],["78712.15000000","0.00000000"],["78717.18000000","0.12724000"],["78719.61000000","0.00400000"],["78719.88000000","0.00000000"],["78720.62000000","0.00635000"],["78735.32000000","0.00000000"],["78761.97000000","0.00000000"]]}}
{"rx_ns": 26755698900, "frame": {"e":"depthUpdate","E":1787603084214,"s":"BTCUSDT","U":99076633763,"u":99076633779,"b":[["78709.99000000","4.49307000"],["78708.06000000","0.00014000"],["78707.53000000","0.19382000"],["78707.25000000","0.05000000"],["78707.15000000","0.00000000"],["78706.20000000","0.04014000"],["78669.36000000","0.00000000"],["78666.12000000","0.00014000"],["78626.36000000","0.00000000"],["70839.00000000","0.00288000"],["70838.00000000","0.00008000"],["62968.00000000","0.00010000"]],"a":[["78713.18000000","0.00325000"],["78719.24000000","0.00000000"],["78719.60000000","0.00137000"],["78777.11000000","0.00406000"]]}}
{"rx_ns": 26852695800, "frame": {"e":"depthUpdate","E":1787603084314,"s":"BTCUSDT","U":99076633780,"u":99076633823,"b":[["78709.99000000","4.49272000"],["78707.53000000","0.19382000"],["78707.35000000","0.05000000"],["78707.30000000","0.05000000"],["78707.25000000","0.00000000"],["78528.59000000","0.00000000"],["78520.83000000","0.00778000"],["78316.44000000","0.01010000"],["77924.85000000","0.01000000"],["77535.23000000","0.01000000"],["77147.55000000","0.01000000"],["76761.81000000","0.01000000"],["76378.01000000","0.01000000"],["75996.12000000","0.01000000"],["75616.13000000","0.01000000"],["75238.05000000","0.01000000"],["74861.86000000","0.01000000"],["74487.55000000","0.01000000"],["74115.12000000","0.01000000"],["73744.54000000","0.01000000"],["73375.82000000","0.01000000"],["73008.94000000","0.01000000"],["70839.00000000","0.00304000"],["62968.00000000","0.00010000"]],"a":[["78710.00000000","1.38750000"],["78710.01000000","0.00090000"],["78717.18000000","0.12717000"],["78719.55000000","0.00000000"],["78720.12000000","0.31766000"],["79103.55000000","0.01000000"],["79499.07000000","0.01000000"],["79896.57000000","0.01027000"],["80296.05000000","0.01000000"],["80697.53000000","0.01000000"],["81101.02000000","0.01000000"],["81506.52000000","0.01000000"],["81914.06000000","0.01000000"],["82323.63000000","0.01000000"],["82735.24000000","0.01000000"],["83148.92000000","0.01000000"],["83564.67000000","0.01000000"],["83982.49000000","0.01000000"],["84402.40000000","0.01000000"],["84824.41000000","0.01000000"]]}}
{"rx_ns": 26952958000, "frame": {"e":"depthUpdate","E":1787603084414,"s":"BTCUSDT","U":99076633824,"u":99076633854,"b":[["78709.99000000","4.23216000"],["78707.53000000","0.19382000"],["78707.35000000","0.00000000"],["78707.30000000","0.00000000"],["78706.00000000","0.01249000"],["78705.01000000","0.21541000"],["78700.88000000","0.00254000"],["78573.64000000","0.00000000"],["78567.05000000","0.00000000"],["78562.32000000","0.00000000"],["78559.20000000","1.52231000"],["78477.75000000","0.00089000"],["70839.00000000","0.00304000"],["70838.00000000","0.00018000"]],"a":[["78710.00000000","0.90241000"],["78716.61000000","0.00254000"],["78720.12000000","0.00000000"],["78720.62000000","0.00000000"],["78721.19000000","0.31766000"],["78721.20000000","0.00000000"],["78721.24000000","0.00000000"],["78721.82000000","0.00635000"],["78777.11000000","0.00000000"],["78858.29000000","1.52231000"],["78861.42000000","0.00000000"],["78876.14000000","0.00000000"],["78926.72000000","0.00000000"]]}}
{"rx_ns": 27052786200, "frame": {"e":"depthUpdate","E":1787603084514,"s":"BTCUSDT","U":99076633855,"u":99076633884,"b":[["78709.99000000","4.23300000"],["78709.98000000","0.00062000"],["78707.53000000","0.19382000"],["72420.55000000","0.00014000"],["70839.00000000","0.00320000"],["70838.00000000","0.00008000"],["62968.00000000","0.00041000"]],"a":[["78710.00000000","0.90290000"],["78774.23000000","0.00007000"]]}}
{"rx_ns": 27153135700, "frame": {"e":"depthUpdate","E":1787603084614,"s":"BTCUSDT","U":99076633885,"u":99076633888,"b":[["78573.63000000","0.00406000"],["62968.00000000","0.00010000"]],"a":[["78711.24000000","0.00333000"],["79095.45000000","0.00089000"]]}}
{"rx_ns": 27252491000, "frame": {"e":"depthUpdate","E":1787603084714,"s":"BTCUSDT","U":99076633889,"u":99076633934,"b":[["78709.99000000","4.23209000"],["78709.98000000","0.00020000"],["78706.27000000","0.46819000"],["78703.58000000","0.00400000"],["78670.58000000","0.00000000"],["78665.46000000","0.00317000"],["70839.00000000","0.00336000"],["70834.50000000","0.00000000"]],"a":[["78710.00000000","0.46884000"],["78710.01000000","0.00097000"],["78717.98000000","0.00000000"],["78719.24000000","0.00254000"],["78719.60000000","0.00000000"],["78720.47000000","0.00137000"],["78795.26000000","0.00320000"],["78800.38000000","0.00000000"]]}}
{"rx_ns": 27355209600, "frame": {"e":"depthUpdate","E":1787603084814,"s":"BTCUSDT","U":99076633935,"u":99076633970,"b":[["78709.99000000","4.22971000"],["78626.36000000","0.02116000"],["78316.44000000","0.00010000"],["77924.85000000","0.00000000"],["77535.23000000","0.00000000"],["77147.55000000","0.00000000"],["76761.81000000","0.00000000"],["76378.01000000","0.00000000"],["75996.12000000","0.00000000"],["75616.13000000","0.00000000"],["75238.05000000","0.00000000"],["74861.86000000","0.00000000"],["74487.55000000","0.00000000"],["74115.12000000","0.00000000"],["73744.54000000","0.00000000"],["73375.82000000","0.00000000"],["73008.94000000","0.00000000"],["70839.00000000","0.00336000"]],"a":[["78759.04000000","0.00000000"],["78759.35000000","0.00316000"],["78777.11000000","0.00406000"],["79103.55000000","0.00000000"],["79499.07000000","0.00000000"],["79896.57000000","0.00027000"],["80296.05000000","0.00000000"],["80697.53000000","0.00000000"],["81101.02000000","0.00000000"],["81506.52000000","0.00000000"],["81914.06000000","0.00000000"],["82323.63000000","0.00000000"],["82735.24000000","0.00000000"],["83148.92000000","0.00000000"],["83564.67000000","0.00000000"],["83982.49000000","0.00000000"],["84402.40000000","0.00000000"],["84824.41000000","0.00000000"]]}}
{"rx_ns": 27457901400, "frame": {"e":"depthUpdate","E":1787603084914,"s":"BTCUSDT","U":99076633971,"u":99076634019,"b":[["78709.99000000","4.23055000"],["78709.98000000","0.00062000"],["78702.07000000","0.00261000"],["78700.88000000","0.00000000"],["78626.36000000","0.00000000"],["70839.00000000","0.00352000"],["62967.99000000","0.00000000"]],"a":[["78710.00000000","0.63735000"],["78711.24000000","0.00000000"],["78713.18000000","0.00000000"],["78714.28000000","0.20866000"],["78716.61000000","0.00000000"],["78717.80000000","0.00254000"],["78721.20000000","0.01270000"],["78721.24000000","0.06350000"],["78771.66000000","0.00007000"],["80000.00000000","103.82403000"]]}}
{"rx_ns": 27553417200, "frame": {"e":"depthUpdate","E":1787603085014,"s":"BTCUSDT","U":99076634020,"u":99076634054,"b":[["78709.99000000","4.23062000"],["78709.98000000","0.00069000"],["78708.07000000","0.00635000"],["78707.25000000","0.00000000"],["78707.20000000","0.00000000"],["78706.48000000","0.00635000"],["78705.88000000","0.00000000"],["78704.81000000","0.00000000"],["77000.00000000","69.38256000"],["72420.55000000","0.00000000"],["70839.00000000","0.00368000"],["62968.00000000","0.00041000"]],"a":[["78710.00000000","0.63915000"],["78710.01000000","0.00097000"],["78712.57000000","0.05435000"],["78713.80000000","0.00327000"],["78714.00000000","0.02407000"],["78714.28000000","0.20873000"],["78717.17000000","0.02161000"],["78720.47000000","0.00000000"],["78721.18000000","0.00137000"],["78721.19000000","0.00000000"],["78721.81000000","0.31765000"],["78721.82000000","0.00000000"],["78722.40000000","0.00635000"],["78926.72000000","0.00406000"],["81025.10000000","0.00000000"],["81038.25000000","0.00000000"]]}}
{"rx_ns": 27652981500, "frame": {"e":"depthUpdate","E":1787603085114,"s":"BTCUSDT","U":99076634055,"u":99076634082,"b":[["78709.99000000","4.23069000"],["78709.98000000","0.00069000"],["78708.78000000","1.58183000"],["78708.07000000","0.00642000"],["78707.53000000","0.19382000"],["78707.40000000","0.05000000"],["78707.20000000","0.05000000"],["78706.27000000","0.46812000"],["78686.33000000","0.00007000"],["78609.18000000","0.00200000"],["78001.60000000","0.00000000"],["70839.00000000","0.00388000"]],"a":[["78710.00000000","0.63735000"],["78733.57000000","0.00007000"],["78736.18000000","0.00427000"],["78926.72000000","0.00000000"],["81014.80000000","0.00000000"]]}}
{"rx_ns": 27753331500, "frame": {"e":"depthUpdate","E":1787603085214,"s":"BTCUSDT","U":99076634083,"u":99076634127,"b":[["78709.99000000","4.22978000"],["78709.98000000","0.00027000"],["78708.80000000","0.00014000"],["78708.00000000","0.00500000"],["78707.53000000","0.19389000"],["78707.40000000","0.00007000"],["78707.20000000","0.05007000"],["78706.47000000","0.02000000"],["78706.28000000","0.30021000"],["78702.29000000","0.00400000"],["78694.17000000","0.00000000"],["78626.36000000","0.02116000"],["70839.00000000","0.00378000"],["62968.00000000","0.00010000"]],"a":[["78710.00000000","0.60648000"],["78710.01000000","0.00090000"],["78713.80000000","0.00000000"],["78721.81000000","0.00000000"],["78722.39000000","0.31765000"],["78722.40000000","0.00000000"],["78723.53000000","0.00635000"],["78927.00000000","0.00406000"]]}}
{"rx_ns": 27859560900, "frame": {"e":"depthUpdate","E":1787603085314,"s":"BTCUSDT","U":99076634128,"u":99076634162,"b":[["78709.99000000","3.92978000"],["78708.07000000","0.00642000"],["78708.06000000","0.00007000"],["78708.00000000","0.00507000"],["78707.53000000","0.19389000"],["78707.40000000","0.00000000"],["78707.25000000","0.05000000"],["78626.36000000","0.00000000"],["78597.62000000","0.02541000"],["70839.00000000","0.00384000"],["70838.00000000","0.00008000"],["62968.00000000","0.00010000"]],"a":[["78710.00000000","0.82752000"],["78710.01000000","0.00090000"],["78711.89000000","0.00014000"],["78711.90000000","0.19677000"],["78713.77000000","0.00000000"],["78714.00000000","0.02733000"],["78714.28000000","0.00007000"],["78927.00000000","0.00000000"],["80946.01000000","0.00000000"]]}}
{"rx_ns": 27953465000, "frame": {"e":"depthUpdate","E":1787603085414,"s":"BTCUSDT","U":99076634163,"u":99076634210,"b":[["78708.06000000","0.00014000"],["78707.53000000","0.19389000"],["78707.30000000","0.05000000"],["78707.20000000","0.00007000"],["78316.44000000","0.01010000"],["77924.85000000","0.01000000"],["77535.23000000","0.01000000"],["77147.55000000","0.01000000"],["76761.81000000","0.01000000"],["76378.01000000","0.01000000"],["75996.12000000","0.01000000"],["75616.13000000","0.01000000"],["75238.05000000","0.01000000"],["74861.86000000","0.01000000"],["74487.55000000","0.01000000"],["74115.12000000","0.01000000"],["73744.54000000","0.01000000"],["73375.82000000","0.01000000"],["73008.94000000","0.01000000"],["70839.00000000","0.00400000"]],"a":[["78710.00000000","0.82752000"],["78711.26000000","0.04070000"],["78711.90000000","0.19684000"],["78712.57000000","0.05428000"],["78714.00000000","0.02733000"],["78714.28000000","0.00000000"],["78927.00000000","0.00406000"],["79103.55000000","0.01000000"],["79499.07000000","0.01000000"],["79896.57000000","0.01027000"],["80296.05000000","0.01000000"],["80697.53000000","0.01000000"],["81101.02000000","0.01000000"],["81506.52000000","0.01000000"],["81914.06000000","0.01000000"],["82323.63000000","0.01000000"],["82735.24000000","0.01000000"],["83148.92000000","0.01000000"],["83564.67000000","0.01000000"],["83982.49000000","0.01000000"],["84402.40000000","0.01000000"],["84824.41000000","0.01000000"]]}}
{"rx_ns": 28053597800, "frame": {"e":"depthUpdate","E":1787603085514,"s":"BTCUSDT","U":99076634211,"u":99076634225,"b":[["78707.53000000","0.19389000"],["78707.30000000","0.00007000"],["78707.20000000","0.05000000"],["78610.60000000","2.77206000"],["70839.00000000","0.00384000"],["70838.00000000","0.00018000"],["62968.00000000","0.00041000"]],"a":[["78712.01000000","0.00020000"],["78746.91000000","1.21978000"],["78759.70000000","0.00000000"]]}}
{"rx_ns": 28153250500, "frame": {"e":"depthUpdate","E":1787603085614,"s":"BTCUSDT","U":99076634226,"u":99076634238,"b":[["78707.53000000","0.19389000"],["78707.30000000","0.00000000"],["78707.25000000","0.00007000"],["78707.20000000","0.00000000"],["70839.00000000","0.00416000"],["70838.00000000","0.00018000"],["62968.00000000","0.00010000"]],"a":[]}}
{"rx_ns": 28253374300, "frame": {"e":"depthUpdate","E":1787603085714,"s":"BTCUSDT","U":99076634239,"u":99076634249,"b":[["78709.99000000","3.73623000"],["78707.53000000","0.19382000"],["78707.25000000","0.00000000"],["78706.48000000","0.00007000"],["78705.03000000","0.00635000"],["70839.00000000","0.00416000"],["70838.00000000","0.00008000"]],"a":[["78853.35000000","0.00000000"]]}}
{"rx_ns": 28355481700, "frame": {"e":"depthUpdate","E":1787603085814,"s":"BTCUSDT","U":99076634250,"u":99076634258,"b":[["78707.53000000","0.19382000"],["78706.48000000","0.00000000"],["78706.47000000","0.02007000"],["70839.00000000","0.00432000"]],"a":[["80863.37000000","0.00000000"],["80942.85000000","0.00031000"]]}}
{"rx_ns": 28458992800, "frame": {"e":"depthUpdate","E":1787603085916,"s":"BTCUSDT","U":99076634259,"u":99076634296,"b":[["78705.01000000","0.21534000"],["78704.66000000","0.00000000"],["78316.44000000","0.00010000"],["77924.85000000","0.00000000"],["77535.23000000","0.00000000"],["77147.55000000","0.00000000"],["76761.81000000","0.00000000"],["76378.01000000","0.00000000"],["75996.12000000","0.00000000"],["75616.13000000","0.00000000"],["75238.05000000","0.00000000"],["74861.86000000","0.00000000"],["74487.55000000","0.00000000"],["74115.12000000","0.00000000"],["73744.54000000","0.00000000"],["73375.82000000","0.00000000"],["73008.94000000","0.00000000"],["70839.00000000","0.00416000"],["62967.99000000","0.00000000"]],"a":[["79103.55000000","0.00000000"],["79499.07000000","0.00000000"],["79896.57000000","0.00027000"],["80296.05000000","0.00000000"],["80697.53000000","0.00000000"],["80853.09000000","0.00000000"],["81101.02000000","0.00000000"],["81506.52000000","0.00000000"],["81914.06000000","0.00000000"],["82323.63000000","0.00000000"],["82735.24000000","0.00000000"],["83148.92000000","0.00000000"],["83564.67000000","0.00000000"],["83982.49000000","0.00000000"],["84402.40000000","0.00000000"],["84824.41000000","0.00000000"]]}}
{"rx_ns": 28559957400, "frame": {"e":"depthUpdate","E":1787603086014,"s":"BTCUSDT","U":99076634297,"u":99076634308,"b":[["78709.99000000","3.94466000"],["78707.55000000","0.05014000"],["78707.50000000","0.05000000"],["78705.01000000","0.21541000"],["78704.61000000","0.12712000"],["70839.00000000","0.00432000"],["62968.00000000","0.00041000"]],"a":[["78710.00000000","0.82765000"],["78719.66000000","0.00137000"],["78721.18000000","0.00000000"],["80250.00000000","1.69141000"]]}}
{"rx_ns": 28665633000, "frame": {"e":"depthUpdate","E":1787603086115,"s":"BTCUSDT","U":99076634309,"u":99076634329,"b":[["78708.00000000","0.00507000"],["78707.55000000","0.00021000"],["78707.53000000","0.19382000"],["78707.50000000","0.00000000"],["78706.47000000","0.02000000"],["78705.01000000","0.21534000"],["78704.61000000","0.00000000"],["78686.33000000","0.00007000"],["78626.36000000","0.02116000"],["78545.97000000","0.01990000"],["78518.35000000","0.00000000"],["78001.60000000","0.00010000"],["70839.00000000","0.00416000"]],"a":[["78710.00000000","0.82775000"],["78733.57000000","0.00007000"]]}}
{"rx_ns": 28761652300, "frame": {"e":"depthUpdate","E":1787603086214,"s":"BTCUSDT","U":99076634330,"u":99076634344,"b":[["78708.00000000","0.00507000"],["78707.55000000","0.00014000"],["78707.53000000","0.19382000"],["78707.35000000","0.05000000"],["78707.30000000","0.05000000"],["78706.47000000","0.02007000"],["78500.81000000","0.01990000"],["78488.05000000","0.00000000"],["70839.00000000","0.00416000"],["62968.00000000","0.00010000"]],"a":[["80830.52000000","0.00000000"],["80846.94000000","0.00000000"]]}}
{"rx_ns": 28857542700, "frame": {"e":"depthUpdate","E":1787603086316,"s":"BTCUSDT","U":99076634345,"u":99076634360,"b":[["78707.53000000","0.19389000"],["78707.40000000","0.05000000"],["78707.35000000","0.05007000"],["78707.30000000","0.00000000"],["78706.47000000","0.02000000"],["78626.36000000","0.00000000"],["70839.00000000","0.00416000"],["70838.00000000","0.00008000"],["62968.00000000","0.00010000"]],"a":[["80784.44000000","0.00000000"],["80790.75000000","0.00000000"]]}}
{"rx_ns": 28953294300, "frame": {"e":"depthUpdate","E":1787603086414,"s":"BTCUSDT","U":99076634361,"u":99076634373,"b":[["78707.53000000","0.19396000"],["78707.40000000","0.00007000"],["78707.35000000","0.05000000"],["78705.01000000","0.21541000"],["78704.33000000","0.00000000"],["70839.00000000","0.00416000"]],"a":[]}}
{"rx_ns": 29054696700, "frame": {"e":"depthUpdate","E":1787603086514,"s":"BTCUSDT","U":99076634374,"u":99076634421,"b":[["78707.53000000","0.19389000"],["78707.45000000","0.05000000"],["78707.40000000","0.00000000"],["78707.35000000","0.00007000"],["78705.01000000","0.21534000"],["78704.92000000","0.00000000"],["78704.21000000","0.00000000"],["78316.44000000","0.01010000"],["77924.85000000","0.01000000"],["77535.23000000","0.01000000"],["77147.55000000","0.01000000"],["76761.81000000","0.01000000"],["76378.01000000","0.01000000"],["75996.12000000","0.01000000"],["75616.13000000","0.01000000"],["75238.05000000","0.01000000"],["74861.86000000","0.01000000"],["74487.55000000","0.01000000"],["74115.12000000","0.01000000"],["73744.54000000","0.01000000"],["73375.82000000","0.01000000"],["73008.94000000","0.01000000"],["70839.00000000","0.00432000"],["62968.00000000","0.00041000"]],"a":[["79103.55000000","0.01000000"],["79499.07000000","0.01000000"],["79896.57000000","0.01027000"],["80296.05000000","0.01000000"],["80697.53000000","0.01000000"],["81101.02000000","0.01000000"],["81506.52000000","0.01000000"],["81914.06000000","0.01000000"],["82323.63000000","0.01000000"],["82735.24000000","0.01000000"],["83148.92000000","0.01000000"],["83564.67000000","0.01000000"],["83982.49000000","0.01000000"],["84402.40000000","0.01000000"],["84824.41000000","0.01000000"]]}}
{"rx_ns": 29152693500, "frame": {"e":"depthUpdate","E":1787603086614,"s":"BTCUSDT","U":99076634422,"u":99076634433,"b":[["78707.53000000","0.19389000"],["78707.50000000","0.05000000"],["78707.45000000","0.05007000"],["78707.35000000","0.00000000"],["70839.00000000","0.00416000"],["62968.00000000","0.00010000"]],"a":[["80781.28000000","0.00000000"]]}}
{"rx_ns": 29257393400, "frame": {"e":"depthUpdate","E":1787603086714,"s":"BTCUSDT","U":99076634434,"u":99076634441,"b":[["78707.53000000","0.19389000"],["78707.45000000","0.00007000"],["78706.00000000","0.01949000"],["70839.00000000","0.00432000"]],"a":[["78721.99000000","0.00635000"],["78723.53000000","0.00000000"]]}}
{"rx_ns": 29352707600, "frame": {"e":"depthUpdate","E":1787603086814,"s":"BTCUSDT","U":99076634442,"u":99076634453,"b":[["78709.99000000","3.98482000"],["78707.53000000","0.19389000"],["78707.50000000","0.00007000"],["78707.45000000","0.00000000"],["78704.86000000","0.00000000"],["70839.00000000","0.00400000"]],"a":[["80701.96000000","0.00000000"]]}}
{"rx_ns": 29454952700, "frame": {"e":"depthUpdate","E":1787603086914,"s":"BTCUSDT","U":99076634454,"u":99076634472,"b":[["78707.53000000","0.19382000"],["78707.50000000","0.00000000"],["78706.47000000","0.02007000"],["78705.01000000","0.21541000"],["78704.33000000","0.00000000"],["78626.36000000","0.00000000"],["70839.00000000","0.00432000"],["62967.99000000","0.00000000"]],"a":[["78922.11000000","0.01990000"],["78930.06000000","0.00000000"],["80691.70000000","0.00000000"]]}}
{"rx_ns": 29560700500, "frame": {"e":"depthUpdate","E":1787603087014,"s":"BTCUSDT","U":99076634473,"u":99076634513,"b":[["78707.35000000","0.05000000"],["78707.15000000","0.05000000"],["78705.01000000","0.21534000"],["78316.44000000","0.00010000"],["77924.85000000","0.00000000"],["77535.23000000","0.00000000"],["77147.55000000","0.00000000"],["76761.81000000","0.00000000"],["76378.01000000","0.00000000"],["75996.12000000","0.00000000"],["75616.13000000","0.00000000"],["75238.05000000","0.00000000"],["74861.86000000","0.00000000"],["74487.55000000","0.00000000"],["74115.12000000","0.00000000"],["73744.54000000","0.00000000"],["73375.82000000","0.00000000"],["73008.94000000","0.00000000"],["70839.00000000","0.00416000"],["62968.00000000","0.00041000"]],"a":[["78719.66000000","0.00000000"],["78720.47000000","0.00137000"],["79103.55000000","0.00000000"],["79499.07000000","0.00000000"],["79896.57000000","0.00027000"],["80296.05000000","0.00000000"],["80629.49000000","0.00009000"],["80669.18000000","0.00000000"],["80685.56000000","0.00000000"],["80697.53000000","0.00000000"],["81101.02000000","0.00000000"],["81506.52000000","0.00000000"],["81914.06000000","0.00000000"],["82323.63000000","0.00000000"],["82735.24000000","0.00000000"],["83148.92000000","0.00000000"],["83564.67000000","0.00000000"],["83982.49000000","0.00000000"],["84402.40000000","0.00000000"],["84824.41000000","0.00000000"]]}}
{"rx_ns": 29653839100, "frame": {"e":"depthUpdate","E":1787603087114,"s":"BTCUSDT","U":99076634514,"u":99076634531,"b":[["78709.99000000","3.98489000"],["78707.53000000","0.19382000"],["78707.35000000","0.00007000"],["78707.15000000","0.00000000"],["78706.47000000","0.02000000"],["78686.33000000","0.00007000"],["70839.00000000","0.00416000"],["65000.00000000","77.52239000"]],"a":[["78710.00000000","0.60845000"],["78721.99000000","0.00000000"],["78722.93000000","0.00635000"],["78725.28000000","0.00800000"],["78727.82000000","0.00000000"],["78733.57000000","0.00007000"],["80623.19000000","0.00000000"]]}}
{"rx_ns": 29752871900, "frame": {"e":"depthUpdate","E":1787603087214,"s":"BTCUSDT","U":99076634532,"u":99076634559,"b":[["78709.99000000","3.98489000"],["78709.98000000","0.00027000"],["78707.53000000","0.19382000"],["78707.35000000","0.00000000"],["78707.25000000","0.05000000"],["78707.20000000","0.05000000"],["78706.47000000","0.02007000"],["78702.07000000","0.00007000"],["70839.00000000","0.00425000"],["62968.00000000","0.00010000"]],"a":[["78710.00000000","0.60090000"],["78711.89000000","0.00000000"],["78711.90000000","0.00007000"],["78713.77000000","0.00007000"],["78717.80000000","0.00000000"],["78720.47000000","0.00000000"],["78721.82000000","0.00137000"],["78722.93000000","0.00000000"],["78724.10000000","0.00635000"],["78724.96000000","0.00000000"],["78730.87000000","0.02000000"],["78732.10000000","0.00000000"],["80620.03000000","0.00000000"]]}}
{"rx_ns": 29858441900, "frame": {"e":"depthUpdate","E":1787603087315,"s":"BTCUSDT","U":99076634560,"u":99076634583,"b":[["78707.53000000","0.19389000"],["78707.30000000","0.05000000"],["78707.25000000","0.05007000"],["78707.20000000","0.00000000"],["78706.47000000","0.02000000"],["78703.04000000","0.00254000"],["70839.00000000","0.00441000"],["62968.00000000","0.00010000"]],"a":[["78710.00000000","0.60076000"],["78710.01000000","0.00083000"],["78711.26000000","0.04070000"],["78711.90000000","0.00000000"],["78714.00000000","0.02407000"],["78717.17000000","0.02168000"],["78718.78000000","0.00254000"]]}}
{"rx_ns": 29952853900, "frame": {"e":"depthUpdate","E":1787603087414,"s":"BTCUSDT","U":99076634584,"u":99076634608,"b":[["78709.99000000","3.98130000"],["78707.53000000","0.19389000"],["78707.30000000","0.00007000"],["78707.25000000","0.00000000"],["78706.00000000","0.02400000"],["78626.36000000","0.02116000"],["70839.00000000","0.00425000"],["70838.00000000","0.00008000"]],"a":[["78710.00000000","0.92801000"],["78712.78000000","0.22336000"],["78758.73000000","0.00400000"],["78759.35000000","0.00000000"],["78759.36000000","0.00000000"],["78759.75000000","0.00315000"],["78837.94000000","0.00000000"]]}}
{"rx_ns": 30057852700, "frame": {"e":"depthUpdate","E":1787603087514,"s":"BTCUSDT","U":99076634609,"u":99076634662,"b":[["78707.53000000","0.19382000"],["78707.30000000","0.00000000"],["78706.47000000","0.02007000"],["78626.36000000","0.00000000"],["78316.44000000","0.01010000"],["77924.85000000","0.01000000"],["77535.23000000","0.01000000"],["77147.55000000","0.01000000"],["76761.81000000","0.01000000"],["76378.01000000","0.01000000"],["75996.12000000","0.01000000"],["75616.13000000","0.01000000"],["75238.05000000","0.01000000"],["74861.86000000","0.01000000"],["74487.55000000","0.01000000"],["74115.12000000","0.01000000"],["73744.54000000","0.01000000"],["73375.82000000","0.01000000"],["73008.94000000","0.01000000"],["70839.00000000","0.00432000"],["70838.99000000","0.00009000"],["62968.00000000","0.00041000"]],"a":[["78710.00000000","0.60074000"],["78710.01000000","0.00090000"],["78712.57000000","0.05435000"],["78712.77000000","0.00007000"],["78712.78000000","0.22343000"],["78714.15000000","0.00319000"],["78717.17000000","0.02161000"],["78806.33000000","0.93647000"],["78808.94000000","0.00000000"],["79103.55000000","0.01000000"],["79499.07000000","0.01000000"],["79896.57000000","0.01027000"],["80296.05000000","0.01000000"],["80697.53000000","0.01000000"],["81101.02000000","0.01000000"],["81506.52000000","0.01000000"],["81914.06000000","0.01000000"],["82323.63000000","0.01000000"],["82735.24000000","0.01000000"],["83148.92000000","0.01000000"],["83564.67000000","0.01000000"],["83982.49000000","0.01000000"],["84402.40000000","0.01000000"],["84824.41000000","0.01000000"]]}}
{"rx_ns": 30154693700, "frame": {"e":"depthUpdate","E":1787603087616,"s":"BTCUSDT","U":99076634663,"u":99076634672,"b":[["78707.40000000","0.05000000"],["78528.59000000","0.00778000"],["78520.83000000","0.00000000"],["70839.00000000","0.00416000"],["62968.00000000","0.00010000"]],"a":[["78712.01000000","0.00027000"],["78721.18000000","0.01270000"],["78721.20000000","0.00000000"],["78877.35000000","0.00000000"]]}}
{"rx_ns": 30253396500, "frame": {"e":"depthUpdate","E":1787603087714,"s":"BTCUSDT","U":99076634673,"u":99076634697,"b":[["78709.99000000","3.78775000"],["78707.53000000","0.19382000"],["78707.40000000","0.00000000"],["78707.30000000","0.05000000"],["70839.00000000","0.00416000"]],"a":[["78710.00000000","0.81998000"],["78710.01000000","0.00090000"],["78711.64000000","0.00014000"],["78711.65000000","0.17846000"],["78712.77000000","0.00000000"],["78712.78000000","0.00007000"],["78713.58000000","0.00000000"],["78713.77000000","0.00000000"],["78721.99000000","0.00635000"],["78724.10000000","0.00000000"],["78732.10000000","0.36224000"]]}}
{"rx_ns": 30352920400, "frame": {"e":"depthUpdate","E":1787603087814,"s":"BTCUSDT","U":99076634698,"u":99076634721,"b":[["78707.53000000","0.19382000"],["78707.30000000","0.00000000"],["70838.99000000","0.00000000"]],"a":[["78710.00000000","0.51183000"],["78711.26000000","0.04070000"],["78711.64000000","0.00000000"],["78711.65000000","0.00007000"],["78712.57000000","0.05428000"],["78712.78000000","0.00000000"],["78713.77000000","0.00007000"]]}}
{"rx_ns": 30452969000, "frame": {"e":"depthUpdate","E":1787603087914,"s":"BTCUSDT","U":99076634722,"u":99076634745,"b":[["78707.53000000","0.19382000"],["78705.01000000","0.21534000"],["78704.39000000","0.00000000"],["70839.00000000","0.00400000"],["62967.99000000","0.00000000"]],"a":[["78710.00000000","0.51169000"],["78710.01000000","0.00090000"],["78711.26000000","0.04070000"],["78711.65000000","0.00000000"],["78717.17000000","0.02168000"],["78721.99000000","0.00000000"],["78723.47000000","0.00635000"]]}}
{"rx_ns": 30553034500, "frame": {"e":"depthUpdate","E":1787603088014,"s":"BTCUSDT","U":99076634746,"u":99076634787,"b":[["78707.40000000","0.05000000"],["78707.35000000","0.05000000"],["78705.01000000","0.21534000"],["78704.39000000","0.00000000"],["78316.44000000","0.00010000"],["77924.85000000","0.00000000"],["77535.23000000","0.00000000"],["77147.55000000","0.00000000"],["76761.81000000","0.00000000"],["76378.01000000","0.00000000"],["75996.12000000","0.00000000"],["75616.13000000","0.00000000"],["75238.05000000","0.00000000"],["74861.86000000","0.00000000"],["74487.55000000","0.00000000"],["74115.12000000","0.00000000"],["73744.54000000","0.00000000"],["73375.82000000","0.00000000"],["73008.94000000","0.00000000"],["70839.00000000","0.00416000"],["62968.00000000","0.00041000"]],"a":[["78718.81000000","0.00007000"],["79103.55000000","0.00000000"],["79499.07000000","0.00000000"],["79896.57000000","0.00027000"],["80296.05000000","0.00000000"],["80540.87000000","0.00000000"],["80697.53000000","0.00000000"],["81101.02000000","0.00000000"],["81506.52000000","0.00000000"],["81914.06000000","0.00000000"],["82323.63000000","0.00000000"],["82735.24000000","0.00000000"],["83148.92000000","0.00000000"],["83564.67000000","0.00000000"],["83982.49000000","0.00000000"],["84402.40000000","0.00000000"],["84824.41000000","0.00000000"]]}}
{"rx_ns": 30652609400, "frame": {"e":"depthUpdate","E":1787603088114,"s":"BTCUSDT","U":99076634788,"u":99076634805,"b":[["78707.53000000","0.19389000"],["78707.40000000","0.00007000"],["78707.35000000","0.00000000"],["78706.47000000","0.02000000"],["78704.11000000","0.00000000"],["78686.33000000","0.00007000"],["78671.25000000","0.00417000"],["78671.00000000","0.00000000"],["70839.00000000","0.00400000"]],"a":[["78710.00000000","0.50989000"],["78713.78000000","0.26005000"],["78733.57000000","0.00007000"],["80530.63000000","0.00000000"]]}}
{"rx_ns": 30753865200, "frame": {"e":"depthUpdate","E":1787603088215,"s":"BTCUSDT","U":99076634806,"u":99076634821,"b":[["78709.99000000","3.78763000"],["78707.53000000","0.19382000"],["78707.40000000","0.00000000"],["78707.35000000","0.05000000"],["78707.30000000","0.05000000"],["78706.47000000","0.02007000"],["78626.36000000","0.02116000"],["70839.00000000","0.00416000"],["62968.00000000","0.00010000"]],"a":[["78710.00000000","0.50981000"],["78712.57000000","0.05435000"],["78713.58000000","0.00007000"]]}}
{"rx_ns": 30855403300, "frame": {"e":"depthUpdate","E":1787603088314,"s":"BTCUSDT","U":99076634822,"u":99076634839,"b":[["78707.53000000","0.19389000"],["78707.35000000","0.05007000"],["78707.30000000","0.00000000"],["78706.47000000","0.02000000"],["78626.36000000","0.00000000"],["70839.00000000","0.00416000"],["62968.00000000","0.00010000"]],"a":[["78710.00000000","0.51161000"]]}}
{"rx_ns": 30953157300, "frame": {"e":"depthUpdate","E":1787603088414,"s":"BTCUSDT","U":99076634840,"u":99076634851,"b":[["78707.35000000","0.00007000"],["78707.30000000","0.05000000"],["78626.36000000","0.02116000"],["76500.00000000","16.88036000"],["70839.00000000","0.00416000"]],"a":[["78710.00000000","0.87479000"],["78835.93000000","0.00160000"],["80524.51000000","0.00010000"]]}}
{"rx_ns": 31052790100, "frame": {"e":"depthUpdate","E":1787603088514,"s":"BTCUSDT","U":99076634852,"u":99076634894,"b":[["78707.53000000","0.19389000"],["78707.35000000","0.00000000"],["78707.30000000","0.05007000"],["78626.36000000","0.00000000"],["78316.44000000","0.01010000"],["77924.85000000","0.01000000"],["77535.23000000","0.01000000"],["77147.55000000","0.01000000"],["76761.81000000","0.01000000"],["76378.01000000","0.01000000"],["75996.12000000","0.01000000"],["75616.13000000","0.01000000"],["75238.05000000","0.01000000"],["74861.86000000","0.01000000"],["74487.55000000","0.01000000"],["74115.12000000","0.01000000"],["73744.54000000","0.01000000"],["73375.82000000","0.01000000"],["73008.94000000","0.01000000"],["70839.00000000","0.00416000"],["70838.00000000","0.00028000"],["62968.00000000","0.00041000"]],"a":[["78710.00000000","0.51161000"],["79103.55000000","0.01000000"],["79499.07000000","0.01000000"],["79896.57000000","0.01027000"],["80296.05000000","0.01000000"],["80697.53000000","0.01000000"],["81101.02000000","0.01000000"],["81506.52000000","0.01000000"],["81914.06000000","0.01000000"],["82323.63000000","0.01000000"],["82735.24000000","0.01000000"],["83148.92000000","0.01000000"],["83564.67000000","0.01000000"],["83982.49000000","0.01000000"],["84402.40000000","0.01000000"],["84824.41000000","0.01000000"]]}}
{"rx_ns": 31153027600, "frame": {"e":"depthUpdate","E":1787603088614,"s":"BTCUSDT","U":99076634895,"u":99076634910,"b":[["78707.35000000","0.05000000"],["78705.01000000","0.21541000"],["78704.27000000","0.12712000"],["78626.36000000","0.02116000"],["70839.00000000","0.00432000"],["70838.00000000","0.00008000"],["62968.00000000","0.00010000"]],"a":[["78710.00000000","0.51168000"],["78711.87000000","0.00014000"],["78711.88000000","0.23327000"],["78713.77000000","0.00000000"],["78713.78000000","0.04882000"],["78718.81000000","0.00000000"]]}}
{"rx_ns": 31256116100, "frame": {"e":"depthUpdate","E":1787603088714,"s":"BTCUSDT","U":99076634911,"u":99076634933,"b":[["78709.99000000","3.78662000"],["78707.53000000","0.19389000"],["78707.35000000","0.00000000"],["78707.30000000","0.00007000"],["78707.25000000","0.05000000"],["70839.00000000","0.00400000"],["70838.99000000","0.00009000"]],"a":[["78710.00000000","0.86001000"],["78710.01000000","0.00097000"],["78711.26000000","0.04070000"],["78711.88000000","0.23334000"],["78712.01000000","0.00020000"],["78717.17000000","0.02161000"],["78719.82000000","0.00137000"],["78721.82000000","0.00000000"],["78875.34000000","0.00160000"],["80508.16000000","0.00000000"]]}}
{"rx_ns": 31353297500, "frame": {"e":"depthUpdate","E":1787603088814,"s":"BTCUSDT","U":99076634934,"u":99076634950,"b":[["78707.53000000","0.19389000"],["78707.30000000","0.00000000"],["78707.25000000","0.00007000"],["78626.36000000","0.00000000"],["78528.59000000","0.00000000"],["78520.83000000","0.00778000"],["77500.00000000","13.67590000"],["70839.00000000","0.00432000"]],"a":[["78710.00000000","0.51168000"],["78710.01000000","0.00090000"],["78714.15000000","0.00000000"]]}}
{"rx_ns": 31459846600, "frame": {"e":"depthUpdate","E":1787603088914,"s":"BTCUSDT","U":99076634951,"u":99076634966,"b":[["78707.53000000","0.19382000"],["78707.25000000","0.00000000"],["78706.47000000","0.02007000"],["78705.01000000","0.21541000"],["78704.31000000","0.12712000"],["78704.27000000","0.00000000"],["70839.00000000","0.00416000"],["62967.99000000","0.00000000"]],"a":[]}}
{"rx_ns": 31557008400, "frame": {"e":"depthUpdate","E":1787603089014,"s":"BTCUSDT","U":99076634967,"u":99076635005,"b":[["78316.44000000","0.00010000"],["77924.85000000","0.00000000"],["77535.23000000","0.00000000"],["77147.55000000","0.00000000"],["76761.81000000","0.00000000"],["76378.01000000","0.00000000"],["75996.12000000","0.00000000"],["75616.13000000","0.00000000"],["75238.05000000","0.00000000"],["74861.86000000","0.00000000"],["74487.55000000","0.00000000"],["74115.12000000","0.00000000"],["73744.54000000","0.00000000"],["73375.82000000","0.00000000"],["73008.94000000","0.00000000"],["70839.00000000","0.00416000"],["70838.99000000","0.00000000"],["70838.98000000","0.00009000"],["62968.00000000","0.00041000"]],"a":[["78710.00000000","0.50919000"],["78719.82000000","0.00000000"],["78721.17000000","0.00137000"],["79103.55000000","0.00000000"],["79499.07000000","0.00000000"],["79896.57000000","0.00027000"],["80296.05000000","0.00000000"],["80459.11000000","0.00000000"],["80462.26000000","0.00000000"],["80468.55000000","0.00000000"],["80697.53000000","0.00000000"],["81101.02000000","0.00000000"],["81506.52000000","0.00000000"],["81914.06000000","0.00000000"],["82323.63000000","0.00000000"],["82735.24000000","0.00000000"],["83148.92000000","0.00000000"],["83564.67000000","0.00000000"],["83982.49000000","0.00000000"],["84402.40000000","0.00000000"],["84824.41000000","0.00000000"]]}}
{"rx_ns": 31654682500, "frame": {"e":"depthUpdate","E":1787603089114,"s":"BTCUSDT","U":99076635006,"u":99076635031,"b":[["78709.99000000","3.78655000"],["78709.98000000","0.00020000"],["78707.20000000","0.00000000"],["78707.15000000","0.00000000"],["78686.33000000","0.00000000"],["78626.36000000","0.02116000"],["70839.00000000","0.00416000"]],"a":[["78710.00000000","0.50199000"],["78714.48000000","0.00327000"],["78733.57000000","0.00000000"]]}}
{"rx_ns": 31752887600, "frame": {"e":"depthUpdate","E":1787603089214,"s":"BTCUSDT","U":99076635032,"u":99076635038,"b":[["78686.33000000","0.00007000"],["70839.00000000","0.00416000"],["62968.00000000","0.00010000"]],"a":[["78733.57000000","0.00007000"]]}}
{"rx_ns": 31852639400, "frame": {"e":"depthUpdate","E":1787603089314,"s":"BTCUSDT","U":99076635039,"u":99076635047,"b":[["78707.25000000","0.00000000"],["78707.20000000","0.00000000"],["78626.36000000","0.00000000"],["70839.00000000","0.00416000"],["62968.00000000","0.00010000"]],"a":[]}}
{"rx_ns": 31953115700, "frame": {"e":"depthUpdate","E":1787603089414,"s":"BTCUSDT","U":99076635048,"u":99076635052,"b":[["78707.35000000","0.05000000"],["70839.00000000","0.00426000"]],"a":[["80380.10000000","0.00000000"]]}}
{"rx_ns": 32052642200, "frame": {"e":"depthUpdate","E":1787603089514,"s":"BTCUSDT","U":99076635053,"u":99076635093,"b":[["78707.53000000","0.19382000"],["78704.31000000","0.00000000"],["78316.44000000","0.01010000"],["77924.85000000","0.01000000"],["77535.23000000","0.01000000"],["77147.55000000","0.01000000"],["76761.81000000","0.01000000"],["76378.01000000","0.01000000"],["75996.12000000","0.01000000"],["75616.13000000","0.01000000"],["75238.05000000","0.01000000"],["74861.86000000","0.01000000"],["74487.55000000","0.01000000"],["74115.12000000","0.01000000"],["73744.54000000","0.01000000"],["73375.82000000","0.01000000"],["73008.94000000","0.01000000"],["70839.00000000","0.00432000"],["62968.00000000","0.00041000"]],"a":[["79103.55000000","0.01000000"],["79499.07000000","0.01000000"],["79896.57000000","0.01027000"],["80296.05000000","0.01000000"],["80369.89000000","0.00000000"],["80697.53000000","0.01000000"],["81101.02000000","0.01000000"],["81506.52000000","0.01000000"],["81914.06000000","0.01000000"],["82323.63000000","0.01000000"],["82735.24000000","0.01000000"],["83148.92000000","0.01000000"],["83564.67000000","0.01000000"],["83982.49000000","0.01000000"],["84402.40000000","0.01000000"],["84824.41000000","0.01000000"]]}}
{"rx_ns": 32153113000, "frame": {"e":"depthUpdate","E":1787603089614,"s":"BTCUSDT","U":99076635094,"u":99076635107,"b":[["78707.35000000","0.00000000"],["78706.27000000","0.46812000"],["78705.15000000","0.00000000"],["78705.01000000","0.21534000"],["78704.71000000","0.00000000"],["70839.00000000","0.00416000"],["70838.00000000","0.00008000"],["62968.00000000","0.00010000"]],"a":[]}}
{"rx_ns": 32255007500, "kind": "rest", "req": {"method": "GET", "url": "https://data-api.binance.vision/api/v3/depth?symbol=BTCUSDT&limit=100", "limit": 100, "weight": 5, "sent_ns": 31256451400, "status": 200, "used_weight_1m": "20", "recv_ns": 32215143000}, "frame": {"lastUpdateId":99076635107,"bids":[["78709.99000000","3.78655000"],["78709.98000000","0.00020000"],["78709.97000000","0.00013000"],["78709.77000000","0.00400000"],["78708.85000000","0.00014000"],["78708.80000000","0.00014000"],["78708.79000000","1.97795000"],["78708.78000000","1.58183000"],["78708.07000000","0.00642000"],["78708.06000000","0.00014000"],["78708.00000000","0.00507000"],["78707.55000000","0.00014000"],["78707.54000000","0.31773000"],["78707.53000000","0.19382000"],["78707.16000000","0.00400000"],["78706.47000000","0.02007000"],["78706.28000000","0.30021000"],["78706.27000000","0.46812000"],["78706.26000000","0.00661000"],["78706.20000000","0.04014000"],["78706.16000000","0.00007000"],["78706.06000000","0.01373000"],["78706.00000000","0.02400000"],["78705.87000000","0.00400000"],["78705.03000000","0.00635000"],["78705.02000000","0.04199000"],["78705.01000000","0.21534000"],["78704.80000000","0.02289000"],["78704.55000000","0.00400000"],["78704.19000000","0.00014000"],["78704.12000000","0.00007000"],["78704.05000000","0.03224000"],["78704.00000000","0.02400000"],["78703.71000000","0.00595000"],["78703.63000000","0.00326000"],["78703.58000000","0.00400000"],["78703.57000000","1.21952000"],["78703.54000000","0.03001000"],["78703.04000000","0.00254000"],["78702.77000000","0.00010000"],["78702.29000000","0.00400000"],["78702.28000000","0.02747000"],["78702.07000000","0.00007000"],["78702.00000000","0.02400000"],["78701.92000000","0.00007000"],["78701.79000000","0.02800000"],["78701.73000000","0.02200000"],["78701.70000000","0.00008000"],["78701.59000000","0.00321000"],["78701.52000000","0.02287000"],["78701.41000000","0.00007000"],["78701.38000000","0.12706000"],["78701.14000000","0.00334000"],["78701.08000000","0.00027000"],["78701.00000000","0.00007000"],["78700.59000000","0.08576000"],["78700.49000000","0.02200000"],["78700.32000000","0.00414000"],["78700.17000000","0.00007000"],["78700.02000000","0.00007000"],["78700.01000000","0.01200000"],["78700.00000000","0.02407000"],["78699.56000000","0.00326000"],["78699.37000000","1.21952000"],["78698.85000000","0.36224000"],["78698.28000000","1.90515000"],["78698.26000000","0.00014000"],["78698.17000000","0.00007000"],["78698.04000000","0.00007000"],["78698.00000000","0.02400000"],["78697.98000000","0.00007000"],["78697.92000000","0.03224000"],["78697.84000000","0.00400000"],["78697.66000000","0.00762000"],["78697.43000000","0.00317000"],["78697.37000000","0.11000000"],["78696.89000000","0.02000000"],["78696.45000000","0.12721000"],["78696.04000000","0.00007000"],["78696.00000000","0.03701000"],["78695.93000000","0.00007000"],["78695.63000000","0.00190000"],["78695.36000000","0.00400000"],["78695.34000000","1.21952000"],["78695.20000000","0.00007000"],["78695.11000000","0.00007000"],["78695.07000000","0.04000000"],["78694.90000000","0.02410000"],["78694.86000000","0.02600000"],["78694.16000000","0.00007000"],["78694.08000000","1.21956000"],["78694.07000000","0.02800000"],["78694.00000000","0.02415000"],["78693.88000000","0.00014000"],["78693.51000000","0.38126000"],["78693.26000000","0.00326000"],["78693.12000000","0.00060000"],["78693.03000000","0.00027000"],["78693.00000000","0.70000000"],["78692.88000000","0.00400000"]],"asks":[["78710.00000000","0.50199000"],["78710.01000000","0.00090000"],["78710.02000000","0.00013000"],["78711.25000000","0.00014000"],["78711.26000000","0.04070000"],["78711.87000000","0.00014000"],["78711.88000000","0.23334000"],["78711.93000000","0.00014000"],["78711.99000000","0.00014000"],["78712.00000000","0.02407000"],["78712.01000000","0.00020000"],["78712.29000000","0.00007000"],["78712.51000000","0.00014000"],["78712.52000000","0.04882000"],["78712.56000000","0.00014000"],["78712.57000000","0.05435000"],["78713.56000000","0.00007000"],["78713.58000000","0.00007000"],["78713.78000000","0.04882000"],["78714.00000000","0.02407000"],["78714.34000000","0.00007000"],["78714.48000000","0.00327000"],["78715.00000000","0.00007000"],["78715.23000000","0.00322000"],["78715.79000000","0.00007000"],["78715.80000000","0.00014000"],["78716.00000000","0.02407000"],["78716.38000000","0.00007000"],["78716.52000000","0.00007000"],["78716.80000000","0.00319000"],["78717.17000000","0.02161000"],["78717.18000000","0.12717000"],["78717.44000000","0.00007000"],["78717.99000000","0.00007000"],["78718.00000000","0.02400000"],["78718.43000000","0.00007000"],["78718.77000000","0.00007000"],["78718.78000000","0.00254000"],["78719.24000000","0.00254000"],["78719.25000000","0.00254000"],["78719.26000000","0.00230000"],["78719.56000000","0.00331000"],["78719.61000000","0.00400000"],["78719.67000000","0.00014000"],["78719.83000000","0.03000000"],["78719.89000000","0.21930000"],["78720.00000000","0.02400000"],["78720.10000000","0.00027000"],["78720.13000000","0.04000000"],["78720.33000000","0.00007000"],["78720.48000000","0.00007000"],["78720.63000000","0.00192000"],["78720.76000000","0.00007000"],["78721.17000000","0.00137000"],["78721.18000000","0.01270000"],["78721.24000000","0.06350000"],["78721.32000000","0.00342000"],["78721.83000000","0.02007000"],["78722.00000000","0.02407000"],["78722.03000000","0.08000000"],["78722.39000000","0.31765000"],["78722.41000000","0.00047000"],["78722.52000000","0.00007000"],["78722.94000000","0.00400000"],["78723.47000000","0.00635000"],["78723.48000000","0.00007000"],["78723.50000000","0.00320000"],["78723.54000000","0.00014000"],["78723.94000000","0.00191000"],["78723.97000000","0.00007000"],["78724.00000000","0.02400000"],["78724.11000000","0.25411000"],["78724.57000000","0.00007000"],["78724.60000000","0.02161000"],["78724.61000000","0.02057000"],["78724.62000000","0.02782000"],["78724.80000000","0.00008000"],["78725.11000000","0.02000000"],["78725.20000000","0.00007000"],["78725.28000000","0.00800000"],["78725.29000000","0.00325000"],["78725.44000000","0.02600000"],["78725.46000000","0.00400000"],["78725.50000000","0.00048000"],["78725.90000000","0.04000000"],["78726.00000000","0.02400000"],["78726.15000000","0.02286000"],["78726.33000000","0.00254000"],["78726.62000000","0.00007000"],["78727.41000000","0.00014000"],["78727.44000000","0.00330000"],["78727.53000000","0.06588000"],["78727.62000000","0.05257000"],["78727.76000000","0.00007000"],["78727.83000000","0.00635000"],["78727.84000000","0.02161000"],["78727.85000000","0.12701000"],["78727.88000000","1.21952000"],["78727.89000000","0.21930000"],["78728.00000000","0.02400000"]]}}
{"rx_ns": 32255007500, "frame": {"e":"depthUpdate","E":1787603089714,"s":"BTCUSDT","U":99076635108,"u":99076635123,"b":[["78709.99000000","3.59307000"],["78709.98000000","0.00027000"],["78707.65000000","0.05000000"],["78707.53000000","0.19382000"],["78707.30000000","0.00000000"],["78705.01000000","0.21534000"],["78704.87000000","0.12712000"],["78704.82000000","0.00000000"],["70839.00000000","0.00432000"]],"a":[["78710.00000000","0.72116000"]]}}
{"rx_ns": 32355000300, "frame": {"e":"depthUpdate","E":1787603089814,"s":"BTCUSDT","U":99076635124,"u":99076635141,"b":[["78709.99000000","3.59317000"],["78708.00000000","0.00507000"],["78707.65000000","0.00000000"],["78705.01000000","0.21534000"],["78704.87000000","0.00000000"],["78704.51000000","0.00000000"],["78704.36000000","0.00000000"],["70839.00000000","0.00416000"]],"a":[["78717.10000000","0.00008000"],["80363.78000000","0.00000000"]]}}
{"rx_ns": 32459256600, "frame": {"e":"depthUpdate","E":1787603089914,"s":"BTCUSDT","U":99076635142,"u":99076635150,"b":[["78708.00000000","0.00507000"],["78703.88000000","0.12712000"],["70839.00000000","0.00432000"],["62967.99000000","0.00020000"]],"a":[]}}
{"rx_ns": 32552992800, "frame": {"e":"depthUpdate","E":1787603090014,"s":"BTCUSDT","U":99076635151,"u":99076635187,"b":[["78316.44000000","0.00010000"],["77924.85000000","0.00000000"],["77535.23000000","0.00000000"],["77147.55000000","0.00000000"],["76761.81000000","0.00000000"],["76378.01000000","0.00000000"],["75996.12000000","0.00000000"],["75616.13000000","0.00000000"],["75238.05000000","0.00000000"],["74861.86000000","0.00000000"],["74487.55000000","0.00000000"],["74115.12000000","0.00000000"],["73744.54000000","0.00000000"],["73375.82000000","0.00000000"],["73008.94000000","0.00000000"],["70839.00000000","0.00416000"],["62968.00000000","0.00041000"],["62967.99000000","0.00000000"]],"a":[["78753.87000000","0.00400000"],["78756.30000000","0.00400000"],["78756.75000000","0.00000000"],["78758.73000000","0.00000000"],["79103.55000000","0.00000000"],["79499.07000000","0.00000000"],["79896.57000000","0.00027000"],["80296.05000000","0.00000000"],["80697.53000000","0.00000000"],["81101.02000000","0.00000000"],["81506.52000000","0.00000000"],["81914.06000000","0.00000000"],["82323.63000000","0.00000000"],["82735.24000000","0.00000000"],["83148.92000000","0.00000000"],["83564.67000000","0.00000000"],["83982.49000000","0.00000000"],["84402.40000000","0.00000000"],["84824.41000000","0.00000000"]]}}
{"rx_ns": 32655207800, "frame": {"e":"depthUpdate","E":1787603090114,"s":"BTCUSDT","U":99076635188,"u":99076635199,"b":[["78707.45000000","0.00000000"],["78707.25000000","0.05000000"],["78705.01000000","0.21541000"],["72420.55000000","0.00014000"],["70839.00000000","0.00432000"],["70838.00000000","0.00028000"]],"a":[]}}
{"rx_ns": 32757023900, "frame": {"e":"depthUpdate","E":1787603090214,"s":"BTCUSDT","U":99076635200,"u":99076635213,"b":[["78707.53000000","0.19382000"],["78707.25000000","0.00000000"],["78686.33000000","0.00007000"],["78626.36000000","0.00000000"],["70839.00000000","0.00416000"],["70838.00000000","0.00018000"],["62968.00000000","0.00010000"]],"a":[["78733.57000000","0.00007000"]]}}
{"rx_ns": 32857741000, "frame": {"e":"depthUpdate","E":1787603090314,"s":"BTCUSDT","U":99076635214,"u":99076635227,"b":[["78707.53000000","0.19382000"],["78707.50000000","0.05000000"],["78707.45000000","0.00000000"],["78664.76000000","0.00000000"],["78658.23000000","0.04764000"],["78654.01000000","0.00335000"],["78626.36000000","0.02116000"],["70839.00000000","0.00416000"],["70838.00000000","0.00008000"],["62968.00000000","0.00010000"]],"a":[]}}
{"rx_ns": 32953507800, "frame": {"e":"depthUpdate","E":1787603090414,"s":"BTCUSDT","U":99076635228,"u":99076635235,"b":[["78707.53000000","0.19382000"],["78707.50000000","0.05000000"],["78626.36000000","0.00000000"],["70839.00000000","0.00416000"]],"a":[["78745.85000000","0.00000000"]]}}
{"rx_ns": 33056485800, "frame": {"e":"depthUpdate","E":1787603090514,"s":"BTCUSDT","U":99076635236,"u":99076635286,"b":[["78709.99000000","3.59310000"],["78709.98000000","0.00020000"],["78671.67000000","0.00400000"],["78671.25000000","0.00017000"],["78613.21000000","2.77206000"],["78610.60000000","0.00000000"],["78316.44000000","0.01010000"],["77924.85000000","0.01000000"],["77535.23000000","0.01000000"],["77147.55000000","0.01000000"],["76761.81000000","0.01000000"],["76378.01000000","0.01000000"],["75996.12000000","0.01000000"],["75616.13000000","0.01000000"],["75238.05000000","0.01000000"],["74861.86000000","0.01000000"],["74487.55000000","0.01000000"],["74115.12000000","0.01000000"],["73744.54000000","0.01000000"],["73375.82000000","0.01000000"],["73008.94000000","0.01000000"],["70839.00000000","0.00432000"],["70838.00000000","0.00018000"],["62968.00000000","0.00041000"]],"a":[["78710.00000000","0.50192000"],["78711.88000000","0.00007000"],["78714.48000000","0.00000000"],["78734.04000000","0.00400000"],["78756.30000000","0.00000000"],["79103.55000000","0.01000000"],["79499.07000000","0.01000000"],["79896.57000000","0.01027000"],["80296.05000000","0.01000000"],["80347.46000000","0.00000000"],["80697.53000000","0.01000000"],["81101.02000000","0.01000000"],["81506.52000000","0.01000000"],["81914.06000000","0.01000000"],["82323.63000000","0.01000000"],["82735.24000000","0.01000000"],["83148.92000000","0.01000000"],["83564.67000000","0.01000000"],["83982.49000000","0.01000000"],["84402.40000000","0.01000000"],["84824.41000000","0.01000000"],["86580.99000000","0.00000000"]]}}
{"rx_ns": 33153340900, "frame": {"e":"depthUpdate","E":1787603090614,"s":"BTCUSDT","U":99076635287,"u":99076635317,"b":[["78708.90000000","0.03224000"],["78707.50000000","0.00000000"],["78707.02000000","0.00400000"],["72420.55000000","0.00000000"],["70839.00000000","0.00400000"],["70838.00000000","0.00038000"],["62968.00000000","0.00010000"]],"a":[["78710.00000000","0.49935000"],["78710.01000000","0.00090000"],["78711.26000000","0.04070000"],["78711.87000000","0.00000000"],["78711.88000000","0.00000000"],["78713.77000000","0.00007000"],["78714.49000000","0.00323000"],["78717.17000000","0.02168000"],["78719.40000000","0.00069000"],["78721.20000000","0.00400000"],["80301.65000000","0.00000000"],["80307.93000000","0.00000000"]]}}
{"rx_ns": 33252761800, "frame": {"e":"depthUpdate","E":1787603090714,"s":"BTCUSDT","U":99076635318,"u":99076635330,"b":[["78709.99000000","3.59317000"],["78708.91000000","0.00007000"],["78707.53000000","0.19375000"],["78707.50000000","0.05000000"],["78707.45000000","0.05000000"],["70839.00000000","0.00416000"],["70838.00000000","0.00008000"]],"a":[["78750.63000000","0.00007000"]]}}
{"rx_ns": 33353193500, "frame": {"e":"depthUpdate","E":1787603090814,"s":"BTCUSDT","U":99076635331,"u":99076635338,"b":[["78708.90000000","0.03231000"],["78707.50000000","0.00000000"],["78707.45000000","0.00000000"],["78706.47000000","0.02000000"],["78528.58000000","0.00000000"],["70839.00000000","0.00416000"]],"a":[["80298.51000000","0.00000000"]]}}
{"rx_ns": 33455885100, "frame": {"e":"depthUpdate","E":1787603090914,"s":"BTCUSDT","U":99076635339,"u":99076635415,"b":[["78709.99000000","3.59427000"],["78707.03000000","0.00635000"],["78706.47000000","0.00000000"],["78705.03000000","0.00000000"],["78699.15000000","0.34311000"],["78689.85000000","0.63547000"],["78679.29000000","0.00000000"],["78402.43000000","0.00000000"],["70839.00000000","0.00416000"],["70838.98000000","0.00000000"],["62967.99000000","0.00020000"]],"a":[["78710.00000000","0.22021000"],["78712.01000000","0.00027000"],["78713.21000000","0.00000000"],["78714.49000000","0.00000000"],["78715.23000000","0.00000000"],["78716.80000000","0.00000000"],["78719.25000000","0.00000000"],["78720.47000000","0.00254000"],["78721.20000000","0.00000000"],["78722.54000000","0.00400000"],["78722.58000000","0.00000000"],["78722.71000000","0.00000000"],["78722.83000000","0.00000000"],["78725.28000000","0.00400000"],["78726.61000000","0.00400000"],["78727.40000000","0.00000000"],["78727.52000000","0.00000000"],["78727.88000000","0.00000000"],["78732.10000000","0.00000000"],["78732.11000000","0.00000000"],["78744.80000000","0.00000000"],["78745.97000000","0.02740000"],["78757.32000000","0.02516000"],["78767.97000000","0.01270000"],["78813.98000000","0.00000000"]]}}
{"rx_ns": 33562631800, "frame": {"e":"depthUpdate","E":1787603091014,"s":"BTCUSDT","U":99076635416,"u":99076636020,"b":[["78711.99000000","4.70085000"],["78711.98000000","0.00020000"],["78711.97000000","0.00013000"],["78711.92000000","0.00007000"],["78711.26000000","0.67892000"],["78711.25000000","2.63111000"],["78711.24000000","0.12108000"],["78711.23000000","0.00000000"],["78711.22000000","0.00000000"],["78710.02000000","0.00000000"],["78710.01000000","0.00014000"],["78710.00000000","0.08149000"],["78709.99000000","0.13531000"],["78709.98000000","0.00000000"],["78709.97000000","0.00000000"],["78709.70000000","0.00330000"],["78709.40000000","0.00008000"],["78708.91000000","0.00000000"],["78708.85000000","0.00000000"],["78708.80000000","0.00000000"],["78708.79000000","0.07280000"],["78708.21000000","0.00007000"],["78708.07000000","0.00000000"],["78708.00000000","0.00507000"],["78707.55000000","0.00000000"],["78707.54000000","0.00000000"],["78707.53000000","0.19375000"],["78707.22000000","0.00254000"],["78707.03000000","0.00000000"],["78706.28000000","0.30007000"],["78706.27000000","0.76812000"],["78706.26000000","0.30668000"],["78706.20000000","0.34014000"],["78706.06000000","0.00000000"],["78705.39000000","0.00000000"],["78704.80000000","0.00000000"],["78703.54000000","0.00254000"],["78703.04000000","0.00000000"],["78702.28000000","0.00000000"],["78701.52000000","0.10863000"],["78700.59000000","0.00000000"],["78697.84000000","0.34712000"],["78694.29000000","0.06526000"],["78692.33000000","0.07531000"],["78689.14000000","0.00000000"],["78687.17000000","0.00000000"],["78687.00000000","0.73231000"],["78684.17000000","0.13251000"],["78684.06000000","0.00000000"],["78650.01000000","0.00317000"],["78649.56000000","0.00007000"],["78648.01000000","0.00000000"],["78646.84000000","0.00000000"],["78628.01000000","0.00317000"],["78626.20000000","0.00000000"],["78613.21000000","0.00000000"],["78610.60000000","2.77206000"],["78494.76000000","0.00000000"],["78493.13000000","0.00007000"],["78489.20000000","0.00007000"],["78462.41000000","0.00250000"],["78317.01000000","0.00000000"],["78316.44000000","0.00010000"],["77924.85000000","0.00000000"],["77890.08000000","0.00065000"],["77535.23000000","0.00000000"],["77147.55000000","0.00000000"],["76761.81000000","0.00000000"],["76378.01000000","0.00000000"],["75996.12000000","0.00000000"],["75616.13000000","0.00000000"],["75238.05000000","0.00000000"],["74861.86000000","0.00000000"],["74487.55000000","0.00000000"],["74115.12000000","0.00000000"],["73744.54000000","0.00000000"],["73375.82000000","0.00000000"],["73008.94000000","0.00000000"],["70840.80000000","0.00016000"],["70839.00000000","0.00000000"],["62969.00000000","0.00031000"],["62967.99000000","0.00000000"]],"a":[["78710.00000000","0.00000000"],["78710.01000000","0.00000000"],["78710.02000000","0.00000000"],["78711.25000000","0.00000000"],["78711.26000000","0.00000000"],["78711.27000000","0.00000000"],["78711.93000000","0.00000000"],["78711.99000000","0.00000000"],["78712.00000000","0.02126000"],["78712.01000000","0.00083000"],["78712.29000000","0.00000000"],["78712.51000000","0.00000000"],["78712.52000000","0.00007000"],["78712.56000000","0.00000000"],["78712.57000000","0.00014000"],["78713.16000000","0.20799000"],["78713.58000000","0.00000000"],["78713.77000000","0.00000000"],["78713.78000000","0.00007000"],["78713.82000000","0.00014000"],["78713.83000000","0.00000000"],["78713.99000000","0.00014000"],["78714.34000000","0.00000000"],["78714.58000000","0.05409000"],["78715.00000000","0.00000000"],["78715.16000000","0.00007000"],["78715.99000000","0.00014000"],["78717.09000000","0.00000000"],["78717.17000000","0.00021000"],["78717.18000000","0.12724000"],["78717.99000000","0.00014000"],["78718.00000000","0.02407000"],["78718.78000000","0.00000000"],["78719.24000000","0.00000000"],["78719.40000000","0.00000000"],["78719.56000000","0.00000000"],["78719.82000000","0.02161000"],["78720.47000000","0.00000000"],["78720.77000000","0.00048000"],["78721.12000000","0.00000000"],["78721.17000000","0.00000000"],["78721.18000000","0.00000000"],["78721.24000000","0.00000000"],["78721.32000000","0.00007000"],["78721.63000000","0.00070000"],["78721.69000000","0.01270000"],["78721.73000000","0.06350000"],["78721.82000000","0.00508000"],["78722.17000000","0.00254000"],["78722.38000000","0.00000000"],["78722.39000000","0.00000000"],["78722.54000000","0.00000000"],["78722.58000000","0.00000000"],["78722.62000000","0.00000000"],["78722.63000000","0.00000000"],["78722.64000000","0.00000000"],["78722.74000000","0.00000000"],["78723.46000000","0.00000000"],["78723.47000000","0.00000000"],["78723.90000000","0.00000000"],["78723.93000000","0.00137000"],["78724.10000000","0.00000000"],["78724.27000000","0.00000000"],["78724.29000000","0.00000000"],["78724.30000000","0.00000000"],["78725.10000000","0.31765000"],["78725.28000000","0.00000000"],["78725.89000000","0.00000000"],["78726.61000000","0.00000000"],["78727.40000000","0.00635000"],["78727.53000000","0.00000000"],["78727.62000000","0.00400000"],["78727.82000000","0.00000000"],["78728.55000000","0.04857000"],["78728.99000000","0.00400000"],["78729.49000000","0.00000000"],["78732.11000000","0.00400000"],["78745.97000000","0.00000000"],["78746.15000000","0.00000000"],["78750.00000000","0.81931000"],["78750.63000000","0.00014000"],["78751.00000000","0.00000000"],["78752.00000000","0.03400000"],["78759.75000000","0.00000000"],["78760.56000000","0.00316000"],["78778.00000000","0.02407000"],["78780.66000000","0.00000000"],["78781.88000000","0.00000000"],["78783.99000000","0.00314000"],["78790.64000000","1.21952000"],["78797.82000000","1.90515000"],["78837.93000000","0.00000000"],["78839.99000000","0.00127000"],["78859.99000000","0.00000000"],["78861.99000000","0.00127000"],["79103.55000000","0.00000000"],["79273.61000000","0.00250000"],["79499.07000000","0.00000000"],["79896.57000000","0.00027000"],["80203.37000000","0.00000000"],["80209.47000000","0.00000000"],["80296.05000000","0.00000000"],["80697.53000000","0.00000000"],["81101.02000000","0.00000000"],["81506.52000000","0.00000000"],["81914.06000000","0.00000000"],["82323.63000000","0.00000000"],["82735.24000000","0.00000000"],["83148.92000000","0.00000000"],["83564.67000000","0.00000000"],["83982.49000000","0.00000000"],["84402.40000000","0.00000000"],["84824.41000000","0.00000000"]]}}
{"rx_ns": 33655433200, "kind": "control", "ctl": {"op": "ping", "recv_ns": 33613626000, "pong_ns": 33613736500, "payload_len": 13, "payload_b64": "MTc4NzYwMzA5MTA3NA=="}, "frame": null}
{"rx_ns": 33655433200, "frame": {"e":"depthUpdate","E":1787603091114,"s":"BTCUSDT","U":99076636021,"u":99076636151,"b":[["78711.99000000","4.92304000"],["78711.27000000","0.00014000"],["78711.26000000","0.07521000"],["78711.25000000","2.62708000"],["78711.24000000","0.12094000"],["78710.74000000","0.00331000"],["78710.01000000","0.00007000"],["78709.99000000","0.12322000"],["78709.70000000","0.00000000"],["78709.17000000","0.00323000"],["78708.78000000","1.58176000"],["78708.33000000","0.01419000"],["78707.22000000","0.00000000"],["78707.08000000","0.02365000"],["78706.71000000","0.00254000"],["78705.82000000","0.02838000"],["78704.56000000","0.02838000"],["78702.17000000","0.00007000"],["78701.70000000","0.00408000"],["78688.03000000","0.13644000"],["78673.98000000","0.00400000"],["78673.23000000","0.00014000"],["78671.67000000","0.00000000"],["78671.00000000","0.01000000"],["78670.00000000","0.11212000"],["78669.62000000","0.00000000"],["78532.88000000","4.51219000"],["78489.20000000","0.00000000"],["78001.60000000","0.00000000"],["70840.80000000","0.00032000"]],"a":[["78712.00000000","0.05197000"],["78712.01000000","0.00083000"],["78712.52000000","0.00000000"],["78712.57000000","0.00000000"],["78713.15000000","0.00014000"],["78713.16000000","0.20813000"],["78713.25000000","0.00014000"],["78713.26000000","0.03987000"],["78713.78000000","0.00000000"],["78713.82000000","0.00000000"],["78714.00000000","0.02407000"],["78714.51000000","0.00014000"],["78714.52000000","0.04784000"],["78714.57000000","0.00014000"],["78714.58000000","0.05416000"],["78715.78000000","0.04784000"],["78715.99000000","0.00000000"],["78716.00000000","0.02407000"],["78717.17000000","0.00000000"],["78717.99000000","0.00007000"],["78718.00000000","0.02407000"],["78719.68000000","0.00322000"],["78719.82000000","0.02168000"],["78719.83000000","0.03007000"],["78720.77000000","0.00000000"],["78721.24000000","0.00325000"],["78727.88000000","1.21952000"],["78732.10000000","1.90515000"],["78790.64000000","0.00000000"],["78797.82000000","0.00000000"],["78807.59000000","0.00000000"],["78809.59000000","0.00025000"],["79211.62000000","0.01514000"],["79282.41000000","0.00000000"],["80187.08000000","0.00000000"]]}}
{"rx_ns": 33755325600, "frame": {"e":"depthUpdate","E":1787603091214,"s":"BTCUSDT","U":99076636152,"u":99076636201,"b":[["78711.25000000","2.02348000"],["78706.71000000","0.00000000"],["78688.33000000","0.00007000"],["78686.33000000","0.00000000"],["78684.17000000","0.00000000"],["78672.00000000","0.03400000"],["78671.00000000","0.00000000"],["78493.13000000","0.00000000"],["70840.80000000","0.00064000"],["62969.00000000","0.00000000"]],"a":[["78712.00000000","0.05232000"],["78712.01000000","0.00104000"],["78713.16000000","0.20813000"],["78713.26000000","0.03994000"],["78714.00000000","0.02407000"],["78714.52000000","0.04791000"],["78714.58000000","0.05416000"],["78715.78000000","0.04791000"],["78718.00000000","0.02400000"],["78719.22000000","0.00318000"],["78719.82000000","0.02161000"],["78719.83000000","0.03000000"],["78722.17000000","0.00000000"],["78733.57000000","0.00000000"],["78735.57000000","0.00007000"],["78760.56000000","0.00000000"],["78761.83000000","0.00315000"],["78805.19000000","0.00000000"],["78807.74000000","0.00529000"],["80059.54000000","0.00000000"],["80147.63000000","0.00000000"]]}}
{"rx_ns": 33852614300, "frame": {"e":"depthUpdate","E":1787603091314,"s":"BTCUSDT","U":99076636202,"u":99076636225,"b":[["78711.99000000","4.91669000"],["78710.75000000","0.00635000"],["78710.00000000","0.07514000"],["78708.91000000","0.00635000"],["78705.17000000","0.00000000"],["78626.36000000","0.02116000"],["78529.42000000","0.00778000"],["78520.83000000","0.00000000"],["62968.00000000","0.00010000"]],"a":[["78712.00000000","0.73361000"],["78720.90000000","0.00000000"],["78721.63000000","0.00000000"],["78737.74000000","0.00000000"],["78739.38000000","0.00406000"],["78777.11000000","0.00000000"],["78778.75000000","0.00406000"],["78808.61000000","0.00000000"],["78810.25000000","0.00406000"],["78855.85000000","0.00000000"],["78857.49000000","0.00406000"],["80049.37000000","0.00000000"]]}}
{"rx_ns": 33953060900, "frame": {"e":"depthUpdate","E":1787603091414,"s":"BTCUSDT","U":99076636226,"u":99076636250,"b":[["78711.24000000","0.12101000"],["78710.75000000","0.00642000"],["78709.99000000","0.12315000"],["78708.79000000","0.07273000"],["78706.00000000","0.02654000"],["78626.36000000","0.00000000"],["70840.80000000","0.00096000"]],"a":[["78712.00000000","0.33674000"],["78712.01000000","0.00097000"],["78713.58000000","0.00007000"],["78721.73000000","0.06604000"],["78746.25000000","0.02804000"],["78810.25000000","0.00000000"],["78810.47000000","0.00406000"],["78927.00000000","0.00000000"],["78928.58000000","0.00406000"],["79987.65000000","0.00000000"]]}}
{"rx_ns": 34052979500, "frame": {"e":"depthUpdate","E":1787603091514,"s":"BTCUSDT","U":99076636251,"u":99076636297,"b":[["78711.99000000","4.92304000"],["78711.51000000","0.00321000"],["78711.25000000","2.34099000"],["78710.75000000","0.00007000"],["78697.43000000","0.00000000"],["78318.43000000","0.01000000"],["77926.83000000","0.01000000"],["77537.20000000","0.01000000"],["77149.51000000","0.01000000"],["76763.77000000","0.01000000"],["76379.95000000","0.01029000"],["75998.05000000","0.01000000"],["75618.06000000","0.01000000"],["75239.97000000","0.01093000"],["74863.77000000","0.01000000"],["74489.45000000","0.01000000"],["74117.00000000","0.01000000"],["73746.41000000","0.01000000"],["73377.68000000","0.01000000"],["73010.79000000","0.01000000"],["70840.80000000","0.00112000"],["62969.60000000","0.00046000"]],"a":[["78712.00000000","0.33681000"],["78717.18000000","0.12731000"],["78717.23000000","0.23039000"],["78810.47000000","0.00406000"],["78928.58000000","0.00406000"],["79105.56000000","0.01000000"],["79501.09000000","0.01000000"],["79898.60000000","0.01014000"],["80298.09000000","0.01000000"],["80699.58000000","0.01000000"],["81103.08000000","0.01000000"],["81508.59000000","0.01000000"],["81916.14000000","0.01000000"],["82325.72000000","0.01000000"],["82737.35000000","0.01000000"],["83151.03000000","0.01000000"],["83566.79000000","0.01000000"],["83984.62000000","0.01000000"],["84404.55000000","0.01000000"],["84826.57000000","0.01000000"]]}}
{"rx_ns": 34155003200, "frame": {"e":"depthUpdate","E":1787603091614,"s":"BTCUSDT","U":99076636298,"u":99076636310,"b":[["78711.99000000","4.92314000"],["78711.24000000","0.12101000"],["78710.75000000","0.00000000"],["78709.99000000","0.12322000"],["70840.80000000","0.00128000"],["62969.60000000","0.00015000"]],"a":[["78717.18000000","0.12731000"],["78810.47000000","0.00000000"],["78810.48000000","0.00406000"],["78928.58000000","0.00000000"],["78928.59000000","0.00406000"]]}}
{"rx_ns": 34257397500, "frame": {"e":"depthUpdate","E":1787603091714,"s":"BTCUSDT","U":99076636311,"u":99076636349,"b":[["78711.99000000","4.72359000"],["78711.98000000","0.00041000"],["78711.51000000","0.00000000"],["78710.02000000","0.00635000"],["78708.91000000","0.00642000"],["78706.28000000","0.30021000"],["78706.00000000","0.02400000"],["78705.19000000","0.00254000"],["78626.36000000","0.02116000"],["70840.80000000","0.00144000"],["70840.00000000","0.14260000"]],"a":[["78712.00000000","0.76002000"],["78712.01000000","0.00104000"],["78714.58000000","0.05423000"],["78715.45000000","0.22289000"],["78717.18000000","0.12724000"],["78717.23000000","0.00000000"],["78720.92000000","0.00254000"],["78721.73000000","0.06350000"],["78723.49000000","0.31764000"],["78725.10000000","0.00000000"],["78928.59000000","0.00406000"]]}}
{"rx_ns": 34352636800, "frame": {"e":"depthUpdate","E":1787603091814,"s":"BTCUSDT","U":99076636350,"u":99076636372,"b":[["78711.24000000","0.12101000"],["78626.36000000","0.00000000"],["70840.80000000","0.00160000"],["70840.00000000","0.14240000"]],"a":[["78712.00000000","0.76017000"],["78713.16000000","0.20820000"],["78713.26000000","0.04008000"],["78713.27000000","0.18261000"],["78714.57000000","0.00000000"],["78714.58000000","0.05423000"],["78715.45000000","0.00007000"],["78717.18000000","0.12717000"],["78744.43000000","0.02516000"],["78757.32000000","0.00000000"],["78757.52000000","0.00663000"],["78761.84000000","0.00000000"]]}}
{"rx_ns": 34452588100, "frame": {"e":"depthUpdate","E":1787603091914,"s":"BTCUSDT","U":99076636373,"u":99076636404,"b":[["78711.99000000","4.70359000"],["78711.24000000","0.09101000"],["78708.91000000","0.00007000"],["78708.17000000","0.02000000"],["78707.54000000","0.00635000"],["78626.36000000","0.02116000"],["70840.80000000","0.00144000"]],"a":[["78712.00000000","0.76061000"],["78712.01000000","0.00104000"],["78712.36000000","0.00014000"],["78712.37000000","0.17803000"],["78713.26000000","0.03994000"],["78713.27000000","0.00007000"],["78714.58000000","0.05416000"],["78715.45000000","0.00000000"],["78716.66000000","0.04000000"]]}}
{"rx_ns": 34553330300, "frame": {"e":"depthUpdate","E":1787603092014,"s":"BTCUSDT","U":99076636405,"u":99076636457,"b":[["78710.02000000","0.00642000"],["78709.99000000","0.12322000"],["78708.91000000","0.00000000"],["78626.36000000","0.00000000"],["78318.43000000","0.00000000"],["77926.83000000","0.00000000"],["77537.20000000","0.00000000"],["77149.51000000","0.00000000"],["76763.77000000","0.00000000"],["76379.95000000","0.00029000"],["75998.05000000","0.00000000"],["75618.06000000","0.00000000"],["75239.97000000","0.00093000"],["74863.77000000","0.00000000"],["74489.45000000","0.00000000"],["74117.00000000","0.00000000"],["73746.41000000","0.00000000"],["73377.68000000","0.00000000"],["73010.79000000","0.00000000"],["70840.80000000","0.00176000"],["62969.60000000","0.00046000"],["62969.59000000","0.00000000"]],"a":[["78712.00000000","0.76061000"],["78712.37000000","0.17810000"],["78713.16000000","0.20813000"],["78713.26000000","0.03994000"],["78713.27000000","0.00000000"],["78716.00000000","0.02407000"],["79105.56000000","0.00000000"],["79501.09000000","0.00000000"],["79898.60000000","0.00014000"],["80298.09000000","0.00000000"],["80699.58000000","0.00000000"],["81103.08000000","0.00000000"],["81508.59000000","0.00000000"],["81916.14000000","0.00000000"],["82325.72000000","0.00000000"],["82737.35000000","0.00000000"],["83151.03000000","0.00000000"],["83566.79000000","0.00000000"],["83984.62000000","0.00000000"],["84404.55000000","0.00000000"],["84826.57000000","0.00000000"]]}}
{"rx_ns": 34653117500, "frame": {"e":"depthUpdate","E":1787603092114,"s":"BTCUSDT","U":99076636458,"u":99076636466,"b":[["78703.18000000","0.02287000"],["78701.52000000","0.08576000"],["78003.58000000","0.00010000"],["70840.80000000","0.00176000"]],"a":[["78712.00000000","0.76071000"],["78721.69000000","0.00000000"],["78721.73000000","0.00000000"],["78773.71000000","0.00007000"]]}}
{"rx_ns": 34753065200, "frame": {"e":"depthUpdate","E":1787603092214,"s":"BTCUSDT","U":99076636467,"u":99076636484,"b":[["78711.99000000","4.70387000"],["78711.98000000","0.00062000"],["78705.19000000","0.00000000"],["78688.33000000","0.00007000"],["70840.80000000","0.00176000"],["62969.60000000","0.00015000"]],"a":[["78712.00000000","0.76086000"],["78720.92000000","0.00000000"],["78735.57000000","0.00007000"]]}}
{"rx_ns": 34852978900, "frame": {"e":"depthUpdate","E":1787603092314,"s":"BTCUSDT","U":99076636485,"u":99076636497,"b":[["78703.44000000","0.00254000"],["78691.01000000","0.00000000"],["78690.49000000","0.04450000"],["70840.80000000","0.00192000"],["62968.00000000","0.00010000"]],"a":[["78712.00000000","0.97898000"],["78719.17000000","0.00254000"],["78737.93000000","0.00000000"],["78740.05000000","0.04597000"]]}}
{"rx_ns": 34955355600, "frame": {"e":"depthUpdate","E":1787603092414,"s":"BTCUSDT","U":99076636498,"u":99076636515,"b":[["78711.99000000","2.35982000"],["78711.27000000","0.00000000"],["78711.26000000","0.00021000"],["78711.25000000","2.26599000"],["78710.02000000","0.00007000"],["78708.34000000","0.00635000"],["78707.54000000","0.00000000"],["78706.29000000","0.00635000"],["70840.80000000","0.00208000"]],"a":[["78712.00000000","0.76293000"],["78720.75000000","0.00137000"],["78721.81000000","0.31764000"],["78722.93000000","0.00635000"],["78723.49000000","0.00000000"],["78723.93000000","0.00000000"],["78727.40000000","0.00000000"],["78732.09000000","0.36224000"]]}}
{"rx_ns": 35054964500, "frame": {"e":"depthUpdate","E":1787603092514,"s":"BTCUSDT","U":99076636516,"u":99076636584,"b":[["78711.99000000","4.26513000"],["78711.98000000","0.00048000"],["78711.33000000","0.00327000"],["78711.26000000","0.00014000"],["78711.24000000","0.09101000"],["78710.74000000","0.00000000"],["78710.66000000","0.00329000"],["78710.02000000","0.00000000"],["78710.00000000","0.00014000"],["78709.17000000","0.00000000"],["78709.09000000","0.00319000"],["78708.90000000","0.00007000"],["78708.79000000","0.07280000"],["78708.03000000","0.00000000"],["78707.44000000","0.00400000"],["78707.02000000","0.00000000"],["78706.29000000","0.00000000"],["78705.87000000","0.00000000"],["78705.03000000","0.00635000"],["78703.44000000","0.00000000"],["78702.51000000","0.00254000"],["78701.80000000","0.00000000"],["78701.71000000","0.00000000"],["78701.39000000","0.00400000"],["78701.01000000","0.00400000"],["78700.01000000","0.00000000"],["78317.01000000","0.00007000"],["70840.80000000","0.00208000"],["62969.60000000","0.00046000"]],"a":[["78712.00000000","1.21005000"],["78715.37000000","0.00329000"],["78716.94000000","0.00331000"],["78718.24000000","0.00254000"],["78718.76000000","0.00508000"],["78719.17000000","0.00000000"],["78721.82000000","0.00000000"],["78750.61000000","0.02463000"]]}}
{"rx_ns": 35156712400, "frame": {"e":"depthUpdate","E":1787603092615,"s":"BTCUSDT","U":99076636585,"u":99076636629,"b":[["78711.33000000","0.00000000"],["78711.24000000","0.09101000"],["78710.00000000","0.00007000"],["78709.99000000","0.12322000"],["78708.90000000","0.00000000"],["78708.78000000","1.58183000"],["78708.34000000","0.00642000"],["78318.43000000","0.01000000"],["77926.83000000","0.01000000"],["77537.20000000","0.01000000"],["77310.33000000","0.00000000"],["77228.25000000","0.00130000"],["77149.51000000","0.01000000"],["76763.77000000","0.01000000"],["76379.95000000","0.01029000"],["75998.05000000","0.01000000"],["75618.06000000","0.01000000"],["75239.97000000","0.01093000"],["74863.77000000","0.01000000"],["74489.45000000","0.01000000"],["74117.00000000","0.01000000"],["73746.41000000","0.01000000"],["73377.68000000","0.01000000"],["73010.79000000","0.01000000"],["62969.60000000","0.00015000"]],"a":[["78712.00000000","1.21018000"],["78712.01000000","0.00117000"],["78712.02000000","0.00013000"],["79105.56000000","0.01000000"],["79501.09000000","0.01000000"],["79898.60000000","0.01014000"],["80298.09000000","0.01000000"],["80699.58000000","0.01000000"],["81103.08000000","0.01000000"],["81508.59000000","0.01000000"],["81916.14000000","0.01000000"],["82325.72000000","0.01000000"],["82737.35000000","0.01000000"],["83151.03000000","0.01000000"],["83566.79000000","0.01000000"],["83984.62000000","0.01000000"],["84404.55000000","0.01000000"],["84826.57000000","0.01000000"]]}}
{"rx_ns": 35252618100, "frame": {"e":"depthUpdate","E":1787603092714,"s":"BTCUSDT","U":99076636630,"u":99076636653,"b":[["78711.99000000","4.26513000"],["78711.98000000","0.00048000"],["78710.66000000","0.00000000"],["78710.58000000","0.00320000"],["78709.09000000","0.00000000"],["78709.01000000","0.00321000"],["78676.80000000","0.02800000"],["78673.98000000","0.00000000"],["70840.80000000","0.00224000"]],"a":[["78712.00000000","0.98302000"],["78712.01000000","0.00124000"],["78718.76000000","0.00000000"],["78719.81000000","0.00508000"],["78721.81000000","0.00000000"],["78722.92000000","0.31765000"],["78724.24000000","0.02286000"],["78724.45000000","0.00254000"],["78726.15000000","0.00000000"],["78726.33000000","0.00000000"]]}}
{"rx_ns": 35353583400, "frame": {"e":"depthUpdate","E":1787603092815,"s":"BTCUSDT","U":99076636654,"u":99076636677,"b":[["78711.99000000","4.26513000"],["78711.98000000","0.00055000"],["78711.43000000","0.00000000"],["78708.33000000","0.01426000"],["78626.36000000","0.02116000"],["78529.42000000","0.00000000"],["78520.83000000","0.00778000"],["70840.80000000","0.00224000"]],"a":[["78712.00000000","1.20695000"],["78714.21000000","0.00000000"],["78714.42000000","0.00332000"],["78731.38000000","0.00000000"],["78803.72000000","0.93647000"],["78806.33000000","0.00000000"]]}}
{"rx_ns": 35452870400, "frame": {"e":"depthUpdate","E":1787603092914,"s":"BTCUSDT","U":99076636678,"u":99076636690,"b":[["78711.99000000","4.27045000"],["78711.86000000","0.00000000"],["78711.29000000","0.00320000"],["78708.00000000","0.01200000"],["70840.80000000","0.00240000"]],"a":[["78712.00000000","0.98110000"],["78714.42000000","0.00000000"]]}}
{"rx_ns": 35555059600, "frame": {"e":"depthUpdate","E":1787603093014,"s":"BTCUSDT","U":99076636691,"u":99076636709,"b":[["78711.99000000","4.27052000"],["78711.98000000","0.00062000"],["78626.36000000","0.00000000"],["70840.80000000","0.00240000"],["62969.60000000","0.00046000"],["62969.59000000","0.00000000"]],"a":[["78712.00000000","0.96439000"],["78721.17000000","0.01270000"],["78721.21000000","0.06350000"]]}}
{"rx_ns": 35653298700, "frame": {"e":"depthUpdate","E":1787603093114,"s":"BTCUSDT","U":99076636710,"u":99076636753,"b":[["78711.99000000","4.27045000"],["78711.98000000","0.00055000"],["78711.29000000","0.00000000"],["78318.43000000","0.00000000"],["77926.83000000","0.00000000"],["77537.20000000","0.00000000"],["77149.51000000","0.00000000"],["76763.77000000","0.00000000"],["76379.95000000","0.00029000"],["75998.05000000","0.00000000"],["75618.06000000","0.00000000"],["75239.97000000","0.00093000"],["74863.77000000","0.00000000"],["74489.45000000","0.00000000"],["74117.00000000","0.00000000"],["73746.41000000","0.00000000"],["73377.68000000","0.00000000"],["73010.79000000","0.00000000"],["70840.80000000","0.00256000"],["70840.00000000","0.14260000"]],"a":[["78712.00000000","0.76380000"],["79105.56000000","0.00000000"],["79501.09000000","0.00000000"],["79898.60000000","0.00014000"],["80298.09000000","0.00000000"],["80699.58000000","0.00000000"],["81103.08000000","0.00000000"],["81508.59000000","0.00000000"],["81916.14000000","0.00000000"],["82325.72000000","0.00000000"],["82737.35000000","0.00000000"],["83151.03000000","0.00000000"],["83566.79000000","0.00000000"],["83984.62000000","0.00000000"],["84404.55000000","0.00000000"],["84826.57000000","0.00000000"]]}}
{"rx_ns": 35752790900, "frame": {"e":"depthUpdate","E":1787603093214,"s":"BTCUSDT","U":99076636754,"u":99076636759,"b":[["78711.99000000","4.27957000"],["78705.01000000","0.21654000"],["78626.36000000","0.02116000"],["70840.00000000","0.14240000"],["62969.60000000","0.00015000"]],"a":[["79095.21000000","0.00000000"]]}}
{"rx_ns": 35866100700, "frame": {"e":"depthUpdate","E":1787603093314,"s":"BTCUSDT","U":99076636760,"u":99076636776,"b":[["78709.05000000","0.00000000"],["78709.00000000","0.00000000"],["78688.33000000","0.00007000"],["78626.36000000","0.00000000"],["77144.95000000","0.00091000"],["70840.80000000","0.00272000"],["62970.00000000","0.00000000"]],"a":[["78712.00000000","0.76380000"],["78720.75000000","0.00000000"],["78721.99000000","0.00137000"],["78735.57000000","0.00007000"]]}}
{"rx_ns": 35952729200, "frame": {"e":"depthUpdate","E":1787603093414,"s":"BTCUSDT","U":99076636777,"u":99076636788,"b":[["78711.06000000","0.00316000"],["78626.36000000","0.02116000"],["76990.66000000","0.00171000"],["70840.80000000","0.00272000"]],"a":[["78712.00000000","0.76180000"],["78749.00000000","0.70000000"],["78750.00000000","0.11931000"]]}}
{"rx_ns": 36058539900, "frame": {"e":"depthUpdate","E":1787603093514,"s":"BTCUSDT","U":99076636789,"u":99076636840,"b":[["78711.99000000","4.28550000"],["78711.98000000","0.00020000"],["78709.41000000","0.00635000"],["78709.36000000","0.00027000"],["78708.34000000","0.00007000"],["78706.28000000","0.30007000"],["78705.03000000","0.00000000"],["78702.51000000","0.00000000"],["78626.36000000","0.00000000"],["78317.01000000","0.00000000"],["70840.80000000","0.00288000"],["62969.60000000","0.00046000"]],"a":[["78712.00000000","0.47571000"],["78712.36000000","0.00000000"],["78712.37000000","0.00007000"],["78714.57000000","0.00007000"],["78715.37000000","0.00000000"],["78716.94000000","0.00000000"],["78718.24000000","0.00000000"],["78719.81000000","0.00000000"],["78721.16000000","0.00000000"],["78721.82000000","0.00254000"],["78721.99000000","0.00000000"],["78722.51000000","0.00254000"],["78722.92000000","0.00000000"],["78722.93000000","0.00000000"],["78723.93000000","0.00137000"],["78723.99000000","0.00000000"],["78725.10000000","0.31765000"],["78725.49000000","0.00000000"],["78727.40000000","0.00635000"],["78730.87000000","0.00000000"],["78732.61000000","0.02000000"]]}}
{"rx_ns": 36152819200, "frame": {"e":"depthUpdate","E":1787603093614,"s":"BTCUSDT","U":99076636841,"u":99076636974,"b":[["78711.99000000","4.30865000"],["78711.25000000","0.36084000"],["78711.12000000","0.03224000"],["78711.06000000","0.00000000"],["78709.99000000","0.12322000"],["78709.41000000","0.00642000"],["78708.78000000","1.58176000"],["78708.34000000","0.00000000"],["78708.17000000","0.00000000"],["78706.29000000","1.90515000"],["78705.88000000","0.00000000"],["78704.21000000","0.00254000"],["78704.13000000","0.00000000"],["78703.54000000","0.00000000"],["78318.43000000","0.01000000"],["77926.83000000","0.01000000"],["77537.20000000","0.01000000"],["77149.51000000","0.01000000"],["76836.67000000","0.00195000"],["76763.77000000","0.01000000"],["76682.99000000","0.00223000"],["76379.95000000","0.01029000"],["75998.05000000","0.01000000"],["75618.06000000","0.01000000"],["75239.97000000","0.01093000"],["74863.77000000","0.01000000"],["74489.45000000","0.01000000"],["74117.00000000","0.01000000"],["73746.41000000","0.01000000"],["73377.68000000","0.01000000"],["73010.79000000","0.01000000"],["70840.80000000","0.00297000"],["62969.60000000","0.00015000"]],"a":[["78712.00000000","0.01050000"],["78712.01000000","0.00110000"],["78712.37000000","0.00000000"],["78716.66000000","0.04007000"],["78719.22000000","0.00000000"],["78719.68000000","0.00000000"],["78719.82000000","0.00000000"],["78719.86000000","0.00000000"],["78720.89000000","0.00323000"],["78721.17000000","0.00000000"],["78721.21000000","0.00000000"],["78721.24000000","0.00000000"],["78721.52000000","0.00048000"],["78721.82000000","0.00000000"],["78722.84000000","0.00254000"],["78722.93000000","0.00254000"],["78724.11000000","0.00000000"],["78727.88000000","0.00000000"],["78728.44000000","0.38115000"],["78728.99000000","0.00000000"],["78732.09000000","0.00000000"],["78732.10000000","0.00000000"],["78732.12000000","0.00000000"],["78733.75000000","1.21952000"],["78737.50000000","1.90515000"],["78737.51000000","0.00000000"],["78744.43000000","0.00000000"],["78756.55000000","0.02516000"],["78790.00000000","0.02444000"],["78790.64000000","1.21952000"],["78797.82000000","1.90515000"],["78803.72000000","0.00000000"],["78807.75000000","0.00000000"],["79105.56000000","0.01000000"],["79501.09000000","0.01000000"],["79898.60000000","0.01014000"],["80298.09000000","0.01000000"],["80699.58000000","0.01000000"],["81103.08000000","0.01000000"],["81508.59000000","0.01000000"],["81916.14000000","0.01000000"],["82325.72000000","0.01000000"],["82737.35000000","0.01000000"],["83151.03000000","0.01000000"],["83566.79000000","0.01000000"],["83984.62000000","0.01000000"],["84404.55000000","0.01000000"],["84826.57000000","0.01000000"]]}}
{"rx_ns": 36253302600, "frame": {"e":"depthUpdate","E":1787603093714,"s":"BTCUSDT","U":99076636975,"u":99076637371,"b":[["78713.15000000","5.74630000"],["78713.14000000","0.00041000"],["78713.13000000","0.00013000"],["78712.32000000","0.00400000"],["78712.01000000","0.00014000"],["78712.00000000","0.07514000"],["78711.99000000","2.19733000"],["78711.98000000","0.00000000"],["78711.97000000","0.00000000"],["78711.93000000","0.00014000"],["78711.26000000","0.00000000"],["78711.25000000","0.04319000"],["78711.24000000","0.09101000"],["78711.13000000","0.00000000"],["78711.12000000","0.03231000"],["78710.00000000","0.00007000"],["78709.41000000","0.00007000"],["78708.79000000","0.07112000"],["78708.78000000","1.58183000"],["78708.33000000","0.00000000"],["78707.90000000","0.00000000"],["78707.54000000","0.00635000"],["78707.08000000","0.00000000"],["78706.20000000","0.34021000"],["78705.82000000","0.00000000"],["78705.66000000","0.12705000"],["78705.01000000","0.00127000"],["78704.56000000","0.00007000"],["78702.90000000","0.08576000"],["78701.52000000","0.00000000"],["78701.38000000","0.00000000"],["78699.00000000","0.00400000"],["78695.11000000","0.00000000"],["78689.91000000","0.12708000"],["78685.64000000","0.00000000"],["78679.02000000","0.00400000"],["78678.18000000","0.00000000"],["78676.80000000","0.02400000"],["78675.21000000","0.00000000"],["78673.23000000","0.00000000"],["78673.00000000","0.01000000"],["78672.00000000","0.02400000"],["78585.72000000","0.00000000"],["77500.00000000","13.70903000"],["76529.62000000","0.01635000"],["70841.84000000","0.00016000"],["70840.80000000","0.00009000"]],"a":[["78712.00000000","0.00000000"],["78712.01000000","0.00000000"],["78712.02000000","0.00000000"],["78713.15000000","0.00000000"],["78713.16000000","0.00233000"],["78713.17000000","0.00056000"],["78713.25000000","0.00000000"],["78713.26000000","0.00007000"],["78714.51000000","0.00000000"],["78714.52000000","0.00007000"],["78714.57000000","0.00000000"],["78714.58000000","0.00007000"],["78715.16000000","0.00000000"],["78715.73000000","0.00014000"],["78715.74000000","0.05397000"],["78715.77000000","0.00000000"],["78715.78000000","0.00007000"],["78715.80000000","0.00007000"],["78715.99000000","0.00014000"],["78716.52000000","0.00000000"],["78716.65000000","0.00014000"],["78716.73000000","0.00007000"],["78716.92000000","0.00000000"],["78717.18000000","0.00014000"],["78717.99000000","0.00014000"],["78719.61000000","0.00000000"],["78721.40000000","0.12703000"],["78721.52000000","0.00000000"],["78721.53000000","0.00000000"],["78722.51000000","0.00000000"],["78722.54000000","0.00047000"],["78722.84000000","0.00000000"],["78722.93000000","0.00000000"],["78723.93000000","0.00000000"],["78724.59000000","0.02161000"],["78724.60000000","0.00000000"],["78724.79000000","0.00254000"],["78725.09000000","0.00254000"],["78725.10000000","0.00000000"],["78725.89000000","0.00137000"],["78726.63000000","0.00007000"],["78727.39000000","0.31764000"],["78728.55000000","0.00000000"],["78729.67000000","0.00000000"],["78729.93000000","0.04857000"],["78733.74000000","1.21952000"],["78733.75000000","0.00000000"],["78736.29000000","0.00000000"],["78736.37000000","0.00000000"],["78736.87000000","0.09729000"],["78740.05000000","0.00000000"],["78746.25000000","0.00000000"],["78746.37000000","0.00000000"],["78746.80000000","0.02788000"],["78748.63000000","0.04455000"],["78752.00000000","0.02400000"],["78753.00000000","0.01000000"],["78754.50000000","0.00007000"],["78761.16000000","0.00400000"],["78761.83000000","0.00000000"],["78763.99000000","0.00313000"],["78790.63000000","1.21952000"],["78790.64000000","0.00000000"],["78821.84000000","0.00000000"],["79105.56000000","0.00000000"],["79501.09000000","0.00000000"],["79898.60000000","0.00014000"],["80298.09000000","0.00000000"],["80699.58000000","0.00000000"],["81103.08000000","0.00000000"],["81508.59000000","0.00000000"],["81916.14000000","0.00000000"],["82325.72000000","0.00000000"],["82737.35000000","0.00000000"],["83151.03000000","0.00000000"],["83566.79000000","0.00000000"],["83984.62000000","0.00000000"],["84404.55000000","0.00000000"],["84826.57000000","0.00000000"]]}}
{"rx_ns": 36353032900, "frame": {"e":"depthUpdate","E":1787603093814,"s":"BTCUSDT","U":99076637372,"u":99076637646,"b":[["78713.99000000","3.93683000"],["78713.98000000","0.00034000"],["78713.97000000","0.00013000"],["78713.57000000","0.00000000"],["78713.55000000","0.00000000"],["78713.25000000","0.00000000"],["78713.17000000","0.00014000"],["78713.16000000","0.07514000"],["78713.15000000","3.56420000"],["78713.14000000","0.00007000"],["78713.13000000","0.00000000"],["78712.01000000","0.00000000"],["78712.00000000","0.07507000"],["78711.99000000","0.07827000"],["78710.61000000","0.01463000"],["78710.25000000","0.00007000"],["78709.99000000","0.12322000"],["78709.41000000","0.00000000"],["78709.36000000","0.02466000"],["78708.78000000","1.58176000"],["78708.74000000","0.00254000"],["78708.10000000","0.02927000"],["78706.84000000","0.02927000"],["78706.27000000","0.52864000"],["78705.80000000","0.00007000"],["78705.02000000","0.00000000"],["78705.01000000","0.00113000"],["78704.17000000","0.00007000"],["78703.81000000","0.08576000"],["78702.90000000","0.00000000"],["78674.00000000","0.03400000"],["78673.00000000","0.00000000"],["78672.73000000","0.02460000"],["78668.61000000","0.00000000"],["78664.03000000","0.00633000"],["78663.65000000","0.00433000"],["78652.09000000","0.00317000"],["78652.08000000","0.00000000"],["78651.44000000","0.00000000"],["78650.01000000","0.00000000"],["78649.56000000","0.00000000"],["70841.84000000","0.00000000"]],"a":[["78713.16000000","0.00000000"],["78713.17000000","0.00000000"],["78713.26000000","0.00000000"],["78713.56000000","0.00000000"],["78713.58000000","0.00000000"],["78713.99000000","0.00000000"],["78714.00000000","0.05733000"],["78714.01000000","0.00056000"],["78714.52000000","0.00000000"],["78714.58000000","0.00000000"],["78714.97000000","0.00014000"],["78714.98000000","0.20806000"],["78715.25000000","0.00014000"],["78715.26000000","0.03912000"],["78715.73000000","0.00000000"],["78715.74000000","0.00007000"],["78715.78000000","0.00000000"],["78716.51000000","0.00014000"],["78716.52000000","0.04694000"],["78716.57000000","0.00014000"],["78716.58000000","0.05397000"],["78716.65000000","0.00000000"],["78716.66000000","0.04007000"],["78717.18000000","0.00007000"],["78717.78000000","0.04694000"],["78717.99000000","0.00007000"],["78718.00000000","0.02407000"],["78718.77000000","0.00000000"],["78719.82000000","0.00000000"],["78719.83000000","0.03007000"],["78719.89000000","0.21944000"],["78720.00000000","0.02407000"],["78720.13000000","0.04007000"],["78720.63000000","0.00000000"],["78721.39000000","0.02161000"],["78721.40000000","0.12710000"],["78724.47000000","0.00254000"],["78724.75000000","0.00069000"],["78727.40000000","0.00000000"],["78729.37000000","0.00635000"],["78729.67000000","1.21952000"],["78729.93000000","0.00000000"],["78730.84000000","0.04857000"],["78736.87000000","0.00000000"],["78737.62000000","0.00192000"],["78746.80000000","0.00000000"],["78752.49000000","0.00000000"],["78753.00000000","0.00000000"],["78754.00000000","0.03400000"],["78762.30000000","0.00433000"],["78775.76000000","0.00000000"],["78779.43000000","0.00007000"],["78783.99000000","0.00000000"],["78785.13000000","0.00316000"],["78790.63000000","0.00000000"],["78922.11000000","0.00000000"],["78928.59000000","0.00413000"],["78932.52000000","0.00007000"],["78939.15000000","0.01990000"]]}}
{"rx_ns": 36452952300, "frame": {"e":"depthUpdate","E":1787603093914,"s":"BTCUSDT","U":99076637647,"u":99076637703,"b":[["78713.99000000","4.15536000"],["78713.16000000","0.07521000"],["78713.15000000","3.16282000"],["78711.99000000","0.06835000"],["78711.47000000","0.04010000"],["78711.12000000","0.03224000"],["78709.99000000","0.12315000"],["78708.79000000","0.07105000"],["78706.20000000","0.30007000"],["78526.12000000","0.00778000"],["78520.83000000","0.00000000"],["78498.84000000","0.00000000"],["70842.60000000","0.00032000"]],"a":[["78714.00000000","0.05760000"],["78714.01000000","0.00070000"],["78714.98000000","0.20813000"],["78715.26000000","0.03919000"],["78715.74000000","0.00000000"],["78716.00000000","0.02407000"],["78716.52000000","0.04701000"],["78716.58000000","0.05404000"],["78716.66000000","0.00007000"],["78717.78000000","0.04701000"],["78719.83000000","0.03000000"],["78719.89000000","0.21937000"],["78720.00000000","0.02400000"],["78720.13000000","0.04000000"],["78721.83000000","0.00007000"],["78725.44000000","0.00000000"],["78814.56000000","0.00000000"],["78820.70000000","0.00000000"],["78826.80000000","0.00000000"],["78932.52000000","0.00000000"]]}}
{"rx_ns": 36553285600, "frame": {"e":"depthUpdate","E":1787603094014,"s":"BTCUSDT","U":99076637704,"u":99076637735,"b":[["78713.99000000","4.16466000"],["78713.98000000","0.00020000"],["78713.15000000","3.16182000"],["78712.33000000","0.00635000"],["78711.99000000","0.06835000"],["78710.00000000","0.00507000"],["78707.54000000","0.00000000"],["70842.60000000","0.00064000"],["62971.20000000","0.00031000"],["62971.19000000","0.00000000"]],"a":[["78714.00000000","0.36936000"],["78715.80000000","0.00014000"],["78716.58000000","0.05411000"],["78716.66000000","0.00000000"],["78717.69000000","0.17171000"],["78719.40000000","0.00000000"],["78719.83000000","0.03007000"],["78818.57000000","0.00012000"]]}}
{"rx_ns": 36652804900, "frame": {"e":"depthUpdate","E":1787603094114,"s":"BTCUSDT","U":99076637736,"u":99076637777,"b":[["78713.99000000","4.16487000"],["78713.98000000","0.00034000"],["78713.15000000","3.16182000"],["78712.33000000","0.00000000"],["78712.02000000","0.00007000"],["78710.62000000","0.00635000"],["78710.00000000","0.02507000"],["78708.79000000","0.07119000"],["78318.43000000","0.00000000"],["78003.58000000","0.00000000"],["77926.83000000","0.00000000"],["77537.20000000","0.00000000"],["77149.51000000","0.00000000"],["76763.77000000","0.00000000"],["76379.95000000","0.00029000"],["75998.05000000","0.00000000"],["75618.06000000","0.00000000"],["75239.97000000","0.00093000"],["74863.77000000","0.00000000"],["74489.45000000","0.00000000"],["74117.00000000","0.00000000"],["73746.41000000","0.00000000"],["73377.68000000","0.00000000"],["73010.79000000","0.00000000"]],"a":[["78714.00000000","0.78868000"],["78714.01000000","0.00077000"],["78716.58000000","0.05411000"],["78717.69000000","0.17178000"],["78719.83000000","0.03000000"],["78721.15000000","0.00316000"],["78824.71000000","0.00019000"],["78830.81000000","0.00031000"]]}}
{"rx_ns": 36752601900, "frame": {"e":"depthUpdate","E":1787603094214,"s":"BTCUSDT","U":99076637778,"u":99076637789,"b":[["78713.15000000","3.16182000"],["78532.89000000","0.00778000"],["78526.12000000","0.00000000"],["70842.60000000","0.00096000"],["62971.20000000","0.00000000"]],"a":[["78715.87000000","0.20701000"],["78717.69000000","0.00007000"],["78725.45000000","0.31763000"],["78727.39000000","0.00000000"],["78746.92000000","0.02723000"],["78758.94000000","0.00400000"],["78761.16000000","0.00000000"]]}}
{"rx_ns": 36852913100, "frame": {"e":"depthUpdate","E":1787603094314,"s":"BTCUSDT","U":99076637790,"u":99076637827,"b":[["78690.33000000","0.00007000"],["78688.33000000","0.00000000"],["78657.83000000","0.00000000"],["78625.56000000","0.00000000"],["70842.60000000","0.00112000"],["70842.00000000","0.00225000"],["62971.00000000","0.00000000"]],"a":[["78714.00000000","0.78868000"],["78714.01000000","0.00077000"],["78714.98000000","0.20820000"],["78715.26000000","0.03919000"],["78715.86000000","0.00014000"],["78715.87000000","0.20708000"],["78716.57000000","0.00000000"],["78716.58000000","0.05404000"],["78716.73000000","0.00000000"],["78717.69000000","0.00000000"],["78730.22000000","0.02000000"],["78733.83000000","0.02600000"],["78735.57000000","0.00000000"],["78737.01000000","0.09311000"],["78737.57000000","0.00007000"],["78786.90000000","0.02600000"],["78792.86000000","0.02000000"]]}}
{"rx_ns": 36953454300, "frame": {"e":"depthUpdate","E":1787603094414,"s":"BTCUSDT","U":99076637828,"u":99076637835,"b":[["70842.60000000","0.00144000"],["70842.00000000","0.00235000"]],"a":[["78741.55000000","0.00000000"],["78758.40000000","0.00400000"],["78758.94000000","0.00000000"],["78786.90000000","0.00000000"],["78792.86000000","0.00000000"]]}}
{"rx_ns": 37062969300, "frame": {"e":"depthUpdate","E":1787603094514,"s":"BTCUSDT","U":99076637836,"u":99076637844,"b":[["78713.99000000","4.16494000"],["78713.15000000","3.47946000"],["70842.00000000","0.00225000"],["62971.20000000","0.00031000"]],"a":[["78714.00000000","0.78896000"],["78745.17000000","0.00000000"]]}}
{"rx_ns": 37152721000, "frame": {"e":"depthUpdate","E":1787603094614,"s":"BTCUSDT","U":99076637845,"u":99076637851,"b":[["70842.60000000","0.00160000"],["62971.20000000","0.00000000"]],"a":[["78714.00000000","0.78909000"],["78714.01000000","0.00090000"],["78714.02000000","0.00013000"]]}}
{"rx_ns": 37254169400, "frame": {"e":"depthUpdate","E":1787603094715,"s":"BTCUSDT","U":99076637852,"u":99076637942,"b":[["78713.99000000","4.15929000"],["78713.98000000","0.00062000"],["78713.17000000","0.00000000"],["78713.16000000","0.00021000"],["78711.99000000","0.04835000"],["78711.48000000","0.00635000"],["78710.62000000","0.00000000"],["78709.36000000","0.02439000"],["78708.80000000","0.00635000"],["78708.74000000","0.00000000"],["78704.67000000","0.02000000"],["78691.78000000","0.51702000"],["78665.46000000","0.00000000"],["78320.42000000","0.01000000"],["77928.81000000","0.01010000"],["77539.17000000","0.01000000"],["77151.47000000","0.01000000"],["76765.72000000","0.01000000"],["76381.89000000","0.01000000"],["75999.98000000","0.01012000"],["75619.98000000","0.01000000"],["75241.88000000","0.01000000"],["74865.67000000","0.01009000"],["74491.34000000","0.01000000"],["74118.88000000","0.01000000"],["73748.29000000","0.01000000"],["73379.55000000","0.01000000"],["73012.65000000","0.01000000"],["70842.60000000","0.00160000"]],"a":[["78714.00000000","0.99313000"],["78714.01000000","0.00090000"],["78714.47000000","0.00014000"],["78714.48000000","0.17960000"],["78715.86000000","0.00000000"],["78715.87000000","0.00007000"],["78718.25000000","0.00325000"],["78721.82000000","0.00254000"],["78721.99000000","0.00254000"],["78724.47000000","0.00000000"],["78724.79000000","0.00000000"],["78725.09000000","0.00000000"],["78729.66000000","1.90515000"],["78733.73000000","0.36224000"],["78742.70000000","0.02516000"],["78754.50000000","0.00000000"],["78756.55000000","0.00000000"],["78795.26000000","0.00000000"],["78797.82000000","0.00000000"],["78811.55000000","0.93647000"],["79107.57000000","0.01000000"],["79503.11000000","0.01000000"],["79900.63000000","0.01000000"],["80300.13000000","0.01000000"],["80701.63000000","0.01000000"],["81105.14000000","0.01000000"],["81510.67000000","0.01000000"],["81918.22000000","0.01000000"],["82327.81000000","0.01000000"],["82739.45000000","0.01000000"],["83153.15000000","0.01111000"],["83568.91000000","0.01000000"],["83986.76000000","0.01000000"],["84406.69000000","0.01000000"],["84828.72000000","0.01000000"]]}}
{"rx_ns": 37352717500, "frame": {"e":"depthUpdate","E":1787603094814,"s":"BTCUSDT","U":99076637943,"u":99076637980,"b":[["78713.99000000","4.15929000"],["78713.98000000","0.00062000"],["78713.16000000","0.00014000"],["78711.99000000","0.04835000"],["78709.08000000","0.00027000"],["78707.27000000","0.00254000"],["70842.60000000","0.00176000"],["62971.00000000","0.00000000"]],"a":[["78714.00000000","0.99488000"],["78714.48000000","0.17967000"],["78714.98000000","0.20813000"],["78715.26000000","0.03919000"],["78715.87000000","0.00000000"],["78716.73000000","0.00007000"],["78722.54000000","0.00000000"],["78723.00000000","0.00254000"],["78724.75000000","0.00000000"]]}}
{"rx_ns": 37452816300, "frame": {"e":"depthUpdate","E":1787603094914,"s":"BTCUSDT","U":99076637981,"u":99076638030,"b":[["78713.99000000","2.25414000"],["78713.15000000","0.35479000"],["78712.00000000","0.00007000"],["78711.99000000","0.04505000"],["78711.88000000","0.00330000"],["78711.48000000","0.00642000"],["78711.12000000","0.00000000"],["78707.27000000","0.00000000"],["78706.32000000","0.00000000"],["78706.30000000","0.00014000"],["78706.26000000","0.30661000"],["78699.15000000","0.00000000"],["78684.94000000","0.34317000"],["70842.60000000","0.00176000"],["70840.80000000","0.00000000"],["70840.79000000","0.00009000"]],"a":[["78714.00000000","1.18166000"],["78714.01000000","0.00097000"],["78716.68000000","0.00333000"],["78722.05000000","0.00000000"],["78723.00000000","0.00000000"],["78723.49000000","0.31764000"],["78725.44000000","1.21952000"],["78725.45000000","0.00000000"],["78780.67000000","0.00000000"]]}}
{"rx_ns": 37575207700, "frame": {"e":"depthUpdate","E":1787603095014,"s":"BTCUSDT","U":99076638031,"u":99076638074,"b":[["78713.99000000","2.25221000"],["78713.98000000","0.00062000"],["78713.15000000","0.35479000"],["78712.00000000","0.00014000"],["78711.93000000","0.00007000"],["78711.88000000","0.00000000"],["78711.48000000","0.00656000"],["78711.47000000","0.04017000"],["78711.26000000","0.00014000"],["78711.24000000","0.09101000"],["78708.79000000","0.07105000"],["78706.30000000","0.00000000"],["78704.29000000","0.00254000"],["78673.23000000","0.00007000"],["78626.36000000","0.02116000"],["70842.60000000","0.00192000"],["62971.20000000","0.00031000"],["62971.19000000","0.00000000"],["62971.00000000","0.00000000"]],"a":[["78720.02000000","0.00254000"],["78756.16000000","0.00400000"],["78758.40000000","0.00000000"]]}}
{"rx_ns": 37654459000, "frame": {"e":"depthUpdate","E":1787603095114,"s":"BTCUSDT","U":99076638075,"u":99076638101,"b":[["78713.99000000","2.25421000"],["78713.98000000","0.00062000"],["78711.93000000","0.00014000"],["78710.98000000","0.00000000"],["78626.36000000","0.00000000"],["78604.23000000","0.00400000"],["78597.45000000","0.00000000"],["78005.56000000","0.00010000"],["70842.00000000","0.00245000"]],"a":[["78714.00000000","1.18183000"],["78714.01000000","0.00104000"],["78715.98000000","0.00330000"],["78719.89000000","0.00007000"],["78723.11000000","0.01270000"],["78723.15000000","0.06350000"],["78809.59000000","0.00000000"],["78811.60000000","0.00025000"]]}}
{"rx_ns": 37752702100, "frame": {"e":"depthUpdate","E":1787603095214,"s":"BTCUSDT","U":99076638102,"u":99076638139,"b":[["78713.99000000","2.25421000"],["78320.42000000","0.00000000"],["77928.81000000","0.00010000"],["77539.17000000","0.00000000"],["77151.47000000","0.00000000"],["76765.72000000","0.00000000"],["76381.89000000","0.00000000"],["75999.98000000","0.00012000"],["75619.98000000","0.00000000"],["75241.88000000","0.00000000"],["74865.67000000","0.00009000"],["74491.34000000","0.00000000"],["74118.88000000","0.00000000"],["73748.29000000","0.00000000"],["73379.55000000","0.00000000"],["73012.65000000","0.00000000"],["70842.60000000","0.00208000"],["70842.00000000","0.00235000"],["62971.20000000","0.00000000"]],"a":[["79107.57000000","0.00000000"],["79503.11000000","0.00000000"],["79900.63000000","0.00000000"],["80300.13000000","0.00000000"],["80701.63000000","0.00000000"],["81105.14000000","0.00000000"],["81510.67000000","0.00000000"],["81918.22000000","0.00000000"],["82327.81000000","0.00000000"],["82739.45000000","0.00000000"],["83153.15000000","0.00111000"],["83568.91000000","0.00000000"],["83986.76000000","0.00000000"],["84406.69000000","0.00000000"],["84828.72000000","0.00000000"]]}}
{"rx_ns": 37852815400, "frame": {"e":"depthUpdate","E":1787603095314,"s":"BTCUSDT","U":99076638140,"u":99076638152,"b":[["78690.33000000","0.00000000"],["78626.36000000","0.02116000"],["78532.89000000","0.00000000"],["78520.83000000","0.00778000"],["70842.60000000","0.00208000"],["70842.00000000","0.00225000"],["62970.00000000","0.00000000"]],"a":[["78715.94000000","0.00007000"],["78737.57000000","0.00000000"],["78751.37000000","0.10000000"],["78751.38000000","0.00000000"],["78786.90000000","0.02600000"],["78792.86000000","0.02000000"]]}}
{"rx_ns": 37953684200, "frame": {"e":"depthUpdate","E":1787603095414,"s":"BTCUSDT","U":99076638153,"u":99076638210,"b":[["78713.99000000","4.16508000"],["78713.98000000","0.00041000"],["78712.59000000","0.00014000"],["78712.58000000","0.02000000"],["78711.48000000","0.00007000"],["78711.47000000","0.00007000"],["78711.39000000","0.00326000"],["78708.51000000","0.04010000"],["78706.20000000","0.30000000"],["78705.81000000","0.00254000"],["78704.67000000","0.00000000"],["78704.29000000","0.00000000"],["78690.33000000","0.00007000"],["78673.23000000","0.00000000"],["78626.36000000","0.00000000"],["70842.60000000","0.00208000"],["70842.00000000","0.00225000"]],"a":[["78714.00000000","0.75857000"],["78714.01000000","0.00104000"],["78715.98000000","0.00000000"],["78715.99000000","0.00014000"],["78716.73000000","0.00000000"],["78717.88000000","0.04000000"],["78720.02000000","0.00000000"],["78721.54000000","0.00254000"],["78721.82000000","0.00000000"],["78722.93000000","0.00254000"],["78723.49000000","0.00000000"],["78724.23000000","0.00000000"],["78725.10000000","0.31764000"],["78737.57000000","0.00007000"],["78823.52000000","0.22132000"]]}}
{"rx_ns": 38052865700, "frame": {"e":"depthUpdate","E":1787603095514,"s":"BTCUSDT","U":99076638211,"u":99076638233,"b":[["78713.99000000","4.16508000"],["78713.15000000","0.35479000"],["78712.58000000","0.02007000"],["78711.99000000","0.04505000"],["78711.48000000","0.00000000"],["78711.47000000","0.00000000"],["78710.61000000","0.01470000"],["78710.00000000","0.03207000"],["78708.00000000","0.01900000"],["78626.36000000","0.02116000"],["70842.60000000","0.00240000"],["70842.00000000","0.00235000"],["62971.20000000","0.00031000"]],"a":[["78714.00000000","0.99466000"],["78717.78000000","0.04701000"],["78717.88000000","0.04007000"],["78718.00000000","0.02400000"]]}}
{"rx_ns": 38152730900, "frame": {"e":"depthUpdate","E":1787603095614,"s":"BTCUSDT","U":99076638234,"u":99076638250,"b":[["78713.99000000","4.16515000"],["78713.98000000","0.00048000"],["78713.55000000","0.00000000"],["78701.73000000","0.00000000"],["78699.56000000","0.00000000"],["78662.37000000","0.00000000"],["78642.68000000","0.00000000"],["78626.36000000","0.00000000"],["72420.55000000","0.00014000"],["70842.60000000","0.00240000"],["70842.00000000","0.00235000"],["62971.20000000","0.00000000"]],"a":[["78714.00000000","0.75850000"],["78714.01000000","0.00097000"],["78729.38000000","0.00000000"],["78748.77000000","0.00000000"],["78768.47000000","0.00000000"]]}}
{"rx_ns": 38252934000, "frame": {"e":"depthUpdate","E":1787603095714,"s":"BTCUSDT","U":99076638251,"u":99076638315,"b":[["78713.99000000","3.96360000"],["78713.98000000","0.00062000"],["78710.62000000","0.00635000"],["78710.00000000","0.03214000"],["78320.42000000","0.01000000"],["77928.81000000","0.01010000"],["77539.17000000","0.01000000"],["77151.47000000","0.01000000"],["76765.72000000","0.01000000"],["76381.89000000","0.01000000"],["75999.98000000","0.01012000"],["75619.98000000","0.01000000"],["75241.88000000","0.01000000"],["74865.67000000","0.01009000"],["74491.34000000","0.01000000"],["74118.88000000","0.01000000"],["73748.29000000","0.01000000"],["73379.55000000","0.01000000"],["73012.65000000","0.01000000"],["70842.60000000","0.00240000"],["70842.00000000","0.00225000"],["70840.79000000","0.00000000"]],"a":[["78714.00000000","1.19081000"],["78739.38000000","0.00000000"],["78741.28000000","0.00406000"],["78778.75000000","0.00000000"],["78780.66000000","0.00406000"],["78810.48000000","0.00000000"],["78812.15000000","0.00406000"],["78857.49000000","0.00000000"],["78859.40000000","0.00406000"],["78928.59000000","0.00007000"],["78930.26000000","0.00406000"],["79107.57000000","0.01000000"],["79503.11000000","0.01000000"],["79900.63000000","0.01000000"],["80300.13000000","0.01000000"],["80701.63000000","0.01000000"],["81105.14000000","0.01000000"],["81440.00000000","0.00053000"],["81510.67000000","0.01000000"],["81918.22000000","0.01000000"],["82327.81000000","0.01000000"],["82739.45000000","0.01000000"],["83153.15000000","0.01111000"],["83568.91000000","0.01000000"],["83986.76000000","0.01000000"],["84406.69000000","0.01000000"],["84828.72000000","0.01000000"]]}}
{"rx_ns": 38359038600, "frame": {"e":"depthUpdate","E":1787603095820,"s":"BTCUSDT","U":99076638316,"u":99076638334,"b":[["78713.99000000","3.96560000"],["78713.98000000","0.00062000"],["78712.59000000","0.00000000"],["78712.58000000","0.00007000"],["78711.25000000","0.04333000"],["78711.24000000","0.09101000"],["78711.15000000","0.00000000"],["78711.10000000","0.00000000"],["78707.17000000","0.02000000"],["70842.60000000","0.00256000"]],"a":[["78714.00000000","0.97151000"]]}}
{"rx_ns": 38452615200, "frame": {"e":"depthUpdate","E":1787603095914,"s":"BTCUSDT","U":99076638335,"u":99076638350,"b":[["78713.99000000","3.96553000"],["78713.98000000","0.00062000"],["78713.15000000","0.35479000"],["78712.58000000","0.00000000"],["78710.62000000","0.00642000"],["78710.00000000","0.03914000"],["78708.00000000","0.01907000"],["70842.60000000","0.00272000"],["64139.97000000","0.00744000"]],"a":[]}}
{"rx_ns": 38554655900, "frame": {"e":"depthUpdate","E":1787603096014,"s":"BTCUSDT","U":99076638351,"u":99076638362,"b":[["78700.04000000","0.02200000"],["78660.64000000","0.02200000"],["70842.60000000","0.00272000"],["62971.20000000","0.00031000"],["62971.19000000","0.00000000"]],"a":[["78730.19000000","0.02000000"],["78749.89000000","0.02000000"],["78769.58000000","0.02007000"]]}}
{"rx_ns": 38652553400, "frame": {"e":"depthUpdate","E":1787603096114,"s":"BTCUSDT","U":99076638363,"u":99076638364,"b":[["78545.97000000","0.00000000"],["70842.60000000","0.00288000"]],"a":[]}}
{"rx_ns": 38757034800, "frame": {"e":"depthUpdate","E":1787603096214,"s":"BTCUSDT","U":99076638365,"u":99076638403,"b":[["78710.00000000","0.04414000"],["78708.00000000","0.02407000"],["78564.14000000","0.01990000"],["78508.87000000","0.01990000"],["78500.81000000","0.00000000"],["78320.42000000","0.00000000"],["77928.81000000","0.00010000"],["77539.17000000","0.00000000"],["77151.47000000","0.00000000"],["76765.72000000","0.00000000"],["76381.89000000","0.00000000"],["75999.98000000","0.00012000"],["75619.98000000","0.00000000"],["75241.88000000","0.00000000"],["74865.67000000","0.00009000"],["74491.34000000","0.00000000"],["74118.88000000","0.00000000"],["73748.29000000","0.00000000"],["73379.55000000","0.00000000"],["73012.65000000","0.00000000"],["72420.55000000","0.00000000"],["70842.60000000","0.00288000"],["62971.20000000","0.00000000"]],"a":[["79107.57000000","0.00000000"],["79503.11000000","0.00000000"],["79900.63000000","0.00000000"],["80300.13000000","0.00000000"],["80701.63000000","0.00000000"],["81105.14000000","0.00000000"],["81510.67000000","0.00000000"],["81918.22000000","0.00000000"],["82327.81000000","0.00000000"],["82739.45000000","0.00000000"],["83153.15000000","0.00111000"],["83568.91000000","0.00000000"],["83986.76000000","0.00000000"],["84406.69000000","0.00000000"],["84828.72000000","0.00000000"]]}}
{"rx_ns": 38852704400, "frame": {"e":"depthUpdate","E":1787603096314,"s":"BTCUSDT","U":99076638404,"u":99076638411,"b":[["70842.60000000","0.00288000"],["62971.00000000","0.00000000"]],"a":[["78714.00000000","1.20461000"],["78723.11000000","0.00000000"],["78723.15000000","0.00000000"]]}}
{"rx_ns": 38953360100, "frame": {"e":"depthUpdate","E":1787603096414,"s":"BTCUSDT","U":99076638412,"u":99076638418,"b":[["78690.33000000","0.00007000"]],"a":[["78714.00000000","0.97151000"],["78718.93000000","0.12711000"],["78737.57000000","0.00007000"],["78787.71000000","0.00000000"]]}}
{"rx_ns": 39054710100, "frame": {"e":"depthUpdate","E":1787603096514,"s":"BTCUSDT","U":99076638419,"u":99076638441,"b":[["78701.79000000","0.00000000"],["78662.40000000","0.00000000"],["78642.70000000","0.00000000"],["78626.36000000","0.02116000"],["70842.60000000","0.00304000"],["70842.00000000","0.00225000"],["62971.20000000","0.00031000"]],"a":[["78714.00000000","1.19075000"],["78716.58000000","0.05411000"],["78718.93000000","0.00000000"],["78719.10000000","0.00000000"],["78719.25000000","0.00000000"],["78725.44000000","0.00000000"],["78725.90000000","0.02000000"],["78755.98000000","0.00000000"],["78775.68000000","0.00000000"],["78780.67000000","1.21952000"]]}}
{"rx_ns": 39156129000, "frame": {"e":"depthUpdate","E":1787603096614,"s":"BTCUSDT","U":99076638442,"u":99076638456,"b":[["78713.99000000","3.96553000"],["78626.36000000","0.00000000"],["70842.60000000","0.00304000"],["62971.20000000","0.00000000"]],"a":[["78714.00000000","1.19088000"],["78716.58000000","0.05411000"],["78719.14000000","0.00000000"],["78719.32000000","0.00000000"]]}}
{"rx_ns": 39252652400, "frame": {"e":"depthUpdate","E":1787603096714,"s":"BTCUSDT","U":99076638457,"u":99076638501,"b":[["78320.42000000","0.01000000"],["77928.81000000","0.01010000"],["77539.17000000","0.01000000"],["77151.47000000","0.01000000"],["76765.72000000","0.01000000"],["76381.89000000","0.01000000"],["75999.98000000","0.01012000"],["75619.98000000","0.01000000"],["75241.88000000","0.01000000"],["74865.67000000","0.01009000"],["74491.34000000","0.01000000"],["74118.88000000","0.01000000"],["73748.29000000","0.01000000"],["73379.55000000","0.01000000"],["73012.65000000","0.01000000"],["70842.60000000","0.00320000"]],"a":[["78714.00000000","1.19088000"],["78716.58000000","0.05411000"],["78719.57000000","0.00000000"],["78719.66000000","0.00000000"],["78806.33000000","0.93647000"],["78811.55000000","0.00000000"],["79107.57000000","0.01000000"],["79503.11000000","0.01000000"],["79900.63000000","0.01000000"],["80300.13000000","0.01000000"],["80701.63000000","0.01000000"],["81105.14000000","0.01000000"],["81510.67000000","0.01000000"],["81918.22000000","0.01000000"],["82327.81000000","0.01000000"],["82739.45000000","0.01000000"],["83153.15000000","0.01111000"],["83568.91000000","0.01000000"],["83986.76000000","0.01000000"],["84406.69000000","0.01000000"],["84828.72000000","0.01000000"]]}}
{"rx_ns": 39352517400, "frame": {"e":"depthUpdate","E":1787603096814,"s":"BTCUSDT","U":99076638502,"u":99076638514,"b":[["78700.00000000","0.05207000"],["78660.60000000","0.02800000"],["70842.60000000","0.00320000"]],"a":[["78714.00000000","1.19081000"],["78716.58000000","0.05404000"],["78719.90000000","0.00000000"],["78720.18000000","0.12711000"],["78730.23000000","0.02000000"],["78737.01000000","0.00000000"],["78749.93000000","0.02000000"],["78769.63000000","0.02000000"]]}}
{"rx_ns": 39452589700, "frame": {"e":"depthUpdate","E":1787603096914,"s":"BTCUSDT","U":99076638515,"u":99076638519,"b":[["78712.00000000","0.00514000"],["70842.60000000","0.00336000"]],"a":[["78716.58000000","0.05411000"]]}}
{"rx_ns": 39554227000, "frame": {"e":"depthUpdate","E":1787603097014,"s":"BTCUSDT","U":99076638520,"u":99076638527,"b":[["78713.15000000","0.35479000"],["78640.95000000","0.02200000"],["70842.60000000","0.00336000"],["62971.20000000","0.00031000"],["62971.19000000","0.00000000"]],"a":[]}}
{"rx_ns": 39654702300, "frame": {"e":"depthUpdate","E":1787603097116,"s":"BTCUSDT","U":99076638528,"u":99076638537,"b":[["78713.99000000","3.96567000"],["78705.81000000","0.00000000"],["78673.23000000","0.00007000"],["70842.60000000","0.00352000"],["62971.19000000","0.00000000"]],"a":[["78720.18000000","0.00000000"],["78721.54000000","0.00000000"],["78736.18000000","0.00227000"]]}}
{"rx_ns": 39755280100, "frame": {"e":"depthUpdate","E":1787603097214,"s":"BTCUSDT","U":99076638538,"u":99076638583,"b":[["78713.99000000","3.96574000"],["78713.98000000","0.00069000"],["78704.40000000","0.00254000"],["78320.42000000","0.00000000"],["77928.81000000","0.00010000"],["77539.17000000","0.00000000"],["77151.47000000","0.00000000"],["76765.72000000","0.00000000"],["76381.89000000","0.00000000"],["75999.98000000","0.00012000"],["75619.98000000","0.00000000"],["75241.88000000","0.00000000"],["74865.67000000","0.00009000"],["74491.34000000","0.00000000"],["74118.88000000","0.00000000"],["73748.29000000","0.00000000"],["73379.55000000","0.00000000"],["73012.65000000","0.00000000"],["70842.60000000","0.00368000"],["62971.20000000","0.00000000"]],"a":[["78714.00000000","1.19088000"],["78714.01000000","0.00104000"],["78715.90000000","0.00323000"],["78716.58000000","0.05411000"],["78719.69000000","0.12711000"],["78719.90000000","0.00000000"],["78720.14000000","0.00254000"],["79107.57000000","0.00000000"],["79503.11000000","0.00000000"],["79900.63000000","0.00000000"],["80300.13000000","0.00000000"],["80701.63000000","0.00000000"],["81105.14000000","0.00000000"],["81510.67000000","0.00000000"],["81918.22000000","0.00000000"],["82327.81000000","0.00000000"],["82739.45000000","0.00000000"],["83153.15000000","0.00111000"],["83568.91000000","0.00000000"],["83986.76000000","0.00000000"],["84406.69000000","0.00000000"],["84828.72000000","0.00000000"]]}}
{"rx_ns": 39852840600, "frame": {"e":"depthUpdate","E":1787603097314,"s":"BTCUSDT","U":99076638584,"u":99076638591,"b":[["70842.60000000","0.00352000"],["62971.00000000","0.00000000"]],"a":[["78722.69000000","0.01270000"],["78722.73000000","0.06350000"],["78737.09000000","0.09472000"]]}}
{"rx_ns": 39954133400, "frame": {"e":"depthUpdate","E":1787603097414,"s":"BTCUSDT","U":99076638592,"u":99076638613,"b":[["78713.99000000","3.96560000"],["78690.33000000","0.00007000"],["70842.60000000","0.00384000"]],"a":[["78716.58000000","0.05411000"],["78719.69000000","0.00000000"],["78719.78000000","0.12711000"],["78719.98000000","0.00000000"],["78720.00000000","0.02400000"],["78737.02000000","0.00400000"],["78737.57000000","0.00007000"],["78756.16000000","0.00000000"],["78835.93000000","0.00000000"]]}}
{"rx_ns": 40059030500, "frame": {"e":"depthUpdate","E":1787603097514,"s":"BTCUSDT","U":99076638614,"u":99076638634,"b":[["78713.99000000","3.96548000"],["78694.07000000","0.00000000"],["78667.80000000","0.00000000"],["78648.11000000","0.00000000"],["78483.84000000","0.00000000"],["70842.60000000","0.00384000"],["62971.20000000","0.00031000"]],"a":[["78714.00000000","1.54318000"],["78716.58000000","0.05418000"],["78719.25000000","0.00000000"],["78719.44000000","0.00000000"],["78719.72000000","0.12711000"],["78719.78000000","0.00000000"],["78725.90000000","0.00000000"],["78756.05000000","0.00000000"],["78775.75000000","0.00000000"]]}}
{"rx_ns": 40152712900, "frame": {"e":"depthUpdate","E":1787603097614,"s":"BTCUSDT","U":99076638635,"u":99076638644,"b":[["78713.99000000","3.96348000"],["78517.48000000","0.09955000"],["70842.60000000","0.00384000"],["70842.00000000","0.00225000"],["62971.20000000","0.00000000"]],"a":[["78714.00000000","1.19095000"],["78719.72000000","0.00000000"],["78875.34000000","0.00000000"]]}}
{"rx_ns": 40254814800, "frame": {"e":"depthUpdate","E":1787603097715,"s":"BTCUSDT","U":99076638645,"u":99076638680,"b":[["78713.99000000","3.96362000"],["78320.42000000","0.01000000"],["77928.81000000","0.01010000"],["77539.17000000","0.01000000"],["77151.47000000","0.01000000"],["76765.72000000","0.01000000"],["76381.89000000","0.01000000"],["75999.98000000","0.01012000"],["75619.98000000","0.01000000"],["75241.88000000","0.01000000"],["74865.67000000","0.01009000"],["74491.34000000","0.01000000"],["74118.88000000","0.01000000"],["73748.29000000","0.01000000"],["73379.55000000","0.01000000"],["73012.65000000","0.01000000"],["70842.60000000","0.00400000"]],"a":[["78716.58000000","0.05418000"],["78720.13000000","0.16711000"],["79107.57000000","0.01000000"],["79503.11000000","0.01000000"],["79900.63000000","0.01000000"],["80300.13000000","0.01000000"],["80701.63000000","0.01000000"],["81105.14000000","0.01000000"],["81510.67000000","0.01000000"],["81918.22000000","0.01000000"],["82327.81000000","0.01000000"],["82739.45000000","0.01000000"],["83153.15000000","0.01111000"],["83568.91000000","0.01000000"],["83986.76000000","0.01000000"],["84406.69000000","0.01000000"],["84828.72000000","0.01000000"]]}}
{"rx_ns": 40352564200, "frame": {"e":"depthUpdate","E":1787603097814,"s":"BTCUSDT","U":99076638681,"u":99076638690,"b":[["78700.12000000","0.02800000"],["78660.73000000","0.02800000"],["78640.91000000","0.02800000"],["78626.36000000","0.02116000"],["70842.60000000","0.00416000"]],"a":[["78730.16000000","0.02000000"],["78749.85000000","0.02000000"],["78769.55000000","0.02000000"]]}}
{"rx_ns": 40452560800, "frame": {"e":"depthUpdate","E":1787603097914,"s":"BTCUSDT","U":99076638691,"u":99076638694,"b":[["78626.36000000","0.00000000"],["77893.45000000","0.00000000"],["70842.60000000","0.00416000"]],"a":[]}}
{"rx_ns": 40552749100, "frame": {"e":"depthUpdate","E":1787603098014,"s":"BTCUSDT","U":99076638695,"u":99076638699,"b":[["70842.60000000","0.00416000"],["62971.20000000","0.00031000"],["62971.00000000","0.00000000"]],"a":[]}}
{"rx_ns": 40652550000, "frame": {"e":"depthUpdate","E":1787603098114,"s":"BTCUSDT","U":99076638700,"u":99076638706,"b":[["70842.60000000","0.00416000"],["62971.19000000","0.00000000"]],"a":[["79000.00000000","1.85044000"]]}}
{"rx_ns": 40752612100, "frame": {"e":"depthUpdate","E":1787603098214,"s":"BTCUSDT","U":99076638707,"u":99076638717,"b":[["78320.42000000","0.00000000"],["77410.94000000","0.00000000"],["77151.47000000","0.00000000"],["70842.60000000","0.00416000"],["62971.20000000","0.00000000"]],"a":[["78737.09000000","0.00000000"],["78746.92000000","0.00000000"],["83986.76000000","0.00000000"]]}}
{"rx_ns": 40860441100, "frame": {"e":"depthUpdate","E":1787603098314,"s":"BTCUSDT","U":99076638718,"u":99076638752,"b":[["78713.99000000","3.96362000"],["78613.21000000","2.77192000"],["78610.60000000","0.00000000"],["77928.81000000","0.00010000"],["77539.17000000","0.00000000"],["76765.72000000","0.00000000"],["76381.89000000","0.00000000"],["75999.98000000","0.00012000"],["75619.98000000","0.00000000"],["75241.88000000","0.00000000"],["74865.67000000","0.00009000"],["74491.34000000","0.00000000"],["74118.88000000","0.00000000"],["73748.29000000","0.00000000"],["73379.55000000","0.00000000"],["73012.65000000","0.00000000"],["62971.00000000","0.00000000"]],"a":[["79107.57000000","0.00000000"],["79503.11000000","0.00000000"],["79900.63000000","0.00000000"],["80300.13000000","0.00000000"],["80701.63000000","0.00000000"],["81105.14000000","0.00000000"],["81510.67000000","0.00000000"],["81918.22000000","0.00000000"],["82327.81000000","0.00000000"],["82739.45000000","0.00000000"],["83153.15000000","0.00111000"],["83568.91000000","0.00000000"],["84406.69000000","0.00000000"],["84828.72000000","0.00000000"]]}}
{"rx_ns": 40953813400, "frame": {"e":"depthUpdate","E":1787603098414,"s":"BTCUSDT","U":99076638753,"u":99076638759,"b":[["78690.33000000","0.00000000"],["78626.36000000","0.02116000"],["76934.14000000","0.00000000"],["70842.60000000","0.00416000"]],"a":[["78737.57000000","0.00000000"]]}}
{"rx_ns": 41056789300, "frame": {"e":"depthUpdate","E":1787603098514,"s":"BTCUSDT","U":99076638760,"u":99076638772,"b":[["78713.99000000","3.95335000"],["78694.86000000","0.00000000"],["78690.33000000","0.00007000"],["78668.60000000","0.00000000"],["78648.90000000","0.00000000"],["78626.36000000","0.00000000"],["70842.60000000","0.00432000"],["70842.59000000","0.00009000"],["62971.20000000","0.00031000"]],"a":[["78725.11000000","0.00000000"],["78737.57000000","0.00007000"],["78755.26000000","0.00000000"],["78774.96000000","0.00000000"]]}}
{"rx_ns": 41152808800, "frame": {"e":"depthUpdate","E":1787603098614,"s":"BTCUSDT","U":99076638773,"u":99076638776,"b":[["70842.60000000","0.00416000"],["70842.00000000","0.00225000"],["62971.20000000","0.00000000"]],"a":[]}}
{"rx_ns": 41254184600, "frame": {"e":"depthUpdate","E":1787603098714,"s":"BTCUSDT","U":99076638777,"u":99076638787,"b":[["78713.99000000","3.95314000"],["78713.98000000","0.00062000"],["77911.45000000","0.00000000"],["77120.19000000","0.00379000"],["70842.60000000","0.00432000"]],"a":[["78737.17000000","0.09313000"],["78747.00000000","0.02748000"],["78839.93000000","0.00160000"]]}}
{"rx_ns": 41357945900, "frame": {"e":"depthUpdate","E":1787603098814,"s":"BTCUSDT","U":99076638788,"u":99076638861,"b":[["78713.99000000","3.95335000"],["78711.78000000","0.00000000"],["78711.58000000","0.00400000"],["78711.57000000","0.00000000"],["78711.32000000","0.00000000"],["78707.44000000","0.00000000"],["78706.30000000","0.00800000"],["78701.39000000","0.00000000"],["78701.01000000","0.00000000"],["78700.97000000","0.02600000"],["78661.58000000","0.02600000"],["78641.03000000","0.02800000"],["78320.42000000","0.01000000"],["77928.81000000","0.01010000"],["77539.17000000","0.01000000"],["77151.47000000","0.01000000"],["76765.72000000","0.01000000"],["76381.89000000","0.01000000"],["75999.98000000","0.01012000"],["75619.98000000","0.01000000"],["75241.88000000","0.01000000"],["74865.67000000","0.01009000"],["74491.34000000","0.01000000"],["74118.88000000","0.01000000"],["73748.29000000","0.01000000"],["73379.55000000","0.01000000"],["73012.65000000","0.01000000"],["70842.60000000","0.00416000"]],"a":[["78722.69000000","0.00000000"],["78722.73000000","0.00000000"],["78729.30000000","0.02000000"],["78748.99000000","0.02000000"],["78768.69000000","0.02000000"],["79107.57000000","0.01000000"],["79503.11000000","0.01000000"],["79900.63000000","0.01000000"],["80300.13000000","0.01000000"],["80701.63000000","0.01000000"],["81105.14000000","0.01000000"],["81510.67000000","0.01000000"],["81918.22000000","0.01000000"],["82327.81000000","0.01000000"],["82739.45000000","0.01000000"],["83153.15000000","0.01111000"],["83568.91000000","0.01000000"],["83986.76000000","0.01000000"],["84406.69000000","0.01000000"],["84828.72000000","0.01000000"]]}}
{"rx_ns": 41452962900, "frame": {"e":"depthUpdate","E":1787603098914,"s":"BTCUSDT","U":99076638862,"u":99076638878,"b":[["78713.99000000","3.95163000"],["78713.98000000","0.00069000"],["70842.60000000","0.00416000"]],"a":[["78714.00000000","1.19102000"],["78714.01000000","0.00111000"],["78714.58000000","0.00213000"]]}}
{"rx_ns": 41554814300, "frame": {"e":"depthUpdate","E":1787603099014,"s":"BTCUSDT","U":99076638879,"u":99076638885,"b":[["78713.99000000","3.95363000"],["70842.60000000","0.00416000"],["62971.20000000","0.00031000"]],"a":[["78872.01000000","0.00095000"],["78879.34000000","0.00160000"],["79029.76000000","0.00469000"]]}}
{"rx_ns": 41652652900, "frame": {"e":"depthUpdate","E":1787603099114,"s":"BTCUSDT","U":99076638886,"u":99076638896,"b":[["78626.36000000","0.02116000"],["70842.60000000","0.00432000"],["62971.19000000","0.00000000"]],"a":[["78737.17000000","0.00000000"],["78747.00000000","0.00000000"],["79187.82000000","0.00575000"]]}}
{"rx_ns": 41753600700, "frame": {"e":"depthUpdate","E":1787603099214,"s":"BTCUSDT","U":99076638897,"u":99076638902,"b":[["78713.99000000","3.95356000"],["78626.36000000","0.00000000"],["70842.60000000","0.00400000"],["62971.20000000","0.00000000"]],"a":[["78714.00000000","0.97172000"]]}}
{"rx_ns": 41852985600, "frame": {"e":"depthUpdate","E":1787603099314,"s":"BTCUSDT","U":99076638903,"u":99076638938,"b":[["78320.42000000","0.00000000"],["77928.81000000","0.00010000"],["77539.17000000","0.00000000"],["77151.47000000","0.00000000"],["76765.72000000","0.00000000"],["76381.89000000","0.00000000"],["75999.98000000","0.00012000"],["75619.98000000","0.00000000"],["75241.88000000","0.00000000"],["74865.67000000","0.00009000"],["74491.34000000","0.00000000"],["74118.88000000","0.00000000"],["73748.29000000","0.00000000"],["73379.55000000","0.00000000"],["73012.65000000","0.00000000"],["70842.60000000","0.00432000"],["62971.00000000","0.00000000"]],"a":[["79107.57000000","0.00000000"],["79346.20000000","0.00111000"],["79503.11000000","0.00000000"],["79663.91000000","0.00029000"],["79900.63000000","0.00000000"],["80300.13000000","0.00000000"],["80701.63000000","0.00000000"],["81105.14000000","0.00000000"],["81510.67000000","0.00000000"],["81918.22000000","0.00000000"],["82327.81000000","0.00000000"],["82739.45000000","0.00000000"],["83153.15000000","0.00111000"],["83568.91000000","0.00000000"],["83986.76000000","0.00000000"],["84406.69000000","0.00000000"],["84828.72000000","0.00000000"]]}}
{"rx_ns": 41952458900, "frame": {"e":"depthUpdate","E":1787603099414,"s":"BTCUSDT","U":99076638939,"u":99076638947,"b":[["78706.30000000","0.01200000"],["70842.60000000","0.00416000"],["70842.00000000","0.00235000"],["62971.00000000","0.00300000"]],"a":[["78727.83000000","0.01035000"],["78790.14000000","0.00316000"],["79823.24000000","0.00033000"]]}}
{"rx_ns": 42052966800, "frame": {"e":"depthUpdate","E":1787603099514,"s":"BTCUSDT","U":99076638948,"u":99076638962,"b":[["78690.33000000","0.00007000"],["70842.60000000","0.00416000"],["70842.00000000","0.00225000"],["62971.20000000","0.00031000"],["62971.00000000","0.00000000"]],"a":[["78737.57000000","0.00007000"],["78805.19000000","0.00529000"],["78807.74000000","0.00000000"],["79982.89000000","0.08975000"]]}}
{"rx_ns": 42153871000, "frame": {"e":"depthUpdate","E":1787603099615,"s":"BTCUSDT","U":99076638963,"u":99076638968,"b":[["78626.36000000","0.02116000"],["62971.20000000","0.00000000"]],"a":[["78731.38000000","0.06523000"],["78733.35000000","0.07527000"],["78737.18000000","0.09659000"],["78747.01000000","0.02807000"]]}}
