{"rx_ns": 13878811168100, "frame": {"stream":"btcusdt@depth20","data":{"lastUpdateId":99118602366,"bids":[["79913.00000000","1.71858000"],["79912.99000000","0.00041000"],["79912.98000000","0.00013000"],["79912.96000000","0.00007000"],["79912.95000000","0.05014000"],["79912.55000000","0.00007000"],["79912.54000000","1.18432000"],["79912.53000000","1.04953000"],["79912.04000000","0.00699000"],["79911.99000000","0.00007000"],["79911.72000000","0.02144000"],["79911.64000000","0.00007000"],["79911.63000000","0.00014000"],["79911.49000000","0.00007000"],["79911.28000000","0.00007000"],["79911.20000000","0.00007000"],["79910.89000000","0.00007000"],["79910.88000000","0.12542000"],["79910.86000000","0.00007000"],["79910.85000000","0.12060000"]],"asks":[["79913.01000000","0.90049000"],["79913.02000000","0.00083000"],["79913.03000000","0.00013000"],["79913.85000000","0.00007000"],["79913.99000000","0.00007000"],["79914.00000000","0.02442000"],["79914.03000000","0.00007000"],["79914.23000000","0.00007000"],["79914.48000000","0.00007000"],["79914.84000000","0.00007000"],["79915.40000000","0.00007000"],["79915.41000000","0.06131000"],["79915.45000000","0.00007000"],["79915.50000000","0.00007000"],["79915.76000000","0.00007000"],["79915.79000000","0.00007000"],["79915.97000000","0.00007000"],["79915.98000000","0.05615000"],["79915.99000000","0.04696000"],["79916.00000000","0.02435000"]]}}}
{"rx_ns": 13878811279800, "frame": {"stream":"btcusdt@depth@100ms","data":{"e":"depthUpdate","E":1787650874015,"s":"BTCUSDT","U":99118602358,"u":99118602366,"b":[["79912.04000000","0.00699000"],["79904.00000000","1.05446000"],["79902.00000000","0.00500000"],["79879.36000000","0.00400000"],["79785.00000000","0.00000000"],["63930.40000000","0.00031000"]],"a":[["79921.23000000","0.00000000"],["80024.72000000","0.00000000"]]}}}
{"rx_ns": 13878909233200, "frame": {"stream":"btcusdt@depth@100ms","data":{"e":"depthUpdate","E":1787650874114,"s":"BTCUSDT","U":99118602367,"u":99118602397,"b":[["79912.53000000","1.04953000"],["79912.04000000","0.00706000"],["79910.78000000","0.22893000"],["79904.11000000","0.00007000"],["79904.00000000","1.06646000"],["79902.00000000","0.01700000"],["79900.00000000","1.06639000"],["79898.00000000","0.01700000"],["79896.00000000","0.01207000"],["79875.00000000","0.00000000"],["79774.69000000","0.04532000"],["71921.70000000","0.00256000"]],"a":[["79913.01000000","0.90049000"],["79947.93000000","0.00000000"],["79950.00000000","0.12510000"],["79960.00000000","1.02766000"],["79966.45000000","0.00007000"],["80014.39000000","0.02804000"]]}}}
{"rx_ns": 13878997867400, "frame": {"stream":"btcusdt@depth@100ms","data":{"e":"depthUpdate","E":1787650874214,"s":"BTCUSDT","U":99118602398,"u":99118602409,"b":[["79911.12000000","0.12521000"],["79910.88000000","0.00021000"],["79896.00000000","0.01707000"],["79853.62000000","0.03129000"],["79807.46000000","0.00400000"],["71921.70000000","0.00256000"],["63930.40000000","0.00000000"]],"a":[["79919.33000000","0.00000000"],["80150.61000000","0.00000000"],["80222.60000000","0.00000000"]]}}}
{"rx_ns": 13879096814200, "frame": {"stream":"btcusdt@depth@100ms","data":{"e":"depthUpdate","E":1787650874314,"s":"BTCUSDT","U":99118602410,"u":99118602434,"b":[["79912.04000000","0.00713000"],["79911.72000000","0.02151000"],["79911.13000000","0.00007000"],["79911.12000000","0.00007000"],["79910.89000000","0.00000000"],["79910.88000000","0.00007000"],["79910.00000000","0.00007000"],["79908.98000000","0.00007000"],["79908.42000000","0.00000000"],["79845.62000000","0.02086000"],["71921.70000000","0.00272000"],["63930.00000000","0.00788000"]],"a":[["79913.01000000","0.90056000"],["79918.41000000","0.06131000"],["79918.46000000","0.06117000"],["79949.10000000","0.49565000"]]}}}
{"rx_ns": 13879208822600, "frame": {"stream":"btcusdt@depth@100ms","data":{"e":"depthUpdate","E":1787650874414,"s":"BTCUSDT","U":99118602435,"u":99118602457,"b":[["79911.72000000","0.02144000"],["79911.13000000","0.00000000"],["79911.12000000","0.00000000"],["79910.85000000","0.00007000"],["79910.80000000","0.55320000"],["79910.78000000","0.22900000"],["79908.42000000","0.00007000"],["79853.62000000","0.00000000"],["79845.62000000","0.00000000"],["79687.64000000","0.00400000"],["78714.30000000","0.00030000"],["71921.70000000","0.00272000"]],"a":[["79950.00000000","0.12761000"],["80107.95000000","0.00000000"],["80188.06000000","0.00000000"],["95478.30000000","0.02035000"],["95573.78000000","0.04769000"]]}}}
{"rx_ns": 13879297594900, "kind": "rest", "req": {"method": "GET", "url": "https://data-api.binance.vision/api/v3/depth?symbol=BTCUSDT&limit=1000", "limit": 1000, "weight": 50, "sent_ns": 13877696118300, "status": 200, "used_weight_1m": "50", "recv_ns": 13879234777800}, "frame": {"lastUpdateId":99118602357,"bids":[["79913.00000000","1.71858000"],["79912.99000000","0.00041000"],["79912.98000000","0.00013000"],["79912.96000000","0.00007000"],["79912.95000000","0.05014000"],["79912.55000000","0.00007000"],["79912.54000000","1.18432000"],["79912.53000000","1.04953000"],["79912.04000000","0.00007000"],["79911.99000000","0.00007000"],["79911.72000000","0.02144000"],["79911.64000000","0.00007000"],["79911.63000000","0.00014000"],["79911.49000000","0.00007000"],["79911.28000000","0.00007000"],["79911.20000000","0.00007000"],["79910.89000000","0.00007000"],["79910.88000000","0.12542000"],["79910.86000000","0.00007000"],["79910.85000000","0.12060000"],["79910.84000000","0.00007000"],["79910.81000000","0.00007000"],["79910.80000000","0.31306000"],["79910.79000000","0.00014000"],["79910.78000000","0.22900000"],["79910.44000000","0.02522000"],["79910.40000000","0.05344000"],["79910.19000000","0.00007000"],["79910.13000000","0.03224000"],["79910.00000000","0.00007000"],["79909.99000000","0.33494000"],["79909.59000000","0.18362000"],["79909.22000000","0.00026000"],["79909.16000000","0.02522000"],["79909.14000000","0.00008000"],["79908.98000000","0.00007000"],["79908.97000000","0.39538000"],["79908.96000000","0.00007000"],["79908.42000000","0.00007000"],["79908.41000000","1.04939000"],["79908.26000000","0.00007000"],["79908.06000000","0.00635000"],["79907.99000000","0.00007000"],["79907.76000000","0.00014000"],["79907.75000000","0.00007000"],["79907.01000000","0.00013000"],["79906.18000000","0.00007000"],["79906.03000000","0.00625000"],["79906.02000000","1.15758000"],["79906.01000000","1.87677000"],["79905.99000000","0.20704000"],["79905.85000000","0.00400000"],["79905.56000000","0.12514000"],["79905.01000000","0.00008000"],["79905.00000000","0.00009000"],["79904.72000000","0.00007000"],["79904.30000000","0.15000000"],["79904.27000000","0.00625000"],["79904.13000000","0.03224000"],["79904.01000000","0.00400000"],["79904.00000000","1.04946000"],["79903.99000000","0.41741000"],["79903.89000000","0.00014000"],["79903.63000000","0.26111000"],["79903.37000000","0.08576000"],["79903.34000000","0.00400000"],["79903.02000000","0.00007000"],["79902.73000000","1.40448000"],["79902.72000000","0.54586000"],["79902.69000000","0.00007000"],["79902.03000000","0.00007000"],["79901.79000000","0.37554000"],["79901.52000000","0.00010000"],["79901.47000000","0.00700000"],["79901.36000000","0.00183000"],["79901.12000000","0.00026000"],["79901.07000000","0.00008000"],["79900.84000000","0.00007000"],["79900.83000000","0.00400000"],["79900.62000000","0.12515000"],["79900.55000000","0.00060000"],["79900.23000000","1.88077000"],["79900.02000000","0.00014000"],["79900.00000000","1.04939000"],["79899.99000000","0.48560000"],["79899.95000000","0.00007000"],["79899.49000000","0.00007000"],["79899.21000000","0.00704000"],["79899.03000000","0.00007000"],["79898.42000000","0.00012000"],["79898.32000000","0.00400000"],["79898.09000000","0.50863000"],["79898.08000000","1.20205000"],["79897.99000000","0.20250000"],["79897.87000000","0.00007000"],["79897.78000000","0.00007000"],["79897.20000000","0.02800000"],["79897.12000000","0.02600000"],["79896.96000000","0.00007000"],["79896.39000000","0.04200000"],["79896.33000000","0.04400000"],["79896.29000000","0.00007000"],["79896.15000000","0.00014000"],["79896.01000000","0.00007000"],["79896.00000000","0.00007000"],["79895.80000000","0.00007000"],["79895.10000000","0.09462000"],["79895.04000000","0.00400000"],["79894.99000000","0.00017000"],["79894.43000000","0.00250000"],["79894.42000000","0.28365000"],["79894.41000000","0.37558000"],["79894.21000000","0.00008000"],["79894.20000000","0.02252000"],["79894.19000000","0.33802000"],["79894.01000000","0.36586000"],["79894.00000000","1.38678000"],["79893.99000000","2.03908000"],["79893.80000000","0.02000000"],["79893.72000000","0.00007000"],["79893.54000000","0.00010000"],["79893.30000000","0.00400000"],["79893.21000000","0.02400000"],["79893.10000000","0.10366000"],["79893.08000000","0.00007000"],["79893.00000000","0.00008000"],["79892.84000000","0.00026000"],["79892.74000000","0.02200000"],["79892.46000000","0.00625000"],["79892.45000000","0.16283000"],["79892.35000000","0.02200000"],["79892.34000000","0.02200000"],["79892.29000000","0.42931000"],["79892.28000000","0.00014000"],["79892.00000000","1.07339000"],["79891.99000000","0.18706000"],["79891.88000000","0.33803000"],["79891.75000000","0.51560000"],["79891.64000000","0.00007000"],["79890.21000000","0.00008000"],["79890.10000000","0.00189000"],["79890.01000000","0.64787000"],["79890.00000000","1.35468000"],["79889.99000000","0.34062000"],["79889.92000000","0.00400000"],["79889.58000000","0.12517000"],["79889.57000000","0.00007000"],["79889.28000000","0.00028000"],["79889.21000000","0.02000000"],["79889.20000000","0.00007000"],["79888.41000000","0.00014000"],["79888.01000000","1.87677000"],["79888.00000000","0.02407000"],["79887.98000000","1.04939000"],["79887.49000000","0.00007000"],["79887.36000000","0.00400000"],["79886.74000000","0.00007000"],["79886.60000000","0.48133000"],["79886.37000000","0.37562000"],["79886.22000000","0.00008000"],["79886.02000000","0.00007000"],["79886.00000000","0.12859000"],["79885.80000000","0.33806000"],["79885.79000000","0.33806000"],["79885.78000000","0.00904000"],["79885.56000000","0.00010000"],["79885.41000000","0.00007000"],["79885.12000000","0.00400000"],["79885.01000000","0.29828000"],["79885.00000000","0.70000000"],["79884.93000000","0.00008000"],["79884.54000000","0.00014000"],["79884.02000000","0.00007000"],["79884.01000000","0.00007000"],["79884.00000000","0.02400000"],["79883.88000000","0.00026000"],["79883.33000000","0.00007000"],["79882.88000000","0.00400000"],["79882.22000000","0.00008000"],["79882.12000000","0.36586000"],["79882.11000000","1.11929000"],["79882.10000000","2.39084000"],["79882.08000000","1.04939000"],["79882.07000000","0.05227000"],["79882.04000000","0.22193000"],["79882.01000000","0.00007000"],["79882.00000000","0.02400000"],["79881.94000000","0.05280000"],["79881.44000000","0.00007000"],["79881.26000000","0.00007000"],["79880.78000000","0.02800000"],["79880.69000000","0.02600000"],["79880.67000000","0.00014000"],["79880.64000000","0.00400000"],["79880.01000000","0.00007000"],["79880.00000000","0.12041000"],["79879.90000000","0.02000000"],["79879.44000000","0.35797000"],["79879.24000000","0.33808000"],["79879.18000000","0.00007000"],["79878.77000000","0.37565000"],["79878.40000000","0.00400000"],["79878.23000000","0.00008000"],["79878.03000000","0.02100000"],["79878.01000000","0.00007000"],["79878.00000000","0.02400000"],["79877.91000000","0.04457000"],["79877.79000000","0.20250000"],["79877.58000000","0.00010000"],["79877.10000000","0.00007000"],["79876.86000000","0.00008000"],["79876.80000000","0.00014000"],["79876.78000000","0.02400000"],["79876.33000000","0.02200000"],["79876.16000000","0.00400000"],["79876.02000000","0.00125000"],["79876.00000000","0.02400000"],["79875.94000000","0.02200000"],["79875.92000000","0.02000000"],["79875.87000000","0.00033000"],["79875.03000000","0.00007000"],["79875.00000000","0.09488000"],["79874.77000000","0.50958000"],["79874.23000000","0.00008000"],["79874.00000000","0.02400000"],["79873.98000000","1.67268000"],["79873.92000000","0.00400000"],["79873.79000000","0.02000000"],["79873.68000000","0.00007000"],["79873.04000000","0.64110000"],["79873.00000000","0.01000000"],["79872.95000000","0.00007000"],["79872.42000000","0.01146000"],["79872.38000000","1.87677000"],["79872.23000000","0.01147000"],["79872.03000000","0.30007000"],["79872.01000000","1.34939000"],["79872.00000000","0.32407000"],["79871.77000000","0.00072000"],["79871.68000000","0.30400000"],["79871.51000000","0.62013000"],["79871.50000000","0.37569000"],["79871.01000000","0.30000000"],["79870.87000000","0.00007000"],["79870.67000000","0.34804000"],["79870.23000000","0.00008000"],["79870.01000000","0.00010000"],["79870.00000000","0.11791000"],["79869.60000000","0.00010000"],["79869.29000000","0.20631000"],["79869.26000000","0.20250000"],["79869.25000000","0.03948000"],["79868.80000000","0.00007000"],["79868.79000000","0.00008000"],["79868.61000000","0.00014000"],["79868.29000000","0.00009000"],["79868.10000000","0.00007000"],["79868.04000000","0.00007000"],["79868.00000000","0.02400000"],["79867.71000000","0.00400000"],["79867.16000000","0.83186000"],["79866.76000000","0.00026000"],["79866.72000000","0.00007000"],["79866.00000000","0.02400000"],["79865.92000000","0.00007000"],["79865.58000000","0.36586000"],["79865.57000000","1.15821000"],["79865.56000000","1.87677000"],["79865.54000000","1.04939000"],["79865.00000000","0.70000000"],["79864.65000000","0.00335000"],["79864.64000000","0.00007000"],["79864.29000000","0.03224000"],["79864.11000000","0.00007000"],["79864.02000000","0.37572000"],["79864.00000000","0.02400000"],["79862.57000000","0.00007000"],["79862.23000000","0.38938000"],["79862.05000000","0.00007000"],["79862.00000000","0.02400000"],["79861.62000000","0.00010000"],["79861.26000000","0.20250000"],["79860.72000000","0.00008000"],["79860.49000000","0.00007000"],["79860.33000000","1.04939000"],["79860.14000000","0.00425000"],["79860.00000000","0.02400000"],["79859.32000000","0.00007000"],["79858.92000000","0.92043000"],["79858.91000000","1.87677000"],["79858.41000000","0.00007000"],["79858.20000000","0.00026000"],["79858.16000000","0.00007000"],["79858.00000000","0.02400000"],["79857.99000000","0.00037000"],["79857.77000000","0.00619000"],["79856.93000000","0.36586000"],["79856.34000000","0.00007000"],["79856.23000000","0.03224000"],["79856.13000000","0.00007000"],["79856.00000000","0.02407000"],["79855.92000000","0.02400000"],["79855.72000000","1.11670000"],["79855.65000000","1.04939000"],["79855.41000000","0.37576000"],["79855.11000000","0.02200000"],["79855.09000000","0.02000000"],["79855.07000000","0.02400000"],["79854.26000000","0.00007000"],["79854.10000000","0.82212000"],["79854.05000000","0.02600000"],["79854.04000000","1.87677000"],["79854.01000000","0.00007000"],["79854.00000000","0.16565000"],["79853.64000000","0.00010000"],["79853.21000000","0.00429000"],["79852.99000000","0.07894000"],["79852.85000000","0.04752000"],["79852.65000000","0.00008000"],["79852.35000000","0.00010000"],["79852.19000000","0.00007000"],["79852.06000000","0.00007000"],["79852.00000000","0.02400000"],["79851.99000000","0.00052000"],["79851.98000000","0.00429000"],["79851.71000000","0.12573000"],["79851.32000000","1.22152000"],["79851.31000000","1.04939000"],["79851.24000000","0.02000000"],["79851.14000000","0.00100000"],["79850.86000000","0.02200000"],["79850.40000000","0.00007000"],["79850.11000000","0.00007000"],["79850.10000000","0.00026000"],["79850.05000000","0.04200000"],["79850.02000000","0.00007000"],["79850.00000000","0.02699000"],["79849.61000000","0.02000000"],["79849.25000000","0.04000000"],["79849.21000000","0.02000000"],["79849.20000000","0.02000000"],["79848.93000000","0.20250000"],["79848.05000000","2.24263000"],["79848.03000000","0.00007000"],["79848.00000000","0.02400000"],["79847.70000000","0.00007000"],["79847.10000000","0.53895000"],["79847.09000000","1.04939000"],["79846.85000000","0.01725000"],["79846.00000000","0.02400000"],["79845.96000000","0.00007000"],["79845.87000000","0.82220000"],["79845.66000000","0.00010000"],["79844.58000000","0.00008000"],["79844.01000000","0.00007000"],["79844.00000000","0.02400000"],["79842.76000000","1.24119000"],["79842.75000000","1.87677000"],["79842.73000000","1.04939000"],["79842.64000000","0.00007000"],["79842.01000000","0.00007000"],["79842.00000000","0.02400000"],["79841.85000000","0.03224000"],["79841.81000000","0.00007000"],["79841.48000000","0.00026000"],["79841.21000000","0.00540000"],["79840.03000000","0.36586000"],["79840.00000000","0.92657000"],["79839.47000000","0.00111000"],["79839.42000000","0.00400000"],["79838.42000000","0.00007000"],["79838.00000000","0.02400000"],["79837.70000000","3.39880000"],["79837.68000000","0.00010000"],["79836.51000000","0.00008000"],["79836.44000000","1.04939000"],["79836.26000000","0.02541000"],["79836.08000000","0.00007000"],["79836.02000000","1.87677000"],["79836.01000000","0.00007000"],["79836.00000000","0.02400000"],["79835.58000000","0.00007000"],["79835.11000000","0.02200000"],["79834.88000000","0.00007000"],["79834.03000000","0.00007000"],["79834.00000000","0.02400000"],["79833.57000000","2.32135000"],["79833.38000000","0.00026000"],["79833.35000000","0.00008000"],["79832.08000000","0.00007000"],["79832.07000000","0.00312000"],["79832.06000000","1.04939000"],["79832.00000000","0.02400000"],["79831.81000000","0.36586000"],["79831.80000000","0.32628000"],["79831.75000000","0.00750000"],["79831.71000000","0.00270000"],["79831.43000000","0.00007000"],["79830.87000000","0.00008000"],["79830.34000000","0.00311000"],["79830.00000000","0.02400000"],["79829.82000000","0.00021000"],["79829.70000000","0.00010000"],["79829.34000000","1.87677000"],["79829.28000000","0.12897000"],["79829.25000000","0.02000000"],["79828.44000000","0.00008000"],["79828.28000000","0.00500000"],["79828.00000000","0.02400000"],["79827.99000000","1.04939000"],["79827.83000000","0.20631000"],["79827.73000000","0.00070000"],["79827.12000000","0.00007000"],["79826.33000000","0.00010000"],["79826.32000000","0.00007000"],["79826.30000000","0.00052000"],["79826.00000000","0.02400000"],["79825.39000000","0.00026000"],["79825.33000000","0.00541000"],["79825.20000000","0.00007000"],["79824.68000000","0.00626000"],["79824.50000000","0.03224000"],["79824.00000000","0.02400000"],["79823.81000000","0.36586000"],["79823.79000000","1.04939000"],["79823.52000000","1.99484000"],["79823.16000000","0.00007000"],["79822.60000000","3.75921000"],["79822.16000000","0.20250000"],["79822.00000000","0.02400000"],["79821.72000000","0.00010000"],["79820.37000000","0.00008000"],["79820.10000000","0.00007000"],["79820.09000000","0.00012000"],["79820.00000000","0.02400000"],["79819.99000000","0.00007000"],["79819.60000000","0.04588000"],["79819.40000000","1.04939000"],["79819.36000000","0.00007000"],["79818.98000000","0.00007000"],["79818.06000000","0.00015000"],["79818.00000000","0.02400000"],["79817.97000000","0.04564000"],["79817.50000000","0.03224000"],["79817.28000000","0.02000000"],["79817.15000000","0.00026000"],["79816.35000000","0.00007000"],["79816.00000000","0.02400000"],["79815.50000000","0.36586000"],["79815.10000000","0.02400000"],["79815.05000000","1.04939000"],["79815.00000000","0.00187000"],["79814.82000000","0.00007000"],["79814.27000000","0.00007000"],["79814.02000000","0.20250000"],["79814.01000000","0.00007000"],["79814.00000000","0.02400000"],["79813.74000000","0.00010000"],["79812.98000000","0.00010000"],["79812.49000000","0.62569000"],["79812.32000000","0.00025000"],["79812.30000000","0.00008000"],["79812.00000000","0.02400000"],["79811.62000000","0.02541000"],["79811.60000000","0.00007000"],["79811.30000000","0.20631000"],["79810.43000000","0.00100000"],["79810.29000000","0.02000000"],["79810.28000000","0.00007000"],["79810.10000000","0.00020000"],["79810.00000000","0.02400000"],["79809.62000000","0.02541000"],["79809.22000000","0.04696000"],["79809.16000000","0.00026000"],["79808.00000000","0.02407000"],["79807.19000000","0.00007000"],["79806.68000000","0.05767000"],["79806.61000000","0.36711000"],["79806.60000000","0.06139000"],["79806.52000000","0.00007000"],["79806.44000000","0.00013000"],["79806.01000000","0.20250000"],["79806.00000000","0.02400000"],["79805.76000000","0.00010000"],["79804.59000000","0.00654000"],["79804.45000000","0.00007000"],["79804.23000000","0.00008000"],["79804.12000000","0.00007000"],["79804.02000000","0.00007000"],["79804.00000000","0.02400000"],["79803.84000000","0.02207000"],["79803.35000000","0.00654000"],["79802.09000000","0.00007000"],["79802.00000000","0.02400000"],["79800.92000000","0.00007000"],["79800.86000000","0.00026000"],["79800.32000000","0.80000000"],["79800.00000000","0.82870000"],["79798.23000000","0.00007000"],["79798.06000000","0.00007000"],["79798.05000000","0.36586000"],["79798.00000000","0.02400000"],["79797.99000000","0.00200000"],["79797.90000000","0.00007000"],["79797.78000000","0.00010000"],["79797.43000000","0.20250000"],["79796.16000000","0.00008000"],["79796.08000000","0.00007000"],["79796.05000000","0.00007000"],["79796.00000000","0.02400000"],["79794.59000000","0.03224000"],["79794.03000000","0.00007000"],["79794.00000000","0.02400000"],["79793.86000000","1.24098000"],["79793.48000000","0.00253000"],["79793.41000000","0.00020000"],["79792.66000000","0.00026000"],["79792.23000000","0.00413000"],["79792.03000000","0.00007000"],["79792.00000000","0.02407000"],["79791.03000000","0.00014000"],["79790.58000000","0.00270000"],["79790.00000000","0.02400000"],["79789.80000000","0.00010000"],["79789.43000000","0.20250000"],["79788.77000000","0.00011000"],["79788.59000000","0.36586000"],["79788.53000000","0.00007000"],["79788.32000000","0.00007000"],["79788.14000000","0.00007000"],["79788.00000000","0.02400000"],["79787.85000000","0.00007000"],["79786.12000000","0.00014000"],["79786.00000000","0.02400000"],["79785.00000000","0.04407000"],["79784.19000000","0.00012000"],["79784.04000000","0.00007000"],["79784.00000000","0.02400000"],["79783.70000000","0.00007000"],["79782.80000000","0.00007000"],["79782.00000000","0.02426000"],["79781.82000000","0.00010000"],["79781.80000000","0.03224000"],["79781.43000000","0.20250000"],["79780.99000000","0.00014000"],["79780.57000000","0.00007000"],["79780.56000000","0.00007000"],["79780.48000000","0.36586000"],["79780.36000000","0.00011000"],["79780.02000000","0.00008000"],["79780.00000000","0.02400000"],["79778.86000000","0.00100000"],["79778.68000000","0.00394000"],["79778.18000000","0.00067000"],["79778.16000000","0.00007000"],["79778.00000000","0.02400000"],["79777.06000000","0.03224000"],["79777.00000000","0.00012000"],["79776.11000000","0.00007000"],["79776.00000000","0.02407000"],["79775.41000000","0.00007000"],["79774.00000000","0.02400000"],["79773.97000000","0.00026000"],["79773.84000000","0.00010000"],["79773.61000000","0.00010000"],["79773.43000000","0.20250000"],["79773.13000000","0.00007000"],["79772.80000000","1.50235000"],["79772.69000000","0.00020000"],["79772.16000000","0.00007000"],["79772.00000000","0.02400000"],["79771.26000000","0.00007000"],["79770.99000000","0.00007000"],["79770.39000000","0.36586000"],["79770.15000000","0.00007000"],["79770.00000000","0.02917000"],["79769.41000000","0.03224000"],["79769.12000000","0.00010000"],["79768.85000000","0.00007000"],["79768.00000000","0.02400000"],["79766.71000000","0.00007000"],["79766.66000000","0.00016000"],["79766.00000000","0.02482000"],["79765.99000000","0.00026000"],["79765.86000000","0.00010000"],["79765.25000000","0.01253000"],["79765.04000000","0.00007000"],["79764.70000000","0.00541000"],["79764.51000000","0.00007000"],["79764.09000000","0.09365000"],["79764.00000000","0.02400000"],["79763.88000000","0.00008000"],["79762.96000000","0.00007000"],["79762.26000000","0.36586000"],["79762.17000000","0.00009000"],["79762.12000000","0.00007000"],["79762.00000000","0.02400000"],["79761.89000000","0.00200000"],["79761.88000000","0.00008000"],["79761.84000000","1.24148000"],["79760.16000000","0.00390000"],["79760.08000000","0.00007000"],["79760.00000000","0.02625000"],["79759.54000000","0.00400000"],["79758.95000000","0.00202000"],["79758.00000000","0.02400000"],["79757.99000000","0.00007000"],["79757.88000000","0.00010000"],["79757.62000000","0.00007000"],["79757.52000000","0.00026000"],["79757.41000000","0.00231000"],["79757.38000000","0.00034000"],["79757.28000000","0.00007000"],["79756.79000000","0.03224000"],["79756.43000000","0.00501000"],["79756.18000000","0.00007000"],["79756.00000000","0.02400000"],["79755.98000000","0.01960000"],["79755.93000000","0.00007000"],["79755.00000000","0.09659000"],["79754.67000000","0.00007000"],["79754.20000000","0.00126000"],["79754.00000000","0.02400000"],["79752.24000000","0.00014000"],["79752.06000000","0.00007000"],["79752.00000000","0.02400000"],["79751.41000000","0.00270000"],["79750.96000000","0.00008000"],["79750.52000000","0.00007000"],["79750.00000000","0.02799000"],["79749.90000000","0.00010000"],["79749.37000000","0.00026000"],["79748.08000000","0.00007000"],["79748.00000000","0.02400000"],["79747.88000000","0.36586000"],["79747.84000000","0.00088000"],["79747.74000000","0.00008000"],["79746.89000000","0.00160000"],["79746.37000000","0.00007000"],["79746.04000000","0.08730000"],["79746.00000000","0.02400000"],["79745.46000000","0.00016000"],["79744.74000000","0.00007000"],["79744.00000000","0.02407000"],["79743.95000000","0.00200000"],["79743.94000000","0.00752000"],["79743.28000000","0.25000000"],["79742.45000000","0.00125000"],["79742.44000000","0.01306000"],["79742.19000000","0.00007000"],["79742.00000000","0.02400000"],["79740.20000000","0.00007000"],["79740.16000000","0.00125000"],["79740.15000000","0.00026000"],["79740.00000000","0.05014000"],["79739.48000000","0.00007000"],["79739.28000000","4.62081000"],["79738.93000000","0.00100000"],["79738.83000000","0.00016000"],["79738.00000000","0.02400000"],["79737.27000000","0.12897000"],["79736.72000000","0.07529000"],["79736.67000000","0.00007000"],["79736.47000000","0.00376000"],["79736.04000000","0.00007000"],["79736.01000000","0.00007000"],["79736.00000000","0.02400000"],["79734.24000000","0.00010000"],["79734.00000000","0.02407000"],["79733.69000000","0.00007000"],["79733.57000000","0.00020000"],["79733.50000000","0.36586000"],["79733.18000000","1.20000000"],["79732.48000000","0.00059000"],["79732.00000000","0.02400000"],["79731.98000000","0.00026000"],["79731.70000000","0.00007000"],["79731.60000000","0.00008000"],["79730.76000000","0.00035000"],["79730.00000000","0.03474000"],["79729.79000000","0.00007000"],["79729.72000000","0.00111000"],["79729.70000000","0.00007000"],["79729.04000000","0.00042000"],["79728.65000000","0.00012000"],["79728.64000000","0.00007000"],["79728.57000000","0.00020000"],["79728.40000000","0.00413000"],["79728.00000000","0.02400000"],["79727.14000000","0.00009000"],["79727.11000000","0.00048000"],["79727.00000000","0.00251000"],["79726.86000000","0.00007000"],["79726.69000000","3.76373000"],["79726.00000000","0.02400000"],["79725.64000000","0.00007000"],["79724.22000000","0.00007000"],["79724.07000000","0.00007000"],["79724.00000000","0.02426000"],["79723.98000000","0.00260000"],["79723.52000000","0.00010000"],["79723.40000000","0.00009000"],["79722.28000000","0.00009000"],["79722.00000000","0.02400000"],["79721.94000000","0.00007000"],["79721.64000000","0.00007000"],["79721.57000000","0.00007000"],["79721.30000000","0.03224000"],["79720.20000000","0.00390000"],["79720.00000000","0.02550000"],["79719.42000000","0.00007000"],["79718.52000000","0.00007000"],["79718.16000000","0.00009000"],["79718.00000000","0.02400000"],["79717.58000000","0.00023000"],["79717.43000000","0.00170000"],["79717.34000000","0.00007000"],["79716.78000000","0.00062000"],["79716.66000000","0.00010000"],["79716.45000000","0.00007000"],["79716.03000000","0.00008000"],["79716.00000000","0.02400000"],["79715.91000000","0.00026000"],["79715.53000000","0.00017000"],["79715.46000000","0.00008000"],["79715.28000000","0.00007000"],["79714.36000000","0.00007000"],["79714.28000000","0.00013000"],["79714.20000000","0.00016000"],["79714.00000000","0.02400000"],["79713.90000000","0.00165000"],["79713.76000000","0.00010000"],["79713.56000000","0.00007000"],["79713.45000000","0.00014000"],["79712.53000000","0.00008000"],["79712.00000000","0.02407000"],["79711.26000000","0.00035000"],["79711.23000000","0.05082000"],["79711.00000000","0.00270000"],["79710.76000000","0.00011000"],["79710.75000000","0.00030000"],["79710.72000000","0.00007000"],["79710.54000000","0.00007000"],["79710.00000000","0.02467000"],["79709.77000000","0.03499000"],["79709.57000000","0.00007000"],["79709.06000000","0.00007000"],["79708.33000000","0.00007000"],["79708.24000000","0.00007000"],["79708.00000000","0.02400000"],["79707.66000000","0.00015000"],["79707.50000000","0.00026000"],["79707.44000000","0.00021000"],["79706.59000000","0.03224000"],["79706.00000000","0.02400000"],["79705.88000000","0.00959000"],["79705.59000000","0.00007000"],["79705.45000000","0.00022000"],["79705.00000000","0.00010000"],["79704.92000000","0.00007000"],["79704.88000000","0.00007000"],["79704.00000000","0.02462000"],["79703.75000000","0.00013000"],["79703.74000000","0.00091000"],["79703.71000000","0.00021000"],["79703.56000000","0.00023000"],["79703.52000000","0.00123000"],["79703.38000000","0.00007000"],["79703.19000000","0.00044000"],["79702.97000000","0.02163000"],["79702.92000000","0.00008000"],["79702.91000000","0.07182000"],["79702.82000000","0.00015000"],["79702.64000000","0.00007000"],["79702.54000000","0.00024000"],["79702.00000000","0.02424000"],["79701.79000000","0.00008000"],["79701.66000000","0.00013000"],["79701.60000000","0.00007000"],["79701.33000000","0.00010000"],["79701.32000000","0.00034000"],["79700.91000000","0.00023000"],["79700.90000000","0.01267000"],["79700.89000000","0.00024000"],["79700.88000000","0.00010000"],["79700.85000000","0.00109000"],["79700.51000000","0.00033000"],["79700.48000000","0.00016000"],["79700.29000000","0.00013000"],["79700.28000000","0.05082000"],["79700.15000000","0.00093000"],["79700.10000000","0.00012000"],["79700.00000000","1.18142000"],["79699.86000000","0.00079000"],["79699.77000000","0.00010000"],["79699.72000000","0.00012000"],["79699.59000000","0.00043000"],["79699.51000000","0.00026000"],["79699.39000000","0.00007000"],["79699.32000000","0.00008000"],["79699.20000000","0.00007000"],["79699.02000000","0.00015000"],["79699.01000000","0.00770000"],["79699.00000000","0.13279000"],["79698.79000000","0.00013000"],["79698.70000000","0.00007000"],["79698.63000000","0.00008000"],["79698.48000000","0.00007000"],["79697.89000000","0.00007000"],["79697.86000000","0.00012000"],["79697.56000000","0.00007000"],["79697.50000000","0.00654000"],["79697.09000000","0.00010000"],["79696.96000000","0.00010000"],["79696.91000000","0.00007000"],["79696.86000000","0.00013000"],["79696.59000000","0.00015000"],["79696.39000000","0.00032000"],["79696.10000000","0.00007000"],["79695.64000000","0.00012000"],["79695.39000000","0.00011000"],["79695.21000000","0.03224000"],["79695.12000000","0.00010000"],["79694.95000000","0.00380000"],["79694.87000000","0.00010000"],["79694.84000000","0.00134000"],["79694.71000000","0.00009000"],["79694.66000000","0.00007000"],["79694.44000000","0.00031000"],["79694.34000000","0.00035000"],["79694.22000000","0.00048000"],["79694.05000000","0.00050000"],["79694.00000000","0.00087000"],["79693.69000000","0.00012000"],["79693.58000000","0.00020000"],["79693.43000000","0.00118000"],["79693.33000000","0.00019000"],["79693.13000000","0.00072000"],["79692.59000000","0.00025000"],["79692.55000000","0.00007000"],["79692.48000000","0.00007000"],["79692.32000000","0.00951000"],["79692.30000000","0.00056000"],["79692.26000000","0.00007000"],["79692.22000000","0.00028000"],["79692.07000000","0.00530000"],["79691.34000000","0.00009000"],["79691.01000000","0.00100000"],["79690.79000000","0.00020000"],["79690.52000000","0.00159000"],["79690.50000000","0.00022000"],["79690.37000000","0.00008000"],["79690.31000000","0.00009000"],["79690.00000000","0.00050000"],["79689.83000000","0.00007000"],["79689.80000000","0.00026000"],["79689.65000000","0.00007000"],["79689.59000000","0.00030000"],["79689.44000000","0.00026000"],["79689.19000000","0.00028000"],["79689.16000000","0.00122000"],["79689.00000000","0.00125000"],["79688.88000000","0.00013000"],["79688.76000000","0.00012000"],["79688.63000000","0.00098000"],["79688.40000000","0.00019000"],["79688.34000000","0.00007000"],["79688.20000000","3.76555000"],["79687.85000000","0.00009000"],["79687.77000000","0.00023000"],["79687.55000000","0.00007000"],["79687.50000000","0.00685000"],["79687.44000000","0.00007000"],["79687.36000000","0.00023000"],["79687.12000000","0.00012000"],["79687.03000000","0.00010000"],["79686.99000000","0.00023000"],["79686.89000000","0.01000000"],["79686.72000000","0.00014000"],["79686.68000000","0.00007000"],["79685.71000000","0.00008000"],["79685.56000000","0.00013000"],["79684.94000000","0.00045000"],["79684.66000000","0.00025000"],["79684.65000000","0.00501000"],["79684.56000000","0.00007000"],["79684.21000000","0.00457000"],["79684.15000000","0.00013000"],["79683.74000000","0.00007000"],["79683.66000000","0.11607000"],["79683.58000000","0.00021000"],["79683.54000000","0.00007000"],["79683.48000000","0.00023000"],["79683.18000000","0.00008000"],["79683.15000000","0.00374000"],["79683.07000000","0.00008000"],["79682.75000000","0.00020000"],["79682.72000000","0.00007000"],["79682.35000000","0.00008000"],["79682.12000000","0.00007000"],["79681.92000000","0.00007000"],["79681.81000000","0.00010000"],["79681.62000000","0.00025000"],["79681.51000000","0.00132000"],["79681.46000000","0.00026000"],["79681.39000000","0.00011000"],["79681.01000000","3.76589000"],["79680.97000000","0.00010000"],["79680.88000000","0.00014000"],["79680.85000000","0.00007000"],["79680.82000000","0.00010000"],["79680.38000000","0.00023000"],["79680.36000000","0.00148000"],["79680.32000000","0.00050000"],["79680.11000000","0.00019000"],["79680.00000000","0.02056000"],["79679.90000000","0.00144000"],["79679.89000000","0.00033000"],["79679.17000000","0.00010000"],["79679.06000000","0.00010000"],["79679.02000000","0.00009000"],["79678.57000000","0.00028000"],["79678.27000000","0.00048000"],["79678.17000000","0.00007000"],["79677.97000000","0.00010000"],["79677.58000000","0.00012000"],["79677.53000000","0.00009000"],["79677.47000000","0.00454000"],["79677.41000000","0.00130000"],["79677.21000000","0.00011000"],["79677.10000000","2.84330000"],["79677.06000000","0.00007000"],["79676.94000000","0.01389000"],["79676.89000000","0.00245000"],["79676.76000000","0.00039000"],["79676.60000000","0.00190000"],["79676.47000000","0.00653000"],["79676.40000000","0.00091000"],["79676.28000000","0.00007000"],["79675.91000000","0.00007000"],["79675.86000000","0.00053000"],["79675.78000000","0.00021000"],["79675.70000000","0.00008000"],["79675.67000000","0.00156000"],["79675.66000000","3.40571000"],["79675.00000000","0.00012000"],["79674.66000000","0.00014000"],["79674.64000000","0.01572000"],["79674.47000000","0.00060000"],["79674.41000000","0.00094000"],["79674.14000000","0.00057000"],["79673.70000000","0.00013000"],["79673.64000000","0.00007000"],["79673.37000000","0.00026000"],["79673.33000000","0.00025000"],["79673.20000000","0.00020000"],["79673.14000000","0.00008000"],["79672.84000000","0.00062000"],["79672.69000000","0.00012000"],["79672.31000000","0.00010000"],["79672.01000000","0.00270000"],["79671.91000000","0.00007000"],["79671.90000000","0.00200000"],["79671.39000000","0.00010000"],["79671.05000000","0.00008000"],["79670.91000000","0.11607000"],["79670.66000000","0.00007000"],["79670.58000000","0.00031000"],["79670.26000000","0.00012000"],["79670.14000000","0.00016000"],["79670.01000000","0.00013000"],["79670.00000000","0.00067000"],["79669.97000000","0.00008000"],["79669.86000000","0.00013000"],["79669.78000000","0.00078000"],["79669.77000000","0.00125000"],["79669.70000000","0.00007000"],["79669.48000000","0.00105000"],["79668.89000000","0.00368000"],["79668.59000000","0.00044000"],["79668.58000000","0.00065000"],["79668.49000000","0.00010000"],["79668.13000000","0.00864000"],["79668.00000000","0.03000000"],["79667.95000000","0.00088000"],["79667.46000000","0.00009000"],["79667.45000000","0.00043000"],["79667.27000000","0.00269000"],["79667.26000000","2.32631000"],["79667.17000000","0.00008000"],["79667.09000000","0.03229000"],["79667.04000000","0.00008000"],["79667.03000000","0.00029000"],["79666.66000000","0.03573000"],["79666.60000000","0.00011000"],["79666.55000000","0.00124000"],["79666.52000000","0.00034000"],["79666.40000000","0.00010000"],["79666.28000000","0.00137000"],["79666.19000000","0.00602000"]],"asks":[["79913.01000000","0.90049000"],["79913.02000000","0.00083000"],["79913.03000000","0.00013000"],["79913.85000000","0.00007000"],["79913.99000000","0.00007000"],["79914.00000000","0.02442000"],["79914.03000000","0.00007000"],["79914.23000000","0.00007000"],["79914.48000000","0.00007000"],["79914.84000000","0.00007000"],["79915.40000000","0.00007000"],["79915.41000000","0.06131000"],["79915.45000000","0.00007000"],["79915.50000000","0.00007000"],["79915.76000000","0.00007000"],["79915.79000000","0.00007000"],["79915.97000000","0.00007000"],["79915.98000000","0.05615000"],["79915.99000000","0.04696000"],["79916.00000000","0.02435000"],["79916.20000000","0.00007000"],["79916.36000000","0.00014000"],["79916.37000000","0.00007000"],["79916.42000000","0.00007000"],["79916.58000000","0.00007000"],["79916.59000000","0.06138000"],["79916.67000000","0.00007000"],["79917.05000000","0.00007000"],["79917.06000000","0.00007000"],["79917.19000000","0.00007000"],["79917.20000000","0.26175000"],["79917.21000000","0.05716000"],["79917.28000000","0.00007000"],["79917.71000000","0.00010000"],["79917.78000000","0.00622000"],["79917.79000000","0.00007000"],["79917.80000000","0.05600000"],["79917.87000000","0.00007000"],["79918.00000000","0.02414000"],["79918.02000000","0.00007000"],["79918.36000000","0.00007000"],["79918.41000000","0.06124000"],["79918.47000000","0.11757000"],["79918.64000000","0.00007000"],["79918.75000000","0.42254000"],["79919.00000000","0.00013000"],["79919.06000000","0.01026000"],["79919.36000000","0.00075000"],["79919.37000000","0.00014000"],["79919.99000000","0.45212000"],["79920.00000000","1.02767000"],["79920.23000000","0.00007000"],["79920.24000000","0.00007000"],["79920.33000000","0.00145000"],["79920.34000000","0.01231000"],["79920.37000000","0.00007000"],["79920.40000000","0.00215000"],["79920.72000000","0.00007000"],["79920.96000000","0.00205000"],["79921.00000000","0.00008000"],["79921.06000000","0.00007000"],["79921.07000000","0.00007000"],["79921.54000000","0.12512000"],["79921.62000000","0.01231000"],["79922.00000000","0.02400000"],["79922.01000000","0.01876000"],["79922.42000000","0.00413000"],["79922.47000000","0.00007000"],["79923.20000000","0.00353000"],["79923.24000000","0.00014000"],["79923.38000000","0.00048000"],["79923.58000000","0.02000000"],["79923.59000000","0.02000000"],["79923.66000000","0.02000000"],["79923.70000000","0.00026000"],["79923.97000000","0.01029000"],["79924.00000000","0.02400000"],["79924.12000000","0.00007000"],["79924.26000000","0.00070000"],["79924.27000000","0.00007000"],["79924.31000000","0.00200000"],["79924.60000000","0.00007000"],["79924.87000000","0.00007000"],["79924.97000000","0.71315000"],["79924.98000000","0.20250000"],["79925.28000000","0.00008000"],["79925.34000000","0.00708000"],["79925.69000000","0.00010000"],["79925.70000000","0.00048000"],["79925.71000000","0.00157000"],["79925.76000000","0.00200000"],["79925.99000000","0.02056000"],["79926.00000000","0.02400000"],["79926.01000000","0.00007000"],["79926.22000000","0.00250000"],["79926.29000000","0.02252000"],["79926.74000000","0.00400000"],["79926.75000000","1.04939000"],["79926.76000000","1.87677000"],["79926.95000000","0.00007000"],["79926.98000000","0.00007000"],["79926.99000000","0.02000000"],["79927.11000000","0.00014000"],["79927.24000000","0.02000000"],["79927.68000000","0.00337000"],["79927.79000000","0.02000000"],["79928.00000000","0.04407000"],["79928.13000000","0.52521000"],["79928.54000000","0.00625000"],["79928.55000000","0.02000000"],["79928.94000000","0.02000000"],["79928.96000000","0.36586000"],["79928.99000000","0.00007000"],["79929.03000000","0.00007000"],["79929.34000000","0.00706000"],["79929.54000000","0.12511000"],["79929.58000000","0.00190000"],["79929.76000000","0.00007000"],["79929.85000000","0.00007000"],["79929.90000000","0.00007000"],["79929.92000000","0.00330000"],["79929.99000000","0.00008000"],["79930.00000000","0.02400000"],["79930.98000000","0.00014000"],["79931.00000000","1.04939000"],["79931.11000000","0.00007000"],["79931.61000000","0.00007000"],["79931.71000000","0.02000000"],["79931.76000000","0.04000000"],["79931.88000000","0.00007000"],["79931.96000000","0.64897000"],["79931.97000000","1.88605000"],["79932.00000000","0.02400000"],["79932.09000000","0.00026000"],["79932.16000000","0.00330000"],["79932.66000000","0.02000000"],["79933.34000000","0.00704000"],["79933.35000000","0.00008000"],["79933.67000000","0.00010000"],["79933.71000000","0.09457000"],["79933.75000000","0.02000000"],["79933.98000000","0.00015000"],["79934.00000000","0.02400000"],["79934.20000000","0.15000000"],["79934.40000000","0.00205000"],["79934.80000000","0.19019000"],["79934.81000000","0.00250000"],["79934.85000000","0.00014000"],["79935.14000000","0.00625000"],["79935.15000000","0.00010000"],["79935.37000000","0.00070000"],["79935.71000000","0.10360000"],["79935.76000000","0.00007000"],["79935.77000000","1.06942000"],["79935.78000000","1.04939000"],["79935.99000000","0.00007000"],["79936.00000000","0.02407000"],["79936.13000000","0.00012000"],["79937.08000000","0.37601000"],["79937.09000000","2.24263000"],["79937.25000000","0.00400000"],["79937.33000000","0.00014000"],["79937.34000000","0.00703000"],["79937.98000000","0.00008000"],["79938.00000000","0.02400000"],["79938.01000000","0.20250000"],["79938.07000000","0.00007000"],["79938.56000000","0.12509000"],["79938.72000000","0.00014000"],["79939.80000000","0.98766000"],["79939.81000000","1.04939000"],["79939.90000000","0.00200000"],["79939.97000000","0.00926000"],["79939.99000000","0.00047000"],["79940.00000000","0.33434000"],["79940.34000000","0.00190000"],["79941.06000000","0.00007000"],["79941.11000000","0.00026000"],["79941.34000000","0.00707000"],["79941.42000000","0.00008000"],["79941.65000000","0.00010000"],["79941.97000000","0.00008000"],["79942.00000000","0.02400000"],["79942.59000000","0.00014000"],["79942.66000000","0.62580000"],["79942.67000000","1.87677000"],["79943.20000000","0.00200000"],["79943.52000000","0.00007000"],["79943.58000000","0.00007000"],["79943.64000000","0.00007000"],["79943.65000000","0.00007000"],["79943.68000000","0.00400000"],["79943.80000000","0.64968000"],["79943.81000000","1.04939000"],["79943.84000000","0.03224000"],["79944.00000000","0.02400000"],["79945.23000000","0.36586000"],["79945.28000000","0.33781000"],["79945.53000000","0.00374000"],["79945.66000000","0.00007000"],["79945.68000000","0.00021000"],["79945.82000000","0.00007000"],["79945.89000000","0.00100000"],["79945.97000000","0.00008000"],["79945.99000000","0.00007000"],["79946.00000000","0.02400000"],["79946.10000000","0.00400000"],["79946.46000000","0.00014000"],["79946.98000000","0.33780000"],["79947.65000000","1.89621000"],["79947.66000000","1.87677000"],["79947.93000000","0.51192000"],["79947.94000000","0.00007000"],["79947.97000000","0.00920000"],["79948.00000000","0.22650000"],["79948.51000000","1.04939000"],["79948.52000000","0.00400000"],["79948.93000000","0.02000000"],["79948.97000000","0.10000000"],["79949.32000000","0.00007000"],["79949.33000000","0.00026000"],["79949.49000000","0.00008000"],["79949.53000000","0.02000000"],["79949.63000000","0.00010000"],["79949.81000000","0.00007000"],["79949.99000000","0.00270000"],["79950.00000000","0.12761000"],["79950.27000000","0.02000000"],["79950.33000000","0.04014000"],["79951.00000000","0.70000000"],["79951.03000000","0.00400000"],["79951.28000000","0.00007000"],["79951.61000000","0.64047000"],["79951.62000000","1.11655000"],["79952.00000000","0.02400000"],["79952.46000000","0.00653000"],["79952.81000000","0.00652000"],["79952.87000000","0.02000000"],["79952.97000000","0.00008000"],["79953.00000000","0.01000000"],["79953.02000000","0.62551000"],["79953.16000000","0.00007000"],["79953.48000000","0.02000000"],["79953.54000000","0.00400000"],["79953.74000000","0.02000000"],["79953.91000000","1.04939000"],["79953.97000000","0.00007000"],["79954.00000000","0.02400000"],["79954.06000000","0.00012000"],["79954.12000000","0.09203000"],["79954.20000000","0.00007000"],["79954.37000000","0.02000000"],["79954.41000000","0.36586000"],["79955.00000000","0.00011000"],["79955.15000000","0.00007000"],["79955.31000000","0.04572000"],["79955.43000000","0.33776000"],["79955.45000000","0.00012000"],["79955.51000000","0.40000000"],["79955.57000000","0.00070000"],["79955.89000000","0.00373000"],["79955.97000000","0.00934000"],["79956.00000000","0.02400000"],["79956.17000000","0.02479000"],["79956.35000000","0.00060000"],["79956.81000000","0.02000000"],["79957.15000000","0.00007000"],["79957.24000000","0.98578000"],["79957.25000000","1.87677000"],["79957.28000000","0.03224000"],["79957.39000000","0.00026000"],["79957.56000000","0.00008000"],["79957.61000000","0.00010000"],["79958.00000000","0.02400000"],["79958.13000000","0.00007000"],["79958.24000000","0.00434000"],["79958.33000000","0.09823000"],["79958.40000000","0.00239000"],["79958.42000000","1.20202000"],["79958.48000000","0.00198000"],["79958.54000000","0.00500000"],["79958.90000000","1.04939000"],["79959.04000000","0.00007000"],["79959.18000000","0.20250000"],["79959.21000000","0.00197000"],["79959.22000000","0.00491000"],["79959.42000000","0.00007000"],["79959.83000000","0.33774000"],["79959.88000000","0.99370000"],["79959.96000000","0.00360000"],["79960.00000000","1.02515000"],["79960.22000000","0.02000000"],["79960.91000000","0.62545000"],["79960.96000000","0.00010000"],["79961.00000000","0.00202000"],["79961.35000000","1.23838000"],["79961.43000000","0.04696000"],["79961.44000000","0.00007000"],["79961.51000000","0.02000000"],["79961.66000000","0.33774000"],["79961.70000000","0.00436000"],["79961.79000000","0.00007000"],["79961.93000000","0.02000000"],["79962.00000000","0.02400000"],["79962.02000000","0.00430000"],["79962.18000000","0.02000000"],["79963.39000000","0.83086000"],["79963.65000000","0.00007000"],["79963.73000000","0.00380000"],["79963.92000000","0.00007000"],["79963.99000000","0.84983000"],["79964.00000000","0.02400000"],["79964.06000000","1.87677000"],["79964.13000000","0.00078000"],["79964.37000000","0.00007000"],["79964.78000000","0.00018000"],["79964.80000000","0.00017000"],["79964.96000000","0.00007000"],["79964.97000000","0.34682000"],["79965.16000000","0.00070000"],["79965.20000000","0.82098000"],["79965.59000000","0.00036000"],["79965.63000000","0.00008000"],["79965.87000000","0.00088000"],["79966.00000000","0.02400000"],["79966.04000000","0.00032000"],["79966.29000000","0.00018000"],["79966.60000000","0.00012000"],["79966.80000000","0.00014000"],["79967.46000000","0.00007000"],["79967.51000000","0.00016000"],["79967.61000000","0.00025000"],["79967.83000000","0.36586000"],["79967.84000000","0.35969000"],["79968.00000000","0.02420000"],["79968.01000000","0.00151000"],["79968.15000000","0.00007000"],["79968.92000000","0.02000000"],["79969.09000000","0.51583000"],["79969.50000000","1.04939000"],["79969.52000000","0.02000000"],["79969.87000000","0.00176000"],["79970.00000000","0.02450000"],["79970.02000000","0.00011000"],["79970.27000000","0.02000000"],["79970.32000000","0.02000000"],["79970.33000000","0.02000000"],["79970.50000000","0.00375000"],["79970.57000000","0.00010000"],["79970.58000000","0.00009000"],["79970.60000000","0.00053000"],["79971.08000000","0.00049000"],["79971.44000000","0.00007000"],["79972.00000000","0.02400000"],["79972.66000000","1.01673000"],["79972.72000000","0.20250000"],["79972.86000000","0.02000000"],["79972.97000000","1.48825000"],["79972.98000000","0.03224000"],["79973.25000000","0.00007000"],["79973.48000000","0.02000000"],["79973.56000000","0.00007000"],["79973.57000000","0.00010000"],["79973.64000000","1.04939000"],["79973.65000000","1.87677000"],["79973.70000000","0.00008000"],["79973.73000000","0.02000000"],["79973.83000000","1.23819000"],["79974.00000000","0.02400000"],["79974.29000000","0.92475000"],["79974.34000000","0.00026000"],["79974.36000000","0.02000000"],["79974.52000000","0.00010000"],["79974.56000000","0.00007000"],["79974.76000000","0.00007000"],["79975.00000000","0.00024000"],["79975.99000000","0.58746000"],["79976.00000000","0.02400000"],["79976.12000000","0.00007000"],["79976.15000000","0.00007000"],["79976.26000000","0.00016000"],["79976.81000000","0.02000000"],["79977.90000000","0.00011000"],["79977.99000000","0.00310000"],["79978.00000000","0.02400000"],["79978.25000000","1.23812000"],["79978.27000000","0.00104000"],["79978.47000000","0.00007000"],["79978.78000000","0.82084000"],["79979.11000000","0.00048000"],["79979.88000000","1.04939000"],["79979.89000000","1.01497000"],["79979.90000000","0.00007000"],["79980.00000000","1.02719000"],["79980.22000000","0.02000000"],["79980.70000000","0.20250000"],["79981.00000000","0.00007000"],["79981.50000000","0.00311000"],["79981.51000000","0.02000000"],["79981.55000000","0.00010000"],["79981.77000000","0.00008000"],["79981.81000000","0.01580000"],["79981.92000000","0.02000000"],["79982.00000000","0.02400000"],["79982.09000000","0.02500000"],["79982.17000000","0.02000000"],["79982.21000000","0.36586000"],["79982.32000000","0.00007000"],["79982.38000000","0.00020000"],["79982.41000000","0.00026000"],["79982.45000000","0.00007000"],["79983.24000000","1.87677000"],["79983.55000000","0.00117000"],["79983.99000000","0.02996000"],["79984.00000000","0.02400000"],["79984.95000000","0.01701000"],["79984.98000000","0.00014000"],["79985.16000000","0.00007000"],["79985.29000000","0.01131000"],["79985.34000000","0.00007000"],["79985.44000000","0.00040000"],["79985.45000000","0.00029000"],["79985.71000000","0.00013000"],["79985.82000000","0.00100000"],["79985.98000000","0.02000000"],["79986.00000000","0.02400000"],["79986.02000000","0.00375000"],["79986.08000000","0.00400000"],["79986.41000000","0.00412000"],["79987.28000000","0.00540000"],["79987.56000000","2.11388000"],["79987.92000000","0.00008000"],["79988.00000000","0.02400000"],["79988.17000000","0.03224000"],["79988.41000000","1.23797000"],["79988.68000000","0.20250000"],["79988.79000000","3.43796000"],["79989.32000000","0.00007000"],["79989.53000000","0.00010000"],["79989.84000000","0.00008000"],["79989.96000000","0.00035000"],["79989.99000000","0.00270000"],["79990.00000000","0.02817000"],["79990.08000000","0.00007000"],["79990.27000000","1.04939000"],["79990.65000000","0.00026000"],["79991.99000000","0.57394000"],["79992.00000000","0.02400000"],["79992.16000000","0.00016000"],["79992.83000000","1.87677000"],["79992.87000000","0.00007000"],["79993.19000000","0.00112000"],["79993.85000000","0.01662000"],["79994.00000000","0.02400000"],["79994.02000000","0.00375000"],["79994.15000000","0.00007000"],["79994.28000000","0.00011000"],["79994.55000000","0.00036000"],["79994.94000000","0.00007000"],["79995.56000000","0.00007000"],["79995.88000000","0.00007000"],["79996.00000000","0.02400000"],["79996.06000000","0.00038000"],["79996.18000000","0.18857000"],["79996.59000000","0.36586000"],["79996.66000000","0.20250000"],["79996.85000000","0.00007000"],["79997.44000000","0.00069000"],["79997.62000000","0.00041000"],["79997.84000000","0.00007000"],["79998.00000000","0.02400000"],["79998.36000000","0.00378000"],["79998.83000000","0.00026000"],["79999.00000000","0.00461000"],["79999.01000000","0.01307000"],["79999.03000000","0.01059000"],["79999.10000000","0.00010000"],["79999.17000000","0.00007000"],["79999.38000000","0.00007000"],["79999.55000000","0.00022000"],["79999.60000000","0.00136000"],["79999.85000000","0.00010000"],["79999.89000000","1.04939000"],["79999.90000000","1.99263000"],["79999.92000000","0.00310000"],["79999.94000000","0.00010000"],["80000.00000000","3.37529000"],["80000.17000000","0.04451000"],["80001.80000000","0.00007000"],["80001.83000000","0.00010000"],["80002.12000000","0.00008000"],["80002.42000000","1.87684000"],["80002.51000000","0.00007000"],["80003.61000000","0.00124000"],["80003.99000000","0.00409000"],["80004.63000000","0.78060000"],["80004.64000000","0.20250000"],["80004.85000000","0.00268000"],["80005.00000000","0.00025000"],["80005.04000000","0.00007000"],["80005.46000000","0.36586000"],["80005.54000000","0.00017000"],["80005.60000000","0.00007000"],["80005.95000000","0.00009000"],["80005.98000000","0.00008000"],["80006.05000000","0.00007000"],["80006.59000000","0.00033000"],["80006.66000000","1.99028000"],["80006.85000000","0.00026000"],["80007.19000000","0.00018000"],["80007.44000000","0.00010000"],["80008.00000000","0.00087000"],["80008.04000000","0.00007000"],["80008.30000000","0.09375000"],["80008.52000000","0.00022000"],["80008.56000000","0.00016000"],["80009.02000000","0.00007000"],["80009.89000000","0.04524000"],["80010.00000000","0.00057000"],["80010.03000000","0.00065000"],["80010.27000000","0.31324000"],["80010.28000000","1.04939000"],["80011.59000000","0.00025000"],["80011.86000000","0.00007000"],["80012.00000000","1.41666000"],["80012.01000000","1.87677000"],["80012.11000000","0.00025000"],["80012.23000000","0.00007000"],["80012.46000000","0.03224000"],["80012.61000000","0.00023000"],["80012.62000000","0.20250000"],["80012.68000000","0.00008000"],["80012.85000000","0.80000000"],["80013.11000000","1.95350000"],["80013.12000000","0.00020000"],["80013.36000000","0.00007000"],["80013.42000000","0.00007000"],["80013.72000000","0.12054000"],["80013.89000000","0.00010000"],["80013.94000000","0.00011000"],["80014.31000000","0.00010000"],["80014.71000000","0.00055000"],["80014.90000000","0.00026000"],["80015.29000000","0.00045000"],["80015.37000000","0.00008000"],["80015.74000000","1.54613000"],["80016.06000000","0.00007000"],["80016.10000000","0.01144000"],["80016.21000000","0.00007000"],["80016.66000000","0.00010000"],["80017.15000000","0.00076000"],["80017.64000000","0.00027000"],["80017.81000000","0.00150000"],["80018.06000000","0.00400000"],["80018.81000000","0.00007000"],["80018.82000000","0.00007000"],["80019.08000000","1.41525000"],["80019.10000000","3.74998000"],["80019.33000000","0.00010000"],["80019.50000000","0.62843000"],["80019.99000000","0.00869000"],["80020.00000000","0.00078000"],["80020.60000000","0.20250000"],["80021.12000000","0.00007000"],["80021.13000000","0.03224000"],["80021.19000000","0.00007000"],["80021.34000000","0.00007000"],["80021.42000000","0.00030000"],["80021.57000000","0.00024000"],["80021.60000000","1.87677000"],["80021.85000000","0.00007000"],["80022.12000000","0.00008000"],["80022.22000000","0.00055000"],["80022.66000000","0.01448000"],["80022.76000000","0.00014000"],["80023.13000000","0.00007000"],["80023.25000000","0.00094000"],["80023.28000000","0.00011000"],["80023.30000000","0.00026000"],["80023.52000000","0.00030000"],["80023.77000000","0.00014000"],["80024.70000000","0.00011000"],["80024.72000000","0.02804000"],["80024.83000000","0.00023000"],["80025.00000000","0.00043000"],["80025.16000000","0.00013000"],["80025.83000000","0.00007000"],["80026.29000000","0.00041000"],["80026.63000000","0.00007000"],["80027.39000000","0.00008000"],["80027.71000000","0.00226000"],["80027.84000000","0.00007000"],["80028.44000000","0.00039000"],["80028.57000000","0.93118000"],["80028.58000000","0.20250000"],["80029.22000000","0.00007000"],["80029.37000000","0.00011000"],["80029.38000000","0.00008000"],["80029.41000000","0.00156000"],["80029.47000000","1.04939000"],["80029.74000000","0.00012000"],["80029.98000000","0.00270000"],["80030.00000000","0.01142000"],["80030.01000000","0.00077000"],["80030.07000000","0.00013000"],["80030.10000000","0.00009000"],["80030.30000000","0.00010000"],["80031.19000000","1.87677000"],["80031.25000000","0.00007000"],["80031.31000000","0.00026000"],["80031.35000000","0.00122000"],["80031.41000000","0.00007000"],["80031.91000000","0.00007000"],["80032.00000000","0.00007000"],["80032.15000000","0.12905000"],["80032.16000000","0.06930000"],["80032.43000000","0.00018000"],["80032.69000000","0.00008000"],["80033.06000000","0.00010000"],["80033.17000000","0.00010000"],["80033.31000000","0.00265000"],["80033.33000000","0.00077000"],["80033.42000000","0.00139000"],["80033.52000000","0.00025000"],["80033.74000000","0.00100000"],["80034.28000000","0.00053000"],["80034.88000000","0.36586000"],["80034.90000000","0.00007000"],["80035.27000000","0.00394000"],["80035.45000000","0.00007000"],["80035.46000000","0.00088000"],["80035.57000000","0.17543000"],["80035.58000000","0.34723000"],["80035.76000000","0.02000000"],["80036.03000000","0.00012000"],["80036.56000000","0.20250000"],["80036.59000000","0.00031000"],["80036.64000000","0.00007000"],["80037.03000000","0.00043000"],["80037.19000000","0.00007000"],["80037.22000000","0.00015000"],["80037.44000000","0.00126000"],["80037.53000000","0.00007000"],["80037.64000000","0.00010000"],["80037.68000000","0.00041000"],["80038.18000000","0.00187000"],["80038.26000000","0.00008000"],["80038.52000000","0.03224000"],["80038.85000000","0.00072000"],["80038.93000000","0.00040000"],["80039.79000000","0.00007000"],["80039.81000000","0.00050000"],["80039.84000000","0.00026000"],["80039.85000000","0.88302000"],["80039.86000000","1.04939000"],["80039.88000000","0.00410000"],["80040.00000000","0.00195000"],["80040.01000000","0.00052000"],["80040.24000000","0.00009000"],["80040.55000000","0.00150000"],["80040.78000000","1.89279000"],["80040.80000000","0.00010000"],["80040.93000000","0.00313000"],["80041.22000000","0.00016000"],["80041.77000000","0.00014000"],["80042.15000000","0.00050000"],["80042.47000000","0.00007000"],["80042.73000000","0.00109000"],["80042.85000000","0.00007000"],["80043.25000000","0.00010000"],["80043.46000000","0.00010000"],["80043.78000000","0.00007000"],["80043.82000000","0.00007000"],["80044.17000000","0.00012000"],["80044.53000000","0.08419000"],["80044.54000000","0.20250000"],["80044.63000000","0.00028000"],["80045.29000000","0.00010000"],["80045.39000000","0.00007000"],["80045.42000000","0.00008000"],["80045.63000000","0.00007000"],["80045.72000000","0.03134000"],["80045.95000000","0.00044000"],["80046.18000000","0.04561000"],["80047.05000000","0.00031000"],["80047.45000000","0.01960000"],["80047.47000000","0.25000000"],["80047.75000000","0.00045000"],["80047.77000000","0.00007000"],["80047.88000000","0.00026000"],["80048.04000000","0.00007000"],["80049.06000000","0.00007000"],["80049.25000000","1.25990000"],["80049.26000000","0.36586000"],["80049.66000000","0.00125000"],["80049.87000000","0.00020000"],["80049.99000000","2.92616000"],["80050.00000000","1.00087000"],["80050.28000000","0.00007000"],["80050.53000000","0.11607000"],["80051.13000000","0.00007000"],["80051.50000000","0.09345000"],["80051.51000000","0.10010000"],["80051.58000000","0.00007000"],["80051.76000000","0.00007000"],["80051.92000000","0.00007000"],["80051.99000000","0.00007000"],["80052.13000000","0.00012000"],["80052.44000000","0.00011000"],["80052.52000000","0.20250000"],["80052.98000000","0.00040000"],["80053.04000000","0.00007000"],["80053.26000000","0.00010000"],["80053.50000000","0.00129000"],["80053.52000000","0.00018000"],["80053.58000000","0.00007000"],["80053.64000000","0.00057000"],["80053.81000000","0.00007000"],["80054.31000000","0.00010000"],["80054.40000000","0.00058000"],["80054.46000000","0.00237000"],["80055.00000000","0.00007000"],["80055.26000000","0.00007000"],["80055.92000000","0.00053000"],["80056.01000000","0.01234000"],["80056.27000000","0.00026000"],["80056.60000000","0.00025000"],["80056.73000000","0.00132000"],["80056.74000000","0.00164000"],["80057.14000000","0.00048000"],["80057.25000000","0.00074000"],["80057.49000000","0.00256000"],["80057.59000000","0.00028000"],["80057.81000000","0.00150000"],["80058.32000000","0.00007000"],["80058.82000000","0.00025000"],["80059.11000000","0.00042000"],["80059.43000000","0.00007000"],["80059.48000000","0.00125000"],["80059.80000000","0.00007000"],["80059.92000000","0.00007000"],["80060.00000000","0.00176000"],["80060.24000000","0.00013000"],["80060.40000000","0.00034000"],["80060.49000000","0.20463000"],["80060.50000000","0.20250000"],["80060.52000000","0.00007000"],["80060.58000000","0.00029000"],["80061.53000000","0.00046000"],["80062.10000000","0.00007000"],["80062.54000000","0.11607000"],["80062.56000000","0.00014000"],["80062.78000000","0.36586000"],["80062.82000000","0.00007000"],["80063.61000000","0.00007000"],["80063.82000000","0.00009000"],["80064.00000000","0.00007000"],["80064.15000000","0.00017000"],["80064.72000000","0.00026000"],["80065.00000000","0.00018000"],["80065.13000000","3.74783000"],["80065.15000000","0.00032000"],["80065.23000000","0.02288000"],["80065.65000000","0.02105000"],["80066.02000000","0.00400000"],["80066.09000000","0.00007000"],["80066.66000000","0.00058000"],["80066.84000000","0.00381000"],["80067.46000000","0.00007000"],["80067.83000000","0.00008000"],["80067.99000000","0.00007000"],["80068.00000000","0.00025000"],["80068.75000000","0.00019000"],["80068.89000000","0.00007000"],["80068.90000000","0.00007000"],["80069.18000000","0.00223000"],["80069.99000000","0.00269000"],["80070.00000000","0.00057000"],["80071.26000000","0.00007000"],["80071.42000000","0.00017000"],["80071.54000000","0.00202000"],["80072.13000000","0.00008000"],["80072.21000000","0.00107000"],["80073.03000000","0.00008000"],["80073.12000000","0.00056000"],["80073.18000000","0.00026000"],["80073.59000000","0.00007000"],["80073.64000000","0.00012000"],["80074.10000000","0.00374000"],["80074.16000000","0.00021000"],["80074.17000000","0.00007000"],["80074.29000000","3.74740000"],["80074.39000000","0.01253000"],["80074.55000000","0.11607000"],["80074.67000000","0.00056000"],["80074.73000000","0.00007000"],["80075.00000000","0.00033000"],["80075.18000000","0.00013000"],["80075.78000000","0.00007000"],["80076.46000000","0.20250000"],["80076.50000000","0.00023000"],["80076.51000000","1.50235000"],["80076.60000000","0.00045000"],["80076.70000000","0.00023000"],["80076.73000000","0.00021000"],["80076.80000000","0.00010000"],["80076.81000000","0.00007000"],["80076.92000000","0.00007000"],["80077.16000000","0.36586000"],["80077.39000000","0.00007000"],["80077.58000000","0.00026000"],["80077.62000000","0.00049000"],["80077.87000000","0.00007000"],["80079.13000000","0.00011000"],["80079.30000000","0.00026000"],["80079.31000000","0.00018000"],["80079.33000000","0.00009000"],["80079.46000000","0.00007000"],["80079.76000000","0.00010000"],["80079.84000000","0.00260000"],["80080.00000000","0.00090000"],["80080.39000000","0.00016000"],["80080.50000000","0.00007000"],["80080.83000000","0.00007000"],["80081.25000000","0.00012000"],["80081.50000000","0.00026000"],["80081.65000000","0.00007000"],["80082.11000000","0.00374000"],["80082.19000000","0.00016000"],["80082.30000000","0.00067000"],["80082.35000000","0.00007000"],["80083.20000000","0.00007000"],["80083.33000000","0.00007000"],["80083.43000000","0.00007000"],["80083.76000000","0.00008000"],["80083.83000000","0.00007000"],["80083.96000000","0.00010000"],["80084.02000000","0.01262000"],["80084.40000000","0.00007000"],["80084.74000000","0.00007000"],["80085.42000000","0.00027000"],["80085.63000000","0.00011000"],["80086.27000000","0.00672000"],["80086.28000000","0.00013000"],["80086.37000000","0.00019000"],["80086.57000000","0.11607000"],["80086.68000000","0.00008000"],["80086.76000000","0.00007000"],["80087.57000000","0.00008000"],["80087.62000000","0.00011000"],["80087.68000000","0.00250000"],["80088.23000000","0.00010000"],["80088.88000000","0.00202000"],["80088.94000000","0.00240000"],["80089.13000000","0.00008000"],["80089.32000000","0.00190000"],["80089.70000000","0.00026000"],["80089.95000000","0.00013000"],["80090.00000000","0.00050000"],["80090.03000000","0.00007000"],["80090.09000000","0.00111000"],["80090.10000000","0.00010000"],["80090.19000000","0.00013000"],["80090.44000000","0.00021000"],["80090.63000000","0.00374000"],["80090.75000000","0.00007000"],["80090.87000000","0.00023000"],["80090.90000000","0.00131000"],["80091.25000000","0.00011000"],["80091.54000000","0.36586000"],["80091.76000000","0.00007000"],["80091.93000000","0.00023000"],["80092.41000000","0.00270000"],["80092.42000000","0.20250000"],["80092.63000000","0.00010000"],["80093.75000000","0.00007000"],["80093.79000000","0.00084000"],["80093.80000000","0.00020000"],["80093.82000000","0.00020000"],["80093.92000000","0.00008000"],["80094.38000000","0.00013000"],["80094.74000000","0.00007000"],["80094.91000000","0.00078000"],["80095.32000000","0.00007000"],["80095.39000000","0.00107000"],["80095.92000000","0.00390000"],["80096.00000000","0.00007000"],["80096.13000000","0.01270000"],["80096.31000000","0.00007000"],["80096.37000000","0.00010000"],["80096.38000000","0.00021000"],["80096.45000000","0.00049000"],["80096.66000000","0.00010000"],["80096.87000000","0.22425000"],["80097.23000000","0.01757000"],["80097.48000000","0.00046000"],["80097.51000000","0.00024000"],["80097.64000000","0.00100000"],["80097.96000000","0.00024000"],["80098.01000000","0.00026000"],["80098.59000000","0.11607000"],["80098.73000000","0.00007000"],["80099.93000000","0.00033000"],["80100.00000000","2.23162000"],["80100.22000000","0.00018000"],["80100.40000000","0.20250000"],["80100.60000000","0.00007000"],["80101.00000000","2.26061000"],["80101.02000000","0.00010000"],["80101.35000000","0.00014000"],["80101.47000000","0.00076000"],["80102.29000000","0.00018000"],["80102.45000000","0.00140000"],["80102.67000000","0.00007000"],["80102.86000000","0.00022000"],["80103.01000000","0.00017000"],["80103.46000000","0.00007000"],["80103.61000000","0.00011000"],["80104.34000000","0.00029000"],["80104.93000000","0.00011000"],["80105.17000000","0.00007000"],["80105.23000000","0.00007000"],["80105.57000000","0.00024000"],["80105.59000000","0.00010000"],["80105.89000000","0.00007000"],["80105.92000000","0.36586000"],["80106.08000000","0.00030000"],["80106.29000000","0.00026000"],["80106.32000000","3.74590000"],["80106.48000000","0.00007000"],["80106.66000000","0.00007000"],["80107.35000000","0.00250000"],["80107.53000000","0.00007000"],["80107.62000000","4.57464000"],["80107.74000000","0.00007000"],["80107.89000000","0.00010000"],["80107.95000000","0.02471000"],["80108.40000000","0.20250000"],["80108.66000000","0.00008000"],["80108.71000000","0.00042000"],["80109.05000000","0.00011000"],["80109.10000000","0.00535000"],["80109.80000000","0.00052000"],["80110.00000000","0.00059000"],["80110.24000000","0.00010000"],["80110.61000000","0.11607000"],["80111.00000000","0.00012000"],["80111.02000000","0.00093000"],["80111.11000000","0.00016000"],["80111.52000000","0.00007000"],["80111.91000000","0.00008000"],["80112.12000000","0.00007000"],["80112.14000000","0.00043000"],["80112.42000000","0.00010000"],["80113.13000000","0.00126000"],["80113.33000000","0.00016000"],["80113.40000000","0.00231000"],["80113.68000000","0.00015000"],["80114.32000000","0.00026000"],["80114.74000000","0.00009000"],["80115.04000000","0.00281000"],["80115.35000000","0.00088000"],["80115.38000000","0.00100000"],["80115.50000000","0.00007000"],["80116.80000000","0.00010000"],["80116.86000000","0.00013000"],["80116.89000000","0.00177000"],["80117.05000000","0.00019000"],["80117.25000000","0.00009000"],["80117.28000000","0.00011000"],["80117.64000000","0.01131000"],["80117.78000000","0.00007000"],["80118.76000000","0.00013000"],["80118.81000000","0.00053000"],["80118.96000000","0.00008000"],["80119.73000000","0.00008000"],["80119.85000000","0.00008000"],["80120.00000000","0.00535000"],["80120.30000000","0.36586000"],["80121.87000000","0.00007000"],["80122.15000000","0.00010000"],["80122.32000000","0.00010000"],["80122.63000000","0.11607000"],["80122.77000000","0.00026000"],["80122.82000000","0.02294000"],["80123.69000000","0.00024000"],["80123.70000000","3.74509000"],["80123.72000000","0.00021000"],["80123.80000000","0.00007000"],["80123.87000000","0.00026000"],["80124.19000000","0.00022000"],["80124.34000000","0.20250000"],["80125.00000000","0.00549000"],["80125.11000000","0.00007000"],["80125.68000000","0.00096000"],["80125.78000000","0.00190000"],["80126.29000000","0.00008000"],["80126.52000000","0.00061000"],["80126.68000000","0.00018000"],["80127.47000000","0.00027000"]]}}
{"rx_ns": 13879297594900, "frame": {"stream":"btcusdt@depth@100ms","data":{"e":"depthUpdate","E":1787650874514,"s":"BTCUSDT","U":99118602458,"u":99118602479,"b":[["79911.72000000","0.02137000"],["79911.49000000","0.00000000"],["79910.88000000","0.00000000"],["79910.86000000","0.00000000"],["79910.85000000","0.00000000"],["79910.44000000","0.02529000"],["79906.03000000","0.00632000"],["79904.00000000","1.07346000"],["79902.00000000","0.02400000"],["79900.00000000","1.07339000"],["79898.00000000","0.02400000"],["79896.00000000","0.02407000"],["79845.62000000","0.02086000"],["79687.64000000","0.00000000"],["71921.70000000","0.00288000"],["63930.40000000","0.00031000"]],"a":[]}}}
{"rx_ns": 13879396143000, "frame": {"stream":"btcusdt@depth@100ms","data":{"e":"depthUpdate","E":1787650874614,"s":"BTCUSDT","U":99118602480,"u":99118602590,"b":[["79913.00000000","1.71921000"],["79912.99000000","0.00090000"],["79910.79000000","0.00014000"],["79909.59000000","0.17667000"],["79909.22000000","0.00000000"],["79908.98000000","0.00007000"],["79908.97000000","0.39545000"],["79908.42000000","0.00007000"],["79908.25000000","0.00714000"],["79906.03000000","0.00632000"],["79906.02000000","0.60450000"],["79906.01000000","0.00000000"],["79901.79000000","0.00000000"],["79891.75000000","0.00000000"],["79885.54000000","0.09411000"],["79882.10000000","1.87677000"],["79849.00000000","1.24013000"],["79845.62000000","0.00000000"],["79809.62000000","0.00000000"],["79700.01000000","0.00770000"],["79699.01000000","0.00000000"],["79687.90000000","0.00400000"],["63930.40000000","0.00000000"]],"a":[["79913.01000000","1.10660000"],["79913.02000000","0.00104000"],["79913.60000000","0.00007000"],["79913.61000000","0.06124000"],["79913.98000000","0.00007000"],["79913.99000000","0.05903000"],["79914.00000000","0.02449000"],["79914.20000000","0.00007000"],["79914.21000000","0.06124000"],["79914.53000000","0.10759000"],["79914.80000000","0.00007000"],["79914.81000000","0.06117000"],["79915.68000000","0.00026000"],["79915.98000000","0.05615000"],["79915.99000000","0.04696000"],["79916.58000000","0.00007000"],["79917.19000000","0.00000000"],["79917.20000000","0.26168000"],["79917.21000000","0.05723000"],["79917.64000000","0.00000000"],["79917.79000000","0.00000000"],["79918.00000000","0.02407000"],["79918.02000000","0.00000000"],["79918.41000000","0.06124000"],["79918.47000000","0.00000000"],["79919.61000000","0.06056000"],["79919.64000000","0.00000000"],["79919.85000000","0.00000000"],["79919.97000000","0.96493000"],["79919.98000000","1.87677000"],["79919.99000000","0.00000000"],["79923.38000000","0.00000000"],["79937.97000000","0.33784000"],["79943.39000000","0.62558000"],["79946.93000000","0.33780000"],["79949.10000000","0.00000000"],["79959.83000000","0.00000000"],["79960.00000000","1.02515000"],["79961.66000000","0.00000000"],["79972.66000000","0.00000000"],["79975.99000000","0.26684000"],["79978.25000000","0.00000000"]]}}}
{"rx_ns": 13879500429300, "frame": {"stream":"btcusdt@depth@100ms","data":{"e":"depthUpdate","E":1787650874714,"s":"BTCUSDT","U":99118602591,"u":99118602671,"b":[["79913.00000000","1.68004000"],["79912.99000000","0.00090000"],["79908.98000000","0.00007000"],["79908.42000000","0.00007000"],["79906.03000000","0.00632000"],["79687.90000000","0.00000000"],["71921.70000000","0.00304000"],["63930.40000000","0.00000000"]],"a":[["79913.01000000","1.30761000"],["79913.02000000","0.00111000"],["79913.61000000","0.06138000"],["79913.99000000","0.08720000"],["79914.00000000","0.02449000"],["79914.21000000","0.06145000"],["79914.52000000","0.00007000"],["79914.53000000","0.10766000"],["79914.81000000","0.06124000"],["79915.40000000","0.00007000"],["79915.97000000","0.00007000"],["79915.98000000","0.05615000"],["79915.99000000","0.04675000"],["79916.00000000","0.02421000"],["79916.58000000","0.00000000"],["79916.59000000","0.06131000"],["79917.20000000","0.26161000"],["79917.21000000","0.05702000"],["79919.96000000","0.36586000"],["79924.26000000","0.00000000"],["79930.00000000","0.11784000"],["81111.71000000","0.00030000"]]}}}
{"rx_ns": 13879600487900, "frame": {"stream":"btcusdt@depth@100ms","data":{"e":"depthUpdate","E":1787650874814,"s":"BTCUSDT","U":99118602672,"u":99118602684,"b":[["79909.39000000","0.00026000"],["79853.62000000","0.03129000"],["79845.62000000","0.02086000"],["79720.59000000","0.02145000"],["79702.97000000","0.00000000"],["79687.94000000","0.00400000"],["71921.70000000","0.00304000"],["63930.40000000","0.00000000"]],"a":[["79913.01000000","1.30769000"],["79915.50000000","0.00014000"],["79915.68000000","0.00000000"],["80065.23000000","0.00000000"],["80082.92000000","0.01589000"]]}}}
{"rx_ns": 13879701023700, "frame": {"stream":"btcusdt@depth@100ms","data":{"e":"depthUpdate","E":1787650874914,"s":"BTCUSDT","U":99118602685,"u":99118602701,"b":[["79913.00000000","1.67836000"],["79911.82000000","0.03849000"],["79897.78000000","0.00007000"],["79853.62000000","0.00000000"],["79845.62000000","0.00000000"],["79687.94000000","0.00000000"],["71921.70000000","0.00304000"]],"a":[["79913.01000000","1.30762000"],["79929.76000000","0.00007000"],["79942.82000000","0.02479000"],["79956.17000000","0.00000000"]]}}}
{"rx_ns": 13879795665900, "frame": {"stream":"btcusdt@depth20","data":{"lastUpdateId":99118602716,"bids":[["79913.00000000","1.67962000"],["79912.99000000","0.00090000"],["79912.98000000","0.00013000"],["79912.96000000","0.00007000"],["79912.95000000","0.05014000"],["79912.55000000","0.00007000"],["79912.54000000","1.18432000"],["79912.53000000","1.04953000"],["79912.04000000","0.00720000"],["79911.99000000","0.00007000"],["79911.82000000","0.03856000"],["79911.72000000","0.02137000"],["79911.64000000","0.00007000"],["79911.63000000","0.00014000"],["79911.28000000","0.00007000"],["79911.20000000","0.00007000"],["79910.84000000","0.00007000"],["79910.81000000","0.00007000"],["79910.80000000","0.55320000"],["79910.79000000","0.00014000"]],"asks":[["79913.01000000","1.30762000"],["79913.02000000","0.00111000"],["79913.03000000","0.00013000"],["79913.60000000","0.00007000"],["79913.61000000","0.06138000"],["79913.85000000","0.00007000"],["79913.98000000","0.00007000"],["79913.99000000","0.08720000"],["79914.00000000","0.02449000"],["79914.03000000","0.00007000"],["79914.20000000","0.00007000"],["79914.21000000","0.06145000"],["79914.23000000","0.00007000"],["79914.48000000","0.00007000"],["79914.52000000","0.00007000"],["79914.53000000","0.10766000"],["79914.80000000","0.00007000"],["79914.81000000","0.06124000"],["79914.84000000","0.00007000"],["79915.40000000","0.00007000"]]}}}
{"rx_ns": 13879795778800, "frame": {"stream":"btcusdt@depth@100ms","data":{"e":"depthUpdate","E":1787650875014,"s":"BTCUSDT","U":99118602702,"u":99118602716,"b":[["79913.00000000","1.67962000"],["79912.04000000","0.00720000"],["79911.82000000","0.03856000"],["79910.44000000","0.02522000"],["79895.89000000","0.52114000"],["79871.29000000","1.07207000"],["79687.94000000","0.00400000"],["71921.70000000","0.00320000"],["63930.40000000","0.00031000"]],"a":[["79947.06000000","0.52290000"],["79971.67000000","1.02395000"]]}}}
{"rx_ns": 13879896203400, "frame": {"stream":"btcusdt@depth@100ms","data":{"e":"depthUpdate","E":1787650875114,"s":"BTCUSDT","U":99118602717,"u":99118602742,"b":[["79913.00000000","1.67962000"],["79912.99000000","0.00097000"],["79911.82000000","0.03863000"],["79911.64000000","0.00000000"],["79830.97000000","0.62551000"],["79812.49000000","0.00000000"],["79687.94000000","0.00000000"],["71921.70000000","0.00336000"],["71921.69000000","0.00000000"],["71921.00000000","0.00017000"],["63930.00000000","0.00788000"]],"a":[["79913.01000000","1.30748000"],["79914.53000000","0.10773000"],["79962.29000000","0.00007000"],["79968.52000000","0.00007000"],["79970.00000000","0.03023000"]]}}}
{"rx_ns": 13879997883300, "frame": {"stream":"btcusdt@depth@100ms","data":{"e":"depthUpdate","E":1787650875214,"s":"BTCUSDT","U":99118602743,"u":99118602748,"b":[["79899.99000000","0.48810000"],["79687.93000000","0.00400000"],["71921.70000000","0.00320000"],["63930.40000000","0.00000000"]],"a":[["79919.61000000","0.00000000"],["79947.06000000","0.00000000"]]}}}
{"rx_ns": 13880097769400, "frame": {"stream":"btcusdt@depth@100ms","data":{"e":"depthUpdate","E":1787650875314,"s":"BTCUSDT","U":99118602749,"u":99118602784,"b":[["79913.00000000","1.68034000"],["79905.00000000","0.00067000"],["79897.01000000","0.00067000"],["79889.02000000","0.00067000"],["79881.03000000","0.00067000"],["79687.93000000","0.00000000"],["71921.70000000","0.00352000"],["63930.00000000","0.00788000"]],"a":[["79913.01000000","1.30748000"],["79913.02000000","0.00104000"],["79913.49000000","0.10333000"],["79913.50000000","0.07473000"],["79913.99000000","0.00021000"],["79914.52000000","0.00000000"],["79914.53000000","0.00014000"],["79916.59000000","0.06124000"],["79917.20000000","0.19191000"],["79917.21000000","0.00000000"],["79920.51000000","0.00000000"],["79950.00000000","0.12510000"]]}}}
{"rx_ns": 13880197540700, "frame": {"stream":"btcusdt@depth@100ms","data":{"e":"depthUpdate","E":1787650875414,"s":"BTCUSDT","U":99118602785,"u":99118602826,"b":[["79845.62000000","0.02086000"],["79687.91000000","0.00400000"],["78714.30000000","0.00030000"],["71921.70000000","0.00368000"]],"a":[["79913.01000000","1.30747000"],["79913.02000000","0.00104000"],["79913.48000000","0.00007000"],["79913.49000000","0.10347000"],["79913.50000000","0.07487000"],["79913.61000000","0.06138000"],["79913.98000000","0.00000000"],["79913.99000000","0.00007000"],["79914.21000000","0.06138000"],["79914.53000000","0.00000000"],["79948.00000000","0.92650000"],["79951.00000000","0.00000000"]]}}}
{"rx_ns": 13880296493900, "frame": {"stream":"btcusdt@depth@100ms","data":{"e":"depthUpdate","E":1787650875514,"s":"BTCUSDT","U":99118602827,"u":99118602840,"b":[["79910.50000000","0.07888000"],["79893.02000000","0.00007000"],["79885.54000000","0.00000000"],["79884.27000000","0.09459000"],["79852.99000000","0.00000000"],["79845.62000000","0.00000000"],["79833.08000000","0.00022000"],["79818.06000000","0.00007000"],["79687.91000000","0.00000000"],["71921.70000000","0.00368000"],["63930.40000000","0.00031000"]],"a":[["79954.12000000","0.00000000"],["79954.55000000","0.09263000"]]}}}
{"rx_ns": 13880397036900, "frame": {"stream":"btcusdt@depth@100ms","data":{"e":"depthUpdate","E":1787650875614,"s":"BTCUSDT","U":99118602841,"u":99118602862,"b":[["79913.00000000","1.68020000"],["79910.78000000","0.22907000"],["79845.62000000","0.02086000"],["79687.91000000","0.00400000"],["79669.76000000","0.01960000"],["79653.11000000","0.00000000"],["71921.70000000","0.00392000"],["63930.40000000","0.00000000"]],"a":[["79913.01000000","1.30576000"],["79913.02000000","0.00097000"],["79913.60000000","0.00000000"],["79913.61000000","0.00021000"],["79915.99000000","0.04682000"],["79947.05000000","0.49574000"],["79953.70000000","0.01270000"]]}}}
{"rx_ns": 13880495698100, "frame": {"stream":"btcusdt@depth@100ms","data":{"e":"depthUpdate","E":1787650875714,"s":"BTCUSDT","U":99118602863,"u":99118602877,"b":[["79913.00000000","1.67953000"],["79905.00000000","0.00000000"],["79845.62000000","0.00000000"],["71921.70000000","0.00392000"],["63930.40000000","0.00000000"]],"a":[["79913.50000000","0.07487000"],["79913.61000000","0.00007000"],["79914.81000000","0.06131000"],["79915.99000000","0.04689000"]]}}}
{"rx_ns": 13880597746100, "frame": {"stream":"btcusdt@depth@100ms","data":{"e":"depthUpdate","E":1787650875814,"s":"BTCUSDT","U":99118602878,"u":99118602918,"b":[["79913.00000000","1.67960000"],["79912.99000000","0.00041000"],["79905.00000000","0.00068000"],["79897.01000000","0.00068000"],["79889.02000000","0.00068000"],["79881.03000000","0.00068000"],["79700.01000000","0.00000000"],["79688.21000000","0.00770000"],["71921.70000000","0.00408000"],["63930.40000000","0.00000000"]],"a":[["79913.01000000","1.30769000"],["79913.02000000","0.00090000"],["79913.49000000","0.06678000"],["79914.20000000","0.00000000"],["79914.21000000","0.00021000"],["79916.58000000","0.00007000"],["81111.71000000","0.00030000"]]}}}
{"rx_ns": 13880701531300, "frame": {"stream":"btcusdt@depth@100ms","data":{"e":"depthUpdate","E":1787650875914,"s":"BTCUSDT","U":99118602919,"u":99118602968,"b":[["79913.00000000","1.67960000"],["79912.99000000","0.00041000"],["79897.78000000","0.00007000"]],"a":[["79914.00000000","0.02449000"],["79914.21000000","0.00007000"],["79915.99000000","0.04696000"],["79916.00000000","0.02428000"],["79917.19000000","0.06117000"],["79929.76000000","0.00007000"]]}}}
{"rx_ns": 13880796344700, "frame": {"stream":"btcusdt@depth20","data":{"lastUpdateId":99118602998,"bids":[["79913.00000000","1.67995000"],["79912.99000000","0.00090000"],["79912.98000000","0.00013000"],["79912.96000000","0.00007000"],["79912.95000000","0.05014000"],["79912.55000000","0.00007000"],["79912.54000000","1.18432000"],["79912.53000000","1.04953000"],["79912.04000000","0.00720000"],["79911.99000000","0.00007000"],["79911.82000000","0.03863000"],["79911.72000000","0.02137000"],["79911.63000000","0.00014000"],["79911.28000000","0.00007000"],["79911.21000000","0.00007000"],["79911.20000000","0.12528000"],["79910.84000000","0.00007000"],["79910.81000000","0.00007000"],["79910.80000000","0.55320000"],["79910.79000000","0.00014000"]],"asks":[["79913.01000000","1.30763000"],["79913.02000000","0.00090000"],["79913.03000000","0.00013000"],["79913.48000000","0.00007000"],["79913.49000000","0.06678000"],["79913.50000000","0.07487000"],["79913.61000000","0.00007000"],["79913.85000000","0.00007000"],["79913.99000000","0.00007000"],["79914.00000000","0.02449000"],["79914.03000000","0.00007000"],["79914.21000000","0.00007000"],["79914.23000000","0.00007000"],["79914.48000000","0.00007000"],["79914.80000000","0.00007000"],["79914.81000000","0.06131000"],["79914.84000000","0.00007000"],["79915.40000000","0.00007000"],["79915.41000000","0.06131000"],["79915.45000000","0.00007000"]]}}}
{"rx_ns": 13880796527400, "frame": {"stream":"btcusdt@depth@100ms","data":{"e":"depthUpdate","E":1787650876014,"s":"BTCUSDT","U":99118602969,"u":99118602998,"b":[["79913.00000000","1.67995000"],["79912.99000000","0.00090000"],["79911.21000000","0.00007000"],["79911.20000000","0.12528000"],["79903.63000000","0.00000000"],["71921.70000000","0.00424000"],["63930.40000000","0.00031000"],["63930.00000000","0.00788000"]],"a":[["79913.01000000","1.30763000"],["79916.59000000","0.06131000"],["79947.05000000","0.00000000"]]}}}
{"rx_ns": 13880896440300, "frame": {"stream":"btcusdt@depth@100ms","data":{"e":"depthUpdate","E":1787650876114,"s":"BTCUSDT","U":99118602999,"u":99118603017,"b":[["79913.00000000","1.68002000"],["79912.99000000","0.00097000"],["79911.72000000","0.02137000"],["79911.20000000","0.12535000"],["79910.78000000","0.22900000"],["79906.04000000","1.16570000"],["79906.03000000","1.88302000"],["79906.02000000","0.00153000"],["79772.80000000","0.00000000"],["71921.70000000","0.00424000"]],"a":[["79960.00000000","1.02766000"],["79960.21000000","0.00007000"],["79972.68000000","0.00007000"],["80076.51000000","0.00000000"]]}}}
{"rx_ns": 13880997080600, "frame": {"stream":"btcusdt@depth@100ms","data":{"e":"depthUpdate","E":1787650876214,"s":"BTCUSDT","U":99118603018,"u":99118603029,"b":[["79913.00000000","1.67995000"],["79912.99000000","0.00090000"],["79911.21000000","0.00000000"],["79911.20000000","0.00014000"],["79906.05000000","0.00007000"],["71921.70000000","0.00440000"],["71921.00000000","0.00017000"],["63930.40000000","0.00000000"]],"a":[["79915.50000000","0.00007000"],["79960.00000000","1.02515000"],["80232.65000000","0.00124000"]]}}}
{"rx_ns": 13881095978900, "frame": {"stream":"btcusdt@depth@100ms","data":{"e":"depthUpdate","E":1787650876314,"s":"BTCUSDT","U":99118603030,"u":99118603049,"b":[["79913.00000000","1.68016000"],["79911.72000000","0.02137000"],["79911.20000000","0.00007000"],["79910.78000000","0.22907000"],["79910.27000000","0.00716000"],["79903.94000000","0.13275000"],["71921.70000000","0.00440000"],["63930.00000000","0.00788000"]],"a":[["79913.01000000","1.30013000"],["79942.06000000","0.01270000"],["79947.03000000","0.51240000"],["79950.86000000","0.00573000"],["79970.00000000","0.02450000"],["80312.56000000","0.00124000"]]}}}
{"rx_ns": 13881196163200, "frame": {"stream":"btcusdt@depth@100ms","data":{"e":"depthUpdate","E":1787650876414,"s":"BTCUSDT","U":99118603050,"u":99118603069,"b":[["79913.00000000","1.68030000"],["79906.04000000","0.64509000"],["79906.03000000","0.00625000"],["79852.47000000","0.04694000"],["79809.22000000","0.00000000"],["78714.30000000","0.00030000"],["71921.70000000","0.00440000"]],"a":[["79913.01000000","1.29976000"],["79915.50000000","0.00014000"],["79919.95000000","0.06117000"]]}}}
{"rx_ns": 13881306897900, "frame": {"stream":"btcusdt@depth@100ms","data":{"e":"depthUpdate","E":1787650876514,"s":"BTCUSDT","U":99118603070,"u":99118603080,"b":[["71921.70000000","0.00432000"],["71921.69000000","0.00008000"],["63930.40000000","0.00031000"]],"a":[["79913.01000000","1.08468000"],["79913.02000000","0.00083000"],["79913.48000000","0.06124000"],["79914.21000000","0.06124000"],["79942.06000000","0.00000000"],["79950.86000000","0.00000000"],["79953.70000000","0.00000000"]]}}}
{"rx_ns": 13881396592800, "frame": {"stream":"btcusdt@depth@100ms","data":{"e":"depthUpdate","E":1787650876614,"s":"BTCUSDT","U":99118603081,"u":99118603139,"b":[["79913.00000000","1.67948000"],["79911.82000000","0.03870000"],["79911.81000000","0.00000000"],["79908.98000000","0.00007000"],["79908.42000000","0.00007000"],["79906.05000000","0.00007000"],["79865.00000000","0.00000000"],["71921.70000000","0.00432000"],["63930.40000000","0.00000000"]],"a":[["79913.01000000","1.39446000"],["79913.02000000","0.00090000"],["79913.47000000","0.00007000"],["79913.48000000","0.06138000"],["79914.00000000","0.02449000"],["79914.20000000","0.00007000"],["79914.21000000","0.06131000"],["79915.40000000","0.00007000"],["79915.97000000","0.00007000"],["79915.98000000","0.05615000"],["79915.99000000","0.04675000"],["79916.00000000","0.02421000"],["79916.58000000","0.00000000"],["79919.61000000","0.06117000"],["79919.77000000","0.00933000"],["79921.13000000","0.00685000"],["79954.20000000","0.00000000"]]}}}
{"rx_ns": 13881498827700, "frame": {"stream":"btcusdt@depth@100ms","data":{"e":"depthUpdate","E":1787650876714,"s":"BTCUSDT","U":99118603140,"u":99118603936,"b":[["79913.00000000","0.00000000"],["79912.99000000","0.00000000"],["79912.98000000","0.00000000"],["79912.96000000","0.00000000"],["79912.95000000","0.00000000"],["79912.94000000","0.00000000"],["79912.55000000","0.00000000"],["79912.54000000","0.00000000"],["79912.53000000","0.00000000"],["79912.04000000","0.00000000"],["79911.99000000","0.00000000"],["79911.82000000","0.00000000"],["79911.73000000","0.00000000"],["79911.72000000","0.00000000"],["79911.63000000","0.00000000"],["79911.28000000","0.00000000"],["79911.20000000","0.00000000"],["79910.91000000","0.00000000"],["79910.90000000","0.00000000"],["79910.84000000","0.00000000"],["79910.81000000","0.00000000"],["79910.80000000","0.03197000"],["79910.79000000","0.00077000"],["79910.78000000","0.00048000"],["79910.59000000","0.00000000"],["79910.51000000","0.00007000"],["79910.50000000","0.07902000"],["79910.45000000","0.00007000"],["79910.44000000","0.02536000"],["79910.41000000","0.00000000"],["79910.40000000","0.00014000"],["79910.27000000","0.00014000"],["79910.13000000","0.00014000"],["79910.00000000","0.00000000"],["79909.99000000","0.00021000"],["79909.59000000","0.00028000"],["79909.39000000","0.00000000"],["79909.17000000","0.00007000"],["79908.97000000","0.04138000"],["79908.96000000","0.00000000"],["79908.77000000","0.00000000"],["79908.43000000","0.00007000"],["79908.42000000","1.04939000"],["79908.41000000","0.00000000"],["79908.34000000","0.42248000"],["79908.25000000","0.00000000"],["79908.21000000","0.00000000"],["79908.20000000","0.00007000"],["79908.19000000","0.05337000"],["79908.06000000","0.00007000"],["79907.99000000","0.00000000"],["79907.76000000","0.00014000"],["79907.75000000","0.00000000"],["79907.01000000","0.00000000"],["79906.05000000","0.00000000"],["79906.04000000","0.00000000"],["79906.03000000","0.00000000"],["79906.02000000","0.00000000"],["79905.99000000","0.00718000"],["79905.85000000","0.00000000"],["79905.58000000","0.00007000"],["79905.57000000","0.00007000"],["79905.56000000","0.12535000"],["79905.01000000","0.00000000"],["79904.81000000","0.00013000"],["79904.80000000","0.00000000"],["79904.30000000","0.00000000"],["79904.27000000","0.00000000"],["79904.21000000","0.00000000"],["79904.20000000","0.00007000"],["79904.13000000","0.00000000"],["79904.02000000","0.00000000"],["79904.01000000","0.00007000"],["79904.00000000","1.07353000"],["79903.99000000","0.41748000"],["79903.94000000","0.00000000"],["79903.43000000","0.00047000"],["79903.38000000","0.00000000"],["79903.37000000","0.00007000"],["79902.81000000","0.00008000"],["79902.74000000","0.00000000"],["79902.73000000","0.78636000"],["79901.53000000","0.00007000"],["79901.26000000","0.08576000"],["79900.85000000","0.00000000"],["79900.70000000","0.07000000"],["79900.62000000","0.00000000"],["79900.23000000","0.00000000"],["79900.22000000","0.00190000"],["79899.22000000","0.00000000"],["79898.33000000","0.00625000"],["79898.09000000","0.14758000"],["79898.08000000","0.00000000"],["79897.86000000","0.00153000"],["79896.30000000","0.08000000"],["79896.02000000","0.00625000"],["79895.89000000","0.00000000"],["79895.88000000","0.12516000"],["79894.43000000","0.01050000"],["79894.42000000","0.00000000"],["79894.41000000","0.00000000"],["79894.19000000","0.00000000"],["79894.01000000","0.00000000"],["79892.46000000","0.00000000"],["79892.29000000","0.00000000"],["79891.88000000","0.00000000"],["79890.02000000","0.00000000"],["79890.01000000","0.02207000"],["79890.00000000","1.35217000"],["79889.29000000","0.00625000"],["79887.50000000","0.42933000"],["79886.62000000","0.87670000"],["79886.61000000","0.36091000"],["79886.60000000","0.00000000"],["79882.14000000","0.62589000"],["79882.13000000","0.36586000"],["79882.12000000","0.00000000"],["79881.42000000","0.62607000"],["79878.77000000","0.00000000"],["79877.61000000","0.33809000"],["79873.00000000","0.00000000"],["79872.93000000","0.00014000"],["79872.00000000","0.32407000"],["79871.29000000","0.00000000"],["79870.00000000","0.12791000"],["79869.73000000","0.33813000"],["79869.06000000","0.00007000"],["79868.61000000","0.00007000"],["79864.36000000","1.23989000"],["79864.02000000","0.00000000"],["79857.32000000","0.00400000"],["79842.73000000","2.28962000"],["79837.71000000","0.90940000"],["79830.97000000","0.00000000"],["79815.51000000","0.50517000"],["79789.44000000","0.13992000"],["79762.27000000","0.06646000"],["79758.95000000","0.00000000"],["79752.99000000","0.00202000"],["78714.30000000","0.00000000"],["71921.70000000","0.00000000"],["71919.72000000","0.00016000"],["63930.40000000","0.00000000"]],"a":[["79910.81000000","4.49499000"],["79910.82000000","0.00013000"],["79910.83000000","0.00013000"],["79910.91000000","0.00000000"],["79911.21000000","0.00000000"],["79911.29000000","0.00000000"],["79911.63000000","0.00014000"],["79911.64000000","0.00000000"],["79911.73000000","0.00000000"],["79911.83000000","0.00000000"],["79912.00000000","0.00000000"],["79912.05000000","0.00000000"],["79912.54000000","0.00000000"],["79912.55000000","0.00400000"],["79912.56000000","0.00000000"],["79912.61000000","0.00000000"],["79912.94000000","1.26364000"],["79912.95000000","2.05636000"],["79912.96000000","1.25200000"],["79912.97000000","0.00000000"],["79912.98000000","0.00000000"],["79912.99000000","0.00000000"],["79913.00000000","0.28131000"],["79913.01000000","1.04932000"],["79913.02000000","0.00000000"],["79913.03000000","0.00000000"],["79913.47000000","0.00000000"],["79913.48000000","0.00000000"],["79913.49000000","0.00000000"],["79913.50000000","0.07480000"],["79913.61000000","0.00000000"],["79913.78000000","0.04675000"],["79913.99000000","0.00000000"],["79914.00000000","0.02414000"],["79914.16000000","0.00000000"],["79914.20000000","0.00000000"],["79914.21000000","0.00000000"],["79914.23000000","0.00000000"],["79914.80000000","0.00000000"],["79914.81000000","0.00000000"],["79914.84000000","0.00000000"],["79915.15000000","0.00026000"],["79915.18000000","0.00400000"],["79915.39000000","0.00000000"],["79915.40000000","0.00000000"],["79915.41000000","0.00000000"],["79915.45000000","0.00000000"],["79915.97000000","0.00000000"],["79915.98000000","0.02156000"],["79915.99000000","0.00000000"],["79916.00000000","0.02414000"],["79916.59000000","0.00000000"],["79916.80000000","0.00013000"],["79917.17000000","0.00157000"],["79917.19000000","0.00000000"],["79917.20000000","0.00000000"],["79917.78000000","0.00615000"],["79917.80000000","0.00000000"],["79917.81000000","0.00400000"],["79918.00000000","0.02407000"],["79918.41000000","0.00000000"],["79918.46000000","0.00000000"],["79918.75000000","0.00000000"],["79918.80000000","0.00008000"],["79919.00000000","0.00000000"],["79919.06000000","0.01033000"],["79919.36000000","0.00075000"],["79919.56000000","0.00000000"],["79919.61000000","0.00000000"],["79919.93000000","0.00000000"],["79919.94000000","1.04939000"],["79919.95000000","0.00000000"],["79920.33000000","0.00000000"],["79921.00000000","0.00000000"],["79921.06000000","0.00194000"],["79922.57000000","0.02000000"],["79924.11000000","0.19019000"],["79925.68000000","0.00625000"],["79925.70000000","0.00000000"],["79925.71000000","0.00000000"],["79925.99000000","0.02008000"],["79928.54000000","0.00000000"],["79928.55000000","0.00000000"],["79928.81000000","0.03224000"],["79928.95000000","0.34482000"],["79929.58000000","0.00000000"],["79930.78000000","0.33787000"],["79931.96000000","0.96422000"],["79933.70000000","0.62585000"],["79933.72000000","0.62566000"],["79934.41000000","0.12510000"],["79934.80000000","0.00000000"],["79935.14000000","0.00000000"],["79937.08000000","0.00000000"],["79938.54000000","0.33784000"],["79938.56000000","0.00000000"],["79942.66000000","0.00000000"],["79946.98000000","0.00000000"],["79952.89000000","1.23852000"],["79953.02000000","0.00000000"],["79953.54000000","0.00000000"],["79955.43000000","0.00000000"],["79955.89000000","0.00000000"],["79958.48000000","0.00000000"],["79961.35000000","0.00000000"],["80065.02000000","0.00202000"],["80071.54000000","0.00000000"],["81111.71000000","0.00000000"],["95478.30000000","0.00000000"],["95573.78000000","0.00000000"]]}}}
{"rx_ns": 13881596436500, "frame": {"stream":"btcusdt@depth@100ms","data":{"e":"depthUpdate","E":1787650876814,"s":"BTCUSDT","U":99118603937,"u":99118604058,"b":[["79910.80000000","0.28558000"],["79910.79000000","0.00063000"],["79910.78000000","0.00034000"],["79910.45000000","0.00000000"],["79910.44000000","0.00014000"],["79910.40000000","0.00000000"],["79910.27000000","0.00000000"],["79910.13000000","0.00000000"],["79910.04000000","0.00007000"],["79909.99000000","0.00007000"],["79909.59000000","0.00014000"],["79909.17000000","0.00000000"],["79909.16000000","0.00014000"],["79908.97000000","0.04159000"],["79908.42000000","1.04953000"],["79908.35000000","0.00007000"],["79908.34000000","0.42262000"],["79908.20000000","0.00000000"],["79908.19000000","0.06291000"],["79907.76000000","0.00007000"],["79905.99000000","0.00732000"],["79905.58000000","0.00000000"],["79905.56000000","0.12528000"],["79902.74000000","0.00007000"],["79902.73000000","0.78643000"],["79893.87000000","1.20187000"],["79890.00000000","1.25829000"],["79886.62000000","0.01252000"],["79885.00000000","0.00000000"],["79879.36000000","0.00000000"],["79840.00000000","0.22657000"],["79839.42000000","0.00000000"],["79807.46000000","0.00000000"],["79759.54000000","0.00000000"],["79755.05000000","0.00400000"],["79739.29000000","0.86418000"],["79687.91000000","0.00000000"],["79683.17000000","0.00400000"],["71919.72000000","0.00032000"],["63928.64000000","0.00000000"]],"a":[["79910.81000000","6.37440000"],["79912.96000000","1.00606000"],["79913.00000000","0.28138000"],["79913.01000000","0.84682000"],["79916.00000000","0.02407000"],["79916.67000000","0.00000000"],["79917.28000000","0.00000000"],["79917.78000000","0.00000000"],["79919.06000000","0.00007000"],["79920.00000000","1.12152000"],["79920.34000000","0.00000000"],["79921.06000000","0.00007000"],["79921.62000000","0.00000000"],["79927.09000000","0.09458000"],["79929.09000000","0.10361000"],["79933.71000000","0.00000000"],["79935.71000000","0.00000000"],["79946.10000000","0.00000000"],["79947.03000000","0.53671000"],["79951.00000000","0.01000000"],["79953.00000000","0.00000000"],["79981.60000000","0.00400000"],["79986.08000000","0.00000000"],["80013.57000000","0.00400000"],["80018.06000000","0.00000000"],["80026.97000000","0.01739000"],["80026.98000000","0.05818000"],["80061.54000000","0.00400000"],["80066.02000000","0.00000000"],["80133.48000000","0.00400000"],["80137.98000000","0.00000000"],["81109.48000000","0.00030000"]]}}}
{"rx_ns": 13881707371200, "frame": {"stream":"btcusdt@depth@100ms","data":{"e":"depthUpdate","E":1787650876914,"s":"BTCUSDT","U":99118604059,"u":99118604128,"b":[["79910.80000000","0.27740000"],["79910.79000000","0.00077000"],["79910.78000000","0.00027000"],["79910.50000000","0.07909000"],["79910.44000000","0.00000000"],["79909.59000000","0.00007000"],["79909.53000000","0.00007000"],["79909.52000000","0.01996000"],["79909.16000000","0.00000000"],["79908.34000000","0.42269000"],["79908.24000000","0.02396000"],["79908.19000000","0.06298000"],["79906.96000000","0.02396000"],["79905.56000000","0.12542000"],["79905.27000000","0.03589000"],["79904.02000000","0.00007000"],["79904.01000000","0.44522000"],["79904.00000000","1.07367000"],["79903.99000000","0.41755000"],["79903.78000000","0.00000000"],["79902.73000000","0.78636000"],["79900.99000000","0.07174000"],["79897.78000000","0.00000000"],["79891.19000000","0.49594000"],["79886.62000000","0.00000000"],["79866.60000000","0.99718000"],["79843.62000000","0.03129000"],["71919.72000000","0.00064000"]],"a":[["79910.81000000","6.39819000"],["79912.93000000","0.00007000"],["79912.94000000","1.26371000"],["79912.95000000","2.05643000"],["79912.96000000","0.49450000"],["79912.99000000","0.00007000"],["79913.00000000","0.28145000"],["79913.50000000","0.00007000"],["79914.00000000","0.02421000"],["79914.77000000","0.00678000"],["79916.00000000","0.02414000"],["79916.05000000","0.01138000"],["79917.33000000","0.01357000"],["79918.00000000","0.02414000"],["79918.61000000","0.01357000"],["79929.76000000","0.00000000"]]}}}
{"rx_ns": 13881797695800, "frame": {"stream":"btcusdt@depth20","data":{"lastUpdateId":99118604226,"bids":[["79910.80000000","0.25036000"],["79910.79000000","0.00070000"],["79910.78000000","0.00027000"],["79910.51000000","0.00007000"],["79910.50000000","0.07909000"],["79910.19000000","0.00007000"],["79910.04000000","0.00007000"],["79909.99000000","0.00007000"],["79909.59000000","0.00007000"],["79909.53000000","0.00007000"],["79909.52000000","0.02010000"],["79909.14000000","0.00008000"],["79908.97000000","0.00035000"],["79908.44000000","0.00007000"],["79908.43000000","1.04939000"],["79908.42000000","0.00014000"],["79908.35000000","0.00007000"],["79908.34000000","0.42269000"],["79908.26000000","0.00007000"],["79908.24000000","0.02410000"]],"asks":[["79910.81000000","6.39819000"],["79910.82000000","0.00013000"],["79910.83000000","0.00013000"],["79911.63000000","0.00014000"],["79912.55000000","0.00400000"],["79912.94000000","1.26364000"],["79912.95000000","2.05636000"],["79912.96000000","0.49450000"],["79913.00000000","0.28138000"],["79913.01000000","0.84682000"],["79913.50000000","0.00007000"],["79913.78000000","0.04675000"],["79913.85000000","0.00007000"],["79914.00000000","0.02421000"],["79914.03000000","0.00007000"],["79914.48000000","0.00007000"],["79914.77000000","0.00685000"],["79915.15000000","0.00026000"],["79915.18000000","0.00400000"],["79915.48000000","0.00905000"]]}}}
{"rx_ns": 13881797838100, "frame": {"stream":"btcusdt@depth@100ms","data":{"e":"depthUpdate","E":1787650877014,"s":"BTCUSDT","U":99118604129,"u":99118604226,"b":[["79910.80000000","0.25036000"],["79910.79000000","0.00070000"],["79910.50000000","0.07909000"],["79909.52000000","0.02010000"],["79908.98000000","0.00000000"],["79908.97000000","0.00035000"],["79908.44000000","0.00007000"],["79908.43000000","1.04939000"],["79908.42000000","0.00014000"],["79908.34000000","0.42269000"],["79908.24000000","0.02410000"],["79908.19000000","0.05358000"],["79906.96000000","0.02410000"],["79905.99000000","0.00014000"],["79905.56000000","0.12535000"],["79905.27000000","0.03596000"],["79905.00000000","0.00000000"],["79904.95000000","0.04030000"],["79904.00000000","1.07353000"],["79903.99000000","0.41748000"],["79903.34000000","0.00000000"],["79902.80000000","0.00054000"],["79901.53000000","0.00000000"],["79901.43000000","0.00047000"],["79901.38000000","0.00070000"],["79900.70000000","0.03000000"],["79900.56000000","0.00012000"],["79898.10000000","0.04000000"],["79897.01000000","0.00000000"],["79895.58000000","0.00007000"],["79889.29000000","0.00000000"],["79889.02000000","0.00000000"],["79886.03000000","0.00625000"],["79881.03000000","0.00000000"],["79862.58000000","0.00400000"],["79858.92000000","0.92031000"],["79856.72000000","0.00012000"],["79843.62000000","0.00000000"],["79834.93000000","0.00400000"],["79823.05000000","0.62551000"],["71919.72000000","0.00080000"],["63928.64000000","0.00031000"]],"a":[["79912.93000000","0.00000000"],["79912.94000000","1.26364000"],["79912.95000000","2.05636000"],["79912.99000000","0.00000000"],["79913.00000000","0.28138000"],["79914.77000000","0.00685000"],["79915.48000000","0.00905000"],["79915.98000000","0.03734000"],["79916.05000000","0.01145000"],["79916.75000000","0.04007000"],["79917.08000000","0.00712000"],["79927.56000000","0.00007000"],["79933.92000000","0.00012000"],["79936.13000000","0.00000000"],["79941.34000000","0.00000000"],["79955.97000000","0.00000000"]]}}}
{"rx_ns": 13881900378900, "frame": {"stream":"btcusdt@depth@100ms","data":{"e":"depthUpdate","E":1787650877114,"s":"BTCUSDT","U":99118604227,"u":99118604255,"b":[["79910.80000000","0.25131000"],["79910.50000000","0.07916000"],["79910.19000000","0.00014000"],["79910.18000000","0.02479000"],["79909.52000000","0.02010000"],["79908.97000000","0.00021000"],["79908.43000000","1.04953000"],["79908.42000000","0.00000000"],["79906.96000000","0.02410000"],["79905.56000000","0.12549000"],["79894.81000000","0.00054000"],["79886.82000000","0.00054000"],["79878.83000000","0.00054000"],["79874.78000000","0.02000000"],["79812.32000000","0.00000000"],["79688.21000000","0.00000000"],["79681.02000000","0.00770000"],["71919.72000000","0.00096000"]],"a":[["79951.89000000","0.00007000"],["79956.05000000","0.00007000"]]}}}
{"rx_ns": 13882004586600, "frame": {"stream":"btcusdt@depth@100ms","data":{"e":"depthUpdate","E":1787650877214,"s":"BTCUSDT","U":99118604256,"u":99118604292,"b":[["79910.80000000","0.25168000"],["79910.79000000","0.00077000"],["79910.50000000","0.07916000"],["79910.18000000","0.02493000"],["79908.19000000","0.05365000"],["79907.93000000","0.00007000"],["79907.92000000","0.00000000"],["79906.96000000","0.02417000"],["79906.85000000","0.00007000"],["79905.97000000","0.00668000"],["79905.56000000","0.12535000"],["79905.27000000","0.00007000"],["79902.74000000","0.00000000"],["79900.99000000","0.00000000"],["79874.87000000","0.00400000"],["79810.13000000","0.00025000"],["71919.72000000","0.00112000"],["63928.64000000","0.00000000"]],"a":[["79913.01000000","0.85933000"],["79916.42000000","0.00000000"],["79932.01000000","0.00007000"],["80009.90000000","0.00025000"],["80012.11000000","0.00000000"],["80013.89000000","0.00566000"],["80632.22000000","0.00000000"]]}}}
{"rx_ns": 13882095819700, "frame": {"stream":"btcusdt@depth@100ms","data":{"e":"depthUpdate","E":1787650877314,"s":"BTCUSDT","U":99118604293,"u":99118604337,"b":[["79910.80000000","0.25159000"],["79910.04000000","0.00000000"],["79909.24000000","0.00007000"],["79908.34000000","0.00021000"],["79908.19000000","0.05358000"],["79907.93000000","0.00000000"],["79906.96000000","0.02410000"],["79905.97000000","0.00000000"],["79905.63000000","0.31294000"],["79904.50000000","0.03000000"],["79900.70000000","0.00000000"],["79898.10000000","0.00000000"],["79896.50000000","0.04000000"],["79889.99000000","0.34051000"],["79837.33000000","0.02086000"],["79810.29000000","0.00000000"],["79600.58000000","0.00000000"],["71919.72000000","0.00128000"],["71919.00000000","0.00000000"],["63930.00000000","0.00788000"]],"a":[["79910.81000000","6.40150000"],["79914.76000000","0.00000000"],["79925.49000000","0.03000000"],["79931.71000000","0.35787000"],["79934.20000000","0.12000000"],["79946.93000000","0.00000000"]]}}}
{"rx_ns": 13882198523600, "frame": {"stream":"btcusdt@depth@100ms","data":{"e":"depthUpdate","E":1787650877414,"s":"BTCUSDT","U":99118604338,"u":99118604565,"b":[["79910.80000000","1.67689000"],["79910.79000000","0.00042000"],["79910.18000000","0.02500000"],["79909.70000000","0.00007000"],["79909.69000000","0.00567000"],["79909.56000000","0.00000000"],["79909.52000000","0.02017000"],["79908.94000000","0.00000000"],["79908.45000000","0.00007000"],["79908.44000000","0.33665000"],["79908.43000000","1.04953000"],["79908.35000000","0.00000000"],["79908.34000000","0.00007000"],["79908.20000000","0.00000000"],["79907.76000000","0.00014000"],["79906.98000000","0.00000000"],["79906.96000000","0.02417000"],["79905.99000000","0.00007000"],["79905.66000000","0.00007000"],["79905.65000000","1.16501000"],["79905.64000000","1.87677000"],["79905.63000000","0.31308000"],["79905.57000000","0.00000000"],["79904.96000000","0.00000000"],["79904.95000000","0.04044000"],["79904.77000000","0.03224000"],["79904.02000000","0.00000000"],["79904.01000000","0.00007000"],["79904.00000000","1.07346000"],["79903.99000000","0.41029000"],["79903.63000000","0.00701000"],["79903.37000000","0.00000000"],["79902.73000000","1.12667000"],["79901.43000000","0.00000000"],["79901.38000000","0.00000000"],["79900.56000000","0.00000000"],["79900.01000000","1.87677000"],["79892.01000000","0.36586000"],["79884.30000000","0.02446000"],["79875.00000000","0.70000000"],["79869.06000000","0.00000000"],["79868.61000000","0.00014000"],["79859.95000000","0.00400000"],["79857.32000000","0.00000000"],["79837.33000000","0.00000000"],["79762.17000000","0.00000000"],["79752.99000000","0.00000000"],["79591.12000000","0.00030000"],["78712.13000000","0.00030000"],["73513.51000000","0.00014000"],["71921.69000000","0.00000000"],["71919.72000000","0.00128000"],["63930.00000000","0.01088000"]],"a":[["79910.81000000","2.23209000"],["79911.63000000","0.00007000"],["79912.93000000","0.00000000"],["79912.94000000","0.00000000"],["79912.95000000","0.49312000"],["79912.99000000","0.00007000"],["79913.00000000","0.20645000"],["79914.77000000","0.00685000"],["79915.15000000","0.00000000"],["79915.17000000","0.00048000"],["79915.48000000","0.00000000"],["79915.50000000","0.00014000"],["79915.68000000","0.00926000"],["79916.75000000","0.04007000"],["79917.08000000","0.00000000"],["79917.21000000","0.00008000"],["79917.28000000","0.00703000"],["79919.93000000","1.87677000"],["79919.94000000","0.00000000"],["79919.96000000","0.00000000"],["79919.97000000","0.41454000"],["79919.98000000","0.00000000"],["79922.02000000","0.00190000"],["79924.11000000","0.00000000"],["79924.13000000","0.36586000"],["79925.68000000","0.00000000"],["79926.73000000","0.19019000"],["79926.74000000","1.05339000"],["79926.75000000","0.00000000"],["79928.81000000","0.00000000"],["79928.95000000","0.00000000"],["79928.96000000","0.00000000"],["79929.33000000","0.00625000"],["79929.53000000","0.28802000"],["79930.78000000","0.00000000"],["79931.71000000","0.02000000"],["79931.96000000","0.64897000"],["79933.70000000","0.00000000"],["79933.72000000","0.00000000"],["79934.19000000","0.62587000"],["79941.05000000","0.42932000"],["79941.62000000","0.00400000"],["79947.65000000","1.46693000"],["79947.81000000","0.33780000"],["79954.01000000","0.33777000"],["79954.20000000","0.00000000"],["79982.26000000","1.23807000"],["80013.89000000","0.00010000"],["80065.02000000","0.00000000"],["80231.03000000","0.02752000"]]}}}
{"rx_ns": 13882300822300, "frame": {"stream":"btcusdt@depth@100ms","data":{"e":"depthUpdate","E":1787650877514,"s":"BTCUSDT","U":99118604566,"u":99118604631,"b":[["79910.80000000","1.69729000"],["79910.79000000","0.00063000"],["79910.18000000","0.02500000"],["79909.86000000","0.00007000"],["79909.85000000","0.05007000"],["79909.81000000","0.00007000"],["79909.80000000","0.05000000"],["79909.70000000","0.00000000"],["79909.69000000","0.00581000"],["79909.52000000","0.02017000"],["79909.41000000","0.00901000"],["79908.44000000","0.33672000"],["79906.96000000","0.02410000"],["79906.71000000","0.00718000"],["79905.63000000","0.31294000"],["79902.74000000","0.00000000"],["79896.23000000","0.05683000"],["79774.69000000","0.00000000"],["71919.72000000","0.00144000"],["63930.00000000","0.00788000"],["63928.64000000","0.00031000"]],"a":[["79910.81000000","2.28229000"],["79912.94000000","0.00007000"],["79919.92000000","0.97532000"],["79919.97000000","0.00000000"],["79940.00000000","0.33685000"]]}}}
{"rx_ns": 13882403200100, "frame": {"stream":"btcusdt@depth@100ms","data":{"e":"depthUpdate","E":1787650877614,"s":"BTCUSDT","U":99118604632,"u":99118604704,"b":[["79910.80000000","1.68736000"],["79910.79000000","0.00076000"],["79910.78000000","0.00040000"],["79910.18000000","0.02507000"],["79910.06000000","0.00007000"],["79910.05000000","0.05007000"],["79910.01000000","0.00007000"],["79910.00000000","0.05000000"],["79909.86000000","0.00000000"],["79909.85000000","0.00014000"],["79909.81000000","0.00000000"],["79909.80000000","0.00007000"],["79909.69000000","0.00588000"],["79909.57000000","0.00007000"],["79909.56000000","0.04423000"],["79909.52000000","0.02017000"],["79909.41000000","0.00007000"],["79909.06000000","0.00000000"],["79908.43000000","1.04939000"],["79908.24000000","0.02396000"],["79908.19000000","0.05344000"],["79905.56000000","0.12521000"],["79904.20000000","0.00000000"],["79904.01000000","0.00000000"],["79900.22000000","0.00000000"],["79834.93000000","0.00000000"],["79802.98000000","0.00400000"],["79773.23000000","0.04532000"],["79739.29000000","0.00000000"],["79722.28000000","0.00000000"],["79683.67000000","0.00770000"],["79681.02000000","0.00000000"],["71919.72000000","0.00144000"],["63929.00000000","0.00060000"],["63928.64000000","0.00000000"]],"a":[["79910.81000000","1.88229000"],["79912.89000000","0.00007000"],["79912.90000000","0.14293000"],["79925.58000000","0.02000000"]]}}}
{"rx_ns": 13882495673900, "frame": {"stream":"btcusdt@depth@100ms","data":{"e":"depthUpdate","E":1787650877714,"s":"BTCUSDT","U":99118604705,"u":99118604768,"b":[["79910.80000000","1.68743000"],["79910.79000000","0.00076000"],["79910.41000000","0.03357000"],["79910.18000000","0.02507000"],["79910.06000000","0.00000000"],["79910.05000000","0.00014000"],["79910.01000000","0.00000000"],["79910.00000000","0.00617000"],["79909.85000000","0.00000000"],["79909.80000000","0.00000000"],["79909.71000000","0.00007000"],["79909.70000000","0.05000000"],["79909.69000000","0.00021000"],["79909.66000000","0.00007000"],["79909.65000000","0.05000000"],["79909.56000000","0.00007000"],["79909.52000000","0.02017000"],["79909.41000000","0.00000000"],["79909.04000000","0.00944000"],["79904.01000000","0.00000000"],["79890.00000000","1.35217000"],["71919.72000000","0.00160000"],["63928.64000000","0.00000000"]],"a":[["79910.81000000","1.88236000"],["79912.06000000","0.00007000"],["79912.07000000","0.04676000"],["79912.89000000","0.00000000"],["79912.90000000","0.00000000"],["79915.69000000","0.00026000"],["79920.01000000","0.00007000"]]}}}
{"rx_ns": 13882604389500, "frame": {"stream":"btcusdt@depth@100ms","data":{"e":"depthUpdate","E":1787650877814,"s":"BTCUSDT","U":99118604769,"u":99118604830,"b":[["79910.80000000","1.66837000"],["79910.79000000","0.00055000"],["79910.50000000","0.07916000"],["79910.42000000","0.00007000"],["79910.41000000","0.03364000"],["79910.18000000","0.02507000"],["79910.05000000","0.00007000"],["79910.00000000","0.00617000"],["79909.70000000","0.05007000"],["79909.69000000","0.00007000"],["79909.65000000","0.05007000"],["79909.57000000","0.00000000"],["79909.56000000","0.00000000"],["79909.52000000","0.02017000"],["79909.04000000","0.00951000"],["79908.44000000","0.33665000"],["79905.89000000","0.00661000"],["79893.41000000","0.33803000"],["79869.73000000","0.00000000"],["79869.36000000","0.00400000"],["79859.95000000","0.00000000"],["79834.16000000","0.00400000"],["63929.00000000","0.00060000"],["63928.64000000","0.00000000"]],"a":[["79910.81000000","1.88236000"],["79918.00000000","0.02407000"],["79919.06000000","0.00000000"],["79920.00000000","1.02767000"],["79922.57000000","0.00000000"],["79924.97000000","0.98628000"],["79926.17000000","0.02000000"],["79933.75000000","0.00000000"],["79954.20000000","0.00007000"],["80017.81000000","0.00000000"],["81109.48000000","0.00030000"]]}}}
{"rx_ns": 13882697573900, "frame": {"stream":"btcusdt@depth@100ms","data":{"e":"depthUpdate","E":1787650877914,"s":"BTCUSDT","U":99118604831,"u":99118604859,"b":[["79910.80000000","1.66848000"],["79910.79000000","0.00069000"],["79909.71000000","0.00000000"],["79909.70000000","0.00007000"],["79909.66000000","0.00000000"],["79909.65000000","0.00014000"],["79909.61000000","0.00007000"],["79909.60000000","0.05000000"],["79908.44000000","0.33672000"],["79906.71000000","0.00725000"],["79904.95000000","0.04037000"],["79794.28000000","0.00253000"],["79793.48000000","0.00000000"],["71919.72000000","0.00184000"]],"a":[["79910.81000000","1.88202000"],["79912.06000000","0.00000000"],["79912.07000000","0.00000000"],["79919.36000000","0.00000000"],["79920.16000000","0.00075000"],["80001.03000000","0.00573000"],["80010.21000000","0.01270000"],["80028.20000000","0.01270000"]]}}}
{"rx_ns": 13882798327800, "frame": {"stream":"btcusdt@depth20","data":{"lastUpdateId":99118604897,"bids":[["79910.80000000","1.66834000"],["79910.79000000","0.00055000"],["79910.78000000","0.00040000"],["79910.51000000","0.00007000"],["79910.50000000","0.07916000"],["79910.42000000","0.00007000"],["79910.41000000","0.03364000"],["79910.19000000","0.00014000"],["79910.18000000","0.03067000"],["79910.05000000","0.00007000"],["79910.00000000","0.00007000"],["79909.99000000","0.00007000"],["79909.60000000","0.00007000"],["79909.59000000","0.00007000"],["79909.53000000","0.00007000"],["79909.52000000","0.02017000"],["79909.24000000","0.00007000"],["79909.14000000","0.00008000"],["79909.04000000","0.00951000"],["79908.97000000","0.00021000"]],"asks":[["79910.81000000","1.88202000"],["79910.82000000","0.00013000"],["79910.83000000","0.00013000"],["79911.63000000","0.00007000"],["79912.55000000","0.00400000"],["79912.94000000","0.00007000"],["79912.95000000","0.49312000"],["79912.96000000","0.49450000"],["79912.99000000","0.00007000"],["79913.00000000","0.20645000"],["79913.01000000","0.85933000"],["79913.50000000","0.00007000"],["79913.78000000","0.04675000"],["79913.85000000","0.00007000"],["79914.00000000","0.02421000"],["79914.03000000","0.00007000"],["79914.48000000","0.00007000"],["79914.77000000","0.00685000"],["79915.17000000","0.00048000"],["79915.18000000","0.00400000"]]}}}
{"rx_ns": 13882798457800, "frame": {"stream":"btcusdt@depth@100ms","data":{"e":"depthUpdate","E":1787650878014,"s":"BTCUSDT","U":99118604860,"u":99118604897,"b":[["79910.80000000","1.66834000"],["79910.79000000","0.00055000"],["79910.18000000","0.03067000"],["79910.00000000","0.00007000"],["79909.70000000","0.00000000"],["79909.69000000","0.00000000"],["79909.65000000","0.00000000"],["79909.61000000","0.00000000"],["79909.60000000","0.00007000"],["79908.44000000","0.33679000"],["79904.01000000","0.00007000"],["79895.58000000","0.00007000"],["79872.28000000","0.02400000"],["79857.99000000","0.00000000"],["73513.51000000","0.00000000"],["71919.72000000","0.00184000"],["63928.64000000","0.00031000"]],"a":[["79910.81000000","1.88202000"],["79927.56000000","0.00007000"]]}}}
{"rx_ns": 13882901721200, "frame": {"stream":"btcusdt@depth@100ms","data":{"e":"depthUpdate","E":1787650878114,"s":"BTCUSDT","U":99118604898,"u":99118604935,"b":[["79910.80000000","1.66841000"],["79910.79000000","0.00062000"],["79910.18000000","0.03060000"],["79910.05000000","0.00000000"],["79910.00000000","0.00000000"],["79909.60000000","0.00000000"],["79908.43000000","1.04946000"],["79908.24000000","0.02403000"],["79898.09000000","0.30244000"],["79896.12000000","0.37557000"],["79842.73000000","1.04939000"],["79839.03000000","0.02086000"],["79838.12000000","0.00400000"],["79834.16000000","0.00000000"],["79688.21000000","0.00770000"],["79683.67000000","0.00000000"],["71919.72000000","0.00200000"]],"a":[["79912.96000000","0.49387000"],["79913.01000000","0.85940000"],["79913.36000000","0.00007000"],["79913.37000000","0.12050000"],["79914.77000000","0.00678000"],["79915.68000000","0.00000000"],["79915.70000000","0.00000000"],["79916.75000000","0.04000000"],["79917.28000000","0.00000000"],["79918.69000000","0.00689000"],["79947.74000000","0.00007000"],["79973.83000000","1.23826000"],["80057.81000000","0.00000000"]]}}}
{"rx_ns": 13883002023400, "frame": {"stream":"btcusdt@depth@100ms","data":{"e":"depthUpdate","E":1787650878214,"s":"BTCUSDT","U":99118604936,"u":99118604951,"b":[["79910.80000000","1.66858000"],["79910.79000000","0.00069000"],["79909.04000000","0.00958000"],["79908.81000000","0.00716000"],["79839.03000000","0.00000000"],["79838.12000000","0.00400000"],["79332.23000000","0.01516000"],["78956.79000000","0.00000000"],["71919.72000000","0.00200000"],["63928.64000000","0.00000000"]],"a":[["79910.81000000","1.88185000"],["79913.01000000","0.85840000"],["79954.20000000","0.00000000"],["80630.00000000","0.00060000"]]}}}
{"rx_ns": 13883098767200, "frame": {"stream":"btcusdt@depth@100ms","data":{"e":"depthUpdate","E":1787650878314,"s":"BTCUSDT","U":99118604952,"u":99118604981,"b":[["79910.80000000","1.66886000"],["79910.79000000","0.00076000"],["79909.04000000","0.00014000"],["79908.81000000","0.00007000"],["79908.24000000","0.02396000"],["79906.71000000","0.00007000"],["79906.44000000","0.00711000"],["79884.27000000","0.00000000"],["79880.00000000","0.82041000"],["79874.87000000","0.00000000"],["79831.80000000","0.20250000"],["79802.98000000","0.00000000"],["79755.05000000","0.00000000"],["79683.17000000","0.00000000"],["71919.72000000","0.00216000"],["71919.00000000","0.00020000"],["63930.00000000","0.00788000"]],"a":[["79918.69000000","0.00000000"],["79947.00000000","0.70000000"],["79948.00000000","0.22650000"],["80197.51000000","0.00000000"]]}}}
{"rx_ns": 13883202696900, "frame": {"stream":"btcusdt@depth@100ms","data":{"e":"depthUpdate","E":1787650878414,"s":"BTCUSDT","U":99118604982,"u":99118605033,"b":[["79910.80000000","1.66844000"],["79910.79000000","0.00055000"],["79909.52000000","0.02010000"],["79909.04000000","0.00000000"],["79908.81000000","0.00000000"],["79908.24000000","0.02403000"],["79908.19000000","0.05351000"],["79906.96000000","0.02417000"],["79878.09000000","0.00400000"],["79839.03000000","0.00000000"],["79803.84000000","0.00007000"],["78712.13000000","0.00030000"],["71919.72000000","0.00216000"],["71919.00000000","0.00000000"]],"a":[["79910.81000000","1.63165000"],["79910.82000000","0.00020000"],["79912.95000000","0.49319000"],["79912.96000000","0.49394000"],["79913.00000000","0.20652000"],["79913.01000000","0.85847000"],["79913.37000000","0.12057000"],["79913.78000000","0.04682000"],["79914.00000000","0.02428000"],["79914.77000000","0.00685000"],["79919.77000000","0.00000000"],["79921.13000000","0.00000000"],["79921.68000000","0.00691000"],["80188.07000000","0.00033000"]]}}}
{"rx_ns": 13883296092900, "frame": {"stream":"btcusdt@depth@100ms","data":{"e":"depthUpdate","E":1787650878514,"s":"BTCUSDT","U":99118605034,"u":99118605062,"b":[["79910.80000000","1.66851000"],["79910.50000000","0.07923000"],["79910.41000000","0.03371000"],["79910.18000000","0.03074000"],["79909.76000000","0.00000000"],["79909.75000000","0.00007000"],["79909.71000000","0.00007000"],["79909.70000000","0.05000000"],["79909.52000000","0.02017000"],["79908.44000000","0.33686000"],["79908.43000000","1.04953000"],["79908.24000000","0.02410000"],["79904.01000000","0.00000000"],["71919.72000000","0.00232000"],["63928.64000000","0.00031000"]],"a":[["79910.81000000","1.63172000"],["79910.82000000","0.00027000"],["79912.95000000","0.49326000"],["79912.96000000","0.49401000"],["79913.00000000","0.20659000"],["79913.01000000","0.85854000"],["79913.37000000","0.12064000"],["79913.78000000","0.04689000"],["79914.00000000","0.02435000"],["79914.77000000","0.00692000"]]}}}
{"rx_ns": 13883395553000, "frame": {"stream":"btcusdt@depth@100ms","data":{"e":"depthUpdate","E":1787650878614,"s":"BTCUSDT","U":99118605063,"u":99118605088,"b":[["79910.80000000","1.66858000"],["79910.79000000","0.00062000"],["79910.18000000","0.03074000"],["79909.76000000","0.00007000"],["79909.75000000","0.05007000"],["79909.70000000","0.05007000"],["79909.65000000","0.00000000"],["79908.19000000","0.05344000"],["79886.62000000","0.56960000"],["79839.03000000","0.02086000"],["79686.38000000","0.00400000"],["71919.72000000","0.00248000"],["63928.64000000","0.00000000"]],"a":[["79915.98000000","0.07246000"],["79916.75000000","0.04007000"],["79917.01000000","0.00007000"],["79917.02000000","0.12522000"],["79919.84000000","0.00928000"]]}}}
{"rx_ns": 13883505278200, "frame": {"stream":"btcusdt@depth@100ms","data":{"e":"depthUpdate","E":1787650878714,"s":"BTCUSDT","U":99118605089,"u":99118605206,"b":[["79910.80000000","1.75855000"],["79910.79000000","0.00027000"],["79910.51000000","0.06283000"],["79910.30000000","0.03224000"],["79910.18000000","0.03074000"],["79909.80000000","0.05000000"],["79909.75000000","0.05021000"],["79909.71000000","0.00000000"],["79909.70000000","0.00014000"],["79909.56000000","0.06276000"],["79909.55000000","0.00026000"],["79909.15000000","0.00925000"],["79908.94000000","0.06276000"],["79908.45000000","0.06283000"],["79908.24000000","0.02396000"],["79908.17000000","0.00000000"],["79906.97000000","0.00625000"],["79905.66000000","0.00007000"],["79905.65000000","1.16501000"],["79898.33000000","0.00000000"],["79892.66000000","0.33803000"],["79882.77000000","0.09356000"],["79877.61000000","0.00000000"],["79839.03000000","0.00000000"],["79830.53000000","0.11885000"],["79695.76000000","0.00380000"],["79694.95000000","0.00000000"],["71919.72000000","0.00224000"],["71919.71000000","0.00008000"],["63928.64000000","0.00000000"]],"a":[["79910.81000000","0.81768000"],["79910.82000000","0.00055000"],["79912.95000000","0.00021000"],["79912.96000000","0.29265000"],["79912.99000000","0.00000000"],["79913.00000000","0.00028000"],["79913.01000000","0.65869000"],["79913.37000000","0.00014000"],["79915.17000000","0.00000000"],["79915.69000000","0.00000000"],["79916.35000000","0.00000000"],["79918.35000000","0.00000000"],["79919.84000000","0.00000000"],["79919.93000000","0.00000000"],["79920.36000000","0.00050000"],["79921.68000000","0.00000000"],["79921.95000000","0.00704000"],["79925.49000000","0.00000000"],["79926.72000000","2.93416000"],["79926.73000000","0.00000000"],["79926.74000000","0.00000000"],["79926.76000000","0.00000000"],["79927.29000000","0.03000000"],["79929.33000000","0.00000000"],["79929.53000000","0.00000000"],["79930.99000000","1.04939000"],["79931.00000000","0.00000000"],["79931.75000000","0.19019000"],["79931.96000000","0.64497000"],["79932.65000000","0.00625000"],["79934.19000000","1.06111000"],["79941.05000000","0.00000000"],["79942.82000000","0.00000000"],["79945.96000000","0.42929000"],["79947.03000000","0.02431000"],["79952.89000000","0.00000000"],["79954.20000000","0.00007000"],["79958.42000000","0.00000000"],["79961.48000000","1.23839000"],["79963.73000000","0.00000000"],["79964.53000000","0.00380000"],["79971.67000000","0.00000000"]]}}}
{"rx_ns": 13883599380300, "frame": {"stream":"btcusdt@depth@100ms","data":{"e":"depthUpdate","E":1787650878814,"s":"BTCUSDT","U":99118605207,"u":99118605401,"b":[["79910.80000000","1.80579000"],["79910.52000000","0.00007000"],["79910.51000000","0.06297000"],["79910.41000000","0.03378000"],["79910.31000000","0.00007000"],["79910.30000000","0.03238000"],["79910.19000000","0.00608000"],["79910.18000000","0.02507000"],["79909.81000000","0.00007000"],["79909.80000000","0.05014000"],["79909.76000000","0.00000000"],["79909.75000000","0.05021000"],["79909.70000000","0.00000000"],["79909.57000000","0.00000000"],["79909.53000000","0.00000000"],["79909.52000000","0.02010000"],["79909.15000000","0.00932000"],["79908.95000000","0.00000000"],["79908.94000000","0.06283000"],["79908.45000000","0.06276000"],["79908.44000000","0.33665000"],["79908.43000000","1.04939000"],["79908.19000000","0.05351000"],["79905.66000000","0.00000000"],["79905.65000000","1.16494000"],["79905.56000000","0.12514000"],["79905.27000000","0.00000000"],["79904.95000000","0.00000000"],["79903.43000000","0.00000000"],["79900.02000000","0.36600000"],["79896.02000000","0.00000000"],["79890.00000000","1.35468000"],["79888.35000000","0.02407000"],["79884.30000000","0.00000000"],["79879.44000000","0.00000000"],["79864.00000000","0.02800000"],["79862.58000000","0.00000000"],["79806.19000000","0.00400000"],["71919.72000000","0.00256000"]],"a":[["79910.81000000","0.30293000"],["79910.82000000","0.00055000"],["79912.55000000","0.00000000"],["79912.94000000","0.00000000"],["79912.95000000","0.00000000"],["79912.96000000","0.00021000"],["79913.00000000","0.00014000"],["79913.01000000","0.33260000"],["79913.36000000","0.00000000"],["79913.37000000","0.00000000"],["79913.77000000","0.00007000"],["79913.99000000","0.00007000"],["79914.77000000","0.00699000"],["79915.50000000","0.00007000"],["79915.76000000","0.00014000"],["79915.77000000","0.05946000"],["79915.96000000","0.00007000"],["79915.97000000","0.06283000"],["79915.98000000","0.22117000"],["79915.99000000","0.00000000"],["79916.00000000","0.02428000"],["79916.05000000","0.01159000"],["79916.74000000","0.00007000"],["79916.75000000","0.04007000"],["79917.00000000","0.00007000"],["79917.01000000","0.06276000"],["79917.02000000","0.00000000"],["79917.17000000","0.00000000"],["79917.33000000","0.01371000"],["79917.39000000","0.00007000"],["79917.40000000","0.06283000"],["79917.41000000","0.42248000"],["79918.86000000","0.00000000"],["79918.87000000","0.06276000"],["79919.49000000","0.06276000"],["79919.90000000","0.00000000"],["79919.91000000","0.06276000"],["79919.92000000","0.38157000"],["79919.99000000","0.00000000"],["79920.11000000","0.00070000"],["79921.95000000","0.00000000"],["79922.46000000","0.00048000"],["79922.88000000","0.00048000"],["79926.46000000","0.00157000"],["79926.72000000","1.88477000"],["79930.00000000","0.02400000"],["79931.96000000","0.89763000"],["79934.19000000","0.43524000"],["79937.33000000","0.00000000"],["79937.97000000","0.00000000"],["79938.53000000","0.62584000"],["79939.25000000","0.02479000"],["79940.00000000","0.33434000"],["79951.34000000","1.20181000"],["79951.62000000","0.72652000"],["79952.67000000","0.33778000"],["79960.48000000","0.00400000"],["81109.48000000","0.00030000"]]}}}
{"rx_ns": 13883702365500, "frame": {"stream":"btcusdt@depth@100ms","data":{"e":"depthUpdate","E":1787650878914,"s":"BTCUSDT","U":99118605402,"u":99118605488,"b":[["79910.80000000","1.80572000"],["79910.71000000","0.00007000"],["79910.70000000","0.05000000"],["79910.66000000","0.00007000"],["79910.65000000","0.05000000"],["79910.30000000","0.03238000"],["79910.19000000","0.00622000"],["79909.81000000","0.00000000"],["79909.80000000","0.00014000"],["79909.76000000","0.00000000"],["79909.75000000","0.00021000"],["79909.57000000","0.00007000"],["79909.55000000","0.00000000"],["79908.95000000","0.00007000"],["79908.94000000","0.06290000"],["79908.51000000","0.00700000"],["79908.06000000","0.00000000"],["79905.99000000","0.00000000"],["79905.91000000","0.00153000"],["79897.86000000","0.00000000"],["79837.67000000","0.00626000"],["79824.68000000","0.00000000"],["79761.86000000","0.00202000"],["71919.72000000","0.00256000"],["63930.00000000","0.01088000"],["63928.64000000","0.00000000"]],"a":[["79910.81000000","0.33062000"],["79912.96000000","0.00007000"],["79913.00000000","0.06038000"],["79914.53000000","0.06276000"],["79914.77000000","0.00699000"],["79915.14000000","0.00007000"],["79915.15000000","0.06276000"],["79915.34000000","0.00026000"],["79915.77000000","0.05960000"],["79915.97000000","0.06297000"],["79916.05000000","0.01145000"],["79916.74000000","0.00000000"],["79916.75000000","0.00007000"],["79920.06000000","0.00000000"],["79920.11000000","0.00000000"],["79920.30000000","0.00047000"],["79920.38000000","0.00070000"],["79924.97000000","0.71315000"],["79926.71000000","1.04939000"],["79946.91000000","0.51316000"],["79947.33000000","0.00022000"],["79971.52000000","1.02683000"],["80074.51000000","0.00202000"]]}}}
{"rx_ns": 13883804379600, "frame": {"stream":"btcusdt@depth20","data":{"lastUpdateId":99118605592,"bids":[["79910.80000000","1.80429000"],["79910.79000000","0.00027000"],["79910.78000000","0.00040000"],["79910.70000000","0.00021000"],["79910.68000000","0.00717000"],["79910.65000000","0.00014000"],["79910.52000000","0.00007000"],["79910.51000000","0.06297000"],["79910.50000000","0.07923000"],["79910.42000000","0.00007000"],["79910.41000000","0.03378000"],["79910.31000000","0.00007000"],["79910.30000000","0.03238000"],["79910.19000000","0.00622000"],["79910.18000000","0.02486000"],["79909.99000000","0.00007000"],["79909.75000000","0.00007000"],["79909.59000000","0.00007000"],["79909.57000000","0.00007000"],["79909.56000000","0.06276000"]],"asks":[["79910.81000000","0.33124000"],["79910.82000000","0.00062000"],["79910.83000000","0.00013000"],["79911.63000000","0.00007000"],["79912.66000000","0.00007000"],["79912.67000000","0.06276000"],["79912.96000000","0.00007000"],["79912.99000000","0.00007000"],["79913.00000000","0.06052000"],["79913.01000000","0.33260000"],["79913.50000000","0.00007000"],["79913.77000000","0.00007000"],["79913.78000000","0.04689000"],["79913.85000000","0.00007000"],["79913.99000000","0.00007000"],["79914.00000000","0.02442000"],["79914.03000000","0.00007000"],["79914.48000000","0.00007000"],["79914.52000000","0.00007000"],["79914.53000000","0.06290000"]]}}}
{"rx_ns": 13883804520100, "frame": {"stream":"btcusdt@depth@100ms","data":{"e":"depthUpdate","E":1787650879014,"s":"BTCUSDT","U":99118605489,"u":99118605592,"b":[["79910.80000000","1.80429000"],["79910.71000000","0.00000000"],["79910.70000000","0.00021000"],["79910.68000000","0.00717000"],["79910.66000000","0.00000000"],["79910.65000000","0.00014000"],["79910.19000000","0.00622000"],["79910.18000000","0.02486000"],["79909.80000000","0.00000000"],["79909.75000000","0.00007000"],["79909.57000000","0.00007000"],["79909.53000000","0.00007000"],["79908.97000000","0.00014000"],["79908.95000000","0.00007000"],["79908.46000000","0.00007000"],["79906.96000000","0.02410000"],["79906.71000000","0.00000000"],["79905.89000000","0.00694000"],["79895.89000000","0.25422000"],["79895.58000000","0.00007000"],["79892.67000000","0.62584000"],["79886.61000000","0.00000000"],["79882.14000000","0.00000000"],["79825.33000000","0.00000000"],["79773.23000000","0.00000000"],["79758.27000000","0.00400000"],["71919.72000000","0.00272000"],["63930.00000000","0.00788000"],["63928.64000000","0.00031000"]],"a":[["79910.81000000","0.33124000"],["79910.82000000","0.00062000"],["79912.66000000","0.00007000"],["79912.67000000","0.06276000"],["79912.99000000","0.00007000"],["79913.00000000","0.06052000"],["79914.00000000","0.02442000"],["79914.52000000","0.00007000"],["79914.53000000","0.06290000"],["79914.77000000","0.00706000"],["79915.15000000","0.06290000"],["79915.76000000","0.00014000"],["79915.96000000","0.00007000"],["79915.97000000","0.06283000"],["79915.98000000","0.22103000"],["79916.00000000","0.02414000"],["79916.36000000","0.15939000"],["79917.00000000","0.00000000"],["79917.39000000","0.00000000"],["79917.40000000","0.06276000"],["79920.30000000","0.00000000"],["79927.56000000","0.00007000"],["79950.00000000","0.12761000"],["79954.55000000","0.00000000"],["79958.95000000","0.09591000"],["80014.39000000","0.00000000"]]}}}
{"rx_ns": 13883914161500, "frame": {"stream":"btcusdt@depth@100ms","data":{"e":"depthUpdate","E":1787650879114,"s":"BTCUSDT","U":99118605593,"u":99118605640,"b":[["79910.80000000","1.80436000"],["79910.70000000","0.00000000"],["79910.68000000","0.00731000"],["79910.65000000","0.00000000"],["79910.50000000","0.08472000"],["79910.19000000","0.00028000"],["79896.23000000","0.00000000"],["79830.97000000","0.62553000"],["79823.05000000","0.00000000"],["79773.97000000","0.04558000"],["79758.27000000","0.00000000"],["79733.57000000","0.00000000"],["79700.91000000","0.00793000"],["79688.21000000","0.00000000"]],"a":[["79910.81000000","0.33200000"],["79910.82000000","0.00069000"],["79912.67000000","0.06290000"],["79915.77000000","0.05946000"],["79920.05000000","0.00000000"],["79920.38000000","0.00000000"],["79941.62000000","0.00000000"],["79981.60000000","0.00000000"],["80012.00000000","0.63103000"],["80013.11000000","0.00000000"],["80013.57000000","0.00000000"],["80013.67000000","0.02804000"],["80061.54000000","0.00000000"],["80133.48000000","0.00000000"],["80264.74000000","0.00018000"]]}}}
{"rx_ns": 13883995594500, "frame": {"stream":"btcusdt@depth@100ms","data":{"e":"depthUpdate","E":1787650879214,"s":"BTCUSDT","U":99118605641,"u":99118605657,"b":[["79910.80000000","1.79811000"],["79910.30000000","0.03238000"],["79910.19000000","0.00014000"],["79910.18000000","0.02500000"],["79908.19000000","0.05358000"],["79906.98000000","0.00625000"],["71919.72000000","0.00288000"],["63928.64000000","0.00000000"]],"a":[["79941.50000000","0.00007000"],["80016.79000000","0.00400000"],["80111.18000000","0.00007000"]]}}}
{"rx_ns": 13884102370900, "frame": {"stream":"btcusdt@depth@100ms","data":{"e":"depthUpdate","E":1787650879314,"s":"BTCUSDT","U":99118605658,"u":99118605706,"b":[["79909.53000000","0.00007000"],["79908.95000000","0.00007000"],["79908.46000000","0.00007000"],["71919.72000000","0.00288000"],["63929.00000000","0.00060000"]],"a":[["79910.81000000","0.30272000"],["79910.82000000","0.00062000"],["79912.99000000","0.00000000"],["79913.00000000","0.00028000"],["79914.52000000","0.00000000"],["79914.53000000","0.00014000"],["79915.96000000","0.00007000"],["79915.97000000","0.06283000"],["79915.98000000","0.15364000"],["79916.05000000","0.01138000"],["79916.35000000","0.00000000"],["79916.36000000","0.00014000"],["79916.75000000","0.00000000"],["79917.01000000","0.00000000"],["79917.33000000","0.01364000"],["79917.40000000","0.00007000"],["79918.87000000","0.00000000"],["79919.49000000","0.06276000"],["79982.09000000","0.00000000"],["80096.27000000","0.02500000"]]}}}
{"rx_ns": 13884196861900, "frame": {"stream":"btcusdt@depth@100ms","data":{"e":"depthUpdate","E":1787650879414,"s":"BTCUSDT","U":99118605707,"u":99118605744,"b":[["79910.50000000","0.07923000"],["79910.41000000","0.04029000"],["79900.90000000","0.24847000"],["79843.32000000","0.02086000"],["79782.94000000","0.00015000"],["78712.13000000","0.00030000"],["71919.72000000","0.00304000"],["71919.00000000","0.00000000"]],"a":[["79910.81000000","0.30272000"],["79910.82000000","0.00055000"],["79912.67000000","0.06290000"],["79913.00000000","0.00014000"],["79914.00000000","0.02428000"],["79914.53000000","0.00000000"],["79915.77000000","0.05960000"],["79915.97000000","0.06290000"],["79915.98000000","0.00000000"],["79919.48000000","0.00007000"],["79920.26000000","0.00047000"],["79984.81000000","0.00400000"]]}}}
{"rx_ns": 13884308078600, "frame": {"stream":"btcusdt@depth@100ms","data":{"e":"depthUpdate","E":1787650879514,"s":"BTCUSDT","U":99118605745,"u":99118605764,"b":[["79910.80000000","1.84811000"],["79910.76000000","0.00007000"],["79910.75000000","0.05000000"],["79896.97000000","0.00625000"],["79886.03000000","0.00000000"],["79843.32000000","0.00000000"],["79700.91000000","0.00023000"],["79700.01000000","0.00770000"],["71919.72000000","0.00304000"],["63928.64000000","0.00031000"]],"a":[["79915.97000000","0.06290000"],["79917.01000000","0.06276000"],["79917.40000000","0.06283000"],["79918.25000000","0.06276000"],["79918.87000000","0.06276000"],["79919.62000000","0.14869000"]]}}}
{"rx_ns": 13884396147200, "frame": {"stream":"btcusdt@depth@100ms","data":{"e":"depthUpdate","E":1787650879614,"s":"BTCUSDT","U":99118605765,"u":99118605830,"b":[["79910.80000000","1.84641000"],["79910.75000000","0.05014000"],["79910.52000000","0.00000000"],["79910.51000000","0.00021000"],["79909.57000000","0.00000000"],["79909.56000000","0.00014000"],["79909.53000000","0.00007000"],["79908.95000000","0.00000000"],["79908.46000000","0.00000000"],["79879.25000000","0.22593000"],["79758.27000000","0.00400000"],["79743.04000000","0.00015000"],["71919.72000000","0.00320000"],["71919.71000000","0.00000000"],["63928.64000000","0.00000000"]],"a":[["79910.81000000","0.33063000"],["79912.99000000","0.00007000"],["79913.00000000","0.06290000"],["79914.00000000","0.02435000"],["79914.53000000","0.06276000"],["79915.14000000","0.00000000"],["79915.76000000","0.00007000"],["79915.96000000","0.00000000"],["79916.05000000","0.01152000"],["79916.99000000","0.00000000"],["79917.00000000","0.28093000"],["79917.33000000","0.01371000"],["79917.39000000","0.00000000"],["79917.40000000","0.06276000"],["79919.17000000","0.00938000"],["79919.48000000","0.00000000"],["79920.26000000","0.00000000"],["79920.59000000","0.00719000"],["79922.99000000","0.00686000"]]}}}
{"rx_ns": 13884496844000, "frame": {"stream":"btcusdt@depth@100ms","data":{"e":"depthUpdate","E":1787650879714,"s":"BTCUSDT","U":99118605831,"u":99118605879,"b":[["79910.80000000","1.84641000"],["79910.68000000","0.00731000"],["79910.51000000","0.00007000"],["79910.18000000","0.02493000"],["79909.75000000","0.00000000"],["79909.56000000","0.00000000"],["79909.52000000","0.02024000"],["79909.15000000","0.00946000"],["79908.95000000","0.00007000"],["79908.46000000","0.00007000"],["79908.45000000","0.06283000"]],"a":[["79910.81000000","0.33070000"],["79910.82000000","0.00062000"],["79912.67000000","0.06290000"],["79913.00000000","0.06304000"],["79914.00000000","0.02435000"],["79914.52000000","0.00007000"],["79914.53000000","0.06290000"],["79915.14000000","0.00007000"],["79915.76000000","0.00014000"],["79915.77000000","0.05946000"],["79915.96000000","0.00007000"],["79915.97000000","0.06276000"],["79916.53000000","0.03945000"],["79919.62000000","0.00000000"]]}}}
{"rx_ns": 13884599740000, "frame": {"stream":"btcusdt@depth@100ms","data":{"e":"depthUpdate","E":1787650879814,"s":"BTCUSDT","U":99118605880,"u":99118605889,"b":[["71919.72000000","0.00336000"],["63928.64000000","0.00000000"]],"a":[["79916.05000000","0.01159000"],["80038.66000000","0.00144000"],["80136.70000000","0.00400000"],["81109.48000000","0.00030000"]]}}}
{"rx_ns": 13884695907300, "frame": {"stream":"btcusdt@depth@100ms","data":{"e":"depthUpdate","E":1787650879914,"s":"BTCUSDT","U":99118605890,"u":99118605964,"b":[["79910.80000000","1.77796000"],["79910.41000000","0.03378000"],["79910.31000000","0.00000000"],["79910.30000000","0.00014000"],["79908.95000000","0.00000000"],["79908.94000000","0.00014000"],["79908.46000000","0.00000000"],["79908.45000000","0.00007000"],["79908.44000000","0.33672000"],["79908.19000000","0.05351000"],["79906.97000000","0.00000000"],["79906.44000000","0.00718000"],["79905.89000000","0.00701000"],["79905.66000000","0.00407000"],["79905.65000000","0.59423000"],["79905.64000000","0.00007000"],["79904.82000000","0.00625000"],["79896.97000000","0.00000000"],["79895.89000000","0.00000000"],["79893.03000000","0.00625000"],["79892.67000000","0.29695000"],["79888.02000000","0.62584000"],["79843.32000000","0.02086000"],["79773.97000000","0.00026000"],["71919.72000000","0.00352000"],["63928.64000000","0.00000000"]],"a":[["79910.81000000","0.89477000"],["79910.82000000","0.00069000"],["79912.04000000","0.00007000"],["79912.05000000","0.05800000"],["79913.99000000","0.00000000"],["79915.14000000","0.00007000"],["79915.15000000","0.06297000"],["79915.50000000","0.00014000"],["79915.61000000","0.00007000"],["79915.62000000","0.14183000"],["79915.76000000","0.00014000"],["79915.96000000","0.00000000"],["79916.05000000","0.01152000"],["79916.53000000","0.00000000"],["79916.79000000","0.00054000"],["79917.05000000","0.00000000"],["79917.06000000","0.00000000"],["79918.00000000","0.02400000"],["79918.25000000","0.00000000"],["79919.89000000","0.96275000"],["79919.90000000","1.87677000"],["79919.91000000","0.00000000"],["79919.92000000","0.00000000"],["79920.01000000","0.00000000"],["79920.36000000","0.00000000"],["79924.12000000","0.00407000"],["79954.20000000","0.00000000"],["80013.67000000","0.00000000"]]}}}
{"rx_ns": 13884800447500, "frame": {"stream":"btcusdt@depth20","data":{"lastUpdateId":99118605998,"bids":[["79910.80000000","1.77796000"],["79910.79000000","0.00027000"],["79910.78000000","0.00040000"],["79910.76000000","0.00007000"],["79910.75000000","0.05014000"],["79910.68000000","0.00731000"],["79910.51000000","0.00007000"],["79910.50000000","0.07923000"],["79910.42000000","0.00007000"],["79910.41000000","0.03371000"],["79910.19000000","0.00014000"],["79910.18000000","0.02493000"],["79909.99000000","0.00007000"],["79909.59000000","0.00007000"],["79909.53000000","0.00007000"],["79909.52000000","0.02024000"],["79909.24000000","0.00007000"],["79909.15000000","0.00946000"],["79909.14000000","0.00008000"],["79908.97000000","0.00014000"]],"asks":[["79910.81000000","0.89491000"],["79910.82000000","0.00069000"],["79910.83000000","0.00013000"],["79911.63000000","0.00007000"],["79912.04000000","0.00007000"],["79912.05000000","0.05814000"],["79912.66000000","0.00007000"],["79912.67000000","0.06290000"],["79912.96000000","0.00007000"],["79912.99000000","0.00007000"],["79913.00000000","0.06304000"],["79913.01000000","0.33260000"],["79913.50000000","0.00007000"],["79913.77000000","0.00007000"],["79913.78000000","0.04689000"],["79913.85000000","0.00007000"],["79914.00000000","0.02435000"],["79914.03000000","0.00007000"],["79914.48000000","0.00007000"],["79914.52000000","0.00007000"]]}}}
{"rx_ns": 13884800581800, "frame": {"stream":"btcusdt@depth@100ms","data":{"e":"depthUpdate","E":1787650880014,"s":"BTCUSDT","U":99118605965,"u":99118605998,"b":[["79910.41000000","0.03371000"],["79910.30000000","0.00000000"],["79909.15000000","0.00946000"],["79905.66000000","0.00007000"],["79904.01000000","0.00400000"],["79895.58000000","0.00000000"],["79843.32000000","0.00000000"],["79774.00000000","0.06932000"],["71919.72000000","0.00336000"],["63928.64000000","0.00031000"]],"a":[["79910.81000000","0.89491000"],["79912.05000000","0.05814000"],["79915.15000000","0.06283000"],["79916.36000000","0.00007000"],["79916.37000000","0.00000000"],["79919.88000000","0.00400000"],["79924.12000000","0.00007000"],["79927.56000000","0.00000000"],["80013.12000000","0.00000000"],["80013.70000000","0.02804000"],["80064.75000000","0.00400000"],["80078.67000000","0.00144000"]]}}}
{"rx_ns": 13884915659700, "frame": {"stream":"btcusdt@depth@100ms","data":{"e":"depthUpdate","E":1787650880114,"s":"BTCUSDT","U":99118605999,"u":99118606018,"b":[["79899.28000000","0.00007000"],["79895.58000000","0.00007000"],["79762.24000000","1.50235000"],["79720.59000000","0.00000000"],["79702.97000000","0.01648000"],["71919.72000000","0.00368000"]],"a":[["79910.81000000","0.89602000"],["79912.43000000","0.00007000"],["79912.99000000","0.19232000"],["79914.00000000","0.02442000"],["79914.10000000","0.00007000"],["79914.11000000","0.03943000"],["79915.15000000","0.06276000"],["79915.61000000","0.00000000"],["79915.62000000","0.00000000"],["79927.56000000","0.00007000"],["80065.90000000","1.50235000"],["80082.92000000","0.00000000"],["80083.73000000","0.03915000"]]}}}
{"rx_ns": 13885001360400, "frame": {"stream":"btcusdt@depth@100ms","data":{"e":"depthUpdate","E":1787650880214,"s":"BTCUSDT","U":99118606019,"u":99118606062,"b":[["79910.80000000","1.85939000"],["79905.68000000","0.00007000"],["79905.67000000","1.15575000"],["79905.66000000","1.87677000"],["79905.65000000","0.00000000"],["79905.64000000","0.00000000"],["79739.28000000","0.00000000"],["71919.72000000","0.00368000"],["63928.64000000","0.00000000"]],"a":[["79910.81000000","0.89332000"],["79912.67000000","0.06297000"],["79912.98000000","0.00000000"],["79912.99000000","0.00021000"],["79914.00000000","0.02442000"],["79914.11000000","0.03957000"],["79914.53000000","0.06276000"],["79914.77000000","0.00692000"],["79916.79000000","0.00000000"],["79918.35000000","0.00052000"],["79919.17000000","0.00000000"],["79919.88000000","0.00400000"],["79920.59000000","0.00000000"],["79939.42000000","0.00007000"],["79944.83000000","0.00400000"],["80107.62000000","0.00000000"],["80116.46000000","0.00007000"]]}}}
{"rx_ns": 13885100761900, "frame": {"stream":"btcusdt@depth@100ms","data":{"e":"depthUpdate","E":1787650880315,"s":"BTCUSDT","U":99118606063,"u":99118606076,"b":[["79905.89000000","0.00694000"],["71919.72000000","0.00368000"],["63929.00000000","0.00060000"]],"a":[["79912.67000000","0.06297000"],["79912.99000000","0.00007000"],["79914.53000000","0.06290000"],["79944.83000000","0.00000000"]]}}}
{"rx_ns": 13885203882700, "frame": {"stream":"btcusdt@depth@100ms","data":{"e":"depthUpdate","E":1787650880414,"s":"BTCUSDT","U":99118606077,"u":99118606090,"b":[["79910.18000000","0.02493000"],["79909.94000000","0.00000000"],["79909.93000000","0.00000000"],["79736.19000000","4.60640000"],["78712.13000000","0.00030000"],["71919.72000000","0.00384000"]],"a":[["79910.81000000","0.69352000"],["79944.82000000","0.00400000"],["80103.73000000","4.56710000"]]}}}
{"rx_ns": 13885299636700, "frame": {"stream":"btcusdt@depth@100ms","data":{"e":"depthUpdate","E":1787650880514,"s":"BTCUSDT","U":99118606091,"u":99118606102,"b":[["79910.18000000","0.02500000"],["79909.64000000","0.00007000"],["79909.63000000","0.03224000"],["77600.00000000","2.19345000"],["71919.72000000","0.00400000"],["71919.00000000","0.00000000"],["63928.64000000","0.00031000"]],"a":[["79910.81000000","0.69082000"],["79954.20000000","0.00007000"]]}}}
{"rx_ns": 13885401233100, "frame": {"stream":"btcusdt@depth@100ms","data":{"e":"depthUpdate","E":1787650880614,"s":"BTCUSDT","U":99118606103,"u":99118606114,"b":[["79910.18000000","0.02500000"],["79905.68000000","0.00807000"],["71919.72000000","0.00384000"],["63928.64000000","0.00000000"]],"a":[["79919.88000000","0.01200000"],["79959.78000000","0.00400000"],["79960.48000000","0.00000000"]]}}}
{"rx_ns": 13885496046400, "frame": {"stream":"btcusdt@depth@100ms","data":{"e":"depthUpdate","E":1787650880714,"s":"BTCUSDT","U":99118606115,"u":99118606125,"b":[["79905.89000000","0.00701000"],["79905.69000000","0.00400000"],["79700.01000000","0.00000000"],["79688.21000000","0.00770000"],["77650.00000000","0.14547000"],["71919.72000000","0.00416000"]],"a":[["79910.81000000","0.69069000"],["79919.87000000","0.00400000"],["79920.91000000","0.00400000"],["79943.80000000","0.96457000"],["79967.84000000","0.77468000"]]}}}
{"rx_ns": 13885595974600, "frame": {"stream":"btcusdt@depth@100ms","data":{"e":"depthUpdate","E":1787650880814,"s":"BTCUSDT","U":99118606126,"u":99118606136,"b":[["79904.76000000","0.00400000"],["79864.00000000","0.02400000"],["79854.00000000","0.02400000"],["71919.72000000","0.00416000"],["63928.64000000","0.00000000"]],"a":[["79910.81000000","0.89312000"],["81109.48000000","0.00030000"]]}}}
{"rx_ns": 13885696428300, "frame": {"stream":"btcusdt@depth@100ms","data":{"e":"depthUpdate","E":1787650880914,"s":"BTCUSDT","U":99118606137,"u":99118606144,"b":[["71919.72000000","0.00416000"],["63928.64000000","0.00000000"]],"a":[["79910.81000000","0.69069000"]]}}}
{"rx_ns": 13885805762500, "frame": {"stream":"btcusdt@depth20","data":{"lastUpdateId":99118606148,"bids":[["79910.80000000","1.85939000"],["79910.79000000","0.00027000"],["79910.78000000","0.00040000"],["79910.76000000","0.00007000"],["79910.75000000","0.05014000"],["79910.68000000","0.00731000"],["79910.51000000","0.00007000"],["79910.50000000","0.07923000"],["79910.42000000","0.00007000"],["79910.41000000","0.03371000"],["79910.19000000","0.00014000"],["79910.18000000","0.02500000"],["79909.99000000","0.00007000"],["79909.64000000","0.00007000"],["79909.63000000","0.03224000"],["79909.59000000","0.00007000"],["79909.53000000","0.00007000"],["79909.52000000","0.02024000"],["79909.24000000","0.00007000"],["79909.15000000","0.00946000"]],"asks":[["79910.81000000","0.69069000"],["79910.82000000","0.00069000"],["79910.83000000","0.00013000"],["79911.63000000","0.00007000"],["79912.04000000","0.00007000"],["79912.05000000","0.05814000"],["79912.43000000","0.00007000"],["79912.66000000","0.00007000"],["79912.67000000","0.06297000"],["79912.96000000","0.00007000"],["79912.99000000","0.00007000"],["79913.00000000","0.06304000"],["79913.01000000","0.33260000"],["79913.50000000","0.00007000"],["79913.77000000","0.00007000"],["79913.78000000","0.04689000"],["79913.85000000","0.00007000"],["79914.00000000","0.02442000"],["79914.03000000","0.00007000"],["79914.10000000","0.00007000"]]}}}
{"rx_ns": 13885805901700, "frame": {"stream":"btcusdt@depth@100ms","data":{"e":"depthUpdate","E":1787650881014,"s":"BTCUSDT","U":99118606145,"u":99118606148,"b":[["79906.48000000","0.00400000"],["79843.32000000","0.02086000"],["63928.64000000","0.00031000"]],"a":[["79920.87000000","0.00400000"]]}}}
{"rx_ns": 13885895765400, "frame": {"stream":"btcusdt@depth@100ms","data":{"e":"depthUpdate","E":1787650881114,"s":"BTCUSDT","U":99118606149,"u":99118606156,"b":[["79895.58000000","0.00007000"],["79843.32000000","0.00000000"],["71919.72000000","0.00416000"]],"a":[["79927.56000000","0.00007000"]]}}}
{"rx_ns": 13885996898300, "frame": {"stream":"btcusdt@depth@100ms","data":{"e":"depthUpdate","E":1787650881214,"s":"BTCUSDT","U":99118606157,"u":99118606169,"b":[["79910.80000000","1.85926000"],["79909.63000000","0.03238000"],["79843.32000000","0.02086000"],["71919.72000000","0.00432000"],["63928.64000000","0.00000000"],["62150.00000000","1.22909000"]],"a":[["79910.81000000","0.69055000"],["79935.26000000","0.00007000"],["80121.75000000","0.00007000"]]}}}
{"rx_ns": 13886096061300, "frame": {"stream":"btcusdt@depth@100ms","data":{"e":"depthUpdate","E":1787650881314,"s":"BTCUSDT","U":99118606170,"u":99118606190,"b":[["79843.32000000","0.00000000"],["79640.31000000","0.00000000"],["71919.72000000","0.00416000"],["63929.00000000","0.00060000"]],"a":[["79919.87000000","0.01600000"],["79919.88000000","0.00000000"]]}}}
{"rx_ns": 13886197818700, "frame": {"stream":"btcusdt@depth@100ms","data":{"e":"depthUpdate","E":1787650881414,"s":"BTCUSDT","U":99118606191,"u":99118606200,"b":[["79910.50000000","0.07930000"],["79910.42000000","0.00640000"],["79771.01000000","0.00020000"],["79728.30000000","0.03032000"],["78712.13000000","0.00030000"],["71919.72000000","0.00432000"]],"a":[["80050.70000000","0.00020000"]]}}}
{"rx_ns": 13886297789300, "frame": {"stream":"btcusdt@depth@100ms","data":{"e":"depthUpdate","E":1787650881514,"s":"BTCUSDT","U":99118606201,"u":99118606212,"b":[["79910.50000000","0.07930000"],["79910.42000000","0.00654000"],["79909.15000000","0.00932000"],["79843.32000000","0.02086000"],["71919.72000000","0.00432000"],["63928.64000000","0.00031000"]],"a":[]}}}
{"rx_ns": 13886399475100, "frame": {"stream":"btcusdt@depth@100ms","data":{"e":"depthUpdate","E":1787650881614,"s":"BTCUSDT","U":99118606213,"u":99118606219,"b":[["79843.32000000","0.00000000"],["71919.72000000","0.00448000"],["71919.00000000","0.00000000"],["63928.64000000","0.00000000"]],"a":[["79910.81000000","0.69155000"],["79954.20000000","0.00000000"]]}}}
{"rx_ns": 13886496031600, "frame": {"stream":"btcusdt@depth@100ms","data":{"e":"depthUpdate","E":1787650881714,"s":"BTCUSDT","U":99118606220,"u":99118606348,"b":[["79910.80000000","1.95656000"],["79910.68000000","0.01131000"],["79910.52000000","0.00007000"],["79910.51000000","0.06283000"],["79910.50000000","0.08580000"],["79910.42000000","0.00021000"],["79910.18000000","0.02507000"],["79909.65000000","0.00007000"],["79909.64000000","0.06283000"],["79909.53000000","0.00007000"],["79908.95000000","0.00007000"],["79908.94000000","0.06290000"],["79908.45000000","0.06276000"],["79908.44000000","0.33665000"],["79906.48000000","0.00000000"],["79905.68000000","0.00800000"],["79905.67000000","1.15568000"],["72000.00000000","74.61326000"],["71919.72000000","0.00432000"]],"a":[["79910.81000000","0.30485000"],["79910.82000000","0.00048000"],["79912.04000000","0.00000000"],["79912.05000000","0.00014000"],["79912.43000000","0.00000000"],["79912.66000000","0.00000000"],["79912.67000000","0.00014000"],["79912.99000000","0.00000000"],["79913.00000000","0.00028000"],["79913.99000000","0.00007000"],["79914.10000000","0.00000000"],["79914.11000000","0.00014000"],["79914.52000000","0.00000000"],["79914.53000000","0.00014000"],["79914.77000000","0.00685000"],["79915.14000000","0.00000000"],["79915.15000000","0.00000000"],["79915.77000000","0.05939000"],["79915.97000000","0.00000000"],["79915.99000000","0.00007000"],["79916.05000000","0.01152000"],["79916.38000000","0.00007000"],["79916.39000000","0.06283000"],["79916.98000000","0.00007000"],["79916.99000000","0.06283000"],["79917.00000000","0.14279000"],["79917.01000000","0.00000000"],["79917.33000000","0.01371000"],["79917.39000000","0.00007000"],["79917.40000000","0.06283000"],["79918.35000000","0.00000000"],["79918.87000000","0.00000000"],["79919.49000000","0.05656000"],["79919.87000000","0.00000000"],["79919.88000000","0.06276000"],["79919.89000000","0.38181000"],["79919.90000000","0.00000000"],["79920.87000000","0.00000000"],["79920.91000000","0.00000000"],["79921.99000000","0.00059000"],["79922.73000000","0.00000000"],["79923.45000000","0.00000000"],["79924.26000000","0.00000000"],["79924.27000000","0.00007000"],["79924.29000000","0.00000000"],["79924.33000000","0.00000000"],["79924.34000000","0.00400000"],["79924.35000000","0.00000000"],["79924.71000000","0.00400000"],["79925.07000000","0.00000000"],["79926.21000000","0.00400000"],["79926.28000000","0.00000000"],["79926.70000000","0.01200000"],["79932.65000000","0.00000000"],["79937.08000000","0.00625000"],["79939.25000000","0.00000000"],["79951.34000000","0.00000000"],["79954.20000000","0.00007000"],["80012.00000000","1.41653000"],["80013.11000000","1.95350000"]]}}}
{"rx_ns": 13886596189300, "frame": {"stream":"btcusdt@depth@100ms","data":{"e":"depthUpdate","E":1787650881814,"s":"BTCUSDT","U":99118606349,"u":99118606419,"b":[["79910.80000000","1.95656000"],["79910.68000000","0.01131000"],["79910.51000000","0.06297000"],["79910.50000000","0.08580000"],["79910.42000000","0.00007000"],["79910.18000000","0.02507000"],["79909.64000000","0.06297000"],["79909.52000000","0.02010000"],["71919.72000000","0.00448000"],["63928.64000000","0.00000000"]],"a":[["79910.81000000","0.30401000"],["79912.05000000","0.00000000"],["79912.67000000","0.00000000"],["79913.00000000","0.00014000"],["79914.00000000","0.02428000"],["79914.11000000","0.00000000"],["79914.53000000","0.00000000"],["79914.77000000","0.00699000"],["79915.77000000","0.05953000"],["79916.00000000","0.02428000"],["79916.05000000","0.01166000"],["79916.39000000","0.06297000"],["79917.41000000","0.42255000"],["79920.08000000","0.00000000"],["79939.62000000","0.02479000"],["79951.53000000","1.20175000"],["81109.48000000","0.00030000"]]}}}
{"rx_ns": 13886699608400, "frame": {"stream":"btcusdt@depth@100ms","data":{"e":"depthUpdate","E":1787650881916,"s":"BTCUSDT","U":99118606420,"u":99118606429,"b":[["79900.28000000","0.33800000"],["79879.25000000","0.12501000"],["79879.24000000","0.00000000"],["71919.72000000","0.00416000"],["63928.64000000","0.00000000"]],"a":[["79910.81000000","0.29756000"],["79920.03000000","0.00069000"]]}}}
{"rx_ns": 13886796388400, "frame": {"stream":"btcusdt@depth20","data":{"lastUpdateId":99118606472,"bids":[["79910.80000000","1.95656000"],["79910.79000000","0.00027000"],["79910.78000000","0.00040000"],["79910.76000000","0.00007000"],["79910.75000000","0.05014000"],["79910.68000000","0.00731000"],["79910.51000000","0.00021000"],["79910.50000000","0.07930000"],["79910.42000000","0.00007000"],["79910.41000000","0.03371000"],["79910.19000000","0.00014000"],["79910.18000000","0.02507000"],["79909.99000000","0.00007000"],["79909.65000000","0.00007000"],["79909.64000000","0.06297000"],["79909.63000000","0.03238000"],["79909.59000000","0.00007000"],["79909.53000000","0.00007000"],["79909.52000000","0.02010000"],["79909.24000000","0.00007000"]],"asks":[["79910.81000000","0.29832000"],["79910.82000000","0.00055000"],["79910.83000000","0.00013000"],["79911.63000000","0.00007000"],["79912.96000000","0.00007000"],["79912.99000000","0.00007000"],["79913.00000000","0.06290000"],["79913.01000000","0.33260000"],["79913.23000000","0.00007000"],["79913.50000000","0.00007000"],["79913.77000000","0.00007000"],["79913.78000000","0.04689000"],["79913.85000000","0.00007000"],["79913.99000000","0.00007000"],["79914.00000000","0.02435000"],["79914.03000000","0.00007000"],["79914.48000000","0.00007000"],["79914.52000000","0.00007000"],["79914.53000000","0.06276000"],["79914.77000000","0.00706000"]]}}}
{"rx_ns": 13886796494700, "frame": {"stream":"btcusdt@depth@100ms","data":{"e":"depthUpdate","E":1787650882014,"s":"BTCUSDT","U":99118606430,"u":99118606472,"b":[["79910.68000000","0.00731000"],["79910.52000000","0.00000000"],["79910.51000000","0.00021000"],["79910.50000000","0.07930000"],["79909.53000000","0.00007000"],["79908.95000000","0.00007000"],["79908.88000000","0.00400000"],["79908.46000000","0.00007000"],["79786.78000000","0.04407000"],["79774.00000000","0.02400000"],["71919.72000000","0.00448000"],["63928.64000000","0.00031000"]],"a":[["79910.81000000","0.29832000"],["79910.82000000","0.00055000"],["79912.99000000","0.00007000"],["79913.00000000","0.06290000"],["79913.23000000","0.00007000"],["79914.00000000","0.02435000"],["79914.52000000","0.00007000"],["79914.53000000","0.06276000"],["79914.77000000","0.00706000"],["79915.14000000","0.00007000"],["79915.15000000","0.06276000"],["79915.76000000","0.00014000"],["79915.99000000","0.00000000"],["79916.38000000","0.00007000"],["79916.98000000","0.00007000"],["79916.99000000","0.06276000"],["79917.00000000","0.20590000"],["79917.39000000","0.00000000"],["79917.40000000","0.06276000"],["79918.68000000","0.06276000"],["79918.69000000","0.15305000"],["79920.03000000","0.00000000"],["80013.70000000","0.00000000"],["80026.51000000","0.02804000"]]}}}
{"rx_ns": 13886899786100, "frame": {"stream":"btcusdt@depth@100ms","data":{"e":"depthUpdate","E":1787650882114,"s":"BTCUSDT","U":99118606473,"u":99118606514,"b":[["79910.80000000","1.95656000"],["79910.68000000","0.00731000"],["79910.51000000","0.00007000"],["79910.42000000","0.00669000"],["79895.58000000","0.00007000"],["79843.32000000","0.02086000"],["79700.91000000","0.00793000"],["79688.21000000","0.00000000"],["71919.72000000","0.00432000"]],"a":[["79910.81000000","0.29798000"],["79913.00000000","0.06304000"],["79914.00000000","0.02435000"],["79914.53000000","0.06290000"],["79914.77000000","0.00706000"],["79915.15000000","0.06290000"],["79916.00000000","0.02414000"],["79916.05000000","0.01152000"],["79916.39000000","0.06283000"],["79927.56000000","0.00007000"]]}}}
{"rx_ns": 13886998952700, "frame": {"stream":"btcusdt@depth@100ms","data":{"e":"depthUpdate","E":1787650882214,"s":"BTCUSDT","U":99118606515,"u":99118606531,"b":[["79910.50000000","0.07930000"],["79900.90000000","0.00000000"],["79891.05000000","0.02466000"],["79888.35000000","0.00000000"],["79847.26000000","0.00007000"],["71919.72000000","0.00432000"],["63928.64000000","0.00000000"]],"a":[["79910.81000000","0.29846000"],["79918.48000000","0.00929000"],["79947.03000000","0.00000000"],["80127.04000000","0.00007000"],["80127.63000000","0.01960000"],["80137.39000000","0.00000000"]]}}}
{"rx_ns": 13887099356000, "frame": {"stream":"btcusdt@depth@100ms","data":{"e":"depthUpdate","E":1787650882314,"s":"BTCUSDT","U":99118606532,"u":99118606545,"b":[["79910.80000000","1.87933000"],["79843.32000000","0.00000000"],["79648.39000000","0.03032000"],["79580.46000000","0.10015000"],["79568.48000000","0.10000000"],["79565.27000000","0.00000000"],["79493.43000000","0.00000000"],["79481.45000000","0.00000000"],["71919.72000000","0.00432000"],["63929.00000000","0.00060000"]],"a":[["79912.67000000","0.06276000"],["79920.06000000","0.00703000"]]}}}
{"rx_ns": 13887200779300, "frame": {"stream":"btcusdt@depth@100ms","data":{"e":"depthUpdate","E":1787650882414,"s":"BTCUSDT","U":99118606546,"u":99118606567,"b":[["79905.89000000","0.00007000"],["79882.00000000","0.72400000"],["78712.13000000","0.00030000"],["71919.72000000","0.00432000"]],"a":[["79910.81000000","0.29874000"],["79910.82000000","0.00062000"],["79912.66000000","0.00007000"],["79915.50000000","0.00007000"],["79915.77000000","0.05939000"],["79917.07000000","0.00000000"],["79947.00000000","0.00000000"]]}}}
{"rx_ns": 13887297380700, "frame": {"stream":"btcusdt@depth@100ms","data":{"e":"depthUpdate","E":1787650882514,"s":"BTCUSDT","U":99118606568,"u":99118606582,"b":[["79909.64000000","0.00021000"],["79905.83000000","0.00000000"],["79905.82000000","0.00708000"],["79903.92000000","0.09383000"],["71919.72000000","0.00432000"],["63928.64000000","0.00031000"]],"a":[["79910.81000000","0.29757000"],["79912.05000000","0.06276000"],["79920.33000000","0.00070000"],["79920.53000000","0.00048000"],["79947.60000000","0.09474000"],["79958.95000000","0.00000000"]]}}}
{"rx_ns": 13887400289500, "frame": {"stream":"btcusdt@depth@100ms","data":{"e":"depthUpdate","E":1787650882614,"s":"BTCUSDT","U":99118606583,"u":99118606640,"b":[["79910.18000000","0.02493000"],["79909.65000000","0.00007000"],["79909.64000000","0.06283000"],["79908.95000000","0.00007000"],["79908.46000000","0.00007000"],["79908.45000000","0.06283000"],["79890.07000000","0.04434000"],["79877.91000000","0.00000000"],["71919.72000000","0.00440000"],["71919.00000000","0.00000000"],["63928.64000000","0.00000000"]],"a":[["79910.81000000","0.27907000"],["79910.82000000","0.00069000"],["79912.04000000","0.00007000"],["79912.05000000","0.06290000"],["79912.67000000","0.06290000"],["79913.99000000","0.00000000"],["79915.14000000","0.00007000"],["79915.15000000","0.06276000"],["79915.76000000","0.00014000"],["79916.38000000","0.00007000"],["79916.98000000","0.00000000"],["79918.68000000","0.00000000"],["79919.49000000","0.00000000"],["79919.88000000","0.00000000"],["79923.11000000","0.00400000"],["79923.54000000","0.00400000"],["79924.34000000","0.00000000"],["79924.71000000","0.00000000"],["79926.69000000","0.01200000"],["79926.70000000","0.00000000"],["79957.68000000","0.00400000"],["79959.78000000","0.00000000"]]}}}
{"rx_ns": 13887496092900, "frame": {"stream":"btcusdt@depth@100ms","data":{"e":"depthUpdate","E":1787650882714,"s":"BTCUSDT","U":99118606641,"u":99118606648,"b":[["79880.00000000","0.12041000"],["79786.78000000","0.00000000"],["71919.72000000","0.00456000"]],"a":[["79918.22000000","0.00000000"],["80026.51000000","0.00000000"]]}}}
{"rx_ns": 13887597085800, "frame": {"stream":"btcusdt@depth@100ms","data":{"e":"depthUpdate","E":1787650882814,"s":"BTCUSDT","U":99118606649,"u":99118606759,"b":[["79910.80000000","1.88010000"],["79910.79000000","0.00076000"],["79909.65000000","0.00000000"],["79909.64000000","0.00007000"],["79908.95000000","0.00000000"],["79908.94000000","0.00014000"],["79908.88000000","0.00000000"],["79908.46000000","0.00000000"],["79908.45000000","0.00007000"],["79908.44000000","0.33672000"],["79906.35000000","0.00000000"],["79905.68000000","0.00807000"],["79905.66000000","0.00000000"],["79905.02000000","0.00400000"],["79900.28000000","0.00000000"],["79900.02000000","0.00014000"],["79785.06000000","0.04407000"],["71919.72000000","0.00440000"],["63928.64000000","0.00000000"]],"a":[["79910.81000000","0.96550000"],["79911.42000000","0.00007000"],["79911.43000000","0.06276000"],["79912.66000000","0.21806000"],["79913.01000000","0.33267000"],["79913.76000000","0.00007000"],["79913.77000000","0.06283000"],["79914.52000000","0.00007000"],["79915.14000000","0.00007000"],["79915.50000000","0.00014000"],["79915.76000000","0.00007000"],["79916.38000000","0.00000000"],["79917.39000000","0.04037000"],["79917.99000000","0.00057000"],["79918.48000000","0.00000000"],["79918.65000000","0.00918000"],["79918.68000000","0.06276000"],["79918.69000000","0.00000000"],["79919.33000000","0.00400000"],["79919.49000000","0.06276000"],["79919.88000000","1.93953000"],["79920.33000000","0.00000000"],["79921.99000000","0.00000000"],["79923.54000000","0.00000000"],["79939.47000000","0.33783000"],["79948.79000000","0.62555000"],["79951.77000000","0.02407000"],["79954.01000000","0.00000000"],["79988.41000000","0.00000000"],["80024.79000000","0.02804000"],["81109.48000000","0.00030000"]]}}}
{"rx_ns": 13887703313800, "frame": {"stream":"btcusdt@depth@100ms","data":{"e":"depthUpdate","E":1787650882914,"s":"BTCUSDT","U":99118606760,"u":99118607624,"b":[["79913.00000000","7.21223000"],["79912.99000000","0.00041000"],["79912.98000000","0.00013000"],["79912.95000000","0.00000000"],["79912.80000000","0.05000000"],["79912.75000000","0.05000000"],["79912.66000000","0.00014000"],["79912.65000000","0.00014000"],["79912.04000000","0.20631000"],["79912.03000000","0.00000000"],["79911.76000000","0.00000000"],["79911.63000000","0.00014000"],["79911.62000000","1.42199000"],["79911.43000000","0.31292000"],["79911.42000000","0.00021000"],["79911.41000000","0.30737000"],["79910.82000000","0.00000000"],["79910.81000000","0.07500000"],["79910.80000000","2.75628000"],["79910.79000000","0.00000000"],["79910.78000000","0.00027000"],["79910.76000000","0.00000000"],["79910.75000000","0.00014000"],["79910.68000000","0.00014000"],["79910.58000000","0.00000000"],["79910.56000000","0.00400000"],["79910.51000000","0.00000000"],["79910.50000000","0.07916000"],["79910.42000000","0.00000000"],["79910.41000000","0.03357000"],["79910.40000000","0.05337000"],["79910.19000000","0.00007000"],["79909.96000000","0.00026000"],["79909.76000000","0.00000000"],["79909.64000000","0.00000000"],["79909.63000000","0.03224000"],["79909.53000000","0.00000000"],["79908.94000000","0.00014000"],["79908.45000000","0.00000000"],["79908.44000000","0.00007000"],["79908.19000000","0.00007000"],["79908.08000000","0.00400000"],["79907.70000000","0.00000000"],["79907.08000000","0.00000000"],["79907.01000000","0.00013000"],["79906.98000000","0.00000000"],["79906.85000000","0.00007000"],["79906.46000000","0.00000000"],["79906.44000000","0.00725000"],["79905.89000000","0.00000000"],["79905.84000000","0.00000000"],["79905.82000000","0.00715000"],["79905.70000000","0.00000000"],["79905.69000000","1.87677000"],["79905.68000000","0.00000000"],["79905.67000000","0.62582000"],["79905.63000000","0.00000000"],["79905.02000000","0.00000000"],["79905.01000000","0.00008000"],["79904.82000000","0.00000000"],["79904.81000000","0.00000000"],["79904.60000000","0.00000000"],["79904.50000000","0.00000000"],["79904.31000000","0.08576000"],["79904.01000000","0.00000000"],["79903.51000000","0.00000000"],["79903.12000000","0.00400000"],["79903.03000000","0.00000000"],["79902.81000000","0.00000000"],["79902.74000000","0.36586000"],["79901.48000000","0.00007000"],["79901.26000000","0.00000000"],["79901.18000000","0.00000000"],["79900.02000000","0.00014000"],["79900.00000000","1.07346000"],["79899.28000000","0.00000000"],["79896.50000000","0.00000000"],["79896.30000000","0.00000000"],["79895.88000000","0.00000000"],["79891.05000000","0.00000000"],["79889.58000000","0.00000000"],["79883.67000000","0.00400000"],["79883.60000000","0.00400000"],["79882.77000000","0.00000000"],["79882.00000000","0.02400000"],["79877.08000000","0.33810000"],["79872.93000000","0.00000000"],["79871.68000000","0.30000000"],["79869.36000000","0.00000000"],["79867.71000000","0.00000000"],["79867.16000000","0.00000000"],["79847.26000000","0.00000000"],["79830.97000000","0.00000000"],["79829.34000000","0.00000000"],["79781.43000000","0.00000000"],["79773.43000000","0.00000000"],["79761.86000000","0.00000000"],["79759.44000000","0.00202000"],["79528.77000000","0.00000000"],["79124.39000000","0.00400000"],["79124.09000000","0.00400000"],["78712.13000000","0.00000000"],["71921.70000000","0.00016000"],["71919.72000000","0.00000000"],["71919.71000000","0.00008000"],["67821.25000000","0.00000000"],["67818.11000000","0.00297000"],["63928.64000000","0.00000000"]],"a":[["79910.81000000","0.00000000"],["79910.82000000","0.00000000"],["79910.83000000","0.00000000"],["79911.18000000","0.00000000"],["79911.42000000","0.00000000"],["79911.43000000","0.00000000"],["79911.63000000","0.00000000"],["79912.04000000","0.00000000"],["79912.05000000","0.00000000"],["79912.65000000","0.00000000"],["79912.66000000","0.00000000"],["79912.67000000","0.00000000"],["79912.96000000","0.00000000"],["79912.99000000","0.00000000"],["79913.00000000","0.00000000"],["79913.01000000","0.33210000"],["79913.02000000","0.00042000"],["79913.76000000","0.00000000"],["79913.77000000","0.00021000"],["79913.78000000","0.00014000"],["79913.94000000","0.00000000"],["79913.99000000","0.00007000"],["79914.00000000","0.02428000"],["79914.52000000","0.00000000"],["79914.53000000","0.00014000"],["79914.77000000","0.00692000"],["79915.14000000","0.00000000"],["79915.15000000","0.00014000"],["79915.18000000","0.00000000"],["79915.34000000","0.00000000"],["79915.50000000","0.00007000"],["79915.77000000","0.00014000"],["79915.99000000","0.04682000"],["79916.00000000","0.02428000"],["79916.04000000","0.00000000"],["79916.05000000","0.01145000"],["79916.39000000","0.00000000"],["79916.80000000","0.00000000"],["79916.99000000","0.00000000"],["79917.00000000","0.00000000"],["79917.21000000","0.00000000"],["79917.32000000","0.00007000"],["79917.33000000","0.01364000"],["79917.38000000","0.00007000"],["79917.39000000","0.00007000"],["79917.40000000","0.00000000"],["79917.41000000","0.00000000"],["79917.81000000","0.00000000"],["79917.99000000","0.00007000"],["79918.00000000","0.02407000"],["79918.59000000","0.06276000"],["79918.61000000","0.01364000"],["79918.65000000","0.00007000"],["79918.68000000","0.00000000"],["79918.80000000","0.00000000"],["79918.87000000","0.00000000"],["79919.00000000","0.00013000"],["79919.15000000","0.00000000"],["79919.21000000","0.06276000"],["79919.33000000","0.00000000"],["79919.37000000","0.00007000"],["79919.49000000","0.00000000"],["79919.83000000","0.06276000"],["79919.85000000","0.06283000"],["79919.86000000","0.00014000"],["79919.87000000","0.00007000"],["79919.88000000","0.00000000"],["79919.89000000","0.00000000"],["79919.99000000","0.00007000"],["79920.06000000","0.00000000"],["79920.34000000","0.00000000"],["79920.53000000","0.00000000"],["79920.96000000","0.00000000"],["79921.00000000","0.00008000"],["79921.54000000","0.00000000"],["79921.73000000","0.00000000"],["79922.99000000","0.00000000"],["79923.11000000","0.00000000"],["79923.24000000","0.00007000"],["79923.58000000","0.00000000"],["79923.59000000","0.00000000"],["79923.66000000","0.00000000"],["79923.70000000","0.00000000"],["79924.11000000","0.12511000"],["79924.12000000","0.00007000"],["79924.13000000","0.00000000"],["79924.97000000","0.14889000"],["79925.28000000","0.00000000"],["79925.29000000","0.00000000"],["79925.58000000","0.00000000"],["79925.99000000","0.00008000"],["79926.17000000","0.00000000"],["79926.21000000","0.00000000"],["79926.69000000","0.00000000"],["79926.70000000","0.00000000"],["79926.71000000","0.00000000"],["79926.72000000","0.00000000"],["79927.11000000","0.00007000"],["79927.24000000","0.00000000"],["79927.29000000","0.00000000"],["79927.38000000","0.00000000"],["79928.00000000","0.02407000"],["79928.13000000","0.08469000"],["79929.54000000","0.00000000"],["79930.98000000","0.00007000"],["79930.99000000","0.00000000"],["79931.65000000","0.00000000"],["79931.66000000","0.00400000"],["79931.72000000","0.00000000"],["79931.75000000","0.00000000"],["79931.88000000","0.00007000"],["79931.90000000","0.00000000"],["79931.96000000","0.25273000"],["79931.97000000","0.00928000"],["79932.10000000","0.12510000"],["79932.12000000","0.00000000"],["79932.26000000","0.00000000"],["79933.79000000","0.02000000"],["79934.19000000","0.00000000"],["79934.20000000","0.00000000"],["79934.41000000","0.00000000"],["79935.76000000","1.87684000"],["79935.77000000","0.47598000"],["79935.78000000","0.00000000"],["79936.60000000","0.07000000"],["79936.70000000","0.08000000"],["79937.08000000","0.36586000"],["79937.09000000","0.00000000"],["79938.52000000","1.04939000"],["79938.53000000","0.00000000"],["79938.54000000","0.00000000"],["79939.05000000","0.00000000"],["79939.47000000","0.00000000"],["79939.62000000","0.00000000"],["79939.80000000","0.00000000"],["79939.81000000","0.00000000"],["79940.56000000","1.87677000"],["79942.66000000","1.04939000"],["79942.67000000","0.00000000"],["79943.39000000","0.00000000"],["79943.80000000","0.31489000"],["79943.81000000","0.00000000"],["79945.28000000","0.00000000"],["79945.95000000","1.87677000"],["79945.96000000","0.00000000"],["79946.91000000","0.00000000"],["79947.60000000","0.00000000"],["79947.64000000","1.04939000"],["79947.65000000","1.01931000"],["79947.66000000","0.00000000"],["79948.51000000","0.00000000"],["79948.79000000","0.00000000"],["79950.49000000","0.62554000"],["79951.00000000","0.00000000"],["79951.52000000","1.87677000"],["79951.53000000","0.00000000"],["79951.62000000","0.39399000"],["79951.77000000","0.00000000"],["79952.00000000","0.02400000"],["79952.46000000","0.00000000"],["79952.92000000","0.00000000"],["79953.00000000","0.01000000"],["79953.91000000","0.00000000"],["79954.20000000","0.00007000"],["79955.20000000","0.00400000"],["79955.31000000","0.00000000"],["79956.12000000","0.33776000"],["79956.45000000","1.04939000"],["79957.24000000","0.00000000"],["79957.25000000","0.00000000"],["79957.68000000","0.00400000"],["79958.07000000","0.00007000"],["79958.89000000","1.87677000"],["79958.90000000","0.00000000"],["79960.16000000","0.00400000"],["79961.48000000","0.00000000"],["79961.94000000","0.00007000"],["79962.13000000","0.33774000"],["79963.39000000","0.00000000"],["79963.76000000","1.87677000"],["79963.99000000","0.00000000"],["79964.06000000","0.00000000"],["79965.12000000","0.00400000"],["79966.84000000","1.04939000"],["79967.84000000","0.35969000"],["79969.21000000","0.04377000"],["79969.50000000","0.00000000"],["79971.52000000","0.00000000"],["79972.96000000","2.92616000"],["79972.97000000","0.00000000"],["79973.64000000","0.00000000"],["79973.65000000","0.00000000"],["79974.76000000","0.00000000"],["79977.23000000","1.04939000"],["79979.88000000","0.00000000"],["79982.55000000","1.87677000"],["79983.24000000","0.00000000"],["79987.55000000","1.04939000"],["79987.56000000","1.42622000"],["79988.81000000","1.23797000"],["79990.27000000","0.00000000"],["79991.98000000","1.87677000"],["79991.99000000","0.01620000"],["79992.83000000","0.00000000"],["79996.81000000","0.00000000"],["80013.11000000","0.00000000"],["80059.58000000","1.87677000"],["80060.38000000","1.04939000"],["80069.17000000","1.87677000"],["80070.77000000","1.04939000"],["80071.95000000","0.00202000"],["80074.51000000","0.00000000"],["80078.76000000","1.87677000"],["80188.07000000","0.00000000"],["81109.48000000","0.00000000"]]}}}
