{"rx_ns": 23953107100, "kind": "rest", "req": {"method": "GET", "url": "https://data-api.binance.vision/api/v3/depth?symbol=BTCUSDT&limit=100", "limit": 100, "weight": 5, "sent_ns": 22186164000, "status": 200, "used_weight_1m": "20", "recv_ns": 23169428000}, "frame": {"lastUpdateId":99076504320,"bids":[["78740.00000000","0.80365000"],["78739.99000000","0.00722000"],["78739.98000000","0.00013000"],["78739.02000000","0.00007000"],["78738.96000000","0.00014000"],["78738.95000000","0.01845000"],["78738.76000000","0.00007000"],["78738.01000000","0.00014000"],["78738.00000000","0.02407000"],["78737.97000000","0.00007000"],["78737.70000000","0.00007000"],["78737.69000000","0.03071000"],["78737.65000000","0.00014000"],["78737.64000000","0.05085000"],["78737.54000000","0.00286000"],["78737.47000000","0.04813000"],["78736.84000000","0.00007000"],["78736.44000000","0.00007000"],["78736.43000000","0.03684000"],["78736.20000000","0.02522000"],["78736.08000000","0.00204000"],["78736.00000000","0.02407000"],["78735.75000000","0.00200000"],["78735.17000000","0.03677000"],["78735.15000000","0.00007000"],["78734.82000000","0.00007000"],["78734.49000000","0.20791000"],["78734.25000000","0.00017000"],["78734.23000000","0.00027000"],["78734.00000000","0.02400000"],["78733.48000000","0.00007000"],["78732.96000000","0.00007000"],["78732.84000000","0.00328000"],["78732.78000000","0.00318000"],["78732.77000000","0.00007000"],["78732.50000000","0.00008000"],["78732.24000000","0.00007000"],["78732.18000000","0.00047000"],["78732.14000000","0.02540000"],["78732.00000000","0.02400000"],["78731.70000000","0.00400000"],["78731.31000000","0.00163000"],["78731.28000000","0.00014000"],["78731.26000000","0.00321000"],["78730.86000000","0.00048000"],["78730.72000000","0.00007000"],["78730.62000000","0.00007000"],["78730.33000000","0.00007000"],["78730.18000000","0.00400000"],["78730.17000000","0.00807000"],["78730.16000000","1.21952000"],["78730.00000000","0.02424000"],["78729.60000000","0.12701000"],["78729.49000000","0.00400000"],["78729.15000000","0.00635000"],["78729.14000000","0.08576000"],["78729.08000000","0.00007000"],["78729.00000000","0.00007000"],["78728.73000000","0.00328000"],["78728.67000000","0.00007000"],["78728.43000000","2.27061000"],["78728.00000000","0.02400000"],["78727.99000000","0.00007000"],["78727.69000000","0.00254000"],["78727.68000000","0.00400000"],["78727.41000000","0.00021000"],["78727.28000000","0.15000000"],["78727.18000000","0.02293000"],["78726.77000000","0.00254000"],["78726.65000000","0.00635000"],["78726.63000000","0.00007000"],["78726.38000000","0.00010000"],["78726.24000000","0.00027000"],["78726.01000000","1.21952000"],["78726.00000000","0.02400000"],["78725.38000000","0.00406000"],["78725.36000000","0.02200000"],["78725.28000000","0.02400000"],["78725.20000000","0.00007000"],["78725.14000000","0.00400000"],["78724.80000000","0.00008000"],["78724.72000000","0.00007000"],["78724.58000000","0.02007000"],["78724.51000000","0.02600000"],["78724.49000000","0.02931000"],["78724.42000000","0.02000000"],["78724.38000000","0.00007000"],["78724.33000000","0.02000000"],["78724.26000000","0.21930000"],["78724.00000000","0.02400000"],["78723.66000000","0.00400000"],["78723.60000000","0.00400000"],["78723.59000000","1.90515000"],["78723.54000000","0.00014000"],["78722.87000000","1.21915000"],["78722.53000000","0.00007000"],["78722.32000000","0.00007000"],["78722.21000000","0.02200000"],["78722.00000000","0.02407000"],["78721.72000000","0.12702000"]],"asks":[["78740.01000000","2.44660000"],["78740.02000000","0.00020000"],["78740.03000000","0.00013000"],["78740.22000000","0.00014000"],["78740.23000000","0.01978000"],["78740.25000000","0.00014000"],["78740.26000000","0.77426000"],["78740.90000000","0.00400000"],["78740.94000000","0.00014000"],["78740.95000000","0.04077000"],["78741.27000000","0.00663000"],["78741.28000000","0.61370000"],["78741.49000000","0.03292000"],["78741.89000000","0.00007000"],["78741.90000000","0.25407000"],["78742.00000000","0.00507000"],["78742.51000000","0.00254000"],["78742.73000000","0.00007000"],["78742.74000000","0.31758000"],["78742.75000000","0.03942000"],["78742.87000000","0.00400000"],["78742.89000000","0.00014000"],["78743.01000000","0.02188000"],["78743.15000000","0.05074000"],["78743.40000000","0.07220000"],["78743.41000000","0.00371000"],["78743.93000000","0.00635000"],["78743.94000000","0.00027000"],["78744.00000000","0.01200000"],["78744.01000000","0.03942000"],["78744.84000000","0.00400000"],["78745.34000000","0.00329000"],["78745.96000000","0.00400000"],["78745.97000000","0.00007000"],["78746.00000000","0.01200000"],["78746.45000000","1.90515000"],["78746.76000000","0.00014000"],["78746.77000000","0.08509000"],["78746.81000000","0.00400000"],["78746.92000000","0.00333000"],["78747.25000000","0.38100000"],["78747.29000000","0.02161000"],["78747.30000000","0.08278000"],["78747.90000000","0.00008000"],["78747.95000000","0.02000000"],["78748.00000000","0.08707000"],["78748.01000000","0.08581000"],["78748.48000000","0.02007000"],["78748.75000000","0.02000000"],["78748.78000000","0.00400000"],["78748.84000000","1.21952000"],["78748.85000000","0.14842000"],["78749.14000000","0.00007000"],["78750.00000000","0.01207000"],["78750.01000000","0.26882000"],["78750.05000000","0.12698000"],["78750.17000000","0.00007000"],["78750.21000000","0.36224000"],["78750.63000000","0.00014000"],["78750.64000000","0.02161000"],["78750.75000000","0.00400000"],["78750.94000000","0.38099000"],["78751.11000000","0.02000000"],["78751.18000000","0.00007000"],["78751.31000000","0.00007000"],["78751.61000000","0.02000000"],["78751.91000000","0.02000000"],["78752.00000000","1.91715000"],["78752.07000000","0.02600000"],["78752.17000000","0.00027000"],["78752.36000000","0.00007000"],["78752.68000000","0.02000000"],["78752.69000000","0.03000000"],["78752.72000000","0.00400000"],["78752.75000000","0.04000000"],["78753.22000000","0.00007000"],["78753.32000000","0.00007000"],["78753.62000000","0.01500000"],["78753.95000000","0.00326000"],["78754.00000000","1.24307000"],["78754.29000000","0.00323000"],["78754.33000000","0.12697000"],["78754.50000000","0.00014000"],["78754.69000000","0.00400000"],["78754.72000000","0.02000000"],["78754.81000000","0.02161000"],["78755.31000000","0.04103000"],["78755.51000000","0.04000000"],["78755.60000000","0.00008000"],["78755.76000000","0.00007000"],["78755.99000000","0.00400000"],["78756.00000000","0.01900000"],["78756.01000000","0.09744000"],["78756.24000000","0.00007000"],["78756.47000000","0.00007000"],["78756.66000000","0.00400000"],["78757.00000000","0.00007000"],["78757.15000000","0.00007000"],["78757.33000000","0.00007000"],["78757.64000000","1.90515000"]]}}
{"rx_ns": 23953107100, "frame": {"stream":"btcusdt@depth20","data":{"lastUpdateId":99076504722,"bids":[["78740.00000000","0.04955000"],["78739.99000000","0.00715000"],["78739.98000000","0.00013000"],["78739.54000000","0.00007000"],["78739.02000000","0.00007000"],["78738.96000000","0.00014000"],["78738.95000000","0.01845000"],["78738.76000000","0.00007000"],["78738.01000000","0.00014000"],["78738.00000000","0.02407000"],["78737.97000000","0.00007000"],["78737.70000000","0.00007000"],["78737.69000000","0.03071000"],["78737.65000000","0.00014000"],["78737.64000000","0.05078000"],["78737.54000000","0.00286000"],["78736.84000000","0.00007000"],["78736.44000000","0.00007000"],["78736.43000000","0.03684000"],["78736.20000000","0.02522000"]],"asks":[["78740.01000000","2.79423000"],["78740.02000000","0.00020000"],["78740.03000000","0.00013000"],["78740.04000000","0.00014000"],["78740.05000000","0.06357000"],["78740.22000000","0.00014000"],["78740.23000000","0.01978000"],["78740.25000000","0.00014000"],["78740.26000000","0.77222000"],["78740.90000000","0.00400000"],["78740.94000000","0.00014000"],["78740.95000000","0.04077000"],["78741.08000000","0.00400000"],["78741.11000000","0.00007000"],["78741.27000000","0.00021000"],["78741.28000000","0.61363000"],["78741.49000000","0.03292000"],["78741.90000000","0.25407000"],["78742.00000000","0.00507000"],["78742.75000000","0.03942000"]]}}}
{"rx_ns": 23953392700, "frame": {"stream":"btcusdt@depth","data":{"e":"depthUpdate","E":1787602891014,"s":"BTCUSDT","U":99076504275,"u":99076504722,"b":[["78740.00000000","0.04955000"],["78739.99000000","0.00715000"],["78739.54000000","0.00007000"],["78737.64000000","0.05078000"],["78737.47000000","0.00000000"],["78736.08000000","0.00000000"],["78736.06000000","0.00267000"],["78734.49000000","0.00000000"],["78734.23000000","0.00000000"],["78734.15000000","0.00027000"],["78732.84000000","0.00000000"],["78732.63000000","0.04146000"],["78732.13000000","0.00267000"],["78731.47000000","0.00000000"],["78731.28000000","0.00007000"],["78731.26000000","0.00000000"],["78730.86000000","0.00048000"],["78730.62000000","0.00000000"],["78730.20000000","0.01600000"],["78730.19000000","0.00000000"],["78730.18000000","0.00000000"],["78730.17000000","0.00007000"],["78729.49000000","0.00400000"],["78729.48000000","0.00000000"],["78729.15000000","0.00000000"],["78728.73000000","0.00000000"],["78728.57000000","0.00000000"],["78728.55000000","0.00334000"],["78728.44000000","1.90515000"],["78728.43000000","0.00000000"],["78727.42000000","0.00000000"],["78727.41000000","0.00021000"],["78727.00000000","0.00000000"],["78726.97000000","0.00330000"],["78726.90000000","0.00000000"],["78726.79000000","0.00000000"],["78726.77000000","0.00000000"],["78726.65000000","0.00000000"],["78725.39000000","0.00000000"],["78725.36000000","0.00000000"],["78725.28000000","0.00000000"],["78724.68000000","0.00000000"],["78724.58000000","0.00007000"],["78724.54000000","0.00400000"],["78724.51000000","0.00000000"],["78724.49000000","0.00331000"],["78724.47000000","0.00000000"],["78724.42000000","0.00000000"],["78724.37000000","0.00000000"],["78724.01000000","0.00635000"],["78723.97000000","0.00000000"],["78723.81000000","0.00000000"],["78723.71000000","0.00000000"],["78723.53000000","0.00000000"],["78722.98000000","0.00000000"],["78722.97000000","0.00000000"],["78722.92000000","0.00000000"],["78722.88000000","0.00635000"],["78722.67000000","0.00000000"],["78722.66000000","0.00000000"],["78722.65000000","0.00000000"],["78722.64000000","0.00000000"],["78722.63000000","0.00000000"],["78722.59000000","0.00000000"],["78722.48000000","0.00000000"],["78722.38000000","0.00000000"],["78722.21000000","0.00000000"],["78721.43000000","0.00000000"],["78721.27000000","0.00000000"],["78720.65000000","0.00000000"],["78720.64000000","0.00000000"],["78720.58000000","0.00000000"],["78718.82000000","0.00007000"],["78718.75000000","0.00000000"],["78718.18000000","0.00000000"],["78717.80000000","0.00000000"],["78717.45000000","0.00000000"],["78717.27000000","0.00000000"],["78716.97000000","0.00000000"],["78716.78000000","0.00000000"],["78716.33000000","0.00007000"],["78712.76000000","0.02000000"],["78711.98000000","0.02000000"],["78711.91000000","0.02000000"],["78711.09000000","0.00000000"],["78710.82000000","0.00000000"],["78708.01000000","0.12154000"],["78706.17000000","0.00000000"],["78704.20000000","0.00635000"],["78700.27000000","0.00000000"],["78699.49000000","0.00000000"],["78698.67000000","0.34312000"],["78696.26000000","0.34313000"],["78694.58000000","0.34675000"],["78692.58000000","0.00007000"],["78688.71000000","0.00000000"],["78687.73000000","0.02806000"],["78685.84000000","0.02337000"],["78681.80000000","0.87955000"],["78681.66000000","0.00627000"],["78681.32000000","0.02630000"],["78671.14000000","0.04762000"],["78668.42000000","0.91087000"],["78660.86000000","0.00000000"],["78660.08000000","0.00000000"],["78654.29000000","0.02000000"],["78652.35000000","0.00000000"],["78631.48000000","0.00000000"],["78610.86000000","0.00000000"],["78607.29000000","0.00406000"],["78601.36000000","0.09071000"],["78585.05000000","1.52163000"],["78545.16000000","0.00778000"],["78540.77000000","0.00000000"],["78498.00000000","0.00007000"],["78346.30000000","0.00000000"],["78031.34000000","0.00010000"],["77954.56000000","0.00000000"],["77564.79000000","0.00000000"],["77176.97000000","0.00000000"],["76791.08000000","0.00000000"],["76407.13000000","0.00000000"],["76025.09000000","0.00000000"],["75644.97000000","0.00000000"],["75266.74000000","0.00000000"],["74890.41000000","0.00000000"],["74515.95000000","0.00000000"],["74143.37000000","0.00000000"],["73772.66000000","0.00000000"],["73403.79000000","0.00000000"],["73036.78000000","0.00000000"],["70866.00000000","0.01700000"],["62992.00000000","0.00031000"]],"a":[["78740.01000000","2.79423000"],["78740.04000000","0.00014000"],["78740.05000000","0.06357000"],["78740.11000000","0.00000000"],["78740.26000000","0.77222000"],["78740.88000000","0.00000000"],["78740.89000000","0.00000000"],["78740.94000000","0.00014000"],["78740.95000000","0.04077000"],["78741.08000000","0.00400000"],["78741.11000000","0.00007000"],["78741.27000000","0.00021000"],["78741.28000000","0.61363000"],["78741.49000000","0.03292000"],["78741.88000000","0.00000000"],["78741.89000000","0.00000000"],["78741.90000000","0.25407000"],["78742.00000000","0.00507000"],["78742.51000000","0.00000000"],["78742.70000000","0.00000000"],["78742.73000000","0.00000000"],["78742.74000000","0.00000000"],["78743.93000000","0.00000000"],["78744.00000000","0.01700000"],["78745.04000000","0.00007000"],["78746.00000000","0.01700000"],["78746.44000000","0.00455000"],["78747.09000000","0.00007000"],["78747.30000000","0.08271000"],["78748.00000000","0.09200000"],["78750.00000000","0.09833000"],["78751.31000000","0.00007000"],["78752.00000000","1.91715000"],["78753.62000000","0.00000000"],["78754.00000000","1.23852000"],["78756.00000000","0.01900000"],["78756.07000000","0.06553000"],["78758.00000000","0.01900000"],["78759.03000000","0.00000000"],["78760.12000000","0.00014000"],["78762.13000000","0.00000000"],["78763.59000000","0.00007000"],["78764.82000000","0.00406000"],["78775.64000000","0.00435000"],["78775.69000000","0.00629000"],["78785.25000000","0.00000000"],["78785.87000000","0.00000000"],["78791.14000000","0.01130000"],["78799.81000000","0.00111000"],["78815.55000000","0.00000000"],["78817.51000000","0.00000000"],["78835.71000000","0.22336000"],["78837.53000000","0.02789000"],["78837.64000000","0.00025000"],["78847.06000000","0.00000000"],["78853.66000000","0.00000000"],["78882.33000000","0.00406000"],["78882.97000000","0.00000000"],["78884.23000000","1.52163000"],["78953.86000000","0.00000000"],["79121.54000000","0.01905000"],["79133.72000000","0.00000000"],["79529.38000000","0.00000000"],["79927.03000000","0.00000000"],["80326.67000000","0.00000000"],["80728.30000000","0.00000000"],["81131.94000000","0.00000000"],["81537.60000000","0.00000000"],["81945.29000000","0.00000000"],["82355.01000000","0.00000000"],["82766.79000000","0.00000000"],["83180.62000000","0.00000000"],["83596.53000000","0.00000000"],["84014.51000000","0.00000000"],["84202.54000000","0.00884000"],["84434.58000000","0.00000000"],["84856.75000000","0.00000000"],["86422.88000000","0.20801000"]]}}}
{"rx_ns": 24958233300, "frame": {"stream":"btcusdt@depth20","data":{"lastUpdateId":99076505394,"bids":[["78738.95000000","0.04830000"],["78738.94000000","0.00070000"],["78738.76000000","0.00007000"],["78738.01000000","0.00014000"],["78738.00000000","0.02407000"],["78737.97000000","0.00007000"],["78737.90000000","0.00007000"],["78737.89000000","0.01845000"],["78737.54000000","0.00286000"],["78737.18000000","0.00007000"],["78736.84000000","0.00007000"],["78736.65000000","0.00007000"],["78736.64000000","0.03071000"],["78736.21000000","0.00014000"],["78736.20000000","0.07616000"],["78736.06000000","0.00267000"],["78736.01000000","0.00014000"],["78736.00000000","0.02407000"],["78735.75000000","0.00200000"],["78735.38000000","0.03684000"]],"asks":[["78738.96000000","4.09006000"],["78738.97000000","0.00020000"],["78738.98000000","0.00013000"],["78739.17000000","0.00014000"],["78739.18000000","0.01978000"],["78739.99000000","0.00014000"],["78740.00000000","0.45689000"],["78740.01000000","0.24883000"],["78740.04000000","0.00014000"],["78740.05000000","0.06357000"],["78740.10000000","0.00327000"],["78740.25000000","0.00014000"],["78740.26000000","0.70779000"],["78740.44000000","0.03285000"],["78740.90000000","0.00400000"],["78740.95000000","0.04077000"],["78741.08000000","0.00400000"],["78741.11000000","0.00007000"],["78741.27000000","0.00007000"],["78741.28000000","0.61363000"]]}}}
{"rx_ns": 24958334500, "frame": {"stream":"btcusdt@depth","data":{"e":"depthUpdate","E":1787602892014,"s":"BTCUSDT","U":99076504723,"u":99076505394,"b":[["78740.00000000","0.00000000"],["78739.99000000","0.00000000"],["78739.98000000","0.00000000"],["78739.54000000","0.00000000"],["78739.02000000","0.00000000"],["78738.96000000","0.00000000"],["78738.95000000","0.04830000"],["78738.94000000","0.00070000"],["78738.00000000","0.02407000"],["78737.90000000","0.00007000"],["78737.89000000","0.01845000"],["78737.70000000","0.00000000"],["78737.69000000","0.00000000"],["78737.65000000","0.00000000"],["78737.64000000","0.00000000"],["78737.18000000","0.00007000"],["78736.65000000","0.00007000"],["78736.64000000","0.03071000"],["78736.44000000","0.00000000"],["78736.43000000","0.00000000"],["78736.21000000","0.00014000"],["78736.20000000","0.07616000"],["78736.01000000","0.00014000"],["78736.00000000","0.02407000"],["78735.38000000","0.03684000"],["78735.17000000","0.00000000"],["78734.12000000","0.03684000"],["78734.01000000","0.00000000"],["78734.00000000","0.02407000"],["78732.64000000","0.00000000"],["78732.63000000","0.04146000"],["78732.39000000","0.00000000"],["78732.14000000","0.02540000"],["78732.11000000","0.20791000"],["78732.00000000","0.02400000"],["78731.99000000","0.00204000"],["78731.43000000","0.00000000"],["78731.37000000","0.00000000"],["78731.36000000","0.00000000"],["78730.22000000","0.00000000"],["78730.21000000","0.00000000"],["78730.20000000","0.00000000"],["78730.17000000","0.00007000"],["78730.14000000","0.00000000"],["78729.72000000","0.04816000"],["78729.14000000","0.00000000"],["78728.55000000","0.00000000"],["78728.34000000","0.00000000"],["78728.33000000","0.00332000"],["78727.61000000","0.08576000"],["78726.97000000","0.00000000"],["78726.76000000","0.00330000"],["78726.02000000","0.00000000"],["78725.21000000","0.00635000"],["78724.01000000","0.00000000"],["78723.91000000","0.00000000"],["78723.89000000","0.00000000"],["78723.88000000","0.00000000"],["78723.87000000","0.00000000"],["78723.84000000","0.00254000"],["78723.83000000","0.00000000"],["78723.82000000","0.00000000"],["78723.14000000","0.00000000"],["78723.02000000","0.00000000"],["78718.01000000","0.01600000"],["78716.68000000","0.04600000"],["78716.33000000","0.00000000"],["78716.00000000","0.04400000"],["78715.95000000","0.02000000"],["78715.92000000","1.24552000"],["78715.90000000","0.02600000"],["78715.28000000","0.00007000"],["78715.00000000","0.00007000"],["78713.63000000","0.02200000"],["78712.77000000","0.02200000"],["78712.06000000","0.02000000"],["78708.01000000","0.00000000"],["78706.01000000","0.12281000"],["78704.19000000","0.00014000"],["78701.03000000","0.00007000"],["78700.84000000","0.00000000"],["78700.50000000","0.00000000"],["78700.46000000","0.00000000"],["78700.32000000","0.00014000"],["78700.00000000","0.02433000"],["78699.45000000","0.00000000"],["78699.00000000","0.01000000"],["78688.71000000","0.00000000"],["78687.73000000","0.00000000"],["78687.58000000","0.02843000"],["78685.84000000","0.00000000"],["78685.69000000","0.02369000"],["78678.01000000","0.00000000"],["78676.13000000","0.00315000"],["78664.78000000","0.02200000"],["78661.62000000","0.02200000"],["78661.43000000","0.02000000"],["78661.10000000","0.02600000"],["78661.05000000","0.00000000"],["78660.86000000","0.02000000"],["78660.08000000","0.02000000"],["78660.04000000","0.02000000"],["78658.28000000","0.00000000"],["78655.12000000","0.00000000"],["78654.29000000","0.00000000"],["78651.95000000","0.00000000"],["78646.47000000","0.00000000"],["78628.87000000","2.77101000"],["78570.51000000","0.00000000"],["78550.82000000","4.54902000"],["78545.16000000","0.00000000"],["78541.91000000","0.00778000"],["78500.00000000","4.70464000"],["78462.96000000","0.00250000"],["78345.25000000","0.00000000"],["78300.00000000","4.53484000"],["78117.66000000","0.00000000"],["77953.52000000","0.00000000"],["77772.63000000","0.00032000"],["77563.76000000","0.00000000"],["77175.94000000","0.00000000"],["76790.06000000","0.00000000"],["76406.11000000","0.00000000"],["76024.08000000","0.00000000"],["75700.00000000","1.21735000"],["75643.96000000","0.00000000"],["75265.74000000","0.00000000"],["74889.41000000","0.00000000"],["74514.96000000","0.00000000"],["74142.39000000","0.00000000"],["73771.67000000","0.00000000"],["73402.82000000","0.00018000"],["73035.80000000","0.00000000"],["70866.00000000","0.01412000"],["70865.06000000","0.00112000"],["66000.00000000","20.02566000"],["62992.00000000","0.00000000"],["62991.16000000","0.00031000"]],"a":[["78738.96000000","4.09006000"],["78738.97000000","0.00020000"],["78738.98000000","0.00013000"],["78739.03000000","0.00000000"],["78739.17000000","0.00014000"],["78739.18000000","0.01978000"],["78739.55000000","0.00000000"],["78739.99000000","0.00014000"],["78740.00000000","0.45689000"],["78740.01000000","0.24883000"],["78740.02000000","0.00000000"],["78740.03000000","0.00000000"],["78740.04000000","0.00014000"],["78740.05000000","0.06357000"],["78740.10000000","0.00327000"],["78740.22000000","0.00000000"],["78740.23000000","0.00000000"],["78740.26000000","0.70779000"],["78740.44000000","0.03285000"],["78740.94000000","0.00000000"],["78741.27000000","0.00007000"],["78741.28000000","0.61363000"],["78741.49000000","0.00000000"],["78741.70000000","0.03942000"],["78741.71000000","0.05074000"],["78741.89000000","0.00000000"],["78741.90000000","0.25400000"],["78742.00000000","0.00500000"],["78742.74000000","0.01400000"],["78742.75000000","0.00000000"],["78742.96000000","0.03942000"],["78742.99000000","0.00007000"],["78743.00000000","0.00007000"],["78743.01000000","0.02181000"],["78743.15000000","0.00000000"],["78743.40000000","0.07220000"],["78744.00000000","0.02400000"],["78744.01000000","0.00000000"],["78744.42000000","0.00321000"],["78745.93000000","0.12699000"],["78745.97000000","0.00000000"],["78746.00000000","0.02400000"],["78746.44000000","0.00455000"],["78746.77000000","0.08502000"],["78747.02000000","0.00007000"],["78748.00000000","0.09900000"],["78750.00000000","0.10533000"],["78750.26000000","0.00007000"],["78751.31000000","0.00000000"],["78752.00000000","1.92915000"],["78753.23000000","0.00007000"],["78753.77000000","0.04103000"],["78754.00000000","1.24352000"],["78754.33000000","0.00000000"],["78754.71000000","0.10576000"],["78755.31000000","0.00000000"],["78755.34000000","0.02515000"],["78756.00000000","0.02400000"],["78756.01000000","0.00000000"],["78756.47000000","0.00000000"],["78758.00000000","0.02400000"],["78758.42000000","0.00406000"],["78759.15000000","0.00000000"],["78760.00000000","0.11923000"],["78762.54000000","0.00007000"],["78762.69000000","0.00000000"],["78763.59000000","0.00000000"],["78764.82000000","0.00000000"],["78768.30000000","0.00000000"],["78777.17000000","0.00000000"],["78779.00000000","0.01000000"],["78780.00000000","0.08981000"],["78788.06000000","0.00317000"],["78789.30000000","0.00000000"],["78797.80000000","0.00416000"],["78804.21000000","0.00000000"],["78806.00000000","0.02400000"],["78809.99000000","0.00316000"],["78811.99000000","0.00000000"],["78829.31000000","0.00406000"],["78835.71000000","0.21930000"],["78876.56000000","0.00406000"],["78882.33000000","0.00000000"],["78948.17000000","0.01989000"],["78953.22000000","0.00000000"],["78973.24000000","0.00000000"],["79132.66000000","0.00000000"],["79188.00000000","0.38709000"],["79274.64000000","0.00250000"],["79528.32000000","0.00000000"],["79666.26000000","0.00000000"],["79925.96000000","0.00000000"],["80325.59000000","0.00000000"],["80727.22000000","0.00000000"],["81130.86000000","0.00000000"],["81536.51000000","0.00000000"],["81944.20000000","0.00000000"],["82353.92000000","0.00000000"],["82765.69000000","0.00000000"],["83179.51000000","0.00000000"],["83595.41000000","0.00000000"],["84013.39000000","0.00000000"],["84433.46000000","0.00000000"],["84855.62000000","0.00000000"]]}}}
{"rx_ns": 25959640700, "frame": {"stream":"btcusdt@depth20","data":{"lastUpdateId":99076507350,"bids":[["78726.38000000","1.14277000"],["78726.37000000","0.00056000"],["78726.02000000","0.00014000"],["78726.01000000","1.21959000"],["78726.00000000","0.02407000"],["78725.20000000","0.00007000"],["78724.80000000","0.00008000"],["78724.72000000","0.01748000"],["78724.00000000","0.02407000"],["78723.72000000","0.00014000"],["78723.71000000","0.20791000"],["78723.58000000","0.05015000"],["78723.54000000","0.00007000"],["78723.47000000","0.02902000"],["78723.19000000","0.00204000"],["78723.14000000","0.00406000"],["78722.91000000","0.00328000"],["78722.53000000","0.00007000"],["78722.32000000","0.00007000"],["78722.21000000","0.03482000"]],"asks":[["78726.39000000","1.59382000"],["78726.40000000","0.00013000"],["78726.41000000","0.00013000"],["78727.12000000","0.00007000"],["78727.19000000","0.00014000"],["78727.41000000","0.00014000"],["78727.64000000","0.00014000"],["78727.65000000","0.03448000"],["78727.69000000","0.00007000"],["78728.89000000","0.00254000"],["78728.90000000","0.00014000"],["78728.91000000","0.04138000"],["78729.07000000","0.00635000"],["78729.08000000","0.00014000"],["78729.09000000","0.05176000"],["78729.60000000","0.00254000"],["78729.61000000","0.00007000"],["78730.01000000","0.00007000"],["78730.16000000","0.00014000"],["78730.17000000","0.04145000"]]}}}
{"rx_ns": 25959779900, "frame": {"stream":"btcusdt@depth","data":{"e":"depthUpdate","E":1787602893014,"s":"BTCUSDT","U":99076505395,"u":99076507350,"b":[["78738.95000000","0.00000000"],["78738.94000000","0.00000000"],["78738.93000000","0.00000000"],["78738.76000000","0.00000000"],["78738.01000000","0.00000000"],["78738.00000000","0.00000000"],["78737.97000000","0.00000000"],["78737.90000000","0.00000000"],["78737.89000000","0.00000000"],["78737.54000000","0.00000000"],["78737.18000000","0.00000000"],["78736.84000000","0.00000000"],["78736.65000000","0.00000000"],["78736.64000000","0.00000000"],["78736.21000000","0.00000000"],["78736.20000000","0.00000000"],["78736.06000000","0.00000000"],["78736.01000000","0.00000000"],["78736.00000000","0.00000000"],["78735.75000000","0.00000000"],["78735.39000000","0.00000000"],["78735.38000000","0.00000000"],["78735.37000000","0.00000000"],["78735.15000000","0.00000000"],["78735.14000000","0.00000000"],["78734.82000000","0.00000000"],["78734.41000000","0.00000000"],["78734.40000000","0.00000000"],["78734.25000000","0.00000000"],["78734.15000000","0.00000000"],["78734.13000000","0.00000000"],["78734.12000000","0.00000000"],["78734.11000000","0.00000000"],["78734.01000000","0.00000000"],["78734.00000000","0.00000000"],["78733.84000000","0.00000000"],["78733.48000000","0.00000000"],["78733.22000000","0.00000000"],["78732.96000000","0.00000000"],["78732.78000000","0.00000000"],["78732.77000000","0.00000000"],["78732.63000000","0.00000000"],["78732.62000000","0.00000000"],["78732.61000000","0.00000000"],["78732.50000000","0.00000000"],["78732.47000000","0.00000000"],["78732.24000000","0.00000000"],["78732.18000000","0.00000000"],["78732.15000000","0.00000000"],["78732.14000000","0.00000000"],["78732.13000000","0.00000000"],["78732.11000000","0.00000000"],["78732.01000000","0.00000000"],["78732.00000000","0.00000000"],["78731.99000000","0.00000000"],["78731.70000000","0.00000000"],["78731.34000000","0.00000000"],["78731.31000000","0.00000000"],["78731.28000000","0.00000000"],["78730.86000000","0.00000000"],["78730.72000000","0.00000000"],["78730.33000000","0.00000000"],["78730.17000000","0.00000000"],["78730.16000000","0.00000000"],["78730.01000000","0.00000000"],["78730.00000000","0.00000000"],["78729.72000000","0.00000000"],["78729.60000000","0.00000000"],["78729.49000000","0.00000000"],["78729.08000000","0.00000000"],["78729.00000000","0.00000000"],["78728.67000000","0.00000000"],["78728.44000000","0.00000000"],["78728.33000000","0.00000000"],["78728.01000000","0.00000000"],["78728.00000000","0.00000000"],["78727.99000000","0.00000000"],["78727.69000000","0.00000000"],["78727.68000000","0.00000000"],["78727.61000000","0.00000000"],["78727.41000000","0.00000000"],["78727.28000000","0.00000000"],["78727.18000000","0.00000000"],["78726.76000000","0.00000000"],["78726.63000000","0.00000000"],["78726.38000000","1.14277000"],["78726.37000000","0.00056000"],["78726.24000000","0.00000000"],["78726.02000000","0.00014000"],["78726.01000000","1.21959000"],["78726.00000000","0.02407000"],["78725.70000000","0.00000000"],["78725.69000000","0.00000000"],["78725.47000000","0.00000000"],["78725.46000000","0.00000000"],["78725.38000000","0.00000000"],["78725.21000000","0.00000000"],["78725.14000000","0.00000000"],["78724.72000000","0.01748000"],["78724.58000000","0.00000000"],["78724.54000000","0.00000000"],["78724.49000000","0.00000000"],["78724.39000000","0.00000000"],["78724.38000000","0.00000000"],["78724.33000000","0.00000000"],["78724.26000000","0.00000000"],["78724.03000000","0.00000000"],["78724.00000000","0.02407000"],["78723.84000000","0.00000000"],["78723.72000000","0.00014000"],["78723.71000000","0.20791000"],["78723.67000000","0.00000000"],["78723.66000000","0.00000000"],["78723.60000000","0.00000000"],["78723.59000000","0.00000000"],["78723.58000000","0.05015000"],["78723.54000000","0.00007000"],["78723.49000000","0.00000000"],["78723.48000000","0.00000000"],["78723.47000000","0.02902000"],["78723.46000000","0.00000000"],["78723.34000000","0.00000000"],["78723.33000000","0.00000000"],["78723.32000000","0.00000000"],["78723.31000000","0.00000000"],["78723.19000000","0.00204000"],["78723.14000000","0.00406000"],["78722.91000000","0.00328000"],["78722.88000000","0.00000000"],["78722.87000000","0.00000000"],["78722.73000000","0.00000000"],["78722.21000000","0.03482000"],["78722.00000000","0.02414000"],["78721.84000000","0.00254000"],["78721.73000000","0.00000000"],["78721.72000000","0.00000000"],["78721.36000000","0.02293000"],["78721.25000000","0.00014000"],["78721.24000000","1.21959000"],["78720.95000000","0.03482000"],["78720.88000000","0.00000000"],["78720.06000000","0.02515000"],["78720.00000000","0.02407000"],["78719.67000000","0.00014000"],["78719.41000000","0.00014000"],["78719.40000000","0.36224000"],["78719.36000000","0.00007000"],["78719.35000000","1.90515000"],["78718.83000000","0.00000000"],["78718.78000000","0.00000000"],["78718.45000000","0.00000000"],["78718.18000000","0.00635000"],["78718.03000000","0.00000000"],["78718.01000000","0.00000000"],["78717.77000000","0.00048000"],["78717.73000000","0.00000000"],["78717.58000000","0.00000000"],["78717.36000000","0.08576000"],["78717.28000000","0.03000000"],["78717.11000000","0.00000000"],["78716.39000000","0.00007000"],["78716.08000000","0.00000000"],["78715.97000000","0.00254000"],["78715.58000000","0.00000000"],["78715.28000000","0.00007000"],["78715.24000000","0.00000000"],["78715.23000000","0.00000000"],["78715.05000000","0.00000000"],["78715.01000000","0.00400000"],["78714.58000000","0.00000000"],["78714.45000000","0.00635000"],["78714.44000000","0.00163000"],["78714.31000000","0.00000000"],["78714.14000000","0.00000000"],["78714.13000000","1.92515000"],["78713.64000000","0.00000000"],["78713.58000000","0.04000000"],["78713.33000000","0.00000000"],["78713.28000000","0.00000000"],["78713.05000000","0.00000000"],["78712.84000000","0.00000000"],["78712.38000000","0.00000000"],["78712.33000000","0.00000000"],["78712.18000000","0.08000000"],["78711.50000000","0.00000000"],["78711.49000000","0.36224000"],["78711.36000000","0.00400000"],["78711.08000000","0.00000000"],["78710.69000000","0.12704000"],["78710.20000000","0.00000000"],["78709.24000000","0.00000000"],["78708.05000000","1.21925000"],["78707.67000000","0.00000000"],["78706.22000000","0.06557000"],["78706.17000000","0.13242000"],["78706.01000000","0.00000000"],["78704.26000000","0.07572000"],["78704.20000000","0.00000000"],["78703.88000000","0.00000000"],["78703.47000000","0.00653000"],["78702.09000000","0.00000000"],["78701.48000000","0.00000000"],["78700.91000000","0.00000000"],["78700.63000000","0.13745000"],["78700.00000000","0.10811000"],["78699.90000000","0.00012000"],["78699.68000000","0.00000000"],["78699.61000000","0.13093000"],["78699.10000000","0.00000000"],["78699.00000000","0.00000000"],["78698.59000000","0.00000000"],["78698.26000000","0.00000000"],["78697.62000000","0.00000000"],["78697.56000000","0.00400000"],["78697.00000000","0.00000000"],["78696.85000000","0.00635000"],["78696.45000000","0.00014000"],["78696.00000000","0.02400000"],["78695.59000000","0.00400000"],["78695.00000000","0.00000000"],["78694.68000000","0.00000000"],["78694.54000000","0.00000000"],["78694.30000000","0.02446000"],["78694.00000000","0.02415000"],["78693.62000000","0.00400000"],["78693.59000000","0.34314000"],["78693.15000000","0.00000000"],["78692.58000000","0.00014000"],["78692.55000000","0.00000000"],["78692.30000000","0.00000000"],["78691.65000000","0.00400000"],["78691.55000000","0.00000000"],["78691.21000000","0.00000000"],["78689.91000000","0.00000000"],["78689.11000000","0.63549000"],["78688.71000000","0.00014000"],["78687.71000000","0.00400000"],["78687.58000000","0.00000000"],["78687.00000000","0.01007000"],["78686.57000000","0.34317000"],["78686.01000000","0.00000000"],["78685.69000000","0.00000000"],["78685.34000000","0.00000000"],["78684.97000000","0.00000000"],["78684.86000000","0.21930000"],["78684.84000000","0.00007000"],["78683.77000000","0.00406000"],["78683.55000000","0.00000000"],["78683.44000000","0.00000000"],["78683.08000000","0.00000000"],["78682.79000000","0.00000000"],["78682.65000000","0.00000000"],["78681.80000000","0.88155000"],["78681.70000000","0.04493000"],["78681.46000000","0.00000000"],["78681.32000000","0.02200000"],["78681.11000000","0.00000000"],["78680.97000000","0.00000000"],["78680.94000000","0.00000000"],["78680.90000000","0.00000000"],["78680.76000000","0.00000000"],["78680.43000000","0.00000000"],["78679.57000000","0.00000000"],["78679.22000000","0.00000000"],["78679.21000000","0.00000000"],["78679.00000000","0.00000000"],["78678.95000000","0.00000000"],["78678.77000000","0.02722000"],["78677.52000000","0.00007000"],["78677.50000000","0.00000000"],["78677.21000000","0.00000000"],["78676.13000000","0.00000000"],["78674.83000000","0.00000000"],["78673.27000000","0.00000000"],["78671.22000000","0.00000000"],["78669.92000000","0.00436000"],["78667.51000000","0.00426000"],["78666.63000000","0.00429000"],["78666.12000000","0.00014000"],["78666.00000000","0.02407000"],["78664.44000000","0.00317000"],["78661.19000000","0.86785000"],["78661.05000000","0.02600000"],["78660.36000000","1.25873000"],["78656.01000000","0.00000000"],["78655.68000000","0.00000000"],["78655.08000000","0.00000000"],["78654.52000000","0.00000000"],["78652.55000000","0.01727000"],["78652.01000000","0.00000000"],["78651.95000000","0.00000000"],["78650.13000000","0.00000000"],["78649.70000000","0.00111000"],["78649.18000000","0.00000000"],["78642.27000000","0.00314000"],["78636.00000000","0.02400000"],["78634.74000000","0.00000000"],["78628.87000000","0.00000000"],["78624.32000000","0.00007000"],["78623.79000000","0.00400000"],["78608.69000000","0.04545000"],["78607.29000000","0.00000000"],["78605.05000000","0.00406000"],["78601.36000000","0.00000000"],["78598.24000000","0.00000000"],["78596.01000000","0.00127000"],["78582.73000000","0.00000000"],["78577.60000000","0.00000000"],["78573.49000000","0.00000000"],["78564.04000000","0.00127000"],["78563.96000000","1.20632000"],["78540.76000000","0.00000000"],["78536.43000000","0.00000000"],["78534.20000000","0.00406000"],["78520.06000000","0.00007000"],["78516.13000000","0.00007000"],["78512.20000000","0.00007000"],["78508.27000000","0.00007000"],["78503.59000000","2.88324000"],["78482.25000000","0.00007000"],["78414.17000000","7.65263000"],["78409.99000000","0.00000000"],["78400.02000000","0.00033000"],["78345.25000000","0.00000000"],["78031.34000000","0.00000000"],["77953.52000000","0.00000000"],["77563.76000000","0.00000000"],["77175.94000000","0.00000000"],["76790.06000000","0.00000000"],["76406.11000000","0.00000000"],["76024.08000000","0.00000000"],["75643.96000000","0.00000000"],["75265.74000000","0.00000000"],["74889.41000000","0.00000000"],["74514.96000000","0.00000000"],["74142.39000000","0.00000000"],["73771.67000000","0.00000000"],["73402.82000000","0.00018000"],["73035.80000000","0.00000000"],["72460.16000000","0.00014000"],["70865.06000000","0.00000000"],["70865.05000000","0.00009000"],["70865.00000000","0.00000000"],["70853.75000000","0.00032000"],["62992.00000000","0.00000000"],["62991.16000000","0.00000000"],["62981.11000000","0.00031000"]],"a":[["78726.39000000","1.59382000"],["78726.40000000","0.00013000"],["78726.41000000","0.00013000"],["78726.64000000","0.00000000"],["78727.11000000","0.00000000"],["78727.12000000","0.00007000"],["78727.17000000","0.00000000"],["78727.18000000","0.00000000"],["78727.19000000","0.00014000"],["78727.20000000","0.00000000"],["78727.21000000","0.00000000"],["78727.41000000","0.00014000"],["78727.64000000","0.00014000"],["78727.65000000","0.03448000"],["78727.68000000","0.00000000"],["78727.69000000","0.00007000"],["78728.01000000","0.00000000"],["78728.78000000","0.00000000"],["78728.89000000","0.00254000"],["78728.90000000","0.00014000"],["78728.91000000","0.04138000"],["78729.07000000","0.00635000"],["78729.08000000","0.00014000"],["78729.09000000","0.05176000"],["78729.60000000","0.00254000"],["78729.61000000","0.00007000"],["78730.00000000","0.00000000"],["78730.01000000","0.00007000"],["78730.16000000","0.00014000"],["78730.17000000","0.04145000"],["78730.59000000","0.00014000"],["78730.60000000","0.25421000"],["78731.04000000","0.31762000"],["78731.05000000","0.00400000"],["78731.07000000","0.00000000"],["78731.08000000","0.00007000"],["78731.28000000","0.00014000"],["78731.71000000","0.00254000"],["78731.81000000","0.00000000"],["78731.82000000","0.02000000"],["78731.97000000","0.00000000"],["78731.98000000","0.38100000"],["78732.00000000","0.00000000"],["78732.01000000","0.00007000"],["78732.12000000","0.00007000"],["78732.13000000","0.00000000"],["78732.14000000","0.00007000"],["78732.15000000","0.00007000"],["78732.62000000","0.00007000"],["78732.79000000","0.00007000"],["78733.02000000","0.00400000"],["78733.85000000","0.00007000"],["78734.01000000","0.00000000"],["78734.02000000","0.00007000"],["78734.11000000","0.00000000"],["78734.12000000","0.07507000"],["78734.13000000","0.52606000"],["78734.14000000","0.00000000"],["78734.15000000","0.00000000"],["78734.16000000","0.00000000"],["78734.26000000","0.00000000"],["78734.41000000","0.00007000"],["78734.42000000","0.00014000"],["78734.83000000","0.00000000"],["78734.99000000","0.00400000"],["78735.15000000","0.07521000"],["78735.16000000","0.14303000"],["78735.17000000","0.00000000"],["78735.18000000","0.00000000"],["78735.38000000","0.00000000"],["78735.39000000","0.41335000"],["78735.40000000","0.00000000"],["78735.41000000","0.00000000"],["78735.76000000","0.00007000"],["78736.00000000","0.00014000"],["78736.01000000","0.00007000"],["78736.02000000","0.11389000"],["78736.07000000","0.00000000"],["78736.19000000","0.00000000"],["78736.20000000","0.00000000"],["78736.21000000","0.32264000"],["78736.22000000","0.00000000"],["78736.64000000","0.00000000"],["78736.65000000","0.60861000"],["78736.66000000","0.00000000"],["78736.85000000","0.00000000"],["78736.86000000","0.00000000"],["78736.89000000","0.00000000"],["78736.96000000","0.00400000"],["78737.01000000","0.00007000"],["78737.18000000","0.00000000"],["78737.19000000","0.09916000"],["78737.20000000","0.00000000"],["78737.21000000","0.04112000"],["78737.22000000","0.00100000"],["78737.45000000","0.00000000"],["78737.55000000","0.00000000"],["78737.57000000","0.00007000"],["78737.68000000","0.00007000"],["78737.90000000","0.00000000"],["78737.98000000","0.00000000"],["78738.01000000","0.00000000"],["78738.02000000","0.00000000"],["78738.12000000","0.00000000"],["78738.20000000","0.00000000"],["78738.48000000","0.00000000"],["78738.59000000","0.00000000"],["78738.69000000","0.00000000"],["78738.74000000","0.00000000"],["78738.77000000","0.00000000"],["78738.92000000","0.00000000"],["78738.93000000","0.00400000"],["78738.94000000","0.00000000"],["78738.95000000","0.15824000"],["78738.96000000","0.20506000"],["78738.97000000","0.00000000"],["78738.98000000","0.00000000"],["78738.99000000","0.00000000"],["78739.00000000","0.06350000"],["78739.02000000","0.00014000"],["78739.17000000","0.00000000"],["78739.18000000","0.00000000"],["78739.73000000","0.00152000"],["78739.92000000","0.00000000"],["78739.98000000","0.00455000"],["78739.99000000","3.12467000"],["78740.00000000","0.00000000"],["78740.01000000","0.22743000"],["78740.04000000","0.00000000"],["78740.05000000","0.00000000"],["78740.20000000","0.00008000"],["78740.25000000","0.00000000"],["78740.26000000","0.26500000"],["78740.44000000","0.00000000"],["78740.45000000","0.58742000"],["78740.72000000","0.00007000"],["78740.94000000","0.00007000"],["78740.95000000","0.00000000"],["78741.27000000","0.36224000"],["78741.28000000","0.58542000"],["78741.65000000","0.12699000"],["78741.67000000","0.00318000"],["78741.70000000","0.00000000"],["78741.71000000","0.00000000"],["78741.90000000","0.00000000"],["78742.14000000","0.10323000"],["78742.59000000","0.00253000"],["78742.96000000","0.00000000"],["78743.01000000","0.02161000"],["78743.38000000","0.38103000"],["78743.40000000","0.00000000"],["78743.41000000","0.00224000"],["78743.53000000","0.04103000"],["78743.87000000","0.00000000"],["78743.95000000","0.00007000"],["78744.41000000","0.02285000"],["78744.60000000","0.00007000"],["78745.42000000","0.00000000"],["78745.93000000","0.00000000"],["78745.96000000","0.00000000"],["78746.44000000","0.00000000"],["78746.45000000","1.90515000"],["78746.68000000","0.00000000"],["78746.77000000","0.00007000"],["78747.02000000","0.00000000"],["78747.25000000","0.00000000"],["78747.30000000","0.00000000"],["78747.36000000","0.06553000"],["78747.50000000","0.00000000"],["78748.00000000","0.02400000"],["78748.01000000","0.00007000"],["78748.48000000","0.02007000"],["78748.51000000","0.00000000"],["78748.85000000","0.00000000"],["78749.32000000","0.07568000"],["78750.00000000","0.10540000"],["78750.01000000","0.22576000"],["78750.17000000","0.00000000"],["78750.26000000","0.00000000"],["78750.41000000","0.00127000"],["78750.58000000","0.00010000"],["78751.85000000","0.00000000"],["78751.96000000","0.00000000"],["78753.32000000","0.00000000"],["78753.77000000","0.00000000"],["78754.71000000","0.00000000"],["78755.28000000","0.00007000"],["78755.33000000","0.00060000"],["78755.89000000","0.09721000"],["78756.07000000","0.00000000"],["78756.16000000","0.00192000"],["78756.63000000","0.00000000"],["78757.00000000","0.00000000"],["78757.89000000","0.00000000"],["78758.85000000","0.00000000"],["78759.42000000","0.00000000"],["78760.62000000","0.00000000"],["78760.63000000","0.00000000"],["78760.64000000","0.00000000"],["78760.80000000","0.00000000"],["78761.00000000","0.00000000"],["78761.98000000","0.00000000"],["78762.31000000","0.38912000"],["78762.54000000","0.00007000"],["78762.57000000","0.00000000"],["78763.86000000","0.00000000"],["78764.51000000","0.02821000"],["78765.87000000","0.00000000"],["78766.00000000","0.03400000"],["78766.11000000","0.00000000"],["78766.37000000","0.00000000"],["78767.13000000","0.00000000"],["78767.67000000","0.67584000"],["78767.85000000","0.00000000"],["78767.88000000","0.00000000"],["78769.37000000","0.00000000"],["78769.89000000","0.00000000"],["78769.98000000","0.00000000"],["78770.06000000","0.00000000"],["78770.74000000","0.00000000"],["78771.05000000","0.00000000"],["78771.42000000","1.21925000"],["78773.05000000","0.02528000"],["78773.25000000","0.00430000"],["78773.85000000","0.00000000"],["78773.88000000","0.00000000"],["78774.31000000","0.00435000"],["78777.00000000","0.00000000"],["78777.72000000","0.00000000"],["78778.50000000","0.35097000"],["78779.00000000","0.00000000"],["78779.33000000","0.00000000"],["78780.00000000","0.02400000"],["78781.05000000","0.87844000"],["78781.23000000","0.86653000"],["78781.42000000","0.00000000"],["78782.52000000","0.00000000"],["78783.47000000","0.00316000"],["78787.77000000","0.00000000"],["78788.06000000","0.00000000"],["78788.07000000","0.00000000"],["78791.28000000","0.00000000"],["78792.14000000","0.00000000"],["78792.71000000","0.00000000"],["78794.19000000","0.00000000"],["78794.46000000","0.01705000"],["78794.79000000","0.00000000"],["78794.81000000","0.00000000"],["78795.03000000","0.00000000"],["78795.77000000","0.00000000"],["78798.99000000","0.00274000"],["78800.23000000","0.00000000"],["78800.35000000","0.00000000"],["78801.22000000","0.00000000"],["78807.88000000","0.00317000"],["78809.53000000","0.00000000"],["78809.89000000","0.09419000"],["78809.99000000","0.00000000"],["78827.83000000","0.00000000"],["78829.89000000","0.00000000"],["78832.46000000","0.04591000"],["78835.71000000","0.00000000"],["78836.59000000","0.00025000"],["78837.64000000","0.00000000"],["78843.77000000","0.00000000"],["78862.88000000","0.00000000"],["78944.43000000","2.43915000"],["78946.33000000","0.00000000"],["78947.45000000","0.00406000"],["78950.26000000","0.00000000"],["78953.28000000","0.00000000"],["78955.53000000","0.00000000"],["78981.82000000","0.00000000"],["78996.11000000","0.00000000"],["79131.60000000","0.00000000"],["79132.66000000","0.01000000"],["79528.32000000","0.01000000"],["79925.96000000","0.01000000"],["80000.00000000","103.82268000"],["80325.59000000","0.01000000"],["80727.22000000","0.01000000"],["81130.86000000","0.01000000"],["81536.51000000","0.01000000"],["81944.20000000","0.01000000"],["82353.92000000","0.01000000"],["82587.15000000","0.00000000"],["82617.91000000","0.00000000"],["82672.95000000","0.00010000"],["82674.05000000","0.00020000"],["82674.06000000","0.00010000"],["82688.34000000","0.00000000"],["82689.61000000","0.00000000"],["82765.69000000","0.01000000"],["83179.51000000","0.01000000"],["83595.41000000","0.01000000"],["84013.39000000","0.01000000"],["84433.46000000","0.01000000"],["84855.62000000","0.01000000"]]}}}
{"rx_ns": 26952742400, "frame": {"stream":"btcusdt@depth20","data":{"lastUpdateId":99076507782,"bids":[["78726.38000000","3.02736000"],["78726.37000000","0.00056000"],["78726.02000000","0.00014000"],["78726.01000000","1.21959000"],["78726.00000000","0.02407000"],["78725.39000000","0.00007000"],["78725.20000000","0.00007000"],["78724.80000000","0.00008000"],["78724.72000000","0.01748000"],["78724.60000000","0.00007000"],["78724.00000000","0.02407000"],["78723.58000000","0.05022000"],["78723.54000000","0.00007000"],["78723.47000000","0.02909000"],["78723.03000000","0.00007000"],["78722.91000000","0.00328000"],["78722.53000000","0.00007000"],["78722.32000000","0.00007000"],["78722.21000000","0.03489000"],["78722.00000000","0.02414000"]],"asks":[["78726.39000000","1.84523000"],["78726.40000000","0.00020000"],["78726.41000000","0.00013000"],["78727.19000000","0.00014000"],["78727.41000000","0.00014000"],["78727.64000000","0.00014000"],["78727.65000000","0.03455000"],["78727.69000000","0.00007000"],["78728.90000000","0.00014000"],["78728.91000000","0.04145000"],["78729.08000000","0.00014000"],["78729.09000000","0.05190000"],["78729.31000000","0.00007000"],["78729.61000000","0.00007000"],["78730.01000000","0.00007000"],["78730.16000000","0.00014000"],["78730.17000000","0.04152000"],["78730.60000000","0.00007000"],["78731.05000000","0.00400000"],["78731.28000000","0.00014000"]]}}}
{"rx_ns": 26952909200, "frame": {"stream":"btcusdt@depth","data":{"e":"depthUpdate","E":1787602894014,"s":"BTCUSDT","U":99076507351,"u":99076507782,"b":[["78726.38000000","3.02736000"],["78726.37000000","0.00056000"],["78726.00000000","0.02407000"],["78725.39000000","0.00007000"],["78724.72000000","0.01748000"],["78724.60000000","0.00007000"],["78724.00000000","0.02407000"],["78723.72000000","0.00000000"],["78723.71000000","0.00000000"],["78723.58000000","0.05022000"],["78723.47000000","0.02909000"],["78723.19000000","0.00000000"],["78723.14000000","0.00000000"],["78723.03000000","0.00007000"],["78722.21000000","0.03489000"],["78722.00000000","0.02414000"],["78721.36000000","0.02286000"],["78721.24000000","1.21952000"],["78720.14000000","0.00000000"],["78720.00000000","0.02400000"],["78719.88000000","0.00000000"],["78719.67000000","0.00014000"],["78718.82000000","0.00000000"],["78718.51000000","0.00645000"],["78718.18000000","0.00000000"],["78718.00000000","0.02400000"],["78717.77000000","0.00000000"],["78717.18000000","0.00000000"],["78717.05000000","0.00000000"],["78716.94000000","0.00000000"],["78716.77000000","0.00400000"],["78716.69000000","0.00635000"],["78715.97000000","0.00000000"],["78715.38000000","0.03224000"],["78715.28000000","0.00000000"],["78715.01000000","0.00000000"],["78714.45000000","0.00000000"],["78713.56000000","0.00007000"],["78712.91000000","0.00007000"],["78710.63000000","0.00007000"],["78707.01000000","0.00007000"],["78705.80000000","0.04439000"],["78705.26000000","0.00400000"],["78704.01000000","0.00000000"],["78702.85000000","0.16549000"],["78702.84000000","0.51730000"],["78702.72000000","0.00007000"],["78701.94000000","0.12706000"],["78700.63000000","0.00000000"],["78691.01000000","0.00000000"],["78689.68000000","0.00000000"],["78687.71000000","0.00000000"],["78685.23000000","0.63552000"],["78683.77000000","0.00000000"],["78683.13000000","0.34319000"],["78681.70000000","0.00000000"],["78678.77000000","0.00000000"],["78678.54000000","0.00000000"],["78678.41000000","0.00000000"],["78678.05000000","0.02739000"],["78676.88000000","0.00000000"],["78676.65000000","0.00000000"],["78676.24000000","0.00000000"],["78673.72000000","0.00406000"],["78658.25000000","1.25876000"],["78652.28000000","0.00000000"],["78621.04000000","2.77104000"],["78605.05000000","0.00000000"],["78601.29000000","0.04091000"],["78541.91000000","0.00000000"],["78541.90000000","0.00778000"],["78536.01000000","0.01999000"],["78534.20000000","0.00000000"],["78524.16000000","0.00406000"],["78515.17000000","0.01989000"],["78510.34000000","0.00000000"],["78509.99000000","0.00000000"],["78332.74000000","0.01000000"],["78017.84000000","0.00010000"],["77941.08000000","0.01000000"],["77551.37000000","0.01000000"],["77163.62000000","0.01000000"],["76777.80000000","0.01000000"],["76393.91000000","0.01000000"],["76011.94000000","0.01000000"],["75631.88000000","0.01000000"],["75253.72000000","0.01000000"],["74877.45000000","0.01019000"],["74503.07000000","0.01000000"],["74130.55000000","0.01000000"],["73759.90000000","0.01000000"],["73391.10000000","0.01000000"],["73024.14000000","0.01000000"],["72460.16000000","0.00000000"],["70865.05000000","0.00000000"],["70853.75000000","0.00176000"],["70853.00000000","0.00000000"],["62981.11000000","0.00031000"],["62981.10000000","0.00000000"],["62981.00000000","0.00031000"]],"a":[["78726.39000000","1.84523000"],["78726.40000000","0.00020000"],["78727.12000000","0.00000000"],["78727.65000000","0.03455000"],["78728.89000000","0.00000000"],["78728.91000000","0.04145000"],["78729.07000000","0.00000000"],["78729.09000000","0.05190000"],["78729.31000000","0.00007000"],["78729.59000000","0.00000000"],["78729.60000000","0.00000000"],["78730.17000000","0.04152000"],["78730.58000000","0.00000000"],["78730.59000000","0.00000000"],["78730.60000000","0.00007000"],["78731.04000000","0.00000000"],["78731.08000000","0.00000000"],["78731.27000000","0.00000000"],["78731.71000000","0.00000000"],["78731.80000000","0.00000000"],["78731.81000000","0.00000000"],["78731.82000000","0.00000000"],["78731.98000000","0.00000000"],["78732.00000000","0.01015000"],["78732.67000000","0.00000000"],["78732.78000000","0.00642000"],["78732.79000000","0.00007000"],["78733.00000000","0.00000000"],["78733.01000000","0.00000000"],["78733.42000000","0.00007000"],["78733.43000000","0.12708000"],["78733.51000000","0.00007000"],["78733.52000000","0.02007000"],["78733.74000000","0.00000000"],["78734.00000000","0.00500000"],["78734.11000000","0.31760000"],["78734.12000000","0.07500000"],["78734.13000000","0.52599000"],["78734.81000000","0.00007000"],["78734.98000000","0.00000000"],["78735.15000000","0.07514000"],["78735.16000000","0.14296000"],["78735.39000000","0.19398000"],["78735.54000000","0.25400000"],["78735.84000000","0.00325000"],["78736.01000000","0.00000000"],["78736.02000000","0.11576000"],["78736.08000000","0.00000000"],["78736.20000000","0.00400000"],["78736.21000000","0.10327000"],["78736.33000000","0.38100000"],["78736.65000000","0.04453000"],["78736.84000000","0.00007000"],["78736.85000000","0.00007000"],["78737.21000000","0.00000000"],["78737.22000000","0.00000000"],["78738.96000000","0.00000000"],["78739.00000000","0.00000000"],["78739.61000000","0.00322000"],["78739.99000000","1.90515000"],["78740.72000000","0.00014000"],["78741.08000000","0.00000000"],["78741.11000000","0.00000000"],["78742.01000000","0.21930000"],["78742.14000000","0.10330000"],["78742.71000000","0.00010000"],["78743.37000000","1.21952000"],["78743.49000000","0.02000000"],["78744.28000000","0.02000000"],["78744.30000000","0.02000000"],["78748.44000000","0.02515000"],["78749.96000000","0.00007000"],["78753.95000000","0.00000000"],["78754.21000000","0.38912000"],["78754.49000000","0.43576000"],["78754.72000000","0.00000000"],["78755.34000000","0.00000000"],["78755.51000000","0.00000000"],["78755.76000000","0.00000000"],["78755.99000000","0.00000000"],["78758.42000000","0.00000000"],["78760.12000000","0.00000000"],["78762.31000000","0.00000000"],["78762.54000000","0.00000000"],["78763.76000000","0.10000000"],["78764.14000000","0.00000000"],["78770.87000000","0.00000000"],["78797.80000000","0.00010000"],["78801.59000000","0.00000000"],["78805.66000000","0.00000000"],["78818.22000000","0.00406000"],["78827.83000000","0.21930000"],["78829.31000000","0.00000000"],["78830.98000000","0.00012000"],["78837.11000000","0.00019000"],["78843.21000000","0.00038000"],["78844.61000000","0.00000000"],["78850.75000000","0.00000000"],["78853.63000000","0.01989000"],["78856.85000000","0.00000000"],["78864.88000000","0.00000000"],["78865.47000000","0.00406000"],["78876.56000000","0.00000000"],["78885.48000000","0.00000000"],["78924.92000000","0.00000000"],["78943.77000000","0.00000000"],["78947.45000000","0.00000000"],["78986.07000000","0.00037000"],["79120.03000000","0.01000000"],["79132.66000000","0.00000000"],["79515.63000000","0.01000000"],["79528.32000000","0.00000000"],["79913.21000000","0.01000000"],["79925.96000000","0.00000000"],["80312.77000000","0.01000000"],["80325.59000000","0.00000000"],["80714.34000000","0.01013000"],["80727.22000000","0.00000000"],["81117.91000000","0.01000000"],["81130.86000000","0.00000000"],["81523.50000000","0.01000000"],["81536.51000000","0.00000000"],["81931.11000000","0.01000000"],["81944.20000000","0.00000000"],["82340.77000000","0.01020000"],["82353.92000000","0.00000000"],["82752.47000000","0.01000000"],["82765.69000000","0.00000000"],["83166.24000000","0.01000000"],["83179.51000000","0.00000000"],["83582.07000000","0.01000000"],["83595.41000000","0.00000000"],["83999.98000000","0.01015000"],["84013.39000000","0.00000000"],["84419.98000000","0.01000000"],["84433.46000000","0.00000000"],["84842.08000000","0.01000000"],["84855.62000000","0.00000000"]]}}}
{"rx_ns": 27957791600, "frame": {"stream":"btcusdt@depth20","data":{"lastUpdateId":99076508235,"bids":[["78726.38000000","3.26766000"],["78726.37000000","0.00069000"],["78726.36000000","0.00013000"],["78726.11000000","0.00014000"],["78726.10000000","0.20798000"],["78726.02000000","0.00014000"],["78726.01000000","1.21959000"],["78726.00000000","0.02407000"],["78725.72000000","0.00204000"],["78725.39000000","0.00007000"],["78725.20000000","0.00007000"],["78724.80000000","0.00008000"],["78724.72000000","0.01748000"],["78724.60000000","0.00007000"],["78724.00000000","0.02407000"],["78723.58000000","0.05022000"],["78723.54000000","0.00014000"],["78723.47000000","0.02909000"],["78723.44000000","0.00400000"],["78723.03000000","0.00007000"]],"asks":[["78726.39000000","1.42473000"],["78726.40000000","0.00020000"],["78726.41000000","0.00013000"],["78727.17000000","0.00014000"],["78727.18000000","0.31773000"],["78727.19000000","0.00014000"],["78727.41000000","0.00014000"],["78727.64000000","0.00014000"],["78727.65000000","0.03455000"],["78727.69000000","0.00007000"],["78727.74000000","0.00007000"],["78727.84000000","0.01277000"],["78727.87000000","0.00014000"],["78727.88000000","0.06357000"],["78728.90000000","0.00014000"],["78728.91000000","0.04145000"],["78729.08000000","0.00014000"],["78729.09000000","0.05176000"],["78729.31000000","0.00007000"],["78729.61000000","0.00007000"]]}}}
{"rx_ns": 27957894600, "frame": {"stream":"btcusdt@depth","data":{"e":"depthUpdate","E":1787602895015,"s":"BTCUSDT","U":99076507783,"u":99076508235,"b":[["78726.38000000","3.26766000"],["78726.37000000","0.00069000"],["78726.36000000","0.00013000"],["78726.11000000","0.00014000"],["78726.10000000","0.20798000"],["78726.00000000","0.02407000"],["78725.72000000","0.00204000"],["78725.40000000","0.00000000"],["78723.58000000","0.05022000"],["78723.54000000","0.00014000"],["78723.47000000","0.02909000"],["78723.44000000","0.00400000"],["78722.57000000","0.00000000"],["78722.43000000","0.00000000"],["78722.22000000","0.00000000"],["78722.21000000","0.03482000"],["78722.00000000","0.02407000"],["78721.44000000","0.00000000"],["78720.90000000","0.00000000"],["78720.64000000","0.00000000"],["78720.25000000","0.00635000"],["78719.41000000","0.00007000"],["78719.36000000","0.00000000"],["78719.24000000","0.00635000"],["78718.51000000","0.00010000"],["78718.13000000","0.02000000"],["78717.89000000","0.00000000"],["78717.07000000","0.00000000"],["78716.77000000","0.00000000"],["78716.69000000","0.00000000"],["78716.27000000","0.00000000"],["78716.06000000","0.00000000"],["78715.30000000","0.00000000"],["78714.63000000","0.00000000"],["78714.48000000","0.00000000"],["78714.45000000","0.00000000"],["78714.42000000","0.00400000"],["78714.13000000","1.90515000"],["78713.08000000","0.00406000"],["78705.81000000","0.34309000"],["78704.27000000","0.15146000"],["78702.85000000","0.00000000"],["78702.72000000","0.00007000"],["78701.95000000","0.00000000"],["78700.63000000","0.00000000"],["78698.93000000","0.63541000"],["78691.65000000","0.00000000"],["78690.94000000","0.09698000"],["78685.23000000","0.00000000"],["78684.84000000","0.00000000"],["78683.13000000","0.00000000"],["78681.66000000","0.00000000"],["78676.16000000","0.02436000"],["78670.65000000","0.00620000"],["78642.23000000","0.00406000"],["78596.01000000","0.00000000"],["78585.06000000","0.00127000"],["78585.05000000","0.00000000"],["78332.74000000","0.01000000"],["77941.08000000","0.01000000"],["77727.94000000","0.00000000"],["77551.37000000","0.01000000"],["77255.90000000","0.00000000"],["77163.62000000","0.01000000"],["76783.87000000","0.00000000"],["76777.80000000","0.01000000"],["76393.91000000","0.01000000"],["76311.84000000","0.00007000"],["76011.94000000","0.01000000"],["75839.81000000","0.00000000"],["75631.88000000","0.01000000"],["75367.78000000","0.00000000"],["75253.72000000","0.01000000"],["74895.74000000","0.00000000"],["74877.45000000","0.01019000"],["74503.07000000","0.01000000"],["74423.71000000","0.00000000"],["74130.55000000","0.01000000"],["73951.68000000","0.00000000"],["73759.90000000","0.01000000"],["73479.65000000","0.00000000"],["73391.10000000","0.01000000"],["73024.14000000","0.01000000"],["70853.75000000","0.00256000"],["70853.74000000","0.00009000"],["70853.00000000","0.00000000"],["62981.11000000","0.00031000"],["62981.10000000","0.00000000"],["62981.00000000","0.00031000"]],"a":[["78726.39000000","1.42473000"],["78727.17000000","0.00014000"],["78727.18000000","0.31773000"],["78727.65000000","0.03455000"],["78727.74000000","0.00007000"],["78727.84000000","0.01277000"],["78727.87000000","0.00014000"],["78727.88000000","0.06357000"],["78729.09000000","0.05176000"],["78729.30000000","0.00000000"],["78729.99000000","0.00000000"],["78730.00000000","0.00000000"],["78730.16000000","0.00000000"],["78730.17000000","0.04145000"],["78730.19000000","0.00323000"],["78730.60000000","0.00000000"],["78731.04000000","0.00000000"],["78731.77000000","0.00329000"],["78731.80000000","0.00000000"],["78731.98000000","0.00000000"],["78731.99000000","0.00254000"],["78732.00000000","0.01207000"],["78732.01000000","0.00000000"],["78732.12000000","0.00000000"],["78732.14000000","0.00000000"],["78732.15000000","0.00000000"],["78732.62000000","0.00000000"],["78732.75000000","0.00000000"],["78732.76000000","0.00007000"],["78732.77000000","0.00000000"],["78732.78000000","0.00000000"],["78732.79000000","0.00000000"],["78732.80000000","0.00000000"],["78733.41000000","0.00254000"],["78733.42000000","0.00000000"],["78733.43000000","0.12701000"],["78733.51000000","0.00000000"],["78733.52000000","0.02000000"],["78733.63000000","0.00000000"],["78733.85000000","0.00000000"],["78733.98000000","0.02161000"],["78733.99000000","0.00000000"],["78734.00000000","0.01200000"],["78734.02000000","0.00000000"],["78734.11000000","0.00000000"],["78734.12000000","0.00000000"],["78734.13000000","0.51971000"],["78734.41000000","0.00000000"],["78734.42000000","0.00007000"],["78734.98000000","0.31760000"],["78735.14000000","0.00000000"],["78735.15000000","0.00021000"],["78735.16000000","0.14296000"],["78735.39000000","0.19391000"],["78735.71000000","0.00321000"],["78735.76000000","0.00000000"],["78735.83000000","0.00635000"],["78735.95000000","0.00188000"],["78736.00000000","0.01207000"],["78736.02000000","0.00027000"],["78736.64000000","0.00000000"],["78736.65000000","0.00000000"],["78736.78000000","0.00047000"],["78736.97000000","0.00325000"],["78737.23000000","0.00048000"],["78738.00000000","0.01200000"],["78738.90000000","0.00007000"],["78739.72000000","0.00635000"],["78739.98000000","0.00000000"],["78739.99000000","0.00000000"],["78740.00000000","0.01200000"],["78741.27000000","0.00000000"],["78742.00000000","0.01700000"],["78745.45000000","0.00169000"],["78745.99000000","0.00455000"],["78746.59000000","0.34291000"],["78746.92000000","0.00000000"],["78747.34000000","0.00406000"],["78747.45000000","0.34291000"],["78749.96000000","0.00007000"],["78750.01000000","0.22254000"],["78753.45000000","0.34288000"],["78758.01000000","0.34286000"],["78759.89000000","0.00000000"],["78775.63000000","0.00317000"],["78783.47000000","0.00000000"],["78786.72000000","0.00406000"],["78797.99000000","0.00315000"],["78799.29000000","1.90515000"],["78805.66000000","0.02000000"],["78807.88000000","0.00000000"],["78816.77000000","0.93647000"],["78820.49000000","0.00529000"],["78824.00000000","0.02425000"],["78836.59000000","0.00000000"],["78840.26000000","0.00000000"],["78845.99000000","0.00000000"],["78852.34000000","0.00160000"],["78855.28000000","0.00127000"],["78867.99000000","0.00000000"],["78875.99000000","0.00127000"],["78884.23000000","0.00000000"],["78889.97000000","0.00000000"],["78891.76000000","0.00160000"],["78936.34000000","0.00406000"],["79120.03000000","0.01000000"],["79481.15000000","0.01509000"],["79515.63000000","0.01000000"],["79545.40000000","0.00010000"],["79913.21000000","0.01000000"],["80312.77000000","0.01000000"],["80714.34000000","0.01013000"],["81117.91000000","0.01000000"],["81523.50000000","0.01000000"],["81931.11000000","0.01000000"],["82340.77000000","0.01020000"],["82752.47000000","0.01000000"],["83166.24000000","0.01000000"],["83582.07000000","0.01000000"],["83999.98000000","0.01015000"],["84419.98000000","0.01000000"],["84842.08000000","0.01000000"]]}}}
{"rx_ns": 28953783900, "frame": {"stream":"btcusdt@depth20","data":{"lastUpdateId":99076508478,"bids":[["78726.38000000","3.28286000"],["78726.37000000","0.00069000"],["78726.36000000","0.00013000"],["78726.11000000","0.00014000"],["78726.10000000","0.20798000"],["78726.02000000","0.00014000"],["78726.01000000","1.21959000"],["78726.00000000","0.02407000"],["78725.72000000","0.00204000"],["78725.39000000","0.00007000"],["78725.20000000","0.00007000"],["78724.80000000","0.00008000"],["78724.72000000","0.01748000"],["78724.60000000","0.00007000"],["78724.00000000","0.02407000"],["78723.58000000","0.05022000"],["78723.54000000","0.00007000"],["78723.47000000","0.02909000"],["78723.44000000","0.00400000"],["78723.03000000","0.00007000"]],"asks":[["78726.39000000","1.36609000"],["78726.40000000","0.00076000"],["78726.41000000","0.00013000"],["78727.17000000","0.00014000"],["78727.18000000","0.31773000"],["78727.19000000","0.00014000"],["78727.41000000","0.00014000"],["78727.64000000","0.00014000"],["78727.65000000","0.03455000"],["78727.69000000","0.00007000"],["78727.74000000","0.00007000"],["78727.84000000","0.01277000"],["78727.87000000","0.00014000"],["78727.88000000","0.06357000"],["78728.52000000","0.00007000"],["78728.90000000","0.00014000"],["78728.91000000","0.04145000"],["78729.08000000","0.00014000"],["78729.09000000","0.05176000"],["78729.61000000","0.00007000"]]}}}
{"rx_ns": 28953890300, "frame": {"stream":"btcusdt@depth","data":{"e":"depthUpdate","E":1787602896014,"s":"BTCUSDT","U":99076508236,"u":99076508478,"b":[["78726.38000000","3.28286000"],["78723.54000000","0.00007000"],["78723.47000000","0.02909000"],["78720.25000000","0.00000000"],["78719.24000000","0.00000000"],["78718.01000000","0.00000000"],["78717.80000000","0.00000000"],["78717.05000000","0.00000000"],["78716.02000000","0.00635000"],["78715.39000000","0.00635000"],["78704.27000000","0.15227000"],["78702.85000000","0.00000000"],["78702.72000000","0.00007000"],["78701.48000000","0.00000000"],["78684.84000000","0.00007000"],["78641.85000000","0.00000000"],["78595.01000000","0.00406000"],["78541.90000000","0.00000000"],["78534.01000000","0.00000000"],["78529.42000000","0.00778000"],["78332.74000000","0.01000000"],["77941.08000000","0.01000000"],["77781.66000000","0.00042000"],["77551.37000000","0.01000000"],["77309.31000000","0.00043000"],["77163.62000000","0.01000000"],["76777.80000000","0.01000000"],["76393.91000000","0.01000000"],["76011.94000000","0.01000000"],["75631.88000000","0.01000000"],["75253.72000000","0.01000000"],["74877.45000000","0.01019000"],["74503.07000000","0.01000000"],["74130.55000000","0.01000000"],["73759.90000000","0.01000000"],["73391.10000000","0.01000000"],["73024.14000000","0.01000000"],["70853.75000000","0.00352000"],["70853.00000000","0.00000000"],["62981.11000000","0.00031000"],["62981.10000000","0.00000000"],["62981.00000000","0.00031000"]],"a":[["78726.39000000","1.36609000"],["78726.40000000","0.00076000"],["78728.52000000","0.00007000"],["78729.09000000","0.05176000"],["78729.30000000","0.00000000"],["78729.31000000","0.00000000"],["78729.60000000","0.00000000"],["78730.00000000","0.00500000"],["78730.17000000","0.04145000"],["78730.19000000","0.00000000"],["78730.71000000","0.00007000"],["78731.04000000","0.00000000"],["78731.76000000","0.00000000"],["78731.77000000","0.00000000"],["78731.99000000","0.00000000"],["78732.00000000","0.02407000"],["78732.74000000","0.00254000"],["78732.75000000","0.00254000"],["78733.41000000","0.00000000"],["78733.42000000","0.00000000"],["78733.51000000","0.00635000"],["78734.00000000","0.02400000"],["78734.13000000","0.51978000"],["78734.98000000","0.31760000"],["78735.14000000","0.00635000"],["78735.81000000","0.00048000"],["78735.83000000","0.00000000"],["78735.95000000","0.00192000"],["78735.96000000","0.00000000"],["78736.00000000","0.02407000"],["78736.78000000","0.00000000"],["78737.23000000","0.00000000"],["78738.00000000","0.02400000"],["78739.72000000","0.00000000"],["78740.00000000","0.02400000"],["78740.44000000","1.90515000"],["78740.95000000","0.00007000"],["78741.99000000","0.00000000"],["78742.00000000","0.02400000"],["78749.96000000","0.00007000"],["78799.28000000","0.00000000"],["78799.29000000","0.00000000"],["78934.51000000","0.00406000"],["78936.34000000","0.00000000"],["79120.03000000","0.01000000"],["79515.63000000","0.01000000"],["79913.21000000","0.01000000"],["80312.77000000","0.01000000"],["80714.34000000","0.01013000"],["81117.91000000","0.01000000"],["81523.50000000","0.01000000"],["81931.11000000","0.01000000"],["82340.77000000","0.01020000"],["82752.47000000","0.01000000"],["83166.24000000","0.01000000"],["83582.07000000","0.01000000"],["83999.98000000","0.01015000"],["84419.98000000","0.01000000"],["84842.08000000","0.01000000"]]}}}
{"rx_ns": 29953025700, "frame": {"stream":"btcusdt@depth20","data":{"lastUpdateId":99076510137,"bids":[["78724.00000000","0.03320000"],["78723.99000000","0.00070000"],["78723.58000000","0.00014000"],["78723.54000000","0.00007000"],["78722.53000000","0.00007000"],["78722.35000000","0.01748000"],["78722.24000000","0.00007000"],["78722.01000000","0.00014000"],["78722.00000000","0.02407000"],["78721.46000000","0.00007000"],["78721.32000000","0.00007000"],["78721.21000000","0.00007000"],["78721.20000000","0.05015000"],["78721.09000000","0.02909000"],["78720.49000000","0.00007000"],["78720.07000000","0.00014000"],["78720.06000000","0.02522000"],["78720.01000000","0.00007000"],["78720.00000000","0.02407000"],["78719.83000000","0.03489000"]],"asks":[["78724.01000000","3.71118000"],["78724.02000000","0.00020000"],["78724.03000000","0.00013000"],["78724.04000000","0.00014000"],["78724.05000000","0.06357000"],["78724.71000000","0.00014000"],["78724.72000000","0.31781000"],["78724.73000000","0.70521000"],["78725.27000000","0.03456000"],["78725.45000000","0.00642000"],["78725.46000000","0.00400000"],["78726.00000000","0.03014000"],["78726.01000000","0.00034000"],["78726.02000000","0.38133000"],["78726.37000000","0.00007000"],["78726.38000000","0.09668000"],["78726.39000000","0.04173000"],["78726.52000000","0.00635000"],["78726.53000000","0.04139000"],["78726.59000000","0.25415000"]]}}}
{"rx_ns": 29954919800, "frame": {"stream":"btcusdt@depth","data":{"e":"depthUpdate","E":1787602897014,"s":"BTCUSDT","U":99076508479,"u":99076510137,"b":[["78726.38000000","0.00000000"],["78726.37000000","0.00000000"],["78726.36000000","0.00000000"],["78726.11000000","0.00000000"],["78726.10000000","0.00000000"],["78726.02000000","0.00000000"],["78726.01000000","0.00000000"],["78726.00000000","0.00000000"],["78725.99000000","0.00000000"],["78725.72000000","0.00000000"],["78725.39000000","0.00000000"],["78725.20000000","0.00000000"],["78724.80000000","0.00000000"],["78724.73000000","0.00000000"],["78724.72000000","0.00000000"],["78724.71000000","0.00000000"],["78724.60000000","0.00000000"],["78724.01000000","0.00000000"],["78724.00000000","0.03320000"],["78723.99000000","0.00070000"],["78723.59000000","0.00000000"],["78723.58000000","0.00014000"],["78723.48000000","0.00000000"],["78723.47000000","0.00000000"],["78723.44000000","0.00000000"],["78723.16000000","0.00000000"],["78723.10000000","0.00000000"],["78723.03000000","0.00000000"],["78722.91000000","0.00000000"],["78722.35000000","0.01748000"],["78722.32000000","0.00000000"],["78722.24000000","0.00007000"],["78722.22000000","0.00000000"],["78722.21000000","0.00000000"],["78722.01000000","0.00014000"],["78722.00000000","0.02407000"],["78721.95000000","0.00000000"],["78721.93000000","0.00000000"],["78721.92000000","0.00000000"],["78721.84000000","0.00000000"],["78721.46000000","0.00007000"],["78721.36000000","0.00000000"],["78721.25000000","0.00000000"],["78721.24000000","0.00000000"],["78721.21000000","0.00007000"],["78721.20000000","0.05015000"],["78721.09000000","0.02909000"],["78720.95000000","0.00000000"],["78720.85000000","0.00000000"],["78720.66000000","0.00000000"],["78720.55000000","0.00000000"],["78720.53000000","0.00000000"],["78720.24000000","0.00000000"],["78720.07000000","0.00014000"],["78720.06000000","0.02522000"],["78720.01000000","0.00007000"],["78720.00000000","0.02407000"],["78719.83000000","0.03489000"],["78719.67000000","0.00007000"],["78719.64000000","0.00000000"],["78719.56000000","0.00000000"],["78719.41000000","0.00000000"],["78719.40000000","0.00000000"],["78719.36000000","0.00000000"],["78719.35000000","0.00000000"],["78719.23000000","0.00000000"],["78718.57000000","0.03482000"],["78718.49000000","0.00027000"],["78718.47000000","0.00000000"],["78718.34000000","0.00000000"],["78718.29000000","0.00000000"],["78718.28000000","0.00007000"],["78718.24000000","0.00000000"],["78718.13000000","0.20791000"],["78718.00000000","0.02400000"],["78717.99000000","0.01627000"],["78717.75000000","0.00000000"],["78717.36000000","0.00000000"],["78717.34000000","0.00000000"],["78717.29000000","0.00000000"],["78717.28000000","0.00000000"],["78717.27000000","0.00000000"],["78717.26000000","0.00000000"],["78717.19000000","0.00204000"],["78717.09000000","0.00000000"],["78716.77000000","0.00000000"],["78716.68000000","0.00000000"],["78716.61000000","0.00000000"],["78716.38000000","0.00000000"],["78716.37000000","0.00000000"],["78716.31000000","0.00000000"],["78716.24000000","0.00000000"],["78716.23000000","0.00000000"],["78716.02000000","0.00000000"],["78716.00000000","0.02469000"],["78715.95000000","0.00000000"],["78715.92000000","1.21952000"],["78715.90000000","0.00000000"],["78715.80000000","0.00007000"],["78715.73000000","0.00000000"],["78715.71000000","0.00000000"],["78715.70000000","0.00000000"],["78715.65000000","0.00000000"],["78715.39000000","0.00000000"],["78715.38000000","0.00000000"],["78714.79000000","0.00047000"],["78714.78000000","0.00000000"],["78714.61000000","0.00000000"],["78714.42000000","0.00000000"],["78713.93000000","0.00000000"],["78713.68000000","0.00000000"],["78713.63000000","0.00000000"],["78713.58000000","0.00000000"],["78713.57000000","0.00000000"],["78713.47000000","0.00000000"],["78713.20000000","0.00000000"],["78713.08000000","0.00000000"],["78712.86000000","0.00000000"],["78712.77000000","0.00000000"],["78712.76000000","0.00000000"],["78712.63000000","0.08576000"],["78712.18000000","0.00000000"],["78712.10000000","0.00000000"],["78712.06000000","0.00000000"],["78711.98000000","0.00000000"],["78711.91000000","0.00000000"],["78711.80000000","0.00000000"],["78711.79000000","0.00319000"],["78711.38000000","0.00406000"],["78711.01000000","0.00000000"],["78710.70000000","0.00000000"],["78710.69000000","0.00000000"],["78710.40000000","0.02000000"],["78710.08000000","0.00000000"],["78710.00000000","0.02400000"],["78709.98000000","0.00000000"],["78709.96000000","0.00000000"],["78709.95000000","0.00000000"],["78708.51000000","0.00635000"],["78707.85000000","0.00326000"],["78707.18000000","0.00048000"],["78707.02000000","0.00635000"],["78706.70000000","0.12705000"],["78706.22000000","0.00000000"],["78706.17000000","0.00000000"],["78705.81000000","0.00000000"],["78705.80000000","0.00007000"],["78705.78000000","0.02200000"],["78705.77000000","0.06000000"],["78705.74000000","0.02400000"],["78705.56000000","0.02287000"],["78705.47000000","0.01000000"],["78705.00000000","0.02000000"],["78704.95000000","0.02600000"],["78704.92000000","0.02600000"],["78704.68000000","0.00254000"],["78704.27000000","0.00000000"],["78704.26000000","0.00000000"],["78703.91000000","0.00322000"],["78703.80000000","0.00000000"],["78703.07000000","0.08000000"],["78702.85000000","0.00000000"],["78702.84000000","0.00000000"],["78702.72000000","0.00000000"],["78702.66000000","0.02200000"],["78701.90000000","0.00000000"],["78701.87000000","0.02000000"],["78701.48000000","0.00000000"],["78701.09000000","0.02000000"],["78701.08000000","0.02000000"],["78701.04000000","0.00000000"],["78701.00000000","0.00007000"],["78700.38000000","0.00127000"],["78700.34000000","0.00007000"],["78699.97000000","0.00319000"],["78698.94000000","0.00000000"],["78698.93000000","0.00000000"],["78698.67000000","0.00000000"],["78697.24000000","0.00191000"],["78696.85000000","0.00000000"],["78696.27000000","0.00000000"],["78696.17000000","0.00060000"],["78694.91000000","0.13244000"],["78694.58000000","0.00000000"],["78694.30000000","0.00000000"],["78694.06000000","0.04584000"],["78692.76000000","0.19287000"],["78692.75000000","0.00000000"],["78691.12000000","0.00400000"],["78690.94000000","0.00000000"],["78690.58000000","0.00000000"],["78690.55000000","0.00635000"],["78690.41000000","0.00000000"],["78690.00000000","0.11572000"],["78689.39000000","0.00000000"],["78689.11000000","0.63549000"],["78689.10000000","0.00400000"],["78689.02000000","0.00000000"],["78688.44000000","0.00000000"],["78687.96000000","0.00000000"],["78687.82000000","0.00000000"],["78687.66000000","0.00000000"],["78687.08000000","0.00400000"],["78687.00000000","0.00007000"],["78686.00000000","0.02400000"],["78685.69000000","0.00000000"],["78685.33000000","0.63552000"],["78685.11000000","0.00000000"],["78685.00000000","0.00000000"],["78684.84000000","0.00014000"],["78684.18000000","0.00000000"],["78684.00000000","0.03400000"],["78683.52000000","0.34318000"],["78683.05000000","0.00000000"],["78683.04000000","0.00400000"],["78682.96000000","0.34319000"],["78682.19000000","0.00000000"],["78682.14000000","0.67658000"],["78681.80000000","0.00200000"],["78680.97000000","0.00007000"],["78679.50000000","0.34681000"],["78678.05000000","0.00000000"],["78677.75000000","0.00000000"],["78677.10000000","0.00007000"],["78676.99000000","0.00000000"],["78676.16000000","0.00000000"],["78676.12000000","0.22411000"],["78675.88000000","0.00000000"],["78675.86000000","0.00000000"],["78675.30000000","0.00000000"],["78675.10000000","0.00000000"],["78674.89000000","0.00000000"],["78674.78000000","0.00000000"],["78674.63000000","0.00000000"],["78674.17000000","0.00007000"],["78673.72000000","0.00000000"],["78673.59000000","0.00000000"],["78673.23000000","0.00000000"],["78673.06000000","0.00000000"],["78672.95000000","0.00000000"],["78672.94000000","0.00000000"],["78672.77000000","0.00000000"],["78672.63000000","0.00000000"],["78672.40000000","0.00000000"],["78672.02000000","0.00406000"],["78671.44000000","0.00000000"],["78671.38000000","0.00007000"],["78671.12000000","0.00000000"],["78670.85000000","0.00000000"],["78670.75000000","0.00000000"],["78670.51000000","0.00000000"],["78669.55000000","0.00000000"],["78668.75000000","0.82105000"],["78664.44000000","0.00000000"],["78662.01000000","0.00315000"],["78661.75000000","0.01131000"],["78661.19000000","0.00000000"],["78660.79000000","0.00000000"],["78654.31000000","0.02000000"],["78654.30000000","0.02000000"],["78654.22000000","0.86793000"],["78650.66000000","1.25888000"],["78646.48000000","0.00000000"],["78645.08000000","0.02200000"],["78644.88000000","0.00543000"],["78642.27000000","0.00000000"],["78642.23000000","0.00000000"],["78641.92000000","0.02200000"],["78641.85000000","0.00000000"],["78641.74000000","0.02000000"],["78641.40000000","0.00000000"],["78641.35000000","0.00000000"],["78641.17000000","0.00000000"],["78640.53000000","0.00406000"],["78640.38000000","0.00000000"],["78640.34000000","0.00000000"],["78640.01000000","0.00313000"],["78637.05000000","0.00000000"],["78631.30000000","0.00000000"],["78630.96000000","0.00000000"],["78621.04000000","0.00000000"],["78615.82000000","2.77149000"],["78610.04000000","0.04572000"],["78605.69000000","0.05750000"],["78601.29000000","0.00000000"],["78595.01000000","0.00000000"],["78593.31000000","0.00406000"],["78590.56000000","0.04092000"],["78576.75000000","0.00000000"],["78561.00000000","0.00000000"],["78545.25000000","0.00000000"],["78533.83000000","0.00778000"],["78529.50000000","0.00000000"],["78529.42000000","0.00000000"],["78524.16000000","0.00000000"],["78523.84000000","0.00007000"],["78522.47000000","0.00406000"],["78513.75000000","0.00000000"],["78506.05000000","0.00007000"],["78502.12000000","0.00000000"],["78498.00000000","0.00000000"],["78482.25000000","0.00000000"],["78415.72000000","0.21930000"],["78332.74000000","0.00000000"],["78330.38000000","0.01000000"],["77941.08000000","0.00000000"],["77938.72000000","0.01000000"],["77893.45000000","0.00000000"],["77551.37000000","0.00000000"],["77549.03000000","0.01000000"],["77410.94000000","0.00000000"],["77163.62000000","0.00000000"],["77161.28000000","0.01000000"],["76836.95000000","0.00043000"],["76777.80000000","0.00000000"],["76775.48000000","0.01000000"],["76393.91000000","0.00000000"],["76391.60000000","0.01000000"],["76364.59000000","0.00043000"],["76011.94000000","0.00000000"],["76009.64000000","0.01000000"],["75892.23000000","0.00043000"],["75631.88000000","0.00000000"],["75629.59000000","0.01000000"],["75253.72000000","0.00000000"],["75251.45000000","0.01000000"],["74877.45000000","0.00019000"],["74875.19000000","0.01000000"],["74503.07000000","0.00000000"],["74500.81000000","0.01000000"],["74130.55000000","0.00000000"],["74128.31000000","0.01000000"],["73759.90000000","0.00000000"],["73757.67000000","0.01000000"],["73391.10000000","0.00000000"],["73388.88000000","0.01000000"],["73024.14000000","0.00000000"],["73021.93000000","0.01000000"],["70853.75000000","0.00000000"],["70853.74000000","0.00000000"],["70853.40000000","0.00000000"],["70851.60000000","0.00080000"],["70851.00000000","0.00000000"],["62981.11000000","0.00000000"],["62981.00000000","0.00031000"],["62980.80000000","0.00000000"],["62979.20000000","0.00031000"],["60000.00000000","176.67970000"]],"a":[["78724.01000000","3.71118000"],["78724.02000000","0.00020000"],["78724.03000000","0.00013000"],["78724.04000000","0.00014000"],["78724.05000000","0.06357000"],["78724.61000000","0.00000000"],["78724.71000000","0.00014000"],["78724.72000000","0.31781000"],["78724.73000000","0.70521000"],["78724.74000000","0.00000000"],["78724.75000000","0.00000000"],["78725.21000000","0.00000000"],["78725.27000000","0.03456000"],["78725.40000000","0.00000000"],["78725.45000000","0.00642000"],["78725.46000000","0.00400000"],["78725.98000000","0.00000000"],["78725.99000000","0.00000000"],["78726.00000000","0.03014000"],["78726.01000000","0.00034000"],["78726.02000000","0.38133000"],["78726.03000000","0.00000000"],["78726.11000000","0.00000000"],["78726.37000000","0.00007000"],["78726.38000000","0.09668000"],["78726.39000000","0.04173000"],["78726.40000000","0.00000000"],["78726.41000000","0.00000000"],["78726.52000000","0.00635000"],["78726.53000000","0.04139000"],["78726.58000000","0.00000000"],["78726.59000000","0.25415000"],["78726.71000000","0.05162000"],["78727.17000000","0.00000000"],["78727.18000000","0.00000000"],["78727.19000000","0.00007000"],["78727.43000000","0.00000000"],["78727.48000000","0.00400000"],["78727.63000000","0.00000000"],["78727.64000000","0.00000000"],["78727.65000000","0.00000000"],["78727.69000000","0.00000000"],["78727.74000000","0.00000000"],["78727.79000000","0.04139000"],["78727.84000000","0.00000000"],["78727.85000000","0.00027000"],["78727.87000000","0.00000000"],["78727.88000000","0.00000000"],["78728.08000000","0.00000000"],["78728.09000000","0.00000000"],["78728.51000000","0.00000000"],["78728.52000000","0.00000000"],["78728.82000000","0.00323000"],["78728.90000000","0.00000000"],["78728.91000000","0.00000000"],["78729.00000000","0.00007000"],["78729.07000000","0.00000000"],["78729.08000000","0.00000000"],["78729.09000000","0.00007000"],["78729.50000000","0.00400000"],["78729.61000000","0.00000000"],["78730.00000000","0.01000000"],["78730.01000000","0.00000000"],["78730.16000000","0.00000000"],["78730.17000000","0.00000000"],["78730.27000000","0.00319000"],["78730.70000000","0.00000000"],["78731.33000000","0.00000000"],["78731.37000000","0.00152000"],["78731.84000000","0.00000000"],["78731.85000000","0.00324000"],["78732.00000000","0.02400000"],["78732.50000000","0.00008000"],["78732.74000000","0.00000000"],["78732.75000000","0.00455000"],["78732.96000000","0.00007000"],["78733.42000000","0.00000000"],["78733.43000000","0.12701000"],["78733.51000000","0.00000000"],["78733.52000000","0.00000000"],["78733.96000000","0.00000000"],["78733.97000000","0.00000000"],["78734.13000000","0.21951000"],["78734.98000000","0.00000000"],["78735.14000000","1.21952000"],["78735.15000000","1.90529000"],["78735.16000000","0.14289000"],["78735.54000000","0.00000000"],["78735.81000000","0.00000000"],["78735.95000000","0.00000000"],["78736.16000000","0.38106000"],["78736.20000000","0.00400000"],["78736.33000000","0.00000000"],["78737.01000000","0.00000000"],["78737.31000000","0.02000000"],["78737.68000000","0.00000000"],["78737.92000000","0.02000000"],["78738.48000000","0.00007000"],["78738.79000000","0.04103000"],["78738.95000000","0.15189000"],["78739.22000000","0.34294000"],["78739.67000000","0.02000000"],["78739.73000000","0.00000000"],["78739.84000000","0.00000000"],["78739.91000000","0.06554000"],["78739.99000000","0.36224000"],["78740.00000000","0.11649000"],["78740.09000000","0.34294000"],["78740.13000000","0.02515000"],["78740.46000000","0.02000000"],["78740.48000000","0.10264000"],["78740.94000000","0.00007000"],["78741.24000000","0.03000000"],["78741.25000000","0.02000000"],["78741.31000000","0.04000000"],["78741.81000000","0.00000000"],["78741.88000000","0.07569000"],["78741.99000000","0.00000000"],["78742.14000000","0.00007000"],["78743.53000000","0.00000000"],["78744.42000000","0.00000000"],["78745.45000000","0.00000000"],["78745.99000000","0.00000000"],["78746.06000000","0.12699000"],["78747.34000000","0.00000000"],["78747.36000000","0.00000000"],["78747.58000000","0.00007000"],["78747.66000000","0.09487000"],["78747.95000000","0.00000000"],["78748.44000000","0.00000000"],["78748.75000000","0.00000000"],["78749.32000000","0.00000000"],["78749.67000000","0.00406000"],["78749.96000000","0.00000000"],["78750.00000000","0.10533000"],["78750.05000000","0.00000000"],["78750.27000000","0.00007000"],["78751.11000000","0.00000000"],["78751.15000000","0.00012000"],["78751.91000000","0.00000000"],["78752.36000000","0.00000000"],["78752.68000000","0.00000000"],["78752.69000000","0.00000000"],["78752.75000000","0.00000000"],["78755.89000000","0.00000000"],["78756.66000000","0.00000000"],["78758.01000000","0.00000000"],["78758.63000000","0.00000000"],["78759.30000000","0.00000000"],["78760.23000000","0.67591000"],["78760.60000000","0.00000000"],["78762.75000000","0.00426000"],["78763.04000000","0.00434000"],["78763.11000000","0.02443000"],["78763.26000000","0.00431000"],["78763.99000000","0.00619000"],["78764.00000000","0.03414000"],["78765.00000000","0.00000000"],["78765.63000000","0.00000000"],["78765.75000000","0.00000000"],["78766.00000000","0.02400000"],["78767.67000000","0.00000000"],["78769.80000000","0.00000000"],["78770.00000000","0.02400000"],["78773.05000000","0.00000000"],["78773.25000000","0.00000000"],["78774.25000000","0.86661000"],["78774.31000000","0.00000000"],["78775.64000000","0.00000000"],["78775.69000000","0.00000000"],["78775.84000000","0.00000000"],["78781.23000000","0.00000000"],["78784.31000000","0.00110000"],["78786.72000000","0.00000000"],["78786.99000000","0.90950000"],["78788.92000000","0.00540000"],["78789.31000000","0.00000000"],["78789.83000000","0.00879000"],["78790.37000000","0.00000000"],["78791.97000000","0.00000000"],["78799.81000000","0.00000000"],["78800.95000000","0.00000000"],["78804.44000000","0.00000000"],["78806.10000000","0.00000000"],["78817.71000000","0.00000000"],["78818.22000000","0.00000000"],["78820.55000000","0.00406000"],["78826.70000000","0.02789000"],["78827.83000000","0.00000000"],["78837.53000000","0.00000000"],["78857.12000000","0.00000000"],["78860.25000000","0.00000000"],["78865.47000000","0.00000000"],["78876.00000000","0.02407000"],["78891.75000000","0.00000000"],["78907.50000000","0.00000000"],["78923.25000000","0.00000000"],["78932.00000000","0.00000000"],["78934.51000000","0.00000000"],["78938.67000000","0.00406000"],["78939.00000000","0.00000000"],["78944.11000000","0.00000000"],["78948.05000000","0.00000000"],["78951.98000000","0.00000000"],["78954.75000000","0.00000000"],["78970.50000000","0.00000000"],["78986.25000000","0.00000000"],["79117.64000000","0.02945000"],["79120.03000000","0.00000000"],["79513.22000000","0.01000000"],["79515.63000000","0.00000000"],["79910.79000000","0.01000000"],["79913.21000000","0.00000000"],["80310.34000000","0.01000000"],["80312.77000000","0.00000000"],["80711.89000000","0.01000000"],["80714.34000000","0.00013000"],["81115.45000000","0.01000000"],["81117.91000000","0.00000000"],["81521.03000000","0.01000000"],["81523.50000000","0.00000000"],["81928.64000000","0.01000000"],["81931.11000000","0.00000000"],["82338.28000000","0.01000000"],["82340.77000000","0.00020000"],["82749.97000000","0.01000000"],["82752.47000000","0.00000000"],["83163.72000000","0.01000000"],["83166.24000000","0.00000000"],["83579.54000000","0.01066000"],["83582.07000000","0.00000000"],["83997.44000000","0.01000000"],["83999.98000000","0.00015000"],["84417.42000000","0.01000000"],["84419.98000000","0.00000000"],["84839.51000000","0.01000000"],["84842.08000000","0.00000000"]]}}}
{"rx_ns": 30958785600, "frame": {"stream":"btcusdt@depth20","data":{"lastUpdateId":99076510406,"bids":[["78724.00000000","0.02654000"],["78723.99000000","0.00090000"],["78723.98000000","0.00013000"],["78723.81000000","0.00007000"],["78723.58000000","0.00014000"],["78723.54000000","0.00007000"],["78722.53000000","0.00007000"],["78722.35000000","0.01748000"],["78722.24000000","0.00007000"],["78722.01000000","0.00014000"],["78722.00000000","0.02407000"],["78721.99000000","0.04867000"],["78721.32000000","0.00007000"],["78721.21000000","0.00007000"],["78721.20000000","0.05008000"],["78721.09000000","0.02909000"],["78720.49000000","0.00007000"],["78720.07000000","0.00014000"],["78720.06000000","0.02522000"],["78720.01000000","0.00007000"]],"asks":[["78724.01000000","3.70279000"],["78724.02000000","0.00020000"],["78724.03000000","0.00013000"],["78724.04000000","0.00014000"],["78724.05000000","0.06357000"],["78724.71000000","0.00014000"],["78724.72000000","0.31781000"],["78724.73000000","0.70317000"],["78725.27000000","0.03456000"],["78725.45000000","0.00642000"],["78725.46000000","0.00400000"],["78726.00000000","0.03014000"],["78726.01000000","0.00034000"],["78726.02000000","0.38133000"],["78726.38000000","0.02168000"],["78726.39000000","0.04156000"],["78726.53000000","0.04139000"],["78726.58000000","0.00007000"],["78726.59000000","0.25415000"],["78726.71000000","0.05162000"]]}}}
{"rx_ns": 30958917500, "frame": {"stream":"btcusdt@depth","data":{"e":"depthUpdate","E":1787602898014,"s":"BTCUSDT","U":99076510138,"u":99076510406,"b":[["78724.00000000","0.02654000"],["78723.99000000","0.00090000"],["78723.98000000","0.00013000"],["78723.81000000","0.00007000"],["78722.00000000","0.02407000"],["78721.99000000","0.04867000"],["78721.46000000","0.00000000"],["78721.20000000","0.05008000"],["78721.16000000","0.00000000"],["78720.92000000","0.00000000"],["78718.51000000","0.00000000"],["78718.17000000","0.00000000"],["78718.13000000","0.00000000"],["78717.69000000","0.20791000"],["78717.48000000","0.00204000"],["78717.19000000","0.00000000"],["78716.22000000","0.00000000"],["78715.93000000","1.90515000"],["78715.87000000","0.00000000"],["78715.60000000","0.00000000"],["78714.56000000","0.03320000"],["78714.44000000","0.00000000"],["78714.13000000","0.00000000"],["78711.93000000","0.00014000"],["78711.49000000","0.00000000"],["78711.38000000","0.00000000"],["78711.36000000","0.00000000"],["78711.01000000","1.90515000"],["78710.47000000","0.00635000"],["78710.28000000","0.02000000"],["78709.48000000","0.01000000"],["78708.51000000","0.00635000"],["78708.06000000","0.00014000"],["78707.32000000","0.36224000"],["78707.02000000","0.00000000"],["78706.25000000","0.00163000"],["78705.77000000","0.00000000"],["78705.47000000","0.00000000"],["78704.68000000","0.00654000"],["78704.19000000","0.00014000"],["78703.07000000","0.00000000"],["78701.47000000","0.00027000"],["78700.87000000","0.12000000"],["78700.34000000","0.00007000"],["78700.32000000","0.00014000"],["78699.44000000","0.36224000"],["78696.45000000","0.00014000"],["78693.18000000","0.49982000"],["78684.06000000","0.09620000"],["78677.26000000","0.51542000"],["78672.02000000","0.00000000"],["78671.34000000","0.02819000"],["78669.57000000","0.99745000"],["78669.45000000","0.02434000"],["78667.29000000","0.00007000"],["78658.28000000","0.02000000"],["78655.12000000","0.02200000"],["78654.68000000","0.02000000"],["78645.08000000","0.00000000"],["78641.92000000","0.00000000"],["78641.74000000","0.00000000"],["78640.53000000","0.00000000"],["78636.93000000","0.00406000"],["78636.85000000","0.00000000"],["78629.13000000","0.02541000"],["78593.31000000","0.00000000"],["78533.83000000","0.00000000"],["78522.47000000","0.00000000"],["78515.17000000","0.00000000"],["78505.01000000","0.01989000"],["78504.57000000","0.00779000"],["78503.67000000","0.00007000"],["78500.24000000","0.00000000"],["78496.31000000","0.00000000"],["78330.38000000","0.01000000"],["78017.84000000","0.00000000"],["77938.72000000","0.01000000"],["77549.03000000","0.01000000"],["77161.28000000","0.01000000"],["76934.14000000","0.00000000"],["76775.48000000","0.01000000"],["76391.60000000","0.01000000"],["76009.64000000","0.01000000"],["75629.59000000","0.01000000"],["75419.87000000","0.00044000"],["75251.45000000","0.01000000"],["74947.51000000","0.00044000"],["74875.19000000","0.01000000"],["74500.81000000","0.01000000"],["74475.16000000","0.00044000"],["74128.31000000","0.01000000"],["73757.67000000","0.01000000"],["73388.88000000","0.01000000"],["73021.93000000","0.01000000"],["70851.60000000","0.00208000"],["70851.00000000","0.00000000"],["62979.20000000","0.00031000"],["62979.00000000","0.00000000"]],"a":[["78724.01000000","3.70279000"],["78724.73000000","0.70317000"],["78726.37000000","0.00000000"],["78726.38000000","0.02168000"],["78726.39000000","0.04156000"],["78726.52000000","0.00000000"],["78726.58000000","0.00007000"],["78727.19000000","0.00000000"],["78727.74000000","0.00007000"],["78728.66000000","0.00007000"],["78729.08000000","0.00400000"],["78730.00000000","0.01700000"],["78731.39000000","0.02000000"],["78732.11000000","0.02000000"],["78732.18000000","0.02000000"],["78732.19000000","0.02000000"],["78734.13000000","0.21944000"],["78735.26000000","0.02000000"],["78735.73000000","0.02600000"],["78736.20000000","0.00000000"],["78743.49000000","0.00000000"],["78744.28000000","0.00000000"],["78744.30000000","0.00000000"],["78747.58000000","0.00007000"],["78749.67000000","0.00000000"],["78754.28000000","0.00200000"],["78781.50000000","0.00413000"],["78789.05000000","0.00000000"],["78795.59000000","0.02000000"],["78796.37000000","0.03000000"],["78805.66000000","0.00000000"],["78813.79000000","0.00000000"],["78816.94000000","0.00000000"],["78817.45000000","0.00000000"],["78820.55000000","0.00000000"],["78860.24000000","0.00406000"],["78867.80000000","0.00000000"],["78938.67000000","0.00000000"],["79117.64000000","0.02945000"],["79513.22000000","0.01000000"],["79910.79000000","0.01000000"],["80310.34000000","0.01000000"],["80711.89000000","0.01000000"],["81115.45000000","0.01000000"],["81521.03000000","0.01000000"],["81928.64000000","0.01000000"],["82338.28000000","0.01000000"],["82749.97000000","0.01000000"],["83163.72000000","0.01000000"],["83579.54000000","0.01066000"],["83997.44000000","0.01000000"],["84417.42000000","0.01000000"],["84839.51000000","0.01000000"]]}}}
{"rx_ns": 31952269300, "frame": {"stream":"btcusdt@depth20","data":{"lastUpdateId":99076510588,"bids":[["78724.00000000","0.02654000"],["78723.99000000","0.00090000"],["78723.98000000","0.00013000"],["78723.81000000","0.00007000"],["78723.58000000","0.00014000"],["78723.54000000","0.00007000"],["78722.53000000","0.00007000"],["78722.35000000","0.01748000"],["78722.24000000","0.00007000"],["78722.01000000","0.00014000"],["78722.00000000","0.02407000"],["78721.32000000","0.00007000"],["78721.21000000","0.00007000"],["78721.20000000","0.05015000"],["78721.09000000","0.02902000"],["78720.49000000","0.00007000"],["78720.07000000","0.00014000"],["78720.06000000","0.02522000"],["78720.01000000","0.00007000"],["78720.00000000","0.02407000"]],"asks":[["78724.01000000","3.70643000"],["78724.02000000","0.00020000"],["78724.03000000","0.00013000"],["78724.04000000","0.00014000"],["78724.05000000","0.06357000"],["78724.37000000","0.00014000"],["78724.38000000","0.02661000"],["78724.71000000","0.00014000"],["78724.72000000","0.31781000"],["78724.73000000","0.70317000"],["78725.27000000","0.03456000"],["78725.45000000","0.00642000"],["78725.46000000","0.00400000"],["78726.00000000","0.03014000"],["78726.01000000","0.00034000"],["78726.02000000","0.38133000"],["78726.38000000","0.02161000"],["78726.39000000","0.04149000"],["78726.53000000","0.04139000"],["78726.59000000","0.25415000"]]}}}
{"rx_ns": 31952460800, "frame": {"stream":"btcusdt@depth","data":{"e":"depthUpdate","E":1787602899014,"s":"BTCUSDT","U":99076510407,"u":99076510588,"b":[["78724.00000000","0.02654000"],["78723.99000000","0.00090000"],["78722.00000000","0.02407000"],["78721.99000000","0.00000000"],["78721.20000000","0.05015000"],["78721.09000000","0.02902000"],["78720.13000000","0.00000000"],["78715.93000000","0.00000000"],["78714.66000000","0.00000000"],["78714.62000000","0.00000000"],["78714.57000000","0.00000000"],["78714.56000000","0.00000000"],["78714.34000000","0.02654000"],["78710.28000000","0.00000000"],["78709.48000000","0.00000000"],["78708.74000000","0.00048000"],["78707.77000000","0.00413000"],["78705.57000000","0.03000000"],["78700.34000000","0.00007000"],["78681.61000000","0.00007000"],["78673.43000000","0.00007000"],["78671.34000000","0.00000000"],["78671.33000000","0.02731000"],["78669.45000000","0.00000000"],["78669.44000000","0.02445000"],["78636.85000000","0.00000000"],["78589.70000000","0.00406000"],["78518.87000000","0.00406000"],["78505.02000000","0.00779000"],["78504.57000000","0.00000000"],["78330.38000000","0.01000000"],["78015.48000000","0.00010000"],["77938.72000000","0.01000000"],["77549.03000000","0.01000000"],["77161.28000000","0.01000000"],["76775.48000000","0.01000000"],["76391.60000000","0.01000000"],["76009.64000000","0.01000000"],["75629.59000000","0.01000000"],["75251.45000000","0.01000000"],["74875.19000000","0.01000000"],["74500.81000000","0.01000000"],["74128.31000000","0.01000000"],["74002.80000000","0.00070000"],["73757.67000000","0.01000000"],["73530.44000000","0.00045000"],["73388.88000000","0.01000000"],["73021.93000000","0.01000000"],["72426.09000000","0.00000000"],["70851.60000000","0.00272000"],["70851.00000000","0.00020000"],["62979.20000000","0.00031000"],["62979.00000000","0.00000000"]],"a":[["78724.01000000","3.70643000"],["78724.05000000","0.06357000"],["78724.37000000","0.00014000"],["78724.38000000","0.02661000"],["78726.38000000","0.02161000"],["78726.39000000","0.04149000"],["78726.58000000","0.00000000"],["78728.00000000","0.00500000"],["78728.82000000","0.00000000"],["78728.97000000","0.00331000"],["78729.09000000","0.00000000"],["78730.00000000","0.02400000"],["78742.12000000","0.00406000"],["78747.58000000","0.00007000"],["78751.13000000","0.02000000"],["78751.92000000","0.02000000"],["78751.93000000","0.02000000"],["78765.93000000","0.00000000"],["78794.12000000","0.00000000"],["78805.39000000","0.00000000"],["78805.66000000","0.00000000"],["78805.69000000","0.00000000"],["78812.99000000","0.00406000"],["78821.62000000","0.00025000"],["78824.00000000","0.02400000"],["78847.75000000","0.00400000"],["78891.80000000","0.00000000"],["79117.64000000","0.02945000"],["79513.22000000","0.01000000"],["79910.79000000","0.01000000"],["79916.00000000","0.07577000"],["80310.34000000","0.01000000"],["80711.89000000","0.01000000"],["81115.45000000","0.01000000"],["81521.03000000","0.01000000"],["81928.64000000","0.01000000"],["82338.28000000","0.01000000"],["82749.97000000","0.01000000"],["83163.72000000","0.01000000"],["83579.54000000","0.01066000"],["83997.44000000","0.01000000"],["84417.42000000","0.01000000"],["84839.51000000","0.01000000"],["88000.00000000","30.57068000"]]}}}
{"rx_ns": 32955991100, "frame": {"stream":"btcusdt@depth20","data":{"lastUpdateId":99076511888,"bids":[["78720.00000000","0.77580000"],["78719.99000000","0.00056000"],["78719.88000000","0.00007000"],["78719.67000000","0.00007000"],["78719.52000000","0.03698000"],["78718.44000000","0.00007000"],["78718.01000000","0.00014000"],["78718.00000000","0.02421000"],["78717.99000000","0.01634000"],["78717.81000000","0.01661000"],["78717.79000000","0.00200000"],["78717.44000000","0.00007000"],["78717.25000000","0.00014000"],["78717.24000000","0.04965000"],["78716.74000000","0.00007000"],["78716.55000000","0.02764000"],["78716.39000000","0.00007000"],["78716.01000000","0.00011000"],["78716.00000000","0.02476000"],["78715.80000000","0.00007000"]],"asks":[["78720.01000000","6.67002000"],["78720.02000000","0.00020000"],["78720.03000000","0.00013000"],["78720.06000000","0.00014000"],["78720.07000000","0.65025000"],["78720.10000000","0.00014000"],["78720.11000000","0.06364000"],["78720.20000000","0.00322000"],["78721.20000000","0.02182000"],["78721.21000000","0.04126000"],["78721.25000000","0.00014000"],["78721.26000000","0.00007000"],["78721.27000000","0.03601000"],["78721.77000000","0.31765000"],["78721.78000000","0.00318000"],["78721.99000000","0.00400000"],["78722.01000000","0.00014000"],["78722.53000000","0.04320000"],["78722.74000000","0.00007000"],["78722.75000000","0.05219000"]]}}}
{"rx_ns": 32956539100, "frame": {"stream":"btcusdt@depth","data":{"e":"depthUpdate","E":1787602900016,"s":"BTCUSDT","U":99076510589,"u":99076511888,"b":[["78724.00000000","0.00000000"],["78723.99000000","0.00000000"],["78723.98000000","0.00000000"],["78723.81000000","0.00000000"],["78723.58000000","0.00000000"],["78723.54000000","0.00000000"],["78722.53000000","0.00000000"],["78722.35000000","0.00000000"],["78722.24000000","0.00000000"],["78722.01000000","0.00000000"],["78722.00000000","0.00000000"],["78721.32000000","0.00000000"],["78721.21000000","0.00000000"],["78721.20000000","0.00000000"],["78721.09000000","0.00000000"],["78720.49000000","0.00000000"],["78720.07000000","0.00000000"],["78720.06000000","0.00000000"],["78720.05000000","0.00000000"],["78720.01000000","0.00000000"],["78720.00000000","0.77580000"],["78719.99000000","0.00056000"],["78719.88000000","0.00007000"],["78719.84000000","0.00000000"],["78719.83000000","0.00000000"],["78719.52000000","0.03698000"],["78718.67000000","0.00000000"],["78718.58000000","0.00000000"],["78718.57000000","0.00000000"],["78718.50000000","0.00000000"],["78718.49000000","0.00000000"],["78718.28000000","0.00000000"],["78718.07000000","0.00000000"],["78718.06000000","0.00000000"],["78718.01000000","0.00014000"],["78718.00000000","0.02421000"],["78717.99000000","0.01634000"],["78717.81000000","0.01661000"],["78717.69000000","0.00000000"],["78717.48000000","0.00000000"],["78717.25000000","0.00014000"],["78717.24000000","0.04965000"],["78717.10000000","0.00000000"],["78716.74000000","0.00007000"],["78716.73000000","0.00000000"],["78716.55000000","0.02764000"],["78716.17000000","0.00000000"],["78716.00000000","0.02476000"],["78715.92000000","0.00000000"],["78715.70000000","0.00000000"],["78715.29000000","0.03308000"],["78714.97000000","0.00000000"],["78714.79000000","0.00000000"],["78714.61000000","0.00000000"],["78714.56000000","0.00000000"],["78714.43000000","0.00000000"],["78714.34000000","0.00000000"],["78714.03000000","0.03308000"],["78714.00000000","0.02400000"],["78713.70000000","0.00000000"],["78713.32000000","0.00000000"],["78713.19000000","0.00000000"],["78712.97000000","0.00000000"],["78712.91000000","0.00000000"],["78712.63000000","0.00000000"],["78712.00000000","0.02400000"],["78711.95000000","0.00000000"],["78711.93000000","0.00007000"],["78711.89000000","0.00000000"],["78711.79000000","0.00000000"],["78711.35000000","0.00000000"],["78711.32000000","0.00000000"],["78711.28000000","0.00000000"],["78711.27000000","0.00000000"],["78711.26000000","0.00000000"],["78711.19000000","0.00329000"],["78711.03000000","0.00000000"],["78711.02000000","1.22352000"],["78711.01000000","0.00000000"],["78711.00000000","0.00000000"],["78710.47000000","0.00000000"],["78710.40000000","0.00000000"],["78710.38000000","0.00000000"],["78710.32000000","0.00000000"],["78710.18000000","0.00000000"],["78710.13000000","0.00000000"],["78709.97000000","0.00000000"],["78709.70000000","0.00000000"],["78709.69000000","0.00000000"],["78709.51000000","0.00000000"],["78709.49000000","0.00000000"],["78709.41000000","0.02515000"],["78709.40000000","0.00000000"],["78709.29000000","0.12704000"],["78708.51000000","0.00000000"],["78708.45000000","0.08576000"],["78708.20000000","0.02000000"],["78708.07000000","0.36224000"],["78708.06000000","1.90529000"],["78708.05000000","0.00000000"],["78707.77000000","0.00007000"],["78707.67000000","0.00007000"],["78707.32000000","0.00000000"],["78707.03000000","1.21952000"],["78706.70000000","0.00000000"],["78706.26000000","0.00635000"],["78705.99000000","0.00047000"],["78705.84000000","0.00188000"],["78705.57000000","0.00000000"],["78704.68000000","0.00254000"],["78704.67000000","0.00000000"],["78704.10000000","0.00000000"],["78703.47000000","0.00400000"],["78702.90000000","0.00400000"],["78702.89000000","1.21952000"],["78702.75000000","0.00000000"],["78702.09000000","1.90515000"],["78702.08000000","0.00000000"],["78701.94000000","0.00000000"],["78701.80000000","0.00000000"],["78701.71000000","0.00635000"],["78701.42000000","0.12706000"],["78701.11000000","0.00007000"],["78700.87000000","0.00000000"],["78700.34000000","0.00000000"],["78700.10000000","0.00000000"],["78700.00000000","0.11479000"],["78699.92000000","0.36224000"],["78699.90000000","0.00000000"],["78699.87000000","0.15000000"],["78699.44000000","0.00000000"],["78697.16000000","1.21943000"],["78696.96000000","0.00000000"],["78696.85000000","3.12467000"],["78696.84000000","0.00000000"],["78696.34000000","0.00007000"],["78696.26000000","0.00000000"],["78696.04000000","0.06333000"],["78696.02000000","0.00000000"],["78696.01000000","0.00000000"],["78695.75000000","0.00254000"],["78694.91000000","0.00000000"],["78694.07000000","0.07280000"],["78694.06000000","0.00000000"],["78693.59000000","0.00000000"],["78693.18000000","0.00000000"],["78692.76000000","0.00000000"],["78692.13000000","0.04649000"],["78692.02000000","2.26739000"],["78692.01000000","0.00000000"],["78691.51000000","0.00000000"],["78690.07000000","0.50604000"],["78689.53000000","0.34316000"],["78689.13000000","0.13245000"],["78689.12000000","0.63530000"],["78689.11000000","0.00000000"],["78686.55000000","0.00012000"],["78684.06000000","0.00000000"],["78684.00000000","0.38624000"],["78682.98000000","0.00000000"],["78680.97000000","0.00014000"],["78680.00000000","0.12487000"],["78679.79000000","0.00400000"],["78678.10000000","0.00000000"],["78677.68000000","0.00400000"],["78676.51000000","0.00000000"],["78676.02000000","0.63559000"],["78675.99000000","0.00000000"],["78675.73000000","0.09334000"],["78675.57000000","0.00400000"],["78675.49000000","0.34322000"],["78673.46000000","0.00000000"],["78673.23000000","0.00007000"],["78671.33000000","0.00000000"],["78670.65000000","0.00000000"],["78669.92000000","0.00000000"],["78669.57000000","0.00000000"],["78669.44000000","0.00000000"],["78669.36000000","0.00000000"],["78668.42000000","0.00000000"],["78668.41000000","0.00000000"],["78667.51000000","0.00000000"],["78667.08000000","0.00000000"],["78666.63000000","0.00000000"],["78666.47000000","0.99894000"],["78666.24000000","0.00000000"],["78666.12000000","0.00014000"],["78664.88000000","0.00000000"],["78664.70000000","0.00000000"],["78664.50000000","0.00000000"],["78664.35000000","0.00000000"],["78664.16000000","0.00000000"],["78664.06000000","0.00000000"],["78663.56000000","0.02781000"],["78662.99000000","0.00000000"],["78662.81000000","0.00000000"],["78662.46000000","0.00000000"],["78662.27000000","0.00000000"],["78662.17000000","0.00007000"],["78662.01000000","0.00000000"],["78661.67000000","0.02348000"],["78658.07000000","0.00617000"],["78656.90000000","0.00424000"],["78654.22000000","0.00000000"],["78654.11000000","0.00431000"],["78653.58000000","0.00436000"],["78644.83000000","1.21952000"],["78644.08000000","0.86804000"],["78640.01000000","0.00000000"],["78636.93000000","0.00000000"],["78636.85000000","0.00000000"],["78636.61000000","0.00317000"],["78634.59000000","1.21952000"],["78633.93000000","0.00406000"],["78632.55000000","1.90515000"],["78630.70000000","0.00000000"],["78628.01000000","0.00243000"],["78624.35000000","1.21952000"],["78623.10000000","1.90515000"],["78619.38000000","0.00315000"],["78615.82000000","0.00000000"],["78613.65000000","1.90515000"],["78610.60000000","2.77157000"],["78605.56000000","0.00007000"],["78603.57000000","2.13881000"],["78593.46000000","0.00000000"],["78592.50000000","0.00000000"],["78590.56000000","0.00000000"],["78589.82000000","0.00007000"],["78589.70000000","0.00000000"],["78588.38000000","0.00000000"],["78587.60000000","0.09418000"],["78585.06000000","0.00000000"],["78574.08000000","0.00007000"],["78564.04000000","0.00000000"],["78562.13000000","0.09241000"],["78558.34000000","0.00007000"],["78557.67000000","0.00127000"],["78549.81000000","0.00097000"],["78546.15000000","0.00007000"],["78542.60000000","0.00007000"],["78526.86000000","0.00007000"],["78518.87000000","0.00000000"],["78511.12000000","0.00007000"],["78505.02000000","0.00000000"],["78505.01000000","0.00000000"],["78503.60000000","0.00779000"],["78498.76000000","0.00000000"],["78497.96000000","0.00007000"],["78495.38000000","0.00007000"],["78494.83000000","0.00000000"],["78494.03000000","0.00000000"],["78489.05000000","0.01990000"],["78479.64000000","0.00133000"],["78462.96000000","0.00000000"],["78400.02000000","0.00000000"],["78382.99000000","0.00031000"],["78330.38000000","0.00000000"],["78326.40000000","0.01000000"],["78317.01000000","0.00007000"],["77938.72000000","0.00000000"],["77934.76000000","0.01000000"],["77903.56000000","0.00154000"],["77549.03000000","0.00000000"],["77545.09000000","0.01000000"],["77161.28000000","0.00000000"],["77157.36000000","0.01000000"],["76775.48000000","0.00000000"],["76771.58000000","0.01000000"],["76391.60000000","0.00000000"],["76387.72000000","0.01000000"],["76009.64000000","0.00000000"],["76005.78000000","0.05000000"],["75629.59000000","0.00000000"],["75625.75000000","0.01000000"],["75251.45000000","0.00000000"],["75247.62000000","0.01000000"],["74875.19000000","0.00000000"],["74871.38000000","0.01000000"],["74500.81000000","0.00000000"],["74497.03000000","0.01000000"],["74128.31000000","0.00000000"],["74124.54000000","0.01000000"],["73757.67000000","0.00000000"],["73753.92000000","0.01000000"],["73388.88000000","0.00000000"],["73385.15000000","0.01000000"],["73021.93000000","0.00000000"],["73018.22000000","0.01000000"],["70851.60000000","0.00000000"],["70851.00000000","0.00000000"],["70849.80000000","0.00000000"],["70849.79000000","0.00009000"],["70848.00000000","0.00144000"],["62979.20000000","0.00000000"],["62979.00000000","0.00000000"],["62976.00000000","0.00031000"]],"a":[["78720.01000000","6.67002000"],["78720.02000000","0.00020000"],["78720.03000000","0.00013000"],["78720.04000000","0.00000000"],["78720.06000000","0.00014000"],["78720.07000000","0.65025000"],["78720.08000000","0.00000000"],["78720.09000000","0.00000000"],["78720.10000000","0.00014000"],["78720.11000000","0.06364000"],["78720.20000000","0.00322000"],["78720.50000000","0.00000000"],["78721.10000000","0.00000000"],["78721.20000000","0.02182000"],["78721.21000000","0.04126000"],["78721.22000000","0.00000000"],["78721.25000000","0.00014000"],["78721.26000000","0.00007000"],["78721.27000000","0.03601000"],["78721.33000000","0.00000000"],["78721.77000000","0.31765000"],["78721.78000000","0.00318000"],["78721.99000000","0.00400000"],["78722.00000000","0.00000000"],["78722.01000000","0.00014000"],["78722.36000000","0.00000000"],["78722.52000000","0.00000000"],["78722.53000000","0.04320000"],["78722.74000000","0.00007000"],["78722.75000000","0.05219000"],["78723.02000000","0.00007000"],["78723.53000000","0.00635000"],["78723.54000000","0.00014000"],["78723.55000000","0.00000000"],["78723.59000000","0.00000000"],["78723.79000000","0.04313000"],["78723.82000000","0.00000000"],["78723.84000000","0.00000000"],["78723.98000000","0.00000000"],["78723.99000000","0.31760000"],["78724.00000000","0.00000000"],["78724.01000000","0.05415000"],["78724.02000000","0.00000000"],["78724.03000000","0.00000000"],["78724.04000000","0.36224000"],["78724.05000000","0.00000000"],["78724.37000000","0.00000000"],["78724.38000000","0.02654000"],["78724.57000000","0.00007000"],["78724.71000000","0.00000000"],["78724.72000000","0.00400000"],["78724.73000000","0.23138000"],["78724.80000000","0.00008000"],["78725.27000000","0.00000000"],["78725.45000000","0.00635000"],["78725.75000000","0.02286000"],["78725.87000000","0.00326000"],["78726.00000000","0.03507000"],["78726.01000000","0.00020000"],["78726.02000000","0.38133000"],["78726.05000000","0.00319000"],["78726.39000000","0.00030000"],["78726.41000000","0.00254000"],["78726.53000000","0.00000000"],["78726.59000000","0.00000000"],["78726.62000000","0.00007000"],["78726.71000000","0.00000000"],["78727.40000000","0.00000000"],["78727.74000000","0.00000000"],["78727.79000000","0.00000000"],["78728.00000000","0.01000000"],["78728.12000000","0.00007000"],["78728.45000000","0.00000000"],["78728.63000000","0.38110000"],["78728.91000000","0.02000000"],["78729.08000000","0.00407000"],["78729.49000000","0.00455000"],["78729.83000000","0.00007000"],["78729.91000000","0.02000000"],["78730.00000000","0.11443000"],["78730.11000000","1.21952000"],["78731.27000000","0.00007000"],["78731.30000000","0.00007000"],["78731.37000000","0.00000000"],["78731.48000000","0.00007000"],["78731.95000000","0.34297000"],["78732.08000000","0.02000000"],["78732.10000000","0.36224000"],["78732.63000000","0.34297000"],["78732.75000000","0.00000000"],["78732.86000000","0.03000000"],["78732.90000000","0.02000000"],["78732.91000000","0.02000000"],["78733.23000000","0.02515000"],["78734.61000000","0.04103000"],["78735.76000000","0.11347000"],["78736.09000000","0.00000000"],["78736.16000000","0.00000000"],["78736.36000000","0.06329000"],["78736.77000000","0.09462000"],["78737.31000000","0.00000000"],["78737.57000000","0.00000000"],["78737.92000000","0.00000000"],["78738.32000000","0.07275000"],["78738.49000000","0.34295000"],["78738.79000000","0.00000000"],["78739.61000000","0.00000000"],["78739.91000000","0.00000000"],["78740.09000000","0.00000000"],["78740.13000000","0.00000000"],["78740.46000000","0.00000000"],["78740.48000000","0.00000000"],["78740.72000000","0.00007000"],["78741.24000000","0.00000000"],["78741.31000000","0.02000000"],["78741.36000000","0.00000000"],["78741.65000000","0.00000000"],["78741.67000000","0.00000000"],["78741.88000000","0.00000000"],["78742.27000000","0.00059000"],["78742.59000000","0.00000000"],["78743.09000000","0.00190000"],["78743.58000000","0.00007000"],["78744.41000000","0.00000000"],["78744.71000000","0.02843000"],["78746.06000000","0.00000000"],["78746.59000000","0.00000000"],["78747.11000000","0.34291000"],["78747.22000000","0.00007000"],["78747.45000000","0.00000000"],["78747.58000000","0.00000000"],["78747.66000000","0.00000000"],["78749.18000000","0.00314000"],["78750.01000000","0.21930000"],["78753.04000000","0.02505000"],["78753.45000000","0.00000000"],["78754.29000000","0.00000000"],["78754.69000000","0.00000000"],["78755.33000000","0.00000000"],["78756.16000000","0.00000000"],["78760.00000000","0.12923000"],["78762.24000000","0.00000000"],["78762.65000000","0.01162000"],["78762.96000000","0.00007000"],["78763.11000000","0.00000000"],["78764.00000000","0.02414000"],["78764.09000000","0.86672000"],["78764.51000000","0.00000000"],["78765.82000000","0.49721000"],["78766.62000000","0.00000000"],["78769.64000000","0.00316000"],["78770.05000000","0.81999000"],["78774.25000000","0.00000000"],["78775.62000000","0.00317000"],["78775.63000000","0.00000000"],["78778.80000000","0.00390000"],["78779.31000000","1.25683000"],["78781.05000000","0.00000000"],["78782.60000000","0.00000000"],["78782.84000000","0.00000000"],["78783.48000000","0.00000000"],["78784.63000000","0.00000000"],["78784.93000000","0.00000000"],["78795.59000000","0.00000000"],["78796.37000000","0.00000000"],["78797.99000000","0.00000000"],["78804.64000000","2.13335000"],["78809.53000000","0.04648000"],["78810.18000000","0.00007000"],["78818.75000000","0.02789000"],["78819.95000000","0.21930000"],["78824.59000000","0.00012000"],["78825.92000000","0.00007000"],["78826.70000000","0.00000000"],["78830.73000000","0.00019000"],["78830.98000000","0.00000000"],["78831.84000000","0.00000000"],["78833.11000000","0.00000000"],["78836.82000000","0.00031000"],["78837.11000000","0.00000000"],["78839.29000000","0.01270000"],["78841.66000000","0.00007000"],["78843.21000000","0.00007000"],["78855.27000000","0.00127000"],["78857.40000000","0.00007000"],["78873.14000000","0.00007000"],["78875.99000000","0.00000000"],["78888.88000000","0.00017000"],["78904.62000000","0.00007000"],["78920.36000000","0.00007000"],["78931.11000000","0.00406000"],["78936.10000000","0.00007000"],["78942.10000000","0.00000000"],["78951.84000000","0.00007000"],["78957.43000000","0.13173000"],["78968.91000000","0.00029000"],["78986.07000000","0.00000000"],["78989.95000000","0.02386000"],["78990.28000000","0.00486000"],["79007.83000000","0.00000000"],["79045.92000000","0.00000000"],["79047.26000000","0.00000000"],["79113.62000000","0.01000000"],["79117.64000000","0.01945000"],["79121.54000000","0.00000000"],["79155.30000000","0.00000000"],["79274.64000000","0.00000000"],["79509.18000000","0.01000000"],["79513.22000000","0.00000000"],["79906.73000000","0.01000000"],["79910.79000000","0.00000000"],["80306.26000000","0.01000000"],["80310.34000000","0.00000000"],["80707.79000000","0.01000000"],["80711.89000000","0.00000000"],["81111.33000000","0.01000000"],["81115.45000000","0.00000000"],["81516.89000000","0.01000000"],["81521.03000000","0.00000000"],["81924.47000000","0.01000000"],["81928.64000000","0.00000000"],["82334.10000000","0.01000000"],["82338.28000000","0.00000000"],["82745.77000000","0.01000000"],["82749.97000000","0.00000000"],["83159.50000000","0.01000000"],["83163.72000000","0.00000000"],["83575.29000000","0.01000000"],["83579.54000000","0.00066000"],["83993.17000000","0.01000000"],["83997.44000000","0.00000000"],["84413.14000000","0.01000000"],["84417.42000000","0.00000000"],["84835.20000000","0.01000000"],["84839.51000000","0.00000000"]]}}}
{"rx_ns": 33951481800, "frame": {"stream":"btcusdt@depth20","data":{"lastUpdateId":99076512191,"bids":[["78720.00000000","0.02590000"],["78719.99000000","0.00076000"],["78719.98000000","0.00013000"],["78719.88000000","0.00007000"],["78719.67000000","0.00007000"],["78718.44000000","0.00007000"],["78718.01000000","0.00014000"],["78718.00000000","0.02421000"],["78717.99000000","0.01634000"],["78717.81000000","0.01661000"],["78717.79000000","0.00200000"],["78717.44000000","0.00007000"],["78717.25000000","0.00014000"],["78717.24000000","0.04965000"],["78716.74000000","0.00007000"],["78716.55000000","0.02764000"],["78716.39000000","0.00007000"],["78716.01000000","0.00011000"],["78716.00000000","0.02476000"],["78715.80000000","0.00007000"]],"asks":[["78720.01000000","7.08087000"],["78720.02000000","0.00020000"],["78720.03000000","0.00013000"],["78720.06000000","0.00014000"],["78720.07000000","0.63748000"],["78720.20000000","0.00322000"],["78720.84000000","0.00400000"],["78721.20000000","0.02182000"],["78721.21000000","0.04126000"],["78721.26000000","0.00014000"],["78721.27000000","0.03601000"],["78721.45000000","0.00007000"],["78721.78000000","0.00318000"],["78721.99000000","0.00400000"],["78722.01000000","0.00014000"],["78722.23000000","0.00007000"],["78722.52000000","0.00014000"],["78722.53000000","0.04320000"],["78722.74000000","0.00007000"],["78722.75000000","0.05219000"]]}}}
{"rx_ns": 33951623500, "frame": {"stream":"btcusdt@depth","data":{"e":"depthUpdate","E":1787602901014,"s":"BTCUSDT","U":99076511889,"u":99076512191,"b":[["78720.00000000","0.02590000"],["78719.99000000","0.00076000"],["78719.98000000","0.00013000"],["78719.52000000","0.00000000"],["78717.24000000","0.04965000"],["78716.67000000","0.00000000"],["78715.29000000","0.03315000"],["78712.87000000","1.90515000"],["78712.86000000","0.20791000"],["78712.63000000","0.00204000"],["78711.03000000","0.00000000"],["78710.57000000","0.00324000"],["78709.90000000","0.00000000"],["78709.40000000","0.00000000"],["78708.81000000","0.00000000"],["78708.20000000","0.00000000"],["78706.50000000","0.00400000"],["78704.92000000","0.02600000"],["78704.91000000","0.00000000"],["78704.89000000","0.00400000"],["78704.77000000","0.00000000"],["78704.25000000","0.00000000"],["78704.24000000","0.00254000"],["78703.90000000","0.02000000"],["78702.90000000","0.00000000"],["78700.03000000","0.01600000"],["78696.34000000","0.00007000"],["78694.17000000","0.12707000"],["78692.13000000","0.00000000"],["78690.07000000","0.00000000"],["78689.29000000","0.04642000"],["78687.73000000","0.00000000"],["78687.70000000","0.49672000"],["78665.41000000","0.00000000"],["78665.25000000","0.00007000"],["78661.15000000","0.00007000"],["78643.29000000","0.02541000"],["78633.93000000","0.00000000"],["78630.76000000","0.00000000"],["78587.60000000","0.00000000"],["78586.71000000","0.00000000"],["78585.40000000","0.09418000"],["78562.45000000","1.52163000"],["78550.82000000","0.00000000"],["78515.87000000","0.00000000"],["78515.85000000","0.00406000"],["78326.40000000","0.01000000"],["78015.48000000","0.00000000"],["77934.76000000","0.01000000"],["77545.09000000","0.01000000"],["77157.36000000","0.01000000"],["76771.58000000","0.01000000"],["76387.72000000","0.01000000"],["76005.78000000","0.05000000"],["75625.75000000","0.01000000"],["75247.62000000","0.01000000"],["74871.38000000","0.01000000"],["74497.03000000","0.01000000"],["74124.54000000","0.01000000"],["73753.92000000","0.01000000"],["73385.15000000","0.01000000"],["73018.22000000","0.01000000"],["70848.00000000","0.00240000"],["62979.00000000","0.00000000"],["62976.00000000","0.00031000"]],"a":[["78720.01000000","7.08087000"],["78720.07000000","0.63748000"],["78720.09000000","0.00000000"],["78720.10000000","0.00000000"],["78720.11000000","0.00000000"],["78720.84000000","0.00400000"],["78721.20000000","0.02182000"],["78721.21000000","0.04126000"],["78721.25000000","0.00000000"],["78721.26000000","0.00014000"],["78721.27000000","0.03601000"],["78721.45000000","0.00007000"],["78721.76000000","0.00000000"],["78721.77000000","0.00000000"],["78722.23000000","0.00007000"],["78722.52000000","0.00014000"],["78722.74000000","0.00007000"],["78723.02000000","0.00000000"],["78723.53000000","0.00642000"],["78723.79000000","0.04320000"],["78723.98000000","0.00000000"],["78724.01000000","0.05398000"],["78724.04000000","0.00000000"],["78724.73000000","0.23145000"],["78725.66000000","0.12702000"],["78726.00000000","0.04207000"],["78726.02000000","0.38126000"],["78728.00000000","0.01700000"],["78731.37000000","0.02000000"],["78732.94000000","0.02000000"],["78736.46000000","0.04681000"],["78739.67000000","0.00000000"],["78741.25000000","0.00000000"],["78741.31000000","0.00000000"],["78741.40000000","0.12699000"],["78743.58000000","0.00007000"],["78751.85000000","0.02000000"],["78752.64000000","0.03000000"],["78752.68000000","0.02000000"],["78752.70000000","0.02000000"],["78752.72000000","0.00000000"],["78758.09000000","0.00000000"],["78795.59000000","0.00000000"],["78796.37000000","0.00000000"],["78817.61000000","0.00025000"],["78818.75000000","0.00000000"],["78821.52000000","0.02789000"],["78821.62000000","0.00000000"],["78861.54000000","1.52163000"],["79113.62000000","0.01000000"],["79509.18000000","0.01000000"],["79906.73000000","0.01000000"],["79988.00000000","0.02284000"],["80306.26000000","0.01000000"],["80707.79000000","0.01000000"],["81111.33000000","0.01000000"],["81516.89000000","0.01000000"],["81924.47000000","0.01000000"],["82334.10000000","0.01000000"],["82745.77000000","0.01000000"],["83159.50000000","0.01000000"],["83575.29000000","0.01000000"],["83993.17000000","0.01000000"],["84413.14000000","0.01000000"],["84835.20000000","0.01000000"]]}}}
{"rx_ns": 34953882500, "kind": "rest", "req": {"method": "GET", "url": "https://data-api.binance.vision/api/v3/depth?symbol=BTCUSDT&limit=100", "limit": 100, "weight": 5, "sent_ns": 32956335900, "status": 200, "used_weight_1m": "25", "recv_ns": 34014804900}, "frame": {"lastUpdateId":99076512191,"bids":[["78720.00000000","0.02590000"],["78719.99000000","0.00076000"],["78719.98000000","0.00013000"],["78719.88000000","0.00007000"],["78719.67000000","0.00007000"],["78718.44000000","0.00007000"],["78718.01000000","0.00014000"],["78718.00000000","0.02421000"],["78717.99000000","0.01634000"],["78717.81000000","0.01661000"],["78717.79000000","0.00200000"],["78717.44000000","0.00007000"],["78717.25000000","0.00014000"],["78717.24000000","0.04965000"],["78716.74000000","0.00007000"],["78716.55000000","0.02764000"],["78716.39000000","0.00007000"],["78716.01000000","0.00011000"],["78716.00000000","0.02476000"],["78715.80000000","0.00007000"],["78715.29000000","0.03315000"],["78715.00000000","0.00007000"],["78714.35000000","0.00007000"],["78714.03000000","0.03308000"],["78714.00000000","0.02400000"],["78713.56000000","0.00007000"],["78712.87000000","1.90515000"],["78712.86000000","0.20791000"],["78712.63000000","0.00204000"],["78712.30000000","0.00007000"],["78712.00000000","0.02400000"],["78711.93000000","0.00007000"],["78711.19000000","0.00329000"],["78711.02000000","1.22352000"],["78710.64000000","0.00010000"],["78710.63000000","0.00007000"],["78710.62000000","0.00010000"],["78710.57000000","0.00324000"],["78710.46000000","0.00027000"],["78710.25000000","0.00007000"],["78710.17000000","0.00007000"],["78710.00000000","0.02400000"],["78709.68000000","0.00007000"],["78709.41000000","0.02515000"],["78709.38000000","0.00400000"],["78709.29000000","0.12704000"],["78708.74000000","0.00048000"],["78708.50000000","0.21930000"],["78708.45000000","0.08576000"],["78708.21000000","0.00007000"],["78708.07000000","0.36224000"],["78708.06000000","1.90529000"],["78708.00000000","0.02407000"],["78707.85000000","0.00326000"],["78707.77000000","0.00007000"],["78707.67000000","0.00007000"],["78707.41000000","0.00400000"],["78707.18000000","0.00048000"],["78707.03000000","1.21952000"],["78707.01000000","0.00007000"],["78706.50000000","0.00400000"],["78706.26000000","0.00635000"],["78706.25000000","0.00163000"],["78706.16000000","0.00007000"],["78706.00000000","0.02400000"],["78705.99000000","0.00047000"],["78705.84000000","0.00188000"],["78705.80000000","0.00007000"],["78705.78000000","0.02200000"],["78705.74000000","0.02400000"],["78705.56000000","0.02287000"],["78705.26000000","0.00400000"],["78705.09000000","0.00328000"],["78705.01000000","0.00007000"],["78705.00000000","0.02000000"],["78704.95000000","0.02600000"],["78704.92000000","0.02600000"],["78704.89000000","0.00400000"],["78704.68000000","0.00254000"],["78704.24000000","0.00254000"],["78704.19000000","0.00014000"],["78704.12000000","0.00007000"],["78704.00000000","0.02400000"],["78703.91000000","0.00322000"],["78703.90000000","0.02000000"],["78703.47000000","0.00400000"],["78703.01000000","0.00007000"],["78702.89000000","1.21952000"],["78702.77000000","0.00010000"],["78702.66000000","0.02200000"],["78702.09000000","1.90515000"],["78702.07000000","0.00007000"],["78702.00000000","0.02400000"],["78701.92000000","0.00007000"],["78701.87000000","0.02000000"],["78701.71000000","0.00635000"],["78701.70000000","0.00008000"],["78701.50000000","0.00400000"],["78701.47000000","0.00027000"],["78701.42000000","0.12706000"]],"asks":[["78720.01000000","7.08087000"],["78720.02000000","0.00020000"],["78720.03000000","0.00013000"],["78720.06000000","0.00014000"],["78720.07000000","0.63748000"],["78720.20000000","0.00322000"],["78720.84000000","0.00400000"],["78721.20000000","0.02182000"],["78721.21000000","0.04126000"],["78721.26000000","0.00014000"],["78721.27000000","0.03601000"],["78721.45000000","0.00007000"],["78721.78000000","0.00318000"],["78721.99000000","0.00400000"],["78722.01000000","0.00014000"],["78722.23000000","0.00007000"],["78722.52000000","0.00014000"],["78722.53000000","0.04320000"],["78722.74000000","0.00007000"],["78722.75000000","0.05219000"],["78723.53000000","0.00642000"],["78723.54000000","0.00014000"],["78723.79000000","0.04320000"],["78723.99000000","0.31760000"],["78724.01000000","0.05398000"],["78724.38000000","0.02654000"],["78724.57000000","0.00007000"],["78724.72000000","0.00400000"],["78724.73000000","0.23145000"],["78724.80000000","0.00008000"],["78725.45000000","0.00635000"],["78725.46000000","0.00400000"],["78725.66000000","0.12702000"],["78725.75000000","0.02286000"],["78725.87000000","0.00326000"],["78726.00000000","0.04207000"],["78726.01000000","0.00020000"],["78726.02000000","0.38126000"],["78726.05000000","0.00319000"],["78726.38000000","0.02161000"],["78726.39000000","0.00030000"],["78726.41000000","0.00254000"],["78726.62000000","0.00007000"],["78727.41000000","0.00014000"],["78727.48000000","0.00400000"],["78727.85000000","0.00027000"],["78728.00000000","0.01700000"],["78728.12000000","0.00007000"],["78728.63000000","0.38110000"],["78728.66000000","0.00007000"],["78728.91000000","0.02000000"],["78728.97000000","0.00331000"],["78729.00000000","0.00007000"],["78729.08000000","0.00407000"],["78729.49000000","0.00455000"],["78729.50000000","0.00400000"],["78729.83000000","0.00007000"],["78729.91000000","0.02000000"],["78730.00000000","0.11443000"],["78730.11000000","1.21952000"],["78730.27000000","0.00319000"],["78730.71000000","0.00007000"],["78731.05000000","0.00400000"],["78731.27000000","0.00007000"],["78731.28000000","0.00014000"],["78731.30000000","0.00007000"],["78731.37000000","0.02000000"],["78731.39000000","0.02000000"],["78731.48000000","0.00007000"],["78731.85000000","0.00324000"],["78731.95000000","0.34297000"],["78732.00000000","0.02400000"],["78732.08000000","0.02000000"],["78732.10000000","0.36224000"],["78732.11000000","0.02000000"],["78732.18000000","0.02000000"],["78732.19000000","0.02000000"],["78732.50000000","0.00008000"],["78732.63000000","0.34297000"],["78732.76000000","0.00007000"],["78732.86000000","0.03000000"],["78732.90000000","0.02000000"],["78732.91000000","0.02000000"],["78732.94000000","0.02000000"],["78732.96000000","0.00007000"],["78733.02000000","0.00400000"],["78733.23000000","0.02515000"],["78733.43000000","0.12701000"],["78733.98000000","0.02161000"],["78734.00000000","0.02400000"],["78734.13000000","0.21944000"],["78734.42000000","0.00007000"],["78734.61000000","0.04103000"],["78734.81000000","0.00007000"],["78734.99000000","0.00400000"],["78735.14000000","1.21952000"],["78735.15000000","1.90529000"],["78735.16000000","0.14289000"],["78735.26000000","0.02000000"],["78735.39000000","0.19391000"]]}}
{"rx_ns": 34953882500, "frame": {"stream":"btcusdt@depth20","data":{"lastUpdateId":99076512677,"bids":[["78720.00000000","0.02576000"],["78719.99000000","0.00069000"],["78719.98000000","0.00013000"],["78719.88000000","0.00007000"],["78719.67000000","0.00007000"],["78718.44000000","0.00007000"],["78718.01000000","0.00014000"],["78718.00000000","0.02421000"],["78717.99000000","0.01634000"],["78717.81000000","0.01661000"],["78717.79000000","0.00200000"],["78717.44000000","0.00007000"],["78717.25000000","0.00014000"],["78717.24000000","0.04965000"],["78716.55000000","0.02764000"],["78716.39000000","0.00007000"],["78716.01000000","0.00011000"],["78716.00000000","0.02469000"],["78715.80000000","0.00007000"],["78715.29000000","0.03315000"]],"asks":[["78720.01000000","6.15693000"],["78720.02000000","0.00020000"],["78720.03000000","0.00013000"],["78720.04000000","0.00014000"],["78720.05000000","0.06357000"],["78720.06000000","0.00014000"],["78720.07000000","0.63748000"],["78720.20000000","0.00322000"],["78720.84000000","0.00400000"],["78721.20000000","0.02182000"],["78721.21000000","0.04126000"],["78721.26000000","0.00014000"],["78721.27000000","0.03601000"],["78721.45000000","0.00007000"],["78721.78000000","0.00318000"],["78721.99000000","0.00400000"],["78722.01000000","0.00014000"],["78722.23000000","0.00007000"],["78722.52000000","0.00007000"],["78722.53000000","0.04320000"]]}}}
{"rx_ns": 34954064800, "frame": {"stream":"btcusdt@depth","data":{"e":"depthUpdate","E":1787602902014,"s":"BTCUSDT","U":99076512192,"u":99076512677,"b":[["78720.00000000","0.02576000"],["78719.99000000","0.00069000"],["78719.97000000","0.00000000"],["78717.99000000","0.01634000"],["78717.95000000","0.00000000"],["78717.24000000","0.04965000"],["78716.74000000","0.00000000"],["78716.61000000","0.00000000"],["78716.00000000","0.02469000"],["78715.78000000","0.00000000"],["78712.88000000","0.00000000"],["78712.87000000","0.00000000"],["78712.86000000","0.00000000"],["78712.63000000","0.00000000"],["78711.19000000","0.00000000"],["78711.02000000","1.21952000"],["78710.57000000","0.00000000"],["78709.46000000","0.00000000"],["78709.38000000","0.00000000"],["78709.30000000","0.20791000"],["78709.11000000","0.00000000"],["78708.92000000","0.00000000"],["78708.66000000","0.00000000"],["78708.50000000","0.00000000"],["78708.06000000","1.90522000"],["78707.85000000","0.00000000"],["78707.48000000","0.00000000"],["78707.03000000","1.24535000"],["78706.92000000","0.00330000"],["78706.50000000","0.00000000"],["78706.36000000","0.00000000"],["78706.25000000","0.00000000"],["78705.20000000","0.00000000"],["78705.19000000","0.00000000"],["78704.89000000","0.00000000"],["78704.75000000","0.00000000"],["78704.74000000","0.00400000"],["78704.73000000","0.00000000"],["78704.69000000","0.00406000"],["78704.63000000","0.00000000"],["78704.62000000","0.00000000"],["78704.24000000","0.00000000"],["78703.96000000","0.00000000"],["78703.94000000","0.00000000"],["78703.90000000","0.00000000"],["78703.20000000","0.00000000"],["78703.19000000","0.00000000"],["78702.91000000","0.00000000"],["78702.90000000","0.00000000"],["78702.30000000","0.00000000"],["78701.78000000","0.00000000"],["78700.03000000","0.00000000"],["78700.01000000","0.01600000"],["78700.00000000","0.04433000"],["78697.91000000","0.00150000"],["78696.34000000","0.00007000"],["78689.12000000","0.00000000"],["78688.01000000","0.63532000"],["78683.65000000","0.00007000"],["78681.70000000","0.00400000"],["78675.73000000","0.00000000"],["78675.57000000","0.00000000"],["78671.40000000","0.00400000"],["78669.36000000","0.00007000"],["78666.12000000","0.00007000"],["78665.39000000","0.00406000"],["78663.56000000","0.00000000"],["78663.26000000","0.00000000"],["78663.03000000","0.02747000"],["78661.67000000","0.00000000"],["78661.37000000","0.00000000"],["78661.14000000","0.02356000"],["78654.76000000","0.00007000"],["78633.91000000","0.00000000"],["78630.76000000","0.00000000"],["78628.56000000","0.00000000"],["78610.60000000","0.00000000"],["78605.38000000","2.77171000"],["78588.52000000","0.04474000"],["78586.69000000","0.00419000"],["78585.40000000","0.00000000"],["78532.50000000","4.42364000"],["78504.57000000","0.00779000"],["78503.60000000","0.00000000"],["78407.84000000","0.21930000"],["78326.40000000","0.01000000"],["78011.52000000","0.00010000"],["77934.76000000","0.01000000"],["77545.09000000","0.01000000"],["77157.36000000","0.01000000"],["76771.58000000","0.01000000"],["76387.72000000","0.01000000"],["76005.78000000","0.05000000"],["75625.75000000","0.01000000"],["75247.62000000","0.01000000"],["74871.38000000","0.01000000"],["74497.03000000","0.01000000"],["74124.54000000","0.01000000"],["73753.92000000","0.01000000"],["73385.15000000","0.01000000"],["73018.22000000","0.01000000"],["70849.79000000","0.00000000"],["70848.00000000","0.00320000"],["62976.00000000","0.00031000"]],"a":[["78720.01000000","6.15693000"],["78720.04000000","0.00014000"],["78720.05000000","0.06357000"],["78720.07000000","0.63748000"],["78720.21000000","0.00000000"],["78720.23000000","0.00000000"],["78720.26000000","0.00000000"],["78720.28000000","0.00000000"],["78720.30000000","0.00000000"],["78720.44000000","0.00000000"],["78720.82000000","0.00000000"],["78720.83000000","0.00000000"],["78721.20000000","0.02182000"],["78721.26000000","0.00014000"],["78722.52000000","0.00007000"],["78722.74000000","0.00007000"],["78722.75000000","0.05226000"],["78723.53000000","0.00007000"],["78723.79000000","0.04313000"],["78723.97000000","0.00000000"],["78723.98000000","2.26739000"],["78724.00000000","0.00500000"],["78724.01000000","0.02248000"],["78724.72000000","0.00000000"],["78724.73000000","0.20145000"],["78726.00000000","0.02407000"],["78728.00000000","0.02400000"],["78729.31000000","1.90515000"],["78729.99000000","0.02161000"],["78733.00000000","0.02515000"],["78733.23000000","0.00000000"],["78743.58000000","0.00007000"],["78744.39000000","0.00000000"],["78750.33000000","1.25729000"],["78751.13000000","0.04000000"],["78752.71000000","0.02000000"],["78762.55000000","0.00000000"],["78777.03000000","0.00000000"],["78777.19000000","0.00000000"],["78782.81000000","0.00000000"],["78800.09000000","0.00000000"],["78802.26000000","0.00000000"],["78807.07000000","0.00000000"],["78807.53000000","0.00000000"],["78807.89000000","0.00000000"],["78820.49000000","0.00000000"],["78926.22000000","0.01990000"],["78948.17000000","0.00000000"],["78949.72000000","0.00000000"],["79113.62000000","0.01000000"],["79509.18000000","0.01000000"],["79906.73000000","0.01000000"],["80306.26000000","0.01000000"],["80707.79000000","0.01000000"],["81111.33000000","0.01000000"],["81516.89000000","0.01000000"],["81924.47000000","0.01000000"],["82334.10000000","0.01000000"],["82745.77000000","0.01000000"],["83159.50000000","0.01000000"],["83575.29000000","0.01000000"],["83993.17000000","0.01000000"],["84413.14000000","0.01000000"],["84835.20000000","0.01000000"]]}}}
{"rx_ns": 35954005400, "frame": {"stream":"btcusdt@depth20","data":{"lastUpdateId":99076513321,"bids":[["78718.00000000","0.02528000"],["78717.99000000","0.01690000"],["78717.79000000","0.00200000"],["78717.52000000","0.00007000"],["78717.44000000","0.00007000"],["78716.01000000","0.00025000"],["78716.00000000","0.02407000"],["78715.95000000","0.00007000"],["78715.81000000","0.01661000"],["78715.80000000","0.00007000"],["78715.28000000","0.04176000"],["78715.19000000","0.00007000"],["78715.18000000","0.04963000"],["78714.55000000","0.02764000"],["78714.35000000","0.00007000"],["78714.01000000","0.00007000"],["78714.00000000","0.02407000"],["78713.56000000","0.00007000"],["78713.29000000","0.03308000"],["78712.30000000","0.00007000"]],"asks":[["78718.01000000","5.69086000"],["78718.02000000","0.00020000"],["78718.03000000","0.00013000"],["78718.76000000","0.00014000"],["78718.77000000","0.31774000"],["78718.78000000","0.00400000"],["78719.26000000","0.00014000"],["78719.27000000","0.03601000"],["78719.67000000","0.00014000"],["78719.99000000","0.00014000"],["78720.00000000","0.31783000"],["78720.01000000","2.04225000"],["78720.06000000","0.00014000"],["78720.07000000","0.42760000"],["78720.20000000","0.00322000"],["78720.53000000","0.04320000"],["78720.69000000","0.05215000"],["78720.84000000","0.00400000"],["78721.20000000","0.02168000"],["78721.21000000","0.04119000"]]}}}
{"rx_ns": 35954166200, "frame": {"stream":"btcusdt@depth","data":{"e":"depthUpdate","E":1787602903014,"s":"BTCUSDT","U":99076512678,"u":99076513321,"b":[["78720.00000000","0.00000000"],["78719.99000000","0.00000000"],["78719.98000000","0.00000000"],["78719.88000000","0.00000000"],["78719.67000000","0.00000000"],["78718.44000000","0.00000000"],["78718.01000000","0.00000000"],["78718.00000000","0.02528000"],["78717.99000000","0.01690000"],["78717.82000000","0.00000000"],["78717.81000000","0.00000000"],["78717.52000000","0.00007000"],["78717.25000000","0.00000000"],["78717.24000000","0.00000000"],["78716.74000000","0.00000000"],["78716.56000000","0.00000000"],["78716.55000000","0.00000000"],["78716.39000000","0.00000000"],["78716.01000000","0.00025000"],["78716.00000000","0.02407000"],["78715.95000000","0.00007000"],["78715.81000000","0.01661000"],["78715.29000000","0.00000000"],["78715.28000000","0.04176000"],["78715.19000000","0.00007000"],["78715.18000000","0.04963000"],["78715.00000000","0.00000000"],["78714.55000000","0.02764000"],["78714.03000000","0.00000000"],["78714.01000000","0.00007000"],["78714.00000000","0.02407000"],["78713.90000000","0.00000000"],["78713.29000000","0.03308000"],["78712.91000000","0.00000000"],["78712.66000000","0.00000000"],["78712.03000000","0.03308000"],["78712.00000000","0.02400000"],["78711.03000000","0.00000000"],["78711.02000000","1.21952000"],["78710.00000000","0.02400000"],["78709.37000000","0.00204000"],["78709.30000000","0.20798000"],["78709.29000000","0.12711000"],["78708.45000000","0.00007000"],["78708.06000000","0.00007000"],["78707.23000000","0.00000000"],["78707.05000000","0.00400000"],["78707.04000000","1.90515000"],["78707.03000000","1.21952000"],["78707.01000000","0.00007000"],["78706.92000000","0.00000000"],["78706.79000000","0.00070000"],["78706.49000000","0.08576000"],["78706.41000000","0.00000000"],["78706.40000000","0.00330000"],["78706.38000000","0.00000000"],["78706.34000000","0.00000000"],["78706.26000000","0.00000000"],["78704.74000000","0.00000000"],["78704.69000000","0.00000000"],["78703.46000000","0.00400000"],["78703.02000000","0.00635000"],["78702.90000000","0.00000000"],["78701.42000000","0.12706000"],["78701.38000000","0.00000000"],["78701.33000000","0.00000000"],["78701.32000000","0.00000000"],["78701.31000000","0.00000000"],["78701.29000000","0.00254000"],["78700.65000000","0.00000000"],["78700.64000000","0.00000000"],["78700.63000000","0.00000000"],["78700.62000000","0.21930000"],["78700.59000000","0.00000000"],["78700.01000000","0.00400000"],["78697.99000000","0.00092000"],["78696.34000000","0.00000000"],["78694.34000000","0.00007000"],["78690.55000000","0.00000000"],["78689.29000000","0.00000000"],["78687.34000000","0.04657000"],["78682.46000000","0.00635000"],["78680.00000000","0.11487000"],["78678.00000000","0.03400000"],["78675.13000000","0.00000000"],["78675.01000000","0.09758000"],["78674.65000000","0.00400000"],["78672.66000000","0.00000000"],["78671.40000000","0.00000000"],["78670.57000000","0.00000000"],["78665.39000000","0.00000000"],["78663.03000000","0.00000000"],["78662.22000000","0.02827000"],["78661.14000000","0.00000000"],["78660.34000000","0.02427000"],["78657.06000000","0.00007000"],["78652.55000000","0.00000000"],["78645.86000000","0.01133000"],["78636.75000000","0.01698000"],["78636.61000000","0.00000000"],["78634.60000000","0.00317000"],["78633.85000000","0.00000000"],["78631.81000000","0.00406000"],["78628.01000000","0.00000000"],["78626.96000000","0.02116000"],["78626.01000000","0.00243000"],["78588.52000000","0.00000000"],["78586.69000000","0.00013000"],["78584.59000000","0.00406000"],["78579.95000000","0.09531000"],["78563.96000000","0.00632000"],["78544.83000000","1.20000000"],["78515.85000000","0.00000000"],["78501.32000000","0.00007000"],["78497.96000000","0.00000000"],["78326.40000000","0.00000000"],["78324.41000000","0.01000000"],["78232.00000000","0.00015000"],["77934.76000000","0.00000000"],["77932.78000000","0.01000000"],["77545.09000000","0.00000000"],["77543.12000000","0.01000000"],["77157.36000000","0.00000000"],["77155.40000000","0.01000000"],["76771.58000000","0.00000000"],["76769.63000000","0.01000000"],["76387.72000000","0.00000000"],["76385.78000000","0.01000000"],["76005.78000000","0.04000000"],["76003.85000000","0.01000000"],["75625.75000000","0.00000000"],["75623.83000000","0.01000000"],["75247.62000000","0.00000000"],["75245.71000000","0.01000000"],["74871.38000000","0.00000000"],["74869.48000000","0.01000000"],["74497.03000000","0.00000000"],["74495.13000000","0.01000000"],["74124.54000000","0.00000000"],["74122.66000000","0.01000000"],["73753.92000000","0.00000000"],["73752.05000000","0.01000000"],["73385.15000000","0.00000000"],["73383.29000000","0.01000000"],["73018.22000000","0.00000000"],["73016.37000000","0.01000000"],["70848.00000000","0.00000000"],["70846.20000000","0.00160000"],["70846.00000000","0.00000000"],["62976.00000000","0.00000000"],["62974.40000000","0.00031000"],["62974.00000000","0.00000000"]],"a":[["78718.01000000","5.69086000"],["78718.02000000","0.00020000"],["78718.03000000","0.00013000"],["78718.76000000","0.00014000"],["78718.77000000","0.31774000"],["78718.78000000","0.00400000"],["78719.26000000","0.00014000"],["78719.27000000","0.03601000"],["78719.67000000","0.00014000"],["78719.99000000","0.00014000"],["78720.00000000","0.31783000"],["78720.01000000","2.04225000"],["78720.02000000","0.00000000"],["78720.03000000","0.00000000"],["78720.04000000","0.00000000"],["78720.05000000","0.00000000"],["78720.06000000","0.00014000"],["78720.07000000","0.42760000"],["78720.53000000","0.04320000"],["78720.69000000","0.05215000"],["78721.20000000","0.02168000"],["78721.21000000","0.04119000"],["78721.26000000","0.00000000"],["78721.27000000","0.00000000"],["78721.45000000","0.00000000"],["78721.79000000","0.04313000"],["78722.00000000","0.00071000"],["78722.23000000","0.00000000"],["78722.52000000","0.00007000"],["78722.53000000","0.00000000"],["78722.74000000","0.00000000"],["78722.75000000","0.00007000"],["78723.53000000","0.00000000"],["78723.79000000","0.00000000"],["78723.96000000","0.00000000"],["78723.97000000","1.21952000"],["78723.99000000","0.00000000"],["78724.00000000","0.01000000"],["78725.66000000","0.12709000"],["78725.89000000","0.21930000"],["78726.01000000","0.00007000"],["78726.02000000","0.38119000"],["78726.39000000","0.00000000"],["78727.83000000","0.00007000"],["78728.11000000","0.00455000"],["78729.30000000","0.00007000"],["78729.49000000","0.00000000"],["78731.30000000","0.00000000"],["78732.65000000","0.04103000"],["78733.76000000","0.10037000"],["78734.61000000","0.00000000"],["78735.76000000","0.00000000"],["78736.77000000","0.00000000"],["78741.13000000","0.09471000"],["78741.58000000","0.00007000"],["78742.12000000","0.00000000"],["78743.00000000","0.00000000"],["78743.58000000","0.00000000"],["78748.28000000","0.00400000"],["78748.78000000","0.00000000"],["78750.75000000","0.00000000"],["78753.58000000","0.00428000"],["78754.38000000","0.00630000"],["78758.00000000","0.03400000"],["78758.37000000","0.36224000"],["78760.00000000","0.11923000"],["78763.04000000","0.00000000"],["78763.99000000","0.00000000"],["78777.04000000","0.00000000"],["78780.29000000","0.01709000"],["78781.50000000","0.00007000"],["78783.95000000","0.00000000"],["78793.23000000","0.09295000"],["78794.46000000","0.00000000"],["78806.26000000","0.00000000"],["78807.94000000","0.00406000"],["78809.89000000","0.00000000"],["78812.99000000","0.00000000"],["78816.06000000","0.02789000"],["78821.52000000","0.00000000"],["78855.18000000","0.00406000"],["78860.24000000","0.00000000"],["78931.11000000","0.00000000"],["78938.17000000","0.00000000"],["78940.05000000","0.00000000"],["79111.61000000","0.01008000"],["79113.62000000","0.00000000"],["79507.16000000","0.01000000"],["79509.18000000","0.00000000"],["79904.70000000","0.01000000"],["79906.73000000","0.00000000"],["80304.22000000","0.01000000"],["80306.26000000","0.00000000"],["80705.74000000","0.01000000"],["80707.79000000","0.00000000"],["81109.27000000","0.01000000"],["81111.33000000","0.00000000"],["81514.82000000","0.01000000"],["81516.89000000","0.00000000"],["81922.39000000","0.01000000"],["81924.47000000","0.00000000"],["82332.00000000","0.01020000"],["82334.10000000","0.00000000"],["82743.66000000","0.01000000"],["82745.77000000","0.00000000"],["83157.38000000","0.01000000"],["83159.50000000","0.00000000"],["83573.17000000","0.01000000"],["83575.29000000","0.00000000"],["83991.04000000","0.01000000"],["83993.17000000","0.00000000"],["84410.99000000","0.01000000"],["84413.14000000","0.00000000"],["84833.05000000","0.01000000"],["84835.20000000","0.00000000"]]}}}
{"rx_ns": 36953725700, "frame": {"stream":"btcusdt@depth20","data":{"lastUpdateId":99076513498,"bids":[["78718.00000000","0.02515000"],["78717.99000000","0.01696000"],["78717.98000000","0.00013000"],["78717.79000000","0.00200000"],["78717.52000000","0.00007000"],["78717.44000000","0.00007000"],["78716.01000000","0.00025000"],["78716.00000000","0.02407000"],["78715.95000000","0.00007000"],["78715.81000000","0.01661000"],["78715.80000000","0.00007000"],["78715.19000000","0.00007000"],["78715.18000000","0.04963000"],["78714.55000000","0.02764000"],["78714.35000000","0.00007000"],["78714.25000000","0.03835000"],["78714.01000000","0.00007000"],["78714.00000000","0.02407000"],["78713.56000000","0.00007000"],["78713.29000000","0.03315000"]],"asks":[["78718.01000000","6.27487000"],["78718.02000000","0.00020000"],["78718.03000000","0.00013000"],["78718.04000000","0.00014000"],["78718.05000000","0.06357000"],["78718.78000000","0.00400000"],["78719.09000000","0.00007000"],["78719.26000000","0.00014000"],["78719.27000000","0.03601000"],["78719.67000000","0.00014000"],["78719.99000000","0.00014000"],["78720.00000000","0.31783000"],["78720.01000000","2.04215000"],["78720.06000000","0.00014000"],["78720.07000000","0.42760000"],["78720.20000000","0.00322000"],["78720.53000000","0.04320000"],["78720.69000000","0.05215000"],["78720.84000000","0.00400000"],["78721.20000000","0.02168000"]]}}}
{"rx_ns": 36953835600, "frame": {"stream":"btcusdt@depth","data":{"e":"depthUpdate","E":1787602904014,"s":"BTCUSDT","U":99076513322,"u":99076513498,"b":[["78718.00000000","0.02515000"],["78717.99000000","0.01696000"],["78717.98000000","0.00013000"],["78715.81000000","0.01661000"],["78715.28000000","0.00000000"],["78714.55000000","0.02764000"],["78714.25000000","0.03835000"],["78713.29000000","0.03315000"],["78707.05000000","0.00400000"],["78706.17000000","0.00000000"],["78706.10000000","0.00000000"],["78702.65000000","0.00406000"],["78701.29000000","0.00000000"],["78701.28000000","0.00000000"],["78701.27000000","0.00000000"],["78701.26000000","0.00000000"],["78701.23000000","0.00000000"],["78701.17000000","0.00000000"],["78701.16000000","0.00000000"],["78700.40000000","0.00000000"],["78700.38000000","0.00381000"],["78697.92000000","0.00000000"],["78694.34000000","0.00007000"],["78663.29000000","0.00406000"],["78633.98000000","0.02541000"],["78626.96000000","0.00000000"],["78584.66000000","0.04474000"],["78579.95000000","0.00000000"],["78560.55000000","0.00000000"],["78554.57000000","0.01990000"],["78536.01000000","0.00010000"],["78513.76000000","0.00406000"],["78504.57000000","0.00000000"],["78503.14000000","0.00779000"],["78324.41000000","0.00000000"],["78011.52000000","0.00000000"],["77932.78000000","0.00000000"],["77543.12000000","0.00000000"],["77155.40000000","0.00000000"],["76769.63000000","0.00000000"],["76385.78000000","0.00000000"],["76003.85000000","0.00000000"],["75623.83000000","0.00000000"],["75245.71000000","0.00000000"],["74869.48000000","0.00000000"],["74495.13000000","0.00000000"],["74122.66000000","0.00000000"],["73752.05000000","0.00000000"],["73383.29000000","0.00000000"],["73016.37000000","0.00000000"],["72426.09000000","0.00014000"],["70846.20000000","0.00265000"],["70846.00000000","0.00000000"],["62976.00000000","0.00000000"],["62974.40000000","0.00031000"]],"a":[["78718.01000000","6.27487000"],["78718.04000000","0.00014000"],["78718.05000000","0.06357000"],["78718.76000000","0.00000000"],["78718.77000000","0.00000000"],["78719.09000000","0.00007000"],["78720.01000000","2.04215000"],["78721.21000000","0.04119000"],["78723.96000000","0.00000000"],["78724.00000000","0.01700000"],["78737.07000000","0.00406000"],["78741.58000000","0.00007000"],["78757.33000000","0.00669000"],["78776.44000000","0.00406000"],["78792.75000000","0.00000000"],["78801.11000000","0.93647000"],["78816.77000000","0.00000000"],["78833.60000000","0.00000000"],["78844.82000000","0.00000000"],["78852.34000000","0.00000000"],["78853.63000000","0.00000000"],["78891.76000000","0.00000000"],["79111.61000000","0.00008000"],["79507.16000000","0.00000000"],["79904.70000000","0.00000000"],["80304.22000000","0.00000000"],["80705.74000000","0.00000000"],["81109.27000000","0.00000000"],["81514.82000000","0.00000000"],["81922.39000000","0.00000000"],["82332.00000000","0.00020000"],["82743.66000000","0.00000000"],["83157.38000000","0.00000000"],["83573.17000000","0.00000000"],["83991.04000000","0.00000000"],["84410.99000000","0.00000000"],["84833.05000000","0.00000000"],["85372.92000000","0.00000000"]]}}}
{"rx_ns": 37951181000, "frame": {"stream":"btcusdt@depth20","data":{"lastUpdateId":99076513704,"bids":[["78718.00000000","0.06302000"],["78717.99000000","0.01703000"],["78717.98000000","0.00013000"],["78717.79000000","0.00200000"],["78717.52000000","0.00007000"],["78717.44000000","0.00007000"],["78716.31000000","0.04644000"],["78716.01000000","0.00025000"],["78716.00000000","0.02407000"],["78715.95000000","0.00007000"],["78715.81000000","0.01661000"],["78715.80000000","0.00007000"],["78715.19000000","0.00007000"],["78715.18000000","0.04963000"],["78714.55000000","0.02757000"],["78714.35000000","0.00007000"],["78714.01000000","0.00007000"],["78714.00000000","0.02407000"],["78713.56000000","0.00007000"],["78713.29000000","0.03315000"]],"asks":[["78718.01000000","6.35071000"],["78718.02000000","0.00020000"],["78718.03000000","0.00013000"],["78718.04000000","0.00014000"],["78718.05000000","0.06364000"],["78718.76000000","0.00014000"],["78718.77000000","0.31774000"],["78718.78000000","0.00400000"],["78719.09000000","0.00007000"],["78719.26000000","0.00014000"],["78719.27000000","0.03601000"],["78719.67000000","0.00014000"],["78719.87000000","0.00007000"],["78719.99000000","0.00014000"],["78720.00000000","0.31769000"],["78720.01000000","0.00208000"],["78720.06000000","0.00014000"],["78720.07000000","0.42760000"],["78720.20000000","0.00322000"],["78720.53000000","0.04320000"]]}}}
{"rx_ns": 37951288100, "frame": {"stream":"btcusdt@depth","data":{"e":"depthUpdate","E":1787602905014,"s":"BTCUSDT","U":99076513499,"u":99076513704,"b":[["78718.00000000","0.06302000"],["78717.99000000","0.01703000"],["78716.31000000","0.04644000"],["78715.81000000","0.01661000"],["78715.24000000","0.00000000"],["78714.55000000","0.02757000"],["78714.25000000","0.00000000"],["78710.12000000","0.21930000"],["78707.11000000","0.00000000"],["78707.05000000","0.00400000"],["78706.77000000","0.00000000"],["78706.56000000","0.00000000"],["78705.88000000","0.00000000"],["78701.37000000","0.00000000"],["78701.36000000","0.00254000"],["78700.39000000","0.00000000"],["78700.38000000","0.00127000"],["78694.34000000","0.00007000"],["78690.21000000","0.00007000"],["78662.22000000","0.00000000"],["78662.15000000","0.02826000"],["78660.34000000","0.00000000"],["78660.26000000","0.24304000"],["78629.62000000","0.00316000"],["78626.96000000","0.00000000"],["78619.38000000","0.00000000"],["78503.60000000","0.00779000"],["78503.14000000","0.00000000"],["78501.32000000","0.00000000"],["78393.54000000","0.00221000"],["78324.41000000","0.00000000"],["78009.54000000","0.00010000"],["77932.78000000","0.00000000"],["77543.12000000","0.00000000"],["77155.40000000","0.00000000"],["77147.95000000","0.00291000"],["76769.63000000","0.00000000"],["76385.78000000","0.00000000"],["76003.85000000","0.00000000"],["75623.83000000","0.00000000"],["75245.71000000","0.00000000"],["74869.48000000","0.00000000"],["74495.13000000","0.00000000"],["74122.66000000","0.00000000"],["73752.05000000","0.00000000"],["73383.29000000","0.00000000"],["73016.37000000","0.00000000"],["72426.09000000","0.00000000"],["70846.20000000","0.00336000"],["70846.19000000","0.00009000"],["70846.00000000","0.00000000"],["62974.40000000","0.00031000"],["62974.00000000","0.00000000"]],"a":[["78718.01000000","6.35071000"],["78718.05000000","0.06364000"],["78718.76000000","0.00014000"],["78718.77000000","0.31774000"],["78719.87000000","0.00007000"],["78720.00000000","0.31769000"],["78720.01000000","0.00208000"],["78720.52000000","0.00000000"],["78721.21000000","0.04119000"],["78722.00000000","0.00571000"],["78724.00000000","0.02400000"],["78726.02000000","0.38112000"],["78741.58000000","0.00007000"],["78749.18000000","0.00000000"],["78759.42000000","0.00316000"],["78784.65000000","0.04763000"],["78815.61000000","0.00025000"],["78817.61000000","0.00000000"],["78832.04000000","0.00000000"],["78843.95000000","0.00160000"],["78858.20000000","0.00000000"],["78883.37000000","0.00160000"],["78898.17000000","0.01990000"],["78925.24000000","0.00406000"],["78926.04000000","0.00000000"],["79111.61000000","0.00008000"],["79507.16000000","0.00000000"],["79904.70000000","0.00000000"],["80304.22000000","0.00000000"],["80705.74000000","0.00000000"],["81109.27000000","0.00000000"],["81514.82000000","0.00000000"],["81922.39000000","0.00000000"],["82332.00000000","0.00020000"],["82743.66000000","0.00000000"],["83157.38000000","0.00000000"],["83573.17000000","0.00000000"],["83991.04000000","0.00000000"],["84410.99000000","0.00000000"],["84833.05000000","0.00000000"]]}}}
{"rx_ns": 38951587400, "frame": {"stream":"btcusdt@depth20","data":{"lastUpdateId":99076514099,"bids":[["78718.00000000","0.28393000"],["78717.99000000","0.01703000"],["78717.98000000","0.00013000"],["78717.79000000","0.00200000"],["78717.78000000","0.04354000"],["78717.44000000","0.00007000"],["78716.01000000","0.00025000"],["78716.00000000","0.02515000"],["78715.95000000","0.00007000"],["78715.82000000","0.00007000"],["78715.81000000","0.01661000"],["78715.80000000","0.00007000"],["78715.19000000","0.00007000"],["78715.18000000","0.04963000"],["78714.55000000","0.02764000"],["78714.35000000","0.00007000"],["78714.00000000","0.02407000"],["78713.56000000","0.00007000"],["78713.29000000","0.03315000"],["78712.30000000","0.00134000"]],"asks":[["78718.01000000","4.57174000"],["78718.02000000","0.00020000"],["78718.03000000","0.00013000"],["78718.04000000","0.00014000"],["78718.05000000","0.06364000"],["78718.77000000","0.31766000"],["78718.78000000","0.00400000"],["78719.09000000","0.00007000"],["78719.26000000","0.00014000"],["78719.27000000","0.03601000"],["78719.55000000","0.00324000"],["78719.67000000","0.00014000"],["78719.87000000","0.00007000"],["78719.99000000","0.00014000"],["78720.00000000","0.31769000"],["78720.01000000","0.00208000"],["78720.06000000","0.00014000"],["78720.07000000","0.42760000"],["78720.20000000","0.00322000"],["78720.52000000","0.00007000"]]}}}
{"rx_ns": 38951701900, "frame": {"stream":"btcusdt@depth","data":{"e":"depthUpdate","E":1787602906014,"s":"BTCUSDT","U":99076513705,"u":99076514099,"b":[["78718.00000000","0.28393000"],["78717.99000000","0.01703000"],["78717.78000000","0.04354000"],["78717.52000000","0.00000000"],["78717.39000000","0.00000000"],["78717.38000000","0.00000000"],["78716.31000000","0.00000000"],["78716.00000000","0.02515000"],["78715.82000000","0.00007000"],["78714.55000000","0.02764000"],["78714.01000000","0.00000000"],["78712.30000000","0.00134000"],["78711.03000000","0.00000000"],["78709.37000000","0.00000000"],["78709.30000000","0.00007000"],["78708.06000000","0.00014000"],["78707.05000000","0.00000000"],["78703.16000000","0.00000000"],["78703.15000000","0.00000000"],["78703.14000000","0.00000000"],["78702.90000000","0.00000000"],["78701.96000000","0.00254000"],["78701.95000000","0.00000000"],["78701.94000000","0.00000000"],["78701.36000000","0.00000000"],["78701.35000000","0.00000000"],["78701.34000000","0.00000000"],["78701.33000000","0.00000000"],["78694.34000000","0.00007000"],["78684.60000000","0.00400000"],["78679.38000000","0.02541000"],["78677.86000000","0.00400000"],["78677.68000000","0.00000000"],["78674.65000000","0.00000000"],["78669.36000000","0.00007000"],["78666.12000000","0.00007000"],["78662.15000000","0.00000000"],["78662.10000000","0.02804000"],["78660.26000000","0.21930000"],["78660.21000000","0.02389000"],["78650.08000000","0.91108000"],["78629.13000000","0.00000000"],["78626.96000000","0.02116000"],["78607.99000000","2.77178000"],["78605.38000000","0.00000000"],["78584.66000000","0.00000000"],["78582.35000000","0.09531000"],["78510.34000000","0.00778000"],["78503.60000000","0.00000000"],["78324.41000000","0.00000000"],["77932.78000000","0.00000000"],["77543.12000000","0.00000000"],["77155.40000000","0.00000000"],["76993.65000000","0.00321000"],["76839.66000000","0.00368000"],["76769.63000000","0.00000000"],["76685.98000000","0.00421000"],["76532.60000000","0.00483000"],["76385.78000000","0.00000000"],["76003.85000000","0.00000000"],["75623.83000000","0.00000000"],["75245.71000000","0.00000000"],["75133.13000000","0.00000000"],["74869.48000000","0.00000000"],["74495.13000000","0.00000000"],["74122.66000000","0.00000000"],["73752.05000000","0.00000000"],["73383.29000000","0.00000000"],["73016.37000000","0.00000000"],["70846.20000000","0.00416000"],["70846.19000000","0.00000000"],["70846.00000000","0.00000000"],["62974.40000000","0.00031000"],["62974.00000000","0.00000000"]],"a":[["78718.01000000","4.57174000"],["78718.02000000","0.00020000"],["78718.05000000","0.06364000"],["78718.76000000","0.00000000"],["78718.77000000","0.31766000"],["78719.26000000","0.00014000"],["78719.55000000","0.00324000"],["78719.98000000","0.00000000"],["78719.99000000","0.00014000"],["78720.07000000","0.42760000"],["78720.52000000","0.00007000"],["78720.53000000","0.04320000"],["78720.68000000","0.00000000"],["78721.21000000","0.04126000"],["78721.98000000","0.00635000"],["78722.00000000","0.00707000"],["78722.01000000","0.00007000"],["78722.75000000","0.00000000"],["78723.97000000","0.00000000"],["78723.98000000","0.00000000"],["78726.00000000","0.02400000"],["78726.01000000","0.00000000"],["78736.97000000","0.00000000"],["78741.58000000","0.00007000"],["78744.42000000","0.02447000"],["78754.28000000","0.00000000"],["78772.38000000","0.00000000"],["78781.65000000","1.90515000"],["78783.25000000","1.21952000"],["78844.14000000","0.00000000"],["79111.61000000","0.00008000"],["79507.16000000","0.00000000"],["79904.70000000","0.00000000"],["80304.22000000","0.00000000"],["80705.74000000","0.00000000"],["81109.27000000","0.00000000"],["81514.82000000","0.00000000"],["81922.39000000","0.00000000"],["82332.00000000","0.00020000"],["82743.66000000","0.00000000"],["83157.38000000","0.00000000"],["83573.17000000","0.00000000"],["83991.04000000","0.00000000"],["84410.99000000","0.00000000"],["84833.05000000","0.00000000"]]}}}
{"rx_ns": 39951661200, "frame": {"stream":"btcusdt@depth20","data":{"lastUpdateId":99076514324,"bids":[["78718.00000000","0.80051000"],["78717.99000000","0.01703000"],["78717.98000000","0.00013000"],["78717.79000000","0.00200000"],["78717.78000000","0.04354000"],["78717.44000000","0.00007000"],["78716.01000000","0.00025000"],["78716.00000000","0.02515000"],["78715.95000000","0.00007000"],["78715.82000000","0.00007000"],["78715.81000000","0.01661000"],["78715.80000000","0.00007000"],["78715.19000000","0.00007000"],["78715.18000000","0.04963000"],["78714.55000000","0.02764000"],["78714.35000000","0.00007000"],["78714.00000000","0.02407000"],["78713.56000000","0.00007000"],["78713.29000000","0.03315000"],["78712.30000000","0.00134000"]],"asks":[["78718.01000000","4.57229000"],["78718.02000000","0.00069000"],["78718.03000000","0.00013000"],["78718.04000000","0.00014000"],["78718.05000000","0.06371000"],["78718.78000000","0.00400000"],["78719.09000000","0.00007000"],["78719.25000000","0.00014000"],["78719.26000000","0.00014000"],["78719.27000000","0.03601000"],["78719.55000000","0.00324000"],["78719.67000000","0.00014000"],["78719.87000000","0.00007000"],["78719.99000000","0.31780000"],["78720.00000000","0.31769000"],["78720.01000000","0.00208000"],["78720.06000000","0.00014000"],["78720.07000000","0.42760000"],["78720.20000000","0.00322000"],["78720.53000000","0.04320000"]]}}}
{"rx_ns": 39951751100, "frame": {"stream":"btcusdt@depth","data":{"e":"depthUpdate","E":1787602907014,"s":"BTCUSDT","U":99076514100,"u":99076514324,"b":[["78718.00000000","0.80051000"],["78711.34000000","0.00204000"],["78711.14000000","0.20844000"],["78709.14000000","0.00332000"],["78705.93000000","0.00000000"],["78705.72000000","0.00000000"],["78705.68000000","0.00000000"],["78705.49000000","0.00000000"],["78705.01000000","0.00007000"],["78702.18000000","0.00000000"],["78702.17000000","0.00000000"],["78702.16000000","0.00000000"],["78702.15000000","0.00000000"],["78702.14000000","0.00000000"],["78702.13000000","0.00000000"],["78701.96000000","0.00000000"],["78700.00000000","0.13963000"],["78694.34000000","0.00007000"],["78687.75000000","0.50846000"],["78687.70000000","0.00000000"],["78626.96000000","0.02116000"],["78607.99000000","0.00000000"],["78605.38000000","2.77178000"],["78401.00000000","0.05000000"],["78324.41000000","0.00000000"],["77932.78000000","0.00000000"],["77543.12000000","0.00000000"],["77155.40000000","0.00000000"],["76769.63000000","0.00000000"],["76385.78000000","0.00000000"],["76003.85000000","0.00000000"],["75623.83000000","0.00000000"],["75245.71000000","0.00000000"],["74869.48000000","0.00000000"],["74495.13000000","0.00000000"],["74122.66000000","0.00000000"],["73752.05000000","0.00000000"],["73383.29000000","0.00000000"],["73016.37000000","0.00000000"],["70846.20000000","0.00441000"],["70846.00000000","0.00000000"],["62974.40000000","0.00031000"],["62974.00000000","0.00000000"]],"a":[["78718.01000000","4.57229000"],["78718.02000000","0.00069000"],["78718.05000000","0.06371000"],["78718.76000000","0.00000000"],["78718.77000000","0.00000000"],["78719.25000000","0.00014000"],["78719.26000000","0.00014000"],["78719.99000000","0.31780000"],["78720.52000000","0.00000000"],["78721.21000000","0.04126000"],["78741.58000000","0.00007000"],["78753.04000000","0.00000000"],["78758.92000000","0.02521000"],["78800.09000000","0.00529000"],["79111.61000000","0.00008000"],["79507.16000000","0.00000000"],["79904.70000000","0.00000000"],["80304.22000000","0.00000000"],["80705.74000000","0.00000000"],["81109.27000000","0.00000000"],["81514.82000000","0.00000000"],["81922.39000000","0.00000000"],["82332.00000000","0.00020000"],["82743.66000000","0.00000000"],["83157.38000000","0.00000000"],["83573.17000000","0.00000000"],["83991.04000000","0.00000000"],["84410.99000000","0.00000000"],["84833.05000000","0.00000000"]]}}}
{"rx_ns": 40951975000, "kind": "control", "ctl": {"op": "ping", "recv_ns": 40344054600, "pong_ns": 40344180200, "payload_len": 13, "payload_b64": "MTc4NzYwMjkwNzQwNg=="}, "frame": null}
{"rx_ns": 40951975000, "frame": {"stream":"btcusdt@depth20","data":{"lastUpdateId":99076514534,"bids":[["78718.00000000","0.08794000"],["78717.99000000","0.01703000"],["78717.98000000","0.00013000"],["78717.79000000","0.00200000"],["78717.78000000","0.04354000"],["78717.44000000","0.00007000"],["78716.01000000","0.00025000"],["78716.00000000","0.02515000"],["78715.95000000","0.00007000"],["78715.82000000","0.00007000"],["78715.81000000","0.01661000"],["78715.80000000","0.00007000"],["78715.19000000","0.00007000"],["78715.18000000","0.04963000"],["78714.55000000","0.02764000"],["78714.35000000","0.00007000"],["78714.00000000","0.02407000"],["78713.56000000","0.00007000"],["78713.29000000","0.03315000"],["78712.30000000","0.00134000"]],"asks":[["78718.01000000","5.13058000"],["78718.02000000","0.00020000"],["78718.03000000","0.00013000"],["78718.04000000","0.00014000"],["78718.05000000","0.06371000"],["78718.78000000","0.00400000"],["78719.09000000","0.00007000"],["78719.26000000","0.00014000"],["78719.27000000","0.03601000"],["78719.55000000","0.00324000"],["78719.67000000","0.00014000"],["78719.87000000","0.00007000"],["78719.99000000","0.00014000"],["78720.00000000","0.31769000"],["78720.01000000","0.00208000"],["78720.06000000","0.00014000"],["78720.07000000","0.42760000"],["78720.20000000","0.00322000"],["78720.52000000","0.00007000"],["78720.53000000","0.04320000"]]}}}
{"rx_ns": 40952132400, "frame": {"stream":"btcusdt@depth","data":{"e":"depthUpdate","E":1787602908014,"s":"BTCUSDT","U":99076514325,"u":99076514534,"b":[["78718.00000000","0.08794000"],["78705.76000000","0.00000000"],["78705.73000000","0.00000000"],["78705.68000000","0.00000000"],["78705.35000000","0.00000000"],["78705.30000000","0.00000000"],["78705.22000000","0.00000000"],["78705.20000000","0.00000000"],["78705.15000000","0.00000000"],["78703.02000000","0.00635000"],["78703.01000000","0.00007000"],["78702.19000000","0.00000000"],["78702.18000000","0.00000000"],["78694.34000000","0.00007000"],["78669.36000000","0.00007000"],["78666.12000000","0.00007000"],["78626.96000000","0.00000000"],["78607.99000000","2.77178000"],["78605.38000000","0.00000000"],["78587.72000000","0.04474000"],["78582.35000000","0.00000000"],["78510.34000000","0.00778000"],["78504.57000000","0.00000000"],["78324.41000000","0.00000000"],["77932.78000000","0.00000000"],["77543.12000000","0.00000000"],["77155.40000000","0.00000000"],["76769.63000000","0.00000000"],["76385.78000000","0.00000000"],["76003.85000000","0.00000000"],["75623.83000000","0.00000000"],["75245.71000000","0.00000000"],["74869.48000000","0.00000000"],["74495.13000000","0.00000000"],["74122.66000000","0.00000000"],["73752.05000000","0.00000000"],["73383.29000000","0.00000000"],["73016.37000000","0.00000000"],["70846.20000000","0.00425000"],["70846.00000000","0.00000000"],["62974.40000000","0.00031000"],["62974.00000000","0.00000000"]],"a":[["78718.01000000","5.13058000"],["78718.02000000","0.00020000"],["78718.03000000","0.00013000"],["78718.04000000","0.00014000"],["78719.25000000","0.00000000"],["78719.27000000","0.03601000"],["78719.98000000","0.00000000"],["78719.99000000","0.00014000"],["78720.52000000","0.00007000"],["78721.21000000","0.04119000"],["78741.58000000","0.00007000"],["78768.45000000","0.01270000"],["78779.31000000","0.00000000"],["78800.73000000","0.00000000"],["78801.11000000","0.00000000"],["79020.52000000","7.59391000"],["79111.61000000","0.00008000"],["79507.16000000","0.00000000"],["79904.70000000","0.00000000"],["80304.22000000","0.00000000"],["80705.74000000","0.00000000"],["81109.27000000","0.00000000"],["81514.82000000","0.00000000"],["81922.39000000","0.00000000"],["82332.00000000","0.00020000"],["82743.66000000","0.00000000"],["83157.38000000","0.00000000"],["83573.17000000","0.00000000"],["83991.04000000","0.00000000"],["84410.99000000","0.00000000"],["84833.05000000","0.00000000"]]}}}
{"rx_ns": 41951276600, "frame": {"stream":"btcusdt@depth20","data":{"lastUpdateId":99076514689,"bids":[["78718.00000000","0.29438000"],["78717.99000000","0.01703000"],["78717.98000000","0.00013000"],["78717.79000000","0.00200000"],["78717.78000000","0.04354000"],["78717.44000000","0.00007000"],["78716.01000000","0.00025000"],["78716.00000000","0.02515000"],["78715.95000000","0.00007000"],["78715.82000000","0.00007000"],["78715.81000000","0.01661000"],["78715.80000000","0.00007000"],["78715.19000000","0.00007000"],["78715.18000000","0.04963000"],["78714.55000000","0.02764000"],["78714.35000000","0.00007000"],["78714.00000000","0.02407000"],["78713.56000000","0.00007000"],["78713.29000000","0.03315000"],["78712.30000000","0.00134000"]],"asks":[["78718.01000000","4.56806000"],["78718.02000000","0.00020000"],["78718.03000000","0.00013000"],["78718.04000000","0.00014000"],["78718.05000000","0.06378000"],["78718.76000000","0.00014000"],["78718.78000000","0.00400000"],["78719.09000000","0.00007000"],["78719.26000000","0.31780000"],["78719.27000000","0.03601000"],["78719.55000000","0.00324000"],["78719.67000000","0.00014000"],["78719.87000000","0.00007000"],["78719.99000000","0.00014000"],["78720.00000000","0.31769000"],["78720.01000000","0.00208000"],["78720.06000000","0.00014000"],["78720.07000000","0.42760000"],["78720.20000000","0.00322000"],["78720.53000000","0.04320000"]]}}}
{"rx_ns": 41951371500, "frame": {"stream":"btcusdt@depth","data":{"e":"depthUpdate","E":1787602909014,"s":"BTCUSDT","U":99076514535,"u":99076514689,"b":[["78718.00000000","0.29438000"],["78708.99000000","0.00000000"],["78708.82000000","0.00332000"],["78705.81000000","0.00000000"],["78705.79000000","0.00000000"],["78705.71000000","0.06821000"],["78705.49000000","0.00000000"],["78705.37000000","0.00000000"],["78702.21000000","0.00000000"],["78702.20000000","0.00000000"],["78702.19000000","0.00000000"],["78628.00000000","0.02600000"],["78626.96000000","0.00000000"],["78607.99000000","0.00000000"],["78562.45000000","0.00000000"],["78510.34000000","0.00000000"],["78504.57000000","0.00779000"],["78324.41000000","0.00000000"],["77932.78000000","0.00000000"],["77543.12000000","0.00000000"],["77155.40000000","0.00000000"],["76769.63000000","0.00000000"],["76385.78000000","0.00000000"],["76003.85000000","0.00000000"],["75623.83000000","0.00000000"],["75245.71000000","0.00000000"],["74869.48000000","0.00000000"],["74495.13000000","0.00000000"],["74122.66000000","0.00000000"],["73752.05000000","0.00000000"],["73383.29000000","0.00000000"],["73016.37000000","0.00000000"],["70846.20000000","0.00425000"],["70846.00000000","0.00000000"],["62974.40000000","0.00031000"],["62974.00000000","0.00000000"]],"a":[["78718.01000000","4.56806000"],["78718.05000000","0.06378000"],["78718.76000000","0.00014000"],["78718.77000000","0.00000000"],["78719.26000000","0.31780000"],["78720.52000000","0.00000000"],["78754.20000000","0.00200000"],["78801.11000000","0.93647000"],["78861.54000000","0.00000000"],["79111.61000000","0.00008000"],["79507.16000000","0.00000000"],["79904.70000000","0.00000000"],["80304.22000000","0.00000000"],["80705.74000000","0.00000000"],["81109.27000000","0.00000000"],["81514.82000000","0.00000000"],["81922.39000000","0.00000000"],["82332.00000000","0.00020000"],["82743.66000000","0.00000000"],["83157.38000000","0.00000000"],["83573.17000000","0.00000000"],["83991.04000000","0.00000000"],["84410.99000000","0.00000000"],["84833.05000000","0.00000000"]]}}}
{"rx_ns": 42951291000, "frame": {"stream":"btcusdt@depth20","data":{"lastUpdateId":99076514946,"bids":[["78718.00000000","0.03683000"],["78717.99000000","0.01703000"],["78717.98000000","0.00013000"],["78717.79000000","0.00200000"],["78717.78000000","0.04354000"],["78717.44000000","0.00007000"],["78716.01000000","0.00025000"],["78716.00000000","0.02515000"],["78715.95000000","0.00007000"],["78715.82000000","0.00007000"],["78715.81000000","0.01661000"],["78715.80000000","0.00007000"],["78715.19000000","0.00007000"],["78715.18000000","0.04963000"],["78714.55000000","0.02764000"],["78714.35000000","0.00007000"],["78714.00000000","0.02407000"],["78713.56000000","0.00007000"],["78713.29000000","0.03315000"],["78712.30000000","0.00134000"]],"asks":[["78718.01000000","5.12558000"],["78718.02000000","0.00020000"],["78718.03000000","0.00013000"],["78718.04000000","0.00014000"],["78718.05000000","0.06378000"],["78718.78000000","0.00400000"],["78719.09000000","0.00007000"],["78719.26000000","0.00014000"],["78719.27000000","0.03601000"],["78719.55000000","0.00324000"],["78719.57000000","0.00014000"],["78719.58000000","0.20007000"],["78719.67000000","0.00014000"],["78719.87000000","0.00007000"],["78719.99000000","0.00014000"],["78720.00000000","0.31769000"],["78720.01000000","0.00208000"],["78720.06000000","0.00007000"],["78720.07000000","0.42760000"],["78720.20000000","0.00322000"]]}}}
{"rx_ns": 42951736600, "frame": {"stream":"btcusdt@depth","data":{"e":"depthUpdate","E":1787602910014,"s":"BTCUSDT","U":99076514690,"u":99076514946,"b":[["78718.00000000","0.03683000"],["78708.82000000","0.00000000"],["78708.77000000","0.00329000"],["78705.71000000","0.00000000"],["78705.11000000","0.00000000"],["78705.07000000","0.00000000"],["78704.95000000","0.02600000"],["78704.70000000","0.00000000"],["78702.90000000","0.00000000"],["78702.11000000","0.00254000"],["78697.92000000","0.00400000"],["78694.34000000","0.00007000"],["78675.01000000","0.00000000"],["78674.50000000","0.09451000"],["78626.96000000","0.00000000"],["78623.79000000","0.00000000"],["78607.99000000","2.77178000"],["78600.39000000","0.00400000"],["78588.17000000","0.04474000"],["78587.72000000","0.00000000"],["78559.65000000","1.52237000"],["78555.39000000","0.00000000"],["78554.60000000","0.00385000"],["78510.34000000","0.00778000"],["78504.57000000","0.00000000"],["78498.22000000","0.01990000"],["78489.05000000","0.00000000"],["78324.41000000","0.00000000"],["77932.78000000","0.00000000"],["77543.12000000","0.00000000"],["77155.40000000","0.00000000"],["76769.63000000","0.00000000"],["76385.78000000","0.00000000"],["76003.85000000","0.00000000"],["75623.83000000","0.00000000"],["75245.71000000","0.00000000"],["75133.13000000","0.00088000"],["74869.48000000","0.00000000"],["74495.13000000","0.00000000"],["74122.66000000","0.00000000"],["73752.05000000","0.00000000"],["73383.29000000","0.00000000"],["73016.37000000","0.00000000"],["72426.09000000","0.00014000"],["70846.20000000","0.00416000"],["70846.19000000","0.00009000"],["70846.00000000","0.00000000"],["65000.00000000","77.52834000"],["62974.40000000","0.00031000"],["62974.00000000","0.00000000"]],"a":[["78718.01000000","5.12558000"],["78718.02000000","0.00020000"],["78718.03000000","0.00013000"],["78718.04000000","0.00014000"],["78718.05000000","0.06378000"],["78718.76000000","0.00000000"],["78719.25000000","0.00000000"],["78719.26000000","0.00014000"],["78719.27000000","0.03601000"],["78719.57000000","0.00014000"],["78719.58000000","0.20007000"],["78719.98000000","0.00000000"],["78719.99000000","0.00014000"],["78720.06000000","0.00007000"],["78721.20000000","0.02168000"],["78723.53000000","0.00400000"],["78741.58000000","0.00007000"],["78816.06000000","0.00000000"],["78819.66000000","0.00385000"],["78820.45000000","0.00000000"],["78824.29000000","0.02789000"],["78858.73000000","1.52237000"],["79111.61000000","0.00008000"],["79507.16000000","0.00000000"],["79904.70000000","0.00000000"],["80304.22000000","0.00000000"],["80705.74000000","0.00000000"],["81109.27000000","0.00000000"],["81514.82000000","0.00000000"],["81922.39000000","0.00000000"],["82332.00000000","0.00020000"],["82743.66000000","0.00000000"],["83157.38000000","0.00000000"],["83573.17000000","0.00000000"],["83991.04000000","0.00000000"],["84410.99000000","0.00000000"],["84833.05000000","0.00000000"]]}}}
{"rx_ns": 43957199900, "frame": {"stream":"btcusdt@depth20","data":{"lastUpdateId":99076515249,"bids":[["78718.00000000","0.78452000"],["78717.99000000","0.01703000"],["78717.98000000","0.00013000"],["78717.88000000","0.04745000"],["78717.79000000","0.00200000"],["78717.44000000","0.00007000"],["78716.28000000","0.00007000"],["78716.01000000","0.00025000"],["78716.00000000","0.02515000"],["78715.95000000","0.00007000"],["78715.82000000","0.00007000"],["78715.81000000","0.01661000"],["78715.80000000","0.00007000"],["78715.19000000","0.00007000"],["78715.18000000","0.04956000"],["78714.55000000","0.02764000"],["78714.35000000","0.00007000"],["78714.00000000","0.02407000"],["78713.56000000","0.00007000"],["78713.29000000","0.03315000"]],"asks":[["78718.01000000","4.57048000"],["78718.02000000","0.00069000"],["78718.03000000","0.00013000"],["78718.04000000","0.00014000"],["78718.05000000","0.06385000"],["78718.76000000","0.00014000"],["78718.78000000","0.00400000"],["78719.09000000","0.00007000"],["78719.25000000","0.00635000"],["78719.26000000","0.00014000"],["78719.27000000","0.03601000"],["78719.54000000","0.31773000"],["78719.55000000","0.00324000"],["78719.57000000","0.00014000"],["78719.58000000","0.20007000"],["78719.67000000","0.00014000"],["78719.87000000","0.00007000"],["78719.99000000","0.00014000"],["78720.00000000","0.31769000"],["78720.01000000","0.00208000"]]}}}
{"rx_ns": 43957295100, "frame": {"stream":"btcusdt@depth","data":{"e":"depthUpdate","E":1787602911014,"s":"BTCUSDT","U":99076514947,"u":99076515249,"b":[["78718.00000000","0.78452000"],["78717.99000000","0.01703000"],["78717.88000000","0.04745000"],["78717.78000000","0.00000000"],["78716.28000000","0.00007000"],["78715.18000000","0.04956000"],["78714.81000000","0.00000000"],["78711.15000000","0.01600000"],["78710.12000000","0.21930000"],["78709.38000000","0.00400000"],["78708.77000000","0.00000000"],["78708.07000000","0.36859000"],["78708.06000000","0.00007000"],["78707.06000000","0.00000000"],["78707.05000000","0.00000000"],["78705.95000000","0.00000000"],["78705.87000000","0.00000000"],["78705.49000000","0.00000000"],["78705.41000000","0.00000000"],["78705.10000000","0.00000000"],["78704.93000000","0.00635000"],["78704.20000000","0.00000000"],["78703.02000000","0.00000000"],["78702.90000000","0.00000000"],["78702.71000000","0.00400000"],["78702.67000000","0.00000000"],["78702.11000000","0.00000000"],["78702.10000000","0.00000000"],["78702.09000000","1.90515000"],["78702.08000000","0.00000000"],["78702.07000000","0.00007000"],["78702.06000000","0.00000000"],["78702.05000000","0.00000000"],["78702.04000000","0.00254000"],["78701.71000000","0.00000000"],["78698.02000000","0.00000000"],["78698.01000000","0.00000000"],["78697.99000000","0.00092000"],["78697.92000000","0.00000000"],["78694.34000000","0.00007000"],["78679.83000000","0.00400000"],["78679.79000000","0.00000000"],["78677.86000000","0.00000000"],["78638.31000000","0.00000000"],["78637.52000000","0.00076000"],["78626.96000000","0.00000000"],["78588.17000000","0.00000000"],["78578.96000000","0.09531000"],["78557.67000000","0.00000000"],["78556.04000000","0.00127000"],["78549.81000000","0.00000000"],["78547.76000000","0.00097000"],["78324.41000000","0.00000000"],["77932.78000000","0.00000000"],["77543.12000000","0.00000000"],["77155.40000000","0.00000000"],["76769.63000000","0.00000000"],["76385.78000000","0.00000000"],["76003.85000000","0.00000000"],["75623.83000000","0.00000000"],["75245.71000000","0.00000000"],["74869.48000000","0.00000000"],["74495.13000000","0.00000000"],["74122.66000000","0.00000000"],["73752.05000000","0.00000000"],["73383.29000000","0.00000000"],["73016.37000000","0.00000000"],["72426.09000000","0.00000000"],["70846.20000000","0.00416000"],["70846.00000000","0.00000000"],["62974.40000000","0.00031000"],["62974.00000000","0.00000000"]],"a":[["78718.01000000","4.57048000"],["78718.02000000","0.00069000"],["78718.05000000","0.06385000"],["78718.76000000","0.00014000"],["78718.77000000","0.00000000"],["78719.25000000","0.00635000"],["78719.27000000","0.03601000"],["78719.54000000","0.31773000"],["78719.98000000","0.00000000"],["78720.06000000","0.00000000"],["78721.20000000","0.02161000"],["78721.77000000","0.00000000"],["78721.98000000","0.00000000"],["78722.51000000","0.00635000"],["78741.58000000","0.00007000"],["78762.15000000","0.00076000"],["78762.94000000","0.00000000"],["78767.99000000","0.00315000"],["78769.64000000","0.00000000"],["78773.99000000","0.00315000"],["78775.62000000","0.00000000"],["78815.06000000","0.02789000"],["78824.29000000","0.00000000"],["78845.90000000","0.00127000"],["78851.99000000","0.00127000"],["78855.27000000","0.00000000"],["78855.28000000","0.00000000"],["79111.61000000","0.00008000"],["79507.16000000","0.00000000"],["79904.70000000","0.00000000"],["80304.22000000","0.00000000"],["80705.74000000","0.00000000"],["81109.27000000","0.00000000"],["81514.82000000","0.00000000"],["81922.39000000","0.00000000"],["82332.00000000","0.00020000"],["82743.66000000","0.00000000"],["83157.38000000","0.00000000"],["83573.17000000","0.00000000"],["83991.04000000","0.00000000"],["84410.99000000","0.00000000"],["84833.05000000","0.00000000"],["85372.92000000","0.00010000"],["86589.81000000","0.00000000"]]}}}
{"rx_ns": 44962579600, "kind": "rest", "req": {"method": "GET", "url": "https://data-api.binance.vision/api/v3/depth?symbol=BTCUSDT&limit=100", "limit": 100, "weight": 5, "sent_ns": 42951621200, "status": 200, "used_weight_1m": "30", "recv_ns": 43961036600}, "frame": {"lastUpdateId":99076515249,"bids":[["78718.00000000","0.78452000"],["78717.99000000","0.01703000"],["78717.98000000","0.00013000"],["78717.88000000","0.04745000"],["78717.79000000","0.00200000"],["78717.44000000","0.00007000"],["78716.28000000","0.00007000"],["78716.01000000","0.00025000"],["78716.00000000","0.02515000"],["78715.95000000","0.00007000"],["78715.82000000","0.00007000"],["78715.81000000","0.01661000"],["78715.80000000","0.00007000"],["78715.19000000","0.00007000"],["78715.18000000","0.04956000"],["78714.55000000","0.02764000"],["78714.35000000","0.00007000"],["78714.00000000","0.02407000"],["78713.56000000","0.00007000"],["78713.29000000","0.03315000"],["78712.30000000","0.00134000"],["78712.03000000","0.03308000"],["78712.00000000","0.02400000"],["78711.93000000","0.00007000"],["78711.34000000","0.00204000"],["78711.15000000","0.01600000"],["78711.14000000","0.20844000"],["78711.02000000","1.21952000"],["78710.64000000","0.00010000"],["78710.63000000","0.00007000"],["78710.62000000","0.00010000"],["78710.46000000","0.00027000"],["78710.25000000","0.00007000"],["78710.17000000","0.00007000"],["78710.12000000","0.21930000"],["78710.00000000","0.02400000"],["78709.68000000","0.00007000"],["78709.41000000","0.02515000"],["78709.38000000","0.00400000"],["78709.30000000","0.00007000"],["78709.29000000","0.12711000"],["78709.14000000","0.00332000"],["78708.74000000","0.00048000"],["78708.45000000","0.00007000"],["78708.21000000","0.00007000"],["78708.07000000","0.36859000"],["78708.06000000","0.00007000"],["78708.00000000","0.02407000"],["78707.77000000","0.00007000"],["78707.67000000","0.00007000"],["78707.41000000","0.00400000"],["78707.18000000","0.00048000"],["78707.04000000","1.90515000"],["78707.03000000","1.21952000"],["78707.01000000","0.00007000"],["78706.79000000","0.00070000"],["78706.49000000","0.08576000"],["78706.40000000","0.00330000"],["78706.16000000","0.00007000"],["78706.00000000","0.02400000"],["78705.99000000","0.00047000"],["78705.84000000","0.00188000"],["78705.80000000","0.00007000"],["78705.78000000","0.02200000"],["78705.74000000","0.02400000"],["78705.56000000","0.02287000"],["78705.26000000","0.00400000"],["78705.09000000","0.00328000"],["78705.01000000","0.00007000"],["78705.00000000","0.02000000"],["78704.95000000","0.02600000"],["78704.93000000","0.00635000"],["78704.92000000","0.02600000"],["78704.68000000","0.00254000"],["78704.19000000","0.00014000"],["78704.12000000","0.00007000"],["78704.00000000","0.02400000"],["78703.91000000","0.00322000"],["78703.47000000","0.00400000"],["78703.46000000","0.00400000"],["78703.01000000","0.00007000"],["78702.89000000","1.21952000"],["78702.77000000","0.00010000"],["78702.71000000","0.00400000"],["78702.66000000","0.02200000"],["78702.65000000","0.00406000"],["78702.09000000","1.90515000"],["78702.07000000","0.00007000"],["78702.04000000","0.00254000"],["78702.00000000","0.02400000"],["78701.92000000","0.00007000"],["78701.87000000","0.02000000"],["78701.70000000","0.00008000"],["78701.50000000","0.00400000"],["78701.47000000","0.00027000"],["78701.42000000","0.12706000"],["78701.11000000","0.00007000"],["78701.09000000","0.02000000"],["78701.08000000","0.02000000"],["78701.03000000","0.00007000"]],"asks":[["78718.01000000","4.57048000"],["78718.02000000","0.00069000"],["78718.03000000","0.00013000"],["78718.04000000","0.00014000"],["78718.05000000","0.06385000"],["78718.76000000","0.00014000"],["78718.78000000","0.00400000"],["78719.09000000","0.00007000"],["78719.25000000","0.00635000"],["78719.26000000","0.00014000"],["78719.27000000","0.03601000"],["78719.54000000","0.31773000"],["78719.55000000","0.00324000"],["78719.57000000","0.00014000"],["78719.58000000","0.20007000"],["78719.67000000","0.00014000"],["78719.87000000","0.00007000"],["78719.99000000","0.00014000"],["78720.00000000","0.31769000"],["78720.01000000","0.00208000"],["78720.07000000","0.42760000"],["78720.20000000","0.00322000"],["78720.53000000","0.04320000"],["78720.69000000","0.05215000"],["78720.84000000","0.00400000"],["78721.20000000","0.02161000"],["78721.21000000","0.04119000"],["78721.78000000","0.00318000"],["78721.79000000","0.04313000"],["78721.99000000","0.00400000"],["78722.00000000","0.00707000"],["78722.01000000","0.00007000"],["78722.51000000","0.00635000"],["78722.52000000","0.00007000"],["78723.53000000","0.00400000"],["78723.54000000","0.00014000"],["78724.00000000","0.02400000"],["78724.01000000","0.02248000"],["78724.38000000","0.02654000"],["78724.57000000","0.00007000"],["78724.73000000","0.20145000"],["78724.80000000","0.00008000"],["78725.45000000","0.00635000"],["78725.46000000","0.00400000"],["78725.66000000","0.12709000"],["78725.75000000","0.02286000"],["78725.87000000","0.00326000"],["78725.89000000","0.21930000"],["78726.00000000","0.02400000"],["78726.02000000","0.38112000"],["78726.05000000","0.00319000"],["78726.38000000","0.02161000"],["78726.41000000","0.00254000"],["78726.62000000","0.00007000"],["78727.41000000","0.00014000"],["78727.48000000","0.00400000"],["78727.83000000","0.00007000"],["78727.85000000","0.00027000"],["78728.00000000","0.02400000"],["78728.11000000","0.00455000"],["78728.12000000","0.00007000"],["78728.63000000","0.38110000"],["78728.66000000","0.00007000"],["78728.91000000","0.02000000"],["78728.97000000","0.00331000"],["78729.00000000","0.00007000"],["78729.08000000","0.00407000"],["78729.30000000","0.00007000"],["78729.31000000","1.90515000"],["78729.50000000","0.00400000"],["78729.83000000","0.00007000"],["78729.91000000","0.02000000"],["78729.99000000","0.02161000"],["78730.00000000","0.11443000"],["78730.11000000","1.21952000"],["78730.27000000","0.00319000"],["78730.71000000","0.00007000"],["78731.05000000","0.00400000"],["78731.27000000","0.00007000"],["78731.28000000","0.00014000"],["78731.37000000","0.02000000"],["78731.39000000","0.02000000"],["78731.48000000","0.00007000"],["78731.85000000","0.00324000"],["78731.95000000","0.34297000"],["78732.00000000","0.02400000"],["78732.08000000","0.02000000"],["78732.10000000","0.36224000"],["78732.11000000","0.02000000"],["78732.18000000","0.02000000"],["78732.19000000","0.02000000"],["78732.50000000","0.00008000"],["78732.63000000","0.34297000"],["78732.65000000","0.04103000"],["78732.76000000","0.00007000"],["78732.86000000","0.03000000"],["78732.90000000","0.02000000"],["78732.91000000","0.02000000"],["78732.94000000","0.02000000"],["78732.96000000","0.00007000"]]}}
{"rx_ns": 44962579600, "frame": {"stream":"btcusdt@depth20","data":{"lastUpdateId":99076515435,"bids":[["78718.00000000","0.80458000"],["78717.99000000","0.01703000"],["78717.98000000","0.00013000"],["78717.88000000","0.04752000"],["78717.79000000","0.00200000"],["78717.44000000","0.00007000"],["78716.01000000","0.00025000"],["78716.00000000","0.02515000"],["78715.95000000","0.00007000"],["78715.82000000","0.00007000"],["78715.81000000","0.01661000"],["78715.80000000","0.00007000"],["78715.19000000","0.00007000"],["78715.18000000","0.04956000"],["78714.55000000","0.02764000"],["78714.35000000","0.00007000"],["78714.00000000","0.02407000"],["78713.56000000","0.00007000"],["78713.29000000","0.03315000"],["78712.30000000","0.00134000"]],"asks":[["78718.01000000","4.56879000"],["78718.02000000","0.00069000"],["78718.03000000","0.00013000"],["78718.04000000","0.00014000"],["78718.05000000","0.06385000"],["78718.78000000","0.00400000"],["78719.09000000","0.00007000"],["78719.25000000","0.00642000"],["78719.26000000","0.00014000"],["78719.27000000","0.03601000"],["78719.53000000","0.00014000"],["78719.54000000","0.31773000"],["78719.55000000","0.00324000"],["78719.57000000","0.00014000"],["78719.58000000","0.20007000"],["78719.67000000","0.00014000"],["78719.87000000","0.00007000"],["78719.99000000","0.00014000"],["78720.00000000","0.31769000"],["78720.01000000","0.00208000"]]}}}
{"rx_ns": 44962760600, "frame": {"stream":"btcusdt@depth","data":{"e":"depthUpdate","E":1787602912014,"s":"BTCUSDT","U":99076515250,"u":99076515435,"b":[["78718.00000000","0.80458000"],["78717.99000000","0.01703000"],["78717.88000000","0.04752000"],["78716.28000000","0.00000000"],["78711.35000000","0.00400000"],["78711.15000000","0.00000000"],["78708.07000000","0.36224000"],["78708.06000000","0.00014000"],["78707.42000000","0.00635000"],["78705.88000000","0.00150000"],["78704.70000000","0.00000000"],["78704.69000000","0.00000000"],["78704.62000000","0.12713000"],["78704.51000000","0.00000000"],["78704.47000000","0.00000000"],["78704.45000000","0.00000000"],["78702.99000000","0.00254000"],["78702.98000000","0.00000000"],["78702.97000000","0.00000000"],["78702.96000000","0.00000000"],["78702.90000000","0.01600000"],["78702.04000000","0.00000000"],["78702.03000000","0.00000000"],["78697.91000000","0.00000000"],["78694.34000000","0.00007000"],["78681.80000000","0.00600000"],["78681.70000000","0.00000000"],["78679.83000000","0.00000000"],["78669.36000000","0.00000000"],["78666.12000000","0.00014000"],["78627.36000000","0.00000000"],["78578.96000000","0.00000000"],["78324.41000000","0.00000000"],["77932.78000000","0.00000000"],["77903.56000000","0.00000000"],["77583.04000000","0.00000000"],["77543.12000000","0.00000000"],["77155.40000000","0.00000000"],["76769.63000000","0.00000000"],["76720.01000000","0.00043000"],["76385.78000000","0.00000000"],["76003.85000000","0.00000000"],["75623.83000000","0.00000000"],["75245.71000000","0.00000000"],["74869.48000000","0.00000000"],["74495.13000000","0.00000000"],["74122.66000000","0.00000000"],["73752.05000000","0.00000000"],["73383.29000000","0.00000000"],["73016.37000000","0.00000000"],["70846.20000000","0.00432000"],["70846.00000000","0.00000000"],["62974.40000000","0.00031000"],["62974.00000000","0.00000000"]],"a":[["78718.01000000","4.56879000"],["78718.02000000","0.00069000"],["78718.05000000","0.06385000"],["78718.76000000","0.00000000"],["78719.25000000","0.00642000"],["78719.53000000","0.00014000"],["78720.69000000","0.05208000"],["78721.77000000","0.00635000"],["78722.00000000","0.00725000"],["78722.51000000","0.00000000"],["78723.52000000","0.00000000"],["78733.94000000","0.04634000"],["78736.46000000","0.00000000"],["78741.58000000","0.00007000"],["78759.35000000","0.01270000"],["78815.06000000","0.00000000"],["79111.61000000","0.00008000"],["79507.16000000","0.00000000"],["79904.70000000","0.00000000"],["80304.22000000","0.00000000"],["80705.74000000","0.00000000"],["81109.27000000","0.00000000"],["81514.82000000","0.00000000"],["81922.39000000","0.00000000"],["82332.00000000","0.00020000"],["82743.66000000","0.00000000"],["83157.38000000","0.00000000"],["83573.17000000","0.00000000"],["83991.04000000","0.00000000"],["84410.99000000","0.00000000"],["84833.05000000","0.00000000"]]}}}
