{"rx_ns": 13863801559600, "frame": {"stream":"btcusdt@depth20","data":{"lastUpdateId":99118582423,"bids":[["79873.29000000","1.71133000"],["79873.28000000","0.01269000"],["79873.27000000","0.00026000"],["79872.93000000","0.00007000"],["79872.64000000","0.00007000"],["79872.63000000","0.02014000"],["79872.49000000","0.00007000"],["79872.08000000","0.00014000"],["79872.02000000","0.00007000"],["79872.01000000","0.02559000"],["79871.99000000","0.00014000"],["79871.69000000","0.00007000"],["79870.83000000","0.00007000"],["79870.82000000","1.04953000"],["79870.73000000","0.02323000"],["79870.64000000","0.00007000"],["79870.63000000","0.05291000"],["79870.55000000","0.00007000"],["79870.09000000","0.00007000"],["79870.00000000","0.00007000"]],"asks":[["79873.30000000","2.13899000"],["79873.31000000","0.00048000"],["79873.32000000","0.00013000"],["79873.33000000","0.00007000"],["79873.34000000","0.08964000"],["79873.35000000","0.05014000"],["79873.38000000","0.00007000"],["79873.39000000","0.17636000"],["79873.68000000","0.00007000"],["79873.99000000","0.00007000"],["79874.00000000","0.02435000"],["79874.15000000","0.00400000"],["79874.18000000","0.00007000"],["79874.28000000","0.00007000"],["79874.54000000","0.00007000"],["79874.60000000","0.00007000"],["79874.62000000","0.00007000"],["79874.87000000","0.00007000"],["79875.02000000","0.00007000"],["79875.37000000","0.00007000"]]}}}
{"rx_ns": 13863801653800, "frame": {"stream":"btcusdt@depth@100ms","data":{"e":"depthUpdate","E":1787650859014,"s":"BTCUSDT","U":99118582404,"u":99118582423,"b":[["79873.29000000","1.71133000"],["79872.01000000","0.02559000"],["79871.99000000","0.00014000"],["79869.91000000","0.00014000"],["79869.61000000","0.00953000"],["79866.44000000","0.00007000"],["79858.89000000","0.00400000"],["79821.72000000","0.00345000"],["71885.97000000","0.00432000"],["63898.64000000","0.00031000"]],"a":[["79874.00000000","0.02435000"],["79875.93000000","0.00692000"],["79922.94000000","0.82141000"],["79936.52000000","0.82127000"]]}}}
{"rx_ns": 13863897215400, "frame": {"stream":"btcusdt@depth@100ms","data":{"e":"depthUpdate","E":1787650859114,"s":"BTCUSDT","U":99118582424,"u":99118582459,"b":[["79873.29000000","1.62646000"],["79873.28000000","0.01262000"],["79870.63000000","0.05284000"],["79869.91000000","0.00000000"],["79869.45000000","0.02324000"],["79866.44000000","0.00007000"],["79863.59000000","0.00191000"],["79858.90000000","0.00000000"],["79858.89000000","0.00000000"],["71885.97000000","0.00448000"]],"a":[["79874.00000000","0.02435000"],["79875.93000000","0.00007000"],["79876.65000000","0.00733000"],["79924.87000000","0.00007000"],["81071.40000000","0.00092000"]]}}}
{"rx_ns": 13863995503900, "frame": {"stream":"btcusdt@depth@100ms","data":{"e":"depthUpdate","E":1787650859214,"s":"BTCUSDT","U":99118582460,"u":99118582479,"b":[["79872.01000000","0.01933000"],["78675.19000000","0.00030000"],["71885.97000000","0.00432000"],["63898.64000000","0.00000000"]],"a":[["79873.30000000","2.13899000"],["79873.31000000","0.00048000"],["79874.00000000","0.02428000"],["79875.41000000","0.00000000"],["79875.93000000","0.00000000"],["79876.65000000","0.00740000"]]}}}
{"rx_ns": 13864096299400, "frame": {"stream":"btcusdt@depth@100ms","data":{"e":"depthUpdate","E":1787650859314,"s":"BTCUSDT","U":99118582480,"u":99118582513,"b":[["79873.29000000","1.41652000"],["79872.63000000","0.00014000"],["79872.02000000","0.00688000"],["79871.93000000","0.02000000"],["79869.61000000","0.00014000"],["79866.73000000","0.00000000"],["79866.45000000","0.00000000"],["79865.31000000","0.00013000"],["79864.30000000","0.00007000"],["79863.58000000","0.00000000"],["79861.72000000","0.00626000"],["79858.08000000","0.00007000"],["79838.35000000","0.00000000"],["71885.97000000","0.00448000"],["71885.00000000","0.00060000"],["63899.00000000","0.13788000"]],"a":[["79873.30000000","4.01845000"],["79873.31000000","0.00020000"],["79875.36000000","0.00710000"],["79878.68000000","0.00407000"],["79888.21000000","0.33805000"],["79890.04000000","0.00007000"],["79909.13000000","0.00000000"],["79912.57000000","1.23914000"],["80074.36000000","0.00000000"]]}}}
{"rx_ns": 13864196764400, "frame": {"stream":"btcusdt@depth@100ms","data":{"e":"depthUpdate","E":1787650859414,"s":"BTCUSDT","U":99118582514,"u":99118582578,"b":[["79873.29000000","1.41652000"],["79873.28000000","0.01262000"],["79872.64000000","0.00000000"],["79872.63000000","0.00000000"],["79872.02000000","0.00702000"],["79872.01000000","0.01940000"],["79871.94000000","0.00007000"],["79871.93000000","0.02014000"],["79870.63000000","0.05277000"],["79869.61000000","0.00000000"],["79869.34000000","0.00000000"],["79867.59000000","0.00007000"],["79865.29000000","0.00695000"],["79864.92000000","0.00000000"],["79837.00000000","0.00000000"],["79733.57000000","0.00020000"],["71885.97000000","0.00432000"],["71885.00000000","0.00040000"],["63898.63000000","0.00000000"]],"a":[["79873.30000000","4.02033000"],["79874.00000000","0.02435000"],["79875.36000000","0.00717000"],["79876.65000000","0.00733000"],["79883.07000000","0.00000000"],["79911.85000000","0.84259000"],["79967.84000000","1.48055000"],["80013.12000000","0.00020000"],["80756.54000000","0.00371000"]]}}}
{"rx_ns": 13864296067800, "frame": {"stream":"btcusdt@depth@100ms","data":{"e":"depthUpdate","E":1787650859514,"s":"BTCUSDT","U":99118582579,"u":99118582601,"b":[["79873.29000000","0.99817000"],["79868.36000000","0.00566000"],["79867.52000000","0.00000000"],["79867.34000000","0.00703000"],["79865.31000000","0.00000000"],["79863.60000000","0.00015000"],["79839.76000000","1.02042000"],["79830.36000000","0.00007000"],["79829.82000000","0.00014000"],["79736.04000000","0.00007000"],["71885.97000000","0.00448000"],["63898.64000000","0.00031000"],["63898.63000000","0.00000000"]],"a":[["79873.30000000","4.07033000"]]}}}
{"rx_ns": 13864397030200, "frame": {"stream":"btcusdt@depth@100ms","data":{"e":"depthUpdate","E":1787650859614,"s":"BTCUSDT","U":99118582602,"u":99118582608,"b":[["79800.13000000","0.02087000"],["79739.42000000","0.04910000"],["71885.97000000","0.00416000"],["63899.00000000","0.13788000"],["63898.64000000","0.00000000"]],"a":[]}}}
{"rx_ns": 13864500515000, "frame": {"stream":"btcusdt@depth@100ms","data":{"e":"depthUpdate","E":1787650859714,"s":"BTCUSDT","U":99118582609,"u":99118582620,"b":[["79873.29000000","0.99213000"],["79873.28000000","0.01262000"],["79872.02000000","0.00021000"],["79871.99000000","0.00645000"],["79800.13000000","0.00000000"],["71885.97000000","0.00448000"]],"a":[["79877.52000000","0.00000000"]]}}}
{"rx_ns": 13864599650700, "frame": {"stream":"btcusdt@depth@100ms","data":{"e":"depthUpdate","E":1787650859814,"s":"BTCUSDT","U":99118582621,"u":99118582654,"b":[["79873.29000000","0.96583000"],["79873.28000000","0.01262000"],["79872.02000000","0.00007000"],["79872.01000000","0.01940000"],["79871.99000000","0.00659000"],["79870.83000000","0.00000000"],["79870.82000000","0.00014000"],["79870.74000000","0.00007000"],["79869.46000000","0.00007000"],["79869.26000000","0.00007000"],["79869.07000000","0.00007000"],["79868.80000000","0.00014000"],["79866.44000000","0.00000000"],["79866.43000000","1.00419000"],["79864.00000000","0.09907000"],["79849.19000000","0.09307000"],["79795.98000000","0.02400000"],["71885.97000000","0.00432000"]],"a":[["79876.21000000","0.00000000"]]}}}
{"rx_ns": 13864696546100, "frame": {"stream":"btcusdt@depth@100ms","data":{"e":"depthUpdate","E":1787650859914,"s":"BTCUSDT","U":99118582655,"u":99118582680,"b":[["79873.29000000","0.96576000"],["79871.94000000","0.00000000"],["79871.93000000","0.00014000"],["79870.82000000","0.00000000"],["79869.25000000","0.04047000"],["79868.79000000","0.04021000"],["79868.64000000","0.00007000"],["79868.63000000","0.02000000"],["79868.36000000","0.00559000"],["79867.34000000","0.00000000"],["79866.44000000","0.00400000"],["79866.43000000","0.00000000"],["79842.00000000","0.02400000"],["79800.44000000","0.59961000"],["79739.42000000","0.00000000"],["71885.97000000","0.00432000"]],"a":[["79878.68000000","0.00807000"]]}}}
{"rx_ns": 13864796311300, "frame": {"stream":"btcusdt@depth20","data":{"lastUpdateId":99118582717,"bids":[["79873.29000000","0.96576000"],["79873.28000000","0.01262000"],["79873.27000000","0.00026000"],["79872.93000000","0.00007000"],["79872.49000000","0.00007000"],["79872.08000000","0.00014000"],["79872.02000000","0.00007000"],["79872.01000000","0.01933000"],["79871.99000000","0.00659000"],["79871.69000000","0.00007000"],["79870.74000000","0.00007000"],["79870.73000000","0.02323000"],["79870.64000000","0.00007000"],["79870.63000000","0.05277000"],["79870.55000000","0.00007000"],["79870.09000000","0.00007000"],["79870.00000000","0.00007000"],["79869.46000000","0.00007000"],["79869.45000000","0.02324000"],["79869.26000000","0.00007000"]],"asks":[["79873.30000000","4.07033000"],["79873.31000000","0.00020000"],["79873.32000000","0.00013000"],["79873.33000000","0.00007000"],["79873.34000000","0.08964000"],["79873.35000000","0.05014000"],["79873.38000000","0.00007000"],["79873.39000000","0.17636000"],["79873.68000000","0.00007000"],["79873.99000000","0.00007000"],["79874.00000000","0.02435000"],["79874.15000000","0.00400000"],["79874.18000000","0.00007000"],["79874.28000000","0.00007000"],["79874.54000000","0.00007000"],["79874.60000000","0.00007000"],["79874.62000000","0.00007000"],["79874.87000000","0.00007000"],["79875.02000000","0.00007000"],["79875.36000000","0.00717000"]]}}}
{"rx_ns": 13864796425500, "frame": {"stream":"btcusdt@depth@100ms","data":{"e":"depthUpdate","E":1787650860014,"s":"BTCUSDT","U":99118582681,"u":99118582717,"b":[["79872.01000000","0.01933000"],["79871.99000000","0.00659000"],["79871.93000000","0.00000000"],["79869.06000000","0.12555000"],["79868.36000000","0.00566000"],["79866.47000000","0.06324000"],["79866.44000000","0.00000000"],["79866.43000000","0.06317000"],["79864.31000000","0.00015000"],["79864.01000000","0.00800000"],["79863.60000000","0.00000000"],["79853.35000000","0.00000000"],["79850.94000000","0.00000000"],["79850.03000000","0.00626000"],["79844.00000000","0.02400000"],["79841.80000000","0.33824000"],["79801.30000000","0.00312000"],["79800.13000000","0.02087000"],["79721.31000000","0.00125000"],["71885.97000000","0.00432000"],["63899.00000000","0.13788000"],["63898.64000000","0.00031000"]],"a":[["79876.21000000","0.00007000"],["79887.33000000","0.19419000"],["79888.67000000","0.00626000"],["79893.94000000","0.00000000"],["79896.43000000","0.00000000"],["79935.96000000","0.00190000"],["80016.23000000","0.00076000"]]}}}
{"rx_ns": 13864896317500, "frame": {"stream":"btcusdt@depth@100ms","data":{"e":"depthUpdate","E":1787650860114,"s":"BTCUSDT","U":99118582718,"u":99118582746,"b":[["79873.29000000","0.96576000"],["79873.28000000","0.01248000"],["79872.56000000","0.00202000"],["79868.29000000","0.00009000"],["79864.31000000","0.00000000"],["79864.30000000","0.00000000"],["79864.09000000","0.00025000"],["79862.54000000","0.00250000"],["79856.15000000","0.00000000"],["79835.20000000","0.62643000"],["79800.13000000","0.00000000"],["79733.68000000","0.04534000"],["79718.77000000","1.50023000"],["71885.97000000","0.00432000"]],"a":[["79873.30000000","4.07235000"],["79878.50000000","0.00250000"],["80022.27000000","1.50023000"],["81071.40000000","0.00092000"],["86422.88000000","0.20801000"]]}}}
{"rx_ns": 13864998691200, "frame": {"stream":"btcusdt@depth@100ms","data":{"e":"depthUpdate","E":1787650860214,"s":"BTCUSDT","U":99118582747,"u":99118582755,"b":[["79873.29000000","0.96583000"],["79873.28000000","0.01255000"],["78675.19000000","0.00030000"],["71885.97000000","0.00432000"],["63898.64000000","0.00000000"]],"a":[]}}}
{"rx_ns": 13865099471300, "frame": {"stream":"btcusdt@depth@100ms","data":{"e":"depthUpdate","E":1787650860314,"s":"BTCUSDT","U":99118582756,"u":99118582769,"b":[["79873.29000000","0.96583000"],["79858.08000000","0.00007000"],["79780.81000000","0.00000000"],["79778.17000000","0.62582000"],["75215.42000000","0.00000000"],["71885.97000000","0.00432000"],["63899.00000000","0.13788000"]],"a":[["79890.04000000","0.00007000"],["84202.54000000","0.00884000"]]}}}
{"rx_ns": 13865203040800, "frame": {"stream":"btcusdt@depth@100ms","data":{"e":"depthUpdate","E":1787650860414,"s":"BTCUSDT","U":99118582770,"u":99118582851,"b":[["79873.29000000","1.39226000"],["79873.28000000","0.01255000"],["79872.01000000","0.02501000"],["79871.99000000","0.00028000"],["79870.63000000","0.05284000"],["79869.58000000","0.00007000"],["79869.57000000","0.06317000"],["79869.08000000","0.00007000"],["79869.07000000","0.06324000"],["79868.64000000","0.00000000"],["79868.63000000","0.02007000"],["79868.43000000","0.00685000"],["79868.36000000","0.00573000"],["79868.33000000","0.06324000"],["79867.71000000","0.06317000"],["79867.09000000","0.06317000"],["79866.48000000","0.00007000"],["79865.31000000","0.00016000"],["79864.72000000","0.00250000"],["79864.65000000","0.00000000"],["79864.33000000","0.03224000"],["79864.09000000","0.00000000"],["79864.02000000","0.03456000"],["79863.38000000","0.00000000"],["79862.54000000","0.00000000"],["79858.88000000","0.00000000"],["79830.36000000","0.00000000"],["79829.82000000","0.00021000"],["78930.53000000","0.00038000"],["71885.97000000","0.00432000"],["71885.00000000","0.00040000"],["63898.63000000","0.00000000"]],"a":[["79873.30000000","2.19108000"],["79873.31000000","0.00048000"],["79875.36000000","0.00007000"],["79876.65000000","0.00726000"],["79876.91000000","0.00000000"],["79878.18000000","0.00000000"],["79878.50000000","0.00000000"],["79878.68000000","0.00014000"],["79879.35000000","0.00000000"],["79880.68000000","0.00250000"],["79882.28000000","0.00400000"],["79888.67000000","0.00000000"],["79890.59000000","0.00626000"],["79908.00000000","0.02400000"],["79939.90000000","0.54190000"],["79942.95000000","0.00000000"],["80067.97000000","3.74769000"]]}}}
{"rx_ns": 13865296259000, "frame": {"stream":"btcusdt@depth@100ms","data":{"e":"depthUpdate","E":1787650860514,"s":"BTCUSDT","U":99118582852,"u":99118582893,"b":[["79873.29000000","1.41175000"],["79872.01000000","0.02501000"],["79871.99000000","0.00014000"],["79870.63000000","0.05284000"],["79869.57000000","0.06331000"],["79869.25000000","0.04047000"],["79869.07000000","0.06338000"],["79869.06000000","0.12541000"],["79867.31000000","0.00012000"],["79866.48000000","0.00000000"],["79866.43000000","1.43604000"],["79865.31000000","0.00000000"],["79864.02000000","0.00000000"],["79863.88000000","1.87677000"],["79858.88000000","0.03457000"],["79856.05000000","0.37576000"],["79835.20000000","0.00000000"],["71885.97000000","0.00416000"],["63898.64000000","0.00031000"]],"a":[["79874.00000000","0.02428000"],["79875.36000000","0.00000000"],["79876.65000000","0.00733000"],["79878.68000000","0.00414000"],["79882.28000000","0.00000000"],["79883.17000000","0.00191000"]]}}}
{"rx_ns": 13865397601700, "frame": {"stream":"btcusdt@depth@100ms","data":{"e":"depthUpdate","E":1787650860614,"s":"BTCUSDT","U":99118582894,"u":99118582947,"b":[["79873.29000000","1.40582000"],["79873.28000000","0.01255000"],["79872.01000000","0.02508000"],["79871.84000000","0.00916000"],["79869.58000000","0.00000000"],["79869.57000000","0.00014000"],["79869.08000000","0.00000000"],["79869.07000000","0.00021000"],["79868.64000000","0.00007000"],["79868.36000000","0.00573000"],["79868.33000000","0.00000000"],["79867.71000000","0.00000000"],["79867.31000000","0.00000000"],["79866.48000000","0.01200000"],["79866.43000000","1.00683000"],["79865.31000000","0.00019000"],["79864.01000000","0.00400000"],["79863.88000000","0.00000000"],["79863.76000000","0.00000000"],["79863.59000000","0.00192000"],["79851.33000000","0.27285000"],["79848.04000000","0.62618000"],["71885.97000000","0.00432000"],["63898.64000000","0.00000000"],["63898.63000000","0.00000000"]],"a":[["79873.30000000","2.19101000"],["79878.68000000","0.01214000"],["79889.99000000","0.00000000"],["79891.40000000","0.41326000"],["79893.40000000","0.62618000"]]}}}
{"rx_ns": 13865495647200, "frame": {"stream":"btcusdt@depth@100ms","data":{"e":"depthUpdate","E":1787650860714,"s":"BTCUSDT","U":99118582948,"u":99118582988,"b":[["79873.29000000","1.39845000"],["79872.01000000","0.02508000"],["79871.84000000","0.00930000"],["79870.76000000","0.00709000"],["79870.63000000","0.05277000"],["79869.57000000","0.00000000"],["79869.25000000","0.04047000"],["79869.07000000","0.00007000"],["79869.06000000","0.12555000"],["79867.09000000","0.06324000"],["79866.49000000","0.00400000"],["79865.31000000","0.00011000"],["79864.72000000","0.00000000"],["79863.90000000","0.00250000"],["73465.69000000","0.00014000"],["71885.97000000","0.00416000"]],"a":[["79873.30000000","2.19405000"],["79876.02000000","0.00711000"],["79876.91000000","0.00926000"],["79878.15000000","0.00714000"],["79878.47000000","0.00400000"],["79878.67000000","0.00400000"],["79879.86000000","0.00250000"],["79880.68000000","0.00000000"]]}}}
{"rx_ns": 13865596552700, "frame": {"stream":"btcusdt@depth@100ms","data":{"e":"depthUpdate","E":1787650860814,"s":"BTCUSDT","U":99118582989,"u":99118583013,"b":[["79873.29000000","1.39852000"],["79873.28000000","0.01262000"],["79871.84000000","0.00937000"],["79870.76000000","0.00723000"],["79869.06000000","0.12541000"],["79829.54000000","0.00400000"],["79829.50000000","0.00000000"],["79697.36000000","0.00000000"],["71885.97000000","0.00432000"]],"a":[["79873.30000000","2.19412000"],["79873.31000000","0.00055000"],["79876.00000000","0.02428000"],["79876.02000000","0.00718000"],["79876.65000000","0.00726000"],["79878.68000000","0.01207000"],["80065.47000000","0.00000000"]]}}}
{"rx_ns": 13865696602700, "frame": {"stream":"btcusdt@depth@100ms","data":{"e":"depthUpdate","E":1787650860914,"s":"BTCUSDT","U":99118583014,"u":99118583015,"b":[["79800.13000000","0.02087000"],["71885.97000000","0.00416000"]],"a":[]}}}
{"rx_ns": 13865805427600, "frame": {"stream":"btcusdt@depth20","data":{"lastUpdateId":99118585034,"bids":[["79869.25000000","1.74453000"],["79869.24000000","0.00105000"],["79869.06000000","0.00028000"],["79868.79000000","0.00028000"],["79868.63000000","0.00014000"],["79868.44000000","0.00007000"],["79868.43000000","0.00014000"],["79868.36000000","0.00014000"],["79868.33000000","0.00007000"],["79868.29000000","0.00009000"],["79867.34000000","0.00686000"],["79867.09000000","0.00014000"],["79866.80000000","0.00007000"],["79866.79000000","0.05256000"],["79866.77000000","0.00007000"],["79866.57000000","0.00007000"],["79866.49000000","0.00400000"],["79866.48000000","0.00014000"],["79866.47000000","0.00014000"],["79866.36000000","0.00026000"]],"asks":[["79869.26000000","2.31479000"],["79869.27000000","0.00027000"],["79869.28000000","0.00013000"],["79869.43000000","0.00007000"],["79869.45000000","0.00007000"],["79869.46000000","0.37199000"],["79869.47000000","0.10466000"],["79869.68000000","0.00400000"],["79870.08000000","0.00007000"],["79870.63000000","0.00007000"],["79870.64000000","0.00007000"],["79870.65000000","0.00007000"],["79870.73000000","0.00007000"],["79870.74000000","0.55571000"],["79870.97000000","0.16884000"],["79871.91000000","0.00400000"],["79872.00000000","0.00007000"],["79872.01000000","0.35070000"],["79872.02000000","0.88495000"],["79872.06000000","0.01540000"]]}}}
{"rx_ns": 13865805554400, "frame": {"stream":"btcusdt@depth@100ms","data":{"e":"depthUpdate","E":1787650861014,"s":"BTCUSDT","U":99118583016,"u":99118585034,"b":[["79873.29000000","0.00000000"],["79873.28000000","0.00000000"],["79873.27000000","0.00000000"],["79872.93000000","0.00000000"],["79872.56000000","0.00000000"],["79872.49000000","0.00000000"],["79872.08000000","0.00000000"],["79872.02000000","0.00000000"],["79872.01000000","0.00000000"],["79872.00000000","0.00000000"],["79871.99000000","0.00000000"],["79871.84000000","0.00000000"],["79871.69000000","0.00000000"],["79870.76000000","0.00000000"],["79870.74000000","0.00000000"],["79870.73000000","0.00000000"],["79870.72000000","0.00000000"],["79870.64000000","0.00000000"],["79870.63000000","0.00000000"],["79870.55000000","0.00000000"],["79870.09000000","0.00000000"],["79870.00000000","0.00000000"],["79869.46000000","0.00000000"],["79869.45000000","0.00000000"],["79869.44000000","0.00000000"],["79869.43000000","0.00000000"],["79869.42000000","0.00000000"],["79869.26000000","0.00000000"],["79869.25000000","1.74453000"],["79869.24000000","0.00105000"],["79869.07000000","0.00000000"],["79869.06000000","0.00028000"],["79868.80000000","0.00000000"],["79868.79000000","0.00028000"],["79868.64000000","0.00000000"],["79868.63000000","0.00014000"],["79868.43000000","0.00014000"],["79868.36000000","0.00014000"],["79868.34000000","0.00000000"],["79868.33000000","0.00007000"],["79868.07000000","0.00000000"],["79868.01000000","0.00000000"],["79867.59000000","0.00000000"],["79867.39000000","0.00000000"],["79867.34000000","0.00686000"],["79867.32000000","0.00000000"],["79867.30000000","0.00000000"],["79867.10000000","0.00000000"],["79867.09000000","0.00014000"],["79867.08000000","0.00000000"],["79866.83000000","0.00000000"],["79866.80000000","0.00007000"],["79866.79000000","0.05256000"],["79866.78000000","0.00000000"],["79866.77000000","0.00007000"],["79866.72000000","0.00000000"],["79866.58000000","0.00000000"],["79866.57000000","0.00007000"],["79866.49000000","0.00400000"],["79866.48000000","0.00014000"],["79866.47000000","0.00014000"],["79866.43000000","0.00000000"],["79866.42000000","0.00000000"],["79866.36000000","0.00026000"],["79866.18000000","0.00000000"],["79866.16000000","0.00007000"],["79866.15000000","0.06325000"],["79865.71000000","0.00202000"],["79865.54000000","0.00007000"],["79865.53000000","0.06325000"],["79865.38000000","0.33812000"],["79865.31000000","0.00000000"],["79865.30000000","0.00000000"],["79865.29000000","0.00000000"],["79865.20000000","0.00017000"],["79865.19000000","0.00007000"],["79865.04000000","0.00000000"],["79865.03000000","0.00000000"],["79864.92000000","0.00007000"],["79864.91000000","0.06332000"],["79864.74000000","0.00013000"],["79864.50000000","0.00905000"],["79864.33000000","0.00000000"],["79864.30000000","0.00007000"],["79864.29000000","0.06325000"],["79864.23000000","0.00000000"],["79864.08000000","0.00000000"],["79864.02000000","0.00007000"],["79864.01000000","0.06318000"],["79864.00000000","0.02414000"],["79863.99000000","0.33113000"],["79863.90000000","0.00000000"],["79863.87000000","0.00000000"],["79863.86000000","0.00000000"],["79863.84000000","0.00000000"],["79863.59000000","0.00000000"],["79863.58000000","0.00000000"],["79863.57000000","0.00694000"],["79863.08000000","0.00000000"],["79863.05000000","0.00000000"],["79862.43000000","0.00000000"],["79862.37000000","0.00000000"],["79862.36000000","0.00000000"],["79862.34000000","0.00000000"],["79862.33000000","0.02282000"],["79862.32000000","0.00000000"],["79862.05000000","0.00000000"],["79862.03000000","0.00000000"],["79862.02000000","0.00000000"],["79862.01000000","0.00000000"],["79862.00000000","0.02407000"],["79861.99000000","0.04963000"],["79861.79000000","0.00000000"],["79861.72000000","0.00000000"],["79861.68000000","0.00000000"],["79861.62000000","0.00010000"],["79861.52000000","0.00000000"],["79861.47000000","0.00008000"],["79861.43000000","0.00000000"],["79861.32000000","0.00014000"],["79861.26000000","0.20250000"],["79861.24000000","0.00000000"],["79861.19000000","0.00000000"],["79860.85000000","0.00000000"],["79860.73000000","0.00713000"],["79860.45000000","0.00000000"],["79860.32000000","0.31312000"],["79860.31000000","0.12521000"],["79860.23000000","0.00000000"],["79859.99000000","0.00000000"],["79859.69000000","0.00000000"],["79859.61000000","0.00000000"],["79859.53000000","0.00626000"],["79858.99000000","0.00000000"],["79858.94000000","0.00000000"],["79858.93000000","0.00000000"],["79858.90000000","0.87026000"],["79858.89000000","0.00000000"],["79858.88000000","0.00000000"],["79858.87000000","0.00000000"],["79858.86000000","0.00000000"],["79858.84000000","0.00000000"],["79858.56000000","0.00190000"],["79858.42000000","0.00000000"],["79858.37000000","0.00000000"],["79858.03000000","0.00000000"],["79858.02000000","0.00000000"],["79858.01000000","0.00000000"],["79858.00000000","0.02400000"],["79857.54000000","0.08576000"],["79857.45000000","0.00014000"],["79857.35000000","0.00000000"],["79857.34000000","0.00000000"],["79857.24000000","0.00000000"],["79857.13000000","0.00000000"],["79856.97000000","0.00000000"],["79856.96000000","0.00000000"],["79856.93000000","0.00000000"],["79856.79000000","0.00000000"],["79856.59000000","0.02000000"],["79856.49000000","0.05000000"],["79856.44000000","0.00000000"],["79856.43000000","0.00000000"],["79856.39000000","0.00000000"],["79856.23000000","0.03224000"],["79856.14000000","0.00250000"],["79856.11000000","0.00000000"],["79856.06000000","0.00000000"],["79856.05000000","0.00000000"],["79855.93000000","0.00000000"],["79855.73000000","0.00000000"],["79855.72000000","1.11670000"],["79855.39000000","0.08000000"],["79855.12000000","0.00000000"],["79854.94000000","0.00000000"],["79854.03000000","1.87677000"],["79854.02000000","0.00000000"],["79854.00000000","0.16565000"],["79853.58000000","0.00014000"],["79853.00000000","0.00626000"],["79852.30000000","0.00000000"],["79851.93000000","0.00000000"],["79851.82000000","0.00000000"],["79851.33000000","0.00000000"],["79851.26000000","0.00000000"],["79850.94000000","0.42953000"],["79850.41000000","0.00626000"],["79850.03000000","0.00000000"],["79850.00000000","0.02699000"],["79849.80000000","0.00000000"],["79849.71000000","0.00014000"],["79849.35000000","0.00000000"],["79849.19000000","0.00000000"],["79848.94000000","0.33548000"],["79848.51000000","0.00000000"],["79848.50000000","0.00000000"],["79848.46000000","0.00162000"],["79848.05000000","2.24663000"],["79848.04000000","0.00000000"],["79848.03000000","0.00007000"],["79848.01000000","0.00000000"],["79847.83000000","0.33822000"],["79847.71000000","0.00000000"],["79847.37000000","0.37580000"],["79847.11000000","0.00000000"],["79847.10000000","0.33698000"],["79846.46000000","0.00000000"],["79845.84000000","0.00014000"],["79845.17000000","0.00000000"],["79845.08000000","0.00000000"],["79845.07000000","0.00000000"],["79844.59000000","0.00000000"],["79844.49000000","0.00000000"],["79843.24000000","0.00000000"],["79842.78000000","0.62620000"],["79842.77000000","0.00000000"],["79841.97000000","0.00014000"],["79841.62000000","0.00000000"],["79841.61000000","0.00000000"],["79841.17000000","0.00000000"],["79840.94000000","0.00000000"],["79840.69000000","0.00000000"],["79840.46000000","0.00000000"],["79840.45000000","0.09340000"],["79840.26000000","0.00000000"],["79840.13000000","0.00000000"],["79840.03000000","0.36586000"],["79840.01000000","0.00000000"],["79840.00000000","0.32302000"],["79839.77000000","0.00000000"],["79838.10000000","0.00014000"],["79837.52000000","0.00000000"],["79837.04000000","0.33826000"],["79836.23000000","0.00400000"],["79835.00000000","0.04502000"],["79834.37000000","0.62644000"],["79833.00000000","0.00000000"],["79832.00000000","0.02400000"],["79831.33000000","0.00000000"],["79831.26000000","0.33829000"],["79830.47000000","0.00000000"],["79830.36000000","0.00014000"],["79830.02000000","0.00000000"],["79830.00000000","0.11795000"],["79829.82000000","0.00007000"],["79829.00000000","0.01000000"],["79827.85000000","0.61403000"],["79827.31000000","0.00400000"],["79826.82000000","0.00000000"],["79826.49000000","0.00007000"],["79825.08000000","0.00000000"],["79824.60000000","0.50981000"],["79823.07000000","0.00000000"],["79822.85000000","0.00000000"],["79822.62000000","0.00000000"],["79821.72000000","0.00010000"],["79820.49000000","0.34819000"],["79818.75000000","0.00000000"],["79818.56000000","0.00000000"],["79818.02000000","0.00000000"],["79814.88000000","0.00000000"],["79808.60000000","0.00000000"],["79805.38000000","0.00431000"],["79805.21000000","0.00000000"],["79802.63000000","0.00312000"],["79801.30000000","0.00311000"],["79800.13000000","0.00000000"],["79797.95000000","1.24092000"],["79797.44000000","0.00312000"],["79795.67000000","0.00000000"],["79779.16000000","0.80040000"],["79750.01000000","0.06893000"],["79733.48000000","0.00000000"],["79726.70000000","1.13069000"],["79722.01000000","0.00125000"],["79721.31000000","0.00000000"],["79718.77000000","0.00000000"],["79717.59000000","0.00125000"],["79704.26000000","1.50023000"],["79702.92000000","0.04874000"],["79695.98000000","4.46765000"],["79635.83000000","0.00007000"],["79631.84000000","0.00007000"],["79554.25000000","0.00000000"],["79553.96000000","7.54382000"],["79543.69000000","0.00036000"],["79528.85000000","0.00250000"],["78675.19000000","0.00000000"],["71885.97000000","0.00000000"],["71884.87000000","0.00008000"],["71884.81000000","0.00000000"],["71882.33000000","0.00044000"],["63895.40000000","0.00031000"]],"a":[["79869.26000000","2.31479000"],["79869.27000000","0.00027000"],["79869.28000000","0.00013000"],["79869.42000000","0.00000000"],["79869.43000000","0.00007000"],["79869.45000000","0.00007000"],["79869.46000000","0.37199000"],["79869.47000000","0.10466000"],["79869.68000000","0.00400000"],["79869.99000000","0.00000000"],["79870.00000000","0.00000000"],["79870.01000000","0.00000000"],["79870.08000000","0.00007000"],["79870.10000000","0.00000000"],["79870.56000000","0.00000000"],["79870.63000000","0.00007000"],["79870.64000000","0.00007000"],["79870.65000000","0.00007000"],["79870.70000000","0.00000000"],["79870.73000000","0.00007000"],["79870.74000000","0.55571000"],["79870.75000000","0.00000000"],["79870.76000000","0.00000000"],["79870.77000000","0.00000000"],["79870.97000000","0.16884000"],["79871.20000000","0.00000000"],["79871.22000000","0.00000000"],["79871.33000000","0.00000000"],["79871.36000000","0.00000000"],["79871.70000000","0.00000000"],["79871.85000000","0.00000000"],["79871.91000000","0.00400000"],["79871.98000000","0.00000000"],["79872.00000000","0.00007000"],["79872.01000000","0.35070000"],["79872.02000000","0.88495000"],["79872.03000000","0.00000000"],["79872.04000000","0.00000000"],["79872.06000000","0.01540000"],["79872.08000000","0.00000000"],["79872.09000000","0.00021000"],["79872.15000000","0.00000000"],["79872.38000000","0.04768000"],["79872.50000000","0.00007000"],["79872.55000000","0.00000000"],["79872.57000000","0.00007000"],["79872.64000000","0.00000000"],["79872.93000000","0.00021000"],["79872.94000000","0.10480000"],["79872.96000000","0.00000000"],["79872.97000000","0.00007000"],["79873.00000000","0.05007000"],["79873.05000000","0.05014000"],["79873.06000000","0.00000000"],["79873.26000000","0.00000000"],["79873.27000000","0.00007000"],["79873.28000000","0.00000000"],["79873.29000000","0.00014000"],["79873.30000000","0.56943000"],["79873.31000000","0.00000000"],["79873.32000000","0.00000000"],["79873.33000000","0.00000000"],["79873.34000000","0.00007000"],["79873.35000000","0.00007000"],["79873.38000000","0.00000000"],["79873.39000000","0.00000000"],["79873.58000000","0.00000000"],["79873.66000000","0.00000000"],["79873.67000000","0.00000000"],["79873.71000000","0.00000000"],["79873.95000000","0.00000000"],["79873.99000000","0.00000000"],["79874.00000000","0.02421000"],["79874.01000000","0.00000000"],["79874.02000000","0.00000000"],["79874.05000000","0.00000000"],["79874.14000000","0.00000000"],["79874.18000000","0.00000000"],["79874.34000000","0.00000000"],["79874.38000000","0.04027000"],["79874.40000000","0.00000000"],["79874.54000000","0.00007000"],["79874.68000000","0.00000000"],["79874.77000000","0.00000000"],["79874.87000000","0.00007000"],["79874.91000000","0.00000000"],["79875.01000000","0.00000000"],["79875.16000000","0.00000000"],["79875.33000000","0.00000000"],["79875.47000000","0.00000000"],["79875.49000000","0.00000000"],["79875.54000000","0.00000000"],["79875.55000000","0.00000000"],["79875.69000000","0.00000000"],["79875.78000000","0.00000000"],["79875.99000000","0.00000000"],["79876.00000000","0.02400000"],["79876.02000000","0.00000000"],["79876.03000000","0.09396000"],["79876.10000000","0.00000000"],["79876.15000000","0.00707000"],["79876.21000000","0.00000000"],["79876.22000000","0.00000000"],["79876.27000000","0.00000000"],["79876.46000000","0.00000000"],["79876.53000000","0.00000000"],["79876.54000000","0.00000000"],["79876.58000000","0.00000000"],["79876.65000000","0.00000000"],["79876.73000000","0.00013000"],["79876.86000000","0.00008000"],["79877.02000000","0.00000000"],["79877.25000000","0.00000000"],["79877.64000000","0.00000000"],["79877.75000000","0.00000000"],["79877.77000000","0.00000000"],["79877.80000000","0.00626000"],["79877.93000000","0.00000000"],["79877.98000000","0.00000000"],["79878.10000000","0.00007000"],["79878.26000000","0.00000000"],["79878.47000000","0.00000000"],["79878.52000000","0.00000000"],["79878.53000000","0.00000000"],["79878.66000000","0.00000000"],["79878.67000000","0.02000000"],["79878.68000000","1.87677000"],["79878.69000000","0.00000000"],["79878.73000000","0.00008000"],["79878.77000000","0.00000000"],["79878.92000000","0.00000000"],["79878.98000000","0.00400000"],["79879.02000000","0.00000000"],["79879.05000000","0.00000000"],["79879.11000000","0.12518000"],["79879.20000000","0.00000000"],["79879.21000000","0.00000000"],["79879.25000000","0.00000000"],["79879.29000000","0.00000000"],["79879.35000000","0.00000000"],["79879.49000000","0.00000000"],["79879.77000000","0.00000000"],["79879.81000000","0.00000000"],["79879.86000000","0.00000000"],["79879.98000000","0.00000000"],["79880.00000000","0.02435000"],["79880.35000000","0.00000000"],["79880.49000000","0.00000000"],["79880.60000000","0.00000000"],["79880.69000000","0.00000000"],["79881.23000000","0.00007000"],["79881.29000000","0.20257000"],["79881.33000000","0.00000000"],["79881.43000000","0.00000000"],["79881.59000000","0.00000000"],["79881.93000000","0.00000000"],["79882.05000000","0.00000000"],["79882.28000000","1.04939000"],["79882.29000000","0.00000000"],["79882.75000000","0.02000000"],["79883.17000000","0.00000000"],["79883.21000000","0.00000000"],["79883.57000000","0.11000000"],["79883.95000000","0.03013000"],["79885.10000000","0.00000000"],["79885.34000000","0.00000000"],["79886.29000000","0.00000000"],["79887.32000000","0.00000000"],["79887.33000000","0.19019000"],["79887.34000000","0.00000000"],["79887.67000000","0.00000000"],["79887.92000000","0.00000000"],["79888.00000000","1.37894000"],["79888.16000000","0.00000000"],["79888.21000000","0.00000000"],["79888.30000000","0.00000000"],["79888.74000000","0.33752000"],["79888.75000000","0.00000000"],["79888.94000000","0.00626000"],["79889.77000000","0.00000000"],["79890.59000000","0.00000000"],["79890.74000000","0.00000000"],["79891.40000000","0.00000000"],["79892.80000000","0.62620000"],["79893.40000000","0.00000000"],["79894.21000000","0.00400000"],["79894.44000000","0.00000000"],["79894.58000000","0.33802000"],["79895.32000000","0.33802000"],["79896.21000000","0.00250000"],["79897.28000000","0.00000000"],["79899.45000000","0.00000000"],["79899.49000000","0.00000000"],["79900.07000000","0.00000000"],["79900.26000000","0.00000000"],["79900.42000000","0.00000000"],["79900.43000000","0.00000000"],["79900.95000000","0.00000000"],["79901.13000000","0.00000000"],["79901.54000000","0.00000000"],["79901.96000000","0.00000000"],["79902.70000000","0.33799000"],["79904.88000000","0.00000000"],["79907.04000000","0.00000000"],["79909.20000000","0.00000000"],["79909.92000000","0.00000000"],["79911.04000000","0.00000000"],["79911.63000000","0.00000000"],["79911.85000000","0.80253000"],["79911.86000000","0.00000000"],["79912.12000000","0.00426000"],["79913.00000000","0.06000000"],["79913.14000000","0.00427000"],["79914.00000000","0.02400000"],["79920.82000000","0.00000000"],["79921.63000000","0.00000000"],["79923.81000000","0.00000000"],["79924.00000000","0.02400000"],["79925.53000000","0.17850000"],["79927.44000000","0.00000000"],["79931.61000000","0.00007000"],["79935.26000000","0.00000000"],["79935.96000000","0.00000000"],["79935.97000000","0.00000000"],["79936.89000000","0.00000000"],["79940.23000000","0.00312000"],["79951.62000000","2.10082000"],["79954.42000000","3.75302000"],["79969.49000000","0.00000000"],["80007.69000000","0.44862000"],["80007.70000000","1.50023000"],["80016.23000000","0.00000000"],["80021.12000000","0.00125000"],["80022.27000000","0.00000000"],["80049.65000000","0.00000000"],["80062.79000000","4.40075000"],["80067.97000000","0.00000000"],["80102.67000000","0.00007000"],["80102.72000000","0.00000000"],["80106.66000000","0.00014000"],["80149.63000000","0.00000000"],["80402.50000000","0.00250000"],["80659.10000000","0.00000000"],["80659.12000000","0.00000000"],["81071.40000000","0.00062000"]]}}}
{"rx_ns": 13865909202300, "frame": {"stream":"btcusdt@depth@100ms","data":{"e":"depthUpdate","E":1787650861114,"s":"BTCUSDT","U":99118585035,"u":99118585622,"b":[["79869.25000000","1.25801000"],["79869.24000000","0.00021000"],["79869.06000000","0.00007000"],["79868.79000000","0.00000000"],["79868.63000000","0.00000000"],["79868.44000000","0.00000000"],["79868.43000000","0.00000000"],["79868.36000000","0.00000000"],["79867.98000000","0.00007000"],["79867.97000000","0.01850000"],["79867.34000000","0.00014000"],["79867.09000000","0.00000000"],["79866.81000000","0.00007000"],["79866.80000000","0.06318000"],["79866.79000000","0.05277000"],["79866.76000000","0.00026000"],["79866.70000000","0.00007000"],["79866.69000000","0.02212000"],["79866.49000000","0.00000000"],["79866.48000000","0.00000000"],["79866.47000000","0.00000000"],["79866.36000000","0.00000000"],["79866.16000000","0.00007000"],["79866.15000000","0.06346000"],["79865.83000000","0.00000000"],["79865.71000000","0.00000000"],["79865.56000000","0.00007000"],["79865.55000000","0.48296000"],["79865.54000000","1.04939000"],["79865.53000000","0.00028000"],["79865.41000000","0.02212000"],["79865.40000000","0.00000000"],["79865.39000000","0.00000000"],["79865.38000000","0.00014000"],["79865.20000000","0.00000000"],["79864.92000000","0.00000000"],["79864.91000000","0.00028000"],["79864.50000000","0.00014000"],["79864.31000000","0.00912000"],["79864.30000000","0.00000000"],["79864.29000000","0.00021000"],["79864.02000000","0.00000000"],["79864.01000000","0.00000000"],["79864.00000000","0.02421000"],["79863.99000000","0.33099000"],["79863.57000000","0.00000000"],["79863.13000000","0.00000000"],["79863.05000000","0.00000000"],["79863.02000000","0.00000000"],["79862.85000000","0.00718000"],["79862.58000000","0.00000000"],["79862.44000000","0.00000000"],["79862.43000000","0.00000000"],["79862.33000000","0.02282000"],["79862.02000000","0.00000000"],["79862.01000000","0.00000000"],["79862.00000000","0.02407000"],["79861.99000000","0.04970000"],["79861.71000000","0.00000000"],["79861.69000000","0.00000000"],["79861.63000000","0.00000000"],["79861.44000000","0.02480000"],["79861.32000000","0.00007000"],["79861.27000000","0.00014000"],["79861.26000000","0.20257000"],["79861.20000000","0.61864000"],["79861.19000000","0.20379000"],["79861.03000000","0.31311000"],["79860.57000000","0.00000000"],["79860.45000000","0.00000000"],["79860.34000000","0.00000000"],["79860.33000000","1.04939000"],["79860.32000000","0.00000000"],["79860.01000000","0.00000000"],["79859.95000000","0.33812000"],["79859.94000000","0.00047000"],["79859.53000000","0.00000000"],["79859.48000000","0.00189000"],["79858.92000000","0.92031000"],["79858.91000000","1.87677000"],["79858.90000000","0.00000000"],["79858.56000000","0.00000000"],["79858.44000000","0.00048000"],["79856.93000000","0.36586000"],["79856.14000000","0.00000000"],["79855.93000000","0.00000000"],["79855.73000000","0.00800000"],["79855.44000000","0.00000000"],["79855.08000000","0.00626000"],["79854.04000000","1.87677000"],["79854.03000000","0.00000000"],["79853.55000000","0.50183000"],["79852.82000000","0.00000000"],["79852.70000000","0.00250000"],["79851.54000000","0.00000000"],["79851.24000000","0.02000000"],["79850.94000000","0.00000000"],["79850.41000000","0.00000000"],["79848.95000000","0.00000000"],["79848.94000000","0.00000000"],["79848.82000000","0.33821000"],["79848.05000000","2.24263000"],["79848.03000000","0.00014000"],["79847.83000000","0.00000000"],["79847.50000000","0.54946000"],["79847.49000000","0.00000000"],["79847.37000000","0.00000000"],["79847.11000000","0.00000000"],["79847.10000000","0.00000000"],["79845.85000000","0.42956000"],["79845.73000000","1.20228000"],["79844.12000000","0.00626000"],["79842.77000000","0.50163000"],["79838.58000000","0.02455000"],["79831.26000000","0.00000000"],["79829.60000000","0.98256000"],["79822.62000000","0.00007000"],["79818.75000000","0.00000000"],["79814.09000000","0.00621000"],["79808.17000000","0.00435000"],["79790.31000000","0.02000000"],["79772.66000000","0.00000000"],["79631.84000000","0.00000000"],["71882.33000000","0.00060000"]],"a":[["79869.26000000","2.40229000"],["79869.28000000","0.00020000"],["79869.29000000","0.06256000"],["79869.30000000","0.05007000"],["79869.34000000","0.00007000"],["79869.35000000","0.05000000"],["79869.46000000","0.33826000"],["79869.47000000","0.10473000"],["79869.68000000","0.00000000"],["79869.82000000","0.00000000"],["79870.02000000","0.00000000"],["79870.08000000","0.00014000"],["79870.74000000","0.55578000"],["79870.96000000","0.00000000"],["79870.97000000","0.00007000"],["79872.00000000","0.00007000"],["79872.01000000","0.16889000"],["79872.02000000","0.88502000"],["79872.04000000","0.00771000"],["79872.06000000","0.01547000"],["79872.09000000","0.00014000"],["79872.38000000","0.04775000"],["79872.93000000","0.00014000"],["79872.94000000","0.10473000"],["79872.97000000","0.00000000"],["79873.00000000","0.00007000"],["79873.05000000","0.00007000"],["79873.27000000","0.00000000"],["79873.29000000","0.00014000"],["79873.30000000","0.56929000"],["79873.32000000","0.01286000"],["79873.34000000","0.00000000"],["79873.35000000","0.00000000"],["79874.38000000","0.04001000"],["79874.60000000","0.01543000"],["79874.62000000","0.00000000"],["79874.76000000","0.00000000"],["79874.87000000","0.00000000"],["79875.37000000","0.00000000"],["79875.43000000","0.00000000"],["79875.67000000","0.00000000"],["79875.88000000","0.01543000"],["79876.02000000","0.00000000"],["79876.03000000","0.61025000"],["79878.67000000","0.00800000"],["79878.98000000","0.00000000"],["79881.48000000","0.00000000"],["79882.75000000","0.00000000"],["79888.46000000","0.02000000"],["79888.47000000","0.00000000"],["79893.88000000","0.00000000"],["79902.70000000","0.00000000"],["79908.81000000","0.02478000"],["79909.82000000","0.00400000"],["79910.00000000","0.12786000"],["79911.85000000","0.00000000"],["79912.57000000","0.00000000"],["79912.59000000","0.00627000"],["79913.00000000","0.05000000"],["79914.59000000","0.00435000"],["79931.93000000","0.25000000"],["79931.99000000","0.00190000"],["79941.71000000","1.23869000"],["79972.35000000","0.00000000"],["80012.45000000","0.00076000"],["80106.66000000","0.00007000"],["80144.01000000","0.00033000"]]}}}
{"rx_ns": 13866006226200, "frame": {"stream":"btcusdt@depth@100ms","data":{"e":"depthUpdate","E":1787650861214,"s":"BTCUSDT","U":99118585623,"u":99118585792,"b":[["79869.25000000","1.26333000"],["79869.24000000","0.00021000"],["79867.97000000","0.01864000"],["79867.34000000","0.00000000"],["79866.81000000","0.00000000"],["79866.80000000","0.00021000"],["79866.79000000","0.05277000"],["79866.69000000","0.02233000"],["79866.31000000","0.00708000"],["79866.16000000","0.00000000"],["79866.15000000","0.00035000"],["79865.55000000","0.48310000"],["79865.54000000","1.04953000"],["79865.53000000","0.00007000"],["79865.41000000","0.02233000"],["79865.38000000","0.00000000"],["79864.91000000","0.00007000"],["79864.56000000","0.00202000"],["79864.50000000","0.00000000"],["79864.31000000","0.00902000"],["79864.29000000","0.00007000"],["79863.99000000","0.33106000"],["79863.95000000","0.33812000"],["79862.99000000","0.00400000"],["79862.05000000","0.00008000"],["79861.99000000","0.04977000"],["79861.32000000","0.00014000"],["79861.27000000","0.00014000"],["79861.21000000","0.00007000"],["79861.20000000","0.61871000"],["79859.95000000","0.00000000"],["79858.64000000","0.00162000"],["79854.43000000","0.00250000"],["79852.70000000","0.00000000"],["79850.00000000","0.12092000"],["79848.46000000","0.00000000"],["79840.33000000","0.00000000"],["79827.31000000","0.00000000"],["79824.07000000","0.83231000"],["79795.43000000","0.02087000"],["79793.86000000","1.24098000"],["79768.63000000","0.00025000"],["78671.21000000","0.00030000"],["73465.69000000","0.00000000"],["71882.33000000","0.00076000"],["63895.40000000","0.00000000"]],"a":[["79869.26000000","2.39830000"],["79869.29000000","0.03028000"],["79869.30000000","0.05014000"],["79869.35000000","0.05007000"],["79869.46000000","0.33819000"],["79869.47000000","0.00014000"],["79869.86000000","0.00250000"],["79870.74000000","0.55571000"],["79870.97000000","0.00000000"],["79871.91000000","0.00000000"],["79872.00000000","0.00007000"],["79872.01000000","0.16889000"],["79872.02000000","0.88495000"],["79872.06000000","0.01540000"],["79872.38000000","0.04768000"],["79872.93000000","0.00021000"],["79873.29000000","0.00014000"],["79875.14000000","0.00026000"],["79879.20000000","0.00156000"],["79879.23000000","0.00189000"],["79904.44000000","0.62589000"],["79905.36000000","0.00400000"],["79920.25000000","0.83131000"],["79968.30000000","0.00025000"],["80592.15000000","0.00000000"],["81067.30000000","0.00030000"]]}}}
{"rx_ns": 13866095951100, "frame": {"stream":"btcusdt@depth@100ms","data":{"e":"depthUpdate","E":1787650861314,"s":"BTCUSDT","U":99118585793,"u":99118585950,"b":[["79869.25000000","1.26517000"],["79869.24000000","0.00028000"],["79868.69000000","0.00903000"],["79868.45000000","0.00000000"],["79867.97000000","0.01864000"],["79866.80000000","0.00007000"],["79866.69000000","0.02233000"],["79866.31000000","0.00722000"],["79866.15000000","0.00021000"],["79865.30000000","0.00007000"],["79864.31000000","0.00909000"],["79863.99000000","0.33113000"],["79863.96000000","0.00007000"],["79861.27000000","0.00014000"],["79861.26000000","0.20250000"],["79861.21000000","0.00007000"],["79861.20000000","0.61864000"],["79861.19000000","0.00000000"],["79858.08000000","0.00000000"],["79855.68000000","0.00250000"],["79854.43000000","0.00000000"],["79834.38000000","0.51599000"],["79832.07000000","0.00000000"],["79822.62000000","0.00000000"],["79821.12000000","0.00000000"],["79817.04000000","0.00012000"],["79813.61000000","0.00335000"],["79800.44000000","0.76500000"],["79795.43000000","0.00000000"],["79726.70000000","0.00000000"],["71882.33000000","0.00092000"],["63899.00000000","0.13788000"],["63895.00000000","0.00000000"]],"a":[["79869.26000000","2.39837000"],["79869.29000000","0.19303000"],["79869.46000000","0.33819000"],["79869.47000000","0.00007000"],["79869.86000000","0.00000000"],["79871.64000000","0.00250000"],["79872.01000000","0.51704000"],["79872.02000000","0.88502000"],["79872.04000000","0.00778000"],["79872.93000000","0.00014000"],["79873.29000000","0.00014000"],["79873.30000000","0.64557000"],["79876.02000000","0.00007000"],["79890.04000000","0.00000000"],["79894.20000000","0.00012000"],["79898.28000000","0.00000000"],["79898.43000000","0.00400000"],["79902.08000000","0.00000000"],["79911.99000000","0.36643000"],["79938.38000000","0.00400000"],["79942.03000000","0.00000000"],["79968.23000000","1.95350000"],["79970.34000000","0.00400000"],["79970.87000000","0.00000000"],["79973.99000000","0.00000000"],["80018.28000000","0.00400000"],["80021.94000000","0.00000000"],["80090.19000000","0.00413000"],["80093.85000000","0.00000000"],["80097.23000000","0.01757000"],["80122.82000000","0.02294000"]]}}}
{"rx_ns": 13866203176100, "frame": {"stream":"btcusdt@depth@100ms","data":{"e":"depthUpdate","E":1787650861414,"s":"BTCUSDT","U":99118585951,"u":99118586018,"b":[["79869.25000000","1.26691000"],["79869.24000000","0.00021000"],["79868.69000000","0.00910000"],["79864.56000000","0.00000000"],["79864.31000000","0.00902000"],["79863.99000000","0.33106000"],["79863.96000000","0.00000000"],["79863.95000000","0.00000000"],["79861.20000000","0.45685000"],["79861.04000000","0.00007000"],["79859.48000000","0.00000000"],["79857.56000000","0.00250000"],["79855.68000000","0.00000000"],["79854.04000000","1.87684000"],["79744.55000000","0.00000000"],["79741.95000000","0.00000000"],["71882.33000000","0.00124000"],["63895.40000000","0.00000000"]],"a":[["79869.26000000","2.39845000"],["79869.29000000","0.27318000"],["79871.64000000","0.00000000"],["79872.01000000","0.51704000"],["79873.29000000","0.00014000"],["79873.52000000","0.00250000"],["79876.02000000","0.00007000"],["79886.00000000","0.02407000"],["79989.98000000","0.00000000"],["79992.66000000","0.00000000"],["79996.83000000","0.00000000"]]}}}
{"rx_ns": 13866296084200, "frame": {"stream":"btcusdt@depth@100ms","data":{"e":"depthUpdate","E":1787650861514,"s":"BTCUSDT","U":99118586019,"u":99118586035,"b":[["79869.25000000","1.26705000"],["79869.24000000","0.00028000"],["79866.80000000","0.00644000"],["79849.25000000","0.02000000"],["79834.53000000","0.33827000"],["79799.63000000","0.02087000"],["79766.32000000","0.02000000"],["79740.51000000","0.00012000"],["63895.40000000","0.00031000"]],"a":[["79882.39000000","0.02000000"],["79891.64000000","0.02200000"],["79901.53000000","0.33799000"],["79902.21000000","0.09160000"],["79908.00000000","0.36196000"]]}}}
{"rx_ns": 13866396083100, "frame": {"stream":"btcusdt@depth@100ms","data":{"e":"depthUpdate","E":1787650861614,"s":"BTCUSDT","U":99118586036,"u":99118586066,"b":[["79869.25000000","1.26712000"],["79868.69000000","0.00917000"],["79867.97000000","0.01864000"],["79867.69000000","0.00007000"],["79866.80000000","0.00651000"],["79865.41000000","0.02219000"],["79850.05000000","0.02000000"],["79849.25000000","0.04000000"],["79767.06000000","0.02000000"],["79766.31000000","0.00000000"],["71882.33000000","0.00156000"],["71882.00000000","0.00020000"],["63895.40000000","0.00000000"]],"a":[["79869.26000000","1.88887000"],["79869.28000000","0.00013000"],["79869.29000000","0.00014000"],["79881.59000000","0.02000000"],["79882.39000000","0.04200000"],["79936.82000000","0.00000000"]]}}}
{"rx_ns": 13866496530100, "frame": {"stream":"btcusdt@depth@100ms","data":{"e":"depthUpdate","E":1787650861714,"s":"BTCUSDT","U":99118586067,"u":99118586082,"b":[["79858.98000000","0.17953000"],["79766.32000000","0.00000000"],["79737.91000000","0.00008000"],["79667.74000000","0.02363000"],["71882.33000000","0.00172000"],["71882.00000000","0.00000000"]],"a":[["79869.26000000","1.88886000"],["79869.29000000","0.00007000"],["79890.85000000","0.00000000"],["79891.64000000","0.00000000"],["79985.92000000","0.00012000"],["79988.61000000","0.00018000"],["80029.84000000","0.00000000"],["80165.72000000","0.02482000"]]}}}
{"rx_ns": 13866598136100, "frame": {"stream":"btcusdt@depth@100ms","data":{"e":"depthUpdate","E":1787650861814,"s":"BTCUSDT","U":99118586083,"u":99118586105,"b":[["79854.05000000","0.02600000"],["79850.05000000","0.04200000"],["79849.61000000","0.02400000"],["79849.21000000","0.02000000"],["79849.20000000","0.02000000"],["79836.29000000","0.00000000"],["79799.63000000","0.00000000"],["79782.64000000","0.02000000"],["79782.24000000","0.02000000"],["79781.31000000","0.02600000"],["79767.12000000","0.02200000"],["79767.06000000","0.00000000"],["79766.19000000","0.02000000"],["71882.33000000","0.00188000"]],"a":[["79877.61000000","0.02000000"],["79881.60000000","0.02000000"],["79882.05000000","0.02000000"],["79882.45000000","0.02000000"],["79882.46000000","0.02000000"],["79886.85000000","0.00000000"],["79891.69000000","0.00000000"]]}}}
{"rx_ns": 13866698762900, "frame": {"stream":"btcusdt@depth@100ms","data":{"e":"depthUpdate","E":1787650861914,"s":"BTCUSDT","U":99118586106,"u":99118586120,"b":[["79867.97000000","0.01871000"],["79867.69000000","0.00581000"],["79867.14000000","0.00007000"],["79867.13000000","0.33812000"],["79866.90000000","0.00202000"],["79866.80000000","0.00014000"],["79861.04000000","0.00000000"],["79799.63000000","0.02087000"],["79737.91000000","0.00000000"],["71882.33000000","0.00204000"]],"a":[["79869.26000000","2.09129000"],["79890.84000000","0.00000000"],["79992.78000000","0.00031000"]]}}}
{"rx_ns": 13866798841700, "frame": {"stream":"btcusdt@depth20","data":{"lastUpdateId":99118586161,"bids":[["79869.25000000","1.26726000"],["79869.24000000","0.00042000"],["79869.06000000","0.00007000"],["79868.69000000","0.00917000"],["79868.33000000","0.00007000"],["79868.29000000","0.00009000"],["79867.98000000","0.00007000"],["79867.97000000","0.01871000"],["79867.69000000","0.00588000"],["79867.14000000","0.00007000"],["79867.13000000","0.33819000"],["79866.90000000","0.00202000"],["79866.80000000","0.00007000"],["79866.79000000","0.05277000"],["79866.77000000","0.00007000"],["79866.76000000","0.00026000"],["79866.70000000","0.00007000"],["79866.69000000","0.02233000"],["79866.57000000","0.00007000"],["79866.31000000","0.00722000"]],"asks":[["79869.26000000","2.09136000"],["79869.27000000","0.00027000"],["79869.28000000","0.00013000"],["79869.29000000","0.00007000"],["79869.30000000","0.05014000"],["79869.34000000","0.00007000"],["79869.35000000","0.05007000"],["79869.43000000","0.00007000"],["79869.45000000","0.00007000"],["79869.46000000","0.33819000"],["79869.47000000","0.00007000"],["79870.08000000","0.00014000"],["79870.63000000","0.00007000"],["79870.64000000","0.00007000"],["79870.65000000","0.00007000"],["79870.73000000","0.00007000"],["79870.74000000","0.55571000"],["79872.00000000","0.00007000"],["79872.01000000","0.51704000"],["79872.02000000","0.88502000"]]}}}
{"rx_ns": 13866798962000, "frame": {"stream":"btcusdt@depth@100ms","data":{"e":"depthUpdate","E":1787650862015,"s":"BTCUSDT","U":99118586121,"u":99118586161,"b":[["79869.25000000","1.26726000"],["79869.24000000","0.00042000"],["79867.97000000","0.01871000"],["79867.69000000","0.00588000"],["79867.13000000","0.33819000"],["79866.80000000","0.00007000"],["79865.54000000","1.04939000"],["79853.28000000","0.12522000"],["79850.86000000","0.02200000"],["79848.12000000","0.00626000"],["79848.06000000","0.31459000"],["79845.30000000","0.62621000"],["79845.29000000","0.12524000"],["79844.12000000","0.00000000"],["79842.78000000","0.00000000"],["79842.77000000","0.00000000"],["79837.88000000","0.00000000"],["79836.72000000","0.00000000"],["79806.52000000","0.00007000"],["79805.12000000","0.00007000"],["79799.63000000","0.00000000"],["79783.86000000","0.02200000"],["79781.31000000","0.00000000"],["79733.73000000","0.00018000"],["71882.33000000","0.00204000"],["63895.40000000","0.00031000"]],"a":[["79869.26000000","2.09136000"],["79872.06000000","0.01547000"],["79880.80000000","0.02000000"],["79885.23000000","0.12517000"],["79887.32000000","0.30124000"],["79888.74000000","0.00000000"],["79888.94000000","0.00000000"],["79890.03000000","0.00000000"],["79891.30000000","0.00000000"],["79891.70000000","0.00000000"]]}}}
{"rx_ns": 13866895952200, "frame": {"stream":"btcusdt@depth@100ms","data":{"e":"depthUpdate","E":1787650862114,"s":"BTCUSDT","U":99118586162,"u":99118586170,"b":[["79866.89000000","0.00007000"],["79840.00000000","1.02302000"],["79766.19000000","0.00000000"],["71882.33000000","0.00220000"]],"a":[["79869.44000000","0.00007000"],["79869.45000000","0.26705000"]]}}}
{"rx_ns": 13866996111500, "frame": {"stream":"btcusdt@depth@100ms","data":{"e":"depthUpdate","E":1787650862214,"s":"BTCUSDT","U":99118586171,"u":99118586187,"b":[["79869.25000000","1.26736000"],["79867.97000000","0.01878000"],["79865.19000000","0.00014000"],["79861.27000000","0.00007000"],["79861.21000000","0.00000000"],["79729.69000000","0.00008000"],["78671.21000000","0.00030000"],["63895.40000000","0.00000000"]],"a":[["79869.35000000","0.05007000"],["79869.45000000","0.26712000"],["79872.06000000","0.01540000"],["79912.03000000","0.62583000"],["80588.07000000","0.00010000"],["81067.30000000","0.00030000"]]}}}
{"rx_ns": 13867096399400, "frame": {"stream":"btcusdt@depth@100ms","data":{"e":"depthUpdate","E":1787650862314,"s":"BTCUSDT","U":99118586188,"u":99118586215,"b":[["79869.25000000","1.26756000"],["79869.24000000","0.00063000"],["79867.69000000","0.00595000"],["79867.13000000","0.33826000"],["79847.50000000","0.97749000"],["79767.12000000","0.00000000"],["71882.33000000","0.00236000"],["63899.00000000","0.13788000"]],"a":[["79869.26000000","1.88872000"],["79873.30000000","0.57045000"],["79873.47000000","0.12528000"],["79905.00000000","0.70000000"],["79907.59000000","0.00400000"],["79909.82000000","0.00000000"],["79911.99000000","0.50640000"],["79939.90000000","0.89409000"]]}}}
{"rx_ns": 13867199254400, "frame": {"stream":"btcusdt@depth@100ms","data":{"e":"depthUpdate","E":1787650862414,"s":"BTCUSDT","U":99118586216,"u":99118586270,"b":[["79869.25000000","1.26735000"],["79869.24000000","0.00035000"],["79868.69000000","0.00014000"],["79868.44000000","0.00940000"],["79867.97000000","0.02537000"],["79867.69000000","0.00021000"],["79866.90000000","0.00000000"],["79864.29000000","0.03231000"],["79864.01000000","0.00020000"],["79863.00000000","0.00626000"],["79862.58000000","0.00626000"],["79862.05000000","0.00000000"],["79861.99000000","0.04970000"],["79855.08000000","0.00000000"],["79854.04000000","1.87684000"],["79853.00000000","0.00000000"],["79802.63000000","0.00000000"],["79800.11000000","0.00312000"],["79729.69000000","0.00000000"],["79722.01000000","0.00000000"],["79721.31000000","0.00125000"],["79720.21000000","0.00125000"],["79714.57000000","0.00000000"],["71882.33000000","0.00236000"]],"a":[["79869.26000000","1.65423000"],["79869.35000000","0.05014000"],["79869.45000000","0.00014000"],["79872.02000000","0.88187000"],["79872.06000000","0.00000000"],["79872.89000000","0.00000000"],["79873.32000000","0.01293000"],["79873.47000000","0.00000000"],["79874.00000000","0.02414000"],["79874.08000000","0.00000000"],["79874.38000000","0.00000000"],["79877.80000000","0.00000000"],["79878.29000000","0.00626000"],["79886.00000000","0.02407000"],["79887.32000000","0.00000000"],["79888.40000000","0.00626000"],["79889.06000000","0.36593000"],["79935.99000000","0.00319000"],["79937.72000000","0.00312000"],["79939.98000000","0.00000000"],["79940.23000000","0.00000000"],["80016.23000000","0.00125000"],["80017.63000000","0.00125000"],["80019.98000000","0.00000000"],["80021.12000000","0.00000000"]]}}}
{"rx_ns": 13867297096800, "frame": {"stream":"btcusdt@depth@100ms","data":{"e":"depthUpdate","E":1787650862514,"s":"BTCUSDT","U":99118586271,"u":99118586332,"b":[["79869.25000000","1.59992000"],["79869.24000000","0.00028000"],["79868.88000000","0.00712000"],["79868.69000000","0.00000000"],["79868.44000000","0.00954000"],["79867.97000000","0.02537000"],["79867.69000000","0.00007000"],["79865.54000000","1.04946000"],["79863.99000000","0.33113000"],["79862.85000000","0.00725000"],["79861.27000000","0.00000000"],["79859.07000000","0.00250000"],["79857.56000000","0.00000000"],["79855.41000000","0.37576000"],["79850.08000000","0.33821000"],["79837.04000000","0.00000000"],["79834.53000000","0.00000000"],["79831.46000000","1.24040000"],["79797.95000000","0.00000000"],["79553.10000000","0.00000000"],["71882.33000000","0.00252000"],["63895.40000000","0.00031000"]],"a":[["79869.26000000","1.59023000"],["79869.35000000","0.05014000"],["79869.44000000","0.00000000"],["79869.45000000","0.00007000"],["79872.04000000","0.00778000"],["79872.38000000","0.04775000"],["79873.32000000","0.01286000"],["79873.52000000","0.00000000"],["79875.04000000","0.00250000"],["79878.29000000","0.00000000"],["79879.93000000","0.00626000"],["79902.25000000","0.33799000"]]}}}
{"rx_ns": 13867396987000, "frame": {"stream":"btcusdt@depth@100ms","data":{"e":"depthUpdate","E":1787650862614,"s":"BTCUSDT","U":99118586333,"u":99118586352,"b":[["79869.25000000","1.60019000"],["79869.24000000","0.00041000"],["79869.23000000","0.00013000"],["79868.88000000","0.00007000"],["79865.54000000","1.04939000"],["71882.33000000","0.00252000"],["63895.40000000","0.00000000"]],"a":[["79873.28000000","0.00000000"],["79936.82000000","0.02200000"]]}}}
{"rx_ns": 13867495743300, "frame": {"stream":"btcusdt@depth@100ms","data":{"e":"depthUpdate","E":1787650862714,"s":"BTCUSDT","U":99118586353,"u":99118586362,"b":[["79868.88000000","0.00000000"],["79865.54000000","1.04946000"],["79799.63000000","0.00000000"],["71882.33000000","0.00268000"],["71882.00000000","0.00000000"]],"a":[["82000.00000000","121.90952000"]]}}}
{"rx_ns": 13867596871100, "frame": {"stream":"btcusdt@depth@100ms","data":{"e":"depthUpdate","E":1787650862814,"s":"BTCUSDT","U":99118586363,"u":99118586366,"b":[],"a":[["79874.28000000","0.00014000"],["79874.29000000","0.18509000"],["79902.21000000","0.00000000"],["79907.93000000","0.09298000"]]}}}
{"rx_ns": 13867695616100, "frame": {"stream":"btcusdt@depth@100ms","data":{"e":"depthUpdate","E":1787650862914,"s":"BTCUSDT","U":99118586367,"u":99118586388,"b":[["79869.25000000","1.60067000"],["79858.44000000","0.00000000"],["79737.59000000","0.01961000"],["79732.90000000","0.00000000"],["71882.33000000","0.00284000"]],"a":[["79873.57000000","0.00000000"],["79873.64000000","0.00000000"],["79873.80000000","0.00000000"],["79873.87000000","0.00000000"],["79873.88000000","0.00000000"],["79874.09000000","0.00000000"],["79874.28000000","0.00007000"]]}}}
{"rx_ns": 13867803754000, "frame": {"stream":"btcusdt@depth20","data":{"lastUpdateId":99118588347,"bids":[["79882.07000000","2.99034000"],["79882.06000000","0.00034000"],["79882.05000000","0.00020000"],["79882.04000000","0.68916000"],["79881.77000000","0.00917000"],["79881.17000000","0.00007000"],["79880.67000000","0.00014000"],["79880.58000000","0.00183000"],["79880.55000000","0.00007000"],["79880.22000000","0.00704000"],["79879.98000000","0.00007000"],["79879.97000000","0.01871000"],["79879.96000000","0.00021000"],["79879.87000000","0.00007000"],["79879.43000000","0.05279000"],["79879.10000000","0.00014000"],["79878.07000000","0.00007000"],["79877.86000000","0.11282000"],["79877.85000000","0.12526000"],["79877.45000000","0.00007000"]],"asks":[["79882.08000000","0.21924000"],["79882.09000000","0.00049000"],["79882.88000000","0.00346000"],["79883.28000000","0.00007000"],["79883.29000000","0.00007000"],["79883.51000000","0.00007000"],["79883.52000000","0.00007000"],["79883.53000000","0.00028000"],["79883.57000000","0.00007000"],["79883.95000000","0.00007000"],["79884.27000000","0.00007000"],["79884.28000000","0.00007000"],["79884.36000000","0.00007000"],["79884.37000000","0.02014000"],["79884.38000000","0.00007000"],["79884.44000000","0.00007000"],["79884.45000000","0.00007000"],["79884.54000000","0.00007000"],["79884.57000000","0.00007000"],["79884.93000000","0.00008000"]]}}}
{"rx_ns": 13867803889700, "frame": {"stream":"btcusdt@depth@100ms","data":{"e":"depthUpdate","E":1787650863014,"s":"BTCUSDT","U":99118586389,"u":99118588347,"b":[["79883.10000000","0.00000000"],["79882.07000000","2.99034000"],["79882.06000000","0.00034000"],["79882.05000000","0.00020000"],["79882.04000000","0.68916000"],["79882.03000000","0.00000000"],["79882.02000000","0.00000000"],["79881.99000000","0.00000000"],["79881.79000000","0.00000000"],["79881.77000000","0.00917000"],["79881.59000000","0.00000000"],["79881.58000000","0.00000000"],["79881.35000000","0.00000000"],["79881.28000000","0.00000000"],["79881.17000000","0.00007000"],["79880.90000000","0.00000000"],["79880.80000000","0.00000000"],["79880.79000000","0.00000000"],["79880.67000000","0.00014000"],["79880.58000000","0.00183000"],["79880.55000000","0.00007000"],["79880.22000000","0.00704000"],["79880.14000000","0.00000000"],["79880.02000000","0.00000000"],["79879.99000000","0.00000000"],["79879.98000000","0.00007000"],["79879.97000000","0.01871000"],["79879.96000000","0.00021000"],["79879.93000000","0.00000000"],["79879.87000000","0.00007000"],["79879.43000000","0.05279000"],["79879.31000000","0.00000000"],["79879.11000000","0.00000000"],["79879.10000000","0.00014000"],["79878.69000000","0.00000000"],["79878.07000000","0.00007000"],["79877.99000000","0.00000000"],["79877.86000000","0.11282000"],["79877.85000000","0.12526000"],["79877.60000000","0.00000000"],["79877.46000000","0.00000000"],["79877.45000000","0.00007000"],["79876.91000000","0.00000000"],["79876.90000000","0.00014000"],["79876.83000000","0.00007000"],["79876.81000000","0.00000000"],["79876.80000000","0.00014000"],["79876.72000000","0.00000000"],["79876.54000000","0.03224000"],["79876.29000000","0.00162000"],["79876.22000000","0.00701000"],["79876.21000000","0.00007000"],["79876.14000000","0.00014000"],["79876.06000000","0.00013000"],["79876.02000000","0.00021000"],["79876.01000000","0.00000000"],["79876.00000000","0.00007000"],["79875.99000000","0.00014000"],["79875.88000000","0.00000000"],["79875.87000000","0.00047000"],["79875.25000000","0.00007000"],["79875.01000000","0.00000000"],["79874.63000000","0.00007000"],["79874.59000000","0.00000000"],["79874.53000000","0.00000000"],["79874.28000000","0.00000000"],["79874.27000000","0.00000000"],["79874.14000000","0.00000000"],["79874.08000000","0.00008000"],["79874.01000000","0.00007000"],["79873.99000000","0.00000000"],["79873.89000000","0.15007000"],["79873.78000000","0.00944000"],["79873.39000000","0.00007000"],["79873.31000000","0.00000000"],["79873.29000000","0.00007000"],["79873.28000000","0.00000000"],["79873.04000000","0.00000000"],["79872.99000000","0.00000000"],["79872.95000000","0.00007000"],["79872.93000000","0.00014000"],["79872.92000000","0.00000000"],["79872.77000000","0.00007000"],["79872.56000000","0.00000000"],["79872.49000000","0.00000000"],["79872.38000000","1.87677000"],["79872.37000000","0.00007000"],["79872.15000000","0.00000000"],["79872.08000000","0.00000000"],["79872.04000000","1.17382000"],["79872.03000000","2.60440000"],["79872.02000000","0.00000000"],["79872.01000000","1.04939000"],["79872.00000000","0.00007000"],["79871.99000000","0.00000000"],["79871.68000000","0.00400000"],["79871.41000000","0.00000000"],["79871.01000000","0.08576000"],["79870.87000000","0.00007000"],["79870.79000000","0.00000000"],["79870.74000000","0.07500000"],["79870.73000000","0.54793000"],["79870.72000000","0.00000000"],["79870.71000000","0.00000000"],["79870.69000000","0.00007000"],["79870.64000000","0.00000000"],["79870.63000000","0.00000000"],["79870.62000000","0.00007000"],["79870.55000000","0.00007000"],["79870.21000000","0.33812000"],["79870.11000000","0.00000000"],["79870.07000000","0.18341000"],["79870.04000000","0.00000000"],["79869.88000000","0.00000000"],["79869.60000000","0.00010000"],["79869.49000000","0.00000000"],["79869.46000000","0.00000000"],["79869.45000000","0.84102000"],["79869.44000000","0.00400000"],["79869.42000000","0.00000000"],["79869.38000000","0.00000000"],["79869.34000000","0.00000000"],["79869.33000000","0.00000000"],["79869.30000000","0.00000000"],["79869.29000000","0.70909000"],["79869.28000000","0.00000000"],["79869.27000000","0.00000000"],["79869.26000000","0.30709000"],["79869.25000000","0.25522000"],["79869.24000000","0.00000000"],["79869.23000000","0.00000000"],["79869.07000000","0.00000000"],["79869.06000000","0.00014000"],["79868.90000000","0.00703000"],["79868.79000000","0.00008000"],["79868.63000000","0.00000000"],["79868.44000000","0.00940000"],["79868.33000000","0.00000000"],["79868.10000000","0.00007000"],["79868.04000000","0.00007000"],["79868.01000000","0.00000000"],["79867.98000000","0.00599000"],["79867.97000000","0.01843000"],["79867.88000000","0.00000000"],["79867.85000000","0.00000000"],["79867.70000000","0.00000000"],["79867.49000000","0.00007000"],["79867.39000000","0.00000000"],["79867.21000000","0.00626000"],["79867.20000000","0.00400000"],["79867.14000000","0.00000000"],["79867.13000000","0.00000000"],["79866.86000000","0.00007000"],["79866.80000000","0.00000000"],["79866.79000000","0.00000000"],["79866.77000000","0.00000000"],["79866.70000000","0.00000000"],["79866.69000000","0.02212000"],["79866.57000000","0.00000000"],["79866.31000000","0.00708000"],["79866.19000000","0.00000000"],["79866.16000000","0.00000000"],["79866.15000000","0.00000000"],["79866.06000000","0.00008000"],["79865.92000000","0.00007000"],["79865.57000000","2.04664000"],["79865.56000000","1.87677000"],["79865.55000000","0.00000000"],["79865.54000000","1.04939000"],["79865.53000000","0.00000000"],["79865.41000000","0.02212000"],["79864.99000000","0.00000000"],["79864.96000000","0.00400000"],["79864.92000000","0.00000000"],["79864.91000000","0.00000000"],["79864.78000000","0.00000000"],["79864.77000000","0.12521000"],["79864.74000000","0.00000000"],["79864.32000000","0.00000000"],["79864.29000000","0.03224000"],["79864.11000000","0.00007000"],["79864.04000000","0.00000000"],["79864.02000000","0.37572000"],["79864.01000000","0.00000000"],["79864.00000000","0.02407000"],["79863.99000000","0.33092000"],["79863.87000000","0.00000000"],["79863.13000000","0.09466000"],["79863.06000000","0.00000000"],["79863.00000000","0.00000000"],["79862.85000000","0.00718000"],["79862.70000000","0.00000000"],["79862.58000000","0.00000000"],["79862.44000000","0.00000000"],["79862.33000000","0.02275000"],["79862.07000000","0.00008000"],["79862.05000000","0.00007000"],["79862.01000000","0.00000000"],["79862.00000000","0.02400000"],["79861.99000000","0.04956000"],["79861.47000000","0.00000000"],["79861.29000000","0.00000000"],["79861.27000000","0.00000000"],["79861.13000000","0.10370000"],["79861.10000000","0.00000000"],["79860.73000000","0.00000000"],["79860.34000000","0.00000000"],["79860.31000000","0.00000000"],["79860.29000000","0.00914000"],["79860.07000000","0.00000000"],["79859.94000000","0.00000000"],["79859.20000000","0.00000000"],["79859.07000000","0.00000000"],["79858.64000000","0.00000000"],["79858.33000000","0.00000000"],["79858.17000000","0.00125000"],["79858.08000000","0.00008000"],["79857.91000000","0.00000000"],["79857.77000000","0.00000000"],["79857.54000000","0.00000000"],["79857.32000000","0.00000000"],["79856.92000000","0.00000000"],["79856.85000000","0.00000000"],["79856.59000000","0.00000000"],["79856.49000000","0.00000000"],["79856.32000000","0.33818000"],["79856.10000000","0.00000000"],["79856.01000000","0.42950000"],["79855.64000000","0.00911000"],["79855.39000000","0.00000000"],["79854.08000000","0.00008000"],["79854.06000000","0.00000000"],["79854.04000000","1.87677000"],["79853.28000000","0.00000000"],["79852.10000000","0.00000000"],["79852.06000000","0.00007000"],["79851.45000000","0.00000000"],["79850.93000000","0.00000000"],["79850.43000000","0.62631000"],["79850.28000000","0.09519000"],["79850.17000000","0.00000000"],["79850.09000000","0.00008000"],["79850.08000000","0.00000000"],["79850.00000000","0.12343000"],["79848.93000000","0.20250000"],["79848.82000000","0.00000000"],["79848.12000000","0.00000000"],["79848.11000000","0.00000000"],["79848.06000000","0.00000000"],["79848.00000000","0.02418000"],["79846.52000000","0.00000000"],["79846.33000000","0.00000000"],["79846.09000000","0.00008000"],["79845.85000000","0.00000000"],["79845.30000000","0.00000000"],["79845.29000000","0.00000000"],["79844.11000000","0.00000000"],["79842.26000000","0.50985000"],["79842.10000000","0.00008000"],["79841.97000000","0.00000000"],["79841.80000000","0.00000000"],["79841.06000000","0.64136000"],["79840.45000000","0.00000000"],["79840.12000000","0.62639000"],["79840.02000000","0.00000000"],["79839.90000000","0.00000000"],["79838.16000000","0.34822000"],["79838.10000000","0.00000000"],["79836.23000000","0.00000000"],["79836.13000000","0.00000000"],["79836.08000000","0.00007000"],["79834.23000000","0.00000000"],["79834.20000000","0.00000000"],["79832.13000000","0.00000000"],["79831.85000000","0.00000000"],["79831.46000000","0.00000000"],["79830.36000000","0.00000000"],["79829.82000000","0.00021000"],["79829.54000000","0.00000000"],["79828.90000000","0.00000000"],["79827.48000000","0.82239000"],["79826.49000000","0.00000000"],["79824.60000000","0.00000000"],["79824.07000000","0.00000000"],["79821.80000000","0.00335000"],["79820.49000000","0.00000000"],["79820.10000000","0.00007000"],["79816.90000000","0.00000000"],["79815.32000000","0.00000000"],["79813.90000000","0.82253000"],["79812.75000000","0.00000000"],["79810.67000000","0.00000000"],["79810.38000000","0.00000000"],["79810.30000000","0.00312000"],["79807.96000000","0.46836000"],["79805.12000000","0.00000000"],["79804.12000000","0.00007000"],["79802.16000000","0.00008000"],["79800.10000000","0.00000000"],["79799.63000000","0.02087000"],["79797.90000000","0.00007000"],["79797.44000000","0.00000000"],["79792.20000000","0.00000000"],["79791.21000000","0.00000000"],["79790.84000000","0.00000000"],["79788.14000000","0.00007000"],["79785.69000000","0.00000000"],["79780.81000000","0.62585000"],["79778.17000000","0.00000000"],["79772.16000000","0.00007000"],["79768.08000000","0.00000000"],["79756.18000000","0.00007000"],["79755.81000000","0.00000000"],["79754.18000000","0.00000000"],["79752.12000000","0.00000000"],["79750.01000000","0.00000000"],["79749.46000000","0.00000000"],["79741.76000000","0.00000000"],["79741.47000000","0.00000000"],["79740.20000000","0.00007000"],["79738.21000000","0.00000000"],["79736.16000000","0.00000000"],["79732.89000000","1.50023000"],["79724.22000000","0.00007000"],["79722.28000000","0.00008000"],["79722.24000000","0.00000000"],["79720.20000000","0.00390000"],["79712.33000000","0.00000000"],["79708.24000000","0.00007000"],["79706.27000000","0.00000000"],["79704.26000000","0.00000000"],["79704.24000000","0.00000000"],["79692.26000000","0.00007000"],["79690.30000000","0.00000000"],["79688.28000000","0.00000000"],["79676.28000000","0.00007000"],["79674.33000000","0.00000000"],["79666.65000000","0.00000000"],["79660.30000000","0.00007000"],["79658.36000000","0.00000000"],["79644.32000000","0.00007000"],["79642.39000000","0.00008000"],["79638.61000000","0.00007000"],["79632.45000000","0.00000000"],["79626.42000000","0.00000000"],["79596.50000000","0.00000000"],["79567.51000000","0.00000000"],["79562.51000000","0.00008000"],["79555.65000000","0.00028000"],["79552.58000000","0.00000000"],["79543.69000000","0.00000000"],["79482.63000000","0.00008000"],["79480.71000000","0.00000000"],["79472.71000000","0.00000000"],["79402.75000000","0.00008000"],["79392.84000000","0.00000000"],["79322.87000000","0.00008000"],["79312.97000000","0.00000000"],["79242.98000000","0.00008000"],["79233.09000000","0.00000000"],["78671.21000000","0.00000000"],["71884.87000000","0.00000000"],["71884.86000000","0.00008000"],["71882.43000000","0.00000000"],["71882.33000000","0.00028000"],["63905.66000000","0.00031000"],["63866.95000000","0.00000000"]],"a":[["79869.26000000","0.00000000"],["79869.27000000","0.00000000"],["79869.28000000","0.00000000"],["79869.29000000","0.00000000"],["79869.30000000","0.00000000"],["79869.34000000","0.00000000"],["79869.35000000","0.00000000"],["79869.43000000","0.00000000"],["79869.45000000","0.00000000"],["79869.46000000","0.00000000"],["79869.47000000","0.00000000"],["79870.08000000","0.00000000"],["79870.63000000","0.00000000"],["79870.64000000","0.00000000"],["79870.65000000","0.00000000"],["79870.73000000","0.00000000"],["79870.74000000","0.00000000"],["79872.00000000","0.00000000"],["79872.01000000","0.00000000"],["79872.02000000","0.00000000"],["79872.04000000","0.00000000"],["79872.05000000","0.00000000"],["79872.09000000","0.00000000"],["79872.37000000","0.00000000"],["79872.38000000","0.00000000"],["79872.44000000","0.00000000"],["79872.50000000","0.00000000"],["79872.57000000","0.00000000"],["79872.93000000","0.00000000"],["79872.94000000","0.00000000"],["79873.00000000","0.00000000"],["79873.05000000","0.00000000"],["79873.28000000","0.00000000"],["79873.29000000","0.00000000"],["79873.30000000","0.00000000"],["79873.32000000","0.00000000"],["79873.67000000","0.00000000"],["79873.68000000","0.00000000"],["79874.00000000","0.00000000"],["79874.15000000","0.00000000"],["79874.28000000","0.00000000"],["79874.29000000","0.00000000"],["79874.54000000","0.00000000"],["79874.60000000","0.00000000"],["79875.02000000","0.00000000"],["79875.04000000","0.00000000"],["79875.14000000","0.00000000"],["79875.88000000","0.00000000"],["79876.00000000","0.00000000"],["79876.02000000","0.00000000"],["79876.03000000","0.00000000"],["79876.15000000","0.00000000"],["79876.73000000","0.00000000"],["79876.80000000","0.00000000"],["79876.86000000","0.00000000"],["79876.91000000","0.00000000"],["79877.09000000","0.00000000"],["79877.56000000","0.00000000"],["79877.61000000","0.00000000"],["79877.81000000","0.00000000"],["79877.99000000","0.00000000"],["79878.00000000","0.00000000"],["79878.10000000","0.00000000"],["79878.15000000","0.00000000"],["79878.30000000","0.00000000"],["79878.48000000","0.00000000"],["79878.67000000","0.00000000"],["79878.68000000","0.00000000"],["79878.73000000","0.00000000"],["79878.88000000","0.00000000"],["79879.10000000","0.00000000"],["79879.11000000","0.00000000"],["79879.20000000","0.00000000"],["79879.23000000","0.00000000"],["79879.93000000","0.00000000"],["79879.94000000","0.00000000"],["79879.96000000","0.00000000"],["79879.97000000","0.00000000"],["79880.00000000","0.00000000"],["79880.14000000","0.00000000"],["79880.32000000","0.00000000"],["79880.36000000","0.00000000"],["79880.67000000","0.00000000"],["79880.80000000","0.00000000"],["79880.96000000","0.00000000"],["79881.23000000","0.00000000"],["79881.25000000","0.00000000"],["79881.29000000","0.00000000"],["79881.39000000","0.00000000"],["79881.44000000","0.00000000"],["79881.59000000","0.00000000"],["79881.60000000","0.00000000"],["79881.94000000","0.00000000"],["79882.00000000","0.00000000"],["79882.05000000","0.00000000"],["79882.08000000","0.21924000"],["79882.09000000","0.00049000"],["79882.28000000","0.00000000"],["79882.38000000","0.00000000"],["79882.39000000","0.00000000"],["79882.45000000","0.00000000"],["79882.46000000","0.00000000"],["79882.63000000","0.00000000"],["79882.74000000","0.00000000"],["79882.87000000","0.00000000"],["79882.88000000","0.00346000"],["79882.92000000","0.00000000"],["79883.05000000","0.00000000"],["79883.09000000","0.00000000"],["79883.13000000","0.00000000"],["79883.28000000","0.00007000"],["79883.29000000","0.00007000"],["79883.32000000","0.00000000"],["79883.42000000","0.00000000"],["79883.51000000","0.00007000"],["79883.52000000","0.00007000"],["79883.53000000","0.00028000"],["79883.54000000","0.00000000"],["79883.57000000","0.00007000"],["79883.60000000","0.00000000"],["79883.87000000","0.00000000"],["79883.95000000","0.00007000"],["79883.98000000","0.00000000"],["79884.00000000","0.00000000"],["79884.02000000","0.00000000"],["79884.03000000","0.00000000"],["79884.27000000","0.00007000"],["79884.28000000","0.00007000"],["79884.36000000","0.00007000"],["79884.37000000","0.02014000"],["79884.38000000","0.00007000"],["79884.44000000","0.00007000"],["79884.45000000","0.00007000"],["79884.48000000","0.00000000"],["79884.50000000","0.00000000"],["79884.54000000","0.00007000"],["79884.56000000","0.00000000"],["79884.57000000","0.00007000"],["79885.02000000","0.04737000"],["79885.03000000","0.00000000"],["79885.18000000","0.00000000"],["79885.23000000","0.00000000"],["79886.00000000","0.02407000"],["79886.17000000","0.00000000"],["79886.29000000","0.00000000"],["79886.30000000","0.00000000"],["79886.60000000","0.00000000"],["79886.74000000","0.00014000"],["79886.96000000","0.00000000"],["79887.17000000","0.00000000"],["79887.32000000","0.00000000"],["79887.33000000","0.00007000"],["79887.66000000","0.06318000"],["79887.67000000","0.00000000"],["79887.96000000","0.00000000"],["79887.99000000","0.06325000"],["79888.00000000","0.10849000"],["79888.40000000","0.00007000"],["79888.41000000","0.00007000"],["79888.46000000","0.00007000"],["79888.97000000","0.00007000"],["79889.05000000","0.00000000"],["79889.06000000","0.00007000"],["79889.07000000","0.00007000"],["79889.29000000","0.00007000"],["79889.31000000","0.00000000"],["79889.36000000","0.00000000"],["79889.48000000","0.00000000"],["79889.73000000","0.00000000"],["79889.74000000","0.00007000"],["79890.00000000","0.02414000"],["79890.07000000","0.20258000"],["79890.60000000","0.00000000"],["79890.68000000","0.00000000"],["79890.98000000","0.00000000"],["79891.08000000","0.00000000"],["79891.28000000","0.00000000"],["79891.41000000","0.00007000"],["79891.51000000","0.00000000"],["79891.86000000","0.00000000"],["79892.27000000","0.00007000"],["79892.28000000","0.00007000"],["79892.35000000","0.00007000"],["79892.67000000","0.00000000"],["79892.68000000","0.00007000"],["79892.79000000","0.00000000"],["79892.80000000","0.00007000"],["79892.81000000","0.00112000"],["79893.31000000","0.00714000"],["79893.36000000","0.00000000"],["79893.41000000","0.00000000"],["79893.70000000","0.00000000"],["79893.72000000","0.00000000"],["79893.86000000","0.06318000"],["79893.93000000","0.39085000"],["79893.94000000","0.00000000"],["79893.95000000","0.00000000"],["79893.96000000","0.00000000"],["79894.48000000","0.00000000"],["79894.58000000","0.00000000"],["79894.59000000","0.00000000"],["79895.08000000","0.15000000"],["79895.32000000","0.00000000"],["79895.47000000","0.00007000"],["79895.67000000","0.00000000"],["79895.75000000","0.00000000"],["79895.76000000","0.00000000"],["79895.85000000","0.00000000"],["79896.15000000","0.00007000"],["79896.21000000","0.00000000"],["79896.40000000","0.36586000"],["79896.52000000","0.00000000"],["79896.53000000","0.96393000"],["79897.31000000","0.00718000"],["79897.35000000","0.00000000"],["79897.85000000","0.00626000"],["79897.91000000","0.00000000"],["79898.39000000","0.00000000"],["79898.58000000","0.00000000"],["79898.60000000","0.00000000"],["79898.67000000","0.00000000"],["79898.82000000","0.00007000"],["79898.89000000","0.02000000"],["79898.90000000","1.04939000"],["79898.91000000","0.00000000"],["79899.51000000","0.00008000"],["79899.84000000","0.00000000"],["79899.98000000","1.59266000"],["79899.99000000","0.00000000"],["79900.00000000","1.12062000"],["79900.02000000","0.00007000"],["79900.24000000","0.00000000"],["79900.26000000","0.00007000"],["79901.31000000","0.00704000"],["79901.52000000","0.00000000"],["79901.53000000","0.00000000"],["79901.86000000","0.00000000"],["79902.05000000","0.00008000"],["79902.25000000","0.00000000"],["79902.40000000","0.00000000"],["79902.58000000","0.00000000"],["79902.77000000","0.00000000"],["79902.78000000","0.00000000"],["79903.01000000","0.19019000"],["79903.02000000","0.00000000"],["79903.04000000","1.04939000"],["79903.63000000","1.87677000"],["79903.76000000","0.57893000"],["79903.77000000","0.00000000"],["79903.84000000","0.00000000"],["79903.89000000","0.00007000"],["79904.43000000","0.00000000"],["79904.44000000","0.00000000"],["79904.85000000","0.36586000"],["79904.99000000","0.00000000"],["79905.31000000","0.00720000"],["79905.79000000","0.00000000"],["79905.80000000","0.00000000"],["79905.97000000","0.00626000"],["79906.04000000","0.00133000"],["79906.57000000","0.00000000"],["79907.30000000","0.42950000"],["79907.65000000","0.28879000"],["79907.66000000","1.04939000"],["79907.76000000","0.00007000"],["79907.83000000","0.00000000"],["79907.92000000","0.00000000"],["79907.93000000","0.00000000"],["79908.48000000","0.00000000"],["79908.53000000","1.87677000"],["79908.54000000","0.45372000"],["79908.55000000","0.00000000"],["79908.79000000","0.20250000"],["79909.01000000","0.00000000"],["79909.85000000","0.00000000"],["79910.00000000","0.11786000"],["79910.04000000","0.00008000"],["79910.13000000","0.00000000"],["79910.16000000","0.00000000"],["79910.30000000","0.33795000"],["79910.57000000","0.00000000"],["79911.00000000","0.00000000"],["79911.63000000","0.00007000"],["79911.82000000","0.00000000"],["79911.97000000","0.62616000"],["79911.98000000","1.04946000"],["79912.00000000","0.72973000"],["79912.03000000","0.00000000"],["79912.72000000","0.00000000"],["79913.55000000","0.36586000"],["79913.70000000","1.87677000"],["79914.03000000","0.00008000"],["79914.24000000","0.00400000"],["79914.96000000","0.09568000"],["79915.24000000","0.10000000"],["79915.50000000","0.00007000"],["79915.82000000","0.00000000"],["79916.00000000","0.02400000"],["79916.06000000","0.33793000"],["79917.79000000","0.62579000"],["79917.89000000","1.04939000"],["79917.90000000","0.00000000"],["79917.91000000","0.00000000"],["79917.92000000","0.00000000"],["79918.03000000","0.00008000"],["79918.60000000","0.00000000"],["79919.37000000","0.00007000"],["79920.25000000","0.00000000"],["79920.78000000","0.00000000"],["79922.02000000","0.00008000"],["79922.37000000","1.04939000"],["79922.69000000","0.00000000"],["79923.00000000","0.01000000"],["79923.24000000","0.00000000"],["79923.29000000","1.87677000"],["79925.53000000","0.00000000"],["79926.29000000","0.00000000"],["79926.73000000","0.36586000"],["79928.14000000","1.04939000"],["79928.15000000","0.89533000"],["79928.16000000","0.00000000"],["79928.18000000","0.00000000"],["79929.00000000","0.04480000"],["79931.93000000","0.00000000"],["79931.99000000","0.00000000"],["79932.76000000","1.04939000"],["79932.88000000","1.89677000"],["79933.19000000","0.00000000"],["79933.71000000","0.00000000"],["79935.45000000","0.00000000"],["79935.99000000","0.00007000"],["79937.72000000","0.00000000"],["79937.73000000","0.00000000"],["79937.74000000","0.00000000"],["79937.76000000","0.00000000"],["79941.11000000","0.36612000"],["79941.70000000","2.92616000"],["79943.59000000","0.01662000"],["79943.69000000","0.00000000"],["79947.34000000","0.00000000"],["79947.35000000","0.00000000"],["79949.98000000","0.00310000"],["79950.71000000","0.01270000"],["79951.61000000","0.00309000"],["79951.62000000","1.11655000"],["79951.63000000","0.00000000"],["79953.42000000","0.00000000"],["79953.92000000","1.23850000"],["79954.41000000","0.36586000"],["79954.42000000","0.00000000"],["79959.89000000","0.00000000"],["79961.96000000","0.00008000"],["79964.64000000","0.00000000"],["79965.53000000","0.00000000"],["79967.83000000","0.36586000"],["79967.84000000","0.98089000"],["79968.23000000","0.00000000"],["79968.48000000","0.00000000"],["79972.97000000","0.81588000"],["79973.65000000","1.87677000"],["79975.89000000","0.00000000"],["79976.70000000","0.00000000"],["79977.76000000","0.00000000"],["79978.19000000","0.00000000"],["79979.88000000","1.04939000"],["79982.21000000","0.36586000"],["79982.32000000","0.00007000"],["79983.24000000","1.87677000"],["79990.27000000","1.04939000"],["79991.08000000","0.00000000"],["79992.83000000","1.87677000"],["79993.73000000","0.00000000"],["79996.59000000","0.36586000"],["79999.89000000","1.04939000"],["80002.42000000","1.87684000"],["80005.46000000","0.36586000"],["80007.69000000","0.00000000"],["80007.70000000","0.00000000"],["80009.70000000","0.00000000"],["80010.28000000","1.04939000"],["80012.01000000","1.87677000"],["80012.45000000","0.00000000"],["80019.08000000","1.41525000"],["80019.50000000","0.62843000"],["80021.60000000","1.87677000"],["80025.67000000","0.00000000"],["80029.47000000","1.04939000"],["80031.19000000","1.87677000"],["80033.30000000","0.00000000"],["80034.88000000","0.36586000"],["80036.44000000","1.50023000"],["80039.86000000","1.04939000"],["80040.78000000","1.89279000"],["80041.64000000","0.00000000"],["80041.84000000","0.00008000"],["80049.26000000","0.36586000"],["80057.61000000","0.00000000"],["80062.78000000","0.36586000"],["80073.58000000","0.00000000"],["80074.29000000","3.74740000"],["80077.16000000","0.36586000"],["80089.55000000","0.00000000"],["80091.54000000","0.36586000"],["80105.52000000","0.00000000"],["80105.92000000","0.36586000"],["80107.53000000","0.00007000"],["80111.52000000","0.00007000"],["80113.17000000","0.00000000"],["80120.30000000","0.36586000"],["80121.73000000","0.00008000"],["80134.68000000","0.36586000"],["80144.01000000","0.00000000"],["80154.95000000","0.00030000"],["80272.92000000","0.00000000"],["80281.49000000","0.00008000"],["80432.66000000","0.00000000"],["80441.25000000","0.00008000"],["80512.54000000","0.00000000"],["80521.14000000","0.00008000"],["81067.30000000","0.00000000"]]}}}
{"rx_ns": 13867902270200, "frame": {"stream":"btcusdt@depth@100ms","data":{"e":"depthUpdate","E":1787650863114,"s":"BTCUSDT","U":99118588348,"u":99118588855,"b":[["79882.07000000","3.41296000"],["79882.06000000","0.00027000"],["79882.05000000","0.20946000"],["79882.04000000","0.68229000"],["79881.77000000","0.00938000"],["79881.53000000","0.03224000"],["79880.22000000","0.00718000"],["79879.98000000","0.00000000"],["79879.97000000","0.00028000"],["79879.96000000","0.00007000"],["79879.69000000","0.02480000"],["79879.44000000","0.08541000"],["79879.43000000","0.05307000"],["79879.14000000","0.00000000"],["79879.13000000","0.04023000"],["79879.10000000","0.00000000"],["79877.87000000","0.00000000"],["79877.86000000","0.00014000"],["79877.85000000","0.12547000"],["79876.90000000","0.00000000"],["79876.86000000","0.00008000"],["79876.63000000","0.00250000"],["79876.54000000","0.03252000"],["79876.32000000","0.02253000"],["79876.22000000","0.00708000"],["79876.16000000","0.00400000"],["79876.14000000","0.00000000"],["79876.02000000","0.00007000"],["79875.99000000","0.00000000"],["79875.87000000","0.00033000"],["79874.63000000","0.06325000"],["79874.01000000","0.06332000"],["79873.92000000","0.00400000"],["79873.90000000","0.06318000"],["79873.89000000","0.15014000"],["79872.77000000","0.06318000"],["79872.39000000","1.71882000"],["79872.37000000","0.00000000"],["79872.04000000","0.07500000"],["79872.03000000","2.60433000"],["79872.01000000","1.34939000"],["79872.00000000","0.08583000"],["79871.68000000","0.30400000"],["79871.50000000","0.37569000"],["79871.01000000","0.30000000"],["79870.97000000","0.00000000"],["79870.73000000","0.68912000"],["79870.62000000","0.00000000"],["79870.22000000","0.25532000"],["79869.85000000","0.00000000"],["79869.79000000","0.00000000"],["79869.46000000","0.00000000"],["79869.45000000","0.54095000"],["79869.29000000","0.40909000"],["79869.25000000","0.24391000"],["79867.97000000","0.00000000"],["79866.69000000","0.00000000"],["79865.58000000","0.00000000"],["79865.57000000","1.15821000"],["79865.41000000","0.00000000"],["79864.03000000","0.62605000"],["79863.79000000","0.04000000"],["79861.44000000","0.00000000"],["79860.00000000","0.11792000"],["79856.13000000","0.00007000"],["79855.70000000","0.00000000"],["79854.86000000","0.00000000"],["79852.85000000","0.04752000"],["79847.50000000","0.54946000"],["79842.00000000","0.03400000"],["79840.32000000","0.00000000"],["79840.29000000","0.00000000"],["79840.00000000","1.02051000"],["79838.58000000","0.00000000"],["79838.46000000","0.00000000"],["79830.96000000","0.00632000"],["79830.29000000","0.00335000"],["79830.00000000","0.02400000"],["79829.00000000","0.00000000"],["79825.70000000","0.00434000"],["79823.80000000","0.00000000"],["79823.65000000","0.00435000"],["79820.54000000","0.00000000"],["79814.09000000","0.00000000"],["79814.00000000","0.02400000"],["79813.61000000","0.00000000"],["79812.22000000","0.01729000"],["79808.17000000","0.00000000"],["79807.25000000","0.12077000"],["79805.38000000","0.00000000"],["79799.63000000","0.00000000"],["79793.68000000","0.00000000"],["79789.61000000","0.00000000"],["79779.16000000","0.00000000"],["79779.15000000","0.00000000"],["79768.63000000","0.00000000"],["79702.92000000","0.00008000"],["79700.04000000","0.00000000"],["79650.77000000","0.00000000"],["79647.04000000","0.00000000"],["79643.45000000","0.00000000"],["79641.35000000","0.00000000"],["79638.61000000","0.00000000"],["79635.83000000","0.00000000"],["71893.87000000","0.00016000"],["63906.00000000","0.00000000"],["63905.66000000","0.00067000"]],"a":[["79882.08000000","0.00384000"],["79882.09000000","0.00063000"],["79882.88000000","0.00000000"],["79883.28000000","0.00000000"],["79883.29000000","0.00000000"],["79883.51000000","0.00000000"],["79883.52000000","0.00000000"],["79883.53000000","0.00007000"],["79884.27000000","0.00000000"],["79884.36000000","0.00000000"],["79884.37000000","0.00028000"],["79884.44000000","0.00000000"],["79884.93000000","0.00000000"],["79884.99000000","0.00007000"],["79885.00000000","0.00007000"],["79885.01000000","0.00007000"],["79885.02000000","0.04758000"],["79885.59000000","0.00000000"],["79885.79000000","0.00017000"],["79885.80000000","0.00000000"],["79885.99000000","0.00007000"],["79886.00000000","0.02442000"],["79886.09000000","0.00675000"],["79886.41000000","0.00007000"],["79886.42000000","0.00007000"],["79886.58000000","0.00521000"],["79886.74000000","0.00007000"],["79887.03000000","0.00007000"],["79887.04000000","0.00000000"],["79887.37000000","0.01125000"],["79887.65000000","0.00007000"],["79887.66000000","0.06339000"],["79887.98000000","0.00007000"],["79887.99000000","0.06346000"],["79888.00000000","0.19045000"],["79888.65000000","0.01350000"],["79888.90000000","0.06318000"],["79888.95000000","0.00014000"],["79888.97000000","0.00000000"],["79889.44000000","0.00000000"],["79889.52000000","0.06318000"],["79889.93000000","0.01350000"],["79889.99000000","0.06318000"],["79890.00000000","0.02414000"],["79890.06000000","0.00000000"],["79890.15000000","0.00000000"],["79890.21000000","0.00918000"],["79890.76000000","0.00000000"],["79890.95000000","0.00000000"],["79891.22000000","0.00000000"],["79891.27000000","0.00000000"],["79891.38000000","0.06318000"],["79891.41000000","0.00000000"],["79891.99000000","0.06318000"],["79892.28000000","0.00007000"],["79892.35000000","0.00000000"],["79892.47000000","0.00000000"],["79892.61000000","0.65852000"],["79892.62000000","0.00000000"],["79892.68000000","0.00000000"],["79892.80000000","0.00000000"],["79893.24000000","0.00000000"],["79893.70000000","0.00000000"],["79893.85000000","0.00000000"],["79893.86000000","0.00000000"],["79893.91000000","0.00000000"],["79893.92000000","0.00000000"],["79893.93000000","0.00000000"],["79894.68000000","0.00000000"],["79895.07000000","0.00000000"],["79895.08000000","0.00000000"],["79895.46000000","0.00043000"],["79895.72000000","0.00000000"],["79896.15000000","0.00014000"],["79896.34000000","0.00000000"],["79896.39000000","1.03813000"],["79896.53000000","0.00000000"],["79896.68000000","0.00000000"],["79896.88000000","0.00000000"],["79897.78000000","0.00000000"],["79898.14000000","0.00914000"],["79898.20000000","0.00000000"],["79898.82000000","1.87684000"],["79898.88000000","0.02800000"],["79899.28000000","0.01026000"],["79899.29000000","0.00000000"],["79899.73000000","0.00250000"],["79900.02000000","0.00014000"],["79900.65000000","0.00000000"],["79901.88000000","0.02000000"],["79902.28000000","0.00000000"],["79902.90000000","0.51692000"],["79903.01000000","0.00000000"],["79903.08000000","0.08000000"],["79903.58000000","0.04000000"],["79903.89000000","0.00014000"],["79905.00000000","0.00000000"],["79905.97000000","0.00000000"],["79906.13000000","0.00934000"],["79907.30000000","0.00000000"],["79907.51000000","0.19019000"],["79907.76000000","0.00014000"],["79907.79000000","0.00250000"],["79908.00000000","0.02400000"],["79908.24000000","0.00626000"],["79908.81000000","0.00000000"],["79909.99000000","0.00000000"],["79911.45000000","0.42948000"],["79911.63000000","0.00014000"],["79912.00000000","0.02973000"],["79912.12000000","0.00000000"],["79912.59000000","0.00000000"],["79913.14000000","0.00000000"],["79913.46000000","0.02480000"],["79914.12000000","0.00928000"],["79914.59000000","0.00000000"],["79914.96000000","0.00000000"],["79915.49000000","0.00000000"],["79915.50000000","0.00014000"],["79915.69000000","0.00000000"],["79916.19000000","0.00000000"],["79916.76000000","0.00000000"],["79918.39000000","0.00000000"],["79918.72000000","0.00200000"],["79919.37000000","0.00014000"],["79921.55000000","0.00654000"],["79922.11000000","0.00947000"],["79923.20000000","0.00353000"],["79923.24000000","0.00007000"],["79926.21000000","1.20226000"],["79927.11000000","0.00007000"],["79928.04000000","0.00654000"],["79928.05000000","0.00630000"],["79928.15000000","0.00430000"],["79929.28000000","0.00000000"],["79929.77000000","0.00000000"],["79930.10000000","0.00435000"],["79930.69000000","0.00431000"],["79930.98000000","0.00007000"],["79940.37000000","0.03744000"],["79945.55000000","0.00190000"],["79949.49000000","0.00008000"],["79952.87000000","0.02000000"],["79968.02000000","0.00000000"],["79968.46000000","0.00000000"],["79968.59000000","0.00000000"],["79968.94000000","0.00000000"],["79969.14000000","0.00000000"],["79969.31000000","0.00000000"],["79969.82000000","0.00000000"],["79970.15000000","0.00000000"],["79975.61000000","0.00000000"],["79979.57000000","0.25000000"],["79996.18000000","0.17736000"],["80024.82000000","0.00076000"],["80045.24000000","0.00000000"],["80115.50000000","0.00007000"],["80119.49000000","0.00007000"],["80228.17000000","0.00270000"],["80262.52000000","0.00000000"]]}}}
{"rx_ns": 13867999785400, "frame": {"stream":"btcusdt@depth@100ms","data":{"e":"depthUpdate","E":1787650863214,"s":"BTCUSDT","U":99118588856,"u":99118589930,"b":[["79885.99000000","5.61258000"],["79885.98000000","0.00027000"],["79885.97000000","0.00013000"],["79885.79000000","2.89466000"],["79885.78000000","2.36671000"],["79885.77000000","0.00000000"],["79885.76000000","0.00000000"],["79885.65000000","0.03224000"],["79885.51000000","0.00000000"],["79885.39000000","0.00000000"],["79885.31000000","0.00000000"],["79885.28000000","0.00000000"],["79885.16000000","0.00007000"],["79885.02000000","0.07500000"],["79885.01000000","0.35348000"],["79885.00000000","0.00000000"],["79884.99000000","0.00000000"],["79884.56000000","0.00000000"],["79884.54000000","0.00014000"],["79884.50000000","0.02011000"],["79884.47000000","0.00162000"],["79884.44000000","0.00000000"],["79884.40000000","0.00000000"],["79884.39000000","0.00007000"],["79884.37000000","0.00000000"],["79884.36000000","0.00000000"],["79884.27000000","0.00007000"],["79883.94000000","0.00007000"],["79883.86000000","0.00026000"],["79883.77000000","0.00007000"],["79883.67000000","0.00007000"],["79883.56000000","0.00007000"],["79883.52000000","0.00007000"],["79883.22000000","0.02405000"],["79883.16000000","0.00000000"],["79883.15000000","0.05302000"],["79882.88000000","0.00400000"],["79882.54000000","0.00000000"],["79882.53000000","0.00000000"],["79882.38000000","0.00000000"],["79882.10000000","0.00000000"],["79882.09000000","0.80949000"],["79882.08000000","1.12439000"],["79882.07000000","0.22942000"],["79882.06000000","0.00000000"],["79882.05000000","0.00014000"],["79882.04000000","0.39242000"],["79881.94000000","0.02405000"],["79881.90000000","0.03000000"],["79881.77000000","0.00945000"],["79881.53000000","0.03238000"],["79880.64000000","0.00400000"],["79880.22000000","0.00725000"],["79880.00000000","0.00007000"],["79879.97000000","0.00007000"],["79879.69000000","0.02487000"],["79879.45000000","0.00000000"],["79879.44000000","0.13500000"],["79879.43000000","0.00000000"],["79879.13000000","0.00000000"],["79878.40000000","0.00400000"],["79878.35000000","0.00000000"],["79877.86000000","0.00000000"],["79877.85000000","0.12526000"],["79877.80000000","0.00626000"],["79877.79000000","0.20250000"],["79877.58000000","0.00010000"],["79877.45000000","0.00000000"],["79877.11000000","0.00000000"],["79877.09000000","0.00007000"],["79877.02000000","0.00008000"],["79876.83000000","0.00000000"],["79876.55000000","0.00000000"],["79876.54000000","0.00000000"],["79876.29000000","0.00000000"],["79876.22000000","0.00701000"],["79876.21000000","0.00000000"],["79876.19000000","0.08576000"],["79876.06000000","0.00000000"],["79876.02000000","0.00000000"],["79876.00000000","0.00000000"],["79875.87000000","0.00033000"],["79875.25000000","0.00000000"],["79874.63000000","0.00000000"],["79874.47000000","0.00007000"],["79874.26000000","0.00000000"],["79874.08000000","0.00000000"],["79874.01000000","0.00000000"],["79873.97000000","1.20226000"],["79873.90000000","0.00000000"],["79873.89000000","0.12007000"],["79873.49000000","0.00000000"],["79873.39000000","0.00000000"],["79873.29000000","0.00000000"],["79873.23000000","0.00000000"],["79872.77000000","0.00000000"],["79872.39000000","1.18498000"],["79872.04000000","0.00000000"],["79872.03000000","0.72756000"],["79872.00000000","0.30007000"],["79871.73000000","0.00060000"],["79871.51000000","0.62013000"],["79870.74000000","0.00000000"],["79870.73000000","0.00000000"],["79870.55000000","0.00000000"],["79870.00000000","0.09391000"],["79869.92000000","0.00012000"],["79869.25000000","0.03958000"],["79867.69000000","0.00000000"],["79867.49000000","0.00000000"],["79867.21000000","0.00000000"],["79866.89000000","0.00000000"],["79866.84000000","0.09465000"],["79865.58000000","0.36586000"],["79865.05000000","0.04375000"],["79864.84000000","0.10370000"],["79863.13000000","0.00000000"],["79861.13000000","0.00000000"],["79859.60000000","0.09488000"],["79857.99000000","0.00037000"],["79856.32000000","0.00000000"],["79855.48000000","0.00000000"],["79853.81000000","0.00000000"],["79850.28000000","0.00000000"],["79850.27000000","0.01158000"],["79850.00000000","0.12092000"],["79847.50000000","0.33235000"],["79847.38000000","0.00000000"],["79845.84000000","0.00000000"],["79845.73000000","0.00000000"],["79845.15000000","0.00000000"],["79845.11000000","0.00400000"],["79845.00000000","0.01000000"],["79842.92000000","0.00000000"],["79842.76000000","1.68646000"],["79842.00000000","0.02400000"],["79840.00000000","0.92657000"],["79836.78000000","0.00436000"],["79836.71000000","0.00000000"],["79835.00000000","0.00000000"],["79826.12000000","0.00000000"],["79823.80000000","0.58653000"],["79822.26000000","0.00000000"],["79821.96000000","0.00540000"],["79821.80000000","0.00000000"],["79805.20000000","0.00000000"],["79805.18000000","0.00400000"],["79803.63000000","0.00000000"],["79800.44000000","0.00000000"],["79800.03000000","0.00000000"],["79797.65000000","0.04633000"],["79796.79000000","0.00000000"],["79773.51000000","0.00000000"],["79773.24000000","0.00400000"],["79764.85000000","0.00000000"],["79749.46000000","0.20250000"],["79746.29000000","0.04033000"],["79733.68000000","0.00000000"],["79725.34000000","0.00400000"],["79716.95000000","0.00000000"],["79654.76000000","0.00000000"],["79653.48000000","0.00400000"],["79645.10000000","0.00000000"],["79573.78000000","0.02792000"],["79566.43000000","0.01922000"],["79555.65000000","0.00000000"],["79528.85000000","0.00000000"],["79508.39000000","0.00000000"],["79501.09000000","0.00000000"],["79137.74000000","0.00000000"],["79000.00000000","25.28493000"],["78999.21000000","0.01520000"],["78687.49000000","0.00030000"],["71893.87000000","0.00000000"],["63905.66000000","0.00036000"]],"a":[["79882.08000000","0.00000000"],["79882.09000000","0.00000000"],["79883.53000000","0.00000000"],["79883.57000000","0.00000000"],["79883.95000000","0.00000000"],["79884.28000000","0.00000000"],["79884.37000000","0.00000000"],["79884.38000000","0.00000000"],["79884.45000000","0.00000000"],["79884.54000000","0.00000000"],["79884.57000000","0.00000000"],["79884.99000000","0.00000000"],["79885.00000000","0.00000000"],["79885.01000000","0.00000000"],["79885.02000000","0.00000000"],["79885.03000000","0.00000000"],["79885.32000000","0.00000000"],["79885.40000000","0.00000000"],["79885.79000000","0.00000000"],["79885.80000000","0.00000000"],["79885.99000000","0.00000000"],["79886.00000000","0.02555000"],["79886.01000000","0.00049000"],["79886.08000000","0.00000000"],["79886.09000000","0.00014000"],["79886.41000000","0.00000000"],["79886.58000000","0.00521000"],["79887.03000000","0.00000000"],["79887.36000000","0.00000000"],["79887.37000000","0.00014000"],["79887.48000000","0.00000000"],["79887.65000000","0.00000000"],["79887.66000000","0.00021000"],["79887.98000000","0.00000000"],["79887.99000000","0.00028000"],["79888.00000000","0.02428000"],["79888.64000000","0.00000000"],["79888.65000000","0.00021000"],["79888.68000000","0.00000000"],["79888.73000000","0.00007000"],["79888.74000000","0.00007000"],["79888.75000000","0.04721000"],["79888.89000000","0.00000000"],["79888.90000000","0.00014000"],["79888.95000000","0.00000000"],["79889.07000000","0.00000000"],["79889.51000000","0.00000000"],["79889.52000000","0.00000000"],["79889.92000000","0.00000000"],["79889.93000000","0.00000000"],["79889.98000000","0.00000000"],["79889.99000000","0.00007000"],["79890.00000000","0.02421000"],["79890.06000000","0.00000000"],["79890.07000000","0.00000000"],["79890.21000000","0.00000000"],["79890.57000000","0.00000000"],["79891.05000000","0.00000000"],["79891.21000000","0.00000000"],["79891.36000000","0.00007000"],["79891.37000000","0.00000000"],["79891.38000000","0.00000000"],["79891.52000000","0.00000000"],["79891.82000000","0.00000000"],["79891.96000000","0.00007000"],["79891.97000000","0.06325000"],["79891.98000000","0.14168000"],["79891.99000000","0.00007000"],["79892.13000000","0.00000000"],["79892.28000000","0.00007000"],["79892.45000000","0.00007000"],["79892.46000000","0.00007000"],["79892.61000000","0.00000000"],["79892.89000000","0.00000000"],["79893.01000000","0.00008000"],["79893.07000000","0.00000000"],["79893.08000000","0.06057000"],["79893.19000000","0.00000000"],["79893.31000000","0.00000000"],["79893.70000000","0.06325000"],["79893.88000000","0.00912000"],["79893.99000000","0.00000000"],["79894.32000000","0.06318000"],["79894.42000000","0.00000000"],["79894.83000000","0.00000000"],["79894.94000000","0.06318000"],["79895.07000000","0.19501000"],["79895.46000000","0.00000000"],["79895.56000000","0.06318000"],["79895.72000000","0.00000000"],["79896.15000000","0.00007000"],["79896.34000000","0.06318000"],["79896.38000000","0.00000000"],["79896.39000000","0.08939000"],["79896.40000000","0.00000000"],["79897.34000000","0.06407000"],["79897.57000000","0.06318000"],["79897.85000000","0.00000000"],["79897.99000000","0.06318000"],["79898.42000000","0.00000000"],["79898.43000000","0.00000000"],["79898.66000000","0.06318000"],["79898.67000000","0.00007000"],["79898.81000000","0.00400000"],["79898.82000000","0.00007000"],["79898.88000000","0.02000000"],["79898.89000000","0.00000000"],["79898.90000000","0.00000000"],["79899.28000000","0.00026000"],["79899.43000000","0.06318000"],["79899.50000000","0.00000000"],["79899.73000000","0.00000000"],["79899.97000000","0.06318000"],["79899.98000000","0.84031000"],["79900.00000000","1.02675000"],["79900.25000000","0.00000000"],["79900.45000000","0.00000000"],["79900.79000000","0.00000000"],["79900.98000000","0.00000000"],["79901.08000000","0.00000000"],["79901.51000000","0.00000000"],["79901.73000000","0.00000000"],["79901.74000000","0.00626000"],["79901.88000000","0.00000000"],["79901.99000000","0.00042000"],["79902.61000000","0.00038000"],["79902.62000000","0.00400000"],["79902.90000000","0.00000000"],["79902.98000000","0.03000000"],["79903.04000000","0.00000000"],["79903.08000000","0.00000000"],["79903.29000000","0.02000000"],["79903.62000000","1.87677000"],["79903.63000000","0.00000000"],["79903.88000000","0.00000000"],["79906.24000000","0.09461000"],["79906.78000000","0.08000000"],["79907.51000000","0.00000000"],["79907.64000000","1.04939000"],["79907.65000000","0.00000000"],["79907.66000000","0.00000000"],["79908.24000000","0.10364000"],["79908.44000000","0.00000000"],["79908.52000000","0.67911000"],["79908.54000000","0.00007000"],["79909.31000000","0.00000000"],["79909.91000000","0.02252000"],["79909.99000000","0.00000000"],["79910.01000000","0.00250000"],["79910.30000000","0.00000000"],["79910.46000000","0.00000000"],["79911.45000000","0.00000000"],["79911.97000000","0.00000000"],["79911.99000000","1.11340000"],["79912.89000000","0.00000000"],["79913.46000000","0.00000000"],["79913.54000000","0.19019000"],["79915.23000000","0.42175000"],["79916.60000000","0.00626000"],["79916.77000000","0.67010000"],["79917.70000000","0.42944000"],["79917.79000000","0.00000000"],["79918.66000000","0.00000000"],["79918.86000000","0.00000000"],["79919.10000000","0.00654000"],["79919.98000000","0.62600000"],["79919.99000000","1.17799000"],["79920.00000000","1.12152000"],["79920.82000000","0.00000000"],["79922.10000000","0.00000000"],["79922.94000000","0.00000000"],["79923.00000000","0.00000000"],["79923.18000000","0.00000000"],["79923.24000000","0.00014000"],["79924.58000000","0.00013000"],["79925.00000000","0.00000000"],["79925.90000000","0.02480000"],["79926.00000000","0.03400000"],["79926.20000000","0.46817000"],["79926.55000000","0.00060000"],["79928.04000000","0.00000000"],["79928.13000000","0.35337000"],["79928.15000000","0.00000000"],["79929.04000000","0.00000000"],["79932.75000000","0.89290000"],["79934.85000000","0.00000000"],["79936.52000000","0.00000000"],["79937.99000000","0.06883000"],["79938.38000000","0.00000000"],["79939.90000000","1.73183000"],["79942.58000000","0.00400000"],["79943.83000000","0.02875000"],["79947.55000000","0.00000000"],["79960.74000000","0.00000000"],["79961.43000000","0.04696000"],["79963.70000000","0.00113000"],["79970.34000000","0.00000000"],["79974.54000000","0.00400000"],["79975.99000000","0.01493000"],["79979.89000000","1.01497000"],["79980.44000000","0.02804000"],["79989.70000000","0.01154000"],["79991.99000000","0.57394000"],["80004.63000000","0.17120000"],["80010.27000000","0.31324000"],["80016.24000000","0.00000000"],["80018.28000000","0.00000000"],["80022.48000000","0.00400000"],["80028.57000000","0.93118000"],["80032.15000000","0.12905000"],["80035.57000000","0.60679000"],["80090.19000000","0.00013000"],["80094.39000000","0.00400000"],["80095.12000000","0.00000000"],["80116.07000000","0.00000000"],["80149.12000000","0.01940000"],["80154.95000000","0.00000000"],["80157.44000000","0.00000000"],["80165.39000000","0.00036000"],["80175.24000000","0.02404000"],["80188.58000000","1.19998000"],["80252.15000000","0.20250000"],["80287.66000000","0.00626000"],["80402.50000000","0.00000000"],["81080.32000000","0.00000000"]]}}}
{"rx_ns": 13868106305200, "frame": {"stream":"btcusdt@depth@100ms","data":{"e":"depthUpdate","E":1787650863314,"s":"BTCUSDT","U":99118589931,"u":99118590170,"b":[["79885.99000000","6.10902000"],["79885.80000000","0.65689000"],["79885.79000000","0.47303000"],["79885.78000000","2.36377000"],["79885.65000000","0.03238000"],["79885.12000000","0.00400000"],["79885.02000000","0.07514000"],["79885.01000000","0.35348000"],["79884.50000000","0.02025000"],["79883.22000000","0.02419000"],["79883.15000000","0.05309000"],["79882.09000000","0.21831000"],["79882.07000000","0.23266000"],["79882.05000000","0.00000000"],["79882.04000000","0.39228000"],["79881.77000000","0.00931000"],["79881.53000000","0.03224000"],["79880.22000000","0.00711000"],["79877.07000000","0.08576000"],["79876.19000000","0.00000000"],["79872.14000000","0.00192000"],["79867.98000000","0.00000000"],["79858.98000000","0.00000000"],["79857.92000000","0.00000000"],["79856.00000000","0.02807000"],["79850.88000000","0.00000000"],["79849.61000000","0.02000000"],["79847.50000000","0.54118000"],["79846.27000000","0.83208000"],["79845.11000000","0.00000000"],["79829.86000000","0.00012000"],["79820.93000000","0.02087000"],["79820.37000000","0.00119000"],["79817.04000000","0.00000000"],["79811.35000000","0.00000000"],["79805.18000000","0.00000000"],["79803.04000000","1.99535000"],["79781.43000000","0.20275000"],["79773.24000000","0.00000000"],["79725.34000000","0.00000000"],["79653.48000000","0.00000000"],["79568.70000000","0.00030000"],["71897.40000000","0.00032000"],["71884.86000000","0.00000000"],["63909.00000000","0.00000000"]],"a":[["79886.00000000","0.02377000"],["79886.01000000","0.00056000"],["79886.09000000","0.00000000"],["79886.58000000","0.00514000"],["79887.37000000","0.00000000"],["79887.66000000","0.00007000"],["79887.99000000","0.00014000"],["79888.00000000","0.02428000"],["79888.65000000","0.00007000"],["79888.73000000","0.00000000"],["79888.75000000","0.04735000"],["79888.90000000","0.00000000"],["79890.00000000","0.02435000"],["79890.01000000","0.00681000"],["79891.03000000","0.00007000"],["79891.04000000","0.06407000"],["79891.29000000","0.01124000"],["79891.36000000","0.00000000"],["79891.66000000","0.00007000"],["79891.67000000","0.06407000"],["79891.97000000","0.06339000"],["79891.98000000","0.00028000"],["79892.00000000","0.02414000"],["79892.45000000","0.00000000"],["79892.57000000","0.01349000"],["79892.92000000","0.18627000"],["79892.93000000","0.06407000"],["79893.07000000","0.00007000"],["79893.08000000","0.06071000"],["79893.69000000","0.00000000"],["79893.85000000","0.01349000"],["79893.99000000","0.00000000"],["79894.20000000","0.00000000"],["79895.77000000","0.00202000"],["79896.15000000","0.00007000"],["79896.39000000","0.20698000"],["79896.74000000","0.33812000"],["79898.45000000","0.00007000"],["79899.98000000","1.18095000"],["79902.62000000","0.00000000"],["79902.96000000","0.00000000"],["79903.61000000","1.04939000"],["79905.24000000","0.00257000"],["79907.31000000","0.00000000"],["79907.63000000","0.00400000"],["79912.51000000","0.00000000"],["79912.90000000","0.00000000"],["79923.95000000","0.09192000"],["79926.77000000","0.00189000"],["79927.68000000","0.00337000"],["79928.05000000","0.00000000"],["79929.92000000","0.00330000"],["79930.10000000","0.00000000"],["79930.69000000","0.00000000"],["79931.96000000","0.00007000"],["79932.16000000","0.00330000"],["79934.85000000","0.00007000"],["79938.31000000","0.00429000"],["79939.12000000","0.00630000"],["79941.01000000","0.00428000"],["79941.33000000","0.00429000"],["79942.47000000","0.83108000"],["79942.58000000","0.00000000"],["79947.94000000","0.00007000"],["79954.96000000","0.00000000"],["79963.92000000","0.00007000"],["79968.30000000","0.00000000"],["79974.54000000","0.00000000"],["79979.90000000","0.00007000"],["79980.44000000","0.00000000"],["79981.14000000","0.00025000"],["79995.88000000","0.00007000"],["80011.86000000","0.00007000"],["80022.48000000","0.00000000"],["80027.84000000","0.00007000"],["80043.82000000","0.00007000"],["80059.80000000","0.00007000"],["80075.78000000","0.00007000"],["80091.76000000","0.00007000"],["80094.39000000","0.00000000"],["80095.18000000","0.00000000"],["80105.17000000","0.00007000"],["80107.74000000","0.00007000"],["80116.58000000","0.00000000"],["80119.49000000","0.00000000"],["80123.72000000","0.00021000"],["80142.91000000","0.11428000"],["80163.69000000","0.11473000"],["80267.05000000","0.00000000"],["80291.68000000","0.00626000"],["80295.30000000","0.00007000"]]}}}
{"rx_ns": 13868207044400, "frame": {"stream":"btcusdt@depth@100ms","data":{"e":"depthUpdate","E":1787650863414,"s":"BTCUSDT","U":99118590171,"u":99118590486,"b":[["79886.57000000","5.78315000"],["79886.56000000","0.00013000"],["79886.55000000","0.00013000"],["79886.41000000","0.00014000"],["79886.01000000","0.47873000"],["79886.00000000","0.95280000"],["79885.99000000","2.16546000"],["79885.98000000","0.00000000"],["79885.97000000","0.00000000"],["79885.80000000","0.00007000"],["79885.79000000","0.07514000"],["79885.78000000","0.36101000"],["79883.94000000","0.05302000"],["79883.86000000","0.00000000"],["79883.22000000","0.02405000"],["79883.15000000","0.00007000"],["79882.08000000","1.04939000"],["79882.07000000","0.22921000"],["79879.87000000","0.00000000"],["79879.44000000","0.23241000"],["79878.77000000","0.37565000"],["79878.07000000","0.08576000"],["79877.85000000","0.12519000"],["79877.56000000","0.00007000"],["79877.07000000","0.00000000"],["79875.05000000","0.00007000"],["79874.47000000","0.00000000"],["79871.51000000","0.91710000"],["79870.81000000","0.33812000"],["79870.59000000","0.00008000"],["79869.29000000","0.20631000"],["79869.14000000","0.33813000"],["79866.60000000","0.00008000"],["79866.06000000","0.00000000"],["79862.60000000","0.00008000"],["79862.07000000","0.00000000"],["79858.61000000","0.00008000"],["79858.08000000","0.00000000"],["79854.62000000","0.00008000"],["79854.08000000","0.00000000"],["79850.62000000","0.00008000"],["79850.09000000","0.00000000"],["79848.03000000","0.00007000"],["79846.63000000","0.00008000"],["79846.09000000","0.00000000"],["79846.00000000","0.03400000"],["79845.00000000","0.00000000"],["79842.10000000","0.00000000"],["79823.80000000","0.40541000"],["79822.29000000","0.00000000"],["79821.05000000","0.00000000"],["79797.70000000","0.00000000"],["79789.73000000","0.00000000"],["79749.46000000","0.00000000"],["79740.51000000","0.00000000"],["79733.73000000","0.00000000"],["71897.92000000","0.00016000"],["71897.40000000","0.00000000"]],"a":[["79886.00000000","0.00000000"],["79886.01000000","0.00000000"],["79886.42000000","0.00000000"],["79886.58000000","0.00571000"],["79886.59000000","0.00035000"],["79888.00000000","0.02428000"],["79888.74000000","0.00000000"],["79888.75000000","0.00014000"],["79889.10000000","0.00292000"],["79889.53000000","0.00007000"],["79889.54000000","0.04720000"],["79890.00000000","0.02442000"],["79890.01000000","0.00702000"],["79891.03000000","0.00000000"],["79891.04000000","0.00021000"],["79891.27000000","0.00026000"],["79891.29000000","0.01138000"],["79891.67000000","0.06421000"],["79891.96000000","0.00000000"],["79891.97000000","0.00007000"],["79891.98000000","0.00014000"],["79892.00000000","0.02407000"],["79892.48000000","0.00000000"],["79892.78000000","0.06305000"],["79892.87000000","0.00007000"],["79892.88000000","0.06407000"],["79892.91000000","0.00000000"],["79892.92000000","0.00007000"],["79892.93000000","0.00000000"],["79893.07000000","0.00000000"],["79893.08000000","0.00137000"],["79893.69000000","0.00007000"],["79894.21000000","0.00000000"],["79896.39000000","0.14272000"],["79896.73000000","0.06407000"],["79897.34000000","0.00000000"],["79897.57000000","0.00000000"],["79897.99000000","0.00000000"],["79898.36000000","0.06305000"],["79898.55000000","0.06407000"],["79898.66000000","0.00000000"],["79899.18000000","0.06407000"],["79899.43000000","0.00000000"],["79900.84000000","0.00007000"],["79902.01000000","0.00007000"],["79902.05000000","0.00000000"],["79905.18000000","0.00000000"],["79905.24000000","0.00007000"],["79906.04000000","0.00125000"],["79906.55000000","0.00008000"],["79907.04000000","0.00012000"],["79910.04000000","0.00000000"],["79910.55000000","0.00008000"],["79914.03000000","0.00000000"],["79914.54000000","0.00008000"],["79915.24000000","0.00000000"],["79918.03000000","0.00000000"],["79918.46000000","0.00400000"],["79918.53000000","0.00008000"],["79920.71000000","0.33791000"],["79922.02000000","0.00000000"],["79922.53000000","0.00008000"],["79923.95000000","0.00000000"],["79926.00000000","0.02400000"],["79926.52000000","0.00008000"],["79927.00000000","0.01000000"],["79928.13000000","0.49208000"],["79928.20000000","0.62570000"],["79930.73000000","0.33787000"],["79931.32000000","0.10000000"],["79934.40000000","0.00205000"],["79936.64000000","0.00205000"],["79952.73000000","0.00000000"],["79961.35000000","1.23838000"],["79969.13000000","0.00535000"],["79979.57000000","0.00000000"],["79985.92000000","0.00000000"],["79986.29000000","0.00000000"],["79988.61000000","0.00000000"],["79989.59000000","0.02804000"],["79992.78000000","0.00000000"],["80032.58000000","0.10014000"],["80117.78000000","0.00007000"],["80121.77000000","0.00007000"]]}}}
{"rx_ns": 13868297868000, "frame": {"stream":"btcusdt@depth@100ms","data":{"e":"depthUpdate","E":1787650863514,"s":"BTCUSDT","U":99118590487,"u":99118590639,"b":[["79886.57000000","5.90486000"],["79886.41000000","0.00000000"],["79886.01000000","0.32965000"],["79886.00000000","0.49274000"],["79885.99000000","2.16532000"],["79885.80000000","0.00000000"],["79885.65000000","0.03897000"],["79884.93000000","0.00008000"],["79884.50000000","0.02011000"],["79883.88000000","0.00026000"],["79882.09000000","0.50333000"],["79882.07000000","0.22914000"],["79881.17000000","0.00000000"],["79880.55000000","0.00000000"],["79879.97000000","0.00000000"],["79879.96000000","0.00000000"],["79871.18000000","0.02000000"],["79833.78000000","0.00012000"],["79831.70000000","0.92933000"],["79829.86000000","0.00000000"],["79829.60000000","0.00000000"],["79820.93000000","0.00000000"],["79811.69000000","0.00626000"],["79806.68000000","0.05767000"],["79757.23000000","0.00012000"],["79732.89000000","0.00000000"],["71897.92000000","0.00032000"],["63909.26000000","0.00031000"]],"a":[["79886.58000000","0.00599000"],["79886.59000000","0.00042000"],["79888.00000000","0.02421000"],["79888.65000000","0.00000000"],["79888.75000000","0.00000000"],["79889.10000000","0.00000000"],["79889.54000000","0.04734000"],["79890.00000000","0.02435000"],["79890.01000000","0.00702000"],["79891.04000000","0.00007000"],["79891.29000000","0.01145000"],["79891.53000000","0.00007000"],["79891.54000000","0.00000000"],["79891.66000000","0.00000000"],["79891.67000000","0.00014000"],["79891.97000000","0.00000000"],["79892.00000000","0.02421000"],["79892.57000000","0.01363000"],["79892.77000000","0.00007000"],["79892.78000000","0.00007000"],["79892.88000000","0.00000000"],["79892.92000000","0.00000000"],["79893.00000000","0.00000000"],["79893.99000000","0.00007000"],["79895.07000000","0.00000000"],["79895.77000000","0.00000000"],["79896.39000000","0.20063000"],["79896.74000000","0.00000000"],["79897.74000000","0.00000000"],["79898.36000000","0.00000000"],["79898.55000000","0.00000000"],["79898.81000000","0.00000000"],["79899.96000000","0.00000000"],["79902.98000000","0.00000000"],["79903.29000000","0.00000000"],["79903.58000000","0.00000000"],["79903.61000000","0.00000000"],["79903.62000000","0.00000000"],["79904.28000000","0.00000000"],["79906.78000000","0.00000000"],["79907.04000000","0.00000000"],["79908.33000000","0.02000000"],["79908.68000000","0.04000000"],["79908.98000000","0.03000000"],["79908.99000000","0.02000000"],["79910.96000000","0.00012000"],["79911.29000000","0.08000000"],["79911.46000000","0.00000000"],["79921.65000000","0.49227000"],["79922.21000000","0.00000000"],["79924.31000000","0.00200000"],["79924.61000000","0.00000000"],["79924.85000000","0.00000000"],["79938.72000000","0.00007000"],["79943.83000000","0.31200000"],["79945.62000000","0.96121000"],["79962.18000000","0.02000000"],["79967.46000000","0.01727000"],["79976.66000000","0.02448000"],["79984.08000000","0.25000000"],["80035.57000000","0.17543000"],["80036.44000000","0.00000000"],["80044.84000000","0.00000000"],["80056.64000000","0.05740000"],["80074.41000000","0.00000000"],["80098.68000000","0.00000000"],["80121.77000000","0.00000000"]]}}}
{"rx_ns": 13868401261500, "frame": {"stream":"btcusdt@depth@100ms","data":{"e":"depthUpdate","E":1787650863614,"s":"BTCUSDT","U":99118590640,"u":99118591073,"b":[["79887.99000000","7.54250000"],["79887.98000000","1.04966000"],["79887.97000000","0.00013000"],["79887.65000000","0.00000000"],["79887.37000000","0.00000000"],["79887.36000000","0.00400000"],["79887.32000000","0.00000000"],["79886.75000000","0.00000000"],["79886.73000000","0.00000000"],["79886.58000000","0.95201000"],["79886.57000000","2.14659000"],["79886.56000000","0.00000000"],["79886.55000000","0.00000000"],["79886.01000000","0.00021000"],["79886.00000000","0.17973000"],["79885.99000000","0.00462000"],["79885.78000000","0.01789000"],["79885.65000000","0.03904000"],["79885.36000000","0.05295000"],["79885.02000000","0.00014000"],["79885.01000000","0.36035000"],["79884.50000000","0.00000000"],["79883.94000000","0.00007000"],["79883.22000000","0.00000000"],["79882.04000000","0.39221000"],["79881.94000000","0.00000000"],["79881.90000000","0.00000000"],["79880.00000000","0.09405000"],["79879.48000000","0.08576000"],["79879.44000000","0.32083000"],["79878.80000000","0.42216000"],["79878.20000000","0.33809000"],["79878.07000000","0.00000000"],["79878.01000000","0.00007000"],["79877.02000000","0.00000000"],["79876.47000000","0.00007000"],["79875.74000000","0.02200000"],["79875.05000000","0.00000000"],["79873.98000000","0.36586000"],["79873.89000000","0.00007000"],["79872.48000000","0.02000000"],["79869.45000000","0.34118000"],["79865.30000000","0.00000000"],["79862.85000000","0.00000000"],["79855.64000000","0.00000000"],["79852.23000000","0.00000000"],["79848.00000000","0.03418000"],["79846.00000000","0.02400000"],["79843.28000000","0.00629000"],["79838.86000000","0.00335000"],["79837.69000000","0.00425000"],["79836.46000000","0.00432000"],["79830.96000000","0.00000000"],["79825.70000000","0.00000000"],["79823.65000000","0.00000000"],["79786.29000000","0.00000000"],["79746.29000000","0.00000000"],["79732.09000000","0.00400000"],["79677.10000000","2.84330000"],["79643.16000000","0.00000000"],["71899.20000000","0.00040000"],["71897.92000000","0.00000000"],["63909.26000000","0.00000000"]],"a":[["79886.58000000","0.00000000"],["79886.59000000","0.00000000"],["79886.74000000","0.00000000"],["79887.33000000","0.00000000"],["79887.66000000","0.00000000"],["79887.99000000","0.00000000"],["79888.00000000","0.00489000"],["79888.01000000","0.00048000"],["79888.02000000","0.00013000"],["79889.26000000","0.00007000"],["79889.53000000","0.00000000"],["79889.54000000","0.00014000"],["79890.00000000","0.02428000"],["79890.01000000","0.00035000"],["79890.95000000","0.00007000"],["79890.96000000","0.04720000"],["79891.27000000","0.00000000"],["79891.29000000","0.00014000"],["79891.53000000","0.00000000"],["79891.67000000","0.00000000"],["79892.27000000","0.00000000"],["79892.56000000","0.00000000"],["79892.57000000","0.00014000"],["79892.77000000","0.00000000"],["79892.78000000","0.00000000"],["79892.87000000","0.00000000"],["79893.01000000","0.00000000"],["79893.69000000","0.00000000"],["79893.70000000","0.00028000"],["79893.84000000","0.00000000"],["79893.85000000","0.00007000"],["79893.88000000","0.00007000"],["79894.00000000","0.02421000"],["79894.31000000","0.00000000"],["79894.32000000","0.00000000"],["79894.93000000","0.00000000"],["79894.94000000","0.00000000"],["79895.43000000","0.00007000"],["79895.44000000","0.00000000"],["79895.55000000","0.00000000"],["79895.56000000","0.00000000"],["79895.98000000","0.00007000"],["79895.99000000","0.00015000"],["79896.00000000","0.02414000"],["79896.33000000","0.00007000"],["79896.34000000","0.00000000"],["79896.39000000","0.00000000"],["79896.44000000","0.00000000"],["79896.73000000","0.00000000"],["79897.28000000","0.00007000"],["79897.29000000","0.00007000"],["79897.30000000","0.06305000"],["79897.31000000","0.00000000"],["79897.36000000","0.00000000"],["79897.68000000","0.00000000"],["79897.92000000","0.06305000"],["79898.33000000","0.00000000"],["79898.36000000","0.06305000"],["79898.88000000","0.00000000"],["79898.98000000","0.06305000"],["79899.51000000","0.00000000"],["79899.98000000","0.34064000"],["79900.02000000","0.00007000"],["79900.80000000","0.00000000"],["79901.09000000","0.00202000"],["79901.70000000","0.33812000"],["79901.74000000","0.00000000"],["79901.87000000","0.00007000"],["79903.98000000","0.00008000"],["79904.85000000","0.00000000"],["79907.63000000","0.00800000"],["79907.64000000","0.00000000"],["79907.79000000","0.00000000"],["79908.68000000","0.00000000"],["79908.98000000","0.00000000"],["79910.00000000","0.02400000"],["79910.39000000","0.01000000"],["79910.99000000","0.02000000"],["79911.29000000","0.00000000"],["79912.29000000","0.00000000"],["79913.79000000","0.12000000"],["79916.06000000","0.00000000"],["79916.61000000","0.00000000"],["79917.70000000","0.00000000"],["79918.42000000","0.00000000"],["79919.10000000","0.00000000"],["79920.96000000","0.00205000"],["79921.55000000","0.00000000"],["79925.15000000","0.00000000"],["79925.27000000","0.42940000"],["79926.28000000","0.00000000"],["79926.75000000","0.00000000"],["79927.00000000","0.00000000"],["79927.11000000","0.00014000"],["79927.39000000","0.00000000"],["79928.00000000","0.03407000"],["79928.12000000","0.00000000"],["79928.65000000","0.09237000"],["79930.00000000","0.11784000"],["79933.98000000","0.00580000"],["79936.64000000","0.00000000"],["79938.72000000","0.00007000"],["79939.90000000","1.73383000"],["79939.96000000","0.00000000"],["79945.20000000","0.00200000"],["79945.55000000","0.00000000"],["79950.70000000","0.00190000"],["79953.74000000","0.02000000"],["79956.81000000","0.02000000"],["79961.13000000","0.01270000"],["79962.00000000","0.03540000"],["79970.66000000","0.00000000"],["79989.59000000","0.00000000"],["80005.64000000","0.00000000"],["80045.72000000","0.03134000"],["80092.15000000","0.01960000"],["80107.91000000","0.01960000"],["80272.37000000","0.00000000"]]}}}
{"rx_ns": 13868498558200, "frame": {"stream":"btcusdt@depth@100ms","data":{"e":"depthUpdate","E":1787650863714,"s":"BTCUSDT","U":99118591074,"u":99118591522,"b":[["79889.99000000","6.15497000"],["79889.98000000","0.00027000"],["79889.97000000","0.00013000"],["79889.73000000","0.00007000"],["79889.53000000","0.00007000"],["79889.37000000","0.00000000"],["79889.28000000","0.34895000"],["79889.05000000","0.00007000"],["79888.75000000","0.00000000"],["79888.71000000","0.02011000"],["79888.47000000","0.00007000"],["79888.45000000","0.00007000"],["79888.41000000","0.00014000"],["79888.40000000","0.00000000"],["79888.39000000","0.00007000"],["79888.13000000","0.00000000"],["79888.01000000","0.00000000"],["79888.00000000","1.45651000"],["79887.99000000","3.03289000"],["79887.98000000","1.04953000"],["79887.97000000","0.00000000"],["79887.43000000","0.02412000"],["79887.36000000","0.05695000"],["79886.58000000","0.23637000"],["79886.57000000","0.06432000"],["79886.15000000","0.02405000"],["79886.01000000","0.00007000"],["79886.00000000","0.17973000"],["79885.99000000","0.00455000"],["79885.79000000","0.00014000"],["79885.78000000","0.01782000"],["79885.65000000","0.03897000"],["79885.36000000","0.00000000"],["79885.16000000","0.00000000"],["79885.02000000","0.00000000"],["79885.01000000","0.31885000"],["79884.47000000","0.00000000"],["79883.67000000","0.00000000"],["79883.52000000","0.00000000"],["79883.15000000","0.00000000"],["79882.11000000","1.11929000"],["79882.10000000","1.87677000"],["79882.09000000","0.00000000"],["79882.04000000","0.39214000"],["79881.77000000","0.00917000"],["79881.68000000","0.08576000"],["79881.53000000","0.00000000"],["79880.29000000","0.00007000"],["79880.22000000","0.00704000"],["79880.01000000","0.00007000"],["79879.69000000","0.02480000"],["79879.48000000","0.00000000"],["79878.47000000","0.00007000"],["79876.47000000","0.00000000"],["79873.68000000","0.00007000"],["79872.09000000","0.09465000"],["79870.69000000","0.00000000"],["79870.09000000","0.10369000"],["79870.07000000","0.00000000"],["79866.84000000","0.00000000"],["79864.84000000","0.00000000"],["79864.77000000","0.00000000"],["79850.02000000","0.64135000"],["79850.00000000","0.13092000"],["79849.71000000","0.00000000"],["79848.00000000","0.02418000"],["79841.06000000","0.00000000"],["79830.29000000","0.00000000"],["79823.13000000","0.00000000"],["79819.44000000","0.04455000"],["79818.88000000","0.00000000"],["79817.97000000","0.04564000"],["79815.06000000","0.00000000"],["79807.96000000","0.00000000"],["79806.55000000","0.00000000"],["79793.09000000","0.00000000"],["79765.44000000","0.00000000"],["79757.45000000","0.00000000"],["79755.76000000","0.04533000"],["79751.03000000","0.00017000"],["79749.52000000","0.00000000"],["79714.24000000","1.20000000"],["79696.36000000","0.00000000"],["79667.26000000","2.32631000"],["79656.94000000","0.00000000"],["79585.32000000","0.00026000"],["79576.60000000","0.01894000"],["79511.78000000","0.00270000"],["71901.00000000","0.00016000"],["71899.20000000","0.00008000"]],"a":[["79888.00000000","0.00000000"],["79888.01000000","0.00000000"],["79888.02000000","0.00000000"],["79888.40000000","0.00000000"],["79888.41000000","0.00000000"],["79888.46000000","0.00000000"],["79888.84000000","0.00000000"],["79889.06000000","0.00000000"],["79889.20000000","0.00000000"],["79889.26000000","0.00000000"],["79889.29000000","0.00000000"],["79889.54000000","0.00000000"],["79889.56000000","0.00000000"],["79889.74000000","0.00000000"],["79889.99000000","0.00000000"],["79890.00000000","0.02257000"],["79890.01000000","0.00056000"],["79890.95000000","0.00000000"],["79890.96000000","0.00014000"],["79891.04000000","0.00000000"],["79891.29000000","0.00000000"],["79891.63000000","0.00000000"],["79892.00000000","0.02421000"],["79892.57000000","0.00000000"],["79892.95000000","0.00007000"],["79892.96000000","0.04720000"],["79893.70000000","0.00007000"],["79893.85000000","0.00000000"],["79894.00000000","0.02435000"],["79894.01000000","0.00681000"],["79895.29000000","0.01124000"],["79895.43000000","0.00000000"],["79895.98000000","0.00000000"],["79896.00000000","0.02421000"],["79896.33000000","0.00000000"],["79896.57000000","0.01356000"],["79896.81000000","0.00007000"],["79896.82000000","0.05972000"],["79897.28000000","0.00000000"],["79897.30000000","0.06312000"],["79897.85000000","0.01349000"],["79897.91000000","0.00007000"],["79897.92000000","0.06312000"],["79897.99000000","0.00007000"],["79898.00000000","0.02407000"],["79898.14000000","0.00928000"],["79898.35000000","0.00702000"],["79898.36000000","0.06312000"],["79898.40000000","0.00000000"],["79898.97000000","0.00007000"],["79898.98000000","0.06319000"],["79899.18000000","0.00007000"],["79899.33000000","0.00202000"],["79899.50000000","0.33812000"],["79899.92000000","0.06049000"],["79899.97000000","0.06325000"],["79901.09000000","0.00000000"],["79901.70000000","0.00000000"],["79902.86000000","0.18180000"],["79903.76000000","0.12854000"],["79904.88000000","0.00000000"],["79905.50000000","0.00000000"],["79906.12000000","0.06306000"],["79906.24000000","0.00000000"],["79906.74000000","0.06306000"],["79907.36000000","0.06306000"],["79907.98000000","0.06306000"],["79908.23000000","0.06307000"],["79908.24000000","0.00000000"],["79915.51000000","0.00250000"],["79916.77000000","0.38960000"],["79923.29000000","2.21467000"],["79928.00000000","0.02407000"],["79928.13000000","0.85495000"],["79928.65000000","0.00000000"],["79929.32000000","0.09272000"],["79930.00000000","0.13035000"],["79930.71000000","0.64064000"],["79933.28000000","0.62566000"],["79937.25000000","0.00400000"],["79940.37000000","0.00000000"],["79943.83000000","0.52094000"],["79944.29000000","0.82119000"],["79957.85000000","0.60824000"],["79957.87000000","0.82105000"],["79959.12000000","0.00000000"],["79967.84000000","0.35969000"],["79968.42000000","0.00000000"],["79986.22000000","0.00000000"],["79986.60000000","0.09383000"],["79995.40000000","0.02804000"],["79997.84000000","0.00007000"],["80002.69000000","0.00012000"],["80009.89000000","0.04524000"],["80012.00000000","0.63103000"],["80012.61000000","0.00023000"],["80014.26000000","0.00000000"],["80039.85000000","0.88302000"],["80121.87000000","0.00007000"],["80125.86000000","0.00007000"],["80196.22000000","0.20250000"],["80217.65000000","7.48141000"],["80296.50000000","0.00420000"]]}}}
{"rx_ns": 13868603188000, "frame": {"stream":"btcusdt@depth@100ms","data":{"e":"depthUpdate","E":1787650863814,"s":"BTCUSDT","U":99118591523,"u":99118591635,"b":[["79889.99000000","6.16076000"],["79889.28000000","0.34909000"],["79888.71000000","0.02025000"],["79888.00000000","1.03258000"],["79887.99000000","2.32742000"],["79887.98000000","1.04953000"],["79887.43000000","0.02419000"],["79887.36000000","0.05702000"],["79886.57000000","0.06418000"],["79886.00000000","0.17959000"],["79885.99000000","0.00448000"],["79885.79000000","0.00000000"],["79885.78000000","0.01768000"],["79885.65000000","0.03224000"],["79885.01000000","0.31878000"],["79884.39000000","0.00000000"],["79884.27000000","0.00000000"],["79883.94000000","0.00000000"],["79883.77000000","0.00000000"],["79883.56000000","0.00000000"],["79881.77000000","0.00924000"],["79881.68000000","0.08583000"],["79880.78000000","0.02807000"],["79880.69000000","0.02600000"],["79879.90000000","0.02000000"],["79876.78000000","0.02400000"],["79876.33000000","0.02200000"],["79875.94000000","0.02200000"],["79875.92000000","0.02000000"],["79873.98000000","2.18621000"],["79873.48000000","0.51192000"],["79872.39000000","0.00000000"],["79828.28000000","0.00500000"],["79787.05000000","0.00000000"],["79786.30000000","0.00000000"],["79765.44000000","0.20250000"],["79757.45000000","0.20250000"],["79660.93000000","0.00000000"],["71901.00000000","0.00032000"]],"a":[["79890.00000000","0.02284000"],["79890.01000000","0.00049000"],["79890.96000000","0.00000000"],["79892.00000000","0.02421000"],["79892.96000000","0.04734000"],["79894.00000000","0.02435000"],["79894.01000000","0.00695000"],["79895.29000000","0.01138000"],["79896.00000000","0.02442000"],["79896.19000000","0.00007000"],["79896.20000000","0.06306000"],["79896.57000000","0.01363000"],["79896.82000000","0.05979000"],["79897.30000000","0.06319000"],["79898.97000000","0.00000000"],["79899.97000000","0.06318000"],["79900.29000000","0.06112000"],["79902.86000000","0.00000000"],["79907.95000000","0.06306000"],["79907.96000000","1.02048000"],["79907.97000000","1.04939000"],["79907.98000000","0.00000000"],["79908.23000000","0.00000000"],["79908.52000000","0.00000000"],["79948.93000000","0.02000000"],["79949.53000000","0.02000000"],["79950.33000000","0.02000000"],["79953.48000000","0.02000000"],["79954.37000000","0.02000000"],["79958.42000000","0.00400000"],["79961.51000000","0.02000000"],["79961.93000000","0.02000000"],["80125.86000000","0.00000000"]]}}}
{"rx_ns": 13868700066000, "frame": {"stream":"btcusdt@depth@100ms","data":{"e":"depthUpdate","E":1787650863914,"s":"BTCUSDT","U":99118591636,"u":99118591658,"b":[["79880.72000000","0.02400000"],["79878.80000000","0.00000000"],["79837.77000000","0.00012000"],["79833.78000000","0.00000000"],["79795.98000000","0.00000000"],["79795.14000000","0.00000000"],["71901.00000000","0.00048000"],["71900.00000000","0.42791000"]],"a":[["79893.73000000","0.00267000"],["79893.77000000","0.00000000"],["79896.00000000","0.02442000"],["79896.20000000","0.06313000"],["79896.82000000","0.05972000"],["79899.17000000","0.18507000"],["79900.29000000","0.00000000"],["79910.96000000","0.00000000"],["79913.79000000","0.04000000"],["80005.38000000","0.00018000"],["80009.55000000","0.00031000"]]}}}
{"rx_ns": 13868800735000, "frame": {"stream":"btcusdt@depth20","data":{"lastUpdateId":99118591732,"bids":[["79889.99000000","5.85167000"],["79889.98000000","0.00027000"],["79889.97000000","0.00013000"],["79889.73000000","0.00007000"],["79889.53000000","0.00007000"],["79889.28000000","0.34909000"],["79889.05000000","0.00007000"],["79888.71000000","0.02025000"],["79888.47000000","0.00007000"],["79888.45000000","0.00007000"],["79888.41000000","0.00014000"],["79888.39000000","0.00007000"],["79888.00000000","1.31378000"],["79887.99000000","2.32742000"],["79887.98000000","1.04953000"],["79887.43000000","0.02419000"],["79887.36000000","0.05702000"],["79886.58000000","0.23637000"],["79886.57000000","0.06418000"],["79886.15000000","0.02405000"]],"asks":[["79890.00000000","0.02298000"],["79890.01000000","0.00056000"],["79891.98000000","0.00014000"],["79891.99000000","0.00007000"],["79892.00000000","0.02421000"],["79892.28000000","0.00007000"],["79892.46000000","0.00007000"],["79892.81000000","0.00112000"],["79892.95000000","0.00007000"],["79892.96000000","0.04734000"],["79893.08000000","0.00137000"],["79893.70000000","0.00007000"],["79893.71000000","0.00007000"],["79893.73000000","0.00267000"],["79893.88000000","0.00007000"],["79893.99000000","0.00007000"],["79894.00000000","0.02435000"],["79894.01000000","0.00695000"],["79894.69000000","0.00007000"],["79894.74000000","0.00007000"]]}}}
{"rx_ns": 13868800831000, "frame": {"stream":"btcusdt@depth@100ms","data":{"e":"depthUpdate","E":1787650864014,"s":"BTCUSDT","U":99118591659,"u":99118591732,"b":[["79889.99000000","5.85167000"],["79888.00000000","1.31378000"],["79885.01000000","0.44395000"],["79884.00000000","0.00013000"],["79882.12000000","0.36586000"],["79881.44000000","0.00007000"],["79880.78000000","0.02821000"],["79880.76000000","0.02200000"],["79879.69000000","0.00000000"],["79879.18000000","0.00007000"],["79878.36000000","0.02400000"],["79878.21000000","0.27200000"],["79877.10000000","0.00007000"],["79873.99000000","1.05537000"],["79870.22000000","0.00000000"],["79869.03000000","0.12520000"],["79864.03000000","0.00000000"],["79856.01000000","0.00000000"],["79822.17000000","0.00312000"],["79820.38000000","0.00311000"],["79801.30000000","0.00000000"],["79801.29000000","0.00000000"],["79800.11000000","0.00000000"],["79742.45000000","0.00125000"],["79740.16000000","0.00125000"],["79721.31000000","0.00000000"],["79720.21000000","0.00000000"],["79681.02000000","0.00000000"],["79648.00000000","0.00000000"],["78687.49000000","0.00000000"],["71901.00000000","0.00080000"],["63912.00000000","0.00046000"]],"a":[["79890.00000000","0.02298000"],["79890.01000000","0.00056000"],["79894.96000000","0.06306000"],["79895.29000000","0.01145000"],["79895.57000000","0.00007000"],["79895.58000000","0.06306000"],["79895.99000000","0.00028000"],["79896.01000000","0.00007000"],["79898.35000000","0.00695000"],["79898.98000000","0.06305000"],["79899.18000000","0.00000000"],["79899.33000000","0.00000000"],["79899.50000000","0.00000000"],["79900.99000000","0.12515000"],["79901.99000000","0.00000000"],["79902.01000000","0.00000000"],["79902.60000000","0.00044000"],["79905.50000000","0.06306000"],["79906.54000000","0.00625000"],["79907.94000000","0.19019000"],["79908.60000000","0.00007000"],["79908.68000000","0.00156000"],["79908.98000000","0.12514000"],["79913.54000000","0.00000000"],["79914.95000000","0.00012000"],["79915.23000000","0.00000000"],["79915.59000000","0.08000000"],["79916.76000000","0.25218000"],["79917.07000000","0.12512000"],["79949.98000000","0.00000000"],["79950.27000000","0.02000000"],["79950.33000000","0.04000000"],["79951.61000000","0.00000000"],["79956.80000000","0.00312000"],["79958.32000000","0.00312000"],["79960.22000000","0.02000000"],["79987.56000000","1.18199000"],["79990.39000000","0.00400000"],["79991.43000000","1.99066000"],["80016.23000000","0.00000000"],["80017.63000000","0.00000000"],["80037.02000000","0.00125000"],["80038.51000000","0.00125000"],["81088.35000000","0.00030000"]]}}}
{"rx_ns": 13868896464700, "frame": {"stream":"btcusdt@depth@100ms","data":{"e":"depthUpdate","E":1787650864114,"s":"BTCUSDT","U":99118591733,"u":99118591763,"b":[["79889.99000000","5.96054000"],["79887.99000000","2.24255000"],["79885.01000000","0.44402000"],["79880.77000000","0.02000000"],["79874.78000000","0.00007000"],["79866.86000000","0.00000000"],["79795.17000000","0.00000000"],["79786.17000000","0.00000000"],["79782.64000000","0.00000000"],["79691.62000000","0.00770000"],["79647.23000000","0.00000000"]],"a":[["79892.45000000","0.00007000"],["79894.01000000","0.00702000"],["79894.95000000","0.00007000"],["79894.96000000","0.06320000"],["79895.29000000","0.01138000"],["79895.58000000","0.06313000"],["79896.20000000","0.06306000"],["79896.57000000","0.01356000"],["79897.99000000","0.00000000"],["79898.82000000","0.00000000"],["79906.74000000","0.06313000"],["79910.29000000","0.02000000"],["79921.65000000","0.00000000"],["79972.85000000","0.02000000"]]}}}
{"rx_ns": 13868995883100, "frame": {"stream":"btcusdt@depth@100ms","data":{"e":"depthUpdate","E":1787650864214,"s":"BTCUSDT","U":99118591764,"u":99118591779,"b":[["79889.99000000","5.95436000"],["79889.29000000","0.00625000"],["79889.28000000","0.15405000"],["79878.21000000","0.00000000"],["79874.00000000","0.62598000"],["79869.25000000","0.03948000"],["79859.60000000","0.00000000"],["79854.00000000","0.02400000"],["79811.94000000","0.00400000"],["79782.24000000","0.00000000"],["78691.64000000","0.00125000"],["71901.00000000","0.00112000"],["63912.00000000","0.00015000"]],"a":[["79890.06000000","0.00007000"],["79897.99000000","0.20250000"],["80588.07000000","0.00000000"]]}}}
{"rx_ns": 13869100106200, "frame": {"stream":"btcusdt@depth@100ms","data":{"e":"depthUpdate","E":1787650864314,"s":"BTCUSDT","U":99118591780,"u":99118591818,"b":[["79889.99000000","5.95443000"],["79889.29000000","0.00639000"],["79886.58000000","0.23623000"],["79885.01000000","0.44409000"],["79882.39000000","0.51389000"],["79878.03000000","0.02100000"],["79870.00000000","0.79391000"],["79866.31000000","0.00000000"],["79837.77000000","0.00000000"],["79835.93000000","0.00012000"],["79826.63000000","0.02087000"],["79795.12000000","0.00000000"],["79790.31000000","0.00000000"],["79787.10000000","0.00000000"],["71901.00000000","0.00128000"],["63912.00000000","0.00015000"]],"a":[["79890.00000000","0.02305000"],["79890.01000000","0.00063000"],["79893.72000000","0.06306000"],["79894.33000000","0.00007000"],["79894.34000000","0.06147000"],["79897.91000000","0.00000000"],["79897.99000000","0.20250000"],["79898.05000000","0.05217000"],["79898.14000000","0.00014000"],["79898.35000000","0.00000000"],["79899.17000000","0.00000000"],["79904.88000000","0.06306000"],["79913.11000000","0.00012000"],["79914.95000000","0.00000000"],["79972.85000000","0.00000000"]]}}}
{"rx_ns": 13869200344700, "frame": {"stream":"btcusdt@depth@100ms","data":{"e":"depthUpdate","E":1787650864414,"s":"BTCUSDT","U":99118591819,"u":99118591888,"b":[["79889.99000000","5.94790000"],["79889.29000000","0.00014000"],["79889.28000000","0.00028000"],["79888.72000000","0.00632000"],["79888.48000000","0.00625000"],["79888.01000000","0.00007000"],["79888.00000000","1.31385000"],["79887.99000000","2.24965000"],["79885.02000000","0.00000000"],["79880.78000000","0.02807000"],["79877.80000000","0.00000000"],["79876.17000000","0.00625000"],["79873.99000000","0.42940000"],["79872.39000000","0.62599000"],["79870.00000000","0.09642000"],["79854.28000000","0.00000000"],["79826.63000000","0.00000000"],["79783.86000000","0.00000000"],["71901.00000000","0.00144000"]],"a":[["79890.00000000","0.32738000"],["79892.00000000","0.02428000"],["79892.94000000","0.00007000"],["79892.95000000","0.06313000"],["79892.96000000","0.04741000"],["79893.71000000","0.00014000"],["79893.72000000","0.06320000"],["79894.01000000","0.00709000"],["79894.34000000","0.06154000"],["79895.58000000","0.06306000"],["79896.00000000","0.02428000"],["79896.46000000","0.19814000"],["79896.81000000","0.00000000"],["79897.29000000","0.00000000"],["79898.05000000","0.00000000"],["79898.14000000","0.00007000"],["79898.36000000","0.06305000"],["79899.20000000","0.00910000"],["79900.02000000","0.00014000"],["79900.25000000","0.00043000"],["79900.98000000","0.00022000"],["79902.60000000","0.00000000"],["79902.61000000","0.00000000"],["79945.29000000","0.34690000"],["79947.99000000","0.25620000"],["79949.41000000","0.51594000"],["79987.56000000","2.11388000"],["79988.79000000","3.43796000"],["80002.69000000","0.00000000"],["80110.27000000","0.00400000"],["80137.42000000","3.43158000"]]}}}
{"rx_ns": 13869296096400, "frame": {"stream":"btcusdt@depth@100ms","data":{"e":"depthUpdate","E":1787650864514,"s":"BTCUSDT","U":99118591889,"u":99118591951,"b":[["79889.99000000","5.94804000"],["79889.29000000","0.00000000"],["79889.28000000","0.00014000"],["79888.72000000","0.00021000"],["79888.71000000","0.02032000"],["79888.48000000","0.00632000"],["79887.44000000","0.00625000"],["79887.43000000","0.02426000"],["79885.02000000","0.00000000"],["79874.01000000","0.00007000"],["79857.31000000","0.00000000"],["79757.23000000","0.00000000"],["71901.00000000","0.00144000"],["71899.20000000","0.00000000"],["71899.19000000","0.00008000"],["63912.00000000","0.00046000"],["63911.99000000","0.00000000"]],"a":[["79890.00000000","0.32731000"],["79890.01000000","0.00070000"],["79892.00000000","0.02421000"],["79892.95000000","0.06320000"],["79894.34000000","0.06161000"],["79895.29000000","0.01131000"],["79895.55000000","0.00007000"],["79895.56000000","0.04765000"],["79896.01000000","0.00000000"],["79896.19000000","0.00000000"],["79896.46000000","0.00000000"],["79896.81000000","0.00000000"],["79902.01000000","0.00007000"],["79902.17000000","0.00625000"],["79906.54000000","0.00000000"],["79928.91000000","0.50634000"],["79929.01000000","0.33787000"],["79938.72000000","0.00000000"],["79947.99000000","0.24838000"],["79984.21000000","0.11785000"],["79998.59000000","0.00556000"],["80005.38000000","0.00000000"]]}}}
{"rx_ns": 13869400359300, "frame": {"stream":"btcusdt@depth@100ms","data":{"e":"depthUpdate","E":1787650864614,"s":"BTCUSDT","U":99118591952,"u":99118591982,"b":[["79889.99000000","5.94441000"],["79888.72000000","0.00007000"],["79888.71000000","0.02719000"],["79888.48000000","0.00639000"],["79887.98000000","1.04953000"],["79887.44000000","0.00639000"],["71901.00000000","0.00160000"],["63912.00000000","0.00015000"],["63911.99000000","0.00000000"]],"a":[["79890.00000000","0.32353000"],["79890.01000000","0.00083000"],["79890.02000000","0.00013000"],["79892.00000000","0.02428000"],["79896.81000000","0.16887000"],["80038.34000000","0.00400000"]]}}}
{"rx_ns": 13869498127600, "frame": {"stream":"btcusdt@depth@100ms","data":{"e":"depthUpdate","E":1787650864714,"s":"BTCUSDT","U":99118591983,"u":99118592006,"b":[["79889.99000000","5.94703000"],["79889.28000000","0.00042000"],["79867.69000000","0.09230000"],["79863.79000000","0.00000000"],["79761.22000000","0.00012000"],["71901.00000000","0.00144000"]],"a":[["79890.00000000","0.27473000"],["79890.06000000","0.00000000"],["79895.99000000","0.00020000"],["79898.00000000","0.02415000"],["79900.25000000","0.00000000"],["79901.06000000","0.00043000"],["79904.88000000","0.00000000"]]}}}
{"rx_ns": 13869596672500, "frame": {"stream":"btcusdt@depth@100ms","data":{"e":"depthUpdate","E":1787650864814,"s":"BTCUSDT","U":99118592007,"u":99118592066,"b":[["79888.48000000","0.00646000"],["79888.01000000","0.00000000"],["79888.00000000","1.31378000"],["79887.99000000","2.24958000"],["79660.22000000","0.00400000"],["71901.00000000","0.00176000"]],"a":[["79890.00000000","0.27486000"],["79890.01000000","0.00076000"],["79892.94000000","0.00000000"],["79892.95000000","0.00014000"],["79893.71000000","0.00007000"],["79893.72000000","0.00014000"],["79894.33000000","0.00007000"],["79894.34000000","0.06320000"],["79894.95000000","0.00007000"],["79894.96000000","0.06320000"],["79895.55000000","0.00000000"],["79895.56000000","0.00000000"],["79896.19000000","0.00007000"],["79896.57000000","0.01356000"],["79896.79000000","0.00007000"],["79896.80000000","0.06306000"],["79896.81000000","0.00000000"],["79896.82000000","0.00000000"],["79897.29000000","0.00000000"],["79897.91000000","0.00000000"],["79898.00000000","0.02408000"],["79898.14000000","0.00000000"],["79898.36000000","0.00000000"],["79898.68000000","0.05890000"],["79902.17000000","0.00000000"],["79903.76000000","0.11222000"],["79904.09000000","0.00625000"],["79905.50000000","0.06306000"],["79906.12000000","0.06306000"]]}}}
{"rx_ns": 13869696320100, "frame": {"stream":"btcusdt@depth@100ms","data":{"e":"depthUpdate","E":1787650864914,"s":"BTCUSDT","U":99118592067,"u":99118592105,"b":[["79888.01000000","0.00007000"],["79888.00000000","1.31385000"],["79887.99000000","2.24965000"],["79691.62000000","0.00000000"],["79688.21000000","0.00770000"],["71901.00000000","0.00192000"]],"a":[["79890.00000000","0.27472000"],["79892.00000000","0.02428000"],["79892.95000000","0.06313000"],["79892.96000000","0.04741000"],["79893.71000000","0.00014000"],["79893.72000000","0.06306000"],["79895.29000000","0.01145000"],["79895.58000000","0.06313000"],["79904.88000000","0.06306000"],["79912.82000000","0.09460000"],["79914.82000000","0.10363000"],["79996.18000000","0.74901000"],["79997.27000000","1.95350000"],["80006.70000000","0.00012000"],["80009.39000000","0.00018000"]]}}}
{"rx_ns": 13869796251800, "frame": {"stream":"btcusdt@depth20","data":{"lastUpdateId":99118592157,"bids":[["79889.99000000","5.94703000"],["79889.98000000","0.00027000"],["79889.97000000","0.00013000"],["79889.73000000","0.00007000"],["79889.53000000","0.00007000"],["79889.28000000","0.00042000"],["79889.05000000","0.00007000"],["79888.72000000","0.00007000"],["79888.71000000","0.02719000"],["79888.48000000","0.00646000"],["79888.47000000","0.00007000"],["79888.45000000","0.00007000"],["79888.41000000","0.00014000"],["79888.39000000","0.00007000"],["79888.01000000","0.00007000"],["79888.00000000","1.31385000"],["79887.99000000","2.24965000"],["79887.98000000","1.04953000"],["79887.44000000","0.00639000"],["79887.43000000","0.02426000"]],"asks":[["79890.00000000","0.27479000"],["79890.01000000","0.00083000"],["79890.02000000","0.00013000"],["79891.98000000","0.00014000"],["79891.99000000","0.00007000"],["79892.00000000","0.02428000"],["79892.28000000","0.00007000"],["79892.45000000","0.00007000"],["79892.46000000","0.00007000"],["79892.81000000","0.00112000"],["79892.94000000","0.00007000"],["79892.95000000","0.06327000"],["79892.96000000","0.04741000"],["79893.08000000","0.00137000"],["79893.70000000","0.00007000"],["79893.71000000","0.00014000"],["79893.72000000","0.06313000"],["79893.73000000","0.00267000"],["79893.88000000","0.00007000"],["79893.99000000","0.00007000"]]}}}
{"rx_ns": 13869796384700, "frame": {"stream":"btcusdt@depth@100ms","data":{"e":"depthUpdate","E":1787650865014,"s":"BTCUSDT","U":99118592106,"u":99118592157,"b":[["79882.00000000","0.01200000"],["79881.26000000","0.00007000"],["79880.00000000","0.10605000"],["79878.00000000","0.01200000"],["79876.00000000","0.01200000"],["79875.03000000","0.00007000"],["79874.00000000","0.63298000"],["79872.00000000","0.30707000"],["79870.00000000","0.10342000"],["79868.90000000","0.00000000"],["79868.00000000","0.00700000"],["79867.69000000","0.00000000"],["79780.00000000","0.02800000"],["71901.00000000","0.00176000"],["63912.00000000","0.00046000"]],"a":[["79890.00000000","0.27479000"],["79890.01000000","0.00083000"],["79892.00000000","0.02428000"],["79892.94000000","0.00007000"],["79892.95000000","0.06327000"],["79892.96000000","0.04741000"],["79893.72000000","0.06313000"],["79895.29000000","0.01131000"],["79895.58000000","0.06306000"],["79896.57000000","0.01363000"],["79896.79000000","0.16861000"],["79899.20000000","0.00000000"],["79901.31000000","0.00000000"],["79901.57000000","0.00902000"],["79902.97000000","0.00702000"],["79929.32000000","0.00000000"],["79932.00000000","0.72400000"],["79984.21000000","0.00000000"],["79996.18000000","0.63194000"],["81088.35000000","0.00030000"]]}}}
{"rx_ns": 13869898637000, "frame": {"stream":"btcusdt@depth@100ms","data":{"e":"depthUpdate","E":1787650865114,"s":"BTCUSDT","U":99118592158,"u":99118592199,"b":[["79889.99000000","6.36956000"],["79882.00000000","0.01700000"],["79880.78000000","0.02800000"],["79880.00000000","0.11105000"],["79878.00000000","0.01700000"],["79876.00000000","0.01700000"],["79874.78000000","0.00007000"],["79874.00000000","0.64298000"],["79872.00000000","0.31707000"],["79870.00000000","0.11342000"],["79868.00000000","0.01200000"],["79866.00000000","0.01200000"],["79789.34000000","0.00025000"],["79781.43000000","0.20250000"],["71901.00000000","0.00208000"]],"a":[["79896.79000000","0.32491000"],["79898.51000000","0.18242000"],["79899.19000000","0.42253000"],["79899.97000000","0.00000000"],["79904.88000000","0.00000000"],["79905.50000000","0.00000000"],["79906.12000000","0.00000000"],["79906.74000000","0.00007000"],["79907.95000000","0.00000000"],["79908.01000000","0.00007000"],["79981.14000000","0.00000000"],["79989.07000000","0.00025000"],["80172.54000000","0.00491000"],["80180.41000000","0.00000000"],["80228.75000000","0.01508000"],["80260.76000000","0.01507000"],["80263.83000000","0.00018000"]]}}}
{"rx_ns": 13869997723400, "kind": "control", "ctl": {"op": "ping", "recv_ns": 13869953866600, "pong_ns": 13869954072500, "payload_len": 13, "payload_b64": "MTc4NzY1MDg2NTE3MQ=="}, "frame": null}
{"rx_ns": 13869997723400, "frame": {"stream":"btcusdt@depth@100ms","data":{"e":"depthUpdate","E":1787650865214,"s":"BTCUSDT","U":99118592200,"u":99118592229,"b":[["79889.99000000","6.36973000"],["79870.01000000","0.00010000"],["79868.00000000","0.01700000"],["79866.00000000","0.01700000"],["79865.00000000","0.70000000"],["79851.87000000","0.00000000"],["79816.12000000","0.00000000"],["79811.94000000","0.00000000"],["79810.10000000","0.00020000"],["79780.00000000","0.02400000"],["79732.09000000","0.00000000"],["79660.22000000","0.00000000"],["78691.64000000","0.00125000"],["71901.00000000","0.00208000"],["71900.00000000","0.42811000"],["63912.00000000","0.00015000"]],"a":[["79897.52000000","0.06477000"],["79898.51000000","0.00000000"],["79899.92000000","0.00000000"],["79903.76000000","0.07255000"],["79918.46000000","0.00000000"],["79958.42000000","0.00000000"],["79990.39000000","0.00000000"],["80038.34000000","0.00000000"],["80110.27000000","0.00000000"],["80609.00000000","0.00010000"]]}}}
{"rx_ns": 13870100427400, "frame": {"stream":"btcusdt@depth@100ms","data":{"e":"depthUpdate","E":1787650865314,"s":"BTCUSDT","U":99118592230,"u":99118592242,"b":[["79889.99000000","6.37667000"],["71901.00000000","0.00224000"],["71900.00000000","0.42791000"],["63909.00000000","0.00000000"]],"a":[["79897.99000000","0.00000000"],["79898.98000000","0.00000000"],["79900.98000000","0.00000000"],["79901.56000000","0.00011000"],["79901.57000000","0.00000000"],["79901.76000000","0.00923000"],["79902.97000000","0.00000000"]]}}}
{"rx_ns": 13870204262200, "frame": {"stream":"btcusdt@depth@100ms","data":{"e":"depthUpdate","E":1787650865414,"s":"BTCUSDT","U":99118592243,"u":99118592276,"b":[["79889.99000000","6.37595000"],["79882.00000000","0.02400000"],["79880.00000000","0.11805000"],["79878.00000000","0.02400000"],["79876.00000000","0.02400000"],["79874.00000000","0.64998000"],["79751.03000000","0.00000000"],["79665.76000000","0.00400000"]],"a":[["79890.00000000","0.27472000"],["79890.01000000","0.00076000"],["79892.94000000","0.00000000"],["79892.95000000","0.00021000"],["79893.71000000","0.00007000"],["79893.72000000","0.00007000"],["79894.33000000","0.00000000"],["79894.34000000","0.00014000"],["79896.57000000","0.01356000"],["79896.79000000","0.00007000"],["79897.29000000","0.00007000"],["79897.30000000","0.06326000"],["79899.18000000","0.06306000"],["79899.92000000","0.06306000"],["79899.97000000","0.06306000"],["79906.12000000","0.06306000"],["79906.74000000","0.06313000"],["79907.93000000","0.06306000"],["79976.66000000","0.00000000"],["79992.95000000","0.02476000"]]}}}
{"rx_ns": 13870299363000, "frame": {"stream":"btcusdt@depth@100ms","data":{"e":"depthUpdate","E":1787650865514,"s":"BTCUSDT","U":99118592277,"u":99118592341,"b":[["79889.99000000","6.38213000"],["79888.72000000","0.00000000"],["79888.71000000","0.02032000"],["79888.48000000","0.01284000"],["79888.01000000","0.00000000"],["79888.00000000","1.31378000"],["79887.99000000","2.24958000"],["79887.44000000","0.00014000"],["79872.00000000","0.32407000"],["79870.00000000","0.12042000"],["79868.00000000","0.02400000"],["79866.60000000","0.00008000"],["79866.00000000","0.02400000"],["79860.29000000","0.00000000"],["79759.28000000","0.00000000"],["79755.43000000","0.00016000"],["71901.00000000","0.00240000"],["63912.00000000","0.00046000"],["63911.99000000","0.00000000"]],"a":[["79890.00000000","0.27465000"],["79890.01000000","0.00069000"],["79892.00000000","0.02428000"],["79892.95000000","0.00007000"],["79892.96000000","0.04734000"],["79893.72000000","0.00000000"],["79894.01000000","0.00702000"],["79894.34000000","0.00000000"],["79894.95000000","0.00000000"],["79894.96000000","0.00014000"],["79895.29000000","0.01145000"],["79895.58000000","0.06320000"],["79896.00000000","0.02435000"],["79897.51000000","0.00007000"],["79899.92000000","0.00000000"],["79899.97000000","0.00000000"],["79901.76000000","0.00000000"],["79906.12000000","0.00000000"],["79910.39000000","0.00000000"],["79910.99000000","0.00000000"],["79913.49000000","0.03000000"],["79932.81000000","0.33786000"],["79932.92000000","0.09475000"],["79992.82000000","0.11934000"]]}}}
{"rx_ns": 13870408564800, "frame": {"stream":"btcusdt@depth@100ms","data":{"e":"depthUpdate","E":1787650865614,"s":"BTCUSDT","U":99118592342,"u":99118592382,"b":[["79889.99000000","6.39117000"],["79888.48000000","0.01277000"],["79887.98000000","1.04953000"],["79887.44000000","0.00000000"],["79887.36000000","0.05709000"],["79886.58000000","0.23630000"],["79755.76000000","0.00000000"],["79653.11000000","0.01960000"],["79636.66000000","0.00000000"],["71901.00000000","0.00240000"],["63912.00000000","0.00015000"],["63911.99000000","0.00000000"]],"a":[["79890.00000000","0.27253000"],["79894.01000000","0.00702000"],["79894.34000000","0.06306000"],["79894.95000000","0.00007000"],["79894.96000000","0.06306000"],["79896.00000000","0.02442000"],["79896.20000000","0.06313000"],["79897.99000000","0.20250000"],["79899.92000000","0.06306000"],["79899.97000000","0.06306000"],["79902.01000000","0.00000000"],["79906.12000000","0.06306000"],["79995.40000000","0.00000000"],["79995.95000000","0.00400000"]]}}}
{"rx_ns": 13870516982200, "frame": {"stream":"btcusdt@depth@100ms","data":{"e":"depthUpdate","E":1787650865714,"s":"BTCUSDT","U":99118592383,"u":99118592415,"b":[["79888.72000000","0.00007000"],["79888.49000000","0.00007000"],["79888.01000000","0.00007000"],["79888.00000000","1.31385000"],["79887.99000000","2.24965000"],["79767.41000000","0.04408000"],["71901.00000000","0.00256000"]],"a":[["79890.00000000","0.27476000"],["79890.01000000","0.00076000"],["79890.04000000","0.01080000"],["79892.96000000","0.04741000"],["79893.71000000","0.00014000"],["79893.72000000","0.06306000"],["79894.01000000","0.00709000"],["79894.33000000","0.00007000"],["79894.34000000","0.06320000"],["79894.96000000","0.06313000"],["79896.00000000","0.02428000"],["79896.20000000","0.06306000"],["79897.29000000","0.00000000"],["79897.30000000","0.06333000"],["79897.51000000","0.27365000"],["79901.56000000","0.00000000"],["80007.08000000","0.02804000"]]}}}
{"rx_ns": 13870599514300, "frame": {"stream":"btcusdt@depth@100ms","data":{"e":"depthUpdate","E":1787650865814,"s":"BTCUSDT","U":99118592416,"u":99118592436,"b":[["71901.00000000","0.00256000"]],"a":[["79890.00000000","0.27497000"],["79890.03000000","0.00007000"],["79890.04000000","0.01094000"],["79892.94000000","0.00007000"],["79892.95000000","0.06313000"],["79892.96000000","0.04741000"],["79895.29000000","0.01131000"],["79895.58000000","0.06306000"],["79896.19000000","0.00000000"],["79896.79000000","0.00000000"],["80115.83000000","0.00400000"]]}}}
{"rx_ns": 13870697801000, "frame": {"stream":"btcusdt@depth@100ms","data":{"e":"depthUpdate","E":1787650865914,"s":"BTCUSDT","U":99118592437,"u":99118592561,"b":[["79889.99000000","6.54749000"],["79888.72000000","0.00000000"],["79888.49000000","0.00000000"],["79888.48000000","0.00014000"],["79888.01000000","0.00000000"],["79888.00000000","1.31378000"],["79887.99000000","2.09958000"],["79877.86000000","0.28542000"],["79874.00000000","0.02400000"],["79866.52000000","0.09339000"],["79847.50000000","0.33235000"],["79846.27000000","0.00000000"],["79743.09000000","0.00202000"],["71901.00000000","0.00272000"],["71899.19000000","0.00000000"]],"a":[["79890.00000000","0.27495000"],["79890.01000000","0.00069000"],["79892.00000000","0.02428000"],["79892.94000000","0.00000000"],["79892.95000000","0.00014000"],["79892.96000000","0.04734000"],["79893.71000000","0.00007000"],["79893.72000000","0.00000000"],["79894.01000000","0.00702000"],["79894.33000000","0.00000000"],["79894.34000000","0.00014000"],["79894.95000000","0.00000000"],["79894.96000000","0.00000000"],["79895.29000000","0.01124000"],["79895.57000000","0.00000000"],["79895.58000000","0.00000000"],["79896.00000000","0.02421000"],["79896.20000000","0.00000000"],["79896.57000000","0.01356000"],["79896.80000000","0.00000000"],["79896.81000000","0.00007000"],["79896.82000000","0.06313000"],["79897.28000000","0.00007000"],["79897.29000000","0.06306000"],["79897.30000000","0.00014000"],["79897.51000000","0.00000000"],["79897.52000000","0.00000000"],["79897.85000000","0.01356000"],["79897.92000000","0.00007000"],["79897.98000000","0.00007000"],["79897.99000000","0.26563000"],["79898.00000000","0.02415000"],["79898.68000000","0.06306000"],["79899.18000000","0.06306000"],["79899.19000000","0.00000000"],["79899.92000000","0.06306000"],["79899.97000000","0.06313000"],["79900.02000000","0.00014000"],["79900.14000000","0.42253000"],["79901.06000000","0.00000000"],["79901.86000000","0.00067000"],["79903.76000000","0.11559000"],["79905.50000000","0.06306000"],["79906.12000000","0.06306000"],["79906.74000000","0.06313000"],["79907.36000000","0.06306000"],["79907.93000000","0.06306000"],["79913.49000000","0.01000000"],["79913.79000000","0.00000000"],["79914.59000000","0.06000000"],["79932.92000000","0.00000000"],["79933.97000000","0.09365000"],["79938.72000000","0.00000000"],["79942.47000000","0.00000000"],["79992.82000000","0.00000000"],["79993.79000000","0.12332000"],["80055.48000000","0.00202000"]]}}}
{"rx_ns": 13870799801800, "frame": {"stream":"btcusdt@depth20","data":{"lastUpdateId":99118592611,"bids":[["79889.99000000","6.54749000"],["79889.98000000","0.00027000"],["79889.97000000","0.00013000"],["79889.73000000","0.00007000"],["79889.53000000","0.00007000"],["79889.28000000","0.00042000"],["79889.05000000","0.00007000"],["79888.71000000","0.02025000"],["79888.47000000","0.00007000"],["79888.45000000","0.00007000"],["79888.41000000","0.00014000"],["79888.39000000","0.00007000"],["79888.00000000","1.31378000"],["79887.99000000","2.09958000"],["79887.98000000","1.04953000"],["79887.43000000","0.02426000"],["79887.36000000","0.05709000"],["79886.58000000","0.23630000"],["79886.57000000","0.06425000"],["79886.15000000","0.02405000"]],"asks":[["79890.00000000","0.27488000"],["79890.01000000","0.00062000"],["79890.02000000","0.00013000"],["79890.03000000","0.00007000"],["79890.04000000","0.01094000"],["79891.98000000","0.00014000"],["79891.99000000","0.00007000"],["79892.00000000","0.02428000"],["79892.28000000","0.00007000"],["79892.45000000","0.00007000"],["79892.46000000","0.00007000"],["79892.81000000","0.00112000"],["79892.95000000","0.00007000"],["79892.96000000","0.04734000"],["79893.08000000","0.00137000"],["79893.70000000","0.00007000"],["79893.71000000","0.00007000"],["79893.73000000","0.00267000"],["79893.88000000","0.00007000"],["79893.99000000","0.00007000"]]}}}
{"rx_ns": 13870799906800, "frame": {"stream":"btcusdt@depth@100ms","data":{"e":"depthUpdate","E":1787650866014,"s":"BTCUSDT","U":99118592562,"u":99118592611,"b":[["79888.71000000","0.02025000"],["79888.48000000","0.00000000"],["79886.57000000","0.06425000"],["79883.33000000","0.00007000"],["79882.04000000","0.39221000"],["79877.86000000","0.00000000"],["79874.00000000","0.64998000"],["79868.80000000","0.00007000"],["79826.63000000","0.02087000"],["63912.00000000","0.00046000"]],"a":[["79890.00000000","0.27488000"],["79890.01000000","0.00062000"],["79892.00000000","0.02428000"],["79892.95000000","0.00007000"],["79892.96000000","0.04734000"],["79894.01000000","0.00695000"],["79894.34000000","0.00000000"],["79895.29000000","0.01138000"],["79896.00000000","0.02435000"],["79896.19000000","0.00007000"],["79896.20000000","0.06306000"],["79896.57000000","0.01363000"],["79897.99000000","0.26556000"],["79898.67000000","0.00014000"],["79899.97000000","0.06306000"],["79905.50000000","0.00000000"],["79963.98000000","0.00400000"],["81088.35000000","0.00030000"]]}}}
{"rx_ns": 13870900116500, "frame": {"stream":"btcusdt@depth@100ms","data":{"e":"depthUpdate","E":1787650866114,"s":"BTCUSDT","U":99118592612,"u":99118592631,"b":[["79888.71000000","0.02032000"],["79888.47000000","0.00655000"],["79874.78000000","0.00000000"],["79853.65000000","0.83200000"],["79826.63000000","0.00000000"],["79688.21000000","0.00000000"],["79683.67000000","0.00770000"],["71901.00000000","0.00288000"]],"a":[["79896.00000000","0.02435000"],["79896.20000000","0.06313000"],["79896.57000000","0.01356000"],["79897.99000000","0.06306000"],["79900.45000000","0.15551000"],["79902.01000000","0.00007000"],["79906.12000000","0.00000000"],["79906.74000000","0.06306000"],["79947.99000000","0.48247000"],["79949.86000000","0.83100000"],["82150.00000000","0.86715000"]]}}}
{"rx_ns": 13871000468500, "frame": {"stream":"btcusdt@depth@100ms","data":{"e":"depthUpdate","E":1787650866214,"s":"BTCUSDT","U":99118592632,"u":99118592666,"b":[["79888.71000000","0.02032000"],["79888.47000000","0.00662000"],["79886.57000000","0.06418000"],["79874.78000000","0.00007000"],["79867.08000000","0.00000000"],["79866.52000000","0.00000000"],["79844.24000000","0.09483000"],["78691.64000000","0.00125000"],["73465.69000000","0.00014000"],["71901.00000000","0.00288000"],["63912.00000000","0.00015000"]],"a":[["79899.43000000","0.06923000"],["79899.98000000","0.48880000"],["79900.45000000","0.00000000"],["79903.76000000","0.08382000"],["79906.74000000","0.06313000"],["79933.97000000","0.00000000"],["79934.21000000","0.00000000"],["79934.51000000","0.00000000"],["79936.86000000","0.09266000"],["79993.79000000","0.00000000"],["80043.90000000","0.00400000"]]}}}
{"rx_ns": 13871099222700, "frame": {"stream":"btcusdt@depth@100ms","data":{"e":"depthUpdate","E":1787650866314,"s":"BTCUSDT","U":99118592667,"u":99118592676,"b":[["71901.00000000","0.00296000"],["63912.00000000","0.00015000"]],"a":[["79890.00000000","0.25610000"],["79897.99000000","0.06306000"],["79906.74000000","0.00007000"],["79907.36000000","0.00000000"]]}}}
{"rx_ns": 13871196018300, "frame": {"stream":"btcusdt@depth@100ms","data":{"e":"depthUpdate","E":1787650866414,"s":"BTCUSDT","U":99118592677,"u":99118592685,"b":[["79857.42000000","0.00400000"],["79745.49000000","0.00000000"],["79568.31000000","0.01515000"],["79508.13000000","0.00000000"],["71901.00000000","0.00328000"],["71900.00000000","0.42811000"]],"a":[["79897.99000000","0.26556000"],["79903.76000000","0.04620000"]]}}}
{"rx_ns": 13871295959200, "frame": {"stream":"btcusdt@depth@100ms","data":{"e":"depthUpdate","E":1787650866514,"s":"BTCUSDT","U":99118592686,"u":99118592698,"b":[["79889.99000000","6.54408000"],["79889.06000000","0.00625000"],["79888.47000000","0.00014000"],["79826.63000000","0.00000000"],["71901.00000000","0.00328000"],["71900.00000000","0.42791000"],["63912.00000000","0.00046000"],["63911.99000000","0.00000000"]],"a":[]}}}
{"rx_ns": 13871400279900, "frame": {"stream":"btcusdt@depth@100ms","data":{"e":"depthUpdate","E":1787650866614,"s":"BTCUSDT","U":99118592699,"u":99118592714,"b":[["79889.99000000","6.54415000"],["79889.06000000","0.00639000"],["79888.71000000","0.02025000"],["79888.47000000","0.00007000"],["79785.54000000","0.00400000"],["79705.61000000","0.00000000"],["71901.00000000","0.00328000"],["63912.00000000","0.00015000"]],"a":[]}}}
{"rx_ns": 13871496015900, "frame": {"stream":"btcusdt@depth@100ms","data":{"e":"depthUpdate","E":1787650866714,"s":"BTCUSDT","U":99118592715,"u":99118592725,"b":[["71901.00000000","0.00344000"],["63911.99000000","0.00000000"]],"a":[["79890.00000000","0.25617000"],["79895.29000000","0.01145000"],["79895.57000000","0.00007000"],["79895.58000000","0.06306000"],["79898.67000000","0.00007000"],["79902.01000000","0.00000000"],["79907.36000000","0.06306000"],["79993.80000000","0.12287000"]]}}}
{"rx_ns": 13871600678400, "frame": {"stream":"btcusdt@depth@100ms","data":{"e":"depthUpdate","E":1787650866814,"s":"BTCUSDT","U":99118592726,"u":99118592745,"b":[["73465.69000000","0.00000000"],["71901.00000000","0.00352000"],["71900.99000000","0.00008000"]],"a":[["79890.00000000","0.23108000"],["79894.01000000","0.00702000"],["79894.95000000","0.00007000"],["79894.96000000","0.05672000"],["79895.29000000","0.01145000"],["79895.58000000","0.06313000"],["79896.20000000","0.06306000"],["79897.98000000","0.00000000"],["79897.99000000","0.06306000"],["79924.01000000","0.00400000"],["80001.09000000","0.00000000"]]}}}
{"rx_ns": 13871700074300, "frame": {"stream":"btcusdt@depth@100ms","data":{"e":"depthUpdate","E":1787650866914,"s":"BTCUSDT","U":99118592746,"u":99118592760,"b":[["79889.99000000","6.54402000"],["79888.71000000","0.02032000"],["71901.00000000","0.00352000"]],"a":[["79890.00000000","0.23094000"],["79894.01000000","0.00702000"],["79894.96000000","0.05686000"],["79896.00000000","0.02428000"],["79897.99000000","0.26556000"],["79907.36000000","0.00000000"]]}}}
{"rx_ns": 13871800729500, "frame": {"stream":"btcusdt@depth20","data":{"lastUpdateId":99118592771,"bids":[["79889.99000000","6.54402000"],["79889.98000000","0.00027000"],["79889.97000000","0.00013000"],["79889.73000000","0.00007000"],["79889.53000000","0.00007000"],["79889.28000000","0.00042000"],["79889.06000000","0.00639000"],["79889.05000000","0.00007000"],["79888.71000000","0.02032000"],["79888.47000000","0.00007000"],["79888.45000000","0.00007000"],["79888.41000000","0.00014000"],["79888.39000000","0.00007000"],["79888.00000000","1.31378000"],["79887.99000000","2.09958000"],["79887.98000000","1.04953000"],["79887.43000000","0.02426000"],["79887.36000000","0.05709000"],["79886.58000000","0.23630000"],["79886.57000000","0.06418000"]],"asks":[["79890.00000000","0.23094000"],["79890.01000000","0.00062000"],["79890.02000000","0.00013000"],["79890.03000000","0.00007000"],["79890.04000000","0.01094000"],["79891.98000000","0.00014000"],["79891.99000000","0.00007000"],["79892.00000000","0.02428000"],["79892.28000000","0.00007000"],["79892.45000000","0.00007000"],["79892.46000000","0.00007000"],["79892.81000000","0.00112000"],["79892.95000000","0.00007000"],["79892.96000000","0.04734000"],["79893.08000000","0.00137000"],["79893.70000000","0.00007000"],["79893.71000000","0.00007000"],["79893.73000000","0.00267000"],["79893.88000000","0.00007000"],["79893.99000000","0.00007000"]]}}}
{"rx_ns": 13871800832400, "frame": {"stream":"btcusdt@depth@100ms","data":{"e":"depthUpdate","E":1787650867014,"s":"BTCUSDT","U":99118592761,"u":99118592771,"b":[["79817.49000000","0.00400000"],["79812.49000000","0.62569000"],["79780.81000000","0.00000000"],["71901.00000000","0.00368000"],["63912.00000000","0.00046000"]],"a":[["79996.18000000","0.18857000"],["79997.27000000","0.00000000"],["81088.35000000","0.00030000"],["83126.33000000","0.00000000"]]}}}
{"rx_ns": 13871895973800, "frame": {"stream":"btcusdt@depth@100ms","data":{"e":"depthUpdate","E":1787650867114,"s":"BTCUSDT","U":99118592772,"u":99118592787,"b":[["79885.41000000","0.00007000"],["79866.72000000","0.00007000"],["79827.73000000","0.00070000"],["79755.14000000","0.00000000"],["79747.84000000","0.00088000"],["79675.33000000","0.00000000"],["79667.95000000","0.00088000"],["79595.51000000","0.00000000"],["79588.06000000","0.00088000"],["79515.69000000","0.00000000"],["79508.17000000","0.00088000"],["79435.87000000","0.00000000"],["71901.00000000","0.00368000"]],"a":[["79955.57000000","0.00070000"],["79962.68000000","0.00000000"],["80035.46000000","0.00088000"],["80041.09000000","0.00000000"],["80042.50000000","0.00000000"],["80115.35000000","0.00088000"],["80122.32000000","0.00010000"],["80195.24000000","0.00088000"],["80202.14000000","0.00000000"],["80275.13000000","0.00100000"]]}}}
{"rx_ns": 13871996474500, "frame": {"stream":"btcusdt@depth@100ms","data":{"e":"depthUpdate","E":1787650867214,"s":"BTCUSDT","U":99118592788,"u":99118592804,"b":[["79874.78000000","0.00007000"],["79826.63000000","0.02087000"],["79817.49000000","0.00000000"],["79737.63000000","0.00400000"],["79695.98000000","0.00000000"],["78691.64000000","0.00125000"],["71901.00000000","0.00384000"],["63912.00000000","0.00015000"]],"a":[["79897.99000000","0.06306000"],["79906.74000000","0.00007000"],["79907.36000000","0.06306000"],["79943.59000000","0.00000000"],["80062.79000000","0.00000000"]]}}}
{"rx_ns": 13872095967300, "frame": {"stream":"btcusdt@depth@100ms","data":{"e":"depthUpdate","E":1787650867314,"s":"BTCUSDT","U":99118592805,"u":99118592809,"b":[["79889.99000000","6.54411000"],["79882.00000000","0.02408000"],["79826.63000000","0.00000000"],["63912.00000000","0.00015000"]],"a":[]}}}
{"rx_ns": 13872200320600, "frame": {"stream":"btcusdt@depth@100ms","data":{"e":"depthUpdate","E":1787650867414,"s":"BTCUSDT","U":99118592810,"u":99118592823,"b":[["79889.99000000","6.53992000"],["79817.68000000","0.00400000"],["79720.34000000","4.43119000"],["71901.00000000","0.00400000"]],"a":[["79897.99000000","0.26556000"],["79903.76000000","0.07794000"],["79906.74000000","0.06313000"],["79938.72000000","0.00007000"],["79992.95000000","0.00000000"],["79999.70000000","0.02466000"],["80087.31000000","4.47962000"]]}}}
{"rx_ns": 13872295894700, "frame": {"stream":"btcusdt@depth@100ms","data":{"e":"depthUpdate","E":1787650867514,"s":"BTCUSDT","U":99118592824,"u":99118592828,"b":[["71901.00000000","0.00400000"],["63912.00000000","0.00046000"]],"a":[["79890.04000000","0.00014000"],["79993.85000000","0.01662000"]]}}}
{"rx_ns": 13872402521500, "frame": {"stream":"btcusdt@depth@100ms","data":{"e":"depthUpdate","E":1787650867614,"s":"BTCUSDT","U":99118592829,"u":99118592902,"b":[["79889.99000000","4.65706000"],["79889.06000000","0.00014000"],["79888.72000000","0.00007000"],["79888.71000000","0.02039000"],["79888.02000000","0.00639000"],["79888.01000000","0.47963000"],["79888.00000000","0.31322000"],["79887.99000000","0.22288000"],["79886.59000000","0.00007000"],["79886.01000000","0.00014000"],["79885.02000000","0.00007000"],["79881.68000000","0.08576000"],["79778.68000000","0.00394000"],["79741.34000000","0.00000000"],["79683.67000000","0.00000000"],["79681.02000000","0.00770000"],["71901.00000000","0.00416000"],["71900.00000000","0.42811000"],["63912.00000000","0.00015000"],["63911.99000000","0.00000000"]],"a":[["79890.00000000","0.54957000"],["79890.01000000","0.00083000"],["79890.03000000","0.00000000"],["79890.04000000","0.00000000"],["79891.85000000","0.00007000"],["79891.86000000","0.06306000"],["79892.47000000","0.00007000"],["79892.48000000","0.06306000"],["79892.94000000","0.00007000"],["79892.95000000","0.06313000"],["79892.96000000","0.04741000"],["79893.71000000","0.00014000"],["79893.72000000","0.06306000"],["79894.33000000","0.00007000"],["79894.34000000","0.05991000"],["79895.58000000","0.06320000"],["79895.99000000","0.00013000"],["79896.00000000","0.02435000"],["79896.19000000","0.00000000"],["79896.81000000","0.00000000"],["79896.87000000","0.06568000"],["79897.28000000","0.00000000"],["79898.00000000","0.02408000"],["79898.61000000","0.00000000"],["79899.43000000","0.00000000"],["79900.35000000","0.00943000"],["79900.38000000","0.00069000"],["79901.86000000","0.00000000"],["79927.32000000","0.00625000"],["79938.72000000","0.00000000"],["79943.68000000","0.00200000"],["79945.20000000","0.00000000"]]}}}
{"rx_ns": 13872496438400, "frame": {"stream":"btcusdt@depth@100ms","data":{"e":"depthUpdate","E":1787650867714,"s":"BTCUSDT","U":99118592903,"u":99118592996,"b":[["79889.99000000","3.74825000"],["79889.06000000","0.00000000"],["79888.71000000","0.02039000"],["79888.02000000","0.00021000"],["79888.01000000","0.47345000"],["79887.36000000","0.05716000"],["79886.60000000","0.00625000"],["79886.58000000","0.16123000"],["79886.02000000","0.00625000"],["79886.01000000","0.00014000"],["79885.02000000","0.00007000"],["79882.00000000","0.02409000"],["79881.77000000","0.00917000"],["79819.44000000","0.26008000"],["79767.41000000","0.00000000"],["71901.00000000","0.00416000"],["71900.00000000","0.42791000"],["63911.99000000","0.00000000"]],"a":[["79890.00000000","0.57754000"],["79891.86000000","0.06320000"],["79892.00000000","0.02428000"],["79892.48000000","0.06320000"],["79892.95000000","0.06327000"],["79892.96000000","0.04741000"],["79893.72000000","0.06313000"],["79894.01000000","0.00695000"],["79894.94000000","0.00007000"],["79894.95000000","0.13822000"],["79894.96000000","0.05672000"],["79895.29000000","0.01131000"],["79895.57000000","0.00000000"],["79895.58000000","0.06306000"],["79896.00000000","0.02428000"],["79896.81000000","0.18679000"],["79896.87000000","0.00000000"],["79899.98000000","1.00165000"],["79901.80000000","0.00693000"],["79903.64000000","1.87677000"],["79903.76000000","0.04620000"],["79906.74000000","0.00007000"],["79907.36000000","0.00000000"],["79907.93000000","0.00000000"],["79907.94000000","0.00000000"],["79911.97000000","0.19019000"],["80007.08000000","0.00000000"]]}}}
{"rx_ns": 13872597956900, "frame": {"stream":"btcusdt@depth@100ms","data":{"e":"depthUpdate","E":1787650867814,"s":"BTCUSDT","U":99118592997,"u":99118593021,"b":[["79889.99000000","3.74825000"],["79888.71000000","0.02039000"],["79888.02000000","0.00014000"],["79888.01000000","0.47352000"],["79887.36000000","0.05709000"],["79886.60000000","0.00632000"],["79886.15000000","0.02412000"],["79758.60000000","0.04532000"],["79702.97000000","0.00841000"],["79667.74000000","0.00000000"],["71901.00000000","0.00432000"]],"a":[["79890.00000000","0.54964000"],["79902.01000000","0.00007000"],["79925.76000000","0.00200000"],["79943.68000000","0.00000000"],["79998.24000000","0.02804000"],["80065.23000000","0.03395000"],["80165.72000000","0.00000000"]]}}}
{"rx_ns": 13872696324100, "frame": {"stream":"btcusdt@depth@100ms","data":{"e":"depthUpdate","E":1787650867914,"s":"BTCUSDT","U":99118593022,"u":99118593025,"b":[["79826.63000000","0.00000000"],["71901.00000000","0.00448000"]],"a":[["79890.00000000","0.55027000"]]}}}
