{"captured_at": "2026-08-25T08:48:08.551494+00:00", "url": "wss://data-stream.binance.vision/stream?streams=btcusdt@depth@100ms/btcusdt@depth20@100ms", "venue": "binance", "symbol": "BTCUSDT", "streams": ["depth@100ms", "depth20@100ms"], "combined": true, "rest_url": "https://data-api.binance.vision/api/v3/depth?symbol=BTCUSDT&limit=1000", "rest_limit": 1000, "rest_weight_per_fetch": 50, "snapshot_every_s": 25.0, "tool_version": "0.1.0", "clock": "perf_counter_ns", "capture_mode": "baseline", "cycles": 1, "origin_sent": null, "handshake_status": "HTTP/1.1 101 Switching Protocols"}
{"rx_ns": 10693754529300, "frame": {"stream":"btcusdt@depth20@100ms","data":{"lastUpdateId":99116115043,"bids":[["79974.46000000","5.05808000"],["79974.45000000","0.00048000"],["79974.44000000","0.00013000"],["79974.27000000","0.00014000"],["79974.26000000","0.06078000"],["79974.25000000","0.11199000"],["79973.70000000","0.00008000"],["79973.55000000","0.00014000"],["79973.07000000","0.00901000"],["79972.95000000","0.00014000"],["79972.94000000","0.08146000"],["79971.87000000","0.00639000"],["79971.86000000","0.00014000"],["79971.85000000","0.33071000"],["79971.84000000","0.41438000"],["79971.83000000","0.00007000"],["79971.81000000","0.00875000"],["79971.79000000","0.01467000"],["79971.76000000","0.00007000"],["79971.50000000","0.04715000"]],"asks":[["79974.47000000","0.22845000"],["79974.48000000","0.00090000"],["79974.49000000","0.00013000"],["79975.55000000","0.00007000"],["79975.73000000","0.00014000"],["79975.74000000","0.01693000"],["79976.00000000","0.00465000"],["79976.68000000","0.00007000"],["79976.84000000","0.00007000"],["79976.93000000","0.00007000"],["79976.94000000","0.01763000"],["79977.01000000","0.00007000"],["79977.02000000","0.02004000"],["79977.09000000","0.00014000"],["79977.10000000","0.05303000"],["79977.17000000","0.00007000"],["79977.18000000","0.00007000"],["79977.42000000","0.00014000"],["79977.99000000","0.00014000"],["79978.00000000","0.03121000"]]}}}
{"rx_ns": 10693754614900, "frame": {"stream":"btcusdt@depth@100ms","data":{"e":"depthUpdate","E":1787647688914,"s":"BTCUSDT","U":99116115029,"u":99116115043,"b":[["79897.41000000","0.02084000"],["71977.02000000","0.00440000"]],"a":[["80001.24000000","0.00000000"],["80005.24000000","0.00399000"],["80041.25000000","0.00000000"],["80045.25000000","0.00399000"],["80073.25000000","0.00000000"],["80077.25000000","0.00399000"],["80121.25000000","0.00000000"],["80125.25000000","0.00399000"],["80193.25000000","0.00000000"],["80197.26000000","0.00416000"]]}}}
{"rx_ns": 10693852906800, "frame": {"stream":"btcusdt@depth20@100ms","data":{"lastUpdateId":99116115060,"bids":[["79974.46000000","5.05808000"],["79974.45000000","0.00048000"],["79974.44000000","0.00013000"],["79974.27000000","0.00014000"],["79974.26000000","0.06078000"],["79974.25000000","0.11199000"],["79973.70000000","0.00008000"],["79973.55000000","0.00014000"],["79973.07000000","0.00901000"],["79972.95000000","0.00014000"],["79972.94000000","0.08146000"],["79971.87000000","0.00639000"],["79971.86000000","0.00014000"],["79971.85000000","0.33071000"],["79971.84000000","0.41438000"],["79971.83000000","0.00007000"],["79971.81000000","0.00875000"],["79971.79000000","0.01467000"],["79971.76000000","0.00007000"],["79971.50000000","0.04715000"]],"asks":[["79974.47000000","0.22595000"],["79974.48000000","0.00090000"],["79974.49000000","0.00013000"],["79975.73000000","0.00014000"],["79975.74000000","0.01693000"],["79976.00000000","0.00465000"],["79976.35000000","0.00007000"],["79976.68000000","0.00007000"],["79976.84000000","0.00007000"],["79976.93000000","0.00007000"],["79976.94000000","0.01763000"],["79977.01000000","0.00007000"],["79977.02000000","0.02004000"],["79977.09000000","0.00014000"],["79977.10000000","0.05303000"],["79977.17000000","0.00007000"],["79977.18000000","0.00007000"],["79977.42000000","0.00014000"],["79977.99000000","0.00014000"],["79978.00000000","0.03121000"]]}}}
{"rx_ns": 10693853014400, "frame": {"stream":"btcusdt@depth@100ms","data":{"e":"depthUpdate","E":1787647689014,"s":"BTCUSDT","U":99116115044,"u":99116115060,"b":[["78774.84000000","0.00030000"],["71977.02000000","0.00456000"],["63979.57000000","0.00031000"]],"a":[["79974.47000000","0.22595000"],["79975.55000000","0.00000000"],["79976.35000000","0.00007000"],["79978.00000000","0.03121000"],["79981.83000000","0.06466000"],["79983.09000000","0.00000000"],["79983.98000000","0.00000000"],["79984.26000000","0.00000000"],["79985.15000000","0.00084000"],["79988.71000000","0.00000000"],["79989.76000000","0.00625000"]]}}}
{"rx_ns": 10693952891600, "frame": {"stream":"btcusdt@depth20@100ms","data":{"lastUpdateId":99116115074,"bids":[["79974.46000000","5.05808000"],["79974.45000000","0.00048000"],["79974.44000000","0.00013000"],["79974.27000000","0.00014000"],["79974.26000000","0.06078000"],["79974.25000000","0.11199000"],["79973.70000000","0.00008000"],["79973.55000000","0.00014000"],["79973.07000000","0.00901000"],["79972.95000000","0.00014000"],["79972.94000000","0.08146000"],["79971.87000000","0.00639000"],["79971.86000000","0.00014000"],["79971.85000000","0.33071000"],["79971.84000000","0.41438000"],["79971.83000000","0.00007000"],["79971.81000000","0.00875000"],["79971.79000000","0.01467000"],["79971.76000000","0.00007000"],["79971.50000000","0.04715000"]],"asks":[["79974.47000000","0.24782000"],["79974.48000000","0.00090000"],["79974.49000000","0.00013000"],["79975.73000000","0.00014000"],["79975.74000000","0.01693000"],["79976.00000000","0.00465000"],["79976.35000000","0.00007000"],["79976.68000000","0.00007000"],["79976.84000000","0.00007000"],["79976.93000000","0.00007000"],["79976.94000000","0.01763000"],["79977.01000000","0.00007000"],["79977.02000000","0.02004000"],["79977.09000000","0.00014000"],["79977.10000000","0.05303000"],["79977.17000000","0.00007000"],["79977.18000000","0.00007000"],["79977.42000000","0.00014000"],["79977.99000000","0.00014000"],["79978.00000000","0.03121000"]]}}}
{"rx_ns": 10693953007800, "frame": {"stream":"btcusdt@depth@100ms","data":{"e":"depthUpdate","E":1787647689114,"s":"BTCUSDT","U":99116115061,"u":99116115074,"b":[["79897.41000000","0.00000000"],["79821.18000000","0.00202000"],["79781.65000000","0.00769000"],["79778.60000000","0.00000000"],["71977.02000000","0.00440000"]],"a":[["79974.47000000","0.24782000"],["79983.50000000","0.00585000"],["80016.67000000","0.54460000"],["80133.52000000","0.00202000"]]}}}
{"rx_ns": 10694054885000, "frame": {"stream":"btcusdt@depth20@100ms","data":{"lastUpdateId":99116115106,"bids":[["79974.46000000","5.07072000"],["79974.45000000","0.00048000"],["79974.44000000","0.00013000"],["79974.29000000","0.09879000"],["79974.28000000","0.12770000"],["79974.26000000","0.00028000"],["79974.25000000","0.11199000"],["79973.70000000","0.00008000"],["79973.55000000","0.00014000"],["79973.07000000","0.00901000"],["79972.95000000","0.00014000"],["79972.94000000","0.08146000"],["79971.87000000","0.00639000"],["79971.86000000","0.00014000"],["79971.85000000","0.33057000"],["79971.84000000","0.41438000"],["79971.83000000","0.00007000"],["79971.81000000","0.00875000"],["79971.79000000","0.01467000"],["79971.76000000","0.00007000"]],"asks":[["79974.47000000","0.24603000"],["79974.48000000","0.00090000"],["79974.49000000","0.00013000"],["79975.73000000","0.00014000"],["79975.74000000","0.01693000"],["79976.00000000","0.00465000"],["79976.35000000","0.00007000"],["79976.68000000","0.00007000"],["79976.84000000","0.00007000"],["79976.93000000","0.00014000"],["79976.94000000","0.01763000"],["79977.01000000","0.00014000"],["79977.02000000","0.02004000"],["79977.09000000","0.00014000"],["79977.10000000","0.05303000"],["79977.17000000","0.00007000"],["79977.18000000","0.00007000"],["79977.42000000","0.00014000"],["79977.99000000","0.00014000"],["79978.00000000","0.03121000"]]}}}
{"rx_ns": 10694054992400, "frame": {"stream":"btcusdt@depth@100ms","data":{"e":"depthUpdate","E":1787647689214,"s":"BTCUSDT","U":99116115075,"u":99116115106,"b":[["79974.46000000","5.07072000"],["79974.29000000","0.09879000"],["79974.28000000","0.12770000"],["79974.27000000","0.00000000"],["79974.26000000","0.00028000"],["79971.85000000","0.33057000"],["71977.02000000","0.00448000"],["71977.01000000","0.00035000"],["63979.57000000","0.00000000"]],"a":[["79974.47000000","0.24603000"],["79976.93000000","0.00014000"],["79977.01000000","0.00014000"],["79980.14000000","0.03353000"],["79981.83000000","0.00000000"],["79986.00000000","0.02400000"],["79987.99000000","0.08635000"],["79988.11000000","0.06287000"],["81174.09000000","0.00030000"]]}}}
{"rx_ns": 10694153869400, "frame": {"stream":"btcusdt@depth20@100ms","data":{"lastUpdateId":99116115141,"bids":[["79974.46000000","5.07141000"],["79974.45000000","0.00048000"],["79974.44000000","0.00013000"],["79974.29000000","0.09893000"],["79974.28000000","0.12784000"],["79974.26000000","0.00014000"],["79974.25000000","0.11199000"],["79973.70000000","0.00008000"],["79973.55000000","0.00014000"],["79973.07000000","0.00901000"],["79972.95000000","0.00014000"],["79972.94000000","0.08146000"],["79971.87000000","0.00639000"],["79971.86000000","0.00014000"],["79971.85000000","0.33057000"],["79971.84000000","0.41438000"],["79971.83000000","0.00007000"],["79971.81000000","0.00861000"],["79971.79000000","0.01467000"],["79971.76000000","0.00007000"]],"asks":[["79974.47000000","0.24610000"],["79974.48000000","0.00090000"],["79974.49000000","0.00013000"],["79975.73000000","0.00014000"],["79975.74000000","0.01693000"],["79976.00000000","0.00465000"],["79976.35000000","0.00007000"],["79976.68000000","0.00007000"],["79976.84000000","0.00007000"],["79976.93000000","0.00014000"],["79976.94000000","0.01763000"],["79977.01000000","0.00014000"],["79977.02000000","0.02004000"],["79977.09000000","0.00014000"],["79977.10000000","0.05303000"],["79977.17000000","0.00007000"],["79977.18000000","0.00007000"],["79977.42000000","0.00014000"],["79977.99000000","0.00014000"],["79978.00000000","0.03121000"]]}}}
{"rx_ns": 10694153957300, "frame": {"stream":"btcusdt@depth@100ms","data":{"e":"depthUpdate","E":1787647689314,"s":"BTCUSDT","U":99116115107,"u":99116115141,"b":[["79974.46000000","5.07141000"],["79974.29000000","0.09893000"],["79974.28000000","0.12784000"],["79974.26000000","0.00014000"],["79971.81000000","0.00861000"],["79959.22000000","0.00000000"],["79935.12000000","0.00000000"],["79930.41000000","0.02428000"],["71977.02000000","0.00432000"],["63980.00000000","0.18107000"]],"a":[["79974.47000000","0.24610000"],["79980.00000000","0.02421000"],["79983.50000000","0.00000000"],["79991.22000000","0.00000000"],["80004.24000000","0.00000000"]]}}}
{"rx_ns": 10694252552100, "frame": {"stream":"btcusdt@depth20@100ms","data":{"lastUpdateId":99116115154,"bids":[["79974.46000000","5.07141000"],["79974.45000000","0.00048000"],["79974.44000000","0.00013000"],["79974.29000000","0.09893000"],["79974.28000000","0.12784000"],["79974.26000000","0.00014000"],["79974.25000000","0.11199000"],["79973.70000000","0.00008000"],["79973.55000000","0.00014000"],["79973.07000000","0.00901000"],["79972.95000000","0.00014000"],["79972.94000000","0.08146000"],["79971.87000000","0.00639000"],["79971.86000000","0.00014000"],["79971.85000000","0.33057000"],["79971.84000000","0.41438000"],["79971.83000000","0.00007000"],["79971.81000000","0.00861000"],["79971.79000000","0.01467000"],["79971.76000000","0.00007000"]],"asks":[["79974.47000000","0.24610000"],["79974.48000000","0.00090000"],["79974.49000000","0.00013000"],["79975.73000000","0.00014000"],["79975.74000000","0.01693000"],["79976.00000000","0.00465000"],["79976.35000000","0.00007000"],["79976.68000000","0.00007000"],["79976.84000000","0.00007000"],["79976.93000000","0.00014000"],["79976.94000000","0.01763000"],["79977.01000000","0.00014000"],["79977.02000000","0.02004000"],["79977.09000000","0.00014000"],["79977.10000000","0.05303000"],["79977.17000000","0.00007000"],["79977.18000000","0.00007000"],["79977.42000000","0.00014000"],["79977.99000000","0.00014000"],["79978.00000000","0.03121000"]]}}}
{"rx_ns": 10694252637700, "frame": {"stream":"btcusdt@depth@100ms","data":{"e":"depthUpdate","E":1787647689414,"s":"BTCUSDT","U":99116115142,"u":99116115154,"b":[["79962.99000000","0.02000000"],["79959.22000000","0.00007000"],["79954.93000000","0.00000000"],["79942.00000000","0.72400000"],["79940.00000000","0.12219000"],["71977.02000000","0.00448000"],["71977.01000000","0.00008000"],["58250.00000000","1.48059000"]],"a":[["79984.63000000","0.12713000"],["79986.90000000","0.08635000"],["79991.22000000","0.00007000"]]}}}
{"rx_ns": 10694352270600, "frame": {"stream":"btcusdt@depth20@100ms","data":{"lastUpdateId":99116115252,"bids":[["79974.46000000","3.19533000"],["79974.45000000","0.00083000"],["79974.44000000","0.00013000"],["79974.30000000","0.00014000"],["79974.29000000","0.09893000"],["79974.28000000","0.12784000"],["79974.26000000","0.00014000"],["79974.25000000","0.11199000"],["79973.70000000","0.00008000"],["79973.55000000","0.00014000"],["79973.07000000","0.00901000"],["79972.95000000","0.00014000"],["79972.94000000","0.08153000"],["79971.87000000","0.00014000"],["79971.86000000","0.00014000"],["79971.85000000","0.33057000"],["79971.84000000","0.41438000"],["79971.83000000","0.00007000"],["79971.81000000","0.00861000"],["79971.79000000","0.01467000"]],"asks":[["79974.47000000","1.26394000"],["79974.48000000","0.00104000"],["79974.49000000","0.00013000"],["79975.73000000","0.00014000"],["79975.74000000","0.01693000"],["79976.00000000","0.00465000"],["79976.35000000","0.00007000"],["79976.68000000","0.00007000"],["79976.73000000","0.08635000"],["79976.84000000","0.00007000"],["79976.93000000","0.00014000"],["79976.94000000","0.01763000"],["79977.01000000","0.00014000"],["79977.02000000","0.02004000"],["79977.09000000","0.00014000"],["79977.10000000","0.05310000"],["79977.17000000","0.00007000"],["79977.18000000","0.00007000"],["79977.42000000","0.00014000"],["79977.85000000","0.22747000"]]}}}
{"rx_ns": 10694352362100, "frame": {"stream":"btcusdt@depth@100ms","data":{"e":"depthUpdate","E":1787647689514,"s":"BTCUSDT","U":99116115155,"u":99116115252,"b":[["79974.46000000","3.19533000"],["79974.45000000","0.00083000"],["79974.30000000","0.00014000"],["79972.94000000","0.08153000"],["79971.88000000","0.00000000"],["79971.87000000","0.00014000"],["79970.71000000","0.04270000"],["79970.62000000","0.00000000"],["79969.99000000","0.00000000"],["79969.69000000","0.00000000"],["79968.54000000","0.00000000"],["79968.01000000","0.00625000"],["79967.03000000","0.00625000"],["79966.89000000","0.00000000"],["79964.35000000","0.00162000"],["79962.99000000","0.00000000"],["79960.49000000","0.00000000"],["79960.02000000","0.00000000"],["79958.09000000","0.02000000"],["79957.11000000","0.00625000"],["71977.02000000","0.00432000"],["63979.57000000","0.00031000"]],"a":[["79974.47000000","1.26394000"],["79974.48000000","0.00104000"],["79976.73000000","0.08635000"],["79977.10000000","0.05310000"],["79977.85000000","0.22747000"],["79977.86000000","0.06287000"],["79977.99000000","0.00007000"],["79978.00000000","0.03135000"],["79978.17000000","0.03406000"],["79978.23000000","0.08635000"],["79978.30000000","0.02004000"],["79979.25000000","0.00000000"],["79980.00000000","0.02414000"],["79980.12000000","0.08578000"],["79980.14000000","0.00000000"],["79980.16000000","0.32465000"],["79980.45000000","0.00041000"],["79981.28000000","0.00039000"],["79982.46000000","0.00008000"],["79983.23000000","0.00000000"],["79983.43000000","0.00927000"],["79983.57000000","0.00000000"],["79984.26000000","0.00625000"],["79984.63000000","0.11412000"],["79984.64000000","0.00000000"],["79985.15000000","0.00000000"],["79985.77000000","0.00000000"],["79986.90000000","0.00000000"],["79987.13000000","0.00000000"],["79987.99000000","0.00000000"],["79988.11000000","0.00000000"],["79989.75000000","1.87060000"],["79989.76000000","0.00000000"],["79991.64000000","0.33763000"],["79999.49000000","0.02423000"],["80014.22000000","0.00000000"],["80016.12000000","0.00000000"],["80016.67000000","0.50235000"]]}}}
{"rx_ns": 10694456334800, "frame": {"stream":"btcusdt@depth20@100ms","data":{"lastUpdateId":99116115390,"bids":[["79974.46000000","3.19485000"],["79974.45000000","0.00083000"],["79974.44000000","0.00013000"],["79974.30000000","0.00014000"],["79974.29000000","0.09907000"],["79974.28000000","0.12784000"],["79974.26000000","0.00014000"],["79974.25000000","0.11199000"],["79973.70000000","0.00008000"],["79973.55000000","0.00007000"],["79973.07000000","0.00901000"],["79972.95000000","0.00014000"],["79972.94000000","0.08139000"],["79971.86000000","0.00014000"],["79971.85000000","0.33057000"],["79971.84000000","0.41438000"],["79971.83000000","0.00007000"],["79971.81000000","0.00875000"],["79971.79000000","0.01467000"],["79971.76000000","0.00007000"]],"asks":[["79974.47000000","1.26380000"],["79974.48000000","0.00097000"],["79974.49000000","0.00013000"],["79975.73000000","0.00014000"],["79975.74000000","0.01707000"],["79976.00000000","0.00465000"],["79976.35000000","0.00007000"],["79976.68000000","0.00007000"],["79976.71000000","0.00014000"],["79976.72000000","0.08807000"],["79976.73000000","0.00014000"],["79976.84000000","0.00007000"],["79976.93000000","0.00014000"],["79976.94000000","0.01763000"],["79977.01000000","0.00014000"],["79977.02000000","0.02004000"],["79977.09000000","0.00007000"],["79977.10000000","0.05324000"],["79977.13000000","0.05856000"],["79977.17000000","0.00007000"]]}}}
{"rx_ns": 10694456689000, "frame": {"stream":"btcusdt@depth@100ms","data":{"e":"depthUpdate","E":1787647689614,"s":"BTCUSDT","U":99116115253,"u":99116115390,"b":[["79974.46000000","3.19485000"],["79974.45000000","0.00083000"],["79974.29000000","0.09907000"],["79973.55000000","0.00007000"],["79972.94000000","0.08139000"],["79971.87000000","0.00000000"],["79971.81000000","0.00875000"],["79970.71000000","0.04263000"],["79969.23000000","0.01768000"],["79964.27000000","0.00000000"],["79886.41000000","0.00000000"],["79886.40000000","0.62503000"],["79883.77000000","0.00000000"],["71977.02000000","0.00448000"],["71977.00000000","1.00000000"],["63979.57000000","0.00000000"]],"a":[["79974.47000000","1.26380000"],["79974.48000000","0.00097000"],["79975.74000000","0.01707000"],["79976.71000000","0.00014000"],["79976.72000000","0.08807000"],["79976.73000000","0.00014000"],["79977.09000000","0.00007000"],["79977.10000000","0.05324000"],["79977.13000000","0.05856000"],["79977.85000000","0.00014000"],["79977.86000000","0.00014000"],["79977.99000000","0.00000000"],["79978.00000000","0.03114000"],["79978.17000000","0.00000000"],["79978.23000000","0.00000000"],["79978.24000000","0.00000000"],["79978.29000000","0.05637000"],["79978.30000000","0.01990000"],["79980.00000000","0.02414000"],["79980.12000000","0.00592000"],["79980.16000000","0.27933000"],["79980.17000000","0.31273000"],["79980.45000000","0.00000000"],["79980.92000000","0.00000000"],["79981.27000000","0.00037000"],["79982.38000000","0.00000000"],["79982.46000000","0.07749000"],["79983.05000000","0.00597000"],["79983.43000000","0.01027000"],["79984.62000000","0.07320000"],["79984.63000000","0.07535000"],["79984.65000000","0.00048000"],["79985.77000000","0.07968000"],["79986.02000000","0.00000000"],["79986.90000000","0.00000000"],["79988.11000000","0.13341000"],["79988.12000000","1.15964000"],["79992.67000000","0.00000000"],["80032.00000000","0.02814000"],["80034.13000000","0.00000000"]]}}}
{"rx_ns": 10694552511400, "frame": {"stream":"btcusdt@depth20@100ms","data":{"lastUpdateId":99116115433,"bids":[["79974.46000000","3.19485000"],["79974.45000000","0.00083000"],["79974.44000000","0.00013000"],["79974.30000000","0.00014000"],["79974.29000000","0.09907000"],["79974.28000000","0.12784000"],["79974.26000000","0.00014000"],["79974.25000000","0.11199000"],["79973.70000000","0.00008000"],["79973.55000000","0.00007000"],["79973.07000000","0.00901000"],["79972.95000000","0.00014000"],["79972.94000000","0.08139000"],["79971.86000000","0.00014000"],["79971.85000000","0.33057000"],["79971.84000000","0.41438000"],["79971.83000000","0.00007000"],["79971.81000000","0.00875000"],["79971.79000000","0.01467000"],["79971.76000000","0.00007000"]],"asks":[["79974.47000000","1.26387000"],["79974.48000000","0.00097000"],["79974.49000000","0.00013000"],["79975.73000000","0.00014000"],["79975.74000000","0.01700000"],["79976.00000000","0.00465000"],["79976.35000000","0.00007000"],["79976.68000000","0.00007000"],["79976.71000000","0.00014000"],["79976.72000000","0.08821000"],["79976.84000000","0.00007000"],["79976.93000000","0.00014000"],["79976.94000000","0.01763000"],["79977.01000000","0.00014000"],["79977.02000000","0.02004000"],["79977.09000000","0.00007000"],["79977.10000000","0.05310000"],["79977.13000000","0.05870000"],["79977.17000000","0.00007000"],["79977.18000000","0.00007000"]]}}}
{"rx_ns": 10694552605600, "frame": {"stream":"btcusdt@depth@100ms","data":{"e":"depthUpdate","E":1787647689714,"s":"BTCUSDT","U":99116115391,"u":99116115433,"b":[["79974.46000000","3.19485000"],["79964.09000000","0.00048000"],["79895.41000000","0.02084000"],["76800.00000000","3.87425000"],["71977.02000000","0.00432000"]],"a":[["79974.47000000","1.26387000"],["79975.74000000","0.01700000"],["79976.72000000","0.08821000"],["79976.73000000","0.00000000"],["79977.10000000","0.05310000"],["79977.13000000","0.05870000"],["79977.85000000","0.00000000"],["79977.86000000","0.00000000"],["79978.00000000","0.03114000"],["79978.29000000","0.05651000"],["79980.00000000","0.02421000"],["79984.65000000","0.00000000"],["79986.00000000","0.02407000"]]}}}
{"rx_ns": 10694655272500, "frame": {"stream":"btcusdt@depth20@100ms","data":{"lastUpdateId":99116115448,"bids":[["79974.46000000","3.19485000"],["79974.45000000","0.00083000"],["79974.44000000","0.00013000"],["79974.30000000","0.00014000"],["79974.29000000","0.09907000"],["79974.28000000","0.12784000"],["79974.26000000","0.00014000"],["79974.25000000","0.11199000"],["79973.70000000","0.00008000"],["79973.55000000","0.00007000"],["79973.07000000","0.00901000"],["79972.95000000","0.00014000"],["79972.94000000","0.08139000"],["79971.86000000","0.00014000"],["79971.85000000","0.33057000"],["79971.84000000","0.41438000"],["79971.83000000","0.00007000"],["79971.81000000","0.00875000"],["79971.79000000","0.01467000"],["79971.76000000","0.00007000"]],"asks":[["79974.47000000","1.26434000"],["79974.48000000","0.00097000"],["79974.49000000","0.00013000"],["79975.73000000","0.00014000"],["79975.74000000","0.01707000"],["79976.00000000","0.00465000"],["79976.14000000","0.00007000"],["79976.15000000","0.04212000"],["79976.35000000","0.00007000"],["79976.68000000","0.00007000"],["79976.71000000","0.00014000"],["79976.72000000","0.08821000"],["79976.84000000","0.00007000"],["79976.93000000","0.00014000"],["79976.94000000","0.01763000"],["79977.01000000","0.00014000"],["79977.02000000","0.02004000"],["79977.10000000","0.05310000"],["79977.13000000","0.00014000"],["79977.17000000","0.00007000"]]}}}
{"rx_ns": 10694655360000, "frame": {"stream":"btcusdt@depth@100ms","data":{"e":"depthUpdate","E":1787647689815,"s":"BTCUSDT","U":99116115434,"u":99116115448,"b":[["79895.41000000","0.00000000"],["71977.02000000","0.00448000"]],"a":[["79974.47000000","1.26434000"],["79974.48000000","0.00097000"],["79975.74000000","0.01707000"],["79976.14000000","0.00007000"],["79976.15000000","0.04212000"],["79977.09000000","0.00000000"],["79977.13000000","0.00014000"],["79980.51000000","0.00583000"]]}}}
{"rx_ns": 10694754247600, "frame": {"stream":"btcusdt@depth20@100ms","data":{"lastUpdateId":99116115497,"bids":[["79974.46000000","3.12471000"],["79974.45000000","0.00083000"],["79974.44000000","0.00013000"],["79974.30000000","0.00014000"],["79974.29000000","0.09907000"],["79974.28000000","0.12784000"],["79974.26000000","0.00014000"],["79974.25000000","0.11199000"],["79973.70000000","0.00008000"],["79973.55000000","0.00007000"],["79973.07000000","0.00901000"],["79972.95000000","0.00014000"],["79972.94000000","0.08139000"],["79971.86000000","0.00014000"],["79971.85000000","0.33057000"],["79971.84000000","0.41438000"],["79971.83000000","0.00007000"],["79971.81000000","0.00875000"],["79971.79000000","0.01467000"],["79971.76000000","0.00007000"]],"asks":[["79974.47000000","1.28367000"],["79974.48000000","0.00097000"],["79974.49000000","0.00013000"],["79974.80000000","0.00007000"],["79974.81000000","0.04169000"],["79975.73000000","0.00014000"],["79975.74000000","0.01707000"],["79976.00000000","0.00465000"],["79976.15000000","0.00014000"],["79976.35000000","0.00007000"],["79976.68000000","0.00007000"],["79976.71000000","0.00014000"],["79976.72000000","0.08821000"],["79976.84000000","0.00007000"],["79976.93000000","0.00014000"],["79976.94000000","0.01763000"],["79977.01000000","0.00014000"],["79977.02000000","0.02004000"],["79977.10000000","0.05303000"],["79977.17000000","0.00007000"]]}}}
{"rx_ns": 10694754364200, "frame": {"stream":"btcusdt@depth@100ms","data":{"e":"depthUpdate","E":1787647689915,"s":"BTCUSDT","U":99116115449,"u":99116115497,"b":[["79974.46000000","3.12471000"],["79964.35000000","0.00562000"],["79943.00000000","0.70000000"],["79942.00000000","0.02400000"],["79902.54000000","0.00312000"],["79822.07000000","0.00000000"],["79821.19000000","0.00125000"],["71977.02000000","0.00416000"],["63980.00000000","0.18407000"]],"a":[["79974.47000000","1.28367000"],["79974.48000000","0.00097000"],["79974.80000000","0.00007000"],["79974.81000000","0.04169000"],["79975.74000000","0.01707000"],["79976.14000000","0.00000000"],["79976.15000000","0.00014000"],["79977.10000000","0.05303000"],["79977.13000000","0.00000000"],["79978.19000000","0.00445000"],["79980.00000000","0.02428000"],["79980.11000000","0.07968000"],["79980.17000000","0.31280000"],["79984.61000000","0.05786000"],["79984.63000000","0.00000000"],["79985.77000000","0.00000000"],["79986.85000000","0.00400000"]]}}}
{"rx_ns": 10694853361700, "frame": {"stream":"btcusdt@depth20@100ms","data":{"lastUpdateId":99116115514,"bids":[["79974.46000000","3.12471000"],["79974.45000000","0.00083000"],["79974.44000000","0.00013000"],["79974.30000000","0.00014000"],["79974.29000000","0.09907000"],["79974.28000000","0.12784000"],["79974.26000000","0.00014000"],["79974.25000000","0.11199000"],["79973.70000000","0.00008000"],["79973.55000000","0.00007000"],["79973.07000000","0.00901000"],["79972.95000000","0.00014000"],["79972.94000000","0.08139000"],["79971.86000000","0.00014000"],["79971.85000000","0.33057000"],["79971.84000000","0.41438000"],["79971.83000000","0.00007000"],["79971.81000000","0.00875000"],["79971.79000000","0.01467000"],["79971.76000000","0.00007000"]],"asks":[["79974.47000000","1.28381000"],["79974.48000000","0.00097000"],["79974.49000000","0.00013000"],["79974.80000000","0.00007000"],["79974.81000000","0.04183000"],["79975.73000000","0.00014000"],["79975.74000000","0.01686000"],["79976.00000000","0.00465000"],["79976.35000000","0.00007000"],["79976.68000000","0.00007000"],["79976.71000000","0.00014000"],["79976.72000000","0.08821000"],["79976.84000000","0.00007000"],["79976.93000000","0.00014000"],["79976.94000000","0.01763000"],["79977.01000000","0.00014000"],["79977.02000000","0.02004000"],["79977.10000000","0.05303000"],["79977.17000000","0.00007000"],["79977.18000000","0.00007000"]]}}}
{"rx_ns": 10694853444800, "frame": {"stream":"btcusdt@depth@100ms","data":{"e":"depthUpdate","E":1787647690014,"s":"BTCUSDT","U":99116115498,"u":99116115514,"b":[["78774.84000000","0.00030000"],["71977.02000000","0.00416000"],["63980.00000000","0.18107000"],["63979.57000000","0.00031000"]],"a":[["79974.47000000","1.28381000"],["79974.81000000","0.04183000"],["79975.74000000","0.01686000"],["79976.15000000","0.00000000"]]}}}
{"rx_ns": 10694953152600, "frame": {"stream":"btcusdt@depth20@100ms","data":{"lastUpdateId":99116115525,"bids":[["79974.46000000","3.12519000"],["79974.45000000","0.00083000"],["79974.44000000","0.00013000"],["79974.30000000","0.00014000"],["79974.29000000","0.09907000"],["79974.28000000","0.12784000"],["79974.26000000","0.00014000"],["79974.25000000","0.11199000"],["79973.70000000","0.00008000"],["79973.55000000","0.00007000"],["79973.07000000","0.00901000"],["79972.95000000","0.00014000"],["79972.94000000","0.08139000"],["79971.86000000","0.00014000"],["79971.85000000","0.33057000"],["79971.84000000","0.41438000"],["79971.83000000","0.00007000"],["79971.81000000","0.00875000"],["79971.79000000","0.01467000"],["79971.76000000","0.00007000"]],"asks":[["79974.47000000","1.35884000"],["79974.48000000","0.00097000"],["79974.49000000","0.00013000"],["79974.80000000","0.00007000"],["79974.81000000","0.04183000"],["79975.73000000","0.00014000"],["79975.74000000","0.01686000"],["79976.00000000","0.00465000"],["79976.35000000","0.00007000"],["79976.68000000","0.00007000"],["79976.71000000","0.00014000"],["79976.72000000","0.08821000"],["79976.84000000","0.00007000"],["79976.93000000","0.00014000"],["79976.94000000","0.01763000"],["79977.01000000","0.00014000"],["79977.02000000","0.02004000"],["79977.10000000","0.05303000"],["79977.17000000","0.00007000"],["79977.18000000","0.00007000"]]}}}
{"rx_ns": 10694953237100, "frame": {"stream":"btcusdt@depth@100ms","data":{"e":"depthUpdate","E":1787647690114,"s":"BTCUSDT","U":99116115515,"u":99116115525,"b":[["79974.46000000","3.12519000"],["79962.96000000","0.00007000"],["79054.44000000","0.00010000"],["71977.02000000","0.00416000"]],"a":[["79974.47000000","1.35884000"],["79983.43000000","0.00000000"]]}}}
{"rx_ns": 10695052876600, "frame": {"stream":"btcusdt@depth20@100ms","data":{"lastUpdateId":99116115546,"bids":[["79974.46000000","3.12519000"],["79974.45000000","0.00083000"],["79974.44000000","0.00013000"],["79974.30000000","0.00014000"],["79974.29000000","0.09907000"],["79974.28000000","0.12784000"],["79974.26000000","0.00014000"],["79974.25000000","0.11199000"],["79973.70000000","0.00008000"],["79973.55000000","0.00007000"],["79973.07000000","0.00901000"],["79972.95000000","0.00014000"],["79972.94000000","0.08139000"],["79971.86000000","0.00014000"],["79971.85000000","0.33057000"],["79971.84000000","0.41438000"],["79971.83000000","0.00007000"],["79971.81000000","0.00875000"],["79971.79000000","0.01467000"],["79971.76000000","0.00007000"]],"asks":[["79974.47000000","1.35867000"],["79974.48000000","0.00097000"],["79974.49000000","0.00013000"],["79974.80000000","0.00014000"],["79974.81000000","0.04183000"],["79975.73000000","0.00014000"],["79975.74000000","0.01686000"],["79976.00000000","0.00465000"],["79976.35000000","0.00007000"],["79976.68000000","0.00007000"],["79976.71000000","0.00014000"],["79976.72000000","0.08821000"],["79976.84000000","0.00007000"],["79976.93000000","0.00014000"],["79976.94000000","0.01763000"],["79977.01000000","0.00014000"],["79977.02000000","0.02004000"],["79977.10000000","0.05303000"],["79977.17000000","0.00007000"],["79977.18000000","0.00007000"]]}}}
{"rx_ns": 10695052956200, "frame": {"stream":"btcusdt@depth@100ms","data":{"e":"depthUpdate","E":1787647690214,"s":"BTCUSDT","U":99116115526,"u":99116115546,"b":[["79886.40000000","0.00000000"],["79883.78000000","0.20122000"],["79883.77000000","0.62503000"],["79781.65000000","0.00000000"],["79773.62000000","0.00770000"],["71977.02000000","0.00400000"],["63979.57000000","0.00000000"]],"a":[["79974.47000000","1.35867000"],["79974.80000000","0.00014000"],["79984.61000000","0.04041000"],["79984.62000000","0.00000000"],["80004.93000000","1.20062000"],["80014.45000000","0.00000000"],["80068.60000000","0.00000000"],["81174.09000000","0.00030000"]]}}}
{"rx_ns": 10695153022000, "frame": {"stream":"btcusdt@depth20@100ms","data":{"lastUpdateId":99116115597,"bids":[["79974.46000000","3.19588000"],["79974.45000000","0.00083000"],["79974.44000000","0.00013000"],["79974.30000000","0.00014000"],["79974.29000000","0.09907000"],["79974.28000000","0.12784000"],["79974.26000000","0.00014000"],["79974.25000000","0.11199000"],["79973.70000000","0.00008000"],["79973.55000000","0.00007000"],["79973.07000000","0.00901000"],["79972.95000000","0.00014000"],["79972.94000000","0.08139000"],["79971.86000000","0.00014000"],["79971.85000000","0.33057000"],["79971.84000000","0.41438000"],["79971.83000000","0.00007000"],["79971.81000000","0.00875000"],["79971.79000000","0.01474000"],["79971.76000000","0.00007000"]],"asks":[["79974.47000000","0.55587000"],["79974.48000000","0.00090000"],["79974.49000000","0.00013000"],["79974.81000000","0.00014000"],["79975.73000000","0.00014000"],["79975.74000000","0.01686000"],["79976.00000000","0.00465000"],["79976.35000000","0.00007000"],["79976.68000000","0.00007000"],["79976.71000000","0.00014000"],["79976.72000000","0.08821000"],["79976.84000000","0.00007000"],["79976.93000000","0.00014000"],["79976.94000000","0.01763000"],["79977.01000000","0.00014000"],["79977.02000000","0.02004000"],["79977.10000000","0.05303000"],["79977.17000000","0.00007000"],["79977.18000000","0.00007000"],["79977.42000000","0.00014000"]]}}}
{"rx_ns": 10695153150000, "frame": {"stream":"btcusdt@depth@100ms","data":{"e":"depthUpdate","E":1787647690314,"s":"BTCUSDT","U":99116115547,"u":99116115597,"b":[["79974.46000000","3.19588000"],["79971.79000000","0.01474000"],["79971.51000000","0.00625000"],["79970.51000000","0.01794000"],["79969.29000000","0.00625000"],["79969.23000000","0.01761000"],["79968.01000000","0.00625000"],["79967.03000000","0.00000000"],["79964.09000000","0.00000000"],["79886.41000000","0.62503000"],["79883.77000000","0.00000000"],["71977.02000000","0.00416000"],["63980.00000000","0.18107000"]],"a":[["79974.47000000","0.55587000"],["79974.48000000","0.00090000"],["79974.80000000","0.00000000"],["79974.81000000","0.00014000"],["79981.27000000","0.00000000"],["79981.28000000","0.00000000"],["79981.97000000","0.00036000"],["79982.28000000","0.00037000"],["79982.46000000","0.00008000"],["79984.26000000","0.00000000"],["79984.61000000","0.07769000"],["79984.75000000","0.00047000"],["79985.70000000","0.00625000"],["79985.77000000","0.08635000"],["79986.90000000","0.06433000"],["80001.24000000","0.00399000"],["80005.24000000","0.00000000"],["80014.44000000","0.96431000"],["80035.57000000","0.00190000"],["80041.25000000","0.00399000"],["80045.25000000","0.00000000"],["80068.60000000","0.38716000"],["80073.25000000","0.00399000"],["80077.25000000","0.00000000"],["80115.99000000","0.00076000"],["80121.25000000","0.00399000"],["80125.25000000","0.00000000"],["80193.25000000","0.00399000"],["80197.26000000","0.00017000"]]}}}
{"rx_ns": 10695252565400, "kind": "rest", "req": {"method": "GET", "url": "https://data-api.binance.vision/api/v3/depth?symbol=BTCUSDT&limit=1000", "limit": 1000, "weight": 50, "sent_ns": 10693686250600, "status": 200, "used_weight_1m": "50", "recv_ns": 10695189305500}, "frame": {"lastUpdateId":99116115448,"bids":[["79974.46000000","3.19485000"],["79974.45000000","0.00083000"],["79974.44000000","0.00013000"],["79974.30000000","0.00014000"],["79974.29000000","0.09907000"],["79974.28000000","0.12784000"],["79974.26000000","0.00014000"],["79974.25000000","0.11199000"],["79973.70000000","0.00008000"],["79973.55000000","0.00007000"],["79973.07000000","0.00901000"],["79972.95000000","0.00014000"],["79972.94000000","0.08139000"],["79971.86000000","0.00014000"],["79971.85000000","0.33057000"],["79971.84000000","0.41438000"],["79971.83000000","0.00007000"],["79971.81000000","0.00875000"],["79971.79000000","0.01467000"],["79971.76000000","0.00007000"],["79971.50000000","0.04715000"],["79971.28000000","0.00193000"],["79970.71000000","0.04263000"],["79970.61000000","0.00007000"],["79970.56000000","0.00014000"],["79970.54000000","0.00007000"],["79970.51000000","0.01787000"],["79970.45000000","0.00400000"],["79969.91000000","0.00007000"],["79969.68000000","0.00014000"],["79969.28000000","0.00007000"],["79969.23000000","0.01768000"],["79968.86000000","0.00007000"],["79968.53000000","0.00007000"],["79968.52000000","0.00007000"],["79968.47000000","0.00013000"],["79968.01000000","0.00625000"],["79968.00000000","0.62064000"],["79967.85000000","0.02481000"],["79967.47000000","0.64866000"],["79967.44000000","0.00007000"],["79967.42000000","0.00007000"],["79967.25000000","0.12505000"],["79967.24000000","0.00594000"],["79967.03000000","0.00625000"],["79967.02000000","0.00400000"],["79966.87000000","1.04939000"],["79966.80000000","0.00007000"],["79966.46000000","0.00007000"],["79966.45000000","0.00008000"],["79966.01000000","0.00007000"],["79966.00000000","0.02400000"],["79965.85000000","0.03224000"],["79965.81000000","0.00014000"],["79965.74000000","0.00037000"],["79965.63000000","0.00008000"],["79965.36000000","0.00010000"],["79965.23000000","0.00453000"],["79964.48000000","0.00007000"],["79964.38000000","0.00007000"],["79964.35000000","0.00162000"],["79964.34000000","1.87060000"],["79964.14000000","0.08576000"],["79964.09000000","0.00048000"],["79964.00000000","0.02400000"],["79963.78000000","0.00582000"],["79963.50000000","0.00007000"],["79963.28000000","0.00007000"],["79963.27000000","0.02000000"],["79963.06000000","0.45957000"],["79963.05000000","0.36586000"],["79963.00000000","0.00400000"],["79962.92000000","0.00007000"],["79962.81000000","0.03000000"],["79962.78000000","1.04939000"],["79962.51000000","0.00250000"],["79962.45000000","0.02600000"],["79962.11000000","0.02251000"],["79962.00000000","0.02400000"],["79961.94000000","0.00014000"],["79961.86000000","0.00026000"],["79961.59000000","0.02000000"],["79961.53000000","0.02400000"],["79961.49000000","0.00580000"],["79961.42000000","0.00007000"],["79960.96000000","0.00010000"],["79960.30000000","0.00007000"],["79960.24000000","0.00444000"],["79960.22000000","0.00007000"],["79960.01000000","0.00007000"],["79960.00000000","0.02407000"],["79959.81000000","0.02200000"],["79959.75000000","0.00400000"],["79959.52000000","0.02000000"],["79959.50000000","0.16183000"],["79959.49000000","1.05789000"],["79959.48000000","1.87060000"],["79959.44000000","0.07663000"],["79959.22000000","0.00007000"],["79959.16000000","0.02400000"],["79959.14000000","0.02000000"],["79959.04000000","0.00007000"],["79958.75000000","1.04939000"],["79958.64000000","0.00582000"],["79958.14000000","0.00007000"],["79958.09000000","0.02000000"],["79958.07000000","0.00014000"],["79958.00000000","0.02407000"],["79957.99000000","0.20257000"],["79957.56000000","0.00008000"],["79957.38000000","0.00010000"],["79957.11000000","0.00625000"],["79957.10000000","0.00007000"],["79956.80000000","0.00400000"],["79956.08000000","0.02000000"],["79956.06000000","0.12506000"],["79956.01000000","0.00007000"],["79956.00000000","0.02400000"],["79955.93000000","0.02000000"],["79955.88000000","0.02200000"],["79955.83000000","0.00008000"],["79955.74000000","0.00592000"],["79955.45000000","0.00012000"],["79955.42000000","0.02400000"],["79955.16000000","0.00007000"],["79955.08000000","0.00439000"],["79955.03000000","0.02200000"],["79955.02000000","0.02200000"],["79954.97000000","0.00007000"],["79954.82000000","0.36586000"],["79954.81000000","1.47164000"],["79954.75000000","0.03224000"],["79954.62000000","1.87060000"],["79954.59000000","1.04939000"],["79954.34000000","1.20047000"],["79954.20000000","0.00014000"],["79954.01000000","0.42901000"],["79954.00000000","0.09223000"],["79953.98000000","0.00007000"],["79953.48000000","0.00399000"],["79952.88000000","0.00124000"],["79952.83000000","0.00007000"],["79952.73000000","0.00007000"],["79952.56000000","0.00026000"],["79952.41000000","0.04000000"],["79952.37000000","0.33780000"],["79952.00000000","0.02407000"],["79951.90000000","0.07288000"],["79951.83000000","0.00008000"],["79951.63000000","1.00014000"],["79951.28000000","0.00007000"],["79951.26000000","0.01281000"],["79951.25000000","0.46287000"],["79951.20000000","0.00400000"],["79950.81000000","0.12400000"],["79950.71000000","0.00007000"],["79950.70000000","0.00012000"],["79950.62000000","0.00455000"],["79950.51000000","0.00059000"],["79950.33000000","0.00014000"],["79950.00000000","0.12039000"],["79949.82000000","0.00007000"],["79949.73000000","0.00260000"],["79949.49000000","0.00008000"],["79949.43000000","0.00058000"],["79949.40000000","0.00010000"],["79949.28000000","1.87060000"],["79949.05000000","1.04939000"],["79948.63000000","0.00007000"],["79948.52000000","0.51604000"],["79948.07000000","0.00190000"],["79948.00000000","0.02400000"],["79947.83000000","0.00008000"],["79947.75000000","0.00007000"],["79946.71000000","1.09798000"],["79946.70000000","0.36586000"],["79946.64000000","0.00400000"],["79946.46000000","0.00014000"],["79946.45000000","0.20250000"],["79946.39000000","0.17456000"],["79946.32000000","0.00007000"],["79946.00000000","0.02400000"],["79945.68000000","0.00021000"],["79945.67000000","0.00007000"],["79945.00000000","1.04939000"],["79944.68000000","0.33783000"],["79944.53000000","0.00026000"],["79944.47000000","1.87060000"],["79944.00000000","0.02400000"],["79943.83000000","0.00008000"],["79943.76000000","0.00007000"],["79943.59000000","0.00007000"],["79943.55000000","0.47998000"],["79943.54000000","0.33783000"],["79943.52000000","0.00007000"],["79943.50000000","0.00400000"],["79942.92000000","0.62563000"],["79942.59000000","0.00014000"],["79942.00000000","0.72400000"],["79941.90000000","0.00200000"],["79941.63000000","0.00091000"],["79941.51000000","0.00007000"],["79941.42000000","0.00018000"],["79941.17000000","0.00541000"],["79941.02000000","0.03224000"],["79940.87000000","0.00008000"],["79940.73000000","0.00007000"],["79940.72000000","0.00400000"],["79940.40000000","0.42480000"],["79940.22000000","0.04545000"],["79940.00000000","0.12219000"],["79939.83000000","0.00008000"],["79939.80000000","0.53944000"],["79939.79000000","1.04939000"],["79939.43000000","0.00007000"],["79939.06000000","0.00100000"],["79938.72000000","0.00014000"],["79938.59000000","0.00007000"],["79938.34000000","0.00012000"],["79938.00000000","0.02400000"],["79937.93000000","0.00007000"],["79937.88000000","0.36586000"],["79937.76000000","0.00400000"],["79937.35000000","0.00007000"],["79937.20000000","0.00011000"],["79936.90000000","0.00007000"],["79936.71000000","0.33786000"],["79936.48000000","0.00007000"],["79936.37000000","0.00026000"],["79936.00000000","0.02414000"],["79935.83000000","0.00008000"],["79935.76000000","0.00007000"],["79935.41000000","0.00231000"],["79935.13000000","0.01154000"],["79934.88000000","1.61319000"],["79934.87000000","1.87060000"],["79934.85000000","0.00014000"],["79934.81000000","1.04939000"],["79934.78000000","0.26129000"],["79934.68000000","0.65963000"],["79934.28000000","0.20250000"],["79934.01000000","0.00007000"],["79934.00000000","0.03400000"],["79933.99000000","0.83471000"],["79933.92000000","0.00007000"],["79933.76000000","0.00400000"],["79933.67000000","0.09385000"],["79933.44000000","0.00010000"],["79933.35000000","0.00008000"],["79933.20000000","0.00007000"],["79933.14000000","0.02000000"],["79932.72000000","0.00010000"],["79932.63000000","0.62571000"],["79932.21000000","0.03224000"],["79932.00000000","0.02400000"],["79931.83000000","0.00008000"],["79931.79000000","0.00007000"],["79931.68000000","0.02400000"],["79931.56000000","0.02000000"],["79931.12000000","0.00007000"],["79931.09000000","0.00010000"],["79930.72000000","0.00400000"],["79930.63000000","0.81673000"],["79930.62000000","1.04939000"],["79930.51000000","0.02000000"],["79930.41000000","0.02428000"],["79930.00000000","0.11834000"],["79929.96000000","0.02200000"],["79929.43000000","0.02000000"],["79929.28000000","0.36586000"],["79929.16000000","0.02000000"],["79929.04000000","0.00007000"],["79928.61000000","1.23904000"],["79928.01000000","0.00026000"],["79928.00000000","0.72407000"],["79927.68000000","0.00400000"],["79926.96000000","0.00007000"],["79926.61000000","0.00007000"],["79926.60000000","1.19283000"],["79926.59000000","2.91999000"],["79926.57000000","0.02800000"],["79926.35000000","0.00007000"],["79926.00000000","0.02400000"],["79925.46000000","0.00010000"],["79925.28000000","0.00008000"],["79924.60000000","0.00007000"],["79924.54000000","1.06255000"],["79924.17000000","0.00627000"],["79924.00000000","0.02400000"],["79923.89000000","1.50472000"],["79923.76000000","0.00400000"],["79923.19000000","0.00013000"],["79923.07000000","0.00035000"],["79922.81000000","0.00007000"],["79922.65000000","0.00100000"],["79922.55000000","0.02000000"],["79922.07000000","1.04939000"],["79922.06000000","0.02400000"],["79922.04000000","0.01145000"],["79922.00000000","0.02400000"],["79921.98000000","0.20250000"],["79921.66000000","1.87060000"],["79921.65000000","0.02200000"],["79921.48000000","0.02400000"],["79921.08000000","0.83013000"],["79920.84000000","0.36586000"],["79920.82000000","0.00007000"],["79920.73000000","0.00007000"],["79920.48000000","0.00400000"],["79920.39000000","1.23909000"],["79920.24000000","0.00007000"],["79920.00000000","0.05444000"],["79919.99000000","0.00146000"],["79919.81000000","0.03224000"],["79919.76000000","0.02200000"],["79919.66000000","0.00375000"],["79919.45000000","0.02200000"],["79919.21000000","0.00016000"],["79918.75000000","0.00007000"],["79918.65000000","0.00007000"],["79918.48000000","0.00007000"],["79918.05000000","0.33911000"],["79918.04000000","1.04939000"],["79918.02000000","0.00007000"],["79918.00000000","0.02400000"],["79917.48000000","0.00010000"],["79917.42000000","0.03499000"],["79917.21000000","0.00008000"],["79916.57000000","0.00007000"],["79916.28000000","0.00434000"],["79916.01000000","0.00007000"],["79916.00000000","0.02400000"],["79915.96000000","1.00938000"],["79915.95000000","1.87060000"],["79915.87000000","0.00008000"],["79915.80000000","0.00007000"],["79914.27000000","0.00310000"],["79914.26000000","0.03224000"],["79914.01000000","0.00007000"],["79914.00000000","0.02400000"],["79913.31000000","0.12522000"],["79913.12000000","0.02000000"],["79912.48000000","0.00007000"],["79912.47000000","1.04939000"],["79912.42000000","0.00007000"],["79912.29000000","0.00024000"],["79912.07000000","0.00399000"],["79912.01000000","0.00007000"],["79912.00000000","0.02410000"],["79911.96000000","0.00026000"],["79911.88000000","0.25000000"],["79911.76000000","0.00078000"],["79911.66000000","1.24380000"],["79911.65000000","1.23923000"],["79911.54000000","0.02000000"],["79911.53000000","0.36586000"],["79911.36000000","0.00270000"],["79910.58000000","0.00335000"],["79910.52000000","0.00007000"],["79910.49000000","0.02000000"],["79910.34000000","0.00007000"],["79910.26000000","0.37542000"],["79910.01000000","0.00007000"],["79910.00000000","0.02467000"],["79909.99000000","0.20250000"],["79909.94000000","0.02200000"],["79909.90000000","0.00111000"],["79909.62000000","0.00015000"],["79909.50000000","0.00010000"],["79909.40000000","0.02000000"],["79909.33000000","0.00434000"],["79909.14000000","0.02008000"],["79908.89000000","0.00034000"],["79908.11000000","1.04939000"],["79908.01000000","0.00007000"],["79908.00000000","1.02400000"],["79907.89000000","0.00379000"],["79907.64000000","0.88394000"],["79907.63000000","1.87060000"],["79907.61000000","1.00000000"],["79907.40000000","0.00014000"],["79907.37000000","0.00010000"],["79906.72000000","0.00007000"],["79906.66000000","0.00069000"],["79906.55000000","0.02600000"],["79906.00000000","0.02400000"],["79905.92000000","0.00200000"],["79905.91000000","0.00019000"],["79905.89000000","0.00426000"],["79905.88000000","0.00017000"],["79905.77000000","0.03224000"],["79904.88000000","0.00007000"],["79904.75000000","0.83030000"],["79904.72000000","0.00007000"],["79904.45000000","0.00007000"],["79904.11000000","0.00007000"],["79904.00000000","0.02414000"],["79903.96000000","0.00026000"],["79903.48000000","1.91864000"],["79902.83000000","0.04688000"],["79902.54000000","0.00312000"],["79902.53000000","0.02000000"],["79902.25000000","1.87060000"],["79902.22000000","0.36586000"],["79902.11000000","0.00125000"],["79902.04000000","0.02400000"],["79902.03000000","0.00007000"],["79902.00000000","0.02400000"],["79901.98000000","0.20250000"],["79901.89000000","0.00007000"],["79901.63000000","0.02200000"],["79901.52000000","0.00010000"],["79901.47000000","0.00009000"],["79901.46000000","0.02400000"],["79901.07000000","0.00008000"],["79900.53000000","1.23940000"],["79900.37000000","1.74269000"],["79900.00000000","0.12233000"],["79899.95000000","0.00007000"],["79899.93000000","0.00011000"],["79899.88000000","0.00010000"],["79899.74000000","0.02200000"],["79899.62000000","1.12589000"],["79899.42000000","0.02200000"],["79899.14000000","0.00007000"],["79898.66000000","1.04939000"],["79898.33000000","0.00009000"],["79898.01000000","0.00007000"],["79897.56000000","0.05485000"],["79897.39000000","1.87060000"],["79897.14000000","0.01731000"],["79897.04000000","0.00023000"],["79896.96000000","0.00007000"],["79896.88000000","0.00010000"],["79896.57000000","0.00027000"],["79896.54000000","0.80000000"],["79896.45000000","0.00010000"],["79896.35000000","0.00112000"],["79896.20000000","0.04535000"],["79896.14000000","0.00009000"],["79895.98000000","0.00007000"],["79895.88000000","0.02405000"],["79895.82000000","0.00126000"],["79895.24000000","0.00026000"],["79894.98000000","0.00538000"],["79894.87000000","0.00377000"],["79894.73000000","0.00007000"],["79894.65000000","0.00007000"],["79894.62000000","0.00007000"],["79894.34000000","0.00065000"],["79894.31000000","0.00121000"],["79894.11000000","0.00178000"],["79893.96000000","0.00312000"],["79893.95000000","0.20250000"],["79893.63000000","0.01284000"],["79893.61000000","0.00009000"],["79893.54000000","0.00010000"],["79893.40000000","0.31643000"],["79893.39000000","1.04939000"],["79893.33000000","0.00014000"],["79893.00000000","0.00008000"],["79891.99000000","0.03259000"],["79891.72000000","0.00010000"],["79891.64000000","0.00007000"],["79891.52000000","2.08741000"],["79891.51000000","1.87068000"],["79891.09000000","0.00007000"],["79890.00000000","0.00067000"],["79889.58000000","0.00014000"],["79889.36000000","0.36586000"],["79889.20000000","0.00007000"],["79888.95000000","0.00007000"],["79888.88000000","0.00008000"],["79888.85000000","0.00010000"],["79888.32000000","2.01025000"],["79888.28000000","0.00007000"],["79888.20000000","0.29048000"],["79888.18000000","1.04939000"],["79888.12000000","0.00007000"],["79888.03000000","0.00008000"],["79888.00000000","1.40691000"],["79887.99000000","0.00017000"],["79887.89000000","1.74309000"],["79887.76000000","0.00032000"],["79887.19000000","0.00059000"],["79887.02000000","0.00026000"],["79887.01000000","0.00029000"],["79886.82000000","3.75641000"],["79886.40000000","0.62503000"],["79886.25000000","0.00007000"],["79886.11000000","0.00009000"],["79886.10000000","0.12224000"],["79886.04000000","0.00007000"],["79886.01000000","0.00009000"],["79885.92000000","0.20250000"],["79885.78000000","0.00017000"],["79885.56000000","0.00023000"],["79885.41000000","0.00007000"],["79885.32000000","0.00164000"],["79885.26000000","0.00044000"],["79885.08000000","0.00008000"],["79884.92000000","0.00022000"],["79884.61000000","0.00007000"],["79884.59000000","1.87060000"],["79884.34000000","0.01621000"],["79883.94000000","0.00024000"],["79883.78000000","0.01679000"],["79883.68000000","0.00007000"],["79882.71000000","0.00011000"],["79882.42000000","0.00022000"],["79882.40000000","0.00100000"],["79882.37000000","0.00056000"],["79882.35000000","0.00762000"],["79881.60000000","0.00177000"],["79881.47000000","0.00247000"],["79881.44000000","0.00007000"],["79881.26000000","0.00007000"],["79881.12000000","0.00007000"],["79881.00000000","0.00012000"],["79880.63000000","0.00010000"],["79880.61000000","0.03224000"],["79880.34000000","0.00008000"],["79880.28000000","0.00007000"],["79880.09000000","0.00399000"],["79880.04000000","0.00410000"],["79880.01000000","0.00011000"],["79880.00000000","0.00142000"],["79879.51000000","0.00013000"],["79879.41000000","0.00050000"],["79879.35000000","1.05868000"],["79879.34000000","1.87060000"],["79878.86000000","0.00007000"],["79878.78000000","0.00011000"],["79878.65000000","0.00026000"],["79878.47000000","0.00007000"],["79878.40000000","0.00007000"],["79878.23000000","0.00010000"],["79878.01000000","0.00053000"],["79877.89000000","0.20250000"],["79877.78000000","1.04939000"],["79877.36000000","0.36586000"],["79877.01000000","0.00008000"],["79876.86000000","0.00008000"],["79876.52000000","0.00007000"],["79876.35000000","0.00011000"],["79875.87000000","0.00007000"],["79875.71000000","0.00010000"],["79875.34000000","0.00007000"],["79875.27000000","0.01378000"],["79875.26000000","0.01877000"],["79875.25000000","0.01876000"],["79875.16000000","0.00615000"],["79875.03000000","0.00007000"],["79875.00000000","0.00017000"],["79874.72000000","0.00018000"],["79874.44000000","0.00007000"],["79874.19000000","0.00007000"],["79874.15000000","0.00008000"],["79873.71000000","0.00025000"],["79873.68000000","0.00007000"],["79873.31000000","0.00007000"],["79873.20000000","0.00026000"],["79872.97000000","0.00038000"],["79872.86000000","0.00019000"],["79872.72000000","0.00068000"],["79872.10000000","0.00007000"],["79872.00000000","0.00014000"],["79871.79000000","0.00109000"],["79871.74000000","0.00007000"],["79871.42000000","0.04628000"],["79871.15000000","0.03224000"],["79871.11000000","0.00053000"],["79870.87000000","0.00007000"],["79870.67000000","0.00270000"],["79870.58000000","0.00018000"],["79870.05000000","0.00007000"],["79870.00000000","0.00050000"],["79869.86000000","0.20250000"],["79869.75000000","0.55856000"],["79869.74000000","1.87060000"],["79868.99000000","0.00026000"],["79868.61000000","0.00014000"],["79868.29000000","0.00007000"],["79868.26000000","0.00007000"],["79868.09000000","0.00007000"],["79867.78000000","0.00019000"],["79867.47000000","0.00047000"],["79867.39000000","0.32869000"],["79867.38000000","1.04939000"],["79866.66000000","0.00046000"],["79866.51000000","0.00008000"],["79865.92000000","0.00007000"],["79865.78000000","0.00007000"],["79865.54000000","0.00264000"],["79865.39000000","0.03032000"],["79865.30000000","0.00007000"],["79865.25000000","0.01252000"],["79865.12000000","0.00082000"],["79865.01000000","0.00109000"],["79864.99000000","0.00282000"],["79864.86000000","0.00012000"],["79864.81000000","0.00010000"],["79864.75000000","0.00017000"],["79864.64000000","0.00007000"],["79864.26000000","0.00007000"],["79863.71000000","0.00190000"],["79863.63000000","0.00008000"],["79863.46000000","0.74131000"],["79863.41000000","0.00093000"],["79863.38000000","0.00010000"],["79863.01000000","0.00008000"],["79862.95000000","0.36586000"],["79862.44000000","0.03224000"],["79862.31000000","0.00008000"],["79862.30000000","0.00009000"],["79862.11000000","0.00039000"],["79862.05000000","0.00010000"],["79861.96000000","0.00007000"],["79861.90000000","0.00043000"],["79861.83000000","0.20250000"],["79861.44000000","0.00008000"],["79861.32000000","0.00020000"],["79860.72000000","0.00008000"],["79860.64000000","0.00033000"],["79860.49000000","0.00007000"],["79860.14000000","1.87060000"],["79860.12000000","0.00026000"],["79860.07000000","0.00122000"],["79860.00000000","0.00775000"],["79859.46000000","0.00007000"],["79859.27000000","0.00015000"],["79858.97000000","0.00009000"],["79858.82000000","0.00090000"],["79858.58000000","0.00010000"],["79858.46000000","0.00012000"],["79858.30000000","0.00019000"],["79858.02000000","0.00100000"],["79857.98000000","0.00393000"],["79857.96000000","0.00007000"],["79857.70000000","0.00062000"],["79857.60000000","1.12377000"],["79857.59000000","3.75779000"],["79857.40000000","0.00025000"],["79857.14000000","0.00122000"],["79857.04000000","0.00054000"],["79857.01000000","0.00017000"],["79856.25000000","0.00375000"],["79856.00000000","0.00100000"],["79855.95000000","0.00010000"],["79855.66000000","0.00015000"],["79855.55000000","0.00009000"],["79855.49000000","0.00007000"],["79855.13000000","0.00021000"],["79855.11000000","0.00010000"],["79855.00000000","0.00015000"],["79854.97000000","0.00260000"],["79854.30000000","0.00015000"],["79854.19000000","0.00007000"],["79854.06000000","0.00007000"],["79853.82000000","0.07690000"],["79853.81000000","0.20250000"],["79853.63000000","0.00021000"],["79853.45000000","0.00183000"],["79852.94000000","0.00099000"],["79852.59000000","0.00020000"],["79852.53000000","0.00007000"],["79852.50000000","0.00034000"],["79852.35000000","0.00010000"],["79852.11000000","0.00026000"],["79852.06000000","0.00010000"],["79852.05000000","0.00010000"],["79852.00000000","0.00564000"],["79851.85000000","0.00014000"],["79851.76000000","0.00024000"],["79851.69000000","0.00013000"],["79851.50000000","0.00007000"],["79851.43000000","0.70707000"],["79850.59000000","0.00010000"],["79850.54000000","1.87060000"],["79850.48000000","0.00011000"],["79850.46000000","0.11607000"],["79850.40000000","0.00007000"],["79850.38000000","0.00024000"],["79850.06000000","0.00010000"],["79850.00000000","0.00739000"],["79849.97000000","0.00218000"],["79849.73000000","0.00010000"],["79849.63000000","0.00273000"],["79849.52000000","0.00044000"],["79849.47000000","0.00028000"],["79849.34000000","0.00030000"],["79849.25000000","0.00007000"],["79849.22000000","0.00012000"],["79848.83000000","0.00094000"],["79848.54000000","0.36586000"],["79848.48000000","0.00037000"],["79848.47000000","0.00287000"],["79847.76000000","0.05638000"],["79847.50000000","0.00007000"],["79847.30000000","0.00121000"],["79847.26000000","0.00007000"],["79847.05000000","0.00007000"],["79846.18000000","0.00027000"],["79846.15000000","0.00019000"],["79845.84000000","0.00045000"],["79845.80000000","0.07924000"],["79845.79000000","0.20250000"],["79845.56000000","0.00012000"],["79845.00000000","0.00009000"],["79844.98000000","0.06000000"],["79844.85000000","0.00007000"],["79844.58000000","0.00008000"],["79844.56000000","0.00244000"],["79844.44000000","0.00021000"],["79843.99000000","0.00151000"],["79843.73000000","0.00007000"],["79843.60000000","0.00097000"],["79843.59000000","0.00077000"],["79843.23000000","0.00011000"],["79843.04000000","0.00009000"],["79842.38000000","0.00114000"],["79842.09000000","0.00010000"],["79841.99000000","0.00007000"],["79841.57000000","0.00008000"],["79841.26000000","0.00009000"],["79840.85000000","0.00007000"],["79840.84000000","0.00025000"],["79840.32000000","0.01265000"],["79840.01000000","0.00050000"],["79840.00000000","0.00680000"],["79839.44000000","0.00007000"],["79839.29000000","0.00011000"],["79839.28000000","0.00028000"],["79839.16000000","0.00025000"],["79838.90000000","0.00007000"],["79838.78000000","0.00275000"],["79838.70000000","0.00105000"],["79838.49000000","0.09754000"],["79838.48000000","0.11607000"],["79838.38000000","0.00020000"],["79838.19000000","0.00007000"],["79838.07000000","0.00007000"],["79838.00000000","0.00007000"],["79837.83000000","0.00282000"],["79837.77000000","0.20250000"],["79837.55000000","0.00015000"],["79836.92000000","0.04528000"],["79836.86000000","0.00260000"],["79836.72000000","0.00007000"],["79836.28000000","0.00238000"],["79835.86000000","0.00017000"],["79835.70000000","0.00026000"],["79835.38000000","0.00011000"],["79835.29000000","0.00030000"],["79835.22000000","0.00019000"],["79835.14000000","0.00007000"],["79835.08000000","0.00017000"],["79834.87000000","0.00050000"],["79834.24000000","0.00010000"],["79834.15000000","0.00125000"],["79834.14000000","0.36586000"],["79834.09000000","0.00241000"],["79833.33000000","0.01628000"],["79833.11000000","0.00015000"],["79833.02000000","0.00958000"],["79832.94000000","0.00136000"],["79832.82000000","0.00007000"],["79832.34000000","0.00016000"],["79832.12000000","0.00399000"],["79832.00000000","0.00008000"],["79831.75000000","0.00375000"],["79831.60000000","0.00011000"],["79831.46000000","0.00007000"],["79831.39000000","0.00035000"],["79831.38000000","0.00009000"],["79831.34000000","0.00023000"],["79830.86000000","0.00270000"],["79830.32000000","1.50117000"],["79830.00000000","0.00057000"],["79829.85000000","0.00007000"],["79829.82000000","0.00014000"],["79829.76000000","0.00012000"],["79829.75000000","0.20250000"],["79829.00000000","0.00687000"],["79828.91000000","0.00016000"],["79828.82000000","0.00007000"],["79828.57000000","0.00036000"],["79828.44000000","0.00008000"],["79828.23000000","0.00025000"],["79827.91000000","0.00008000"],["79827.75000000","0.00010000"],["79827.65000000","0.00026000"],["79827.46000000","0.00010000"],["79827.42000000","0.00012000"],["79827.38000000","0.00035000"],["79827.17000000","0.00100000"],["79827.12000000","0.00007000"],["79826.92000000","0.00046000"],["79826.88000000","0.00007000"],["79826.70000000","0.00018000"],["79826.69000000","0.00086000"],["79826.65000000","0.00007000"],["79826.54000000","0.00018000"],["79826.50000000","0.11607000"],["79826.36000000","0.00008000"],["79826.21000000","0.00017000"],["79826.19000000","0.00007000"],["79826.00000000","1.15151000"],["79825.99000000","0.00341000"],["79825.34000000","0.00007000"],["79825.00000000","0.00012000"],["79824.65000000","0.00021000"],["79824.07000000","0.00007000"],["79824.03000000","0.00028000"],["79823.86000000","0.00018000"],["79823.75000000","0.00256000"],["79823.52000000","0.00364000"],["79823.40000000","0.00010000"],["79823.36000000","0.00106000"],["79823.33000000","0.00028000"],["79823.09000000","0.00013000"],["79823.07000000","0.00007000"],["79822.57000000","0.00020000"],["79822.22000000","0.00007000"],["79822.08000000","0.00007000"],["79822.07000000","0.00125000"],["79822.05000000","0.00007000"],["79822.03000000","0.00007000"],["79821.73000000","0.20250000"],["79821.71000000","0.00049000"],["79821.55000000","0.00007000"],["79821.45000000","0.00007000"],["79821.18000000","0.00202000"],["79821.02000000","0.05082000"],["79820.92000000","0.00007000"],["79820.46000000","0.00010000"],["79820.00000000","0.00096000"],["79819.85000000","0.00007000"],["79819.84000000","0.00007000"],["79819.73000000","0.36586000"],["79819.66000000","0.00007000"],["79819.56000000","0.00008000"],["79819.47000000","0.00026000"],["79819.07000000","0.00018000"],["79818.72000000","0.00014000"],["79818.67000000","0.00024000"],["79818.18000000","0.00124000"],["79817.97000000","0.00031000"],["79817.64000000","0.00048000"],["79816.85000000","0.00007000"],["79816.11000000","0.00027000"],["79816.00000000","0.00007000"],["79815.65000000","0.00007000"],["79815.38000000","0.00008000"],["79815.25000000","0.00008000"],["79814.84000000","0.00253000"],["79814.81000000","0.00010000"],["79814.63000000","0.00021000"],["79814.52000000","0.11607000"],["79814.06000000","0.00125000"],["79814.05000000","0.01051000"],["79814.00000000","0.00007000"],["79813.72000000","0.20250000"],["79812.98000000","0.00010000"],["79812.80000000","0.00007000"],["79812.50000000","0.00007000"],["79812.30000000","0.00008000"],["79812.28000000","3.75992000"],["79811.62000000","0.00011000"],["79811.60000000","0.00008000"],["79811.45000000","0.00026000"],["79811.22000000","0.00053000"],["79810.75000000","0.00007000"],["79810.74000000","0.00009000"],["79810.38000000","0.00007000"],["79810.31000000","0.00013000"],["79810.26000000","0.00007000"],["79810.00000000","0.00057000"],["79809.99000000","0.00007000"],["79809.96000000","0.00021000"],["79809.21000000","0.00018000"],["79809.07000000","0.00082000"],["79808.84000000","0.00015000"],["79808.45000000","0.00053000"],["79808.43000000","0.00041000"],["79808.06000000","0.00008000"],["79808.05000000","0.00019000"],["79808.00000000","0.00007000"],["79807.79000000","0.00010000"],["79807.69000000","0.00093000"],["79807.53000000","0.00057000"],["79807.00000000","0.00251000"],["79806.91000000","0.00040000"],["79806.84000000","0.00007000"],["79806.54000000","0.00067000"],["79806.43000000","0.00009000"],["79806.41000000","0.00007000"],["79806.23000000","0.00018000"],["79806.09000000","0.00007000"],["79805.99000000","0.00390000"],["79805.88000000","0.00031000"],["79805.69000000","0.20250000"],["79805.55000000","0.00008000"],["79805.43000000","0.00034000"],["79805.42000000","0.00010000"],["79805.33000000","0.36586000"],["79805.12000000","0.00017000"],["79805.00000000","0.00043000"],["79804.93000000","0.00017000"],["79804.90000000","0.00013000"],["79804.61000000","0.00028000"],["79804.43000000","0.00018000"],["79804.33000000","0.00010000"],["79804.00000000","0.00200000"],["79803.84000000","0.00007000"],["79803.66000000","0.00653000"],["79803.34000000","0.00026000"],["79803.06000000","0.00009000"],["79802.95000000","0.00008000"],["79802.91000000","0.00011000"],["79802.84000000","0.00007000"],["79802.82000000","0.00050000"],["79802.55000000","0.00691000"],["79802.54000000","0.11607000"],["79802.28000000","0.00007000"],["79802.15000000","0.00012000"],["79802.11000000","0.00050000"],["79801.54000000","0.00007000"],["79801.42000000","0.00333000"],["79800.78000000","0.00007000"],["79800.69000000","0.00008000"],["79800.37000000","0.00007000"],["79800.01000000","0.00009000"],["79800.00000000","1.64057000"],["79799.90000000","0.00012000"],["79799.85000000","0.00007000"],["79799.77000000","0.00010000"],["79799.01000000","0.00031000"],["79798.86000000","0.00028000"],["79798.69000000","3.76056000"],["79798.68000000","0.00265000"],["79798.28000000","0.00010000"],["79798.18000000","0.00046000"],["79798.08000000","0.00007000"],["79797.90000000","0.00007000"],["79797.75000000","0.00007000"],["79797.67000000","0.20250000"],["79797.66000000","0.00007000"],["79797.15000000","0.00047000"],["79796.73000000","0.00009000"],["79796.62000000","0.00098000"],["79796.50000000","0.00042000"],["79796.47000000","0.00018000"],["79796.29000000","0.00008000"],["79796.16000000","0.00008000"],["79796.00000000","0.00015000"],["79795.32000000","0.00026000"],["79794.87000000","0.00007000"],["79794.64000000","0.00008000"],["79794.58000000","0.00007000"],["79794.40000000","0.00008000"],["79794.26000000","0.00016000"],["79794.10000000","0.00115000"],["79794.07000000","1.20000000"],["79793.84000000","0.36586000"],["79793.20000000","0.00007000"],["79793.05000000","0.00010000"],["79792.73000000","0.00061000"],["79792.31000000","0.00067000"],["79792.19000000","0.00076000"],["79792.15000000","4.46846000"],["79791.91000000","0.00270000"],["79791.66000000","0.00069000"],["79791.58000000","0.00013000"],["79791.17000000","0.00027000"],["79791.05000000","0.00007000"],["79791.03000000","0.00014000"],["79790.81000000","0.00018000"],["79790.60000000","0.00024000"],["79790.56000000","0.11607000"],["79790.10000000","0.00007000"],["79790.09000000","0.00030000"],["79790.00000000","1.47233000"],["79789.89000000","0.00043000"],["79789.65000000","0.20250000"],["79789.32000000","0.00007000"],["79789.20000000","0.00007000"],["79789.06000000","0.00032000"],["79788.77000000","0.00011000"],["79788.46000000","0.00008000"],["79788.23000000","0.00009000"],["79788.05000000","0.00053000"],["79787.78000000","0.00044000"],["79787.40000000","0.00035000"],["79787.18000000","0.00026000"],["79787.09000000","0.00012000"],["79786.63000000","0.00019000"],["79786.45000000","0.00008000"],["79785.93000000","0.00010000"],["79785.90000000","0.00011000"]],"asks":[["79974.47000000","1.26434000"],["79974.48000000","0.00097000"],["79974.49000000","0.00013000"],["79975.73000000","0.00014000"],["79975.74000000","0.01707000"],["79976.00000000","0.00465000"],["79976.14000000","0.00007000"],["79976.15000000","0.04212000"],["79976.35000000","0.00007000"],["79976.68000000","0.00007000"],["79976.71000000","0.00014000"],["79976.72000000","0.08821000"],["79976.84000000","0.00007000"],["79976.93000000","0.00014000"],["79976.94000000","0.01763000"],["79977.01000000","0.00014000"],["79977.02000000","0.02004000"],["79977.10000000","0.05310000"],["79977.13000000","0.00014000"],["79977.17000000","0.00007000"],["79977.18000000","0.00007000"],["79977.42000000","0.00014000"],["79978.00000000","0.03114000"],["79978.29000000","0.05651000"],["79978.30000000","0.01990000"],["79978.43000000","0.00007000"],["79978.44000000","0.00007000"],["79978.74000000","0.00126000"],["79978.92000000","0.00007000"],["79979.54000000","0.02257000"],["79979.88000000","0.00007000"],["79979.99000000","0.00007000"],["79980.00000000","0.02421000"],["79980.12000000","0.00592000"],["79980.16000000","0.27933000"],["79980.17000000","0.31273000"],["79980.46000000","0.00013000"],["79980.51000000","0.00583000"],["79981.00000000","0.00007000"],["79981.27000000","0.00037000"],["79981.28000000","0.00039000"],["79981.29000000","0.00021000"],["79981.30000000","0.00007000"],["79981.55000000","0.00010000"],["79981.77000000","0.00008000"],["79981.98000000","0.00007000"],["79982.00000000","0.02400000"],["79982.29000000","0.00920000"],["79982.32000000","0.00014000"],["79982.46000000","0.07749000"],["79982.47000000","0.20259000"],["79982.67000000","0.00026000"],["79983.02000000","0.15000000"],["79983.05000000","0.00597000"],["79983.07000000","0.00435000"],["79983.08000000","0.00007000"],["79983.24000000","0.12502000"],["79983.43000000","0.01027000"],["79983.58000000","0.00400000"],["79984.00000000","0.02407000"],["79984.26000000","0.00625000"],["79984.27000000","0.01756000"],["79984.33000000","0.00450000"],["79984.62000000","0.07320000"],["79984.63000000","0.07535000"],["79985.16000000","0.00021000"],["79985.52000000","0.00007000"],["79985.71000000","0.00588000"],["79985.77000000","0.07968000"],["79986.00000000","0.02407000"],["79986.08000000","0.00400000"],["79986.20000000","0.00007000"],["79986.29000000","0.03022000"],["79986.86000000","0.00007000"],["79987.14000000","0.00449000"],["79987.24000000","0.00007000"],["79987.66000000","0.01749000"],["79987.73000000","0.00591000"],["79987.82000000","0.00008000"],["79988.00000000","0.02400000"],["79988.11000000","0.13341000"],["79988.12000000","1.15964000"],["79988.14000000","0.00800000"],["79988.20000000","1.04939000"],["79988.72000000","0.00007000"],["79988.84000000","0.08566000"],["79989.03000000","0.00014000"],["79989.32000000","0.00007000"],["79989.53000000","0.00010000"],["79989.75000000","1.87060000"],["79989.77000000","0.37515000"],["79989.84000000","0.00008000"],["79990.00000000","0.02400000"],["79990.08000000","0.00007000"],["79990.33000000","0.02000000"],["79990.47000000","0.00009000"],["79990.59000000","0.00166000"],["79990.75000000","0.00026000"],["79990.84000000","0.03224000"],["79990.85000000","0.00007000"],["79990.93000000","0.02000000"],["79991.07000000","0.02000000"],["79991.13000000","0.01749000"],["79991.14000000","0.00400000"],["79991.16000000","0.02000000"],["79991.20000000","0.06420000"],["79991.21000000","0.02000000"],["79991.22000000","0.00007000"],["79991.24000000","0.12501000"],["79991.39000000","0.00434000"],["79991.40000000","0.00007000"],["79991.64000000","0.33763000"],["79991.73000000","0.00598000"],["79991.82000000","0.00008000"],["79992.00000000","0.02414000"],["79992.68000000","1.13284000"],["79992.69000000","1.04939000"],["79992.87000000","0.00007000"],["79992.90000000","0.00014000"],["79992.93000000","0.20257000"],["79993.20000000","0.07284000"],["79993.48000000","0.00007000"],["79993.89000000","0.00250000"],["79993.90000000","0.01300000"],["79993.96000000","0.00007000"],["79993.99000000","0.02000000"],["79994.00000000","0.02400000"],["79994.02000000","0.20631000"],["79994.56000000","0.00400000"],["79994.92000000","0.02000000"],["79994.99000000","1.87060000"],["79995.00000000","0.70000000"],["79995.37000000","0.01749000"],["79995.56000000","0.00007000"],["79995.82000000","0.00015000"],["79996.00000000","0.02724000"],["79996.18000000","1.26733000"],["79996.23000000","0.00454000"],["79996.57000000","0.00250000"],["79996.61000000","0.00047000"],["79996.64000000","0.00070000"],["79996.77000000","0.00014000"],["79996.96000000","0.00400000"],["79997.20000000","0.37512000"],["79997.51000000","0.00010000"],["79997.64000000","0.00007000"],["79997.84000000","0.00007000"],["79997.91000000","0.00008000"],["79997.97000000","0.00007000"],["79997.99000000","0.02000000"],["79998.00000000","0.02400000"],["79998.03000000","0.02000000"],["79998.46000000","0.00625000"],["79998.47000000","0.00009000"],["79998.48000000","0.02000000"],["79998.57000000","0.01749000"],["79998.81000000","0.02000000"],["79998.82000000","0.02000000"],["79998.83000000","0.00026000"],["79998.88000000","0.04000000"],["79999.13000000","1.04939000"],["79999.19000000","0.33760000"],["79999.24000000","0.12500000"],["79999.49000000","0.02423000"],["79999.56000000","0.00007000"],["79999.72000000","0.00007000"],["79999.74000000","0.02000000"],["79999.82000000","0.00008000"],["79999.92000000","0.00400000"],["79999.97000000","0.36586000"],["79999.98000000","1.87060000"],["80000.00000000","0.12116000"],["80000.18000000","0.51892000"],["80000.23000000","0.20631000"],["80000.55000000","0.00166000"],["80000.56000000","0.02474000"],["80000.64000000","0.00014000"],["80000.93000000","0.20250000"],["80000.97000000","0.33759000"],["80001.80000000","0.00007000"],["80001.84000000","0.01749000"],["80002.00000000","0.02400000"],["80002.31000000","0.01573000"],["80003.20000000","1.04939000"],["80003.25000000","0.00012000"],["80003.55000000","0.00007000"],["80003.56000000","0.49314000"],["80003.82000000","0.00008000"],["80003.88000000","0.00007000"],["80004.00000000","0.02400000"],["80004.20000000","0.00193000"],["80004.23000000","0.00059000"],["80004.40000000","0.00400000"],["80004.44000000","0.00281000"],["80004.51000000","0.00014000"],["80005.17000000","0.01749000"],["80005.18000000","1.54256000"],["80005.24000000","0.00399000"],["80005.49000000","0.00010000"],["80005.60000000","0.00007000"],["80005.81000000","0.00007000"],["80005.83000000","0.03224000"],["80005.94000000","0.62513000"],["80005.96000000","0.00007000"],["80005.98000000","0.00008000"],["80006.00000000","0.02400000"],["80006.46000000","0.00009000"],["80006.84000000","0.42900000"],["80006.85000000","0.00026000"],["80007.20000000","0.00400000"],["80007.28000000","2.91999000"],["80007.52000000","0.33756000"],["80007.73000000","0.10000000"],["80007.82000000","0.00008000"],["80007.97000000","0.36586000"],["80007.98000000","0.65903000"],["80008.00000000","0.02400000"],["80008.04000000","0.00007000"],["80008.38000000","0.00014000"],["80009.81000000","0.00007000"],["80010.00000000","0.12424000"],["80010.01000000","0.16097000"],["80010.02000000","0.20250000"],["80010.03000000","0.00065000"],["80010.12000000","0.00007000"],["80010.35000000","0.02000000"],["80011.10000000","0.33755000"],["80011.82000000","0.00008000"],["80012.00000000","0.02407000"],["80012.20000000","0.00007000"],["80012.25000000","0.00014000"],["80012.46000000","0.03224000"],["80012.73000000","0.01270000"],["80012.80000000","0.00400000"],["80013.04000000","0.01749000"],["80013.27000000","1.04939000"],["80013.36000000","0.00007000"],["80013.47000000","0.00010000"],["80013.89000000","0.00010000"],["80013.96000000","0.00007000"],["80014.00000000","0.02400000"],["80014.05000000","0.00008000"],["80014.07000000","0.02000000"],["80014.28000000","0.00007000"],["80014.44000000","1.37990000"],["80014.45000000","1.20058000"],["80014.83000000","0.02000000"],["80014.90000000","0.00026000"],["80014.95000000","0.02000000"],["80015.00000000","0.01000000"],["80015.04000000","1.87060000"],["80015.10000000","1.23763000"],["80015.60000000","0.00400000"],["80015.61000000","0.00012000"],["80015.69000000","0.04371000"],["80015.99000000","0.00007000"],["80016.00000000","0.02414000"],["80016.20000000","0.01270000"],["80016.36000000","0.00007000"],["80016.67000000","0.50235000"],["80016.68000000","0.36586000"],["80016.87000000","0.09283000"],["80017.68000000","1.04939000"],["80018.00000000","0.02400000"],["80018.01000000","0.00007000"],["80018.06000000","0.02000000"],["80018.25000000","0.00400000"],["80018.44000000","0.00007000"],["80018.56000000","0.02000000"],["80018.87000000","0.02000000"],["80018.88000000","0.02000000"],["80018.95000000","0.04000000"],["80018.97000000","0.00426000"],["80019.38000000","0.00624000"],["80019.68000000","0.02000000"],["80019.74000000","0.02000000"],["80020.00000000","0.11773000"],["80020.01000000","0.84105000"],["80020.02000000","0.20250000"],["80020.35000000","0.00007000"],["80020.52000000","0.00007000"],["80021.12000000","0.00007000"],["80021.13000000","0.03224000"],["80021.33000000","0.00557000"],["80021.45000000","0.00010000"],["80022.00000000","0.02400000"],["80022.12000000","0.00008000"],["80022.54000000","0.00007000"],["80022.60000000","0.00007000"],["80022.67000000","0.00400000"],["80023.27000000","0.62500000"],["80023.30000000","0.00026000"],["80023.77000000","0.00014000"],["80023.99000000","1.87060000"],["80024.00000000","0.02400000"],["80024.68000000","0.00007000"],["80024.80000000","0.00400000"],["80024.88000000","0.00651000"],["80025.57000000","0.00007000"],["80025.60000000","0.00627000"],["80025.69000000","0.75133000"],["80025.70000000","1.04939000"],["80025.88000000","0.00425000"],["80026.00000000","0.02400000"],["80026.76000000","0.00007000"],["80027.01000000","0.36586000"],["80027.22000000","0.04032000"],["80027.56000000","1.00626000"],["80027.64000000","0.00280000"],["80028.00000000","0.02407000"],["80028.02000000","0.20250000"],["80028.76000000","0.00400000"],["80028.84000000","0.00007000"],["80028.88000000","0.00007000"],["80029.31000000","0.00029000"],["80029.43000000","0.00010000"],["80029.95000000","0.00007000"],["80030.00000000","0.02400000"],["80030.01000000","0.01242000"],["80030.19000000","0.00008000"],["80030.37000000","0.02000000"],["80030.92000000","0.00007000"],["80031.31000000","0.00026000"],["80031.60000000","1.12632000"],["80031.61000000","1.87060000"],["80031.62000000","0.82898000"],["80031.65000000","0.00007000"],["80031.90000000","0.37485000"],["80031.91000000","0.00007000"],["80031.93000000","1.04939000"],["80032.00000000","0.02814000"],["80032.53000000","0.00200000"],["80033.69000000","0.00007000"],["80034.00000000","0.02400000"],["80034.53000000","0.93638000"],["80034.54000000","1.23733000"],["80034.62000000","0.00069000"],["80034.97000000","0.02000000"],["80035.05000000","0.36586000"],["80035.08000000","0.00007000"],["80035.57000000","0.00190000"],["80035.58000000","0.43861000"],["80035.77000000","0.00007000"],["80035.92000000","0.00100000"],["80035.98000000","1.04939000"],["80036.00000000","0.02400000"],["80036.02000000","0.20250000"],["80036.64000000","0.00007000"],["80037.17000000","0.00007000"],["80037.19000000","0.00007000"],["80037.23000000","0.00311000"],["80037.24000000","0.04689000"],["80037.30000000","0.30663000"],["80037.31000000","0.83363000"],["80037.41000000","0.00010000"],["80037.76000000","0.01270000"],["80037.83000000","0.00007000"],["80038.00000000","0.02400000"],["80038.08000000","0.02000000"],["80038.26000000","0.00008000"],["80038.52000000","0.03224000"],["80038.86000000","0.02000000"],["80038.92000000","0.02000000"],["80039.25000000","0.00007000"],["80039.71000000","0.02000000"],["80039.77000000","0.02000000"],["80039.84000000","0.00026000"],["80040.00000000","0.02407000"],["80040.44000000","0.30370000"],["80040.68000000","0.99524000"],["80040.69000000","1.04939000"],["80042.00000000","0.02400000"],["80042.35000000","0.00535000"],["80042.51000000","0.00110000"],["80042.92000000","0.02000000"],["80043.16000000","1.87060000"],["80043.17000000","0.36586000"],["80043.26000000","0.01722000"],["80043.41000000","0.00007000"],["80043.42000000","0.02000000"],["80043.73000000","0.02000000"],["80043.77000000","0.00007000"],["80043.80000000","0.02000000"],["80043.82000000","0.02000000"],["80044.00000000","1.27089000"],["80044.40000000","0.00007000"],["80044.41000000","0.02000000"],["80045.15000000","1.04939000"],["80045.25000000","0.00399000"],["80045.39000000","0.00010000"],["80045.94000000","0.00007000"],["80046.00000000","0.02407000"],["80046.33000000","0.00008000"],["80046.36000000","0.83149000"],["80046.69000000","0.47220000"],["80046.77000000","0.02000000"],["80047.88000000","0.00026000"],["80047.99000000","1.87060000"],["80048.00000000","0.02414000"],["80048.60000000","0.00007000"],["80048.93000000","0.84464000"],["80048.94000000","1.23710000"],["80049.65000000","0.00007000"],["80049.99000000","0.00311000"],["80050.00000000","0.02407000"],["80050.01000000","0.12897000"],["80050.99000000","1.04939000"],["80051.47000000","0.00007000"],["80051.76000000","0.36586000"],["80051.98000000","0.00008000"],["80052.00000000","0.02400000"],["80052.16000000","0.00007000"],["80053.14000000","0.01155000"],["80053.26000000","0.00010000"],["80053.37000000","0.00010000"],["80053.58000000","0.00007000"],["80053.81000000","0.00007000"],["80053.89000000","0.04032000"],["80053.98000000","0.88853000"],["80053.99000000","1.87060000"],["80054.00000000","0.02400000"],["80054.40000000","0.00008000"],["80055.14000000","0.00007000"],["80055.31000000","1.04939000"],["80055.32000000","0.00652000"],["80056.00000000","0.02400000"],["80056.01000000","0.01234000"],["80056.27000000","0.00026000"],["80058.00000000","0.02407000"],["80059.90000000","0.87880000"],["80059.91000000","1.87060000"],["80059.92000000","0.00007000"],["80059.93000000","1.04939000"],["80060.00000000","0.02400000"],["80060.01000000","0.10434000"],["80060.06000000","0.00007000"],["80061.04000000","0.02000000"],["80061.20000000","0.20431000"],["80061.21000000","0.36586000"],["80061.35000000","0.00010000"],["80061.90000000","0.02000000"],["80061.93000000","0.00007000"],["80062.00000000","0.02407000"],["80062.47000000","0.00008000"],["80062.56000000","0.00014000"],["80063.20000000","0.25000000"],["80064.00000000","0.02414000"],["80064.02000000","0.00007000"],["80064.04000000","1.04939000"],["80064.22000000","0.00007000"],["80064.72000000","0.00026000"],["80064.95000000","0.00218000"],["80065.90000000","2.15754000"],["80065.91000000","3.13843000"],["80066.00000000","0.02400000"],["80066.01000000","0.00007000"],["80066.22000000","0.01154000"],["80066.61000000","0.03224000"],["80066.88000000","0.00007000"],["80067.29000000","0.10000000"],["80067.43000000","1.87060000"],["80067.44000000","2.02466000"],["80067.68000000","0.00007000"],["80068.00000000","0.02625000"],["80068.60000000","2.18502000"],["80068.61000000","3.74789000"],["80069.33000000","0.00010000"],["80069.57000000","0.36586000"],["80069.99000000","0.00269000"],["80070.00000000","0.02407000"],["80070.47000000","0.00007000"],["80070.54000000","0.00008000"],["80070.70000000","3.14627000"],["80071.90000000","0.00898000"],["80072.00000000","0.02400000"],["80072.51000000","0.00007000"],["80073.18000000","0.00026000"],["80073.64000000","0.00025000"],["80074.00000000","0.02400000"],["80074.40000000","0.00100000"],["80074.44000000","1.04939000"],["80074.63000000","0.00007000"],["80075.09000000","0.00555000"],["80075.44000000","0.00007000"],["80076.00000000","0.02407000"],["80077.03000000","1.87060000"],["80077.25000000","0.00399000"],["80077.31000000","0.00010000"],["80077.58000000","2.00550000"],["80077.92000000","0.00007000"],["80077.94000000","0.02804000"],["80078.00000000","0.02407000"],["80078.53000000","0.03224000"],["80078.61000000","0.00008000"],["80079.84000000","0.00280000"],["80080.00000000","0.02407000"],["80080.52000000","0.36586000"],["80080.88000000","0.00007000"],["80081.14000000","0.12060000"],["80081.29000000","0.00007000"],["80081.50000000","0.00026000"],["80081.92000000","0.01281000"],["80082.00000000","0.02400000"],["80082.11000000","0.00374000"],["80083.20000000","0.00007000"],["80083.60000000","0.00007000"],["80083.97000000","0.00269000"],["80084.00000000","0.02400000"],["80084.19000000","0.04551000"],["80085.04000000","0.00007000"],["80085.29000000","0.00010000"],["80085.41000000","0.00393000"],["80086.00000000","0.02407000"],["80086.22000000","0.00200000"],["80086.63000000","1.87060000"],["80086.68000000","0.00008000"],["80088.00000000","0.15891000"],["80088.63000000","0.36586000"],["80088.74000000","0.40000000"],["80089.70000000","0.00026000"],["80090.00000000","0.02407000"],["80090.63000000","0.00374000"],["80090.96000000","0.00007000"],["80091.29000000","0.00019000"],["80092.00000000","0.02400000"],["80092.63000000","0.00010000"],["80093.27000000","0.00010000"],["80093.29000000","0.00007000"],["80093.75000000","0.00007000"],["80093.91000000","0.00007000"],["80093.95000000","0.12897000"],["80093.98000000","0.00018000"],["80094.00000000","0.02400000"],["80096.00000000","0.02414000"],["80096.15000000","0.00007000"],["80096.87000000","0.22425000"],["80097.30000000","0.36586000"],["80097.54000000","0.00007000"],["80098.00000000","0.02400000"],["80098.01000000","0.00026000"],["80098.14000000","0.00031000"],["80098.72000000","0.00007000"],["80099.79000000","0.03745000"],["80100.00000000","0.02425000"],["80100.11000000","0.00007000"],["80101.25000000","0.00010000"],["80101.35000000","0.00014000"],["80102.00000000","0.02400000"],["80102.42000000","0.00160000"],["80102.82000000","0.00008000"],["80103.78000000","0.00007000"],["80103.95000000","0.00007000"],["80104.00000000","0.02400000"],["80104.34000000","0.00029000"],["80104.93000000","3.74619000"],["80105.30000000","0.00465000"],["80105.57000000","0.00024000"],["80105.77000000","0.36586000"],["80106.00000000","0.02407000"],["80106.29000000","0.00026000"],["80106.48000000","0.00007000"],["80107.86000000","0.05660000"],["80108.00000000","0.02400000"],["80108.01000000","0.00007000"],["80108.94000000","0.03785000"],["80108.95000000","0.04587000"],["80109.23000000","0.00010000"],["80109.90000000","0.00007000"],["80110.00000000","0.02400000"],["80110.03000000","0.00007000"],["80110.87000000","0.03263000"],["80111.69000000","0.00007000"],["80112.00000000","0.02400000"],["80112.11000000","0.00007000"],["80113.99000000","0.02465000"],["80114.00000000","0.02400000"],["80114.32000000","0.00026000"],["80114.54000000","0.03224000"],["80114.59000000","0.00086000"],["80114.87000000","0.00100000"],["80115.99000000","0.00076000"],["80116.00000000","0.02400000"],["80116.01000000","0.00007000"],["80117.21000000","0.00010000"],["80117.98000000","0.00125000"],["80117.99000000","0.01535000"],["80118.00000000","0.02400000"],["80118.29000000","0.00020000"],["80118.36000000","0.00007000"],["80118.96000000","0.00008000"],["80119.27000000","0.00007000"],["80119.80000000","0.00300000"],["80120.00000000","0.02400000"],["80122.00000000","0.02400000"],["80122.53000000","0.00007000"],["80122.77000000","0.00026000"],["80122.88000000","0.00007000"],["80124.00000000","0.02400000"],["80125.00000000","0.00007000"],["80125.05000000","0.00007000"],["80125.19000000","0.00010000"],["80125.25000000","0.00399000"],["80125.89000000","0.00007000"],["80126.00000000","0.02400000"],["80126.66000000","0.80000000"],["80126.68000000","0.00018000"],["80127.08000000","0.00007000"],["80128.00000000","0.02407000"],["80128.16000000","0.00069000"],["80128.78000000","0.00007000"],["80128.80000000","0.03224000"],["80129.28000000","0.00007000"],["80129.32000000","0.00010000"],["80129.76000000","0.00007000"],["80129.99000000","0.00125000"],["80130.00000000","0.02450000"],["80130.95000000","0.00026000"],["80131.95000000","0.00008000"],["80132.00000000","0.02410000"],["80132.01000000","0.00007000"],["80132.89000000","0.00023000"],["80132.95000000","0.00007000"],["80133.17000000","0.00010000"],["80133.52000000","0.00202000"],["80133.92000000","0.00007000"],["80134.00000000","0.02400000"],["80134.25000000","1.50124000"],["80135.10000000","0.00008000"],["80135.29000000","3.74477000"],["80136.00000000","0.02413000"],["80136.35000000","0.00010000"],["80137.08000000","0.00007000"],["80138.00000000","0.02400000"],["80138.41000000","0.00042000"],["80138.46000000","0.00035000"],["80138.47000000","0.00007000"],["80138.81000000","0.03224000"],["80138.88000000","0.00145000"],["80139.20000000","0.00007000"],["80139.35000000","0.00026000"],["80140.00000000","0.12450000"],["80140.14000000","0.00014000"],["80140.32000000","0.00007000"],["80140.90000000","0.00048000"],["80141.88000000","0.00007000"],["80142.00000000","0.02400000"],["80142.47000000","0.00160000"],["80142.51000000","0.00020000"],["80142.85000000","0.00013000"],["80142.90000000","0.00007000"],["80143.36000000","0.00007000"],["80144.00000000","0.02400000"],["80144.08000000","0.01265000"],["80144.81000000","0.00007000"],["80145.91000000","0.00012000"],["80146.00000000","0.02400000"],["80146.11000000","0.00007000"],["80146.15000000","0.00010000"],["80146.53000000","0.00016000"],["80146.60000000","0.00022000"],["80147.46000000","0.00026000"],["80148.00000000","0.02400000"],["80148.09000000","0.00010000"],["80148.26000000","0.01572000"],["80148.30000000","0.00007000"],["80148.89000000","0.03127000"],["80149.62000000","0.00007000"],["80149.73000000","0.00100000"],["80149.99000000","0.00269000"],["80150.00000000","0.75477000"],["80150.88000000","0.00007000"],["80151.24000000","0.00008000"],["80151.51000000","0.00008000"],["80151.89000000","0.00160000"],["80152.00000000","0.02400000"],["80152.64000000","0.00030000"],["80152.83000000","0.00010000"],["80152.89000000","0.00007000"],["80152.94000000","0.00009000"],["80153.04000000","0.00007000"],["80153.78000000","0.00016000"],["80153.89000000","0.03224000"],["80154.00000000","0.02400000"],["80154.85000000","0.00017000"],["80155.51000000","0.00026000"],["80156.00000000","0.02400000"],["80156.88000000","0.00007000"],["80157.87000000","0.00007000"],["80158.00000000","0.02400000"],["80158.15000000","0.32509000"],["80158.30000000","0.01958000"],["80159.14000000","0.00007000"],["80159.70000000","0.00023000"],["80159.76000000","0.00390000"],["80160.00000000","0.02475000"],["80160.41000000","0.00007000"],["80161.36000000","4.49004000"],["80162.00000000","0.02400000"],["80162.16000000","0.00155000"],["80162.64000000","0.00007000"],["80162.99000000","0.00008000"],["80163.63000000","0.01570000"],["80163.98000000","0.03224000"],["80164.00000000","0.02400000"],["80164.06000000","0.00007000"],["80164.07000000","0.00026000"],["80164.12000000","0.00009000"],["80164.28000000","0.00009000"],["80164.32000000","0.00007000"],["80164.45000000","0.00322000"],["80164.59000000","3.74340000"],["80165.49000000","0.00033000"],["80166.00000000","0.02400000"],["80166.26000000","0.00136000"],["80166.29000000","0.00025000"],["80166.63000000","0.00007000"],["80166.66000000","0.11515000"],["80167.38000000","0.00008000"],["80167.50000000","0.00010000"],["80167.88000000","0.00025000"],["80168.00000000","0.02400000"],["80168.75000000","0.00011000"],["80169.34000000","0.00007000"],["80169.41000000","0.00281000"],["80169.69000000","0.00185000"],["80170.00000000","0.02450000"],["80170.30000000","0.00374000"],["80170.83000000","0.00025000"],["80171.34000000","0.00016000"],["80171.37000000","0.00010000"],["80172.00000000","0.02452000"],["80172.19000000","0.00026000"],["80172.41000000","0.00007000"],["80172.54000000","0.00498000"],["80173.07000000","0.00022000"],["80173.33000000","0.00007000"],["80173.86000000","0.00007000"],["80174.00000000","0.02400000"],["80174.09000000","0.00007000"],["80175.16000000","0.12483000"],["80175.43000000","0.00007000"],["80176.00000000","0.02639000"],["80176.32000000","0.00007000"],["80176.41000000","0.00007000"],["80176.47000000","0.00068000"],["80177.35000000","0.00380000"],["80178.00000000","0.02400000"],["80178.57000000","0.00025000"],["80178.79000000","0.00007000"],["80178.93000000","0.00014000"],["80178.99000000","0.05096000"],["80179.06000000","0.00126000"],["80179.20000000","0.00197000"],["80179.42000000","0.00007000"],["80180.00000000","0.02450000"],["80180.01000000","0.00007000"],["80180.06000000","0.00078000"],["80180.30000000","0.00026000"],["80180.54000000","0.00012000"],["80180.88000000","0.00007000"],["80181.75000000","0.00007000"],["80181.81000000","0.00030000"],["80182.00000000","0.02400000"],["80182.23000000","0.00028000"],["80183.52000000","0.00008000"],["80183.78000000","0.12897000"],["80184.00000000","0.02400000"],["80184.45000000","0.00167000"],["80184.71000000","0.00048000"],["80184.75000000","0.00007000"],["80185.71000000","0.00020000"],["80186.00000000","0.02400000"],["80187.03000000","0.00025000"],["80187.13000000","0.00007000"],["80187.19000000","0.00007000"],["80187.70000000","0.00100000"],["80188.00000000","0.02400000"],["80188.37000000","0.00026000"],["80188.67000000","0.00065000"],["80188.98000000","0.00017000"],["80189.85000000","0.00007000"],["80189.99000000","0.00269000"],["80190.00000000","0.02450000"],["80190.47000000","0.00007000"],["80190.63000000","0.00896000"],["80191.15000000","0.00015000"],["80191.18000000","0.00007000"],["80191.30000000","0.00007000"],["80191.77000000","0.00008000"],["80191.78000000","0.00008000"],["80192.00000000","0.02407000"],["80192.07000000","0.00031000"],["80192.28000000","0.00007000"],["80192.46000000","0.00011000"],["80193.16000000","3.74207000"],["80194.00000000","0.02400000"],["80194.39000000","0.00007000"],["80194.56000000","0.00086000"],["80195.26000000","0.01958000"],["80195.42000000","0.03224000"],["80196.00000000","0.02400000"],["80196.39000000","0.00026000"],["80196.77000000","0.00007000"],["80197.26000000","0.00416000"],["80197.45000000","0.00104000"],["80197.56000000","0.00007000"],["80197.67000000","0.00094000"],["80198.00000000","0.02400000"],["80198.58000000","0.00007000"],["80199.60000000","0.00007000"],["80199.66000000","0.00008000"],["80199.72000000","0.00300000"],["80199.75000000","0.00030000"],["80200.00000000","1.12661000"],["80200.17000000","0.00035000"],["80200.21000000","0.00049000"],["80200.56000000","0.00007000"],["80200.60000000","0.00046000"],["80201.73000000","0.00007000"],["80201.84000000","0.00007000"],["80202.63000000","0.00007000"],["80203.00000000","0.00122000"],["80203.13000000","0.00176000"],["80203.90000000","0.00007000"],["80205.34000000","0.00026000"],["80205.84000000","0.00007000"],["80206.32000000","0.02772000"],["80206.78000000","0.00012000"],["80207.14000000","0.00011000"],["80207.20000000","0.00012000"],["80207.42000000","0.00023000"],["80207.59000000","0.03224000"],["80207.78000000","0.00021000"],["80208.33000000","0.00083000"],["80208.69000000","0.00012000"],["80208.81000000","0.00016000"],["80208.85000000","0.00013000"],["80208.87000000","0.00044000"],["80209.13000000","2.83755000"],["80209.36000000","0.00017000"],["80209.51000000","0.11564000"],["80209.95000000","0.00018000"],["80210.00000000","0.00060000"],["80210.07000000","0.00007000"],["80210.74000000","0.00010000"],["80210.94000000","0.00374000"],["80211.76000000","0.00030000"],["80211.91000000","0.00034000"],["80211.93000000","0.00008000"],["80212.00000000","0.07727000"],["80212.45000000","0.00013000"],["80212.71000000","0.00007000"],["80213.40000000","0.01933000"],["80213.49000000","0.00011000"],["80213.67000000","0.00109000"],["80214.20000000","0.00018000"],["80214.25000000","0.00007000"],["80214.28000000","0.00020000"],["80215.36000000","0.00049000"],["80215.80000000","0.00008000"],["80216.00000000","1.69665000"],["80216.08000000","0.00465000"],["80216.15000000","0.01270000"],["80216.39000000","0.00010000"],["80216.99000000","0.00007000"],["80217.06000000","0.00009000"],["80217.24000000","0.01898000"],["80217.72000000","0.00014000"],["80218.68000000","0.00087000"],["80219.44000000","0.20897000"],["80220.00000000","0.00402000"],["80220.21000000","0.00078000"],["80220.67000000","0.00007000"],["80221.47000000","0.00026000"],["80221.71000000","0.00007000"],["80222.22000000","0.00024000"],["80222.28000000","0.00007000"],["80222.49000000","0.00007000"],["80222.88000000","0.00007000"],["80223.20000000","0.00010000"],["80223.38000000","0.00024000"],["80224.05000000","0.00249000"],["80224.14000000","0.00016000"],["80224.47000000","0.00025000"],["80224.55000000","0.00046000"],["80224.82000000","0.00007000"],["80225.00000000","0.00010000"],["80225.32000000","0.00025000"],["80225.36000000","0.03224000"],["80225.38000000","0.00498000"],["80225.44000000","0.00077000"],["80225.52000000","0.00011000"],["80227.21000000","0.00010000"],["80227.24000000","0.00013000"],["80227.27000000","0.00177000"],["80227.58000000","0.00007000"],["80227.88000000","0.00020000"],["80228.16000000","0.00163000"],["80228.21000000","0.00029000"],["80228.57000000","0.00007000"],["80229.14000000","0.00008000"],["80229.56000000","0.00026000"],["80229.58000000","0.00023000"],["80229.93000000","0.14584000"],["80229.99000000","0.00269000"],["80230.00000000","0.00123000"],["80230.47000000","0.00023000"],["80230.76000000","0.00008000"],["80231.36000000","0.00031000"],["80231.70000000","0.00038000"],["80231.94000000","0.00008000"],["80232.05000000","0.00008000"],["80232.07000000","0.00858000"],["80232.38000000","0.00038000"],["80232.73000000","0.00011000"],["80232.87000000","0.00007000"],["80233.33000000","0.00010000"],["80233.34000000","0.00009000"],["80233.72000000","0.01270000"],["80234.04000000","0.00009000"],["80234.06000000","0.00011000"],["80234.87000000","0.00007000"],["80235.29000000","0.00313000"],["80235.85000000","0.00007000"],["80236.23000000","0.01743000"],["80236.60000000","0.00065000"],["80236.66000000","0.00008000"],["80236.98000000","0.00007000"],["80237.66000000","0.00117000"],["80237.95000000","0.00026000"],["80238.09000000","0.00025000"],["80238.17000000","0.00007000"],["80238.53000000","0.03224000"],["80238.88000000","0.00020000"],["80239.12000000","0.00050000"],["80239.81000000","0.00040000"],["80240.00000000","0.00160000"],["80240.01000000","0.00013000"],["80240.09000000","0.01000000"],["80240.49000000","0.00007000"],["80240.96000000","0.00013000"],["80241.73000000","0.00007000"],["80241.77000000","0.00030000"],["80241.79000000","3.73980000"],["80241.87000000","0.00097000"],["80241.97000000","2.50000000"],["80242.36000000","0.00007000"],["80242.75000000","0.00076000"],["80242.86000000","0.00044000"],["80243.46000000","0.00007000"],["80244.11000000","0.00027000"],["80244.63000000","0.00221000"],["80245.66000000","0.11306000"],["80245.71000000","0.00183000"],["80245.82000000","0.00011000"],["80245.98000000","0.00007000"],["80246.04000000","0.00026000"],["80246.16000000","0.00007000"],["80246.91000000","0.00068000"],["80247.16000000","0.00008000"],["80248.00000000","0.00087000"],["80248.08000000","0.00008000"],["80248.76000000","0.00007000"],["80249.38000000","0.00010000"],["80249.61000000","0.00024000"],["80249.65000000","0.00177000"],["80250.00000000","0.34673000"],["80250.11000000","0.00010000"],["80250.37000000","0.00008000"],["80250.47000000","0.00009000"],["80250.56000000","0.00374000"],["80250.57000000","0.11607000"],["80251.40000000","0.00007000"],["80251.67000000","0.00095000"],["80251.76000000","0.00009000"],["80252.18000000","0.00009000"],["80253.11000000","0.00013000"],["80253.15000000","0.00027000"],["80253.30000000","0.00011000"],["80253.55000000","0.00010000"],["80253.92000000","0.00007000"],["80254.06000000","0.00007000"],["80254.08000000","0.00571000"],["80254.14000000","0.00033000"],["80254.25000000","0.00026000"],["80254.36000000","0.00020000"],["80254.44000000","0.00007000"],["80254.54000000","0.00035000"],["80255.25000000","0.00007000"],["80255.42000000","0.00010000"],["80255.92000000","0.00008000"],["80255.96000000","0.00023000"],["80256.00000000","0.00007000"],["80256.28000000","0.00049000"],["80256.41000000","0.00010000"],["80256.47000000","0.00010000"],["80256.51000000","0.00014000"],["80256.89000000","0.00069000"],["80256.98000000","0.00066000"],["80257.00000000","0.00020000"]]}}
{"rx_ns": 10695252565400, "frame": {"stream":"btcusdt@depth20@100ms","data":{"lastUpdateId":99116115640,"bids":[["79974.46000000","3.43497000"],["79974.45000000","0.00048000"],["79974.44000000","0.00013000"],["79974.30000000","0.00014000"],["79974.29000000","0.09907000"],["79974.28000000","0.12784000"],["79974.26000000","0.00014000"],["79974.25000000","0.11199000"],["79973.70000000","0.00008000"],["79973.55000000","0.00007000"],["79973.07000000","0.00901000"],["79972.95000000","0.00014000"],["79972.94000000","0.08139000"],["79971.86000000","0.00014000"],["79971.85000000","0.33057000"],["79971.84000000","0.41438000"],["79971.83000000","0.00007000"],["79971.81000000","0.00875000"],["79971.79000000","0.01474000"],["79971.76000000","0.00007000"]],"asks":[["79974.47000000","0.31968000"],["79974.48000000","0.00090000"],["79974.49000000","0.00013000"],["79975.73000000","0.00014000"],["79975.74000000","0.01700000"],["79976.00000000","0.00465000"],["79976.35000000","0.00007000"],["79976.68000000","0.00007000"],["79976.71000000","0.00014000"],["79976.72000000","0.08821000"],["79976.84000000","0.00007000"],["79976.93000000","0.00014000"],["79976.94000000","0.01763000"],["79977.01000000","0.00014000"],["79977.02000000","0.02004000"],["79977.10000000","0.05303000"],["79977.17000000","0.00007000"],["79977.18000000","0.00007000"],["79977.42000000","0.00014000"],["79978.00000000","0.03114000"]]}}}
{"rx_ns": 10695252910000, "frame": {"stream":"btcusdt@depth@100ms","data":{"e":"depthUpdate","E":1787647690414,"s":"BTCUSDT","U":99116115598,"u":99116115640,"b":[["79974.46000000","3.43497000"],["79974.45000000","0.00048000"],["79969.23000000","0.01768000"],["79959.22000000","0.00007000"],["79921.10000000","0.00400000"],["79920.48000000","0.00000000"],["79883.78000000","0.01679000"],["71977.02000000","0.00416000"],["71977.01000000","0.00000000"]],"a":[["79974.47000000","0.31968000"],["79974.81000000","0.00000000"],["79975.74000000","0.01700000"],["79981.97000000","0.00000000"],["79982.66000000","0.00038000"],["79991.22000000","0.00007000"]]}}}
{"rx_ns": 10695361079800, "frame": {"stream":"btcusdt@depth20@100ms","data":{"lastUpdateId":99116115672,"bids":[["79974.46000000","3.19581000"],["79974.45000000","0.00083000"],["79974.44000000","0.00013000"],["79974.30000000","0.00014000"],["79974.29000000","0.09907000"],["79974.28000000","0.12784000"],["79974.26000000","0.00014000"],["79974.25000000","0.11199000"],["79973.70000000","0.00008000"],["79973.55000000","0.00007000"],["79973.07000000","0.00901000"],["79972.95000000","0.00014000"],["79972.94000000","0.08139000"],["79971.86000000","0.00014000"],["79971.85000000","0.33057000"],["79971.84000000","0.41438000"],["79971.83000000","0.00007000"],["79971.81000000","0.00875000"],["79971.79000000","0.01474000"],["79971.76000000","0.00007000"]],"asks":[["79974.47000000","0.50993000"],["79974.48000000","0.00090000"],["79974.49000000","0.00013000"],["79975.73000000","0.00014000"],["79975.74000000","0.01700000"],["79976.00000000","0.00465000"],["79976.35000000","0.00007000"],["79976.68000000","0.00007000"],["79976.71000000","0.00014000"],["79976.72000000","0.08821000"],["79976.84000000","0.00007000"],["79976.93000000","0.00014000"],["79976.94000000","0.01763000"],["79977.01000000","0.00014000"],["79977.02000000","0.02004000"],["79977.10000000","0.05303000"],["79977.17000000","0.00007000"],["79977.18000000","0.00007000"],["79977.42000000","0.00014000"],["79978.00000000","0.03114000"]]}}}
{"rx_ns": 10695361155500, "frame": {"stream":"btcusdt@depth@100ms","data":{"e":"depthUpdate","E":1787647690514,"s":"BTCUSDT","U":99116115641,"u":99116115672,"b":[["79974.46000000","3.19581000"],["79974.45000000","0.00083000"],["79971.28000000","0.00014000"],["79970.61000000","0.00129000"],["71977.02000000","0.00432000"],["63979.57000000","0.00031000"]],"a":[["79974.47000000","0.50993000"],["79978.30000000","0.01997000"],["79979.13000000","0.05127000"]]}}}
{"rx_ns": 10695452767300, "frame": {"stream":"btcusdt@depth20@100ms","data":{"lastUpdateId":99116115715,"bids":[["79974.46000000","3.19236000"],["79974.45000000","0.00048000"],["79974.44000000","0.00013000"],["79974.30000000","0.00014000"],["79974.29000000","0.09907000"],["79974.28000000","0.12784000"],["79974.26000000","0.00014000"],["79974.25000000","0.11199000"],["79973.70000000","0.00008000"],["79973.55000000","0.00014000"],["79973.07000000","0.00901000"],["79972.95000000","0.00014000"],["79972.94000000","0.08139000"],["79971.86000000","0.00014000"],["79971.85000000","0.33057000"],["79971.84000000","0.41438000"],["79971.83000000","0.00007000"],["79971.81000000","0.00875000"],["79971.79000000","0.01474000"],["79971.76000000","0.00007000"]],"asks":[["79974.47000000","0.31961000"],["79974.48000000","0.00090000"],["79974.49000000","0.00013000"],["79975.73000000","0.00014000"],["79975.74000000","0.01700000"],["79976.00000000","0.00465000"],["79976.35000000","0.00007000"],["79976.68000000","0.00007000"],["79976.71000000","0.00014000"],["79976.72000000","0.00014000"],["79976.84000000","0.00007000"],["79976.93000000","0.00014000"],["79976.94000000","0.01763000"],["79977.01000000","0.00014000"],["79977.02000000","0.02004000"],["79977.10000000","0.05303000"],["79977.17000000","0.00007000"],["79977.18000000","0.00007000"],["79977.42000000","0.00014000"],["79978.00000000","0.03114000"]]}}}
{"rx_ns": 10695452867700, "frame": {"stream":"btcusdt@depth@100ms","data":{"e":"depthUpdate","E":1787647690614,"s":"BTCUSDT","U":99116115673,"u":99116115715,"b":[["79974.46000000","3.19236000"],["79974.45000000","0.00048000"],["79973.55000000","0.00014000"],["79971.72000000","0.00400000"],["79971.29000000","0.00625000"],["79969.29000000","0.00000000"],["79969.14000000","1.87060000"],["79965.24000000","0.00400000"],["79933.67000000","0.00000000"],["71977.02000000","0.00416000"],["71977.00000000","1.00000000"],["63979.57000000","0.00000000"]],"a":[["79974.47000000","0.31961000"],["79976.72000000","0.00014000"],["79978.19000000","0.00000000"],["79978.30000000","0.02011000"],["79980.51000000","0.00007000"],["79982.28000000","0.00000000"],["79982.66000000","0.00000000"],["79983.01000000","0.00039000"],["79983.57000000","0.00038000"],["79985.70000000","0.00000000"],["79986.13000000","0.00400000"],["79987.13000000","0.00625000"],["79988.10000000","0.00400000"],["79989.77000000","0.00000000"],["80010.52000000","0.62510000"],["80158.30000000","0.00000000"]]}}}
{"rx_ns": 10695554882900, "frame": {"stream":"btcusdt@depth20@100ms","data":{"lastUpdateId":99116117732,"bids":[["79979.99000000","6.40585000"],["79979.98000000","0.00027000"],["79979.97000000","0.00013000"],["79978.74000000","2.27043000"],["79978.73000000","2.11687000"],["79978.42000000","0.47887000"],["79978.29000000","0.31259000"],["79978.28000000","0.49647000"],["79977.99000000","0.21365000"],["79977.97000000","0.03231000"],["79977.42000000","0.00014000"],["79977.17000000","0.19417000"],["79977.16000000","0.64736000"],["79977.04000000","0.04715000"],["79976.94000000","0.07500000"],["79976.90000000","0.00400000"],["79976.67000000","0.04020000"],["79976.41000000","0.20278000"],["79976.29000000","0.00591000"],["79975.99000000","0.20966000"]],"asks":[["79980.00000000","0.02578000"],["79980.01000000","0.00070000"],["79980.11000000","0.00014000"],["79980.12000000","0.00014000"],["79980.16000000","0.00014000"],["79980.17000000","0.00021000"],["79980.24000000","0.00877000"],["79981.07000000","0.00007000"],["79981.29000000","0.00014000"],["79981.30000000","0.00007000"],["79981.51000000","0.00014000"],["79981.52000000","0.01451000"],["79981.55000000","0.00010000"],["79981.95000000","0.00007000"],["79981.99000000","0.00014000"],["79982.00000000","0.02421000"],["79982.29000000","0.00955000"],["79982.32000000","0.00007000"],["79982.47000000","0.00009000"],["79982.63000000","0.00014000"]]}}}
{"rx_ns": 10695615644500, "frame": {"stream":"btcusdt@depth@100ms","data":{"e":"depthUpdate","E":1787647690714,"s":"BTCUSDT","U":99116115716,"u":99116117732,"b":[["79979.99000000","6.40585000"],["79979.98000000","0.00027000"],["79979.97000000","0.00013000"],["79979.87000000","0.00000000"],["79979.53000000","0.00000000"],["79979.12000000","0.00000000"],["79978.91000000","0.00000000"],["79978.86000000","0.00000000"],["79978.74000000","2.27043000"],["79978.73000000","2.11687000"],["79978.72000000","0.00000000"],["79978.71000000","0.00000000"],["79978.44000000","0.00000000"],["79978.43000000","0.00000000"],["79978.42000000","0.47887000"],["79978.41000000","0.00000000"],["79978.40000000","0.00000000"],["79978.30000000","0.00000000"],["79978.29000000","0.31259000"],["79978.28000000","0.49647000"],["79978.27000000","0.00000000"],["79978.00000000","0.00000000"],["79977.99000000","0.21365000"],["79977.98000000","0.00000000"],["79977.97000000","0.03231000"],["79977.42000000","0.00014000"],["79977.41000000","0.00000000"],["79977.17000000","0.19417000"],["79977.16000000","0.64736000"],["79977.15000000","0.00000000"],["79977.14000000","0.00000000"],["79977.09000000","0.00000000"],["79977.08000000","0.00000000"],["79977.04000000","0.04715000"],["79977.01000000","0.00000000"],["79977.00000000","0.00000000"],["79976.94000000","0.07500000"],["79976.93000000","0.00000000"],["79976.92000000","0.00000000"],["79976.90000000","0.00400000"],["79976.83000000","0.00000000"],["79976.71000000","0.00000000"],["79976.70000000","0.00000000"],["79976.67000000","0.04020000"],["79976.42000000","0.00000000"],["79976.41000000","0.20278000"],["79976.34000000","0.00000000"],["79976.29000000","0.00591000"],["79975.99000000","0.20966000"],["79975.85000000","0.00000000"],["79975.78000000","0.00007000"],["79975.74000000","0.18263000"],["79975.73000000","0.51851000"],["79975.72000000","0.20878000"],["79975.71000000","0.00000000"],["79975.59000000","0.00436000"],["79975.33000000","0.00000000"],["79975.22000000","0.00000000"],["79974.77000000","0.00007000"],["79974.65000000","0.00000000"],["79974.60000000","0.00000000"],["79974.48000000","0.00000000"],["79974.47000000","1.61782000"],["79974.46000000","0.21570000"],["79974.45000000","0.00007000"],["79974.44000000","0.00000000"],["79974.30000000","0.00000000"],["79974.29000000","0.00000000"],["79974.28000000","0.12770000"],["79974.26000000","0.00000000"],["79974.25000000","0.11192000"],["79973.80000000","0.00400000"],["79973.72000000","0.00000000"],["79973.47000000","0.03231000"],["79973.08000000","0.00000000"],["79973.07000000","0.00007000"],["79972.95000000","0.00000000"],["79972.94000000","0.00000000"],["79972.80000000","0.02000000"],["79972.78000000","0.00000000"],["79972.74000000","0.00013000"],["79972.69000000","0.00007000"],["79972.09000000","0.00591000"],["79971.86000000","0.00000000"],["79971.85000000","0.87831000"],["79971.84000000","0.41268000"],["79971.81000000","0.00840000"],["79971.79000000","0.00000000"],["79971.76000000","0.00000000"],["79971.72000000","0.00000000"],["79971.58000000","0.00453000"],["79971.51000000","0.00000000"],["79971.50000000","0.00000000"],["79971.29000000","0.00000000"],["79971.28000000","0.00007000"],["79970.73000000","0.00008000"],["79970.71000000","0.00259000"],["79970.68000000","0.00007000"],["79970.62000000","0.00625000"],["79970.56000000","0.00000000"],["79970.54000000","0.00000000"],["79970.51000000","0.00026000"],["79970.21000000","0.04000000"],["79969.98000000","0.00570000"],["79969.91000000","0.00000000"],["79969.90000000","0.00007000"],["79969.28000000","0.00000000"],["79969.23000000","0.00000000"],["79969.15000000","0.15543000"],["79968.86000000","0.00000000"],["79968.76000000","0.00007000"],["79968.67000000","0.00000000"],["79968.52000000","0.00000000"],["79968.49000000","0.00007000"],["79968.47000000","0.00000000"],["79968.11000000","0.08000000"],["79968.00000000","0.43576000"],["79967.85000000","0.02474000"],["79967.48000000","0.00000000"],["79967.47000000","0.96142000"],["79967.44000000","0.00000000"],["79967.42000000","0.00000000"],["79967.23000000","0.00000000"],["79967.20000000","0.33773000"],["79966.92000000","0.00000000"],["79966.70000000","0.00007000"],["79966.45000000","0.00000000"],["79966.20000000","0.00000000"],["79965.24000000","0.00000000"],["79964.91000000","0.00000000"],["79964.52000000","0.06296000"],["79964.49000000","0.00000000"],["79964.35000000","0.00000000"],["79964.23000000","0.00000000"],["79964.14000000","0.00000000"],["79963.29000000","0.42896000"],["79962.97000000","0.00000000"],["79962.96000000","0.00000000"],["79962.52000000","0.07247000"],["79962.40000000","0.26126000"],["79962.03000000","0.00007000"],["79960.41000000","0.00008000"],["79960.30000000","0.00000000"],["79960.14000000","0.00000000"],["79960.00000000","0.11787000"],["79959.50000000","0.00800000"],["79958.64000000","0.00000000"],["79958.61000000","0.00000000"],["79958.57000000","0.33777000"],["79958.09000000","0.00000000"],["79957.11000000","0.00000000"],["79957.10000000","0.00000000"],["79956.61000000","0.00000000"],["79956.42000000","0.00008000"],["79955.83000000","0.00000000"],["79955.74000000","0.00000000"],["79954.11000000","0.17333000"],["79954.01000000","0.00000000"],["79954.00000000","0.02800000"],["79952.68000000","0.62555000"],["79952.42000000","0.00008000"],["79952.41000000","0.00000000"],["79952.00000000","0.02414000"],["79951.90000000","0.00000000"],["79951.83000000","0.00000000"],["79951.25000000","0.33780000"],["79950.81000000","0.04400000"],["79950.70000000","0.00000000"],["79950.51000000","0.00000000"],["79950.17000000","0.00400000"],["79949.00000000","0.00400000"],["79948.89000000","0.00400000"],["79948.42000000","0.00008000"],["79948.09000000","0.00000000"],["79948.07000000","0.00000000"],["79947.83000000","0.00000000"],["79946.39000000","0.00000000"],["79944.79000000","0.09215000"],["79944.68000000","0.00000000"],["79944.42000000","0.00008000"],["79943.83000000","0.00000000"],["79943.55000000","0.77601000"],["79943.54000000","0.00000000"],["79941.15000000","1.23877000"],["79940.42000000","0.00008000"],["79940.40000000","0.00000000"],["79940.00000000","0.11968000"],["79939.83000000","0.00000000"],["79938.72000000","0.00000000"],["79936.71000000","0.00000000"],["79936.42000000","0.00008000"],["79935.83000000","0.00000000"],["79934.85000000","0.00000000"],["79934.78000000","0.00000000"],["79933.99000000","0.00000000"],["79931.83000000","0.00000000"],["79930.00000000","0.02450000"],["79928.61000000","0.00007000"],["79927.70000000","1.74250000"],["79927.68000000","0.00000000"],["79924.20000000","0.00000000"],["79924.17000000","0.00000000"],["79923.76000000","0.00000000"],["79922.04000000","0.00000000"],["79921.10000000","0.00000000"],["79918.77000000","0.00335000"],["79918.06000000","0.00310000"],["79916.28000000","0.00000000"],["79915.80000000","0.00000000"],["79914.27000000","0.00000000"],["79912.07000000","0.00000000"],["79911.88000000","0.00000000"],["79911.65000000","0.00000000"],["79910.52000000","0.00000000"],["79909.33000000","0.00000000"],["79903.48000000","0.00000000"],["79900.53000000","0.00000000"],["79900.37000000","0.00000000"],["79897.57000000","0.00311000"],["79896.43000000","0.00008000"],["79894.98000000","0.00000000"],["79893.96000000","0.00000000"],["79888.03000000","0.00000000"],["79883.56000000","0.00399000"],["79880.09000000","0.00000000"],["79867.39000000","0.00000000"],["79867.38000000","0.00000000"],["79863.46000000","0.00000000"],["79860.14000000","0.00000000"],["79851.43000000","0.14935000"],["79850.54000000","0.00000000"],["79838.07000000","0.00000000"],["79835.58000000","0.00399000"],["79832.12000000","0.00000000"],["79827.54000000","0.00202000"],["79824.00000000","0.00007000"],["79822.08000000","0.00000000"],["79821.18000000","0.00000000"],["79816.46000000","0.00008000"],["79808.06000000","0.00000000"],["79808.00000000","0.00014000"],["79806.09000000","0.00000000"],["79792.00000000","0.00007000"],["79790.10000000","0.00000000"],["79776.00000000","0.00014000"],["79774.11000000","0.00000000"],["79760.00000000","0.00824000"],["79758.12000000","0.00000000"],["79748.84000000","0.00000000"],["79745.86000000","0.00000000"],["79744.00000000","0.00027000"],["79742.13000000","0.00000000"],["79736.48000000","0.00008000"],["79728.10000000","0.00000000"],["79728.00000000","0.00000000"],["79726.14000000","0.00000000"],["79656.50000000","0.00056000"],["79653.44000000","0.00000000"],["79648.13000000","0.00000000"],["79645.44000000","0.00000000"],["79638.14000000","0.00000000"],["79610.80000000","0.00250000"],["79576.53000000","0.00008000"],["79568.16000000","0.00000000"],["79496.55000000","0.00008000"],["79488.19000000","0.00000000"],["79416.58000000","0.00031000"],["79408.22000000","0.00000000"],["79336.60000000","0.00008000"],["79328.26000000","0.00000000"],["79189.53000000","0.00400000"],["79188.21000000","0.00000000"],["78774.84000000","0.00000000"],["76042.50000000","0.00000000"],["75975.75000000","0.00010000"],["71982.00000000","0.00016000"],["71980.86000000","0.00000000"],["71977.02000000","0.00008000"]],"a":[["79974.47000000","0.00000000"],["79974.48000000","0.00000000"],["79974.49000000","0.00000000"],["79975.73000000","0.00000000"],["79975.74000000","0.00000000"],["79975.75000000","0.00000000"],["79976.00000000","0.00000000"],["79976.35000000","0.00000000"],["79976.68000000","0.00000000"],["79976.71000000","0.00000000"],["79976.72000000","0.00000000"],["79976.84000000","0.00000000"],["79976.93000000","0.00000000"],["79976.94000000","0.00000000"],["79977.01000000","0.00000000"],["79977.02000000","0.00000000"],["79977.09000000","0.00000000"],["79977.10000000","0.00000000"],["79977.17000000","0.00000000"],["79977.18000000","0.00000000"],["79977.42000000","0.00000000"],["79977.63000000","0.00000000"],["79977.99000000","0.00000000"],["79978.00000000","0.00000000"],["79978.28000000","0.00000000"],["79978.29000000","0.00000000"],["79978.30000000","0.00000000"],["79978.38000000","0.00000000"],["79978.43000000","0.00000000"],["79978.44000000","0.00000000"],["79978.74000000","0.00000000"],["79978.75000000","0.00000000"],["79978.92000000","0.00000000"],["79979.13000000","0.00000000"],["79979.53000000","0.00000000"],["79979.54000000","0.00000000"],["79979.81000000","0.00000000"],["79979.88000000","0.00000000"],["79979.99000000","0.00000000"],["79980.00000000","0.02578000"],["79980.01000000","0.00070000"],["79980.09000000","0.00000000"],["79980.10000000","0.00000000"],["79980.11000000","0.00014000"],["79980.12000000","0.00014000"],["79980.16000000","0.00014000"],["79980.17000000","0.00021000"],["79980.24000000","0.00877000"],["79980.46000000","0.00000000"],["79980.51000000","0.00000000"],["79981.00000000","0.00000000"],["79981.06000000","0.00000000"],["79981.07000000","0.00007000"],["79981.29000000","0.00014000"],["79981.51000000","0.00014000"],["79981.52000000","0.01451000"],["79981.77000000","0.00000000"],["79981.95000000","0.00007000"],["79981.98000000","0.00000000"],["79981.99000000","0.00014000"],["79982.00000000","0.02421000"],["79982.29000000","0.00955000"],["79982.32000000","0.00007000"],["79982.46000000","0.00000000"],["79982.47000000","0.00009000"],["79982.63000000","0.00014000"],["79982.64000000","0.05288000"],["79982.67000000","0.00000000"],["79982.79000000","0.00014000"],["79982.80000000","0.01741000"],["79983.01000000","0.00000000"],["79983.02000000","0.00007000"],["79983.05000000","0.00000000"],["79983.07000000","0.00000000"],["79983.08000000","0.00000000"],["79983.24000000","0.00007000"],["79983.57000000","0.00000000"],["79983.58000000","0.00000000"],["79983.99000000","0.00007000"],["79984.00000000","0.02421000"],["79984.08000000","0.01741000"],["79984.27000000","0.00007000"],["79984.61000000","0.00007000"],["79984.68000000","0.00000000"],["79984.73000000","0.00013000"],["79984.75000000","0.00000000"],["79985.15000000","0.00000000"],["79985.16000000","0.00014000"],["79985.51000000","0.00000000"],["79985.71000000","0.00000000"],["79985.77000000","0.00000000"],["79985.83000000","0.00000000"],["79985.90000000","0.00000000"],["79986.00000000","0.02414000"],["79986.08000000","0.00000000"],["79986.13000000","0.00000000"],["79986.29000000","0.03029000"],["79986.74000000","0.00008000"],["79986.85000000","0.00000000"],["79986.90000000","0.00000000"],["79986.95000000","0.31271000"],["79987.13000000","0.00000000"],["79987.14000000","0.00000000"],["79987.23000000","0.00000000"],["79987.66000000","0.00000000"],["79987.73000000","0.00000000"],["79987.82000000","0.00000000"],["79987.97000000","0.00000000"],["79988.10000000","0.00000000"],["79988.11000000","0.00000000"],["79988.12000000","0.00000000"],["79988.14000000","0.00000000"],["79988.20000000","0.00000000"],["79988.39000000","0.00000000"],["79988.71000000","0.00000000"],["79988.84000000","0.00000000"],["79989.03000000","0.00007000"],["79989.47000000","0.00000000"],["79989.62000000","0.00026000"],["79989.75000000","0.00000000"],["79989.99000000","0.08073000"],["79990.26000000","0.00000000"],["79990.32000000","0.00000000"],["79990.33000000","0.00000000"],["79990.59000000","0.00000000"],["79990.75000000","0.00000000"],["79990.84000000","0.00000000"],["79990.93000000","0.00000000"],["79991.07000000","0.00000000"],["79991.13000000","0.00000000"],["79991.14000000","0.00000000"],["79991.15000000","0.08634000"],["79991.16000000","0.00000000"],["79991.20000000","0.00000000"],["79991.21000000","0.00000000"],["79991.24000000","0.00000000"],["79991.39000000","0.00000000"],["79991.63000000","0.00000000"],["79991.64000000","0.00000000"],["79991.73000000","0.00000000"],["79991.82000000","0.00000000"],["79991.92000000","0.00007000"],["79991.95000000","0.00000000"],["79992.24000000","0.00000000"],["79992.30000000","0.08634000"],["79992.66000000","0.20894000"],["79992.67000000","0.08634000"],["79992.68000000","0.00008000"],["79992.69000000","0.00000000"],["79992.90000000","0.00007000"],["79992.93000000","0.00007000"],["79993.20000000","0.00000000"],["79993.63000000","0.00000000"],["79993.87000000","0.00000000"],["79993.89000000","0.08519000"],["79993.92000000","0.00000000"],["79993.93000000","0.15000000"],["79993.99000000","0.00000000"],["79994.17000000","0.00000000"],["79994.55000000","0.00114000"],["79994.63000000","0.00000000"],["79994.92000000","0.00000000"],["79994.98000000","0.01749000"],["79994.99000000","0.00000000"],["79995.00000000","0.00000000"],["79995.37000000","0.00000000"],["79995.69000000","0.08477000"],["79995.77000000","0.00000000"],["79995.82000000","0.00007000"],["79996.09000000","0.00000000"],["79996.16000000","0.42379000"],["79996.17000000","0.08485000"],["79996.18000000","0.00000000"],["79996.24000000","0.00000000"],["79996.38000000","0.02250000"],["79996.52000000","0.00000000"],["79996.57000000","0.00000000"],["79996.59000000","0.00574000"],["79996.67000000","0.00008000"],["79996.73000000","0.00000000"],["79996.77000000","0.00014000"],["79997.20000000","0.00000000"],["79997.48000000","0.02000000"],["79997.80000000","0.00048000"],["79997.95000000","0.08634000"],["79997.97000000","0.00000000"],["79997.99000000","0.00000000"],["79998.03000000","0.00000000"],["79998.46000000","0.00000000"],["79998.48000000","0.00000000"],["79998.57000000","0.00000000"],["79998.81000000","0.00000000"],["79998.82000000","0.00000000"],["79998.88000000","0.00000000"],["79999.08000000","0.08634000"],["79999.12000000","0.00800000"],["79999.13000000","0.00000000"],["79999.18000000","1.04939000"],["79999.19000000","0.00000000"],["79999.24000000","0.00000000"],["79999.54000000","0.00153000"],["79999.74000000","0.00000000"],["79999.82000000","0.00000000"],["79999.97000000","0.00000000"],["79999.98000000","0.00000000"],["80000.00000000","0.02741000"],["80000.17000000","0.00000000"],["80000.24000000","0.00594000"],["80000.55000000","0.00000000"],["80000.56000000","0.00000000"],["80000.67000000","0.00008000"],["80000.97000000","0.00000000"],["80001.24000000","0.00000000"],["80002.97000000","0.00000000"],["80003.19000000","1.04939000"],["80003.20000000","0.00000000"],["80003.25000000","0.00000000"],["80003.33000000","0.06293000"],["80003.56000000","0.00000000"],["80003.82000000","0.00000000"],["80003.88000000","0.00007000"],["80004.20000000","0.00000000"],["80004.23000000","0.00000000"],["80004.24000000","0.00581000"],["80004.50000000","0.00000000"],["80004.67000000","0.00008000"],["80004.92000000","0.00400000"],["80004.93000000","0.00000000"],["80005.16000000","0.13341000"],["80005.18000000","0.89962000"],["80005.33000000","0.07243000"],["80005.74000000","0.00399000"],["80005.94000000","0.00000000"],["80006.84000000","0.00000000"],["80007.27000000","1.87060000"],["80007.28000000","1.04939000"],["80007.52000000","0.00000000"],["80007.82000000","0.00000000"],["80007.97000000","0.00000000"],["80007.98000000","0.00000000"],["80008.15000000","0.00250000"],["80008.24000000","0.00583000"],["80008.67000000","0.00008000"],["80009.80000000","0.00625000"],["80010.00000000","0.12174000"],["80011.00000000","0.33755000"],["80011.82000000","0.00000000"],["80011.94000000","0.00000000"],["80012.67000000","0.00008000"],["80013.96000000","0.00000000"],["80014.43000000","0.36586000"],["80014.44000000","0.00000000"],["80015.00000000","0.00000000"],["80015.10000000","0.00000000"],["80016.00000000","0.02414000"],["80016.11000000","0.42895000"],["80016.12000000","0.00014000"],["80016.67000000","0.50243000"],["80016.68000000","0.00000000"],["80016.87000000","0.00000000"],["80017.02000000","0.00000000"],["80017.96000000","0.00000000"],["80018.42000000","0.00000000"],["80018.97000000","0.00000000"],["80019.00000000","0.00000000"],["80019.99000000","0.00007000"],["80020.00000000","0.12773000"],["80021.18000000","0.00059000"],["80023.77000000","0.00007000"],["80023.86000000","0.00007000"],["80023.98000000","0.01749000"],["80024.08000000","0.33749000"],["80024.39000000","0.00000000"],["80025.60000000","0.00000000"],["80025.69000000","0.00000000"],["80025.88000000","0.00000000"],["80027.22000000","0.00000000"],["80027.56000000","0.00000000"],["80027.73000000","0.00007000"],["80031.59000000","0.01749000"],["80031.60000000","1.12639000"],["80031.90000000","0.00000000"],["80035.57000000","0.00000000"],["80035.73000000","0.00428000"],["80035.80000000","0.00400000"],["80036.01000000","0.13347000"],["80037.13000000","0.00166000"],["80037.23000000","0.00000000"],["80037.30000000","0.00000000"],["80037.31000000","0.00000000"],["80038.90000000","0.00400000"],["80039.25000000","0.00000000"],["80040.89000000","0.00628000"],["80041.25000000","0.00000000"],["80041.99000000","0.00190000"],["80042.34000000","0.00312000"],["80042.35000000","0.00000000"],["80042.51000000","0.00000000"],["80043.26000000","0.00000000"],["80044.02000000","0.20250000"],["80045.10000000","0.00400000"],["80045.75000000","0.00399000"],["80048.40000000","1.23711000"],["80049.99000000","0.00000000"],["80055.30000000","0.00311000"],["80059.48000000","0.00112000"],["80060.32000000","0.01734000"],["80061.20000000","0.00000000"],["80063.20000000","0.00000000"],["80065.90000000","0.00000000"],["80065.91000000","0.00000000"],["80073.25000000","0.00000000"],["80075.09000000","0.00000000"],["80077.75000000","0.00399000"],["80093.91000000","0.00000000"],["80093.94000000","0.00000000"],["80096.23000000","1.87060000"],["80100.54000000","0.01958000"],["80108.94000000","0.00000000"],["80109.90000000","0.00000000"],["80110.87000000","0.00000000"],["80115.99000000","0.00000000"],["80117.98000000","0.00000000"],["80120.17000000","0.36586000"],["80121.25000000","0.00000000"],["80121.99000000","0.00076000"],["80122.76000000","0.00125000"],["80125.75000000","0.00399000"],["80125.89000000","0.00000000"],["80126.65000000","0.24606000"],["80129.99000000","0.00000000"],["80131.95000000","0.00000000"],["80133.52000000","0.00000000"],["80135.28000000","0.00125000"],["80139.96000000","0.00008000"],["80140.15000000","0.00202000"],["80141.88000000","0.00000000"],["80157.87000000","0.00000000"],["80173.86000000","0.00000000"],["80189.85000000","0.00000000"],["80193.25000000","0.00000000"],["80197.76000000","0.00399000"],["80205.84000000","0.00000000"],["80206.41000000","0.00007000"],["80210.40000000","0.00000000"],["80211.93000000","0.00000000"],["80219.94000000","0.00008000"],["80371.87000000","0.00000000"],["80379.90000000","0.00008000"],["80531.81000000","0.00000000"],["80538.59000000","0.00250000"],["80539.86000000","0.00008000"],["80611.79000000","0.00000000"],["80619.84000000","0.00008000"],["81174.09000000","0.00000000"]]}}}
{"rx_ns": 10695809269000, "frame": {"stream":"btcusdt@depth20@100ms","data":{"lastUpdateId":99116118739,"bids":[["79981.99000000","6.10998000"],["79981.98000000","1.59164000"],["79981.97000000","0.00013000"],["79981.94000000","1.87081000"],["79981.77000000","0.00008000"],["79981.70000000","0.08118000"],["79981.54000000","0.00007000"],["79981.52000000","0.07500000"],["79981.51000000","0.85538000"],["79981.29000000","0.00014000"],["79981.06000000","0.10473000"],["79980.88000000","0.00007000"],["79980.24000000","0.07507000"],["79980.23000000","1.22221000"],["79980.22000000","0.01004000"],["79980.14000000","0.00007000"],["79980.10000000","0.00007000"],["79980.00000000","0.07907000"],["79979.99000000","1.02168000"],["79979.04000000","0.04722000"]],"asks":[["79982.00000000","0.02522000"],["79982.01000000","0.00063000"],["79982.29000000","0.00955000"],["79982.32000000","0.00007000"],["79982.64000000","0.00014000"],["79982.80000000","0.00014000"],["79983.02000000","0.00007000"],["79983.24000000","0.00007000"],["79983.99000000","0.00014000"],["79984.00000000","0.02435000"],["79984.08000000","0.00014000"],["79984.27000000","0.00007000"],["79984.33000000","0.00450000"],["79984.61000000","0.00007000"],["79984.63000000","0.00014000"],["79984.64000000","0.05288000"],["79985.16000000","0.00014000"],["79985.99000000","0.00014000"],["79986.00000000","0.02428000"],["79986.20000000","0.00007000"]]}}}
{"rx_ns": 10695809412200, "frame": {"stream":"btcusdt@depth@100ms","data":{"e":"depthUpdate","E":1787647690814,"s":"BTCUSDT","U":99116117733,"u":99116118739,"b":[["79981.99000000","6.10998000"],["79981.98000000","1.59164000"],["79981.97000000","0.00013000"],["79981.94000000","1.87081000"],["79981.77000000","0.00008000"],["79981.70000000","0.08118000"],["79981.54000000","0.00007000"],["79981.52000000","0.07500000"],["79981.51000000","0.85538000"],["79981.50000000","0.00000000"],["79981.49000000","0.00000000"],["79981.29000000","0.00014000"],["79981.28000000","0.00000000"],["79981.06000000","0.10473000"],["79980.88000000","0.00007000"],["79980.38000000","0.00000000"],["79980.34000000","0.00000000"],["79980.24000000","0.07507000"],["79980.23000000","1.22221000"],["79980.22000000","0.01004000"],["79980.21000000","0.00000000"],["79980.17000000","0.00000000"],["79980.16000000","0.00000000"],["79980.15000000","0.00000000"],["79980.14000000","0.00007000"],["79980.11000000","0.00000000"],["79980.10000000","0.00007000"],["79980.00000000","0.07907000"],["79979.99000000","1.02168000"],["79979.98000000","0.00000000"],["79979.97000000","0.00000000"],["79979.04000000","0.04722000"],["79978.95000000","0.01674000"],["79978.75000000","0.00000000"],["79978.74000000","1.04953000"],["79978.73000000","0.24627000"],["79978.56000000","0.00000000"],["79978.29000000","0.23759000"],["79977.99000000","0.21351000"],["79977.97000000","0.03238000"],["79977.67000000","0.02009000"],["79977.17000000","0.19410000"],["79977.16000000","0.34006000"],["79977.04000000","0.00000000"],["79976.94000000","0.00000000"],["79976.67000000","0.04006000"],["79976.41000000","0.00028000"],["79976.39000000","0.02009000"],["79976.29000000","0.00598000"],["79976.11000000","0.12503000"],["79976.00000000","0.15807000"],["79975.74000000","0.00000000"],["79975.73000000","0.31494000"],["79975.72000000","0.00000000"],["79974.47000000","1.41532000"],["79974.46000000","0.01284000"],["79974.45000000","0.00000000"],["79974.25000000","0.11185000"],["79973.51000000","0.00008000"],["79973.47000000","0.03224000"],["79973.34000000","0.00010000"],["79973.10000000","0.00007000"],["79973.07000000","0.00000000"],["79972.74000000","0.00000000"],["79972.01000000","0.00007000"],["79971.85000000","0.87824000"],["79971.84000000","0.01643000"],["79971.83000000","0.00000000"],["79971.81000000","0.00833000"],["79971.28000000","0.00000000"],["79970.81000000","0.03000000"],["79970.73000000","0.00000000"],["79970.71000000","0.00000000"],["79970.51000000","0.00203000"],["79970.49000000","0.00007000"],["79970.01000000","0.00000000"],["79968.73000000","0.00000000"],["79968.49000000","0.00000000"],["79968.11000000","0.10200000"],["79968.00000000","0.43563000"],["79965.51000000","0.00008000"],["79965.30000000","0.00190000"],["79964.34000000","1.87072000"],["79964.14000000","0.00059000"],["79963.50000000","0.00000000"],["79962.81000000","0.00000000"],["79961.51000000","0.00008000"],["79960.41000000","0.00000000"],["79960.00000000","0.12038000"],["79957.52000000","0.00008000"],["79956.42000000","0.00000000"],["79956.06000000","0.00000000"],["79953.52000000","0.00008000"],["79952.42000000","0.00000000"],["79952.40000000","0.00000000"],["79952.22000000","0.00000000"],["79952.14000000","0.00000000"],["79952.12000000","0.00000000"],["79950.17000000","0.00000000"],["79949.52000000","0.00008000"],["79948.89000000","0.00000000"],["79948.52000000","0.00000000"],["79948.42000000","0.00000000"],["79947.46000000","0.83450000"],["79945.87000000","0.01160000"],["79945.52000000","0.00008000"],["79944.42000000","0.00000000"],["79941.52000000","0.00008000"],["79940.99000000","0.02477000"],["79940.42000000","0.00000000"],["79940.00000000","0.12968000"],["79939.61000000","0.00628000"],["79936.42000000","0.00000000"],["79934.00000000","0.02400000"],["79933.14000000","0.02435000"],["79930.72000000","0.00000000"],["79930.41000000","0.00000000"],["79926.87000000","0.00335000"],["79926.42000000","0.00436000"],["79924.54000000","0.00000000"],["79917.40000000","0.25000000"],["79912.12000000","0.00531000"],["79910.58000000","0.00000000"],["79902.18000000","0.12233000"],["79900.41000000","0.02084000"],["79897.14000000","0.00000000"],["79896.35000000","0.00000000"],["79886.10000000","0.00000000"],["79871.42000000","0.00007000"],["79850.24000000","0.04028000"],["79836.92000000","0.00000000"],["79836.30000000","0.00202000"],["79827.54000000","0.00000000"],["79751.43000000","0.00000000"],["79661.44000000","0.00000000"],["79652.09000000","0.00032000"],["79424.00000000","0.00000000"],["79192.41000000","0.00000000"],["79192.22000000","0.00000000"],["79192.21000000","0.00400000"],["79192.19000000","0.00070000"],["79189.53000000","0.00000000"],["71983.80000000","0.00016000"],["71982.00000000","0.00000000"]],"a":[["79980.00000000","0.00000000"],["79980.01000000","0.00000000"],["79980.11000000","0.00000000"],["79980.12000000","0.00000000"],["79980.16000000","0.00000000"],["79980.17000000","0.00000000"],["79980.24000000","0.00000000"],["79980.25000000","0.00000000"],["79980.35000000","0.00000000"],["79981.07000000","0.00000000"],["79981.29000000","0.00000000"],["79981.30000000","0.00000000"],["79981.51000000","0.00000000"],["79981.52000000","0.00000000"],["79981.53000000","0.00000000"],["79981.55000000","0.00000000"],["79981.95000000","0.00000000"],["79981.99000000","0.00000000"],["79982.00000000","0.02522000"],["79982.01000000","0.00063000"],["79982.29000000","0.00955000"],["79982.47000000","0.00000000"],["79982.63000000","0.00000000"],["79982.64000000","0.00014000"],["79982.79000000","0.00000000"],["79982.80000000","0.00014000"],["79983.99000000","0.00014000"],["79984.00000000","0.02435000"],["79984.07000000","0.00000000"],["79984.08000000","0.00014000"],["79984.15000000","0.00000000"],["79984.16000000","0.00000000"],["79984.63000000","0.00014000"],["79984.64000000","0.05288000"],["79984.73000000","0.00000000"],["79985.52000000","0.00000000"],["79985.99000000","0.00014000"],["79986.00000000","0.02428000"],["79986.28000000","0.00014000"],["79986.29000000","0.03043000"],["79986.74000000","0.00000000"],["79986.94000000","0.00007000"],["79986.95000000","0.31285000"],["79988.00000000","0.02416000"],["79988.98000000","0.00000000"],["79989.52000000","0.00008000"],["79989.62000000","0.00000000"],["79989.84000000","0.00000000"],["79989.99000000","0.00007000"],["79990.00000000","0.02414000"],["79990.47000000","0.00000000"],["79990.65000000","0.00026000"],["79991.14000000","0.03304000"],["79991.15000000","0.08641000"],["79992.30000000","0.08641000"],["79992.45000000","0.18052000"],["79992.46000000","0.12501000"],["79992.66000000","0.00000000"],["79992.67000000","0.00000000"],["79992.68000000","0.00000000"],["79992.90000000","0.00014000"],["79993.80000000","0.08634000"],["79993.89000000","0.00250000"],["79993.90000000","0.00000000"],["79994.02000000","0.00000000"],["79994.55000000","0.00000000"],["79995.12000000","0.00007000"],["79996.00000000","0.02733000"],["79996.16000000","0.06914000"],["79996.17000000","0.00000000"],["79996.59000000","0.00000000"],["79996.60000000","0.00058000"],["79996.61000000","0.00000000"],["79996.64000000","0.00000000"],["79996.67000000","0.00000000"],["79996.70000000","0.00000000"],["79996.77000000","0.00014000"],["79996.95000000","0.00060000"],["79997.26000000","0.00592000"],["79997.52000000","0.00008000"],["79998.47000000","0.00000000"],["79999.07000000","0.00000000"],["79999.12000000","0.00400000"],["79999.18000000","0.00000000"],["79999.49000000","0.00000000"],["80000.17000000","0.08443000"],["80000.46000000","0.12499000"],["80000.64000000","0.00014000"],["80000.67000000","0.00000000"],["80001.52000000","0.00008000"],["80002.03000000","0.50021000"],["80002.30000000","0.00000000"],["80003.18000000","0.00800000"],["80004.00000000","0.02409000"],["80004.51000000","0.00014000"],["80004.67000000","0.00000000"],["80005.18000000","0.39127000"],["80005.51000000","0.00008000"],["80006.46000000","0.00000000"],["80007.27000000","0.00000000"],["80007.81000000","0.00007000"],["80008.00000000","0.02407000"],["80008.38000000","0.00014000"],["80008.67000000","0.00000000"],["80009.51000000","0.00008000"],["80009.99000000","1.87060000"],["80010.00000000","0.02800000"],["80010.94000000","0.04000000"],["80012.00000000","0.02416000"],["80012.25000000","0.00014000"],["80012.67000000","0.00000000"],["80013.51000000","0.00008000"],["80014.43000000","0.00000000"],["80016.67000000","0.50235000"],["80017.51000000","0.00008000"],["80017.67000000","0.36586000"],["80018.67000000","0.00000000"],["80018.95000000","0.02000000"],["80018.97000000","0.00000000"],["80019.99000000","0.00014000"],["80020.00000000","0.11773000"],["80020.02000000","0.22724000"],["80020.47000000","0.00000000"],["80020.77000000","0.00000000"],["80021.00000000","0.00000000"],["80021.39000000","0.00012000"],["80021.51000000","0.00008000"],["80022.00000000","0.03400000"],["80022.43000000","0.00190000"],["80023.64000000","1.20062000"],["80023.77000000","0.00000000"],["80026.03000000","0.99440000"],["80030.00000000","0.11772000"],["80042.74000000","0.00435000"],["80050.82000000","0.83342000"],["80051.98000000","0.00000000"],["80058.94000000","0.02000000"],["80059.30000000","0.00531000"],["80059.99000000","0.00008000"],["80062.94000000","0.02000000"],["80063.83000000","0.02000000"],["80063.84000000","0.02000000"],["80068.73000000","0.25000000"],["80077.94000000","0.00000000"],["80081.14000000","0.00000000"],["80082.19000000","0.00000000"],["80090.16000000","0.02804000"],["80126.66000000","0.00000000"],["80140.15000000","0.00000000"],["80148.73000000","0.00202000"],["80241.77000000","0.00000000"]]}}}
{"rx_ns": 10695809617300, "frame": {"stream":"btcusdt@depth20@100ms","data":{"lastUpdateId":99116119097,"bids":[["79982.28000000","6.88801000"],["79982.27000000","0.00013000"],["79982.26000000","0.00013000"],["79982.00000000","0.60607000"],["79981.99000000","2.52213000"],["79981.98000000","0.00014000"],["79981.94000000","0.00021000"],["79981.77000000","0.00008000"],["79981.70000000","0.08132000"],["79981.54000000","0.00007000"],["79981.52000000","0.07514000"],["79981.51000000","0.85552000"],["79981.29000000","0.00014000"],["79981.06000000","0.10487000"],["79980.88000000","0.00007000"],["79980.24000000","0.07514000"],["79980.23000000","1.22207000"],["79980.14000000","0.00007000"],["79980.10000000","0.00007000"],["79980.00000000","0.00407000"]],"asks":[["79982.29000000","0.01077000"],["79982.30000000","0.00084000"],["79982.32000000","0.00007000"],["79983.02000000","0.00007000"],["79983.24000000","0.00007000"],["79983.50000000","0.00870000"],["79983.99000000","0.00014000"],["79984.00000000","0.02428000"],["79984.27000000","0.00007000"],["79984.33000000","0.00450000"],["79984.61000000","0.00007000"],["79984.63000000","0.00014000"],["79984.64000000","0.05309000"],["79984.77000000","0.00014000"],["79984.78000000","0.01451000"],["79985.16000000","0.00014000"],["79985.99000000","0.00014000"],["79986.00000000","0.02435000"],["79986.05000000","0.00007000"],["79986.06000000","0.01741000"]]}}}
{"rx_ns": 10695809664900, "frame": {"stream":"btcusdt@depth@100ms","data":{"e":"depthUpdate","E":1787647690914,"s":"BTCUSDT","U":99116118740,"u":99116119097,"b":[["79982.28000000","6.88801000"],["79982.27000000","0.00013000"],["79982.26000000","0.00013000"],["79982.00000000","0.60607000"],["79981.99000000","2.52213000"],["79981.98000000","0.00014000"],["79981.97000000","0.00000000"],["79981.94000000","0.00021000"],["79981.70000000","0.08132000"],["79981.52000000","0.07514000"],["79981.51000000","0.85552000"],["79981.06000000","0.10487000"],["79980.24000000","0.07514000"],["79980.23000000","1.22207000"],["79980.22000000","0.00000000"],["79980.00000000","0.00407000"],["79979.99000000","0.18150000"],["79979.98000000","0.00400000"],["79979.04000000","0.04715000"],["79978.95000000","0.00000000"],["79978.74000000","1.04939000"],["79978.73000000","0.24620000"],["79978.43000000","0.45999000"],["79978.42000000","0.47873000"],["79978.29000000","0.23745000"],["79978.28000000","0.29383000"],["79977.97000000","0.03231000"],["79977.67000000","0.00000000"],["79977.16000000","0.34013000"],["79976.90000000","0.30400000"],["79976.41000000","0.00014000"],["79976.39000000","0.00000000"],["79976.12000000","0.00162000"],["79976.11000000","0.12510000"],["79976.00000000","0.06206000"],["79975.99000000","0.00000000"],["79975.78000000","0.00000000"],["79974.46000000","0.01277000"],["79974.25000000","0.00000000"],["79972.79000000","0.08576000"],["79971.99000000","0.20250000"],["79970.49000000","0.00000000"],["79970.00000000","0.09379000"],["79969.15000000","0.15381000"],["79968.52000000","0.02400000"],["79962.01000000","0.00007000"],["79955.42000000","0.00000000"],["79953.48000000","0.00000000"],["79950.00000000","0.11788000"],["79942.00000000","0.03400000"],["79941.00000000","0.00000000"],["79940.00000000","0.11968000"],["79918.77000000","0.00000000"],["79916.57000000","0.00000000"],["79915.55000000","0.00110000"],["79915.54000000","0.00399000"],["79915.00000000","0.01707000"],["79900.41000000","0.00000000"],["79896.61000000","0.04568000"],["79761.69000000","0.00000000"],["79192.21000000","0.00000000"],["71984.06000000","0.00016000"],["71983.80000000","0.00000000"]],"a":[["79982.00000000","0.00000000"],["79982.01000000","0.00000000"],["79982.29000000","0.01077000"],["79982.30000000","0.00084000"],["79982.64000000","0.00000000"],["79982.80000000","0.00000000"],["79983.50000000","0.00870000"],["79984.00000000","0.02428000"],["79984.08000000","0.00000000"],["79984.64000000","0.05309000"],["79984.77000000","0.00014000"],["79984.78000000","0.01451000"],["79986.00000000","0.02435000"],["79986.05000000","0.00007000"],["79986.06000000","0.01741000"],["79986.28000000","0.00007000"],["79986.94000000","0.00000000"],["79986.95000000","0.31292000"],["79987.34000000","0.01741000"],["79988.00000000","0.02430000"],["79990.00000000","0.02428000"],["79991.14000000","0.00014000"],["79991.15000000","0.00007000"],["79992.30000000","0.00007000"],["79992.45000000","0.18059000"],["79992.90000000","0.00007000"],["79993.24000000","0.06027000"],["79993.80000000","0.00000000"],["79994.51000000","0.00007000"],["79994.56000000","0.00000000"],["79994.61000000","0.07895000"],["79995.79000000","0.42211000"],["79996.16000000","0.10429000"],["79996.85000000","0.08574000"],["79997.26000000","0.00000000"],["79997.49000000","0.08566000"],["79997.68000000","0.08574000"],["79997.95000000","0.00000000"],["79998.03000000","0.00573000"],["80000.00000000","0.02748000"],["80001.44000000","0.00400000"],["80005.74000000","0.00000000"],["80009.54000000","0.00048000"],["80009.56000000","0.00069000"],["80010.55000000","0.02000000"],["80018.56000000","0.00000000"],["80021.30000000","0.09376000"],["80022.00000000","0.02400000"],["80023.00000000","0.01000000"],["80042.34000000","0.00000000"],["80044.40000000","0.00319000"],["80045.75000000","0.00000000"],["80048.20000000","0.00400000"],["80055.30000000","0.00000000"],["80057.99000000","0.00310000"],["80063.45000000","0.02000000"],["80077.75000000","0.00000000"],["80081.75000000","3.13843000"],["80082.64000000","0.11949000"],["80100.54000000","0.00000000"],["80104.78000000","0.00000000"],["80105.63000000","0.80000000"],["80112.00000000","0.02407000"],["80122.76000000","0.00000000"],["80125.75000000","0.00000000"],["80125.99000000","0.00125000"],["80126.65000000","0.00000000"],["80128.00000000","0.02414000"],["80135.28000000","0.00000000"],["80137.99000000","0.00125000"],["80144.00000000","0.02407000"],["80160.00000000","0.02482000"],["80176.00000000","0.02646000"],["80186.27000000","0.01958000"],["80192.00000000","0.02414000"],["80197.76000000","0.00000000"],["80208.00000000","0.00007000"],["80251.81000000","0.00031000"]]}}}
{"rx_ns": 10695857064200, "frame": {"stream":"btcusdt@depth20@100ms","data":{"lastUpdateId":99116119424,"bids":[["79983.49000000","5.93896000"],["79983.48000000","0.00013000"],["79983.47000000","0.00013000"],["79983.23000000","0.00014000"],["79983.10000000","0.00400000"],["79982.81000000","0.03224000"],["79982.30000000","0.15378000"],["79982.29000000","0.73320000"],["79982.28000000","2.75419000"],["79982.00000000","0.07514000"],["79981.99000000","0.59692000"],["79981.94000000","0.00007000"],["79981.77000000","0.00008000"],["79981.70000000","0.00014000"],["79981.54000000","0.00007000"],["79981.52000000","0.07514000"],["79981.51000000","0.21892000"],["79981.29000000","0.00014000"],["79981.06000000","0.10494000"],["79981.00000000","0.01681000"]],"asks":[["79983.50000000","0.01020000"],["79983.51000000","0.00070000"],["79983.99000000","0.00014000"],["79984.00000000","0.02428000"],["79984.27000000","0.00007000"],["79984.61000000","0.00007000"],["79984.64000000","0.00021000"],["79984.77000000","0.00014000"],["79984.78000000","0.01465000"],["79985.16000000","0.00014000"],["79985.99000000","0.00014000"],["79986.00000000","0.02435000"],["79986.05000000","0.00014000"],["79986.06000000","0.01762000"],["79986.13000000","0.00007000"],["79986.14000000","0.05288000"],["79986.20000000","0.00007000"],["79986.28000000","0.00007000"],["79986.29000000","0.03043000"],["79986.86000000","0.00007000"]]}}}
{"rx_ns": 10695857161700, "frame": {"stream":"btcusdt@depth@100ms","data":{"e":"depthUpdate","E":1787647691014,"s":"BTCUSDT","U":99116119098,"u":99116119424,"b":[["79983.49000000","5.93896000"],["79983.48000000","0.00013000"],["79983.47000000","0.00013000"],["79983.23000000","0.00014000"],["79983.10000000","0.00400000"],["79983.01000000","0.00000000"],["79982.81000000","0.03224000"],["79982.37000000","0.00000000"],["79982.31000000","0.00000000"],["79982.30000000","0.15378000"],["79982.29000000","0.73320000"],["79982.28000000","2.75419000"],["79982.27000000","0.00000000"],["79982.26000000","0.00000000"],["79982.00000000","0.07514000"],["79981.99000000","0.59692000"],["79981.98000000","0.00000000"],["79981.94000000","0.00007000"],["79981.70000000","0.00014000"],["79981.51000000","0.21892000"],["79981.06000000","0.10494000"],["79981.00000000","0.01681000"],["79980.95000000","0.02481000"],["79980.54000000","0.04715000"],["79980.24000000","0.00014000"],["79980.23000000","0.16025000"],["79980.00000000","0.00400000"],["79979.99000000","0.18157000"],["79979.72000000","0.02009000"],["79979.09000000","0.00580000"],["79979.04000000","0.00000000"],["79978.73000000","0.24627000"],["79978.44000000","0.02009000"],["79978.43000000","0.79583000"],["79978.42000000","0.47473000"],["79976.67000000","0.34006000"],["79976.29000000","0.30598000"],["79976.00000000","0.59621000"],["79975.73000000","0.21489000"],["79975.10000000","0.02400000"],["79974.56000000","0.00007000"],["79974.47000000","1.41525000"],["79974.46000000","0.01270000"],["79973.73000000","0.08576000"],["79973.47000000","0.00000000"],["79972.79000000","0.00000000"],["79972.72000000","0.02000000"],["79969.15000000","0.00000000"],["79969.03000000","0.06296000"],["79968.25000000","0.00007000"],["79967.85000000","0.00000000"],["79967.03000000","0.07246000"],["79964.52000000","0.00000000"],["79962.52000000","0.00000000"],["79961.59000000","0.00000000"],["79961.49000000","0.00000000"],["79959.88000000","0.33776000"],["79959.22000000","0.00000000"],["79957.97000000","0.17333000"],["79955.16000000","0.00000000"],["79955.02000000","0.00000000"],["79950.62000000","0.00000000"],["79945.83000000","0.63417000"],["79942.59000000","0.00000000"],["79938.34000000","0.00000000"],["79934.68000000","0.00000000"],["79933.76000000","0.00000000"],["79932.24000000","0.82457000"],["79921.08000000","0.00000000"],["79918.64000000","0.83015000"],["79904.75000000","0.00000000"],["78782.54000000","0.00030000"],["71984.06000000","0.00000000"],["71977.02000000","0.00000000"],["71977.01000000","0.00008000"],["63986.80000000","0.00031000"]],"a":[["79982.29000000","0.00000000"],["79982.30000000","0.00000000"],["79982.32000000","0.00000000"],["79983.02000000","0.00000000"],["79983.24000000","0.00000000"],["79983.50000000","0.01020000"],["79983.51000000","0.00070000"],["79984.33000000","0.00000000"],["79984.63000000","0.00000000"],["79984.64000000","0.00021000"],["79984.78000000","0.01465000"],["79986.00000000","0.02435000"],["79986.05000000","0.00014000"],["79986.06000000","0.01762000"],["79986.13000000","0.00007000"],["79986.14000000","0.05288000"],["79986.95000000","0.31292000"],["79987.34000000","0.01755000"],["79988.00000000","0.02416000"],["79990.00000000","0.02414000"],["79991.14000000","0.00000000"],["79991.22000000","0.00000000"],["79992.37000000","0.08247000"],["79992.45000000","0.00007000"],["79992.90000000","0.00007000"],["79993.24000000","0.00000000"],["79995.78000000","0.08574000"],["79996.85000000","0.00000000"],["79997.48000000","0.00000000"],["79997.49000000","0.00000000"],["79997.68000000","0.00000000"],["79998.42000000","0.08566000"],["80000.25000000","0.00007000"],["80001.44000000","0.00000000"],["80001.72000000","0.00007000"],["80001.79000000","0.00625000"],["80001.99000000","0.00400000"],["80003.17000000","0.00400000"],["80003.18000000","0.00400000"],["80003.33000000","0.00000000"],["80003.58000000","0.00000000"],["80005.33000000","0.00000000"],["80005.68000000","0.02000000"],["80006.86000000","0.02000000"],["80009.32000000","0.02000000"],["80009.98000000","0.94584000"],["80010.01000000","0.00000000"],["80011.00000000","0.00000000"],["80015.36000000","0.33753000"],["80015.61000000","0.00000000"],["80017.66000000","0.01749000"],["80018.87000000","0.00000000"],["80018.95000000","0.00000000"],["80021.30000000","0.00000000"],["80023.00000000","0.00000000"],["80024.00000000","0.03400000"],["80024.59000000","0.63355000"],["80030.00000000","0.12022000"],["80059.73000000","0.02000000"],["80066.80000000","0.02000000"],["80082.64000000","0.00000000"],["80105.35000000","0.00000000"],["80105.46000000","0.00000000"],["80105.63000000","0.00000000"],["80186.27000000","0.00000000"],["80197.09000000","0.01958000"],["80525.42000000","0.00018000"]]}}}
{"rx_ns": 10695953495400, "frame": {"stream":"btcusdt@depth20@100ms","data":{"lastUpdateId":99116119779,"bids":[["79983.99000000","5.96540000"],["79983.98000000","0.87083000"],["79983.97000000","0.00013000"],["79983.50000000","4.07501000"],["79983.49000000","0.86001000"],["79983.10000000","0.00400000"],["79982.81000000","0.03245000"],["79982.30000000","0.00021000"],["79982.29000000","0.07514000"],["79982.28000000","0.25054000"],["79982.00000000","0.07514000"],["79981.99000000","0.59678000"],["79981.94000000","0.00007000"],["79981.77000000","0.00008000"],["79981.54000000","0.00007000"],["79981.51000000","0.21885000"],["79981.29000000","0.00014000"],["79981.06000000","0.00014000"],["79981.04000000","0.04715000"],["79981.00000000","0.00007000"]],"asks":[["79984.00000000","0.02529000"],["79984.01000000","0.00063000"],["79984.27000000","0.00007000"],["79984.61000000","0.00007000"],["79984.64000000","0.00007000"],["79984.78000000","0.00014000"],["79985.16000000","0.00014000"],["79985.99000000","0.00014000"],["79986.00000000","0.02435000"],["79986.06000000","0.00021000"],["79986.14000000","0.00014000"],["79986.20000000","0.00007000"],["79986.28000000","0.00014000"],["79986.29000000","0.03050000"],["79986.63000000","0.00014000"],["79986.64000000","0.05288000"],["79986.86000000","0.00007000"],["79986.94000000","0.00014000"],["79986.95000000","0.31292000"],["79987.24000000","0.00007000"]]}}}
{"rx_ns": 10695953584700, "frame": {"stream":"btcusdt@depth@100ms","data":{"e":"depthUpdate","E":1787647691114,"s":"BTCUSDT","U":99116119425,"u":99116119779,"b":[["79983.99000000","5.96540000"],["79983.98000000","0.87083000"],["79983.97000000","0.00013000"],["79983.50000000","4.07501000"],["79983.49000000","0.86001000"],["79983.48000000","0.00000000"],["79983.47000000","0.00000000"],["79983.23000000","0.00000000"],["79982.81000000","0.03245000"],["79982.30000000","0.00021000"],["79982.29000000","0.07514000"],["79982.28000000","0.25054000"],["79981.99000000","0.59678000"],["79981.70000000","0.00000000"],["79981.52000000","0.00000000"],["79981.51000000","0.21885000"],["79981.06000000","0.00014000"],["79981.04000000","0.04715000"],["79981.00000000","0.00007000"],["79980.95000000","0.02474000"],["79980.88000000","0.00000000"],["79980.69000000","0.00436000"],["79980.54000000","0.00000000"],["79980.24000000","0.00000000"],["79979.99000000","0.18010000"],["79979.72000000","0.00007000"],["79978.75000000","1.24734000"],["79978.73000000","0.24613000"],["79978.44000000","0.00000000"],["79978.43000000","0.00000000"],["79978.00000000","0.00162000"],["79976.67000000","0.30007000"],["79976.41000000","0.00007000"],["79976.12000000","0.00000000"],["79976.11000000","0.12503000"],["79976.00000000","1.05992000"],["79975.99000000","0.00008000"],["79975.11000000","0.02000000"],["79974.49000000","0.15380000"],["79974.48000000","1.87060000"],["79974.01000000","0.00007000"],["79973.51000000","0.00000000"],["79972.70000000","0.00000000"],["79963.36000000","0.51836000"],["79959.44000000","0.00000000"],["79954.11000000","0.00000000"],["79943.00000000","0.71000000"],["79942.00000000","0.02400000"],["79939.37000000","1.06739000"],["79918.65000000","0.66155000"],["79918.05000000","0.00000000"],["79913.12000000","0.00000000"],["79912.13000000","0.00312000"],["79902.54000000","0.00000000"],["79879.35000000","0.00000000"],["79877.78000000","0.00000000"],["71985.60000000","0.00032000"]],"a":[["79983.50000000","0.00000000"],["79983.51000000","0.00000000"],["79983.52000000","0.00000000"],["79983.99000000","0.00000000"],["79984.00000000","0.02529000"],["79984.01000000","0.00063000"],["79984.64000000","0.00007000"],["79984.77000000","0.00000000"],["79984.78000000","0.00014000"],["79986.05000000","0.00000000"],["79986.06000000","0.00021000"],["79986.13000000","0.00000000"],["79986.14000000","0.00014000"],["79986.28000000","0.00014000"],["79986.29000000","0.03050000"],["79986.63000000","0.00014000"],["79986.64000000","0.05288000"],["79986.94000000","0.00014000"],["79987.34000000","0.00014000"],["79987.99000000","0.00007000"],["79988.00000000","0.02430000"],["79988.72000000","0.00000000"],["79989.52000000","0.00000000"],["79989.62000000","0.00438000"],["79991.99000000","0.00008000"],["79992.90000000","0.00014000"],["79993.92000000","0.08574000"],["79996.23000000","0.00000000"],["79996.46000000","0.00000000"],["79997.09000000","0.00449000"],["79997.91000000","0.03090000"],["79998.03000000","0.00000000"],["79998.32000000","0.00007000"],["80002.03000000","0.00000000"],["80004.46000000","0.00446000"],["80006.82000000","0.02000000"],["80007.79000000","0.06293000"],["80009.79000000","0.07242000"],["80012.46000000","0.03668000"],["80020.46000000","0.00438000"],["80021.33000000","0.00000000"],["80021.92000000","0.09258000"],["80023.86000000","0.00014000"],["80028.46000000","0.00452000"],["80064.44000000","0.00000000"],["80068.73000000","0.00000000"],["80072.74000000","0.25000000"],["80080.37000000","0.00399000"],["80083.17000000","0.12306000"]]}}}
{"rx_ns": 10696057643200, "frame": {"stream":"btcusdt@depth20@100ms","data":{"lastUpdateId":99116119895,"bids":[["79983.99000000","5.97558000"],["79983.98000000","0.87097000"],["79983.97000000","0.00013000"],["79983.51000000","0.00400000"],["79983.50000000","3.78317000"],["79983.49000000","0.23989000"],["79983.10000000","0.00400000"],["79982.81000000","0.03252000"],["79982.71000000","0.01674000"],["79982.30000000","0.00007000"],["79982.29000000","0.07514000"],["79982.28000000","0.25054000"],["79982.00000000","0.07514000"],["79981.99000000","0.59664000"],["79981.94000000","0.00007000"],["79981.77000000","0.00008000"],["79981.54000000","0.00007000"],["79981.51000000","0.21892000"],["79981.43000000","0.02009000"],["79981.29000000","0.00014000"]],"asks":[["79984.00000000","0.02565000"],["79984.01000000","0.00077000"],["79984.27000000","0.00007000"],["79984.61000000","0.00007000"],["79985.16000000","0.00014000"],["79985.50000000","0.00870000"],["79985.99000000","0.00014000"],["79986.00000000","0.02428000"],["79986.20000000","0.00007000"],["79986.28000000","0.00014000"],["79986.29000000","0.03050000"],["79986.63000000","0.00014000"],["79986.64000000","0.05309000"],["79986.77000000","0.00014000"],["79986.78000000","0.01451000"],["79986.86000000","0.00007000"],["79986.94000000","0.00014000"],["79986.95000000","0.31285000"],["79987.24000000","0.00007000"],["79988.00000000","0.02428000"]]}}}
{"rx_ns": 10696057732600, "frame": {"stream":"btcusdt@depth@100ms","data":{"e":"depthUpdate","E":1787647691214,"s":"BTCUSDT","U":99116119780,"u":99116119895,"b":[["79983.99000000","5.97558000"],["79983.98000000","0.87097000"],["79983.51000000","0.00400000"],["79983.50000000","3.78317000"],["79983.49000000","0.23989000"],["79982.81000000","0.03252000"],["79982.71000000","0.01674000"],["79982.30000000","0.00007000"],["79981.99000000","0.59664000"],["79981.51000000","0.21892000"],["79981.43000000","0.02009000"],["79980.23000000","0.16032000"],["79980.15000000","0.02009000"],["79979.98000000","0.00000000"],["79975.00000000","0.02000000"],["79974.46000000","0.01260000"],["79962.99000000","0.62547000"],["79959.16000000","0.00000000"],["79902.26000000","0.82962000"],["79879.35000000","0.72849000"],["79845.56000000","0.00000000"],["79837.55000000","0.00000000"],["79755.42000000","0.00000000"],["63987.19000000","0.00000000"],["63986.80000000","0.00000000"]],"a":[["79984.00000000","0.02565000"],["79984.01000000","0.00077000"],["79984.64000000","0.00000000"],["79984.78000000","0.00000000"],["79985.50000000","0.00870000"],["79986.00000000","0.02428000"],["79986.06000000","0.00000000"],["79986.14000000","0.00000000"],["79986.29000000","0.03050000"],["79986.64000000","0.05309000"],["79986.77000000","0.00014000"],["79986.78000000","0.01451000"],["79986.95000000","0.31285000"],["79987.34000000","0.00000000"],["79987.99000000","0.00000000"],["79988.00000000","0.02428000"],["79988.06000000","0.01748000"],["79989.34000000","0.01741000"],["79990.00000000","0.02435000"],["79992.00000000","0.02435000"],["79992.37000000","0.08261000"],["79996.00000000","0.02724000"],["80000.00000000","0.02755000"],["80004.00000000","0.02400000"],["80006.97000000","0.02000000"],["80008.00000000","0.02414000"],["80012.00000000","0.02407000"],["80016.00000000","0.02421000"],["80019.68000000","0.00000000"],["80023.79000000","0.62499000"],["80056.77000000","1.23698000"],["80059.79000000","0.02000000"],["80083.17000000","0.00000000"],["80091.29000000","0.00007000"],["80093.98000000","0.00000000"],["80098.14000000","0.00000000"],["80694.23000000","0.00000000"],["81183.76000000","0.00030000"]]}}}
{"rx_ns": 10696152853500, "frame": {"stream":"btcusdt@depth20@100ms","data":{"lastUpdateId":99116119947,"bids":[["79983.99000000","5.97717000"],["79983.98000000","0.87097000"],["79983.97000000","0.00013000"],["79983.51000000","0.00400000"],["79983.50000000","3.78317000"],["79983.49000000","0.23989000"],["79983.10000000","0.00400000"],["79982.81000000","0.03252000"],["79982.71000000","0.01674000"],["79982.30000000","0.00007000"],["79982.29000000","0.07514000"],["79982.28000000","0.25054000"],["79982.00000000","0.07514000"],["79981.99000000","0.39414000"],["79981.94000000","0.00007000"],["79981.77000000","0.00008000"],["79981.54000000","0.00007000"],["79981.51000000","0.21892000"],["79981.43000000","0.02009000"],["79981.29000000","0.00014000"]],"asks":[["79984.00000000","0.07565000"],["79984.01000000","0.00077000"],["79984.27000000","0.00007000"],["79984.34000000","0.00007000"],["79984.61000000","0.00007000"],["79985.16000000","0.00014000"],["79985.50000000","0.00884000"],["79985.99000000","0.00014000"],["79986.00000000","0.02428000"],["79986.20000000","0.00007000"],["79986.28000000","0.00014000"],["79986.29000000","0.03050000"],["79986.63000000","0.00014000"],["79986.64000000","0.05309000"],["79986.77000000","0.00014000"],["79986.78000000","0.01465000"],["79986.86000000","0.00007000"],["79986.94000000","0.00014000"],["79986.95000000","0.31285000"],["79987.24000000","0.00007000"]]}}}
{"rx_ns": 10696153005200, "frame": {"stream":"btcusdt@depth@100ms","data":{"e":"depthUpdate","E":1787647691314,"s":"BTCUSDT","U":99116119896,"u":99116119947,"b":[["79983.99000000","5.97717000"],["79982.81000000","0.03252000"],["79981.99000000","0.39414000"],["79975.83000000","0.02200000"],["79975.03000000","0.02400000"],["79963.27000000","0.00000000"],["79961.53000000","0.00000000"],["79959.14000000","0.00000000"],["79882.73000000","0.00025000"],["79873.71000000","0.00000000"],["79661.45000000","0.20250000"],["71985.60000000","0.00064000"],["63987.00000000","0.00000000"]],"a":[["79984.00000000","0.07565000"],["79984.34000000","0.00007000"],["79985.50000000","0.00884000"],["79986.64000000","0.05309000"],["79986.78000000","0.01465000"],["79988.00000000","0.02428000"],["79988.06000000","0.01762000"],["79990.00000000","0.02421000"],["79992.00000000","0.02421000"],["79992.37000000","0.08247000"],["79994.90000000","0.06323000"],["80014.83000000","0.00000000"],["80019.74000000","0.00000000"],["80048.37000000","0.00399000"],["80050.40000000","0.02000000"],["80055.00000000","0.02000000"],["80073.64000000","0.00000000"],["80082.68000000","0.00025000"]]}}}
{"rx_ns": 10696252547000, "frame": {"stream":"btcusdt@depth20@100ms","data":{"lastUpdateId":99116119962,"bids":[["79983.99000000","5.97694000"],["79983.98000000","1.69095000"],["79983.97000000","0.00013000"],["79983.51000000","0.00400000"],["79983.50000000","3.78317000"],["79983.49000000","0.23989000"],["79983.10000000","0.00400000"],["79982.81000000","0.03252000"],["79982.71000000","0.01674000"],["79982.30000000","0.00007000"],["79982.29000000","0.07514000"],["79982.28000000","0.25054000"],["79982.00000000","0.07514000"],["79981.99000000","0.39414000"],["79981.94000000","0.00007000"],["79981.77000000","0.00008000"],["79981.54000000","0.00007000"],["79981.51000000","0.21892000"],["79981.43000000","0.02009000"],["79981.29000000","0.00014000"]],"asks":[["79984.00000000","0.07565000"],["79984.01000000","0.00077000"],["79984.27000000","0.00007000"],["79984.34000000","0.00007000"],["79984.61000000","0.00007000"],["79985.16000000","0.00014000"],["79985.50000000","0.00884000"],["79985.99000000","0.00014000"],["79986.00000000","0.02428000"],["79986.20000000","0.00007000"],["79986.28000000","0.00014000"],["79986.29000000","0.03050000"],["79986.63000000","0.00014000"],["79986.64000000","0.05309000"],["79986.77000000","0.00014000"],["79986.78000000","0.01465000"],["79986.86000000","0.00007000"],["79986.94000000","0.00014000"],["79986.95000000","0.31285000"],["79987.24000000","0.00007000"]]}}}
{"rx_ns": 10696252632400, "frame": {"stream":"btcusdt@depth@100ms","data":{"e":"depthUpdate","E":1787647691414,"s":"BTCUSDT","U":99116119948,"u":99116119962,"b":[["79983.99000000","5.97694000"],["79983.98000000","1.69095000"],["79904.89000000","0.62495000"],["79899.74000000","0.00000000"],["79886.41000000","0.00000000"],["79797.68000000","0.00769000"],["79773.62000000","0.00000000"],["71985.60000000","0.00080000"]],"a":[["79997.91000000","0.00008000"],["80016.11000000","0.00000000"],["80019.20000000","0.49420000"],["80019.99000000","0.42907000"],["80031.60000000","1.12632000"],["80102.42000000","0.00000000"],["80105.87000000","0.00000000"]]}}}
{"rx_ns": 10696358103000, "frame": {"stream":"btcusdt@depth20@100ms","data":{"lastUpdateId":99116120008,"bids":[["79983.99000000","5.97694000"],["79983.98000000","1.69095000"],["79983.97000000","0.00013000"],["79983.50000000","3.78317000"],["79983.49000000","0.23364000"],["79983.10000000","0.00400000"],["79982.81000000","0.00028000"],["79982.71000000","0.01674000"],["79982.30000000","0.00007000"],["79982.29000000","0.07514000"],["79982.28000000","0.25061000"],["79982.05000000","0.00593000"],["79982.00000000","0.07514000"],["79981.99000000","0.39414000"],["79981.94000000","0.00007000"],["79981.77000000","0.00008000"],["79981.54000000","0.00007000"],["79981.51000000","0.21892000"],["79981.43000000","0.02009000"],["79981.29000000","0.00014000"]],"asks":[["79984.00000000","0.85572000"],["79984.01000000","0.00077000"],["79984.27000000","0.00007000"],["79984.34000000","0.00007000"],["79984.61000000","0.00007000"],["79985.16000000","0.00014000"],["79985.50000000","0.00884000"],["79985.99000000","0.00014000"],["79986.00000000","0.02421000"],["79986.20000000","0.00007000"],["79986.28000000","0.00014000"],["79986.29000000","0.03050000"],["79986.63000000","0.00014000"],["79986.64000000","0.05309000"],["79986.77000000","0.00014000"],["79986.78000000","0.01465000"],["79986.94000000","0.00014000"],["79986.95000000","0.31285000"],["79987.24000000","0.00007000"],["79988.00000000","0.02428000"]]}}}
{"rx_ns": 10696358181500, "frame": {"stream":"btcusdt@depth@100ms","data":{"e":"depthUpdate","E":1787647691514,"s":"BTCUSDT","U":99116119963,"u":99116120008,"b":[["79983.51000000","0.00000000"],["79983.49000000","0.23364000"],["79982.81000000","0.00028000"],["79982.28000000","0.25061000"],["79982.05000000","0.00593000"],["79982.01000000","0.00000000"],["79980.24000000","0.00625000"],["79978.76000000","0.00400000"],["79978.00000000","0.00000000"],["79976.91000000","0.00162000"],["79976.67000000","0.30000000"],["79976.41000000","0.00000000"],["79976.29000000","0.30591000"],["79971.04000000","0.02000000"],["79963.78000000","0.00000000"],["79854.57000000","0.00012000"],["79766.24000000","0.00399000"],["71985.60000000","0.00096000"],["63987.20000000","0.00031000"]],"a":[["79984.00000000","0.85572000"],["79986.00000000","0.02421000"],["79986.86000000","0.00000000"],["79991.84000000","0.08575000"],["79992.00000000","0.22671000"],["79992.36000000","0.06829000"],["79993.30000000","0.00000000"],["79993.95000000","0.00059000"],["79994.60000000","0.00060000"],["79994.61000000","0.00000000"],["79994.90000000","0.00000000"],["79995.78000000","0.00000000"],["79996.16000000","0.06914000"],["79996.60000000","0.00000000"],["79996.95000000","0.00000000"],["79998.41000000","0.00000000"],["79999.08000000","0.00000000"],["80000.17000000","0.00000000"],["80004.00000000","0.02407000"],["80010.91000000","0.02000000"],["80021.70000000","0.33750000"],["80081.92000000","0.03281000"],["80105.35000000","0.80000000"],["80209.44000000","0.00007000"],["80213.43000000","0.00000000"]]}}}
{"rx_ns": 10696454524800, "frame": {"stream":"btcusdt@depth20@100ms","data":{"lastUpdateId":99116120035,"bids":[["79983.99000000","5.97694000"],["79983.98000000","1.69095000"],["79983.97000000","0.00013000"],["79983.50000000","3.78317000"],["79983.49000000","0.23364000"],["79983.10000000","0.00400000"],["79982.81000000","0.00014000"],["79982.71000000","0.01688000"],["79982.30000000","0.00007000"],["79982.29000000","0.07514000"],["79982.28000000","0.25061000"],["79982.05000000","0.00586000"],["79982.00000000","0.07514000"],["79981.99000000","0.39414000"],["79981.94000000","0.00007000"],["79981.77000000","0.00008000"],["79981.54000000","0.00007000"],["79981.51000000","0.21892000"],["79981.43000000","0.02009000"],["79981.29000000","0.00014000"]],"asks":[["79984.00000000","0.85572000"],["79984.01000000","0.00077000"],["79984.27000000","0.00007000"],["79984.34000000","0.00007000"],["79984.61000000","0.00007000"],["79985.16000000","0.00014000"],["79985.50000000","0.00884000"],["79985.99000000","0.00014000"],["79986.00000000","0.02421000"],["79986.20000000","0.00007000"],["79986.28000000","0.00014000"],["79986.29000000","0.03050000"],["79986.63000000","0.00014000"],["79986.64000000","0.05309000"],["79986.77000000","0.00014000"],["79986.78000000","0.01465000"],["79986.94000000","0.00014000"],["79986.95000000","0.31285000"],["79987.24000000","0.00007000"],["79988.00000000","0.02428000"]]}}}
{"rx_ns": 10696454667600, "frame": {"stream":"btcusdt@depth@100ms","data":{"e":"depthUpdate","E":1787647691614,"s":"BTCUSDT","U":99116120009,"u":99116120035,"b":[["79983.49000000","0.23364000"],["79982.81000000","0.00014000"],["79982.71000000","0.01688000"],["79982.28000000","0.25061000"],["79982.05000000","0.00586000"],["79971.87000000","0.02200000"],["79955.88000000","0.00000000"],["79944.79000000","0.00000000"],["71985.60000000","0.00112000"],["63987.20000000","0.00000000"]],"a":[["79990.00000000","0.02428000"],["79992.37000000","0.00000000"],["79995.79000000","0.00000000"],["79997.30000000","0.00596000"],["79998.41000000","0.08575000"],["79999.68000000","0.07721000"],["80010.14000000","0.02000000"],["80081.07000000","0.02000000"],["80142.47000000","0.00000000"]]}}}
{"rx_ns": 10696553856400, "frame": {"stream":"btcusdt@depth20@100ms","data":{"lastUpdateId":99116120051,"bids":[["79983.99000000","5.97694000"],["79983.98000000","1.69095000"],["79983.97000000","0.00013000"],["79983.50000000","3.78317000"],["79983.49000000","0.23364000"],["79983.10000000","0.00400000"],["79982.81000000","0.00014000"],["79982.71000000","0.01688000"],["79982.30000000","0.00007000"],["79982.29000000","0.07514000"],["79982.28000000","0.25061000"],["79982.05000000","0.00586000"],["79982.00000000","0.07514000"],["79981.99000000","0.39414000"],["79981.94000000","0.00007000"],["79981.77000000","0.00008000"],["79981.54000000","0.00007000"],["79981.51000000","0.21892000"],["79981.43000000","0.02009000"],["79981.29000000","0.00014000"]],"asks":[["79984.00000000","0.85572000"],["79984.01000000","0.00077000"],["79984.27000000","0.00007000"],["79984.34000000","0.00007000"],["79984.61000000","0.00007000"],["79985.16000000","0.00014000"],["79985.50000000","0.00884000"],["79985.99000000","0.00014000"],["79986.00000000","0.02421000"],["79986.20000000","0.00007000"],["79986.28000000","0.00014000"],["79986.29000000","0.03050000"],["79986.63000000","0.00014000"],["79986.64000000","0.05309000"],["79986.77000000","0.00014000"],["79986.78000000","0.01465000"],["79986.94000000","0.00014000"],["79986.95000000","0.31285000"],["79987.24000000","0.00007000"],["79988.00000000","0.02428000"]]}}}
{"rx_ns": 10696553947400, "frame": {"stream":"btcusdt@depth@100ms","data":{"e":"depthUpdate","E":1787647691714,"s":"BTCUSDT","U":99116120036,"u":99116120051,"b":[["79978.93000000","0.00007000"],["79976.85000000","0.00007000"],["79971.11000000","0.02000000"],["79961.00000000","0.70000000"],["79960.60000000","0.12506000"],["79959.52000000","0.00000000"],["79956.08000000","0.00000000"],["79849.59000000","0.00014000"],["71985.60000000","0.00144000"]],"a":[["80008.59000000","0.12498000"],["80012.06000000","0.04538000"],["80015.69000000","0.00000000"],["80063.76000000","0.02000000"],["80083.18000000","0.12223000"],["80200.39000000","0.00399000"]]}}}
{"rx_ns": 10696652540000, "frame": {"stream":"btcusdt@depth20@100ms","data":{"lastUpdateId":99116120075,"bids":[["79983.99000000","6.08811000"],["79983.98000000","1.62081000"],["79983.97000000","0.00013000"],["79983.50000000","3.78317000"],["79983.49000000","0.23364000"],["79983.10000000","0.00400000"],["79982.81000000","0.00014000"],["79982.71000000","0.01688000"],["79982.30000000","0.00007000"],["79982.29000000","0.07514000"],["79982.28000000","0.25061000"],["79982.05000000","0.00586000"],["79982.00000000","0.07514000"],["79981.99000000","0.39414000"],["79981.94000000","0.00007000"],["79981.77000000","0.00008000"],["79981.54000000","0.00007000"],["79981.51000000","0.21892000"],["79981.43000000","0.02009000"],["79981.29000000","0.00014000"]],"asks":[["79984.00000000","0.85585000"],["79984.01000000","0.00077000"],["79984.27000000","0.00007000"],["79984.34000000","0.00007000"],["79984.61000000","0.00007000"],["79985.16000000","0.00014000"],["79985.50000000","0.00884000"],["79985.94000000","0.00007000"],["79985.99000000","0.00014000"],["79986.00000000","0.02421000"],["79986.20000000","0.00007000"],["79986.28000000","0.00014000"],["79986.29000000","0.03050000"],["79986.63000000","0.00014000"],["79986.64000000","0.05309000"],["79986.77000000","0.00014000"],["79986.78000000","0.01465000"],["79986.94000000","0.00014000"],["79986.95000000","0.31285000"],["79987.24000000","0.00007000"]]}}}
{"rx_ns": 10696652645700, "frame": {"stream":"btcusdt@depth@100ms","data":{"e":"depthUpdate","E":1787647691814,"s":"BTCUSDT","U":99116120052,"u":99116120075,"b":[["79983.99000000","6.08811000"],["79983.98000000","1.62081000"],["79980.95000000","0.02481000"],["79978.73000000","0.20571000"],["79978.00000000","0.00013000"],["79977.16000000","0.34006000"],["79975.89000000","0.02600000"],["79971.89000000","0.02000000"],["79970.99000000","0.02200000"],["79955.03000000","0.00000000"],["79910.11000000","0.02084000"],["78782.54000000","0.00000000"],["73585.27000000","0.00014000"],["71985.60000000","0.00128000"],["71985.00000000","0.00000000"]],"a":[["79984.00000000","0.85585000"],["79985.94000000","0.00007000"],["79989.99000000","0.00020000"],["79990.00000000","0.02421000"],["79992.00000000","0.22678000"]]}}}
{"rx_ns": 10696758190000, "frame": {"stream":"btcusdt@depth20@100ms","data":{"lastUpdateId":99116120088,"bids":[["79983.99000000","6.08811000"],["79983.98000000","1.62081000"],["79983.97000000","0.00013000"],["79983.50000000","3.78317000"],["79983.49000000","0.23364000"],["79983.10000000","0.00400000"],["79982.81000000","0.00014000"],["79982.71000000","0.01688000"],["79982.30000000","0.00007000"],["79982.29000000","0.07514000"],["79982.28000000","0.25061000"],["79982.05000000","0.00586000"],["79982.00000000","0.07514000"],["79981.99000000","0.39414000"],["79981.94000000","0.00007000"],["79981.77000000","0.00008000"],["79981.54000000","0.00007000"],["79981.51000000","0.21892000"],["79981.43000000","0.02009000"],["79981.29000000","0.00014000"]],"asks":[["79984.00000000","0.85585000"],["79984.01000000","0.00077000"],["79984.27000000","0.00007000"],["79984.34000000","0.00007000"],["79984.61000000","0.00007000"],["79985.16000000","0.00014000"],["79985.50000000","0.00884000"],["79985.94000000","0.00007000"],["79985.99000000","0.00014000"],["79986.00000000","0.02421000"],["79986.20000000","0.00007000"],["79986.28000000","0.00014000"],["79986.29000000","0.03050000"],["79986.63000000","0.00014000"],["79986.64000000","0.05309000"],["79986.77000000","0.00014000"],["79986.78000000","0.01465000"],["79986.94000000","0.00014000"],["79986.95000000","0.31285000"],["79987.24000000","0.00007000"]]}}}
{"rx_ns": 10696758268800, "frame": {"stream":"btcusdt@depth@100ms","data":{"e":"depthUpdate","E":1787647691914,"s":"BTCUSDT","U":99116120076,"u":99116120088,"b":[["79955.93000000","0.00000000"],["79910.11000000","0.00000000"],["71985.60000000","0.00160000"]],"a":[["79996.16000000","0.12187000"],["79997.44000000","0.08575000"],["79998.42000000","0.08966000"],["80001.99000000","0.00000000"],["80008.36000000","0.00399000"],["80009.98000000","0.81736000"],["80081.07000000","0.00000000"],["80081.92000000","0.01281000"],["80400.00000000","1.40357000"]]}}}
{"rx_ns": 10696854047500, "frame": {"stream":"btcusdt@depth20@100ms","data":{"lastUpdateId":99116120168,"bids":[["79983.99000000","4.08687000"],["79983.98000000","1.62081000"],["79983.97000000","0.00013000"],["79983.51000000","0.00014000"],["79983.50000000","1.47171000"],["79983.49000000","0.23364000"],["79983.10000000","0.00400000"],["79982.81000000","0.00014000"],["79982.71000000","0.01688000"],["79982.30000000","0.00007000"],["79982.29000000","0.00014000"],["79982.28000000","0.24661000"],["79982.05000000","0.00014000"],["79982.00000000","0.00014000"],["79981.99000000","0.39414000"],["79981.94000000","0.00007000"],["79981.77000000","0.00008000"],["79981.54000000","0.00007000"],["79981.51000000","0.21892000"],["79981.43000000","0.02009000"]],"asks":[["79984.00000000","0.98152000"],["79984.01000000","0.00077000"],["79984.27000000","0.00007000"],["79984.34000000","0.00007000"],["79984.61000000","0.00007000"],["79985.16000000","0.00014000"],["79985.50000000","0.00884000"],["79985.94000000","0.00007000"],["79985.99000000","0.00014000"],["79986.00000000","0.02421000"],["79986.20000000","0.00007000"],["79986.24000000","0.08477000"],["79986.28000000","0.00014000"],["79986.29000000","0.03050000"],["79986.63000000","0.00014000"],["79986.64000000","0.05309000"],["79986.77000000","0.00014000"],["79986.78000000","0.01465000"],["79986.94000000","0.08589000"],["79986.95000000","0.31285000"]]}}}
{"rx_ns": 10696854130600, "frame": {"stream":"btcusdt@depth@100ms","data":{"e":"depthUpdate","E":1787647692014,"s":"BTCUSDT","U":99116120089,"u":99116120168,"b":[["79983.99000000","4.08687000"],["79983.51000000","0.00014000"],["79983.50000000","1.47171000"],["79982.29000000","0.00014000"],["79982.28000000","0.24661000"],["79982.05000000","0.00014000"],["79982.00000000","0.00014000"],["79981.78000000","0.00000000"],["79980.24000000","0.00000000"],["79979.91000000","0.00000000"],["79978.94000000","0.00625000"],["79978.76000000","0.00007000"],["79978.01000000","0.00625000"],["79977.16000000","0.33999000"],["79976.91000000","0.00000000"],["79975.74000000","0.00162000"],["79974.50000000","0.00400000"],["79974.49000000","0.00000000"],["79970.62000000","0.00000000"],["79969.91000000","0.15381000"],["79968.26000000","0.00625000"],["79968.25000000","0.00000000"],["79962.45000000","0.00000000"],["79955.06000000","0.02400000"],["79952.69000000","0.02000000"],["79921.80000000","1.23907000"],["79910.11000000","0.02084000"],["79904.89000000","0.00000000"],["79902.25000000","2.49867000"],["78784.23000000","0.00030000"],["71985.60000000","0.00176000"],["71977.01000000","0.00000000"],["63987.20000000","0.00031000"]],"a":[["79984.00000000","0.98152000"],["79986.24000000","0.08477000"],["79986.94000000","0.08589000"],["79989.60000000","0.08506000"],["79990.00000000","0.02428000"],["79990.72000000","0.08575000"],["79991.53000000","0.00053000"],["79991.54000000","0.03083000"],["79991.83000000","0.00065000"],["79991.84000000","0.08582000"],["79991.99000000","0.08583000"],["79992.00000000","0.22671000"],["79992.36000000","0.00000000"],["79992.68000000","0.00437000"],["79993.95000000","0.00000000"],["79994.31000000","0.00400000"],["79994.60000000","0.00000000"],["79995.20000000","0.08575000"],["79995.69000000","0.00000000"],["79997.08000000","0.00400000"],["79997.44000000","0.00000000"],["79998.41000000","0.00000000"],["79998.42000000","0.08566000"],["79999.68000000","0.00000000"],["80000.25000000","0.00000000"],["80003.17000000","0.00000000"],["80003.18000000","0.00000000"],["80005.15000000","1.87060000"],["80009.78000000","0.01749000"],["80048.94000000","0.00000000"],["80100.33000000","0.00012000"]]}}}
{"rx_ns": 10696955792500, "frame": {"stream":"btcusdt@depth20@100ms","data":{"lastUpdateId":99116120320,"bids":[["79983.99000000","3.99952000"],["79983.98000000","0.80083000"],["79983.97000000","0.00013000"],["79983.51000000","0.00014000"],["79983.50000000","1.47185000"],["79983.49000000","0.19365000"],["79983.10000000","0.00400000"],["79982.81000000","0.00007000"],["79982.71000000","0.01688000"],["79982.29000000","0.00014000"],["79982.28000000","0.24647000"],["79982.00000000","0.00007000"],["79981.99000000","0.39428000"],["79981.94000000","0.00007000"],["79981.77000000","0.00008000"],["79981.54000000","0.00007000"],["79981.51000000","0.21906000"],["79981.43000000","0.02023000"],["79981.29000000","0.00014000"],["79981.06000000","0.00014000"]],"asks":[["79984.00000000","1.42734000"],["79984.01000000","0.00077000"],["79984.27000000","0.00007000"],["79984.34000000","0.00007000"],["79984.61000000","0.00007000"],["79985.16000000","0.00014000"],["79985.50000000","0.00884000"],["79985.94000000","0.00007000"],["79985.99000000","0.00014000"],["79986.00000000","0.02428000"],["79986.20000000","0.00007000"],["79986.24000000","0.00014000"],["79986.28000000","0.00014000"],["79986.29000000","0.03050000"],["79986.63000000","0.00014000"],["79986.64000000","0.05309000"],["79986.77000000","0.00014000"],["79986.78000000","0.01472000"],["79986.94000000","0.00014000"],["79986.95000000","0.00021000"]]}}}
{"rx_ns": 10696955880600, "frame": {"stream":"btcusdt@depth@100ms","data":{"e":"depthUpdate","E":1787647692114,"s":"BTCUSDT","U":99116120169,"u":99116120320,"b":[["79983.99000000","3.99952000"],["79983.98000000","0.80083000"],["79983.50000000","1.47185000"],["79983.49000000","0.19365000"],["79982.81000000","0.00007000"],["79982.71000000","0.01688000"],["79982.30000000","0.00000000"],["79982.29000000","0.00014000"],["79982.28000000","0.24647000"],["79982.05000000","0.00000000"],["79982.00000000","0.00007000"],["79981.99000000","0.39428000"],["79981.51000000","0.21906000"],["79981.43000000","0.02023000"],["79980.95000000","0.02474000"],["79979.09000000","0.00587000"],["79978.76000000","0.00400000"],["79978.73000000","0.20545000"],["79978.67000000","0.00400000"],["79978.29000000","0.18746000"],["79978.28000000","0.19385000"],["79977.99000000","0.21344000"],["79975.74000000","0.00000000"],["79974.50000000","0.00000000"],["79974.49000000","0.00162000"],["79968.75000000","0.00007000"],["79962.64000000","0.42475000"],["79958.14000000","0.00406000"],["79955.04000000","0.02000000"],["79954.08000000","0.09519000"],["79913.11000000","0.00000000"],["79910.11000000","0.00000000"],["71985.60000000","0.00160000"]],"a":[["79984.00000000","1.42734000"],["79984.01000000","0.00077000"],["79986.00000000","0.02428000"],["79986.23000000","0.00000000"],["79986.24000000","0.00014000"],["79986.78000000","0.01472000"],["79986.94000000","0.00014000"],["79986.95000000","0.00021000"],["79987.99000000","0.00007000"],["79988.00000000","0.02414000"],["79988.06000000","0.01748000"],["79989.03000000","0.00014000"],["79989.34000000","0.01748000"],["79989.60000000","0.00007000"],["79989.63000000","0.21791000"],["79989.64000000","0.42218000"],["79989.83000000","0.05476000"],["79990.00000000","0.02421000"],["79990.72000000","0.00000000"],["79991.54000000","0.00000000"],["79991.84000000","0.00007000"],["79991.99000000","0.00008000"],["79992.45000000","0.10800000"],["79992.68000000","0.00000000"],["79992.92000000","0.00625000"],["79993.30000000","0.00000000"],["79993.92000000","0.00000000"],["79993.93000000","0.15000000"],["79995.20000000","0.00000000"],["79996.15000000","0.08575000"],["79996.16000000","0.06914000"],["80000.75000000","0.00007000"],["80001.79000000","0.00000000"],["80010.00000000","0.72800000"],["80010.85000000","0.00166000"],["80013.81000000","0.02490000"],["80024.31000000","0.33749000"],["80027.73000000","0.00000000"],["80037.13000000","0.00000000"],["80064.44000000","0.02000000"]]}}}
{"rx_ns": 10697058224200, "frame": {"stream":"btcusdt@depth20@100ms","data":{"lastUpdateId":99116120372,"bids":[["79983.99000000","5.87022000"],["79983.98000000","0.80083000"],["79983.97000000","0.00013000"],["79983.51000000","0.00014000"],["79983.50000000","1.47185000"],["79983.49000000","0.19365000"],["79983.10000000","0.00400000"],["79982.81000000","0.00007000"],["79982.71000000","0.01688000"],["79982.29000000","0.00014000"],["79982.28000000","0.24647000"],["79982.00000000","0.00007000"],["79981.99000000","0.39428000"],["79981.94000000","0.00007000"],["79981.77000000","0.00008000"],["79981.54000000","0.00007000"],["79981.51000000","0.21906000"],["79981.43000000","0.02023000"],["79981.29000000","0.00014000"],["79981.06000000","0.00014000"]],"asks":[["79984.00000000","1.21103000"],["79984.01000000","0.00077000"],["79984.27000000","0.00007000"],["79984.34000000","0.00007000"],["79984.61000000","0.00007000"],["79985.16000000","0.00014000"],["79985.50000000","0.00884000"],["79985.94000000","0.00007000"],["79985.99000000","0.00014000"],["79986.00000000","0.02421000"],["79986.20000000","0.00007000"],["79986.28000000","0.00014000"],["79986.29000000","0.03050000"],["79986.63000000","0.00014000"],["79986.64000000","0.05309000"],["79986.77000000","0.00014000"],["79986.78000000","0.01465000"],["79986.95000000","0.00007000"],["79987.24000000","0.00007000"],["79987.99000000","0.00007000"]]}}}
{"rx_ns": 10697058356400, "frame": {"stream":"btcusdt@depth@100ms","data":{"e":"depthUpdate","E":1787647692214,"s":"BTCUSDT","U":99116120321,"u":99116120372,"b":[["79983.99000000","5.87022000"],["79978.52000000","0.00026000"],["79961.00000000","0.00000000"],["79954.97000000","0.02007000"],["79943.00000000","0.01000000"],["71985.60000000","0.00192000"],["63987.20000000","0.00000000"],["63987.19000000","0.00000000"]],"a":[["79984.00000000","1.21103000"],["79984.01000000","0.00077000"],["79986.00000000","0.02421000"],["79986.24000000","0.00000000"],["79986.78000000","0.01465000"],["79986.94000000","0.00000000"],["79986.95000000","0.00007000"],["79988.00000000","0.02428000"],["79988.06000000","0.01762000"],["79989.34000000","0.01776000"],["79989.61000000","0.01749000"],["80103.02000000","0.00018000"],["80703.85000000","0.00010000"],["81183.76000000","0.00030000"]]}}}
{"rx_ns": 10697152763500, "frame": {"stream":"btcusdt@depth20@100ms","data":{"lastUpdateId":99116120433,"bids":[["79983.99000000","5.87022000"],["79983.98000000","0.80083000"],["79983.97000000","0.00013000"],["79983.51000000","0.00014000"],["79983.50000000","1.47185000"],["79983.49000000","0.19365000"],["79983.10000000","0.00400000"],["79982.81000000","0.00007000"],["79982.71000000","0.01688000"],["79982.29000000","0.00014000"],["79982.28000000","0.20648000"],["79982.00000000","0.00007000"],["79981.99000000","0.39428000"],["79981.94000000","0.00007000"],["79981.77000000","0.00008000"],["79981.54000000","0.00007000"],["79981.51000000","0.21906000"],["79981.43000000","0.02023000"],["79981.29000000","0.00014000"],["79981.06000000","0.00014000"]],"asks":[["79984.00000000","1.42955000"],["79984.01000000","0.00077000"],["79984.27000000","0.00007000"],["79984.34000000","0.00007000"],["79984.61000000","0.00007000"],["79985.16000000","0.00014000"],["79985.50000000","0.00884000"],["79985.94000000","0.00007000"],["79985.99000000","0.00014000"],["79986.00000000","0.02421000"],["79986.20000000","0.00007000"],["79986.28000000","0.00014000"],["79986.29000000","0.03050000"],["79986.63000000","0.00014000"],["79986.64000000","0.05309000"],["79986.77000000","0.00014000"],["79986.78000000","0.01465000"],["79986.95000000","0.00007000"],["79987.04000000","0.05203000"],["79987.24000000","0.00007000"]]}}}
{"rx_ns": 10697152863000, "frame": {"stream":"btcusdt@depth@100ms","data":{"e":"depthUpdate","E":1787647692314,"s":"BTCUSDT","U":99116120373,"u":99116120433,"b":[["79982.28000000","0.20648000"],["79982.05000000","0.00000000"],["79976.00000000","1.06120000"],["79974.00000000","0.01200000"],["79972.00000000","0.01200000"],["79970.00000000","0.10579000"],["79968.00000000","0.44228000"],["79963.06000000","0.84588000"],["79958.14000000","0.00007000"],["79955.00000000","0.02400000"],["79915.54000000","0.00000000"],["79911.66000000","1.21980000"],["79909.40000000","0.00000000"],["79902.25000000","1.87060000"],["79883.56000000","0.00000000"],["79865.40000000","0.01438000"],["79835.58000000","0.00000000"],["79799.10000000","0.01380000"],["79781.48000000","0.00000000"],["79766.24000000","0.00000000"],["73585.27000000","0.00000000"],["71985.60000000","0.00192000"],["63987.00000000","0.00000000"]],"a":[["79984.00000000","1.42955000"],["79987.04000000","0.05203000"],["79988.06000000","0.01769000"],["79988.71000000","0.00000000"],["79989.34000000","0.01776000"],["79989.64000000","0.42211000"],["79989.83000000","0.00000000"],["80005.14000000","1.01460000"],["80005.18000000","0.00000000"],["80008.36000000","0.00000000"],["80013.15000000","0.33754000"],["80020.00000000","0.12023000"],["80024.31000000","0.00000000"],["80048.37000000","0.00000000"],["80061.03000000","0.16551000"],["80080.37000000","0.00000000"],["80096.22000000","0.76022000"],["80120.16000000","0.12388000"],["80128.38000000","0.00000000"],["80144.08000000","0.00000000"],["80161.77000000","0.01733000"],["80200.39000000","0.00000000"]]}}}
{"rx_ns": 10697252187000, "frame": {"stream":"btcusdt@depth20@100ms","data":{"lastUpdateId":99116120463,"bids":[["79983.99000000","6.11015000"],["79983.98000000","0.80083000"],["79983.97000000","0.00013000"],["79983.51000000","0.00014000"],["79983.50000000","1.47185000"],["79983.49000000","0.19365000"],["79983.10000000","0.00400000"],["79982.81000000","0.00007000"],["79982.71000000","0.01688000"],["79982.29000000","0.00014000"],["79982.28000000","0.20648000"],["79982.00000000","0.00007000"],["79981.99000000","0.39428000"],["79981.94000000","0.00007000"],["79981.77000000","0.00008000"],["79981.54000000","0.00007000"],["79981.51000000","0.21906000"],["79981.43000000","0.02023000"],["79981.29000000","0.00014000"],["79981.06000000","0.00014000"]],"asks":[["79984.00000000","1.08527000"],["79984.01000000","0.00084000"],["79984.27000000","0.00007000"],["79984.61000000","0.00007000"],["79985.16000000","0.00014000"],["79985.50000000","0.00884000"],["79985.94000000","0.00007000"],["79985.99000000","0.00014000"],["79986.00000000","0.02421000"],["79986.20000000","0.00007000"],["79986.28000000","0.00014000"],["79986.29000000","0.03050000"],["79986.63000000","0.00014000"],["79986.64000000","0.05309000"],["79986.77000000","0.00014000"],["79986.78000000","0.01472000"],["79986.95000000","0.00007000"],["79987.04000000","0.05217000"],["79987.24000000","0.00007000"],["79987.99000000","0.00007000"]]}}}
{"rx_ns": 10697252266100, "frame": {"stream":"btcusdt@depth@100ms","data":{"e":"depthUpdate","E":1787647692414,"s":"BTCUSDT","U":99116120434,"u":99116120463,"b":[["79983.99000000","6.11015000"],["79968.00000000","0.44728000"],["79901.46000000","0.00000000"],["71985.60000000","0.00208000"]],"a":[["79984.00000000","1.08527000"],["79984.01000000","0.00084000"],["79984.34000000","0.00000000"],["79986.78000000","0.01472000"],["79987.04000000","0.05217000"],["79988.06000000","0.01762000"],["79989.34000000","0.01762000"],["79992.42000000","0.00455000"],["79994.80000000","0.00585000"],["80042.42000000","0.00400000"],["80048.20000000","0.00000000"],["80111.96000000","0.00160000"]]}}}
{"rx_ns": 10697353862900, "frame": {"stream":"btcusdt@depth20@100ms","data":{"lastUpdateId":99116120471,"bids":[["79983.99000000","5.87003000"],["79983.98000000","0.80083000"],["79983.97000000","0.00013000"],["79983.51000000","0.00014000"],["79983.50000000","1.47185000"],["79983.49000000","0.19365000"],["79983.10000000","0.00400000"],["79982.81000000","0.00007000"],["79982.71000000","0.01688000"],["79982.29000000","0.00014000"],["79982.28000000","0.20648000"],["79982.00000000","0.00007000"],["79981.99000000","0.39428000"],["79981.94000000","0.00007000"],["79981.77000000","0.00008000"],["79981.54000000","0.00007000"],["79981.51000000","0.21906000"],["79981.43000000","0.02023000"],["79981.29000000","0.00014000"],["79981.06000000","0.00014000"]],"asks":[["79984.00000000","1.08527000"],["79984.01000000","0.00084000"],["79984.27000000","0.00007000"],["79984.61000000","0.00007000"],["79985.16000000","0.00014000"],["79985.50000000","0.00884000"],["79985.94000000","0.00007000"],["79985.99000000","0.00014000"],["79986.00000000","0.02421000"],["79986.20000000","0.00007000"],["79986.28000000","0.00014000"],["79986.29000000","0.03050000"],["79986.63000000","0.00014000"],["79986.64000000","0.05309000"],["79986.77000000","0.00014000"],["79986.78000000","0.01472000"],["79986.95000000","0.00007000"],["79987.04000000","0.05217000"],["79987.24000000","0.00007000"],["79987.99000000","0.00007000"]]}}}
{"rx_ns": 10697354017700, "frame": {"stream":"btcusdt@depth@100ms","data":{"e":"depthUpdate","E":1787647692514,"s":"BTCUSDT","U":99116120464,"u":99116120471,"b":[["79983.99000000","5.87003000"],["79951.01000000","0.02000000"],["65146.32000000","0.00000000"],["63987.20000000","0.00031000"],["42091.80000000","0.00036000"]],"a":[["80107.18000000","0.00031000"],["80134.58000000","0.00399000"]]}}}
{"rx_ns": 10697454029900, "frame": {"stream":"btcusdt@depth20@100ms","data":{"lastUpdateId":99116120491,"bids":[["79983.99000000","5.87001000"],["79983.98000000","0.80083000"],["79983.97000000","0.00013000"],["79983.51000000","0.00014000"],["79983.50000000","1.47185000"],["79983.49000000","0.19365000"],["79983.10000000","0.00400000"],["79982.81000000","0.00007000"],["79982.71000000","0.01688000"],["79982.29000000","0.00014000"],["79982.28000000","0.20648000"],["79982.00000000","0.00007000"],["79981.99000000","0.39428000"],["79981.94000000","0.00007000"],["79981.77000000","0.00008000"],["79981.54000000","0.00007000"],["79981.51000000","0.21906000"],["79981.43000000","0.02023000"],["79981.29000000","0.00014000"],["79981.06000000","0.00014000"]],"asks":[["79984.00000000","1.08540000"],["79984.01000000","0.00097000"],["79984.02000000","0.00013000"],["79984.27000000","0.00007000"],["79984.61000000","0.00007000"],["79985.16000000","0.00014000"],["79985.50000000","0.00884000"],["79985.94000000","0.00007000"],["79985.99000000","0.00014000"],["79986.00000000","0.02421000"],["79986.20000000","0.00007000"],["79986.28000000","0.00014000"],["79986.29000000","0.03050000"],["79986.63000000","0.00014000"],["79986.64000000","0.05309000"],["79986.77000000","0.00014000"],["79986.78000000","0.01472000"],["79986.95000000","0.00007000"],["79987.04000000","0.05217000"],["79987.24000000","0.00007000"]]}}}
{"rx_ns": 10697454109300, "frame": {"stream":"btcusdt@depth@100ms","data":{"e":"depthUpdate","E":1787647692615,"s":"BTCUSDT","U":99116120472,"u":99116120491,"b":[["79983.99000000","5.87001000"],["79979.60000000","0.00400000"],["79978.76000000","0.00400000"],["79978.67000000","0.00000000"],["79951.84000000","0.02200000"],["79896.97000000","0.62495000"],["79797.68000000","0.00000000"],["79792.16000000","0.00769000"],["71985.60000000","0.00224000"],["71985.59000000","0.00008000"],["63987.20000000","0.00000000"]],"a":[["79984.00000000","1.08540000"],["79984.01000000","0.00097000"],["79984.02000000","0.00013000"],["79992.00000000","0.22664000"],["79998.00000000","0.02407000"],["80152.01000000","0.00160000"]]}}}
{"rx_ns": 10697552559400, "frame": {"stream":"btcusdt@depth20@100ms","data":{"lastUpdateId":99116120514,"bids":[["79983.99000000","5.87001000"],["79983.98000000","0.80083000"],["79983.97000000","0.00013000"],["79983.51000000","0.00014000"],["79983.50000000","1.47185000"],["79983.49000000","0.19365000"],["79983.10000000","0.00400000"],["79982.81000000","0.00007000"],["79982.71000000","0.01688000"],["79982.29000000","0.00014000"],["79982.28000000","0.20648000"],["79982.00000000","0.00007000"],["79981.99000000","0.39428000"],["79981.94000000","0.00007000"],["79981.77000000","0.00008000"],["79981.54000000","0.00007000"],["79981.51000000","0.21906000"],["79981.43000000","0.02023000"],["79981.29000000","0.00014000"],["79981.06000000","0.00014000"]],"asks":[["79984.00000000","1.08390000"],["79984.01000000","0.00097000"],["79984.02000000","0.00013000"],["79984.27000000","0.00007000"],["79984.61000000","0.00007000"],["79985.16000000","0.00014000"],["79985.50000000","0.00884000"],["79985.94000000","0.00007000"],["79985.99000000","0.00014000"],["79986.00000000","0.02421000"],["79986.20000000","0.00007000"],["79986.28000000","0.00014000"],["79986.29000000","0.03050000"],["79986.63000000","0.00014000"],["79986.64000000","0.05309000"],["79986.77000000","0.00014000"],["79986.78000000","0.01472000"],["79986.95000000","0.00007000"],["79987.04000000","0.00014000"],["79987.24000000","0.00007000"]]}}}
{"rx_ns": 10697552656600, "frame": {"stream":"btcusdt@depth@100ms","data":{"e":"depthUpdate","E":1787647692714,"s":"BTCUSDT","U":99116120492,"u":99116120514,"b":[["79976.01000000","0.00162000"],["79974.49000000","0.00000000"],["79951.08000000","0.02000000"],["79911.54000000","0.00000000"],["79849.59000000","0.00000000"],["71985.60000000","0.00224000"]],"a":[["79984.00000000","1.08390000"],["79987.04000000","0.00014000"],["79991.53000000","0.00000000"],["79991.83000000","0.00000000"],["79991.89000000","0.00000000"],["79992.41000000","0.00046000"],["79992.51000000","0.00000000"],["79992.86000000","0.00055000"],["79992.92000000","0.00000000"],["79994.31000000","0.00000000"],["79995.46000000","0.00400000"],["79995.81000000","0.00625000"],["79997.08000000","0.00000000"],["79999.11000000","0.00400000"],["80005.00000000","0.70000000"],["80045.49000000","0.00007000"],["80047.75000000","0.00007000"],["80054.56000000","0.00399000"]]}}}
{"rx_ns": 10697657144200, "frame": {"stream":"btcusdt@depth20@100ms","data":{"lastUpdateId":99116120530,"bids":[["79983.99000000","5.87001000"],["79983.98000000","0.80083000"],["79983.97000000","0.00013000"],["79983.51000000","0.00014000"],["79983.50000000","1.47185000"],["79983.49000000","0.19365000"],["79983.10000000","0.00400000"],["79982.81000000","0.00007000"],["79982.71000000","0.01688000"],["79982.29000000","0.00014000"],["79982.28000000","0.20648000"],["79982.00000000","0.00007000"],["79981.99000000","0.39428000"],["79981.94000000","0.00007000"],["79981.77000000","0.00008000"],["79981.54000000","0.00007000"],["79981.51000000","0.21906000"],["79981.43000000","0.02023000"],["79981.29000000","0.00014000"],["79981.06000000","0.00014000"]],"asks":[["79984.00000000","1.08390000"],["79984.01000000","0.00097000"],["79984.02000000","0.00013000"],["79984.27000000","0.00007000"],["79984.61000000","0.00007000"],["79985.16000000","0.00014000"],["79985.50000000","0.00884000"],["79985.94000000","0.00007000"],["79985.99000000","0.00014000"],["79986.00000000","0.02421000"],["79986.20000000","0.00007000"],["79986.28000000","0.00014000"],["79986.29000000","0.03050000"],["79986.63000000","0.00014000"],["79986.64000000","0.05309000"],["79986.77000000","0.00014000"],["79986.78000000","0.01465000"],["79986.95000000","0.00007000"],["79987.24000000","0.00007000"],["79987.99000000","0.00007000"]]}}}
{"rx_ns": 10697657222400, "frame": {"stream":"btcusdt@depth@100ms","data":{"e":"depthUpdate","E":1787647692814,"s":"BTCUSDT","U":99116120515,"u":99116120530,"b":[["79955.86000000","0.02600000"],["79951.86000000","0.02000000"],["79950.96000000","0.02200000"],["71985.60000000","0.00240000"],["65146.32000000","0.01188000"]],"a":[["79986.78000000","0.01465000"],["79987.04000000","0.00000000"],["79989.34000000","0.01776000"],["80005.00000000","0.00000000"],["80010.00000000","0.02800000"]]}}}
