{"rx_ns": 10705052250000, "frame": {"stream":"btcusdt@depth20@100ms","data":{"lastUpdateId":99116125518,"bids":[["79980.15000000","2.09449000"],["79980.14000000","0.00063000"],["79980.10000000","0.00015000"],["79979.99000000","0.00020000"],["79979.78000000","0.00014000"],["79979.77000000","0.05453000"],["79979.76000000","0.06678000"],["79979.03000000","0.00921000"],["79978.93000000","0.00007000"],["79978.73000000","0.00007000"],["79978.42000000","0.00007000"],["79978.29000000","0.00007000"],["79978.28000000","0.00007000"],["79977.99000000","0.00007000"],["79977.76000000","0.00014000"],["79977.75000000","0.01521000"],["79977.42000000","0.00007000"],["79977.20000000","0.00014000"],["79977.19000000","0.04732000"],["79976.90000000","0.00007000"]],"asks":[["79980.16000000","2.02364000"],["79980.17000000","0.00027000"],["79980.18000000","0.00013000"],["79980.32000000","0.00014000"],["79980.33000000","0.00988000"],["79980.97000000","0.00007000"],["79981.01000000","0.00007000"],["79981.04000000","0.00014000"],["79981.05000000","0.67260000"],["79981.06000000","0.00014000"],["79981.29000000","0.00014000"],["79981.61000000","0.01653000"],["79981.65000000","0.00400000"],["79981.70000000","0.00014000"],["79981.71000000","0.04366000"],["79982.30000000","0.00441000"],["79982.62000000","0.00014000"],["79982.63000000","0.04032000"],["79982.78000000","0.00014000"],["79982.79000000","0.05321000"]]}}}
{"rx_ns": 10705052429700, "frame": {"stream":"btcusdt@depth@100ms","data":{"e":"depthUpdate","E":1787647700214,"s":"BTCUSDT","U":99116125500,"u":99116125518,"b":[["79980.15000000","2.09449000"],["79980.14000000","0.00063000"],["79975.44000000","0.21414000"],["79942.24000000","0.00000000"],["79838.13000000","0.00000000"],["71982.14000000","0.00176000"],["63984.12000000","0.00000000"]],"a":[["79984.79000000","0.00000000"],["80080.63000000","0.00000000"],["80125.69000000","0.00399000"],["80699.97000000","0.00010000"]]}}}
{"rx_ns": 10705152553600, "frame": {"stream":"btcusdt@depth20@100ms","data":{"lastUpdateId":99116125728,"bids":[["79980.15000000","2.16469000"],["79980.14000000","0.00056000"],["79980.10000000","0.00015000"],["79979.99000000","0.00020000"],["79979.78000000","0.00014000"],["79979.77000000","0.14099000"],["79979.76000000","0.06678000"],["79979.03000000","0.00928000"],["79978.93000000","0.00007000"],["79978.73000000","0.00007000"],["79978.42000000","0.00007000"],["79978.29000000","0.00007000"],["79978.28000000","0.00007000"],["79978.03000000","0.00026000"],["79977.99000000","0.00007000"],["79977.90000000","0.00014000"],["79977.75000000","0.01528000"],["79977.50000000","0.00014000"],["79977.49000000","0.00014000"],["79977.48000000","0.31268000"]],"asks":[["79980.16000000","1.70164000"],["79980.17000000","0.00076000"],["79980.18000000","0.00013000"],["79980.32000000","0.00014000"],["79980.33000000","0.00995000"],["79980.61000000","0.00014000"],["79980.62000000","0.03000000"],["79980.97000000","0.00007000"],["79981.01000000","0.00007000"],["79981.04000000","0.00014000"],["79981.05000000","0.32793000"],["79981.06000000","0.00014000"],["79981.29000000","0.00014000"],["79981.61000000","0.01660000"],["79981.71000000","0.00014000"],["79981.81000000","0.00014000"],["79981.82000000","0.04000000"],["79982.62000000","0.00014000"],["79982.63000000","0.04032000"],["79982.79000000","0.05321000"]]}}}
{"rx_ns": 10705152653600, "frame": {"stream":"btcusdt@depth@100ms","data":{"e":"depthUpdate","E":1787647700314,"s":"BTCUSDT","U":99116125519,"u":99116125728,"b":[["79980.15000000","2.16469000"],["79980.14000000","0.00056000"],["79979.77000000","0.14099000"],["79979.03000000","0.00928000"],["79978.03000000","0.00026000"],["79977.90000000","0.00014000"],["79977.89000000","0.00000000"],["79977.76000000","0.00000000"],["79977.75000000","0.01528000"],["79977.50000000","0.00014000"],["79977.49000000","0.00014000"],["79977.48000000","0.31268000"],["79977.42000000","0.00014000"],["79977.20000000","0.00000000"],["79976.48000000","0.00000000"],["79975.73000000","0.00893000"],["79975.63000000","0.00007000"],["79975.47000000","0.00000000"],["79975.46000000","0.77365000"],["79975.45000000","2.91999000"],["79975.44000000","0.00000000"],["79975.43000000","0.00000000"],["79975.35000000","0.00400000"],["79973.70000000","0.00008000"],["79972.24000000","0.00000000"],["79972.09000000","0.00000000"],["79971.48000000","0.36586000"],["79971.20000000","0.00000000"],["79969.66000000","0.00000000"],["79969.05000000","0.00400000"],["79966.97000000","0.15381000"],["79966.77000000","0.08576000"],["79965.75000000","0.00000000"],["79965.02000000","0.00000000"],["79964.91000000","0.00007000"],["79963.01000000","0.00625000"],["79962.45000000","0.37528000"],["79962.36000000","0.30382000"],["79960.97000000","0.00000000"],["79958.00000000","0.64944000"],["79956.45000000","0.00000000"],["79954.69000000","0.33779000"],["79952.75000000","0.00000000"],["79951.64000000","0.00000000"],["79950.01000000","0.00000000"],["79950.00000000","0.12039000"],["79942.22000000","0.09431000"],["79938.72000000","0.00000000"],["79930.44000000","0.00000000"],["79927.68000000","0.00000000"],["79924.95000000","0.00000000"],["79907.47000000","0.00000000"],["79900.00000000","0.12214000"],["79841.87000000","0.04528000"],["71982.14000000","0.00192000"],["63984.00000000","0.00014000"]],"a":[["79980.16000000","1.70164000"],["79980.17000000","0.00076000"],["79980.33000000","0.00995000"],["79980.61000000","0.00014000"],["79980.62000000","0.03000000"],["79981.05000000","0.32793000"],["79981.61000000","0.01660000"],["79981.65000000","0.00000000"],["79981.70000000","0.00000000"],["79981.71000000","0.00014000"],["79981.81000000","0.00014000"],["79981.82000000","0.04000000"],["79982.30000000","0.00000000"],["79982.31000000","0.00000000"],["79982.78000000","0.00000000"],["79983.50000000","0.00007000"],["79983.51000000","0.03779000"],["79984.17000000","0.01956000"],["79984.66000000","0.02931000"],["79984.67000000","0.00000000"],["79985.49000000","0.00000000"],["79986.64000000","0.00000000"],["79986.77000000","0.00000000"],["79986.78000000","0.00000000"],["79987.03000000","0.00000000"],["79987.87000000","0.00000000"],["79987.95000000","0.00000000"],["79987.96000000","0.01749000"],["79988.08000000","0.00033000"],["79988.09000000","0.00000000"],["79988.23000000","0.00008000"],["79988.24000000","0.44654000"],["79990.17000000","0.00000000"],["79990.84000000","0.00000000"],["79991.47000000","0.08576000"],["79991.69000000","0.00117000"],["79991.94000000","0.00400000"],["79991.95000000","0.00000000"],["79992.27000000","0.09740000"],["79992.45000000","0.00000000"],["79995.98000000","0.00000000"],["79996.91000000","0.00007000"],["79997.70000000","0.36586000"],["79997.88000000","0.00000000"],["79998.58000000","0.00000000"],["80001.02000000","0.00000000"],["80001.51000000","0.00625000"],["80001.61000000","0.00000000"],["80001.99000000","0.34174000"],["80004.47000000","0.00000000"],["80006.25000000","0.02446000"],["80007.26000000","0.62537000"],["80021.14000000","0.00166000"],["80026.65000000","0.00000000"],["80038.35000000","0.00400000"],["80045.91000000","0.47211000"],["80068.60000000","0.76749000"],["80081.77000000","0.02804000"],["81179.87000000","0.00030000"]]}}}
{"rx_ns": 10705256467800, "frame": {"stream":"btcusdt@depth20@100ms","data":{"lastUpdateId":99116125855,"bids":[["79980.15000000","2.28802000"],["79980.14000000","0.00063000"],["79980.10000000","0.00007000"],["79979.99000000","0.00020000"],["79979.78000000","0.00014000"],["79979.77000000","0.25599000"],["79979.76000000","0.06678000"],["79979.03000000","0.00921000"],["79978.93000000","0.00007000"],["79978.73000000","0.00007000"],["79978.42000000","0.00007000"],["79978.29000000","0.00007000"],["79978.28000000","0.00007000"],["79977.99000000","0.00007000"],["79977.75000000","0.01528000"],["79977.49000000","0.00014000"],["79977.48000000","0.31282000"],["79977.42000000","0.00007000"],["79977.20000000","0.00014000"],["79977.19000000","0.04732000"]],"asks":[["79980.16000000","1.90384000"],["79980.17000000","0.00076000"],["79980.18000000","0.00013000"],["79980.32000000","0.00014000"],["79980.33000000","0.00995000"],["79980.61000000","0.00014000"],["79980.62000000","0.03014000"],["79980.97000000","0.00007000"],["79981.01000000","0.00007000"],["79981.04000000","0.00014000"],["79981.05000000","0.32793000"],["79981.06000000","0.00014000"],["79981.29000000","0.00014000"],["79981.61000000","0.01653000"],["79981.81000000","0.00014000"],["79981.82000000","0.04014000"],["79982.62000000","0.00014000"],["79982.63000000","0.04032000"],["79982.79000000","0.05321000"],["79982.89000000","0.01963000"]]}}}
{"rx_ns": 10705256621200, "frame": {"stream":"btcusdt@depth@100ms","data":{"e":"depthUpdate","E":1787647700414,"s":"BTCUSDT","U":99116125729,"u":99116125855,"b":[["79980.15000000","2.28802000"],["79980.14000000","0.00063000"],["79980.10000000","0.00007000"],["79979.77000000","0.25599000"],["79979.03000000","0.00921000"],["79978.03000000","0.00000000"],["79977.90000000","0.00000000"],["79977.76000000","0.00000000"],["79977.75000000","0.01528000"],["79977.50000000","0.00000000"],["79977.48000000","0.31282000"],["79977.42000000","0.00007000"],["79977.20000000","0.00014000"],["79976.67000000","0.00228000"],["79976.47000000","0.01821000"],["79976.35000000","0.00007000"],["79976.34000000","0.42215000"],["79976.29000000","0.00368000"],["79975.73000000","0.00879000"],["79975.47000000","0.00400000"],["79975.46000000","0.37786000"],["79975.45000000","1.04939000"],["79975.19000000","0.01807000"],["79974.72000000","0.02474000"],["79971.23000000","0.00000000"],["79969.54000000","0.00048000"],["79966.97000000","0.00000000"],["79962.36000000","0.00000000"],["79962.07000000","0.00000000"],["79961.12000000","0.15382000"],["79960.82000000","0.00000000"],["79959.81000000","0.33290000"],["79958.00000000","0.02407000"],["79955.34000000","0.62535000"],["79942.93000000","0.27501000"],["79938.72000000","0.00007000"],["79919.45000000","0.02200000"],["79895.97000000","1.31502000"],["79893.77000000","0.00000000"],["79887.46000000","0.00000000"],["79844.07000000","0.00020000"],["79841.87000000","0.00000000"],["79840.87000000","0.00000000"],["79767.52000000","0.00000000"],["71982.14000000","0.00176000"],["71982.00000000","0.00000000"],["63984.12000000","0.00000000"]],"a":[["79980.16000000","1.90384000"],["79980.33000000","0.00995000"],["79980.62000000","0.03014000"],["79981.61000000","0.01653000"],["79981.71000000","0.00000000"],["79981.82000000","0.04014000"],["79983.51000000","0.03772000"],["79983.98000000","0.31651000"],["79984.16000000","0.00020000"],["79984.66000000","0.33515000"],["79986.00000000","0.02407000"],["79986.29000000","0.00000000"],["79987.95000000","1.04939000"],["79987.96000000","0.01756000"],["79988.08000000","0.00000000"],["79988.23000000","0.00000000"],["79988.24000000","0.93850000"],["79991.69000000","0.00069000"],["79991.94000000","0.00000000"],["79991.97000000","1.87060000"],["79992.27000000","0.09860000"],["79993.99000000","0.00400000"],["80077.69000000","0.00399000"],["80124.02000000","0.00020000"],["80125.69000000","0.00000000"]]}}}
{"rx_ns": 10705352911900, "frame": {"stream":"btcusdt@depth20@100ms","data":{"lastUpdateId":99116125909,"bids":[["79980.15000000","2.05033000"],["79980.14000000","0.00070000"],["79980.10000000","0.00007000"],["79979.99000000","0.00020000"],["79979.78000000","0.00014000"],["79979.77000000","0.25599000"],["79979.76000000","0.06678000"],["79979.03000000","0.00921000"],["79978.93000000","0.00007000"],["79978.73000000","0.00007000"],["79978.42000000","0.00007000"],["79978.29000000","0.00007000"],["79978.28000000","0.00007000"],["79977.99000000","0.00007000"],["79977.75000000","0.01528000"],["79977.49000000","0.00014000"],["79977.48000000","0.31282000"],["79977.42000000","0.00007000"],["79977.20000000","0.00014000"],["79977.19000000","0.04732000"]],"asks":[["79980.16000000","1.90391000"],["79980.17000000","0.00083000"],["79980.18000000","0.00013000"],["79980.32000000","0.00014000"],["79980.33000000","0.00995000"],["79980.61000000","0.00014000"],["79980.62000000","0.03021000"],["79980.72000000","0.00007000"],["79980.73000000","0.03803000"],["79980.97000000","0.00007000"],["79981.01000000","0.00007000"],["79981.04000000","0.00014000"],["79981.05000000","0.32793000"],["79981.06000000","0.00014000"],["79981.29000000","0.00014000"],["79981.61000000","0.01653000"],["79981.81000000","0.00014000"],["79981.82000000","0.04014000"],["79981.95000000","0.00007000"],["79982.63000000","0.04032000"]]}}}
{"rx_ns": 10705353010700, "frame": {"stream":"btcusdt@depth@100ms","data":{"e":"depthUpdate","E":1787647700514,"s":"BTCUSDT","U":99116125856,"u":99116125909,"b":[["79980.15000000","2.05033000"],["79980.14000000","0.00070000"],["79976.47000000","0.01821000"],["79976.34000000","0.42229000"],["79976.29000000","0.00007000"],["79976.00000000","0.02414000"],["79975.47000000","0.00000000"],["79971.49000000","0.00400000"],["79966.97000000","0.00000000"],["79946.55000000","0.26124000"],["79928.45000000","0.00000000"],["79842.32000000","0.04528000"],["71982.14000000","0.00208000"],["63984.12000000","0.00031000"]],"a":[["79980.16000000","1.90391000"],["79980.17000000","0.00083000"],["79980.62000000","0.03021000"],["79980.72000000","0.00007000"],["79980.73000000","0.03803000"],["79981.82000000","0.04014000"],["79981.95000000","0.00007000"],["79982.08000000","0.00000000"],["79982.09000000","0.00000000"],["79982.62000000","0.00000000"],["79990.64000000","0.00400000"],["79993.99000000","0.00000000"],["80037.42000000","0.00400000"],["80038.35000000","0.00000000"]]}}}
{"rx_ns": 10705453117700, "frame": {"stream":"btcusdt@depth20@100ms","data":{"lastUpdateId":99116125954,"bids":[["79980.15000000","2.05046000"],["79980.14000000","0.00083000"],["79980.13000000","0.00013000"],["79980.10000000","0.00007000"],["79979.99000000","0.00020000"],["79979.78000000","0.00014000"],["79979.77000000","0.25599000"],["79979.76000000","0.06678000"],["79979.03000000","0.00921000"],["79978.93000000","0.00007000"],["79978.73000000","0.00007000"],["79978.42000000","0.00007000"],["79978.29000000","0.00007000"],["79978.28000000","0.00007000"],["79977.99000000","0.00007000"],["79977.75000000","0.01528000"],["79977.49000000","0.00014000"],["79977.48000000","0.31282000"],["79977.42000000","0.00007000"],["79977.20000000","0.00014000"]],"asks":[["79980.16000000","1.90391000"],["79980.17000000","0.00083000"],["79980.18000000","0.00013000"],["79980.32000000","0.00014000"],["79980.33000000","0.00995000"],["79980.61000000","0.00014000"],["79980.62000000","0.03021000"],["79980.72000000","0.00014000"],["79980.73000000","0.03817000"],["79980.97000000","0.00007000"],["79981.01000000","0.00007000"],["79981.04000000","0.00014000"],["79981.05000000","0.32793000"],["79981.06000000","0.00014000"],["79981.29000000","0.00014000"],["79981.61000000","0.01653000"],["79981.81000000","0.00014000"],["79981.82000000","0.04014000"],["79981.95000000","0.00007000"],["79982.63000000","0.04032000"]]}}}
{"rx_ns": 10705453228100, "frame": {"stream":"btcusdt@depth@100ms","data":{"e":"depthUpdate","E":1787647700614,"s":"BTCUSDT","U":99116125910,"u":99116125954,"b":[["79980.15000000","2.05046000"],["79980.14000000","0.00083000"],["79980.13000000","0.00013000"],["79971.84000000","0.02043000"],["79971.49000000","0.00800000"],["79966.97000000","0.00000000"],["79957.52000000","0.00407000"],["79770.98000000","0.00000000"],["79766.63000000","0.00770000"],["71982.14000000","0.00208000"],["63984.12000000","0.00000000"]],"a":[["79980.16000000","1.90391000"],["79980.17000000","0.00083000"],["79980.62000000","0.03021000"],["79980.72000000","0.00014000"],["79980.73000000","0.03817000"],["79982.89000000","0.01949000"],["79986.24000000","0.00400000"],["79991.39000000","0.00400000"],["80000.00000000","0.12123000"],["80241.97000000","0.00000000"],["80319.20000000","0.00000000"],["80396.43000000","0.00000000"]]}}}
{"rx_ns": 10705559978600, "frame": {"stream":"btcusdt@depth20@100ms","data":{"lastUpdateId":99116125968,"bids":[["79980.15000000","2.05046000"],["79980.14000000","0.00083000"],["79980.13000000","0.00013000"],["79980.10000000","0.00007000"],["79979.99000000","0.00020000"],["79979.78000000","0.00014000"],["79979.77000000","0.25599000"],["79979.76000000","0.06678000"],["79979.03000000","0.00921000"],["79978.93000000","0.00007000"],["79978.73000000","0.00007000"],["79978.42000000","0.00007000"],["79978.29000000","0.00007000"],["79978.28000000","0.00007000"],["79977.99000000","0.00007000"],["79977.75000000","0.01528000"],["79977.49000000","0.00014000"],["79977.48000000","0.31282000"],["79977.42000000","0.00007000"],["79977.20000000","0.00014000"]],"asks":[["79980.16000000","1.90391000"],["79980.17000000","0.00083000"],["79980.18000000","0.00013000"],["79980.32000000","0.00014000"],["79980.33000000","0.00995000"],["79980.61000000","0.00014000"],["79980.62000000","0.03021000"],["79980.72000000","0.00014000"],["79980.73000000","0.03817000"],["79980.97000000","0.00007000"],["79981.01000000","0.00007000"],["79981.04000000","0.00014000"],["79981.05000000","0.32793000"],["79981.06000000","0.00014000"],["79981.29000000","0.00014000"],["79981.61000000","0.01653000"],["79981.81000000","0.00014000"],["79981.82000000","0.04014000"],["79981.95000000","0.00007000"],["79982.63000000","0.04032000"]]}}}
{"rx_ns": 10705560100900, "frame": {"stream":"btcusdt@depth@100ms","data":{"e":"depthUpdate","E":1787647700714,"s":"BTCUSDT","U":99116125955,"u":99116125968,"b":[["79971.49000000","0.00000000"],["79966.97000000","0.01200000"],["71982.14000000","0.00208000"],["69571.83000000","0.00041000"],["42091.80000000","0.00036000"]],"a":[["79990.84000000","0.00400000"],["80006.25000000","0.00000000"],["80009.32000000","0.02408000"]]}}}
{"rx_ns": 10705657756800, "frame": {"stream":"btcusdt@depth20@100ms","data":{"lastUpdateId":99116125979,"bids":[["79980.15000000","2.05046000"],["79980.14000000","0.00083000"],["79980.13000000","0.00013000"],["79980.10000000","0.00007000"],["79979.99000000","0.00020000"],["79979.78000000","0.00014000"],["79979.77000000","0.25599000"],["79979.76000000","0.06678000"],["79979.03000000","0.00921000"],["79978.93000000","0.00007000"],["79978.73000000","0.00007000"],["79978.42000000","0.00007000"],["79978.29000000","0.00007000"],["79978.28000000","0.00007000"],["79977.99000000","0.00007000"],["79977.75000000","0.01528000"],["79977.49000000","0.00014000"],["79977.48000000","0.31282000"],["79977.42000000","0.00007000"],["79977.20000000","0.00014000"]],"asks":[["79980.16000000","1.90391000"],["79980.17000000","0.00083000"],["79980.18000000","0.00013000"],["79980.32000000","0.00014000"],["79980.33000000","0.00995000"],["79980.61000000","0.00014000"],["79980.62000000","0.03021000"],["79980.72000000","0.00014000"],["79980.73000000","0.03817000"],["79980.97000000","0.00007000"],["79981.01000000","0.00007000"],["79981.04000000","0.00014000"],["79981.05000000","0.32793000"],["79981.06000000","0.00014000"],["79981.29000000","0.00014000"],["79981.61000000","0.01653000"],["79981.81000000","0.00014000"],["79981.82000000","0.04014000"],["79981.95000000","0.00007000"],["79982.63000000","0.04032000"]]}}}
{"rx_ns": 10705657840400, "frame": {"stream":"btcusdt@depth@100ms","data":{"e":"depthUpdate","E":1787647700814,"s":"BTCUSDT","U":99116125969,"u":99116125979,"b":[["79968.02000000","0.00162000"],["79966.97000000","0.01600000"],["79947.05000000","0.02600000"],["79943.04000000","0.02000000"],["79942.37000000","0.02447000"],["79942.17000000","0.02200000"],["79936.30000000","0.00000000"],["79917.54000000","0.00399000"],["71982.14000000","0.00240000"]],"a":[["79990.64000000","0.00800000"]]}}}
{"rx_ns": 10705752592200, "frame": {"stream":"btcusdt@depth20@100ms","data":{"lastUpdateId":99116125985,"bids":[["79980.15000000","2.05046000"],["79980.14000000","0.00083000"],["79980.13000000","0.00013000"],["79980.10000000","0.00007000"],["79979.99000000","0.00020000"],["79979.78000000","0.00014000"],["79979.77000000","0.25599000"],["79979.76000000","0.06678000"],["79979.03000000","0.00921000"],["79978.93000000","0.00007000"],["79978.73000000","0.00007000"],["79978.42000000","0.00007000"],["79978.29000000","0.00007000"],["79978.28000000","0.00007000"],["79977.99000000","0.00007000"],["79977.75000000","0.01528000"],["79977.49000000","0.00014000"],["79977.48000000","0.31282000"],["79977.42000000","0.00007000"],["79977.20000000","0.00014000"]],"asks":[["79980.16000000","1.90073000"],["79980.17000000","0.00083000"],["79980.18000000","0.00013000"],["79980.32000000","0.00014000"],["79980.33000000","0.00995000"],["79980.61000000","0.00014000"],["79980.62000000","0.03021000"],["79980.72000000","0.00014000"],["79980.73000000","0.03817000"],["79980.97000000","0.00007000"],["79981.01000000","0.00007000"],["79981.04000000","0.00014000"],["79981.05000000","0.32793000"],["79981.06000000","0.00014000"],["79981.29000000","0.00014000"],["79981.61000000","0.01653000"],["79981.81000000","0.00014000"],["79981.82000000","0.04014000"],["79981.95000000","0.00007000"],["79982.63000000","0.04032000"]]}}}
{"rx_ns": 10705752668900, "frame": {"stream":"btcusdt@depth@100ms","data":{"e":"depthUpdate","E":1787647700914,"s":"BTCUSDT","U":99116125980,"u":99116125985,"b":[["79973.73000000","0.00400000"],["79896.21000000","0.02084000"],["71982.14000000","0.00240000"]],"a":[["79980.16000000","1.90073000"],["79988.13000000","0.00400000"]]}}}
{"rx_ns": 10705863112900, "frame": {"stream":"btcusdt@depth20@100ms","data":{"lastUpdateId":99116126000,"bids":[["79980.15000000","2.05046000"],["79980.14000000","0.00083000"],["79980.13000000","0.00013000"],["79980.10000000","0.00007000"],["79979.99000000","0.00020000"],["79979.78000000","0.00014000"],["79979.77000000","0.25599000"],["79979.76000000","0.06678000"],["79979.03000000","0.00921000"],["79978.93000000","0.00007000"],["79978.73000000","0.00007000"],["79978.42000000","0.00007000"],["79978.29000000","0.00007000"],["79978.28000000","0.00007000"],["79977.99000000","0.00007000"],["79977.75000000","0.01528000"],["79977.49000000","0.00014000"],["79977.48000000","0.31282000"],["79977.42000000","0.00007000"],["79977.20000000","0.00014000"]],"asks":[["79980.16000000","1.89733000"],["79980.17000000","0.00083000"],["79980.18000000","0.00013000"],["79980.32000000","0.00014000"],["79980.33000000","0.00995000"],["79980.61000000","0.00014000"],["79980.62000000","0.03021000"],["79980.72000000","0.00014000"],["79980.73000000","0.03817000"],["79980.97000000","0.00007000"],["79981.01000000","0.00007000"],["79981.04000000","0.00014000"],["79981.05000000","0.32793000"],["79981.06000000","0.00014000"],["79981.29000000","0.00014000"],["79981.61000000","0.01653000"],["79981.81000000","0.00014000"],["79981.82000000","0.04014000"],["79981.95000000","0.00007000"],["79982.63000000","0.04032000"]]}}}
{"rx_ns": 10705863198200, "frame": {"stream":"btcusdt@depth@100ms","data":{"e":"depthUpdate","E":1787647701014,"s":"BTCUSDT","U":99116125986,"u":99116126000,"b":[["79976.34000000","0.42458000"],["79906.54000000","0.00000000"],["79896.21000000","0.00000000"],["79770.98000000","0.00770000"],["79766.63000000","0.00000000"],["79765.62000000","0.00399000"],["78780.44000000","0.00030000"],["71982.14000000","0.00256000"],["71982.13000000","0.00000000"],["71982.12000000","0.00008000"],["63984.12000000","0.00031000"]],"a":[["79980.16000000","1.89733000"],["80197.09000000","0.00000000"]]}}}
{"rx_ns": 10705956156200, "frame": {"stream":"btcusdt@depth20@100ms","data":{"lastUpdateId":99116126007,"bids":[["79980.15000000","2.05046000"],["79980.14000000","0.00083000"],["79980.13000000","0.00013000"],["79980.10000000","0.00007000"],["79979.99000000","0.00020000"],["79979.78000000","0.00014000"],["79979.77000000","0.25599000"],["79979.76000000","0.06678000"],["79979.03000000","0.00921000"],["79978.93000000","0.00007000"],["79978.73000000","0.00007000"],["79978.42000000","0.00007000"],["79978.29000000","0.00007000"],["79978.28000000","0.00007000"],["79977.99000000","0.00007000"],["79977.75000000","0.01528000"],["79977.49000000","0.00014000"],["79977.48000000","0.31282000"],["79977.42000000","0.00007000"],["79977.20000000","0.00014000"]],"asks":[["79980.16000000","1.89733000"],["79980.17000000","0.00083000"],["79980.18000000","0.00013000"],["79980.32000000","0.00014000"],["79980.33000000","0.00995000"],["79980.61000000","0.00014000"],["79980.62000000","0.03021000"],["79980.72000000","0.00014000"],["79980.73000000","0.03817000"],["79980.97000000","0.00007000"],["79981.01000000","0.00007000"],["79981.04000000","0.00014000"],["79981.05000000","0.32793000"],["79981.06000000","0.00014000"],["79981.29000000","0.00014000"],["79981.61000000","0.01653000"],["79981.81000000","0.00014000"],["79981.82000000","0.04014000"],["79981.95000000","0.00007000"],["79982.13000000","0.00456000"]]}}}
{"rx_ns": 10705956248500, "frame": {"stream":"btcusdt@depth@100ms","data":{"e":"depthUpdate","E":1787647701114,"s":"BTCUSDT","U":99116126001,"u":99116126007,"b":[["79945.00000000","1.74939000"],["79901.63000000","0.00000000"],["79896.21000000","0.02084000"]],"a":[["79982.13000000","0.00456000"],["80000.00000000","0.82123000"],["80104.54000000","0.01958000"],["80241.97000000","2.50000000"]]}}}
{"rx_ns": 10706056756000, "frame": {"stream":"btcusdt@depth20@100ms","data":{"lastUpdateId":99116126024,"bids":[["79980.15000000","2.05046000"],["79980.14000000","0.00083000"],["79980.13000000","0.00013000"],["79980.10000000","0.00007000"],["79979.99000000","0.00020000"],["79979.78000000","0.00014000"],["79979.77000000","0.25599000"],["79979.76000000","0.06678000"],["79979.03000000","0.00921000"],["79978.93000000","0.00007000"],["79978.73000000","0.00007000"],["79978.42000000","0.00007000"],["79978.29000000","0.00007000"],["79978.28000000","0.00007000"],["79977.99000000","0.00007000"],["79977.75000000","0.01528000"],["79977.49000000","0.00014000"],["79977.48000000","0.31282000"],["79977.42000000","0.00007000"],["79977.20000000","0.00014000"]],"asks":[["79980.16000000","1.89736000"],["79980.17000000","0.00090000"],["79980.18000000","0.00013000"],["79980.32000000","0.00014000"],["79980.33000000","0.00995000"],["79980.61000000","0.00014000"],["79980.62000000","0.03021000"],["79980.72000000","0.00014000"],["79980.73000000","0.03817000"],["79980.97000000","0.00007000"],["79981.01000000","0.00007000"],["79981.04000000","0.00014000"],["79981.05000000","0.32793000"],["79981.06000000","0.00014000"],["79981.29000000","0.00014000"],["79981.61000000","0.01653000"],["79981.81000000","0.00014000"],["79981.82000000","0.04014000"],["79981.95000000","0.00007000"],["79982.13000000","0.00456000"]]}}}
{"rx_ns": 10706056834300, "frame": {"stream":"btcusdt@depth@100ms","data":{"e":"depthUpdate","E":1787647701214,"s":"BTCUSDT","U":99116126008,"u":99116126024,"b":[["79902.53000000","0.00000000"],["79896.21000000","0.00000000"],["79889.05000000","0.62498000"],["79886.41000000","0.00000000"],["79885.55000000","0.00399000"],["71982.14000000","0.00272000"],["63984.12000000","0.00000000"]],"a":[["79980.16000000","1.89736000"],["79980.17000000","0.00090000"],["79983.51000000","0.03779000"],["79983.73000000","0.00587000"],["79987.73000000","0.00570000"],["79996.51000000","0.14500000"]]}}}
{"rx_ns": 10706152532100, "frame": {"stream":"btcusdt@depth20@100ms","data":{"lastUpdateId":99116126108,"bids":[["79980.15000000","1.84448000"],["79980.14000000","0.00076000"],["79980.13000000","0.00013000"],["79980.10000000","0.00007000"],["79979.99000000","0.00020000"],["79979.77000000","0.00014000"],["79979.76000000","0.00014000"],["79979.03000000","0.00921000"],["79978.93000000","0.00007000"],["79978.73000000","0.00007000"],["79978.42000000","0.00007000"],["79978.29000000","0.00007000"],["79978.28000000","0.00007000"],["79977.99000000","0.00007000"],["79977.76000000","0.00014000"],["79977.75000000","0.01528000"],["79977.50000000","0.00014000"],["79977.49000000","0.24785000"],["79977.48000000","0.31282000"],["79977.42000000","0.00007000"]],"asks":[["79980.16000000","1.89694000"],["79980.17000000","0.00097000"],["79980.18000000","0.00013000"],["79980.32000000","0.00014000"],["79980.33000000","0.00995000"],["79980.61000000","0.00014000"],["79980.62000000","0.03021000"],["79980.72000000","0.00014000"],["79980.73000000","0.03824000"],["79980.97000000","0.00007000"],["79981.01000000","0.00007000"],["79981.03000000","0.00014000"],["79981.04000000","0.47979000"],["79981.05000000","0.32793000"],["79981.06000000","0.00014000"],["79981.29000000","0.00014000"],["79981.61000000","0.01653000"],["79981.82000000","0.04014000"],["79981.95000000","0.00007000"],["79982.13000000","0.00456000"]]}}}
{"rx_ns": 10706152613400, "frame": {"stream":"btcusdt@depth@100ms","data":{"e":"depthUpdate","E":1787647701314,"s":"BTCUSDT","U":99116126025,"u":99116126108,"b":[["79980.15000000","1.84448000"],["79980.14000000","0.00076000"],["79979.78000000","0.00000000"],["79979.77000000","0.00014000"],["79979.76000000","0.00014000"],["79977.76000000","0.00014000"],["79977.50000000","0.00014000"],["79977.49000000","0.24785000"],["79976.35000000","0.00014000"],["79975.47000000","0.00000000"],["79973.73000000","0.00000000"],["79972.05000000","0.00000000"],["79971.84000000","0.01643000"],["79970.98000000","0.00400000"],["79970.17000000","0.00400000"],["79970.01000000","0.00000000"],["79969.96000000","0.00444000"],["79969.34000000","0.00000000"],["79964.91000000","0.00007000"],["79963.01000000","0.00000000"],["79962.45000000","0.00000000"],["79959.45000000","0.00625000"],["79889.05000000","0.00000000"],["79886.41000000","0.62498000"],["79886.38000000","3.75644000"],["71982.14000000","0.00272000"],["63984.00000000","0.00014000"]],"a":[["79980.16000000","1.89694000"],["79980.17000000","0.00097000"],["79980.73000000","0.03824000"],["79981.03000000","0.00014000"],["79981.04000000","0.47979000"],["79981.81000000","0.00000000"],["79982.56000000","0.00026000"],["79983.51000000","0.03772000"],["79983.98000000","0.00000000"],["79984.66000000","0.33522000"],["79985.62000000","0.03224000"],["79996.16000000","0.95246000"],["79996.91000000","0.00007000"],["79999.99000000","0.62537000"],["80000.58000000","0.62517000"],["80007.26000000","0.00000000"],["80022.31000000","0.00000000"],["80104.54000000","0.00000000"],["80172.43000000","0.01958000"],["81179.87000000","0.00030000"]]}}}
{"rx_ns": 10706256927200, "frame": {"stream":"btcusdt@depth20@100ms","data":{"lastUpdateId":99116126173,"bids":[["79980.15000000","2.03194000"],["79980.14000000","0.00076000"],["79980.13000000","0.00013000"],["79980.10000000","0.00007000"],["79979.99000000","0.00020000"],["79979.03000000","0.00921000"],["79978.93000000","0.00007000"],["79978.73000000","0.00007000"],["79978.42000000","0.00007000"],["79978.29000000","0.00007000"],["79978.28000000","0.00007000"],["79977.99000000","0.00007000"],["79977.76000000","0.00014000"],["79977.75000000","0.01528000"],["79977.50000000","0.00014000"],["79977.49000000","0.24799000"],["79977.48000000","0.31282000"],["79977.42000000","0.00007000"],["79977.20000000","0.00014000"],["79977.19000000","0.04732000"]],"asks":[["79980.16000000","1.89697000"],["79980.17000000","0.00097000"],["79980.18000000","0.00013000"],["79980.32000000","0.00014000"],["79980.33000000","0.00995000"],["79980.61000000","0.00014000"],["79980.62000000","0.03021000"],["79980.72000000","0.00014000"],["79980.73000000","0.03824000"],["79980.97000000","0.00007000"],["79981.01000000","0.00007000"],["79981.03000000","0.00014000"],["79981.04000000","0.47993000"],["79981.05000000","0.32793000"],["79981.06000000","0.00014000"],["79981.29000000","0.00014000"],["79981.61000000","0.01653000"],["79981.82000000","0.04014000"],["79981.95000000","0.00007000"],["79982.13000000","0.00456000"]]}}}
{"rx_ns": 10706257073700, "frame": {"stream":"btcusdt@depth@100ms","data":{"e":"depthUpdate","E":1787647701414,"s":"BTCUSDT","U":99116126109,"u":99116126173,"b":[["79980.15000000","2.03194000"],["79979.77000000","0.00000000"],["79979.76000000","0.00000000"],["79977.75000000","0.01528000"],["79977.49000000","0.24799000"],["79976.00000000","0.02428000"],["79971.49000000","0.01600000"],["79966.97000000","0.00000000"],["79946.71000000","1.77427000"],["79945.00000000","1.04939000"],["79886.39000000","1.74711000"],["79837.58000000","0.00399000"],["79821.30000000","0.00202000"],["71982.14000000","0.00288000"],["71982.00000000","0.00000000"],["63984.12000000","0.00000000"]],"a":[["79980.16000000","1.89697000"],["79980.73000000","0.03824000"],["79981.04000000","0.47993000"],["79982.56000000","0.00000000"],["79982.79000000","0.05307000"],["80034.24000000","0.00400000"],["80037.42000000","0.00000000"],["80077.64000000","0.00555000"],["80087.84000000","0.00000000"],["80111.96000000","0.00000000"],["80133.34000000","0.00202000"]]}}}
{"rx_ns": 10706356398900, "frame": {"stream":"btcusdt@depth20@100ms","data":{"lastUpdateId":99116126179,"bids":[["79980.15000000","2.03194000"],["79980.14000000","0.00076000"],["79980.13000000","0.00013000"],["79980.10000000","0.00007000"],["79979.99000000","0.00020000"],["79979.03000000","0.00921000"],["79978.93000000","0.00007000"],["79978.73000000","0.00007000"],["79978.42000000","0.00007000"],["79978.29000000","0.00007000"],["79978.28000000","0.00007000"],["79977.99000000","0.00007000"],["79977.76000000","0.00014000"],["79977.75000000","0.01528000"],["79977.50000000","0.00014000"],["79977.49000000","0.24799000"],["79977.48000000","0.31282000"],["79977.42000000","0.00007000"],["79977.20000000","0.00014000"],["79977.19000000","0.04732000"]],"asks":[["79980.16000000","1.89697000"],["79980.17000000","0.00097000"],["79980.18000000","0.00013000"],["79980.32000000","0.00014000"],["79980.33000000","0.00995000"],["79980.61000000","0.00014000"],["79980.62000000","0.03021000"],["79980.72000000","0.00014000"],["79980.73000000","0.03824000"],["79980.97000000","0.00007000"],["79981.01000000","0.00007000"],["79981.03000000","0.00014000"],["79981.04000000","0.47993000"],["79981.05000000","0.32793000"],["79981.06000000","0.00014000"],["79981.29000000","0.00014000"],["79981.61000000","0.01653000"],["79981.82000000","0.04014000"],["79981.95000000","0.00007000"],["79982.13000000","0.00456000"]]}}}
{"rx_ns": 10706356492700, "frame": {"stream":"btcusdt@depth@100ms","data":{"e":"depthUpdate","E":1787647701514,"s":"BTCUSDT","U":99116126174,"u":99116126179,"b":[["79896.21000000","0.02084000"],["71982.14000000","0.00288000"],["63984.12000000","0.00031000"]],"a":[["80104.54000000","0.01958000"],["80172.43000000","0.00000000"]]}}}
{"rx_ns": 10706452765200, "frame": {"stream":"btcusdt@depth20@100ms","data":{"lastUpdateId":99116126196,"bids":[["79980.15000000","2.03201000"],["79980.14000000","0.00083000"],["79980.13000000","0.00013000"],["79980.10000000","0.00007000"],["79979.99000000","0.00020000"],["79979.03000000","0.00921000"],["79978.93000000","0.00007000"],["79978.73000000","0.00007000"],["79978.42000000","0.00007000"],["79978.29000000","0.00007000"],["79978.28000000","0.00007000"],["79977.99000000","0.00007000"],["79977.76000000","0.00014000"],["79977.75000000","0.01535000"],["79977.70000000","0.00014000"],["79977.69000000","0.12053000"],["79977.50000000","0.00014000"],["79977.49000000","0.24799000"],["79977.48000000","0.31282000"],["79977.42000000","0.00007000"]],"asks":[["79980.16000000","1.89697000"],["79980.17000000","0.00097000"],["79980.18000000","0.00013000"],["79980.32000000","0.00014000"],["79980.33000000","0.00995000"],["79980.61000000","0.00014000"],["79980.62000000","0.03021000"],["79980.72000000","0.00014000"],["79980.73000000","0.03824000"],["79980.97000000","0.00007000"],["79981.01000000","0.00007000"],["79981.03000000","0.00014000"],["79981.04000000","0.47993000"],["79981.05000000","0.32793000"],["79981.06000000","0.00014000"],["79981.29000000","0.00014000"],["79981.61000000","0.01653000"],["79981.82000000","0.04014000"],["79981.95000000","0.00007000"],["79982.13000000","0.00456000"]]}}}
{"rx_ns": 10706452873600, "frame": {"stream":"btcusdt@depth@100ms","data":{"e":"depthUpdate","E":1787647701614,"s":"BTCUSDT","U":99116126180,"u":99116126196,"b":[["79980.15000000","2.03201000"],["79980.14000000","0.00083000"],["79977.75000000","0.01535000"],["79977.70000000","0.00014000"],["79977.69000000","0.12053000"],["79976.35000000","0.00000000"],["79896.21000000","0.00000000"],["71982.14000000","0.00304000"],["63984.12000000","0.00000000"],["42091.80000000","0.00000000"]],"a":[["80125.56000000","0.00399000"],["80152.01000000","0.00000000"],["80319.20000000","2.50000000"]]}}}
{"rx_ns": 10706554529800, "frame": {"stream":"btcusdt@depth20@100ms","data":{"lastUpdateId":99116126223,"bids":[["79980.15000000","1.84420000"],["79980.14000000","0.00083000"],["79980.13000000","0.00013000"],["79980.10000000","0.00007000"],["79979.99000000","0.00020000"],["79979.03000000","0.00921000"],["79978.93000000","0.00007000"],["79978.73000000","0.00007000"],["79978.42000000","0.00007000"],["79978.29000000","0.00007000"],["79978.28000000","0.00007000"],["79977.99000000","0.00007000"],["79977.76000000","0.00014000"],["79977.75000000","0.01535000"],["79977.70000000","0.00014000"],["79977.69000000","0.12067000"],["79977.50000000","0.00014000"],["79977.49000000","0.24799000"],["79977.48000000","0.31282000"],["79977.42000000","0.00007000"]],"asks":[["79980.16000000","1.89697000"],["79980.17000000","0.00097000"],["79980.18000000","0.00013000"],["79980.32000000","0.00014000"],["79980.33000000","0.00995000"],["79980.61000000","0.00014000"],["79980.62000000","0.03021000"],["79980.72000000","0.00014000"],["79980.73000000","0.03824000"],["79980.97000000","0.00007000"],["79981.01000000","0.00007000"],["79981.03000000","0.00014000"],["79981.04000000","0.47993000"],["79981.05000000","0.32793000"],["79981.06000000","0.00014000"],["79981.29000000","0.00014000"],["79981.61000000","0.01653000"],["79981.82000000","0.04014000"],["79981.95000000","0.00007000"],["79982.13000000","0.00456000"]]}}}
{"rx_ns": 10706554641600, "frame": {"stream":"btcusdt@depth@100ms","data":{"e":"depthUpdate","E":1787647701714,"s":"BTCUSDT","U":99116126197,"u":99116126223,"b":[["79980.15000000","1.84420000"],["79977.75000000","0.01535000"],["79977.69000000","0.12067000"],["79976.00000000","0.02414000"],["79971.49000000","0.00000000"],["79966.97000000","0.01600000"],["79896.21000000","0.02084000"],["71982.12000000","0.00000000"]],"a":[["79996.61000000","0.00166000"],["80021.14000000","0.00000000"],["80125.56000000","0.00000000"],["80368.08000000","0.00625000"]]}}}
{"rx_ns": 10706652472000, "frame": {"stream":"btcusdt@depth20@100ms","data":{"lastUpdateId":99116126242,"bids":[["79980.15000000","1.84335000"],["79980.14000000","0.00083000"],["79980.13000000","0.00013000"],["79980.10000000","0.00007000"],["79979.99000000","0.00020000"],["79979.03000000","0.00921000"],["79978.93000000","0.00007000"],["79978.73000000","0.00007000"],["79978.42000000","0.00007000"],["79978.29000000","0.00007000"],["79978.28000000","0.00007000"],["79977.99000000","0.00007000"],["79977.76000000","0.00014000"],["79977.75000000","0.01535000"],["79977.70000000","0.00014000"],["79977.69000000","0.12067000"],["79977.50000000","0.00014000"],["79977.49000000","0.24799000"],["79977.48000000","0.31282000"],["79977.42000000","0.00007000"]],"asks":[["79980.16000000","1.89697000"],["79980.17000000","0.00097000"],["79980.18000000","0.00013000"],["79980.32000000","0.00014000"],["79980.33000000","0.00995000"],["79980.61000000","0.00014000"],["79980.62000000","0.03021000"],["79980.72000000","0.00014000"],["79980.73000000","0.03824000"],["79980.97000000","0.00007000"],["79981.01000000","0.00007000"],["79981.03000000","0.00014000"],["79981.04000000","0.47993000"],["79981.05000000","0.32793000"],["79981.06000000","0.00014000"],["79981.29000000","0.00014000"],["79981.61000000","0.01653000"],["79981.82000000","0.04014000"],["79981.95000000","0.00007000"],["79982.13000000","0.00456000"]]}}}
{"rx_ns": 10706652635300, "frame": {"stream":"btcusdt@depth@100ms","data":{"e":"depthUpdate","E":1787647701814,"s":"BTCUSDT","U":99116126224,"u":99116126242,"b":[["79980.15000000","1.84335000"],["79971.49000000","0.01600000"],["79966.97000000","0.00000000"],["79896.21000000","0.00000000"],["71982.14000000","0.00320000"]],"a":[["80068.55000000","3.13843000"],["80071.19000000","0.00000000"],["80104.54000000","0.00000000"],["80125.55000000","0.00399000"],["80153.78000000","0.01974000"],["80368.08000000","0.01250000"]]}}}
{"rx_ns": 10706756678900, "frame": {"stream":"btcusdt@depth20@100ms","data":{"lastUpdateId":99116126247,"bids":[["79980.15000000","1.84335000"],["79980.14000000","0.00083000"],["79980.13000000","0.00013000"],["79980.10000000","0.00007000"],["79979.99000000","0.00020000"],["79979.03000000","0.00921000"],["79978.93000000","0.00007000"],["79978.73000000","0.00007000"],["79978.42000000","0.00007000"],["79978.29000000","0.00007000"],["79978.28000000","0.00007000"],["79977.99000000","0.00007000"],["79977.76000000","0.00014000"],["79977.75000000","0.01535000"],["79977.70000000","0.00014000"],["79977.69000000","0.12067000"],["79977.50000000","0.00014000"],["79977.49000000","0.24799000"],["79977.48000000","0.31282000"],["79977.42000000","0.00007000"]],"asks":[["79980.16000000","1.89697000"],["79980.17000000","0.00097000"],["79980.18000000","0.00013000"],["79980.32000000","0.00014000"],["79980.33000000","0.00995000"],["79980.61000000","0.00014000"],["79980.62000000","0.03021000"],["79980.72000000","0.00014000"],["79980.73000000","0.03824000"],["79980.97000000","0.00007000"],["79981.01000000","0.00007000"],["79981.03000000","0.00014000"],["79981.04000000","0.47993000"],["79981.05000000","0.32793000"],["79981.06000000","0.00014000"],["79981.29000000","0.00014000"],["79981.61000000","0.01653000"],["79981.82000000","0.04014000"],["79981.95000000","0.00007000"],["79982.13000000","0.00456000"]]}}}
{"rx_ns": 10706756788300, "frame": {"stream":"btcusdt@depth@100ms","data":{"e":"depthUpdate","E":1787647701914,"s":"BTCUSDT","U":99116126243,"u":99116126247,"b":[["78512.97000000","0.00600000"],["71982.14000000","0.00320000"]],"a":[["80153.78000000","0.00016000"],["80178.95000000","0.01958000"]]}}}
{"rx_ns": 10706852507600, "frame": {"stream":"btcusdt@depth20@100ms","data":{"lastUpdateId":99116126268,"bids":[["79980.15000000","1.15097000"],["79980.14000000","0.00083000"],["79980.13000000","0.00013000"],["79980.10000000","0.00007000"],["79979.99000000","0.00020000"],["79979.03000000","0.00921000"],["79978.93000000","0.00007000"],["79978.73000000","0.00007000"],["79978.42000000","0.00007000"],["79978.29000000","0.00007000"],["79978.28000000","0.00007000"],["79977.99000000","0.00007000"],["79977.76000000","0.00014000"],["79977.75000000","0.01535000"],["79977.69000000","0.00014000"],["79977.50000000","0.00014000"],["79977.49000000","0.24799000"],["79977.48000000","0.31282000"],["79977.42000000","0.00007000"],["79977.20000000","0.00014000"]],"asks":[["79980.16000000","1.89720000"],["79980.17000000","0.00097000"],["79980.18000000","0.00013000"],["79980.32000000","0.00014000"],["79980.33000000","0.00995000"],["79980.61000000","0.00014000"],["79980.62000000","0.03021000"],["79980.72000000","0.00014000"],["79980.73000000","0.03824000"],["79980.97000000","0.00007000"],["79981.01000000","0.00007000"],["79981.03000000","0.00014000"],["79981.04000000","0.47993000"],["79981.05000000","0.32793000"],["79981.06000000","0.00014000"],["79981.29000000","0.00014000"],["79981.61000000","0.01653000"],["79981.82000000","0.04014000"],["79981.95000000","0.00007000"],["79982.13000000","0.00456000"]]}}}
{"rx_ns": 10706852609200, "frame": {"stream":"btcusdt@depth@100ms","data":{"e":"depthUpdate","E":1787647702014,"s":"BTCUSDT","U":99116126248,"u":99116126268,"b":[["79980.15000000","1.15097000"],["79977.70000000","0.00000000"],["79977.69000000","0.00014000"],["79976.35000000","0.00007000"],["79972.15000000","0.20250000"],["79969.96000000","0.00000000"],["79968.02000000","0.00000000"],["79966.97000000","0.00162000"],["79934.85000000","0.00007000"],["78780.44000000","0.00000000"],["71982.14000000","0.00320000"],["63984.12000000","0.00031000"]],"a":[["79980.16000000","1.89720000"],["79984.00000000","1.04253000"],["79992.27000000","0.29375000"],["79995.00000000","0.70000000"]]}}}
{"rx_ns": 10706954167400, "frame": {"stream":"btcusdt@depth20@100ms","data":{"lastUpdateId":99116126303,"bids":[["79980.15000000","1.35306000"],["79980.14000000","0.00076000"],["79980.13000000","0.00013000"],["79980.10000000","0.00007000"],["79979.99000000","0.00020000"],["79979.03000000","0.00921000"],["79978.93000000","0.00007000"],["79978.73000000","0.00007000"],["79978.42000000","0.00007000"],["79978.29000000","0.00007000"],["79978.28000000","0.00007000"],["79977.99000000","0.00007000"],["79977.76000000","0.00014000"],["79977.75000000","0.01528000"],["79977.50000000","0.00014000"],["79977.49000000","0.24799000"],["79977.48000000","0.31282000"],["79977.42000000","0.00007000"],["79977.20000000","0.00014000"],["79977.19000000","0.04732000"]],"asks":[["79980.16000000","1.96734000"],["79980.17000000","0.00097000"],["79980.18000000","0.00013000"],["79980.32000000","0.00014000"],["79980.33000000","0.00995000"],["79980.61000000","0.00014000"],["79980.62000000","0.03021000"],["79980.72000000","0.00014000"],["79980.73000000","0.03824000"],["79980.97000000","0.00007000"],["79981.01000000","0.00007000"],["79981.03000000","0.00014000"],["79981.04000000","0.47993000"],["79981.05000000","0.32793000"],["79981.06000000","0.00014000"],["79981.29000000","0.00014000"],["79981.61000000","0.01653000"],["79981.82000000","0.04014000"],["79981.95000000","0.00007000"],["79982.13000000","0.00456000"]]}}}
{"rx_ns": 10706954246700, "frame": {"stream":"btcusdt@depth@100ms","data":{"e":"depthUpdate","E":1787647702114,"s":"BTCUSDT","U":99116126269,"u":99116126303,"b":[["79980.15000000","1.35306000"],["79980.14000000","0.00076000"],["79977.75000000","0.01528000"],["79977.69000000","0.00000000"],["79976.00000000","0.02428000"],["79970.17000000","0.00000000"],["79968.99000000","0.00400000"],["79947.00000000","0.00000000"],["79773.62000000","0.00770000"],["79770.98000000","0.00000000"],["78780.44000000","0.00030000"],["71982.14000000","0.00336000"],["71982.13000000","0.00008000"]],"a":[["79980.16000000","1.96734000"],["79984.54000000","0.00400000"],["79988.13000000","0.00000000"],["80010.58000000","1.20058000"],["80020.01000000","0.84105000"],["80023.64000000","0.00000000"],["80396.43000000","2.50000000"]]}}}
{"rx_ns": 10707052849000, "frame": {"stream":"btcusdt@depth20@100ms","data":{"lastUpdateId":99116126312,"bids":[["79980.15000000","1.35306000"],["79980.14000000","0.00076000"],["79980.13000000","0.00013000"],["79980.10000000","0.00007000"],["79979.99000000","0.00020000"],["79979.03000000","0.00921000"],["79978.93000000","0.00007000"],["79978.73000000","0.00007000"],["79978.42000000","0.00007000"],["79978.29000000","0.00007000"],["79978.28000000","0.00007000"],["79977.99000000","0.00007000"],["79977.76000000","0.00014000"],["79977.75000000","0.01528000"],["79977.50000000","0.00014000"],["79977.49000000","0.24799000"],["79977.48000000","0.31282000"],["79977.42000000","0.00007000"],["79977.20000000","0.00014000"],["79977.19000000","0.04732000"]],"asks":[["79980.16000000","1.96727000"],["79980.17000000","0.00097000"],["79980.18000000","0.00013000"],["79980.32000000","0.00014000"],["79980.33000000","0.00995000"],["79980.61000000","0.00014000"],["79980.62000000","0.03021000"],["79980.72000000","0.00014000"],["79980.73000000","0.03824000"],["79980.97000000","0.00007000"],["79981.01000000","0.00007000"],["79981.03000000","0.00014000"],["79981.04000000","0.47993000"],["79981.05000000","0.32793000"],["79981.06000000","0.00014000"],["79981.29000000","0.00014000"],["79981.61000000","0.01653000"],["79981.82000000","0.04014000"],["79981.95000000","0.00007000"],["79982.13000000","0.00456000"]]}}}
{"rx_ns": 10707052981200, "frame": {"stream":"btcusdt@depth@100ms","data":{"e":"depthUpdate","E":1787647702214,"s":"BTCUSDT","U":99116126304,"u":99116126312,"b":[["79974.96000000","0.11885000"],["79896.11000000","0.02084000"],["79842.32000000","0.00000000"],["71982.14000000","0.00352000"],["63984.12000000","0.00000000"]],"a":[["79980.16000000","1.96727000"],["80081.77000000","0.00000000"]]}}}
{"rx_ns": 10707152578600, "frame": {"stream":"btcusdt@depth20@100ms","data":{"lastUpdateId":99116126331,"bids":[["79980.15000000","1.35306000"],["79980.14000000","0.00076000"],["79980.13000000","0.00013000"],["79980.10000000","0.00007000"],["79979.99000000","0.00020000"],["79979.03000000","0.00921000"],["79978.93000000","0.00007000"],["79978.73000000","0.00007000"],["79978.42000000","0.00007000"],["79978.29000000","0.00007000"],["79978.28000000","0.00007000"],["79977.99000000","0.00007000"],["79977.76000000","0.00014000"],["79977.75000000","0.01528000"],["79977.49000000","0.00028000"],["79977.48000000","0.31282000"],["79977.42000000","0.00007000"],["79977.20000000","0.00014000"],["79977.19000000","0.04732000"],["79976.90000000","0.00007000"]],"asks":[["79980.16000000","1.96727000"],["79980.17000000","0.00097000"],["79980.18000000","0.00013000"],["79980.32000000","0.00014000"],["79980.33000000","0.00995000"],["79980.61000000","0.00014000"],["79980.62000000","0.03021000"],["79980.72000000","0.00014000"],["79980.73000000","0.03824000"],["79980.97000000","0.00007000"],["79981.01000000","0.00007000"],["79981.03000000","0.00014000"],["79981.04000000","0.47993000"],["79981.05000000","0.32793000"],["79981.06000000","0.00014000"],["79981.29000000","0.00014000"],["79981.61000000","0.01653000"],["79981.82000000","0.04014000"],["79981.95000000","0.00007000"],["79982.13000000","0.00456000"]]}}}
{"rx_ns": 10707152663700, "frame": {"stream":"btcusdt@depth@100ms","data":{"e":"depthUpdate","E":1787647702314,"s":"BTCUSDT","U":99116126313,"u":99116126331,"b":[["79977.50000000","0.00000000"],["79977.49000000","0.00028000"],["79976.35000000","0.00014000"],["79975.47000000","0.00007000"],["79975.19000000","0.01814000"],["79964.91000000","0.00000000"],["79944.02000000","0.00012000"],["79896.11000000","0.00000000"],["79841.37000000","0.04528000"],["71982.14000000","0.00352000"],["63984.00000000","0.00014000"]],"a":[["79996.91000000","0.00000000"],["80021.30000000","0.00012000"],["80081.27000000","0.02804000"],["81179.87000000","0.00030000"],["101000.00000000","8.48830000"]]}}}
{"rx_ns": 10707257116700, "frame": {"stream":"btcusdt@depth20@100ms","data":{"lastUpdateId":99116126364,"bids":[["79980.15000000","1.59299000"],["79980.14000000","0.00076000"],["79980.13000000","0.00013000"],["79980.10000000","0.00007000"],["79979.99000000","0.00020000"],["79979.03000000","0.00921000"],["79978.93000000","0.00007000"],["79978.73000000","0.00007000"],["79978.42000000","0.00007000"],["79978.29000000","0.00007000"],["79978.28000000","0.00007000"],["79977.99000000","0.00007000"],["79977.76000000","0.00014000"],["79977.75000000","0.01528000"],["79977.49000000","0.00014000"],["79977.48000000","0.31282000"],["79977.42000000","0.00007000"],["79977.20000000","0.00014000"],["79977.19000000","0.04732000"],["79976.90000000","0.00007000"]],"asks":[["79980.16000000","1.96706000"],["79980.17000000","0.00083000"],["79980.18000000","0.00013000"],["79980.32000000","0.00014000"],["79980.33000000","0.00995000"],["79980.61000000","0.00014000"],["79980.62000000","0.03021000"],["79980.72000000","0.00014000"],["79980.73000000","0.03824000"],["79980.97000000","0.00007000"],["79981.01000000","0.00007000"],["79981.03000000","0.00014000"],["79981.04000000","0.47993000"],["79981.05000000","0.32793000"],["79981.06000000","0.00014000"],["79981.29000000","0.00014000"],["79981.61000000","0.01653000"],["79981.82000000","0.04014000"],["79981.95000000","0.00007000"],["79982.13000000","0.00456000"]]}}}
{"rx_ns": 10707257209200, "frame": {"stream":"btcusdt@depth@100ms","data":{"e":"depthUpdate","E":1787647702414,"s":"BTCUSDT","U":99116126332,"u":99116126364,"b":[["79980.15000000","1.59299000"],["79980.14000000","0.00076000"],["79977.75000000","0.01528000"],["79977.49000000","0.00014000"],["79975.73000000","0.00893000"],["79964.91000000","0.00007000"],["79959.81000000","0.02200000"],["79955.34000000","1.18334000"],["79939.80000000","0.90890000"],["71982.14000000","0.00368000"],["63984.12000000","0.00000000"]],"a":[["79980.16000000","1.96706000"],["79980.17000000","0.00083000"],["79996.91000000","0.00007000"],["80031.83000000","0.00400000"],["80034.24000000","0.00000000"],["80108.12000000","0.00160000"]]}}}
{"rx_ns": 10707352676000, "frame": {"stream":"btcusdt@depth20@100ms","data":{"lastUpdateId":99116126487,"bids":[["79980.15000000","0.75959000"],["79980.14000000","0.00076000"],["79980.13000000","0.00013000"],["79980.10000000","0.00007000"],["79979.99000000","0.00020000"],["79979.03000000","0.00921000"],["79978.93000000","0.00007000"],["79978.73000000","0.00007000"],["79978.42000000","0.00007000"],["79978.29000000","0.00007000"],["79978.28000000","0.00007000"],["79977.99000000","0.00007000"],["79977.76000000","0.00014000"],["79977.75000000","0.01528000"],["79977.49000000","0.00014000"],["79977.48000000","0.00014000"],["79977.42000000","0.00007000"],["79977.20000000","0.00014000"],["79977.19000000","0.04732000"],["79976.90000000","0.00007000"]],"asks":[["79980.16000000","1.96671000"],["79980.17000000","0.00048000"],["79980.18000000","0.00013000"],["79980.32000000","0.00014000"],["79980.33000000","0.00995000"],["79980.54000000","0.03224000"],["79980.61000000","0.00014000"],["79980.62000000","0.03021000"],["79980.72000000","0.00014000"],["79980.73000000","0.03824000"],["79980.97000000","0.00007000"],["79981.01000000","0.00007000"],["79981.03000000","0.00014000"],["79981.04000000","0.47993000"],["79981.05000000","0.32793000"],["79981.06000000","0.00014000"],["79981.08000000","0.00400000"],["79981.29000000","0.00014000"],["79981.61000000","0.01653000"],["79981.64000000","0.00400000"]]}}}
{"rx_ns": 10707352777000, "frame": {"stream":"btcusdt@depth@100ms","data":{"e":"depthUpdate","E":1787647702514,"s":"BTCUSDT","U":99116126365,"u":99116126487,"b":[["79980.15000000","0.75959000"],["79977.48000000","0.00014000"],["79976.34000000","0.00243000"],["79975.46000000","0.00000000"],["79975.45000000","0.00000000"],["79975.35000000","0.00000000"],["79974.72000000","0.00000000"],["79973.55000000","0.00007000"],["79971.49000000","0.00000000"],["79971.48000000","0.00000000"],["79970.98000000","0.00000000"],["79970.38000000","0.00000000"],["79970.36000000","0.00000000"],["79969.93000000","0.00000000"],["79969.47000000","0.00000000"],["79968.99000000","0.00000000"],["79968.90000000","0.00000000"],["79967.71000000","0.00000000"],["79967.53000000","0.31271000"],["79967.24000000","0.00000000"],["79967.06000000","0.00000000"],["79967.03000000","0.00625000"],["79966.97000000","0.00000000"],["79966.76000000","0.00400000"],["79965.47000000","0.00162000"],["79962.96000000","0.01200000"],["79962.01000000","0.00007000"],["79959.79000000","1.87060000"],["79959.45000000","0.00000000"],["79955.46000000","0.00625000"],["79955.34000000","0.55799000"],["79954.69000000","0.00000000"],["79951.64000000","0.62539000"],["79950.00000000","0.11788000"],["79946.56000000","0.33782000"],["79933.16000000","0.33788000"],["79921.31000000","0.00400000"],["79886.41000000","0.00000000"],["79883.78000000","0.20001000"],["79883.77000000","0.62498000"],["71982.14000000","0.00384000"],["71982.00000000","0.00000000"],["63984.12000000","0.00031000"]],"a":[["79980.16000000","1.96671000"],["79980.17000000","0.00048000"],["79980.54000000","0.03224000"],["79981.08000000","0.00400000"],["79981.64000000","0.00400000"],["79982.62000000","0.00026000"],["79983.53000000","0.02000000"],["79983.98000000","0.00000000"],["79984.16000000","0.00000000"],["79984.33000000","0.00000000"],["79984.54000000","0.00000000"],["79985.39000000","0.00000000"],["79985.99000000","0.01200000"],["79986.24000000","0.00000000"],["79987.94000000","0.36586000"],["79990.64000000","0.00000000"],["79990.84000000","0.00000000"],["79991.39000000","0.00000000"],["79993.91000000","0.00000000"],["79994.78000000","0.33762000"],["79994.99000000","0.33790000"],["80001.99000000","0.00000000"],["80016.30000000","0.00000000"]]}}}
{"rx_ns": 10707452194600, "frame": {"stream":"btcusdt@depth20@100ms","data":{"lastUpdateId":99116126664,"bids":[["79980.15000000","0.32744000"],["79980.14000000","0.00076000"],["79980.13000000","0.00013000"],["79980.10000000","0.00007000"],["79979.99000000","0.00020000"],["79979.03000000","0.00921000"],["79978.93000000","0.00007000"],["79978.73000000","0.00007000"],["79978.42000000","0.00007000"],["79978.29000000","0.00007000"],["79978.28000000","0.00007000"],["79977.99000000","0.00007000"],["79977.76000000","0.00014000"],["79977.75000000","0.01514000"],["79977.42000000","0.00007000"],["79977.20000000","0.00014000"],["79977.19000000","0.04732000"],["79976.90000000","0.00007000"],["79976.85000000","0.00007000"],["79976.67000000","0.00228000"]],"asks":[["79980.16000000","1.97228000"],["79980.17000000","0.00027000"],["79980.18000000","0.00013000"],["79980.32000000","0.00014000"],["79980.33000000","0.01009000"],["79980.52000000","0.00014000"],["79980.53000000","0.01763000"],["79980.54000000","0.03238000"],["79980.61000000","0.00014000"],["79980.62000000","0.03021000"],["79980.72000000","0.00014000"],["79980.73000000","0.03824000"],["79980.97000000","0.00007000"],["79981.01000000","0.00007000"],["79981.04000000","0.47979000"],["79981.05000000","0.32793000"],["79981.06000000","0.00014000"],["79981.29000000","0.00014000"],["79981.61000000","0.01653000"],["79981.64000000","0.00400000"]]}}}
{"rx_ns": 10707452306800, "frame": {"stream":"btcusdt@depth@100ms","data":{"e":"depthUpdate","E":1787647702614,"s":"BTCUSDT","U":99116126488,"u":99116126664,"b":[["79980.15000000","0.32744000"],["79980.14000000","0.00076000"],["79977.75000000","0.01514000"],["79977.49000000","0.00000000"],["79977.48000000","0.00000000"],["79976.48000000","0.00014000"],["79976.47000000","0.01814000"],["79976.35000000","0.00000000"],["79976.34000000","0.00000000"],["79976.29000000","0.00320000"],["79976.01000000","0.00014000"],["79975.73000000","0.00893000"],["79975.64000000","0.00007000"],["79975.63000000","0.08374000"],["79975.47000000","0.00000000"],["79975.20000000","0.00007000"],["79975.19000000","0.01821000"],["79974.96000000","0.11906000"],["79974.50000000","0.08663000"],["79973.37000000","0.08663000"],["79972.24000000","0.08663000"],["79971.20000000","0.55744000"],["79971.01000000","0.02474000"],["79970.37000000","0.00000000"],["79967.94000000","0.00000000"],["79967.83000000","0.00000000"],["79967.46000000","0.00000000"],["79967.43000000","0.00000000"],["79967.42000000","0.00000000"],["79967.33000000","0.00000000"],["79967.29000000","0.00000000"],["79967.12000000","0.00000000"],["79967.00000000","0.00000000"],["79966.76000000","0.00000000"],["79966.66000000","0.00000000"],["79966.28000000","0.00000000"],["79965.99000000","0.00000000"],["79965.47000000","0.00000000"],["79965.30000000","0.00573000"],["79962.96000000","0.00800000"],["79961.99000000","0.00582000"],["79961.12000000","0.00000000"],["79957.99000000","0.20852000"],["79956.21000000","1.20058000"],["79955.35000000","0.15383000"],["79953.99000000","0.00574000"],["79949.99000000","0.00587000"],["79904.21000000","0.03126000"],["79896.21000000","0.02084000"],["71982.14000000","0.00384000"],["63984.12000000","0.00000000"]],"a":[["79980.16000000","1.97228000"],["79980.17000000","0.00027000"],["79980.33000000","0.01009000"],["79980.52000000","0.00014000"],["79980.53000000","0.01763000"],["79980.54000000","0.03238000"],["79981.03000000","0.00000000"],["79981.04000000","0.47979000"],["79981.08000000","0.00000000"],["79982.19000000","0.00400000"],["79982.63000000","0.04018000"],["79982.71000000","0.00400000"],["79983.51000000","0.03779000"],["79986.00000000","0.02400000"],["79987.96000000","0.01749000"],["79992.27000000","0.46447000"],["80030.00000000","0.02400000"],["80031.83000000","0.00000000"],["80148.17000000","0.00160000"]]}}}
{"rx_ns": 10707552276200, "frame": {"stream":"btcusdt@depth20@100ms","data":{"lastUpdateId":99116126703,"bids":[["79980.15000000","0.32735000"],["79980.14000000","0.00076000"],["79980.13000000","0.00013000"],["79980.10000000","0.00007000"],["79979.99000000","0.00020000"],["79979.03000000","0.00921000"],["79978.93000000","0.00007000"],["79978.73000000","0.00007000"],["79978.42000000","0.00007000"],["79978.29000000","0.00007000"],["79978.28000000","0.00007000"],["79977.99000000","0.00007000"],["79977.76000000","0.00014000"],["79977.75000000","0.01514000"],["79977.42000000","0.00007000"],["79977.20000000","0.00014000"],["79977.19000000","0.04732000"],["79976.90000000","0.00007000"],["79976.85000000","0.00007000"],["79976.67000000","0.00228000"]],"asks":[["79980.16000000","1.96720000"],["79980.17000000","0.00027000"],["79980.18000000","0.00013000"],["79980.32000000","0.00014000"],["79980.33000000","0.01009000"],["79980.52000000","0.00014000"],["79980.53000000","0.01777000"],["79980.54000000","0.03238000"],["79980.61000000","0.00014000"],["79980.62000000","0.03021000"],["79980.72000000","0.00014000"],["79980.73000000","0.03824000"],["79980.97000000","0.00007000"],["79981.01000000","0.00007000"],["79981.04000000","0.47979000"],["79981.05000000","0.32793000"],["79981.06000000","0.00014000"],["79981.29000000","0.00014000"],["79981.61000000","0.01653000"],["79981.64000000","0.00400000"]]}}}
{"rx_ns": 10707552359800, "frame": {"stream":"btcusdt@depth@100ms","data":{"e":"depthUpdate","E":1787647702714,"s":"BTCUSDT","U":99116126665,"u":99116126703,"b":[["79980.15000000","0.32735000"],["79975.73000000","0.00893000"],["79975.63000000","0.08388000"],["79974.96000000","0.11892000"],["79971.20000000","0.25158000"],["79971.19000000","0.00000000"],["79967.40000000","0.00400000"],["79966.97000000","0.01200000"],["79950.81000000","0.00000000"],["79950.00000000","0.24295000"],["79933.43000000","0.04048000"],["79904.21000000","0.00000000"],["79896.21000000","0.00000000"],["79781.48000000","0.01506000"],["71982.14000000","0.00400000"],["71982.13000000","0.00000000"],["71982.12000000","0.00008000"]],"a":[["79980.16000000","1.96720000"],["79980.33000000","0.01009000"],["79980.53000000","0.01777000"],["79981.82000000","0.04000000"],["79982.62000000","0.00000000"],["79995.93000000","0.04570000"],["80012.06000000","0.00000000"],["80144.08000000","0.04945000"]]}}}
{"rx_ns": 10707657625300, "frame": {"stream":"btcusdt@depth20@100ms","data":{"lastUpdateId":99116126712,"bids":[["79980.15000000","0.32735000"],["79980.14000000","0.00076000"],["79980.13000000","0.00013000"],["79980.10000000","0.00007000"],["79979.99000000","0.00020000"],["79979.03000000","0.00921000"],["79978.93000000","0.00007000"],["79978.73000000","0.00007000"],["79978.42000000","0.00007000"],["79978.29000000","0.00007000"],["79978.28000000","0.00007000"],["79977.99000000","0.00007000"],["79977.76000000","0.00014000"],["79977.75000000","0.01514000"],["79977.42000000","0.00007000"],["79977.20000000","0.00014000"],["79977.19000000","0.04732000"],["79976.90000000","0.00007000"],["79976.85000000","0.00007000"],["79976.67000000","0.00228000"]],"asks":[["79980.16000000","1.96720000"],["79980.17000000","0.00027000"],["79980.18000000","0.00013000"],["79980.32000000","0.00014000"],["79980.33000000","0.01009000"],["79980.52000000","0.00014000"],["79980.53000000","0.01777000"],["79980.54000000","0.03238000"],["79980.61000000","0.00014000"],["79980.62000000","0.03021000"],["79980.72000000","0.00014000"],["79980.73000000","0.03824000"],["79980.97000000","0.00007000"],["79981.01000000","0.00007000"],["79981.04000000","0.47979000"],["79981.05000000","0.32793000"],["79981.06000000","0.00014000"],["79981.29000000","0.00014000"],["79981.61000000","0.01653000"],["79981.64000000","0.00400000"]]}}}
{"rx_ns": 10707657715900, "frame": {"stream":"btcusdt@depth@100ms","data":{"e":"depthUpdate","E":1787647702815,"s":"BTCUSDT","U":99116126704,"u":99116126712,"b":[["79975.19000000","0.01828000"],["79974.97000000","0.23151000"],["79967.54000000","0.00000000"],["79956.22000000","0.15383000"],["79955.35000000","0.00000000"],["71982.14000000","0.00400000"]],"a":[["79982.19000000","0.00000000"],["79983.31000000","0.00400000"],["79991.15000000","0.01400000"]]}}}
{"rx_ns": 10707752475400, "frame": {"stream":"btcusdt@depth20@100ms","data":{"lastUpdateId":99116126723,"bids":[["79980.15000000","0.32716000"],["79980.14000000","0.00076000"],["79980.13000000","0.00013000"],["79980.10000000","0.00007000"],["79979.99000000","0.00020000"],["79979.03000000","0.00921000"],["79978.93000000","0.00007000"],["79978.73000000","0.00007000"],["79978.42000000","0.00007000"],["79978.29000000","0.00007000"],["79978.28000000","0.00007000"],["79977.99000000","0.00007000"],["79977.76000000","0.00014000"],["79977.75000000","0.01514000"],["79977.42000000","0.00007000"],["79977.20000000","0.00014000"],["79977.19000000","0.04732000"],["79976.90000000","0.00007000"],["79976.85000000","0.00007000"],["79976.67000000","0.00228000"]],"asks":[["79980.16000000","1.96720000"],["79980.17000000","0.00027000"],["79980.18000000","0.00013000"],["79980.32000000","0.00014000"],["79980.33000000","0.01009000"],["79980.52000000","0.00014000"],["79980.53000000","0.01777000"],["79980.54000000","0.03238000"],["79980.61000000","0.00014000"],["79980.62000000","0.03021000"],["79980.72000000","0.00014000"],["79980.73000000","0.03824000"],["79980.97000000","0.00007000"],["79981.01000000","0.00007000"],["79981.04000000","0.47979000"],["79981.05000000","0.32793000"],["79981.06000000","0.00014000"],["79981.29000000","0.00014000"],["79981.61000000","0.01653000"],["79981.64000000","0.00400000"]]}}}
{"rx_ns": 10707752576000, "frame": {"stream":"btcusdt@depth@100ms","data":{"e":"depthUpdate","E":1787647702914,"s":"BTCUSDT","U":99116126713,"u":99116126723,"b":[["79980.15000000","0.32716000"],["79975.19000000","0.01828000"],["79942.00000000","0.72400000"],["71982.14000000","0.00416000"]],"a":[["80024.88000000","0.00000000"],["80024.98000000","0.00651000"]]}}}
{"rx_ns": 10707857338800, "frame": {"stream":"btcusdt@depth20@100ms","data":{"lastUpdateId":99116126731,"bids":[["79980.15000000","0.32716000"],["79980.14000000","0.00076000"],["79980.13000000","0.00013000"],["79980.10000000","0.00007000"],["79979.99000000","0.00020000"],["79979.03000000","0.00921000"],["79978.93000000","0.00007000"],["79978.73000000","0.00007000"],["79978.42000000","0.00007000"],["79978.29000000","0.00007000"],["79978.28000000","0.00007000"],["79977.99000000","0.00007000"],["79977.76000000","0.00014000"],["79977.75000000","0.01514000"],["79977.42000000","0.00007000"],["79977.20000000","0.00014000"],["79977.19000000","0.04732000"],["79976.90000000","0.00007000"],["79976.85000000","0.00007000"],["79976.67000000","0.00228000"]],"asks":[["79980.16000000","1.96620000"],["79980.17000000","0.00027000"],["79980.18000000","0.00013000"],["79980.32000000","0.00014000"],["79980.33000000","0.01009000"],["79980.52000000","0.00014000"],["79980.53000000","0.01777000"],["79980.54000000","0.03238000"],["79980.61000000","0.00014000"],["79980.62000000","0.03021000"],["79980.72000000","0.00014000"],["79980.73000000","0.03824000"],["79980.97000000","0.00007000"],["79981.01000000","0.00007000"],["79981.04000000","0.47979000"],["79981.05000000","0.32793000"],["79981.06000000","0.00014000"],["79981.29000000","0.00014000"],["79981.61000000","0.01653000"],["79981.64000000","0.00400000"]]}}}
{"rx_ns": 10707857478000, "frame": {"stream":"btcusdt@depth@100ms","data":{"e":"depthUpdate","E":1787647703014,"s":"BTCUSDT","U":99116126724,"u":99116126731,"b":[["79890.02000000","0.02084000"],["73585.27000000","0.00014000"],["71982.12000000","0.00000000"],["63984.12000000","0.00031000"]],"a":[["79980.16000000","1.96620000"],["80064.03000000","1.56648000"],["80065.91000000","3.13843000"],["80068.55000000","0.00000000"]]}}}
{"rx_ns": 10707952975200, "frame": {"stream":"btcusdt@depth20@100ms","data":{"lastUpdateId":99116126736,"bids":[["79980.15000000","0.32716000"],["79980.14000000","0.00076000"],["79980.13000000","0.00013000"],["79980.10000000","0.00007000"],["79979.99000000","0.00020000"],["79979.03000000","0.00921000"],["79978.93000000","0.00007000"],["79978.73000000","0.00007000"],["79978.42000000","0.00007000"],["79978.29000000","0.00007000"],["79978.28000000","0.00007000"],["79977.99000000","0.00007000"],["79977.76000000","0.00014000"],["79977.75000000","0.01514000"],["79977.42000000","0.00007000"],["79977.20000000","0.00014000"],["79977.19000000","0.04732000"],["79976.90000000","0.00007000"],["79976.85000000","0.00007000"],["79976.67000000","0.00228000"]],"asks":[["79980.16000000","1.96620000"],["79980.17000000","0.00027000"],["79980.18000000","0.00013000"],["79980.32000000","0.00014000"],["79980.33000000","0.01009000"],["79980.52000000","0.00014000"],["79980.53000000","0.01777000"],["79980.54000000","0.03238000"],["79980.61000000","0.00014000"],["79980.62000000","0.03021000"],["79980.72000000","0.00014000"],["79980.73000000","0.03824000"],["79980.97000000","0.00007000"],["79981.01000000","0.00007000"],["79981.04000000","0.47979000"],["79981.05000000","0.32793000"],["79981.06000000","0.00014000"],["79981.29000000","0.00014000"],["79981.61000000","0.01653000"],["79981.64000000","0.00400000"]]}}}
{"rx_ns": 10707953051000, "frame": {"stream":"btcusdt@depth@100ms","data":{"e":"depthUpdate","E":1787647703115,"s":"BTCUSDT","U":99116126732,"u":99116126736,"b":[["78780.44000000","0.00030000"],["71982.14000000","0.00432000"]],"a":[]}}}
{"rx_ns": 10708056635100, "frame": {"stream":"btcusdt@depth20@100ms","data":{"lastUpdateId":99116126744,"bids":[["79980.15000000","0.32716000"],["79980.14000000","0.00076000"],["79980.13000000","0.00013000"],["79980.10000000","0.00007000"],["79979.99000000","0.00020000"],["79979.03000000","0.00921000"],["79978.93000000","0.00007000"],["79978.73000000","0.00007000"],["79978.42000000","0.00007000"],["79978.29000000","0.00007000"],["79978.28000000","0.00007000"],["79977.99000000","0.00007000"],["79977.76000000","0.00014000"],["79977.75000000","0.01514000"],["79977.42000000","0.00007000"],["79977.20000000","0.00014000"],["79977.19000000","0.04732000"],["79976.90000000","0.00007000"],["79976.85000000","0.00007000"],["79976.67000000","0.00228000"]],"asks":[["79980.16000000","1.96620000"],["79980.17000000","0.00027000"],["79980.18000000","0.00013000"],["79980.32000000","0.00014000"],["79980.33000000","0.01009000"],["79980.52000000","0.00014000"],["79980.53000000","0.01777000"],["79980.54000000","0.03238000"],["79980.61000000","0.00014000"],["79980.62000000","0.03021000"],["79980.72000000","0.00014000"],["79980.73000000","0.03824000"],["79980.97000000","0.00007000"],["79981.01000000","0.00007000"],["79981.04000000","0.47979000"],["79981.05000000","0.32793000"],["79981.06000000","0.00014000"],["79981.29000000","0.00014000"],["79981.61000000","0.01653000"],["79981.64000000","0.00400000"]]}}}
{"rx_ns": 10708056795700, "frame": {"stream":"btcusdt@depth@100ms","data":{"e":"depthUpdate","E":1787647703214,"s":"BTCUSDT","U":99116126737,"u":99116126744,"b":[["79974.97000000","0.00000000"],["79971.56000000","0.31682000"],["79971.55000000","0.42215000"],["79971.20000000","0.08663000"],["79930.98000000","0.00007000"],["71982.14000000","0.00432000"],["63984.12000000","0.00000000"]],"a":[]}}}
{"rx_ns": 10708155886300, "frame": {"stream":"btcusdt@depth20@100ms","data":{"lastUpdateId":99116126763,"bids":[["79980.15000000","0.32716000"],["79980.14000000","0.00076000"],["79980.13000000","0.00013000"],["79980.10000000","0.00007000"],["79979.99000000","0.00020000"],["79979.03000000","0.00921000"],["79978.93000000","0.00007000"],["79978.73000000","0.00007000"],["79978.42000000","0.00007000"],["79978.29000000","0.00007000"],["79978.28000000","0.00007000"],["79977.99000000","0.00007000"],["79977.76000000","0.00014000"],["79977.75000000","0.01514000"],["79977.42000000","0.00007000"],["79977.20000000","0.00014000"],["79977.19000000","0.04732000"],["79976.90000000","0.00007000"],["79976.85000000","0.00007000"],["79976.67000000","0.00228000"]],"asks":[["79980.16000000","2.01607000"],["79980.17000000","0.00027000"],["79980.18000000","0.00013000"],["79980.32000000","0.00014000"],["79980.33000000","0.01009000"],["79980.52000000","0.00014000"],["79980.53000000","0.01777000"],["79980.54000000","0.03238000"],["79980.61000000","0.00014000"],["79980.62000000","0.03021000"],["79980.72000000","0.00014000"],["79980.73000000","0.03824000"],["79980.97000000","0.00007000"],["79981.01000000","0.00007000"],["79981.04000000","0.47979000"],["79981.05000000","0.32793000"],["79981.06000000","0.00014000"],["79981.29000000","0.00014000"],["79981.61000000","0.01653000"],["79981.64000000","0.00400000"]]}}}
{"rx_ns": 10708156049400, "frame": {"stream":"btcusdt@depth@100ms","data":{"e":"depthUpdate","E":1787647703314,"s":"BTCUSDT","U":99116126745,"u":99116126763,"b":[["79975.19000000","0.01821000"],["79971.20000000","0.00000000"],["79890.02000000","0.00000000"],["71982.14000000","0.00448000"],["63984.00000000","0.00014000"]],"a":[["79980.16000000","2.01607000"],["79981.77000000","0.00008000"],["81179.87000000","0.00030000"]]}}}
{"rx_ns": 10708253799900, "frame": {"stream":"btcusdt@depth20@100ms","data":{"lastUpdateId":99116126778,"bids":[["79980.15000000","0.32716000"],["79980.14000000","0.00076000"],["79980.13000000","0.00013000"],["79980.10000000","0.00007000"],["79979.99000000","0.00020000"],["79979.03000000","0.00921000"],["79978.93000000","0.00007000"],["79978.73000000","0.00007000"],["79978.42000000","0.00007000"],["79978.29000000","0.00007000"],["79978.28000000","0.00007000"],["79977.99000000","0.00007000"],["79977.76000000","0.00014000"],["79977.75000000","0.01514000"],["79977.42000000","0.00007000"],["79977.20000000","0.00014000"],["79977.19000000","0.04732000"],["79976.90000000","0.00007000"],["79976.85000000","0.00007000"],["79976.67000000","0.00228000"]],"asks":[["79980.16000000","2.01522000"],["79980.17000000","0.00027000"],["79980.18000000","0.00013000"],["79980.32000000","0.00014000"],["79980.33000000","0.01009000"],["79980.52000000","0.00014000"],["79980.53000000","0.01777000"],["79980.54000000","0.03238000"],["79980.61000000","0.00014000"],["79980.62000000","0.03021000"],["79980.72000000","0.00014000"],["79980.73000000","0.03824000"],["79980.97000000","0.00007000"],["79981.01000000","0.00007000"],["79981.04000000","0.47979000"],["79981.05000000","0.32793000"],["79981.06000000","0.00014000"],["79981.29000000","0.00014000"],["79981.61000000","0.01653000"],["79981.64000000","0.00400000"]]}}}
{"rx_ns": 10708253877100, "frame": {"stream":"btcusdt@depth@100ms","data":{"e":"depthUpdate","E":1787647703414,"s":"BTCUSDT","U":99116126764,"u":99116126778,"b":[["79964.91000000","0.00007000"],["79942.93000000","0.46267000"],["79773.62000000","0.00000000"],["79770.98000000","0.00770000"],["71982.14000000","0.00432000"],["63984.12000000","0.00000000"],["42091.80000000","0.00036000"]],"a":[["79980.16000000","2.01522000"],["79993.14000000","0.00000000"],["79996.91000000","0.00007000"]]}}}
{"rx_ns": 10708358596500, "frame": {"stream":"btcusdt@depth20@100ms","data":{"lastUpdateId":99116126898,"bids":[["79980.15000000","1.11659000"],["79980.14000000","0.00076000"],["79980.13000000","0.00013000"],["79980.10000000","0.00007000"],["79979.99000000","0.00020000"],["79979.52000000","0.00026000"],["79979.04000000","0.08663000"],["79979.03000000","0.00928000"],["79978.93000000","0.00007000"],["79978.73000000","0.00007000"],["79978.42000000","0.00007000"],["79978.29000000","0.00007000"],["79978.28000000","0.00007000"],["79977.99000000","0.00007000"],["79977.89000000","0.08663000"],["79977.77000000","0.00014000"],["79977.76000000","0.03327000"],["79977.75000000","0.01514000"],["79977.42000000","0.00007000"],["79977.20000000","0.00014000"]],"asks":[["79980.16000000","1.86021000"],["79980.17000000","0.00076000"],["79980.18000000","0.00013000"],["79980.32000000","0.00014000"],["79980.33000000","0.01009000"],["79980.52000000","0.00014000"],["79980.53000000","0.01763000"],["79980.54000000","0.00014000"],["79980.61000000","0.00014000"],["79980.62000000","0.03021000"],["79980.72000000","0.00014000"],["79980.73000000","0.03824000"],["79980.97000000","0.00007000"],["79981.01000000","0.00007000"],["79981.03000000","0.00007000"],["79981.04000000","0.47979000"],["79981.05000000","0.32793000"],["79981.06000000","0.00014000"],["79981.29000000","0.00014000"],["79981.61000000","0.01653000"]]}}}
{"rx_ns": 10708358678000, "frame": {"stream":"btcusdt@depth@100ms","data":{"e":"depthUpdate","E":1787647703514,"s":"BTCUSDT","U":99116126779,"u":99116126898,"b":[["79980.15000000","1.11659000"],["79979.52000000","0.00026000"],["79979.04000000","0.08663000"],["79979.03000000","0.00928000"],["79977.89000000","0.08663000"],["79977.77000000","0.00014000"],["79977.76000000","0.03327000"],["79977.19000000","0.04739000"],["79976.97000000","0.00014000"],["79976.96000000","0.03867000"],["79976.76000000","0.08663000"],["79976.01000000","0.00000000"],["79975.64000000","0.00000000"],["79975.20000000","0.00000000"],["79975.19000000","0.01828000"],["79974.97000000","0.23151000"],["79974.96000000","0.00007000"],["79973.59000000","0.00400000"],["79972.16000000","0.08663000"],["79971.56000000","0.80884000"],["79970.48000000","1.87060000"],["79967.40000000","0.00000000"],["79967.04000000","0.00162000"],["79965.47000000","0.00000000"],["79930.98000000","0.00000000"],["73585.27000000","0.00000000"],["71982.14000000","0.00432000"],["71982.00000000","0.00020000"],["63984.12000000","0.00031000"]],"a":[["79980.16000000","1.86021000"],["79980.17000000","0.00076000"],["79980.53000000","0.01763000"],["79980.54000000","0.00014000"],["79981.03000000","0.00007000"],["79981.64000000","0.00000000"],["79981.81000000","0.00010000"],["79983.31000000","0.00000000"],["79983.51000000","0.03772000"],["79983.53000000","0.00000000"],["79985.23000000","0.02000000"],["79985.99000000","0.00000000"],["79987.93000000","0.00800000"],["79988.00000000","0.03582000"],["79989.37000000","0.00000000"],["79989.90000000","0.00400000"],["79990.25000000","0.00000000"],["79990.64000000","0.00400000"],["79994.99000000","0.00000000"],["79997.69000000","0.37573000"]]}}}
{"rx_ns": 10708452277200, "frame": {"stream":"btcusdt@depth20@100ms","data":{"lastUpdateId":99116127016,"bids":[["79980.15000000","0.99120000"],["79980.14000000","0.00097000"],["79980.13000000","0.00013000"],["79980.10000000","0.00007000"],["79979.99000000","0.00020000"],["79979.06000000","0.00014000"],["79979.05000000","0.12541000"],["79979.04000000","0.08677000"],["79979.03000000","0.00935000"],["79978.93000000","0.00007000"],["79978.73000000","0.00007000"],["79978.42000000","0.00007000"],["79978.29000000","0.00007000"],["79978.28000000","0.00007000"],["79977.99000000","0.00007000"],["79977.90000000","0.00014000"],["79977.89000000","0.08677000"],["79977.86000000","0.00014000"],["79977.85000000","0.10566000"],["79977.76000000","0.00014000"]],"asks":[["79980.16000000","1.86021000"],["79980.17000000","0.00076000"],["79980.18000000","0.00013000"],["79980.32000000","0.00014000"],["79980.33000000","0.01002000"],["79980.52000000","0.00014000"],["79980.53000000","0.01763000"],["79980.61000000","0.00014000"],["79980.62000000","0.03021000"],["79980.72000000","0.00014000"],["79980.73000000","0.03824000"],["79980.97000000","0.00007000"],["79981.01000000","0.00007000"],["79981.03000000","0.00007000"],["79981.04000000","0.47979000"],["79981.05000000","0.32793000"],["79981.06000000","0.00014000"],["79981.29000000","0.00014000"],["79981.61000000","0.01653000"],["79981.77000000","0.00008000"]]}}}
{"rx_ns": 10708452361900, "frame": {"stream":"btcusdt@depth@100ms","data":{"e":"depthUpdate","E":1787647703614,"s":"BTCUSDT","U":99116126899,"u":99116127016,"b":[["79980.15000000","0.99120000"],["79980.14000000","0.00097000"],["79979.52000000","0.00000000"],["79979.06000000","0.00014000"],["79979.05000000","0.12541000"],["79979.04000000","0.08677000"],["79979.03000000","0.00935000"],["79977.90000000","0.00014000"],["79977.89000000","0.08677000"],["79977.86000000","0.00014000"],["79977.85000000","0.10566000"],["79977.77000000","0.00000000"],["79977.76000000","0.00014000"],["79977.19000000","0.04739000"],["79976.97000000","0.00000000"],["79976.96000000","0.00021000"],["79976.76000000","0.08677000"],["79976.48000000","0.00000000"],["79976.47000000","0.01800000"],["79976.00000000","0.02414000"],["79975.73000000","0.00879000"],["79975.63000000","0.08374000"],["79975.19000000","0.01814000"],["79974.00000000","0.02400000"],["79973.55000000","0.00014000"],["79972.25000000","0.01200000"],["79971.55000000","0.00000000"],["79966.97000000","0.00000000"],["79924.38000000","0.00400000"],["79921.31000000","0.00000000"],["79886.41000000","0.62498000"],["79883.78000000","0.01679000"],["79883.77000000","0.00000000"],["71982.14000000","0.00416000"],["71982.00000000","0.00000000"],["63984.12000000","0.00000000"]],"a":[["79980.16000000","1.86021000"],["79980.17000000","0.00076000"],["79980.33000000","0.01002000"],["79980.53000000","0.01763000"],["79980.54000000","0.00000000"],["79981.81000000","0.00000000"],["79981.82000000","0.04014000"],["79983.49000000","0.00015000"],["79987.94000000","0.00000000"],["79988.24000000","0.44654000"],["79991.97000000","0.00000000"],["79992.27000000","0.89078000"],["79994.97000000","1.87060000"],["79995.93000000","0.00000000"],["79998.75000000","0.04414000"]]}}}
{"rx_ns": 10708552577000, "frame": {"stream":"btcusdt@depth20@100ms","data":{"lastUpdateId":99116127055,"bids":[["79980.15000000","0.99120000"],["79980.14000000","0.00097000"],["79980.13000000","0.00013000"],["79980.10000000","0.00007000"],["79979.99000000","0.00020000"],["79979.06000000","0.00014000"],["79979.05000000","0.12555000"],["79979.04000000","0.08677000"],["79979.03000000","0.00928000"],["79978.93000000","0.00007000"],["79978.73000000","0.00007000"],["79978.42000000","0.00007000"],["79978.29000000","0.00007000"],["79978.28000000","0.00007000"],["79977.99000000","0.00007000"],["79977.90000000","0.00014000"],["79977.89000000","0.08684000"],["79977.86000000","0.00014000"],["79977.85000000","0.10580000"],["79977.75000000","0.01514000"]],"asks":[["79980.16000000","1.86010000"],["79980.17000000","0.00076000"],["79980.18000000","0.00013000"],["79980.32000000","0.00014000"],["79980.33000000","0.01002000"],["79980.52000000","0.00014000"],["79980.53000000","0.01763000"],["79980.61000000","0.00014000"],["79980.62000000","0.03021000"],["79980.72000000","0.00014000"],["79980.73000000","0.03824000"],["79980.97000000","0.00007000"],["79981.01000000","0.00007000"],["79981.03000000","0.00007000"],["79981.04000000","0.47979000"],["79981.05000000","0.32793000"],["79981.06000000","0.00014000"],["79981.29000000","0.00014000"],["79981.61000000","0.01653000"],["79981.77000000","0.00008000"]]}}}
{"rx_ns": 10708552665900, "frame": {"stream":"btcusdt@depth@100ms","data":{"e":"depthUpdate","E":1787647703714,"s":"BTCUSDT","U":99116127017,"u":99116127055,"b":[["79980.15000000","0.99120000"],["79979.05000000","0.12555000"],["79979.03000000","0.00928000"],["79977.89000000","0.08684000"],["79977.85000000","0.10580000"],["79977.76000000","0.00000000"],["79977.19000000","0.04739000"],["79976.96000000","0.00007000"],["79972.25000000","0.00000000"],["79966.97000000","0.01200000"],["79800.00000000","1.66951000"],["71982.14000000","0.00432000"]],"a":[["79980.16000000","1.86010000"],["79987.93000000","0.00000000"],["79989.89000000","0.00400000"],["79990.60000000","0.09280000"]]}}}
{"rx_ns": 10708652865000, "frame": {"stream":"btcusdt@depth20@100ms","data":{"lastUpdateId":99116127080,"bids":[["79980.15000000","1.01121000"],["79980.14000000","0.00090000"],["79980.13000000","0.00013000"],["79980.10000000","0.00007000"],["79979.99000000","0.00020000"],["79979.06000000","0.00014000"],["79979.05000000","0.12541000"],["79979.04000000","0.00014000"],["79979.03000000","0.00928000"],["79978.93000000","0.00007000"],["79978.75000000","0.00014000"],["79978.74000000","0.05128000"],["79978.73000000","0.00007000"],["79978.42000000","0.00007000"],["79978.29000000","0.00007000"],["79978.28000000","0.00007000"],["79977.99000000","0.00007000"],["79977.90000000","0.00014000"],["79977.89000000","0.08684000"],["79977.85000000","0.00014000"]],"asks":[["79980.16000000","1.86010000"],["79980.17000000","0.00076000"],["79980.18000000","0.00013000"],["79980.32000000","0.00014000"],["79980.33000000","0.01002000"],["79980.52000000","0.00014000"],["79980.53000000","0.01763000"],["79980.61000000","0.00014000"],["79980.62000000","0.03021000"],["79980.72000000","0.00014000"],["79980.73000000","0.03824000"],["79980.97000000","0.00007000"],["79981.01000000","0.00007000"],["79981.03000000","0.00007000"],["79981.04000000","0.47979000"],["79981.05000000","0.32793000"],["79981.06000000","0.00014000"],["79981.29000000","0.00014000"],["79981.61000000","0.01653000"],["79981.77000000","0.00008000"]]}}}
{"rx_ns": 10708652985600, "frame": {"stream":"btcusdt@depth@100ms","data":{"e":"depthUpdate","E":1787647703815,"s":"BTCUSDT","U":99116127056,"u":99116127080,"b":[["79980.15000000","1.01121000"],["79980.14000000","0.00090000"],["79979.05000000","0.12541000"],["79979.04000000","0.00014000"],["79978.75000000","0.00014000"],["79978.74000000","0.05128000"],["79977.86000000","0.00000000"],["79977.85000000","0.00014000"],["79976.77000000","0.00007000"],["79908.12000000","0.00311000"],["79827.18000000","0.00125000"],["71982.14000000","0.00448000"]],"a":[["79985.23000000","0.00000000"],["79987.63000000","0.02000000"],["80000.00000000","0.82135000"]]}}}
{"rx_ns": 10708752210900, "frame": {"stream":"btcusdt@depth20@100ms","data":{"lastUpdateId":99116127131,"bids":[["79980.15000000","0.81076000"],["79980.14000000","0.00097000"],["79980.13000000","0.00013000"],["79980.10000000","0.00007000"],["79979.99000000","0.00020000"],["79979.63000000","0.00014000"],["79979.62000000","0.10835000"],["79979.06000000","0.00014000"],["79979.05000000","0.08801000"],["79979.03000000","0.00935000"],["79978.93000000","0.00007000"],["79978.74000000","0.00014000"],["79978.73000000","0.00007000"],["79978.42000000","0.00007000"],["79978.29000000","0.00007000"],["79978.28000000","0.00007000"],["79977.99000000","0.00007000"],["79977.90000000","0.00014000"],["79977.89000000","0.08677000"],["79977.75000000","0.01514000"]],"asks":[["79980.16000000","1.86010000"],["79980.17000000","0.00076000"],["79980.18000000","0.00013000"],["79980.32000000","0.00014000"],["79980.33000000","0.01002000"],["79980.52000000","0.00014000"],["79980.53000000","0.01763000"],["79980.61000000","0.00014000"],["79980.62000000","0.03021000"],["79980.72000000","0.00014000"],["79980.73000000","0.03824000"],["79980.97000000","0.00007000"],["79981.01000000","0.00007000"],["79981.03000000","0.00007000"],["79981.04000000","0.47979000"],["79981.05000000","0.32793000"],["79981.06000000","0.00014000"],["79981.29000000","0.00014000"],["79981.61000000","0.01653000"],["79981.77000000","0.00008000"]]}}}
{"rx_ns": 10708752290200, "frame": {"stream":"btcusdt@depth@100ms","data":{"e":"depthUpdate","E":1787647703914,"s":"BTCUSDT","U":99116127081,"u":99116127131,"b":[["79980.15000000","0.81076000"],["79980.14000000","0.00097000"],["79979.63000000","0.00014000"],["79979.62000000","0.10835000"],["79979.05000000","0.08801000"],["79979.04000000","0.00000000"],["79979.03000000","0.00935000"],["79978.75000000","0.00000000"],["79978.74000000","0.00014000"],["79977.89000000","0.08677000"],["79977.85000000","0.00000000"],["79976.47000000","0.01814000"],["79973.55000000","0.00014000"],["79890.02000000","0.02084000"],["79841.37000000","0.00000000"],["79840.72000000","0.04528000"],["79772.51000000","0.00770000"],["79770.98000000","0.00000000"],["77500.00000000","13.25468000"],["71982.14000000","0.00416000"],["71982.13000000","0.00008000"]],"a":[["79993.54000000","0.02474000"],["80004.48000000","0.12499000"]]}}}
{"rx_ns": 10708853321200, "frame": {"stream":"btcusdt@depth20@100ms","data":{"lastUpdateId":99116127151,"bids":[["79980.15000000","0.81090000"],["79980.14000000","0.00097000"],["79980.13000000","0.00013000"],["79980.10000000","0.00007000"],["79979.99000000","0.00020000"],["79979.63000000","0.00014000"],["79979.62000000","0.10849000"],["79979.06000000","0.00014000"],["79979.05000000","0.08801000"],["79979.03000000","0.00914000"],["79978.93000000","0.00007000"],["79978.73000000","0.00007000"],["79978.42000000","0.00007000"],["79978.29000000","0.00007000"],["79978.28000000","0.00007000"],["79977.99000000","0.00007000"],["79977.90000000","0.00014000"],["79977.89000000","0.08677000"],["79977.75000000","0.01514000"],["79977.42000000","0.00007000"]],"asks":[["79980.16000000","1.86010000"],["79980.17000000","0.00076000"],["79980.18000000","0.00013000"],["79980.32000000","0.00014000"],["79980.33000000","0.01002000"],["79980.52000000","0.00014000"],["79980.53000000","0.01763000"],["79980.61000000","0.00014000"],["79980.62000000","0.03021000"],["79980.72000000","0.00014000"],["79980.73000000","0.03824000"],["79980.97000000","0.00007000"],["79981.01000000","0.00007000"],["79981.03000000","0.00007000"],["79981.04000000","0.47979000"],["79981.05000000","0.32793000"],["79981.06000000","0.00014000"],["79981.29000000","0.00014000"],["79981.61000000","0.01653000"],["79981.77000000","0.00008000"]]}}}
{"rx_ns": 10708853400700, "frame": {"stream":"btcusdt@depth@100ms","data":{"e":"depthUpdate","E":1787647704014,"s":"BTCUSDT","U":99116127132,"u":99116127151,"b":[["79980.15000000","0.81090000"],["79979.62000000","0.10849000"],["79979.03000000","0.00914000"],["79978.74000000","0.00000000"],["79972.25000000","0.00800000"],["79966.97000000","0.00000000"],["79890.02000000","0.00000000"],["71982.14000000","0.00448000"],["63984.12000000","0.00031000"]],"a":[]}}}
{"rx_ns": 10708957054400, "frame": {"stream":"btcusdt@depth20@100ms","data":{"lastUpdateId":99116127167,"bids":[["79980.15000000","0.81083000"],["79980.14000000","0.00097000"],["79980.13000000","0.00013000"],["79980.10000000","0.00007000"],["79979.99000000","0.00020000"],["79979.63000000","0.14612000"],["79979.62000000","0.10856000"],["79979.07000000","0.00014000"],["79979.06000000","0.08654000"],["79979.05000000","0.00014000"],["79979.03000000","0.00914000"],["79978.93000000","0.00007000"],["79978.73000000","0.00007000"],["79978.42000000","0.00007000"],["79978.29000000","0.00007000"],["79978.28000000","0.00007000"],["79977.99000000","0.00007000"],["79977.90000000","0.00014000"],["79977.89000000","0.08677000"],["79977.75000000","0.01514000"]],"asks":[["79980.16000000","1.86010000"],["79980.17000000","0.00076000"],["79980.18000000","0.00013000"],["79980.32000000","0.00014000"],["79980.33000000","0.01002000"],["79980.52000000","0.00014000"],["79980.53000000","0.01763000"],["79980.61000000","0.00014000"],["79980.62000000","0.03021000"],["79980.72000000","0.00014000"],["79980.73000000","0.03824000"],["79980.97000000","0.00007000"],["79981.01000000","0.00007000"],["79981.03000000","0.00007000"],["79981.04000000","0.47979000"],["79981.05000000","0.32793000"],["79981.06000000","0.00014000"],["79981.29000000","0.00014000"],["79981.61000000","0.01653000"],["79981.77000000","0.00008000"]]}}}
{"rx_ns": 10708957133400, "frame": {"stream":"btcusdt@depth@100ms","data":{"e":"depthUpdate","E":1787647704114,"s":"BTCUSDT","U":99116127152,"u":99116127167,"b":[["79980.15000000","0.81083000"],["79979.63000000","0.14612000"],["79979.62000000","0.10856000"],["79979.07000000","0.00014000"],["79979.06000000","0.08654000"],["79979.05000000","0.00014000"],["79976.77000000","0.00000000"],["78780.44000000","0.00030000"],["71982.14000000","0.00432000"]],"a":[["81000.00000000","23.32062000"]]}}}
{"rx_ns": 10709054132300, "frame": {"stream":"btcusdt@depth20@100ms","data":{"lastUpdateId":99116127206,"bids":[["79980.15000000","0.98702000"],["79980.14000000","0.00090000"],["79980.13000000","0.00013000"],["79980.10000000","0.00007000"],["79979.99000000","0.00020000"],["79979.64000000","0.00014000"],["79979.63000000","0.14626000"],["79979.62000000","0.10856000"],["79979.07000000","0.00014000"],["79979.06000000","0.08640000"],["79979.03000000","0.00914000"],["79978.93000000","0.00007000"],["79978.73000000","0.00007000"],["79978.42000000","0.00007000"],["79978.29000000","0.00007000"],["79978.28000000","0.00007000"],["79977.99000000","0.00007000"],["79977.90000000","0.00014000"],["79977.89000000","0.08677000"],["79977.75000000","0.01514000"]],"asks":[["79980.16000000","1.86010000"],["79980.17000000","0.00076000"],["79980.18000000","0.00013000"],["79980.32000000","0.00014000"],["79980.33000000","0.01002000"],["79980.52000000","0.00014000"],["79980.53000000","0.01763000"],["79980.61000000","0.00014000"],["79980.62000000","0.03021000"],["79980.72000000","0.00014000"],["79980.73000000","0.03824000"],["79980.97000000","0.00007000"],["79981.01000000","0.00007000"],["79981.03000000","0.00007000"],["79981.04000000","0.47979000"],["79981.05000000","0.32793000"],["79981.06000000","0.00014000"],["79981.29000000","0.00014000"],["79981.61000000","0.01653000"],["79981.77000000","0.00008000"]]}}}
{"rx_ns": 10709054297300, "frame": {"stream":"btcusdt@depth@100ms","data":{"e":"depthUpdate","E":1787647704214,"s":"BTCUSDT","U":99116127168,"u":99116127206,"b":[["79980.15000000","0.98702000"],["79980.14000000","0.00090000"],["79979.64000000","0.00014000"],["79979.63000000","0.14626000"],["79979.62000000","0.10856000"],["79979.06000000","0.08640000"],["79979.05000000","0.00000000"],["79976.47000000","0.02002000"],["79976.29000000","0.00007000"],["79972.25000000","0.00000000"],["79966.97000000","0.00800000"],["79889.05000000","0.62498000"],["79886.41000000","0.00000000"],["71982.14000000","0.00432000"],["63984.12000000","0.00000000"]],"a":[]}}}
{"rx_ns": 10709154390900, "frame": {"stream":"btcusdt@depth20@100ms","data":{"lastUpdateId":99116127230,"bids":[["79980.15000000","1.15892000"],["79980.14000000","0.00090000"],["79980.13000000","0.00013000"],["79980.10000000","0.00007000"],["79979.99000000","0.00020000"],["79979.64000000","0.00014000"],["79979.63000000","0.14626000"],["79979.62000000","0.10849000"],["79979.03000000","0.00914000"],["79978.93000000","0.00007000"],["79978.73000000","0.00007000"],["79978.42000000","0.00007000"],["79978.29000000","0.00007000"],["79978.28000000","0.00007000"],["79977.99000000","0.00007000"],["79977.90000000","0.00014000"],["79977.89000000","0.08677000"],["79977.75000000","0.01514000"],["79977.42000000","0.00007000"],["79977.20000000","0.00014000"]],"asks":[["79980.16000000","1.34025000"],["79980.17000000","0.00076000"],["79980.18000000","0.00013000"],["79980.32000000","0.00014000"],["79980.33000000","0.01002000"],["79980.52000000","0.00014000"],["79980.53000000","0.01763000"],["79980.61000000","0.00014000"],["79980.62000000","0.11021000"],["79980.72000000","0.00014000"],["79980.73000000","0.03824000"],["79980.97000000","0.00007000"],["79981.01000000","0.00007000"],["79981.03000000","0.00007000"],["79981.04000000","0.47979000"],["79981.05000000","0.32793000"],["79981.06000000","0.00014000"],["79981.29000000","0.00014000"],["79981.61000000","0.01653000"],["79981.77000000","0.00008000"]]}}}
{"rx_ns": 10709154490400, "frame": {"stream":"btcusdt@depth@100ms","data":{"e":"depthUpdate","E":1787647704315,"s":"BTCUSDT","U":99116127207,"u":99116127230,"b":[["79980.15000000","1.15892000"],["79979.62000000","0.10849000"],["79979.07000000","0.00000000"],["79979.06000000","0.00000000"],["79976.77000000","0.00007000"],["79968.02000000","0.00162000"],["79967.04000000","0.00000000"],["79944.00000000","0.72400000"],["79942.93000000","0.27501000"],["79942.00000000","0.02400000"],["71982.14000000","0.00432000"],["63984.00000000","0.00014000"],["42091.80000000","0.00000000"]],"a":[["79980.16000000","1.34025000"],["79980.62000000","0.11021000"],["81179.87000000","0.00030000"]]}}}
{"rx_ns": 10709252312400, "frame": {"stream":"btcusdt@depth20@100ms","data":{"lastUpdateId":99116127252,"bids":[["79980.15000000","1.39892000"],["79980.14000000","0.00090000"],["79980.13000000","0.00013000"],["79980.10000000","0.00007000"],["79979.99000000","0.00020000"],["79979.64000000","0.00014000"],["79979.63000000","0.14626000"],["79979.62000000","0.10849000"],["79979.03000000","0.00914000"],["79978.93000000","0.00007000"],["79978.73000000","0.00007000"],["79978.42000000","0.00007000"],["79978.29000000","0.00007000"],["79978.28000000","0.00007000"],["79977.99000000","0.00007000"],["79977.90000000","0.00014000"],["79977.89000000","0.08677000"],["79977.75000000","0.01514000"],["79977.42000000","0.00007000"],["79977.20000000","0.00014000"]],"asks":[["79980.16000000","1.34046000"],["79980.17000000","0.00076000"],["79980.18000000","0.00013000"],["79980.32000000","0.00014000"],["79980.33000000","0.01002000"],["79980.52000000","0.00014000"],["79980.53000000","0.01763000"],["79980.61000000","0.00014000"],["79980.62000000","0.11021000"],["79980.72000000","0.00014000"],["79980.73000000","0.03824000"],["79980.97000000","0.00007000"],["79981.01000000","0.00007000"],["79981.03000000","0.00007000"],["79981.04000000","0.47979000"],["79981.05000000","0.32793000"],["79981.06000000","0.00014000"],["79981.29000000","0.00014000"],["79981.61000000","0.01653000"],["79981.77000000","0.00008000"]]}}}
{"rx_ns": 10709252390700, "frame": {"stream":"btcusdt@depth@100ms","data":{"e":"depthUpdate","E":1787647704414,"s":"BTCUSDT","U":99116127231,"u":99116127252,"b":[["79980.15000000","1.39892000"],["79979.62000000","0.10849000"],["79964.91000000","0.00007000"],["71982.14000000","0.00448000"],["63984.12000000","0.00020000"]],"a":[["79980.16000000","1.34046000"],["79996.91000000","0.00007000"],["80064.03000000","1.63213000"],["81096.89000000","0.00246000"]]}}}
{"rx_ns": 10709352288600, "frame": {"stream":"btcusdt@depth20@100ms","data":{"lastUpdateId":99116127283,"bids":[["79980.15000000","0.98589000"],["79980.14000000","0.00090000"],["79980.13000000","0.00013000"],["79980.10000000","0.00007000"],["79979.99000000","0.00020000"],["79979.64000000","0.00014000"],["79979.63000000","0.14626000"],["79979.62000000","0.10849000"],["79979.03000000","0.00928000"],["79978.93000000","0.00007000"],["79978.73000000","0.00007000"],["79978.42000000","0.00007000"],["79978.29000000","0.00007000"],["79978.28000000","0.00007000"],["79977.99000000","0.00007000"],["79977.90000000","0.00014000"],["79977.89000000","0.08677000"],["79977.75000000","0.01514000"],["79977.42000000","0.00007000"],["79977.20000000","0.00014000"]],"asks":[["79980.16000000","1.33909000"],["79980.17000000","0.00076000"],["79980.18000000","0.00013000"],["79980.32000000","0.00014000"],["79980.33000000","0.01002000"],["79980.52000000","0.00014000"],["79980.53000000","0.01763000"],["79980.61000000","0.00014000"],["79980.62000000","0.11021000"],["79980.72000000","0.00014000"],["79980.73000000","0.03824000"],["79980.97000000","0.00007000"],["79981.01000000","0.00007000"],["79981.03000000","0.00007000"],["79981.04000000","0.47979000"],["79981.05000000","0.32793000"],["79981.06000000","0.00014000"],["79981.29000000","0.00014000"],["79981.61000000","0.01653000"],["79981.77000000","0.00008000"]]}}}
{"rx_ns": 10709352392300, "frame": {"stream":"btcusdt@depth@100ms","data":{"e":"depthUpdate","E":1787647704514,"s":"BTCUSDT","U":99116127253,"u":99116127283,"b":[["79980.15000000","0.98589000"],["79979.03000000","0.00928000"],["79976.47000000","0.02016000"],["79975.19000000","0.01821000"],["79975.07000000","0.08663000"],["79975.06000000","0.34914000"],["79975.05000000","0.42228000"],["79974.97000000","0.00000000"],["79974.96000000","0.00000000"],["79974.50000000","0.00000000"],["79973.37000000","0.00000000"],["79972.16000000","0.00000000"],["71982.14000000","0.00432000"],["63984.12000000","0.00031000"]],"a":[["79980.16000000","1.33909000"]]}}}
{"rx_ns": 10709452475400, "frame": {"stream":"btcusdt@depth20@100ms","data":{"lastUpdateId":99116127304,"bids":[["79980.15000000","0.98603000"],["79980.14000000","0.00097000"],["79980.13000000","0.00013000"],["79980.10000000","0.00007000"],["79979.99000000","0.00020000"],["79979.65000000","0.00014000"],["79979.64000000","0.08677000"],["79979.63000000","0.14626000"],["79979.62000000","0.10849000"],["79979.03000000","0.00928000"],["79978.93000000","0.00007000"],["79978.73000000","0.00007000"],["79978.42000000","0.00007000"],["79978.29000000","0.00007000"],["79978.28000000","0.00007000"],["79977.99000000","0.00007000"],["79977.90000000","0.00014000"],["79977.89000000","0.08677000"],["79977.75000000","0.01514000"],["79977.42000000","0.00007000"]],"asks":[["79980.16000000","1.18831000"],["79980.17000000","0.00076000"],["79980.18000000","0.00013000"],["79980.32000000","0.00014000"],["79980.33000000","0.01002000"],["79980.52000000","0.00014000"],["79980.53000000","0.01763000"],["79980.61000000","0.00014000"],["79980.62000000","0.11021000"],["79980.72000000","0.00014000"],["79980.73000000","0.03824000"],["79980.97000000","0.00007000"],["79981.01000000","0.00007000"],["79981.03000000","0.00007000"],["79981.04000000","0.47979000"],["79981.05000000","0.32793000"],["79981.06000000","0.00014000"],["79981.29000000","0.00014000"],["79981.61000000","0.01653000"],["79981.77000000","0.00008000"]]}}}
{"rx_ns": 10709452687800, "frame": {"stream":"btcusdt@depth@100ms","data":{"e":"depthUpdate","E":1787647704614,"s":"BTCUSDT","U":99116127284,"u":99116127304,"b":[["79980.15000000","0.98603000"],["79980.14000000","0.00097000"],["79979.65000000","0.00014000"],["79979.64000000","0.08677000"],["79976.77000000","0.00000000"],["79975.19000000","0.01821000"],["79974.71000000","0.31269000"],["79967.53000000","0.00000000"],["71982.14000000","0.00448000"],["71982.00000000","0.00000000"],["63984.12000000","0.00000000"]],"a":[["79980.16000000","1.18831000"],["79989.01000000","0.00400000"],["79989.89000000","0.00000000"],["79989.90000000","0.00000000"]]}}}
{"rx_ns": 10709552410800, "frame": {"stream":"btcusdt@depth20@100ms","data":{"lastUpdateId":99116127321,"bids":[["79980.15000000","0.98651000"],["79980.14000000","0.00097000"],["79980.13000000","0.00013000"],["79980.10000000","0.00007000"],["79979.99000000","0.00020000"],["79979.65000000","0.00014000"],["79979.64000000","0.08677000"],["79979.63000000","0.14626000"],["79979.62000000","0.10849000"],["79979.03000000","0.00928000"],["79978.93000000","0.00007000"],["79978.73000000","0.00007000"],["79978.42000000","0.00007000"],["79978.29000000","0.00007000"],["79978.28000000","0.00007000"],["79977.99000000","0.00007000"],["79977.90000000","0.00014000"],["79977.89000000","0.08677000"],["79977.75000000","0.01514000"],["79977.42000000","0.00007000"]],"asks":[["79980.16000000","1.39081000"],["79980.17000000","0.00076000"],["79980.18000000","0.00013000"],["79980.32000000","0.00014000"],["79980.33000000","0.01002000"],["79980.52000000","0.00014000"],["79980.53000000","0.01763000"],["79980.61000000","0.00014000"],["79980.62000000","0.11021000"],["79980.72000000","0.00014000"],["79980.73000000","0.03824000"],["79980.97000000","0.00007000"],["79981.01000000","0.00007000"],["79981.03000000","0.00007000"],["79981.04000000","0.47979000"],["79981.05000000","0.32793000"],["79981.06000000","0.00014000"],["79981.29000000","0.00014000"],["79981.61000000","0.01653000"],["79981.77000000","0.00008000"]]}}}
{"rx_ns": 10709552525600, "frame": {"stream":"btcusdt@depth@100ms","data":{"e":"depthUpdate","E":1787647704714,"s":"BTCUSDT","U":99116127305,"u":99116127321,"b":[["79980.15000000","0.98651000"],["79976.47000000","0.02002000"],["79972.24000000","0.00000000"],["79934.85000000","0.00000000"],["71982.14000000","0.00432000"]],"a":[["79980.16000000","1.39081000"]]}}}
{"rx_ns": 10709652922900, "frame": {"stream":"btcusdt@depth20@100ms","data":{"lastUpdateId":99116127329,"bids":[["79980.15000000","0.98651000"],["79980.14000000","0.00097000"],["79980.13000000","0.00013000"],["79980.10000000","0.00007000"],["79979.99000000","0.00020000"],["79979.65000000","0.00014000"],["79979.64000000","0.08677000"],["79979.63000000","0.14626000"],["79979.62000000","0.10849000"],["79979.03000000","0.00928000"],["79978.93000000","0.00007000"],["79978.73000000","0.00007000"],["79978.42000000","0.00007000"],["79978.29000000","0.00007000"],["79978.28000000","0.00007000"],["79977.99000000","0.00007000"],["79977.90000000","0.00014000"],["79977.89000000","0.08677000"],["79977.75000000","0.01514000"],["79977.42000000","0.00007000"]],"asks":[["79980.16000000","1.39081000"],["79980.17000000","0.00076000"],["79980.18000000","0.00013000"],["79980.32000000","0.00014000"],["79980.33000000","0.01002000"],["79980.52000000","0.00014000"],["79980.53000000","0.01763000"],["79980.61000000","0.00014000"],["79980.62000000","0.11021000"],["79980.72000000","0.00014000"],["79980.73000000","0.03824000"],["79980.97000000","0.00007000"],["79981.01000000","0.00007000"],["79981.03000000","0.00007000"],["79981.04000000","0.47979000"],["79981.05000000","0.32793000"],["79981.06000000","0.00014000"],["79981.29000000","0.00014000"],["79981.61000000","0.01653000"],["79981.77000000","0.00008000"]]}}}
{"rx_ns": 10709653000200, "frame": {"stream":"btcusdt@depth@100ms","data":{"e":"depthUpdate","E":1787647704814,"s":"BTCUSDT","U":99116127322,"u":99116127329,"b":[["79898.01000000","0.03133000"],["79890.02000000","0.02084000"],["71982.14000000","0.00432000"]],"a":[["80009.32000000","0.00000000"],["80014.28000000","0.02506000"]]}}}
{"rx_ns": 10709753959800, "frame": {"stream":"btcusdt@depth20@100ms","data":{"lastUpdateId":99116127346,"bids":[["79980.15000000","0.81001000"],["79980.14000000","0.00097000"],["79980.13000000","0.00013000"],["79980.10000000","0.00007000"],["79979.99000000","0.00020000"],["79979.65000000","0.00014000"],["79979.64000000","0.08677000"],["79979.63000000","0.14626000"],["79979.62000000","0.10849000"],["79979.03000000","0.00928000"],["79978.93000000","0.00007000"],["79978.73000000","0.00007000"],["79978.42000000","0.00007000"],["79978.29000000","0.00007000"],["79978.28000000","0.00007000"],["79977.99000000","0.00007000"],["79977.90000000","0.00014000"],["79977.89000000","0.08677000"],["79977.75000000","0.01514000"],["79977.42000000","0.00007000"]],"asks":[["79980.16000000","1.39081000"],["79980.17000000","0.00076000"],["79980.18000000","0.00013000"],["79980.32000000","0.00014000"],["79980.33000000","0.01002000"],["79980.52000000","0.00014000"],["79980.53000000","0.01763000"],["79980.61000000","0.00014000"],["79980.62000000","0.11021000"],["79980.72000000","0.00014000"],["79980.73000000","0.03824000"],["79980.97000000","0.00007000"],["79981.01000000","0.00007000"],["79981.03000000","0.00007000"],["79981.04000000","0.47979000"],["79981.05000000","0.32793000"],["79981.06000000","0.00014000"],["79981.29000000","0.00014000"],["79981.61000000","0.01653000"],["79981.77000000","0.00008000"]]}}}
{"rx_ns": 10709754043000, "frame": {"stream":"btcusdt@depth@100ms","data":{"e":"depthUpdate","E":1787647704914,"s":"BTCUSDT","U":99116127330,"u":99116127346,"b":[["79980.15000000","0.81001000"],["79898.01000000","0.00007000"],["79890.02000000","0.00000000"]],"a":[["79989.01000000","0.00000000"],["80115.00000000","0.00037000"]]}}}
{"rx_ns": 10709856141900, "frame": {"stream":"btcusdt@depth20@100ms","data":{"lastUpdateId":99116127357,"bids":[["79980.15000000","0.60751000"],["79980.14000000","0.00097000"],["79980.13000000","0.00013000"],["79980.10000000","0.00007000"],["79979.99000000","0.00020000"],["79979.65000000","0.00014000"],["79979.64000000","0.00014000"],["79979.63000000","0.14626000"],["79979.62000000","0.00014000"],["79979.03000000","0.00928000"],["79978.93000000","0.00007000"],["79978.73000000","0.00007000"],["79978.42000000","0.00007000"],["79978.29000000","0.00007000"],["79978.28000000","0.00007000"],["79977.99000000","0.00007000"],["79977.90000000","0.00014000"],["79977.89000000","0.08677000"],["79977.75000000","0.01514000"],["79977.42000000","0.00007000"]],"asks":[["79980.16000000","1.39081000"],["79980.17000000","0.00076000"],["79980.18000000","0.00013000"],["79980.32000000","0.00014000"],["79980.33000000","0.01002000"],["79980.52000000","0.00014000"],["79980.53000000","0.01763000"],["79980.61000000","0.00014000"],["79980.62000000","0.11021000"],["79980.72000000","0.00014000"],["79980.73000000","0.03824000"],["79980.97000000","0.00007000"],["79981.01000000","0.00007000"],["79981.03000000","0.00007000"],["79981.04000000","0.47979000"],["79981.05000000","0.32793000"],["79981.06000000","0.00014000"],["79981.29000000","0.00014000"],["79981.61000000","0.01653000"],["79981.77000000","0.00008000"]]}}}
{"rx_ns": 10709856284500, "frame": {"stream":"btcusdt@depth@100ms","data":{"e":"depthUpdate","E":1787647705014,"s":"BTCUSDT","U":99116127347,"u":99116127357,"b":[["79980.15000000","0.60751000"],["79979.64000000","0.00014000"],["79979.62000000","0.00014000"],["79973.59000000","0.00000000"],["79908.12000000","0.00000000"],["79827.18000000","0.00000000"],["71982.14000000","0.00432000"],["63984.12000000","0.00031000"]],"a":[]}}}
{"rx_ns": 10709958527300, "frame": {"stream":"btcusdt@depth20@100ms","data":{"lastUpdateId":99116127402,"bids":[["79980.15000000","0.60723000"],["79980.14000000","0.00083000"],["79980.13000000","0.00013000"],["79980.10000000","0.00007000"],["79979.99000000","0.00020000"],["79979.64000000","0.00014000"],["79979.63000000","0.08759000"],["79979.03000000","0.00928000"],["79978.93000000","0.00007000"],["79978.73000000","0.00007000"],["79978.42000000","0.00007000"],["79978.29000000","0.00007000"],["79978.28000000","0.00007000"],["79977.99000000","0.00007000"],["79977.90000000","0.00014000"],["79977.89000000","0.08677000"],["79977.76000000","0.00014000"],["79977.75000000","0.01514000"],["79977.42000000","0.00007000"],["79977.20000000","0.00014000"]],"asks":[["79980.16000000","1.39073000"],["79980.17000000","0.00076000"],["79980.18000000","0.00013000"],["79980.32000000","0.00014000"],["79980.33000000","0.01002000"],["79980.52000000","0.00014000"],["79980.53000000","0.01763000"],["79980.61000000","0.00014000"],["79980.62000000","0.11021000"],["79980.72000000","0.00014000"],["79980.73000000","0.03824000"],["79980.97000000","0.00007000"],["79981.01000000","0.00007000"],["79981.03000000","0.00007000"],["79981.04000000","0.47979000"],["79981.05000000","0.32793000"],["79981.06000000","0.00014000"],["79981.29000000","0.00014000"],["79981.61000000","0.01653000"],["79981.77000000","0.00008000"]]}}}
{"rx_ns": 10709958618700, "frame": {"stream":"btcusdt@depth@100ms","data":{"e":"depthUpdate","E":1787647705114,"s":"BTCUSDT","U":99116127358,"u":99116127402,"b":[["79980.15000000","0.60723000"],["79980.14000000","0.00083000"],["79979.65000000","0.00000000"],["79979.63000000","0.08759000"],["79979.62000000","0.00000000"],["79977.76000000","0.00014000"],["79976.77000000","0.00014000"],["79976.48000000","0.00000000"],["79976.47000000","0.02016000"],["79976.00000000","0.02428000"],["79975.05000000","0.42235000"],["79974.46000000","0.01629000"],["79968.02000000","0.00000000"],["79967.41000000","0.00578000"],["79967.04000000","0.00162000"],["79908.12000000","0.00311000"],["79827.18000000","0.00125000"],["78780.44000000","0.00030000"],["71982.14000000","0.00432000"],["71982.13000000","0.00000000"],["71982.12000000","0.00008000"]],"a":[["79980.16000000","1.39073000"]]}}}
{"rx_ns": 10710052818100, "frame": {"stream":"btcusdt@depth20@100ms","data":{"lastUpdateId":99116127562,"bids":[["79980.15000000","0.01440000"],["79980.14000000","0.00069000"],["79980.13000000","0.00013000"],["79980.10000000","0.00007000"],["79979.99000000","0.00020000"],["79979.63000000","0.00014000"],["79979.03000000","0.00928000"],["79978.93000000","0.00007000"],["79978.73000000","0.00007000"],["79978.42000000","0.00007000"],["79978.29000000","0.00007000"],["79978.28000000","0.00007000"],["79977.99000000","0.00007000"],["79977.89000000","0.00014000"],["79977.76000000","0.00014000"],["79977.75000000","0.01514000"],["79977.42000000","0.00007000"],["79977.20000000","0.00014000"],["79977.19000000","0.04739000"],["79976.96000000","0.00007000"]],"asks":[["79980.16000000","1.56735000"],["79980.17000000","0.00027000"],["79980.18000000","0.00013000"],["79980.32000000","0.00014000"],["79980.33000000","0.01002000"],["79980.52000000","0.00014000"],["79980.53000000","0.01770000"],["79980.61000000","0.06904000"],["79980.62000000","0.11021000"],["79980.72000000","0.00014000"],["79980.73000000","0.03831000"],["79980.78000000","0.03224000"],["79980.97000000","0.00007000"],["79981.01000000","0.00007000"],["79981.03000000","0.00007000"],["79981.04000000","0.47979000"],["79981.05000000","0.32793000"],["79981.06000000","0.00014000"],["79981.29000000","0.00014000"],["79981.61000000","0.01653000"]]}}}
{"rx_ns": 10710052897400, "frame": {"stream":"btcusdt@depth@100ms","data":{"e":"depthUpdate","E":1787647705214,"s":"BTCUSDT","U":99116127403,"u":99116127562,"b":[["79980.15000000","0.01440000"],["79980.14000000","0.00069000"],["79979.64000000","0.00000000"],["79979.63000000","0.00014000"],["79979.03000000","0.00928000"],["79977.91000000","0.00000000"],["79977.90000000","0.00000000"],["79977.89000000","0.00014000"],["79976.77000000","0.00000000"],["79976.76000000","0.00014000"],["79976.48000000","0.00014000"],["79976.01000000","0.00007000"],["79975.06000000","0.21256000"],["79975.05000000","0.00020000"],["79973.55000000","0.00007000"],["79971.56000000","0.18919000"],["79970.48000000","0.00000000"],["79969.68000000","0.00007000"],["79968.76000000","0.08125000"],["79967.56000000","0.00000000"],["79967.41000000","0.00000000"],["79967.04000000","0.00000000"],["79966.97000000","0.00000000"],["79934.85000000","0.00007000"],["79890.02000000","0.02084000"],["79889.05000000","0.00000000"],["79886.41000000","0.62498000"],["79821.30000000","0.00000000"],["71982.14000000","0.00432000"],["63984.12000000","0.00000000"]],"a":[["79980.16000000","1.56735000"],["79980.17000000","0.00027000"],["79980.53000000","0.01770000"],["79980.61000000","0.06904000"],["79980.73000000","0.03831000"],["79980.78000000","0.03224000"],["79981.04000000","0.47979000"],["79981.05000000","0.32793000"],["79981.34000000","0.00000000"],["79982.42000000","0.07959000"],["79983.49000000","0.00000000"],["79983.50000000","0.08670000"],["79983.98000000","0.00400000"],["79984.66000000","0.87174000"],["79987.43000000","0.00000000"],["79987.94000000","1.87060000"],["79988.23000000","0.36586000"],["79990.64000000","0.00000000"],["79996.51000000","0.02000000"],["80133.34000000","0.00000000"]]}}}
{"rx_ns": 10710152603500, "frame": {"stream":"btcusdt@depth20@100ms","data":{"lastUpdateId":99116127658,"bids":[["79980.15000000","0.01424000"],["79980.14000000","0.00069000"],["79980.13000000","0.00013000"],["79980.10000000","0.00007000"],["79979.99000000","0.00020000"],["79979.03000000","0.00928000"],["79978.93000000","0.00007000"],["79978.73000000","0.00007000"],["79978.42000000","0.00007000"],["79978.29000000","0.00007000"],["79978.28000000","0.00007000"],["79977.99000000","0.00007000"],["79977.77000000","0.00014000"],["79977.76000000","0.00014000"],["79977.75000000","0.01514000"],["79977.42000000","0.00007000"],["79977.20000000","0.00014000"],["79977.19000000","0.04732000"],["79976.90000000","0.00007000"],["79976.85000000","0.00007000"]],"asks":[["79980.16000000","1.56715000"],["79980.17000000","0.00027000"],["79980.18000000","0.00013000"],["79980.32000000","0.00014000"],["79980.33000000","0.01002000"],["79980.52000000","0.00014000"],["79980.53000000","0.01770000"],["79980.61000000","0.06918000"],["79980.62000000","0.11021000"],["79980.72000000","0.00014000"],["79980.73000000","0.03831000"],["79980.78000000","0.03245000"],["79980.97000000","0.00007000"],["79981.01000000","0.00007000"],["79981.02000000","0.84468000"],["79981.03000000","1.04939000"],["79981.04000000","0.00014000"],["79981.05000000","0.32793000"],["79981.06000000","0.00014000"],["79981.29000000","0.00014000"]]}}}
{"rx_ns": 10710152808100, "frame": {"stream":"btcusdt@depth@100ms","data":{"e":"depthUpdate","E":1787647705314,"s":"BTCUSDT","U":99116127563,"u":99116127658,"b":[["79980.15000000","0.01424000"],["79979.63000000","0.00000000"],["79979.03000000","0.00928000"],["79977.89000000","0.00000000"],["79977.77000000","0.00014000"],["79977.76000000","0.00014000"],["79977.19000000","0.04732000"],["79976.96000000","0.00000000"],["79976.76000000","0.00000000"],["79975.73000000","0.00893000"],["79975.63000000","0.08388000"],["79975.19000000","0.01835000"],["79970.35000000","0.07987000"],["79969.68000000","0.00014000"],["79968.85000000","0.08663000"],["79968.02000000","0.08663000"],["79966.97000000","0.08663000"],["79956.22000000","0.00000000"],["79955.35000000","0.15383000"],["79890.02000000","0.00000000"],["79886.41000000","0.00000000"],["79883.77000000","0.62498000"],["71982.14000000","0.00448000"],["63984.00000000","0.00014000"]],"a":[["79980.16000000","1.56715000"],["79980.53000000","0.01770000"],["79980.61000000","0.06918000"],["79980.73000000","0.03831000"],["79980.78000000","0.03245000"],["79981.02000000","0.84468000"],["79981.03000000","1.04939000"],["79981.04000000","0.00014000"],["79981.61000000","0.01639000"],["79981.82000000","0.04000000"],["79982.42000000","0.00000000"],["79983.50000000","0.00007000"],["80525.54000000","0.00018000"],["81179.87000000","0.00030000"]]}}}
{"rx_ns": 10710252122300, "frame": {"stream":"btcusdt@depth20@100ms","data":{"lastUpdateId":99116127698,"bids":[["79980.15000000","0.01417000"],["79980.14000000","0.00069000"],["79980.13000000","0.00013000"],["79980.10000000","0.00007000"],["79979.99000000","0.00020000"],["79979.03000000","0.00928000"],["79978.93000000","0.00007000"],["79978.73000000","0.00007000"],["79978.42000000","0.00007000"],["79978.29000000","0.00007000"],["79978.28000000","0.00007000"],["79977.99000000","0.00007000"],["79977.76000000","0.00014000"],["79977.75000000","0.01514000"],["79977.42000000","0.00007000"],["79977.20000000","0.00014000"],["79977.19000000","0.04732000"],["79976.90000000","0.00007000"],["79976.85000000","0.00007000"],["79976.76000000","0.08663000"]],"asks":[["79980.16000000","1.56722000"],["79980.17000000","0.00027000"],["79980.18000000","0.00013000"],["79980.32000000","0.00014000"],["79980.33000000","0.01002000"],["79980.52000000","0.00014000"],["79980.53000000","0.01770000"],["79980.61000000","0.06918000"],["79980.62000000","0.11021000"],["79980.72000000","0.00014000"],["79980.73000000","0.03824000"],["79980.78000000","0.03245000"],["79980.97000000","0.00007000"],["79981.01000000","0.00007000"],["79981.02000000","0.84482000"],["79981.03000000","1.04953000"],["79981.05000000","0.32779000"],["79981.06000000","0.00014000"],["79981.29000000","0.00014000"],["79981.61000000","0.01639000"]]}}}
{"rx_ns": 10710252209900, "frame": {"stream":"btcusdt@depth@100ms","data":{"e":"depthUpdate","E":1787647705414,"s":"BTCUSDT","U":99116127659,"u":99116127698,"b":[["79980.15000000","0.01417000"],["79977.77000000","0.00000000"],["79976.76000000","0.08663000"],["79976.01000000","0.00014000"],["79975.64000000","0.00007000"],["79972.24000000","0.08663000"],["79972.16000000","0.08663000"],["79972.12000000","0.09887000"],["79970.79000000","0.08118000"],["79968.76000000","0.00007000"],["79966.97000000","0.00000000"],["79964.91000000","0.00000000"],["79955.34000000","0.00000000"],["79951.64000000","1.05045000"],["79883.78000000","0.20001000"],["71982.14000000","0.00432000"],["58750.00000000","1.62929000"]],"a":[["79980.16000000","1.56722000"],["79980.73000000","0.03824000"],["79980.78000000","0.03245000"],["79981.02000000","0.84482000"],["79981.03000000","1.04953000"],["79981.04000000","0.00000000"],["79981.05000000","0.32779000"],["79996.91000000","0.00000000"],["80088.62000000","0.00000000"],["80093.94000000","0.00000000"],["80117.99000000","0.00000000"]]}}}
{"rx_ns": 10710353585800, "frame": {"stream":"btcusdt@depth20@100ms","data":{"lastUpdateId":99116127747,"bids":[["79980.15000000","0.01724000"],["79980.14000000","0.00076000"],["79980.13000000","0.00013000"],["79980.10000000","0.00007000"],["79979.99000000","0.00020000"],["79979.03000000","0.00928000"],["79978.93000000","0.00007000"],["79978.73000000","0.00007000"],["79978.42000000","0.00007000"],["79978.29000000","0.00007000"],["79978.28000000","0.00007000"],["79977.99000000","0.00007000"],["79977.76000000","0.00014000"],["79977.75000000","0.01521000"],["79977.42000000","0.00007000"],["79977.20000000","0.05422000"],["79977.19000000","0.04739000"],["79976.90000000","0.00007000"],["79976.85000000","0.00007000"],["79976.76000000","0.08677000"]],"asks":[["79980.16000000","1.56652000"],["79980.17000000","0.00027000"],["79980.18000000","0.00013000"],["79980.32000000","0.00014000"],["79980.33000000","0.01002000"],["79980.52000000","0.00014000"],["79980.53000000","0.01770000"],["79980.60000000","0.00014000"],["79980.61000000","0.06918000"],["79980.62000000","0.11021000"],["79980.72000000","0.00014000"],["79980.73000000","0.03824000"],["79980.78000000","0.03245000"],["79980.97000000","0.00007000"],["79981.01000000","0.00007000"],["79981.02000000","0.84482000"],["79981.03000000","1.04953000"],["79981.05000000","0.32779000"],["79981.06000000","0.00014000"],["79981.29000000","0.00014000"]]}}}
{"rx_ns": 10710353667600, "frame": {"stream":"btcusdt@depth@100ms","data":{"e":"depthUpdate","E":1787647705514,"s":"BTCUSDT","U":99116127699,"u":99116127747,"b":[["79980.15000000","0.01724000"],["79980.14000000","0.00076000"],["79977.75000000","0.01521000"],["79977.20000000","0.05422000"],["79977.19000000","0.04739000"],["79976.76000000","0.08677000"],["79976.67000000","0.00007000"],["79976.47000000","0.01814000"],["79975.19000000","0.01821000"],["79974.28000000","0.12973000"],["79974.01000000","0.00156000"],["79972.93000000","0.07038000"],["79972.12000000","0.00000000"],["79970.35000000","0.00000000"],["79964.91000000","0.00007000"],["71982.14000000","0.00432000"],["71982.12000000","0.00000000"],["63984.12000000","0.00031000"]],"a":[["79980.16000000","1.56652000"],["79980.60000000","0.00014000"],["79996.91000000","0.00007000"]]}}}
{"rx_ns": 10710452266200, "frame": {"stream":"btcusdt@depth20@100ms","data":{"lastUpdateId":99116127794,"bids":[["79980.15000000","0.01587000"],["79980.14000000","0.00076000"],["79980.13000000","0.00013000"],["79980.10000000","0.00007000"],["79979.99000000","0.00020000"],["79979.03000000","0.00928000"],["79978.93000000","0.00007000"],["79978.73000000","0.00007000"],["79978.42000000","0.00007000"],["79978.29000000","0.00007000"],["79978.28000000","0.00007000"],["79977.99000000","0.00007000"],["79977.89000000","0.08331000"],["79977.76000000","0.00014000"],["79977.75000000","0.01521000"],["79977.42000000","0.00007000"],["79977.20000000","0.05436000"],["79977.19000000","0.04739000"],["79976.90000000","0.00007000"],["79976.85000000","0.00007000"]],"asks":[["79980.16000000","1.56574000"],["79980.17000000","0.00027000"],["79980.18000000","0.00013000"],["79980.32000000","0.00014000"],["79980.33000000","0.01002000"],["79980.52000000","0.00014000"],["79980.53000000","0.01770000"],["79980.60000000","0.00014000"],["79980.61000000","0.06918000"],["79980.62000000","0.11021000"],["79980.72000000","0.00014000"],["79980.73000000","0.03824000"],["79980.78000000","0.03245000"],["79980.97000000","0.00007000"],["79981.01000000","0.00007000"],["79981.02000000","0.84482000"],["79981.03000000","1.04953000"],["79981.05000000","0.32779000"],["79981.06000000","0.00014000"],["79981.29000000","0.00014000"]]}}}
{"rx_ns": 10710452434000, "frame": {"stream":"btcusdt@depth@100ms","data":{"e":"depthUpdate","E":1787647705614,"s":"BTCUSDT","U":99116127748,"u":99116127794,"b":[["79980.15000000","0.01587000"],["79977.89000000","0.08331000"],["79977.75000000","0.01521000"],["79977.20000000","0.05436000"],["79975.63000000","0.08374000"],["79973.81000000","0.09844000"],["79972.93000000","0.00000000"],["79966.64000000","0.00000000"],["79931.68000000","0.00000000"],["79911.66000000","0.90939000"],["79772.51000000","0.00000000"],["79766.63000000","0.00770000"],["79400.00000000","1.48461000"],["71982.14000000","0.00432000"],["63984.12000000","0.00000000"],["42091.80000000","0.00036000"]],"a":[["79980.16000000","1.56574000"],["79983.98000000","0.00000000"],["79996.37000000","0.00000000"],["80039.71000000","0.00000000"],["80059.73000000","0.00000000"]]}}}
{"rx_ns": 10710553197200, "frame": {"stream":"btcusdt@depth20@100ms","data":{"lastUpdateId":99116127859,"bids":[["79980.15000000","0.01423000"],["79980.14000000","0.00076000"],["79980.13000000","0.00013000"],["79980.10000000","0.00007000"],["79979.99000000","0.00020000"],["79979.03000000","0.00935000"],["79978.93000000","0.00007000"],["79978.73000000","0.00007000"],["79978.42000000","0.00007000"],["79978.29000000","0.00007000"],["79978.28000000","0.00007000"],["79977.99000000","0.00007000"],["79977.89000000","0.00014000"],["79977.76000000","0.00014000"],["79977.75000000","0.01521000"],["79977.42000000","0.00007000"],["79977.20000000","0.05316000"],["79977.19000000","0.04739000"],["79976.90000000","0.00007000"],["79976.85000000","0.00007000"]],"asks":[["79980.16000000","1.56560000"],["79980.17000000","0.00027000"],["79980.18000000","0.00013000"],["79980.32000000","0.00014000"],["79980.33000000","0.01002000"],["79980.52000000","0.00014000"],["79980.53000000","0.01770000"],["79980.60000000","0.00014000"],["79980.61000000","0.06918000"],["79980.62000000","0.11021000"],["79980.72000000","0.00014000"],["79980.73000000","0.03824000"],["79980.78000000","0.03245000"],["79980.97000000","0.00007000"],["79981.01000000","0.00007000"],["79981.02000000","0.84482000"],["79981.03000000","1.04953000"],["79981.05000000","0.32779000"],["79981.06000000","0.00014000"],["79981.29000000","0.00014000"]]}}}
{"rx_ns": 10710553275200, "frame": {"stream":"btcusdt@depth@100ms","data":{"e":"depthUpdate","E":1787647705714,"s":"BTCUSDT","U":99116127795,"u":99116127859,"b":[["79980.15000000","0.01423000"],["79980.14000000","0.00076000"],["79979.03000000","0.00935000"],["79977.90000000","0.00000000"],["79977.89000000","0.00014000"],["79977.20000000","0.05316000"],["79975.73000000","0.00879000"],["79974.76000000","0.07202000"],["79973.81000000","0.00000000"],["79972.24000000","0.00000000"],["79972.16000000","0.00000000"],["79827.01000000","0.01958000"],["79813.37000000","0.00000000"],["71982.14000000","0.00448000"],["71982.00000000","0.00000000"]],"a":[["79980.16000000","1.56560000"],["79991.60000000","0.01307000"]]}}}
{"rx_ns": 10710652199900, "frame": {"stream":"btcusdt@depth20@100ms","data":{"lastUpdateId":99116127880,"bids":[["79980.15000000","0.01430000"],["79980.14000000","0.00076000"],["79980.13000000","0.00013000"],["79980.10000000","0.00007000"],["79979.99000000","0.00020000"],["79979.03000000","0.00928000"],["79978.93000000","0.00007000"],["79978.73000000","0.00007000"],["79978.42000000","0.00007000"],["79978.29000000","0.00007000"],["79978.28000000","0.00007000"],["79977.99000000","0.00007000"],["79977.76000000","0.00014000"],["79977.75000000","0.01521000"],["79977.42000000","0.00007000"],["79977.20000000","0.05316000"],["79977.19000000","0.04739000"],["79976.90000000","0.00007000"],["79976.85000000","0.00007000"],["79976.76000000","0.08677000"]],"asks":[["79980.16000000","1.56560000"],["79980.17000000","0.00027000"],["79980.18000000","0.00013000"],["79980.32000000","0.00014000"],["79980.33000000","0.01002000"],["79980.52000000","0.00014000"],["79980.53000000","0.01770000"],["79980.60000000","0.00014000"],["79980.61000000","0.06918000"],["79980.62000000","0.11021000"],["79980.72000000","0.00014000"],["79980.73000000","0.03824000"],["79980.78000000","0.03245000"],["79980.97000000","0.00007000"],["79981.01000000","0.00007000"],["79981.02000000","0.84482000"],["79981.03000000","1.04953000"],["79981.05000000","0.32779000"],["79981.06000000","0.00014000"],["79981.29000000","0.00014000"]]}}}
{"rx_ns": 10710652277400, "frame": {"stream":"btcusdt@depth@100ms","data":{"e":"depthUpdate","E":1787647705814,"s":"BTCUSDT","U":99116127860,"u":99116127880,"b":[["79980.15000000","0.01430000"],["79980.14000000","0.00076000"],["79979.03000000","0.00928000"],["79977.89000000","0.00000000"],["79975.73000000","0.00893000"],["79975.06000000","0.21263000"],["79972.16000000","0.08663000"],["79964.24000000","0.00162000"],["71982.14000000","0.00416000"]],"a":[]}}}
{"rx_ns": 10710763787300, "frame": {"stream":"btcusdt@depth20@100ms","data":{"lastUpdateId":99116127888,"bids":[["79980.15000000","0.01673000"],["79980.14000000","0.00076000"],["79980.13000000","0.00013000"],["79980.10000000","0.00007000"],["79979.99000000","0.00020000"],["79979.03000000","0.00928000"],["79978.93000000","0.00007000"],["79978.73000000","0.00007000"],["79978.42000000","0.00007000"],["79978.29000000","0.00007000"],["79978.28000000","0.00007000"],["79977.99000000","0.00007000"],["79977.89000000","0.08663000"],["79977.76000000","0.00014000"],["79977.75000000","0.01521000"],["79977.42000000","0.00007000"],["79977.20000000","0.05316000"],["79977.19000000","0.04739000"],["79976.90000000","0.00007000"],["79976.85000000","0.00007000"]],"asks":[["79980.16000000","1.56560000"],["79980.17000000","0.00027000"],["79980.18000000","0.00013000"],["79980.32000000","0.00014000"],["79980.33000000","0.01002000"],["79980.52000000","0.00014000"],["79980.53000000","0.01770000"],["79980.60000000","0.00014000"],["79980.61000000","0.06918000"],["79980.62000000","0.11021000"],["79980.72000000","0.00014000"],["79980.73000000","0.03824000"],["79980.78000000","0.03245000"],["79980.97000000","0.00007000"],["79981.01000000","0.00007000"],["79981.02000000","0.84482000"],["79981.03000000","1.04953000"],["79981.05000000","0.32779000"],["79981.06000000","0.00014000"],["79981.29000000","0.00014000"]]}}}
{"rx_ns": 10710763872400, "frame": {"stream":"btcusdt@depth@100ms","data":{"e":"depthUpdate","E":1787647705914,"s":"BTCUSDT","U":99116127881,"u":99116127888,"b":[["79980.15000000","0.01673000"],["79977.89000000","0.08663000"],["79972.24000000","0.08663000"],["79886.41000000","0.62498000"],["79883.77000000","0.00000000"],["71982.14000000","0.00448000"]],"a":[]}}}
{"rx_ns": 10710855284200, "frame": {"stream":"btcusdt@depth20@100ms","data":{"lastUpdateId":99116127907,"bids":[["79980.15000000","0.01423000"],["79980.14000000","0.00076000"],["79980.13000000","0.00013000"],["79980.10000000","0.00007000"],["79979.99000000","0.00020000"],["79979.03000000","0.00928000"],["79978.93000000","0.00007000"],["79978.73000000","0.00007000"],["79978.42000000","0.00007000"],["79978.29000000","0.00007000"],["79978.28000000","0.00007000"],["79977.99000000","0.00007000"],["79977.89000000","0.08677000"],["79977.76000000","0.00014000"],["79977.75000000","0.01521000"],["79977.42000000","0.00007000"],["79977.20000000","0.05316000"],["79977.19000000","0.04739000"],["79976.90000000","0.00007000"],["79976.85000000","0.00007000"]],"asks":[["79980.16000000","1.56560000"],["79980.17000000","0.00027000"],["79980.18000000","0.00013000"],["79980.32000000","0.00014000"],["79980.33000000","0.01002000"],["79980.52000000","0.00014000"],["79980.53000000","0.01770000"],["79980.60000000","0.00014000"],["79980.61000000","0.06918000"],["79980.62000000","0.11021000"],["79980.72000000","0.00014000"],["79980.73000000","0.03824000"],["79980.78000000","0.03245000"],["79980.97000000","0.00007000"],["79981.01000000","0.00007000"],["79981.02000000","0.84482000"],["79981.03000000","1.04953000"],["79981.05000000","0.32779000"],["79981.06000000","0.00014000"],["79981.29000000","0.00014000"]]}}}
{"rx_ns": 10710855437900, "frame": {"stream":"btcusdt@depth@100ms","data":{"e":"depthUpdate","E":1787647706014,"s":"BTCUSDT","U":99116127889,"u":99116127907,"b":[["79980.15000000","0.01423000"],["79979.03000000","0.00928000"],["79977.89000000","0.08677000"],["79975.73000000","0.00879000"],["79883.78000000","0.01679000"],["79827.01000000","0.00000000"],["79802.27000000","0.01958000"],["78029.24000000","0.00900000"],["71982.14000000","0.00432000"],["63984.12000000","0.00031000"]],"a":[]}}}
{"rx_ns": 10710953947900, "frame": {"stream":"btcusdt@depth20@100ms","data":{"lastUpdateId":99116128070,"bids":[["79980.15000000","1.01426000"],["79980.14000000","0.00083000"],["79980.13000000","0.00013000"],["79980.10000000","0.00007000"],["79979.99000000","0.00020000"],["79979.05000000","0.00014000"],["79979.04000000","0.08663000"],["79979.03000000","0.00928000"],["79978.93000000","0.00007000"],["79978.73000000","0.00007000"],["79978.42000000","0.00007000"],["79978.29000000","0.00007000"],["79978.28000000","0.00007000"],["79977.99000000","0.00007000"],["79977.91000000","0.00014000"],["79977.90000000","0.08367000"],["79977.89000000","0.08677000"],["79977.75000000","0.01521000"],["79977.42000000","0.00007000"],["79977.20000000","0.00028000"]],"asks":[["79980.16000000","1.17866000"],["79980.17000000","0.00076000"],["79980.18000000","0.00013000"],["79980.32000000","0.00014000"],["79980.33000000","0.01002000"],["79980.52000000","0.00014000"],["79980.53000000","0.01770000"],["79980.61000000","0.00028000"],["79980.62000000","0.11021000"],["79980.72000000","0.00014000"],["79980.73000000","0.03824000"],["79980.78000000","0.00021000"],["79980.97000000","0.00007000"],["79981.01000000","0.00014000"],["79981.02000000","0.12862000"],["79981.03000000","0.00014000"],["79981.05000000","0.32779000"],["79981.06000000","0.00014000"],["79981.24000000","0.00580000"],["79981.29000000","0.00007000"]]}}}
{"rx_ns": 10710954024500, "frame": {"stream":"btcusdt@depth@100ms","data":{"e":"depthUpdate","E":1787647706114,"s":"BTCUSDT","U":99116127908,"u":99116128070,"b":[["79980.15000000","1.01426000"],["79980.14000000","0.00083000"],["79979.35000000","0.00000000"],["79979.05000000","0.00014000"],["79979.04000000","0.08663000"],["79979.03000000","0.00928000"],["79977.91000000","0.00014000"],["79977.90000000","0.08367000"],["79977.76000000","0.00000000"],["79977.21000000","0.00000000"],["79977.20000000","0.00028000"],["79976.77000000","0.00007000"],["79976.48000000","0.00000000"],["79976.01000000","0.00000000"],["79976.00000000","0.02435000"],["79975.75000000","0.07804000"],["79975.64000000","0.00000000"],["79975.19000000","0.01807000"],["79975.09000000","0.08663000"],["79975.08000000","0.34128000"],["79975.07000000","0.00000000"],["79975.06000000","0.00000000"],["79974.89000000","0.08118000"],["79974.76000000","0.00000000"],["79973.55000000","0.00014000"],["79973.37000000","0.00000000"],["79972.72000000","0.00000000"],["79972.16000000","0.00000000"],["79970.79000000","0.00000000"],["79970.35000000","0.00000000"],["79968.03000000","0.00162000"],["79967.04000000","0.00000000"],["79965.51000000","0.00008000"],["79964.24000000","0.00000000"],["79963.73000000","0.02400000"],["79958.66000000","0.25044000"],["79951.64000000","0.62539000"],["79923.68000000","0.02400000"],["78780.44000000","0.00030000"],["71982.14000000","0.00448000"]],"a":[["79980.16000000","1.17866000"],["79980.17000000","0.00076000"],["79980.60000000","0.00000000"],["79980.61000000","0.00028000"],["79980.78000000","0.00021000"],["79981.01000000","0.00014000"],["79981.02000000","0.12862000"],["79981.03000000","0.00014000"],["79981.24000000","0.00580000"],["79981.29000000","0.00007000"],["79981.76000000","0.00000000"],["79983.49000000","0.00013000"],["79984.66000000","0.35620000"],["79985.16000000","0.00014000"],["79987.93000000","0.00400000"],["79987.94000000","0.00000000"],["79989.03000000","0.00007000"],["79991.97000000","0.00400000"],["79993.32000000","0.02000000"],["79993.67000000","0.00000000"],["79994.77000000","0.13341000"],["79996.61000000","0.00000000"],["79999.71000000","0.00000000"],["80004.92000000","0.00000000"],["80010.20000000","0.00000000"],["80013.34000000","0.02000000"],["80023.91000000","0.00166000"],["80042.64000000","1.23720000"]]}}}
{"rx_ns": 10711052204400, "frame": {"stream":"btcusdt@depth20@100ms","data":{"lastUpdateId":99116128138,"bids":[["79980.15000000","1.01419000"],["79980.14000000","0.00083000"],["79980.13000000","0.00013000"],["79980.10000000","0.00007000"],["79979.99000000","0.00020000"],["79979.05000000","0.00014000"],["79979.04000000","0.08677000"],["79979.03000000","0.00935000"],["79978.93000000","0.00007000"],["79978.73000000","0.00007000"],["79978.58000000","0.00014000"],["79978.57000000","0.06761000"],["79978.42000000","0.00007000"],["79978.29000000","0.00007000"],["79978.28000000","0.00007000"],["79977.99000000","0.00007000"],["79977.91000000","0.00014000"],["79977.90000000","0.08381000"],["79977.89000000","0.08677000"],["79977.75000000","0.01521000"]],"asks":[["79980.16000000","1.17873000"],["79980.17000000","0.00076000"],["79980.18000000","0.00013000"],["79980.32000000","0.00014000"],["79980.33000000","0.01002000"],["79980.52000000","0.00014000"],["79980.53000000","0.01770000"],["79980.61000000","0.00014000"],["79980.62000000","0.11021000"],["79980.72000000","0.00014000"],["79980.73000000","0.03824000"],["79980.78000000","0.00007000"],["79980.97000000","0.00007000"],["79981.01000000","0.00014000"],["79981.02000000","0.12862000"],["79981.05000000","0.32793000"],["79981.06000000","0.00014000"],["79981.24000000","0.00014000"],["79981.29000000","0.00014000"],["79981.38000000","0.00583000"]]}}}
{"rx_ns": 10711052284700, "frame": {"stream":"btcusdt@depth@100ms","data":{"e":"depthUpdate","E":1787647706214,"s":"BTCUSDT","U":99116128071,"u":99116128138,"b":[["79980.15000000","1.01419000"],["79979.04000000","0.08677000"],["79979.03000000","0.00935000"],["79978.58000000","0.00014000"],["79978.57000000","0.06761000"],["79977.90000000","0.08381000"],["79977.75000000","0.01521000"],["79977.20000000","0.00014000"],["79976.77000000","0.00000000"],["79976.00000000","0.02414000"],["79975.75000000","0.00000000"],["79934.85000000","0.00000000"],["71982.14000000","0.00432000"],["63984.12000000","0.00000000"]],"a":[["79980.16000000","1.17873000"],["79980.53000000","0.01770000"],["79980.61000000","0.00014000"],["79980.73000000","0.03824000"],["79980.78000000","0.00007000"],["79981.02000000","0.12862000"],["79981.03000000","0.00000000"],["79981.05000000","0.32793000"],["79981.24000000","0.00014000"],["79981.29000000","0.00014000"],["79981.38000000","0.00583000"],["79981.61000000","0.01653000"],["79985.16000000","0.00021000"],["79989.03000000","0.00014000"],["80699.97000000","0.00000000"]]}}}
{"rx_ns": 10711152144000, "frame": {"stream":"btcusdt@depth20@100ms","data":{"lastUpdateId":99116128175,"bids":[["79980.15000000","0.83629000"],["79980.14000000","0.00083000"],["79980.13000000","0.00013000"],["79980.10000000","0.00007000"],["79979.99000000","0.00020000"],["79979.05000000","0.00014000"],["79979.04000000","0.08677000"],["79979.03000000","0.00935000"],["79978.93000000","0.00007000"],["79978.73000000","0.00007000"],["79978.58000000","0.00014000"],["79978.57000000","0.06775000"],["79978.42000000","0.00007000"],["79978.29000000","0.00007000"],["79978.28000000","0.00007000"],["79977.99000000","0.00007000"],["79977.91000000","0.00014000"],["79977.90000000","0.08381000"],["79977.89000000","0.08677000"],["79977.75000000","0.01521000"]],"asks":[["79980.16000000","1.17854000"],["79980.17000000","0.00076000"],["79980.18000000","0.00013000"],["79980.32000000","0.00014000"],["79980.33000000","0.01002000"],["79980.52000000","0.00014000"],["79980.53000000","0.01770000"],["79980.61000000","0.00014000"],["79980.62000000","0.11021000"],["79980.72000000","0.00014000"],["79980.73000000","0.03824000"],["79980.78000000","0.00007000"],["79980.97000000","0.00007000"],["79981.01000000","0.00014000"],["79981.02000000","0.12862000"],["79981.05000000","0.32793000"],["79981.06000000","0.00014000"],["79981.29000000","0.00014000"],["79981.38000000","0.00597000"],["79981.61000000","0.01653000"]]}}}
{"rx_ns": 10711152374600, "frame": {"stream":"btcusdt@depth@100ms","data":{"e":"depthUpdate","E":1787647706314,"s":"BTCUSDT","U":99116128139,"u":99116128175,"b":[["79980.15000000","0.83629000"],["79979.03000000","0.00935000"],["79978.57000000","0.06775000"],["79976.47000000","0.01800000"],["79927.30000000","0.00400000"],["79924.38000000","0.00000000"],["71982.14000000","0.00432000"],["63984.00000000","0.00014000"]],"a":[["79980.16000000","1.17854000"],["79980.17000000","0.00076000"],["79981.05000000","0.32793000"],["79981.24000000","0.00000000"],["79981.38000000","0.00597000"],["79996.48000000","0.12500000"],["81179.87000000","0.00030000"]]}}}
{"rx_ns": 10711252784100, "frame": {"stream":"btcusdt@depth20@100ms","data":{"lastUpdateId":99116128188,"bids":[["79980.15000000","1.07663000"],["79980.14000000","0.00083000"],["79980.13000000","0.00013000"],["79980.10000000","0.00007000"],["79979.99000000","0.00020000"],["79979.05000000","0.00014000"],["79979.04000000","0.08677000"],["79979.03000000","0.00935000"],["79978.93000000","0.00007000"],["79978.73000000","0.00007000"],["79978.58000000","0.00014000"],["79978.57000000","0.06775000"],["79978.42000000","0.00007000"],["79978.29000000","0.00007000"],["79978.28000000","0.00007000"],["79977.99000000","0.00007000"],["79977.91000000","0.00014000"],["79977.90000000","0.08381000"],["79977.89000000","0.08677000"],["79977.75000000","0.01521000"]],"asks":[["79980.16000000","1.17902000"],["79980.17000000","0.00076000"],["79980.18000000","0.00013000"],["79980.32000000","0.00014000"],["79980.33000000","0.01002000"],["79980.52000000","0.00014000"],["79980.53000000","0.01770000"],["79980.61000000","0.00014000"],["79980.62000000","0.11021000"],["79980.72000000","0.00014000"],["79980.73000000","0.03824000"],["79980.78000000","0.00007000"],["79980.97000000","0.00007000"],["79981.01000000","0.00014000"],["79981.02000000","0.12862000"],["79981.05000000","0.32793000"],["79981.06000000","0.00014000"],["79981.29000000","0.00014000"],["79981.38000000","0.00597000"],["79981.61000000","0.01653000"]]}}}
{"rx_ns": 10711252865600, "frame": {"stream":"btcusdt@depth@100ms","data":{"e":"depthUpdate","E":1787647706414,"s":"BTCUSDT","U":99116128176,"u":99116128188,"b":[["79980.15000000","1.07663000"],["79934.85000000","0.00007000"],["79923.35000000","0.00428000"],["79648.92000000","0.01903000"],["71982.14000000","0.00432000"]],"a":[["79980.16000000","1.17902000"],["80024.20000000","0.00428000"],["80064.03000000","1.96232000"],["80227.63000000","0.01903000"]]}}}
{"rx_ns": 10711352524300, "frame": {"stream":"btcusdt@depth20@100ms","data":{"lastUpdateId":99116128205,"bids":[["79980.15000000","1.05531000"],["79980.14000000","0.00083000"],["79980.13000000","0.00013000"],["79980.10000000","0.00007000"],["79979.99000000","0.00020000"],["79979.05000000","0.00014000"],["79979.04000000","0.08677000"],["79979.03000000","0.00935000"],["79978.93000000","0.00007000"],["79978.73000000","0.00007000"],["79978.58000000","0.00014000"],["79978.57000000","0.06775000"],["79978.42000000","0.00007000"],["79978.29000000","0.00007000"],["79978.28000000","0.00007000"],["79977.99000000","0.00007000"],["79977.91000000","0.00014000"],["79977.90000000","0.08381000"],["79977.89000000","0.08677000"],["79977.75000000","0.01521000"]],"asks":[["79980.16000000","1.17902000"],["79980.17000000","0.00076000"],["79980.18000000","0.00013000"],["79980.32000000","0.00014000"],["79980.33000000","0.01002000"],["79980.52000000","0.00014000"],["79980.53000000","0.01770000"],["79980.61000000","0.00014000"],["79980.62000000","0.11021000"],["79980.72000000","0.00014000"],["79980.73000000","0.03824000"],["79980.78000000","0.00007000"],["79980.97000000","0.00007000"],["79981.01000000","0.00014000"],["79981.02000000","0.12862000"],["79981.05000000","0.32793000"],["79981.06000000","0.00014000"],["79981.29000000","0.00014000"],["79981.38000000","0.00597000"],["79981.61000000","0.01653000"]]}}}
{"rx_ns": 10711352619400, "frame": {"stream":"btcusdt@depth@100ms","data":{"e":"depthUpdate","E":1787647706514,"s":"BTCUSDT","U":99116128189,"u":99116128205,"b":[["79980.15000000","1.05531000"],["79966.53000000","0.00000000"],["79964.91000000","0.00007000"],["79931.56000000","0.00000000"],["79911.53000000","0.36586000"],["79772.51000000","0.00770000"],["79766.63000000","0.00000000"],["71982.14000000","0.00432000"],["63984.12000000","0.00031000"],["42091.80000000","0.00000000"]],"a":[["79996.51000000","0.00000000"],["79996.91000000","0.00007000"],["80039.77000000","0.00000000"],["80059.79000000","0.00000000"]]}}}
{"rx_ns": 10711461408200, "frame": {"stream":"btcusdt@depth20@100ms","data":{"lastUpdateId":99116128213,"bids":[["79980.15000000","1.01365000"],["79980.14000000","0.00083000"],["79980.13000000","0.00013000"],["79980.10000000","0.00007000"],["79979.99000000","0.00020000"],["79979.05000000","0.00014000"],["79979.04000000","0.08677000"],["79979.03000000","0.00935000"],["79978.93000000","0.00007000"],["79978.73000000","0.00007000"],["79978.58000000","0.00014000"],["79978.57000000","0.06775000"],["79978.42000000","0.00007000"],["79978.29000000","0.00007000"],["79978.28000000","0.00007000"],["79977.99000000","0.00007000"],["79977.91000000","0.00014000"],["79977.90000000","0.08381000"],["79977.89000000","0.08677000"],["79977.75000000","0.01521000"]],"asks":[["79980.16000000","1.17862000"],["79980.17000000","0.00076000"],["79980.18000000","0.00013000"],["79980.32000000","0.00014000"],["79980.33000000","0.01002000"],["79980.52000000","0.00014000"],["79980.53000000","0.01770000"],["79980.61000000","0.00014000"],["79980.62000000","0.11021000"],["79980.72000000","0.00014000"],["79980.73000000","0.03824000"],["79980.78000000","0.00007000"],["79980.97000000","0.00007000"],["79981.01000000","0.00014000"],["79981.02000000","0.12862000"],["79981.05000000","0.32793000"],["79981.06000000","0.00014000"],["79981.29000000","0.00014000"],["79981.38000000","0.00597000"],["79981.61000000","0.01653000"]]}}}
{"rx_ns": 10711461520200, "frame": {"stream":"btcusdt@depth@100ms","data":{"e":"depthUpdate","E":1787647706614,"s":"BTCUSDT","U":99116128206,"u":99116128213,"b":[["79980.15000000","1.01365000"],["71982.14000000","0.00432000"],["63984.12000000","0.00000000"]],"a":[["79980.16000000","1.17862000"]]}}}
{"rx_ns": 10711552429900, "kind": "control", "ctl": {"op": "ping", "recv_ns": 10711500096300, "pong_ns": 10711500258100, "payload_len": 13, "payload_b64": "MTc4NzY0NzcwNjY1NA=="}, "frame": null}
{"rx_ns": 10711552429900, "frame": {"stream":"btcusdt@depth20@100ms","data":{"lastUpdateId":99116128225,"bids":[["79980.15000000","0.83533000"],["79980.14000000","0.00083000"],["79980.13000000","0.00013000"],["79980.10000000","0.00007000"],["79979.99000000","0.00020000"],["79979.05000000","0.00014000"],["79979.04000000","0.08677000"],["79979.03000000","0.00935000"],["79978.93000000","0.00007000"],["79978.73000000","0.00007000"],["79978.58000000","0.00014000"],["79978.57000000","0.06775000"],["79978.42000000","0.00007000"],["79978.29000000","0.00007000"],["79978.28000000","0.00007000"],["79977.99000000","0.00007000"],["79977.91000000","0.00014000"],["79977.90000000","0.08381000"],["79977.89000000","0.08677000"],["79977.75000000","0.01521000"]],"asks":[["79980.16000000","1.17862000"],["79980.17000000","0.00076000"],["79980.18000000","0.00013000"],["79980.32000000","0.00014000"],["79980.33000000","0.01002000"],["79980.52000000","0.00014000"],["79980.53000000","0.01770000"],["79980.61000000","0.00014000"],["79980.62000000","0.11021000"],["79980.72000000","0.00014000"],["79980.73000000","0.03824000"],["79980.78000000","0.00007000"],["79980.97000000","0.00007000"],["79981.01000000","0.00014000"],["79981.02000000","0.12862000"],["79981.05000000","0.32793000"],["79981.06000000","0.00014000"],["79981.29000000","0.00014000"],["79981.38000000","0.00597000"],["79981.61000000","0.01653000"]]}}}
{"rx_ns": 10711552671100, "frame": {"stream":"btcusdt@depth@100ms","data":{"e":"depthUpdate","E":1787647706714,"s":"BTCUSDT","U":99116128214,"u":99116128225,"b":[["79980.15000000","0.83533000"],["79890.02000000","0.02084000"],["71982.14000000","0.00432000"]],"a":[["80007.73000000","0.00000000"],["80009.60000000","0.10000000"]]}}}
{"rx_ns": 10711652385200, "frame": {"stream":"btcusdt@depth20@100ms","data":{"lastUpdateId":99116128230,"bids":[["79980.15000000","0.86024000"],["79980.14000000","0.00083000"],["79980.13000000","0.00013000"],["79980.10000000","0.00007000"],["79979.99000000","0.00020000"],["79979.05000000","0.00014000"],["79979.04000000","0.08677000"],["79979.03000000","0.00935000"],["79978.93000000","0.00007000"],["79978.73000000","0.00007000"],["79978.58000000","0.00014000"],["79978.57000000","0.06775000"],["79978.42000000","0.00007000"],["79978.29000000","0.00007000"],["79978.28000000","0.00007000"],["79977.99000000","0.00007000"],["79977.91000000","0.00014000"],["79977.90000000","0.08381000"],["79977.89000000","0.08677000"],["79977.75000000","0.01521000"]],"asks":[["79980.16000000","1.17862000"],["79980.17000000","0.00076000"],["79980.18000000","0.00013000"],["79980.32000000","0.00014000"],["79980.33000000","0.01002000"],["79980.52000000","0.00014000"],["79980.53000000","0.01770000"],["79980.61000000","0.00014000"],["79980.62000000","0.11021000"],["79980.72000000","0.00014000"],["79980.73000000","0.03824000"],["79980.78000000","0.00007000"],["79980.97000000","0.00007000"],["79981.01000000","0.00014000"],["79981.02000000","0.12862000"],["79981.05000000","0.32793000"],["79981.06000000","0.00014000"],["79981.29000000","0.00014000"],["79981.38000000","0.00597000"],["79981.61000000","0.01653000"]]}}}
{"rx_ns": 10711652521300, "frame": {"stream":"btcusdt@depth@100ms","data":{"e":"depthUpdate","E":1787647706814,"s":"BTCUSDT","U":99116128226,"u":99116128230,"b":[["79980.15000000","0.86024000"],["79972.24000000","0.00000000"],["71982.00000000","0.00000000"]],"a":[]}}}
{"rx_ns": 10711751958900, "frame": {"stream":"btcusdt@depth20@100ms","data":{"lastUpdateId":99116128237,"bids":[["79980.15000000","0.86024000"],["79980.14000000","0.00083000"],["79980.13000000","0.00013000"],["79980.10000000","0.00007000"],["79979.99000000","0.00020000"],["79979.05000000","0.00014000"],["79979.04000000","0.08677000"],["79979.03000000","0.00935000"],["79978.93000000","0.00007000"],["79978.73000000","0.00007000"],["79978.58000000","0.00014000"],["79978.57000000","0.06775000"],["79978.42000000","0.00007000"],["79978.29000000","0.00007000"],["79978.28000000","0.00007000"],["79977.99000000","0.00007000"],["79977.91000000","0.00014000"],["79977.90000000","0.08381000"],["79977.89000000","0.08677000"],["79977.75000000","0.01521000"]],"asks":[["79980.16000000","1.17862000"],["79980.17000000","0.00076000"],["79980.18000000","0.00013000"],["79980.32000000","0.00014000"],["79980.33000000","0.01002000"],["79980.52000000","0.00014000"],["79980.53000000","0.01770000"],["79980.61000000","0.00014000"],["79980.62000000","0.11021000"],["79980.72000000","0.00014000"],["79980.73000000","0.03824000"],["79980.78000000","0.00007000"],["79980.97000000","0.00007000"],["79981.01000000","0.00014000"],["79981.02000000","0.12862000"],["79981.05000000","0.32793000"],["79981.06000000","0.00014000"],["79981.29000000","0.00014000"],["79981.38000000","0.00597000"],["79981.61000000","0.01653000"]]}}}
{"rx_ns": 10711752054700, "frame": {"stream":"btcusdt@depth@100ms","data":{"e":"depthUpdate","E":1787647706914,"s":"BTCUSDT","U":99116128231,"u":99116128237,"b":[["79975.08000000","0.23784000"],["79967.63000000","0.00595000"],["79890.02000000","0.00000000"],["71982.14000000","0.00416000"]],"a":[]}}}
{"rx_ns": 10711860697400, "frame": {"stream":"btcusdt@depth20@100ms","data":{"lastUpdateId":99116128253,"bids":[["79980.15000000","0.86031000"],["79980.14000000","0.00083000"],["79980.13000000","0.00013000"],["79980.10000000","0.00007000"],["79979.99000000","0.00020000"],["79979.04000000","0.00014000"],["79979.03000000","0.00935000"],["79978.93000000","0.00007000"],["79978.73000000","0.00007000"],["79978.58000000","0.00014000"],["79978.57000000","0.06775000"],["79978.42000000","0.00007000"],["79978.29000000","0.00007000"],["79978.28000000","0.00007000"],["79977.99000000","0.00007000"],["79977.91000000","0.00014000"],["79977.90000000","0.08381000"],["79977.89000000","0.08677000"],["79977.75000000","0.01521000"],["79977.42000000","0.00007000"]],"asks":[["79980.16000000","1.17862000"],["79980.17000000","0.00076000"],["79980.18000000","0.00013000"],["79980.32000000","0.00014000"],["79980.33000000","0.01002000"],["79980.52000000","0.00014000"],["79980.53000000","0.01770000"],["79980.61000000","0.00014000"],["79980.62000000","0.11021000"],["79980.72000000","0.00014000"],["79980.73000000","0.03824000"],["79980.78000000","0.00007000"],["79980.97000000","0.00007000"],["79981.01000000","0.00014000"],["79981.02000000","0.12862000"],["79981.05000000","0.32793000"],["79981.06000000","0.00014000"],["79981.29000000","0.00014000"],["79981.38000000","0.00597000"],["79981.61000000","0.01653000"]]}}}
{"rx_ns": 10711860775700, "frame": {"stream":"btcusdt@depth@100ms","data":{"e":"depthUpdate","E":1787647707014,"s":"BTCUSDT","U":99116128238,"u":99116128253,"b":[["79980.15000000","0.86031000"],["79979.05000000","0.00000000"],["79979.04000000","0.00014000"],["79976.77000000","0.00007000"],["79890.02000000","0.02084000"],["79889.05000000","0.62498000"],["79886.41000000","0.00000000"],["71982.14000000","0.00432000"],["63984.12000000","0.00031000"]],"a":[]}}}
{"rx_ns": 10711952287900, "frame": {"stream":"btcusdt@depth20@100ms","data":{"lastUpdateId":99116128270,"bids":[["79980.15000000","0.86031000"],["79980.14000000","0.00076000"],["79980.13000000","0.00013000"],["79980.10000000","0.00007000"],["79979.99000000","0.00020000"],["79979.03000000","0.00935000"],["79978.93000000","0.00007000"],["79978.73000000","0.00007000"],["79978.58000000","0.00014000"],["79978.57000000","0.06775000"],["79978.42000000","0.00007000"],["79978.29000000","0.00007000"],["79978.28000000","0.00007000"],["79977.99000000","0.00007000"],["79977.91000000","0.00014000"],["79977.90000000","0.08381000"],["79977.89000000","0.08677000"],["79977.75000000","0.01521000"],["79977.42000000","0.00007000"],["79977.20000000","0.00014000"]],"asks":[["79980.16000000","1.17862000"],["79980.17000000","0.00076000"],["79980.18000000","0.00013000"],["79980.32000000","0.00014000"],["79980.33000000","0.01002000"],["79980.52000000","0.00014000"],["79980.53000000","0.01770000"],["79980.61000000","0.00014000"],["79980.62000000","0.11021000"],["79980.72000000","0.00014000"],["79980.73000000","0.03824000"],["79980.78000000","0.00007000"],["79980.97000000","0.00007000"],["79981.01000000","0.00014000"],["79981.02000000","0.12862000"],["79981.05000000","0.32793000"],["79981.06000000","0.00014000"],["79981.29000000","0.00014000"],["79981.38000000","0.00597000"],["79981.61000000","0.01653000"]]}}}
{"rx_ns": 10711952392200, "frame": {"stream":"btcusdt@depth@100ms","data":{"e":"depthUpdate","E":1787647707114,"s":"BTCUSDT","U":99116128254,"u":99116128270,"b":[["79980.15000000","0.86031000"],["79980.14000000","0.00076000"],["79979.04000000","0.00000000"],["79903.66000000","0.02400000"],["79890.02000000","0.00000000"],["79600.00000000","1.70513000"],["78780.44000000","0.00030000"],["71982.14000000","0.00400000"]],"a":[["80033.37000000","0.02000000"]]}}}
{"rx_ns": 10712052727100, "frame": {"stream":"btcusdt@depth20@100ms","data":{"lastUpdateId":99116128279,"bids":[["79980.15000000","0.85932000"],["79980.14000000","0.00076000"],["79980.13000000","0.00013000"],["79980.10000000","0.00007000"],["79979.99000000","0.00020000"],["79979.03000000","0.00935000"],["79978.93000000","0.00007000"],["79978.73000000","0.00007000"],["79978.58000000","0.00014000"],["79978.57000000","0.06775000"],["79978.42000000","0.00007000"],["79978.29000000","0.00007000"],["79978.28000000","0.00007000"],["79977.99000000","0.00007000"],["79977.91000000","0.00014000"],["79977.90000000","0.08381000"],["79977.89000000","0.08677000"],["79977.75000000","0.01521000"],["79977.42000000","0.00007000"],["79977.20000000","0.00014000"]],"asks":[["79980.16000000","1.17862000"],["79980.17000000","0.00076000"],["79980.18000000","0.00013000"],["79980.32000000","0.00014000"],["79980.33000000","0.01002000"],["79980.52000000","0.00014000"],["79980.53000000","0.01770000"],["79980.61000000","0.00014000"],["79980.62000000","0.11021000"],["79980.72000000","0.00014000"],["79980.73000000","0.03824000"],["79980.78000000","0.00007000"],["79980.97000000","0.00007000"],["79981.01000000","0.00014000"],["79981.02000000","0.12862000"],["79981.05000000","0.32793000"],["79981.06000000","0.00014000"],["79981.29000000","0.00014000"],["79981.38000000","0.00597000"],["79981.61000000","0.01653000"]]}}}
{"rx_ns": 10712052822200, "frame": {"stream":"btcusdt@depth@100ms","data":{"e":"depthUpdate","E":1787647707214,"s":"BTCUSDT","U":99116128271,"u":99116128279,"b":[["79980.15000000","0.85932000"],["79975.19000000","0.01814000"],["79923.90000000","0.00200000"],["71982.14000000","0.00432000"],["63984.12000000","0.00000000"]],"a":[["80699.97000000","0.00010000"]]}}}
{"rx_ns": 10712152484400, "frame": {"stream":"btcusdt@depth20@100ms","data":{"lastUpdateId":99116128301,"bids":[["79980.15000000","0.85932000"],["79980.14000000","0.00076000"],["79980.13000000","0.00013000"],["79980.10000000","0.00007000"],["79979.99000000","0.00020000"],["79979.03000000","0.00935000"],["79978.93000000","0.00007000"],["79978.73000000","0.00007000"],["79978.58000000","0.00014000"],["79978.57000000","0.06775000"],["79978.42000000","0.00007000"],["79978.29000000","0.00007000"],["79978.28000000","0.00007000"],["79977.99000000","0.00007000"],["79977.91000000","0.00014000"],["79977.90000000","0.08381000"],["79977.89000000","0.08677000"],["79977.75000000","0.01521000"],["79977.42000000","0.00007000"],["79977.20000000","0.00014000"]],"asks":[["79980.16000000","1.17862000"],["79980.17000000","0.00076000"],["79980.18000000","0.00013000"],["79980.32000000","0.00014000"],["79980.33000000","0.01002000"],["79980.52000000","0.00014000"],["79980.53000000","0.01770000"],["79980.61000000","0.00014000"],["79980.62000000","0.11021000"],["79980.72000000","0.00014000"],["79980.73000000","0.03824000"],["79980.78000000","0.00007000"],["79980.97000000","0.00007000"],["79981.01000000","0.00014000"],["79981.02000000","0.12862000"],["79981.05000000","0.32793000"],["79981.06000000","0.00014000"],["79981.29000000","0.00014000"],["79981.38000000","0.00597000"],["79981.61000000","0.01653000"]]}}}
{"rx_ns": 10712152561900, "frame": {"stream":"btcusdt@depth@100ms","data":{"e":"depthUpdate","E":1787647707314,"s":"BTCUSDT","U":99116128280,"u":99116128301,"b":[["79980.15000000","0.85932000"],["79972.24000000","0.08663000"],["79972.16000000","0.08192000"],["79970.35000000","0.08663000"],["79963.64000000","0.02000000"],["79923.60000000","0.02000000"],["71982.14000000","0.00416000"],["63984.00000000","0.00014000"]],"a":[["79993.38000000","0.02000000"],["80013.41000000","0.02000000"],["81179.87000000","0.00030000"]]}}}
{"rx_ns": 10712252508600, "frame": {"stream":"btcusdt@depth20@100ms","data":{"lastUpdateId":99116128316,"bids":[["79980.15000000","0.85950000"],["79980.14000000","0.00076000"],["79980.13000000","0.00013000"],["79980.10000000","0.00007000"],["79979.99000000","0.00020000"],["79979.03000000","0.00935000"],["79978.93000000","0.00007000"],["79978.73000000","0.00007000"],["79978.58000000","0.00014000"],["79978.57000000","0.06775000"],["79978.42000000","0.00007000"],["79978.29000000","0.00007000"],["79978.28000000","0.00007000"],["79977.99000000","0.00007000"],["79977.91000000","0.00014000"],["79977.90000000","0.08381000"],["79977.89000000","0.08677000"],["79977.75000000","0.01521000"],["79977.42000000","0.00007000"],["79977.20000000","0.00014000"]],"asks":[["79980.16000000","1.17862000"],["79980.17000000","0.00076000"],["79980.18000000","0.00013000"],["79980.32000000","0.00014000"],["79980.33000000","0.01002000"],["79980.52000000","0.00014000"],["79980.53000000","0.01770000"],["79980.61000000","0.00014000"],["79980.62000000","0.11021000"],["79980.72000000","0.00014000"],["79980.73000000","0.03824000"],["79980.78000000","0.00007000"],["79980.97000000","0.00007000"],["79981.01000000","0.00014000"],["79981.02000000","0.12862000"],["79981.05000000","0.32793000"],["79981.06000000","0.00014000"],["79981.29000000","0.00014000"],["79981.38000000","0.00597000"],["79981.61000000","0.01653000"]]}}}
{"rx_ns": 10712252608600, "frame": {"stream":"btcusdt@depth@100ms","data":{"e":"depthUpdate","E":1787647707414,"s":"BTCUSDT","U":99116128302,"u":99116128316,"b":[["79980.15000000","0.85950000"],["79972.24000000","0.00000000"],["79972.16000000","0.00000000"],["79970.35000000","0.00000000"],["79927.64000000","0.00400000"],["79927.30000000","0.00000000"],["71982.14000000","0.00416000"]],"a":[]}}}
{"rx_ns": 10712352511100, "frame": {"stream":"btcusdt@depth20@100ms","data":{"lastUpdateId":99116128373,"bids":[["79980.15000000","1.07001000"],["79980.14000000","0.00083000"],["79980.13000000","0.00013000"],["79980.10000000","0.00007000"],["79979.99000000","0.00020000"],["79979.05000000","0.00014000"],["79979.04000000","0.08663000"],["79979.03000000","0.00935000"],["79978.93000000","0.00007000"],["79978.73000000","0.00007000"],["79978.58000000","0.00014000"],["79978.57000000","0.06775000"],["79978.42000000","0.00007000"],["79978.29000000","0.00007000"],["79978.28000000","0.00007000"],["79977.99000000","0.00007000"],["79977.91000000","0.00014000"],["79977.90000000","0.08381000"],["79977.89000000","0.08677000"],["79977.75000000","0.01521000"]],"asks":[["79980.16000000","1.40119000"],["79980.17000000","0.00076000"],["79980.18000000","0.00013000"],["79980.32000000","0.00014000"],["79980.33000000","0.01002000"],["79980.52000000","0.00014000"],["79980.53000000","0.01770000"],["79980.61000000","0.00014000"],["79980.62000000","0.11021000"],["79980.72000000","0.00014000"],["79980.73000000","0.03824000"],["79980.78000000","0.00007000"],["79980.97000000","0.00007000"],["79981.01000000","0.00014000"],["79981.02000000","0.12862000"],["79981.05000000","0.32793000"],["79981.06000000","0.00014000"],["79981.29000000","0.00014000"],["79981.38000000","0.00014000"],["79981.61000000","0.01653000"]]}}}
{"rx_ns": 10712352658900, "frame": {"stream":"btcusdt@depth@100ms","data":{"e":"depthUpdate","E":1787647707514,"s":"BTCUSDT","U":99116128317,"u":99116128373,"b":[["79980.15000000","1.07001000"],["79980.14000000","0.00083000"],["79979.05000000","0.00014000"],["79979.04000000","0.08663000"],["79976.77000000","0.00000000"],["79975.48000000","0.44454000"],["79975.47000000","0.42215000"],["79975.09000000","0.00000000"],["79975.08000000","0.00000000"],["79973.37000000","0.00000000"],["79972.24000000","0.00000000"],["79972.16000000","0.00000000"],["79971.56000000","0.77720000"],["79970.35000000","0.00000000"],["79970.29000000","1.87060000"],["79968.85000000","0.00000000"],["79968.02000000","0.00000000"],["79967.63000000","0.00000000"],["79966.97000000","0.00000000"],["79966.48000000","0.00000000"],["79964.91000000","0.00007000"],["79944.66000000","0.00000000"],["79921.48000000","0.00000000"],["79820.62000000","0.00202000"],["71982.14000000","0.00416000"],["64089.97000000","0.00745000"],["63984.12000000","0.00031000"]],"a":[["79980.16000000","1.40119000"],["79980.17000000","0.00076000"],["79981.38000000","0.00014000"],["79988.23000000","0.00000000"],["79996.45000000","0.00000000"],["79996.91000000","0.00007000"],["80034.97000000","0.00000000"],["80055.00000000","0.00000000"],["80132.46000000","0.00202000"]]}}}
{"rx_ns": 10712451826300, "frame": {"stream":"btcusdt@depth20@100ms","data":{"lastUpdateId":99116128412,"bids":[["79980.15000000","0.85971000"],["79980.14000000","0.00090000"],["79980.13000000","0.00013000"],["79980.10000000","0.00007000"],["79979.99000000","0.00020000"],["79979.92000000","0.00014000"],["79979.91000000","0.08181000"],["79979.03000000","0.00935000"],["79978.93000000","0.00007000"],["79978.73000000","0.00007000"],["79978.57000000","0.00014000"],["79978.42000000","0.00007000"],["79978.29000000","0.00007000"],["79978.28000000","0.00007000"],["79977.99000000","0.00007000"],["79977.91000000","0.00014000"],["79977.90000000","0.05756000"],["79977.89000000","0.00014000"],["79977.76000000","0.00007000"],["79977.75000000","0.01521000"]],"asks":[["79980.16000000","2.10386000"],["79980.17000000","0.00076000"],["79980.18000000","0.00013000"],["79980.32000000","0.00014000"],["79980.33000000","0.01002000"],["79980.52000000","0.00014000"],["79980.53000000","0.01770000"],["79980.61000000","0.00014000"],["79980.62000000","0.11021000"],["79980.72000000","0.00014000"],["79980.73000000","0.03824000"],["79980.78000000","0.00007000"],["79980.97000000","0.00007000"],["79981.01000000","0.00014000"],["79981.02000000","0.46438000"],["79981.05000000","0.32793000"],["79981.06000000","0.00014000"],["79981.29000000","0.00014000"],["79981.61000000","0.01653000"],["79981.77000000","0.00008000"]]}}}
{"rx_ns": 10712451946400, "frame": {"stream":"btcusdt@depth@100ms","data":{"e":"depthUpdate","E":1787647707614,"s":"BTCUSDT","U":99116128374,"u":99116128412,"b":[["79980.15000000","0.85971000"],["79980.14000000","0.00090000"],["79979.92000000","0.00014000"],["79979.91000000","0.08181000"],["79979.05000000","0.00000000"],["79979.04000000","0.00000000"],["79978.58000000","0.00000000"],["79978.57000000","0.00014000"],["79977.90000000","0.05756000"],["79977.89000000","0.00014000"],["79977.76000000","0.00007000"],["79975.19000000","0.01807000"],["79934.85000000","0.00000000"],["71982.14000000","0.00432000"],["63984.12000000","0.00000000"]],"a":[["79980.16000000","2.10386000"],["79981.02000000","0.46438000"],["79981.05000000","0.32793000"],["79981.38000000","0.00000000"],["79981.82000000","0.04014000"]]}}}
{"rx_ns": 10712555698100, "frame": {"stream":"btcusdt@depth20@100ms","data":{"lastUpdateId":99116128461,"bids":[["79980.15000000","0.85964000"],["79980.14000000","0.00090000"],["79980.13000000","0.00013000"],["79980.10000000","0.00007000"],["79979.99000000","0.00020000"],["79979.92000000","0.00014000"],["79979.91000000","0.08195000"],["79979.03000000","0.00928000"],["79978.93000000","0.00007000"],["79978.73000000","0.00007000"],["79978.42000000","0.00007000"],["79978.29000000","0.00007000"],["79978.28000000","0.00007000"],["79977.99000000","0.00007000"],["79977.91000000","0.00014000"],["79977.90000000","0.05749000"],["79977.76000000","0.00014000"],["79977.75000000","0.01521000"],["79977.42000000","0.00007000"],["79977.20000000","0.00014000"]],"asks":[["79980.16000000","2.10336000"],["79980.17000000","0.00076000"],["79980.18000000","0.00013000"],["79980.32000000","0.00014000"],["79980.33000000","0.01002000"],["79980.52000000","0.00014000"],["79980.53000000","0.01770000"],["79980.61000000","0.00014000"],["79980.62000000","0.11021000"],["79980.72000000","0.00014000"],["79980.73000000","0.03824000"],["79980.78000000","0.00007000"],["79980.97000000","0.00007000"],["79981.01000000","0.00014000"],["79981.02000000","0.46438000"],["79981.05000000","0.32793000"],["79981.06000000","0.00014000"],["79981.29000000","0.00014000"],["79981.61000000","0.01653000"],["79981.77000000","0.00008000"]]}}}
{"rx_ns": 10712555792300, "frame": {"stream":"btcusdt@depth@100ms","data":{"e":"depthUpdate","E":1787647707714,"s":"BTCUSDT","U":99116128413,"u":99116128461,"b":[["79980.15000000","0.85964000"],["79979.91000000","0.08195000"],["79979.03000000","0.00928000"],["79978.57000000","0.00000000"],["79977.90000000","0.05749000"],["79977.89000000","0.00000000"],["79977.76000000","0.00014000"],["79976.77000000","0.00007000"],["79976.47000000","0.01814000"],["79976.00000000","0.02428000"],["79975.63000000","0.08381000"],["79975.49000000","0.08663000"],["79975.48000000","0.44461000"],["79944.00000000","0.02400000"],["79889.05000000","0.00000000"],["79886.41000000","0.62498000"],["79857.98000000","0.00000000"],["79850.97000000","0.00393000"],["79772.51000000","0.00000000"],["79770.98000000","0.00770000"],["71982.14000000","0.00416000"]],"a":[["79980.16000000","2.10336000"],["79999.80000000","0.00166000"],["80023.91000000","0.00000000"]]}}}
{"rx_ns": 10712652085300, "frame": {"stream":"btcusdt@depth20@100ms","data":{"lastUpdateId":99116128476,"bids":[["79980.15000000","0.65714000"],["79980.14000000","0.00090000"],["79980.13000000","0.00013000"],["79980.10000000","0.00007000"],["79979.99000000","0.00020000"],["79979.91000000","0.00014000"],["79979.03000000","0.00928000"],["79978.93000000","0.00007000"],["79978.73000000","0.00007000"],["79978.42000000","0.00007000"],["79978.29000000","0.00007000"],["79978.28000000","0.00007000"],["79977.99000000","0.00007000"],["79977.91000000","0.00014000"],["79977.90000000","0.05749000"],["79977.76000000","0.00014000"],["79977.75000000","0.01521000"],["79977.42000000","0.00007000"],["79977.20000000","0.00014000"],["79977.19000000","0.04739000"]],"asks":[["79980.16000000","2.10349000"],["79980.17000000","0.00076000"],["79980.18000000","0.00013000"],["79980.32000000","0.00014000"],["79980.33000000","0.01002000"],["79980.52000000","0.00014000"],["79980.53000000","0.01770000"],["79980.61000000","0.00014000"],["79980.62000000","0.11021000"],["79980.72000000","0.00014000"],["79980.73000000","0.03824000"],["79980.78000000","0.00007000"],["79980.97000000","0.00007000"],["79981.01000000","0.00014000"],["79981.02000000","0.46438000"],["79981.05000000","0.32793000"],["79981.06000000","0.00014000"],["79981.29000000","0.00014000"],["79981.61000000","0.01653000"],["79981.77000000","0.00008000"]]}}}
{"rx_ns": 10712652222900, "frame": {"stream":"btcusdt@depth@100ms","data":{"e":"depthUpdate","E":1787647707814,"s":"BTCUSDT","U":99116128462,"u":99116128476,"b":[["79980.15000000","0.65714000"],["79979.92000000","0.00000000"],["79979.91000000","0.00014000"],["79976.77000000","0.00014000"],["79976.48000000","0.00007000"],["79968.03000000","0.00000000"],["79966.01000000","0.00169000"],["79889.05000000","0.62498000"],["79886.41000000","0.00000000"],["71982.14000000","0.00416000"],["71982.00000000","0.00000000"]],"a":[["79980.16000000","2.10349000"]]}}}
{"rx_ns": 10712752191400, "frame": {"stream":"btcusdt@depth20@100ms","data":{"lastUpdateId":99116128503,"bids":[["79980.15000000","0.85949000"],["79980.14000000","0.00076000"],["79980.13000000","0.00013000"],["79980.10000000","0.00007000"],["79979.99000000","0.00020000"],["79979.03000000","0.00928000"],["79978.93000000","0.00007000"],["79978.73000000","0.00007000"],["79978.42000000","0.00007000"],["79978.29000000","0.00007000"],["79978.28000000","0.00007000"],["79977.99000000","0.00007000"],["79977.91000000","0.00014000"],["79977.90000000","0.05749000"],["79977.76000000","0.00014000"],["79977.75000000","0.01521000"],["79977.42000000","0.00007000"],["79977.20000000","0.00014000"],["79977.19000000","0.04739000"],["79976.90000000","0.00007000"]],"asks":[["79980.16000000","2.10349000"],["79980.17000000","0.00076000"],["79980.18000000","0.00013000"],["79980.32000000","0.00014000"],["79980.33000000","0.01002000"],["79980.52000000","0.00014000"],["79980.53000000","0.01770000"],["79980.61000000","0.00014000"],["79980.62000000","0.11021000"],["79980.72000000","0.00014000"],["79980.73000000","0.03824000"],["79980.78000000","0.00007000"],["79980.97000000","0.00007000"],["79981.01000000","0.00014000"],["79981.02000000","0.46438000"],["79981.05000000","0.32793000"],["79981.06000000","0.00014000"],["79981.29000000","0.00014000"],["79981.61000000","0.01653000"],["79981.77000000","0.00008000"]]}}}
{"rx_ns": 10712752285000, "frame": {"stream":"btcusdt@depth@100ms","data":{"e":"depthUpdate","E":1787647707914,"s":"BTCUSDT","U":99116128477,"u":99116128503,"b":[["79980.15000000","0.85949000"],["79980.14000000","0.00076000"],["79979.91000000","0.00000000"],["79975.73000000","0.00893000"],["79975.63000000","0.08388000"],["79967.04000000","0.00162000"],["79966.01000000","0.00007000"],["79934.85000000","0.00007000"],["71982.14000000","0.00416000"],["71982.13000000","0.00008000"]],"a":[]}}}
{"rx_ns": 10712853520100, "frame": {"stream":"btcusdt@depth20@100ms","data":{"lastUpdateId":99116128516,"bids":[["79980.15000000","0.68766000"],["79980.14000000","0.00076000"],["79980.13000000","0.00013000"],["79980.10000000","0.00007000"],["79979.99000000","0.00020000"],["79979.03000000","0.00928000"],["79978.93000000","0.00007000"],["79978.73000000","0.00007000"],["79978.42000000","0.00007000"],["79978.29000000","0.00007000"],["79978.28000000","0.00007000"],["79977.99000000","0.00007000"],["79977.91000000","0.00014000"],["79977.90000000","0.05749000"],["79977.76000000","0.00014000"],["79977.75000000","0.01521000"],["79977.42000000","0.00007000"],["79977.20000000","0.00014000"],["79977.19000000","0.04739000"],["79976.90000000","0.00007000"]],"asks":[["79980.16000000","2.10292000"],["79980.17000000","0.00076000"],["79980.18000000","0.00013000"],["79980.32000000","0.00014000"],["79980.33000000","0.01002000"],["79980.52000000","0.00014000"],["79980.53000000","0.01770000"],["79980.61000000","0.00014000"],["79980.62000000","0.11021000"],["79980.72000000","0.00014000"],["79980.73000000","0.03824000"],["79980.78000000","0.00007000"],["79980.97000000","0.00007000"],["79981.01000000","0.00014000"],["79981.02000000","0.46438000"],["79981.05000000","0.32793000"],["79981.06000000","0.00014000"],["79981.29000000","0.00014000"],["79981.61000000","0.01653000"],["79981.77000000","0.00008000"]]}}}
{"rx_ns": 10712853613100, "frame": {"stream":"btcusdt@depth@100ms","data":{"e":"depthUpdate","E":1787647708015,"s":"BTCUSDT","U":99116128504,"u":99116128516,"b":[["79980.15000000","0.68766000"],["79889.05000000","0.00000000"],["79886.41000000","0.62498000"],["71982.14000000","0.00416000"],["63984.12000000","0.00031000"]],"a":[["79980.16000000","2.10292000"]]}}}
{"rx_ns": 10712954835500, "frame": {"stream":"btcusdt@depth20@100ms","data":{"lastUpdateId":99116128520,"bids":[["79980.15000000","0.68766000"],["79980.14000000","0.00076000"],["79980.13000000","0.00013000"],["79980.10000000","0.00007000"],["79979.99000000","0.00020000"],["79979.03000000","0.00928000"],["79978.93000000","0.00007000"],["79978.73000000","0.00007000"],["79978.42000000","0.00007000"],["79978.29000000","0.00007000"],["79978.28000000","0.00007000"],["79977.99000000","0.00007000"],["79977.91000000","0.00014000"],["79977.90000000","0.05749000"],["79977.76000000","0.00014000"],["79977.75000000","0.01521000"],["79977.42000000","0.00007000"],["79977.20000000","0.00014000"],["79977.19000000","0.04739000"],["79976.90000000","0.00007000"]],"asks":[["79980.16000000","2.10292000"],["79980.17000000","0.00076000"],["79980.18000000","0.00013000"],["79980.32000000","0.00014000"],["79980.33000000","0.01002000"],["79980.52000000","0.00014000"],["79980.53000000","0.01770000"],["79980.61000000","0.00014000"],["79980.62000000","0.11021000"],["79980.72000000","0.00014000"],["79980.73000000","0.03824000"],["79980.78000000","0.00007000"],["79980.97000000","0.00007000"],["79981.01000000","0.00014000"],["79981.02000000","0.46438000"],["79981.05000000","0.32793000"],["79981.06000000","0.00014000"],["79981.29000000","0.00014000"],["79981.61000000","0.01653000"],["79981.77000000","0.00008000"]]}}}
{"rx_ns": 10712954910600, "frame": {"stream":"btcusdt@depth@100ms","data":{"e":"depthUpdate","E":1787647708115,"s":"BTCUSDT","U":99116128517,"u":99116128520,"b":[["79975.07000000","0.10954000"],["79894.91000000","0.02084000"],["78780.44000000","0.00030000"]],"a":[]}}}
{"rx_ns": 10713052158600, "frame": {"stream":"btcusdt@depth20@100ms","data":{"lastUpdateId":99116128605,"bids":[["79980.15000000","0.27465000"],["79980.14000000","0.00076000"],["79980.13000000","0.00013000"],["79980.10000000","0.00007000"],["79979.99000000","0.00020000"],["79979.03000000","0.00928000"],["79978.93000000","0.00007000"],["79978.73000000","0.00007000"],["79978.42000000","0.00007000"],["79978.29000000","0.00007000"],["79978.28000000","0.00007000"],["79977.99000000","0.00007000"],["79977.90000000","0.00014000"],["79977.76000000","0.00014000"],["79977.75000000","0.01521000"],["79977.42000000","0.00007000"],["79977.21000000","0.00014000"],["79977.20000000","0.02714000"],["79977.19000000","0.04739000"],["79976.90000000","0.00007000"]],"asks":[["79980.16000000","2.12272000"],["79980.17000000","0.00027000"],["79980.18000000","0.00013000"],["79980.32000000","0.00014000"],["79980.33000000","0.01002000"],["79980.52000000","0.00014000"],["79980.53000000","0.01770000"],["79980.61000000","0.00014000"],["79980.62000000","0.11021000"],["79980.72000000","0.00014000"],["79980.73000000","0.03824000"],["79980.78000000","0.00007000"],["79980.85000000","0.00007000"],["79980.86000000","0.03224000"],["79980.97000000","0.00007000"],["79981.01000000","1.04953000"],["79981.02000000","0.46438000"],["79981.05000000","0.32793000"],["79981.06000000","0.00014000"],["79981.29000000","0.00014000"]]}}}
{"rx_ns": 10713052328200, "frame": {"stream":"btcusdt@depth@100ms","data":{"e":"depthUpdate","E":1787647708214,"s":"BTCUSDT","U":99116128521,"u":99116128605,"b":[["79980.15000000","0.27465000"],["79980.14000000","0.00076000"],["79977.91000000","0.00000000"],["79977.90000000","0.00014000"],["79977.21000000","0.00014000"],["79977.20000000","0.02714000"],["79976.77000000","0.00000000"],["79976.76000000","0.00014000"],["79976.48000000","0.00014000"],["79976.01000000","0.00007000"],["79976.00000000","0.02435000"],["79975.89000000","0.05314000"],["79975.64000000","0.08663000"],["79975.63000000","0.00007000"],["79975.49000000","0.00000000"],["79975.07000000","0.00000000"],["79973.55000000","0.00007000"],["79971.56000000","0.18919000"],["79970.29000000","0.00000000"],["79967.04000000","0.00000000"],["79965.51000000","0.00170000"],["79958.66000000","0.00000000"],["79955.10000000","0.26353000"],["79943.01000000","0.49783000"],["79943.00000000","0.70000000"],["79942.93000000","0.00000000"],["79894.91000000","0.00000000"],["71982.14000000","0.00416000"],["71982.13000000","0.00000000"],["71982.12000000","0.00008000"],["63984.12000000","0.00000000"]],"a":[["79980.16000000","2.12272000"],["79980.17000000","0.00027000"],["79980.85000000","0.00007000"],["79980.86000000","0.03224000"],["79981.01000000","1.04953000"],["79981.56000000","0.00583000"],["79983.49000000","0.00000000"],["79984.66000000","0.97946000"],["79987.94000000","2.23646000"],["80013.26000000","1.49231000"],["80015.58000000","1.23762000"],["80020.37000000","0.00400000"],["80028.76000000","0.00000000"],["80043.15000000","0.00000000"]]}}}
{"rx_ns": 10713154251500, "frame": {"stream":"btcusdt@depth20@100ms","data":{"lastUpdateId":99116128699,"bids":[["79980.15000000","0.29829000"],["79980.14000000","0.00083000"],["79980.13000000","0.00013000"],["79980.10000000","0.00007000"],["79979.99000000","0.00020000"],["79979.03000000","0.00921000"],["79978.93000000","0.00007000"],["79978.73000000","0.00007000"],["79978.42000000","0.00007000"],["79978.29000000","0.00007000"],["79978.28000000","0.00007000"],["79977.99000000","0.00007000"],["79977.76000000","0.00014000"],["79977.75000000","0.01521000"],["79977.42000000","0.00007000"],["79977.21000000","0.00014000"],["79977.20000000","0.04964000"],["79977.19000000","0.04732000"],["79976.90000000","0.00007000"],["79976.85000000","0.00007000"]],"asks":[["79980.16000000","2.06942000"],["79980.17000000","0.00027000"],["79980.18000000","0.00013000"],["79980.32000000","0.00014000"],["79980.33000000","0.01002000"],["79980.52000000","0.00014000"],["79980.53000000","0.01770000"],["79980.61000000","0.00014000"],["79980.62000000","0.11021000"],["79980.72000000","0.00014000"],["79980.73000000","0.03824000"],["79980.78000000","0.00007000"],["79980.85000000","0.00007000"],["79980.86000000","0.03238000"],["79980.97000000","0.00007000"],["79981.00000000","0.79570000"],["79981.01000000","1.04960000"],["79981.02000000","0.00014000"],["79981.05000000","0.32793000"],["79981.06000000","0.00014000"]]}}}
{"rx_ns": 10713154359500, "frame": {"stream":"btcusdt@depth@100ms","data":{"e":"depthUpdate","E":1787647708314,"s":"BTCUSDT","U":99116128606,"u":99116128699,"b":[["79980.15000000","0.29829000"],["79980.14000000","0.00083000"],["79979.03000000","0.00921000"],["79977.90000000","0.00000000"],["79977.75000000","0.01521000"],["79977.20000000","0.04964000"],["79977.19000000","0.04732000"],["79976.77000000","0.00014000"],["79976.76000000","0.08663000"],["79976.01000000","0.00000000"],["79976.00000000","0.02435000"],["79975.89000000","0.05328000"],["79975.73000000","0.00900000"],["79975.49000000","0.08663000"],["79975.19000000","0.01814000"],["79968.02000000","0.08663000"],["79963.55000000","0.02400000"],["79943.01000000","0.00000000"],["79943.00000000","0.00000000"],["79923.50000000","0.02400000"],["79903.57000000","0.02000000"],["71982.14000000","0.00432000"],["63984.00000000","0.00014000"]],"a":[["79980.16000000","2.06942000"],["79980.73000000","0.03824000"],["79980.86000000","0.03238000"],["79981.00000000","0.79570000"],["79981.01000000","1.04960000"],["79981.02000000","0.00014000"],["79981.05000000","0.32793000"],["79981.61000000","0.01639000"],["79981.82000000","0.04000000"],["79993.32000000","0.04000000"],["80013.34000000","0.04000000"],["80033.43000000","0.02000000"],["81179.87000000","0.00030000"],["82000.00000000","119.67892000"]]}}}
{"rx_ns": 10713253019700, "frame": {"stream":"btcusdt@depth20@100ms","data":{"lastUpdateId":99116128750,"bids":[["79980.15000000","0.53837000"],["79980.14000000","0.00083000"],["79980.13000000","0.00013000"],["79980.10000000","0.00007000"],["79979.99000000","0.00020000"],["79979.03000000","0.00921000"],["79978.93000000","0.00007000"],["79978.73000000","0.00007000"],["79978.42000000","0.00007000"],["79978.29000000","0.00007000"],["79978.28000000","0.00007000"],["79977.99000000","0.00007000"],["79977.76000000","0.00014000"],["79977.75000000","0.01521000"],["79977.42000000","0.00007000"],["79977.21000000","0.00014000"],["79977.20000000","0.04964000"],["79977.19000000","0.04739000"],["79976.90000000","0.00007000"],["79976.85000000","0.00007000"]],"asks":[["79980.16000000","2.07027000"],["79980.17000000","0.00076000"],["79980.18000000","0.00013000"],["79980.32000000","0.00014000"],["79980.33000000","0.01002000"],["79980.52000000","0.00014000"],["79980.53000000","0.01770000"],["79980.61000000","0.00014000"],["79980.62000000","0.11021000"],["79980.72000000","0.00014000"],["79980.73000000","0.03817000"],["79980.85000000","0.00007000"],["79980.86000000","0.03238000"],["79980.97000000","0.00007000"],["79981.00000000","0.79584000"],["79981.01000000","1.04960000"],["79981.05000000","0.32793000"],["79981.06000000","0.00014000"],["79981.29000000","0.00014000"],["79981.56000000","0.00583000"]]}}}
{"rx_ns": 10713253100200, "frame": {"stream":"btcusdt@depth@100ms","data":{"e":"depthUpdate","E":1787647708415,"s":"BTCUSDT","U":99116128700,"u":99116128750,"b":[["79980.15000000","0.53837000"],["79977.19000000","0.04739000"],["79976.76000000","0.08677000"],["79975.73000000","0.00886000"],["79975.64000000","0.08670000"],["71982.14000000","0.00416000"]],"a":[["79980.16000000","2.07027000"],["79980.17000000","0.00076000"],["79980.73000000","0.03817000"],["79980.78000000","0.00000000"],["79980.86000000","0.03238000"],["79981.00000000","0.79584000"],["79981.01000000","1.04960000"],["79981.02000000","0.00000000"]]}}}
{"rx_ns": 10713357351200, "frame": {"stream":"btcusdt@depth20@100ms","data":{"lastUpdateId":99116128803,"bids":[["79980.15000000","0.29837000"],["79980.14000000","0.00083000"],["79980.13000000","0.00013000"],["79980.10000000","0.00007000"],["79979.99000000","0.00020000"],["79979.03000000","0.00921000"],["79978.93000000","0.00007000"],["79978.73000000","0.00007000"],["79978.42000000","0.00007000"],["79978.29000000","0.00007000"],["79978.28000000","0.00007000"],["79977.99000000","0.00007000"],["79977.91000000","0.00014000"],["79977.90000000","0.08217000"],["79977.89000000","0.08219000"],["79977.76000000","0.00014000"],["79977.75000000","0.01521000"],["79977.42000000","0.00007000"],["79977.20000000","0.00028000"],["79977.19000000","0.04739000"]],"asks":[["79980.16000000","2.06942000"],["79980.17000000","0.00027000"],["79980.18000000","0.00013000"],["79980.32000000","0.00014000"],["79980.33000000","0.01002000"],["79980.52000000","0.00014000"],["79980.53000000","0.01770000"],["79980.61000000","0.00014000"],["79980.62000000","0.11021000"],["79980.72000000","0.00014000"],["79980.73000000","0.03817000"],["79980.85000000","0.00007000"],["79980.86000000","0.03238000"],["79980.97000000","0.00007000"],["79981.00000000","0.79584000"],["79981.01000000","1.04960000"],["79981.05000000","0.32793000"],["79981.06000000","0.00014000"],["79981.29000000","0.00014000"],["79981.56000000","0.00583000"]]}}}
{"rx_ns": 10713357486400, "frame": {"stream":"btcusdt@depth@100ms","data":{"e":"depthUpdate","E":1787647708514,"s":"BTCUSDT","U":99116128751,"u":99116128803,"b":[["79980.15000000","0.29837000"],["79977.91000000","0.00014000"],["79977.90000000","0.08217000"],["79977.89000000","0.08219000"],["79977.21000000","0.00000000"],["79977.20000000","0.00028000"],["79976.48000000","0.00000000"],["79964.91000000","0.00007000"],["79959.81000000","0.00000000"],["79919.76000000","0.00000000"],["79899.74000000","0.00000000"],["73585.27000000","0.00014000"],["71982.14000000","0.00432000"],["63984.12000000","0.00031000"]],"a":[["79980.16000000","2.06942000"],["79980.17000000","0.00027000"],["79990.81000000","0.00000000"],["79996.91000000","0.00007000"],["80030.37000000","0.00000000"],["80050.40000000","0.00000000"],["80068.60000000","0.00000000"],["80073.99000000","0.00000000"],["80096.86000000","0.00000000"],["80101.99000000","0.00000000"]]}}}
{"rx_ns": 10713453830000, "frame": {"stream":"btcusdt@depth20@100ms","data":{"lastUpdateId":99116128878,"bids":[["79980.15000000","0.67764000"],["79980.14000000","0.00090000"],["79980.13000000","0.00013000"],["79980.10000000","0.00007000"],["79979.99000000","0.00020000"],["79979.05000000","0.00014000"],["79979.04000000","0.08663000"],["79979.03000000","0.00921000"],["79978.93000000","0.00007000"],["79978.73000000","0.00007000"],["79978.42000000","0.00007000"],["79978.29000000","0.00007000"],["79978.28000000","0.00007000"],["79977.99000000","0.00007000"],["79977.91000000","0.00014000"],["79977.90000000","0.08231000"],["79977.89000000","0.08233000"],["79977.75000000","0.01521000"],["79977.42000000","0.00007000"],["79977.20000000","0.00014000"]],"asks":[["79980.16000000","2.07040000"],["79980.17000000","0.00076000"],["79980.18000000","0.00013000"],["79980.32000000","0.00014000"],["79980.33000000","0.01002000"],["79980.52000000","0.00014000"],["79980.53000000","0.01770000"],["79980.61000000","0.00014000"],["79980.62000000","0.11021000"],["79980.72000000","0.00014000"],["79980.73000000","0.03817000"],["79980.85000000","0.00007000"],["79980.86000000","0.03238000"],["79980.97000000","0.00007000"],["79981.00000000","0.79584000"],["79981.01000000","1.04960000"],["79981.05000000","0.32793000"],["79981.06000000","0.00014000"],["79981.29000000","0.00014000"],["79981.56000000","0.00583000"]]}}}
{"rx_ns": 10713453913900, "frame": {"stream":"btcusdt@depth@100ms","data":{"e":"depthUpdate","E":1787647708614,"s":"BTCUSDT","U":99116128804,"u":99116128878,"b":[["79980.15000000","0.67764000"],["79980.14000000","0.00090000"],["79979.05000000","0.00014000"],["79979.04000000","0.08663000"],["79979.03000000","0.00921000"],["79977.90000000","0.08231000"],["79977.89000000","0.08233000"],["79977.76000000","0.00000000"],["79977.75000000","0.01521000"],["79977.20000000","0.00014000"],["79977.08000000","0.00007000"],["79977.07000000","0.11320000"],["79976.77000000","0.00007000"],["79976.00000000","0.02428000"],["79975.89000000","0.00000000"],["79975.49000000","0.00000000"],["79968.02000000","0.00000000"],["79770.98000000","0.00000000"],["79765.60000000","0.00770000"],["71982.14000000","0.00416000"],["63984.12000000","0.00000000"]],"a":[["79980.16000000","2.07040000"],["79980.17000000","0.00076000"]]}}}
{"rx_ns": 10713552368200, "frame": {"stream":"btcusdt@depth20@100ms","data":{"lastUpdateId":99116128905,"bids":[["79980.15000000","0.67778000"],["79980.14000000","0.00090000"],["79980.13000000","0.00013000"],["79980.10000000","0.00007000"],["79979.99000000","0.00020000"],["79979.05000000","0.00014000"],["79979.04000000","0.08677000"],["79979.03000000","0.00928000"],["79978.93000000","0.00007000"],["79978.73000000","0.00007000"],["79978.42000000","0.00007000"],["79978.29000000","0.00007000"],["79978.28000000","0.00007000"],["79977.99000000","0.00007000"],["79977.91000000","0.00014000"],["79977.90000000","0.08231000"],["79977.89000000","0.08233000"],["79977.75000000","0.01521000"],["79977.42000000","0.00007000"],["79977.20000000","0.00014000"]],"asks":[["79980.16000000","2.07040000"],["79980.17000000","0.00076000"],["79980.18000000","0.00013000"],["79980.32000000","0.00014000"],["79980.33000000","0.01002000"],["79980.52000000","0.00014000"],["79980.53000000","0.01770000"],["79980.61000000","0.00014000"],["79980.62000000","0.11021000"],["79980.72000000","0.00014000"],["79980.73000000","0.03817000"],["79980.85000000","0.00007000"],["79980.86000000","0.03238000"],["79980.97000000","0.00007000"],["79981.00000000","0.46606000"],["79981.01000000","0.00021000"],["79981.05000000","0.32793000"],["79981.06000000","0.00014000"],["79981.29000000","0.00014000"],["79981.56000000","0.00583000"]]}}}
{"rx_ns": 10713552456900, "frame": {"stream":"btcusdt@depth@100ms","data":{"e":"depthUpdate","E":1787647708714,"s":"BTCUSDT","U":99116128879,"u":99116128905,"b":[["79980.15000000","0.67778000"],["79979.04000000","0.08677000"],["79979.03000000","0.00928000"],["79977.19000000","0.04739000"],["79976.47000000","0.01800000"],["79976.00000000","0.02414000"],["79975.64000000","0.08663000"],["79975.49000000","0.08663000"],["79968.02000000","0.08663000"],["79890.02000000","0.02084000"],["71982.14000000","0.00432000"]],"a":[["79981.00000000","0.46606000"],["79981.01000000","0.00021000"]]}}}
{"rx_ns": 10713656262000, "frame": {"stream":"btcusdt@depth20@100ms","data":{"lastUpdateId":99116128937,"bids":[["79980.15000000","0.67778000"],["79980.14000000","0.00090000"],["79980.13000000","0.00013000"],["79980.10000000","0.00007000"],["79979.99000000","0.00020000"],["79979.05000000","0.00014000"],["79979.04000000","0.08677000"],["79979.03000000","0.00928000"],["79978.93000000","0.00007000"],["79978.73000000","0.00007000"],["79978.42000000","0.00007000"],["79978.29000000","0.00007000"],["79978.28000000","0.00007000"],["79977.99000000","0.00007000"],["79977.91000000","0.00014000"],["79977.90000000","0.08231000"],["79977.89000000","0.08233000"],["79977.75000000","0.01521000"],["79977.42000000","0.00007000"],["79977.20000000","0.00014000"]],"asks":[["79980.16000000","2.07040000"],["79980.17000000","0.00076000"],["79980.18000000","0.00013000"],["79980.32000000","0.00014000"],["79980.33000000","0.01002000"],["79980.52000000","0.00014000"],["79980.53000000","0.01770000"],["79980.61000000","0.00014000"],["79980.62000000","0.11021000"],["79980.72000000","0.00014000"],["79980.73000000","0.03817000"],["79980.85000000","0.00007000"],["79980.86000000","0.03238000"],["79980.97000000","0.00007000"],["79981.00000000","0.46606000"],["79981.01000000","0.00007000"],["79981.05000000","0.32793000"],["79981.06000000","0.00014000"],["79981.29000000","0.00014000"],["79981.56000000","0.00597000"]]}}}
{"rx_ns": 10713656363400, "frame": {"stream":"btcusdt@depth@100ms","data":{"e":"depthUpdate","E":1787647708814,"s":"BTCUSDT","U":99116128906,"u":99116128937,"b":[["79973.55000000","0.00014000"],["79972.21000000","0.00625000"],["79968.77000000","0.00625000"],["79967.03000000","0.00000000"],["79920.40000000","0.00311000"],["79918.06000000","0.00000000"],["79899.63000000","0.00312000"],["79897.57000000","0.00000000"],["79890.02000000","0.00000000"],["79889.05000000","0.62498000"],["79886.41000000","0.00000000"],["79840.02000000","0.00125000"],["79834.15000000","0.00000000"],["79819.74000000","0.00125000"],["79814.06000000","0.00000000"],["71982.14000000","0.00416000"]],"a":[["79980.16000000","2.07040000"],["79980.17000000","0.00076000"],["79981.00000000","0.46606000"],["79981.01000000","0.00007000"],["79981.56000000","0.00597000"],["79987.03000000","0.00625000"],["79994.00000000","0.72400000"],["79995.00000000","0.00000000"],["80042.52000000","0.00311000"],["80044.40000000","0.00007000"],["80055.30000000","0.00312000"],["80057.99000000","0.00000000"],["80121.98000000","0.00125000"],["80125.99000000","0.00000000"],["80135.28000000","0.00125000"],["80137.99000000","0.00000000"]]}}}
{"rx_ns": 10713752320900, "frame": {"stream":"btcusdt@depth20@100ms","data":{"lastUpdateId":99116128950,"bids":[["79980.15000000","0.69074000"],["79980.14000000","0.00083000"],["79980.13000000","0.00013000"],["79980.10000000","0.00007000"],["79979.99000000","0.00020000"],["79979.05000000","0.12529000"],["79979.04000000","0.08677000"],["79979.03000000","0.00928000"],["79978.93000000","0.00007000"],["79978.73000000","0.00007000"],["79978.42000000","0.00007000"],["79978.29000000","0.00007000"],["79978.28000000","0.00007000"],["79977.99000000","0.00007000"],["79977.91000000","0.00014000"],["79977.90000000","0.04818000"],["79977.89000000","0.08233000"],["79977.75000000","0.01521000"],["79977.42000000","0.00007000"],["79977.20000000","0.00014000"]],"asks":[["79980.16000000","2.07040000"],["79980.17000000","0.00076000"],["79980.18000000","0.00013000"],["79980.32000000","0.00014000"],["79980.33000000","0.01002000"],["79980.52000000","0.00014000"],["79980.53000000","0.01770000"],["79980.61000000","0.00014000"],["79980.62000000","0.11021000"],["79980.72000000","0.00014000"],["79980.73000000","0.03817000"],["79980.85000000","0.00007000"],["79980.86000000","0.03238000"],["79980.97000000","0.00007000"],["79981.00000000","0.46606000"],["79981.01000000","0.00007000"],["79981.05000000","0.32793000"],["79981.06000000","0.00014000"],["79981.29000000","0.00014000"],["79981.56000000","0.00597000"]]}}}
{"rx_ns": 10713752414800, "frame": {"stream":"btcusdt@depth@100ms","data":{"e":"depthUpdate","E":1787647708914,"s":"BTCUSDT","U":99116128938,"u":99116128950,"b":[["79980.15000000","0.69074000"],["79980.14000000","0.00083000"],["79979.05000000","0.12529000"],["79977.90000000","0.04818000"],["79977.08000000","0.00000000"],["79977.07000000","0.00000000"],["71982.14000000","0.00432000"],["71982.00000000","0.00020000"]],"a":[]}}}
{"rx_ns": 10713852202500, "frame": {"stream":"btcusdt@depth20@100ms","data":{"lastUpdateId":99116128983,"bids":[["79980.15000000","0.80633000"],["79980.14000000","0.00090000"],["79980.13000000","0.00013000"],["79980.10000000","0.00007000"],["79979.99000000","0.00020000"],["79979.06000000","0.00014000"],["79979.05000000","0.12529000"],["79979.04000000","0.08677000"],["79979.03000000","0.00928000"],["79978.93000000","0.00007000"],["79978.73000000","0.00007000"],["79978.71000000","0.00014000"],["79978.70000000","0.09239000"],["79978.42000000","0.00007000"],["79978.29000000","0.00007000"],["79978.28000000","0.00007000"],["79977.99000000","0.00007000"],["79977.90000000","0.00028000"],["79977.89000000","0.08233000"],["79977.75000000","0.01521000"]],"asks":[["79980.16000000","2.04951000"],["79980.17000000","0.00076000"],["79980.18000000","0.00013000"],["79980.32000000","0.00014000"],["79980.33000000","0.01002000"],["79980.52000000","0.00014000"],["79980.53000000","0.01770000"],["79980.61000000","0.00014000"],["79980.62000000","0.11021000"],["79980.72000000","0.00014000"],["79980.73000000","0.03817000"],["79980.85000000","0.00007000"],["79980.86000000","0.00014000"],["79980.97000000","0.00007000"],["79981.00000000","0.46606000"],["79981.01000000","0.00007000"],["79981.05000000","0.32793000"],["79981.06000000","0.00014000"],["79981.29000000","0.00014000"],["79981.56000000","0.00597000"]]}}}
{"rx_ns": 10713852279900, "frame": {"stream":"btcusdt@depth@100ms","data":{"e":"depthUpdate","E":1787647709014,"s":"BTCUSDT","U":99116128951,"u":99116128983,"b":[["79980.15000000","0.80633000"],["79980.14000000","0.00090000"],["79979.06000000","0.00014000"],["79978.71000000","0.00014000"],["79978.70000000","0.09239000"],["79977.91000000","0.00000000"],["79977.90000000","0.00028000"],["79977.19000000","0.04725000"],["79976.77000000","0.00000000"],["79972.70000000","0.00625000"],["79972.21000000","0.00000000"],["79969.06000000","0.00625000"],["79968.77000000","0.00000000"],["79966.97000000","0.00162000"],["79965.51000000","0.00008000"],["79765.60000000","0.00000000"],["79762.12000000","0.00770000"],["71982.14000000","0.00400000"],["71982.00000000","0.00000000"],["63984.12000000","0.00031000"]],"a":[["79980.16000000","2.04951000"],["79980.86000000","0.00014000"],["79981.81000000","0.00012000"],["79987.03000000","0.00000000"],["79987.23000000","0.00625000"],["80009.31000000","0.02419000"],["80014.28000000","0.00007000"]]}}}
{"rx_ns": 10713954852600, "frame": {"stream":"btcusdt@depth20@100ms","data":{"lastUpdateId":99116129028,"bids":[["79980.15000000","1.06223000"],["79980.14000000","0.00083000"],["79980.13000000","0.00013000"],["79980.10000000","0.00007000"],["79979.99000000","0.00020000"],["79979.06000000","0.00014000"],["79979.05000000","0.12543000"],["79979.04000000","0.08677000"],["79979.03000000","0.00928000"],["79978.93000000","0.00007000"],["79978.73000000","0.00007000"],["79978.71000000","0.00014000"],["79978.42000000","0.00007000"],["79978.29000000","0.00007000"],["79978.28000000","0.00007000"],["79977.99000000","0.00007000"],["79977.90000000","0.00014000"],["79977.89000000","0.08233000"],["79977.75000000","0.01521000"],["79977.42000000","0.00007000"]],"asks":[["79980.16000000","2.04951000"],["79980.17000000","0.00076000"],["79980.18000000","0.00013000"],["79980.32000000","0.00014000"],["79980.33000000","0.01002000"],["79980.52000000","0.00014000"],["79980.53000000","0.01770000"],["79980.61000000","0.00014000"],["79980.62000000","0.11021000"],["79980.72000000","0.00014000"],["79980.73000000","0.03817000"],["79980.97000000","0.00007000"],["79980.99000000","0.00007000"],["79981.00000000","0.46606000"],["79981.01000000","0.00007000"],["79981.05000000","0.32793000"],["79981.06000000","0.00014000"],["79981.29000000","0.00014000"],["79981.56000000","0.00597000"],["79981.61000000","0.01653000"]]}}}
{"rx_ns": 10713954933500, "frame": {"stream":"btcusdt@depth@100ms","data":{"e":"depthUpdate","E":1787647709114,"s":"BTCUSDT","U":99116128984,"u":99116129028,"b":[["79980.15000000","1.06223000"],["79980.14000000","0.00083000"],["79979.05000000","0.12543000"],["79979.03000000","0.00928000"],["79978.70000000","0.00000000"],["79977.90000000","0.00014000"],["79970.35000000","0.00625000"],["79969.06000000","0.00000000"],["78780.44000000","0.00030000"],["73585.27000000","0.00000000"],["71982.14000000","0.00432000"]],"a":[["79980.16000000","2.04951000"],["79980.17000000","0.00076000"],["79980.73000000","0.03817000"],["79980.85000000","0.00000000"],["79980.86000000","0.00000000"],["79980.99000000","0.00007000"],["79981.61000000","0.01653000"],["79984.66000000","0.35620000"],["79987.23000000","0.00000000"],["79987.62000000","0.00625000"],["79987.94000000","0.36586000"]]}}}
