{"captured_at": "2026-08-24T20:21:07.276316+00:00", "url": "wss://data-stream.binance.vision/stream?streams=btcusdt@depth/btcusdt@depth20", "venue": "binance", "symbol": "BTCUSDT", "streams": ["depth", "depth20"], "combined": true, "rest_url": "https://data-api.binance.vision/api/v3/depth?symbol=BTCUSDT&limit=100", "rest_limit": 100, "rest_weight_per_fetch": 5, "snapshot_every_s": 10.0, "tool_version": "0.1.0", "clock": "perf_counter_ns", "capture_mode": "baseline", "cycles": 1, "origin_sent": null, "handshake_status": "HTTP/1.1 101 Switching Protocols"}
{"rx_ns": 1957448900, "frame": {"stream":"btcusdt@depth20","data":{"lastUpdateId":99076491957,"bids":[["78761.99000000","5.21780000"],["78761.98000000","0.00062000"],["78761.97000000","0.00013000"],["78761.05000000","0.00014000"],["78761.04000000","1.90536000"],["78761.03000000","0.49357000"],["78760.72000000","0.03834000"],["78760.60000000","0.00400000"],["78760.00000000","0.00346000"],["78759.99000000","0.00007000"],["78759.76000000","0.00014000"],["78759.60000000","0.00007000"],["78759.46000000","0.04599000"],["78759.29000000","0.05171000"],["78759.20000000","0.00007000"],["78758.64000000","0.00641000"],["78758.63000000","0.00400000"],["78758.38000000","0.03231000"],["78758.37000000","0.00014000"],["78758.21000000","0.00634000"]],"asks":[["78762.00000000","0.63432000"],["78762.01000000","0.00083000"],["78762.02000000","0.00013000"],["78762.15000000","0.00076000"],["78762.20000000","0.00007000"],["78762.24000000","0.00014000"],["78762.87000000","0.00126000"],["78763.00000000","0.00381000"],["78763.12000000","0.00007000"],["78763.41000000","0.00007000"],["78763.89000000","0.00014000"],["78763.90000000","0.19569000"],["78763.99000000","0.00014000"],["78764.00000000","0.02414000"],["78765.07000000","0.00014000"],["78765.08000000","0.01519000"],["78765.49000000","0.00007000"],["78765.52000000","0.00007000"],["78765.75000000","0.00007000"],["78765.97000000","0.00014000"]]}}}
{"rx_ns": 1957547800, "frame": {"stream":"btcusdt@depth","data":{"e":"depthUpdate","E":1787602869014,"s":"BTCUSDT","U":99076491598,"u":99076491957,"b":[["78761.99000000","5.21780000"],["78761.98000000","0.00062000"],["78760.72000000","0.03834000"],["78760.40000000","0.00000000"],["78760.35000000","0.00000000"],["78760.15000000","0.00000000"],["78760.10000000","0.00000000"],["78760.01000000","0.00000000"],["78760.00000000","0.00346000"],["78759.95000000","0.00000000"],["78759.60000000","0.00007000"],["78759.55000000","0.00000000"],["78759.29000000","0.05171000"],["78758.64000000","0.00641000"],["78758.38000000","0.03231000"],["78758.21000000","0.00634000"],["78758.20000000","0.04593000"],["78757.63000000","0.00400000"],["78757.36000000","0.00000000"],["78757.35000000","0.00000000"],["78756.01000000","0.00000000"],["78754.76000000","0.00800000"],["78753.99000000","0.03948000"],["78750.23000000","0.00000000"],["78750.03000000","0.00000000"],["78746.26000000","0.13235000"],["78745.91000000","0.34291000"],["78740.24000000","0.00000000"],["78739.03000000","0.00634000"],["78738.32000000","0.00007000"],["78736.01000000","0.00000000"],["78722.25000000","0.00000000"],["78683.05000000","0.00000000"],["78368.18000000","0.01000000"],["77976.33000000","0.01000000"],["77586.45000000","0.01000000"],["77198.52000000","0.01000000"],["76812.53000000","0.01000000"],["76428.46000000","0.01000000"],["76046.32000000","0.01000000"],["75666.09000000","0.01000000"],["75287.76000000","0.01023000"],["74911.32000000","0.01000000"],["74536.76000000","0.01000000"],["74164.08000000","0.01000000"],["73793.26000000","0.01000000"],["73424.29000000","0.01000000"],["73057.17000000","0.01000000"],["70885.80000000","0.00457000"],["70885.79000000","0.00000000"],["70885.78000000","0.00009000"],["70885.00000000","0.00000000"],["63010.00000000","0.05451000"],["63009.60000000","0.00031000"],["63009.59000000","0.00015000"]],"a":[["78762.00000000","0.63432000"],["78762.01000000","0.00083000"],["78763.13000000","0.00000000"],["78763.89000000","0.00014000"],["78763.90000000","0.19569000"],["78763.91000000","0.00000000"],["78764.00000000","0.02414000"],["78764.14000000","0.00000000"],["78764.83000000","0.00000000"],["78764.84000000","0.00000000"],["78765.08000000","0.01519000"],["78765.20000000","0.00000000"],["78765.49000000","0.00007000"],["78765.97000000","0.00014000"],["78765.98000000","0.20798000"],["78766.33000000","0.00000000"],["78766.34000000","0.02527000"],["78766.50000000","0.00000000"],["78767.18000000","0.00000000"],["78767.19000000","0.00000000"],["78767.23000000","0.00000000"],["78767.60000000","0.03031000"],["78767.95000000","0.00000000"],["78768.00000000","0.02407000"],["78768.28000000","0.00000000"],["78768.85000000","0.00000000"],["78768.90000000","0.00000000"],["78769.00000000","0.00000000"],["78769.01000000","0.00000000"],["78769.14000000","0.00000000"],["78769.79000000","0.00000000"],["78769.80000000","0.02161000"],["78769.99000000","0.00000000"],["78770.87000000","0.00253000"],["78771.25000000","0.00253000"],["78771.64000000","0.00000000"],["78771.65000000","0.00000000"],["78772.36000000","0.00000000"],["78772.78000000","0.00000000"],["78773.38000000","0.00634000"],["78773.62000000","0.00634000"],["78775.35000000","0.00000000"],["78775.36000000","0.00000000"],["78777.04000000","0.00634000"],["78777.99000000","0.00000000"],["78782.81000000","1.90515000"],["78782.83000000","0.00000000"],["78785.58000000","0.00007000"],["78855.92000000","0.93647000"],["78856.19000000","0.00000000"],["78927.85000000","0.00026000"],["79155.81000000","0.01000000"],["79551.59000000","0.01000000"],["79561.19000000","0.00007000"],["79949.35000000","0.01000000"],["80349.10000000","0.01000000"],["80750.84000000","0.01000000"],["81004.85000000","0.00031000"],["81154.60000000","0.01000000"],["81560.37000000","0.01000000"],["81968.17000000","0.01000000"],["82378.01000000","0.01000000"],["82789.90000000","0.01000000"],["83203.85000000","0.01000000"],["83619.87000000","0.01000000"],["84037.97000000","0.01000000"],["84458.16000000","0.01000000"],["84880.45000000","0.01000000"]]}}}
{"rx_ns": 2953567700, "kind": "rest", "req": {"method": "GET", "url": "https://data-api.binance.vision/api/v3/depth?symbol=BTCUSDT&limit=100", "limit": 100, "weight": 5, "sent_ns": 1122004200, "status": 200, "used_weight_1m": "10", "recv_ns": 2104515600}, "frame": {"lastUpdateId":99076491970,"bids":[["78761.99000000","5.20752000"],["78761.98000000","0.00069000"],["78761.97000000","0.00013000"],["78761.05000000","0.00014000"],["78761.04000000","1.90536000"],["78761.03000000","0.49357000"],["78760.72000000","0.03834000"],["78760.60000000","0.00400000"],["78760.25000000","0.05000000"],["78760.00000000","0.00346000"],["78759.99000000","0.00007000"],["78759.76000000","0.00014000"],["78759.60000000","0.00007000"],["78759.46000000","0.04599000"],["78759.29000000","0.05171000"],["78759.20000000","0.00007000"],["78758.64000000","0.00641000"],["78758.63000000","0.00400000"],["78758.38000000","0.03231000"],["78758.37000000","0.00014000"],["78758.21000000","0.00634000"],["78758.20000000","0.04593000"],["78758.04000000","0.00027000"],["78758.00000000","0.00523000"],["78757.99000000","0.03845000"],["78757.98000000","1.58176000"],["78757.69000000","0.00007000"],["78757.63000000","0.00400000"],["78757.34000000","0.00007000"],["78757.32000000","0.00007000"],["78757.00000000","0.00007000"],["78756.98000000","0.00007000"],["78756.79000000","0.03000000"],["78756.66000000","0.00400000"],["78756.00000000","0.09300000"],["78755.99000000","0.30007000"],["78755.93000000","0.37576000"],["78755.60000000","0.00008000"],["78755.52000000","0.02400000"],["78755.29000000","0.00007000"],["78754.76000000","0.00800000"],["78754.75000000","1.90515000"],["78754.74000000","0.02600000"],["78754.73000000","0.02600000"],["78754.69000000","0.00400000"],["78754.67000000","0.00099000"],["78754.52000000","1.21930000"],["78754.50000000","0.00014000"],["78754.00000000","1.24359000"],["78753.99000000","0.03948000"],["78753.46000000","0.02000000"],["78753.42000000","0.00360000"],["78753.41000000","0.02998000"],["78753.40000000","0.01159000"],["78753.24000000","0.00007000"],["78753.22000000","0.02000000"],["78753.19000000","0.02000000"],["78753.18000000","0.08576000"],["78752.72000000","0.00400000"],["78752.38000000","0.00007000"],["78752.37000000","0.00328000"],["78752.36000000","0.00007000"],["78752.14000000","0.01072000"],["78752.00000000","0.02400000"],["78751.21000000","0.00007000"],["78751.19000000","0.00007000"],["78750.75000000","0.00400000"],["78750.64000000","0.00800000"],["78750.63000000","0.00014000"],["78750.22000000","0.12698000"],["78750.20000000","0.03224000"],["78750.07000000","0.02200000"],["78750.05000000","0.02000000"],["78750.02000000","1.90542000"],["78750.01000000","1.58176000"],["78750.00000000","0.12573000"],["78749.99000000","0.00206000"],["78749.89000000","0.00326000"],["78749.73000000","0.02200000"],["78749.65000000","0.00007000"],["78749.60000000","0.02000000"],["78749.27000000","0.02000000"],["78749.23000000","0.00007000"],["78749.16000000","0.02000000"],["78749.15000000","0.00007000"],["78748.78000000","0.00400000"],["78748.69000000","0.04000000"],["78748.48000000","0.00007000"],["78748.17000000","0.00007000"],["78748.00000000","0.02400000"],["78747.90000000","0.00008000"],["78747.10000000","0.00007000"],["78746.81000000","0.00400000"],["78746.76000000","0.00014000"],["78746.58000000","0.02200000"],["78746.26000000","0.13235000"],["78746.25000000","0.12699000"],["78746.17000000","0.00007000"],["78746.10000000","0.00406000"],["78746.08000000","0.00007000"]],"asks":[["78762.00000000","0.63432000"],["78762.01000000","0.00083000"],["78762.02000000","0.00013000"],["78762.15000000","0.00076000"],["78762.20000000","0.00007000"],["78762.24000000","0.00014000"],["78762.87000000","0.00126000"],["78763.00000000","0.00381000"],["78763.12000000","0.00007000"],["78763.41000000","0.00007000"],["78763.89000000","0.00014000"],["78763.90000000","0.19569000"],["78763.99000000","0.00014000"],["78764.00000000","0.02414000"],["78765.07000000","0.00014000"],["78765.08000000","0.01519000"],["78765.49000000","0.00007000"],["78765.52000000","0.00007000"],["78765.75000000","0.00007000"],["78765.97000000","0.00014000"],["78765.98000000","0.20798000"],["78765.99000000","0.00014000"],["78766.00000000","0.02407000"],["78766.11000000","0.00014000"],["78766.23000000","0.00022000"],["78766.34000000","0.02527000"],["78766.58000000","0.00014000"],["78767.52000000","0.00007000"],["78767.57000000","0.00007000"],["78767.60000000","0.03031000"],["78767.83000000","0.00007000"],["78767.88000000","0.00007000"],["78768.00000000","0.02407000"],["78768.66000000","0.00027000"],["78768.86000000","0.03024000"],["78769.07000000","0.00007000"],["78769.12000000","0.02000000"],["78769.61000000","0.00007000"],["78769.80000000","0.02161000"],["78769.81000000","0.12702000"],["78769.83000000","0.00007000"],["78769.88000000","0.21930000"],["78769.98000000","0.00014000"],["78770.00000000","0.02400000"],["78770.30000000","0.31741000"],["78770.87000000","0.00253000"],["78770.88000000","0.00381000"],["78771.00000000","0.00015000"],["78771.25000000","0.00253000"],["78771.26000000","0.00400000"],["78771.66000000","0.00007000"],["78771.76000000","0.00007000"],["78771.79000000","0.00325000"],["78771.83000000","0.00007000"],["78771.93000000","0.00007000"],["78772.00000000","0.02400000"],["78772.22000000","0.00007000"],["78772.37000000","0.38100000"],["78772.64000000","0.00048000"],["78772.79000000","0.03000000"],["78773.16000000","0.00321000"],["78773.38000000","0.00634000"],["78773.39000000","0.00190000"],["78773.40000000","0.00400000"],["78773.62000000","0.00634000"],["78773.63000000","0.00048000"],["78773.65000000","0.38100000"],["78773.69000000","0.04000000"],["78773.71000000","0.00007000"],["78773.85000000","0.00014000"],["78773.88000000","0.02161000"],["78773.89000000","0.08000000"],["78774.00000000","0.02400000"],["78774.01000000","0.00007000"],["78774.12000000","0.00007000"],["78774.19000000","0.00010000"],["78775.37000000","0.00007000"],["78775.64000000","0.00007000"],["78775.76000000","0.00007000"],["78775.84000000","0.00007000"],["78776.00000000","0.02400000"],["78776.36000000","0.00400000"],["78776.38000000","0.00152000"],["78776.40000000","0.02284000"],["78776.60000000","0.00027000"],["78776.67000000","0.00253000"],["78776.88000000","0.00326000"],["78777.04000000","0.00634000"],["78777.05000000","0.12694000"],["78777.17000000","0.02161000"],["78777.72000000","0.00014000"],["78777.76000000","0.03072000"],["78777.81000000","0.00007000"],["78777.83000000","0.00007000"],["78778.00000000","0.02407000"],["78778.33000000","0.00400000"],["78778.70000000","0.00015000"],["78778.80000000","0.00169000"],["78779.01000000","0.00381000"],["78779.34000000","0.00328000"]]}}
{"rx_ns": 2953567700, "frame": {"stream":"btcusdt@depth20","data":{"lastUpdateId":99076492363,"bids":[["78761.99000000","2.82041000"],["78761.98000000","0.00055000"],["78761.97000000","0.00013000"],["78761.04000000","0.00014000"],["78761.03000000","0.49357000"],["78760.73000000","0.00014000"],["78760.72000000","0.03834000"],["78760.60000000","0.00400000"],["78760.00000000","0.00346000"],["78759.99000000","0.00007000"],["78759.76000000","0.00014000"],["78759.60000000","0.00007000"],["78759.47000000","0.00014000"],["78759.46000000","0.04599000"],["78759.30000000","0.00014000"],["78759.29000000","0.05171000"],["78759.20000000","0.00007000"],["78758.63000000","0.00400000"],["78758.37000000","0.00014000"],["78758.21000000","0.00007000"]],"asks":[["78762.00000000","1.19945000"],["78762.01000000","0.00097000"],["78762.02000000","0.00013000"],["78762.15000000","0.00076000"],["78762.20000000","0.00007000"],["78762.24000000","0.00014000"],["78762.41000000","0.00014000"],["78762.42000000","0.22195000"],["78762.87000000","0.00126000"],["78763.00000000","0.00381000"],["78763.41000000","0.00007000"],["78763.82000000","0.00014000"],["78763.83000000","0.31751000"],["78763.99000000","0.00014000"],["78764.00000000","0.02414000"],["78764.13000000","0.00204000"],["78764.54000000","0.00319000"],["78765.08000000","0.01519000"],["78765.49000000","0.00007000"],["78765.52000000","0.00007000"]]}}}
{"rx_ns": 2953840900, "frame": {"stream":"btcusdt@depth","data":{"e":"depthUpdate","E":1787602870014,"s":"BTCUSDT","U":99076491958,"u":99076492363,"b":[["78761.99000000","2.82041000"],["78761.98000000","0.00055000"],["78761.05000000","0.00000000"],["78761.04000000","0.00014000"],["78761.03000000","0.49357000"],["78760.73000000","0.00014000"],["78760.72000000","0.03834000"],["78760.25000000","0.00000000"],["78760.20000000","0.00000000"],["78760.16000000","0.00000000"],["78760.15000000","0.00000000"],["78760.11000000","0.00000000"],["78760.10000000","0.00000000"],["78760.06000000","0.00000000"],["78760.05000000","0.00000000"],["78759.47000000","0.00014000"],["78759.30000000","0.00014000"],["78759.29000000","0.05171000"],["78758.64000000","0.00000000"],["78758.38000000","0.00000000"],["78758.21000000","0.00007000"],["78758.20000000","0.04600000"],["78758.04000000","0.00000000"],["78758.00000000","0.00530000"],["78757.99000000","0.03831000"],["78757.89000000","0.00000000"],["78757.70000000","0.00000000"],["78757.63000000","0.00000000"],["78757.01000000","0.00000000"],["78756.01000000","0.00000000"],["78755.30000000","0.00634000"],["78754.76000000","0.00634000"],["78754.00000000","1.24352000"],["78750.76000000","0.00000000"],["78750.64000000","0.01200000"],["78746.26000000","0.00000000"],["78746.06000000","0.00000000"],["78742.90000000","0.13236000"],["78742.13000000","0.00000000"],["78739.03000000","0.00000000"],["78738.32000000","0.00007000"],["78736.97000000","0.00634000"],["78719.67000000","0.00000000"],["78683.05000000","0.00000000"],["78634.57000000","0.00000000"],["78632.78000000","0.04090000"],["78632.18000000","0.00316000"],["78577.60000000","0.00778000"],["78575.60000000","0.00000000"],["78368.18000000","0.01000000"],["77976.33000000","0.01000000"],["77586.45000000","0.01000000"],["77198.52000000","0.01000000"],["76812.53000000","0.01000000"],["76428.46000000","0.01000000"],["76046.32000000","0.01000000"],["75666.09000000","0.01000000"],["75287.76000000","0.01023000"],["74911.32000000","0.01000000"],["74536.76000000","0.01000000"],["74164.08000000","0.01000000"],["73793.26000000","0.01000000"],["73424.29000000","0.01000000"],["73057.17000000","0.01000000"],["70885.80000000","0.00466000"],["70885.78000000","0.00000000"],["70885.00000000","0.00000000"],["63010.00000000","0.05451000"],["63009.60000000","0.00031000"],["63009.59000000","0.00015000"]],"a":[["78762.00000000","1.19945000"],["78762.01000000","0.00097000"],["78762.41000000","0.00014000"],["78762.42000000","0.22195000"],["78763.12000000","0.00000000"],["78763.82000000","0.00014000"],["78763.83000000","0.31751000"],["78763.89000000","0.00000000"],["78763.90000000","0.00000000"],["78764.13000000","0.00204000"],["78764.54000000","0.00319000"],["78765.07000000","0.00000000"],["78765.08000000","0.01519000"],["78765.97000000","0.00000000"],["78765.98000000","0.00007000"],["78765.99000000","0.00000000"],["78767.59000000","0.00014000"],["78767.60000000","0.03031000"],["78767.68000000","0.01276000"],["78767.71000000","0.00007000"],["78767.72000000","0.06345000"],["78767.82000000","0.00000000"],["78768.00000000","0.02400000"],["78768.65000000","0.00506000"],["78768.79000000","0.00000000"],["78768.80000000","0.00000000"],["78768.87000000","0.00000000"],["78768.91000000","0.00000000"],["78768.99000000","0.00000000"],["78769.06000000","0.00000000"],["78769.07000000","0.00007000"],["78769.09000000","0.00000000"],["78769.13000000","0.00000000"],["78769.14000000","0.00000000"],["78769.31000000","0.00000000"],["78769.34000000","0.00000000"],["78769.79000000","0.00634000"],["78770.29000000","0.00000000"],["78770.30000000","0.00000000"],["78770.87000000","0.00000000"],["78771.24000000","0.00634000"],["78771.25000000","0.00000000"],["78771.65000000","0.00000000"],["78772.63000000","0.00000000"],["78773.38000000","0.00000000"],["78773.62000000","0.00000000"],["78773.70000000","0.00000000"],["78774.11000000","0.00000000"],["78775.36000000","0.00634000"],["78777.04000000","0.00400000"],["78780.60000000","0.06551000"],["78782.57000000","0.07565000"],["78782.73000000","0.34275000"],["78785.58000000","0.00007000"],["78795.03000000","0.00007000"],["78798.49000000","0.43552000"],["78804.54000000","0.00000000"],["78869.04000000","0.02789000"],["78870.84000000","0.00000000"],["79155.81000000","0.01000000"],["79551.59000000","0.01000000"],["79949.35000000","0.01000000"],["80349.10000000","0.01000000"],["80750.84000000","0.01000000"],["81154.60000000","0.01000000"],["81560.37000000","0.01000000"],["81968.17000000","0.01000000"],["82378.01000000","0.01000000"],["82789.90000000","0.01000000"],["83203.85000000","0.01000000"],["83619.87000000","0.01000000"],["84037.97000000","0.01000000"],["84458.16000000","0.01000000"],["84880.45000000","0.01000000"],["150000.00000000","68.97666000"]]}}}
{"rx_ns": 3956081300, "frame": {"stream":"btcusdt@depth20","data":{"lastUpdateId":99076492767,"bids":[["78761.99000000","4.72772000"],["78761.98000000","0.00055000"],["78761.97000000","0.00013000"],["78761.04000000","0.00014000"],["78761.03000000","0.49364000"],["78760.73000000","0.00014000"],["78760.72000000","0.03834000"],["78760.60000000","0.00400000"],["78760.15000000","0.00007000"],["78760.00000000","0.00014000"],["78759.99000000","0.00007000"],["78759.76000000","0.00014000"],["78759.60000000","0.00007000"],["78759.47000000","0.00014000"],["78759.46000000","0.04599000"],["78759.30000000","0.00014000"],["78759.29000000","0.05171000"],["78759.20000000","0.00007000"],["78758.63000000","0.00400000"],["78758.37000000","0.00014000"]],"asks":[["78762.00000000","1.19913000"],["78762.01000000","0.00104000"],["78762.02000000","0.00013000"],["78762.15000000","0.00076000"],["78762.20000000","0.00007000"],["78762.24000000","0.00014000"],["78762.42000000","0.00007000"],["78762.87000000","0.00126000"],["78762.88000000","0.00014000"],["78762.89000000","0.20805000"],["78763.00000000","0.00381000"],["78763.01000000","0.00007000"],["78763.12000000","0.00007000"],["78763.41000000","0.00007000"],["78763.82000000","0.00014000"],["78763.83000000","0.31751000"],["78763.99000000","0.00014000"],["78764.00000000","0.02414000"],["78764.13000000","0.00204000"],["78764.54000000","0.00319000"]]}}}
{"rx_ns": 3956192200, "frame": {"stream":"btcusdt@depth","data":{"e":"depthUpdate","E":1787602871015,"s":"BTCUSDT","U":99076492364,"u":99076492767,"b":[["78761.99000000","4.72772000"],["78761.98000000","0.00055000"],["78761.03000000","0.49364000"],["78760.72000000","0.03834000"],["78760.36000000","0.00000000"],["78760.35000000","0.00000000"],["78760.31000000","0.00000000"],["78760.30000000","0.00000000"],["78760.26000000","0.00000000"],["78760.25000000","0.00000000"],["78760.16000000","0.00000000"],["78760.15000000","0.00007000"],["78760.11000000","0.00000000"],["78760.10000000","0.00000000"],["78760.00000000","0.00014000"],["78759.76000000","0.00014000"],["78759.75000000","0.00000000"],["78759.70000000","0.00000000"],["78759.30000000","0.00014000"],["78759.25000000","0.00000000"],["78758.21000000","0.00007000"],["78758.20000000","0.04600000"],["78758.15000000","0.00000000"],["78758.05000000","0.00541000"],["78758.00000000","0.01007000"],["78757.90000000","0.00027000"],["78757.77000000","0.00400000"],["78757.70000000","0.00000000"],["78757.51000000","0.00000000"],["78757.30000000","0.00000000"],["78756.80000000","0.00000000"],["78756.71000000","0.00000000"],["78756.69000000","0.00400000"],["78756.60000000","0.00254000"],["78756.02000000","0.00634000"],["78756.01000000","0.00634000"],["78755.93000000","0.37569000"],["78755.30000000","0.00000000"],["78754.76000000","0.00800000"],["78754.11000000","0.00267000"],["78738.32000000","0.00000000"],["78683.05000000","0.02115000"],["78615.53000000","1.52163000"],["78368.18000000","0.01000000"],["77976.33000000","0.01000000"],["77586.45000000","0.01000000"],["77198.52000000","0.01000000"],["76812.53000000","0.01000000"],["76428.46000000","0.01000000"],["76046.32000000","0.01000000"],["75666.09000000","0.01000000"],["75287.76000000","0.01023000"],["74911.32000000","0.01000000"],["74536.76000000","0.01000000"],["74164.08000000","0.01000000"],["73793.26000000","0.01000000"],["73424.29000000","0.01000000"],["73057.17000000","0.01000000"],["72460.16000000","0.00000000"],["70885.80000000","0.00457000"],["70885.79000000","0.00009000"],["70885.00000000","0.00000000"],["63010.00000000","0.05451000"],["63009.60000000","0.00031000"],["63009.59000000","0.00015000"]],"a":[["78762.00000000","1.19913000"],["78762.01000000","0.00104000"],["78762.41000000","0.00000000"],["78762.42000000","0.00007000"],["78762.88000000","0.00014000"],["78762.89000000","0.20805000"],["78763.00000000","0.00381000"],["78763.01000000","0.00007000"],["78763.12000000","0.00007000"],["78763.83000000","0.31751000"],["78763.96000000","0.00000000"],["78763.97000000","0.00000000"],["78763.99000000","0.00014000"],["78765.98000000","0.00000000"],["78765.99000000","0.00014000"],["78766.33000000","0.00007000"],["78767.59000000","0.00000000"],["78767.60000000","0.03031000"],["78767.68000000","0.00000000"],["78767.71000000","0.00000000"],["78767.72000000","0.00000000"],["78768.20000000","0.00000000"],["78768.30000000","0.00000000"],["78768.65000000","0.00000000"],["78768.78000000","0.00000000"],["78768.81000000","0.00000000"],["78769.06000000","0.00506000"],["78769.60000000","0.00000000"],["78769.79000000","0.00000000"],["78769.80000000","0.02161000"],["78769.87000000","0.00000000"],["78770.73000000","0.00634000"],["78770.74000000","0.38093000"],["78770.87000000","0.00000000"],["78771.23000000","0.00000000"],["78771.24000000","0.00000000"],["78771.49000000","0.00000000"],["78771.50000000","0.00000000"],["78771.96000000","0.00400000"],["78772.21000000","0.00000000"],["78772.35000000","0.00254000"],["78772.45000000","0.00000000"],["78772.78000000","0.00000000"],["78773.05000000","0.00000000"],["78773.25000000","0.00000000"],["78773.38000000","0.00634000"],["78773.65000000","0.00000000"],["78775.36000000","0.00000000"],["78776.59000000","0.00634000"],["78785.58000000","0.00000000"],["78914.82000000","1.52163000"],["79155.81000000","0.01000000"],["79551.59000000","0.01000000"],["79949.35000000","0.01000000"],["80349.10000000","0.01000000"],["80750.84000000","0.01000000"],["81154.60000000","0.01000000"],["81560.37000000","0.01000000"],["81968.17000000","0.01000000"],["82378.01000000","0.01000000"],["82789.90000000","0.01000000"],["83203.85000000","0.01000000"],["83619.87000000","0.01000000"],["84037.97000000","0.01000000"],["84458.16000000","0.01000000"],["84880.45000000","0.01000000"]]}}}
{"rx_ns": 4958682900, "frame": {"stream":"btcusdt@depth20","data":{"lastUpdateId":99076493173,"bids":[["78761.99000000","5.17867000"],["78761.98000000","0.00041000"],["78761.97000000","0.00013000"],["78761.04000000","0.00014000"],["78761.03000000","0.49364000"],["78760.74000000","0.00634000"],["78760.73000000","0.00014000"],["78760.72000000","0.03834000"],["78760.61000000","0.00321000"],["78760.60000000","0.00400000"],["78760.16000000","0.00007000"],["78760.15000000","0.00007000"],["78760.00000000","0.00014000"],["78759.99000000","0.00007000"],["78759.76000000","0.00014000"],["78759.60000000","0.00007000"],["78759.47000000","0.00014000"],["78759.46000000","0.04599000"],["78759.30000000","0.00014000"],["78759.29000000","0.05171000"]],"asks":[["78762.00000000","0.79287000"],["78762.01000000","0.00083000"],["78762.02000000","0.00013000"],["78762.15000000","0.00076000"],["78762.20000000","0.00007000"],["78762.24000000","0.00007000"],["78762.42000000","0.00007000"],["78762.87000000","0.00126000"],["78763.00000000","0.00381000"],["78763.12000000","0.00007000"],["78763.41000000","0.00007000"],["78763.83000000","0.00007000"],["78763.99000000","0.00014000"],["78764.00000000","0.02414000"],["78764.13000000","0.00204000"],["78764.54000000","0.00319000"],["78765.07000000","0.00014000"],["78765.08000000","0.01519000"],["78765.49000000","0.00007000"],["78765.52000000","0.00007000"]]}}}
{"rx_ns": 4958782100, "frame": {"stream":"btcusdt@depth","data":{"e":"depthUpdate","E":1787602872014,"s":"BTCUSDT","U":99076492768,"u":99076493173,"b":[["78761.99000000","5.17867000"],["78761.98000000","0.00041000"],["78761.52000000","0.00000000"],["78761.05000000","0.00000000"],["78761.03000000","0.49364000"],["78760.74000000","0.00634000"],["78760.72000000","0.03834000"],["78760.61000000","0.00321000"],["78760.21000000","0.00000000"],["78760.20000000","0.00000000"],["78760.16000000","0.00007000"],["78760.15000000","0.00007000"],["78760.11000000","0.00000000"],["78760.10000000","0.00000000"],["78760.06000000","0.00000000"],["78760.05000000","0.00000000"],["78759.30000000","0.00014000"],["78759.29000000","0.05171000"],["78758.64000000","0.00641000"],["78758.62000000","0.02000000"],["78758.53000000","0.00254000"],["78758.21000000","0.00000000"],["78758.05000000","0.00534000"],["78758.00000000","0.01707000"],["78757.80000000","0.03224000"],["78756.60000000","0.00000000"],["78756.02000000","0.00000000"],["78756.01000000","0.00000000"],["78756.00000000","0.09900000"],["78753.46000000","0.00000000"],["78744.59000000","0.34292000"],["78742.91000000","0.61061000"],["78740.75000000","0.00000000"],["78738.32000000","0.00007000"],["78731.70000000","0.00400000"],["78731.05000000","0.00000000"],["78730.30000000","0.00000000"],["78710.82000000","0.04762000"],["78686.54000000","0.00000000"],["78683.05000000","0.00000000"],["78657.58000000","2.77023000"],["78654.97000000","0.00000000"],["78368.18000000","0.01000000"],["77976.33000000","0.01000000"],["77586.45000000","0.01000000"],["77198.52000000","0.01000000"],["76812.53000000","0.01000000"],["76428.46000000","0.01000000"],["76046.32000000","0.01000000"],["75666.09000000","0.01000000"],["75287.76000000","0.01023000"],["74911.32000000","0.01000000"],["74536.76000000","0.01000000"],["74164.08000000","0.01000000"],["73793.26000000","0.01000000"],["73424.29000000","0.01000000"],["73057.17000000","0.01000000"],["70885.80000000","0.00473000"],["70885.00000000","0.00000000"],["63010.00000000","0.05451000"],["63009.60000000","0.00031000"],["63009.59000000","0.00015000"]],"a":[["78762.00000000","0.79287000"],["78762.01000000","0.00083000"],["78762.24000000","0.00007000"],["78762.88000000","0.00000000"],["78762.89000000","0.00000000"],["78763.01000000","0.00000000"],["78763.82000000","0.00000000"],["78763.83000000","0.00007000"],["78765.07000000","0.00014000"],["78765.08000000","0.01519000"],["78765.60000000","0.00000000"],["78765.61000000","0.00007000"],["78765.64000000","0.00000000"],["78765.65000000","0.00014000"],["78765.99000000","0.00014000"],["78766.33000000","0.00014000"],["78767.59000000","0.00007000"],["78768.00000000","0.02407000"],["78768.85000000","0.00000000"],["78769.02000000","0.00000000"],["78769.06000000","0.00000000"],["78769.12000000","0.00000000"],["78769.28000000","0.00000000"],["78769.31000000","0.00000000"],["78769.68000000","0.12704000"],["78770.19000000","0.31741000"],["78770.22000000","0.00000000"],["78770.72000000","0.00253000"],["78770.73000000","0.00000000"],["78770.87000000","0.00000000"],["78771.00000000","0.00007000"],["78771.25000000","0.00253000"],["78771.79000000","0.00000000"],["78771.96000000","0.00000000"],["78772.30000000","0.00048000"],["78772.35000000","0.00000000"],["78772.71000000","0.00068000"],["78772.82000000","0.00400000"],["78772.83000000","0.00000000"],["78773.14000000","0.31745000"],["78773.15000000","0.00634000"],["78773.16000000","0.00000000"],["78773.38000000","0.00000000"],["78773.39000000","0.00190000"],["78774.18000000","0.00000000"],["78774.27000000","0.00254000"],["78774.40000000","0.00000000"],["78775.99000000","0.00634000"],["78776.23000000","0.02000000"],["78777.04000000","0.00000000"],["78780.00000000","0.02400000"],["78782.73000000","0.00000000"],["78783.29000000","0.00000000"],["78785.58000000","0.00007000"],["78791.97000000","0.63466000"],["78802.87000000","0.00000000"],["78803.00000000","0.34266000"],["78805.42000000","0.00000000"],["78887.68000000","0.01988000"],["78954.90000000","0.00000000"],["79155.81000000","0.01000000"],["79551.59000000","0.01000000"],["79949.35000000","0.01000000"],["80349.10000000","0.01000000"],["80750.84000000","0.01000000"],["81154.60000000","0.01000000"],["81560.37000000","0.01000000"],["81968.17000000","0.01000000"],["82378.01000000","0.01000000"],["82789.90000000","0.01000000"],["83203.85000000","0.01000000"],["83619.87000000","0.01000000"],["84037.97000000","0.01000000"],["84458.16000000","0.01000000"],["84880.45000000","0.01000000"]]}}}
{"rx_ns": 5955477900, "frame": {"stream":"btcusdt@depth20","data":{"lastUpdateId":99076493994,"bids":[["78761.99000000","1.85670000"],["78761.98000000","0.00069000"],["78761.97000000","0.00013000"],["78761.04000000","0.00014000"],["78761.03000000","0.01220000"],["78760.73000000","0.00014000"],["78760.72000000","0.03834000"],["78760.57000000","0.00014000"],["78760.56000000","0.20791000"],["78760.55000000","0.00204000"],["78760.00000000","0.00521000"],["78759.99000000","0.00007000"],["78759.76000000","0.00014000"],["78759.60000000","0.00007000"],["78759.47000000","0.00014000"],["78759.46000000","0.04599000"],["78759.36000000","0.00007000"],["78759.30000000","0.00007000"],["78759.29000000","0.05171000"],["78759.20000000","0.00007000"]],"asks":[["78762.00000000","2.10104000"],["78762.01000000","0.00097000"],["78762.02000000","0.00013000"],["78762.20000000","0.00007000"],["78762.24000000","0.00014000"],["78762.87000000","0.00126000"],["78762.94000000","0.00076000"],["78763.00000000","0.00381000"],["78763.12000000","0.00007000"],["78763.41000000","0.00007000"],["78763.56000000","0.00014000"],["78763.57000000","0.31765000"],["78763.58000000","0.00014000"],["78763.59000000","0.25402000"],["78763.86000000","0.00400000"],["78763.91000000","0.00007000"],["78763.99000000","0.00014000"],["78764.00000000","0.02414000"],["78764.44000000","0.00007000"],["78764.54000000","0.00319000"]]}}}
{"rx_ns": 5955579300, "frame": {"stream":"btcusdt@depth","data":{"e":"depthUpdate","E":1787602873014,"s":"BTCUSDT","U":99076493174,"u":99076493994,"b":[["78761.99000000","1.85670000"],["78761.98000000","0.00069000"],["78761.03000000","0.01220000"],["78760.74000000","0.00000000"],["78760.72000000","0.03834000"],["78760.61000000","0.00000000"],["78760.60000000","0.00000000"],["78760.57000000","0.00014000"],["78760.56000000","0.20791000"],["78760.55000000","0.00204000"],["78760.46000000","0.00000000"],["78760.45000000","0.00000000"],["78760.36000000","0.00000000"],["78760.35000000","0.00000000"],["78760.31000000","0.00000000"],["78760.30000000","0.00000000"],["78760.25000000","0.00000000"],["78760.16000000","0.00000000"],["78760.15000000","0.00000000"],["78760.00000000","0.00521000"],["78759.76000000","0.00014000"],["78759.75000000","0.00000000"],["78759.36000000","0.00007000"],["78759.35000000","0.00000000"],["78759.30000000","0.00007000"],["78759.29000000","0.05171000"],["78758.64000000","0.00000000"],["78758.63000000","0.00000000"],["78758.62000000","0.00000000"],["78758.53000000","0.00000000"],["78758.37000000","0.00007000"],["78758.21000000","0.00000000"],["78758.20000000","0.04600000"],["78758.05000000","0.00541000"],["78758.00000000","0.02407000"],["78757.99000000","0.00027000"],["78757.98000000","0.00000000"],["78757.90000000","0.00000000"],["78757.80000000","0.00000000"],["78757.77000000","0.00000000"],["78757.70000000","0.00000000"],["78757.47000000","0.00000000"],["78757.35000000","0.00000000"],["78756.79000000","0.00000000"],["78756.69000000","0.00000000"],["78756.66000000","0.00000000"],["78756.25000000","0.00000000"],["78756.05000000","0.00000000"],["78756.00000000","0.02400000"],["78755.99000000","0.00007000"],["78755.93000000","0.01246000"],["78755.79000000","0.00000000"],["78755.64000000","0.00000000"],["78755.62000000","0.00000000"],["78755.58000000","0.00330000"],["78754.77000000","0.00000000"],["78754.76000000","2.26739000"],["78754.75000000","0.00000000"],["78754.67000000","0.00000000"],["78754.59000000","0.01000000"],["78754.52000000","0.00000000"],["78754.50000000","0.00014000"],["78754.49000000","0.00000000"],["78754.11000000","0.22197000"],["78754.00000000","0.02400000"],["78753.42000000","0.00000000"],["78753.40000000","0.00000000"],["78753.18000000","0.00000000"],["78753.01000000","0.00000000"],["78752.51000000","0.00000000"],["78752.40000000","0.00400000"],["78752.39000000","1.21952000"],["78752.13000000","0.00254000"],["78752.07000000","0.00048000"],["78752.01000000","0.00634000"],["78751.97000000","0.08576000"],["78751.81000000","0.00164000"],["78751.78000000","0.00000000"],["78751.68000000","0.00000000"],["78751.67000000","0.00000000"],["78751.64000000","0.00027000"],["78751.63000000","0.00000000"],["78751.61000000","0.00000000"],["78751.57000000","0.00000000"],["78751.40000000","0.00000000"],["78751.36000000","0.00048000"],["78751.29000000","0.02000000"],["78751.13000000","0.00000000"],["78750.72000000","0.00000000"],["78750.64000000","0.00000000"],["78750.63000000","0.00014000"],["78750.55000000","0.00191000"],["78750.28000000","0.00000000"],["78750.20000000","0.00000000"],["78750.03000000","0.00400000"],["78750.02000000","0.00000000"],["78750.01000000","0.00000000"],["78750.00000000","0.03683000"],["78749.51000000","0.02000000"],["78749.32000000","0.00000000"],["78749.27000000","0.02000000"],["78748.69000000","0.00000000"],["78748.52000000","0.00000000"],["78748.25000000","1.90515000"],["78747.90000000","1.21960000"],["78747.67000000","1.21916000"],["78747.11000000","0.01200000"],["78746.77000000","0.00000000"],["78746.76000000","0.00014000"],["78746.59000000","0.00000000"],["78746.25000000","0.00000000"],["78745.91000000","0.00000000"],["78745.23000000","0.36224000"],["78745.09000000","0.04000000"],["78744.59000000","0.00000000"],["78744.33000000","0.00000000"],["78743.91000000","1.21952000"],["78743.40000000","1.90515000"],["78743.39000000","0.00000000"],["78742.91000000","0.00000000"],["78742.90000000","0.00000000"],["78742.89000000","0.00014000"],["78742.51000000","0.00000000"],["78742.23000000","0.00000000"],["78741.41000000","0.00000000"],["78740.74000000","0.00000000"],["78740.70000000","0.50191000"],["78739.68000000","1.21952000"],["78739.02000000","0.00014000"],["78738.60000000","1.90515000"],["78738.58000000","0.00000000"],["78738.57000000","0.00000000"],["78738.55000000","0.00000000"],["78738.32000000","0.00007000"],["78737.27000000","0.00000000"],["78737.18000000","0.00000000"],["78736.99000000","0.61068000"],["78736.98000000","0.13237000"],["78736.97000000","0.00000000"],["78736.01000000","0.00000000"],["78735.42000000","1.21952000"],["78735.15000000","0.00014000"],["78734.14000000","0.00000000"],["78733.62000000","1.90515000"],["78733.04000000","0.00000000"],["78732.97000000","0.00634000"],["78731.48000000","1.21952000"],["78730.19000000","0.00000000"],["78729.89000000","0.34298000"],["78728.42000000","1.90515000"],["78728.22000000","0.00000000"],["78727.68000000","0.00400000"],["78726.01000000","1.21952000"],["78725.99000000","0.00000000"],["78725.63000000","0.00000000"],["78724.06000000","0.34301000"],["78723.66000000","0.00400000"],["78723.59000000","1.90515000"],["78723.47000000","0.00000000"],["78721.24000000","1.21952000"],["78720.00000000","0.38624000"],["78719.67000000","0.00007000"],["78719.64000000","0.00400000"],["78717.78000000","0.00000000"],["78716.74000000","0.04539000"],["78715.98000000","0.00000000"],["78715.92000000","1.21952000"],["78715.91000000","1.25784000"],["78715.80000000","0.00000000"],["78714.13000000","1.90515000"],["78712.90000000","0.00000000"],["78711.00000000","1.21952000"],["78710.00000000","0.02400000"],["78708.14000000","0.00000000"],["78706.00000000","0.02400000"],["78704.67000000","1.90515000"],["78702.08000000","1.21952000"],["78702.07000000","0.00007000"],["78701.64000000","0.00000000"],["78696.84000000","1.90515000"],["78696.83000000","0.00000000"],["78692.30000000","1.25822000"],["78690.72000000","0.00315000"],["78684.15000000","0.00000000"],["78683.05000000","0.00000000"],["78660.19000000","0.00000000"],["78657.58000000","0.00000000"],["78655.07000000","1.21952000"],["78651.46000000","1.90515000"],["78642.00000000","1.92915000"],["78638.31000000","0.00076000"],["78637.51000000","0.00000000"],["78632.18000000","0.00000000"],["78621.73000000","0.01988000"],["78614.53000000","0.00000000"],["78612.01000000","0.00126000"],["78555.39000000","0.00385000"],["78554.59000000","0.00000000"],["78368.18000000","0.00000000"],["77976.33000000","0.00000000"],["77586.45000000","0.00000000"],["77198.52000000","0.00000000"],["76812.53000000","0.00000000"],["76428.46000000","0.00000000"],["76046.32000000","0.00000000"],["75666.09000000","0.00000000"],["75287.76000000","0.00023000"],["74911.32000000","0.00000000"],["74536.76000000","0.00000000"],["74164.08000000","0.00000000"],["73793.26000000","0.00000000"],["73424.29000000","0.00000000"],["73057.17000000","0.00000000"],["70885.80000000","0.00457000"],["70885.00000000","0.00000000"],["63010.00000000","0.05451000"],["63009.60000000","0.00031000"],["63009.59000000","0.00015000"]],"a":[["78762.00000000","2.10104000"],["78762.01000000","0.00097000"],["78762.15000000","0.00000000"],["78762.24000000","0.00014000"],["78762.42000000","0.00000000"],["78762.44000000","0.00000000"],["78762.45000000","0.00000000"],["78762.94000000","0.00076000"],["78763.56000000","0.00014000"],["78763.57000000","0.31765000"],["78763.58000000","0.00014000"],["78763.59000000","0.25402000"],["78763.83000000","0.00000000"],["78763.86000000","0.00400000"],["78763.91000000","0.00007000"],["78763.98000000","0.00000000"],["78764.13000000","0.00000000"],["78764.26000000","0.00000000"],["78764.43000000","0.00000000"],["78764.44000000","0.00007000"],["78765.01000000","0.00000000"],["78765.06000000","0.00000000"],["78765.07000000","0.00000000"],["78765.08000000","0.01519000"],["78765.32000000","0.00000000"],["78765.33000000","0.00000000"],["78765.49000000","0.00000000"],["78765.51000000","0.00506000"],["78765.61000000","0.00000000"],["78765.65000000","0.00000000"],["78765.87000000","0.00400000"],["78765.99000000","0.00000000"],["78766.02000000","0.00000000"],["78766.33000000","0.00000000"],["78766.34000000","0.02527000"],["78766.46000000","0.00000000"],["78766.62000000","0.02168000"],["78766.63000000","0.00000000"],["78767.07000000","0.00000000"],["78767.11000000","0.00000000"],["78767.12000000","0.02007000"],["78767.31000000","0.00000000"],["78767.51000000","0.00634000"],["78767.58000000","0.00014000"],["78767.59000000","0.31745000"],["78767.60000000","0.03024000"],["78767.64000000","0.04041000"],["78767.88000000","0.00661000"],["78768.00000000","0.02400000"],["78768.65000000","0.00000000"],["78768.86000000","0.03024000"],["78769.60000000","0.00634000"],["78769.68000000","0.00000000"],["78769.79000000","0.00000000"],["78769.81000000","0.12695000"],["78769.89000000","0.00400000"],["78770.19000000","0.00000000"],["78770.72000000","0.00000000"],["78770.87000000","0.00634000"],["78771.25000000","0.00000000"],["78771.26000000","0.00000000"],["78771.90000000","0.00400000"],["78771.99000000","0.00000000"],["78772.30000000","0.00000000"],["78772.37000000","0.00000000"],["78772.64000000","0.00000000"],["78772.71000000","0.00000000"],["78772.88000000","0.00324000"],["78773.14000000","0.00000000"],["78773.15000000","0.00000000"],["78773.39000000","0.00000000"],["78773.63000000","0.00000000"],["78774.27000000","0.00000000"],["78774.45000000","0.00332000"],["78775.91000000","0.38087000"],["78775.99000000","0.00000000"],["78776.23000000","0.00000000"],["78776.59000000","0.00000000"],["78777.04000000","1.21952000"],["78777.07000000","0.01200000"],["78777.19000000","1.90515000"],["78777.71000000","0.00455000"],["78778.15000000","0.04103000"],["78778.80000000","0.00000000"],["78779.35000000","0.00419000"],["78780.00000000","0.08981000"],["78781.25000000","0.34276000"],["78782.10000000","0.34276000"],["78782.56000000","0.36224000"],["78782.82000000","0.00000000"],["78783.11000000","0.34275000"],["78783.48000000","0.38083000"],["78785.58000000","0.00007000"],["78787.27000000","0.43558000"],["78790.68000000","0.04620000"],["78790.72000000","0.00000000"],["78794.01000000","0.00400000"],["78794.09000000","0.00000000"],["78796.06000000","0.00000000"],["78796.55000000","0.00000000"],["78796.74000000","0.00000000"],["78797.42000000","0.00000000"],["78798.03000000","0.00000000"],["78798.49000000","0.00000000"],["78800.00000000","0.13762000"],["78800.78000000","0.02515000"],["78801.22000000","1.25648000"],["78801.97000000","0.00000000"],["78802.09000000","0.00000000"],["78803.00000000","0.00000000"],["78808.08000000","0.00000000"],["78813.04000000","0.00000000"],["78819.66000000","0.00000000"],["78820.45000000","0.00385000"],["78846.19000000","0.00000000"],["78846.20000000","0.00000000"],["78846.21000000","0.00000000"],["78858.74000000","0.00529000"],["78861.29000000","0.00000000"],["78887.68000000","0.00000000"],["78911.23000000","0.00000000"],["78959.51000000","0.01988000"],["79155.81000000","0.00000000"],["79551.59000000","0.00000000"],["79949.35000000","0.00000000"],["80349.10000000","0.00000000"],["80750.84000000","0.00000000"],["81154.60000000","0.00000000"],["81560.37000000","0.00000000"],["81968.17000000","0.00000000"],["82378.01000000","0.00000000"],["82789.90000000","0.00000000"],["83203.85000000","0.00000000"],["83619.87000000","0.00000000"],["84037.97000000","0.00000000"],["84458.16000000","0.00000000"],["84880.45000000","0.00000000"]]}}}
{"rx_ns": 6954253600, "frame": {"stream":"btcusdt@depth20","data":{"lastUpdateId":99076494217,"bids":[["78761.99000000","1.86358000"],["78761.98000000","0.00069000"],["78761.97000000","0.00013000"],["78761.04000000","0.00014000"],["78761.03000000","0.01220000"],["78760.73000000","0.00014000"],["78760.72000000","0.03834000"],["78760.57000000","0.00014000"],["78760.56000000","0.20791000"],["78760.55000000","0.00204000"],["78760.00000000","0.00521000"],["78759.99000000","0.00007000"],["78759.76000000","0.00014000"],["78759.60000000","0.00007000"],["78759.47000000","0.00014000"],["78759.46000000","0.04599000"],["78759.30000000","0.00007000"],["78759.29000000","0.05171000"],["78759.20000000","0.00007000"],["78758.37000000","0.00007000"]],"asks":[["78762.00000000","2.61188000"],["78762.01000000","0.00090000"],["78762.02000000","0.00013000"],["78762.03000000","0.00014000"],["78762.04000000","0.06345000"],["78762.20000000","0.00007000"],["78762.24000000","0.00014000"],["78762.87000000","0.00126000"],["78762.94000000","0.00076000"],["78763.00000000","0.00381000"],["78763.12000000","0.00007000"],["78763.41000000","0.00007000"],["78763.56000000","0.00014000"],["78763.57000000","0.31758000"],["78763.58000000","0.00014000"],["78763.59000000","0.25402000"],["78763.86000000","0.00400000"],["78763.91000000","0.00007000"],["78764.00000000","0.02414000"],["78764.54000000","0.00319000"]]}}}
{"rx_ns": 6954428700, "frame": {"stream":"btcusdt@depth","data":{"e":"depthUpdate","E":1787602874014,"s":"BTCUSDT","U":99076493995,"u":99076494217,"b":[["78761.99000000","1.86358000"],["78759.36000000","0.00000000"],["78754.79000000","0.00254000"],["78753.12000000","0.00000000"],["78752.55000000","0.00400000"],["78752.40000000","0.00000000"],["78752.13000000","0.00000000"],["78748.26000000","0.00800000"],["78747.11000000","0.00400000"],["78745.77000000","0.12699000"],["78738.32000000","0.00007000"],["78729.63000000","0.02000000"],["78721.65000000","0.00400000"],["78719.64000000","0.00000000"],["78678.35000000","0.02115000"],["78577.60000000","0.00000000"],["78573.49000000","0.00778000"],["78368.18000000","0.00000000"],["78053.13000000","0.00000000"],["77976.33000000","0.00000000"],["77586.45000000","0.00000000"],["77198.52000000","0.00000000"],["76812.53000000","0.00000000"],["76428.46000000","0.00000000"],["76046.32000000","0.00000000"],["75666.09000000","0.00000000"],["75287.76000000","0.00023000"],["74911.32000000","0.00000000"],["74536.76000000","0.00000000"],["74164.08000000","0.00000000"],["73793.26000000","0.00000000"],["73424.29000000","0.00000000"],["73057.17000000","0.00000000"],["70885.80000000","0.00425000"],["70885.79000000","0.00000000"],["70885.00000000","0.00000000"],["63010.00000000","0.05451000"],["63009.60000000","0.00031000"],["63009.59000000","0.00015000"]],"a":[["78762.00000000","2.61188000"],["78762.01000000","0.00090000"],["78762.03000000","0.00014000"],["78762.04000000","0.06345000"],["78763.57000000","0.31758000"],["78763.59000000","0.25402000"],["78763.99000000","0.00000000"],["78764.44000000","0.00000000"],["78765.08000000","0.01519000"],["78765.51000000","0.00000000"],["78765.86000000","0.00513000"],["78766.89000000","0.00000000"],["78767.12000000","0.02000000"],["78767.17000000","0.00000000"],["78767.18000000","0.00000000"],["78767.19000000","0.00000000"],["78767.20000000","0.00000000"],["78767.58000000","0.00000000"],["78767.59000000","0.00000000"],["78767.63000000","0.31761000"],["78767.87000000","0.00000000"],["78767.88000000","0.00407000"],["78768.84000000","0.00007000"],["78768.85000000","0.00000000"],["78768.86000000","0.03024000"],["78770.53000000","0.00254000"],["78770.87000000","0.00000000"],["78772.21000000","0.00634000"],["78777.45000000","0.02000000"],["78778.18000000","0.02000000"],["78778.24000000","0.02000000"],["78778.26000000","0.02000000"],["78785.52000000","0.00000000"],["78785.58000000","0.00007000"],["78786.22000000","0.00000000"],["78786.29000000","0.00000000"],["78786.30000000","0.00000000"],["78786.32000000","0.00405000"],["78789.93000000","0.00010000"],["78825.72000000","0.00405000"],["78829.33000000","0.00000000"],["78857.23000000","0.00405000"],["78860.85000000","0.00000000"],["78887.05000000","0.00000000"],["78904.50000000","0.00405000"],["78908.12000000","0.00000000"],["78926.49000000","0.00000000"],["78975.41000000","0.00405000"],["78979.03000000","0.00000000"],["79155.81000000","0.00000000"],["79551.59000000","0.00000000"],["79949.35000000","0.00000000"],["80349.10000000","0.00000000"],["80750.84000000","0.00000000"],["81154.60000000","0.00000000"],["81560.37000000","0.00000000"],["81968.17000000","0.00000000"],["82378.01000000","0.00000000"],["82789.90000000","0.00000000"],["83203.85000000","0.00000000"],["83619.87000000","0.00000000"],["84037.97000000","0.00000000"],["84458.16000000","0.00000000"],["84880.45000000","0.00000000"],["150000.00000000","68.97649000"]]}}}
{"rx_ns": 7957442500, "frame": {"stream":"btcusdt@depth20","data":{"lastUpdateId":99076494423,"bids":[["78761.99000000","2.08335000"],["78761.98000000","0.00069000"],["78761.97000000","0.00013000"],["78761.04000000","0.00014000"],["78761.03000000","0.01220000"],["78760.73000000","0.00014000"],["78760.72000000","0.03834000"],["78760.57000000","0.00014000"],["78760.56000000","0.20798000"],["78760.55000000","0.00204000"],["78760.00000000","0.00521000"],["78759.99000000","0.00007000"],["78759.76000000","0.00014000"],["78759.60000000","0.00007000"],["78759.47000000","0.00014000"],["78759.46000000","0.04599000"],["78759.30000000","0.00007000"],["78759.29000000","0.05171000"],["78759.20000000","0.00007000"],["78758.37000000","0.00007000"]],"asks":[["78762.00000000","2.39011000"],["78762.01000000","0.00083000"],["78762.02000000","0.00013000"],["78762.03000000","0.00014000"],["78762.04000000","0.06352000"],["78762.20000000","0.00007000"],["78762.24000000","0.00014000"],["78762.87000000","0.00126000"],["78762.94000000","0.00076000"],["78763.00000000","0.00381000"],["78763.12000000","0.00007000"],["78763.41000000","0.00007000"],["78763.56000000","0.00014000"],["78763.57000000","0.31758000"],["78763.58000000","0.00014000"],["78763.59000000","0.25402000"],["78763.86000000","0.00400000"],["78763.91000000","0.00007000"],["78764.00000000","0.02414000"],["78765.08000000","0.01519000"]]}}}
{"rx_ns": 7957533400, "frame": {"stream":"btcusdt@depth","data":{"e":"depthUpdate","E":1787602875014,"s":"BTCUSDT","U":99076494218,"u":99076494423,"b":[["78761.99000000","2.08335000"],["78760.56000000","0.20798000"],["78759.29000000","0.05171000"],["78759.10000000","0.00000000"],["78759.05000000","0.00000000"],["78759.00000000","0.00000000"],["78758.20000000","0.04593000"],["78758.05000000","0.00534000"],["78754.79000000","0.00000000"],["78753.87000000","0.00254000"],["78753.20000000","0.00634000"],["78752.07000000","0.00000000"],["78750.00000000","0.03049000"],["78738.32000000","0.00007000"],["78738.07000000","0.54348000"],["78736.99000000","0.00000000"],["78729.49000000","0.00400000"],["78721.65000000","0.00000000"],["78679.42000000","0.00000000"],["78678.35000000","0.02115000"],["78652.36000000","2.77023000"],["78368.18000000","0.00000000"],["78053.13000000","0.00010000"],["77976.33000000","0.00000000"],["77586.45000000","0.00000000"],["77198.52000000","0.00000000"],["76812.53000000","0.00000000"],["76428.46000000","0.00000000"],["76046.32000000","0.00000000"],["75666.09000000","0.00000000"],["75287.76000000","0.00023000"],["74911.32000000","0.00000000"],["74536.76000000","0.00000000"],["74164.08000000","0.00000000"],["73793.26000000","0.00000000"],["73424.29000000","0.00000000"],["73057.17000000","0.00000000"],["70885.80000000","0.00457000"],["70885.00000000","0.00000000"],["65146.32000000","0.01188000"],["63010.00000000","0.05451000"],["63009.60000000","0.00031000"],["63009.59000000","0.00015000"]],"a":[["78762.00000000","2.39011000"],["78762.01000000","0.00083000"],["78762.04000000","0.06352000"],["78763.59000000","0.25402000"],["78764.54000000","0.00000000"],["78766.62000000","0.02161000"],["78767.62000000","0.00000000"],["78767.63000000","0.00014000"],["78768.84000000","0.00000000"],["78768.85000000","0.31747000"],["78769.62000000","0.00254000"],["78769.80000000","0.02168000"],["78770.53000000","0.00000000"],["78785.58000000","0.00007000"],["78823.99000000","0.00190000"],["78825.71000000","0.02000000"],["78888.01000000","0.00160000"],["78903.51000000","0.00076000"],["78927.45000000","0.00160000"],["79000.00000000","1.93292000"],["79155.81000000","0.00000000"],["79551.59000000","0.00000000"],["79949.35000000","0.00000000"],["80349.10000000","0.00000000"],["80750.84000000","0.00000000"],["81154.60000000","0.00000000"],["81560.37000000","0.00000000"],["81968.17000000","0.00000000"],["82378.01000000","0.00000000"],["82789.90000000","0.00000000"],["83203.85000000","0.00000000"],["83619.87000000","0.00000000"],["84037.97000000","0.00000000"],["84458.16000000","0.00000000"],["84880.45000000","0.00000000"]]}}}
{"rx_ns": 8956944100, "frame": {"stream":"btcusdt@depth20","data":{"lastUpdateId":99076494600,"bids":[["78761.99000000","1.86372000"],["78761.98000000","0.00069000"],["78761.97000000","0.00013000"],["78761.04000000","0.00014000"],["78761.03000000","0.01220000"],["78760.73000000","0.00014000"],["78760.72000000","0.03834000"],["78760.57000000","0.00014000"],["78760.56000000","0.20798000"],["78760.55000000","0.00204000"],["78760.00000000","0.00521000"],["78759.99000000","0.00007000"],["78759.76000000","0.00014000"],["78759.60000000","0.00007000"],["78759.47000000","0.00014000"],["78759.46000000","0.04599000"],["78759.30000000","0.00007000"],["78759.29000000","0.05171000"],["78759.20000000","0.00007000"],["78758.37000000","0.00007000"]],"asks":[["78762.00000000","2.43830000"],["78762.01000000","0.00083000"],["78762.02000000","0.00013000"],["78762.03000000","0.00014000"],["78762.04000000","0.06352000"],["78762.20000000","0.00007000"],["78762.24000000","0.00014000"],["78762.87000000","0.00126000"],["78762.94000000","0.00076000"],["78763.00000000","0.00381000"],["78763.12000000","0.00007000"],["78763.41000000","0.00007000"],["78763.56000000","0.00014000"],["78763.57000000","0.31758000"],["78763.58000000","0.00014000"],["78763.59000000","0.25409000"],["78763.86000000","0.00400000"],["78763.91000000","0.00007000"],["78764.00000000","0.02414000"],["78765.08000000","0.01519000"]]}}}
{"rx_ns": 8957063700, "frame": {"stream":"btcusdt@depth","data":{"e":"depthUpdate","E":1787602876014,"s":"BTCUSDT","U":99076494424,"u":99076494600,"b":[["78761.99000000","1.86372000"],["78759.29000000","0.05171000"],["78759.15000000","0.00000000"],["78759.10000000","0.00000000"],["78759.05000000","0.00000000"],["78759.00000000","0.00000000"],["78753.87000000","0.00000000"],["78752.77000000","0.00000000"],["78752.71000000","0.00254000"],["78738.32000000","0.00007000"],["78738.07000000","0.00000000"],["78736.99000000","0.54511000"],["78678.35000000","0.00000000"],["78368.18000000","0.00000000"],["77976.33000000","0.00000000"],["77586.45000000","0.00000000"],["77200.79000000","0.00010000"],["77198.52000000","0.00000000"],["77046.38000000","0.00012000"],["76892.28000000","0.00013000"],["76812.53000000","0.00000000"],["76738.49000000","0.00015000"],["76585.01000000","0.00020000"],["76428.46000000","0.00000000"],["76046.32000000","0.00000000"],["75666.09000000","0.00000000"],["75287.76000000","0.00023000"],["74911.32000000","0.00000000"],["74536.76000000","0.00000000"],["74164.08000000","0.00000000"],["73793.26000000","0.00000000"],["73424.29000000","0.00000000"],["73057.17000000","0.00000000"],["70885.80000000","0.00441000"],["70885.00000000","0.00000000"],["63010.00000000","0.05451000"],["63009.60000000","0.00031000"],["63009.59000000","0.00015000"]],"a":[["78762.00000000","2.43830000"],["78763.59000000","0.25409000"],["78766.63000000","0.00007000"],["78766.64000000","0.12705000"],["78767.87000000","0.31747000"],["78767.99000000","0.00000000"],["78768.45000000","0.00254000"],["78768.85000000","0.00000000"],["78769.62000000","0.00000000"],["78769.80000000","0.02161000"],["78785.58000000","0.00007000"],["78808.55000000","0.00000000"],["78848.09000000","0.93647000"],["78855.92000000","0.00000000"],["79155.81000000","0.00000000"],["79551.59000000","0.00000000"],["79949.35000000","0.00000000"],["80349.10000000","0.00000000"],["80516.00000000","0.10589000"],["80750.84000000","0.00000000"],["81154.60000000","0.00000000"],["81560.37000000","0.00000000"],["81968.17000000","0.00000000"],["82378.01000000","0.00000000"],["82789.90000000","0.00000000"],["83203.85000000","0.00000000"],["83619.87000000","0.00000000"],["84037.97000000","0.00000000"],["84458.16000000","0.00000000"],["84880.45000000","0.00000000"]]}}}
{"rx_ns": 9960475900, "frame": {"stream":"btcusdt@depth20","data":{"lastUpdateId":99076494847,"bids":[["78761.99000000","2.08366000"],["78761.98000000","0.00069000"],["78761.97000000","0.00013000"],["78761.04000000","0.00014000"],["78761.03000000","0.01220000"],["78760.73000000","0.00014000"],["78760.72000000","0.03834000"],["78760.57000000","0.00014000"],["78760.56000000","0.20798000"],["78760.55000000","0.00204000"],["78760.00000000","0.00521000"],["78759.99000000","0.00007000"],["78759.76000000","0.00014000"],["78759.60000000","0.00007000"],["78759.47000000","0.00014000"],["78759.46000000","0.04599000"],["78759.30000000","0.00007000"],["78759.29000000","0.05171000"],["78759.20000000","0.00007000"],["78758.37000000","0.00007000"]],"asks":[["78762.00000000","1.96727000"],["78762.01000000","0.00083000"],["78762.02000000","0.00013000"],["78762.03000000","0.00014000"],["78762.04000000","0.06352000"],["78762.20000000","0.00007000"],["78762.24000000","0.00014000"],["78762.87000000","0.00126000"],["78762.94000000","0.00076000"],["78763.00000000","0.00381000"],["78763.12000000","0.00007000"],["78763.41000000","0.00007000"],["78763.56000000","0.00014000"],["78763.57000000","0.31758000"],["78763.58000000","0.00014000"],["78763.59000000","0.25409000"],["78763.86000000","0.00400000"],["78763.91000000","0.00007000"],["78764.00000000","0.02414000"],["78765.08000000","0.01519000"]]}}}
{"rx_ns": 9960558400, "frame": {"stream":"btcusdt@depth","data":{"e":"depthUpdate","E":1787602877014,"s":"BTCUSDT","U":99076494601,"u":99076494847,"b":[["78761.99000000","2.08366000"],["78759.29000000","0.05171000"],["78759.05000000","0.00000000"],["78759.00000000","0.00000000"],["78758.20000000","0.04600000"],["78754.26000000","0.00254000"],["78752.71000000","0.00000000"],["78751.36000000","0.00000000"],["78738.32000000","0.00007000"],["78738.07000000","0.52285000"],["78736.99000000","0.00000000"],["78727.47000000","0.63518000"],["78681.53000000","0.00000000"],["78678.35000000","0.00000000"],["78654.97000000","2.77023000"],["78652.36000000","0.00000000"],["78548.84000000","0.01989000"],["78543.50000000","0.00000000"],["78368.18000000","0.00000000"],["77976.33000000","0.00000000"],["77586.45000000","0.00000000"],["77198.52000000","0.00000000"],["76812.53000000","0.00000000"],["76428.46000000","0.00000000"],["76046.32000000","0.00000000"],["75666.09000000","0.00000000"],["75287.76000000","0.00023000"],["74911.32000000","0.00000000"],["74536.76000000","0.00000000"],["74164.08000000","0.00000000"],["73793.26000000","0.00000000"],["73424.29000000","0.00000000"],["73057.17000000","0.00000000"],["72460.16000000","0.00000000"],["70885.80000000","0.00441000"],["70885.79000000","0.00009000"],["70885.00000000","0.00000000"],["63010.00000000","0.05451000"],["63009.60000000","0.00031000"],["63009.59000000","0.00015000"]],"a":[["78762.00000000","1.96727000"],["78763.59000000","0.25409000"],["78765.08000000","0.01519000"],["78765.86000000","0.00000000"],["78766.00000000","0.02407000"],["78766.20000000","0.00000000"],["78766.21000000","0.00000000"],["78766.22000000","0.00513000"],["78766.23000000","0.00022000"],["78766.26000000","0.00000000"],["78766.34000000","0.02527000"],["78766.42000000","0.00000000"],["78766.43000000","0.00000000"],["78766.63000000","0.00000000"],["78766.64000000","0.00000000"],["78766.67000000","0.00000000"],["78766.68000000","0.00000000"],["78767.86000000","0.00000000"],["78767.87000000","0.00000000"],["78768.45000000","0.00000000"],["78768.84000000","0.00007000"],["78768.85000000","0.31747000"],["78770.00000000","0.02654000"],["78785.58000000","0.00007000"],["78823.99000000","0.00190000"],["78903.51000000","0.00076000"],["79155.81000000","0.00000000"],["79551.59000000","0.00000000"],["79949.35000000","0.00000000"],["80349.10000000","0.00000000"],["80750.84000000","0.00000000"],["81154.60000000","0.00000000"],["81560.37000000","0.00000000"],["81968.17000000","0.00000000"],["82378.01000000","0.00000000"],["82789.90000000","0.00000000"],["83203.85000000","0.00000000"],["83619.87000000","0.00000000"],["84037.97000000","0.00000000"],["84458.16000000","0.00000000"],["84880.45000000","0.00000000"]]}}}
{"rx_ns": 10980481600, "frame": {"stream":"btcusdt@depth20","data":{"lastUpdateId":99076495070,"bids":[["78761.99000000","1.86361000"],["78761.98000000","0.00076000"],["78761.97000000","0.00013000"],["78761.04000000","0.00014000"],["78761.03000000","0.01220000"],["78760.73000000","0.00014000"],["78760.72000000","0.03834000"],["78760.57000000","0.00014000"],["78760.56000000","0.20798000"],["78760.55000000","0.00204000"],["78760.13000000","0.00330000"],["78760.00000000","0.00521000"],["78759.99000000","0.00007000"],["78759.76000000","0.00014000"],["78759.60000000","0.00007000"],["78759.47000000","0.00014000"],["78759.46000000","0.04599000"],["78759.30000000","0.00007000"],["78759.29000000","0.05178000"],["78759.20000000","0.00007000"]],"asks":[["78762.00000000","2.01148000"],["78762.01000000","0.00076000"],["78762.02000000","0.00013000"],["78762.03000000","0.00014000"],["78762.04000000","0.06352000"],["78762.20000000","0.00007000"],["78762.24000000","0.00014000"],["78762.87000000","0.00126000"],["78762.94000000","0.00076000"],["78763.00000000","0.00381000"],["78763.12000000","0.00007000"],["78763.41000000","0.00007000"],["78763.56000000","0.00014000"],["78763.57000000","0.31758000"],["78763.58000000","0.00014000"],["78763.59000000","0.25416000"],["78763.86000000","0.00400000"],["78763.91000000","0.00007000"],["78764.00000000","0.02414000"],["78765.07000000","0.00007000"]]}}}
{"rx_ns": 10980636500, "frame": {"stream":"btcusdt@depth","data":{"e":"depthUpdate","E":1787602878014,"s":"BTCUSDT","U":99076494848,"u":99076495070,"b":[["78761.99000000","1.86361000"],["78761.98000000","0.00076000"],["78760.13000000","0.00330000"],["78759.29000000","0.05178000"],["78759.10000000","0.00000000"],["78759.05000000","0.00000000"],["78758.57000000","0.00328000"],["78754.77000000","0.36224000"],["78754.76000000","1.90515000"],["78754.26000000","0.00000000"],["78753.20000000","0.00000000"],["78752.95000000","0.00254000"],["78752.81000000","0.00000000"],["78752.71000000","0.00048000"],["78752.55000000","0.00000000"],["78752.32000000","0.00047000"],["78752.09000000","0.00000000"],["78751.81000000","0.00164000"],["78751.80000000","0.00400000"],["78751.65000000","0.00000000"],["78751.50000000","0.00000000"],["78751.29000000","0.00000000"],["78751.22000000","0.00634000"],["78750.09000000","0.02000000"],["78748.26000000","0.00800000"],["78745.77000000","0.00000000"],["78738.32000000","0.00007000"],["78736.91000000","0.00000000"],["78724.17000000","0.00000000"],["78720.59000000","0.00000000"],["78720.18000000","0.02465000"],["78678.35000000","0.00000000"],["78654.97000000","0.00000000"],["78652.36000000","2.77023000"],["78368.18000000","0.00000000"],["77976.33000000","0.00000000"],["77586.45000000","0.00000000"],["77198.52000000","0.00000000"],["76812.53000000","0.00000000"],["76428.46000000","0.00000000"],["76046.32000000","0.00000000"],["75666.09000000","0.00000000"],["75287.76000000","0.00023000"],["74911.32000000","0.00000000"],["74536.76000000","0.00000000"],["74164.08000000","0.00000000"],["73793.26000000","0.00000000"],["73424.29000000","0.00000000"],["73057.17000000","0.00000000"],["70885.80000000","0.00473000"],["70885.00000000","0.00000000"],["63010.00000000","0.05451000"],["63009.60000000","0.00031000"],["63009.59000000","0.00015000"]],"a":[["78762.00000000","2.01148000"],["78762.01000000","0.00076000"],["78763.59000000","0.25416000"],["78764.00000000","0.02414000"],["78765.07000000","0.00007000"],["78765.08000000","0.01519000"],["78765.74000000","0.00506000"],["78765.92000000","0.00007000"],["78765.93000000","0.12712000"],["78766.00000000","0.02407000"],["78766.22000000","0.00000000"],["78766.34000000","0.02520000"],["78768.69000000","0.00254000"],["78768.84000000","0.00000000"],["78770.00000000","0.02400000"],["78785.58000000","0.00007000"],["78856.19000000","0.00529000"],["78858.74000000","0.00000000"],["78878.26000000","0.00000000"],["78891.80000000","0.00400000"],["79155.81000000","0.00000000"],["79551.59000000","0.00000000"],["79949.35000000","0.00000000"],["80349.10000000","0.00000000"],["80750.84000000","0.00000000"],["81154.60000000","0.00000000"],["81560.37000000","0.00000000"],["81968.17000000","0.00000000"],["82378.01000000","0.00000000"],["82789.90000000","0.00000000"],["83203.85000000","0.00000000"],["83619.87000000","0.00000000"],["84037.97000000","0.00000000"],["84458.16000000","0.00000000"],["84880.45000000","0.00000000"]]}}}
{"rx_ns": 11960669600, "frame": {"stream":"btcusdt@depth20","data":{"lastUpdateId":99076495217,"bids":[["78761.99000000","1.83533000"],["78761.98000000","0.00076000"],["78761.97000000","0.00013000"],["78761.04000000","0.00014000"],["78761.03000000","0.01220000"],["78760.73000000","0.00014000"],["78760.72000000","0.03834000"],["78760.57000000","0.00014000"],["78760.56000000","0.20798000"],["78760.55000000","0.00204000"],["78760.13000000","0.00330000"],["78760.00000000","0.00521000"],["78759.99000000","0.00007000"],["78759.76000000","0.00014000"],["78759.60000000","0.00007000"],["78759.47000000","0.00014000"],["78759.46000000","0.04599000"],["78759.30000000","0.00007000"],["78759.29000000","0.05178000"],["78759.20000000","0.00007000"]],"asks":[["78762.00000000","2.55720000"],["78762.01000000","0.00069000"],["78762.02000000","0.00013000"],["78762.03000000","0.00014000"],["78762.04000000","0.06352000"],["78762.20000000","0.00007000"],["78762.24000000","0.00014000"],["78762.87000000","0.00126000"],["78762.94000000","0.00076000"],["78763.00000000","0.00381000"],["78763.12000000","0.00007000"],["78763.41000000","0.00007000"],["78763.56000000","0.00014000"],["78763.57000000","0.31758000"],["78763.58000000","0.00014000"],["78763.59000000","0.25416000"],["78763.86000000","0.00400000"],["78763.91000000","0.00007000"],["78764.00000000","0.02414000"],["78765.08000000","0.01519000"]]}}}
{"rx_ns": 11961229700, "frame": {"stream":"btcusdt@depth","data":{"e":"depthUpdate","E":1787602879014,"s":"BTCUSDT","U":99076495071,"u":99076495217,"b":[["78761.99000000","1.83533000"],["78753.76000000","0.00254000"],["78752.95000000","0.00000000"],["78745.48000000","0.12699000"],["78738.32000000","0.00007000"],["78738.07000000","0.00000000"],["78736.99000000","0.48107000"],["78678.35000000","0.02115000"],["78368.18000000","0.00000000"],["77976.33000000","0.00000000"],["77586.45000000","0.00000000"],["77198.52000000","0.00000000"],["76812.53000000","0.00000000"],["76428.46000000","0.00000000"],["76046.32000000","0.00000000"],["75666.09000000","0.00000000"],["75287.76000000","0.00023000"],["74911.32000000","0.00000000"],["74536.76000000","0.00000000"],["74164.08000000","0.00000000"],["73793.26000000","0.00000000"],["73424.29000000","0.00000000"],["73057.17000000","0.00000000"],["70885.80000000","0.00457000"],["70885.79000000","0.00000000"],["70885.78000000","0.00000000"],["70885.00000000","0.00000000"],["63010.00000000","0.05451000"],["63009.60000000","0.00031000"],["63009.59000000","0.00015000"]],"a":[["78762.00000000","2.55720000"],["78762.01000000","0.00069000"],["78764.00000000","0.02414000"],["78765.07000000","0.00000000"],["78765.08000000","0.01519000"],["78765.74000000","0.00513000"],["78767.50000000","0.31747000"],["78768.69000000","0.00000000"],["78768.85000000","0.00000000"],["78769.50000000","0.00254000"],["78774.49000000","0.34279000"],["78785.58000000","0.00007000"],["78789.49000000","0.00000000"],["78845.48000000","0.93647000"],["78848.09000000","0.00000000"],["79155.81000000","0.00000000"],["79551.59000000","0.00000000"],["79949.35000000","0.00000000"],["80349.10000000","0.00000000"],["80750.84000000","0.00000000"],["81154.60000000","0.00000000"],["81560.37000000","0.00000000"],["81968.17000000","0.00000000"],["82378.01000000","0.00000000"],["82789.90000000","0.00000000"],["83203.85000000","0.00000000"],["83619.87000000","0.00000000"],["84037.97000000","0.00000000"],["84458.16000000","0.00000000"],["84880.45000000","0.00000000"]]}}}
{"rx_ns": 12963025500, "frame": {"stream":"btcusdt@depth20","data":{"lastUpdateId":99076495351,"bids":[["78761.99000000","1.78816000"],["78761.98000000","0.00076000"],["78761.97000000","0.00013000"],["78761.04000000","0.00014000"],["78761.03000000","0.01220000"],["78760.73000000","0.00014000"],["78760.72000000","0.03834000"],["78760.57000000","0.00014000"],["78760.56000000","0.20798000"],["78760.55000000","0.00204000"],["78760.13000000","0.00330000"],["78760.00000000","0.00521000"],["78759.99000000","0.00007000"],["78759.76000000","0.00014000"],["78759.60000000","0.00007000"],["78759.47000000","0.00014000"],["78759.46000000","0.04599000"],["78759.30000000","0.00007000"],["78759.29000000","0.05178000"],["78759.20000000","0.00007000"]],"asks":[["78762.00000000","2.49126000"],["78762.01000000","0.00069000"],["78762.02000000","0.00013000"],["78762.03000000","0.00014000"],["78762.04000000","0.06352000"],["78762.20000000","0.00007000"],["78762.24000000","0.00014000"],["78762.87000000","0.00126000"],["78762.94000000","0.00076000"],["78763.00000000","0.00381000"],["78763.12000000","0.00007000"],["78763.41000000","0.00007000"],["78763.56000000","0.00014000"],["78763.57000000","0.31758000"],["78763.58000000","0.00014000"],["78763.59000000","0.25416000"],["78763.86000000","0.00400000"],["78763.91000000","0.00007000"],["78764.00000000","0.02414000"],["78765.08000000","0.01519000"]]}}}
{"rx_ns": 12963110300, "frame": {"stream":"btcusdt@depth","data":{"e":"depthUpdate","E":1787602880015,"s":"BTCUSDT","U":99076495218,"u":99076495351,"b":[["78761.99000000","1.78816000"],["78748.26000000","0.01200000"],["78738.32000000","0.00007000"],["78678.35000000","0.02115000"],["78654.97000000","2.77023000"],["78652.36000000","0.00000000"],["78647.54000000","0.00319000"],["78368.18000000","0.00000000"],["77976.33000000","0.00000000"],["77586.45000000","0.00000000"],["77198.52000000","0.00000000"],["76812.53000000","0.00000000"],["76428.46000000","0.00000000"],["76046.32000000","0.00000000"],["75666.09000000","0.00000000"],["75287.76000000","0.00023000"],["74911.32000000","0.00000000"],["74536.76000000","0.00000000"],["74164.08000000","0.00000000"],["73793.26000000","0.00000000"],["73424.29000000","0.00000000"],["73057.17000000","0.00000000"],["70885.80000000","0.00457000"],["70885.79000000","0.00000000"],["70885.78000000","0.00009000"],["70885.00000000","0.00000000"],["63010.00000000","0.05451000"],["63009.60000000","0.00031000"],["63009.59000000","0.00015000"]],"a":[["78762.00000000","2.49126000"],["78765.92000000","0.00014000"],["78765.93000000","0.12719000"],["78767.49000000","0.00000000"],["78767.50000000","0.00000000"],["78767.63000000","0.00007000"],["78767.87000000","0.31747000"],["78770.73000000","0.00400000"],["78772.22000000","0.00321000"],["78785.58000000","0.00007000"],["79155.81000000","0.00000000"],["79551.59000000","0.00000000"],["79949.35000000","0.00000000"],["80349.10000000","0.00000000"],["80750.84000000","0.00000000"],["81154.60000000","0.00000000"],["81560.37000000","0.00000000"],["81968.17000000","0.00000000"],["82378.01000000","0.00000000"],["82789.90000000","0.00000000"],["83203.85000000","0.00000000"],["83619.87000000","0.00000000"],["84037.97000000","0.00000000"],["84458.16000000","0.00000000"],["84880.45000000","0.00000000"]]}}}
{"rx_ns": 13952995100, "kind": "rest", "req": {"method": "GET", "url": "https://data-api.binance.vision/api/v3/depth?symbol=BTCUSDT&limit=100", "limit": 100, "weight": 5, "sent_ns": 11961047200, "status": 200, "used_weight_1m": "15", "recv_ns": 13000566200}, "frame": {"lastUpdateId":99076495351,"bids":[["78761.99000000","1.78816000"],["78761.98000000","0.00076000"],["78761.97000000","0.00013000"],["78761.04000000","0.00014000"],["78761.03000000","0.01220000"],["78760.73000000","0.00014000"],["78760.72000000","0.03834000"],["78760.57000000","0.00014000"],["78760.56000000","0.20798000"],["78760.55000000","0.00204000"],["78760.13000000","0.00330000"],["78760.00000000","0.00521000"],["78759.99000000","0.00007000"],["78759.76000000","0.00014000"],["78759.60000000","0.00007000"],["78759.47000000","0.00014000"],["78759.46000000","0.04599000"],["78759.30000000","0.00007000"],["78759.29000000","0.05178000"],["78759.20000000","0.00007000"],["78758.57000000","0.00328000"],["78758.37000000","0.00007000"],["78758.20000000","0.04600000"],["78758.05000000","0.00534000"],["78758.00000000","0.02407000"],["78757.99000000","0.00027000"],["78757.69000000","0.00007000"],["78757.34000000","0.00007000"],["78757.32000000","0.00007000"],["78757.00000000","0.00007000"],["78756.98000000","0.00007000"],["78756.00000000","0.02400000"],["78755.99000000","0.00007000"],["78755.93000000","0.01246000"],["78755.60000000","0.00008000"],["78755.58000000","0.00330000"],["78755.52000000","0.02400000"],["78755.29000000","0.00007000"],["78754.77000000","0.36224000"],["78754.76000000","1.90515000"],["78754.74000000","0.02600000"],["78754.73000000","0.02600000"],["78754.69000000","0.00400000"],["78754.59000000","0.01000000"],["78754.50000000","0.00014000"],["78754.11000000","0.22197000"],["78754.00000000","0.02400000"],["78753.99000000","0.03948000"],["78753.76000000","0.00254000"],["78753.41000000","0.02998000"],["78753.24000000","0.00007000"],["78753.22000000","0.02000000"],["78753.19000000","0.02000000"],["78752.72000000","0.00400000"],["78752.71000000","0.00048000"],["78752.39000000","1.21952000"],["78752.38000000","0.00007000"],["78752.37000000","0.00328000"],["78752.36000000","0.00007000"],["78752.32000000","0.00047000"],["78752.14000000","0.01072000"],["78752.01000000","0.00634000"],["78752.00000000","0.02400000"],["78751.97000000","0.08576000"],["78751.81000000","0.00164000"],["78751.80000000","0.00400000"],["78751.64000000","0.00027000"],["78751.22000000","0.00634000"],["78751.21000000","0.00007000"],["78751.19000000","0.00007000"],["78750.75000000","0.00400000"],["78750.63000000","0.00014000"],["78750.55000000","0.00191000"],["78750.22000000","0.12698000"],["78750.09000000","0.02000000"],["78750.07000000","0.02200000"],["78750.05000000","0.02000000"],["78750.03000000","0.00400000"],["78750.00000000","0.03049000"],["78749.99000000","0.00206000"],["78749.89000000","0.00326000"],["78749.73000000","0.02200000"],["78749.65000000","0.00007000"],["78749.60000000","0.02000000"],["78749.51000000","0.02000000"],["78749.27000000","0.02000000"],["78749.23000000","0.00007000"],["78749.16000000","0.02000000"],["78749.15000000","0.00007000"],["78748.78000000","0.00400000"],["78748.48000000","0.00007000"],["78748.26000000","0.01200000"],["78748.25000000","1.90515000"],["78748.17000000","0.00007000"],["78748.00000000","0.02400000"],["78747.90000000","1.21960000"],["78747.67000000","1.21916000"],["78747.11000000","0.00400000"],["78747.10000000","0.00007000"],["78746.81000000","0.00400000"]],"asks":[["78762.00000000","2.49126000"],["78762.01000000","0.00069000"],["78762.02000000","0.00013000"],["78762.03000000","0.00014000"],["78762.04000000","0.06352000"],["78762.20000000","0.00007000"],["78762.24000000","0.00014000"],["78762.87000000","0.00126000"],["78762.94000000","0.00076000"],["78763.00000000","0.00381000"],["78763.12000000","0.00007000"],["78763.41000000","0.00007000"],["78763.56000000","0.00014000"],["78763.57000000","0.31758000"],["78763.58000000","0.00014000"],["78763.59000000","0.25416000"],["78763.86000000","0.00400000"],["78763.91000000","0.00007000"],["78764.00000000","0.02414000"],["78765.08000000","0.01519000"],["78765.52000000","0.00007000"],["78765.74000000","0.00513000"],["78765.75000000","0.00007000"],["78765.87000000","0.00400000"],["78765.92000000","0.00014000"],["78765.93000000","0.12719000"],["78766.00000000","0.02407000"],["78766.11000000","0.00014000"],["78766.23000000","0.00022000"],["78766.34000000","0.02520000"],["78766.58000000","0.00014000"],["78766.62000000","0.02161000"],["78767.12000000","0.02000000"],["78767.51000000","0.00634000"],["78767.52000000","0.00007000"],["78767.57000000","0.00007000"],["78767.60000000","0.03024000"],["78767.63000000","0.00007000"],["78767.64000000","0.04041000"],["78767.83000000","0.00007000"],["78767.87000000","0.31747000"],["78767.88000000","0.00407000"],["78768.00000000","0.02400000"],["78768.66000000","0.00027000"],["78768.86000000","0.03024000"],["78769.07000000","0.00007000"],["78769.50000000","0.00254000"],["78769.60000000","0.00634000"],["78769.61000000","0.00007000"],["78769.80000000","0.02161000"],["78769.81000000","0.12695000"],["78769.83000000","0.00007000"],["78769.88000000","0.21930000"],["78769.89000000","0.00400000"],["78769.98000000","0.00014000"],["78770.00000000","0.02400000"],["78770.73000000","0.00400000"],["78770.74000000","0.38093000"],["78770.88000000","0.00381000"],["78771.00000000","0.00007000"],["78771.66000000","0.00007000"],["78771.76000000","0.00007000"],["78771.83000000","0.00007000"],["78771.90000000","0.00400000"],["78771.93000000","0.00007000"],["78772.00000000","0.02400000"],["78772.21000000","0.00634000"],["78772.22000000","0.00321000"],["78772.79000000","0.03000000"],["78772.82000000","0.00400000"],["78772.88000000","0.00324000"],["78773.40000000","0.00400000"],["78773.69000000","0.04000000"],["78773.71000000","0.00007000"],["78773.85000000","0.00014000"],["78773.88000000","0.02161000"],["78773.89000000","0.08000000"],["78774.00000000","0.02400000"],["78774.01000000","0.00007000"],["78774.12000000","0.00007000"],["78774.19000000","0.00010000"],["78774.45000000","0.00332000"],["78774.49000000","0.34279000"],["78775.37000000","0.00007000"],["78775.64000000","0.00007000"],["78775.76000000","0.00007000"],["78775.84000000","0.00007000"],["78775.91000000","0.38087000"],["78776.00000000","0.02400000"],["78776.36000000","0.00400000"],["78776.38000000","0.00152000"],["78776.40000000","0.02284000"],["78776.60000000","0.00027000"],["78776.67000000","0.00253000"],["78776.88000000","0.00326000"],["78777.04000000","1.21952000"],["78777.05000000","0.12694000"],["78777.07000000","0.01200000"],["78777.17000000","0.02161000"],["78777.19000000","1.90515000"]]}}
{"rx_ns": 13952995100, "frame": {"stream":"btcusdt@depth20","data":{"lastUpdateId":99076495948,"bids":[["78761.99000000","0.09104000"],["78761.98000000","0.00062000"],["78761.97000000","0.00013000"],["78761.03000000","0.00014000"],["78760.73000000","0.00014000"],["78760.72000000","0.03834000"],["78760.00000000","0.00521000"],["78759.99000000","0.00007000"],["78759.77000000","0.00014000"],["78759.76000000","0.02535000"],["78759.60000000","0.00007000"],["78759.47000000","0.00014000"],["78759.46000000","0.04599000"],["78759.30000000","0.00014000"],["78759.29000000","0.05178000"],["78759.20000000","0.00007000"],["78758.37000000","0.00007000"],["78758.21000000","0.00007000"],["78758.20000000","0.04600000"],["78758.05000000","0.00541000"]],"asks":[["78762.00000000","2.03013000"],["78762.01000000","0.00020000"],["78762.02000000","0.00013000"],["78762.03000000","0.00014000"],["78762.04000000","0.06366000"],["78762.20000000","0.00007000"],["78762.24000000","0.00014000"],["78762.54000000","0.00014000"],["78762.55000000","0.02175000"],["78762.56000000","0.31755000"],["78762.57000000","0.00400000"],["78762.78000000","0.00014000"],["78762.79000000","0.38103000"],["78762.87000000","0.00126000"],["78762.94000000","0.00076000"],["78763.00000000","0.00381000"],["78763.12000000","0.00007000"],["78763.41000000","0.00007000"],["78763.56000000","0.00014000"],["78763.57000000","0.31758000"]]}}}
{"rx_ns": 13953167300, "frame": {"stream":"btcusdt@depth","data":{"e":"depthUpdate","E":1787602881014,"s":"BTCUSDT","U":99076495352,"u":99076495948,"b":[["78761.99000000","0.09104000"],["78761.98000000","0.00062000"],["78761.04000000","0.00000000"],["78761.03000000","0.00014000"],["78760.72000000","0.03834000"],["78760.57000000","0.00000000"],["78760.56000000","0.00000000"],["78760.55000000","0.00000000"],["78760.13000000","0.00000000"],["78760.00000000","0.00521000"],["78759.77000000","0.00014000"],["78759.76000000","0.02535000"],["78759.30000000","0.00014000"],["78759.29000000","0.05178000"],["78758.88000000","0.00000000"],["78758.87000000","0.00000000"],["78758.57000000","0.00000000"],["78758.21000000","0.00007000"],["78758.05000000","0.00541000"],["78758.00000000","0.02414000"],["78757.55000000","0.04224000"],["78755.93000000","0.00042000"],["78755.58000000","0.00000000"],["78755.57000000","0.00000000"],["78755.52000000","0.00000000"],["78754.77000000","0.00000000"],["78754.76000000","0.00000000"],["78754.74000000","0.00000000"],["78754.73000000","0.00000000"],["78754.69000000","0.00000000"],["78754.59000000","0.00000000"],["78754.50000000","0.00007000"],["78754.11000000","0.22204000"],["78753.99000000","0.03613000"],["78753.76000000","0.00000000"],["78753.41000000","0.00710000"],["78753.19000000","0.38224000"],["78752.88000000","0.00000000"],["78752.38000000","0.00076000"],["78752.37000000","0.00000000"],["78752.34000000","0.00048000"],["78752.14000000","0.00000000"],["78752.01000000","0.00000000"],["78751.97000000","0.00000000"],["78751.80000000","0.00000000"],["78751.43000000","0.00000000"],["78751.41000000","0.00000000"],["78751.40000000","0.00000000"],["78751.39000000","0.00000000"],["78751.22000000","0.00000000"],["78750.75000000","0.00400000"],["78750.65000000","0.08576000"],["78750.60000000","0.00000000"],["78750.40000000","0.00000000"],["78750.39000000","0.00000000"],["78750.29000000","0.00000000"],["78750.09000000","0.00000000"],["78750.08000000","0.00254000"],["78750.04000000","0.00000000"],["78750.01000000","0.00000000"],["78749.93000000","0.00000000"],["78749.80000000","0.00000000"],["78749.79000000","0.00000000"],["78749.77000000","0.00000000"],["78749.57000000","0.00000000"],["78749.55000000","0.00000000"],["78749.51000000","0.00000000"],["78749.31000000","0.00000000"],["78749.30000000","0.00000000"],["78749.29000000","0.00000000"],["78749.28000000","0.00000000"],["78748.49000000","0.00000000"],["78748.27000000","0.00000000"],["78748.26000000","0.00000000"],["78748.09000000","0.01000000"],["78747.32000000","0.00400000"],["78747.20000000","0.00634000"],["78747.19000000","0.02000000"],["78747.11000000","0.00000000"],["78747.05000000","0.00400000"],["78746.82000000","0.00634000"],["78745.77000000","0.02000000"],["78745.59000000","0.08000000"],["78745.48000000","0.00000000"],["78744.79000000","0.00000000"],["78743.92000000","0.00800000"],["78742.74000000","0.00000000"],["78738.32000000","0.00007000"],["78736.99000000","0.00000000"],["78736.98000000","0.00000000"],["78736.69000000","0.12700000"],["78736.01000000","0.00000000"],["78734.36000000","0.00000000"],["78733.03000000","0.13238000"],["78732.97000000","0.00000000"],["78732.22000000","0.35643000"],["78729.80000000","0.00013000"],["78729.64000000","0.00634000"],["78727.47000000","0.00000000"],["78727.16000000","0.02200000"],["78724.00000000","0.04600000"],["78723.43000000","0.00000000"],["78722.43000000","0.02000000"],["78722.37000000","0.02000000"],["78719.23000000","0.00400000"],["78715.80000000","0.00007000"],["78712.49000000","0.00000000"],["78712.28000000","0.00000000"],["78712.25000000","0.00000000"],["78710.49000000","0.00000000"],["78710.47000000","0.00000000"],["78710.24000000","0.00000000"],["78701.22000000","0.00000000"],["78698.29000000","0.00429000"],["78694.74000000","0.86748000"],["78689.91000000","1.25825000"],["78684.47000000","0.00000000"],["78681.31000000","0.00000000"],["78680.26000000","0.02400000"],["78679.73000000","0.00000000"],["78679.43000000","0.02600000"],["78679.36000000","0.02600000"],["78678.35000000","0.00000000"],["78674.95000000","0.00000000"],["78654.97000000","0.00000000"],["78647.54000000","0.00000000"],["78644.98000000","0.00000000"],["78642.42000000","0.00318000"],["78368.18000000","0.00000000"],["77976.33000000","0.00000000"],["77586.45000000","0.00000000"],["77198.52000000","0.00000000"],["76812.53000000","0.00000000"],["76428.46000000","0.00000000"],["76046.32000000","0.00000000"],["75666.09000000","0.00000000"],["75287.76000000","0.00023000"],["74911.32000000","0.00000000"],["74536.76000000","0.00000000"],["74164.08000000","0.00000000"],["73793.26000000","0.00000000"],["73424.29000000","0.00000000"],["73057.17000000","0.00000000"],["70885.80000000","0.00457000"],["63010.00000000","0.05451000"],["63009.60000000","0.00031000"],["63009.59000000","0.00015000"]],"a":[["78762.00000000","2.03013000"],["78762.01000000","0.00020000"],["78762.04000000","0.06366000"],["78762.54000000","0.00014000"],["78762.55000000","0.02175000"],["78762.56000000","0.31755000"],["78762.57000000","0.00400000"],["78762.78000000","0.00014000"],["78762.79000000","0.38103000"],["78762.86000000","0.00000000"],["78763.11000000","0.00000000"],["78763.55000000","0.00000000"],["78763.58000000","0.00000000"],["78763.59000000","0.25423000"],["78763.90000000","0.00000000"],["78763.99000000","0.00000000"],["78764.00000000","0.05414000"],["78765.06000000","0.00000000"],["78765.07000000","0.00000000"],["78765.08000000","0.01519000"],["78765.51000000","0.00000000"],["78765.74000000","0.00000000"],["78765.82000000","0.00254000"],["78765.92000000","0.00000000"],["78765.93000000","0.12705000"],["78766.00000000","0.02400000"],["78766.58000000","0.00007000"],["78766.96000000","0.00000000"],["78767.10000000","0.00000000"],["78767.11000000","0.00000000"],["78767.12000000","0.00000000"],["78767.35000000","0.00317000"],["78767.51000000","0.00000000"],["78767.63000000","0.00000000"],["78767.82000000","0.00634000"],["78767.87000000","0.00000000"],["78768.30000000","0.00324000"],["78768.37000000","0.00160000"],["78768.62000000","0.00000000"],["78769.50000000","0.00000000"],["78769.60000000","0.00000000"],["78769.66000000","0.00320000"],["78769.87000000","0.00332000"],["78770.00000000","0.09900000"],["78770.74000000","0.00000000"],["78771.00000000","0.00015000"],["78771.88000000","0.00331000"],["78772.21000000","0.00000000"],["78772.22000000","0.00007000"],["78772.79000000","0.00000000"],["78772.89000000","0.00455000"],["78772.90000000","0.02000000"],["78774.48000000","0.36224000"],["78775.40000000","0.34278000"],["78775.89000000","0.02000000"],["78776.06000000","0.02000000"],["78776.38000000","0.00000000"],["78776.68000000","0.03000000"],["78776.74000000","0.02000000"],["78776.82000000","0.04103000"],["78777.65000000","0.02000000"],["78777.69000000","0.02000000"],["78777.71000000","0.00000000"],["78778.15000000","0.00000000"],["78781.92000000","0.00000000"],["78783.11000000","0.00000000"],["78783.80000000","0.00000000"],["78784.76000000","0.00000000"],["78785.07000000","0.00000000"],["78785.33000000","0.00059000"],["78785.58000000","0.00007000"],["78786.63000000","0.00000000"],["78786.64000000","0.00000000"],["78786.72000000","0.00000000"],["78786.73000000","0.00000000"],["78792.12000000","0.00400000"],["78792.66000000","0.00000000"],["78794.01000000","0.00000000"],["78798.88000000","0.00000000"],["78808.48000000","0.00200000"],["78814.83000000","0.86616000"],["78820.67000000","0.00000000"],["78821.32000000","0.00000000"],["78837.42000000","0.00000000"],["79155.81000000","0.00000000"],["79551.59000000","0.00000000"],["79949.35000000","0.00000000"],["80349.10000000","0.00000000"],["80750.84000000","0.00000000"],["81154.60000000","0.00000000"],["81560.37000000","0.00000000"],["81968.17000000","0.00000000"],["82378.01000000","0.00000000"],["82789.90000000","0.00000000"],["83203.85000000","0.00000000"],["83619.87000000","0.00000000"],["84037.97000000","0.00000000"],["84458.16000000","0.00000000"],["84880.45000000","0.00000000"]]}}}
{"rx_ns": 14954388200, "frame": {"stream":"btcusdt@depth20","data":{"lastUpdateId":99076496203,"bids":[["78761.99000000","0.08733000"],["78761.98000000","0.00076000"],["78761.97000000","0.00013000"],["78761.56000000","0.00007000"],["78761.03000000","0.00014000"],["78760.97000000","0.00007000"],["78760.96000000","0.02514000"],["78760.78000000","0.00007000"],["78760.73000000","0.00014000"],["78760.72000000","0.03834000"],["78760.00000000","0.00521000"],["78759.99000000","0.00007000"],["78759.76000000","0.00014000"],["78759.60000000","0.00007000"],["78759.47000000","0.00014000"],["78759.46000000","0.04599000"],["78759.30000000","0.00014000"],["78759.29000000","0.05178000"],["78759.20000000","0.00007000"],["78758.37000000","0.00007000"]],"asks":[["78762.00000000","2.34759000"],["78762.01000000","0.00020000"],["78762.02000000","0.00013000"],["78762.03000000","0.00014000"],["78762.04000000","0.06359000"],["78762.20000000","0.00007000"],["78762.24000000","0.00014000"],["78762.54000000","0.00014000"],["78762.55000000","0.02168000"],["78762.57000000","0.00400000"],["78762.78000000","0.00014000"],["78762.79000000","0.38103000"],["78762.87000000","0.00126000"],["78762.94000000","0.00076000"],["78763.00000000","0.00381000"],["78763.12000000","0.00007000"],["78763.41000000","0.00007000"],["78763.56000000","0.00014000"],["78763.57000000","0.31758000"],["78763.58000000","0.00007000"]]}}}
{"rx_ns": 14954502700, "frame": {"stream":"btcusdt@depth","data":{"e":"depthUpdate","E":1787602882014,"s":"BTCUSDT","U":99076495949,"u":99076496203,"b":[["78761.99000000","0.08733000"],["78761.98000000","0.00076000"],["78761.56000000","0.00007000"],["78761.22000000","0.00000000"],["78761.21000000","0.00000000"],["78760.97000000","0.00007000"],["78760.96000000","0.02514000"],["78760.78000000","0.00007000"],["78760.00000000","0.00521000"],["78759.77000000","0.00000000"],["78759.76000000","0.00014000"],["78758.21000000","0.00014000"],["78758.01000000","0.00000000"],["78758.00000000","0.02414000"],["78757.55000000","0.00000000"],["78754.11000000","0.22204000"],["78753.20000000","1.90515000"],["78748.79000000","0.00000000"],["78748.26000000","0.00000000"],["78748.09000000","0.00000000"],["78747.73000000","0.00000000"],["78747.71000000","0.00000000"],["78747.69000000","0.00000000"],["78747.68000000","0.00000000"],["78747.32000000","0.00000000"],["78747.29000000","0.01000000"],["78747.05000000","0.00000000"],["78746.94000000","0.00000000"],["78746.78000000","0.00000000"],["78746.76000000","0.00014000"],["78743.92000000","0.00400000"],["78738.32000000","0.00007000"],["78737.54000000","0.00286000"],["78732.22000000","0.00000000"],["78731.33000000","0.36737000"],["78730.01000000","0.00000000"],["78722.80000000","0.00000000"],["78710.18000000","0.00000000"],["78673.99000000","0.00000000"],["78673.35000000","0.00000000"],["78652.36000000","2.77023000"],["78632.78000000","0.00000000"],["78625.21000000","0.04090000"],["78573.49000000","0.00000000"],["78568.76000000","0.00778000"],["78368.18000000","0.00000000"],["77976.33000000","0.00000000"],["77586.45000000","0.00000000"],["77198.52000000","0.00000000"],["76812.53000000","0.00000000"],["76428.46000000","0.00000000"],["76046.32000000","0.00000000"],["75666.09000000","0.00000000"],["75287.76000000","0.00023000"],["74911.32000000","0.00000000"],["74536.76000000","0.00000000"],["74164.08000000","0.00000000"],["73793.26000000","0.00000000"],["73424.29000000","0.00000000"],["73057.17000000","0.00000000"],["72460.16000000","0.00014000"],["71807.21000000","0.00000000"],["70885.80000000","0.00441000"],["70885.78000000","0.00000000"],["70885.00000000","0.00000000"],["63010.00000000","0.05451000"],["63009.60000000","0.00031000"],["63009.59000000","0.00015000"]],"a":[["78762.00000000","2.34759000"],["78762.02000000","0.00013000"],["78762.03000000","0.00014000"],["78762.04000000","0.06359000"],["78762.55000000","0.02168000"],["78762.56000000","0.00000000"],["78763.58000000","0.00007000"],["78765.93000000","0.12712000"],["78775.40000000","0.36878000"],["78782.89000000","0.02514000"],["78783.10000000","0.00012000"],["78783.34000000","0.00000000"],["78785.30000000","0.00190000"],["78785.58000000","0.00007000"],["78796.30000000","0.00000000"],["78796.72000000","0.00000000"],["78798.50000000","0.00000000"],["78820.66000000","0.02000000"],["78823.15000000","0.00023000"],["78832.04000000","0.04762000"],["78837.42000000","0.03000000"],["78853.64000000","0.00529000"],["78856.19000000","0.00000000"],["78861.45000000","0.02789000"],["78869.04000000","0.00000000"],["78973.24000000","0.01989000"],["78982.27000000","0.00000000"],["79155.81000000","0.00000000"],["79551.59000000","0.00000000"],["79949.35000000","0.00000000"],["80349.10000000","0.00000000"],["80750.84000000","0.00000000"],["81154.60000000","0.00000000"],["81560.37000000","0.00000000"],["81800.00000000","6.68172000"],["81968.17000000","0.00000000"],["82378.01000000","0.00000000"],["82789.90000000","0.00000000"],["83203.85000000","0.00000000"],["83619.87000000","0.00000000"],["84037.97000000","0.00000000"],["84458.16000000","0.00000000"],["84880.45000000","0.00000000"]]}}}
{"rx_ns": 15957913100, "frame": {"stream":"btcusdt@depth20","data":{"lastUpdateId":99076497256,"bids":[["78759.46000000","0.04280000"],["78759.45000000","0.00070000"],["78759.29000000","0.00014000"],["78759.20000000","0.00007000"],["78758.37000000","0.00007000"],["78758.20000000","0.00014000"],["78758.19000000","0.03762000"],["78758.05000000","0.00541000"],["78758.01000000","0.00014000"],["78758.00000000","0.02414000"],["78757.99000000","0.00020000"],["78757.69000000","0.00007000"],["78757.65000000","0.00007000"],["78757.64000000","0.02514000"],["78757.63000000","0.00007000"],["78757.34000000","0.00007000"],["78757.32000000","0.00007000"],["78756.98000000","0.00007000"],["78756.94000000","0.00014000"],["78756.93000000","0.04513000"]],"asks":[["78759.47000000","3.10382000"],["78759.48000000","0.00020000"],["78759.49000000","0.00013000"],["78760.59000000","0.31750000"],["78760.60000000","0.00400000"],["78760.72000000","0.00014000"],["78760.73000000","0.38326000"],["78760.79000000","0.00007000"],["78760.95000000","0.00014000"],["78760.96000000","0.39252000"],["78760.97000000","0.01290000"],["78761.00000000","0.00014000"],["78761.01000000","0.06359000"],["78761.55000000","0.00007000"],["78761.98000000","0.00014000"],["78761.99000000","0.07507000"],["78762.00000000","0.04109000"],["78762.04000000","0.00007000"],["78762.13000000","0.00254000"],["78762.24000000","0.00014000"]]}}}
{"rx_ns": 15958020300, "frame": {"stream":"btcusdt@depth","data":{"e":"depthUpdate","E":1787602883014,"s":"BTCUSDT","U":99076496204,"u":99076497256,"b":[["78761.99000000","0.00000000"],["78761.98000000","0.00000000"],["78761.97000000","0.00000000"],["78761.56000000","0.00000000"],["78761.03000000","0.00000000"],["78760.97000000","0.00000000"],["78760.96000000","0.00000000"],["78760.95000000","0.00000000"],["78760.78000000","0.00000000"],["78760.73000000","0.00000000"],["78760.72000000","0.00000000"],["78760.71000000","0.00000000"],["78760.00000000","0.00000000"],["78759.99000000","0.00000000"],["78759.76000000","0.00000000"],["78759.60000000","0.00000000"],["78759.47000000","0.00000000"],["78759.46000000","0.04280000"],["78759.45000000","0.00070000"],["78759.30000000","0.00000000"],["78759.29000000","0.00014000"],["78758.67000000","0.00000000"],["78758.66000000","0.00000000"],["78758.26000000","0.00000000"],["78758.25000000","0.00000000"],["78758.21000000","0.00000000"],["78758.20000000","0.00014000"],["78758.19000000","0.03762000"],["78758.01000000","0.00014000"],["78758.00000000","0.02414000"],["78757.99000000","0.00020000"],["78757.65000000","0.00007000"],["78757.64000000","0.02514000"],["78757.63000000","0.00007000"],["78757.00000000","0.00000000"],["78756.94000000","0.00014000"],["78756.93000000","0.04513000"],["78756.76000000","0.00014000"],["78756.75000000","0.05171000"],["78756.48000000","0.00204000"],["78756.47000000","0.20798000"],["78756.06000000","0.00000000"],["78756.01000000","0.00000000"],["78756.00000000","0.02407000"],["78755.99000000","0.00000000"],["78755.93000000","0.00000000"],["78755.67000000","0.04507000"],["78755.60000000","0.00000000"],["78755.18000000","0.00000000"],["78755.17000000","0.00000000"],["78754.81000000","0.03525000"],["78754.50000000","0.00007000"],["78754.45000000","0.00000000"],["78754.11000000","0.00267000"],["78754.01000000","0.00000000"],["78754.00000000","0.02400000"],["78753.99000000","0.03613000"],["78753.88000000","0.00000000"],["78753.41000000","0.00710000"],["78753.23000000","0.00000000"],["78753.22000000","0.00000000"],["78753.20000000","0.00000000"],["78753.19000000","0.00000000"],["78753.08000000","0.00000000"],["78752.72000000","0.00000000"],["78751.58000000","0.21930000"],["78750.75000000","0.00000000"],["78750.65000000","0.00000000"],["78750.63000000","0.00007000"],["78750.08000000","0.00000000"],["78750.07000000","0.00000000"],["78750.05000000","0.00000000"],["78749.60000000","0.00000000"],["78749.36000000","0.00000000"],["78749.27000000","0.00000000"],["78749.16000000","0.00000000"],["78748.44000000","0.08576000"],["78748.27000000","0.00000000"],["78748.26000000","0.36224000"],["78747.71000000","0.00000000"],["78747.67000000","0.00000000"],["78747.62000000","0.00000000"],["78747.29000000","0.01000000"],["78747.20000000","0.00000000"],["78747.19000000","0.00000000"],["78746.82000000","0.00000000"],["78746.79000000","0.00000000"],["78746.49000000","0.00000000"],["78746.39000000","0.00254000"],["78745.77000000","0.00000000"],["78745.59000000","0.00000000"],["78745.23000000","0.00000000"],["78745.11000000","0.00635000"],["78745.09000000","0.00000000"],["78744.85000000","0.00635000"],["78744.84000000","0.02400000"],["78743.99000000","0.00000000"],["78743.97000000","0.02000000"],["78743.92000000","0.00000000"],["78742.99000000","0.02000000"],["78742.39000000","0.04000000"],["78742.19000000","0.00000000"],["78741.23000000","0.02000000"],["78740.73000000","0.00400000"],["78740.72000000","0.07282000"],["78740.70000000","0.00000000"],["78740.19000000","0.00000000"],["78740.18000000","0.00000000"],["78740.00000000","0.02400000"],["78739.62000000","1.22100000"],["78739.29000000","0.08000000"],["78738.61000000","0.36224000"],["78738.59000000","0.00000000"],["78738.32000000","0.00000000"],["78737.93000000","0.00000000"],["78735.79000000","0.00007000"],["78733.03000000","0.00000000"],["78731.73000000","0.00000000"],["78731.33000000","0.00000000"],["78730.01000000","0.36690000"],["78729.64000000","0.00000000"],["78729.63000000","0.00000000"],["78728.99000000","0.49492000"],["78728.68000000","0.13238000"],["78726.02000000","0.00635000"],["78722.00000000","0.02407000"],["78721.96000000","0.00000000"],["78721.20000000","0.00400000"],["78721.00000000","0.00000000"],["78720.50000000","0.00000000"],["78720.29000000","0.00000000"],["78720.08000000","0.00000000"],["78720.00000000","0.47590000"],["78719.53000000","0.34303000"],["78719.52000000","0.09512000"],["78718.31000000","0.34303000"],["78715.91000000","0.00000000"],["78715.29000000","0.00400000"],["78711.93000000","0.00007000"],["78708.21000000","0.00007000"],["78708.03000000","0.00000000"],["78707.85000000","0.00000000"],["78707.34000000","0.00000000"],["78707.32000000","0.02770000"],["78705.37000000","0.96880000"],["78700.01000000","0.00000000"],["78698.30000000","0.00316000"],["78694.92000000","0.00428000"],["78694.00000000","0.02415000"],["78684.17000000","1.25835000"],["78680.57000000","0.02000000"],["78679.78000000","0.02000000"],["78679.42000000","0.02000000"],["78678.01000000","0.00000000"],["78677.83000000","0.00000000"],["78676.13000000","0.00314000"],["78674.38000000","0.02000000"],["78673.99000000","0.02000000"],["78652.36000000","0.00000000"],["78649.75000000","2.77023000"],["78642.42000000","0.00000000"],["78639.86000000","0.00318000"],["78628.57000000","0.00000000"],["78626.92000000","0.00000000"],["78626.89000000","0.00000000"],["78626.81000000","0.00406000"],["78626.72000000","0.00000000"],["78625.56000000","0.04471000"],["78625.21000000","0.00000000"],["78584.95000000","0.00000000"],["78573.49000000","0.00000000"],["78570.51000000","4.53304000"],["78568.76000000","0.00000000"],["78562.29000000","0.00778000"],["78557.61000000","0.00000000"],["78556.02000000","0.06561000"],["78555.94000000","0.00406000"],["78555.85000000","0.00000000"],["78462.96000000","0.00250000"],["78442.89000000","7.64983000"],["78441.27000000","0.00000000"],["78429.91000000","0.00038000"],["78365.66000000","0.00000000"],["78355.80000000","0.00007000"],["77973.83000000","0.00009000"],["77583.96000000","0.00000000"],["77196.04000000","0.00000000"],["76810.06000000","0.00000000"],["76426.01000000","0.00000000"],["76043.88000000","0.00149000"],["75663.66000000","0.00000000"],["75285.34000000","0.00000000"],["74908.92000000","0.00000000"],["74830.08000000","0.00000000"],["74534.37000000","0.00000000"],["74161.70000000","0.00000000"],["73790.89000000","0.00000000"],["73421.94000000","0.00000000"],["73271.12000000","0.00008000"],["73054.83000000","0.00000000"],["72460.16000000","0.00000000"],["71712.16000000","0.00000000"],["70885.80000000","0.00025000"],["70885.79000000","0.00000000"],["70885.78000000","0.00009000"],["70885.00000000","0.00000000"],["70883.52000000","0.00144000"],["70153.20000000","0.00000000"],["68594.24000000","0.00000000"],["67035.28000000","0.00000000"],["65476.32000000","0.00000000"],["63917.36000000","0.00000000"],["63009.60000000","0.00000000"],["63008.00000000","0.14940000"],["63007.57000000","0.00031000"],["62358.40000000","0.00000000"],["60799.44000000","0.00000000"],["59240.48000000","0.00000000"],["57681.52000000","0.00000000"],["56122.56000000","0.00000000"],["54563.60000000","0.00000000"],["53004.64000000","0.00000000"],["51445.68000000","0.00000000"],["49886.72000000","0.00000000"],["48327.76000000","0.00000000"],["46768.80000000","0.00000000"]],"a":[["78759.47000000","3.10382000"],["78759.48000000","0.00020000"],["78759.49000000","0.00013000"],["78759.61000000","0.00000000"],["78760.00000000","0.00000000"],["78760.01000000","0.00000000"],["78760.59000000","0.31750000"],["78760.60000000","0.00400000"],["78760.70000000","0.00000000"],["78760.71000000","0.00000000"],["78760.72000000","0.00014000"],["78760.73000000","0.38326000"],["78760.74000000","0.00000000"],["78760.75000000","0.00000000"],["78760.79000000","0.00007000"],["78760.95000000","0.00014000"],["78760.96000000","0.39252000"],["78760.97000000","0.01290000"],["78760.98000000","0.00000000"],["78760.99000000","0.00000000"],["78761.00000000","0.00014000"],["78761.01000000","0.06359000"],["78761.04000000","0.00000000"],["78761.22000000","0.00000000"],["78761.55000000","0.00007000"],["78761.98000000","0.00014000"],["78761.99000000","0.07507000"],["78762.00000000","0.04109000"],["78762.01000000","0.00000000"],["78762.02000000","0.00000000"],["78762.03000000","0.00000000"],["78762.04000000","0.00007000"],["78762.13000000","0.00254000"],["78762.20000000","0.00000000"],["78762.27000000","0.01562000"],["78762.35000000","0.00007000"],["78762.53000000","0.00000000"],["78762.54000000","0.00000000"],["78762.55000000","0.02168000"],["78762.78000000","0.00007000"],["78762.79000000","0.38096000"],["78763.12000000","0.00000000"],["78763.30000000","0.00008000"],["78763.36000000","0.00000000"],["78763.41000000","0.00000000"],["78763.45000000","0.00000000"],["78763.47000000","0.00007000"],["78763.54000000","0.02592000"],["78763.56000000","0.00000000"],["78763.57000000","0.31751000"],["78763.58000000","0.00000000"],["78763.59000000","0.25416000"],["78763.91000000","0.00000000"],["78764.00000000","0.02414000"],["78764.14000000","0.00335000"],["78764.54000000","0.00320000"],["78764.80000000","0.03110000"],["78765.08000000","0.00000000"],["78765.55000000","0.00000000"],["78765.82000000","0.00000000"],["78765.93000000","0.12705000"],["78766.06000000","0.03110000"],["78766.34000000","0.00000000"],["78766.58000000","0.00000000"],["78767.52000000","0.00000000"],["78767.60000000","0.00000000"],["78767.64000000","0.00000000"],["78768.45000000","0.38091000"],["78768.86000000","0.00000000"],["78768.87000000","0.02000000"],["78769.63000000","0.02000000"],["78769.65000000","0.02000000"],["78769.66000000","0.00000000"],["78769.67000000","0.02000000"],["78769.69000000","0.02000000"],["78771.67000000","1.90515000"],["78772.03000000","1.21952000"],["78773.69000000","0.00000000"],["78773.89000000","0.00000000"],["78774.19000000","0.34289000"],["78774.61000000","0.04103000"],["78774.93000000","0.02000000"],["78775.23000000","0.11058000"],["78775.53000000","0.00000000"],["78776.49000000","0.00000000"],["78776.82000000","0.00000000"],["78777.05000000","0.00000000"],["78777.45000000","0.00000000"],["78777.76000000","0.00007000"],["78778.18000000","0.00000000"],["78778.24000000","0.00000000"],["78778.26000000","0.00000000"],["78779.03000000","0.09717000"],["78779.73000000","0.00000000"],["78781.25000000","0.00000000"],["78782.86000000","0.00000000"],["78783.05000000","0.00007000"],["78785.00000000","0.00000000"],["78785.58000000","0.00000000"],["78788.53000000","0.00000000"],["78790.23000000","0.00000000"],["78792.12000000","0.00000000"],["78793.12000000","0.00000000"],["78795.98000000","0.02475000"],["78797.21000000","0.00435000"],["78797.49000000","0.00616000"],["78799.00000000","0.02582000"],["78800.31000000","0.00428000"],["78800.78000000","0.00000000"],["78800.94000000","0.00000000"],["78801.00000000","0.00000000"],["78801.52000000","0.00434000"],["78802.00000000","0.02400000"],["78806.72000000","0.00000000"],["78807.33000000","0.00000000"],["78809.99000000","0.00316000"],["78810.38000000","0.00000000"],["78810.94000000","0.00000000"],["78811.99000000","0.00000000"],["78820.80000000","0.00543000"],["78821.03000000","0.00007000"],["78825.71000000","0.00000000"],["78826.24000000","0.00000000"],["78828.09000000","0.00000000"],["78831.99000000","0.00315000"],["78832.97000000","0.00000000"],["78835.06000000","0.00000000"],["78836.13000000","0.00000000"],["78836.14000000","0.00000000"],["78836.23000000","0.00000000"],["78859.35000000","0.00000000"],["78878.67000000","0.00000000"],["78901.07000000","0.00000000"],["78943.77000000","0.01989000"],["78959.51000000","0.00000000"],["79016.18000000","0.00026000"],["79027.63000000","0.00000000"],["79153.27000000","0.00000000"],["79274.64000000","0.00250000"],["79549.04000000","0.00000000"],["79946.78000000","0.00000000"],["80346.52000000","0.00000000"],["80748.25000000","0.00000000"],["81151.99000000","0.00000000"],["81557.75000000","0.00000000"],["81965.54000000","0.00000000"],["82375.37000000","0.00000000"],["82787.24000000","0.00000000"],["83201.18000000","0.00000000"],["83617.19000000","0.00000000"],["84035.27000000","0.00000000"],["84455.45000000","0.00000000"],["84877.73000000","0.00000000"],["121877.02000000","0.00000000"]]}}}
{"rx_ns": 16953404200, "frame": {"stream":"btcusdt@depth20","data":{"lastUpdateId":99076497557,"bids":[["78759.46000000","0.53712000"],["78759.45000000","0.00083000"],["78759.44000000","0.00013000"],["78759.29000000","0.00014000"],["78758.37000000","0.00007000"],["78758.20000000","0.00014000"],["78758.19000000","0.03762000"],["78758.05000000","0.00541000"],["78758.01000000","0.00014000"],["78758.00000000","0.02414000"],["78757.99000000","0.00020000"],["78757.69000000","0.00007000"],["78757.65000000","0.00014000"],["78757.64000000","0.02521000"],["78757.63000000","0.00007000"],["78757.34000000","0.00007000"],["78757.32000000","0.00007000"],["78756.98000000","0.00007000"],["78756.94000000","0.00014000"],["78756.93000000","0.04513000"]],"asks":[["78759.47000000","2.82877000"],["78759.48000000","0.00034000"],["78759.49000000","0.00013000"],["78760.60000000","0.00400000"],["78760.72000000","0.00014000"],["78760.73000000","0.38326000"],["78760.79000000","0.00007000"],["78760.95000000","0.00014000"],["78760.96000000","0.31752000"],["78760.97000000","0.00014000"],["78761.01000000","0.00007000"],["78761.55000000","0.00007000"],["78761.96000000","0.00635000"],["78761.97000000","0.00014000"],["78761.98000000","0.31757000"],["78762.00000000","0.04099000"],["78762.04000000","0.00007000"],["78762.24000000","0.00014000"],["78762.27000000","0.01562000"],["78762.55000000","0.02168000"]]}}}
{"rx_ns": 16953526900, "frame": {"stream":"btcusdt@depth","data":{"e":"depthUpdate","E":1787602884014,"s":"BTCUSDT","U":99076497257,"u":99076497557,"b":[["78759.46000000","0.53712000"],["78759.45000000","0.00083000"],["78759.44000000","0.00013000"],["78759.20000000","0.00000000"],["78758.00000000","0.02414000"],["78757.66000000","0.00000000"],["78757.65000000","0.00014000"],["78757.64000000","0.02521000"],["78756.76000000","0.00007000"],["78756.59000000","0.00000000"],["78756.47000000","0.20798000"],["78756.46000000","0.00000000"],["78756.00000000","0.02400000"],["78755.49000000","0.00000000"],["78755.07000000","0.00000000"],["78754.81000000","0.00000000"],["78752.38000000","0.00007000"],["78750.63000000","0.00014000"],["78750.58000000","0.00070000"],["78750.38000000","0.00000000"],["78748.64000000","0.00000000"],["78747.33000000","0.00000000"],["78747.29000000","0.03000000"],["78747.08000000","0.00254000"],["78746.39000000","0.00000000"],["78742.99000000","0.00000000"],["78742.39000000","0.00000000"],["78739.29000000","0.00000000"],["78737.19000000","0.12000000"],["78735.79000000","0.00007000"],["78732.48000000","0.04702000"],["78722.11000000","0.02000000"],["78718.47000000","0.02000000"],["78717.26000000","0.00400000"],["78716.74000000","0.00000000"],["78715.29000000","0.00000000"],["78711.93000000","0.00007000"],["78707.32000000","0.00000000"],["78707.14000000","0.02800000"],["78698.30000000","0.00000000"],["78696.85000000","0.00315000"],["78696.30000000","0.00007000"],["78690.72000000","0.00000000"],["78677.98000000","0.02000000"],["78674.82000000","0.02200000"],["78674.38000000","0.00000000"],["78671.55000000","0.00000000"],["78620.07000000","0.00000000"],["78618.01000000","0.00126000"],["78612.01000000","0.00000000"],["78598.24000000","0.00000000"],["78596.81000000","0.00126000"],["78568.76000000","0.00778000"],["78562.29000000","0.00000000"],["78365.66000000","0.00000000"],["78355.80000000","0.00000000"],["78053.13000000","0.00000000"],["77973.83000000","0.00009000"],["77583.96000000","0.00000000"],["77196.04000000","0.00000000"],["76810.06000000","0.00000000"],["76426.01000000","0.00000000"],["76043.88000000","0.00149000"],["75663.66000000","0.00000000"],["75285.34000000","0.00000000"],["74908.92000000","0.00000000"],["74534.37000000","0.00000000"],["74161.70000000","0.00000000"],["73790.89000000","0.00000000"],["73421.94000000","0.00000000"],["73054.83000000","0.00000000"],["70883.52000000","0.00240000"],["70883.00000000","0.31111000"],["63010.00000000","0.05451000"],["63007.57000000","0.00031000"]],"a":[["78759.47000000","2.82877000"],["78759.48000000","0.00034000"],["78760.59000000","0.00000000"],["78760.95000000","0.00014000"],["78760.96000000","0.31752000"],["78760.97000000","0.00014000"],["78761.00000000","0.00000000"],["78761.01000000","0.00007000"],["78761.54000000","0.00000000"],["78761.96000000","0.00635000"],["78761.97000000","0.00014000"],["78761.98000000","0.31757000"],["78761.99000000","0.00000000"],["78762.00000000","0.04099000"],["78762.13000000","0.00000000"],["78762.27000000","0.01562000"],["78762.35000000","0.00000000"],["78762.55000000","0.02168000"],["78762.78000000","0.00014000"],["78762.79000000","0.38103000"],["78762.83000000","0.00254000"],["78763.07000000","0.00000000"],["78763.54000000","0.02599000"],["78763.57000000","0.00007000"],["78763.58000000","0.00007000"],["78764.38000000","0.00000000"],["78764.74000000","0.00317000"],["78768.09000000","0.34282000"],["78773.86000000","0.12694000"],["78778.34000000","0.04480000"],["78780.82000000","0.00000000"],["78782.10000000","0.00000000"],["78783.05000000","0.00007000"],["78784.59000000","0.34274000"],["78790.68000000","0.00000000"],["78790.85000000","0.00000000"],["78791.95000000","0.00000000"],["78792.75000000","0.00660000"],["78796.85000000","0.10000000"],["78825.71000000","0.02000000"],["78830.25000000","0.00317000"],["78831.99000000","0.00000000"],["78887.29000000","0.00126000"],["78888.01000000","0.00000000"],["78889.97000000","0.00000000"],["78927.45000000","0.00000000"],["79153.27000000","0.00000000"],["79549.04000000","0.00000000"],["79946.78000000","0.00000000"],["80346.52000000","0.00000000"],["80748.25000000","0.00000000"],["81151.99000000","0.00000000"],["81557.75000000","0.00000000"],["81965.54000000","0.00000000"],["82375.37000000","0.00000000"],["82787.24000000","0.00000000"],["83201.18000000","0.00000000"],["83617.19000000","0.00000000"],["84035.27000000","0.00000000"],["84455.45000000","0.00000000"],["84877.73000000","0.00000000"]]}}}
{"rx_ns": 17955331500, "frame": {"stream":"btcusdt@depth20","data":{"lastUpdateId":99076498790,"bids":[["78756.07000000","0.55958000"],["78756.06000000","0.00056000"],["78756.01000000","0.00014000"],["78756.00000000","0.02407000"],["78755.27000000","0.00007000"],["78754.81000000","0.00014000"],["78754.80000000","0.03575000"],["78754.50000000","0.00007000"],["78754.27000000","0.00204000"],["78754.11000000","0.00267000"],["78754.01000000","0.00014000"],["78754.00000000","0.02421000"],["78753.99000000","0.03457000"],["78753.89000000","0.00014000"],["78753.88000000","0.20805000"],["78753.54000000","0.04288000"],["78753.36000000","0.05172000"],["78753.24000000","0.00007000"],["78752.92000000","0.00007000"],["78752.39000000","1.21959000"]],"asks":[["78756.08000000","3.04911000"],["78756.09000000","0.00027000"],["78756.10000000","0.00013000"],["78756.48000000","0.00007000"],["78757.64000000","0.00014000"],["78757.65000000","1.71865000"],["78757.70000000","0.00007000"],["78758.18000000","0.01675000"],["78758.19000000","0.07507000"],["78758.20000000","0.00014000"],["78758.37000000","0.07535000"],["78758.38000000","0.59066000"],["78758.63000000","0.00400000"],["78759.43000000","0.00014000"],["78759.44000000","0.31753000"],["78759.45000000","0.02787000"],["78759.46000000","0.00007000"],["78759.47000000","0.01306000"],["78759.51000000","0.06345000"],["78760.43000000","0.00027000"]]}}}
{"rx_ns": 17955417200, "frame": {"stream":"btcusdt@depth","data":{"e":"depthUpdate","E":1787602885014,"s":"BTCUSDT","U":99076497558,"u":99076498790,"b":[["78759.46000000","0.00000000"],["78759.45000000","0.00000000"],["78759.44000000","0.00000000"],["78759.29000000","0.00000000"],["78758.37000000","0.00000000"],["78758.36000000","0.00000000"],["78758.20000000","0.00000000"],["78758.19000000","0.00000000"],["78758.05000000","0.00000000"],["78758.01000000","0.00000000"],["78758.00000000","0.00000000"],["78757.99000000","0.00000000"],["78757.69000000","0.00000000"],["78757.65000000","0.00000000"],["78757.64000000","0.00000000"],["78757.63000000","0.00000000"],["78757.34000000","0.00000000"],["78757.32000000","0.00000000"],["78756.98000000","0.00000000"],["78756.94000000","0.00000000"],["78756.93000000","0.00000000"],["78756.84000000","0.00000000"],["78756.76000000","0.00000000"],["78756.75000000","0.00000000"],["78756.48000000","0.00000000"],["78756.47000000","0.00000000"],["78756.08000000","0.00000000"],["78756.07000000","0.55958000"],["78756.06000000","0.00056000"],["78756.01000000","0.00014000"],["78756.00000000","0.02407000"],["78755.68000000","0.00000000"],["78755.67000000","0.00000000"],["78755.66000000","0.00000000"],["78755.29000000","0.00000000"],["78755.27000000","0.00007000"],["78755.26000000","0.00000000"],["78754.94000000","0.00000000"],["78754.93000000","0.00000000"],["78754.81000000","0.00014000"],["78754.80000000","0.03575000"],["78754.46000000","0.00000000"],["78754.45000000","0.00000000"],["78754.41000000","0.00000000"],["78754.40000000","0.00000000"],["78754.27000000","0.00204000"],["78754.01000000","0.00014000"],["78754.00000000","0.02421000"],["78753.99000000","0.03457000"],["78753.89000000","0.00014000"],["78753.88000000","0.20805000"],["78753.54000000","0.04288000"],["78753.41000000","0.00000000"],["78753.37000000","0.00000000"],["78753.36000000","0.05172000"],["78753.25000000","0.00000000"],["78753.20000000","0.00000000"],["78752.92000000","0.00007000"],["78752.71000000","0.00000000"],["78752.40000000","0.00000000"],["78752.39000000","1.21959000"],["78752.38000000","0.00000000"],["78752.34000000","0.00000000"],["78752.28000000","0.04281000"],["78752.10000000","0.04859000"],["78752.00000000","0.02400000"],["78751.81000000","0.00000000"],["78751.58000000","0.00007000"],["78750.63000000","0.00007000"],["78750.58000000","0.00000000"],["78750.50000000","0.00000000"],["78750.49000000","0.00000000"],["78750.22000000","0.12698000"],["78750.00000000","0.02724000"],["78749.89000000","0.00000000"],["78749.73000000","0.00000000"],["78749.19000000","0.00000000"],["78748.88000000","0.00000000"],["78748.44000000","0.00000000"],["78748.27000000","0.00000000"],["78748.26000000","2.26739000"],["78748.25000000","0.00000000"],["78748.20000000","0.00000000"],["78748.18000000","0.00000000"],["78747.62000000","0.00000000"],["78747.34000000","0.00332000"],["78747.14000000","0.00000000"],["78747.08000000","0.00000000"],["78747.06000000","0.00000000"],["78746.62000000","0.00000000"],["78746.58000000","0.00000000"],["78746.10000000","0.00000000"],["78745.48000000","0.08576000"],["78745.42000000","0.00254000"],["78745.17000000","0.00000000"],["78745.11000000","0.00000000"],["78745.00000000","0.00000000"],["78744.93000000","0.00000000"],["78744.85000000","0.00000000"],["78744.37000000","0.00000000"],["78744.26000000","0.00327000"],["78743.97000000","0.00000000"],["78743.16000000","0.00048000"],["78743.15000000","0.00163000"],["78742.93000000","0.00007000"],["78742.78000000","0.00406000"],["78742.69000000","0.00000000"],["78742.64000000","0.00635000"],["78742.63000000","1.21912000"],["78742.13000000","0.00635000"],["78741.16000000","0.02000000"],["78741.03000000","0.02200000"],["78740.73000000","0.00000000"],["78740.72000000","0.00007000"],["78740.32000000","0.00323000"],["78739.62000000","0.00189000"],["78738.62000000","0.00400000"],["78737.88000000","0.02200000"],["78736.88000000","0.06554000"],["78736.69000000","0.00000000"],["78736.39000000","0.00000000"],["78736.38000000","0.00325000"],["78736.31000000","0.02000000"],["78736.24000000","0.02000000"],["78735.79000000","0.00007000"],["78734.91000000","0.07569000"],["78732.69000000","0.12701000"],["78732.44000000","0.00323000"],["78731.91000000","0.00000000"],["78731.33000000","0.00000000"],["78730.01000000","0.00000000"],["78727.50000000","0.00000000"],["78727.17000000","0.00000000"],["78727.16000000","0.00000000"],["78726.02000000","0.23517000"],["78724.00000000","0.02400000"],["78722.43000000","0.00000000"],["78722.37000000","0.00000000"],["78720.00000000","0.46590000"],["78719.67000000","0.00014000"],["78719.52000000","0.00000000"],["78718.00000000","0.02400000"],["78716.00000000","0.03400000"],["78713.36000000","0.63529000"],["78713.14000000","0.34306000"],["78712.31000000","0.00000000"],["78711.93000000","0.00007000"],["78709.92000000","0.00000000"],["78709.56000000","0.00000000"],["78707.14000000","0.00000000"],["78706.98000000","0.00000000"],["78706.88000000","0.00000000"],["78706.72000000","0.00000000"],["78703.40000000","0.00406000"],["78698.34000000","0.00429000"],["78697.76000000","0.00619000"],["78696.85000000","0.00000000"],["78695.93000000","0.00000000"],["78694.09000000","0.00317000"],["78692.48000000","0.00000000"],["78691.10000000","0.00007000"],["78684.48000000","0.02200000"],["78684.17000000","0.00000000"],["78681.32000000","0.02200000"],["78679.75000000","1.25842000"],["78679.74000000","0.02000000"],["78679.42000000","0.00000000"],["78676.65000000","0.00539000"],["78676.13000000","0.00000000"],["78675.22000000","0.00000000"],["78674.00000000","0.04400000"],["78672.47000000","0.00316000"],["78671.91000000","0.00000000"],["78671.54000000","0.00406000"],["78670.75000000","0.02115000"],["78639.86000000","0.00000000"],["78626.81000000","0.00000000"],["78625.56000000","0.00000000"],["78624.66000000","0.00406000"],["78623.81000000","0.04471000"],["78618.01000000","0.00000000"],["78614.46000000","0.00126000"],["78596.81000000","0.00000000"],["78593.47000000","0.00126000"],["78555.94000000","0.00000000"],["78553.79000000","0.00020000"],["78553.42000000","0.00406000"],["78365.66000000","0.00000000"],["78355.80000000","0.00007000"],["78050.62000000","0.00010000"],["77973.83000000","0.00009000"],["77583.96000000","0.00000000"],["77196.04000000","0.00000000"],["76810.06000000","0.00000000"],["76426.01000000","0.00000000"],["76043.88000000","0.00149000"],["75663.66000000","0.00000000"],["75285.34000000","0.00000000"],["74908.92000000","0.00000000"],["74534.37000000","0.00000000"],["74161.70000000","0.00000000"],["73790.89000000","0.00000000"],["73421.94000000","0.00000000"],["73054.83000000","0.00000000"],["72600.00000000","2.91177000"],["70885.78000000","0.00000000"],["70883.52000000","0.00000000"],["70883.00000000","0.31111000"],["70881.88000000","0.00564000"],["70880.47000000","0.00080000"],["63010.00000000","0.05451000"],["63008.00000000","0.14940000"],["63007.57000000","0.00000000"],["63006.12000000","0.00000000"],["63006.11000000","0.00000000"],["63004.86000000","0.00031000"]],"a":[["78756.08000000","3.04911000"],["78756.09000000","0.00027000"],["78756.10000000","0.00013000"],["78756.48000000","0.00007000"],["78756.76000000","0.00000000"],["78756.83000000","0.00000000"],["78756.85000000","0.00000000"],["78756.94000000","0.00000000"],["78756.99000000","0.00000000"],["78757.33000000","0.00000000"],["78757.63000000","0.00000000"],["78757.64000000","0.00014000"],["78757.65000000","1.71865000"],["78757.66000000","0.00000000"],["78757.67000000","0.00000000"],["78757.70000000","0.00007000"],["78758.00000000","0.00000000"],["78758.01000000","0.00000000"],["78758.02000000","0.00000000"],["78758.05000000","0.00000000"],["78758.06000000","0.00000000"],["78758.17000000","0.00000000"],["78758.18000000","0.01675000"],["78758.19000000","0.07507000"],["78758.20000000","0.00014000"],["78758.21000000","0.00000000"],["78758.36000000","0.00000000"],["78758.37000000","0.07535000"],["78758.38000000","0.59066000"],["78758.39000000","0.00000000"],["78758.40000000","0.00000000"],["78758.63000000","0.00400000"],["78759.30000000","0.00000000"],["78759.43000000","0.00014000"],["78759.44000000","0.31753000"],["78759.45000000","0.02787000"],["78759.46000000","0.00007000"],["78759.47000000","0.01306000"],["78759.48000000","0.00000000"],["78759.49000000","0.00000000"],["78759.50000000","0.00000000"],["78759.51000000","0.06345000"],["78760.11000000","0.00000000"],["78760.43000000","0.00027000"],["78760.71000000","0.03336000"],["78760.72000000","0.00014000"],["78760.73000000","0.38312000"],["78760.91000000","0.00000000"],["78760.95000000","0.00000000"],["78760.96000000","0.00000000"],["78760.97000000","0.00007000"],["78761.01000000","0.00000000"],["78761.15000000","0.00635000"],["78761.16000000","0.00254000"],["78761.42000000","0.00007000"],["78761.55000000","0.00000000"],["78761.84000000","0.00000000"],["78761.96000000","0.00000000"],["78761.97000000","0.03336000"],["78761.98000000","0.00000000"],["78761.99000000","0.00000000"],["78762.00000000","0.04592000"],["78762.13000000","0.00319000"],["78762.27000000","0.00000000"],["78762.55000000","0.02161000"],["78762.78000000","0.00000000"],["78762.79000000","0.38096000"],["78762.80000000","0.00000000"],["78762.83000000","0.00000000"],["78763.54000000","0.00000000"],["78763.58000000","0.00000000"],["78763.59000000","0.00007000"],["78764.54000000","0.00000000"],["78764.62000000","0.00000000"],["78764.78000000","0.12696000"],["78764.80000000","0.00000000"],["78765.92000000","0.00007000"],["78766.06000000","0.00000000"],["78766.60000000","0.36224000"],["78766.61000000","0.00455000"],["78767.82000000","0.00000000"],["78768.78000000","0.34281000"],["78771.65000000","0.04103000"],["78771.84000000","0.09360000"],["78772.58000000","0.06551000"],["78772.79000000","0.00000000"],["78772.82000000","0.00000000"],["78772.89000000","0.00000000"],["78773.41000000","0.00000000"],["78773.86000000","0.00000000"],["78774.49000000","0.00000000"],["78774.55000000","0.07565000"],["78774.61000000","0.00000000"],["78775.23000000","0.00000000"],["78775.37000000","0.00000000"],["78776.88000000","0.00000000"],["78779.90000000","0.00317000"],["78780.53000000","0.12693000"],["78780.60000000","0.00000000"],["78782.13000000","0.00000000"],["78782.57000000","0.00000000"],["78783.05000000","0.00007000"],["78784.82000000","0.00000000"],["78786.32000000","0.00000000"],["78790.15000000","0.00000000"],["78792.86000000","0.67563000"],["78796.00000000","0.03400000"],["78797.07000000","0.00000000"],["78798.00000000","0.02400000"],["78799.00000000","0.01582000"],["78800.84000000","0.00000000"],["78805.22000000","0.00317000"],["78806.89000000","0.00000000"],["78809.99000000","0.00000000"],["78820.83000000","0.00000000"],["78821.03000000","0.00000000"],["78821.53000000","0.00405000"],["78825.72000000","0.00000000"],["78826.78000000","0.00317000"],["78830.25000000","0.00000000"],["78840.26000000","0.93647000"],["78845.48000000","0.00000000"],["78848.54000000","0.00529000"],["78851.47000000","0.21930000"],["78853.04000000","0.00405000"],["78853.64000000","0.00000000"],["78857.12000000","0.00032000"],["78857.23000000","0.00000000"],["78859.65000000","0.00000000"],["78862.27000000","0.00012000"],["78866.63000000","0.00000000"],["78868.41000000","0.00019000"],["78872.77000000","0.00000000"],["78874.51000000","0.00031000"],["78878.87000000","0.00000000"],["78885.48000000","0.00160000"],["78900.31000000","0.00405000"],["78904.50000000","0.00000000"],["78905.53000000","0.00126000"],["78912.12000000","0.00000000"],["78924.92000000","0.00160000"],["78971.21000000","0.00405000"],["78975.41000000","0.00000000"],["79153.27000000","0.00000000"],["79549.04000000","0.00000000"],["79946.78000000","0.00000000"],["80346.52000000","0.00000000"],["80748.25000000","0.00000000"],["81151.99000000","0.00000000"],["81557.75000000","0.00000000"],["81965.54000000","0.00000000"],["82375.37000000","0.00000000"],["82787.24000000","0.00000000"],["83201.18000000","0.00000000"],["83617.19000000","0.00000000"],["84035.27000000","0.00000000"],["84455.45000000","0.00000000"],["84877.73000000","0.00000000"]]}}}
{"rx_ns": 18953508800, "frame": {"stream":"btcusdt@depth20","data":{"lastUpdateId":99076499094,"bids":[["78756.07000000","0.53325000"],["78756.06000000","0.00062000"],["78756.05000000","0.00013000"],["78756.01000000","0.00014000"],["78756.00000000","0.02407000"],["78755.27000000","0.00007000"],["78754.81000000","0.00014000"],["78754.80000000","0.03575000"],["78754.50000000","0.00007000"],["78754.11000000","0.00267000"],["78754.01000000","0.00014000"],["78754.00000000","0.02421000"],["78753.99000000","0.03457000"],["78753.88000000","0.00007000"],["78753.55000000","0.00007000"],["78753.54000000","0.04288000"],["78753.36000000","0.05179000"],["78753.26000000","0.04449000"],["78753.24000000","0.00007000"],["78752.96000000","0.02521000"]],"asks":[["78756.08000000","3.01067000"],["78756.09000000","0.00020000"],["78756.10000000","0.00013000"],["78756.48000000","0.00007000"],["78756.65000000","0.31751000"],["78756.66000000","0.00400000"],["78757.64000000","0.00014000"],["78757.65000000","1.39480000"],["78757.70000000","0.00007000"],["78758.18000000","0.01675000"],["78758.19000000","0.00007000"],["78758.20000000","0.00014000"],["78758.37000000","0.00035000"],["78758.38000000","0.59066000"],["78758.63000000","0.00400000"],["78759.37000000","0.00007000"],["78759.43000000","0.00268000"],["78759.44000000","0.31753000"],["78759.45000000","0.02794000"],["78759.46000000","0.00007000"]]}}}
{"rx_ns": 18953659000, "frame": {"stream":"btcusdt@depth","data":{"e":"depthUpdate","E":1787602886014,"s":"BTCUSDT","U":99076498791,"u":99076499094,"b":[["78756.07000000","0.53325000"],["78756.06000000","0.00062000"],["78756.05000000","0.00013000"],["78754.27000000","0.00000000"],["78753.99000000","0.03457000"],["78753.89000000","0.00000000"],["78753.88000000","0.00007000"],["78753.55000000","0.00007000"],["78753.36000000","0.05179000"],["78753.26000000","0.04449000"],["78752.96000000","0.02521000"],["78752.43000000","0.20995000"],["78752.39000000","1.21952000"],["78752.10000000","0.00000000"],["78751.64000000","0.00000000"],["78751.58000000","0.00000000"],["78751.21000000","0.00000000"],["78750.55000000","0.00000000"],["78750.22000000","0.00000000"],["78750.01000000","0.00027000"],["78748.78000000","0.00000000"],["78748.27000000","0.00400000"],["78748.26000000","1.90515000"],["78747.34000000","0.00000000"],["78747.29000000","0.02000000"],["78746.76000000","0.00014000"],["78746.65000000","0.00000000"],["78746.57000000","0.00000000"],["78746.51000000","0.00047000"],["78746.28000000","0.12699000"],["78745.42000000","0.00000000"],["78744.84000000","0.00400000"],["78744.07000000","0.00000000"],["78743.99000000","0.00000000"],["78743.69000000","0.00254000"],["78742.89000000","0.01014000"],["78742.78000000","0.00000000"],["78742.13000000","0.00000000"],["78741.11000000","0.00406000"],["78741.03000000","0.02388000"],["78740.25000000","0.02000000"],["78739.62000000","0.00000000"],["78739.40000000","0.00635000"],["78738.90000000","0.00000000"],["78738.62000000","0.00000000"],["78736.89000000","0.00000000"],["78736.18000000","0.00000000"],["78735.79000000","0.00000000"],["78732.48000000","0.00000000"],["78732.40000000","0.00007000"],["78730.57000000","0.34298000"],["78729.14000000","0.04518000"],["78728.01000000","0.00000000"],["78726.65000000","0.00190000"],["78726.03000000","0.22873000"],["78726.02000000","0.00000000"],["78725.88000000","0.00060000"],["78722.11000000","0.00000000"],["78721.25000000","0.00635000"],["78720.18000000","0.00000000"],["78719.35000000","0.00000000"],["78717.88000000","0.00000000"],["78717.23000000","0.09365000"],["78713.32000000","0.00400000"],["78713.14000000","0.00000000"],["78708.06000000","0.00000000"],["78706.66000000","0.00000000"],["78705.40000000","0.00000000"],["78704.91000000","0.00014000"],["78703.40000000","0.00000000"],["78701.73000000","0.00406000"],["78700.84000000","0.02000000"],["78699.13000000","0.02600000"],["78693.88000000","0.00007000"],["78671.55000000","0.00000000"],["78671.54000000","0.00000000"],["78670.75000000","0.00000000"],["78670.42000000","0.00406000"],["78624.66000000","0.00000000"],["78623.81000000","0.04471000"],["78622.99000000","0.00406000"],["78568.76000000","0.00000000"],["78562.29000000","0.00778000"],["78548.42000000","0.00007000"],["78544.49000000","0.00000000"],["78362.28000000","0.00000000"],["77970.47000000","0.00000000"],["77580.62000000","0.00000000"],["77192.72000000","0.00000000"],["76806.75000000","0.00000000"],["76422.72000000","0.00036000"],["76040.61000000","0.00000000"],["75660.40000000","0.00000000"],["75282.10000000","0.00000000"],["74905.69000000","0.00000000"],["74531.16000000","0.00000000"],["74500.00000000","26.37692000"],["74158.51000000","0.00000000"],["73787.71000000","0.00000000"],["73418.78000000","0.00000000"],["73051.68000000","0.00000000"],["70880.47000000","0.00208000"],["70880.46000000","0.00009000"],["70880.00000000","0.00071000"],["63005.00000000","0.02539000"],["63004.86000000","0.00031000"]],"a":[["78756.08000000","3.01067000"],["78756.09000000","0.00020000"],["78756.65000000","0.31751000"],["78756.66000000","0.00400000"],["78757.65000000","1.39480000"],["78758.18000000","0.01675000"],["78758.19000000","0.00007000"],["78758.36000000","0.00000000"],["78758.37000000","0.00035000"],["78759.37000000","0.00007000"],["78759.42000000","0.00000000"],["78759.43000000","0.00268000"],["78759.45000000","0.02794000"],["78759.47000000","0.00030000"],["78759.51000000","0.00000000"],["78759.81000000","0.00000000"],["78760.14000000","0.00152000"],["78760.71000000","0.03343000"],["78760.72000000","0.00014000"],["78761.16000000","0.00000000"],["78762.00000000","0.05792000"],["78762.78000000","0.00007000"],["78766.18000000","0.02000000"],["78768.37000000","0.00000000"],["78769.63000000","0.00000000"],["78779.03000000","0.00000000"],["78779.66000000","0.00007000"],["78781.45000000","0.09441000"],["78781.76000000","0.00000000"],["78783.05000000","0.00000000"],["78785.89000000","0.02000000"],["78788.18000000","0.00000000"],["78800.00000000","0.04244000"],["78805.59000000","0.02000000"],["78805.93000000","0.00000000"],["78825.64000000","0.00000000"],["78837.65000000","0.93647000"],["78840.26000000","0.00000000"],["79149.87000000","0.00000000"],["79545.61000000","0.00000000"],["79943.34000000","0.00000000"],["80343.06000000","0.00000000"],["80744.77000000","0.00000000"],["81148.50000000","0.00000000"],["81554.24000000","0.00000000"],["81962.01000000","0.00000000"],["82371.82000000","0.00000000"],["82783.68000000","0.00000000"],["83197.60000000","0.00023000"],["83613.59000000","0.00000000"],["84031.66000000","0.00000000"],["84451.81000000","0.00000000"],["84874.07000000","0.00000000"]]}}}
{"rx_ns": 19951596700, "frame": {"stream":"btcusdt@depth20","data":{"lastUpdateId":99076499408,"bids":[["78756.07000000","0.95080000"],["78756.06000000","0.00062000"],["78756.05000000","0.00013000"],["78756.01000000","0.00014000"],["78756.00000000","0.02407000"],["78755.27000000","0.00007000"],["78754.81000000","0.00014000"],["78754.80000000","0.03575000"],["78754.50000000","0.00007000"],["78754.49000000","0.00014000"],["78754.48000000","0.03843000"],["78754.11000000","0.00267000"],["78754.01000000","0.00014000"],["78754.00000000","0.02421000"],["78753.99000000","0.03457000"],["78753.88000000","0.00007000"],["78753.54000000","0.04288000"],["78753.36000000","0.05179000"],["78753.24000000","0.00007000"],["78752.96000000","0.02514000"]],"asks":[["78756.08000000","2.84960000"],["78756.09000000","0.00069000"],["78756.10000000","0.00013000"],["78756.11000000","0.00014000"],["78756.12000000","0.06359000"],["78756.48000000","0.00007000"],["78756.65000000","0.00007000"],["78756.66000000","0.00400000"],["78757.64000000","0.00014000"],["78757.65000000","1.39473000"],["78757.70000000","0.00007000"],["78758.17000000","0.00641000"],["78758.18000000","0.01675000"],["78758.20000000","0.00014000"],["78758.37000000","0.31778000"],["78758.38000000","0.59073000"],["78758.63000000","0.00400000"],["78759.37000000","0.00007000"],["78759.43000000","0.00021000"],["78759.44000000","0.31753000"]]}}}
{"rx_ns": 19951681800, "frame": {"stream":"btcusdt@depth","data":{"e":"depthUpdate","E":1787602887014,"s":"BTCUSDT","U":99076499095,"u":99076499408,"b":[["78756.07000000","0.95080000"],["78756.06000000","0.00062000"],["78754.80000000","0.03575000"],["78754.49000000","0.00014000"],["78754.48000000","0.03843000"],["78753.55000000","0.00000000"],["78753.36000000","0.05179000"],["78753.26000000","0.00000000"],["78752.96000000","0.02514000"],["78752.92000000","0.00000000"],["78752.43000000","0.00000000"],["78748.28000000","0.00000000"],["78748.27000000","0.36224000"],["78746.51000000","0.00000000"],["78746.36000000","0.00325000"],["78746.21000000","0.00254000"],["78745.40000000","0.00000000"],["78743.92000000","0.00000000"],["78743.69000000","0.00000000"],["78742.89000000","0.00014000"],["78741.89000000","0.01000000"],["78739.87000000","0.02600000"],["78739.69000000","0.00000000"],["78738.62000000","0.00000000"],["78738.49000000","0.00000000"],["78732.40000000","0.00007000"],["78728.01000000","0.22654000"],["78726.03000000","0.00000000"],["78716.24000000","0.02000000"],["78715.86000000","0.02441000"],["78715.29000000","0.00400000"],["78713.32000000","0.00000000"],["78705.13000000","0.02851000"],["78701.73000000","0.00000000"],["78701.54000000","0.00406000"],["78700.46000000","0.02600000"],["78699.07000000","0.00000000"],["78681.14000000","0.02000000"],["78679.36000000","0.00000000"],["78671.55000000","0.00000000"],["78623.81000000","0.00000000"],["78622.28000000","0.04472000"],["78362.28000000","0.00000000"],["78355.80000000","0.00000000"],["78050.62000000","0.00000000"],["77970.47000000","0.00000000"],["77580.62000000","0.00000000"],["77192.72000000","0.00000000"],["76806.75000000","0.00000000"],["76422.72000000","0.00036000"],["76040.61000000","0.00000000"],["75660.40000000","0.00000000"],["75282.10000000","0.00000000"],["74905.69000000","0.00000000"],["74531.16000000","0.00000000"],["74158.51000000","0.00000000"],["73787.71000000","0.00000000"],["73418.78000000","0.00000000"],["73051.68000000","0.00000000"],["70880.47000000","0.00288000"],["70880.00000000","0.00071000"],["63005.00000000","0.02539000"],["63004.86000000","0.00031000"]],"a":[["78756.08000000","2.84960000"],["78756.09000000","0.00069000"],["78756.11000000","0.00014000"],["78756.12000000","0.06359000"],["78756.64000000","0.00000000"],["78756.65000000","0.00007000"],["78757.63000000","0.00000000"],["78757.64000000","0.00014000"],["78757.65000000","1.39473000"],["78757.74000000","0.00000000"],["78758.17000000","0.00641000"],["78758.18000000","0.01675000"],["78758.19000000","0.00000000"],["78758.37000000","0.31778000"],["78758.38000000","0.59073000"],["78759.43000000","0.00021000"],["78759.45000000","0.02787000"],["78759.47000000","0.00020000"],["78760.13000000","0.00635000"],["78760.43000000","0.00000000"],["78760.71000000","0.03336000"],["78760.72000000","0.00000000"],["78760.73000000","0.38339000"],["78761.14000000","0.00000000"],["78761.95000000","0.00254000"],["78762.00000000","0.06485000"],["78762.78000000","0.00000000"],["78763.57000000","0.00000000"],["78763.59000000","0.00000000"],["78766.26000000","0.02000000"],["78766.61000000","0.00000000"],["78769.66000000","0.00455000"],["78769.69000000","0.00000000"],["78774.33000000","0.02514000"],["78779.66000000","0.00007000"],["78780.37000000","0.00000000"],["78780.38000000","0.00000000"],["78780.39000000","0.00405000"],["78780.46000000","0.00000000"],["78782.89000000","0.00000000"],["78785.96000000","0.02000000"],["78805.67000000","0.02010000"],["78806.01000000","0.00000000"],["78825.71000000","0.00000000"],["78837.65000000","0.00000000"],["78853.73000000","0.00025000"],["78857.12000000","0.00007000"],["78858.51000000","0.02789000"],["78861.45000000","0.00000000"],["79149.87000000","0.00000000"],["79545.61000000","0.00000000"],["79943.34000000","0.00000000"],["80343.06000000","0.00000000"],["80744.77000000","0.00000000"],["81148.50000000","0.00000000"],["81554.24000000","0.00000000"],["81962.01000000","0.00000000"],["82371.82000000","0.00000000"],["82783.68000000","0.00000000"],["83197.60000000","0.00023000"],["83613.59000000","0.00000000"],["84031.66000000","0.00000000"],["84451.81000000","0.00000000"],["84874.07000000","0.00000000"]]}}}
{"rx_ns": 20958458700, "kind": "control", "ctl": {"op": "ping", "recv_ns": 20370130500, "pong_ns": 20370222700, "payload_len": 13, "payload_b64": "MTc4NzYwMjg4NzQzMw=="}, "frame": null}
{"rx_ns": 20958458700, "frame": {"stream":"btcusdt@depth20","data":{"lastUpdateId":99076499932,"bids":[["78756.00000000","0.04237000"],["78755.99000000","0.00028000"],["78754.81000000","0.00014000"],["78754.80000000","0.03575000"],["78754.50000000","0.00007000"],["78754.11000000","0.00267000"],["78754.01000000","0.00014000"],["78754.00000000","0.02421000"],["78753.99000000","0.03457000"],["78753.88000000","0.00007000"],["78753.55000000","0.00014000"],["78753.54000000","0.04288000"],["78753.37000000","0.00007000"],["78753.36000000","0.05179000"],["78753.24000000","0.00007000"],["78752.96000000","0.02521000"],["78752.91000000","0.00014000"],["78752.39000000","0.00007000"],["78752.36000000","0.00007000"],["78752.28000000","0.04281000"]],"asks":[["78756.01000000","3.19487000"],["78756.02000000","0.00020000"],["78756.03000000","0.00013000"],["78756.07000000","0.99985000"],["78756.08000000","0.32628000"],["78756.12000000","0.00007000"],["78756.48000000","0.00007000"],["78756.66000000","0.00400000"],["78757.64000000","0.00014000"],["78757.65000000","1.18478000"],["78757.70000000","0.00007000"],["78758.18000000","0.01675000"],["78758.20000000","0.00014000"],["78758.37000000","0.00028000"],["78758.38000000","0.59066000"],["78758.63000000","0.00400000"],["78759.37000000","0.00007000"],["78759.44000000","0.00007000"],["78759.45000000","0.02794000"],["78759.46000000","0.00007000"]]}}}
{"rx_ns": 20958643200, "frame": {"stream":"btcusdt@depth","data":{"e":"depthUpdate","E":1787602888014,"s":"BTCUSDT","U":99076499409,"u":99076499932,"b":[["78756.07000000","0.00000000"],["78756.06000000","0.00000000"],["78756.05000000","0.00000000"],["78756.01000000","0.00000000"],["78756.00000000","0.04237000"],["78755.99000000","0.00028000"],["78755.33000000","0.00000000"],["78755.32000000","0.00000000"],["78755.27000000","0.00000000"],["78754.80000000","0.03575000"],["78754.49000000","0.00000000"],["78754.48000000","0.00000000"],["78753.55000000","0.00014000"],["78753.37000000","0.00007000"],["78753.36000000","0.05179000"],["78752.96000000","0.02521000"],["78752.91000000","0.00014000"],["78752.39000000","0.00007000"],["78752.32000000","0.00000000"],["78750.95000000","0.05000000"],["78750.90000000","0.05000000"],["78750.03000000","0.00000000"],["78750.01000000","0.00000000"],["78749.93000000","0.00102000"],["78749.77000000","0.00000000"],["78749.14000000","0.00000000"],["78748.33000000","0.00007000"],["78748.27000000","0.00000000"],["78748.26000000","0.00000000"],["78747.54000000","0.00000000"],["78747.42000000","0.00000000"],["78747.41000000","0.00000000"],["78747.35000000","0.00000000"],["78747.23000000","0.00000000"],["78747.22000000","0.00000000"],["78747.21000000","0.00000000"],["78747.20000000","0.00000000"],["78747.18000000","0.03583000"],["78746.95000000","0.12714000"],["78746.76000000","0.00007000"],["78746.67000000","0.00048000"],["78746.21000000","0.00000000"],["78745.48000000","0.00000000"],["78745.33000000","0.00000000"],["78744.63000000","0.08576000"],["78743.92000000","0.00000000"],["78741.96000000","0.00000000"],["78741.89000000","0.00000000"],["78741.16000000","0.00000000"],["78739.91000000","0.02600000"],["78739.84000000","0.02000000"],["78739.59000000","0.01000000"],["78738.56000000","0.00000000"],["78738.06000000","0.00000000"],["78732.40000000","0.00007000"],["78728.01000000","0.00000000"],["78726.02000000","0.00000000"],["78725.15000000","0.00000000"],["78725.14000000","0.00400000"],["78724.61000000","0.23301000"],["78718.26000000","0.00000000"],["78717.23000000","0.00000000"],["78716.70000000","0.00000000"],["78715.35000000","0.00000000"],["78715.29000000","0.00000000"],["78710.95000000","0.63531000"],["78708.06000000","0.00007000"],["78705.13000000","0.00000000"],["78704.91000000","0.00007000"],["78704.47000000","0.00000000"],["78700.50000000","0.02600000"],["78699.13000000","0.00000000"],["78694.74000000","0.00000000"],["78682.19000000","1.25838000"],["78681.78000000","0.00000000"],["78680.75000000","0.02600000"],["78679.75000000","0.00000000"],["78679.43000000","0.00000000"],["78674.00000000","0.02400000"],["78671.55000000","0.00000000"],["78649.75000000","0.00000000"],["78615.53000000","0.00000000"],["78565.62000000","0.00778000"],["78562.29000000","0.00000000"],["78362.28000000","0.00000000"],["78355.80000000","0.00007000"],["78047.27000000","0.00010000"],["77970.47000000","0.00000000"],["77580.62000000","0.00000000"],["77192.72000000","0.00000000"],["76806.75000000","0.00000000"],["76422.72000000","0.00036000"],["76040.61000000","0.00000000"],["75660.40000000","0.00000000"],["75282.10000000","0.00000000"],["74905.69000000","0.00000000"],["74531.16000000","0.00000000"],["74158.51000000","0.00000000"],["73787.71000000","0.00000000"],["73418.78000000","0.00000000"],["73051.68000000","0.00000000"],["72460.16000000","0.00000000"],["70880.47000000","0.00000000"],["70880.00000000","0.00071000"],["63005.00000000","0.02539000"],["63004.86000000","0.00031000"]],"a":[["78756.01000000","3.19487000"],["78756.02000000","0.00020000"],["78756.03000000","0.00013000"],["78756.06000000","0.00000000"],["78756.07000000","0.99985000"],["78756.08000000","0.32628000"],["78756.09000000","0.00000000"],["78756.10000000","0.00000000"],["78756.11000000","0.00000000"],["78756.12000000","0.00007000"],["78756.65000000","0.00000000"],["78757.63000000","0.00000000"],["78757.64000000","0.00014000"],["78757.65000000","1.18478000"],["78758.17000000","0.00000000"],["78758.18000000","0.01675000"],["78758.36000000","0.00000000"],["78758.37000000","0.00028000"],["78758.38000000","0.59066000"],["78759.43000000","0.00000000"],["78759.44000000","0.00007000"],["78759.45000000","0.02794000"],["78760.00000000","0.00507000"],["78760.13000000","0.00000000"],["78760.71000000","0.03336000"],["78760.72000000","0.00000000"],["78760.74000000","0.00000000"],["78761.07000000","0.00000000"],["78761.95000000","0.00000000"],["78762.78000000","0.00400000"],["78765.50000000","3.12467000"],["78765.51000000","0.38092000"],["78766.28000000","0.02000000"],["78767.13000000","0.34282000"],["78768.09000000","0.00000000"],["78768.45000000","0.00000000"],["78769.67000000","0.00000000"],["78770.00000000","0.11922000"],["78770.73000000","0.00000000"],["78770.80000000","0.04103000"],["78771.65000000","0.00000000"],["78778.34000000","0.00000000"],["78779.66000000","0.00007000"],["78779.90000000","0.00000000"],["78780.95000000","0.04586000"],["78781.40000000","0.34276000"],["78782.05000000","0.00000000"],["78784.59000000","0.00000000"],["78785.99000000","0.02000000"],["78805.69000000","0.02000000"],["78806.02000000","0.00000000"],["78814.83000000","0.00000000"],["78820.82000000","0.00000000"],["78824.21000000","0.00000000"],["78825.73000000","0.00000000"],["78826.24000000","0.00000000"],["78826.25000000","0.00000000"],["78840.26000000","0.93647000"],["78914.82000000","0.00000000"],["79149.87000000","0.00000000"],["79545.61000000","0.00000000"],["79943.34000000","0.00000000"],["80343.06000000","0.00000000"],["80744.77000000","0.00000000"],["81148.50000000","0.00000000"],["81554.24000000","0.00000000"],["81962.01000000","0.00000000"],["82371.82000000","0.00000000"],["82783.68000000","0.00000000"],["83197.60000000","0.00023000"],["83613.59000000","0.00000000"],["84031.66000000","0.00000000"],["84451.81000000","0.00000000"],["84874.07000000","0.00000000"]]}}}
{"rx_ns": 21953500400, "frame": {"stream":"btcusdt@depth20","data":{"lastUpdateId":99076503891,"bids":[["78740.00000000","0.55534000"],["78739.99000000","0.00702000"],["78739.02000000","0.00007000"],["78738.96000000","0.00014000"],["78738.95000000","0.01845000"],["78738.76000000","0.00007000"],["78738.01000000","0.00014000"],["78738.00000000","0.02407000"],["78737.70000000","0.00007000"],["78737.69000000","0.03071000"],["78737.65000000","0.00014000"],["78737.64000000","0.05085000"],["78737.54000000","0.00286000"],["78736.84000000","0.00007000"],["78736.43000000","0.03684000"],["78736.21000000","0.00007000"],["78736.20000000","0.02522000"],["78736.08000000","0.00204000"],["78736.00000000","0.02407000"],["78735.75000000","0.00200000"]],"asks":[["78740.01000000","2.44206000"],["78740.02000000","0.00020000"],["78740.03000000","0.00013000"],["78740.22000000","0.00014000"],["78740.23000000","0.01978000"],["78740.25000000","0.00014000"],["78740.26000000","0.77426000"],["78740.89000000","0.00635000"],["78740.90000000","0.00400000"],["78740.94000000","0.00014000"],["78740.95000000","0.04077000"],["78741.27000000","0.31778000"],["78741.28000000","0.61363000"],["78741.49000000","0.03292000"],["78742.72000000","0.00642000"],["78742.73000000","0.00007000"],["78742.74000000","0.00007000"],["78742.75000000","0.03949000"],["78742.87000000","0.07900000"],["78742.89000000","0.00014000"]]}}}
{"rx_ns": 22185499300, "frame": {"stream":"btcusdt@depth","data":{"e":"depthUpdate","E":1787602889014,"s":"BTCUSDT","U":99076499933,"u":99076503891,"b":[["78756.00000000","0.00000000"],["78755.99000000","0.00000000"],["78754.82000000","0.00000000"],["78754.81000000","0.00000000"],["78754.80000000","0.00000000"],["78754.79000000","0.00000000"],["78754.50000000","0.00000000"],["78754.11000000","0.00000000"],["78754.01000000","0.00000000"],["78754.00000000","0.00000000"],["78753.99000000","0.00000000"],["78753.88000000","0.00000000"],["78753.70000000","0.00000000"],["78753.55000000","0.00000000"],["78753.54000000","0.00000000"],["78753.37000000","0.00000000"],["78753.36000000","0.00000000"],["78753.24000000","0.00000000"],["78752.97000000","0.00000000"],["78752.96000000","0.00000000"],["78752.91000000","0.00000000"],["78752.74000000","0.00000000"],["78752.73000000","0.00000000"],["78752.39000000","0.00000000"],["78752.36000000","0.00000000"],["78752.29000000","0.00000000"],["78752.28000000","0.00000000"],["78752.10000000","0.00000000"],["78752.09000000","0.00000000"],["78752.01000000","0.00000000"],["78752.00000000","0.00000000"],["78751.99000000","0.00000000"],["78751.56000000","0.00000000"],["78751.55000000","0.00000000"],["78751.51000000","0.00000000"],["78751.50000000","0.00000000"],["78751.48000000","0.00000000"],["78751.47000000","0.00000000"],["78751.34000000","0.00000000"],["78751.30000000","0.00000000"],["78751.29000000","0.00000000"],["78751.19000000","0.00000000"],["78750.95000000","0.00000000"],["78750.90000000","0.00000000"],["78750.85000000","0.00000000"],["78750.80000000","0.00000000"],["78750.63000000","0.00000000"],["78750.62000000","0.00000000"],["78750.24000000","0.00000000"],["78750.22000000","0.00000000"],["78750.21000000","0.00000000"],["78750.20000000","0.00000000"],["78750.03000000","0.00000000"],["78750.01000000","0.00000000"],["78750.00000000","0.00000000"],["78749.99000000","0.00000000"],["78749.93000000","0.00000000"],["78749.65000000","0.00000000"],["78749.55000000","0.00000000"],["78749.27000000","0.00000000"],["78749.23000000","0.00000000"],["78749.15000000","0.00000000"],["78748.85000000","0.00000000"],["78748.84000000","0.00000000"],["78748.83000000","0.00000000"],["78748.64000000","0.00000000"],["78748.63000000","0.00000000"],["78748.48000000","0.00000000"],["78748.35000000","0.00000000"],["78748.33000000","0.00000000"],["78748.17000000","0.00000000"],["78748.01000000","0.00000000"],["78748.00000000","0.00000000"],["78747.90000000","0.00000000"],["78747.49000000","0.00000000"],["78747.48000000","0.00000000"],["78747.30000000","0.00000000"],["78747.29000000","0.00000000"],["78747.24000000","0.00000000"],["78747.18000000","0.00000000"],["78747.10000000","0.00000000"],["78746.95000000","0.00000000"],["78746.81000000","0.00000000"],["78746.79000000","0.00000000"],["78746.76000000","0.00000000"],["78746.67000000","0.00000000"],["78746.63000000","0.00000000"],["78746.41000000","0.00000000"],["78746.36000000","0.00000000"],["78746.30000000","0.00000000"],["78746.28000000","0.00000000"],["78746.17000000","0.00000000"],["78746.11000000","0.00000000"],["78746.08000000","0.00000000"],["78746.01000000","0.00000000"],["78746.00000000","0.00000000"],["78745.68000000","0.00000000"],["78745.67000000","0.00000000"],["78745.10000000","0.00000000"],["78745.05000000","0.00000000"],["78744.84000000","0.00000000"],["78744.82000000","0.00000000"],["78744.72000000","0.00000000"],["78744.71000000","0.00000000"],["78744.63000000","0.00000000"],["78744.60000000","0.00000000"],["78744.26000000","0.00000000"],["78744.17000000","0.00000000"],["78744.16000000","0.00000000"],["78744.15000000","0.00000000"],["78744.01000000","0.00000000"],["78744.00000000","0.00000000"],["78743.92000000","0.00000000"],["78743.91000000","0.00000000"],["78743.85000000","0.00000000"],["78743.83000000","0.00000000"],["78743.40000000","0.00000000"],["78743.29000000","0.00000000"],["78743.16000000","0.00000000"],["78743.15000000","0.00000000"],["78743.00000000","0.00000000"],["78742.93000000","0.00000000"],["78742.92000000","0.00000000"],["78742.89000000","0.00000000"],["78742.87000000","0.00000000"],["78742.64000000","0.00000000"],["78742.63000000","0.00000000"],["78742.51000000","0.00000000"],["78742.46000000","0.00000000"],["78742.43000000","0.00000000"],["78742.42000000","0.00000000"],["78742.18000000","0.00000000"],["78742.12000000","0.00000000"],["78742.11000000","0.00000000"],["78742.01000000","0.00000000"],["78742.00000000","0.00000000"],["78741.41000000","0.00000000"],["78741.40000000","0.00000000"],["78741.28000000","0.00000000"],["78741.27000000","0.00000000"],["78741.23000000","0.00000000"],["78741.11000000","0.00000000"],["78741.03000000","0.00000000"],["78740.96000000","0.00000000"],["78740.90000000","0.00000000"],["78740.72000000","0.00000000"],["78740.65000000","0.00000000"],["78740.57000000","0.00000000"],["78740.55000000","0.00000000"],["78740.32000000","0.00000000"],["78740.25000000","0.00000000"],["78740.24000000","0.00000000"],["78740.23000000","0.00000000"],["78740.22000000","0.00000000"],["78740.21000000","0.00000000"],["78740.20000000","0.00000000"],["78740.19000000","0.00000000"],["78740.17000000","0.00000000"],["78740.01000000","0.00000000"],["78740.00000000","0.55534000"],["78739.99000000","0.00702000"],["78739.91000000","0.00000000"],["78739.87000000","0.00000000"],["78739.84000000","0.00000000"],["78739.78000000","0.00000000"],["78739.68000000","0.00000000"],["78739.59000000","0.00000000"],["78739.48000000","0.00000000"],["78739.41000000","0.00000000"],["78739.40000000","0.00000000"],["78739.39000000","0.00000000"],["78739.02000000","0.00007000"],["78738.96000000","0.00014000"],["78738.95000000","0.01845000"],["78738.93000000","0.00000000"],["78738.91000000","0.00000000"],["78738.76000000","0.00007000"],["78738.61000000","0.00000000"],["78738.60000000","0.00000000"],["78738.52000000","0.00000000"],["78738.18000000","0.00000000"],["78738.01000000","0.00014000"],["78738.00000000","0.02407000"],["78737.88000000","0.00000000"],["78737.79000000","0.00000000"],["78737.74000000","0.00000000"],["78737.73000000","0.00000000"],["78737.70000000","0.00007000"],["78737.69000000","0.03071000"],["78737.65000000","0.00014000"],["78737.64000000","0.05085000"],["78737.29000000","0.00000000"],["78737.19000000","0.00000000"],["78737.18000000","0.00000000"],["78736.96000000","0.00000000"],["78736.90000000","0.00000000"],["78736.88000000","0.00000000"],["78736.86000000","0.00000000"],["78736.70000000","0.00000000"],["78736.63000000","0.00000000"],["78736.61000000","0.00000000"],["78736.59000000","0.00000000"],["78736.52000000","0.00000000"],["78736.43000000","0.03684000"],["78736.39000000","0.00000000"],["78736.38000000","0.00000000"],["78736.31000000","0.00000000"],["78736.24000000","0.00000000"],["78736.21000000","0.00007000"],["78736.20000000","0.02522000"],["78736.17000000","0.00000000"],["78736.11000000","0.00000000"],["78736.10000000","0.00000000"],["78736.08000000","0.00204000"],["78736.01000000","0.00000000"],["78736.00000000","0.02407000"],["78735.56000000","0.00000000"],["78735.43000000","0.00000000"],["78735.42000000","0.00000000"],["78735.36000000","0.00000000"],["78735.29000000","0.00000000"],["78735.17000000","0.03677000"],["78735.15000000","0.00007000"],["78735.04000000","0.00000000"],["78735.02000000","0.00000000"],["78734.99000000","0.00000000"],["78734.91000000","0.00000000"],["78734.58000000","0.00000000"],["78734.57000000","0.00000000"],["78734.49000000","0.20791000"],["78734.35000000","0.00000000"],["78734.04000000","0.00000000"],["78734.00000000","0.02400000"],["78733.94000000","0.00000000"],["78733.63000000","0.00000000"],["78733.62000000","0.00000000"],["78733.58000000","0.00000000"],["78733.48000000","0.00007000"],["78733.36000000","0.00000000"],["78733.03000000","0.00000000"],["78733.02000000","0.00000000"],["78732.84000000","0.00328000"],["78732.69000000","0.00000000"],["78732.57000000","0.00000000"],["78732.56000000","0.00000000"],["78732.44000000","0.00000000"],["78732.40000000","0.00000000"],["78732.37000000","0.00000000"],["78732.36000000","0.00000000"],["78732.28000000","0.00000000"],["78732.21000000","0.00000000"],["78732.20000000","0.00000000"],["78732.18000000","0.00047000"],["78732.14000000","0.02540000"],["78731.80000000","0.00000000"],["78731.49000000","0.00000000"],["78731.48000000","0.00000000"],["78731.41000000","0.00000000"],["78731.32000000","0.00000000"],["78731.31000000","0.00163000"],["78731.28000000","0.00014000"],["78731.26000000","0.00321000"],["78730.62000000","0.00007000"],["78730.57000000","0.00000000"],["78730.33000000","0.00007000"],["78730.18000000","0.00000000"],["78730.16000000","1.21952000"],["78730.00000000","0.02424000"],["78729.90000000","0.00000000"],["78729.89000000","0.00000000"],["78729.80000000","0.00000000"],["78729.60000000","0.12701000"],["78729.50000000","0.00000000"],["78729.14000000","0.08576000"],["78729.08000000","0.00007000"],["78729.00000000","0.00007000"],["78728.99000000","0.00000000"],["78728.78000000","0.00000000"],["78728.73000000","0.00328000"],["78728.68000000","0.00000000"],["78728.54000000","0.00000000"],["78728.46000000","0.00000000"],["78728.43000000","2.27061000"],["78728.42000000","0.00000000"],["78728.01000000","0.00635000"],["78727.69000000","0.00254000"],["78727.41000000","0.00021000"],["78727.28000000","0.15000000"],["78727.19000000","0.00000000"],["78727.18000000","0.02293000"],["78726.83000000","0.00000000"],["78726.65000000","0.00000000"],["78726.63000000","0.00007000"],["78726.02000000","0.00635000"],["78725.88000000","0.00000000"],["78725.36000000","0.02200000"],["78725.28000000","0.02400000"],["78725.21000000","0.00000000"],["78724.61000000","0.00000000"],["78724.60000000","0.00000000"],["78724.58000000","0.02007000"],["78724.51000000","0.02600000"],["78724.49000000","0.02931000"],["78724.33000000","0.02000000"],["78724.27000000","0.00000000"],["78724.06000000","0.00000000"],["78723.60000000","0.00400000"],["78723.58000000","0.00000000"],["78723.23000000","0.00000000"],["78722.87000000","1.21915000"],["78722.77000000","0.00000000"],["78722.21000000","0.02200000"],["78721.72000000","0.12702000"],["78721.43000000","0.02000000"],["78721.32000000","0.00007000"],["78721.25000000","0.00000000"],["78720.85000000","0.00334000"],["78720.65000000","0.02000000"],["78720.64000000","0.02000000"],["78720.58000000","0.02000000"],["78720.55000000","0.00329000"],["78720.50000000","0.00000000"],["78720.01000000","0.00000000"],["78719.53000000","0.00000000"],["78718.91000000","0.00000000"],["78718.75000000","0.06556000"],["78718.31000000","0.00000000"],["78717.00000000","0.00000000"],["78716.78000000","0.07571000"],["78716.61000000","0.00325000"],["78716.58000000","0.00007000"],["78716.38000000","0.22057000"],["78716.14000000","0.00000000"],["78716.01000000","0.00011000"],["78716.00000000","0.02400000"],["78715.86000000","0.00000000"],["78715.80000000","0.00014000"],["78715.67000000","0.00000000"],["78715.29000000","0.00400000"],["78715.23000000","0.00012000"],["78715.22000000","0.00000000"],["78715.05000000","0.13376000"],["78715.00000000","0.00000000"],["78714.70000000","0.00000000"],["78714.67000000","0.00000000"],["78714.17000000","0.00000000"],["78714.00000000","0.02400000"],["78713.49000000","0.00000000"],["78713.36000000","0.00000000"],["78713.33000000","0.13241000"],["78713.32000000","0.00400000"],["78713.00000000","0.00000000"],["78712.97000000","0.00320000"],["78712.86000000","0.00191000"],["78712.85000000","0.00000000"],["78712.63000000","0.00000000"],["78712.00000000","0.02400000"],["78711.93000000","0.00014000"],["78711.80000000","0.00060000"],["78711.35000000","0.00400000"],["78710.95000000","0.00000000"],["78710.73000000","0.00000000"],["78710.50000000","0.00000000"],["78710.20000000","0.34307000"],["78710.01000000","0.17895000"],["78710.00000000","0.11929000"],["78709.04000000","0.00000000"],["78709.00000000","0.00000000"],["78708.88000000","0.00000000"],["78708.06000000","0.00014000"],["78707.84000000","0.00000000"],["78707.67000000","0.34308000"],["78707.41000000","0.00400000"],["78707.14000000","0.00000000"],["78706.17000000","0.00635000"],["78705.37000000","0.00000000"],["78705.09000000","0.00328000"],["78704.93000000","0.00000000"],["78704.91000000","0.00000000"],["78704.42000000","0.00000000"],["78704.23000000","0.00000000"],["78704.19000000","0.02214000"],["78704.10000000","0.00000000"],["78703.91000000","0.00000000"],["78703.47000000","0.00400000"],["78703.20000000","0.00000000"],["78703.17000000","0.00000000"],["78703.04000000","0.00000000"],["78703.00000000","0.00000000"],["78702.67000000","0.00000000"],["78702.43000000","0.00000000"],["78701.96000000","0.00000000"],["78701.54000000","0.00000000"],["78701.50000000","0.00400000"],["78701.48000000","0.63539000"],["78700.78000000","0.00000000"],["78700.75000000","0.00000000"],["78700.71000000","0.00000000"],["78700.62000000","0.21930000"],["78700.32000000","0.00007000"],["78700.09000000","0.00000000"],["78700.00000000","0.03433000"],["78699.97000000","0.00000000"],["78699.68000000","0.67643000"],["78699.53000000","0.00400000"],["78698.59000000","0.04525000"],["78698.34000000","0.00000000"],["78698.29000000","0.00000000"],["78697.76000000","0.00000000"],["78697.56000000","0.00400000"],["78696.86000000","0.00000000"],["78696.62000000","0.00000000"],["78696.45000000","0.00007000"],["78696.14000000","0.00000000"],["78695.66000000","0.00000000"],["78695.06000000","0.00000000"],["78694.92000000","0.00000000"],["78694.34000000","0.00000000"],["78694.09000000","0.00000000"],["78693.86000000","0.00000000"],["78693.56000000","0.00000000"],["78692.75000000","0.51533000"],["78692.74000000","0.21930000"],["78692.58000000","0.00007000"],["78692.45000000","0.00000000"],["78692.31000000","0.00315000"],["78692.14000000","0.00000000"],["78691.84000000","0.00007000"],["78691.38000000","0.00000000"],["78691.14000000","0.00000000"],["78690.82000000","0.00000000"],["78690.71000000","0.00000000"],["78690.69000000","0.00000000"],["78689.49000000","0.00000000"],["78689.29000000","0.00000000"],["78689.25000000","0.00000000"],["78689.12000000","0.00000000"],["78689.02000000","1.05106000"],["78688.93000000","0.00000000"],["78688.92000000","0.00000000"],["78688.88000000","0.00000000"],["78688.80000000","0.00000000"],["78688.59000000","0.00000000"],["78688.42000000","0.00000000"],["78688.24000000","0.00000000"],["78688.03000000","0.00000000"],["78687.40000000","0.00000000"],["78687.23000000","0.00000000"],["78687.03000000","0.00010000"],["78686.70000000","0.00000000"],["78686.53000000","0.00000000"],["78686.25000000","0.00000000"],["78686.13000000","0.02367000"],["78685.88000000","0.02400000"],["78685.52000000","0.00000000"],["78684.97000000","0.00000000"],["78683.44000000","0.00435000"],["78683.05000000","0.01151000"],["78680.26000000","0.00000000"],["78678.95000000","0.00433000"],["78676.65000000","0.00000000"],["78674.01000000","0.38224000"],["78673.27000000","0.01731000"],["78672.47000000","0.00000000"],["78671.99000000","1.25854000"],["78671.55000000","0.00000000"],["78671.22000000","0.86774000"],["78670.87000000","0.00344000"],["78670.57000000","0.01135000"],["78670.42000000","0.00000000"],["78668.61000000","0.00000000"],["78666.12000000","0.00124000"],["78664.78000000","0.02200000"],["78661.62000000","0.02200000"],["78661.43000000","0.02000000"],["78661.05000000","0.00000000"],["78660.86000000","0.00000000"],["78660.79000000","0.00543000"],["78660.08000000","0.00000000"],["78660.04000000","0.00000000"],["78658.23000000","2.31213000"],["78655.06000000","0.00000000"],["78654.52000000","0.00406000"],["78654.29000000","0.02000000"],["78653.89000000","0.00000000"],["78631.30000000","0.04605000"],["78630.70000000","2.13807000"],["78622.99000000","0.00000000"],["78622.28000000","0.00000000"],["78621.73000000","0.00000000"],["78621.37000000","0.00000000"],["78617.42000000","0.00000000"],["78611.54000000","0.00000000"],["78601.38000000","0.09070000"],["78557.06000000","0.00000000"],["78553.42000000","0.00000000"],["78551.43000000","0.00000000"],["78551.07000000","0.00000000"],["78548.84000000","0.00000000"],["78544.06000000","0.00007000"],["78541.90000000","0.01989000"],["78540.13000000","0.00007000"],["78540.00000000","0.00565000"],["78537.61000000","0.00007000"],["78533.68000000","0.00007000"],["78529.75000000","0.00007000"],["78525.82000000","0.00007000"],["78521.96000000","0.01989000"],["78462.96000000","0.00000000"],["78429.91000000","0.00000000"],["78419.35000000","0.00000000"],["78409.99000000","0.00030000"],["78355.80000000","0.00014000"],["78346.30000000","0.00000000"],["77954.56000000","0.00000000"],["77564.79000000","0.00000000"],["77176.97000000","0.00000000"],["76791.08000000","0.00000000"],["76407.13000000","0.00000000"],["76025.09000000","0.00000000"],["75644.97000000","0.00000000"],["75266.74000000","0.00000000"],["74890.41000000","0.00000000"],["74515.95000000","0.00000000"],["74143.37000000","0.00000000"],["73772.66000000","0.00000000"],["73403.79000000","0.00000000"],["73036.78000000","0.00000000"],["70880.46000000","0.00000000"],["70880.45000000","0.00000000"],["70880.40000000","0.00000000"],["70879.32000000","0.00000000"],["70878.60000000","0.00000000"],["70866.00000000","0.01540000"],["63005.00000000","0.02539000"],["63004.86000000","0.00000000"],["62992.00000000","0.00031000"]],"a":[["78740.01000000","2.44206000"],["78740.02000000","0.00020000"],["78740.03000000","0.00013000"],["78740.18000000","0.00000000"],["78740.21000000","0.00000000"],["78740.22000000","0.00014000"],["78740.23000000","0.01978000"],["78740.25000000","0.00014000"],["78740.26000000","0.77426000"],["78740.27000000","0.00000000"],["78740.28000000","0.00000000"],["78740.89000000","0.00635000"],["78740.90000000","0.00400000"],["78740.94000000","0.00014000"],["78740.95000000","0.04077000"],["78741.25000000","0.00000000"],["78741.26000000","0.00000000"],["78741.27000000","0.31778000"],["78741.28000000","0.61363000"],["78741.29000000","0.00000000"],["78741.30000000","0.00000000"],["78741.41000000","0.00000000"],["78741.49000000","0.03292000"],["78742.01000000","0.00000000"],["78742.13000000","0.00000000"],["78742.17000000","0.00000000"],["78742.43000000","0.00000000"],["78742.46000000","0.00000000"],["78742.47000000","0.00000000"],["78742.64000000","0.00000000"],["78742.72000000","0.00642000"],["78742.73000000","0.00007000"],["78742.74000000","0.00007000"],["78742.75000000","0.03949000"],["78742.86000000","0.00000000"],["78742.87000000","0.07900000"],["78742.89000000","0.00014000"],["78742.90000000","0.00000000"],["78742.94000000","0.00000000"],["78743.00000000","0.00000000"],["78743.01000000","0.02188000"],["78743.02000000","0.00000000"],["78743.14000000","0.00000000"],["78743.15000000","0.05074000"],["78743.39000000","0.00000000"],["78743.40000000","0.07227000"],["78743.41000000","0.00371000"],["78743.42000000","0.00000000"],["78743.43000000","0.00000000"],["78743.92000000","0.00000000"],["78743.94000000","0.00027000"],["78744.00000000","0.00000000"],["78744.01000000","0.03942000"],["78744.15000000","0.00000000"],["78744.72000000","0.00000000"],["78744.83000000","0.00000000"],["78744.84000000","0.00400000"],["78745.06000000","0.00000000"],["78745.11000000","0.00000000"],["78745.34000000","0.00329000"],["78745.68000000","0.00000000"],["78745.76000000","0.00000000"],["78745.96000000","0.00000000"],["78745.97000000","0.00007000"],["78746.00000000","0.00000000"],["78746.01000000","0.00000000"],["78746.02000000","0.00000000"],["78746.09000000","0.00000000"],["78746.18000000","0.00000000"],["78746.46000000","0.25400000"],["78746.68000000","0.00000000"],["78746.76000000","0.00014000"],["78746.77000000","0.08509000"],["78746.81000000","0.00400000"],["78746.92000000","0.00333000"],["78747.11000000","0.00000000"],["78747.25000000","0.38100000"],["78747.28000000","0.00000000"],["78747.29000000","0.02161000"],["78747.30000000","0.08278000"],["78747.49000000","0.00000000"],["78747.90000000","0.00008000"],["78747.91000000","0.00000000"],["78747.95000000","0.02000000"],["78748.00000000","0.07507000"],["78748.01000000","0.08588000"],["78748.02000000","0.00000000"],["78748.03000000","0.00000000"],["78748.16000000","0.00000000"],["78748.18000000","0.00000000"],["78748.49000000","0.00000000"],["78748.64000000","0.00000000"],["78748.65000000","0.00000000"],["78748.75000000","0.02000000"],["78748.78000000","0.00400000"],["78748.84000000","1.21952000"],["78748.85000000","0.14849000"],["78748.86000000","0.00000000"],["78748.87000000","0.00000000"],["78749.16000000","0.00000000"],["78749.24000000","0.00000000"],["78749.35000000","0.00000000"],["78749.36000000","0.00000000"],["78749.51000000","0.00000000"],["78749.86000000","0.00000000"],["78749.95000000","0.00000000"],["78749.98000000","0.00000000"],["78749.99000000","0.00000000"],["78750.00000000","0.00014000"],["78750.01000000","0.26889000"],["78750.02000000","0.00014000"],["78750.03000000","0.00000000"],["78750.05000000","0.12698000"],["78750.17000000","0.00007000"],["78750.20000000","0.00000000"],["78750.21000000","0.36224000"],["78750.22000000","0.00000000"],["78750.23000000","0.00000000"],["78750.24000000","0.00000000"],["78750.63000000","0.00014000"],["78750.64000000","0.02161000"],["78750.65000000","0.00000000"],["78750.66000000","0.00000000"],["78750.75000000","0.00400000"],["78750.94000000","0.38099000"],["78750.97000000","0.00000000"],["78751.11000000","0.02000000"],["78751.28000000","0.00000000"],["78751.29000000","0.00000000"],["78751.30000000","0.00000000"],["78751.47000000","0.00000000"],["78751.48000000","0.00000000"],["78751.49000000","0.00000000"],["78751.56000000","0.00000000"],["78751.69000000","0.00000000"],["78751.90000000","0.00000000"],["78751.91000000","0.02000000"],["78752.00000000","1.90515000"],["78752.01000000","0.00000000"],["78752.02000000","0.00000000"],["78752.03000000","0.00000000"],["78752.17000000","0.00027000"],["78752.37000000","0.00000000"],["78752.66000000","0.00000000"],["78752.68000000","0.02000000"],["78752.69000000","0.03000000"],["78752.72000000","0.00400000"],["78752.73000000","0.00000000"],["78752.74000000","0.00000000"],["78752.75000000","0.04000000"],["78752.96000000","0.00000000"],["78752.97000000","0.00000000"],["78752.98000000","0.00000000"],["78752.99000000","0.00000000"],["78753.22000000","0.00007000"],["78753.32000000","0.00007000"],["78753.40000000","0.00000000"],["78753.43000000","0.00000000"],["78753.44000000","0.00000000"],["78753.49000000","0.00000000"],["78753.62000000","0.01500000"],["78753.71000000","0.00000000"],["78753.95000000","0.00326000"],["78754.00000000","1.23107000"],["78754.01000000","0.00000000"],["78754.02000000","0.00000000"],["78754.03000000","0.00000000"],["78754.12000000","0.00000000"],["78754.29000000","0.00323000"],["78754.50000000","0.00014000"],["78754.51000000","0.00000000"],["78754.69000000","0.00400000"],["78754.72000000","0.02000000"],["78754.79000000","0.00000000"],["78754.80000000","0.00000000"],["78754.81000000","0.03530000"],["78754.82000000","0.00000000"],["78754.83000000","0.00000000"],["78754.84000000","0.00000000"],["78754.85000000","0.06345000"],["78755.31000000","0.04103000"],["78755.51000000","0.04000000"],["78755.60000000","0.00008000"],["78755.62000000","0.04509000"],["78755.76000000","0.00007000"],["78755.86000000","0.00000000"],["78755.98000000","0.00000000"],["78755.99000000","0.00400000"],["78756.00000000","0.00700000"],["78756.01000000","0.13797000"],["78756.02000000","0.00000000"],["78756.03000000","0.00000000"],["78756.06000000","0.00000000"],["78756.07000000","0.00000000"],["78756.08000000","0.00010000"],["78756.12000000","0.00000000"],["78756.24000000","0.00007000"],["78756.47000000","0.00007000"],["78756.48000000","0.00000000"],["78757.00000000","0.00007000"],["78757.13000000","0.00000000"],["78757.15000000","0.00007000"],["78757.33000000","0.00007000"],["78757.64000000","1.90515000"],["78757.65000000","0.00000000"],["78757.70000000","0.00000000"],["78757.89000000","0.00323000"],["78758.00000000","0.00700000"],["78758.18000000","0.00000000"],["78758.20000000","0.00000000"],["78758.37000000","0.36238000"],["78758.38000000","0.40256000"],["78758.39000000","0.00000000"],["78758.45000000","0.00010000"],["78759.03000000","0.06552000"],["78759.15000000","0.00332000"],["78759.19000000","0.00007000"],["78759.30000000","0.34285000"],["78759.44000000","0.00000000"],["78759.45000000","0.00000000"],["78759.46000000","0.00000000"],["78759.47000000","0.00000000"],["78759.62000000","0.00000000"],["78759.65000000","0.00000000"],["78759.89000000","0.00324000"],["78760.00000000","0.10723000"],["78760.12000000","0.00007000"],["78760.14000000","0.00000000"],["78760.62000000","0.02285000"],["78760.63000000","0.34285000"],["78760.64000000","0.00253000"],["78760.66000000","0.00000000"],["78760.71000000","0.00000000"],["78760.72000000","0.00000000"],["78760.73000000","0.00027000"],["78760.79000000","0.00000000"],["78760.80000000","0.12696000"],["78760.97000000","0.00000000"],["78761.00000000","0.07567000"],["78761.01000000","0.00000000"],["78761.15000000","0.00000000"],["78761.31000000","0.00000000"],["78761.52000000","0.00000000"],["78761.62000000","0.00007000"],["78761.89000000","0.21930000"],["78761.94000000","0.00000000"],["78761.97000000","0.00000000"],["78762.00000000","0.02407000"],["78762.04000000","0.00000000"],["78762.27000000","0.00000000"],["78762.56000000","0.09289000"],["78762.60000000","0.00000000"],["78762.69000000","0.02514000"],["78762.77000000","0.00000000"],["78762.78000000","0.00000000"],["78762.79000000","0.00000000"],["78763.31000000","0.00000000"],["78763.83000000","0.00007000"],["78763.84000000","0.00007000"],["78764.04000000","0.00000000"],["78764.27000000","0.00000000"],["78764.28000000","0.00000000"],["78764.74000000","0.00000000"],["78764.78000000","0.00000000"],["78765.31000000","0.00000000"],["78765.63000000","0.00012000"],["78765.83000000","0.00007000"],["78765.92000000","0.00000000"],["78766.26000000","0.00000000"],["78766.28000000","0.00000000"],["78766.32000000","0.00010000"],["78767.10000000","0.00000000"],["78767.35000000","0.00000000"],["78767.42000000","0.02600000"],["78767.44000000","0.00000000"],["78767.71000000","0.00000000"],["78767.77000000","0.00000000"],["78767.85000000","0.38966000"],["78768.63000000","0.00000000"],["78768.78000000","0.00000000"],["78768.87000000","0.00000000"],["78769.07000000","0.00000000"],["78769.37000000","0.00127000"],["78769.46000000","0.00000000"],["78769.66000000","0.00000000"],["78769.68000000","0.00000000"],["78769.77000000","0.00000000"],["78769.81000000","0.00000000"],["78769.87000000","0.00000000"],["78770.06000000","0.00060000"],["78770.57000000","0.00000000"],["78770.80000000","0.00000000"],["78770.87000000","0.43568000"],["78771.00000000","0.00008000"],["78771.05000000","0.00189000"],["78771.84000000","0.00000000"],["78771.88000000","0.00000000"],["78771.90000000","0.00000000"],["78771.93000000","0.00000000"],["78772.22000000","0.00000000"],["78772.38000000","0.02403000"],["78772.58000000","0.00000000"],["78772.88000000","0.00000000"],["78772.99000000","0.00000000"],["78773.40000000","0.00000000"],["78774.12000000","0.00000000"],["78774.19000000","0.00010000"],["78774.33000000","0.00000000"],["78774.42000000","0.02000000"],["78774.45000000","0.00000000"],["78774.55000000","0.00000000"],["78775.40000000","0.00000000"],["78776.36000000","0.00000000"],["78776.40000000","0.00000000"],["78776.55000000","0.00000000"],["78776.67000000","0.00000000"],["78777.07000000","0.00000000"],["78777.83000000","0.00000000"],["78778.33000000","0.00000000"],["78779.33000000","0.67574000"],["78779.34000000","0.00000000"],["78779.66000000","0.00000000"],["78780.00000000","0.09981000"],["78780.30000000","0.00000000"],["78780.39000000","0.00000000"],["78780.53000000","0.00000000"],["78780.95000000","0.00000000"],["78781.40000000","0.00000000"],["78781.42000000","0.02838000"],["78781.45000000","0.00000000"],["78781.59000000","0.00000000"],["78781.81000000","0.00000000"],["78781.90000000","0.00007000"],["78782.27000000","0.00000000"],["78782.49000000","0.00014000"],["78782.52000000","0.02521000"],["78782.60000000","0.49714000"],["78783.10000000","0.00000000"],["78783.49000000","0.00000000"],["78784.24000000","0.00000000"],["78784.93000000","0.01143000"],["78785.25000000","0.00619000"],["78785.30000000","0.00000000"],["78785.33000000","0.00000000"],["78785.46000000","0.00000000"],["78785.63000000","0.00000000"],["78785.80000000","0.00000000"],["78785.87000000","0.00435000"],["78786.21000000","0.00000000"],["78787.27000000","0.00000000"],["78787.77000000","0.00435000"],["78787.80000000","0.00000000"],["78788.07000000","0.00427000"],["78789.00000000","0.00000000"],["78789.33000000","0.00000000"],["78790.00000000","0.02400000"],["78791.28000000","0.86642000"],["78791.77000000","0.00000000"],["78792.71000000","0.87831000"],["78792.86000000","0.00000000"],["78793.00000000","0.00000000"],["78793.20000000","0.00000000"],["78794.00000000","0.02400000"],["78794.79000000","1.90515000"],["78795.00000000","0.00000000"],["78795.77000000","0.35087000"],["78795.98000000","0.00000000"],["78796.00000000","0.02400000"],["78796.85000000","0.00000000"],["78797.21000000","0.00000000"],["78797.49000000","0.00000000"],["78798.19000000","0.00000000"],["78798.59000000","0.00000000"],["78798.83000000","0.00000000"],["78800.08000000","0.00000000"],["78800.31000000","0.00000000"],["78801.52000000","0.00000000"],["78804.15000000","0.00663000"],["78804.44000000","0.00535000"],["78805.23000000","0.00000000"],["78805.43000000","0.00000000"],["78805.58000000","0.00000000"],["78805.59000000","0.02000000"],["78805.67000000","0.00010000"],["78806.10000000","0.90928000"],["78806.58000000","0.00000000"],["78806.88000000","0.00000000"],["78806.90000000","0.00000000"],["78808.49000000","0.00000000"],["78809.53000000","0.01719000"],["78810.11000000","0.00000000"],["78810.58000000","0.00000000"],["78810.63000000","0.00000000"],["78812.28000000","0.00000000"],["78814.86000000","0.00507000"],["78815.09000000","0.00000000"],["78815.16000000","0.00000000"],["78815.55000000","0.00112000"],["78815.83000000","0.00000000"],["78816.87000000","0.00000000"],["78816.88000000","0.00000000"],["78818.32000000","0.00007000"],["78820.50000000","3.31177000"],["78820.66000000","0.00000000"],["78820.80000000","0.00000000"],["78821.53000000","0.00000000"],["78821.88000000","0.00000000"],["78824.94000000","0.00000000"],["78825.21000000","0.00000000"],["78827.24000000","0.00000000"],["78829.89000000","0.09294000"],["78830.26000000","0.00000000"],["78831.84000000","2.13262000"],["78833.11000000","0.04605000"],["78837.42000000","0.00000000"],["78837.55000000","0.02789000"],["78843.59000000","0.00000000"],["78844.61000000","0.00012000"],["78845.99000000","0.00529000"],["78846.34000000","0.00000000"],["78848.54000000","0.00000000"],["78849.84000000","0.00000000"],["78850.75000000","0.00019000"],["78851.47000000","0.00000000"],["78853.04000000","0.00000000"],["78853.63000000","0.00000000"],["78853.66000000","0.00025000"],["78853.73000000","0.00000000"],["78856.23000000","0.00000000"],["78856.30000000","0.00000000"],["78856.31000000","0.00000000"],["78856.85000000","0.00031000"],["78858.51000000","0.00000000"],["78862.27000000","0.00000000"],["78868.41000000","0.00000000"],["78874.51000000","0.00000000"],["78897.10000000","0.00000000"],["78900.31000000","0.00000000"],["78937.74000000","0.00000000"],["78958.32000000","0.00000000"],["78960.32000000","0.00000000"],["78962.88000000","0.00000000"],["78966.81000000","0.00000000"],["78968.00000000","0.00000000"],["78969.76000000","0.00000000"],["78971.21000000","0.00000000"],["78972.01000000","0.00000000"],["78974.57000000","0.00000000"],["78976.05000000","0.00000000"],["78977.15000000","0.00000000"],["78996.11000000","0.00026000"],["79004.04000000","0.00000000"],["79016.18000000","0.00000000"],["79133.72000000","0.00000000"],["79151.20000000","0.00000000"],["79240.00000000","0.00635000"],["79274.64000000","0.00000000"],["79529.38000000","0.00000000"],["79927.03000000","0.00000000"],["80326.67000000","0.00000000"],["80728.30000000","0.00000000"],["81131.94000000","0.00000000"],["81537.60000000","0.00000000"],["81945.29000000","0.00000000"],["82355.01000000","0.00000000"],["82564.99000000","0.00000000"],["82569.00000000","0.00007000"],["82685.41000000","0.00020000"],["82766.79000000","0.00000000"],["83180.62000000","0.00000000"],["83596.53000000","0.00000000"],["84014.51000000","0.00000000"],["84434.58000000","0.00000000"],["84856.75000000","0.00000000"],["85600.00000000","0.29913000"]]}}}
{"rx_ns": 22955122900, "frame": {"stream":"btcusdt@depth20","data":{"lastUpdateId":99076504274,"bids":[["78740.00000000","0.75712000"],["78739.99000000","0.00722000"],["78739.98000000","0.00013000"],["78739.02000000","0.00007000"],["78738.96000000","0.00014000"],["78738.95000000","0.01845000"],["78738.76000000","0.00007000"],["78738.01000000","0.00014000"],["78738.00000000","0.02407000"],["78737.97000000","0.00007000"],["78737.70000000","0.00007000"],["78737.69000000","0.03071000"],["78737.65000000","0.00014000"],["78737.64000000","0.05085000"],["78737.54000000","0.00286000"],["78737.47000000","0.04813000"],["78736.84000000","0.00007000"],["78736.44000000","0.00007000"],["78736.43000000","0.03684000"],["78736.20000000","0.02522000"]],"asks":[["78740.01000000","2.44532000"],["78740.02000000","0.00020000"],["78740.03000000","0.00013000"],["78740.22000000","0.00014000"],["78740.23000000","0.01978000"],["78740.25000000","0.00014000"],["78740.26000000","0.77426000"],["78740.90000000","0.00400000"],["78740.94000000","0.00014000"],["78740.95000000","0.04077000"],["78741.27000000","0.00656000"],["78741.28000000","0.61370000"],["78741.49000000","0.03292000"],["78741.89000000","0.00007000"],["78741.90000000","0.25407000"],["78742.00000000","0.00500000"],["78742.70000000","0.00007000"],["78742.73000000","0.00007000"],["78742.74000000","0.31765000"],["78742.75000000","0.03942000"]]}}}
{"rx_ns": 22955274200, "frame": {"stream":"btcusdt@depth","data":{"e":"depthUpdate","E":1787602890014,"s":"BTCUSDT","U":99076503892,"u":99076504274,"b":[["78740.00000000","0.75712000"],["78739.99000000","0.00722000"],["78739.98000000","0.00013000"],["78739.17000000","0.00000000"],["78739.16000000","0.00000000"],["78738.76000000","0.00007000"],["78737.97000000","0.00007000"],["78737.64000000","0.05085000"],["78737.47000000","0.04813000"],["78736.44000000","0.00007000"],["78736.43000000","0.03684000"],["78736.32000000","0.00000000"],["78736.21000000","0.00000000"],["78734.49000000","0.20791000"],["78732.32000000","0.00000000"],["78731.61000000","0.00000000"],["78731.37000000","0.00000000"],["78731.36000000","0.00000000"],["78731.32000000","0.00000000"],["78731.30000000","0.00000000"],["78730.99000000","0.00000000"],["78730.96000000","0.00000000"],["78730.62000000","0.00007000"],["78730.17000000","0.00407000"],["78729.15000000","0.00635000"],["78728.01000000","0.00000000"],["78726.65000000","0.00635000"],["78726.64000000","0.00000000"],["78726.02000000","0.00000000"],["78725.38000000","0.00406000"],["78724.72000000","0.00007000"],["78724.59000000","0.00000000"],["78724.42000000","0.02000000"],["78721.27000000","0.02200000"],["78716.97000000","0.34304000"],["78716.58000000","0.00000000"],["78716.33000000","0.00007000"],["78714.97000000","0.12704000"],["78712.85000000","0.00000000"],["78711.09000000","0.22560000"],["78711.01000000","0.00000000"],["78710.01000000","0.00000000"],["78709.38000000","0.00400000"],["78709.24000000","0.49753000"],["78703.88000000","0.34310000"],["78700.91000000","0.02470000"],["78700.30000000","0.00000000"],["78699.10000000","0.09394000"],["78698.26000000","0.63541000"],["78697.56000000","0.00000000"],["78692.58000000","0.00000000"],["78692.31000000","0.00000000"],["78688.02000000","0.00000000"],["78687.96000000","0.00000000"],["78686.13000000","0.00000000"],["78686.07000000","0.00000000"],["78686.01000000","0.00406000"],["78680.80000000","0.02600000"],["78678.01000000","0.00317000"],["78674.38000000","0.02000000"],["78670.87000000","0.00029000"],["78670.85000000","0.02541000"],["78666.17000000","0.02400000"],["78664.78000000","0.00000000"],["78661.62000000","0.00000000"],["78661.43000000","0.00000000"],["78658.28000000","0.00000000"],["78656.01000000","0.00315000"],["78655.12000000","0.00000000"],["78654.29000000","0.00000000"],["78649.35000000","0.00000000"],["78634.74000000","0.00316000"],["78614.46000000","0.00000000"],["78610.86000000","0.04472000"],["78601.38000000","0.00000000"],["78598.24000000","0.00127000"],["78593.47000000","0.00000000"],["78577.60000000","0.00127000"],["78565.62000000","0.00000000"],["78540.77000000","0.00778000"],["78536.43000000","0.00406000"],["78521.96000000","0.00000000"],["78509.99000000","0.01989000"],["78346.30000000","0.00000000"],["78047.27000000","0.00000000"],["77962.48000000","0.00704000"],["77954.56000000","0.00000000"],["77564.79000000","0.00000000"],["77176.97000000","0.00000000"],["77155.88000000","0.00000000"],["76791.08000000","0.00000000"],["76407.13000000","0.00000000"],["76025.09000000","0.00000000"],["75644.97000000","0.00000000"],["75266.74000000","0.00000000"],["74890.41000000","0.00000000"],["74515.95000000","0.00000000"],["74143.37000000","0.00000000"],["73772.66000000","0.00000000"],["73403.79000000","0.00000000"],["73036.78000000","0.00000000"],["70866.00000000","0.01636000"],["62992.00000000","0.00031000"]],"a":[["78740.01000000","2.44532000"],["78740.26000000","0.77426000"],["78740.88000000","0.00000000"],["78740.89000000","0.00000000"],["78740.95000000","0.04077000"],["78741.25000000","0.00000000"],["78741.26000000","0.00000000"],["78741.27000000","0.00656000"],["78741.28000000","0.61370000"],["78741.49000000","0.03292000"],["78741.83000000","0.00000000"],["78741.89000000","0.00007000"],["78741.90000000","0.25407000"],["78742.00000000","0.00500000"],["78742.70000000","0.00007000"],["78742.71000000","0.00000000"],["78742.72000000","0.00000000"],["78742.73000000","0.00007000"],["78742.74000000","0.31765000"],["78742.75000000","0.03942000"],["78742.87000000","0.00400000"],["78743.40000000","0.07220000"],["78743.93000000","0.00635000"],["78744.00000000","0.01200000"],["78745.96000000","0.00400000"],["78746.00000000","0.01200000"],["78746.45000000","1.90515000"],["78746.46000000","0.00000000"],["78748.00000000","0.08707000"],["78748.01000000","0.08581000"],["78748.48000000","0.02007000"],["78748.85000000","0.14842000"],["78749.14000000","0.00007000"],["78750.00000000","0.01207000"],["78750.01000000","0.26882000"],["78750.02000000","0.00000000"],["78751.18000000","0.00007000"],["78751.61000000","0.02000000"],["78752.00000000","1.91215000"],["78752.07000000","0.02600000"],["78752.36000000","0.00007000"],["78754.00000000","1.23807000"],["78754.33000000","0.12697000"],["78754.81000000","0.02161000"],["78754.85000000","0.00000000"],["78755.62000000","0.00000000"],["78756.00000000","0.01400000"],["78756.01000000","0.09744000"],["78756.08000000","0.00000000"],["78758.00000000","0.01400000"],["78758.09000000","0.04545000"],["78760.00000000","0.11423000"],["78761.98000000","0.00318000"],["78762.56000000","0.00000000"],["78763.59000000","0.00007000"],["78763.84000000","0.00000000"],["78767.42000000","0.00000000"],["78767.88000000","0.00400000"],["78770.74000000","0.09581000"],["78775.64000000","0.00000000"],["78789.30000000","0.00316000"],["78791.48000000","0.02600000"],["78794.12000000","0.02000000"],["78800.36000000","0.00000000"],["78804.21000000","0.00406000"],["78805.22000000","0.00000000"],["78805.59000000","0.00000000"],["78805.66000000","0.02000000"],["78811.99000000","0.00314000"],["78821.93000000","0.00000000"],["78825.97000000","0.00000000"],["78826.78000000","0.00000000"],["78826.79000000","0.00000000"],["78827.60000000","0.00000000"],["78833.51000000","0.00000000"],["78836.66000000","0.00000000"],["78837.17000000","0.00000000"],["78837.55000000","0.00000000"],["78847.06000000","0.02789000"],["78867.99000000","0.00127000"],["78887.29000000","0.00000000"],["78889.97000000","0.00127000"],["78905.53000000","0.00000000"],["78953.86000000","0.00406000"],["79121.54000000","0.01270000"],["79133.72000000","0.00000000"],["79529.38000000","0.00000000"],["79927.03000000","0.00000000"],["80326.67000000","0.00000000"],["80728.30000000","0.00000000"],["81131.94000000","0.00000000"],["81537.60000000","0.00000000"],["81945.29000000","0.00000000"],["82355.01000000","0.00000000"],["82766.79000000","0.00000000"],["83180.62000000","0.00000000"],["83596.53000000","0.00000000"],["84014.51000000","0.00000000"],["84434.58000000","0.00000000"],["84856.75000000","0.00000000"]]}}}
