{"rx_ns": 13985794688200, "frame": {"stream":"btcusdt@depth20","data":{"lastUpdateId":99118686776,"bids":[["79864.33000000","0.09731000"],["79864.32000000","0.00090000"],["79864.31000000","0.00013000"],["79863.70000000","0.00007000"],["79863.05000000","0.00007000"],["79862.53000000","0.00007000"],["79862.52000000","0.02494000"],["79862.45000000","0.00856000"],["79862.10000000","0.00007000"],["79861.77000000","0.00014000"],["79861.69000000","0.00007000"],["79861.68000000","0.05260000"],["79861.66000000","0.00007000"],["79861.65000000","0.00014000"],["79861.32000000","0.00007000"],["79861.29000000","0.00007000"],["79861.18000000","0.00007000"],["79861.17000000","0.01431000"],["79861.04000000","0.00007000"],["79860.50000000","0.00007000"]],"asks":[["79864.34000000","3.60135000"],["79864.35000000","0.01265000"],["79864.36000000","0.00013000"],["79864.54000000","0.29968000"],["79864.55000000","0.07885000"],["79864.59000000","0.00007000"],["79864.80000000","0.78014000"],["79865.19000000","0.00014000"],["79865.62000000","0.01761000"],["79865.99000000","0.00007000"],["79866.00000000","0.00400000"],["79866.09000000","0.00007000"],["79866.15000000","0.00951000"],["79866.41000000","0.03238000"],["79866.47000000","0.04014000"],["79866.71000000","0.00007000"],["79866.78000000","0.00007000"],["79866.81000000","0.00400000"],["79866.90000000","0.02079000"],["79867.27000000","0.04779000"]]}}}
{"rx_ns": 13985794875800, "frame": {"stream":"btcusdt@depth@100ms","data":{"e":"depthUpdate","E":1787650981014,"s":"BTCUSDT","U":99118686749,"u":99118686776,"b":[["79864.33000000","0.09731000"],["79853.58000000","0.00014000"],["79852.20000000","0.00000000"],["79852.01000000","0.00010000"],["79849.40000000","0.00000000"],["79849.35000000","0.00400000"],["79849.12000000","0.00007000"],["79847.32000000","0.00250000"],["79846.49000000","0.00000000"],["79845.67000000","0.00000000"],["79845.37000000","0.01200000"],["79845.36000000","0.00400000"],["79836.35000000","0.00000000"],["79833.81000000","0.42962000"],["71877.90000000","0.00416000"],["71877.89000000","0.00008000"],["71877.00000000","0.00010000"],["63891.47000000","0.00031000"]],"a":[["79864.34000000","3.60135000"],["79875.99000000","0.00626000"],["79876.00000000","0.27846000"],["79877.55000000","0.00000000"],["79878.06000000","0.00000000"],["79879.37000000","0.62629000"],["79880.79000000","0.00000000"],["79881.08000000","0.00007000"]]}}}
{"rx_ns": 13985902263200, "frame": {"stream":"btcusdt@depth@100ms","data":{"e":"depthUpdate","E":1787650981114,"s":"BTCUSDT","U":99118686777,"u":99118688288,"b":[["79864.33000000","0.00000000"],["79864.32000000","0.00000000"],["79864.31000000","0.00000000"],["79863.70000000","0.00000000"],["79863.05000000","0.00000000"],["79862.53000000","0.00000000"],["79862.52000000","0.00000000"],["79862.51000000","0.00000000"],["79862.45000000","0.00000000"],["79862.44000000","0.00000000"],["79862.10000000","0.00000000"],["79861.77000000","0.00000000"],["79861.69000000","0.00000000"],["79861.68000000","0.00000000"],["79861.67000000","0.00000000"],["79861.66000000","0.00000000"],["79861.65000000","0.00000000"],["79861.32000000","0.00000000"],["79861.29000000","0.00000000"],["79861.18000000","0.00000000"],["79861.17000000","0.00000000"],["79861.04000000","0.00000000"],["79860.50000000","0.00000000"],["79860.49000000","0.00000000"],["79860.43000000","0.00000000"],["79860.00000000","0.00000000"],["79859.99000000","0.00000000"],["79859.90000000","0.00000000"],["79859.89000000","0.00000000"],["79859.78000000","0.00000000"],["79859.38000000","0.00000000"],["79859.37000000","0.00000000"],["79859.21000000","0.00000000"],["79859.02000000","0.00000000"],["79859.01000000","0.00837000"],["79859.00000000","0.00063000"],["79858.76000000","0.00000000"],["79858.75000000","0.00014000"],["79858.62000000","0.00000000"],["79858.61000000","0.00028000"],["79858.41000000","0.00000000"],["79858.35000000","0.00000000"],["79858.14000000","0.00000000"],["79858.13000000","0.00014000"],["79858.00000000","0.02428000"],["79857.58000000","0.00000000"],["79857.52000000","0.00000000"],["79857.51000000","0.00014000"],["79856.97000000","0.00000000"],["79856.96000000","0.00021000"],["79856.90000000","0.00000000"],["79856.89000000","0.00007000"],["79856.35000000","0.00007000"],["79856.34000000","0.05805000"],["79856.29000000","0.00000000"],["79856.28000000","0.00101000"],["79856.19000000","0.00000000"],["79856.01000000","0.00007000"],["79856.00000000","0.02414000"],["79855.70000000","0.00000000"],["79855.67000000","0.00000000"],["79855.66000000","0.00007000"],["79855.57000000","0.00007000"],["79855.56000000","0.05008000"],["79855.26000000","0.00000000"],["79855.17000000","0.00000000"],["79855.16000000","0.00007000"],["79855.08000000","0.00000000"],["79855.07000000","0.00007000"],["79854.97000000","0.00007000"],["79854.72000000","0.00000000"],["79854.69000000","0.00000000"],["79854.68000000","0.00000000"],["79854.67000000","0.00007000"],["79854.60000000","0.00000000"],["79854.25000000","0.00007000"],["79854.16000000","0.00000000"],["79854.15000000","0.00007000"],["79854.14000000","0.31315000"],["79854.01000000","0.00007000"],["79853.69000000","0.00000000"],["79853.60000000","0.00000000"],["79853.58000000","0.00007000"],["79853.39000000","0.00000000"],["79853.15000000","0.00000000"],["79853.03000000","0.00013000"],["79852.65000000","0.00000000"],["79852.62000000","0.00000000"],["79852.61000000","0.00000000"],["79852.36000000","0.02000000"],["79852.01000000","0.00007000"],["79851.77000000","0.00000000"],["79851.72000000","0.00007000"],["79851.58000000","0.00000000"],["79851.38000000","0.00008000"],["79851.05000000","0.00000000"],["79851.04000000","0.00000000"],["79850.78000000","0.12523000"],["79850.25000000","0.00000000"],["79850.20000000","0.00000000"],["79849.94000000","0.00000000"],["79849.71000000","0.00007000"],["79849.53000000","0.00000000"],["79849.42000000","0.00000000"],["79849.35000000","0.00000000"],["79849.18000000","0.00000000"],["79849.12000000","0.00007000"],["79849.10000000","0.00000000"],["79849.09000000","0.06138000"],["79849.08000000","0.00000000"],["79849.03000000","0.00000000"],["79848.93000000","0.00000000"],["79848.62000000","0.00000000"],["79848.61000000","0.00000000"],["79848.60000000","0.00000000"],["79848.54000000","0.00000000"],["79848.47000000","0.05695000"],["79848.36000000","0.00000000"],["79848.17000000","0.00000000"],["79848.11000000","0.00000000"],["79847.86000000","0.00000000"],["79847.85000000","0.06138000"],["79847.83000000","0.00000000"],["79847.82000000","0.00000000"],["79847.72000000","0.00000000"],["79847.62000000","0.00000000"],["79847.61000000","0.00000000"],["79847.60000000","0.00000000"],["79847.58000000","0.06138000"],["79847.57000000","0.39880000"],["79847.32000000","0.00000000"],["79847.27000000","0.00000000"],["79847.10000000","0.00000000"],["79847.05000000","0.00000000"],["79846.88000000","0.00000000"],["79846.61000000","0.06138000"],["79846.29000000","0.00000000"],["79846.19000000","0.00000000"],["79846.16000000","0.00000000"],["79846.13000000","0.00000000"],["79846.01000000","0.06150000"],["79845.86000000","0.00007000"],["79845.84000000","0.00007000"],["79845.67000000","0.00000000"],["79845.63000000","0.00000000"],["79845.37000000","0.06138000"],["79845.36000000","1.04939000"],["79845.35000000","0.00400000"],["79845.34000000","0.00000000"],["79845.15000000","0.00007000"],["79845.12000000","0.00704000"],["79844.91000000","0.00048000"],["79844.53000000","0.08566000"],["79844.48000000","0.07000000"],["79844.47000000","0.00000000"],["79844.42000000","0.00000000"],["79844.41000000","0.00000000"],["79844.36000000","0.00000000"],["79844.13000000","0.00000000"],["79843.40000000","0.00008000"],["79843.29000000","0.00000000"],["79843.22000000","0.00000000"],["79842.89000000","0.06138000"],["79842.85000000","0.00000000"],["79842.80000000","0.18374000"],["79842.79000000","0.12524000"],["79842.52000000","0.00000000"],["79842.51000000","0.00000000"],["79842.49000000","0.00000000"],["79841.65000000","0.06138000"],["79841.51000000","0.00000000"],["79841.12000000","0.00707000"],["79841.03000000","0.06138000"],["79841.02000000","0.00626000"],["79840.58000000","0.08000000"],["79840.47000000","0.00250000"],["79840.41000000","0.06138000"],["79840.37000000","0.00568000"],["79840.04000000","0.00400000"],["79840.03000000","0.00000000"],["79840.01000000","0.06138000"],["79840.00000000","0.22657000"],["79839.86000000","1.87677000"],["79839.85000000","0.54607000"],["79839.41000000","0.00008000"],["79838.88000000","0.02254000"],["79838.29000000","0.00000000"],["79838.01000000","0.00626000"],["79837.12000000","0.00709000"],["79836.58000000","0.00000000"],["79836.38000000","0.00000000"],["79836.36000000","0.00000000"],["79835.41000000","0.00008000"],["79834.30000000","0.00000000"],["79833.81000000","0.00000000"],["79833.12000000","0.00707000"],["79832.39000000","0.00626000"],["79832.38000000","0.00568000"],["79832.25000000","0.28595000"],["79832.24000000","0.00000000"],["79832.00000000","0.02807000"],["79831.42000000","0.00008000"],["79830.37000000","0.42964000"],["79830.32000000","0.04405000"],["79830.00000000","0.07187000"],["79829.98000000","0.00000000"],["79829.67000000","0.00000000"],["79829.30000000","0.00000000"],["79829.18000000","0.00000000"],["79828.39000000","0.00000000"],["79827.70000000","0.00000000"],["79827.53000000","0.00000000"],["79827.43000000","0.00008000"],["79826.86000000","0.09413000"],["79825.35000000","0.62630000"],["79824.40000000","0.00000000"],["79824.00000000","0.02807000"],["79823.43000000","0.00008000"],["79822.62000000","0.00014000"],["79822.00000000","0.02400000"],["79821.18000000","0.33834000"],["79821.00000000","0.00000000"],["79820.00000000","0.12048000"],["79819.44000000","0.00008000"],["79819.00000000","0.01000000"],["79813.51000000","0.00400000"],["79811.61000000","0.00000000"],["79811.01000000","0.00007000"],["79809.79000000","0.00000000"],["79807.23000000","0.00000000"],["79804.07000000","0.00000000"],["79803.52000000","1.36940000"],["79800.56000000","0.00000000"],["79799.85000000","0.00007000"],["79798.23000000","0.00000000"],["79797.29000000","0.02827000"],["79796.80000000","0.00000000"],["79795.08000000","0.00000000"],["79794.60000000","0.00000000"],["79792.25000000","0.00310000"],["79792.24000000","0.00000000"],["79791.19000000","0.00312000"],["79790.01000000","0.00000000"],["79784.49000000","0.00000000"],["79784.22000000","0.00000000"],["79783.79000000","0.00000000"],["79783.74000000","0.02087000"],["79782.53000000","0.00000000"],["79781.81000000","0.12094000"],["79772.89000000","0.00000000"],["79769.87000000","1.87677000"],["79768.43000000","3.40135000"],["79760.28000000","1.87677000"],["79743.29000000","0.14233000"],["79733.51000000","0.20250000"],["79719.13000000","0.10302000"],["79716.79000000","0.00000000"],["79714.30000000","0.00000000"],["79713.68000000","0.00000000"],["79712.01000000","0.00000000"],["79711.27000000","0.00125000"],["79710.01000000","0.00000000"],["79696.98000000","1.50049000"],["79530.12000000","0.00250000"],["78666.36000000","0.00000000"],["71877.90000000","0.00000000"],["71877.00000000","0.00000000"],["71873.11000000","0.00016000"]],"a":[["79859.02000000","6.57078000"],["79859.03000000","0.00027000"],["79859.04000000","0.00013000"],["79859.22000000","0.00000000"],["79859.36000000","0.00000000"],["79859.37000000","0.00000000"],["79859.38000000","3.85991000"],["79859.39000000","0.00000000"],["79859.90000000","0.00021000"],["79859.91000000","0.00000000"],["79860.00000000","0.00021000"],["79860.20000000","0.00400000"],["79860.44000000","0.00000000"],["79860.50000000","0.19652000"],["79860.51000000","0.00000000"],["79860.62000000","0.00000000"],["79860.72000000","0.00008000"],["79861.05000000","0.00021000"],["79861.17000000","0.07500000"],["79861.18000000","0.00000000"],["79861.19000000","0.00000000"],["79861.24000000","0.00000000"],["79861.30000000","0.00000000"],["79861.32000000","0.00014000"],["79861.33000000","0.00000000"],["79861.65000000","0.42350000"],["79861.66000000","0.33305000"],["79861.67000000","0.50278000"],["79861.68000000","0.26063000"],["79861.69000000","1.45635000"],["79861.70000000","0.00000000"],["79861.71000000","0.00000000"],["79861.78000000","0.00000000"],["79861.89000000","0.00156000"],["79861.93000000","0.04789000"],["79862.11000000","0.00000000"],["79862.31000000","0.00000000"],["79862.44000000","0.00000000"],["79862.45000000","0.00000000"],["79862.46000000","0.70550000"],["79862.47000000","0.00000000"],["79862.48000000","0.00000000"],["79862.52000000","0.00000000"],["79862.53000000","0.55206000"],["79862.54000000","0.00000000"],["79863.06000000","0.00000000"],["79864.00000000","0.00007000"],["79864.26000000","0.00400000"],["79864.32000000","0.90194000"],["79864.33000000","1.15398000"],["79864.34000000","0.87387000"],["79864.35000000","0.01217000"],["79864.36000000","0.00000000"],["79864.53000000","0.00000000"],["79864.54000000","0.00000000"],["79864.55000000","0.00708000"],["79864.60000000","0.00000000"],["79864.80000000","0.78000000"],["79865.00000000","0.00013000"],["79865.37000000","0.00000000"],["79865.62000000","0.00014000"],["79866.12000000","0.00026000"],["79866.14000000","0.00000000"],["79866.15000000","0.00937000"],["79866.41000000","0.03224000"],["79866.47000000","0.00000000"],["79866.81000000","0.00000000"],["79866.90000000","0.00007000"],["79867.01000000","0.00008000"],["79867.27000000","0.00007000"],["79867.67000000","0.00000000"],["79868.00000000","0.02814000"],["79868.14000000","0.72143000"],["79868.18000000","0.00000000"],["79868.42000000","0.00000000"],["79868.97000000","1.87677000"],["79869.20000000","0.08576000"],["79869.68000000","0.00000000"],["79870.00000000","0.12191000"],["79870.24000000","0.00000000"],["79870.32000000","0.00000000"],["79871.16000000","0.00000000"],["79871.47000000","0.00007000"],["79871.65000000","0.00626000"],["79871.66000000","0.00000000"],["79871.67000000","0.00000000"],["79871.76000000","0.35405000"],["79871.77000000","0.00000000"],["79871.89000000","0.00000000"],["79872.33000000","0.00000000"],["79872.91000000","0.33812000"],["79873.69000000","0.00000000"],["79874.25000000","0.62630000"],["79874.99000000","0.00008000"],["79875.71000000","0.09528000"],["79875.99000000","0.00000000"],["79876.00000000","0.02400000"],["79877.70000000","0.10374000"],["79878.98000000","0.00008000"],["79879.37000000","0.00000000"],["79880.31000000","0.00000000"],["79881.28000000","0.02480000"],["79881.56000000","0.03000000"],["79882.98000000","0.00008000"],["79883.55000000","0.00000000"],["79884.31000000","0.00000000"],["79884.63000000","0.00250000"],["79885.84000000","0.62605000"],["79886.12000000","0.00012000"],["79886.97000000","0.62612000"],["79887.48000000","0.00007000"],["79888.30000000","0.00000000"],["79889.09000000","0.00000000"],["79889.43000000","0.00400000"],["79889.48000000","0.00400000"],["79890.96000000","0.00008000"],["79891.32000000","0.00000000"],["79891.63000000","0.00007000"],["79892.29000000","0.00000000"],["79892.31000000","0.00000000"],["79892.68000000","0.00000000"],["79893.00000000","0.00008000"],["79894.40000000","1.23945000"],["79894.96000000","0.00008000"],["79895.04000000","0.00000000"],["79896.29000000","0.00000000"],["79896.99000000","0.92914000"],["79897.92000000","0.00000000"],["79898.95000000","0.00008000"],["79900.02000000","0.00000000"],["79900.28000000","0.00007000"],["79901.17000000","0.25000000"],["79902.27000000","0.00000000"],["79903.00000000","0.01000000"],["79903.89000000","0.00000000"],["79904.27000000","0.00000000"],["79905.00000000","0.00000000"],["79906.49000000","0.00000000"],["79907.40000000","0.00014000"],["79916.15000000","0.00000000"],["79919.70000000","0.00000000"],["79920.71000000","0.82264000"],["79924.06000000","0.94003000"],["79924.72000000","0.00190000"],["79925.76000000","0.00312000"],["79926.34000000","0.00000000"],["79926.86000000","0.00000000"],["79927.04000000","0.00000000"],["79929.43000000","0.00000000"],["79930.31000000","0.00312000"],["79931.59000000","0.00000000"],["79931.61000000","0.00000000"],["79931.99000000","0.00000000"],["79937.02000000","0.00000000"],["79937.03000000","0.00000000"],["79941.37000000","0.00000000"],["79959.19000000","0.00000000"],["79981.62000000","0.00000000"],["80000.40000000","1.50049000"],["80009.99000000","0.00125000"],["80011.58000000","0.00000000"],["80017.16000000","0.00000000"],["80096.00000000","0.00000000"],["80404.43000000","0.00250000"],["80648.05000000","0.00400000"],["80650.22000000","0.00000000"]]}}}
{"rx_ns": 13986028486400, "frame": {"stream":"btcusdt@depth@100ms","data":{"e":"depthUpdate","E":1787650981214,"s":"BTCUSDT","U":99118688289,"u":99118690314,"b":[["79859.01000000","0.00000000"],["79859.00000000","0.00000000"],["79858.75000000","0.00000000"],["79858.66000000","0.00000000"],["79858.61000000","0.00000000"],["79858.16000000","0.00000000"],["79858.15000000","0.00000000"],["79858.13000000","0.00000000"],["79858.04000000","0.00000000"],["79858.01000000","0.00000000"],["79858.00000000","0.00000000"],["79857.77000000","0.00000000"],["79857.51000000","0.00000000"],["79857.45000000","0.00000000"],["79857.31000000","0.00000000"],["79857.17000000","0.00000000"],["79856.96000000","0.00000000"],["79856.89000000","0.00000000"],["79856.35000000","0.00000000"],["79856.34000000","0.00000000"],["79856.28000000","0.00000000"],["79856.01000000","0.00000000"],["79856.00000000","0.00000000"],["79855.99000000","0.00000000"],["79855.90000000","0.00000000"],["79855.89000000","0.00000000"],["79855.66000000","0.00000000"],["79855.65000000","0.00000000"],["79855.57000000","0.00000000"],["79855.56000000","0.00000000"],["79855.31000000","0.00000000"],["79855.16000000","0.00000000"],["79855.07000000","0.00000000"],["79854.97000000","0.00000000"],["79854.67000000","0.00000000"],["79854.62000000","0.00000000"],["79854.61000000","0.00000000"],["79854.34000000","0.00000000"],["79854.28000000","0.00000000"],["79854.26000000","0.00000000"],["79854.25000000","0.00000000"],["79854.15000000","0.00000000"],["79854.14000000","0.00000000"],["79854.03000000","0.00000000"],["79854.01000000","0.00000000"],["79854.00000000","0.00000000"],["79853.64000000","0.00000000"],["79853.58000000","0.00000000"],["79853.34000000","0.00000000"],["79853.33000000","0.00000000"],["79853.30000000","0.00000000"],["79853.03000000","0.00000000"],["79853.01000000","0.00000000"],["79852.82000000","0.00000000"],["79852.36000000","0.00000000"],["79852.19000000","0.00000000"],["79852.01000000","0.00000000"],["79852.00000000","0.03266000"],["79851.99000000","0.00063000"],["79851.95000000","0.00000000"],["79851.53000000","0.00000000"],["79851.38000000","0.00000000"],["79850.79000000","0.00000000"],["79850.78000000","0.00007000"],["79850.34000000","0.00000000"],["79850.33000000","0.00007000"],["79850.18000000","0.00000000"],["79850.16000000","0.00000000"],["79850.02000000","0.00000000"],["79850.01000000","0.00007000"],["79850.00000000","0.03425000"],["79849.78000000","0.00000000"],["79849.71000000","0.00007000"],["79849.68000000","0.00000000"],["79849.67000000","0.00000000"],["79849.52000000","0.00000000"],["79849.30000000","0.00007000"],["79849.29000000","0.05141000"],["79849.28000000","0.00000000"],["79849.21000000","0.00000000"],["79849.18000000","0.00000000"],["79849.12000000","0.00000000"],["79849.09000000","0.00000000"],["79848.47000000","0.00007000"],["79848.35000000","0.00575000"],["79848.34000000","0.00000000"],["79848.01000000","0.00007000"],["79847.85000000","0.00000000"],["79847.77000000","0.00007000"],["79847.64000000","0.00000000"],["79847.61000000","0.00000000"],["79847.58000000","0.00000000"],["79847.57000000","0.00000000"],["79846.76000000","0.00007000"],["79846.75000000","0.31324000"],["79846.73000000","0.00000000"],["79846.68000000","0.00000000"],["79846.61000000","0.00000000"],["79846.58000000","0.00000000"],["79846.42000000","0.00000000"],["79846.27000000","0.00000000"],["79846.05000000","0.00007000"],["79846.01000000","0.00000000"],["79845.86000000","0.00000000"],["79845.85000000","0.00000000"],["79845.84000000","0.00007000"],["79845.37000000","0.00000000"],["79845.36000000","0.00000000"],["79845.35000000","0.00000000"],["79845.12000000","0.00007000"],["79844.58000000","0.00000000"],["79844.54000000","0.00007000"],["79844.53000000","0.00014000"],["79844.48000000","0.00000000"],["79844.15000000","0.02000000"],["79844.02000000","0.00008000"],["79844.00000000","0.02407000"],["79843.99000000","0.00000000"],["79843.89000000","0.00000000"],["79843.40000000","0.00000000"],["79843.26000000","0.00000000"],["79843.14000000","0.00000000"],["79843.04000000","0.00069000"],["79842.89000000","0.00000000"],["79842.80000000","0.00000000"],["79842.79000000","0.00007000"],["79841.97000000","0.00007000"],["79841.96000000","0.00007000"],["79841.74000000","0.00000000"],["79841.67000000","0.00000000"],["79841.65000000","0.00000000"],["79841.48000000","0.00026000"],["79841.24000000","0.00000000"],["79841.13000000","0.00000000"],["79841.12000000","0.00000000"],["79841.03000000","0.00000000"],["79841.02000000","0.00000000"],["79840.59000000","0.00000000"],["79840.58000000","0.00000000"],["79840.52000000","0.00000000"],["79840.47000000","0.00000000"],["79840.41000000","0.00000000"],["79840.31000000","0.00048000"],["79840.14000000","0.00187000"],["79840.04000000","0.00000000"],["79840.02000000","0.00000000"],["79840.01000000","0.00000000"],["79840.00000000","0.02407000"],["79839.87000000","0.00000000"],["79839.86000000","0.00000000"],["79839.85000000","0.00000000"],["79839.84000000","0.00000000"],["79839.64000000","0.00250000"],["79839.60000000","0.06128000"],["79839.41000000","0.00000000"],["79838.98000000","0.06139000"],["79838.89000000","0.00000000"],["79838.88000000","0.02254000"],["79838.77000000","0.00007000"],["79838.70000000","0.00008000"],["79838.36000000","0.06139000"],["79838.10000000","0.00007000"],["79838.01000000","0.00000000"],["79837.74000000","0.06139000"],["79837.72000000","0.00000000"],["79837.28000000","0.02000000"],["79837.22000000","0.08566000"],["79837.13000000","0.06139000"],["79836.88000000","0.05000000"],["79836.79000000","0.00007000"],["79836.69000000","0.06139000"],["79836.68000000","0.00000000"],["79836.58000000","0.00034000"],["79836.34000000","0.00000000"],["79836.08000000","0.00000000"],["79836.04000000","0.00007000"],["79835.88000000","0.06139000"],["79835.62000000","0.00000000"],["79835.46000000","0.00000000"],["79835.41000000","0.00000000"],["79835.34000000","0.00000000"],["79835.26000000","0.06139000"],["79834.71000000","0.06147000"],["79834.70000000","0.02480000"],["79834.31000000","0.42889000"],["79834.30000000","1.05565000"],["79834.29000000","0.00000000"],["79834.28000000","0.00000000"],["79833.62000000","0.00000000"],["79833.51000000","0.00626000"],["79833.28000000","0.08000000"],["79833.03000000","0.00000000"],["79832.80000000","0.09533000"],["79832.45000000","0.00160000"],["79832.39000000","0.00000000"],["79832.27000000","0.00250000"],["79832.25000000","0.00000000"],["79831.66000000","0.00060000"],["79831.45000000","0.00000000"],["79831.42000000","0.00000000"],["79830.81000000","0.10380000"],["79830.71000000","0.00008000"],["79830.37000000","0.00000000"],["79830.32000000","0.00000000"],["79830.25000000","1.20231000"],["79830.00000000","0.02417000"],["79829.84000000","0.00012000"],["79829.79000000","0.00000000"],["79829.78000000","0.00000000"],["79829.36000000","0.00000000"],["79829.30000000","0.00400000"],["79829.18000000","0.00000000"],["79829.14000000","0.00192000"],["79828.79000000","1.87677000"],["79828.78000000","0.00000000"],["79827.43000000","0.00000000"],["79826.86000000","0.00000000"],["79826.72000000","0.00008000"],["79826.31000000","0.00800000"],["79826.02000000","0.47422000"],["79826.01000000","0.42966000"],["79825.74000000","0.00000000"],["79825.72000000","0.00000000"],["79825.36000000","0.00000000"],["79825.35000000","0.00000000"],["79825.34000000","0.00000000"],["79824.51000000","0.00626000"],["79824.30000000","0.00000000"],["79823.95000000","0.00000000"],["79823.84000000","1.87677000"],["79823.73000000","0.00000000"],["79823.43000000","0.00000000"],["79822.73000000","0.00008000"],["79822.68000000","0.25689000"],["79822.50000000","0.00000000"],["79821.21000000","0.00000000"],["79821.19000000","0.62633000"],["79820.09000000","0.00000000"],["79820.06000000","0.00000000"],["79820.00000000","0.11797000"],["79819.89000000","0.33834000"],["79819.44000000","0.00000000"],["79819.00000000","0.00000000"],["79818.75000000","0.00014000"],["79818.74000000","0.00008000"],["79818.33000000","0.00000000"],["79818.00000000","0.02400000"],["79817.57000000","0.00400000"],["79816.00000000","0.02400000"],["79815.54000000","0.00400000"],["79814.88000000","0.00014000"],["79814.74000000","0.00008000"],["79814.12000000","0.00000000"],["79813.52000000","0.75868000"],["79812.84000000","0.62662000"],["79812.53000000","0.04539000"],["79812.00000000","0.03400000"],["79811.67000000","0.00000000"],["79811.20000000","0.00000000"],["79810.19000000","0.00000000"],["79810.00000000","0.11798000"],["79809.94000000","0.60183000"],["79809.93000000","0.00000000"],["79809.55000000","1.04939000"],["79809.45000000","0.00400000"],["79807.14000000","0.00007000"],["79806.62000000","0.22435000"],["79805.39000000","0.00400000"],["79803.27000000","0.00007000"],["79802.95000000","0.00000000"],["79801.88000000","0.00000000"],["79799.40000000","0.00007000"],["79796.92000000","0.00424000"],["79796.79000000","0.00000000"],["79795.87000000","0.34830000"],["79795.39000000","0.00000000"],["79794.46000000","0.00000000"],["79792.25000000","0.00000000"],["79791.26000000","0.02000000"],["79791.19000000","0.00000000"],["79788.01000000","0.03711000"],["79787.40000000","0.00000000"],["79786.34000000","0.00311000"],["79785.32000000","0.00000000"],["79784.46000000","0.00312000"],["79783.74000000","0.00000000"],["79783.59000000","0.43422000"],["79783.58000000","0.82405000"],["79781.81000000","0.00000000"],["79781.66000000","0.00000000"],["79781.27000000","0.00000000"],["79780.24000000","0.00000000"],["79780.09000000","0.00533000"],["79779.47000000","1.91129000"],["79779.22000000","0.00000000"],["79778.16000000","0.00007000"],["79778.02000000","0.01720000"],["79777.41000000","1.24126000"],["79777.31000000","0.00008000"],["79775.71000000","0.66371000"],["79775.44000000","0.00000000"],["79773.50000000","0.00000000"],["79773.39000000","0.12099000"],["79769.88000000","1.04939000"],["79769.19000000","2.03901000"],["79765.48000000","0.06586000"],["79762.27000000","0.66227000"],["79757.49000000","0.07240000"],["79755.01000000","0.03646000"],["79750.70000000","0.62914000"],["79750.69000000","1.87677000"],["79749.52000000","0.00007000"],["79747.89000000","0.13984000"],["79743.29000000","0.68435000"],["79741.10000000","1.87677000"],["79726.70000000","0.00000000"],["79725.52000000","0.20250000"],["79719.13000000","0.00000000"],["79718.74000000","0.00000000"],["79711.95000000","0.00654000"],["79707.51000000","0.00000000"],["79705.89000000","0.00000000"],["79704.27000000","0.00000000"],["79700.01000000","0.00000000"],["79696.93000000","0.00000000"],["79694.96000000","0.00008000"],["79678.99000000","1.20000000"],["79632.84000000","0.00007000"],["79628.85000000","0.00007000"],["79624.41000000","0.00000000"],["79615.11000000","0.00008000"],["79544.54000000","0.00000000"],["79537.81000000","0.00010000"],["79535.25000000","0.00008000"],["79464.68000000","0.00000000"],["79455.40000000","0.00008000"],["79441.92000000","0.00007000"],["79384.82000000","0.00000000"],["79375.54000000","0.00008000"],["79304.95000000","0.00000000"],["79295.69000000","0.00008000"],["71873.11000000","0.00000000"],["71866.81000000","0.00000000"],["63891.47000000","0.00000000"]],"a":[["79852.01000000","6.58280000"],["79852.02000000","3.13398000"],["79852.03000000","0.00013000"],["79852.04000000","0.00000000"],["79852.08000000","0.00400000"],["79852.10000000","0.00021000"],["79852.11000000","0.30535000"],["79852.37000000","0.00000000"],["79852.65000000","0.00008000"],["79852.95000000","0.00000000"],["79853.00000000","0.00000000"],["79853.02000000","0.00000000"],["79853.26000000","0.00000000"],["79853.29000000","0.00000000"],["79853.31000000","0.00000000"],["79853.33000000","0.51064000"],["79853.34000000","0.00021000"],["79853.45000000","0.00156000"],["79853.58000000","0.00014000"],["79853.59000000","0.00000000"],["79853.65000000","0.00000000"],["79854.01000000","0.00021000"],["79854.02000000","0.00000000"],["79854.04000000","0.02533000"],["79854.11000000","0.00400000"],["79854.13000000","0.00000000"],["79854.14000000","0.07500000"],["79854.15000000","0.30021000"],["79854.16000000","0.00000000"],["79854.26000000","0.00000000"],["79854.27000000","0.00000000"],["79854.29000000","0.00000000"],["79854.35000000","0.00000000"],["79854.60000000","0.00000000"],["79854.62000000","0.00021000"],["79854.67000000","0.00000000"],["79854.68000000","0.20715000"],["79854.69000000","0.00000000"],["79854.70000000","0.00000000"],["79854.88000000","0.04885000"],["79854.92000000","0.00000000"],["79854.93000000","0.00000000"],["79854.96000000","0.00000000"],["79854.97000000","1.04939000"],["79854.98000000","0.00007000"],["79855.08000000","0.00000000"],["79855.17000000","0.00000000"],["79855.30000000","0.00000000"],["79855.32000000","0.00000000"],["79855.56000000","0.00000000"],["79855.57000000","0.00000000"],["79855.58000000","0.00000000"],["79855.66000000","0.00000000"],["79855.67000000","0.00000000"],["79855.90000000","0.00000000"],["79855.91000000","0.10669000"],["79855.93000000","0.00000000"],["79856.00000000","0.87964000"],["79856.01000000","0.17358000"],["79856.02000000","0.45229000"],["79856.03000000","0.00000000"],["79856.04000000","0.00000000"],["79856.09000000","0.03224000"],["79856.14000000","0.00400000"],["79856.27000000","0.00000000"],["79856.29000000","0.00007000"],["79856.35000000","0.51393000"],["79856.36000000","0.00000000"],["79856.90000000","0.00014000"],["79856.97000000","0.00007000"],["79857.18000000","0.00007000"],["79857.19000000","0.00000000"],["79857.32000000","0.00000000"],["79857.45000000","0.00014000"],["79857.46000000","0.00000000"],["79857.52000000","0.00000000"],["79857.54000000","0.00000000"],["79857.78000000","0.00000000"],["79857.80000000","0.00007000"],["79858.00000000","1.87677000"],["79858.01000000","0.95655000"],["79858.02000000","0.00000000"],["79858.05000000","0.00000000"],["79858.14000000","0.00000000"],["79858.16000000","0.22208000"],["79858.17000000","0.00407000"],["79858.18000000","0.00000000"],["79858.22000000","0.00000000"],["79858.62000000","0.00000000"],["79858.66000000","0.00000000"],["79858.67000000","0.20257000"],["79858.68000000","0.00000000"],["79858.69000000","0.00000000"],["79858.73000000","0.20257000"],["79858.76000000","0.00000000"],["79858.84000000","0.00000000"],["79858.89000000","0.00000000"],["79858.93000000","0.00000000"],["79858.94000000","0.20257000"],["79859.00000000","0.00000000"],["79859.01000000","0.68958000"],["79859.02000000","0.19890000"],["79859.03000000","0.00000000"],["79859.04000000","0.00000000"],["79859.37000000","0.00000000"],["79859.38000000","1.60908000"],["79859.90000000","0.00007000"],["79860.00000000","0.00000000"],["79860.06000000","0.00000000"],["79860.08000000","0.00937000"],["79860.10000000","0.00008000"],["79860.30000000","0.01720000"],["79860.34000000","0.00007000"],["79860.50000000","0.00000000"],["79860.76000000","0.02000000"],["79861.05000000","0.00000000"],["79861.17000000","0.00000000"],["79861.50000000","0.00000000"],["79861.57000000","0.24621000"],["79861.58000000","0.02064000"],["79861.63000000","0.00699000"],["79861.65000000","0.00000000"],["79861.66000000","0.33284000"],["79861.67000000","0.50250000"],["79861.68000000","0.00000000"],["79861.69000000","1.04705000"],["79861.85000000","0.00010000"],["79861.88000000","0.08576000"],["79861.89000000","0.00000000"],["79861.93000000","0.00000000"],["79861.98000000","0.00007000"],["79862.23000000","0.00400000"],["79862.46000000","0.51476000"],["79862.53000000","0.50792000"],["79862.86000000","0.02064000"],["79863.06000000","0.12521000"],["79863.53000000","0.00007000"],["79863.93000000","1.37324000"],["79863.94000000","1.87677000"],["79864.01000000","0.00000000"],["79864.25000000","0.03000000"],["79864.32000000","0.00000000"],["79864.34000000","0.37484000"],["79864.46000000","0.00007000"],["79864.47000000","0.00000000"],["79864.55000000","0.00701000"],["79864.56000000","0.00000000"],["79864.59000000","0.00000000"],["79864.65000000","0.00007000"],["79865.00000000","0.00000000"],["79865.62000000","0.00000000"],["79865.92000000","0.00007000"],["79865.97000000","0.00007000"],["79865.99000000","0.00000000"],["79866.15000000","0.00930000"],["79866.58000000","0.33815000"],["79866.72000000","0.00007000"],["79866.78000000","0.00000000"],["79866.90000000","0.00000000"],["79867.01000000","0.00000000"],["79867.13000000","0.00000000"],["79867.27000000","0.00000000"],["79867.39000000","0.00000000"],["79867.57000000","0.00000000"],["79868.00000000","0.02800000"],["79868.46000000","0.00000000"],["79868.64000000","0.00007000"],["79868.75000000","0.00007000"],["79868.76000000","0.00000000"],["79868.96000000","0.19019000"],["79869.20000000","0.00000000"],["79869.55000000","0.09529000"],["79869.63000000","0.00000000"],["79869.91000000","0.00000000"],["79870.46000000","0.00000000"],["79870.65000000","0.00008000"],["79871.46000000","0.00000000"],["79871.47000000","0.00000000"],["79871.55000000","0.10375000"],["79873.10000000","0.00000000"],["79873.45000000","0.00000000"],["79874.01000000","0.00000000"],["79874.26000000","0.00000000"],["79874.64000000","0.00008000"],["79874.99000000","0.00000000"],["79875.71000000","0.00000000"],["79876.01000000","0.00000000"],["79876.21000000","0.62612000"],["79876.29000000","0.00000000"],["79876.45000000","0.00000000"],["79876.91000000","0.00250000"],["79877.70000000","0.00000000"],["79878.64000000","0.00008000"],["79878.98000000","0.00000000"],["79879.30000000","0.00125000"],["79879.38000000","0.00000000"],["79880.30000000","0.00000000"],["79880.35000000","0.41998000"],["79880.80000000","0.00000000"],["79881.08000000","0.00000000"],["79881.56000000","0.00000000"],["79882.63000000","0.00008000"],["79882.98000000","0.00000000"],["79883.03000000","0.09467000"],["79883.17000000","0.00400000"],["79883.31000000","0.00000000"],["79883.87000000","0.01270000"],["79884.09000000","0.00000000"],["79884.63000000","0.00000000"],["79885.18000000","0.00000000"],["79885.32000000","0.00000000"],["79885.58000000","0.00000000"],["79886.00000000","0.02400000"],["79886.62000000","0.00015000"],["79886.97000000","0.00000000"],["79887.06000000","0.00000000"],["79887.40000000","0.65368000"],["79888.50000000","0.00000000"],["79889.43000000","0.00000000"],["79889.48000000","0.00000000"],["79890.00000000","0.77201000"],["79890.03000000","0.00000000"],["79890.61000000","0.00008000"],["79890.96000000","0.00000000"],["79891.74000000","0.00000000"],["79892.28000000","0.00000000"],["79893.66000000","0.00573000"],["79894.61000000","0.00008000"],["79894.96000000","0.00000000"],["79895.39000000","0.00000000"],["79895.78000000","0.00010000"],["79896.15000000","0.00000000"],["79898.95000000","0.00000000"],["79899.00000000","0.01000000"],["79899.24000000","0.00000000"],["79900.00000000","0.02407000"],["79900.97000000","0.82284000"],["79901.17000000","0.00000000"],["79903.00000000","0.00000000"],["79903.10000000","0.00000000"],["79903.69000000","0.00000000"],["79904.51000000","0.00000000"],["79905.82000000","0.00000000"],["79906.09000000","0.00000000"],["79906.87000000","0.00000000"],["79907.62000000","0.00000000"],["79910.00000000","0.02400000"],["79912.82000000","0.00000000"],["79916.05000000","0.83397000"],["79918.64000000","0.00000000"],["79920.72000000","0.00000000"],["79921.06000000","0.00000000"],["79923.80000000","0.00110000"],["79933.08000000","0.00007000"],["79935.52000000","0.00000000"],["79936.84000000","0.00000000"],["79937.04000000","0.00008000"],["79937.07000000","0.51937000"],["79939.13000000","0.00000000"],["79939.20000000","0.09268000"],["79945.22000000","1.29568000"],["79945.67000000","0.00000000"],["79951.70000000","0.01163000"],["79961.65000000","0.00000000"],["79961.72000000","0.00000000"],["79963.75000000","0.58654000"],["79964.80000000","0.00017000"],["79972.95000000","0.29312000"],["79972.96000000","0.00000000"],["79979.99000000","0.50215000"],["79982.55000000","0.00000000"],["80016.89000000","0.00008000"],["80025.53000000","0.00000000"],["80096.75000000","0.00008000"],["80105.40000000","0.00000000"],["80105.52000000","0.00000000"],["80133.92000000","0.00010000"],["80159.47000000","1.19998000"],["80160.74000000","7.48687000"],["80164.26000000","0.00000000"],["80166.62000000","0.00010000"],["80172.25000000","0.00000000"],["80188.23000000","0.00000000"],["80190.86000000","0.00000000"],["80191.28000000","0.00000000"],["80196.22000000","0.00000000"],["80204.21000000","0.00000000"],["80220.19000000","0.00000000"],["80236.17000000","0.00000000"],["80256.47000000","0.00018000"],["80256.51000000","0.00000000"],["80265.13000000","0.00000000"],["80271.57000000","0.00000000"],["80416.18000000","0.00008000"],["80424.86000000","0.00000000"],["80496.04000000","0.00008000"],["80504.73000000","0.00000000"],["80583.11000000","0.00000000"],["80648.05000000","0.00000000"]]}}}
{"rx_ns": 13986126977200, "frame": {"stream":"btcusdt@depth@100ms","data":{"e":"depthUpdate","E":1787650981314,"s":"BTCUSDT","U":99118690315,"u":99118690810,"b":[["79852.00000000","0.00000000"],["79851.99000000","0.00000000"],["79851.72000000","0.00000000"],["79851.71000000","0.12659000"],["79851.70000000","0.00042000"],["79850.00000000","0.03439000"],["79849.29000000","0.05162000"],["79848.82000000","0.00740000"],["79848.35000000","0.00596000"],["79848.00000000","0.02428000"],["79847.70000000","0.00000000"],["79847.54000000","0.01233000"],["79846.76000000","0.00000000"],["79846.75000000","0.00028000"],["79846.27000000","0.00007000"],["79846.26000000","0.01480000"],["79846.01000000","0.00007000"],["79846.00000000","0.02421000"],["79845.66000000","0.00000000"],["79844.99000000","0.00007000"],["79844.98000000","0.01480000"],["79844.91000000","0.00000000"],["79844.54000000","0.00000000"],["79844.15000000","0.00014000"],["79844.01000000","0.00014000"],["79844.00000000","0.02421000"],["79843.04000000","0.00000000"],["79842.01000000","0.00014000"],["79841.69000000","0.00202000"],["79841.47000000","0.00007000"],["79841.46000000","0.39946000"],["79841.01000000","0.00000000"],["79840.85000000","0.00007000"],["79840.84000000","0.06128000"],["79840.49000000","0.00007000"],["79840.44000000","0.00000000"],["79840.37000000","0.00568000"],["79840.23000000","0.00000000"],["79840.22000000","0.06128000"],["79840.13000000","0.00000000"],["79839.99000000","0.00000000"],["79839.84000000","0.31320000"],["79838.10000000","0.00014000"],["79838.08000000","0.00070000"],["79837.75000000","0.02000000"],["79837.58000000","0.00047000"],["79837.28000000","0.00000000"],["79836.88000000","0.01000000"],["79836.28000000","0.02000000"],["79834.70000000","0.00000000"],["79834.33000000","0.42926000"],["79834.32000000","0.00000000"],["79834.31000000","0.00000000"],["79833.31000000","0.00000000"],["79833.28000000","0.00000000"],["79833.25000000","0.00250000"],["79832.27000000","0.00000000"],["79832.18000000","0.00000000"],["79831.82000000","0.00048000"],["79831.28000000","0.12000000"],["79827.84000000","0.15376000"],["79827.01000000","0.00000000"],["79826.02000000","0.00000000"],["79826.01000000","0.00000000"],["79825.33000000","0.00000000"],["79824.20000000","0.00000000"],["79823.94000000","0.00000000"],["79822.67000000","0.00000000"],["79821.79000000","0.00400000"],["79820.68000000","0.00000000"],["79820.11000000","0.42969000"],["79817.26000000","0.00000000"],["79816.98000000","0.00000000"],["79816.02000000","0.00000000"],["79811.48000000","0.00400000"],["79810.67000000","0.00019000"],["79810.00000000","0.12049000"],["79809.94000000","0.35334000"],["79807.69000000","0.00015000"],["79804.34000000","0.04400000"],["79800.49000000","0.01133000"],["79799.40000000","0.00000000"],["79797.29000000","0.02200000"],["79797.18000000","0.00000000"],["79790.52000000","0.00000000"],["79787.39000000","0.00000000"],["79786.38000000","0.00628000"],["79784.21000000","0.00435000"],["79783.47000000","0.00429000"],["79781.87000000","0.00400000"],["79780.10000000","0.00312000"],["79777.94000000","0.00000000"],["79775.71000000","0.00000000"],["79775.70000000","0.00000000"],["79773.47000000","0.08825000"],["79773.39000000","0.00000000"],["79773.16000000","0.00000000"],["79772.80000000","0.00007000"],["79772.70000000","0.00000000"],["79772.47000000","0.00000000"],["79772.39000000","0.00000000"],["79772.16000000","0.00007000"],["79771.99000000","0.00000000"],["79771.59000000","0.00000000"],["79769.89000000","1.89844000"],["79769.19000000","0.00000000"],["79769.18000000","0.00000000"],["79755.26000000","0.00000000"],["79749.95000000","0.00400000"],["79747.97000000","0.04595000"],["79738.01000000","0.05487000"],["79733.52000000","0.16983000"],["79729.09000000","0.00000000"],["79726.70000000","0.51723000"],["79724.67000000","0.00000000"],["79711.95000000","0.00000000"],["79707.36000000","0.00000000"],["79702.05000000","0.00400000"],["79700.52000000","0.00125000"],["79644.18000000","0.00000000"],["79643.68000000","3.76773000"],["79637.49000000","0.00000000"],["79635.72000000","0.00000000"],["79630.21000000","0.00400000"],["79629.93000000","0.00000000"],["79625.11000000","0.00007000"],["79621.95000000","0.01961000"],["79621.12000000","0.00007000"],["79610.45000000","0.00007000"],["79578.96000000","0.11549000"],["79571.49000000","0.00000000"],["79521.47000000","0.00027000"],["79494.28000000","0.00498000"],["79296.00000000","0.00026000"],["71877.89000000","0.00000000"],["71877.88000000","0.00008000"],["71866.80000000","0.00000000"],["63891.00000000","0.00000000"],["63890.04000000","0.00018000"]],"a":[["79851.72000000","6.39801000"],["79851.73000000","0.01028000"],["79852.00000000","4.61787000"],["79852.01000000","4.50564000"],["79852.02000000","1.05233000"],["79852.03000000","0.00000000"],["79852.10000000","0.00007000"],["79852.11000000","0.25548000"],["79852.75000000","0.02007000"],["79853.13000000","0.00715000"],["79853.33000000","0.00014000"],["79853.34000000","0.00007000"],["79853.45000000","0.00000000"],["79854.01000000","0.00007000"],["79854.04000000","0.02547000"],["79854.14000000","0.07514000"],["79854.15000000","0.30021000"],["79854.62000000","0.00007000"],["79854.68000000","0.20682000"],["79854.88000000","0.04892000"],["79854.98000000","0.00000000"],["79855.59000000","0.00915000"],["79855.91000000","0.10676000"],["79856.00000000","0.87971000"],["79856.35000000","0.51400000"],["79856.79000000","0.00026000"],["79857.13000000","0.00700000"],["79858.16000000","0.00000000"],["79859.02000000","0.10844000"],["79859.90000000","0.00000000"],["79860.00000000","0.09392000"],["79860.08000000","0.28346000"],["79860.09000000","0.33817000"],["79860.30000000","0.00000000"],["79860.76000000","0.00000000"],["79861.57000000","0.00000000"],["79861.58000000","0.00000000"],["79861.69000000","0.20631000"],["79862.46000000","0.00000000"],["79862.53000000","0.00000000"],["79862.86000000","0.00000000"],["79864.17000000","0.00007000"],["79864.34000000","0.17174000"],["79864.46000000","0.00000000"],["79866.09000000","0.00000000"],["79872.05000000","0.00000000"],["79874.41000000","0.00000000"],["79874.98000000","0.00189000"],["79877.71000000","0.00059000"],["79879.37000000","0.00000000"],["79879.51000000","0.00000000"],["79880.00000000","0.11797000"],["79883.17000000","0.00000000"],["79885.98000000","0.00000000"],["79887.57000000","0.00616000"],["79887.83000000","0.00012000"],["79888.47000000","0.00400000"],["79888.74000000","0.00433000"],["79888.75000000","0.00000000"],["79889.68000000","0.00436000"],["79890.07000000","0.00429000"],["79891.56000000","0.00000000"],["79891.82000000","0.04320000"],["79892.00000000","0.03400000"],["79893.19000000","0.00000000"],["79893.96000000","0.00000000"],["79894.16000000","0.25000000"],["79899.00000000","0.00000000"],["79901.07000000","0.00008000"],["79903.07000000","0.00000000"],["79906.97000000","0.01149000"],["79916.73000000","0.04926000"],["79917.31000000","0.00625000"],["79918.82000000","0.00535000"],["79928.42000000","0.00400000"],["79930.32000000","0.00000000"],["79933.66000000","0.00000000"],["79933.92000000","0.00000000"],["79937.94000000","0.12204000"],["79953.21000000","0.04619000"],["79955.64000000","0.00000000"],["79959.88000000","0.31568000"],["79960.37000000","0.00400000"],["79964.21000000","0.00000000"],["79965.93000000","0.00000000"],["79980.46000000","0.00000000"],["79986.64000000","0.04576000"],["80008.31000000","0.00400000"],["80013.52000000","0.00000000"],["80017.14000000","0.00000000"],["80080.21000000","0.00400000"],["80085.77000000","0.00000000"],["80090.75000000","0.00000000"],["80091.16000000","0.11330000"],["80094.74000000","0.00000000"],["80098.73000000","0.00000000"],["80107.30000000","0.01934000"],["80111.69000000","0.11441000"],["80134.27000000","0.00000000"],["80142.91000000","0.00000000"],["80163.69000000","0.00000000"],["80246.94000000","0.00626000"]]}}}
{"rx_ns": 13986206008100, "frame": {"stream":"btcusdt@depth@100ms","data":{"e":"depthUpdate","E":1787650981414,"s":"BTCUSDT","U":99118690811,"u":99118691449,"b":[["79851.71000000","0.00000000"],["79851.70000000","0.00000000"],["79850.91000000","0.00000000"],["79850.78000000","0.00000000"],["79850.40000000","0.00000000"],["79850.33000000","0.00000000"],["79850.11000000","0.00000000"],["79850.01000000","0.00000000"],["79850.00000000","0.01337000"],["79849.99000000","0.00056000"],["79849.30000000","0.00000000"],["79849.29000000","0.00021000"],["79848.82000000","0.00014000"],["79848.03000000","0.00007000"],["79848.00000000","0.02421000"],["79847.55000000","0.00000000"],["79847.54000000","0.00028000"],["79847.29000000","0.00007000"],["79847.28000000","0.05141000"],["79846.75000000","0.00014000"],["79846.27000000","0.00000000"],["79846.26000000","0.00014000"],["79846.00000000","0.02421000"],["79844.99000000","0.00000000"],["79844.98000000","0.00014000"],["79844.53000000","0.00007000"],["79844.15000000","0.00000000"],["79844.02000000","0.00000000"],["79844.00000000","0.02414000"],["79842.82000000","0.00000000"],["79842.02000000","0.00008000"],["79841.46000000","0.33825000"],["79840.85000000","0.00000000"],["79840.84000000","0.00000000"],["79840.31000000","0.00000000"],["79840.22000000","0.00000000"],["79840.14000000","0.00000000"],["79840.01000000","0.00007000"],["79839.85000000","0.00007000"],["79839.78000000","0.00000000"],["79839.60000000","0.00000000"],["79839.50000000","0.00000000"],["79838.98000000","0.00000000"],["79838.76000000","0.00000000"],["79838.70000000","0.00000000"],["79838.66000000","0.00000000"],["79838.38000000","0.00944000"],["79838.36000000","0.00000000"],["79838.22000000","0.05647000"],["79837.74000000","0.00000000"],["79837.60000000","0.06128000"],["79837.23000000","0.05538000"],["79837.22000000","0.00000000"],["79837.13000000","0.00000000"],["79837.12000000","0.00000000"],["79837.04000000","0.00696000"],["79836.58000000","0.00025000"],["79835.21000000","0.08566000"],["79834.89000000","0.00020000"],["79834.71000000","0.06139000"],["79834.03000000","0.00015000"],["79833.25000000","0.00000000"],["79832.80000000","0.00000000"],["79831.69000000","0.00072000"],["79831.62000000","0.00250000"],["79831.51000000","0.00934000"],["79830.81000000","0.00000000"],["79830.71000000","0.00000000"],["79830.35000000","0.00048000"],["79830.04000000","0.00008000"],["79829.68000000","0.00190000"],["79827.35000000","0.02480000"],["79826.72000000","0.00000000"],["79826.05000000","0.00008000"],["79826.04000000","0.00125000"],["79823.52000000","0.00907000"],["79822.73000000","0.00000000"],["79822.05000000","0.00008000"],["79821.79000000","0.00000000"],["79821.19000000","0.00000000"],["79818.74000000","0.00000000"],["79818.06000000","0.00015000"],["79816.64000000","0.00000000"],["79815.73000000","0.01813000"],["79815.53000000","0.00918000"],["79815.51000000","0.62641000"],["79814.74000000","0.00000000"],["79814.07000000","0.00008000"],["79812.00000000","0.02400000"],["79811.01000000","0.00014000"],["79811.00000000","0.00000000"],["79810.08000000","0.00008000"],["79810.00000000","0.13049000"],["79807.54000000","0.00935000"],["79803.83000000","0.65436000"],["79801.33000000","0.00400000"],["79800.32000000","0.00000000"],["79799.40000000","0.00007000"],["79790.26000000","0.82398000"],["79781.87000000","0.00000000"],["79778.62000000","0.00112000"],["79773.47000000","0.06057000"],["79771.87000000","0.00000000"],["79771.69000000","0.00000000"],["79770.96000000","0.12383000"],["79749.95000000","0.00000000"],["79747.37000000","0.05661000"],["79733.52000000","0.38692000"],["79732.39000000","0.80000000"],["79732.01000000","0.02869000"],["79722.91000000","0.00000000"],["79716.79000000","0.01961000"],["79713.33000000","0.04385000"],["79702.05000000","0.00000000"],["79700.36000000","0.00654000"],["79692.35000000","0.09249000"],["79630.21000000","0.00000000"],["79621.12000000","0.00000000"],["79582.85000000","0.11441000"],["79220.34000000","0.00000000"],["79211.97000000","0.00008000"],["71865.00000000","0.00016000"],["63890.04000000","0.00000000"],["63881.37000000","0.00018000"]],"a":[["79850.01000000","6.85611000"],["79850.02000000","0.00027000"],["79850.03000000","0.00013000"],["79850.05000000","0.00400000"],["79850.12000000","0.00000000"],["79850.33000000","0.36593000"],["79850.34000000","0.00014000"],["79850.41000000","0.00000000"],["79850.63000000","0.00000000"],["79850.79000000","0.36964000"],["79850.92000000","0.00000000"],["79851.25000000","0.00000000"],["79851.29000000","0.01897000"],["79851.70000000","0.00000000"],["79851.71000000","3.32334000"],["79851.72000000","1.04001000"],["79851.73000000","0.00014000"],["79851.74000000","0.00000000"],["79852.00000000","0.07521000"],["79852.01000000","0.86172000"],["79852.11000000","0.05298000"],["79852.57000000","0.02276000"],["79852.75000000","0.02014000"],["79852.87000000","0.04879000"],["79853.13000000","0.00722000"],["79853.33000000","0.00000000"],["79853.85000000","0.02276000"],["79854.04000000","0.02533000"],["79854.14000000","0.07500000"],["79854.15000000","0.30007000"],["79854.68000000","0.00418000"],["79854.88000000","0.00014000"],["79856.00000000","0.80471000"],["79856.01000000","0.13159000"],["79856.02000000","0.38014000"],["79856.35000000","0.00007000"],["79856.62000000","0.02254000"],["79856.74000000","0.00250000"],["79856.90000000","0.00000000"],["79856.97000000","0.00000000"],["79857.18000000","0.00000000"],["79857.80000000","0.00000000"],["79858.00000000","1.87685000"],["79858.01000000","0.07561000"],["79858.17000000","0.00400000"],["79858.67000000","0.00000000"],["79858.73000000","0.00000000"],["79858.94000000","0.00000000"],["79859.01000000","0.30000000"],["79859.02000000","0.10837000"],["79859.37000000","0.29057000"],["79859.38000000","1.45544000"],["79859.87000000","0.08576000"],["79859.98000000","0.00007000"],["79860.08000000","0.42823000"],["79860.10000000","0.00000000"],["79861.88000000","0.00000000"],["79862.46000000","0.00007000"],["79864.16000000","0.00000000"],["79864.17000000","0.00000000"],["79865.93000000","0.09529000"],["79865.98000000","0.00008000"],["79866.54000000","0.02480000"],["79867.75000000","0.00000000"],["79867.92000000","0.10375000"],["79869.55000000","0.00000000"],["79869.97000000","0.00008000"],["79870.65000000","0.00000000"],["79871.55000000","0.00000000"],["79871.76000000","0.00000000"],["79873.09000000","0.00000000"],["79873.97000000","1.87685000"],["79873.99000000","0.00000000"],["79874.64000000","0.00000000"],["79876.91000000","0.00250000"],["79877.96000000","0.00008000"],["79878.64000000","0.00000000"],["79880.00000000","0.11790000"],["79880.35000000","0.72398000"],["79880.61000000","0.00000000"],["79881.21000000","1.20232000"],["79881.28000000","0.00000000"],["79881.95000000","0.00008000"],["79882.24000000","0.00000000"],["79882.63000000","0.00000000"],["79885.94000000","0.00008000"],["79886.62000000","0.00007000"],["79887.73000000","0.02472000"],["79888.47000000","0.00000000"],["79889.94000000","0.00008000"],["79890.61000000","0.00000000"],["79894.61000000","0.00000000"],["79904.47000000","1.01683000"],["79905.37000000","0.00000000"],["79913.01000000","0.11316000"],["79928.42000000","0.00000000"],["79948.78000000","0.02804000"],["79956.44000000","0.67125000"],["79956.45000000","0.00000000"],["79960.37000000","0.00000000"],["79963.75000000","0.00000000"],["79963.76000000","0.00000000"],["79963.99000000","0.01674000"],["80008.31000000","0.00000000"],["80044.53000000","0.00000000"],["80045.72000000","0.00000000"],["80077.16000000","0.00000000"],["80080.21000000","0.00000000"],["80086.76000000","0.00000000"],["80117.81000000","0.00030000"],["80164.26000000","0.20250000"],["80172.25000000","0.20250000"]]}}}
{"rx_ns": 13986291788100, "frame": {"stream":"btcusdt@depth@100ms","data":{"e":"depthUpdate","E":1787650981514,"s":"BTCUSDT","U":99118691450,"u":99118691604,"b":[["79850.00000000","0.01702000"],["79849.99000000","0.00070000"],["79849.29000000","0.00000000"],["79848.82000000","0.00000000"],["79848.35000000","0.00028000"],["79848.00000000","0.02421000"],["79847.54000000","0.00007000"],["79847.28000000","0.05162000"],["79846.82000000","0.00740000"],["79846.26000000","0.00000000"],["79846.00000000","0.02421000"],["79845.54000000","0.01240000"],["79844.98000000","0.00000000"],["79844.27000000","0.00007000"],["79844.26000000","0.01480000"],["79844.00000000","0.02442000"],["79842.99000000","0.00007000"],["79842.98000000","0.01480000"],["79842.01000000","0.00354000"],["79842.00000000","0.02428000"],["79841.82000000","0.00007000"],["79841.81000000","0.05966000"],["79841.48000000","0.00033000"],["79841.47000000","0.06217000"],["79841.46000000","0.33839000"],["79840.37000000","0.00021000"],["79840.01000000","0.00000000"],["79840.00000000","0.02414000"],["79839.93000000","0.00000000"],["79839.92000000","0.06210000"],["79839.86000000","0.00000000"],["79839.85000000","0.06210000"],["79838.76000000","0.00007000"],["79838.66000000","0.06210000"],["79834.03000000","0.00355000"],["79832.38000000","0.00000000"],["79831.62000000","0.00000000"],["79831.59000000","0.00250000"],["79826.04000000","0.00465000"],["79815.64000000","0.09260000"],["79810.67000000","0.00007000"],["79810.61000000","0.59467000"],["79810.60000000","0.33838000"],["79809.94000000","0.00000000"],["79808.43000000","0.33839000"],["79801.66000000","0.00012000"],["79796.44000000","0.83260000"],["79770.96000000","0.00000000"],["79760.96000000","0.04576000"],["79755.01000000","0.62778000"],["79753.24000000","1.99660000"],["79716.79000000","0.00000000"],["79694.49000000","0.00400000"],["79653.40000000","0.01961000"],["79629.94000000","0.00000000"],["79599.03000000","0.00771000"],["71865.00000000","0.00048000"],["63880.00000000","0.02132000"]],"a":[["79850.01000000","6.85612000"],["79850.33000000","0.36607000"],["79850.34000000","0.00000000"],["79850.79000000","0.36978000"],["79851.29000000","0.01911000"],["79851.71000000","3.12084000"],["79851.72000000","0.53396000"],["79851.73000000","0.00000000"],["79852.02000000","0.84983000"],["79852.11000000","0.05284000"],["79856.00000000","1.14483000"],["79858.16000000","0.00007000"],["79867.39000000","0.33814000"],["79878.81000000","0.00012000"],["79887.83000000","0.00000000"],["79890.00000000","0.78201000"],["79891.99000000","1.72688000"],["79892.00000000","0.02400000"],["79892.58000000","0.83159000"],["79935.81000000","1.17007000"],["79935.82000000","1.99204000"],["79937.07000000","0.00000000"],["79982.32000000","0.00000000"],["80004.70000000","0.03132000"],["80180.24000000","0.20250000"],["80204.21000000","0.20250000"],["81669.03000000","0.00000000"]]}}}
{"rx_ns": 13986391379800, "frame": {"stream":"btcusdt@depth@100ms","data":{"e":"depthUpdate","E":1787650981614,"s":"BTCUSDT","U":99118691605,"u":99118691661,"b":[["79850.00000000","0.01688000"],["79848.35000000","0.00014000"],["79848.03000000","0.00000000"],["79847.28000000","0.05162000"],["79846.82000000","0.00754000"],["79846.00000000","0.02421000"],["79845.54000000","0.01254000"],["79844.26000000","0.01494000"],["79844.00000000","0.02442000"],["79842.98000000","0.01494000"],["79842.00000000","0.02414000"],["79841.46000000","0.33825000"],["79840.37000000","0.00007000"],["79831.59000000","0.00000000"],["79831.55000000","0.00250000"],["79823.43000000","0.51822000"],["79818.06000000","0.00355000"],["79799.48000000","1.04677000"],["79790.43000000","0.13295000"],["79785.17000000","0.02000000"],["79770.46000000","0.12242000"],["63880.00000000","0.02101000"]],"a":[["79850.01000000","6.85581000"],["79851.29000000","0.01918000"],["79851.72000000","0.53410000"],["79861.35000000","0.02000000"],["79866.02000000","0.00007000"],["79877.63000000","0.00000000"],["79910.13000000","0.00000000"]]}}}
{"rx_ns": 13986495741500, "frame": {"stream":"btcusdt@depth@100ms","data":{"e":"depthUpdate","E":1787650981714,"s":"BTCUSDT","U":99118691662,"u":99118691696,"b":[["79850.00000000","0.01307000"],["79849.99000000","0.00063000"],["79831.55000000","0.00000000"],["79831.52000000","0.00250000"],["79825.34000000","0.02200000"],["79824.56000000","0.02000000"],["79815.73000000","0.01159000"],["79777.30000000","0.02200000"],["79769.28000000","0.00000000"],["79764.74000000","0.00000000"],["79735.60000000","0.00000000"],["79730.48000000","0.00000000"],["79721.28000000","0.00012000"],["79717.46000000","0.00011000"],["78652.25000000","0.00030000"],["71877.88000000","0.00000000"],["71865.00000000","0.00080000"]],"a":[["79850.01000000","6.85581000"],["79851.70000000","1.86131000"],["79851.71000000","2.26841000"],["79860.16000000","0.02000000"],["79860.94000000","0.02000000"],["79929.44000000","0.00000000"],["79952.79000000","0.00400000"],["79981.00000000","0.00007000"],["79983.69000000","0.00000000"],["79987.86000000","0.00000000"],["81062.31000000","0.00000000"]]}}}
{"rx_ns": 13986592841000, "frame": {"stream":"btcusdt@depth@100ms","data":{"e":"depthUpdate","E":1787650981814,"s":"BTCUSDT","U":99118691697,"u":99118691723,"b":[["79850.00000000","0.01304000"],["79842.98000000","0.01501000"],["79842.45000000","0.00007000"],["79842.44000000","0.06202000"],["79841.47000000","0.06210000"],["79796.92000000","0.00000000"],["79785.90000000","0.00428000"],["79621.95000000","0.00000000"],["79610.71000000","0.01961000"],["71865.00000000","0.00096000"]],"a":[["79850.01000000","6.85581000"],["79851.29000000","0.01918000"],["79851.70000000","1.86145000"],["79852.02000000","0.84969000"],["79858.00000000","1.88385000"],["79860.00000000","0.10092000"],["79862.00000000","0.00700000"],["79864.00000000","0.00707000"],["79866.00000000","0.01100000"],["81000.00000000","31.68329000"]]}}}
{"rx_ns": 13986696622100, "frame": {"stream":"btcusdt@depth@100ms","data":{"e":"depthUpdate","E":1787650981914,"s":"BTCUSDT","U":99118691724,"u":99118691777,"b":[["79849.32000000","0.00007000"],["79842.98000000","0.01501000"],["79831.52000000","0.00000000"],["79831.49000000","0.00000000"],["79829.93000000","0.02800000"],["79829.85000000","0.02600000"],["79829.06000000","0.02000000"],["79825.46000000","0.02200000"],["79825.06000000","0.04400000"],["79817.28000000","0.00000000"],["79809.62000000","0.00000000"],["79809.25000000","0.00000000"],["79785.97000000","0.02400000"],["79774.09000000","0.02800000"],["79769.65000000","0.02200000"],["79769.25000000","0.02200000"],["79769.24000000","0.00000000"],["79768.60000000","0.02000000"],["79766.35000000","0.02600000"],["79741.76000000","0.00007000"],["71865.00000000","0.00128000"]],"a":[["79850.01000000","6.85456000"],["79856.19000000","0.02000000"],["79856.30000000","0.02000000"],["79857.11000000","0.02000000"],["79860.17000000","0.02000000"],["79860.62000000","0.02000000"],["79861.02000000","0.02000000"],["79861.03000000","0.02000000"],["79862.04000000","0.00007000"],["79871.33000000","0.51609000"],["79877.56000000","0.00000000"],["79924.86000000","0.00000000"],["79927.37000000","0.00000000"],["79928.16000000","0.00000000"],["79928.24000000","0.00000000"],["79966.64000000","0.00012000"],["80000.72000000","0.00400000"],["80493.39000000","0.00031000"]]}}}
{"rx_ns": 13986802191400, "frame": {"stream":"btcusdt@depth20","data":{"lastUpdateId":99118692072,"bids":[["79848.00000000","0.01916000"],["79847.99000000","0.00076000"],["79847.77000000","0.00007000"],["79847.54000000","0.00007000"],["79847.29000000","0.00007000"],["79847.28000000","0.00021000"],["79846.82000000","0.00754000"],["79846.75000000","0.00014000"],["79846.52000000","0.00007000"],["79846.05000000","0.00007000"],["79846.01000000","0.00007000"],["79846.00000000","0.02421000"],["79845.84000000","0.00007000"],["79845.55000000","0.00007000"],["79845.54000000","0.01254000"],["79845.28000000","0.05141000"],["79845.12000000","0.00007000"],["79844.53000000","0.00007000"],["79844.27000000","0.00007000"],["79844.26000000","0.01494000"]],"asks":[["79848.01000000","6.82298000"],["79848.02000000","2.92643000"],["79848.48000000","0.19357000"],["79849.71000000","0.00014000"],["79850.00000000","4.41049000"],["79850.01000000","1.77110000"],["79850.05000000","0.00400000"],["79850.33000000","0.36607000"],["79850.79000000","0.18225000"],["79850.87000000","0.04879000"],["79851.29000000","0.01918000"],["79851.69000000","0.19019000"],["79851.70000000","0.00014000"],["79851.71000000","0.39164000"],["79851.72000000","0.53410000"],["79852.00000000","0.07521000"],["79852.01000000","0.86158000"],["79852.02000000","0.84969000"],["79852.08000000","0.00400000"],["79852.10000000","0.00007000"]]}}}
{"rx_ns": 13986802365000, "frame": {"stream":"btcusdt@depth@100ms","data":{"e":"depthUpdate","E":1787650982014,"s":"BTCUSDT","U":99118691778,"u":99118692072,"b":[["79850.00000000","0.00000000"],["79849.99000000","0.00000000"],["79849.71000000","0.00000000"],["79849.32000000","0.00000000"],["79848.47000000","0.00000000"],["79848.35000000","0.00000000"],["79848.01000000","0.00000000"],["79848.00000000","0.01916000"],["79847.99000000","0.00076000"],["79847.28000000","0.00021000"],["79847.26000000","0.00000000"],["79845.55000000","0.00007000"],["79845.28000000","0.05141000"],["79845.15000000","0.00000000"],["79842.44000000","0.00014000"],["79842.02000000","0.00000000"],["79841.81000000","0.00000000"],["79841.47000000","0.00000000"],["79840.02000000","0.00008000"],["79839.92000000","0.00000000"],["79839.85000000","0.00000000"],["79838.66000000","0.00000000"],["79838.22000000","0.00000000"],["79836.89000000","0.00000000"],["79836.58000000","0.00000000"],["79836.05000000","0.00056000"],["79835.58000000","0.00014000"],["79834.89000000","0.00000000"],["79831.41000000","0.00000000"],["79829.06000000","0.04400000"],["79824.51000000","0.00000000"],["79822.33000000","0.00626000"],["79820.11000000","0.00000000"],["79818.62000000","0.62641000"],["79817.68000000","0.42971000"],["79815.64000000","0.00000000"],["79815.51000000","0.00000000"],["79814.06000000","0.00000000"],["79810.00000000","0.12049000"],["79809.22000000","0.00000000"],["79809.21000000","0.00000000"],["79803.13000000","0.62670000"],["79780.10000000","0.00000000"],["79778.19000000","0.00312000"],["79777.31000000","0.00000000"],["79770.46000000","0.00000000"],["79768.60000000","0.00000000"],["79768.15000000","0.00008000"],["79766.35000000","0.00000000"],["79764.46000000","0.02400000"],["78652.25000000","0.00000000"],["71865.00000000","0.00008000"],["63880.00000000","0.02132000"]],"a":[["79848.01000000","6.82298000"],["79848.02000000","2.92643000"],["79848.36000000","0.00000000"],["79848.48000000","0.19357000"],["79848.64000000","0.00000000"],["79849.27000000","0.00000000"],["79849.33000000","0.00000000"],["79849.71000000","0.00014000"],["79849.72000000","0.00000000"],["79849.90000000","0.00000000"],["79850.00000000","4.41049000"],["79850.01000000","1.77110000"],["79850.02000000","0.00000000"],["79850.03000000","0.00000000"],["79850.79000000","0.18225000"],["79850.87000000","0.04879000"],["79851.69000000","0.19019000"],["79851.70000000","0.00014000"],["79851.71000000","0.39164000"],["79852.01000000","0.86158000"],["79852.87000000","0.00000000"],["79854.14000000","0.00000000"],["79855.91000000","0.00014000"],["79855.99000000","0.00008000"],["79856.01000000","0.01928000"],["79856.02000000","0.30014000"],["79857.05000000","0.02000000"],["79857.15000000","0.00007000"],["79858.00000000","1.88377000"],["79859.02000000","0.00717000"],["79859.37000000","0.00000000"],["79860.46000000","0.00007000"],["79861.01000000","0.00626000"],["79861.65000000","0.33267000"],["79862.46000000","0.00000000"],["79862.74000000","0.22495000"],["79864.32000000","0.62641000"],["79866.59000000","0.62620000"],["79866.72000000","0.00000000"],["79868.13000000","0.42971000"],["79868.14000000","1.03647000"],["79868.96000000","0.00000000"],["79870.00000000","0.82191000"],["79871.65000000","0.00000000"],["79874.25000000","0.00000000"],["79887.99000000","0.00000000"],["79888.41000000","0.00000000"],["79890.00000000","0.73400000"],["79912.71000000","0.00190000"],["79913.44000000","0.00000000"],["79914.25000000","0.00000000"],["79914.48000000","0.00000000"],["79924.72000000","0.00000000"],["79927.86000000","0.00008000"],["79937.04000000","0.00000000"],["79969.33000000","0.00018000"],["79992.84000000","0.00076000"],["80006.84000000","0.00000000"],["80007.71000000","0.00008000"],["80016.89000000","0.00000000"],["80087.55000000","0.00008000"],["80096.75000000","0.00000000"],["80247.25000000","0.00008000"],["80256.47000000","0.00010000"],["80406.95000000","0.00008000"],["80416.18000000","0.00000000"],["80486.79000000","0.00008000"],["80496.04000000","0.00000000"]]}}}
{"rx_ns": 13986891765000, "frame": {"stream":"btcusdt@depth@100ms","data":{"e":"depthUpdate","E":1787650982114,"s":"BTCUSDT","U":99118692073,"u":99118692287,"b":[["79848.00000000","0.02609000"],["79847.99000000","0.00083000"],["79847.98000000","0.00013000"],["79847.29000000","0.00000000"],["79847.28000000","0.00007000"],["79846.82000000","0.00014000"],["79845.55000000","0.00000000"],["79845.54000000","0.00028000"],["79845.29000000","0.00007000"],["79845.28000000","0.05155000"],["79844.27000000","0.00000000"],["79844.26000000","0.00014000"],["79842.99000000","0.00000000"],["79842.98000000","0.00014000"],["79842.45000000","0.00000000"],["79842.44000000","0.00000000"],["79842.02000000","0.00013000"],["79842.00000000","0.02421000"],["79841.82000000","0.00000000"],["79841.71000000","0.00007000"],["79841.70000000","0.06216000"],["79841.48000000","0.00033000"],["79841.47000000","0.06216000"],["79841.46000000","0.33832000"],["79840.45000000","0.00007000"],["79840.44000000","0.06209000"],["79840.01000000","0.00000000"],["79840.00000000","0.02421000"],["79839.86000000","0.00007000"],["79839.85000000","0.06216000"],["79839.44000000","0.00000000"],["79839.43000000","0.12525000"],["79838.55000000","0.06209000"],["79837.92000000","0.06209000"],["79836.03000000","0.06209000"],["79835.21000000","0.00000000"],["79833.04000000","0.08566000"],["79831.49000000","0.12526000"],["79831.39000000","0.00250000"],["79829.14000000","0.02392000"],["79826.75000000","0.02400000"],["79823.50000000","0.12527000"],["79822.68000000","0.00000000"],["79821.19000000","0.34297000"],["79814.80000000","0.09287000"],["79808.00000000","0.03407000"],["79801.66000000","0.00000000"],["79799.66000000","0.00012000"],["79786.34000000","0.00000000"],["79778.97000000","0.00312000"],["79770.90000000","0.02400000"],["79770.18000000","0.00000000"],["79764.41000000","0.02200000"],["79714.29000000","0.00000000"],["79699.03000000","0.00125000"],["78650.28000000","0.00030000"],["71863.20000000","0.00032000"]],"a":[["79848.01000000","6.92953000"],["79848.02000000","2.92657000"],["79848.03000000","0.00013000"],["79848.48000000","0.19378000"],["79849.99000000","0.51827000"],["79850.00000000","0.07514000"],["79850.01000000","1.01600000"],["79850.79000000","0.18232000"],["79851.29000000","0.00014000"],["79851.69000000","0.00007000"],["79851.70000000","0.00000000"],["79851.71000000","0.39150000"],["79851.72000000","0.53396000"],["79852.00000000","1.04034000"],["79852.11000000","0.05277000"],["79852.57000000","0.00000000"],["79852.75000000","0.02007000"],["79853.13000000","0.00715000"],["79853.85000000","0.00000000"],["79853.99000000","0.00013000"],["79854.04000000","0.02526000"],["79854.68000000","0.30425000"],["79854.97000000","1.34939000"],["79855.40000000","0.12522000"],["79855.59000000","0.30915000"],["79856.02000000","0.30007000"],["79856.29000000","0.00000000"],["79856.35000000","0.00000000"],["79856.99000000","0.02000000"],["79857.69000000","0.08576000"],["79857.98000000","0.00007000"],["79857.99000000","0.19019000"],["79858.40000000","0.00007000"],["79859.01000000","0.00000000"],["79859.41000000","0.02000000"],["79859.87000000","0.00000000"],["79860.08000000","0.62194000"],["79860.48000000","0.00007000"],["79861.66000000","0.03284000"],["79861.67000000","0.20250000"],["79873.05000000","0.00250000"],["79876.91000000","0.00000000"],["79878.81000000","0.00000000"],["79880.89000000","0.00400000"],["79888.00000000","0.03407000"],["79890.00000000","0.72400000"],["79890.16000000","0.25000000"],["79894.16000000","0.00000000"],["79923.38000000","0.00000000"],["79924.73000000","0.00000000"]]}}}
{"rx_ns": 13986991881900, "frame": {"stream":"btcusdt@depth@100ms","data":{"e":"depthUpdate","E":1787650982214,"s":"BTCUSDT","U":99118692288,"u":99118692374,"b":[["79848.00000000","0.02654000"],["79847.99000000","0.00104000"],["79847.54000000","0.00000000"],["79847.28000000","0.00000000"],["79846.82000000","0.00000000"],["79846.00000000","0.02421000"],["79845.54000000","0.00007000"],["79845.28000000","0.05162000"],["79844.82000000","0.00740000"],["79844.26000000","0.00000000"],["79844.00000000","0.02442000"],["79843.54000000","0.01233000"],["79842.98000000","0.00000000"],["79842.27000000","0.00007000"],["79842.26000000","0.01480000"],["79842.00000000","0.02421000"],["79841.70000000","0.06230000"],["79841.47000000","0.06230000"],["79841.46000000","0.33846000"],["79840.98000000","0.01480000"],["79840.44000000","0.06223000"],["79839.85000000","0.06209000"],["79836.79000000","0.00000000"],["79831.39000000","0.00000000"],["79831.37000000","0.00000000"],["79831.36000000","0.00250000"],["79831.00000000","0.00007000"],["79810.87000000","0.00000000"],["79764.41000000","0.00000000"],["79717.46000000","0.00000000"],["71863.20000000","0.00064000"],["63880.00000000","0.02101000"]],"a":[["79848.01000000","6.94198000"],["79848.48000000","0.19371000"],["79849.29000000","0.01897000"],["79850.33000000","0.36614000"],["79850.57000000","0.02276000"],["79851.72000000","0.53403000"],["79851.85000000","0.02276000"],["79856.97000000","0.02000000"],["79868.75000000","0.00000000"],["79876.81000000","0.00012000"],["79919.25000000","0.00000000"],["79927.83000000","0.00000000"],["79973.50000000","0.00031000"],["80083.43000000","0.00000000"],["80312.56000000","0.00000000"]]}}}
{"rx_ns": 13987091689400, "frame": {"stream":"btcusdt@depth@100ms","data":{"e":"depthUpdate","E":1787650982314,"s":"BTCUSDT","U":99118692375,"u":99118692428,"b":[["79848.00000000","0.02919000"],["79847.99000000","0.00097000"],["79845.28000000","0.05162000"],["79844.82000000","0.00754000"],["79844.00000000","0.02428000"],["79842.01000000","0.00014000"],["79841.47000000","0.06216000"],["79841.46000000","0.33832000"],["79840.44000000","0.06209000"],["79840.01000000","0.00272000"],["79834.03000000","0.00015000"],["79832.80000000","0.00007000"],["79832.03000000","0.00272000"],["79826.04000000","0.00125000"],["79824.04000000","0.00272000"],["79818.06000000","0.00015000"],["79816.06000000","0.00272000"],["79808.00000000","0.73407000"],["79543.11000000","0.00000000"],["79474.73000000","0.01516000"],["79435.12000000","0.00000000"],["79338.00000000","0.00000000"],["79101.56000000","0.01522000"],["79007.21000000","0.01522000"],["63891.00000000","0.00000000"]],"a":[["79848.01000000","7.28225000"],["79848.48000000","0.19385000"],["79849.29000000","0.01911000"],["79849.99000000","0.51841000"],["79850.33000000","0.36614000"],["79850.57000000","0.02290000"],["79850.79000000","0.18218000"],["79864.74000000","0.00007000"],["79920.84000000","0.00400000"],["79928.23000000","0.00000000"],["80566.63000000","0.00010000"]]}}}
{"rx_ns": 13987191682100, "frame": {"stream":"btcusdt@depth@100ms","data":{"e":"depthUpdate","E":1787650982414,"s":"BTCUSDT","U":99118692429,"u":99118692464,"b":[["79848.00000000","0.02891000"],["79844.00000000","0.02442000"],["79843.54000000","0.01247000"],["79831.36000000","0.00000000"],["79831.34000000","0.00000000"],["79831.33000000","0.00250000"],["79786.54000000","0.00335000"],["79784.46000000","0.00000000"],["79780.49000000","0.00313000"],["79764.46000000","0.00000000"],["79759.70000000","0.26658000"],["79759.69000000","0.62602000"],["79757.49000000","0.00000000"],["79714.51000000","0.00018000"],["79711.27000000","0.00000000"],["79700.53000000","0.00125000"],["71865.00000000","0.00000000"],["71864.99000000","0.00008000"],["71863.20000000","0.00096000"]],"a":[["79848.01000000","7.28094000"],["79849.99000000","0.72906000"],["79864.34000000","0.09662000"],["79915.00000000","0.00312000"],["79915.99000000","0.00312000"],["79919.32000000","0.00000000"],["79925.76000000","0.00000000"],["79930.31000000","0.00000000"],["79992.11000000","0.00000000"],["79994.54000000","0.00125000"],["79995.99000000","0.00125000"],["80009.99000000","0.00000000"],["80011.99000000","0.00000000"]]}}}
{"rx_ns": 13987292798700, "frame": {"stream":"btcusdt@depth@100ms","data":{"e":"depthUpdate","E":1787650982514,"s":"BTCUSDT","U":99118692465,"u":99118692482,"b":[["79848.00000000","0.02898000"],["79847.99000000","0.00104000"],["79842.34000000","0.00007000"],["79842.33000000","0.06210000"],["79839.86000000","0.00000000"],["79831.33000000","0.00000000"],["79831.32000000","0.00250000"],["79809.60000000","0.33839000"],["79742.38000000","0.00400000"],["71863.20000000","0.00112000"],["63878.40000000","0.00031000"]],"a":[["79848.01000000","7.21816000"],["79849.31000000","0.00007000"],["79927.05000000","0.00000000"]]}}}
{"rx_ns": 13987391719700, "frame": {"stream":"btcusdt@depth@100ms","data":{"e":"depthUpdate","E":1787650982614,"s":"BTCUSDT","U":99118692483,"u":99118692507,"b":[["79843.54000000","0.01247000"],["79842.33000000","0.06224000"],["79841.70000000","0.06216000"],["79832.32000000","0.00250000"],["79831.32000000","0.00000000"],["79769.64000000","0.12171000"],["71863.20000000","0.00128000"],["63878.40000000","0.00000000"]],"a":[["79856.00000000","1.15178000"],["79858.00000000","1.89577000"],["79860.00000000","0.11292000"],["79862.00000000","0.01900000"],["79864.00000000","0.01907000"],["79866.00000000","0.02300000"],["79920.00000000","1.01986000"]]}}}
{"rx_ns": 13987504640300, "frame": {"stream":"btcusdt@depth@100ms","data":{"e":"depthUpdate","E":1787650982714,"s":"BTCUSDT","U":99118692508,"u":99118692531,"b":[["79848.00000000","0.02704000"],["79838.55000000","0.00000000"],["79837.60000000","0.00000000"],["79836.05000000","0.00021000"],["79835.59000000","0.00037000"],["79832.32000000","0.00000000"],["79832.31000000","0.00250000"],["79814.22000000","0.00400000"],["79769.28000000","0.02000000"],["79767.94000000","0.02087000"],["79667.74000000","0.00000000"],["79650.12000000","0.02393000"],["79610.72000000","0.00771000"],["79599.03000000","0.00000000"],["71864.99000000","0.00000000"],["71863.20000000","0.00144000"]],"a":[["79848.01000000","7.21841000"],["79855.40000000","0.42522000"],["79856.02000000","0.00007000"],["79864.34000000","0.06878000"],["80012.15000000","0.02007000"],["80165.72000000","0.00000000"],["81045.74000000","0.00030000"]]}}}
{"rx_ns": 13987591437400, "frame": {"stream":"btcusdt@depth@100ms","data":{"e":"depthUpdate","E":1787650982814,"s":"BTCUSDT","U":99118692532,"u":99118692537,"b":[["79832.31000000","0.00000000"],["79832.30000000","0.00250000"],["79767.94000000","0.00000000"],["71863.20000000","0.00160000"]],"a":[]}}}
{"rx_ns": 13987691695200, "frame": {"stream":"btcusdt@depth@100ms","data":{"e":"depthUpdate","E":1787650982914,"s":"BTCUSDT","U":99118692538,"u":99118692558,"b":[["79848.00000000","0.02690000"],["79847.99000000","0.00097000"],["79843.54000000","0.01254000"],["79842.34000000","0.00000000"],["79842.33000000","0.00014000"],["79841.46000000","0.33832000"],["79840.45000000","0.00000000"],["79840.44000000","0.00000000"],["79840.00000000","0.02414000"],["79839.85000000","0.00007000"],["79837.92000000","0.00000000"],["79836.05000000","0.00000000"],["79832.30000000","0.00000000"],["79832.29000000","0.00000000"],["79769.24000000","0.02200000"]],"a":[["80032.10000000","0.00000000"],["80072.61000000","0.00400000"]]}}}
{"rx_ns": 13987791816400, "frame": {"stream":"btcusdt@depth20","data":{"lastUpdateId":99118692578,"bids":[["79848.00000000","0.02621000"],["79847.99000000","0.00097000"],["79847.98000000","0.00013000"],["79847.77000000","0.00007000"],["79846.75000000","0.00014000"],["79846.52000000","0.00007000"],["79846.05000000","0.00007000"],["79846.01000000","0.00007000"],["79846.00000000","0.02421000"],["79845.84000000","0.00007000"],["79845.54000000","0.00007000"],["79845.29000000","0.00007000"],["79845.28000000","0.05162000"],["79845.12000000","0.00007000"],["79844.82000000","0.00754000"],["79844.53000000","0.00007000"],["79844.01000000","0.00014000"],["79844.00000000","0.02442000"],["79843.88000000","0.00007000"],["79843.54000000","0.01254000"]],"asks":[["79848.01000000","7.21726000"],["79848.02000000","2.92657000"],["79848.03000000","0.00013000"],["79848.48000000","0.19385000"],["79849.29000000","0.01911000"],["79849.31000000","0.00007000"],["79849.71000000","0.00014000"],["79849.99000000","0.72906000"],["79850.00000000","0.07514000"],["79850.01000000","1.01600000"],["79850.05000000","0.00400000"],["79850.33000000","0.36614000"],["79850.57000000","0.02290000"],["79850.79000000","0.18218000"],["79850.87000000","0.04879000"],["79851.29000000","0.00014000"],["79851.69000000","0.00007000"],["79851.71000000","0.39150000"],["79851.72000000","0.53403000"],["79851.85000000","0.02276000"]]}}}
{"rx_ns": 13987791905800, "frame": {"stream":"btcusdt@depth@100ms","data":{"e":"depthUpdate","E":1787650983014,"s":"BTCUSDT","U":99118692559,"u":99118692578,"b":[["79848.00000000","0.02621000"],["79843.54000000","0.01254000"],["79842.33000000","0.00000000"],["79842.26000000","0.01494000"],["79837.29000000","0.06210000"],["79832.28000000","0.00250000"],["79822.33000000","0.00000000"],["79821.20000000","0.00626000"],["79778.19000000","0.00000000"],["79776.01000000","0.00312000"],["79700.52000000","0.00000000"],["79695.22000000","0.00125000"],["71863.20000000","0.00176000"],["71863.00000000","0.00020000"],["63878.40000000","0.00031000"]],"a":[["79848.01000000","7.21726000"]]}}}
{"rx_ns": 13987891309700, "frame": {"stream":"btcusdt@depth@100ms","data":{"e":"depthUpdate","E":1787650983114,"s":"BTCUSDT","U":99118692579,"u":99118692608,"b":[["79848.00000000","0.02453000"],["79847.99000000","0.00097000"],["79843.67000000","0.00000000"],["79843.66000000","0.00000000"],["79832.28000000","0.00000000"],["79832.27000000","0.00250000"],["79764.14000000","0.02087000"],["79763.72000000","0.00000000"],["79622.66000000","0.00400000"],["78650.28000000","0.00030000"],["71863.20000000","0.00184000"],["71863.00000000","0.00000000"],["63878.00000000","0.00226000"]],"a":[["79856.33000000","0.00007000"],["79859.38000000","1.41525000"],["79862.56000000","0.00007000"],["79963.38000000","0.00000000"]]}}}
{"rx_ns": 13987998130500, "frame": {"stream":"btcusdt@depth@100ms","data":{"e":"depthUpdate","E":1787650983214,"s":"BTCUSDT","U":99118692609,"u":99118692621,"b":[["79837.92000000","0.06210000"],["79832.27000000","0.00000000"],["79832.26000000","0.00250000"],["79764.14000000","0.00000000"],["79759.70000000","0.24504000"],["79747.41000000","0.00025000"],["71863.20000000","0.00184000"],["63878.40000000","0.00000000"],["63878.00000000","0.00026000"]],"a":[["79848.01000000","7.21601000"],["79947.03000000","0.00025000"]]}}}
{"rx_ns": 13988091933800, "frame": {"stream":"btcusdt@depth@100ms","data":{"e":"depthUpdate","E":1787650983314,"s":"BTCUSDT","U":99118692622,"u":99118692648,"b":[["79832.80000000","0.00007000"],["79832.26000000","0.00000000"],["79832.25000000","0.00250000"],["79814.22000000","0.00000000"],["79774.31000000","0.00000000"],["79742.38000000","0.00000000"],["79694.49000000","0.00000000"],["79622.66000000","0.00000000"],["79568.31000000","0.00000000"],["79507.19000000","0.01516000"],["71863.20000000","0.00200000"],["63878.00000000","0.00026000"]],"a":[["79864.74000000","0.00007000"],["79880.89000000","0.00000000"],["79920.84000000","0.00000000"],["79952.79000000","0.00000000"],["80000.72000000","0.00000000"],["80072.61000000","0.00000000"],["80082.43000000","0.00000000"]]}}}
{"rx_ns": 13988191373600, "frame": {"stream":"btcusdt@depth@100ms","data":{"e":"depthUpdate","E":1787650983414,"s":"BTCUSDT","U":99118692649,"u":99118692663,"b":[["79848.00000000","0.02453000"],["79847.99000000","0.00097000"],["79843.20000000","0.00000000"],["79843.19000000","0.00000000"],["79832.25000000","0.00000000"],["79832.24000000","0.00250000"],["71863.20000000","0.00216000"]],"a":[["79848.01000000","7.24106000"],["80082.31000000","0.07334000"]]}}}
{"rx_ns": 13988291233800, "frame": {"stream":"btcusdt@depth@100ms","data":{"e":"depthUpdate","E":1787650983514,"s":"BTCUSDT","U":99118692664,"u":99118692674,"b":[["79832.24000000","0.00000000"],["79832.23000000","0.00250000"],["79763.44000000","0.02087000"],["71863.20000000","0.00200000"],["63878.40000000","0.00031000"]],"a":[["79848.01000000","7.29103000"],["79949.00000000","0.00400000"]]}}}
{"rx_ns": 13988391493400, "frame": {"stream":"btcusdt@depth@100ms","data":{"e":"depthUpdate","E":1787650983614,"s":"BTCUSDT","U":99118692675,"u":99118692692,"b":[["79848.00000000","0.08240000"],["79847.99000000","0.00104000"],["79842.34000000","0.00007000"],["79842.33000000","0.06210000"],["79839.85000000","0.06217000"],["79838.55000000","0.05882000"],["79832.23000000","0.00000000"],["79832.22000000","0.00250000"],["79763.44000000","0.00000000"],["71863.20000000","0.00232000"],["63878.40000000","0.00000000"]],"a":[["79848.01000000","7.29116000"]]}}}
{"rx_ns": 13988495930700, "frame": {"stream":"btcusdt@depth@100ms","data":{"e":"depthUpdate","E":1787650983714,"s":"BTCUSDT","U":99118692693,"u":99118692717,"b":[["79848.00000000","0.08122000"],["79847.99000000","0.00111000"],["79843.54000000","0.01254000"],["79842.99000000","0.00000000"],["79842.74000000","0.00007000"],["79842.73000000","0.08240000"],["79842.27000000","0.00000000"],["79838.55000000","0.00000000"],["79832.22000000","0.00000000"],["79832.21000000","0.00250000"],["79738.61000000","0.00400000"],["73475.18000000","0.00014000"],["71863.20000000","0.00248000"]],"a":[["79848.01000000","7.31204000"],["81045.74000000","0.00030000"]]}}}
{"rx_ns": 13988595125600, "frame": {"stream":"btcusdt@depth@100ms","data":{"e":"depthUpdate","E":1787650983814,"s":"BTCUSDT","U":99118692718,"u":99118692738,"b":[["79848.00000000","0.08115000"],["79847.99000000","0.00104000"],["79843.54000000","0.01254000"],["79842.74000000","0.00000000"],["79842.73000000","0.00014000"],["79842.52000000","0.08122000"],["79842.27000000","0.00007000"],["79842.00000000","0.02407000"],["79832.21000000","0.00000000"],["79832.20000000","0.00250000"],["71863.20000000","0.00240000"],["71863.19000000","0.00008000"]],"a":[["79848.01000000","7.31434000"]]}}}
{"rx_ns": 13988692869200, "frame": {"stream":"btcusdt@depth@100ms","data":{"e":"depthUpdate","E":1787650983914,"s":"BTCUSDT","U":99118692739,"u":99118692760,"b":[["79848.00000000","0.08115000"],["79847.99000000","0.00104000"],["79843.54000000","0.01254000"],["79842.73000000","0.00000000"],["79842.53000000","0.00000000"],["79842.52000000","0.00014000"],["79842.27000000","0.00007000"],["79832.20000000","0.00000000"],["79832.19000000","0.00250000"],["79763.54000000","0.02087000"],["79618.89000000","0.00400000"],["71863.20000000","0.00256000"]],"a":[]}}}
{"rx_ns": 13988798490000, "frame": {"stream":"btcusdt@depth20","data":{"lastUpdateId":99118692781,"bids":[["79848.00000000","0.08122000"],["79847.99000000","0.00111000"],["79847.98000000","0.00013000"],["79847.77000000","0.00007000"],["79846.75000000","0.00014000"],["79846.52000000","0.00007000"],["79846.05000000","0.00007000"],["79846.01000000","0.00007000"],["79846.00000000","0.02421000"],["79845.84000000","0.00007000"],["79845.54000000","0.00007000"],["79845.29000000","0.00007000"],["79845.28000000","0.05162000"],["79845.12000000","0.00007000"],["79844.82000000","0.00754000"],["79844.53000000","0.00007000"],["79844.01000000","0.00014000"],["79844.00000000","0.02442000"],["79843.88000000","0.00007000"],["79843.54000000","0.01254000"]],"asks":[["79848.01000000","7.31434000"],["79848.02000000","2.92657000"],["79848.03000000","0.00013000"],["79848.48000000","0.19385000"],["79849.29000000","0.01911000"],["79849.31000000","0.00007000"],["79849.71000000","0.00014000"],["79849.99000000","0.72906000"],["79850.00000000","0.07514000"],["79850.01000000","1.01600000"],["79850.05000000","0.00400000"],["79850.33000000","0.36614000"],["79850.57000000","0.02290000"],["79850.79000000","0.18218000"],["79850.87000000","0.04879000"],["79851.29000000","0.00014000"],["79851.69000000","0.00007000"],["79851.71000000","0.39150000"],["79851.72000000","0.53403000"],["79851.85000000","0.02276000"]]}}}
{"rx_ns": 13988798578100, "frame": {"stream":"btcusdt@depth@100ms","data":{"e":"depthUpdate","E":1787650984015,"s":"BTCUSDT","U":99118692761,"u":99118692781,"b":[["79848.00000000","0.08122000"],["79847.99000000","0.00111000"],["79843.54000000","0.01254000"],["79842.78000000","0.00007000"],["79842.77000000","0.08115000"],["79842.52000000","0.00000000"],["79842.33000000","0.06224000"],["79842.27000000","0.00000000"],["79833.45000000","0.00250000"],["79832.19000000","0.00000000"],["79799.40000000","0.00000000"],["71863.20000000","0.00256000"],["63878.40000000","0.00031000"],["63878.00000000","0.00026000"]],"a":[]}}}
{"rx_ns": 13988891460700, "frame": {"stream":"btcusdt@depth@100ms","data":{"e":"depthUpdate","E":1787650984114,"s":"BTCUSDT","U":99118692782,"u":99118692805,"b":[["79848.00000000","0.08122000"],["79847.99000000","0.00111000"],["79843.54000000","0.01254000"],["79843.02000000","0.06217000"],["79843.01000000","0.08122000"],["79842.78000000","0.00000000"],["79842.77000000","0.00000000"],["79833.45000000","0.00000000"],["79833.44000000","0.00250000"],["79810.44000000","0.00400000"],["79763.54000000","0.00000000"],["78650.28000000","0.00030000"],["71863.20000000","0.00272000"]],"a":[["79854.25000000","0.00007000"],["79864.63000000","0.00007000"]]}}}
{"rx_ns": 13988991479500, "frame": {"stream":"btcusdt@depth@100ms","data":{"e":"depthUpdate","E":1787650984214,"s":"BTCUSDT","U":99118692806,"u":99118692828,"b":[["79848.00000000","0.08129000"],["79847.99000000","0.00118000"],["79843.59000000","0.06210000"],["79843.54000000","0.01254000"],["79843.03000000","0.00007000"],["79843.02000000","0.06231000"],["79842.26000000","0.01480000"],["79840.44000000","0.06210000"],["79839.85000000","0.06210000"],["79833.44000000","0.00000000"],["79833.41000000","0.00250000"],["73475.18000000","0.00000000"],["71863.00000000","0.00000000"],["63878.40000000","0.00000000"]],"a":[["79852.01000000","0.64230000"],["79864.55000000","0.00000000"],["80247.25000000","0.00132000"]]}}}
{"rx_ns": 13989091763600, "frame": {"stream":"btcusdt@depth@100ms","data":{"e":"depthUpdate","E":1787650984314,"s":"BTCUSDT","U":99118692829,"u":99118692884,"b":[["79848.00000000","0.31060000"],["79847.99000000","0.00132000"],["79844.82000000","0.00761000"],["79844.23000000","0.00007000"],["79844.22000000","0.06210000"],["79844.01000000","0.00007000"],["79844.00000000","0.02449000"],["79843.60000000","0.00007000"],["79843.59000000","0.06224000"],["79843.54000000","0.01261000"],["79842.33000000","0.06210000"],["79841.48000000","0.00026000"],["79841.47000000","0.06209000"],["79840.01000000","0.20522000"],["79840.00000000","0.02407000"],["79836.29000000","0.00000000"],["79835.59000000","0.00000000"],["79833.41000000","0.00000000"],["79832.80000000","0.00007000"],["79831.95000000","0.00250000"],["79799.40000000","0.00007000"],["79622.56000000","0.00007000"],["79618.57000000","0.00007000"],["71863.20000000","0.00288000"],["63878.00000000","0.00026000"]],"a":[["79848.01000000","7.31441000"],["79848.47000000","0.00000000"],["79848.48000000","0.00028000"],["79849.98000000","0.00007000"],["79850.00000000","0.07521000"],["79851.71000000","0.39157000"],["79851.99000000","0.00007000"],["79856.01000000","0.01921000"],["79856.02000000","0.00000000"],["79864.74000000","0.00007000"],["79870.00000000","0.82442000"],["80068.82000000","0.00400000"]]}}}
{"rx_ns": 13989191698200, "frame": {"stream":"btcusdt@depth@100ms","data":{"e":"depthUpdate","E":1787650984414,"s":"BTCUSDT","U":99118692885,"u":99118692923,"b":[["79844.82000000","0.00761000"],["79842.03000000","0.00000000"],["79831.95000000","0.00000000"],["79814.80000000","0.00000000"],["79799.40000000","0.00000000"],["79696.98000000","0.00000000"],["79618.57000000","0.00000000"],["71863.20000000","0.00288000"],["71863.19000000","0.00000000"]],"a":[["79848.01000000","7.31112000"],["79848.02000000","2.92657000"],["79848.48000000","0.00014000"],["79850.79000000","0.18232000"],["79851.99000000","0.00000000"],["79871.14000000","0.00000000"],["79884.03000000","0.00000000"],["79931.27000000","1.95361000"],["79945.22000000","0.80714000"],["79947.11000000","0.00000000"],["79975.76000000","0.00160000"],["80000.40000000","0.00000000"],["84200.00000000","1.16763000"],["84900.00000000","1.93377000"],["85600.00000000","0.32422000"],["86300.00000000","0.07177000"],["87000.00000000","19.18812000"]]}}}
{"rx_ns": 13989293947100, "frame": {"stream":"btcusdt@depth@100ms","data":{"e":"depthUpdate","E":1787650984514,"s":"BTCUSDT","U":99118692924,"u":99118692947,"b":[["79848.00000000","0.31059000"],["79813.62000000","0.09313000"],["79798.75000000","0.51006000"],["79713.33000000","0.00000000"],["79707.12000000","0.04535000"],["71863.20000000","0.00304000"],["63878.40000000","0.00031000"]],"a":[["79856.00000000","1.15236000"],["79858.00000000","1.90077000"],["79860.00000000","0.11792000"],["79862.00000000","0.02400000"],["79864.00000000","0.02407000"],["79864.34000000","0.01878000"],["79866.00000000","0.02800000"],["79874.42000000","0.00000000"],["79877.11000000","0.00400000"],["79883.03000000","0.00000000"],["79888.00000000","0.38121000"],["79888.28000000","0.09430000"],["79931.47000000","3.44030000"]]}}}
{"rx_ns": 13989397682800, "frame": {"stream":"btcusdt@depth@100ms","data":{"e":"depthUpdate","E":1787650984614,"s":"BTCUSDT","U":99118692948,"u":99118692953,"b":[["71863.20000000","0.00304000"],["63878.40000000","0.00000000"]],"a":[["80015.74000000","1.54773000"]]}}}
{"rx_ns": 13989491485600, "frame": {"stream":"btcusdt@depth@100ms","data":{"e":"depthUpdate","E":1787650984714,"s":"BTCUSDT","U":99118692954,"u":99118692976,"b":[["79848.00000000","0.61766000"],["79843.02000000","0.06238000"],["79843.01000000","0.00000000"],["79842.75000000","0.12533000"],["79839.85000000","0.00000000"],["79839.09000000","0.00706000"],["79837.23000000","0.00000000"],["79690.72000000","0.00400000"],["71863.20000000","0.00328000"]],"a":[["79848.01000000","7.27548000"],["79850.32000000","0.00007000"],["79851.99000000","0.00007000"],["79854.57000000","0.00374000"],["79855.91000000","0.00007000"],["81045.74000000","0.00030000"],["83500.00000000","22.06426000"]]}}}
{"rx_ns": 13989601119600, "frame": {"stream":"btcusdt@depth@100ms","data":{"e":"depthUpdate","E":1787650984814,"s":"BTCUSDT","U":99118692977,"u":99118693008,"b":[["79848.00000000","0.61759000"],["79847.99000000","0.00118000"],["79844.52000000","0.00007000"],["79844.23000000","0.00000000"],["79844.22000000","0.00014000"],["79843.02000000","0.06217000"],["79842.76000000","0.00000000"],["79842.75000000","0.00007000"],["79842.74000000","0.00000000"],["79840.44000000","0.00000000"],["79837.92000000","0.00000000"],["79837.29000000","0.00000000"],["79835.88000000","0.00000000"],["71863.20000000","0.00312000"]],"a":[["79851.71000000","0.39150000"],["79851.99000000","0.00000000"]]}}}
{"rx_ns": 13989691529400, "frame": {"stream":"btcusdt@depth@100ms","data":{"e":"depthUpdate","E":1787650984914,"s":"BTCUSDT","U":99118693009,"u":99118693027,"b":[["79848.00000000","0.61752000"],["79844.82000000","0.00754000"],["79844.22000000","0.00000000"],["79843.02000000","0.06231000"],["79842.75000000","0.00000000"],["79841.48000000","0.00033000"],["79835.40000000","0.06209000"],["79770.53000000","0.00400000"],["71863.20000000","0.00344000"]],"a":[["82800.00000000","12.33832000"]]}}}
{"rx_ns": 13989791649900, "frame": {"stream":"btcusdt@depth20","data":{"lastUpdateId":99118693039,"bids":[["79848.00000000","0.61759000"],["79847.99000000","0.00125000"],["79847.98000000","0.00013000"],["79847.77000000","0.00007000"],["79846.75000000","0.00014000"],["79846.52000000","0.00007000"],["79846.05000000","0.00007000"],["79846.01000000","0.00007000"],["79846.00000000","0.02421000"],["79845.84000000","0.00007000"],["79845.54000000","0.00007000"],["79845.29000000","0.00007000"],["79845.28000000","0.05162000"],["79845.12000000","0.00007000"],["79844.82000000","0.00754000"],["79844.53000000","0.00007000"],["79844.52000000","0.00007000"],["79844.01000000","0.00007000"],["79844.00000000","0.02449000"],["79843.88000000","0.00007000"]],"asks":[["79848.01000000","7.27548000"],["79848.02000000","2.92657000"],["79848.03000000","0.00013000"],["79848.48000000","0.00014000"],["79849.29000000","0.01911000"],["79849.31000000","0.00007000"],["79849.71000000","0.00014000"],["79849.98000000","0.00007000"],["79849.99000000","0.72906000"],["79850.00000000","0.07521000"],["79850.01000000","1.01600000"],["79850.05000000","0.00400000"],["79850.32000000","0.00007000"],["79850.33000000","0.36614000"],["79850.57000000","0.02290000"],["79850.79000000","0.18232000"],["79850.87000000","0.04879000"],["79851.29000000","0.00014000"],["79851.69000000","0.00007000"],["79851.71000000","0.39150000"]]}}}
{"rx_ns": 13989791743500, "frame": {"stream":"btcusdt@depth@100ms","data":{"e":"depthUpdate","E":1787650985014,"s":"BTCUSDT","U":99118693028,"u":99118693039,"b":[["79848.00000000","0.61759000"],["79847.99000000","0.00125000"],["79843.54000000","0.01268000"],["79843.05000000","0.00007000"],["79843.04000000","0.12533000"],["79825.86000000","0.09534000"],["79823.87000000","1.67142000"],["79813.63000000","1.04939000"],["79767.94000000","0.02087000"],["71863.20000000","0.00344000"],["63878.40000000","0.00031000"]],"a":[]}}}
{"rx_ns": 13989892189500, "frame": {"stream":"btcusdt@depth@100ms","data":{"e":"depthUpdate","E":1787650985115,"s":"BTCUSDT","U":99118693040,"u":99118693069,"b":[["79848.00000000","0.31034000"],["79847.99000000","0.00118000"],["79843.54000000","0.01261000"],["79843.05000000","0.00000000"],["79843.04000000","0.00000000"],["79842.51000000","0.00000000"],["79842.26000000","0.01494000"],["79842.25000000","0.12533000"],["79767.94000000","0.00000000"],["78650.28000000","0.00030000"],["71863.20000000","0.00344000"],["71863.00000000","0.00010000"]],"a":[["79852.18000000","0.00007000"],["79910.51000000","0.00007000"],["79996.93000000","0.00400000"],["82100.00000000","5.58858000"]]}}}
{"rx_ns": 13989995894800, "frame": {"stream":"btcusdt@depth@100ms","data":{"e":"depthUpdate","E":1787650985214,"s":"BTCUSDT","U":99118693070,"u":99118693087,"b":[["79848.00000000","0.64211000"],["79843.54000000","0.01261000"],["79842.26000000","0.01480000"],["79842.25000000","0.00000000"],["79841.98000000","0.00000000"],["71863.20000000","0.00368000"],["71863.19000000","0.00008000"],["71863.00000000","0.00000000"],["63878.40000000","0.00000000"]],"a":[["79848.01000000","7.27399000"]]}}}
{"rx_ns": 13990091433800, "frame": {"stream":"btcusdt@depth@100ms","data":{"e":"depthUpdate","E":1787650985314,"s":"BTCUSDT","U":99118693088,"u":99118693098,"b":[["79832.80000000","0.00000000"],["79767.94000000","0.02087000"],["71863.20000000","0.00368000"],["71863.00000000","0.00020000"],["63878.00000000","0.00026000"]],"a":[["79864.74000000","0.00000000"],["79917.05000000","0.00400000"],["80517.97000000","0.00074000"]]}}}
{"rx_ns": 13990191685500, "frame": {"stream":"btcusdt@depth@100ms","data":{"e":"depthUpdate","E":1787650985414,"s":"BTCUSDT","U":99118693099,"u":99118693147,"b":[["79848.00000000","0.26423000"],["79843.59000000","0.00014000"],["79843.02000000","0.00021000"],["79842.33000000","0.00000000"],["79841.70000000","0.00007000"],["79841.47000000","0.00000000"],["79832.80000000","0.00007000"],["79809.00000000","0.70000000"],["79808.00000000","0.03407000"],["71863.20000000","0.00384000"],["71863.00000000","0.00000000"],["63878.00000000","0.00326000"]],"a":[["79848.01000000","7.27406000"],["79849.98000000","0.00000000"],["79850.00000000","0.07514000"],["79850.32000000","0.00000000"],["79864.74000000","0.00007000"],["79917.05000000","0.00000000"],["81400.00000000","2.32827000"]]}}}
{"rx_ns": 13990291829800, "frame": {"stream":"btcusdt@depth@100ms","data":{"e":"depthUpdate","E":1787650985514,"s":"BTCUSDT","U":99118693148,"u":99118693223,"b":[["79848.00000000","0.24075000"],["79847.99000000","0.00097000"],["79844.00000000","0.02442000"],["79843.60000000","0.00000000"],["79843.59000000","0.00000000"],["79843.54000000","0.01261000"],["79843.03000000","0.00000000"],["79843.02000000","0.00000000"],["79842.34000000","0.00007000"],["79842.33000000","0.06209000"],["79842.27000000","0.00007000"],["79842.26000000","0.01494000"],["79842.00000000","0.02421000"],["79841.71000000","0.00007000"],["79841.70000000","0.06216000"],["79841.48000000","0.00033000"],["79841.47000000","0.06216000"],["79840.98000000","0.01494000"],["79840.45000000","0.00007000"],["79840.44000000","0.06216000"],["79840.02000000","0.06217000"],["79839.85000000","0.00000000"],["79839.44000000","0.00000000"],["79837.29000000","0.06209000"],["79799.40000000","0.00007000"],["79767.94000000","0.00000000"],["63878.40000000","0.00031000"],["63878.00000000","0.00026000"]],"a":[["79917.07000000","0.00400000"]]}}}
{"rx_ns": 13990392480500, "frame": {"stream":"btcusdt@depth@100ms","data":{"e":"depthUpdate","E":1787650985614,"s":"BTCUSDT","U":99118693224,"u":99118693254,"b":[["79848.00000000","0.24082000"],["79847.99000000","0.00104000"],["79843.54000000","0.01261000"],["79842.97000000","0.00007000"],["79842.96000000","0.06209000"],["79842.42000000","0.00000000"],["79842.41000000","0.00000000"],["79842.33000000","0.06223000"],["79842.27000000","0.00000000"],["79842.00000000","0.02407000"],["79840.45000000","0.00000000"],["71863.20000000","0.00400000"],["63878.40000000","0.00000000"],["63878.00000000","0.00226000"]],"a":[["79856.00000000","1.15041000"]]}}}
{"rx_ns": 13990496767700, "frame": {"stream":"btcusdt@depth@100ms","data":{"e":"depthUpdate","E":1787650985714,"s":"BTCUSDT","U":99118693255,"u":99118693272,"b":[["79848.00000000","0.23996000"],["79843.54000000","0.01261000"],["79767.94000000","0.02087000"],["71863.20000000","0.00400000"],["71863.19000000","0.00000000"],["71863.00000000","0.00000000"],["63878.00000000","0.00026000"]],"a":[["79848.01000000","7.27395000"],["79856.00000000","1.15741000"],["80700.00000000","1.40609000"],["81045.74000000","0.00030000"]]}}}
{"rx_ns": 13990591836000, "frame": {"stream":"btcusdt@depth@100ms","data":{"e":"depthUpdate","E":1787650985814,"s":"BTCUSDT","U":99118693273,"u":99118693280,"b":[["79801.55000000","0.00400000"],["79801.33000000","0.00000000"],["79767.94000000","0.00000000"],["71863.20000000","0.00416000"],["71863.00000000","0.00000000"],["63878.00000000","0.00026000"]],"a":[]}}}
{"rx_ns": 13990691407500, "frame": {"stream":"btcusdt@depth@100ms","data":{"e":"depthUpdate","E":1787650985914,"s":"BTCUSDT","U":99118693281,"u":99118693300,"b":[["79848.00000000","0.23951000"],["79847.99000000","0.00111000"],["79843.60000000","0.00007000"],["79843.59000000","0.05857000"],["79840.01000000","0.20467000"],["79832.03000000","0.00217000"],["79824.04000000","0.00217000"],["79816.06000000","0.00217000"],["79300.00000000","2.56424000"],["71863.20000000","0.00416000"],["71863.00000000","0.00010000"]],"a":[["79848.01000000","7.27440000"],["79927.99000000","1.72239000"]]}}}
{"rx_ns": 13990792384600, "frame": {"stream":"btcusdt@depth20","data":{"lastUpdateId":99118693319,"bids":[["79848.00000000","0.23958000"],["79847.99000000","0.00111000"],["79847.98000000","0.00013000"],["79847.77000000","0.00007000"],["79846.75000000","0.00014000"],["79846.52000000","0.00007000"],["79846.05000000","0.00007000"],["79846.01000000","0.00007000"],["79846.00000000","0.02421000"],["79845.84000000","0.00007000"],["79845.54000000","0.00007000"],["79845.29000000","0.00007000"],["79845.28000000","0.05162000"],["79845.12000000","0.00007000"],["79844.82000000","0.00754000"],["79844.53000000","0.00007000"],["79844.52000000","0.00007000"],["79844.01000000","0.00007000"],["79844.00000000","0.02442000"],["79843.88000000","0.00007000"]],"asks":[["79848.01000000","7.27440000"],["79848.02000000","2.92657000"],["79848.03000000","0.00013000"],["79848.48000000","0.00014000"],["79849.29000000","0.01911000"],["79849.31000000","0.00007000"],["79849.71000000","0.00014000"],["79849.99000000","0.72906000"],["79850.00000000","0.07514000"],["79850.01000000","1.01600000"],["79850.05000000","0.00400000"],["79850.33000000","0.36614000"],["79850.57000000","0.02290000"],["79850.79000000","0.18232000"],["79850.87000000","0.04879000"],["79851.29000000","0.00014000"],["79851.69000000","0.00007000"],["79851.71000000","0.39150000"],["79851.72000000","0.53403000"],["79851.85000000","0.02276000"]]}}}
{"rx_ns": 13990792476200, "frame": {"stream":"btcusdt@depth@100ms","data":{"e":"depthUpdate","E":1787650986014,"s":"BTCUSDT","U":99118693301,"u":99118693319,"b":[["79848.00000000","0.23958000"],["79844.00000000","0.02442000"],["79843.59000000","0.05871000"],["79842.83000000","0.00007000"],["79842.82000000","0.00000000"],["79842.26000000","0.01480000"],["79841.47000000","0.06209000"],["71863.20000000","0.00432000"],["71863.00000000","0.00010000"],["63878.40000000","0.00031000"]],"a":[]}}}
{"rx_ns": 13990891647900, "frame": {"stream":"btcusdt@depth@100ms","data":{"e":"depthUpdate","E":1787650986114,"s":"BTCUSDT","U":99118693320,"u":99118693326,"b":[["79848.00000000","0.23951000"],["79842.83000000","0.00000000"],["79794.08000000","0.00007000"],["79789.93000000","0.00007000"],["78650.28000000","0.00030000"],["71863.00000000","0.00000000"]],"a":[]}}}
{"rx_ns": 13990991336900, "kind": "control", "ctl": {"op": "ping", "recv_ns": 13990973690200, "pong_ns": 13990973834200, "payload_len": 13, "payload_b64": "MTc4NzY1MDk4NjE5MA=="}, "frame": null}
{"rx_ns": 13990991336900, "frame": {"stream":"btcusdt@depth@100ms","data":{"e":"depthUpdate","E":1787650986214,"s":"BTCUSDT","U":99118693327,"u":99118693332,"b":[["78600.00000000","5.61719000"],["71863.20000000","0.00448000"],["63878.40000000","0.00000000"]],"a":[["80566.63000000","0.00000000"]]}}}
{"rx_ns": 13991095923800, "frame": {"stream":"btcusdt@depth@100ms","data":{"e":"depthUpdate","E":1787650986314,"s":"BTCUSDT","U":99118693333,"u":99118693340,"b":[["79848.00000000","0.23913000"],["71863.20000000","0.00440000"],["63878.00000000","0.00026000"]],"a":[["80260.59000000","0.00000000"]]}}}
{"rx_ns": 13991191389100, "frame": {"stream":"btcusdt@depth@100ms","data":{"e":"depthUpdate","E":1787650986414,"s":"BTCUSDT","U":99118693341,"u":99118693357,"b":[["79848.00000000","0.23926000"],["79840.01000000","0.20482000"],["79832.80000000","0.00007000"],["79832.03000000","0.00232000"],["79824.04000000","0.00232000"],["79816.06000000","0.00000000"],["77900.00000000","2.44605000"],["71863.20000000","0.00424000"]],"a":[["79864.74000000","0.00007000"],["79884.28000000","0.00654000"]]}}}
{"rx_ns": 13991294048600, "frame": {"stream":"btcusdt@depth@100ms","data":{"e":"depthUpdate","E":1787650986514,"s":"BTCUSDT","U":99118693358,"u":99118693366,"b":[["79848.00000000","0.23601000"],["79816.06000000","0.00232000"],["71863.20000000","0.00440000"],["71863.00000000","0.00000000"],["63878.40000000","0.00031000"]],"a":[]}}}
{"rx_ns": 13991391926300, "frame": {"stream":"btcusdt@depth@100ms","data":{"e":"depthUpdate","E":1787650986614,"s":"BTCUSDT","U":99118693367,"u":99118693379,"b":[["79842.92000000","0.12533000"],["71863.20000000","0.00440000"],["63878.40000000","0.00000000"],["63878.00000000","0.00026000"]],"a":[["79888.28000000","0.00000000"],["79967.28000000","0.00394000"],["79992.85000000","0.00000000"]]}}}
{"rx_ns": 13991498917800, "frame": {"stream":"btcusdt@depth@100ms","data":{"e":"depthUpdate","E":1787650986714,"s":"BTCUSDT","U":99118693380,"u":99118693395,"b":[["79848.00000000","0.23601000"],["79842.96000000","0.06223000"],["79842.93000000","0.00000000"],["79842.92000000","0.00000000"],["79842.33000000","0.06209000"],["79810.00000000","0.82049000"],["79809.00000000","0.00000000"],["77200.00000000","1.38860000"],["71863.20000000","0.00440000"]],"a":[["81045.74000000","0.00030000"]]}}}
{"rx_ns": 13991597924500, "frame": {"stream":"btcusdt@depth@100ms","data":{"e":"depthUpdate","E":1787650986814,"s":"BTCUSDT","U":99118693396,"u":99118693433,"b":[["79848.00000000","0.23580000"],["79847.99000000","0.00097000"],["79842.96000000","0.06223000"],["79841.69000000","0.00000000"],["79841.46000000","0.00014000"],["79840.44000000","0.00007000"],["79840.01000000","0.00232000"],["79838.10000000","0.00007000"],["79837.29000000","0.06209000"],["79834.23000000","0.00007000"],["79830.36000000","0.00007000"],["79830.26000000","0.77317000"],["79829.30000000","0.00000000"],["79829.29000000","0.00000000"],["79828.79000000","0.00000000"],["79827.35000000","0.00000000"],["79826.49000000","0.00007000"],["79822.62000000","0.00007000"],["79814.34000000","0.02480000"],["79797.64000000","0.00000000"],["79763.45000000","0.04697000"],["71863.20000000","0.00440000"]],"a":[["79848.01000000","7.27238000"],["79849.27000000","0.03224000"]]}}}
{"rx_ns": 13991700789500, "frame": {"stream":"btcusdt@depth@100ms","data":{"e":"depthUpdate","E":1787650986914,"s":"BTCUSDT","U":99118693434,"u":99118695393,"b":[["79848.00000000","0.00000000"],["79847.99000000","0.00000000"],["79847.98000000","0.00000000"],["79847.77000000","0.00000000"],["79846.75000000","0.00000000"],["79846.52000000","0.00000000"],["79846.05000000","0.00000000"],["79846.01000000","0.00000000"],["79846.00000000","0.00000000"],["79845.99000000","0.00000000"],["79845.84000000","0.00000000"],["79845.54000000","0.00000000"],["79845.29000000","0.00000000"],["79845.28000000","0.00000000"],["79845.12000000","0.00000000"],["79844.82000000","0.00000000"],["79844.53000000","0.00000000"],["79844.52000000","0.00000000"],["79844.01000000","0.00000000"],["79844.00000000","0.00000000"],["79843.88000000","0.00000000"],["79843.60000000","0.00000000"],["79843.59000000","0.00000000"],["79843.55000000","0.00000000"],["79843.54000000","0.00000000"],["79843.27000000","0.00000000"],["79843.26000000","0.00000000"],["79842.97000000","0.00000000"],["79842.96000000","0.00000000"],["79842.79000000","0.00000000"],["79842.64000000","0.00000000"],["79842.34000000","0.00000000"],["79842.33000000","0.00000000"],["79842.27000000","0.00000000"],["79842.26000000","0.00000000"],["79842.02000000","0.00000000"],["79842.01000000","0.00000000"],["79842.00000000","0.00000000"],["79841.99000000","0.00000000"],["79841.97000000","0.00000000"],["79841.96000000","0.00000000"],["79841.71000000","0.00000000"],["79841.70000000","0.00000000"],["79841.48000000","0.00000000"],["79841.47000000","0.00000000"],["79841.46000000","0.00000000"],["79840.98000000","0.00000000"],["79840.97000000","0.00000000"],["79840.49000000","0.00000000"],["79840.44000000","0.00000000"],["79840.37000000","0.00000000"],["79840.18000000","0.00000000"],["79840.03000000","0.00000000"],["79840.02000000","0.00000000"],["79840.01000000","0.00000000"],["79840.00000000","0.00000000"],["79839.87000000","0.00000000"],["79839.86000000","0.00000000"],["79839.85000000","0.00000000"],["79839.84000000","0.00000000"],["79839.83000000","0.00000000"],["79839.73000000","0.00000000"],["79839.64000000","0.00000000"],["79839.44000000","0.00000000"],["79839.43000000","0.00000000"],["79839.09000000","0.00000000"],["79838.89000000","0.00000000"],["79838.88000000","0.00191000"],["79838.87000000","0.00049000"],["79838.77000000","0.00000000"],["79838.42000000","0.00000000"],["79838.38000000","0.00007000"],["79838.27000000","0.00000000"],["79838.23000000","0.00007000"],["79838.22000000","0.00000000"],["79838.10000000","0.00007000"],["79838.02000000","0.00000000"],["79838.01000000","0.00007000"],["79838.00000000","0.02407000"],["79837.92000000","0.00000000"],["79837.75000000","0.00007000"],["79837.58000000","0.00000000"],["79837.29000000","0.00000000"],["79837.22000000","0.00000000"],["79837.08000000","0.00000000"],["79837.04000000","0.00007000"],["79836.97000000","0.00000000"],["79836.88000000","0.00007000"],["79836.70000000","0.00000000"],["79836.69000000","0.00007000"],["79836.61000000","0.00000000"],["79836.57000000","0.00000000"],["79836.51000000","0.00000000"],["79836.41000000","0.00000000"],["79836.28000000","0.00007000"],["79836.13000000","0.05065000"],["79836.04000000","0.00000000"],["79836.03000000","0.00007000"],["79836.01000000","0.00007000"],["79836.00000000","0.02407000"],["79835.58000000","0.00007000"],["79835.41000000","0.00000000"],["79835.40000000","0.00000000"],["79835.26000000","0.00000000"],["79835.00000000","0.00000000"],["79834.71000000","0.00000000"],["79834.33000000","0.00000000"],["79834.30000000","0.00000000"],["79834.23000000","0.00007000"],["79834.04000000","0.00000000"],["79834.03000000","0.00007000"],["79834.01000000","0.00007000"],["79833.85000000","0.00007000"],["79833.84000000","0.02007000"],["79833.60000000","0.00000000"],["79833.51000000","0.00000000"],["79833.13000000","0.31323000"],["79833.12000000","0.00000000"],["79833.05000000","0.00007000"],["79833.04000000","0.00007000"],["79832.80000000","0.00000000"],["79832.45000000","0.00000000"],["79832.39000000","0.00007000"],["79832.38000000","0.00000000"],["79832.17000000","0.00007000"],["79832.16000000","0.00007000"],["79832.01000000","0.00007000"],["79832.00000000","0.02414000"],["79831.89000000","0.00007000"],["79831.88000000","0.00007000"],["79831.86000000","0.00008000"],["79831.81000000","0.00007000"],["79831.80000000","0.00000000"],["79831.79000000","0.00000000"],["79831.66000000","0.00000000"],["79831.51000000","0.00000000"],["79831.49000000","0.00000000"],["79831.36000000","0.00000000"],["79831.28000000","0.00000000"],["79831.06000000","0.00000000"],["79830.90000000","0.00000000"],["79830.37000000","0.00000000"],["79830.36000000","0.00007000"],["79830.28000000","0.00000000"],["79830.27000000","0.00000000"],["79830.26000000","0.00000000"],["79830.04000000","0.00000000"],["79830.03000000","0.00400000"],["79829.93000000","0.00000000"],["79829.85000000","0.00000000"],["79829.84000000","0.00000000"],["79829.83000000","0.00000000"],["79829.48000000","0.00000000"],["79829.28000000","0.00000000"],["79829.20000000","0.00007000"],["79829.14000000","0.02200000"],["79829.06000000","0.00000000"],["79828.48000000","0.00000000"],["79828.45000000","0.00695000"],["79828.28000000","0.00500000"],["79827.84000000","0.13376000"],["79827.83000000","0.00000000"],["79826.76000000","0.00000000"],["79826.75000000","0.00000000"],["79826.50000000","0.00626000"],["79826.49000000","0.00007000"],["79826.38000000","0.00250000"],["79826.31000000","0.00000000"],["79826.05000000","0.00000000"],["79826.04000000","0.00125000"],["79826.03000000","0.00008000"],["79826.01000000","0.00007000"],["79825.86000000","0.00000000"],["79825.68000000","0.00000000"],["79825.65000000","0.08566000"],["79825.46000000","0.00000000"],["79825.34000000","0.00000000"],["79825.06000000","0.00000000"],["79824.56000000","0.00000000"],["79824.50000000","0.00000000"],["79824.45000000","0.00714000"],["79823.98000000","0.15000000"],["79823.90000000","0.00000000"],["79823.88000000","0.00000000"],["79823.87000000","1.06493000"],["79823.86000000","0.00000000"],["79823.84000000","0.00000000"],["79823.50000000","0.00000000"],["79823.43000000","0.00000000"],["79823.24000000","0.00007000"],["79823.12000000","0.00007000"],["79822.92000000","0.00160000"],["79822.81000000","0.02254000"],["79822.63000000","0.00626000"],["79822.62000000","0.00014000"],["79822.05000000","0.00000000"],["79822.04000000","0.00000000"],["79821.20000000","0.00000000"],["79821.19000000","0.00000000"],["79821.18000000","0.00000000"],["79821.02000000","0.00008000"],["79820.45000000","0.00699000"],["79820.00000000","0.02400000"],["79819.89000000","0.00000000"],["79819.81000000","0.00000000"],["79818.76000000","0.00000000"],["79818.63000000","0.00000000"],["79818.62000000","0.00000000"],["79818.60000000","0.00000000"],["79818.06000000","0.00007000"],["79818.04000000","0.00000000"],["79817.69000000","1.87677000"],["79817.68000000","0.00000000"],["79817.67000000","0.00000000"],["79817.50000000","0.00000000"],["79817.03000000","0.00008000"],["79816.45000000","0.00689000"],["79816.44000000","0.00000000"],["79816.00000000","0.02407000"],["79815.91000000","0.00000000"],["79815.74000000","0.00000000"],["79815.51000000","0.00000000"],["79815.50000000","0.00000000"],["79814.07000000","0.00000000"],["79814.06000000","0.00000000"],["79813.62000000","0.00000000"],["79813.04000000","0.00008000"],["79812.53000000","0.00000000"],["79812.40000000","0.00000000"],["79812.27000000","0.00000000"],["79811.61000000","0.00626000"],["79811.36000000","0.00000000"],["79811.31000000","1.23349000"],["79810.61000000","0.00000000"],["79810.43000000","0.00100000"],["79810.29000000","0.42975000"],["79810.21000000","0.00000000"],["79810.08000000","0.00000000"],["79810.07000000","0.00000000"],["79810.00000000","0.11798000"],["79809.04000000","0.00008000"],["79808.00000000","0.02407000"],["79807.14000000","0.00014000"],["79806.63000000","0.62646000"],["79806.61000000","0.00125000"],["79806.08000000","0.00000000"],["79806.07000000","0.00008000"],["79806.05000000","0.00000000"],["79806.00000000","0.02400000"],["79805.31000000","0.00000000"],["79805.15000000","0.09469000"],["79803.27000000","0.00014000"],["79802.08000000","0.00008000"],["79802.03000000","0.04407000"],["79802.00000000","0.02400000"],["79801.00000000","0.00000000"],["79800.01000000","0.62672000"],["79799.95000000","0.33843000"],["79799.48000000","0.00000000"],["79799.40000000","0.00414000"],["79799.04000000","0.00000000"],["79799.00000000","0.00000000"],["79798.00000000","0.03400000"],["79797.25000000","0.00400000"],["79796.44000000","0.00000000"],["79795.53000000","0.00007000"],["79795.10000000","0.00400000"],["79791.66000000","0.00007000"],["79791.03000000","0.00007000"],["79787.79000000","0.00007000"],["79786.54000000","0.00000000"],["79780.49000000","0.00000000"],["79778.97000000","0.00000000"],["79777.04000000","0.00000000"],["79776.01000000","0.00000000"],["79773.84000000","0.02551000"],["79773.48000000","0.00313000"],["79772.69000000","0.02561000"],["79772.01000000","0.00310000"],["79770.54000000","0.00313000"],["79769.64000000","0.00000000"],["79768.83000000","0.00000000"],["79768.15000000","0.00000000"],["79767.18000000","0.00000000"],["79767.06000000","0.00000000"],["79766.29000000","0.00000000"],["79765.49000000","0.00000000"],["79764.12000000","0.00000000"],["79762.49000000","1.24150000"],["79761.45000000","0.00000000"],["79760.29000000","1.04939000"],["79760.00000000","0.02633000"],["79759.70000000","0.07971000"],["79759.69000000","0.00000000"],["79757.05000000","0.00000000"],["79748.05000000","2.32384000"],["79747.75000000","0.07560000"],["79731.51000000","1.87677000"],["79726.70000000","1.03802000"],["79717.53000000","0.20250000"],["79694.96000000","0.00000000"],["79690.36000000","0.36586000"],["79686.31000000","0.00008000"],["79681.94000000","0.36586000"],["79618.99000000","0.00025000"],["79615.11000000","0.00000000"],["79615.00000000","0.00007000"],["79606.46000000","0.00008000"],["79535.25000000","0.00000000"],["79530.55000000","0.00000000"],["79530.12000000","0.00000000"],["79526.62000000","0.00008000"],["79521.47000000","0.00000000"],["79495.59000000","1.74255000"],["79455.40000000","0.00000000"],["79446.77000000","0.00008000"],["79441.92000000","0.00014000"],["79375.54000000","0.00000000"],["79366.92000000","0.00008000"],["79295.69000000","0.00000000"],["79287.08000000","0.00008000"],["79211.97000000","0.00000000"],["79203.28000000","0.00008000"],["78650.28000000","0.00000000"],["76500.00000000","17.94797000"],["71863.20000000","0.00000000"],["71863.19000000","0.00008000"],["71861.40000000","0.00000000"],["63878.00000000","0.00326000"]],"a":[["79838.89000000","9.66882000"],["79838.90000000","2.29172000"],["79838.91000000","0.00013000"],["79838.92000000","0.00000000"],["79838.93000000","0.00400000"],["79839.08000000","0.00000000"],["79839.09000000","0.00000000"],["79839.10000000","0.00021000"],["79839.42000000","0.00000000"],["79839.44000000","0.00000000"],["79839.64000000","0.00000000"],["79839.65000000","0.10682000"],["79839.66000000","0.00000000"],["79839.74000000","0.00000000"],["79839.83000000","0.07500000"],["79839.84000000","0.00000000"],["79839.85000000","0.06046000"],["79839.86000000","0.00000000"],["79839.87000000","0.00000000"],["79840.01000000","0.00007000"],["79840.02000000","0.00000000"],["79840.03000000","0.00000000"],["79840.25000000","0.00400000"],["79840.38000000","0.00000000"],["79840.45000000","0.00000000"],["79840.50000000","0.00000000"],["79840.91000000","0.00000000"],["79840.98000000","0.07500000"],["79840.99000000","0.57466000"],["79841.00000000","0.00000000"],["79841.01000000","0.00000000"],["79841.14000000","0.04019000"],["79841.45000000","0.00000000"],["79841.47000000","0.00000000"],["79841.48000000","0.00007000"],["79841.49000000","0.00000000"],["79841.64000000","0.00156000"],["79841.71000000","0.04963000"],["79841.72000000","0.00000000"],["79841.97000000","0.00014000"],["79841.98000000","0.00000000"],["79842.00000000","0.00000000"],["79842.01000000","0.00000000"],["79842.02000000","1.41525000"],["79842.03000000","0.00021000"],["79842.25000000","0.00000000"],["79842.27000000","0.20278000"],["79842.33000000","0.00000000"],["79842.34000000","0.00014000"],["79842.40000000","0.00400000"],["79842.66000000","0.00000000"],["79842.77000000","0.03224000"],["79842.91000000","0.00007000"],["79842.97000000","0.00000000"],["79843.27000000","0.00000000"],["79843.39000000","0.12524000"],["79843.55000000","0.00000000"],["79843.60000000","0.00000000"],["79843.80000000","0.00000000"],["79843.89000000","0.00000000"],["79844.01000000","0.06571000"],["79844.02000000","0.09630000"],["79844.04000000","0.02000000"],["79844.54000000","0.00000000"],["79844.55000000","0.00400000"],["79844.58000000","0.00008000"],["79844.83000000","0.00007000"],["79845.13000000","0.00000000"],["79845.17000000","0.00000000"],["79845.29000000","0.00014000"],["79845.30000000","0.00000000"],["79845.55000000","0.00000000"],["79845.80000000","0.00000000"],["79845.84000000","0.00014000"],["79845.85000000","0.00000000"],["79845.97000000","0.00007000"],["79845.98000000","0.00000000"],["79846.00000000","0.07507000"],["79846.01000000","1.30087000"],["79846.02000000","0.00000000"],["79846.03000000","0.00000000"],["79846.06000000","0.00000000"],["79846.24000000","0.04019000"],["79846.64000000","0.00000000"],["79846.70000000","0.00400000"],["79846.76000000","0.00000000"],["79846.97000000","0.00000000"],["79847.27000000","0.00000000"],["79847.58000000","0.00007000"],["79847.78000000","0.00000000"],["79847.83000000","0.00008000"],["79847.90000000","0.00000000"],["79847.99000000","0.00000000"],["79848.00000000","3.24522000"],["79848.01000000","0.49617000"],["79848.02000000","1.04939000"],["79848.03000000","0.00000000"],["79848.31000000","0.00026000"],["79848.85000000","0.00000000"],["79849.27000000","0.03224000"],["79849.29000000","0.01897000"],["79849.31000000","0.00000000"],["79849.82000000","0.00007000"],["79849.99000000","0.25505000"],["79850.00000000","0.00000000"],["79850.01000000","0.97030000"],["79850.31000000","0.08576000"],["79850.32000000","0.00626000"],["79850.33000000","0.36600000"],["79850.57000000","0.02276000"],["79850.77000000","0.00007000"],["79850.79000000","0.18204000"],["79850.87000000","0.00000000"],["79851.29000000","0.00000000"],["79851.69000000","0.00000000"],["79851.71000000","0.10459000"],["79851.72000000","0.34970000"],["79852.00000000","0.96527000"],["79852.01000000","0.35616000"],["79852.02000000","0.30171000"],["79852.10000000","0.00000000"],["79852.11000000","0.00000000"],["79852.64000000","0.02000000"],["79852.75000000","0.00000000"],["79852.85000000","0.00007000"],["79853.04000000","0.01000000"],["79853.07000000","0.33820000"],["79853.34000000","0.00000000"],["79853.87000000","0.00010000"],["79853.96000000","0.00007000"],["79853.99000000","0.00000000"],["79854.01000000","0.00000000"],["79854.04000000","0.00000000"],["79854.14000000","0.62646000"],["79854.15000000","0.30000000"],["79854.28000000","0.00007000"],["79854.57000000","0.30374000"],["79854.62000000","0.00000000"],["79854.68000000","0.30000000"],["79854.88000000","0.00000000"],["79854.95000000","0.00007000"],["79855.40000000","0.30000000"],["79855.59000000","0.00915000"],["79855.91000000","0.00000000"],["79855.99000000","0.00000000"],["79856.01000000","0.00000000"],["79856.72000000","0.62628000"],["79856.80000000","0.09530000"],["79856.96000000","0.00008000"],["79857.13000000","0.00000000"],["79857.15000000","0.00000000"],["79857.69000000","0.00000000"],["79857.95000000","0.04522000"],["79857.99000000","0.00000000"],["79858.01000000","0.00000000"],["79858.79000000","0.10377000"],["79859.02000000","0.00000000"],["79859.70000000","0.33817000"],["79860.00000000","0.12043000"],["79860.34000000","0.12000000"],["79860.46000000","0.00000000"],["79860.95000000","0.00008000"],["79861.01000000","0.00000000"],["79861.63000000","0.00000000"],["79861.65000000","0.00000000"],["79861.98000000","0.00007000"],["79863.23000000","0.00125000"],["79863.53000000","0.00000000"],["79864.25000000","0.00000000"],["79864.32000000","0.00000000"],["79864.33000000","1.04939000"],["79864.74000000","0.00000000"],["79864.80000000","0.00000000"],["79864.94000000","0.00008000"],["79865.93000000","0.00000000"],["79865.97000000","0.00007000"],["79865.98000000","0.00000000"],["79867.39000000","0.00000000"],["79867.92000000","0.00000000"],["79868.93000000","0.00008000"],["79869.31000000","0.00000000"],["79869.96000000","0.00000000"],["79869.97000000","0.00000000"],["79871.43000000","0.09373000"],["79872.26000000","0.00000000"],["79872.75000000","0.00000000"],["79872.91000000","0.00000000"],["79872.93000000","0.00022000"],["79873.05000000","0.00000000"],["79873.36000000","0.00000000"],["79873.96000000","0.00000000"],["79873.97000000","1.87677000"],["79874.44000000","0.00000000"],["79874.64000000","0.65378000"],["79875.84000000","0.00000000"],["79876.61000000","0.00000000"],["79876.92000000","0.00008000"],["79877.15000000","0.00000000"],["79877.55000000","1.23971000"],["79877.60000000","0.00000000"],["79877.62000000","0.00573000"],["79877.95000000","0.00000000"],["79877.96000000","0.00000000"],["79879.18000000","0.10000000"],["79879.30000000","0.00000000"],["79879.79000000","0.00000000"],["79879.80000000","0.00000000"],["79880.67000000","0.00000000"],["79880.91000000","0.00008000"],["79881.94000000","0.00007000"],["79881.95000000","0.00000000"],["79884.54000000","0.00000000"],["79884.57000000","0.00000000"],["79885.93000000","0.00000000"],["79885.94000000","0.00000000"],["79886.12000000","0.00000000"],["79887.40000000","0.00000000"],["79887.98000000","0.82795000"],["79888.00000000","0.37121000"],["79888.22000000","0.82297000"],["79889.94000000","0.00000000"],["79890.16000000","0.00000000"],["79892.58000000","0.00000000"],["79893.66000000","0.00000000"],["79900.97000000","0.00000000"],["79901.79000000","0.82283000"],["79903.67000000","0.00000000"],["79905.99000000","0.00196000"],["79908.25000000","0.00000000"],["79909.97000000","0.00270000"],["79910.33000000","0.00000000"],["79910.51000000","0.00000000"],["79911.96000000","0.00667000"],["79912.71000000","0.00000000"],["79919.69000000","0.00008000"],["79920.00000000","1.01979000"],["79920.71000000","0.00000000"],["79923.80000000","0.00000000"],["79927.86000000","0.00000000"],["79947.63000000","0.65807000"],["79947.64000000","0.00000000"],["79999.53000000","0.00008000"],["80007.71000000","0.00000000"],["80024.59000000","3.74980000"],["80060.49000000","0.00000000"],["80062.78000000","0.00000000"],["80065.13000000","0.00000000"],["80079.37000000","0.00008000"],["80087.55000000","0.00000000"],["80097.76000000","0.01898000"],["80149.12000000","0.00000000"],["80162.80000000","0.00000000"],["80228.17000000","0.00000000"],["80238.59000000","0.00626000"],["80239.05000000","0.00008000"],["80241.11000000","0.00626000"],["80247.25000000","0.00124000"],["80263.23000000","0.00000000"],["80265.44000000","0.00000000"],["80398.73000000","0.00008000"],["80404.43000000","0.00000000"],["80406.95000000","0.00000000"],["80478.57000000","0.00008000"],["80486.79000000","0.00000000"],["81045.74000000","0.00000000"]]}}}
{"rx_ns": 13991795861500, "frame": {"stream":"btcusdt@depth20","data":{"lastUpdateId":99118695985,"bids":[["79838.00000000","0.02564000"],["79837.99000000","0.00077000"],["79837.75000000","0.00007000"],["79837.04000000","0.00007000"],["79836.88000000","0.00007000"],["79836.69000000","0.00007000"],["79836.28000000","0.00007000"],["79836.13000000","0.00014000"],["79836.03000000","0.00007000"],["79836.01000000","0.00007000"],["79836.00000000","0.02442000"],["79835.25000000","0.00007000"],["79835.24000000","0.05065000"],["79834.88000000","0.00007000"],["79834.52000000","0.00647000"],["79834.23000000","0.00007000"],["79834.16000000","0.00026000"],["79834.01000000","0.00007000"],["79834.00000000","0.02414000"],["79833.85000000","0.00007000"]],"asks":[["79838.01000000","8.14898000"],["79838.02000000","0.00027000"],["79838.03000000","0.00013000"],["79838.10000000","0.00414000"],["79838.11000000","0.00007000"],["79838.24000000","0.00007000"],["79838.39000000","0.00007000"],["79838.64000000","0.00007000"],["79838.77000000","0.00007000"],["79838.88000000","0.07500000"],["79838.89000000","2.64684000"],["79838.90000000","0.18512000"],["79838.93000000","0.00400000"],["79839.10000000","0.00007000"],["79839.65000000","0.10487000"],["79839.83000000","0.07514000"],["79839.85000000","0.84067000"],["79840.01000000","0.00007000"],["79840.25000000","0.00400000"],["79840.82000000","0.04956000"]]}}}
{"rx_ns": 13991796149400, "frame": {"stream":"btcusdt@depth@100ms","data":{"e":"depthUpdate","E":1787650987014,"s":"BTCUSDT","U":99118695394,"u":99118695985,"b":[["79838.88000000","0.00000000"],["79838.87000000","0.00000000"],["79838.76000000","0.00000000"],["79838.38000000","0.00000000"],["79838.23000000","0.00000000"],["79838.10000000","0.00000000"],["79838.08000000","0.00000000"],["79838.01000000","0.00000000"],["79838.00000000","0.02564000"],["79837.99000000","0.00077000"],["79837.68000000","0.00000000"],["79837.65000000","0.00000000"],["79836.14000000","0.00000000"],["79836.13000000","0.00014000"],["79836.00000000","0.02442000"],["79835.58000000","0.00000000"],["79835.25000000","0.00007000"],["79835.24000000","0.05065000"],["79834.52000000","0.00647000"],["79834.16000000","0.00026000"],["79834.03000000","0.00000000"],["79834.00000000","0.02414000"],["79833.84000000","0.02035000"],["79833.38000000","0.00000000"],["79833.24000000","0.01079000"],["79833.14000000","0.00007000"],["79833.13000000","0.31337000"],["79833.05000000","0.00000000"],["79832.17000000","0.00000000"],["79832.00000000","0.02435000"],["79831.96000000","0.01302000"],["79831.89000000","0.00000000"],["79831.88000000","0.00000000"],["79831.82000000","0.00000000"],["79831.81000000","0.00000000"],["79831.69000000","0.00000000"],["79830.68000000","0.01295000"],["79830.35000000","0.00000000"],["79830.26000000","0.00007000"],["79830.03000000","0.00000000"],["79830.00000000","0.02431000"],["79829.88000000","0.00000000"],["79829.68000000","0.00000000"],["79829.58000000","0.00935000"],["79829.14000000","0.00000000"],["79828.61000000","0.00000000"],["79828.45000000","0.00000000"],["79828.44000000","0.00000000"],["79828.00000000","0.02407000"],["79827.99000000","0.00695000"],["79827.85000000","0.00000000"],["79827.84000000","0.00000000"],["79826.93000000","0.33829000"],["79826.68000000","0.00202000"],["79826.50000000","0.00000000"],["79826.03000000","0.00000000"],["79826.01000000","0.04350000"],["79825.65000000","0.00000000"],["79823.98000000","0.00000000"],["79823.87000000","0.18979000"],["79823.82000000","0.08566000"],["79823.68000000","0.00007000"],["79823.25000000","0.00010000"],["79823.08000000","0.07000000"],["79822.93000000","0.00012000"],["79822.91000000","0.00069000"],["79822.63000000","0.00000000"],["79822.62000000","0.00014000"],["79822.50000000","0.00000000"],["79822.17000000","0.00000000"],["79822.03000000","0.00008000"],["79821.29000000","0.00000000"],["79821.28000000","0.08000000"],["79821.06000000","0.00626000"],["79820.93000000","0.00000000"],["79820.61000000","0.00000000"],["79820.10000000","0.00000000"],["79820.01000000","0.06210000"],["79819.39000000","0.00048000"],["79819.35000000","0.06210000"],["79818.83000000","0.00048000"],["79818.76000000","0.00626000"],["79818.72000000","0.06210000"],["79818.63000000","0.00000000"],["79818.62000000","0.00000000"],["79818.16000000","0.00187000"],["79816.88000000","0.02400000"],["79816.79000000","0.00059000"],["79814.86000000","0.00012000"],["79814.49000000","0.09535000"],["79812.50000000","0.10383000"],["79812.31000000","0.00191000"],["79811.61000000","0.00000000"],["79811.31000000","0.92509000"],["79810.44000000","0.00000000"],["79810.29000000","0.00000000"],["79808.58000000","0.00626000"],["79807.69000000","0.33852000"],["79806.65000000","0.42977000"],["79806.64000000","0.71062000"],["79806.63000000","0.00000000"],["79806.62000000","0.00000000"],["79806.07000000","0.00000000"],["79805.65000000","0.00400000"],["79805.15000000","0.00000000"],["79804.45000000","0.00007000"],["79804.21000000","0.00000000"],["79803.83000000","0.00000000"],["79803.54000000","0.62651000"],["79803.53000000","0.09635000"],["79802.08000000","0.00000000"],["79802.07000000","0.00008000"],["79800.12000000","0.00000000"],["79800.00000000","0.92269000"],["79798.08000000","0.00008000"],["79797.90000000","0.00000000"],["79790.80000000","0.00400000"],["79790.26000000","0.00000000"],["79788.65000000","0.00400000"],["79788.42000000","0.00072000"],["79787.70000000","0.00014000"],["79786.38000000","0.00000000"],["79784.21000000","0.00000000"],["79783.59000000","0.18666000"],["79783.58000000","0.00000000"],["79783.47000000","0.00000000"],["79780.09000000","0.00000000"],["79779.47000000","1.20785000"],["79778.62000000","0.00000000"],["79778.02000000","0.00000000"],["79773.34000000","0.00625000"],["79771.95000000","0.00008000"],["79770.53000000","0.00000000"],["79769.72000000","0.00431000"],["79769.27000000","0.00434000"],["79765.74000000","0.00400000"],["79764.47000000","0.02400000"],["79762.27000000","0.91946000"],["79761.14000000","0.00000000"],["79760.71000000","0.00000000"],["79760.56000000","0.00000000"],["79760.34000000","0.00000000"],["79760.16000000","0.00390000"],["79760.02000000","0.00000000"],["79759.92000000","0.00000000"],["79759.70000000","0.11353000"],["79759.60000000","0.00544000"],["79759.54000000","0.00110000"],["79759.29000000","0.00000000"],["79759.04000000","0.00000000"],["79758.88000000","0.00000000"],["79758.58000000","0.00000000"],["79758.48000000","0.12380000"],["79757.59000000","0.01710000"],["79748.06000000","0.89737000"],["79747.89000000","0.00000000"],["79738.61000000","0.00000000"],["79733.82000000","0.00400000"],["79732.01000000","0.58521000"],["79724.01000000","0.02498000"],["79719.13000000","0.09012000"],["79700.36000000","0.00000000"],["79692.27000000","0.00654000"],["79690.72000000","0.00000000"],["79685.94000000","0.00400000"],["79641.59000000","0.00000000"],["79618.89000000","0.00000000"],["79614.11000000","0.00408000"],["79611.97000000","0.00007000"],["79607.98000000","0.00000000"],["79602.30000000","2.84409000"],["79596.50000000","0.00007000"],["79554.18000000","0.00000000"],["79509.62000000","0.00034000"],["79481.45000000","0.02354000"],["71854.20000000","0.00016000"],["63878.00000000","0.00026000"],["63870.40000000","0.00031000"]],"a":[["79838.01000000","8.14898000"],["79838.02000000","0.00027000"],["79838.03000000","0.00013000"],["79838.10000000","0.00414000"],["79838.11000000","0.00007000"],["79838.24000000","0.00007000"],["79838.39000000","0.00007000"],["79838.64000000","0.00007000"],["79838.77000000","0.00007000"],["79838.88000000","0.07500000"],["79838.89000000","2.64684000"],["79838.90000000","0.18512000"],["79838.91000000","0.00000000"],["79839.10000000","0.00007000"],["79839.65000000","0.10487000"],["79839.83000000","0.07514000"],["79839.85000000","0.84067000"],["79840.30000000","0.00000000"],["79840.82000000","0.04956000"],["79840.97000000","0.26277000"],["79840.98000000","0.07514000"],["79840.99000000","0.57233000"],["79841.14000000","0.04033000"],["79841.48000000","0.00000000"],["79841.64000000","0.00000000"],["79841.71000000","0.00000000"],["79842.03000000","0.00007000"],["79842.27000000","0.20264000"],["79842.34000000","0.00000000"],["79842.77000000","0.03231000"],["79843.39000000","0.12531000"],["79844.02000000","0.09637000"],["79844.04000000","0.02007000"],["79844.99000000","0.00701000"],["79845.29000000","0.00007000"],["79846.00000000","0.00007000"],["79846.01000000","1.15276000"],["79848.01000000","0.48458000"],["79848.48000000","0.08576000"],["79849.29000000","0.00000000"],["79849.99000000","0.25498000"],["79850.00000000","0.09393000"],["79850.01000000","0.97023000"],["79850.31000000","0.00000000"],["79850.33000000","0.36586000"],["79850.57000000","0.00000000"],["79850.69000000","0.62651000"],["79850.70000000","0.09531000"],["79850.79000000","0.00000000"],["79851.85000000","0.00000000"],["79852.01000000","0.35603000"],["79852.02000000","0.00000000"],["79852.70000000","0.10377000"],["79854.14000000","0.00000000"],["79854.75000000","0.02480000"],["79855.62000000","0.00007000"],["79856.80000000","0.00000000"],["79857.44000000","0.42977000"],["79858.79000000","0.00000000"],["79860.08000000","0.43441000"],["79865.33000000","0.00000000"],["79866.54000000","0.00000000"],["79868.13000000","0.00000000"],["79868.28000000","0.00012000"],["79870.00000000","0.82191000"],["79872.00000000","0.02407000"],["79874.88000000","0.00629000"],["79875.38000000","0.00427000"],["79876.24000000","0.00436000"],["79876.76000000","0.00438000"],["79877.11000000","0.00000000"],["79879.00000000","0.01000000"],["79880.00000000","0.02400000"],["79886.00000000","0.02400000"],["79887.57000000","0.00000000"],["79887.73000000","0.00000000"],["79888.74000000","0.00000000"],["79889.68000000","0.00000000"],["79890.07000000","0.00000000"],["79901.73000000","0.01719000"],["79903.91000000","0.00536000"],["79904.10000000","0.00000000"],["79907.37000000","0.00111000"],["79912.26000000","0.00400000"],["79916.73000000","0.03224000"],["79917.07000000","0.00000000"],["79918.82000000","0.00000000"],["79918.86000000","0.09167000"],["79921.78000000","0.12276000"],["79931.01000000","0.25000000"],["79937.94000000","0.00000000"],["79939.20000000","0.00000000"],["79945.22000000","0.11689000"],["79946.18000000","0.00000000"],["79948.78000000","0.00000000"],["79949.00000000","0.00000000"],["79965.63000000","0.00000000"],["79992.13000000","0.00400000"],["79996.93000000","0.00000000"],["80049.32000000","0.07334000"],["80068.82000000","0.00000000"],["80071.42000000","0.00017000"],["80073.59000000","0.00000000"],["80075.41000000","0.00007000"],["80077.58000000","0.00019000"],["80080.83000000","0.00000000"],["80082.31000000","0.00000000"],["80114.87000000","0.02417000"],["80117.81000000","0.00000000"],["80175.24000000","0.00000000"]]}}}
{"rx_ns": 13991891560200, "frame": {"stream":"btcusdt@depth@100ms","data":{"e":"depthUpdate","E":1787650987114,"s":"BTCUSDT","U":99118695986,"u":99118696123,"b":[["79838.00000000","0.02778000"],["79837.99000000","0.00077000"],["79836.13000000","0.00000000"],["79836.00000000","0.02442000"],["79835.24000000","0.05079000"],["79834.52000000","0.00661000"],["79833.84000000","0.02035000"],["79833.24000000","0.01093000"],["79833.14000000","0.06222000"],["79832.02000000","0.00013000"],["79832.00000000","0.02435000"],["79831.96000000","0.01309000"],["79831.71000000","0.00007000"],["79831.70000000","0.06222000"],["79831.08000000","0.00007000"],["79831.07000000","0.06215000"],["79830.45000000","0.00007000"],["79830.44000000","0.06215000"],["79830.26000000","0.06222000"],["79826.68000000","0.00000000"],["79826.01000000","0.09365000"],["79825.40000000","0.06215000"],["79824.77000000","0.06215000"],["79824.40000000","0.06215000"],["79824.05000000","0.00009000"],["79824.01000000","0.00009000"],["79823.88000000","0.06215000"],["79823.87000000","0.46827000"],["79823.53000000","0.00000000"],["79823.25000000","0.00000000"],["79822.93000000","0.00000000"],["79822.17000000","1.04939000"],["79820.01000000","0.00000000"],["79819.35000000","0.00000000"],["79818.72000000","0.00000000"],["79818.62000000","0.00800000"],["79816.96000000","0.02200000"],["79814.56000000","0.02400000"],["79807.70000000","0.48561000"],["79806.64000000","0.36586000"],["79799.66000000","0.00000000"],["79785.90000000","0.00000000"],["79783.59000000","0.41136000"],["79783.28000000","0.83273000"],["79774.38000000","0.00424000"],["79764.42000000","0.02200000"],["79758.48000000","0.00000000"],["79750.91000000","0.02400000"],["79707.12000000","0.00000000"],["79697.92000000","0.04536000"],["78640.43000000","0.00030000"],["75800.00000000","3.53318000"],["71854.20000000","0.00032000"]],"a":[["79838.01000000","8.10336000"],["79838.88000000","0.07514000"],["79838.90000000","0.18519000"],["79839.29000000","0.02051000"],["79839.85000000","0.84074000"],["79840.57000000","0.02461000"],["79840.98000000","0.07500000"],["79840.99000000","0.36969000"],["79841.14000000","0.04026000"],["79841.85000000","0.02461000"],["79842.27000000","0.00014000"],["79843.99000000","0.00013000"],["79845.95000000","0.00007000"],["79846.01000000","0.64907000"],["79848.02000000","1.04946000"],["79850.69000000","0.00000000"],["79851.99000000","0.62651000"],["79854.75000000","0.32480000"],["79855.40000000","0.00000000"],["79857.43000000","0.00007000"],["79861.47000000","0.00250000"],["79861.51000000","0.00189000"],["79865.33000000","0.00000000"],["79874.96000000","0.02491000"],["79874.98000000","0.00000000"],["79875.19000000","0.00000000"],["79876.81000000","0.00000000"],["79878.00000000","0.03400000"],["79879.00000000","0.00000000"],["79879.41000000","0.83173000"],["79897.30000000","0.00625000"],["79917.31000000","0.00000000"],["79937.38000000","0.02804000"],["79944.21000000","0.00400000"],["79954.84000000","0.05741000"],["80026.98000000","0.00000000"],["80075.41000000","0.00000000"],["80103.96000000","0.00031000"]]}}}
{"rx_ns": 13991994102300, "frame": {"stream":"btcusdt@depth@100ms","data":{"e":"depthUpdate","E":1787650987214,"s":"BTCUSDT","U":99118696124,"u":99118696223,"b":[["79838.00000000","0.02899000"],["79837.99000000","0.00091000"],["79834.52000000","0.00668000"],["79834.23000000","0.00014000"],["79834.22000000","0.06215000"],["79833.84000000","0.02042000"],["79833.60000000","0.00007000"],["79833.59000000","0.06141000"],["79833.24000000","0.01093000"],["79833.15000000","0.00007000"],["79833.14000000","0.06236000"],["79832.34000000","0.00007000"],["79832.33000000","0.06215000"],["79832.01000000","0.00000000"],["79832.00000000","0.02421000"],["79831.08000000","0.00000000"],["79830.45000000","0.00000000"],["79830.26000000","0.06215000"],["79830.00000000","0.02424000"],["79828.00000000","0.02400000"],["79826.94000000","0.09833000"],["79826.93000000","0.00000000"],["79826.49000000","0.00014000"],["79826.01000000","0.00007000"],["79824.78000000","0.00000000"],["79824.01000000","0.00000000"],["79812.51000000","0.50531000"],["79810.61000000","0.25662000"],["79807.71000000","0.62651000"],["79807.69000000","0.00000000"],["79804.44000000","0.00000000"],["79804.38000000","0.00000000"],["79803.54000000","0.00000000"],["79788.56000000","1.03315000"],["79772.01000000","0.00000000"],["79771.28000000","0.02000000"],["79768.44000000","0.00311000"],["79764.42000000","0.00000000"],["79747.41000000","0.00000000"],["79721.28000000","0.00000000"],["79714.51000000","0.00000000"],["79709.31000000","0.00012000"],["79700.53000000","0.00000000"],["79699.03000000","0.00000000"],["79690.53000000","0.00125000"],["79689.20000000","0.00125000"],["71863.19000000","0.00000000"],["71854.20000000","0.00048000"],["63870.40000000","0.00000000"]],"a":[["79838.01000000","8.05449000"],["79838.88000000","0.00014000"],["79838.89000000","2.38632000"],["79838.90000000","0.18519000"],["79839.29000000","0.02065000"],["79839.85000000","0.84074000"],["79840.97000000","0.47898000"],["79844.01000000","0.24275000"],["79846.52000000","0.00007000"],["79846.85000000","0.02000000"],["79847.99000000","1.81161000"],["79848.00000000","2.17162000"],["79866.02000000","0.00000000"],["79869.80000000","0.00000000"],["79886.17000000","0.00000000"],["79905.98000000","0.00312000"],["79915.99000000","0.00000000"],["79947.03000000","0.00000000"],["79966.64000000","0.00000000"],["79967.82000000","0.00000000"],["79969.33000000","0.00000000"],["79973.50000000","0.00000000"],["79974.56000000","0.00000000"],["80556.54000000","0.00010000"]]}}}
{"rx_ns": 13992091731000, "frame": {"stream":"btcusdt@depth@100ms","data":{"e":"depthUpdate","E":1787650987314,"s":"BTCUSDT","U":99118696224,"u":99118696283,"b":[["79838.00000000","0.05822000"],["79837.99000000","0.00084000"],["79834.52000000","0.00668000"],["79834.22000000","0.06229000"],["79833.84000000","0.02028000"],["79833.24000000","0.01100000"],["79833.14000000","0.06222000"],["79833.13000000","0.31330000"],["79832.03000000","0.00000000"],["79830.01000000","0.00139000"],["79825.60000000","0.02703000"],["79824.05000000","0.00000000"],["79824.04000000","0.00000000"],["79822.03000000","0.00147000"],["79816.06000000","0.00000000"],["79814.04000000","0.00139000"],["79813.64000000","1.25136000"],["79813.52000000","0.00000000"],["79806.06000000","0.00139000"],["79787.79000000","0.00000000"],["79773.43000000","0.00335000"],["79737.42000000","0.00025000"],["79650.12000000","0.00000000"],["79632.50000000","0.00698000"],["79610.72000000","0.00000000"],["79599.03000000","0.00771000"],["71854.20000000","0.00080000"],["63870.00000000","0.00030000"]],"a":[["79838.01000000","8.05463000"],["79838.11000000","0.00000000"],["79838.24000000","0.00000000"],["79838.39000000","0.00000000"],["79838.64000000","0.00000000"],["79838.77000000","0.00000000"],["79838.88000000","0.00000000"],["79840.57000000","0.02475000"],["79840.82000000","0.04970000"],["79848.00000000","2.17229000"],["79856.97000000","0.00000000"],["79862.74000000","0.00000000"],["79872.32000000","0.00400000"],["79937.01000000","0.00025000"],["79994.45000000","0.03287000"],["80012.15000000","0.00000000"]]}}}
{"rx_ns": 13992191435200, "frame": {"stream":"btcusdt@depth@100ms","data":{"e":"depthUpdate","E":1787650987414,"s":"BTCUSDT","U":99118696284,"u":99118696306,"b":[["79838.00000000","0.05936000"],["79833.84000000","0.02042000"],["79830.93000000","0.00202000"],["79830.61000000","0.33829000"],["79830.00000000","0.02417000"],["79825.40000000","0.00000000"],["79789.67000000","0.00012000"],["79703.11000000","0.00017000"],["75100.00000000","3.75015000"]],"a":[["79838.01000000","8.05442000"],["79838.89000000","2.39340000"],["79838.90000000","0.10519000"],["79853.13000000","0.00000000"],["79866.81000000","0.00012000"],["79954.63000000","0.00012000"],["80377.32000000","0.01505000"],["80476.52000000","0.00000000"]]}}}
{"rx_ns": 13992296025700, "frame": {"stream":"btcusdt@depth@100ms","data":{"e":"depthUpdate","E":1787650987514,"s":"BTCUSDT","U":99118696307,"u":99118696390,"b":[["79838.00000000","0.02834000"],["79837.99000000","0.00070000"],["79834.23000000","0.00007000"],["79834.22000000","0.00014000"],["79833.84000000","0.02035000"],["79833.60000000","0.00000000"],["79833.59000000","0.00000000"],["79833.15000000","0.00000000"],["79833.14000000","0.00007000"],["79833.13000000","0.31323000"],["79832.34000000","0.00000000"],["79832.33000000","0.00000000"],["79832.01000000","0.00007000"],["79831.96000000","0.01302000"],["79831.71000000","0.00000000"],["79831.70000000","0.00000000"],["79831.08000000","0.00000000"],["79831.07000000","0.00000000"],["79830.68000000","0.01302000"],["79830.62000000","0.00007000"],["79830.44000000","0.00000000"],["79830.26000000","0.00007000"],["79826.94000000","0.00000000"],["79825.61000000","0.04134000"],["79825.40000000","0.00007000"],["79824.77000000","0.00000000"],["79824.46000000","0.00007000"],["79824.40000000","0.00000000"],["79823.88000000","0.00000000"],["79805.65000000","0.00000000"],["79798.85000000","0.33843000"],["79792.95000000","0.00400000"],["79788.65000000","0.00000000"],["79765.74000000","0.00000000"],["79759.24000000","0.02087000"],["79733.82000000","0.00000000"],["79685.94000000","0.00000000"],["79614.11000000","0.00008000"],["79610.71000000","0.00000000"],["79598.75000000","0.01962000"],["71854.20000000","0.00120000"],["63870.40000000","0.00051000"]],"a":[["79839.72000000","0.00007000"],["79842.91000000","0.00000000"],["79848.00000000","2.17729000"],["79848.01000000","0.43448000"],["79850.00000000","0.09893000"],["79852.00000000","0.97027000"],["79853.18000000","0.33820000"],["79854.00000000","0.00500000"],["79856.00000000","1.16183000"],["79872.32000000","0.00000000"],["79912.26000000","0.00000000"],["79941.79000000","0.01662000"],["79944.21000000","0.00000000"],["79957.32000000","0.00018000"],["79961.48000000","0.00031000"],["79992.13000000","0.00000000"],["80064.02000000","0.00000000"]]}}}
{"rx_ns": 13992398570100, "frame": {"stream":"btcusdt@depth@100ms","data":{"e":"depthUpdate","E":1787650987614,"s":"BTCUSDT","U":99118696391,"u":99118696424,"b":[["79834.52000000","0.00661000"],["79834.22000000","0.00000000"],["79833.84000000","0.02028000"],["79833.24000000","0.01093000"],["79833.13000000","0.31330000"],["79831.07000000","0.06216000"],["79830.62000000","0.06223000"],["79824.77000000","0.06216000"],["79824.40000000","0.06216000"],["79823.88000000","0.06216000"],["79800.00000000","0.92520000"],["79758.34000000","0.11925000"],["79750.91000000","0.00000000"],["71854.20000000","0.00136000"],["63870.40000000","0.00000000"]],"a":[["79850.40000000","0.00007000"],["79850.76000000","0.06308000"],["79859.99000000","0.75603000"],["79860.00000000","0.82043000"],["79860.08000000","0.00937000"],["79860.88000000","0.49960000"],["79895.00000000","0.00000000"]]}}}
{"rx_ns": 13992491848000, "frame": {"stream":"btcusdt@depth@100ms","data":{"e":"depthUpdate","E":1787650987714,"s":"BTCUSDT","U":99118696425,"u":99118696449,"b":[["79838.00000000","0.02841000"],["79831.96000000","0.01309000"],["79831.08000000","0.00007000"],["79830.68000000","0.01309000"],["79830.63000000","0.00007000"],["79825.61000000","0.07431000"],["79813.82000000","0.02200000"],["79813.01000000","0.02000000"],["79765.19000000","0.02000000"],["79759.24000000","0.00000000"],["79757.32000000","0.02200000"],["79749.30000000","0.00000000"],["74400.00000000","0.38610000"],["71854.20000000","0.00152000"],["71854.00000000","0.00171000"]],"a":[["79848.01000000","0.42752000"],["79848.75000000","0.02000000"],["79849.57000000","0.02000000"],["79850.79000000","0.02000000"],["79861.35000000","0.00000000"],["79909.45000000","0.00000000"],["79938.83000000","0.00400000"]]}}}
{"rx_ns": 13992591249500, "frame": {"stream":"btcusdt@depth@100ms","data":{"e":"depthUpdate","E":1787650987814,"s":"BTCUSDT","U":99118696450,"u":99118696475,"b":[["79838.00000000","0.03122000"],["79833.15000000","0.00007000"],["79833.14000000","0.06223000"],["79831.96000000","0.01316000"],["79831.71000000","0.00007000"],["79831.70000000","0.06216000"],["79830.62000000","0.06216000"],["79830.26000000","0.00000000"],["79825.40000000","0.00000000"],["79824.46000000","0.00000000"],["79800.00000000","1.62520000"],["71854.20000000","0.00152000"]],"a":[["79838.01000000","8.05455000"],["79848.00000000","2.18429000"],["79848.01000000","0.40664000"],["79850.00000000","0.10593000"],["79852.00000000","0.97727000"],["79854.00000000","0.01200000"],["79856.00000000","1.16883000"],["81035.59000000","0.00030000"]]}}}
{"rx_ns": 13992694508500, "frame": {"stream":"btcusdt@depth@100ms","data":{"e":"depthUpdate","E":1787650987914,"s":"BTCUSDT","U":99118696476,"u":99118696524,"b":[["79833.24000000","0.01093000"],["79829.75000000","0.12526000"],["79825.40000000","0.00000000"],["79821.76000000","0.12527000"],["79817.81000000","0.02800000"],["79817.72000000","0.02600000"],["79816.93000000","0.02000000"],["79813.78000000","0.12529000"],["79813.34000000","0.02200000"],["79812.94000000","0.04400000"],["79803.53000000","0.00000000"],["79803.03000000","0.09627000"],["79768.60000000","0.02000000"],["79766.35000000","0.02600000"],["79765.99000000","0.02426000"],["79760.37000000","0.00400000"],["79758.34000000","0.00000000"],["79757.32000000","0.00000000"],["79754.11000000","0.02800000"],["79749.67000000","0.02200000"],["79749.27000000","0.02200000"],["79749.26000000","0.00000000"],["73700.00000000","10.73795000"],["71854.20000000","0.00160000"],["71854.19000000","0.00008000"]],"a":[["79838.01000000","8.05256000"],["79845.99000000","0.02000000"],["79846.02000000","0.02000000"],["79846.83000000","0.02000000"],["79850.00000000","0.12593000"],["79850.49000000","0.02000000"],["79850.89000000","0.04000000"],["79853.72000000","0.12522000"],["79860.16000000","0.00000000"],["79860.94000000","0.00000000"],["79902.96000000","0.00000000"],["79903.82000000","0.02000000"],["79908.67000000","0.00000000"],["79929.74000000","0.00556000"],["79955.24000000","0.00000000"],["81912.08000000","0.00000000"]]}}}
{"rx_ns": 13992791765800, "frame": {"stream":"btcusdt@depth20","data":{"lastUpdateId":99118696557,"bids":[["79838.00000000","0.02713000"],["79837.99000000","0.00070000"],["79837.75000000","0.00007000"],["79837.04000000","0.00007000"],["79836.88000000","0.00007000"],["79836.69000000","0.00007000"],["79836.28000000","0.00007000"],["79836.03000000","0.00007000"],["79836.01000000","0.00007000"],["79836.00000000","0.02442000"],["79835.25000000","0.00007000"],["79835.24000000","0.05079000"],["79834.88000000","0.00007000"],["79834.52000000","0.00661000"],["79834.23000000","0.00007000"],["79834.16000000","0.00026000"],["79834.01000000","0.00007000"],["79834.00000000","0.02414000"],["79833.85000000","0.00007000"],["79833.84000000","0.02028000"]],"asks":[["79838.01000000","8.05256000"],["79838.02000000","0.00027000"],["79838.03000000","0.00013000"],["79838.10000000","0.00414000"],["79838.88000000","1.70426000"],["79838.89000000","2.39340000"],["79838.90000000","0.10519000"],["79838.93000000","0.00400000"],["79839.10000000","0.00007000"],["79839.29000000","0.02065000"],["79839.65000000","0.10487000"],["79839.72000000","0.00007000"],["79839.83000000","0.07514000"],["79839.85000000","0.84067000"],["79840.01000000","0.00007000"],["79840.25000000","0.00400000"],["79840.57000000","0.02475000"],["79840.82000000","0.04970000"],["79840.98000000","0.07500000"],["79840.99000000","0.36969000"]]}}}
{"rx_ns": 13992791900100, "frame": {"stream":"btcusdt@depth@100ms","data":{"e":"depthUpdate","E":1787650988014,"s":"BTCUSDT","U":99118696525,"u":99118696557,"b":[["79838.00000000","0.02713000"],["79825.61000000","0.04134000"],["79825.60000000","0.00000000"],["79824.78000000","0.00007000"],["79824.77000000","0.00000000"],["79824.40000000","0.00000000"],["79823.88000000","0.00000000"],["79823.68000000","0.00000000"],["79822.80000000","0.00007000"],["79808.57000000","0.00000000"],["79768.60000000","0.00000000"],["79766.35000000","0.00000000"],["63870.40000000","0.00031000"]],"a":[["79838.88000000","1.70426000"],["79839.85000000","0.84067000"],["79840.97000000","0.00000000"],["79845.29000000","0.00000000"],["79845.97000000","0.00000000"],["79846.00000000","0.00000000"],["79846.24000000","0.00000000"],["79846.89000000","0.02000000"],["79850.76000000","0.00000000"],["79854.74000000","0.00007000"],["79855.62000000","0.00000000"],["79856.19000000","0.00000000"],["79857.11000000","0.00000000"],["79860.62000000","0.00000000"],["79861.02000000","0.00000000"],["79861.03000000","0.00000000"],["79893.46000000","0.00000000"],["79894.27000000","0.00000000"]]}}}
{"rx_ns": 13992895799800, "frame": {"stream":"btcusdt@depth@100ms","data":{"e":"depthUpdate","E":1787650988114,"s":"BTCUSDT","U":99118696558,"u":99118696731,"b":[["79838.00000000","1.68141000"],["79834.85000000","0.00000000"],["79834.33000000","0.00000000"],["79834.22000000","0.00000000"],["79833.85000000","0.00000000"],["79833.84000000","0.00028000"],["79833.59000000","0.00000000"],["79833.15000000","0.00000000"],["79833.14000000","0.00007000"],["79832.33000000","0.00000000"],["79831.96000000","0.01302000"],["79831.71000000","0.00000000"],["79831.70000000","0.00000000"],["79831.08000000","0.00000000"],["79831.07000000","0.00000000"],["79830.93000000","0.00000000"],["79830.68000000","0.01295000"],["79830.63000000","0.00000000"],["79830.62000000","0.00000000"],["79830.61000000","0.00000000"],["79830.36000000","0.00014000"],["79830.26000000","0.47976000"],["79829.76000000","0.00007000"],["79828.29000000","0.00000000"],["79825.62000000","0.00000000"],["79824.78000000","0.00000000"],["79824.77000000","0.06215000"],["79824.46000000","0.00626000"],["79824.40000000","0.06215000"],["79823.89000000","1.14374000"],["79823.88000000","1.87677000"],["79823.87000000","0.00000000"],["79823.82000000","0.00000000"],["79823.00000000","0.08566000"],["79822.97000000","0.03224000"],["79818.76000000","0.00000000"],["79814.03000000","0.30523000"],["79812.01000000","0.00626000"],["79810.61000000","0.00000000"],["79808.58000000","0.00000000"],["79807.72000000","0.52961000"],["79807.70000000","0.00000000"],["79806.32000000","0.00000000"],["79791.66000000","0.00000000"],["79791.03000000","0.00014000"],["79790.88000000","0.02800000"],["79790.80000000","0.00000000"],["79764.42000000","0.02200000"],["79754.11000000","0.00000000"],["79724.62000000","0.00000000"],["78640.43000000","0.00030000"],["71854.20000000","0.00176000"]],"a":[["79838.01000000","5.68459000"],["79838.87000000","0.00007000"],["79838.88000000","1.06378000"],["79838.89000000","0.50955000"],["79838.93000000","0.00000000"],["79839.64000000","0.00008000"],["79839.83000000","0.00014000"],["79839.84000000","0.00007000"],["79839.85000000","0.84060000"],["79840.82000000","0.04956000"],["79840.98000000","0.00007000"],["79840.99000000","0.28969000"],["79841.69000000","0.00400000"],["79842.01000000","0.00007000"],["79842.77000000","0.00007000"],["79843.87000000","0.00007000"],["79844.02000000","0.09644000"],["79844.04000000","0.00007000"],["79844.54000000","0.00626000"],["79844.83000000","0.00000000"],["79844.99000000","0.00708000"],["79845.99000000","0.02007000"],["79846.00000000","0.00400000"],["79846.56000000","0.00000000"],["79846.80000000","0.02000000"],["79847.65000000","0.08576000"],["79847.98000000","0.00400000"],["79848.48000000","0.00000000"],["79848.77000000","0.02000000"],["79849.18000000","0.02000000"],["79849.99000000","0.00000000"],["79850.10000000","0.00007000"],["79850.32000000","0.00000000"],["79851.98000000","0.00000000"],["79851.99000000","0.00000000"],["79853.06000000","0.27952000"],["79853.07000000","0.00000000"],["79853.18000000","0.00000000"],["79853.57000000","0.00626000"],["79853.71000000","0.00000000"],["79856.30000000","0.00000000"],["79856.71000000","0.62650000"],["79856.72000000","0.00000000"],["79857.44000000","0.00000000"],["79860.17000000","0.00000000"],["79860.71000000","0.42975000"],["79866.80000000","0.33814000"],["79874.42000000","0.33811000"],["79883.53000000","0.00000000"],["79883.95000000","1.29336000"],["79902.19000000","0.00000000"],["79986.75000000","0.00400000"],["80151.87000000","7.48769000"],["80172.53000000","0.01509000"],["80228.75000000","0.00000000"]]}}}
{"rx_ns": 13992991492300, "frame": {"stream":"btcusdt@depth@100ms","data":{"e":"depthUpdate","E":1787650988214,"s":"BTCUSDT","U":99118696732,"u":99118696786,"b":[["79838.00000000","0.70919000"],["79837.99000000","0.00063000"],["79835.24000000","0.05086000"],["79834.56000000","0.00007000"],["79834.55000000","0.02000000"],["79834.00000000","0.02407000"],["79833.84000000","0.00021000"],["79833.24000000","0.01093000"],["79832.00000000","0.02428000"],["79830.68000000","0.01302000"],["79830.27000000","0.00007000"],["79830.26000000","0.47983000"],["79830.11000000","0.00000000"],["79830.00000000","0.02424000"],["79825.61000000","0.04134000"],["79824.77000000","0.00000000"],["79824.40000000","0.00000000"],["79823.89000000","1.08159000"],["79749.67000000","0.00000000"],["73000.00000000","67.33532000"],["71854.20000000","0.00192000"],["63870.40000000","0.00000000"]],"a":[["79838.01000000","5.69038000"],["79838.86000000","0.00000000"],["79838.89000000","0.50962000"],["79839.64000000","0.00007000"],["79839.65000000","0.10473000"],["79839.83000000","0.00000000"],["79840.82000000","0.04963000"],["79840.98000000","0.00000000"],["79842.01000000","0.00000000"],["79857.05000000","0.00000000"],["79859.41000000","0.00000000"],["79899.27000000","0.00000000"]]}}}
{"rx_ns": 13993091582100, "frame": {"stream":"btcusdt@depth@100ms","data":{"e":"depthUpdate","E":1787650988314,"s":"BTCUSDT","U":99118696787,"u":99118696825,"b":[["79838.00000000","0.70926000"],["79837.99000000","0.00070000"],["79835.24000000","0.05079000"],["79830.68000000","0.01302000"],["79830.45000000","0.00000000"],["79830.44000000","0.00000000"],["79830.26000000","0.00007000"],["79825.71000000","0.02551000"],["79823.88000000","0.00000000"],["79814.03000000","0.00000000"],["79812.52000000","0.00000000"],["79810.61000000","0.31308000"],["79749.27000000","0.00000000"],["79726.70000000","0.51723000"],["79697.92000000","0.00000000"],["79696.01000000","0.04536000"],["79680.57000000","0.00400000"],["79118.30000000","0.00000000"],["78864.59000000","0.01522000"],["71854.20000000","0.00176000"],["63870.00000000","0.00030000"]],"a":[["79838.01000000","7.56702000"],["79838.88000000","1.48792000"],["79839.64000000","0.00000000"],["79839.84000000","0.00000000"],["79843.18000000","1.87677000"],["79848.01000000","0.40652000"],["79850.85000000","0.06555000"],["79856.99000000","0.00000000"]]}}}
{"rx_ns": 13993191234800, "frame": {"stream":"btcusdt@depth@100ms","data":{"e":"depthUpdate","E":1787650988414,"s":"BTCUSDT","U":99118696826,"u":99118696864,"b":[["79838.00000000","0.25630000"],["79837.99000000","0.00077000"],["79835.24000000","0.05072000"],["79834.56000000","0.00000000"],["79834.55000000","0.00000000"],["79833.64000000","0.00202000"],["79833.13000000","0.31337000"],["79832.84000000","0.02000000"],["79832.24000000","0.33829000"],["79830.36000000","0.00007000"],["79830.27000000","0.00000000"],["79825.21000000","0.00007000"],["79823.89000000","0.52137000"],["79822.97000000","0.00000000"],["79791.66000000","0.00007000"],["79791.03000000","0.00007000"],["79758.30000000","0.12317000"],["71854.20000000","0.00208000"]],"a":[["79838.01000000","7.57341000"],["79838.87000000","0.00000000"],["79838.88000000","1.48785000"],["79838.89000000","0.50955000"],["79841.85000000","0.02468000"],["79842.16000000","0.03224000"],["79844.02000000","0.09637000"],["79844.54000000","0.00000000"],["79852.66000000","0.33820000"],["79874.42000000","0.00000000"],["79919.93000000","2.26910000"],["79923.57000000","3.75454000"],["80160.74000000","0.00000000"]]}}}
{"rx_ns": 13993291404000, "frame": {"stream":"btcusdt@depth@100ms","data":{"e":"depthUpdate","E":1787650988514,"s":"BTCUSDT","U":99118696865,"u":99118696886,"b":[["79838.00000000","0.25630000"],["79837.99000000","0.00070000"],["79835.24000000","0.05072000"],["79833.13000000","0.31337000"],["79832.84000000","0.02014000"],["79832.25000000","0.00007000"],["79832.01000000","0.00000000"],["79832.00000000","0.02421000"],["79824.46000000","0.00000000"],["79822.63000000","0.00626000"],["79759.24000000","0.02087000"],["75000.00000000","113.34582000"],["71854.20000000","0.00208000"],["63870.40000000","0.00031000"]],"a":[["79838.01000000","7.62351000"],["79848.01000000","0.38147000"],["80058.63000000","0.00400000"]]}}}
{"rx_ns": 13993391530700, "frame": {"stream":"btcusdt@depth@100ms","data":{"e":"depthUpdate","E":1787650988614,"s":"BTCUSDT","U":99118696887,"u":99118696916,"b":[["79838.00000000","0.25594000"],["79837.99000000","0.00083000"],["79837.98000000","0.00013000"],["79835.24000000","0.05079000"],["79834.00000000","0.02414000"],["79833.24000000","0.01100000"],["79833.13000000","0.31344000"],["79832.84000000","0.02021000"],["79825.71000000","0.00000000"],["79823.90000000","0.06215000"],["79759.24000000","0.02087000"],["79749.13000000","0.62610000"],["71854.20000000","0.00208000"],["63870.40000000","0.00020000"]],"a":[["79838.01000000","7.62358000"],["79838.88000000","1.48792000"],["79839.65000000","0.10480000"],["79840.82000000","0.04970000"],["79846.00000000","0.01364000"],["79848.00000000","2.18929000"],["79850.00000000","0.13093000"],["79852.00000000","0.98227000"],["79854.00000000","0.01700000"]]}}}
{"rx_ns": 13993491470100, "frame": {"stream":"btcusdt@depth@100ms","data":{"e":"depthUpdate","E":1787650988714,"s":"BTCUSDT","U":99118696917,"u":99118696928,"b":[["79838.00000000","0.24601000"],["79602.31000000","0.00771000"],["79599.03000000","0.00000000"],["71854.20000000","0.00224000"],["71854.19000000","0.00000000"],["63870.40000000","0.00000000"]],"a":[["79848.00000000","2.19629000"],["79850.00000000","0.13793000"],["79852.00000000","0.98927000"],["79854.00000000","0.02400000"],["79866.94000000","0.00400000"],["79901.23000000","0.02000000"],["79902.04000000","0.02000000"]]}}}
{"rx_ns": 13993593511600, "frame": {"stream":"btcusdt@depth@100ms","data":{"e":"depthUpdate","E":1787650988814,"s":"BTCUSDT","U":99118696929,"u":99118696946,"b":[["79838.00000000","0.24624000"],["79825.61000000","0.06104000"],["79825.21000000","0.00000000"],["79824.77000000","0.06215000"],["79824.40000000","0.06215000"],["79823.89000000","0.50167000"],["79759.24000000","0.00000000"],["71854.20000000","0.00240000"]],"a":[["79838.01000000","7.65142000"],["81035.59000000","0.00030000"]]}}}
{"rx_ns": 13993699258000, "frame": {"stream":"btcusdt@depth@100ms","data":{"e":"depthUpdate","E":1787650988914,"s":"BTCUSDT","U":99118696947,"u":99118696984,"b":[["79838.00000000","0.27428000"],["79837.99000000","0.00090000"],["79834.00000000","0.02421000"],["79833.60000000","0.00007000"],["79833.59000000","0.06215000"],["79833.15000000","0.00007000"],["79833.14000000","0.06222000"],["79830.68000000","0.01309000"],["79830.45000000","0.00007000"],["79830.44000000","0.06215000"],["79830.36000000","0.00014000"],["79830.27000000","0.00007000"],["79830.26000000","0.06222000"],["79829.76000000","0.00000000"],["79825.71000000","0.02285000"],["79825.40000000","0.06215000"],["79823.92000000","1.09238000"],["79823.91000000","1.87677000"],["79823.90000000","0.00000000"],["79823.89000000","0.00000000"],["79768.60000000","0.02000000"],["79766.35000000","0.02600000"],["79608.75000000","0.00400000"],["78000.00000000","32.33836000"],["71854.20000000","0.00240000"],["71854.00000000","0.00171000"]],"a":[["79838.01000000","7.63968000"],["79893.45000000","0.02000000"],["79894.26000000","0.02000000"],["79902.87000000","0.02000000"],["79903.73000000","0.02000000"]]}}}
{"rx_ns": 13993806378200, "frame": {"stream":"btcusdt@depth20","data":{"lastUpdateId":99118697030,"bids":[["79838.00000000","0.20105000"],["79837.99000000","0.00090000"],["79837.98000000","0.00013000"],["79837.75000000","0.00007000"],["79837.04000000","0.00007000"],["79836.88000000","0.00007000"],["79836.69000000","0.00007000"],["79836.28000000","0.00007000"],["79836.03000000","0.00007000"],["79836.01000000","0.00007000"],["79836.00000000","0.02442000"],["79835.25000000","0.00007000"],["79835.24000000","0.05079000"],["79834.88000000","0.00007000"],["79834.52000000","0.00661000"],["79834.23000000","0.00007000"],["79834.16000000","0.00026000"],["79834.01000000","0.00007000"],["79834.00000000","0.02421000"],["79833.84000000","0.00021000"]],"asks":[["79838.01000000","7.63960000"],["79838.02000000","0.00027000"],["79838.03000000","0.00013000"],["79838.10000000","0.00414000"],["79838.88000000","1.48792000"],["79838.89000000","0.50955000"],["79838.90000000","0.10519000"],["79839.10000000","0.00007000"],["79839.29000000","0.02065000"],["79839.65000000","0.10480000"],["79839.72000000","0.00007000"],["79839.85000000","0.84060000"],["79840.01000000","0.00007000"],["79840.25000000","0.00400000"],["79840.57000000","0.02475000"],["79840.82000000","0.04970000"],["79840.99000000","0.28969000"],["79841.14000000","0.04026000"],["79841.69000000","0.00400000"],["79841.85000000","0.02468000"]]}}}
{"rx_ns": 13993806488500, "frame": {"stream":"btcusdt@depth@100ms","data":{"e":"depthUpdate","E":1787650989014,"s":"BTCUSDT","U":99118696985,"u":99118697030,"b":[["79838.00000000","0.20105000"],["79834.00000000","0.02421000"],["79833.59000000","0.06229000"],["79833.24000000","0.01100000"],["79832.84000000","0.02007000"],["79825.40000000","0.00000000"],["79822.80000000","0.00007000"],["71854.20000000","0.00264000"],["63870.40000000","0.00031000"]],"a":[["79838.01000000","7.63960000"],["79854.74000000","0.00007000"],["80004.15000000","0.00000000"],["82000.00000000","122.72241000"]]}}}
{"rx_ns": 13993890967800, "frame": {"stream":"btcusdt@depth@100ms","data":{"e":"depthUpdate","E":1787650989114,"s":"BTCUSDT","U":99118697031,"u":99118697040,"b":[["79800.28000000","0.00400000"],["78640.43000000","0.00030000"],["71854.20000000","0.00264000"]],"a":[["79841.80000000","0.00007000"],["79848.00000000","2.19761000"],["79899.26000000","0.02000000"],["79899.97000000","0.00007000"],["79902.10000000","0.02000000"]]}}}
{"rx_ns": 13993991888700, "frame": {"stream":"btcusdt@depth@100ms","data":{"e":"depthUpdate","E":1787650989214,"s":"BTCUSDT","U":99118697041,"u":99118697050,"b":[["79838.00000000","0.20238000"],["71854.20000000","0.00280000"],["63870.40000000","0.00000000"]],"a":[["79849.56000000","0.00626000"],["79852.65000000","0.62657000"],["79853.57000000","0.00000000"],["79856.71000000","0.00000000"],["80054.16000000","0.00000000"],["80556.54000000","0.00000000"]]}}}
{"rx_ns": 13994092593900, "frame": {"stream":"btcusdt@depth@100ms","data":{"e":"depthUpdate","E":1787650989314,"s":"BTCUSDT","U":99118697051,"u":99118697082,"b":[["79838.00000000","0.19490000"],["79837.99000000","0.00083000"],["79833.60000000","0.00000000"],["79833.59000000","0.00014000"],["79830.27000000","0.00000000"],["79830.26000000","0.00007000"],["79812.01000000","0.00000000"],["79810.01000000","0.00626000"],["73475.18000000","0.00014000"],["71854.20000000","0.00272000"],["71854.19000000","0.00008000"],["63870.00000000","0.00030000"]],"a":[["79838.01000000","7.63970000"],["79849.26000000","0.27083000"],["79853.06000000","0.00000000"],["79906.88000000","0.00400000"],["79957.32000000","0.01980000"]]}}}
{"rx_ns": 13994192562400, "frame": {"stream":"btcusdt@depth@100ms","data":{"e":"depthUpdate","E":1787650989414,"s":"BTCUSDT","U":99118697083,"u":99118697101,"b":[["79838.00000000","0.19725000"],["79834.00000000","0.02414000"],["79833.59000000","0.00000000"],["79833.14000000","0.06236000"],["79829.76000000","0.00007000"],["79824.01000000","0.06100000"],["71854.20000000","0.00288000"]],"a":[["79838.01000000","7.63982000"],["79957.32000000","0.00018000"],["80026.29000000","0.02003000"]]}}}
{"rx_ns": 13994291457500, "frame": {"stream":"btcusdt@depth@100ms","data":{"e":"depthUpdate","E":1787650989514,"s":"BTCUSDT","U":99118697102,"u":99118697129,"b":[["79838.00000000","0.19690000"],["79833.14000000","0.00021000"],["79830.44000000","0.00000000"],["79830.01000000","0.00111000"],["79825.71000000","0.00000000"],["79824.77000000","0.00000000"],["79824.40000000","0.00000000"],["79824.01000000","0.00000000"],["79823.91000000","0.00000000"],["79822.03000000","0.00119000"],["79814.04000000","0.00111000"],["79806.06000000","0.00000000"],["79793.97000000","0.47298000"],["79792.50000000","0.65446000"],["79778.93000000","0.82410000"],["79765.48000000","0.32318000"],["79765.36000000","0.82424000"],["79728.45000000","0.00000000"],["71854.20000000","0.00288000"],["63870.40000000","0.00031000"]],"a":[["79838.01000000","7.66487000"]]}}}
{"rx_ns": 13994391532500, "frame": {"stream":"btcusdt@depth@100ms","data":{"e":"depthUpdate","E":1787650989614,"s":"BTCUSDT","U":99118697130,"u":99118697167,"b":[["79838.00000000","0.20047000"],["79833.24000000","0.01100000"],["79833.15000000","0.00000000"],["79833.14000000","0.00007000"],["79832.84000000","0.02021000"],["79830.68000000","0.01302000"],["79830.45000000","0.00000000"],["79830.36000000","0.00007000"],["79825.61000000","0.04134000"],["79823.92000000","0.51353000"],["79823.08000000","0.03000000"],["79821.68000000","0.04000000"],["79807.71000000","0.00000000"],["79806.06000000","0.00111000"],["79806.02000000","0.62650000"],["79759.24000000","0.02088000"],["71854.20000000","0.00304000"],["63870.40000000","0.00000000"]],"a":[["79838.01000000","7.66487000"],["79838.15000000","0.00000000"],["79853.99000000","0.33820000"],["79866.80000000","0.00000000"]]}}}
{"rx_ns": 13994494370900, "frame": {"stream":"btcusdt@depth@100ms","data":{"e":"depthUpdate","E":1787650989714,"s":"BTCUSDT","U":99118697168,"u":99118697178,"b":[["79838.00000000","0.19791000"],["79834.16000000","0.00109000"],["79834.01000000","0.00135000"],["79728.42000000","0.00400000"],["71854.20000000","0.00320000"],["71854.19000000","0.00000000"],["63870.40000000","0.00000000"]],"a":[["79838.01000000","7.53132000"]]}}}
{"rx_ns": 13994591573600, "frame": {"stream":"btcusdt@depth@100ms","data":{"e":"depthUpdate","E":1787650989814,"s":"BTCUSDT","U":99118697179,"u":99118697187,"b":[["79838.00000000","0.19816000"],["79758.30000000","0.00000000"],["79728.42000000","0.00000000"],["73475.18000000","0.00000000"],["71854.20000000","0.00320000"]],"a":[["81035.59000000","0.00030000"]]}}}
{"rx_ns": 13994696105700, "frame": {"stream":"btcusdt@depth@100ms","data":{"e":"depthUpdate","E":1787650989914,"s":"BTCUSDT","U":99118697188,"u":99118697199,"b":[["79838.00000000","0.19803000"],["79833.64000000","0.00000000"],["79825.71000000","0.02261000"],["79818.62000000","0.01200000"],["79759.24000000","0.00000000"],["79728.44000000","0.00400000"],["71854.20000000","0.00320000"],["71854.00000000","0.00171000"]],"a":[["79841.79000000","0.00400000"]]}}}
