{"captured_at": "2026-08-25T09:42:24.221174+00:00", "url": "wss://data-stream.binance.vision/stream?streams=btcusdt@depth@100ms/btcusdt@depth20", "venue": "binance", "symbol": "BTCUSDT", "streams": ["depth@100ms", "depth20"], "combined": true, "rest_url": "https://data-api.binance.vision/api/v3/depth?symbol=BTCUSDT&limit=1000", "rest_limit": 1000, "rest_weight_per_fetch": 50, "snapshot_every_s": 25.0, "tool_version": "0.1.0", "clock": "perf_counter_ns", "capture_mode": "baseline", "cycles": 1, "origin_sent": null, "handshake_status": "HTTP/1.1 101 Switching Protocols"}
{"rx_ns": 13949397688000, "frame": {"stream":"btcusdt@depth@100ms","data":{"e":"depthUpdate","E":1787650944614,"s":"BTCUSDT","U":99118672918,"u":99118672938,"b":[["79859.21000000","1.36675000"],["79855.75000000","0.42275000"],["79855.45000000","0.00000000"],["79855.44000000","0.00000000"],["73480.61000000","0.00014000"],["71873.29000000","0.00320000"],["63887.37000000","0.00000000"]],"a":[["79859.22000000","3.78391000"],["79866.19000000","0.20949000"],["79866.90000000","0.00000000"]]}}}
{"rx_ns": 13949493732700, "frame": {"stream":"btcusdt@depth@100ms","data":{"e":"depthUpdate","E":1787650944714,"s":"BTCUSDT","U":99118672939,"u":99118672991,"b":[["79859.21000000","1.09488000"],["79859.20000000","0.00090000"],["79858.66000000","0.00086000"],["79858.16000000","0.00126000"],["79855.77000000","0.00000000"],["79855.76000000","0.00021000"],["79855.75000000","0.00000000"],["79854.43000000","0.02268000"],["79854.33000000","0.00000000"],["79853.15000000","0.00923000"],["79853.11000000","0.00000000"],["79852.92000000","0.00000000"],["79852.05000000","0.00007000"],["79850.73000000","0.00000000"],["79850.23000000","0.48333000"],["79850.22000000","0.00000000"],["79849.34000000","0.00070000"],["79814.88000000","0.00007000"],["79807.23000000","0.70372000"],["79806.62000000","0.00000000"]],"a":[["79859.22000000","4.17271000"],["79860.41000000","0.00000000"],["79860.42000000","0.00014000"],["79860.49000000","0.00007000"],["79861.28000000","0.00000000"],["79861.81000000","0.00400000"],["79862.56000000","0.00007000"],["79863.92000000","0.00000000"],["79863.93000000","0.04000000"],["79863.99000000","0.00000000"],["79864.00000000","0.90514000"],["79866.00000000","0.00000000"],["79866.19000000","0.20942000"],["79867.56000000","1.87677000"],["79921.06000000","0.00007000"]]}}}
{"rx_ns": 13949592446300, "frame": {"stream":"btcusdt@depth@100ms","data":{"e":"depthUpdate","E":1787650944814,"s":"BTCUSDT","U":99118672992,"u":99118673029,"b":[["79859.21000000","1.09433000"],["79859.20000000","0.00083000"],["79856.00000000","0.02421000"],["79855.82000000","0.00000000"],["79855.76000000","0.00000000"],["79854.82000000","0.01256000"],["79854.44000000","0.00007000"],["79854.01000000","0.00007000"],["79853.45000000","0.00007000"],["79852.06000000","0.06053000"],["79852.05000000","0.36607000"],["79849.40000000","0.00047000"],["79779.47000000","0.44146000"],["79691.57000000","0.00019000"],["71873.29000000","0.00320000"],["63887.37000000","0.00000000"]],"a":[["79860.25000000","0.10494000"],["79860.42000000","0.00000000"],["79863.92000000","0.00007000"],["79863.93000000","0.04014000"]]}}}
{"rx_ns": 13949697205500, "frame": {"stream":"btcusdt@depth@100ms","data":{"e":"depthUpdate","E":1787650944914,"s":"BTCUSDT","U":99118673030,"u":99118673067,"b":[["79859.21000000","1.09440000"],["79859.20000000","0.00090000"],["79856.00000000","0.02428000"],["79855.57000000","0.00000000"],["79855.56000000","0.00000000"],["79855.40000000","0.00007000"],["79855.39000000","0.12530000"],["79852.05000000","0.36600000"],["79844.00000000","0.02407000"],["78661.32000000","0.00030000"],["71873.29000000","0.00320000"],["63887.37000000","0.00000000"]],"a":[["79860.49000000","0.00014000"],["79863.92000000","0.00000000"],["79863.93000000","0.00014000"],["79866.19000000","0.20949000"],["79866.92000000","0.12530000"],["79866.96000000","0.00000000"],["79867.08000000","0.00000000"],["79875.96000000","0.00007000"],["81057.11000000","0.00030000"]]}}}
{"rx_ns": 13949797027800, "frame": {"stream":"btcusdt@depth20","data":{"lastUpdateId":99118673110,"bids":[["79859.21000000","1.39275000"],["79859.20000000","0.00083000"],["79859.19000000","0.00013000"],["79858.66000000","0.00086000"],["79858.65000000","0.08157000"],["79858.16000000","0.00126000"],["79858.01000000","0.00007000"],["79858.00000000","0.02435000"],["79857.77000000","0.00007000"],["79857.50000000","0.00007000"],["79857.45000000","0.00007000"],["79857.31000000","0.00007000"],["79856.88000000","0.00007000"],["79856.56000000","0.00007000"],["79856.55000000","0.05261000"],["79856.28000000","0.00007000"],["79856.27000000","0.00014000"],["79856.10000000","0.00759000"],["79856.03000000","0.00007000"],["79856.02000000","0.02021000"]],"asks":[["79859.22000000","4.17284000"],["79859.23000000","0.00027000"],["79859.24000000","0.00013000"],["79860.23000000","0.00007000"],["79860.24000000","0.13119000"],["79860.25000000","0.10494000"],["79860.49000000","0.00014000"],["79860.50000000","0.01909000"],["79861.29000000","0.00007000"],["79861.32000000","0.00014000"],["79861.44000000","0.00007000"],["79861.77000000","0.00007000"],["79861.78000000","0.02279000"],["79861.99000000","0.00007000"],["79862.00000000","0.00007000"],["79862.01000000","0.20652000"],["79862.13000000","0.00007000"],["79862.14000000","0.04800000"],["79862.56000000","0.00007000"],["79862.78000000","0.00400000"]]}}}
{"rx_ns": 13949797126700, "frame": {"stream":"btcusdt@depth@100ms","data":{"e":"depthUpdate","E":1787650945014,"s":"BTCUSDT","U":99118673068,"u":99118673110,"b":[["79859.21000000","1.39275000"],["79859.20000000","0.00083000"],["79856.00000000","0.02421000"],["79855.40000000","0.00000000"],["79855.39000000","0.00000000"],["79853.72000000","0.06053000"],["79853.11000000","0.06053000"],["79852.50000000","0.06053000"],["79842.16000000","0.09404000"],["79840.16000000","0.10348000"],["79825.69000000","0.00000000"],["71873.29000000","0.00336000"],["71873.00000000","0.00010000"],["63887.37000000","0.00031000"]],"a":[["79859.22000000","4.17284000"],["79861.81000000","0.00000000"],["79861.99000000","0.00007000"],["79862.14000000","0.04800000"],["79863.06000000","0.02279000"],["79863.45000000","0.00400000"],["79863.93000000","0.00000000"],["79863.99000000","0.00007000"],["79864.00000000","0.90535000"],["79864.89000000","0.00007000"],["79866.19000000","0.20942000"],["79866.92000000","0.00000000"],["79867.57000000","0.41838000"],["79986.98000000","0.00140000"]]}}}
{"rx_ns": 13949892200000, "frame": {"stream":"btcusdt@depth@100ms","data":{"e":"depthUpdate","E":1787650945114,"s":"BTCUSDT","U":99118673111,"u":99118673144,"b":[["79859.21000000","1.39273000"],["79856.00000000","0.02421000"],["79854.44000000","0.00007000"],["79854.43000000","0.02275000"],["79854.01000000","0.00007000"],["79853.73000000","0.00007000"],["79853.45000000","0.00000000"],["79824.67000000","0.09348000"],["79630.93000000","0.00000000"],["79599.03000000","0.00771000"],["73480.61000000","0.00000000"],["71873.29000000","0.00352000"],["71873.00000000","0.00000000"]],"a":[["79863.99000000","0.00007000"],["79864.00000000","0.90535000"],["79864.89000000","0.00007000"],["79896.19000000","0.00000000"],["79900.24000000","0.09563000"],["79947.63000000","1.42069000"],["79949.75000000","1.95360000"]]}}}
{"rx_ns": 13949992229700, "frame": {"stream":"btcusdt@depth@100ms","data":{"e":"depthUpdate","E":1787650945214,"s":"BTCUSDT","U":99118673145,"u":99118673184,"b":[["79859.21000000","1.09431000"],["79859.20000000","0.00083000"],["79856.00000000","0.02421000"],["79855.56000000","0.00000000"],["79855.55000000","0.00000000"],["79854.68000000","0.00007000"],["79854.44000000","0.00007000"],["79854.01000000","0.00007000"],["79853.73000000","0.00007000"],["71873.29000000","0.00352000"],["63887.37000000","0.00000000"]],"a":[["79863.99000000","0.00007000"],["79864.00000000","0.90535000"],["79864.89000000","0.00000000"],["79866.19000000","0.20942000"],["79866.88000000","0.00000000"],["80026.97000000","0.00140000"]]}}}
{"rx_ns": 13950094525600, "frame": {"stream":"btcusdt@depth@100ms","data":{"e":"depthUpdate","E":1787650945314,"s":"BTCUSDT","U":99118673185,"u":99118673198,"b":[["79859.21000000","1.09438000"],["79854.43000000","0.02282000"],["79854.05000000","0.00688000"],["71873.29000000","0.00352000"],["71873.00000000","0.00010000"],["63887.00000000","0.01877000"]],"a":[["79861.28000000","0.00007000"],["79861.99000000","0.00000000"]]}}}
{"rx_ns": 13950192461000, "frame": {"stream":"btcusdt@depth@100ms","data":{"e":"depthUpdate","E":1787650945414,"s":"BTCUSDT","U":99118673199,"u":99118673212,"b":[["79859.21000000","1.09427000"],["71873.29000000","0.00368000"],["71873.28000000","0.00000000"],["71873.00000000","0.00000000"],["42044.20000000","0.00036000"]],"a":[["79864.89000000","0.00007000"],["79866.70000000","0.00000000"],["79866.86000000","0.00000000"],["79878.77000000","0.00000000"],["82888.00000000","6.97305000"],["84888.00000000","21.20239000"]]}}}
{"rx_ns": 13950292336600, "frame": {"stream":"btcusdt@depth@100ms","data":{"e":"depthUpdate","E":1787650945514,"s":"BTCUSDT","U":99118673213,"u":99118673232,"b":[["79859.21000000","1.09434000"],["79859.20000000","0.00090000"],["79856.00000000","0.02428000"],["79855.39000000","0.00007000"],["79855.38000000","0.00000000"],["79854.01000000","0.00007000"],["79853.73000000","0.00000000"],["79784.94000000","0.02087000"],["71873.29000000","0.00384000"],["63887.37000000","0.00031000"]],"a":[["79863.99000000","0.00007000"],["79864.00000000","0.90535000"],["79864.89000000","0.00000000"],["80023.87000000","0.00000000"]]}}}
{"rx_ns": 13950392504400, "frame": {"stream":"btcusdt@depth@100ms","data":{"e":"depthUpdate","E":1787650945614,"s":"BTCUSDT","U":99118673233,"u":99118673246,"b":[["79859.21000000","1.19072000"],["79859.20000000","0.00083000"],["79856.00000000","0.02421000"],["79855.39000000","0.00000000"],["79853.73000000","0.00007000"],["79848.67000000","0.00000000"],["79815.62000000","0.00000000"],["79795.63000000","0.00000000"],["79784.94000000","0.00000000"],["71873.29000000","0.00368000"],["63887.37000000","0.00000000"]],"a":[["79859.22000000","4.17180000"],["79864.89000000","0.00007000"],["79865.93000000","0.00350000"],["79879.71000000","0.00000000"],["79906.90000000","0.00000000"],["79926.89000000","0.00000000"]]}}}
{"rx_ns": 13950491908100, "frame": {"stream":"btcusdt@depth@100ms","data":{"e":"depthUpdate","E":1787650945714,"s":"BTCUSDT","U":99118673247,"u":99118673254,"b":[["79859.21000000","1.09427000"],["79818.30000000","0.00400000"],["79807.98000000","0.00000000"],["71873.29000000","0.00400000"],["71873.00000000","0.00000000"]],"a":[]}}}
{"rx_ns": 13950592414500, "frame": {"stream":"btcusdt@depth@100ms","data":{"e":"depthUpdate","E":1787650945814,"s":"BTCUSDT","U":99118673255,"u":99118673298,"b":[["79859.21000000","1.19359000"],["79859.20000000","0.00083000"],["79856.00000000","0.02421000"],["79855.40000000","0.00000000"],["79855.39000000","0.00000000"],["79854.01000000","0.00007000"],["79853.73000000","0.00007000"],["79852.51000000","0.42275000"],["79800.30000000","0.00007000"],["79796.15000000","0.00007000"],["79697.59000000","0.00202000"],["71873.29000000","0.00400000"],["71873.00000000","0.00000000"]],"a":[["79863.99000000","0.00007000"],["79864.00000000","0.90535000"],["79864.89000000","0.00007000"],["79866.19000000","0.20949000"],["79866.77000000","0.00000000"],["80010.87000000","0.00202000"]]}}}
{"rx_ns": 13950692200000, "frame": {"stream":"btcusdt@depth@100ms","data":{"e":"depthUpdate","E":1787650945914,"s":"BTCUSDT","U":99118673299,"u":99118673317,"b":[["79859.21000000","1.19243000"],["79844.00000000","0.02407000"],["71873.29000000","0.00416000"],["71873.00000000","0.00010000"],["63887.37000000","0.00000000"]],"a":[["79866.19000000","0.20949000"],["79867.07000000","0.12530000"],["79875.96000000","0.00007000"]]}}}
{"rx_ns": 13950792258600, "frame": {"stream":"btcusdt@depth20","data":{"lastUpdateId":99118673331,"bids":[["79859.21000000","1.19243000"],["79859.20000000","0.00083000"],["79859.19000000","0.00013000"],["79858.66000000","0.00086000"],["79858.65000000","0.08157000"],["79858.16000000","0.00126000"],["79858.01000000","0.00007000"],["79858.00000000","0.02435000"],["79857.77000000","0.00007000"],["79857.50000000","0.00007000"],["79857.45000000","0.00007000"],["79857.31000000","0.00007000"],["79856.88000000","0.00007000"],["79856.56000000","0.00007000"],["79856.55000000","0.05261000"],["79856.28000000","0.00007000"],["79856.27000000","0.00014000"],["79856.10000000","0.00759000"],["79856.03000000","0.00007000"],["79856.02000000","0.02021000"]],"asks":[["79859.22000000","4.17180000"],["79859.23000000","0.00027000"],["79859.24000000","0.00013000"],["79860.23000000","0.00007000"],["79860.24000000","0.13119000"],["79860.25000000","0.10494000"],["79860.49000000","0.00014000"],["79860.50000000","0.01909000"],["79861.28000000","0.00007000"],["79861.29000000","0.00007000"],["79861.32000000","0.00014000"],["79861.44000000","0.00007000"],["79861.77000000","0.00007000"],["79861.78000000","0.02279000"],["79862.00000000","0.00007000"],["79862.01000000","0.20652000"],["79862.13000000","0.00007000"],["79862.14000000","0.04800000"],["79862.56000000","0.00007000"],["79862.78000000","0.00400000"]]}}}
{"rx_ns": 13950792329400, "frame": {"stream":"btcusdt@depth@100ms","data":{"e":"depthUpdate","E":1787650946014,"s":"BTCUSDT","U":99118673318,"u":99118673331,"b":[["79843.84000000","0.02200000"],["79803.86000000","0.02200000"],["78661.32000000","0.00030000"],["71873.00000000","0.00010000"],["63887.37000000","0.00031000"]],"a":[["79873.36000000","0.02000000"],["79893.35000000","0.02000000"],["79913.33000000","0.02000000"],["81057.11000000","0.00030000"]]}}}
{"rx_ns": 13950892932400, "kind": "rest", "req": {"method": "GET", "url": "https://data-api.binance.vision/api/v3/depth?symbol=BTCUSDT&limit=1000", "limit": 1000, "weight": 50, "sent_ns": 13949318707500, "status": 200, "used_weight_1m": "100", "recv_ns": 13950812631200}, "frame": {"lastUpdateId":99118673232,"bids":[["79859.21000000","1.09434000"],["79859.20000000","0.00090000"],["79859.19000000","0.00013000"],["79858.66000000","0.00086000"],["79858.65000000","0.08157000"],["79858.16000000","0.00126000"],["79858.01000000","0.00007000"],["79858.00000000","0.02435000"],["79857.77000000","0.00007000"],["79857.50000000","0.00007000"],["79857.45000000","0.00007000"],["79857.31000000","0.00007000"],["79856.88000000","0.00007000"],["79856.56000000","0.00007000"],["79856.55000000","0.05261000"],["79856.28000000","0.00007000"],["79856.27000000","0.00014000"],["79856.10000000","0.00759000"],["79856.03000000","0.00007000"],["79856.02000000","0.02021000"],["79856.01000000","0.00007000"],["79856.00000000","0.02428000"],["79855.64000000","0.00007000"],["79855.39000000","0.00007000"],["79855.14000000","0.00007000"],["79855.13000000","0.00007000"],["79854.92000000","0.00014000"],["79854.82000000","0.01256000"],["79854.68000000","0.00007000"],["79854.67000000","0.12529000"],["79854.44000000","0.00007000"],["79854.43000000","0.02282000"],["79854.28000000","0.00007000"],["79854.26000000","0.00007000"],["79854.05000000","0.00688000"],["79854.01000000","0.00007000"],["79854.00000000","0.02400000"],["79853.72000000","0.06053000"],["79853.64000000","0.00010000"],["79853.58000000","0.00014000"],["79853.54000000","0.01498000"],["79853.44000000","0.02480000"],["79853.23000000","0.00013000"],["79853.21000000","0.00007000"],["79853.20000000","0.00007000"],["79853.15000000","0.00923000"],["79853.11000000","0.06053000"],["79853.01000000","0.00007000"],["79852.65000000","0.00008000"],["79852.50000000","0.06053000"],["79852.26000000","0.01491000"],["79852.19000000","0.00007000"],["79852.07000000","0.00400000"],["79852.06000000","0.06053000"],["79852.05000000","0.36600000"],["79852.04000000","1.20214000"],["79852.00000000","0.02400000"],["79851.71000000","0.12573000"],["79851.58000000","0.00705000"],["79851.53000000","0.00007000"],["79851.22000000","0.00008000"],["79851.04000000","0.00400000"],["79850.60000000","0.00033000"],["79850.59000000","0.00048000"],["79850.40000000","0.00007000"],["79850.25000000","0.00030000"],["79850.23000000","0.48333000"],["79850.20000000","1.04939000"],["79850.11000000","0.00007000"],["79850.02000000","0.00007000"],["79850.01000000","0.00052000"],["79850.00000000","0.02798000"],["79849.75000000","0.00047000"],["79849.71000000","0.00014000"],["79849.52000000","0.00026000"],["79849.40000000","0.00047000"],["79849.34000000","0.00070000"],["79849.28000000","0.00400000"],["79849.25000000","0.00250000"],["79849.21000000","0.00007000"],["79848.96000000","0.00187000"],["79848.93000000","0.20250000"],["79848.67000000","0.02200000"],["79848.61000000","0.02400000"],["79848.48000000","0.08000000"],["79848.34000000","0.00007000"],["79848.18000000","0.07000000"],["79848.13000000","0.00710000"],["79848.03000000","0.00014000"],["79848.00000000","0.02407000"],["79847.89000000","0.10199000"],["79847.86000000","0.00059000"],["79847.77000000","0.00906000"],["79847.70000000","0.00007000"],["79847.58000000","0.00400000"],["79847.57000000","1.04222000"],["79847.26000000","0.00007000"],["79846.52000000","0.00007000"],["79846.42000000","0.01161000"],["79846.28000000","0.00626000"],["79846.27000000","0.00400000"],["79846.25000000","0.02400000"],["79846.00000000","0.02400000"],["79845.85000000","0.00626000"],["79845.84000000","0.00014000"],["79845.78000000","0.08566000"],["79845.66000000","0.00010000"],["79845.63000000","0.00012000"],["79845.34000000","1.04939000"],["79845.15000000","0.00007000"],["79845.02000000","1.87677000"],["79845.01000000","0.50137000"],["79844.69000000","0.00165000"],["79844.58000000","0.00008000"],["79844.13000000","0.00706000"],["79844.11000000","0.02800000"],["79844.10000000","0.36424000"],["79844.01000000","0.00007000"],["79844.00000000","0.02407000"],["79843.88000000","0.00007000"],["79843.50000000","0.02432000"],["79843.32000000","0.02000000"],["79843.28000000","0.02000000"],["79843.26000000","0.00400000"],["79843.24000000","0.00008000"],["79843.22000000","0.03224000"],["79842.82000000","0.00125000"],["79842.80000000","0.00192000"],["79842.64000000","0.00007000"],["79842.49000000","0.12524000"],["79842.18000000","0.79307000"],["79842.16000000","0.09404000"],["79842.01000000","0.00007000"],["79842.00000000","0.02400000"],["79841.99000000","0.00007000"],["79841.97000000","0.00014000"],["79841.48000000","0.00026000"],["79841.01000000","0.00400000"],["79840.23000000","0.02200000"],["79840.16000000","0.10348000"],["79840.13000000","0.00707000"],["79840.09000000","0.02400000"],["79840.03000000","1.87677000"],["79840.00000000","0.27773000"],["79839.85000000","0.76416000"],["79839.84000000","1.04939000"],["79839.78000000","0.00910000"],["79839.73000000","0.00007000"],["79839.59000000","0.02200000"],["79839.44000000","0.02000000"],["79839.42000000","0.02000000"],["79839.25000000","0.00008000"],["79839.20000000","0.04400000"],["79838.76000000","0.00400000"],["79838.42000000","0.00007000"],["79838.10000000","0.00014000"],["79838.00000000","0.02400000"],["79837.90000000","0.33827000"],["79837.79000000","0.33827000"],["79837.68000000","0.00010000"],["79837.65000000","0.00007000"],["79836.65000000","0.12525000"],["79836.57000000","0.00400000"],["79836.51000000","0.00008000"],["79836.35000000","0.42961000"],["79836.34000000","0.37587000"],["79836.13000000","0.00705000"],["79836.08000000","0.00007000"],["79836.01000000","0.00007000"],["79836.00000000","0.02400000"],["79835.58000000","0.00007000"],["79835.25000000","0.00008000"],["79834.88000000","0.00007000"],["79834.29000000","1.14744000"],["79834.28000000","1.87677000"],["79834.23000000","0.00014000"],["79834.03000000","0.00007000"],["79834.01000000","0.00626000"],["79834.00000000","0.02400000"],["79833.80000000","0.00200000"],["79833.74000000","0.62646000"],["79833.62000000","1.04939000"],["79833.60000000","0.00400000"],["79833.50000000","0.00007000"],["79833.38000000","0.00026000"],["79832.25000000","0.38853000"],["79832.24000000","0.36586000"],["79832.08000000","0.00007000"],["79832.00000000","0.02807000"],["79831.80000000","0.20250000"],["79831.75000000","0.00750000"],["79831.69000000","0.00072000"],["79831.53000000","0.04472000"],["79831.43000000","0.00007000"],["79831.26000000","0.00008000"],["79830.78000000","0.62631000"],["79830.77000000","0.33830000"],["79830.36000000","0.00014000"],["79830.03000000","0.00400000"],["79830.00000000","0.07438000"],["79829.82000000","0.00007000"],["79829.70000000","0.00010000"],["79829.35000000","0.00007000"],["79829.29000000","0.92661000"],["79829.28000000","0.12897000"],["79828.78000000","1.87677000"],["79828.44000000","0.00008000"],["79828.28000000","1.05439000"],["79828.00000000","0.72400000"],["79827.83000000","0.20631000"],["79827.80000000","0.00125000"],["79827.73000000","0.00070000"],["79827.66000000","0.00400000"],["79827.51000000","0.57092000"],["79827.50000000","0.33831000"],["79827.28000000","0.00007000"],["79827.27000000","0.00008000"],["79827.12000000","0.00007000"],["79826.49000000","0.00014000"],["79826.33000000","0.00010000"],["79826.32000000","0.00007000"],["79826.30000000","0.00052000"],["79826.00000000","0.02400000"],["79825.39000000","0.00026000"],["79825.33000000","0.05104000"],["79825.20000000","0.00007000"],["79824.67000000","0.09348000"],["79824.50000000","0.03224000"],["79824.36000000","0.00400000"],["79824.20000000","0.01153000"],["79824.11000000","0.36881000"],["79824.00000000","0.02407000"],["79823.94000000","0.62654000"],["79823.87000000","1.56761000"],["79823.86000000","1.04939000"],["79823.84000000","2.24263000"],["79823.73000000","0.62879000"],["79823.57000000","0.00400000"],["79823.27000000","0.00008000"],["79823.16000000","0.00007000"],["79823.13000000","0.00007000"],["79822.62000000","0.00014000"],["79822.16000000","0.20250000"],["79822.00000000","0.02400000"],["79821.72000000","0.00010000"],["79821.50000000","0.02000000"],["79821.08000000","1.00575000"],["79821.05000000","0.00007000"],["79820.92000000","0.00007000"],["79820.68000000","0.00014000"],["79820.37000000","0.00408000"],["79820.10000000","0.00007000"],["79820.09000000","0.50983000"],["79820.00000000","0.02400000"],["79819.99000000","0.00007000"],["79819.81000000","0.62658000"],["79819.36000000","0.00007000"],["79819.28000000","0.00008000"],["79819.00000000","0.01000000"],["79818.75000000","0.00007000"],["79818.61000000","1.02263000"],["79818.60000000","1.87677000"],["79818.06000000","0.00007000"],["79818.00000000","0.02400000"],["79817.89000000","1.04939000"],["79817.67000000","0.02541000"],["79817.50000000","0.03224000"],["79817.28000000","0.02000000"],["79817.15000000","0.00026000"],["79816.90000000","0.00007000"],["79816.44000000","0.02541000"],["79816.35000000","0.00007000"],["79816.00000000","0.02400000"],["79815.99000000","0.34821000"],["79815.64000000","0.02400000"],["79815.62000000","0.02200000"],["79815.51000000","0.71709000"],["79815.50000000","0.36586000"],["79814.99000000","0.00400000"],["79814.88000000","0.00007000"],["79814.82000000","0.00007000"],["79814.27000000","0.00007000"],["79814.06000000","0.02800000"],["79814.02000000","0.20250000"],["79814.01000000","0.00007000"],["79814.00000000","0.02400000"],["79813.74000000","0.00010000"],["79812.98000000","0.00010000"],["79812.75000000","1.87684000"],["79812.30000000","0.00008000"],["79812.00000000","0.02400000"],["79811.60000000","0.00007000"],["79811.30000000","0.20631000"],["79811.24000000","0.02000000"],["79811.04000000","0.75297000"],["79810.93000000","0.00012000"],["79810.87000000","0.02400000"],["79810.72000000","0.00400000"],["79810.67000000","0.00007000"],["79810.43000000","0.00100000"],["79810.38000000","0.00007000"],["79810.28000000","0.00007000"],["79810.19000000","0.81756000"],["79810.00000000","0.02400000"],["79809.86000000","0.04695000"],["79809.79000000","0.00433000"],["79809.62000000","0.02200000"],["79809.55000000","2.29018000"],["79809.53000000","0.02600000"],["79809.25000000","0.02000000"],["79809.22000000","0.02200000"],["79809.21000000","0.02200000"],["79809.16000000","0.00026000"],["79808.00000000","0.02407000"],["79807.98000000","0.00400000"],["79807.83000000","0.02400000"],["79807.68000000","0.02541000"],["79807.23000000","0.70372000"],["79807.22000000","0.83250000"],["79807.21000000","0.02000000"],["79807.19000000","0.00007000"],["79806.61000000","0.36711000"],["79806.60000000","0.06139000"],["79806.52000000","0.00007000"],["79806.44000000","0.00013000"],["79806.01000000","0.20250000"],["79806.00000000","0.02400000"],["79805.76000000","0.00010000"],["79804.45000000","0.00007000"],["79804.23000000","0.00008000"],["79804.12000000","0.00007000"],["79804.07000000","0.82537000"],["79804.02000000","0.00007000"],["79804.00000000","0.02400000"],["79803.84000000","0.00007000"],["79803.52000000","2.39001000"],["79803.51000000","1.87677000"],["79803.49000000","1.04939000"],["79802.09000000","0.00007000"],["79802.00000000","0.02400000"],["79801.88000000","0.00431000"],["79801.51000000","0.02000000"],["79800.92000000","0.00007000"],["79800.86000000","0.00026000"],["79800.56000000","3.40038000"],["79800.32000000","0.80000000"],["79800.19000000","0.00621000"],["79800.12000000","0.00390000"],["79800.00000000","0.82870000"],["79799.89000000","1.24091000"],["79798.74000000","1.86392000"],["79798.64000000","1.87677000"],["79798.62000000","1.04939000"],["79798.23000000","0.00007000"],["79798.06000000","0.00007000"],["79798.05000000","0.36586000"],["79798.00000000","0.02400000"],["79797.99000000","0.00200000"],["79797.90000000","0.00007000"],["79797.78000000","0.00010000"],["79797.44000000","0.00312000"],["79797.43000000","0.20250000"],["79797.35000000","0.00432000"],["79797.29000000","0.02200000"],["79796.79000000","0.00537000"],["79796.43000000","2.32243000"],["79796.16000000","0.00008000"],["79796.08000000","0.00007000"],["79796.05000000","0.00007000"],["79796.00000000","0.02400000"],["79795.65000000","0.02400000"],["79795.63000000","0.02200000"],["79795.39000000","0.00110000"],["79795.07000000","0.00253000"],["79794.59000000","0.03224000"],["79794.46000000","0.01716000"],["79794.07000000","0.02800000"],["79794.03000000","0.00007000"],["79794.00000000","0.02400000"],["79793.97000000","0.31457000"],["79793.96000000","1.04939000"],["79792.66000000","0.00026000"],["79792.23000000","0.00413000"],["79792.03000000","0.00007000"],["79792.00000000","0.02414000"],["79791.61000000","0.00312000"],["79791.60000000","1.24104000"],["79791.26000000","0.02000000"],["79791.03000000","0.00014000"],["79790.96000000","0.08703000"],["79790.88000000","0.02400000"],["79790.58000000","0.00270000"],["79790.52000000","0.04644000"],["79790.34000000","0.07971000"],["79790.01000000","0.00312000"],["79790.00000000","0.02400000"],["79789.80000000","0.00010000"],["79789.63000000","0.02200000"],["79789.54000000","0.02600000"],["79789.44000000","0.20250000"],["79789.27000000","0.02000000"],["79789.23000000","0.02200000"],["79789.22000000","0.02200000"],["79789.06000000","0.98279000"],["79789.05000000","1.87677000"],["79788.77000000","0.00011000"],["79788.59000000","0.36586000"],["79788.53000000","0.00007000"],["79788.32000000","0.00007000"],["79788.23000000","1.04939000"],["79788.14000000","0.00007000"],["79788.09000000","0.00008000"],["79788.01000000","0.01444000"],["79788.00000000","0.02400000"],["79787.85000000","0.02407000"],["79787.22000000","0.02000000"],["79786.12000000","0.00014000"],["79786.00000000","0.02400000"],["79785.32000000","0.00008000"],["79784.94000000","0.02087000"],["79784.04000000","0.00007000"],["79784.00000000","0.02400000"],["79783.70000000","0.00007000"],["79783.65000000","0.00400000"],["79782.80000000","0.00007000"],["79782.00000000","0.02426000"],["79781.82000000","0.00010000"],["79781.80000000","0.03224000"],["79781.46000000","0.16974000"],["79781.45000000","0.20250000"],["79780.99000000","0.00014000"],["79780.57000000","0.00007000"],["79780.56000000","0.00007000"],["79780.48000000","0.36586000"],["79780.02000000","0.00008000"],["79780.00000000","0.02400000"],["79779.47000000","0.44146000"],["79779.46000000","1.87677000"],["79778.96000000","1.04939000"],["79778.86000000","0.00100000"],["79778.18000000","0.00067000"],["79778.16000000","0.00007000"],["79778.00000000","0.02400000"],["79777.94000000","0.05682000"],["79777.06000000","0.03224000"],["79777.00000000","0.00012000"],["79776.11000000","0.00007000"],["79776.00000000","0.02407000"],["79775.70000000","1.99604000"],["79775.41000000","0.00007000"],["79775.32000000","0.11972000"],["79774.00000000","0.02400000"],["79773.97000000","0.00026000"],["79773.84000000","0.00010000"],["79773.61000000","0.00010000"],["79773.46000000","0.20250000"],["79773.13000000","0.00007000"],["79772.89000000","0.62584000"],["79772.80000000","0.00007000"],["79772.69000000","0.00020000"],["79772.48000000","0.00218000"],["79772.16000000","0.00007000"],["79772.00000000","0.02400000"],["79771.59000000","0.04613000"],["79771.26000000","0.00007000"],["79770.99000000","0.00007000"],["79770.39000000","0.36586000"],["79770.15000000","0.00007000"],["79770.00000000","0.02917000"],["79769.87000000","1.87677000"],["79769.41000000","0.03224000"],["79769.18000000","3.76184000"],["79769.12000000","0.00010000"],["79768.85000000","0.00007000"],["79768.00000000","0.02400000"],["79766.71000000","0.00007000"],["79766.66000000","0.00016000"],["79766.00000000","0.02482000"],["79765.99000000","0.00026000"],["79765.86000000","0.00010000"],["79765.47000000","0.20250000"],["79765.25000000","0.01253000"],["79765.04000000","0.00014000"],["79764.70000000","0.00541000"],["79764.51000000","0.00007000"],["79764.00000000","0.02400000"],["79763.88000000","0.00008000"],["79762.96000000","0.00007000"],["79762.27000000","0.11821000"],["79762.26000000","0.36586000"],["79762.12000000","0.00007000"],["79762.00000000","0.02400000"],["79761.89000000","0.00200000"],["79761.88000000","0.00008000"],["79760.08000000","0.00007000"],["79760.00000000","0.02625000"],["79758.60000000","0.00025000"],["79758.00000000","0.02400000"],["79757.99000000","0.00007000"],["79757.88000000","0.00010000"],["79757.62000000","0.00007000"],["79757.52000000","0.00026000"],["79757.48000000","0.20250000"],["79757.41000000","0.00231000"],["79757.38000000","0.00034000"],["79757.28000000","0.00007000"],["79756.79000000","0.03224000"],["79756.43000000","0.00501000"],["79756.18000000","0.00007000"],["79756.00000000","0.02400000"],["79755.93000000","0.00007000"],["79755.00000000","0.09659000"],["79754.67000000","0.00007000"],["79754.20000000","0.00126000"],["79754.18000000","0.00007000"],["79754.00000000","0.02400000"],["79752.24000000","0.00014000"],["79752.06000000","0.00007000"],["79752.00000000","0.02400000"],["79751.72000000","0.00400000"],["79751.41000000","0.00270000"],["79750.52000000","0.00007000"],["79750.00000000","0.02799000"],["79749.49000000","0.20250000"],["79749.37000000","0.00026000"],["79748.08000000","0.00007000"],["79748.00000000","0.02400000"],["79747.89000000","0.14335000"],["79747.88000000","0.36586000"],["79747.84000000","0.00088000"],["79747.74000000","0.00008000"],["79746.89000000","0.00160000"],["79746.37000000","0.00007000"],["79746.04000000","0.08730000"],["79746.00000000","0.02400000"],["79745.46000000","0.00016000"],["79744.74000000","0.00007000"],["79744.00000000","0.02407000"],["79743.94000000","0.00752000"],["79743.28000000","0.25000000"],["79742.19000000","0.00007000"],["79742.00000000","0.02400000"],["79741.50000000","0.20250000"],["79740.15000000","0.00026000"],["79740.00000000","0.05014000"],["79739.82000000","0.00394000"],["79739.48000000","0.00007000"],["79738.93000000","0.00100000"],["79738.83000000","0.00016000"],["79738.21000000","0.00007000"],["79738.00000000","0.02400000"],["79737.27000000","0.12897000"],["79736.72000000","0.07529000"],["79736.67000000","0.00007000"],["79736.47000000","0.00376000"],["79736.04000000","0.00007000"],["79736.01000000","0.00007000"],["79736.00000000","0.02400000"],["79734.24000000","0.00010000"],["79734.00000000","0.02407000"],["79733.69000000","0.00007000"],["79733.50000000","0.36586000"],["79732.48000000","0.00059000"],["79732.00000000","0.02400000"],["79731.98000000","0.00026000"],["79731.70000000","0.00007000"],["79731.60000000","0.00008000"],["79731.44000000","0.00019000"],["79730.76000000","0.00035000"],["79730.48000000","0.00012000"],["79730.00000000","0.03474000"],["79729.79000000","0.00007000"],["79729.72000000","0.00111000"],["79729.70000000","0.00007000"],["79729.04000000","0.00042000"],["79728.65000000","0.00012000"],["79728.64000000","0.00007000"],["79728.57000000","0.00020000"],["79728.40000000","0.00413000"],["79728.30000000","0.03032000"],["79728.00000000","0.02400000"],["79727.14000000","0.00009000"],["79727.11000000","0.00048000"],["79727.00000000","0.00251000"],["79726.86000000","0.00007000"],["79726.70000000","0.88994000"],["79726.69000000","3.76373000"],["79726.00000000","0.02400000"],["79725.64000000","0.00007000"],["79724.69000000","0.00016000"],["79724.13000000","0.04910000"],["79724.07000000","0.00007000"],["79724.01000000","0.00125000"],["79724.00000000","0.02426000"],["79723.98000000","0.00260000"],["79723.52000000","0.00010000"],["79723.40000000","0.00009000"],["79722.91000000","0.09362000"],["79722.24000000","0.00007000"],["79722.00000000","0.02400000"],["79721.94000000","0.00007000"],["79721.64000000","0.00007000"],["79721.57000000","0.00007000"],["79721.30000000","0.03224000"],["79720.00000000","0.02550000"],["79719.42000000","0.00007000"],["79719.12000000","0.36586000"],["79718.52000000","0.00007000"],["79718.16000000","0.00009000"],["79718.00000000","0.02400000"],["79717.58000000","0.00023000"],["79717.43000000","0.00170000"],["79717.34000000","0.00007000"],["79716.78000000","0.00062000"],["79716.66000000","0.00010000"],["79716.45000000","0.00007000"],["79716.33000000","0.00125000"],["79716.03000000","0.00008000"],["79716.00000000","0.02400000"],["79715.91000000","0.00026000"],["79715.53000000","0.00017000"],["79715.46000000","0.00008000"],["79715.28000000","0.00007000"],["79714.90000000","0.00125000"],["79714.36000000","0.00007000"],["79714.28000000","0.00013000"],["79714.25000000","0.06000000"],["79714.20000000","0.00016000"],["79714.00000000","0.02400000"],["79713.90000000","0.00165000"],["79713.76000000","0.00010000"],["79713.56000000","0.00007000"],["79713.45000000","0.00014000"],["79713.21000000","0.00654000"],["79712.53000000","0.00008000"],["79712.00000000","0.02407000"],["79711.26000000","0.00035000"],["79711.23000000","0.05082000"],["79711.00000000","0.00270000"],["79710.76000000","0.00011000"],["79710.75000000","0.00030000"],["79710.72000000","0.00007000"],["79710.54000000","0.00007000"],["79710.00000000","0.02467000"],["79709.77000000","0.03499000"],["79709.57000000","0.00007000"],["79709.06000000","0.00007000"],["79708.33000000","0.00007000"],["79708.00000000","0.02400000"],["79707.66000000","0.00015000"],["79707.50000000","0.00026000"],["79707.44000000","0.00021000"],["79706.70000000","1.50310000"],["79706.59000000","0.03224000"],["79706.27000000","0.00007000"],["79706.00000000","0.02400000"],["79705.88000000","0.00959000"],["79705.59000000","0.00007000"],["79705.45000000","0.00022000"],["79705.00000000","0.00010000"],["79704.92000000","0.00007000"],["79704.88000000","0.00007000"],["79704.74000000","0.36586000"],["79704.27000000","0.00008000"],["79704.00000000","0.02462000"],["79703.83000000","0.00400000"],["79703.75000000","0.00013000"],["79703.74000000","0.00091000"],["79703.71000000","0.00021000"],["79703.56000000","0.00023000"],["79703.52000000","0.00123000"],["79703.38000000","0.00007000"],["79703.19000000","0.00044000"],["79702.92000000","0.00008000"],["79702.82000000","0.00015000"],["79702.64000000","0.00007000"],["79702.54000000","0.00024000"],["79702.00000000","0.02424000"],["79701.79000000","0.00008000"],["79701.66000000","0.00013000"],["79701.60000000","0.00007000"],["79701.33000000","0.00010000"],["79701.32000000","0.00034000"],["79700.91000000","0.00023000"],["79700.90000000","0.01267000"],["79700.89000000","0.00024000"],["79700.88000000","0.00010000"],["79700.85000000","0.00109000"],["79700.51000000","0.00033000"],["79700.48000000","0.00016000"],["79700.29000000","0.00013000"],["79700.28000000","0.05082000"],["79700.15000000","0.00093000"],["79700.10000000","0.00012000"],["79700.00000000","1.18142000"],["79699.86000000","0.00079000"],["79699.77000000","0.00010000"],["79699.72000000","0.00012000"],["79699.59000000","0.00043000"],["79699.51000000","0.00026000"],["79699.39000000","0.00007000"],["79699.32000000","0.00008000"],["79699.20000000","0.00007000"],["79699.02000000","0.00015000"],["79699.00000000","0.13279000"],["79698.79000000","0.00013000"],["79698.70000000","0.00007000"],["79698.63000000","0.00008000"],["79698.48000000","0.00007000"],["79697.89000000","0.00007000"],["79697.86000000","0.00012000"],["79697.56000000","0.00007000"],["79697.09000000","0.00010000"],["79696.96000000","0.00010000"],["79696.93000000","1.20000000"],["79696.91000000","0.00007000"],["79696.89000000","0.01961000"],["79696.86000000","0.00013000"],["79696.59000000","0.00015000"],["79696.55000000","0.00380000"],["79696.39000000","0.00032000"],["79696.10000000","0.00007000"],["79695.64000000","0.00012000"],["79695.39000000","0.00011000"],["79695.21000000","0.03224000"],["79695.12000000","0.00010000"],["79694.87000000","0.00010000"],["79694.84000000","0.00134000"],["79694.71000000","0.00009000"],["79694.66000000","0.00007000"],["79694.44000000","0.00031000"],["79694.34000000","0.00035000"],["79694.22000000","0.00048000"],["79694.05000000","0.00050000"],["79694.00000000","0.00087000"],["79693.69000000","0.00012000"],["79693.58000000","0.00020000"],["79693.43000000","0.00118000"],["79693.33000000","0.00019000"],["79693.13000000","0.00072000"],["79692.59000000","0.00025000"],["79692.48000000","0.00007000"],["79692.41000000","0.00007000"],["79692.32000000","0.00951000"],["79692.30000000","0.00056000"],["79692.22000000","0.00028000"],["79692.07000000","0.00530000"],["79691.57000000","0.00019000"],["79691.34000000","0.00009000"],["79691.01000000","0.00100000"],["79690.79000000","0.00020000"],["79690.52000000","0.00159000"],["79690.50000000","0.00022000"],["79690.37000000","0.00008000"],["79690.31000000","0.00009000"],["79690.30000000","0.00007000"],["79690.00000000","0.00050000"],["79689.80000000","0.00026000"],["79689.65000000","0.00007000"],["79689.59000000","0.00030000"],["79689.44000000","0.00026000"],["79689.35000000","0.00007000"],["79689.19000000","0.00028000"],["79689.16000000","0.00122000"],["79689.00000000","0.00125000"],["79688.88000000","0.00013000"],["79688.76000000","0.00012000"],["79688.63000000","0.00098000"],["79688.40000000","0.00019000"],["79688.34000000","0.00007000"],["79688.20000000","3.76555000"],["79687.85000000","0.00009000"],["79687.77000000","0.00023000"],["79687.55000000","0.00007000"],["79687.50000000","0.00685000"],["79687.44000000","0.00007000"],["79687.36000000","0.00023000"],["79687.12000000","0.00012000"],["79687.03000000","0.00010000"],["79686.99000000","0.00023000"],["79686.95000000","0.00418000"],["79686.89000000","0.01000000"],["79686.72000000","0.00014000"],["79685.71000000","0.00008000"],["79685.56000000","0.00013000"],["79685.36000000","0.00007000"],["79684.94000000","0.00045000"],["79684.66000000","0.00025000"],["79684.65000000","0.00501000"],["79684.56000000","0.00007000"],["79684.52000000","4.40424000"],["79684.21000000","0.00457000"],["79684.15000000","0.00013000"],["79683.74000000","0.00007000"],["79683.66000000","0.11607000"],["79683.58000000","0.00021000"],["79683.54000000","0.00007000"],["79683.48000000","0.00023000"],["79683.18000000","0.00008000"],["79683.15000000","0.00374000"],["79683.07000000","0.00008000"],["79682.96000000","0.00007000"],["79682.75000000","0.00020000"],["79682.72000000","0.00007000"],["79682.12000000","0.00007000"],["79681.92000000","0.00007000"],["79681.81000000","0.00010000"],["79681.62000000","0.00025000"],["79681.51000000","0.00132000"],["79681.46000000","0.00026000"],["79681.39000000","0.00011000"],["79680.97000000","0.00010000"],["79680.88000000","0.00014000"],["79680.85000000","0.00007000"],["79680.82000000","0.00010000"],["79680.56000000","0.00007000"],["79680.38000000","0.00023000"],["79680.36000000","0.00148000"],["79680.32000000","0.00050000"],["79680.11000000","0.00019000"],["79680.00000000","0.02056000"],["79679.90000000","0.00144000"],["79679.89000000","0.00033000"],["79679.17000000","0.00010000"],["79679.06000000","0.00010000"],["79679.02000000","0.00009000"],["79678.57000000","0.00028000"],["79678.55000000","0.00007000"],["79678.27000000","0.00048000"],["79678.17000000","0.00007000"],["79677.97000000","0.00010000"],["79677.58000000","0.00012000"],["79677.53000000","0.00009000"],["79677.47000000","0.00454000"],["79677.41000000","0.00130000"],["79677.21000000","0.00011000"],["79677.06000000","0.00007000"],["79676.94000000","0.01389000"],["79676.89000000","0.00245000"],["79676.76000000","0.00039000"],["79676.60000000","0.00190000"],["79676.47000000","0.00653000"],["79676.40000000","0.00091000"],["79676.19000000","0.00007000"],["79675.91000000","0.00007000"],["79675.86000000","0.00053000"],["79675.78000000","0.00021000"],["79675.70000000","0.00008000"],["79675.67000000","0.00156000"],["79675.66000000","3.40571000"],["79675.00000000","0.00012000"],["79674.66000000","0.00014000"],["79674.64000000","0.01572000"],["79674.47000000","0.00060000"],["79674.41000000","0.00094000"],["79674.33000000","0.00007000"],["79674.14000000","0.00057000"],["79673.70000000","0.00013000"],["79673.64000000","0.00007000"],["79673.37000000","0.00026000"],["79673.33000000","0.00025000"],["79673.20000000","0.00020000"],["79673.14000000","0.00008000"],["79672.84000000","0.00062000"],["79672.78000000","0.00007000"],["79672.69000000","0.00012000"],["79672.31000000","0.00010000"],["79672.01000000","0.00270000"],["79671.91000000","0.00007000"],["79671.90000000","0.00200000"],["79671.39000000","0.00010000"],["79670.91000000","0.11607000"],["79670.66000000","0.00007000"],["79670.58000000","0.00031000"],["79670.26000000","0.00012000"],["79670.14000000","0.00016000"],["79670.01000000","0.00013000"],["79670.00000000","0.00067000"],["79669.97000000","0.00008000"],["79669.86000000","0.00013000"],["79669.78000000","0.00078000"],["79669.77000000","0.00125000"],["79669.70000000","0.00007000"],["79669.48000000","0.00105000"],["79668.89000000","0.00368000"],["79668.85000000","0.00007000"],["79668.59000000","0.00044000"],["79668.58000000","0.00065000"],["79668.49000000","0.00010000"],["79668.13000000","0.00864000"],["79668.00000000","0.03000000"],["79667.95000000","0.00088000"],["79667.46000000","0.00009000"],["79667.45000000","0.00043000"],["79667.27000000","0.00269000"],["79667.26000000","2.32631000"],["79667.17000000","0.00008000"],["79667.09000000","0.03229000"],["79667.04000000","0.00008000"],["79667.03000000","0.00029000"],["79666.66000000","0.03573000"],["79666.60000000","0.00011000"],["79666.55000000","0.00124000"],["79666.52000000","0.00034000"],["79666.40000000","0.00010000"],["79666.28000000","0.00137000"],["79666.19000000","0.00602000"],["79666.10000000","0.00007000"],["79666.00000000","0.00215000"],["79665.88000000","0.00281000"],["79665.61000000","0.00007000"],["79665.36000000","0.00038000"],["79665.35000000","0.00011000"],["79665.25000000","0.01255000"],["79665.22000000","0.00007000"],["79664.86000000","0.00007000"],["79664.73000000","0.00009000"],["79664.62000000","0.00414000"],["79664.39000000","0.00055000"],["79664.16000000","0.00007000"],["79664.12000000","3.76684000"],["79664.01000000","0.00055000"],["79663.85000000","0.00048000"],["79663.55000000","0.00011000"],["79663.45000000","0.00062000"],["79663.37000000","0.00007000"],["79663.24000000","0.00022000"],["79663.14000000","0.00012000"],["79663.08000000","0.00020000"],["79663.03000000","0.00007000"],["79662.85000000","0.00183000"],["79662.83000000","0.00007000"],["79662.56000000","0.00007000"],["79662.33000000","0.00031000"],["79662.03000000","0.00031000"],["79661.66000000","0.00014000"],["79661.65000000","0.00012000"],["79661.30000000","0.00413000"],["79661.26000000","0.00007000"],["79661.19000000","0.00023000"],["79661.18000000","0.00007000"],["79661.15000000","0.00070000"],["79661.11000000","0.00011000"],["79660.69000000","0.00008000"],["79660.60000000","0.23795000"],["79660.56000000","0.00007000"],["79660.00000000","0.00390000"],["79659.82000000","0.00010000"],["79659.78000000","0.00012000"],["79659.77000000","0.00010000"],["79659.75000000","0.00011000"],["79659.53000000","0.00008000"],["79659.36000000","0.00007000"],["79659.09000000","0.00075000"],["79658.95000000","0.11607000"],["79658.92000000","0.00023000"],["79658.70000000","0.00036000"],["79658.36000000","0.00007000"],["79658.26000000","0.00065000"],["79658.01000000","0.00087000"],["79657.99000000","0.00010000"],["79657.87000000","0.00010000"],["79657.78000000","0.00007000"],["79657.44000000","0.00011000"],["79657.35000000","0.00026000"],["79657.14000000","0.00134000"],["79656.71000000","0.00016000"],["79656.64000000","0.00065000"],["79656.61000000","0.00007000"],["79656.50000000","0.00048000"],["79656.49000000","0.00008000"],["79656.43000000","0.00009000"],["79656.25000000","0.00023000"],["79656.22000000","0.00752000"],["79655.94000000","0.01762000"],["79655.50000000","0.00010000"],["79655.44000000","0.00014000"],["79655.17000000","0.00122000"],["79654.94000000","0.00017000"],["79654.67000000","0.00080000"],["79654.59000000","0.00007000"],["79654.56000000","0.00080000"],["79654.47000000","0.00007000"],["79654.27000000","0.00012000"],["79654.11000000","0.00008000"],["79653.84000000","0.00090000"],["79653.57000000","0.00044000"],["79652.73000000","0.00028000"],["79652.70000000","0.00280000"],["79652.52000000","0.00007000"],["79652.38000000","0.00007000"],["79652.36000000","0.00013000"],["79652.25000000","0.00007000"],["79652.15000000","0.00178000"],["79651.98000000","0.00181000"],["79651.21000000","0.00023000"],["79651.20000000","0.00010000"],["79651.15000000","0.00116000"],["79650.98000000","0.00009000"],["79650.97000000","0.00048000"]],"asks":[["79859.22000000","4.17284000"],["79859.23000000","0.00027000"],["79859.24000000","0.00013000"],["79860.23000000","0.00007000"],["79860.24000000","0.13119000"],["79860.25000000","0.10494000"],["79860.49000000","0.00014000"],["79860.50000000","0.01909000"],["79861.28000000","0.00007000"],["79861.29000000","0.00007000"],["79861.32000000","0.00014000"],["79861.44000000","0.00007000"],["79861.77000000","0.00007000"],["79861.78000000","0.02279000"],["79862.00000000","0.00007000"],["79862.01000000","0.20652000"],["79862.13000000","0.00007000"],["79862.14000000","0.04800000"],["79862.56000000","0.00007000"],["79862.78000000","0.00400000"],["79863.06000000","0.02279000"],["79863.45000000","0.00400000"],["79863.99000000","0.00007000"],["79864.00000000","0.90535000"],["79864.01000000","0.21471000"],["79864.63000000","0.00007000"],["79864.90000000","0.36586000"],["79864.91000000","0.00007000"],["79865.19000000","0.00014000"],["79865.20000000","0.00013000"],["79865.52000000","0.00400000"],["79866.06000000","0.00026000"],["79866.19000000","0.20942000"],["79866.71000000","0.00007000"],["79867.21000000","0.00008000"],["79867.45000000","0.00007000"],["79867.46000000","0.07500000"],["79867.47000000","0.00717000"],["79867.56000000","1.87677000"],["79867.57000000","0.41838000"],["79867.58000000","1.04939000"],["79868.00000000","0.02400000"],["79868.26000000","0.00400000"],["79868.50000000","0.10459000"],["79868.60000000","0.12520000"],["79868.79000000","0.00015000"],["79869.06000000","0.00014000"],["79869.80000000","0.00007000"],["79869.83000000","0.00010000"],["79869.91000000","0.00007000"],["79870.00000000","0.02400000"],["79870.22000000","0.27346000"],["79870.23000000","0.78157000"],["79870.44000000","0.08576000"],["79870.74000000","0.00007000"],["79870.86000000","0.00007000"],["79871.48000000","0.00400000"],["79871.61000000","0.00709000"],["79871.67000000","0.00007000"],["79871.97000000","0.19019000"],["79871.98000000","1.04939000"],["79872.00000000","0.02407000"],["79872.28000000","0.00917000"],["79872.93000000","0.00014000"],["79872.94000000","0.00007000"],["79873.10000000","0.00007000"],["79873.15000000","0.98462000"],["79873.68000000","0.00007000"],["79873.95000000","1.87677000"],["79873.96000000","0.00720000"],["79873.97000000","0.36586000"],["79874.00000000","0.02400000"],["79874.01000000","0.34254000"],["79874.18000000","0.00026000"],["79874.26000000","0.35288000"],["79874.44000000","0.14772000"],["79874.67000000","0.02000000"],["79874.74000000","0.00007000"],["79874.83000000","0.00250000"],["79875.02000000","0.00007000"],["79875.18000000","0.00400000"],["79875.19000000","0.00015000"],["79875.96000000","0.00007000"],["79875.98000000","1.13479000"],["79875.99000000","1.04939000"],["79876.00000000","0.02400000"],["79876.01000000","0.65851000"],["79876.29000000","0.00007000"],["79876.45000000","0.00701000"],["79876.61000000","0.00915000"],["79876.76000000","0.00007000"],["79876.80000000","0.00014000"],["79876.86000000","0.00008000"],["79877.09000000","0.00007000"],["79877.56000000","0.00007000"],["79877.60000000","0.00400000"],["79877.81000000","0.00010000"],["79878.00000000","0.02400000"],["79878.14000000","0.02480000"],["79878.89000000","0.02000000"],["79879.01000000","0.02000000"],["79879.07000000","0.58567000"],["79879.08000000","0.33809000"],["79879.11000000","1.87677000"],["79879.17000000","0.00007000"],["79879.18000000","0.00008000"],["79879.70000000","0.02000000"],["79879.71000000","0.02000000"],["79879.78000000","0.02000000"],["79879.80000000","0.00400000"],["79879.82000000","0.02000000"],["79880.00000000","0.08223000"],["79880.32000000","0.33809000"],["79880.37000000","0.57634000"],["79880.38000000","1.04939000"],["79880.61000000","0.00903000"],["79880.67000000","0.00014000"],["79880.74000000","0.00626000"],["79880.75000000","0.00007000"],["79880.80000000","0.35043000"],["79881.25000000","0.00007000"],["79881.44000000","0.00007000"],["79881.56000000","0.09400000"],["79881.74000000","0.02000000"],["79881.94000000","0.00007000"],["79882.00000000","0.02400000"],["79882.12000000","0.02000000"],["79882.18000000","0.00026000"],["79882.20000000","0.36586000"],["79882.24000000","0.00400000"],["79882.53000000","0.02000000"],["79882.89000000","0.02000000"],["79883.16000000","0.03000000"],["79883.18000000","0.00008000"],["79883.31000000","0.12518000"],["79883.32000000","0.00007000"],["79883.36000000","0.02000000"],["79883.55000000","0.10342000"],["79883.70000000","0.02000000"],["79883.75000000","0.04000000"],["79883.95000000","0.00400000"],["79883.96000000","0.63023000"],["79883.97000000","1.38303000"],["79883.98000000","1.87677000"],["79884.00000000","0.73288000"],["79884.02000000","0.30000000"],["79884.03000000","0.30007000"],["79884.07000000","0.30000000"],["79884.09000000","0.00400000"],["79884.54000000","0.00014000"],["79884.60000000","1.04939000"],["79884.63000000","0.00250000"],["79884.93000000","0.00008000"],["79885.32000000","0.00007000"],["79885.40000000","0.00007000"],["79885.71000000","0.33806000"],["79885.79000000","0.00010000"],["79885.87000000","0.03224000"],["79885.98000000","0.00928000"],["79886.00000000","0.02400000"],["79886.01000000","0.01227000"],["79886.45000000","0.33806000"],["79887.06000000","0.00400000"],["79887.17000000","0.00008000"],["79887.23000000","0.62604000"],["79887.48000000","0.00007000"],["79888.00000000","0.02407000"],["79888.03000000","0.00200000"],["79888.09000000","0.00012000"],["79888.20000000","0.00191000"],["79888.41000000","0.00014000"],["79889.20000000","0.00007000"],["79889.42000000","0.04625000"],["79889.56000000","0.00007000"],["79889.71000000","0.00007000"],["79889.74000000","1.07355000"],["79889.75000000","1.87677000"],["79890.00000000","0.07452000"],["79890.03000000","0.00400000"],["79890.25000000","0.01010000"],["79890.48000000","0.36586000"],["79891.01000000","0.00059000"],["79891.16000000","0.04008000"],["79891.22000000","0.00026000"],["79891.41000000","1.04939000"],["79891.63000000","0.00007000"],["79891.97000000","0.00007000"],["79891.99000000","1.52655000"],["79892.00000000","0.72400000"],["79892.26000000","0.08000000"],["79892.28000000","0.00014000"],["79893.00000000","0.00408000"],["79893.22000000","0.01270000"],["79893.53000000","0.33803000"],["79893.71000000","0.00007000"],["79893.77000000","0.00010000"],["79893.99000000","0.00007000"],["79894.00000000","0.22650000"],["79894.64000000","1.87677000"],["79895.16000000","0.00008000"],["79895.20000000","0.00400000"],["79895.39000000","0.00125000"],["79895.50000000","1.04939000"],["79895.58000000","0.49206000"],["79895.79000000","0.00007000"],["79896.00000000","0.02400000"],["79896.15000000","0.00014000"],["79896.96000000","0.00007000"],["79896.99000000","1.34646000"],["79897.69000000","0.00007000"],["79897.86000000","0.00007000"],["79897.89000000","0.00300000"],["79897.91000000","0.00007000"],["79897.92000000","0.62596000"],["79898.00000000","0.02800000"],["79898.58000000","0.36586000"],["79898.76000000","0.20631000"],["79898.96000000","0.02000000"],["79899.13000000","1.23937000"],["79899.15000000","0.00008000"],["79899.24000000","0.62820000"],["79899.40000000","0.00026000"],["79899.44000000","1.87677000"],["79899.75000000","0.00400000"],["79899.89000000","0.02000000"],["79899.93000000","0.42954000"],["79899.94000000","0.00007000"],["79899.98000000","0.72624000"],["79899.99000000","1.04939000"],["79900.00000000","0.08406000"],["79900.24000000","0.09563000"],["79900.28000000","0.00007000"],["79900.53000000","0.03224000"],["79900.93000000","0.20631000"],["79901.07000000","0.00008000"],["79901.37000000","0.25000000"],["79901.43000000","0.00430000"],["79901.75000000","0.00010000"],["79901.99000000","0.20250000"],["79902.00000000","0.72400000"],["79902.02000000","0.00007000"],["79902.19000000","0.02000000"],["79902.27000000","0.00012000"],["79902.69000000","0.00622000"],["79902.96000000","0.02000000"],["79903.43000000","0.02000000"],["79903.46000000","0.00400000"],["79903.77000000","0.02000000"],["79903.82000000","0.04429000"],["79903.97000000","0.00007000"],["79904.00000000","0.02407000"],["79904.10000000","0.00007000"],["79904.32000000","0.83149000"],["79904.47000000","1.49231000"],["79904.48000000","1.87677000"],["79904.50000000","1.04939000"],["79904.72000000","0.00007000"],["79905.54000000","0.00427000"],["79905.99000000","0.00007000"],["79906.00000000","0.02400000"],["79906.03000000","0.02000000"],["79906.17000000","0.00007000"],["79906.58000000","0.36586000"],["79906.66000000","0.02000000"],["79906.90000000","0.02000000"],["79906.95000000","0.02444000"],["79907.03000000","0.02000000"],["79907.40000000","0.00014000"],["79907.48000000","1.23924000"],["79907.75000000","0.00026000"],["79907.81000000","1.59199000"],["79907.99000000","0.00007000"],["79908.00000000","0.02400000"],["79908.25000000","0.00007000"],["79908.61000000","1.04939000"],["79908.62000000","0.20631000"],["79908.67000000","0.02000000"],["79909.13000000","1.20219000"],["79909.14000000","0.00008000"],["79909.45000000","0.02000000"],["79909.54000000","1.87677000"],["79909.73000000","0.00010000"],["79909.98000000","0.20250000"],["79909.99000000","0.00007000"],["79910.00000000","0.03000000"],["79910.33000000","0.00007000"],["79910.81000000","0.00235000"],["79911.83000000","1.02993000"],["79911.94000000","0.01270000"],["79911.99000000","0.00007000"],["79912.00000000","0.02400000"],["79912.41000000","0.00007000"],["79912.48000000","0.00007000"],["79912.71000000","1.02090000"],["79912.72000000","1.04939000"],["79912.82000000","0.81651000"],["79913.58000000","0.00100000"],["79913.88000000","0.00007000"],["79914.00000000","0.02400000"],["79914.48000000","0.00007000"],["79915.01000000","1.87677000"],["79915.07000000","0.00007000"],["79915.57000000","0.34702000"],["79915.84000000","0.00026000"],["79915.98000000","0.00007000"],["79916.00000000","0.02400000"],["79916.06000000","1.23912000"],["79916.15000000","0.75769000"],["79916.56000000","0.00007000"],["79916.73000000","0.03224000"],["79916.97000000","1.04939000"],["79917.21000000","0.00008000"],["79917.44000000","0.20631000"],["79917.71000000","0.00010000"],["79917.81000000","0.00007000"],["79918.00000000","0.02400000"],["79918.64000000","0.00007000"],["79918.81000000","0.20250000"],["79919.70000000","0.51612000"],["79919.93000000","1.50371000"],["79919.94000000","1.87677000"],["79919.95000000","0.36586000"],["79920.00000000","1.01576000"],["79920.24000000","0.00007000"],["79920.72000000","0.00007000"],["79920.79000000","0.00007000"],["79920.95000000","0.00075000"],["79921.06000000","0.00007000"],["79921.73000000","1.04939000"],["79921.88000000","0.00884000"],["79922.00000000","0.02400000"],["79922.01000000","0.01876000"],["79922.42000000","0.00413000"],["79922.80000000","0.00007000"],["79923.38000000","0.02000000"],["79923.52000000","0.02000000"],["79923.88000000","0.00026000"],["79924.00000000","0.02400000"],["79924.06000000","1.45779000"],["79924.31000000","0.00200000"],["79924.60000000","0.00007000"],["79924.73000000","0.02000000"],["79924.86000000","0.02000000"],["79925.14000000","0.03456000"],["79925.28000000","0.00008000"],["79925.69000000","0.00010000"],["79925.77000000","1.04939000"],["79925.79000000","1.87677000"],["79925.99000000","0.00312000"],["79926.00000000","0.02400000"],["79926.79000000","0.00190000"],["79926.80000000","0.20250000"],["79926.86000000","1.23897000"],["79926.89000000","0.02000000"],["79926.95000000","0.00007000"],["79926.98000000","0.00007000"],["79927.01000000","0.00313000"],["79927.02000000","0.02000000"],["79927.05000000","0.02000000"],["79927.27000000","0.02000000"],["79927.37000000","0.02000000"],["79927.83000000","0.02000000"],["79927.99000000","0.16360000"],["79928.00000000","0.02407000"],["79928.16000000","0.02000000"],["79928.23000000","0.02000000"],["79928.24000000","0.02000000"],["79928.51000000","0.36586000"],["79929.44000000","0.02000000"],["79929.85000000","0.00007000"],["79929.90000000","0.00007000"],["79930.00000000","0.02400000"],["79930.20000000","0.00400000"],["79930.32000000","0.00625000"],["79931.60000000","0.03224000"],["79931.94000000","0.89330000"],["79931.96000000","0.00007000"],["79931.97000000","0.00007000"],["79932.00000000","0.02400000"],["79932.09000000","0.00026000"],["79933.19000000","0.00007000"],["79933.35000000","0.00008000"],["79933.60000000","1.04939000"],["79933.66000000","0.01132000"],["79933.67000000","0.00010000"],["79933.98000000","0.00007000"],["79934.00000000","0.02400000"],["79934.71000000","1.87677000"],["79935.15000000","0.00010000"],["79935.37000000","0.00070000"],["79935.52000000","0.01270000"],["79935.76000000","0.00007000"],["79935.99000000","0.00007000"],["79936.00000000","0.02407000"],["79936.45000000","0.04695000"],["79936.84000000","0.01713000"],["79937.02000000","0.73766000"],["79937.03000000","0.82399000"],["79937.08000000","0.36586000"],["79938.00000000","0.02400000"],["79938.01000000","0.20250000"],["79938.07000000","0.00007000"],["79938.18000000","1.04939000"],["79939.13000000","0.00535000"],["79939.42000000","0.00007000"],["79939.78000000","0.85077000"],["79939.79000000","1.87677000"],["79939.99000000","0.00047000"],["79940.00000000","0.24051000"],["79941.06000000","0.00007000"],["79941.11000000","0.00026000"],["79941.37000000","0.00111000"],["79941.42000000","0.00008000"],["79941.65000000","0.00010000"],["79942.00000000","0.02400000"],["79943.20000000","0.00200000"],["79943.52000000","0.00007000"],["79943.58000000","0.00007000"],["79943.64000000","0.00007000"],["79943.65000000","0.00007000"],["79943.84000000","0.03224000"],["79944.00000000","0.02400000"],["79945.22000000","0.12338000"],["79945.23000000","0.36586000"],["79945.67000000","0.00008000"],["79945.68000000","0.00021000"],["79945.82000000","0.00007000"],["79945.89000000","0.00100000"],["79945.99000000","0.00007000"],["79946.00000000","0.02400000"],["79946.19000000","0.00014000"],["79947.63000000","1.42069000"],["79947.64000000","1.04939000"],["79947.74000000","0.00007000"],["79947.94000000","0.00007000"],["79948.00000000","0.22650000"],["79949.32000000","0.00007000"],["79949.33000000","0.00026000"],["79949.49000000","0.00008000"],["79949.63000000","0.00010000"],["79949.75000000","1.95360000"],["79949.99000000","0.00270000"],["79950.00000000","0.03129000"],["79951.28000000","0.00007000"],["79951.52000000","1.87677000"],["79951.56000000","0.03456000"],["79952.00000000","0.02400000"],["79952.56000000","2.04668000"],["79952.57000000","3.75321000"],["79953.16000000","0.00007000"],["79953.97000000","0.00007000"],["79954.00000000","0.02400000"],["79954.41000000","0.36586000"],["79954.88000000","2.31235000"],["79955.00000000","0.00011000"],["79955.15000000","0.00007000"],["79955.24000000","0.00556000"],["79955.45000000","0.00012000"],["79955.51000000","0.40000000"],["79955.57000000","0.00070000"],["79956.00000000","0.02400000"],["79956.44000000","0.99299000"],["79956.45000000","1.04939000"],["79957.15000000","0.00007000"],["79957.28000000","0.03224000"],["79957.39000000","0.00026000"],["79957.56000000","0.00008000"],["79957.61000000","0.00010000"],["79958.00000000","0.02400000"],["79958.13000000","0.00007000"],["79958.25000000","0.00025000"],["79958.33000000","0.09823000"],["79958.40000000","0.00239000"],["79958.54000000","0.00500000"],["79958.89000000","1.87677000"],["79959.04000000","0.00007000"],["79959.18000000","0.20250000"],["79959.19000000","0.09322000"],["79959.21000000","0.00197000"],["79959.22000000","0.00491000"],["79959.42000000","0.00007000"],["79959.88000000","1.67735000"],["79959.96000000","0.00390000"],["79960.00000000","1.02515000"],["79960.29000000","0.00200000"],["79960.96000000","0.00010000"],["79961.00000000","0.00202000"],["79961.44000000","0.00007000"],["79961.65000000","3.43863000"],["79961.72000000","1.04939000"],["79961.79000000","0.00007000"],["79962.00000000","0.02400000"],["79962.16000000","0.00400000"],["79963.65000000","0.00007000"],["79963.75000000","1.17139000"],["79963.76000000","1.87677000"],["79963.92000000","0.00007000"],["79964.00000000","0.02400000"],["79964.13000000","0.00078000"],["79964.37000000","0.00007000"],["79964.78000000","0.00018000"],["79964.80000000","1.99149000"],["79964.96000000","0.00007000"],["79965.16000000","0.00070000"],["79965.33000000","0.00380000"],["79965.59000000","0.00036000"],["79965.63000000","0.00008000"],["79965.87000000","0.00088000"],["79966.00000000","0.02400000"],["79966.04000000","0.00032000"],["79966.29000000","0.00018000"],["79966.55000000","0.12076000"],["79966.60000000","0.00012000"],["79966.80000000","0.00014000"],["79967.46000000","0.00007000"],["79967.51000000","0.00016000"],["79967.53000000","0.02804000"],["79967.61000000","0.00025000"],["79967.75000000","0.13066000"],["79967.82000000","0.01662000"],["79967.83000000","0.36586000"],["79968.00000000","0.02420000"],["79968.01000000","0.00151000"],["79968.15000000","0.00007000"],["79969.87000000","0.00176000"],["79970.00000000","0.02450000"],["79970.02000000","0.00011000"],["79970.50000000","0.00375000"],["79970.57000000","0.00010000"],["79970.58000000","0.00009000"],["79970.60000000","0.00053000"],["79971.08000000","0.00049000"],["79971.44000000","0.00007000"],["79972.00000000","0.02400000"],["79972.72000000","0.20250000"],["79972.95000000","0.85507000"],["79972.96000000","1.87677000"],["79972.98000000","0.03224000"],["79973.25000000","0.00007000"],["79973.56000000","0.00007000"],["79973.57000000","0.00010000"],["79973.70000000","0.00008000"],["79974.00000000","0.02400000"],["79974.29000000","0.92475000"],["79974.34000000","0.00026000"],["79974.52000000","0.00010000"],["79974.56000000","0.00007000"],["79975.00000000","0.00024000"],["79975.87000000","0.00012000"],["79975.99000000","0.01616000"],["79976.00000000","0.02400000"],["79976.12000000","0.00007000"],["79976.15000000","0.00007000"],["79976.26000000","0.00016000"],["79977.76000000","0.00007000"],["79977.90000000","0.00011000"],["79978.00000000","0.02400000"],["79978.27000000","0.00104000"],["79978.47000000","0.00007000"],["79978.56000000","0.00018000"],["79979.11000000","0.00055000"],["79979.90000000","0.00007000"],["79979.99000000","1.04860000"],["79980.00000000","1.02719000"],["79980.46000000","0.04600000"],["79980.70000000","0.20250000"],["79981.00000000","0.00007000"],["79981.55000000","0.00010000"],["79981.62000000","0.01162000"],["79981.81000000","0.01580000"],["79982.00000000","0.02400000"],["79982.21000000","0.36586000"],["79982.32000000","0.00007000"],["79982.38000000","0.00020000"],["79982.41000000","0.00026000"],["79982.45000000","0.00007000"],["79982.55000000","1.87677000"],["79982.72000000","0.00031000"],["79983.55000000","0.00117000"],["79983.99000000","0.93606000"],["79984.00000000","0.02400000"],["79984.98000000","0.00014000"],["79985.16000000","0.00007000"],["79985.34000000","0.00007000"],["79985.44000000","0.00040000"],["79985.45000000","0.00029000"],["79985.71000000","0.00013000"],["79985.82000000","0.00100000"],["79986.00000000","0.02400000"],["79986.02000000","0.00375000"],["79986.41000000","0.00412000"],["79986.98000000","0.00140000"],["79987.53000000","3.75154000"],["79987.54000000","0.09017000"],["79988.00000000","0.02400000"],["79988.17000000","0.03224000"],["79988.68000000","0.20250000"],["79989.32000000","0.00007000"],["79989.53000000","0.00010000"],["79989.84000000","0.00008000"],["79989.96000000","0.00035000"],["79989.99000000","0.00270000"],["79990.00000000","0.02817000"],["79990.08000000","0.00007000"],["79990.65000000","0.00026000"],["79991.97000000","0.02071000"],["79992.00000000","0.02400000"],["79992.16000000","0.00016000"],["79992.37000000","0.01961000"],["79992.85000000","0.00394000"],["79992.87000000","0.00007000"],["79993.73000000","0.00007000"],["79994.00000000","0.02400000"],["79994.02000000","0.00375000"],["79994.15000000","0.00007000"],["79994.28000000","0.00011000"],["79994.55000000","0.00036000"],["79994.94000000","0.00007000"],["79995.56000000","0.00007000"],["79995.88000000","0.00007000"],["79996.00000000","0.02400000"],["79996.06000000","0.00038000"],["79996.18000000","0.18857000"],["79996.59000000","0.36586000"],["79996.66000000","0.20250000"],["79996.85000000","0.00007000"],["79997.44000000","0.00069000"],["79997.51000000","0.00010000"],["79997.62000000","0.00041000"],["79998.00000000","0.02400000"],["79998.36000000","0.00378000"],["79998.83000000","0.00026000"],["79999.00000000","0.00461000"],["79999.01000000","0.01307000"],["79999.03000000","0.01059000"],["79999.10000000","0.00010000"],["79999.17000000","0.00007000"],["79999.38000000","0.00007000"],["79999.55000000","0.00022000"],["79999.60000000","0.00136000"],["79999.85000000","0.00010000"],["79999.90000000","1.02096000"],["79999.94000000","0.00010000"],["80000.00000000","3.41279000"],["80000.17000000","0.04451000"],["80001.80000000","0.00007000"],["80001.83000000","0.00010000"],["80002.12000000","0.00008000"],["80002.42000000","0.00007000"],["80002.51000000","0.00007000"],["80003.61000000","0.00124000"],["80003.99000000","0.00409000"],["80004.63000000","0.17095000"],["80004.64000000","0.20250000"],["80004.85000000","0.00268000"],["80005.00000000","0.00025000"],["80005.04000000","0.00007000"],["80005.46000000","0.36586000"],["80005.54000000","0.00017000"],["80005.95000000","0.00009000"],["80005.98000000","0.00008000"],["80006.05000000","0.00007000"],["80006.58000000","0.00076000"],["80006.59000000","0.00033000"],["80006.85000000","0.00026000"],["80007.19000000","0.00018000"],["80007.44000000","0.00010000"],["80008.00000000","0.00087000"],["80008.04000000","0.00007000"],["80008.52000000","0.00022000"],["80008.56000000","0.00016000"],["80009.02000000","0.00007000"],["80009.70000000","0.00007000"],["80010.00000000","0.00057000"],["80010.03000000","0.00065000"],["80010.09000000","0.00400000"],["80010.14000000","0.44868000"],["80010.15000000","1.50310000"],["80011.58000000","0.00125000"],["80011.59000000","0.00025000"],["80012.00000000","0.30955000"],["80012.23000000","0.00007000"],["80012.46000000","0.03224000"],["80012.61000000","0.00023000"],["80012.62000000","0.20250000"],["80012.68000000","0.00008000"],["80012.85000000","0.80000000"],["80013.36000000","0.00007000"],["80013.42000000","0.00007000"],["80013.72000000","0.00011000"],["80013.89000000","0.00010000"],["80013.94000000","0.00011000"],["80014.31000000","0.00010000"],["80014.71000000","0.00055000"],["80014.90000000","0.00026000"],["80015.29000000","0.00045000"],["80015.37000000","0.00008000"],["80015.74000000","1.54613000"],["80016.06000000","0.00007000"],["80016.21000000","0.00007000"],["80016.66000000","0.00010000"],["80017.14000000","0.04644000"],["80017.15000000","0.00076000"],["80017.64000000","0.00027000"],["80018.81000000","0.00007000"],["80018.82000000","0.00007000"],["80019.07000000","0.00125000"],["80019.08000000","0.36586000"],["80019.10000000","3.74998000"],["80019.33000000","0.00010000"],["80019.50000000","0.07720000"],["80019.99000000","0.00869000"],["80020.00000000","0.00078000"],["80020.60000000","0.20250000"],["80021.13000000","0.03224000"],["80021.19000000","0.00007000"],["80021.34000000","0.00007000"],["80021.42000000","0.00030000"],["80021.57000000","0.00024000"],["80021.85000000","0.00007000"],["80022.12000000","0.00008000"],["80022.22000000","0.00055000"],["80022.76000000","0.00014000"],["80023.13000000","0.00007000"],["80023.25000000","0.00094000"],["80023.28000000","0.00011000"],["80023.30000000","0.00026000"],["80023.52000000","0.00030000"],["80023.74000000","0.02000000"],["80023.77000000","0.00014000"],["80024.70000000","0.00011000"],["80024.83000000","0.00023000"],["80025.00000000","0.00043000"],["80025.16000000","0.00013000"],["80025.53000000","0.00008000"],["80025.67000000","0.00007000"],["80025.83000000","0.00007000"],["80026.29000000","0.00041000"],["80026.63000000","0.00007000"],["80026.97000000","0.00140000"],["80026.98000000","0.05818000"],["80027.39000000","0.00008000"],["80027.71000000","0.00226000"],["80028.29000000","0.06617000"],["80028.44000000","0.00039000"],["80028.57000000","0.00015000"],["80028.58000000","0.20250000"],["80029.22000000","0.00007000"],["80029.37000000","0.00011000"],["80029.38000000","0.00008000"],["80029.41000000","0.00156000"],["80029.98000000","0.00270000"],["80030.00000000","0.01142000"],["80030.01000000","0.00077000"],["80030.07000000","0.00013000"],["80030.10000000","0.00009000"],["80030.30000000","0.00010000"],["80031.25000000","0.00007000"],["80031.31000000","0.00026000"],["80031.35000000","0.00122000"],["80031.41000000","0.00007000"],["80031.91000000","0.00007000"],["80032.00000000","0.00007000"],["80032.15000000","0.12905000"],["80032.16000000","0.06930000"],["80032.69000000","0.00008000"],["80033.06000000","0.00010000"],["80033.17000000","0.00010000"],["80033.31000000","0.00265000"],["80033.33000000","0.00077000"],["80033.42000000","0.00139000"],["80033.52000000","0.00025000"],["80033.74000000","0.00100000"],["80034.28000000","0.00053000"],["80034.88000000","0.36586000"],["80034.90000000","0.00007000"],["80035.45000000","0.00007000"],["80035.46000000","0.00088000"],["80035.57000000","0.17543000"],["80035.58000000","0.34723000"],["80035.76000000","0.02000000"],["80036.03000000","0.00012000"],["80036.56000000","0.20250000"],["80036.64000000","0.00007000"],["80037.03000000","0.00043000"],["80037.19000000","0.00007000"],["80037.22000000","0.00015000"],["80037.44000000","0.00126000"],["80037.53000000","0.00007000"],["80037.64000000","0.00010000"],["80037.68000000","0.00041000"],["80038.18000000","0.00187000"],["80038.26000000","0.00008000"],["80038.52000000","0.03224000"],["80038.85000000","0.00072000"],["80038.93000000","0.00040000"],["80039.79000000","0.00007000"],["80039.81000000","0.00050000"],["80039.84000000","0.00026000"],["80040.00000000","0.00195000"],["80040.01000000","0.00052000"],["80040.24000000","0.00009000"],["80040.55000000","0.00150000"],["80040.78000000","0.01602000"],["80040.80000000","0.00010000"],["80040.93000000","0.00313000"],["80041.22000000","0.00016000"],["80041.64000000","0.00007000"],["80041.77000000","0.00014000"],["80042.15000000","0.00050000"],["80042.47000000","0.00007000"],["80042.73000000","0.00109000"],["80042.85000000","0.00007000"],["80043.25000000","0.00010000"],["80043.46000000","0.00010000"],["80043.78000000","0.00007000"],["80044.17000000","0.00012000"],["80044.53000000","0.08419000"],["80044.54000000","0.20250000"],["80044.63000000","0.00028000"],["80045.29000000","0.00010000"],["80045.39000000","0.00007000"],["80045.42000000","0.00008000"],["80045.63000000","0.00007000"],["80045.72000000","0.03134000"],["80045.95000000","0.00044000"],["80047.05000000","0.00031000"],["80047.75000000","0.00045000"],["80047.77000000","0.00007000"],["80047.88000000","0.00026000"],["80048.04000000","0.00007000"],["80049.06000000","0.00007000"],["80049.14000000","0.00926000"],["80049.25000000","0.44309000"],["80049.26000000","0.36586000"],["80049.66000000","0.00125000"],["80049.87000000","0.00020000"],["80050.00000000","1.00087000"],["80050.28000000","0.00007000"],["80050.53000000","0.11607000"],["80050.62000000","4.50440000"],["80051.13000000","0.00007000"],["80051.50000000","0.09345000"],["80051.51000000","0.10010000"],["80051.58000000","0.00007000"],["80051.76000000","0.00007000"],["80051.92000000","0.00007000"],["80051.99000000","0.00007000"],["80052.13000000","0.00012000"],["80052.44000000","0.00011000"],["80052.52000000","0.20250000"],["80052.98000000","0.00040000"],["80053.04000000","0.00007000"],["80053.26000000","0.00010000"],["80053.50000000","0.00129000"],["80053.52000000","0.00018000"],["80053.58000000","0.00007000"],["80053.64000000","0.00057000"],["80053.81000000","0.00007000"],["80054.31000000","0.00010000"],["80054.40000000","0.00058000"],["80054.46000000","0.00237000"],["80055.00000000","0.00007000"],["80055.26000000","0.00007000"],["80055.92000000","0.00053000"],["80056.01000000","0.01234000"],["80056.27000000","0.00026000"],["80056.60000000","0.00025000"],["80056.73000000","0.00007000"],["80056.74000000","0.00164000"],["80057.14000000","0.00048000"],["80057.25000000","0.00074000"],["80057.49000000","0.00256000"],["80057.59000000","0.00028000"],["80057.61000000","0.00007000"],["80058.32000000","0.00007000"],["80058.82000000","0.00025000"],["80059.11000000","0.00042000"],["80059.43000000","0.00007000"],["80059.92000000","0.00007000"],["80060.00000000","0.00176000"],["80060.24000000","0.00013000"],["80060.40000000","0.00034000"],["80060.49000000","0.20463000"],["80060.50000000","0.20250000"],["80060.52000000","0.00007000"],["80060.58000000","0.00029000"],["80061.53000000","0.00046000"],["80062.10000000","0.00007000"],["80062.54000000","0.11607000"],["80062.56000000","0.00014000"],["80062.78000000","0.36586000"],["80062.82000000","0.00007000"],["80063.61000000","0.00007000"],["80063.82000000","0.00009000"],["80064.00000000","0.00007000"],["80064.15000000","0.00017000"],["80064.72000000","0.00026000"],["80064.91000000","3.74793000"],["80065.00000000","0.00018000"],["80065.13000000","3.74783000"],["80065.15000000","0.00032000"],["80065.65000000","0.02105000"],["80066.09000000","0.00007000"],["80066.66000000","0.00058000"],["80066.84000000","0.00381000"],["80067.46000000","0.00007000"],["80067.99000000","0.00007000"],["80068.00000000","0.00025000"],["80068.75000000","0.00019000"],["80068.89000000","0.00007000"],["80068.90000000","0.00007000"],["80069.18000000","0.00223000"],["80069.99000000","0.00269000"],["80070.00000000","0.00057000"],["80071.26000000","0.00007000"],["80071.42000000","0.00017000"],["80072.13000000","0.00008000"],["80072.21000000","0.00107000"],["80073.03000000","0.00008000"],["80073.12000000","0.00056000"],["80073.18000000","0.00026000"],["80073.58000000","0.00007000"],["80073.59000000","0.00007000"],["80073.64000000","0.00012000"],["80074.10000000","0.00374000"],["80074.16000000","0.00021000"],["80074.17000000","0.00007000"],["80074.39000000","0.01253000"],["80074.55000000","0.11607000"],["80074.67000000","0.00056000"],["80074.73000000","0.00007000"],["80075.00000000","0.00033000"],["80075.18000000","0.00013000"],["80076.46000000","0.20250000"],["80076.50000000","0.00023000"],["80076.60000000","0.00045000"],["80076.70000000","0.00023000"],["80076.73000000","0.00021000"],["80076.80000000","0.00010000"],["80076.81000000","0.00007000"],["80076.92000000","0.00007000"],["80077.16000000","0.36586000"],["80077.39000000","0.00007000"],["80077.58000000","0.00026000"],["80077.62000000","0.00049000"],["80077.87000000","0.00007000"],["80079.02000000","0.01961000"],["80079.13000000","0.00011000"],["80079.30000000","0.00026000"],["80079.31000000","0.00018000"],["80079.33000000","0.00009000"],["80079.46000000","0.00007000"],["80079.76000000","0.00010000"],["80079.84000000","0.00260000"],["80080.00000000","0.00090000"],["80080.39000000","0.00016000"],["80080.50000000","0.00007000"],["80080.83000000","0.00007000"],["80081.25000000","0.00012000"],["80081.50000000","0.00026000"],["80081.65000000","0.00007000"],["80081.99000000","0.00400000"],["80082.11000000","0.00374000"],["80082.19000000","0.00016000"],["80082.30000000","0.00067000"],["80082.35000000","0.00007000"],["80082.43000000","0.11196000"],["80083.20000000","0.00007000"],["80083.33000000","0.00007000"],["80083.43000000","0.00007000"],["80083.76000000","0.00008000"],["80083.83000000","0.00007000"],["80083.96000000","0.00010000"],["80084.02000000","0.01262000"],["80084.40000000","0.00007000"],["80084.74000000","0.00007000"],["80085.42000000","0.00027000"],["80085.63000000","0.00011000"],["80086.27000000","0.00672000"],["80086.28000000","0.00013000"],["80086.37000000","0.00019000"],["80086.57000000","0.11607000"],["80086.68000000","0.00008000"],["80086.76000000","0.00007000"],["80087.57000000","0.00008000"],["80087.62000000","0.00011000"],["80087.68000000","0.00250000"],["80088.23000000","0.00010000"],["80088.88000000","0.00202000"],["80088.94000000","0.00240000"],["80089.13000000","0.00008000"],["80089.32000000","0.00190000"],["80089.55000000","0.00007000"],["80089.70000000","0.00026000"],["80089.95000000","0.00013000"],["80090.00000000","0.00050000"],["80090.03000000","0.00007000"],["80090.09000000","0.00111000"],["80090.10000000","0.00010000"]]}}
{"rx_ns": 13950892932400, "frame": {"stream":"btcusdt@depth@100ms","data":{"e":"depthUpdate","E":1787650946114,"s":"BTCUSDT","U":99118673332,"u":99118673344,"b":[["79859.21000000","1.19243000"],["71873.29000000","0.00432000"],["71873.00000000","0.00000000"]],"a":[["79859.22000000","4.17117000"],["79866.19000000","0.20942000"],["79867.07000000","0.00000000"]]}}}
{"rx_ns": 13950995915000, "frame": {"stream":"btcusdt@depth@100ms","data":{"e":"depthUpdate","E":1787650946214,"s":"BTCUSDT","U":99118673345,"u":99118673354,"b":[["79859.21000000","1.39693000"],["71873.29000000","0.00416000"],["63887.37000000","0.00000000"],["42044.20000000","0.00000000"]],"a":[["80298.53000000","0.01506000"],["80380.53000000","0.00000000"]]}}}
{"rx_ns": 13951092227100, "frame": {"stream":"btcusdt@depth@100ms","data":{"e":"depthUpdate","E":1787650946314,"s":"BTCUSDT","U":99118673355,"u":99118673369,"b":[["79859.21000000","1.19452000"],["79852.50000000","0.00000000"],["71873.29000000","0.00416000"],["71873.00000000","0.00000000"],["63887.00000000","0.01877000"]],"a":[]}}}
{"rx_ns": 13951200374200, "frame": {"stream":"btcusdt@depth@100ms","data":{"e":"depthUpdate","E":1787650946414,"s":"BTCUSDT","U":99118673370,"u":99118673375,"b":[["79852.52000000","0.06053000"],["79719.52000000","0.00020000"],["79686.95000000","0.00000000"],["79685.35000000","0.01407000"],["71873.29000000","0.00416000"]],"a":[["80049.14000000","0.00000000"],["80183.44000000","0.00895000"]]}}}
{"rx_ns": 13951299283700, "frame": {"stream":"btcusdt@depth@100ms","data":{"e":"depthUpdate","E":1787650946514,"s":"BTCUSDT","U":99118673376,"u":99118673388,"b":[["79859.21000000","1.29862000"],["79848.61000000","0.00000000"],["79815.64000000","0.00000000"],["79795.65000000","0.00000000"],["71873.29000000","0.00416000"],["71873.28000000","0.00008000"],["63887.37000000","0.00031000"]],"a":[["79879.78000000","0.00000000"],["79907.03000000","0.00000000"],["79927.02000000","0.00000000"],["79999.01000000","0.01327000"]]}}}
{"rx_ns": 13951392928700, "frame": {"stream":"btcusdt@depth@100ms","data":{"e":"depthUpdate","E":1787650946614,"s":"BTCUSDT","U":99118673389,"u":99118673391,"b":[["71873.29000000","0.00432000"],["63887.37000000","0.00000000"]],"a":[["90000.00000000","68.66467000"]]}}}
{"rx_ns": 13951492451900, "frame": {"stream":"btcusdt@depth@100ms","data":{"e":"depthUpdate","E":1787650946714,"s":"BTCUSDT","U":99118673392,"u":99118673395,"b":[["79859.21000000","1.29853000"],["71873.29000000","0.00416000"]],"a":[]}}}
{"rx_ns": 13951592495500, "frame": {"stream":"btcusdt@depth@100ms","data":{"e":"depthUpdate","E":1787650946814,"s":"BTCUSDT","U":99118673396,"u":99118673403,"b":[["79859.21000000","1.09610000"],["79802.37000000","0.00007000"],["79794.58000000","0.00007000"],["71873.29000000","0.00432000"]],"a":[["79859.22000000","4.17217000"]]}}}
{"rx_ns": 13951692415800, "frame": {"stream":"btcusdt@depth@100ms","data":{"e":"depthUpdate","E":1787650946914,"s":"BTCUSDT","U":99118673404,"u":99118673412,"b":[["79844.00000000","0.02400000"],["71873.29000000","0.00400000"],["63887.37000000","0.00000000"]],"a":[["79875.96000000","0.00000000"],["79945.22000000","0.68422000"],["79947.11000000","1.95360000"],["79947.63000000","0.97151000"],["79949.75000000","0.00000000"]]}}}
{"rx_ns": 13951793459000, "frame": {"stream":"btcusdt@depth20","data":{"lastUpdateId":99118673431,"bids":[["79859.21000000","1.09610000"],["79859.20000000","0.00083000"],["79859.19000000","0.00013000"],["79858.66000000","0.00086000"],["79858.65000000","0.08157000"],["79858.16000000","0.00126000"],["79858.01000000","0.00007000"],["79858.00000000","0.02435000"],["79857.77000000","0.00007000"],["79857.50000000","0.00007000"],["79857.45000000","0.00007000"],["79857.31000000","0.00007000"],["79856.88000000","0.00007000"],["79856.56000000","0.00007000"],["79856.55000000","0.05261000"],["79856.28000000","0.00007000"],["79856.27000000","0.00014000"],["79856.10000000","0.00759000"],["79856.03000000","0.00007000"],["79856.02000000","0.02021000"]],"asks":[["79859.22000000","4.17153000"],["79859.23000000","0.00027000"],["79859.24000000","0.00013000"],["79860.23000000","0.00007000"],["79860.24000000","0.13119000"],["79860.25000000","0.10494000"],["79860.49000000","0.00014000"],["79860.50000000","0.01909000"],["79861.28000000","0.00007000"],["79861.29000000","0.00007000"],["79861.32000000","0.00014000"],["79861.44000000","0.00007000"],["79861.77000000","0.00007000"],["79861.78000000","0.02279000"],["79862.00000000","0.00007000"],["79862.01000000","0.20652000"],["79862.13000000","0.00007000"],["79862.14000000","0.04800000"],["79862.56000000","0.00007000"],["79862.78000000","0.00400000"]]}}}
{"rx_ns": 13951793550200, "frame": {"stream":"btcusdt@depth@100ms","data":{"e":"depthUpdate","E":1787650947014,"s":"BTCUSDT","U":99118673413,"u":99118673431,"b":[["79855.25000000","0.12530000"],["79844.00000000","0.02407000"],["79843.90000000","0.02400000"],["79803.93000000","0.02400000"],["79783.88000000","0.02200000"],["78661.32000000","0.00030000"],["71873.29000000","0.00432000"],["63887.37000000","0.00031000"]],"a":[["79859.22000000","4.17153000"],["79873.48000000","0.02000000"],["79875.96000000","0.00007000"],["79893.46000000","0.02000000"],["79913.45000000","0.02000000"],["81057.11000000","0.00030000"]]}}}
{"rx_ns": 13951892240400, "frame": {"stream":"btcusdt@depth@100ms","data":{"e":"depthUpdate","E":1787650947114,"s":"BTCUSDT","U":99118673432,"u":99118673472,"b":[["79859.21000000","1.09610000"],["79859.20000000","0.00083000"],["79856.00000000","0.02421000"],["79855.26000000","0.00000000"],["79855.25000000","0.00000000"],["79854.01000000","0.00007000"],["79853.73000000","0.00007000"],["79853.12000000","0.55211000"],["79852.06000000","0.00000000"],["79852.05000000","0.00000000"],["71873.29000000","0.00416000"],["63887.00000000","0.01877000"]],"a":[["79863.99000000","0.00007000"],["79864.00000000","0.90535000"],["79864.89000000","0.00007000"]]}}}
{"rx_ns": 13951994205000, "frame": {"stream":"btcusdt@depth@100ms","data":{"e":"depthUpdate","E":1787650947214,"s":"BTCUSDT","U":99118673473,"u":99118673479,"b":[["79856.00000000","0.02421000"],["71873.29000000","0.00416000"],["63887.37000000","0.00000000"]],"a":[]}}}
{"rx_ns": 13952096036300, "frame": {"stream":"btcusdt@depth@100ms","data":{"e":"depthUpdate","E":1787650947314,"s":"BTCUSDT","U":99118673480,"u":99118673489,"b":[["71873.29000000","0.00416000"],["63887.00000000","0.01877000"]],"a":[]}}}
{"rx_ns": 13952192253500, "frame": {"stream":"btcusdt@depth@100ms","data":{"e":"depthUpdate","E":1787650947414,"s":"BTCUSDT","U":99118673490,"u":99118673522,"b":[["79859.21000000","0.57697000"],["79857.32000000","0.00000000"],["79856.28000000","0.00726000"],["79853.72000000","0.00000000"],["79853.11000000","0.00000000"],["79852.52000000","0.00000000"],["79850.60000000","0.00000000"],["79848.97000000","0.00020000"],["79848.48000000","0.00000000"],["79848.18000000","0.03000000"],["79846.88000000","0.12000000"],["79845.01000000","0.00000000"],["79836.13000000","0.00000000"],["79821.08000000","0.00000000"],["71873.29000000","0.00432000"],["71873.00000000","0.00000000"]],"a":[["79859.22000000","4.22306000"],["79861.28000000","0.00000000"],["79861.92000000","0.00938000"],["79863.21000000","0.00687000"],["79863.99000000","0.00000000"],["79864.00000000","0.90528000"],["79864.89000000","0.00000000"],["79872.81000000","0.03224000"],["79895.58000000","0.00000000"],["79911.83000000","0.00000000"]]}}}
{"rx_ns": 13952296493100, "frame": {"stream":"btcusdt@depth@100ms","data":{"e":"depthUpdate","E":1787650947514,"s":"BTCUSDT","U":99118673523,"u":99118673559,"b":[["79859.21000000","0.78006000"],["79859.20000000","0.00090000"],["79856.55000000","0.05261000"],["79856.28000000","0.00007000"],["79854.43000000","0.02275000"],["79853.73000000","0.00000000"],["79853.58000000","0.00007000"],["79853.45000000","0.00007000"],["79853.16000000","0.06053000"],["79846.88000000","0.04000000"],["79845.98000000","0.08000000"],["79843.32000000","0.00000000"],["79821.50000000","0.00000000"],["79801.51000000","0.00000000"],["71873.29000000","0.00400000"],["63887.37000000","0.00031000"]],"a":[["79861.78000000","0.02286000"],["79861.92000000","0.00952000"],["79863.06000000","0.02286000"],["79863.99000000","0.00007000"],["79864.00000000","0.90521000"],["79879.82000000","0.00000000"],["79899.89000000","0.00000000"],["79923.52000000","0.00000000"]]}}}
{"rx_ns": 13952391905000, "frame": {"stream":"btcusdt@depth@100ms","data":{"e":"depthUpdate","E":1787650947614,"s":"BTCUSDT","U":99118673560,"u":99118673570,"b":[["79859.21000000","0.77999000"],["79859.20000000","0.00083000"],["79856.55000000","0.05261000"],["71873.29000000","0.00432000"],["63887.37000000","0.00000000"]],"a":[["79902.14000000","0.00400000"],["79903.46000000","0.00000000"]]}}}
{"rx_ns": 13952494825800, "frame": {"stream":"btcusdt@depth@100ms","data":{"e":"depthUpdate","E":1787650947714,"s":"BTCUSDT","U":99118673571,"u":99118673603,"b":[["79859.21000000","1.40942000"],["79845.98000000","0.00000000"],["79845.08000000","0.08000000"],["79835.14000000","0.51108000"],["79811.19000000","1.01772000"],["79788.01000000","0.03195000"],["79784.94000000","0.02087000"],["71873.29000000","0.00416000"]],"a":[["79859.22000000","4.17153000"],["79861.28000000","0.00014000"],["79861.92000000","0.00014000"],["79862.76000000","0.00942000"],["79863.06000000","0.02279000"],["79863.21000000","0.00000000"],["79863.99000000","0.00007000"],["79864.00000000","0.90521000"],["79864.89000000","0.00007000"],["79887.82000000","0.50093000"],["79911.79000000","0.97566000"]]}}}
{"rx_ns": 13952598629600, "frame": {"stream":"btcusdt@depth@100ms","data":{"e":"depthUpdate","E":1787650947814,"s":"BTCUSDT","U":99118673604,"u":99118673639,"b":[["79859.21000000","1.40238000"],["79844.08000000","0.02000000"],["79811.20000000","1.30337000"],["79811.04000000","0.00000000"],["79804.10000000","0.02000000"],["79784.94000000","0.00000000"],["71873.29000000","0.00416000"]],"a":[["79861.78000000","0.02279000"],["79861.92000000","0.00000000"],["79862.14000000","0.04807000"],["79862.76000000","0.00956000"],["79863.06000000","0.02279000"],["79863.45000000","0.00000000"],["79864.01000000","0.21478000"],["79864.30000000","0.00695000"],["79864.67000000","0.00400000"],["79873.52000000","0.02000000"],["79893.51000000","0.02000000"],["79913.49000000","0.02000000"]]}}}
{"rx_ns": 13952692002400, "frame": {"stream":"btcusdt@depth@100ms","data":{"e":"depthUpdate","E":1787650947914,"s":"BTCUSDT","U":99118673640,"u":99118673680,"b":[["79859.21000000","1.40238000"],["79859.20000000","0.00083000"],["79856.00000000","0.02421000"],["79855.23000000","0.00000000"],["79855.22000000","0.00000000"],["79854.44000000","0.00007000"],["79854.01000000","0.00007000"],["79853.58000000","0.00014000"],["79853.45000000","0.00007000"],["79500.00000000","10.25792000"],["77500.00000000","13.40825000"],["63887.37000000","0.00000000"]],"a":[["79863.99000000","0.00007000"],["79864.00000000","0.90521000"],["79864.89000000","0.00007000"],["79870.23000000","0.71093000"]]}}}
{"rx_ns": 13952795500700, "frame": {"stream":"btcusdt@depth20","data":{"lastUpdateId":99118673714,"bids":[["79859.21000000","1.40238000"],["79859.20000000","0.00083000"],["79859.19000000","0.00013000"],["79858.66000000","0.00086000"],["79858.65000000","0.08157000"],["79858.16000000","0.00126000"],["79858.01000000","0.00007000"],["79858.00000000","0.02435000"],["79857.77000000","0.00007000"],["79857.50000000","0.00007000"],["79857.45000000","0.00007000"],["79857.31000000","0.00007000"],["79856.88000000","0.00007000"],["79856.56000000","0.00007000"],["79856.55000000","0.05261000"],["79856.28000000","0.00007000"],["79856.27000000","0.00014000"],["79856.10000000","0.00759000"],["79856.03000000","0.00007000"],["79856.02000000","0.02021000"]],"asks":[["79859.22000000","4.17153000"],["79859.23000000","0.00027000"],["79859.24000000","0.00013000"],["79860.23000000","0.00007000"],["79860.24000000","0.13119000"],["79860.25000000","0.10494000"],["79860.49000000","0.00014000"],["79860.50000000","0.01909000"],["79861.28000000","0.00014000"],["79861.29000000","0.00007000"],["79861.32000000","0.00014000"],["79861.44000000","0.00007000"],["79861.77000000","0.00007000"],["79861.78000000","0.02279000"],["79862.00000000","0.00007000"],["79862.01000000","0.20652000"],["79862.13000000","0.00007000"],["79862.14000000","0.04807000"],["79862.56000000","0.00007000"],["79862.76000000","0.00956000"]]}}}
{"rx_ns": 13952795617200, "frame": {"stream":"btcusdt@depth@100ms","data":{"e":"depthUpdate","E":1787650948014,"s":"BTCUSDT","U":99118673681,"u":99118673714,"b":[["79849.90000000","0.00048000"],["79849.40000000","0.00000000"],["79844.00000000","0.02407000"],["79809.86000000","0.00000000"],["79795.91000000","0.04696000"],["79784.94000000","0.02087000"],["79783.94000000","0.02400000"],["78661.32000000","0.00030000"],["71873.29000000","0.00416000"],["63887.37000000","0.00031000"]],"a":[["79870.22000000","0.20213000"],["79870.23000000","0.00157000"],["79875.96000000","0.00007000"],["81057.11000000","0.00030000"]]}}}
{"rx_ns": 13952892260200, "frame": {"stream":"btcusdt@depth@100ms","data":{"e":"depthUpdate","E":1787650948114,"s":"BTCUSDT","U":99118673715,"u":99118673752,"b":[["79859.21000000","1.19017000"],["79854.44000000","0.00007000"],["79854.05000000","0.00695000"],["79854.01000000","0.00007000"],["79853.74000000","0.00007000"],["79853.73000000","0.04018000"],["79853.45000000","0.00000000"],["79812.50000000","0.00400000"],["79810.72000000","0.00000000"],["79784.94000000","0.00000000"],["71873.29000000","0.00432000"]],"a":[["79859.22000000","4.17142000"],["79863.99000000","0.00007000"],["79864.00000000","0.90521000"],["79864.89000000","0.00000000"],["79868.49000000","0.10536000"],["79870.22000000","0.00000000"]]}}}
{"rx_ns": 13952992360800, "frame": {"stream":"btcusdt@depth@100ms","data":{"e":"depthUpdate","E":1787650948214,"s":"BTCUSDT","U":99118673753,"u":99118673759,"b":[["79859.21000000","1.19247000"],["79696.89000000","0.00000000"],["71873.29000000","0.00416000"],["63887.37000000","0.00000000"]],"a":[["79859.22000000","4.17109000"],["79864.89000000","0.00007000"]]}}}
{"rx_ns": 13953091567000, "frame": {"stream":"btcusdt@depth@100ms","data":{"e":"depthUpdate","E":1787650948314,"s":"BTCUSDT","U":99118673760,"u":99118673777,"b":[["79859.21000000","1.20179000"],["79857.45000000","0.00014000"],["79852.51000000","0.00000000"],["79818.75000000","0.00000000"],["79814.88000000","0.00000000"],["79726.70000000","0.00000000"],["79708.80000000","0.01961000"],["71873.29000000","0.00432000"],["63887.00000000","0.01877000"]],"a":[["79859.22000000","3.31084000"],["79861.32000000","0.00007000"],["79900.02000000","0.00007000"]]}}}
{"rx_ns": 13953198969500, "frame": {"stream":"btcusdt@depth@100ms","data":{"e":"depthUpdate","E":1787650948414,"s":"BTCUSDT","U":99118673778,"u":99118674116,"b":[["79859.21000000","1.53483000"],["79859.20000000","0.00062000"],["79858.67000000","0.00007000"],["79858.66000000","0.12264000"],["79858.65000000","0.08164000"],["79858.04000000","0.00902000"],["79858.02000000","0.00000000"],["79858.01000000","0.00007000"],["79858.00000000","0.02449000"],["79857.70000000","0.00026000"],["79857.39000000","0.00000000"],["79857.38000000","0.00007000"],["79856.94000000","0.00690000"],["79856.78000000","0.00007000"],["79856.77000000","0.06053000"],["79856.56000000","0.00007000"],["79856.55000000","0.05268000"],["79856.17000000","0.00007000"],["79856.16000000","0.06053000"],["79856.03000000","0.00000000"],["79856.02000000","0.00021000"],["79856.01000000","0.00007000"],["79856.00000000","0.02435000"],["79855.56000000","0.00007000"],["79855.55000000","0.06053000"],["79855.15000000","0.00000000"],["79854.95000000","0.00007000"],["79854.94000000","0.06053000"],["79854.82000000","0.01263000"],["79854.68000000","0.06053000"],["79854.44000000","0.00000000"],["79854.43000000","0.02268000"],["79854.05000000","0.00702000"],["79854.01000000","0.00000000"],["79853.74000000","0.06679000"],["79853.21000000","0.00000000"],["79853.20000000","0.00000000"],["79853.12000000","0.37171000"],["79852.75000000","0.03224000"],["79852.50000000","0.00000000"],["79852.05000000","0.00000000"],["79850.25000000","0.99465000"],["79850.24000000","1.87677000"],["79850.23000000","0.00000000"],["79849.90000000","0.00000000"],["79849.34000000","0.00000000"],["79848.97000000","0.00000000"],["79845.85000000","0.00000000"],["79843.97000000","0.37582000"],["79843.21000000","0.33824000"],["79833.74000000","0.00000000"],["79827.51000000","0.00000000"],["79827.50000000","0.00000000"],["79822.50000000","0.00400000"],["79815.00000000","0.00400000"],["79814.99000000","0.00000000"],["79812.50000000","0.00000000"],["71873.29000000","0.00416000"]],"a":[["79859.22000000","1.73401000"],["79859.23000000","0.00055000"],["79860.23000000","0.00000000"],["79860.24000000","0.00014000"],["79860.25000000","0.00035000"],["79861.28000000","0.00000000"],["79861.78000000","0.02286000"],["79861.99000000","0.00007000"],["79862.00000000","0.08415000"],["79862.76000000","0.00014000"],["79862.86000000","0.00000000"],["79862.93000000","0.00000000"],["79863.05000000","0.00007000"],["79863.98000000","0.00000000"],["79863.99000000","0.00007000"],["79864.00000000","0.63163000"],["79864.01000000","0.21471000"],["79864.30000000","0.00000000"],["79864.43000000","0.00000000"],["79864.53000000","0.00000000"],["79864.67000000","0.00000000"],["79864.89000000","0.00007000"],["79864.91000000","0.00007000"],["79865.51000000","0.00016000"],["79866.18000000","0.00000000"],["79866.19000000","0.20309000"],["79867.45000000","0.00000000"],["79867.46000000","0.00000000"],["79867.47000000","0.00007000"],["79867.56000000","0.00000000"],["79867.92000000","0.00000000"],["79868.13000000","0.00000000"],["79868.85000000","0.00706000"],["79869.05000000","0.00626000"],["79871.96000000","0.00000000"],["79871.97000000","0.00000000"],["79872.81000000","0.00000000"],["79873.09000000","0.00000000"],["79873.14000000","0.00400000"],["79873.94000000","0.00400000"],["79874.67000000","0.00000000"],["79876.57000000","0.02000000"],["79879.06000000","0.19019000"],["79879.08000000","0.00000000"],["79880.00000000","0.07972000"],["79883.95000000","0.00000000"],["79883.96000000","0.62623000"],["79893.00000000","0.34211000"],["79899.13000000","0.00000000"],["79931.76000000","1.23887000"]]}}}
{"rx_ns": 13953292785700, "frame": {"stream":"btcusdt@depth@100ms","data":{"e":"depthUpdate","E":1787650948514,"s":"BTCUSDT","U":99118674117,"u":99118674217,"b":[["79859.21000000","1.33938000"],["79859.20000000","0.00069000"],["79858.66000000","0.12278000"],["79858.65000000","0.08171000"],["79858.04000000","0.00916000"],["79858.00000000","0.02449000"],["79857.70000000","0.00000000"],["79856.94000000","0.00704000"],["79856.77000000","0.00014000"],["79856.55000000","0.05254000"],["79856.16000000","0.00000000"],["79856.10000000","0.00745000"],["79856.02000000","0.00007000"],["79856.00000000","0.02421000"],["79854.82000000","0.01249000"],["79854.70000000","0.89139000"],["79854.69000000","1.04939000"],["79854.68000000","0.00000000"],["79853.74000000","0.00626000"],["79853.54000000","0.01491000"],["79853.16000000","0.00000000"],["79853.12000000","0.00000000"],["79840.13000000","0.00000000"],["71873.29000000","0.00432000"],["71873.00000000","0.00000000"],["63887.37000000","0.00031000"]],"a":[["79859.22000000","1.73211000"],["79860.24000000","0.00000000"],["79860.25000000","0.00021000"],["79861.78000000","0.02286000"],["79862.00000000","0.08429000"],["79862.14000000","0.04800000"],["79862.76000000","0.00000000"],["79864.00000000","0.63177000"],["79864.01000000","0.21485000"],["79891.98000000","0.09505000"],["79892.00000000","0.02400000"],["79900.24000000","0.00000000"],["79902.00000000","0.02400000"],["79966.55000000","0.00000000"],["79967.53000000","0.00000000"]]}}}
{"rx_ns": 13953392892000, "frame": {"stream":"btcusdt@depth@100ms","data":{"e":"depthUpdate","E":1787650948614,"s":"BTCUSDT","U":99118674218,"u":99118674255,"b":[["79859.21000000","1.54174000"],["79859.20000000","0.00062000"],["79858.66000000","0.06449000"],["79858.00000000","0.02442000"],["79857.38000000","0.00000000"],["79856.94000000","0.00704000"],["79856.78000000","0.00000000"],["79856.77000000","0.00000000"],["79856.55000000","0.05261000"],["79856.17000000","0.00000000"],["79854.95000000","0.00007000"],["79854.71000000","0.00007000"],["79854.70000000","0.89146000"],["79844.10000000","0.33824000"],["79809.53000000","0.00000000"],["79789.54000000","0.00000000"],["71873.29000000","0.00416000"],["63887.37000000","0.00000000"]],"a":[["79859.22000000","1.68399000"],["79863.99000000","0.00007000"],["79864.00000000","0.63177000"],["79864.89000000","0.00007000"],["79879.01000000","0.00000000"],["79906.03000000","0.00000000"],["79927.27000000","0.00000000"],["79959.39000000","0.02804000"]]}}}
{"rx_ns": 13953492347200, "frame": {"stream":"btcusdt@depth@100ms","data":{"e":"depthUpdate","E":1787650948714,"s":"BTCUSDT","U":99118674256,"u":99118674349,"b":[["79859.21000000","1.33861000"],["79859.20000000","0.00076000"],["79858.67000000","0.00000000"],["79858.66000000","0.00100000"],["79856.10000000","0.00759000"],["79854.71000000","0.00007000"],["79854.70000000","0.89146000"],["79854.68000000","0.00007000"],["71873.29000000","0.00432000"],["71873.28000000","0.00000000"],["71873.27000000","0.00008000"],["62000.00000000","97.81450000"],["60288.00000000","1.30016000"]],"a":[["79859.22000000","1.68369000"],["79859.23000000","0.00041000"],["79860.20000000","0.00007000"],["79860.21000000","0.03537000"],["79860.50000000","0.01916000"],["79861.25000000","0.00007000"],["79861.26000000","0.08537000"],["79861.27000000","0.00000000"],["79861.29000000","0.00000000"],["79861.99000000","0.00000000"],["79862.00000000","0.00021000"],["79863.05000000","0.00000000"],["79863.99000000","0.00007000"],["79864.00000000","0.63177000"],["79864.89000000","0.00007000"]]}}}
{"rx_ns": 13953592226500, "frame": {"stream":"btcusdt@depth@100ms","data":{"e":"depthUpdate","E":1787650948814,"s":"BTCUSDT","U":99118674350,"u":99118674412,"b":[["79859.21000000","1.54048000"],["79859.20000000","0.00062000"],["79858.66000000","0.00086000"],["79854.71000000","0.00007000"],["79854.70000000","0.89146000"],["79854.68000000","0.00007000"],["79784.12000000","0.02000000"],["79716.33000000","0.00000000"],["79714.90000000","0.00000000"],["79711.27000000","0.00125000"],["79710.01000000","0.00125000"],["79630.93000000","0.00771000"],["79599.03000000","0.00000000"],["71873.29000000","0.00400000"]],"a":[["79859.22000000","1.68411000"],["79859.23000000","0.00062000"],["79860.21000000","0.03551000"],["79860.50000000","0.01916000"],["79861.26000000","0.08551000"],["79861.78000000","0.02286000"],["79862.00000000","0.00007000"],["79863.05000000","0.00007000"],["79864.01000000","0.21471000"],["79864.89000000","0.00000000"],["80006.57000000","0.00125000"],["80006.84000000","0.00125000"],["80011.58000000","0.00000000"],["80019.07000000","0.00000000"]]}}}
{"rx_ns": 13953692587800, "frame": {"stream":"btcusdt@depth@100ms","data":{"e":"depthUpdate","E":1787650948914,"s":"BTCUSDT","U":99118674413,"u":99118674442,"b":[["79859.21000000","1.96337000"],["79854.71000000","0.00007000"],["79854.70000000","0.89146000"],["79854.68000000","0.00007000"],["79844.94000000","0.02600000"],["79804.97000000","0.02600000"],["79784.94000000","0.02087000"],["71873.29000000","0.00432000"],["63887.37000000","0.00000000"]],"a":[["79859.22000000","1.68223000"],["79859.23000000","0.00062000"],["79860.20000000","0.00000000"],["79860.21000000","0.00014000"],["79864.01000000","0.21478000"],["79864.85000000","0.00007000"],["79864.86000000","0.42275000"],["79869.29000000","0.00190000"],["79872.76000000","0.02000000"],["79892.74000000","0.02000000"],["79912.73000000","0.02000000"]]}}}
{"rx_ns": 13953792304600, "frame": {"stream":"btcusdt@depth20","data":{"lastUpdateId":99118674475,"bids":[["79859.21000000","1.96351000"],["79859.20000000","0.00076000"],["79859.19000000","0.00013000"],["79858.66000000","0.00086000"],["79858.65000000","0.08171000"],["79858.16000000","0.00126000"],["79858.04000000","0.00916000"],["79858.01000000","0.00007000"],["79858.00000000","0.02442000"],["79857.77000000","0.00007000"],["79857.50000000","0.00007000"],["79857.45000000","0.00014000"],["79857.31000000","0.00007000"],["79856.94000000","0.00704000"],["79856.88000000","0.00007000"],["79856.56000000","0.00007000"],["79856.55000000","0.05261000"],["79856.28000000","0.00007000"],["79856.27000000","0.00014000"],["79856.10000000","0.00759000"]],"asks":[["79859.22000000","1.68216000"],["79859.23000000","0.00062000"],["79859.24000000","0.00013000"],["79860.25000000","0.00021000"],["79860.49000000","0.00014000"],["79860.50000000","0.01916000"],["79861.25000000","0.00007000"],["79861.26000000","0.08551000"],["79861.32000000","0.00007000"],["79861.44000000","0.00007000"],["79861.77000000","0.00007000"],["79861.78000000","0.02286000"],["79862.00000000","0.00007000"],["79862.01000000","0.20652000"],["79862.09000000","0.00007000"],["79862.13000000","0.00007000"],["79862.14000000","0.04800000"],["79862.56000000","0.00007000"],["79862.78000000","0.00400000"],["79863.05000000","0.00007000"]]}}}
{"rx_ns": 13953792388300, "frame": {"stream":"btcusdt@depth@100ms","data":{"e":"depthUpdate","E":1787650949014,"s":"BTCUSDT","U":99118674443,"u":99118674475,"b":[["79859.21000000","1.96351000"],["79859.20000000","0.00076000"],["79854.06000000","0.00626000"],["79853.74000000","0.00000000"],["79853.02000000","0.00626000"],["79846.28000000","0.00000000"],["79844.00000000","0.02407000"],["79784.94000000","0.00000000"],["78661.32000000","0.00030000"],["71873.29000000","0.00432000"],["63887.37000000","0.00031000"]],"a":[["79859.22000000","1.68216000"],["79860.21000000","0.00000000"],["79862.09000000","0.00007000"],["79864.01000000","0.21492000"],["79868.78000000","0.00626000"],["79869.05000000","0.00000000"],["79869.29000000","0.00192000"],["79875.96000000","0.00007000"],["79944.77000000","0.11984000"],["81057.11000000","0.00030000"]]}}}
{"rx_ns": 13953892570000, "frame": {"stream":"btcusdt@depth@100ms","data":{"e":"depthUpdate","E":1787650949114,"s":"BTCUSDT","U":99118674476,"u":99118674477,"b":[["71873.29000000","0.00432000"]],"a":[]}}}
{"rx_ns": 13953992127400, "frame": {"stream":"btcusdt@depth@100ms","data":{"e":"depthUpdate","E":1787650949214,"s":"BTCUSDT","U":99118674478,"u":99118674482,"b":[["71873.29000000","0.00432000"],["63887.37000000","0.00000000"]],"a":[["79947.11000000","0.00000000"],["79949.75000000","1.95360000"]]}}}
{"rx_ns": 13954092138900, "frame": {"stream":"btcusdt@depth@100ms","data":{"e":"depthUpdate","E":1787650949314,"s":"BTCUSDT","U":99118674483,"u":99118674493,"b":[["79854.05000000","0.00695000"],["71873.29000000","0.00432000"],["63887.00000000","0.01877000"]],"a":[["79861.29000000","0.00007000"],["79863.81000000","0.17292000"],["79945.22000000","0.12338000"],["79947.63000000","1.42069000"]]}}}
{"rx_ns": 13954192743900, "frame": {"stream":"btcusdt@depth@100ms","data":{"e":"depthUpdate","E":1787650949414,"s":"BTCUSDT","U":99118674494,"u":99118674598,"b":[["79859.21000000","1.96379000"],["79859.20000000","0.00083000"],["79858.67000000","0.00007000"],["79858.66000000","0.09231000"],["79857.50000000","0.00407000"],["79856.94000000","0.00711000"],["79856.78000000","0.00007000"],["79856.77000000","0.00000000"],["79856.55000000","0.05268000"],["79856.17000000","0.00007000"],["79856.16000000","0.00000000"],["79856.15000000","0.00000000"],["79856.01000000","0.00007000"],["79855.56000000","0.00007000"],["79855.55000000","0.00000000"],["79855.00000000","0.00400000"],["79854.95000000","0.00007000"],["79854.94000000","0.00000000"],["79854.71000000","0.00000000"],["79854.70000000","0.83086000"],["79854.68000000","0.00000000"],["79854.43000000","0.02268000"],["79854.06000000","0.00000000"],["79853.74000000","0.00626000"],["79853.45000000","0.00000000"],["79853.02000000","0.00000000"],["79852.76000000","0.00626000"],["79845.35000000","0.36586000"],["79818.30000000","0.00000000"],["79815.00000000","0.00000000"],["71873.29000000","0.00432000"]],"a":[["79859.22000000","1.64837000"],["79861.26000000","0.13183000"],["79862.78000000","0.00000000"],["79863.06000000","0.02286000"],["79863.80000000","0.00007000"],["79863.81000000","0.17306000"],["79863.99000000","0.00007000"],["79864.00000000","0.63177000"],["79864.01000000","0.21478000"],["79864.85000000","0.00000000"],["79865.52000000","0.00000000"],["79868.25000000","0.00000000"],["79868.78000000","0.00000000"],["79869.28000000","0.00626000"],["79905.00000000","0.00400000"],["79907.50000000","0.00400000"],["79944.77000000","0.00000000"],["79945.31000000","0.00000000"],["79947.63000000","0.97151000"],["79949.75000000","0.00000000"]]}}}
{"rx_ns": 13954293049800, "frame": {"stream":"btcusdt@depth@100ms","data":{"e":"depthUpdate","E":1787650949514,"s":"BTCUSDT","U":99118674599,"u":99118674646,"b":[["79859.21000000","1.96365000"],["79859.20000000","0.00076000"],["79858.66000000","0.06322000"],["79856.94000000","0.00704000"],["79856.78000000","0.00000000"],["79856.55000000","0.05261000"],["79856.17000000","0.00000000"],["79856.00000000","0.02407000"],["79855.56000000","0.00000000"],["79854.95000000","0.00000000"],["79854.71000000","0.00007000"],["79854.70000000","0.83093000"],["79854.68000000","0.00007000"],["79854.05000000","0.00702000"],["79838.00000000","0.72400000"],["79828.00000000","0.02400000"],["79826.78000000","0.00400000"],["79823.57000000","0.00000000"],["79786.86000000","0.00400000"],["79783.65000000","0.00000000"],["79754.93000000","0.00400000"],["79751.72000000","0.00000000"],["79707.03000000","0.00400000"],["79703.83000000","0.00000000"],["79635.19000000","0.00400000"],["79631.99000000","0.00000000"],["71873.29000000","0.00432000"],["67880.00000000","0.00401000"],["63887.37000000","0.00031000"]],"a":[["79859.22000000","1.64845000"],["79862.09000000","0.00000000"],["79863.80000000","0.00007000"],["79863.99000000","0.00007000"],["79864.00000000","0.63177000"],["79870.22000000","0.00318000"],["79902.00000000","0.72400000"]]}}}
{"rx_ns": 13954392261200, "frame": {"stream":"btcusdt@depth@100ms","data":{"e":"depthUpdate","E":1787650949614,"s":"BTCUSDT","U":99118674647,"u":99118674662,"b":[["79826.78000000","0.00400000"],["79707.03000000","0.00400000"],["79635.19000000","0.00400000"],["71873.29000000","0.00448000"],["71873.27000000","0.00000000"],["71873.00000000","0.00000000"],["63887.37000000","0.00000000"],["63887.00000000","0.01877000"]],"a":[["79859.22000000","1.64836000"]]}}}
{"rx_ns": 13954500848700, "frame": {"stream":"btcusdt@depth@100ms","data":{"e":"depthUpdate","E":1787650949714,"s":"BTCUSDT","U":99118674663,"u":99118674711,"b":[["79859.21000000","1.96337000"],["79859.20000000","0.00062000"],["79858.66000000","0.09316000"],["79857.31000000","0.00076000"],["79856.94000000","0.00711000"],["79856.78000000","0.00007000"],["79856.77000000","0.06053000"],["79856.55000000","0.05268000"],["79856.28000000","0.00101000"],["79856.17000000","0.00007000"],["79856.16000000","0.06053000"],["79856.00000000","0.02414000"],["79855.56000000","0.00007000"],["79855.55000000","0.06067000"],["79855.15000000","0.00626000"],["79854.95000000","0.00007000"],["79854.94000000","0.06053000"],["79854.82000000","0.01256000"],["79854.71000000","0.06053000"],["79854.70000000","0.83086000"],["79854.68000000","0.00000000"],["79854.43000000","0.02261000"],["79852.76000000","0.00000000"],["79825.34000000","0.36172000"],["79789.63000000","0.04287000"],["71873.29000000","0.00432000"],["62777.00000000","0.10011000"]],"a":[["79859.22000000","0.99870000"],["79869.28000000","0.00000000"],["79869.29000000","0.00000000"],["79869.40000000","0.00187000"],["79870.85000000","0.00626000"]]}}}
{"rx_ns": 13954591899800, "frame": {"stream":"btcusdt@depth@100ms","data":{"e":"depthUpdate","E":1787650949814,"s":"BTCUSDT","U":99118674712,"u":99118674761,"b":[["79859.21000000","1.96330000"],["79859.20000000","0.00055000"],["79856.94000000","0.00711000"],["79856.77000000","0.06067000"],["79856.55000000","0.05268000"],["79856.10000000","0.00745000"],["79856.01000000","0.00007000"],["79855.56000000","0.00007000"],["79855.55000000","0.06060000"],["79855.15000000","0.00000000"],["79854.95000000","0.00007000"],["79853.75000000","0.00626000"],["71873.29000000","0.00448000"],["67880.00000000","0.00281000"],["63887.00000000","0.02077000"]],"a":[["79859.22000000","0.99610000"],["79861.25000000","0.00000000"],["79861.26000000","0.00014000"],["79861.99000000","0.00007000"],["79862.00000000","0.09134000"],["79863.80000000","0.00000000"],["79863.81000000","0.00014000"],["79864.00000000","0.63177000"],["79864.85000000","0.00007000"]]}}}
{"rx_ns": 13954700654100, "frame": {"stream":"btcusdt@depth@100ms","data":{"e":"depthUpdate","E":1787650949914,"s":"BTCUSDT","U":99118674762,"u":99118674974,"b":[["79859.21000000","3.98787000"],["79859.20000000","0.00027000"],["79858.67000000","0.00007000"],["79858.65000000","0.08178000"],["79858.15000000","0.03224000"],["79858.01000000","0.00007000"],["79858.00000000","0.02435000"],["79857.77000000","0.00000000"],["79857.73000000","0.00026000"],["79857.38000000","0.00000000"],["79856.78000000","0.00000000"],["79856.77000000","0.00014000"],["79856.56000000","0.00000000"],["79856.55000000","0.05261000"],["79856.17000000","0.00000000"],["79856.16000000","0.00000000"],["79856.01000000","0.00000000"],["79856.00000000","0.02414000"],["79855.65000000","0.00626000"],["79855.56000000","0.00000000"],["79855.55000000","0.00000000"],["79854.95000000","0.00000000"],["79854.94000000","0.00000000"],["79854.82000000","0.01249000"],["79854.72000000","0.00400000"],["79854.71000000","0.00000000"],["79854.05000000","0.00695000"],["79853.75000000","0.00000000"],["79853.74000000","0.00000000"],["79852.79000000","0.00161000"],["79851.64000000","0.37579000"],["79850.59000000","0.00000000"],["79850.46000000","0.33821000"],["79848.96000000","0.00000000"],["79846.52000000","0.02469000"],["79844.69000000","0.00000000"],["79843.50000000","0.00000000"],["79842.50000000","0.30458000"],["79832.25000000","0.00000000"],["79830.77000000","0.00000000"],["79791.60000000","0.00000000"],["79789.63000000","0.02200000"],["79784.98000000","0.02600000"],["71873.29000000","0.00432000"],["63887.37000000","0.00000000"],["63887.00000000","0.01877000"]],"a":[["79859.22000000","0.13515000"],["79859.23000000","0.00062000"],["79860.50000000","0.01909000"],["79861.26000000","0.00000000"],["79861.78000000","0.02286000"],["79861.99000000","0.00007000"],["79862.00000000","0.03971000"],["79862.01000000","0.00021000"],["79863.06000000","0.02286000"],["79863.48000000","0.00007000"],["79863.49000000","0.00007000"],["79863.81000000","0.00000000"],["79863.98000000","0.00007000"],["79863.99000000","0.06060000"],["79864.00000000","0.12384000"],["79864.01000000","0.00021000"],["79864.85000000","0.00000000"],["79864.86000000","0.00000000"],["79864.89000000","0.00000000"],["79864.90000000","0.00000000"],["79865.19000000","0.00007000"],["79865.51000000","0.00000000"],["79865.92000000","0.06053000"],["79865.98000000","0.00026000"],["79866.06000000","0.00000000"],["79866.18000000","0.00000000"],["79866.19000000","0.00007000"],["79866.54000000","0.06053000"],["79867.15000000","0.06053000"],["79867.55000000","0.00007000"],["79867.56000000","0.06060000"],["79867.57000000","0.40933000"],["79867.58000000","0.00000000"],["79868.00000000","0.02407000"],["79868.37000000","0.06053000"],["79868.48000000","0.06053000"],["79868.49000000","0.14770000"],["79868.50000000","0.10466000"],["79868.85000000","0.00000000"],["79869.39000000","0.00026000"],["79869.59000000","0.06053000"],["79870.20000000","0.06053000"],["79870.81000000","0.06053000"],["79870.85000000","0.00000000"],["79871.42000000","0.06053000"],["79871.61000000","0.00000000"],["79871.83000000","0.00713000"],["79871.97000000","0.97843000"],["79873.09000000","0.00000000"],["79873.15000000","0.00000000"],["79873.95000000","0.00000000"],["79875.17000000","0.00626000"],["79876.57000000","0.00000000"],["79878.14000000","0.00000000"],["79878.79000000","0.02000000"],["79879.06000000","0.00000000"],["79879.07000000","0.00000000"],["79880.32000000","0.00000000"],["79883.17000000","0.00000000"],["79883.54000000","0.25611000"],["79883.96000000","0.00000000"],["79886.62000000","0.00007000"],["79887.23000000","0.00000000"],["79887.81000000","0.62624000"],["79899.63000000","0.33801000"],["79900.57000000","0.62593000"],["79903.89000000","0.00007000"],["79907.40000000","0.00007000"],["79907.81000000","1.02439000"],["79909.13000000","0.00000000"],["79926.79000000","0.00000000"],["79945.32000000","0.00000000"],["80006.58000000","0.00000000"]]}}}
{"rx_ns": 13954794832800, "frame": {"stream":"btcusdt@depth20","data":{"lastUpdateId":99118675172,"bids":[["79859.21000000","3.98447000"],["79859.20000000","0.00027000"],["79859.19000000","0.00013000"],["79858.67000000","0.00626000"],["79858.66000000","0.09309000"],["79858.65000000","0.08171000"],["79858.16000000","0.00126000"],["79858.15000000","0.03238000"],["79858.04000000","0.00916000"],["79858.00000000","0.02435000"],["79857.74000000","0.00626000"],["79857.73000000","0.00026000"],["79857.50000000","0.00407000"],["79857.45000000","0.00014000"],["79857.31000000","0.00076000"],["79856.94000000","0.00704000"],["79856.88000000","0.00007000"],["79856.55000000","0.05261000"],["79856.28000000","0.00101000"],["79856.27000000","0.00014000"]],"asks":[["79859.22000000","0.12225000"],["79859.23000000","0.00048000"],["79859.24000000","0.00013000"],["79860.25000000","0.00021000"],["79860.49000000","0.00014000"],["79860.50000000","0.01909000"],["79861.29000000","0.00007000"],["79861.32000000","0.00007000"],["79861.44000000","0.00007000"],["79861.77000000","0.00007000"],["79861.78000000","0.02286000"],["79862.00000000","0.00014000"],["79862.01000000","0.00007000"],["79862.13000000","0.00007000"],["79862.14000000","0.04800000"],["79862.56000000","0.00007000"],["79863.05000000","0.00007000"],["79863.06000000","0.02286000"],["79863.49000000","0.00007000"],["79863.99000000","0.00021000"]]}}}
{"rx_ns": 13954794954000, "frame": {"stream":"btcusdt@depth@100ms","data":{"e":"depthUpdate","E":1787650950014,"s":"BTCUSDT","U":99118674975,"u":99118675172,"b":[["79859.21000000","3.98447000"],["79858.67000000","0.00626000"],["79858.66000000","0.09309000"],["79858.65000000","0.08171000"],["79858.15000000","0.03238000"],["79858.01000000","0.00000000"],["79857.74000000","0.00626000"],["79856.94000000","0.00704000"],["79856.77000000","0.00000000"],["79856.55000000","0.05261000"],["79856.16000000","0.00000000"],["79855.65000000","0.00000000"],["79855.55000000","0.00000000"],["79854.94000000","0.00000000"],["79854.82000000","0.01249000"],["79854.71000000","0.00000000"],["79853.73000000","0.04025000"],["79853.54000000","0.01498000"],["79849.75000000","0.00000000"],["79844.00000000","0.02400000"],["79842.17000000","0.62623000"],["79830.78000000","0.00000000"],["79724.13000000","0.00000000"],["79697.59000000","0.00000000"],["78661.32000000","0.00030000"],["71873.29000000","0.00448000"],["71873.00000000","0.00010000"],["63887.37000000","0.00031000"]],"a":[["79859.22000000","0.12225000"],["79859.23000000","0.00048000"],["79861.99000000","0.00000000"],["79862.00000000","0.00014000"],["79862.01000000","0.00007000"],["79863.06000000","0.02286000"],["79863.48000000","0.00000000"],["79863.98000000","0.00000000"],["79863.99000000","0.00021000"],["79864.00000000","0.18070000"],["79864.01000000","0.00007000"],["79865.91000000","0.00007000"],["79865.92000000","0.06074000"],["79866.53000000","0.00007000"],["79866.54000000","0.06060000"],["79867.14000000","0.00007000"],["79867.15000000","0.06060000"],["79867.55000000","0.00007000"],["79867.56000000","0.06060000"],["79868.00000000","0.02414000"],["79868.37000000","0.05534000"],["79868.48000000","0.06053000"],["79868.49000000","0.13742000"],["79868.50000000","0.00007000"],["79868.59000000","0.00000000"],["79869.06000000","0.00007000"],["79869.39000000","0.00073000"],["79869.59000000","0.06053000"],["79870.00000000","0.02447000"],["79870.12000000","0.00000000"],["79870.20000000","0.06053000"],["79870.81000000","0.06053000"],["79871.42000000","0.06053000"],["79871.96000000","0.06453000"],["79871.97000000","0.72371000"],["79872.75000000","0.00626000"],["79875.17000000","0.00000000"],["79875.96000000","0.00000000"],["79880.74000000","0.00000000"],["79881.92000000","0.02480000"],["79882.88000000","0.00000000"],["79883.15000000","0.00000000"],["79883.53000000","0.19019000"],["79884.53000000","0.00626000"],["79885.71000000","0.00000000"],["79890.25000000","0.00610000"],["79898.37000000","1.20232000"],["79899.60000000","0.33801000"],["79930.20000000","0.00000000"],["79933.42000000","0.00400000"],["79946.38000000","0.00000000"],["79955.24000000","0.00000000"],["79962.16000000","0.00000000"],["79965.38000000","0.00400000"],["80010.09000000","0.00000000"],["80010.87000000","0.00000000"],["80013.32000000","0.00400000"],["80081.99000000","0.00000000"],["80085.22000000","0.00400000"],["80100.89000000","0.00000000"],["81057.11000000","0.00030000"]]}}}
{"rx_ns": 13954895594800, "frame": {"stream":"btcusdt@depth@100ms","data":{"e":"depthUpdate","E":1787650950114,"s":"BTCUSDT","U":99118675173,"u":99118675249,"b":[["79859.21000000","4.02489000"],["79858.67000000","0.00014000"],["79858.65000000","0.08178000"],["79858.17000000","0.00626000"],["79858.00000000","0.02442000"],["79857.73000000","0.00000000"],["79856.55000000","0.05247000"],["79856.00000000","0.02407000"],["79853.73000000","0.00007000"],["79847.89000000","0.00000000"],["79844.00000000","0.02407000"],["79724.83000000","0.04534000"],["71873.29000000","0.00432000"],["71873.00000000","0.00000000"]],"a":[["79859.22000000","0.12204000"],["79859.23000000","0.00062000"],["79861.78000000","0.02279000"],["79862.00000000","0.00000000"],["79863.06000000","0.02286000"],["79863.48000000","0.00007000"],["79863.49000000","0.05907000"],["79863.98000000","0.00007000"],["79863.99000000","0.06060000"],["79864.00000000","0.18084000"],["79864.70000000","0.00007000"],["79864.71000000","0.06053000"],["79865.31000000","0.00007000"],["79865.32000000","0.06053000"],["79866.53000000","0.00000000"],["79866.54000000","0.06074000"],["79867.14000000","0.00000000"],["79867.15000000","0.06074000"],["79867.55000000","0.00000000"],["79867.56000000","0.06053000"],["79867.57000000","0.40926000"],["79868.50000000","0.00000000"],["79869.06000000","0.00014000"],["79869.13000000","0.00048000"],["79869.39000000","0.00047000"],["79870.43000000","0.00032000"],["79875.96000000","0.00007000"],["79893.47000000","0.00400000"],["79902.00000000","0.02400000"],["79955.24000000","0.00556000"],["80085.22000000","0.00000000"],["86422.88000000","0.20801000"]]}}}
{"rx_ns": 13954999286200, "frame": {"stream":"btcusdt@depth@100ms","data":{"e":"depthUpdate","E":1787650950214,"s":"BTCUSDT","U":99118675250,"u":99118675302,"b":[["79859.21000000","4.04589000"],["79858.67000000","0.00000000"],["79858.65000000","0.08178000"],["79858.17000000","0.00640000"],["79846.43000000","0.00626000"],["79834.01000000","0.00000000"],["73480.61000000","0.00014000"],["71873.29000000","0.00448000"],["63887.37000000","0.00000000"]],"a":[["79859.22000000","0.12186000"],["79860.50000000","0.01916000"],["79861.76000000","0.00007000"],["79861.77000000","0.04334000"],["79863.06000000","0.02286000"],["79863.49000000","0.05921000"],["79863.99000000","0.06074000"],["79864.00000000","0.27624000"],["79864.71000000","0.06067000"],["79865.91000000","0.00000000"],["79865.92000000","0.06060000"],["79866.54000000","0.06060000"],["79867.15000000","0.06060000"],["79867.78000000","0.20529000"],["79869.59000000","0.00000000"],["79887.44000000","0.33806000"],["79899.63000000","0.00000000"]]}}}
{"rx_ns": 13955092257000, "frame": {"stream":"btcusdt@depth@100ms","data":{"e":"depthUpdate","E":1787650950314,"s":"BTCUSDT","U":99118675303,"u":99118675329,"b":[["79792.03000000","0.02094000"],["79641.60000000","0.00771000"],["79630.93000000","0.00000000"],["71873.29000000","0.00432000"],["71873.00000000","0.00010000"],["63887.00000000","0.01877000"]],"a":[["79859.22000000","0.12173000"],["79860.50000000","0.01916000"],["79861.77000000","0.04348000"],["79864.71000000","0.06053000"],["79868.37000000","0.00000000"],["79868.48000000","0.00000000"],["79893.47000000","0.00000000"],["79992.37000000","0.00000000"],["80000.38000000","0.01961000"],["80085.27000000","0.00400000"],["84202.54000000","0.00884000"]]}}}
{"rx_ns": 13955196298500, "frame": {"stream":"btcusdt@depth@100ms","data":{"e":"depthUpdate","E":1787650950414,"s":"BTCUSDT","U":99118675330,"u":99118675338,"b":[["79811.19000000","0.00000000"],["79792.03000000","0.00007000"],["71873.29000000","0.00432000"],["71873.00000000","0.00000000"]],"a":[["79859.69000000","0.00007000"],["79868.00000000","0.02407000"]]}}}
{"rx_ns": 13955304779800, "frame": {"stream":"btcusdt@depth@100ms","data":{"e":"depthUpdate","E":1787650950514,"s":"BTCUSDT","U":99118675339,"u":99118675347,"b":[["79724.83000000","0.00000000"],["71873.29000000","0.00432000"],["63887.37000000","0.00031000"]],"a":[["79869.13000000","0.00000000"],["79893.57000000","0.00400000"],["79946.46000000","0.12224000"],["79959.39000000","0.00000000"],["80085.27000000","0.00000000"]]}}}
{"rx_ns": 13955392540600, "frame": {"stream":"btcusdt@depth@100ms","data":{"e":"depthUpdate","E":1787650950614,"s":"BTCUSDT","U":99118675348,"u":99118675366,"b":[["79854.82000000","0.01256000"],["79854.71000000","0.00800000"],["79839.00000000","0.70000000"],["79838.00000000","0.02400000"],["79734.11000000","0.04410000"],["79634.11000000","0.01961000"],["79630.92000000","0.00000000"],["71873.29000000","0.00448000"],["71873.00000000","0.00000000"],["63887.37000000","0.00000000"],["60777.00000000","1.15110000"]],"a":[["79859.22000000","0.12220000"],["79871.95000000","0.00800000"],["79973.68000000","0.02804000"]]}}}
{"rx_ns": 13955501310400, "frame": {"stream":"btcusdt@depth@100ms","data":{"e":"depthUpdate","E":1787650950714,"s":"BTCUSDT","U":99118675367,"u":99118675379,"b":[["79854.71000000","0.01200000"],["79843.63000000","0.50924000"],["73480.61000000","0.00000000"],["71873.29000000","0.00424000"],["71873.00000000","0.00000000"]],"a":[["79859.22000000","0.12212000"],["79871.94000000","0.00400000"],["79873.40000000","0.00400000"],["80085.54000000","0.00400000"],["80260.48000000","0.00018000"]]}}}
{"rx_ns": 13955592275700, "frame": {"stream":"btcusdt@depth@100ms","data":{"e":"depthUpdate","E":1787650950814,"s":"BTCUSDT","U":99118675380,"u":99118675591,"b":[["79859.21000000","2.04920000"],["79859.20000000","0.00076000"],["79859.06000000","0.00000000"],["79858.67000000","0.00007000"],["79858.66000000","0.09316000"],["79858.17000000","0.00014000"],["79858.16000000","0.00133000"],["79858.01000000","0.00007000"],["79857.74000000","0.00014000"],["79857.32000000","0.00000000"],["79856.56000000","0.00007000"],["79856.29000000","0.00000000"],["79856.01000000","0.00007000"],["79856.00000000","0.02414000"],["79855.15000000","0.00633000"],["79855.01000000","0.00626000"],["79854.72000000","0.00000000"],["79854.71000000","0.00007000"],["79854.70000000","0.83093000"],["79854.68000000","0.00007000"],["79854.05000000","0.00702000"],["79853.90000000","0.08482000"],["79852.05000000","0.01600000"],["79851.64000000","0.00000000"],["79850.46000000","0.00000000"],["79830.94000000","0.33830000"],["79798.78000000","1.24093000"],["71873.29000000","0.00440000"],["71873.00000000","0.00000000"]],"a":[["79859.22000000","0.87250000"],["79859.23000000","0.00083000"],["79859.82000000","0.00007000"],["79859.83000000","0.06053000"],["79860.43000000","0.00007000"],["79860.44000000","0.06053000"],["79860.50000000","0.01923000"],["79861.04000000","0.00007000"],["79861.05000000","0.06060000"],["79861.32000000","0.00014000"],["79861.65000000","0.00007000"],["79861.66000000","0.06053000"],["79861.77000000","0.16660000"],["79861.78000000","0.02286000"],["79862.12000000","0.00007000"],["79862.13000000","0.06060000"],["79862.14000000","0.04807000"],["79862.87000000","0.00000000"],["79862.88000000","0.06053000"],["79862.92000000","0.06053000"],["79862.93000000","0.42275000"],["79863.05000000","0.00000000"],["79863.48000000","0.00000000"],["79863.49000000","0.00021000"],["79863.98000000","0.00000000"],["79863.99000000","0.00014000"],["79864.00000000","0.48620000"],["79864.70000000","0.00000000"],["79864.71000000","0.00000000"],["79865.19000000","0.00014000"],["79865.31000000","0.00000000"],["79865.32000000","0.00007000"],["79865.52000000","0.04026000"],["79867.15000000","0.06053000"],["79867.47000000","0.00000000"],["79867.55000000","1.04939000"],["79867.56000000","0.00000000"],["79867.57000000","0.40919000"],["79867.77000000","0.00000000"],["79867.78000000","0.00000000"],["79868.00000000","0.02400000"],["79868.48000000","0.00000000"],["79868.49000000","0.14256000"],["79869.40000000","0.00587000"],["79869.48000000","0.00696000"],["79869.59000000","0.00000000"],["79869.99000000","0.00626000"],["79870.20000000","0.00000000"],["79870.81000000","0.00000000"],["79871.42000000","0.00000000"],["79871.94000000","0.19419000"],["79871.96000000","0.00400000"],["79871.97000000","1.19260000"],["79872.75000000","0.00000000"],["79873.40000000","0.00000000"],["79873.96000000","1.88397000"],["79879.68000000","0.33809000"],["79883.53000000","0.00000000"],["79888.32000000","0.62603000"],["79899.60000000","0.00000000"],["79900.02000000","0.00000000"],["79900.57000000","0.00000000"],["79903.89000000","0.00000000"],["79907.40000000","0.00014000"],["80085.54000000","0.00000000"]]}}}
{"rx_ns": 13955694917600, "frame": {"stream":"btcusdt@depth@100ms","data":{"e":"depthUpdate","E":1787650950914,"s":"BTCUSDT","U":99118675592,"u":99118675720,"b":[["79859.21000000","2.04667000"],["79859.20000000","0.00076000"],["79858.65000000","0.08171000"],["79858.17000000","0.00000000"],["79858.04000000","0.00923000"],["79858.03000000","0.00007000"],["79858.02000000","0.04042000"],["79858.00000000","0.02435000"],["79857.74000000","0.00000000"],["79856.55000000","0.05261000"],["79856.10000000","0.00759000"],["79854.71000000","0.01207000"],["79852.05000000","0.00400000"],["79849.63000000","0.00047000"],["79848.91000000","0.00187000"],["79846.43000000","0.00000000"],["79842.65000000","0.00626000"],["79734.11000000","0.00000000"],["71873.29000000","0.00440000"],["71873.00000000","0.00010000"],["63887.37000000","0.00000000"]],"a":[["79859.22000000","1.04835000"],["79859.23000000","0.00083000"],["79859.69000000","0.00000000"],["79859.83000000","0.06067000"],["79860.44000000","0.06067000"],["79860.50000000","0.01923000"],["79861.04000000","0.25761000"],["79861.05000000","0.06074000"],["79861.66000000","0.06067000"],["79861.77000000","0.00021000"],["79861.78000000","0.02286000"],["79862.13000000","0.06074000"],["79862.14000000","0.04800000"],["79862.88000000","0.06060000"],["79862.93000000","0.42282000"],["79862.99000000","0.04240000"],["79863.06000000","0.02265000"],["79863.49000000","0.00000000"],["79863.99000000","0.00000000"],["79864.00000000","0.48599000"],["79864.01000000","0.00000000"],["79864.09000000","0.00000000"],["79864.91000000","0.00000000"],["79865.32000000","0.00000000"],["79865.52000000","0.00000000"],["79865.92000000","0.00007000"],["79866.19000000","0.00000000"],["79866.54000000","0.00007000"],["79867.14000000","0.00026000"],["79867.91000000","0.00915000"],["79868.49000000","0.06847000"],["79869.39000000","0.00000000"],["79870.00000000","0.02400000"],["79870.43000000","0.00000000"],["79900.02000000","0.00007000"],["79973.68000000","0.00000000"],["80085.57000000","0.00400000"]]}}}
{"rx_ns": 13955802281600, "frame": {"stream":"btcusdt@depth20","data":{"lastUpdateId":99118675783,"bids":[["79859.21000000","2.02527000"],["79859.20000000","0.00083000"],["79859.19000000","0.00013000"],["79858.67000000","0.00007000"],["79858.66000000","0.09316000"],["79858.65000000","0.08171000"],["79858.16000000","0.00133000"],["79858.15000000","0.03238000"],["79858.04000000","0.00923000"],["79858.03000000","0.00007000"],["79858.02000000","0.04056000"],["79858.01000000","0.00007000"],["79858.00000000","0.02435000"],["79857.50000000","0.00407000"],["79857.45000000","0.00014000"],["79857.31000000","0.00076000"],["79856.94000000","0.00704000"],["79856.88000000","0.00007000"],["79856.56000000","0.00007000"],["79856.55000000","0.05261000"]],"asks":[["79859.22000000","0.87217000"],["79859.23000000","0.00083000"],["79859.24000000","0.00013000"],["79859.82000000","0.00007000"],["79859.83000000","0.06067000"],["79860.25000000","0.00021000"],["79860.43000000","0.00007000"],["79860.44000000","0.06067000"],["79860.49000000","0.00014000"],["79860.50000000","0.01923000"],["79861.03000000","0.00007000"],["79861.04000000","0.25775000"],["79861.05000000","0.06074000"],["79861.29000000","0.00007000"],["79861.32000000","0.00014000"],["79861.44000000","0.00007000"],["79861.65000000","0.00007000"],["79861.66000000","0.06067000"],["79861.78000000","0.02286000"],["79862.01000000","0.00007000"]]}}}
{"rx_ns": 13955802388500, "frame": {"stream":"btcusdt@depth@100ms","data":{"e":"depthUpdate","E":1787650951015,"s":"BTCUSDT","U":99118675721,"u":99118675783,"b":[["79859.21000000","2.02527000"],["79859.20000000","0.00083000"],["79858.04000000","0.00923000"],["79858.02000000","0.04056000"],["79856.10000000","0.00745000"],["79856.01000000","0.00007000"],["79855.15000000","0.00007000"],["79854.71000000","0.01207000"],["79854.70000000","0.83093000"],["79854.68000000","0.00000000"],["79854.45000000","0.00400000"],["79854.06000000","0.00626000"],["79849.50000000","0.00048000"],["79724.83000000","0.04534000"],["79641.60000000","0.00000000"],["79637.50000000","0.00799000"],["78661.32000000","0.00030000"],["71873.29000000","0.00440000"],["71873.00000000","0.00010000"],["63887.37000000","0.00031000"]],"a":[["79859.22000000","0.87217000"],["79860.50000000","0.01923000"],["79861.03000000","0.00007000"],["79861.04000000","0.25775000"],["79861.66000000","0.06067000"],["79861.76000000","0.00000000"],["79861.77000000","0.00000000"],["79862.13000000","0.06074000"],["79862.87000000","0.00007000"],["79868.83000000","0.00400000"],["79900.02000000","0.00000000"],["79964.38000000","0.02804000"],["81057.11000000","0.00030000"]]}}}
{"rx_ns": 13955892161600, "frame": {"stream":"btcusdt@depth@100ms","data":{"e":"depthUpdate","E":1787650951114,"s":"BTCUSDT","U":99118675784,"u":99118675794,"b":[["79859.21000000","2.02574000"],["79849.50000000","0.00000000"],["79844.00000000","0.02407000"],["71873.29000000","0.00456000"],["71873.00000000","0.00000000"]],"a":[["79861.04000000","0.25768000"],["79861.05000000","0.00021000"],["79861.77000000","0.00007000"],["79870.22000000","0.00000000"],["79875.96000000","0.00007000"]]}}}
{"rx_ns": 13955991950500, "frame": {"stream":"btcusdt@depth@100ms","data":{"e":"depthUpdate","E":1787650951214,"s":"BTCUSDT","U":99118675795,"u":99118675811,"b":[["71873.29000000","0.00440000"],["63887.37000000","0.00000000"]],"a":[["79859.22000000","0.87210000"],["79859.23000000","0.00076000"],["79861.04000000","0.25768000"],["79861.05000000","0.00007000"],["79862.14000000","0.04814000"],["79900.02000000","0.00007000"],["79906.68000000","0.00400000"],["79907.50000000","0.00000000"]]}}}
{"rx_ns": 13956096191900, "frame": {"stream":"btcusdt@depth@100ms","data":{"e":"depthUpdate","E":1787650951314,"s":"BTCUSDT","U":99118675812,"u":99118675823,"b":[["79855.01000000","0.00000000"],["79854.29000000","0.00626000"],["71873.29000000","0.00456000"],["63887.00000000","0.01877000"]],"a":[["79859.22000000","1.05587000"],["79867.39000000","0.00693000"],["79900.02000000","0.00000000"]]}}}
{"rx_ns": 13956192424900, "frame": {"stream":"btcusdt@depth@100ms","data":{"e":"depthUpdate","E":1787650951414,"s":"BTCUSDT","U":99118675824,"u":99118675825,"b":[["79792.03000000","0.02094000"],["71873.29000000","0.00440000"]],"a":[]}}}
{"rx_ns": 13956295564700, "frame": {"stream":"btcusdt@depth@100ms","data":{"e":"depthUpdate","E":1787650951514,"s":"BTCUSDT","U":99118675826,"u":99118675834,"b":[["79844.99000000","0.02100000"],["79839.00000000","0.00000000"],["71873.29000000","0.00456000"],["63887.37000000","0.00031000"]],"a":[["79861.65000000","0.18393000"],["79862.99000000","0.00000000"],["79901.00000000","0.70000000"]]}}}
{"rx_ns": 13956392178400, "frame": {"stream":"btcusdt@depth@100ms","data":{"e":"depthUpdate","E":1787650951614,"s":"BTCUSDT","U":99118675835,"u":99118675867,"b":[["79859.21000000","1.98532000"],["79856.00000000","0.02407000"],["79855.15000000","0.00000000"],["79854.43000000","0.02268000"],["79842.17000000","0.00000000"],["79837.91000000","0.62625000"],["71873.29000000","0.00440000"],["63887.37000000","0.00000000"]],"a":[["79859.22000000","0.87196000"],["79859.23000000","0.00069000"],["79861.04000000","0.25775000"],["79861.64000000","0.00007000"],["79861.65000000","0.18400000"],["79861.66000000","0.00014000"],["79861.77000000","0.00000000"],["79862.14000000","0.04800000"],["79862.88000000","0.06053000"],["79862.92000000","0.00007000"],["79862.93000000","0.42275000"],["79886.89000000","0.04600000"],["79889.42000000","0.00000000"]]}}}
{"rx_ns": 13956492902800, "frame": {"stream":"btcusdt@depth@100ms","data":{"e":"depthUpdate","E":1787650951714,"s":"BTCUSDT","U":99118675868,"u":99118675881,"b":[["71873.29000000","0.00456000"],["71873.00000000","0.00000000"]],"a":[["79860.50000000","0.01916000"],["79861.05000000","0.00000000"],["79861.65000000","0.18400000"],["79861.66000000","0.00000000"],["79862.14000000","0.04814000"],["79952.39000000","1.95360000"]]}}}
{"rx_ns": 13956598430600, "frame": {"stream":"btcusdt@depth@100ms","data":{"e":"depthUpdate","E":1787650951814,"s":"BTCUSDT","U":99118675882,"u":99118675902,"b":[["79846.52000000","0.00007000"],["79839.97000000","0.02494000"],["79792.03000000","0.00007000"],["71873.29000000","0.00440000"]],"a":[["79868.49000000","0.06847000"],["79868.91000000","0.00000000"],["79889.83000000","0.00400000"],["79893.57000000","0.00000000"],["79900.50000000","0.02434000"],["79906.95000000","0.00000000"],["79929.78000000","0.00400000"],["79933.42000000","0.00000000"],["79965.38000000","0.00000000"],["80009.67000000","0.00400000"],["80013.32000000","0.00000000"],["80081.57000000","0.00400000"],["80085.57000000","0.00000000"]]}}}
{"rx_ns": 13956691831700, "frame": {"stream":"btcusdt@depth@100ms","data":{"e":"depthUpdate","E":1787650951914,"s":"BTCUSDT","U":99118675903,"u":99118675915,"b":[["79859.21000000","1.98521000"],["79792.03000000","0.00007000"],["79703.36000000","0.00202000"],["71873.29000000","0.00448000"],["71873.28000000","0.00008000"]],"a":[["79929.78000000","0.00000000"],["79961.74000000","0.00400000"],["80016.11000000","0.00202000"]]}}}
{"rx_ns": 13956792286800, "frame": {"stream":"btcusdt@depth20","data":{"lastUpdateId":99118675925,"bids":[["79859.21000000","1.98521000"],["79859.20000000","0.00083000"],["79859.19000000","0.00013000"],["79858.67000000","0.00007000"],["79858.66000000","0.09316000"],["79858.65000000","0.08171000"],["79858.16000000","0.00133000"],["79858.15000000","0.03238000"],["79858.04000000","0.00923000"],["79858.03000000","0.00007000"],["79858.02000000","0.04056000"],["79858.01000000","0.00007000"],["79858.00000000","0.02435000"],["79857.50000000","0.00407000"],["79857.45000000","0.00014000"],["79857.31000000","0.00076000"],["79856.94000000","0.00704000"],["79856.88000000","0.00007000"],["79856.56000000","0.00007000"],["79856.55000000","0.05261000"]],"asks":[["79859.22000000","0.87160000"],["79859.23000000","0.00069000"],["79859.24000000","0.00013000"],["79859.82000000","0.00007000"],["79859.83000000","0.06067000"],["79860.25000000","0.00021000"],["79860.43000000","0.00007000"],["79860.44000000","0.06067000"],["79860.49000000","0.00014000"],["79860.50000000","0.01916000"],["79861.03000000","0.00007000"],["79861.04000000","0.25775000"],["79861.29000000","0.00007000"],["79861.32000000","0.00014000"],["79861.44000000","0.00007000"],["79861.64000000","0.00007000"],["79861.65000000","0.18400000"],["79861.78000000","0.02286000"],["79862.01000000","0.00007000"],["79862.12000000","0.00007000"]]}}}
{"rx_ns": 13956792388500, "frame": {"stream":"btcusdt@depth@100ms","data":{"e":"depthUpdate","E":1787650952014,"s":"BTCUSDT","U":99118675916,"u":99118675925,"b":[["78661.32000000","0.00030000"],["71873.29000000","0.00432000"],["63887.37000000","0.00051000"]],"a":[["79859.22000000","0.87160000"],["81057.11000000","0.00030000"]]}}}
{"rx_ns": 13956894036400, "frame": {"stream":"btcusdt@depth@100ms","data":{"e":"depthUpdate","E":1787650952114,"s":"BTCUSDT","U":99118675926,"u":99118676018,"b":[["79859.21000000","3.86094000"],["79859.20000000","0.00027000"],["79858.60000000","0.00026000"],["79858.55000000","0.00400000"],["79857.38000000","0.00000000"],["79856.77000000","0.00000000"],["79856.16000000","0.00000000"],["79856.01000000","0.00000000"],["79855.55000000","0.00000000"],["79854.94000000","0.00000000"],["79854.72000000","0.36586000"],["79854.71000000","0.01200000"],["79854.70000000","0.83086000"],["79854.45000000","0.00000000"],["79844.00000000","0.02407000"],["71873.29000000","0.00432000"],["63887.37000000","0.00031000"]],"a":[["79859.22000000","0.67809000"],["79859.83000000","0.00014000"],["79860.44000000","0.00014000"],["79861.65000000","0.00014000"],["79862.13000000","0.00021000"],["79862.88000000","0.00000000"],["79863.33000000","0.00000000"],["79865.98000000","0.00000000"],["79867.15000000","0.00000000"],["79867.55000000","0.00000000"],["79868.83000000","0.00000000"],["79869.40000000","0.00187000"],["79871.43000000","0.00000000"],["79871.96000000","1.05339000"],["79871.98000000","0.00000000"],["79872.93000000","0.00014000"],["79873.08000000","0.00400000"],["79873.96000000","0.00720000"],["79873.97000000","0.00000000"],["79875.04000000","0.00400000"],["79875.96000000","0.00007000"],["79875.97000000","1.04939000"],["79875.99000000","0.00000000"],["79879.10000000","1.87677000"],["79879.11000000","0.00000000"],["79879.68000000","0.00000000"],["79880.36000000","1.04939000"],["79880.38000000","0.00000000"],["79882.20000000","0.00000000"],["79883.96000000","1.87677000"],["79883.98000000","0.00000000"],["79886.25000000","0.36586000"],["79888.32000000","0.00000000"],["79889.75000000","0.00000000"],["79890.48000000","0.00000000"],["79900.02000000","0.00007000"],["79929.79000000","0.00400000"],["79952.39000000","0.00000000"]]}}}
{"rx_ns": 13956992382200, "frame": {"stream":"btcusdt@depth@100ms","data":{"e":"depthUpdate","E":1787650952214,"s":"BTCUSDT","U":99118676019,"u":99118676486,"b":[["79859.21000000","3.87976000"],["79859.20000000","0.00027000"],["79858.68000000","0.00000000"],["79858.67000000","0.00000000"],["79858.66000000","0.09309000"],["79858.55000000","0.00000000"],["79858.16000000","0.00126000"],["79858.03000000","0.00000000"],["79858.01000000","0.00000000"],["79857.32000000","0.00400000"],["79856.94000000","0.00711000"],["79856.89000000","0.01200000"],["79856.56000000","0.00000000"],["79856.55000000","0.05268000"],["79856.39000000","0.03000000"],["79856.00000000","0.02407000"],["79855.55000000","0.00000000"],["79854.94000000","0.00000000"],["79854.82000000","0.01256000"],["79854.73000000","0.00000000"],["79854.71000000","0.00000000"],["79854.43000000","0.02261000"],["79854.29000000","0.00000000"],["79854.06000000","0.00000000"],["79852.05000000","0.00000000"],["79851.63000000","0.37579000"],["79850.75000000","0.33821000"],["79850.00000000","0.12191000"],["79849.63000000","0.00000000"],["79848.91000000","0.00000000"],["79848.18000000","0.00000000"],["79847.23000000","0.08566000"],["79846.80000000","0.00000000"],["79845.78000000","0.00000000"],["79840.00000000","0.28024000"],["79836.65000000","0.00000000"],["79832.72000000","0.00000000"],["79832.49000000","0.00000000"],["79831.53000000","0.04472000"],["79830.94000000","0.00000000"],["79807.23000000","0.46895000"],["79807.22000000","0.00000000"],["79798.78000000","0.00000000"],["79073.70000000","0.00000000"],["79072.75000000","0.00000000"],["71873.29000000","0.00432000"],["63887.37000000","0.00000000"]],"a":[["79859.22000000","0.09660000"],["79859.23000000","0.00069000"],["79859.82000000","0.00000000"],["79859.83000000","0.00000000"],["79860.43000000","0.00000000"],["79860.44000000","0.00000000"],["79861.03000000","0.00000000"],["79861.04000000","0.00014000"],["79861.32000000","0.00007000"],["79861.64000000","0.00000000"],["79861.65000000","0.00000000"],["79861.77000000","0.00007000"],["79861.78000000","0.02286000"],["79862.12000000","0.00000000"],["79862.13000000","0.00007000"],["79862.14000000","0.04814000"],["79862.87000000","0.00007000"],["79862.88000000","0.06053000"],["79862.92000000","0.00000000"],["79862.93000000","0.00014000"],["79863.05000000","0.00007000"],["79863.06000000","0.02300000"],["79863.48000000","0.00007000"],["79863.49000000","0.06060000"],["79863.99000000","0.00000000"],["79864.00000000","0.00021000"],["79864.09000000","0.00007000"],["79864.10000000","0.06053000"],["79864.70000000","0.00007000"],["79864.71000000","0.06053000"],["79865.19000000","0.00007000"],["79865.31000000","0.00007000"],["79865.32000000","0.06060000"],["79865.91000000","0.00007000"],["79865.92000000","0.06060000"],["79866.53000000","0.00000000"],["79866.54000000","0.06060000"],["79867.14000000","0.00000000"],["79867.15000000","0.06060000"],["79867.20000000","0.00000000"],["79867.21000000","0.20265000"],["79867.39000000","0.00007000"],["79867.56000000","0.00000000"],["79867.57000000","0.00007000"],["79867.76000000","0.06053000"],["79867.91000000","0.00000000"],["79867.99000000","0.00000000"],["79868.00000000","0.02414000"],["79868.26000000","0.00000000"],["79868.37000000","0.06053000"],["79868.48000000","0.00000000"],["79868.49000000","0.09555000"],["79868.59000000","0.00000000"],["79868.60000000","0.00000000"],["79868.98000000","0.06053000"],["79869.48000000","0.00000000"],["79869.59000000","0.06053000"],["79869.99000000","0.00000000"],["79870.20000000","0.06053000"],["79870.30000000","0.00070000"],["79870.43000000","0.00000000"],["79870.44000000","0.00000000"],["79870.81000000","0.06053000"],["79871.42000000","0.06053000"],["79871.48000000","0.00048000"],["79871.83000000","0.00000000"],["79871.88000000","0.06053000"],["79871.89000000","0.08576000"],["79871.92000000","0.76858000"],["79871.93000000","1.04939000"],["79871.94000000","0.00000000"],["79871.95000000","0.00000000"],["79871.96000000","0.00000000"],["79871.97000000","0.00000000"],["79872.28000000","0.00000000"],["79872.64000000","0.00000000"],["79872.70000000","0.00047000"],["79872.76000000","0.00000000"],["79873.08000000","0.00000000"],["79873.14000000","0.00000000"],["79873.25000000","0.00000000"],["79873.28000000","0.00048000"],["79873.36000000","0.00000000"],["79873.48000000","0.00000000"],["79873.52000000","0.00000000"],["79873.74000000","0.00000000"],["79873.86000000","0.00000000"],["79873.94000000","0.00000000"],["79873.96000000","0.00000000"],["79873.99000000","0.00000000"],["79874.08000000","0.00000000"],["79874.17000000","0.00000000"],["79874.24000000","0.00000000"],["79874.25000000","1.87677000"],["79874.28000000","0.00719000"],["79874.73000000","0.00011000"],["79875.01000000","0.00000000"],["79875.04000000","0.00000000"],["79875.08000000","0.00000000"],["79875.19000000","0.00015000"],["79875.20000000","0.20250000"],["79875.95000000","0.00036000"],["79875.96000000","0.00007000"],["79875.98000000","0.79645000"],["79876.10000000","0.00000000"],["79876.90000000","0.00000000"],["79877.08000000","0.00000000"],["79877.11000000","0.00000000"],["79877.25000000","0.00400000"],["79877.44000000","0.00000000"],["79877.48000000","0.00000000"],["79877.57000000","0.00000000"],["79877.59000000","0.00000000"],["79877.85000000","0.36586000"],["79878.06000000","0.00000000"],["79878.22000000","0.00000000"],["79878.52000000","0.00000000"],["79878.65000000","0.00000000"],["79878.69000000","0.00000000"],["79878.74000000","0.00000000"],["79878.78000000","0.00626000"],["79878.79000000","0.00000000"],["79879.09000000","0.01200000"],["79879.14000000","0.00000000"],["79879.73000000","0.00000000"],["79879.84000000","0.00000000"],["79879.85000000","0.00000000"],["79879.94000000","0.00000000"],["79880.00000000","0.02407000"],["79880.01000000","0.00000000"],["79880.35000000","0.62998000"],["79880.37000000","0.00000000"],["79881.92000000","0.00000000"],["79882.88000000","0.00000000"],["79883.16000000","0.00000000"],["79883.53000000","0.00800000"],["79883.54000000","0.00000000"],["79883.95000000","0.00400000"],["79884.26000000","0.00000000"],["79884.53000000","0.00000000"],["79885.87000000","0.00000000"],["79886.50000000","0.02000000"],["79886.89000000","0.04564000"],["79887.80000000","0.69689000"],["79887.81000000","0.00000000"],["79888.96000000","0.03000000"],["79889.19000000","0.19645000"],["79889.73000000","0.38402000"],["79889.74000000","0.00000000"],["79889.83000000","0.00000000"],["79890.00000000","0.07201000"],["79891.97000000","0.62632000"],["79891.98000000","0.00000000"],["79893.17000000","0.00000000"],["79898.37000000","0.00000000"],["79900.00000000","0.08657000"],["79901.43000000","0.00000000"],["79901.70000000","0.33800000"],["79903.67000000","0.62591000"],["79903.89000000","0.00007000"],["79904.32000000","0.00000000"],["79907.40000000","0.00007000"],["79909.27000000","0.00400000"],["79913.11000000","0.00427000"],["79914.45000000","0.00400000"],["79929.79000000","0.00000000"],["79946.46000000","0.00000000"],["79946.92000000","0.00000000"],["79948.47000000","0.00000000"],["79950.47000000","0.11830000"],["79955.24000000","0.00000000"],["79961.74000000","0.00000000"],["80009.67000000","0.00000000"],["80081.57000000","0.00000000"]]}}}
{"rx_ns": 13957092777000, "frame": {"stream":"btcusdt@depth@100ms","data":{"e":"depthUpdate","E":1787650952314,"s":"BTCUSDT","U":99118676487,"u":99118676604,"b":[["79858.67000000","0.00007000"],["79858.66000000","0.09316000"],["79858.60000000","0.00000000"],["79858.16000000","0.00133000"],["79858.12000000","0.00000000"],["79858.03000000","0.00007000"],["79858.01000000","0.00007000"],["79857.32000000","0.00000000"],["79856.94000000","0.00704000"],["79856.89000000","0.00000000"],["79856.56000000","0.00007000"],["79856.55000000","0.05254000"],["79856.40000000","0.00007000"],["79856.01000000","0.00007000"],["79856.00000000","0.02414000"],["79855.01000000","0.00400000"],["79854.93000000","0.01200000"],["79854.73000000","0.00007000"],["79853.54000000","0.01491000"],["71873.29000000","0.00416000"],["63887.00000000","0.01877000"]],"a":[["79859.22000000","0.12165000"],["79859.23000000","0.00076000"],["79860.50000000","0.01909000"],["79861.04000000","0.00000000"],["79862.12000000","0.00007000"],["79862.13000000","0.06060000"],["79862.14000000","0.04807000"],["79862.88000000","0.06067000"],["79862.93000000","0.00000000"],["79863.06000000","0.02300000"],["79863.49000000","0.06074000"],["79864.00000000","0.00007000"],["79864.10000000","0.06067000"],["79864.71000000","0.06074000"],["79865.30000000","0.00000000"],["79865.31000000","0.15217000"],["79865.91000000","0.00000000"],["79866.02000000","0.00026000"],["79868.49000000","0.09147000"],["79871.87000000","0.01600000"],["79871.92000000","1.10634000"],["79872.02000000","0.00007000"],["79874.73000000","0.00000000"],["79875.59000000","0.00400000"],["79875.96000000","1.21965000"],["79875.98000000","0.00000000"],["79877.25000000","0.00000000"],["79879.09000000","0.00000000"],["79883.53000000","0.00400000"],["79886.89000000","0.00000000"],["79887.99000000","0.02480000"],["79894.82000000","0.09398000"],["79896.86000000","0.04486000"],["79901.00000000","0.00000000"],["79903.20000000","1.20233000"],["79950.47000000","0.00000000"],["80013.65000000","0.00400000"]]}}}
{"rx_ns": 13957193662100, "frame": {"stream":"btcusdt@depth@100ms","data":{"e":"depthUpdate","E":1787650952415,"s":"BTCUSDT","U":99118676605,"u":99118676657,"b":[["79856.94000000","0.00704000"],["79856.40000000","0.00007000"],["79856.01000000","0.00007000"],["79854.73000000","0.00007000"],["79844.99000000","0.00000000"],["79685.35000000","0.02407000"],["71873.29000000","0.00432000"]],"a":[["79859.22000000","0.12158000"],["79860.50000000","0.01916000"],["79861.04000000","0.00007000"],["79861.05000000","0.06060000"],["79861.65000000","0.00007000"],["79861.66000000","0.06053000"],["79861.78000000","0.02286000"],["79862.13000000","0.06074000"],["79862.87000000","0.00007000"],["79863.05000000","0.00007000"],["79863.48000000","0.00007000"],["79864.09000000","0.00000000"],["79864.70000000","0.00000000"],["79864.71000000","0.06053000"],["79865.31000000","0.00000000"],["79867.46000000","0.04241000"],["79868.00000000","0.02407000"],["79868.28000000","0.11164000"],["79868.29000000","0.00000000"],["79868.49000000","0.00000000"],["80183.44000000","0.01500000"]]}}}
{"rx_ns": 13957294303300, "frame": {"stream":"btcusdt@depth@100ms","data":{"e":"depthUpdate","E":1787650952514,"s":"BTCUSDT","U":99118676658,"u":99118676700,"b":[["79817.34000000","0.83239000"],["79724.83000000","0.00000000"],["71873.29000000","0.00432000"],["63887.37000000","0.00031000"]],"a":[["79859.22000000","0.12199000"],["79859.23000000","0.00097000"],["79859.69000000","0.00007000"],["79860.50000000","0.01916000"],["79861.05000000","0.06074000"],["79861.66000000","0.06067000"],["79863.49000000","0.06060000"],["79864.10000000","0.06053000"],["79864.71000000","0.06060000"],["79865.31000000","0.16476000"],["79865.92000000","0.06067000"],["79866.34000000","0.17827000"],["79867.46000000","0.00000000"],["79868.28000000","0.10843000"],["79871.20000000","0.00937000"],["79913.50000000","0.83139000"],["79964.38000000","0.00000000"],["80085.55000000","0.00400000"]]}}}
{"rx_ns": 13957398619100, "frame": {"stream":"btcusdt@depth@100ms","data":{"e":"depthUpdate","E":1787650952614,"s":"BTCUSDT","U":99118676701,"u":99118676712,"b":[["79847.83000000","0.02000000"],["79842.38000000","0.04620000"],["79831.53000000","0.00000000"],["79736.06000000","0.04410000"],["79641.60000000","0.00771000"],["79637.50000000","0.00028000"],["71873.29000000","0.00432000"],["63887.37000000","0.00000000"]],"a":[["79865.19000000","0.00014000"],["79914.15000000","0.00400000"],["79914.45000000","0.00000000"],["79975.64000000","0.02804000"]]}}}
{"rx_ns": 13957492362500, "frame": {"stream":"btcusdt@depth@100ms","data":{"e":"depthUpdate","E":1787650952714,"s":"BTCUSDT","U":99118676713,"u":99118676719,"b":[["79848.61000000","0.02200000"],["79847.82000000","0.02000000"],["79807.39000000","0.00335000"],["79789.27000000","0.00000000"],["71873.29000000","0.00432000"]],"a":[["79965.71000000","0.00400000"]]}}}
{"rx_ns": 13957592305700, "frame": {"stream":"btcusdt@depth@100ms","data":{"e":"depthUpdate","E":1787650952814,"s":"BTCUSDT","U":99118676720,"u":99118676730,"b":[["79840.23000000","0.00000000"],["79840.00000000","0.98024000"],["79839.44000000","0.00000000"],["79839.42000000","0.00000000"],["71873.29000000","0.00448000"],["71873.00000000","0.00000000"]],"a":[["79865.19000000","0.00007000"],["79951.31000000","0.11806000"]]}}}
{"rx_ns": 13957692051700, "frame": {"stream":"btcusdt@depth@100ms","data":{"e":"depthUpdate","E":1787650952914,"s":"BTCUSDT","U":99118676731,"u":99118676749,"b":[["79852.61000000","0.02800000"],["79848.60000000","0.02400000"],["79848.11000000","0.02200000"],["79847.72000000","0.04400000"],["79844.11000000","0.00000000"],["79839.20000000","0.00000000"],["79787.85000000","0.00007000"],["71873.29000000","0.00432000"]],"a":[["79872.02000000","0.00000000"],["79882.74000000","0.02000000"],["79883.55000000","0.12342000"],["79893.51000000","0.00000000"],["79893.80000000","0.00400000"],["79932.71000000","0.02000000"],["79933.48000000","0.02000000"]]}}}
{"rx_ns": 13957798454200, "frame": {"stream":"btcusdt@depth20","data":{"lastUpdateId":99118676770,"bids":[["79859.21000000","4.02275000"],["79859.20000000","0.00027000"],["79859.19000000","0.00013000"],["79858.67000000","0.00007000"],["79858.66000000","0.09316000"],["79858.65000000","0.08171000"],["79858.16000000","0.00133000"],["79858.15000000","0.03238000"],["79858.04000000","0.00923000"],["79858.03000000","0.00007000"],["79858.02000000","0.04056000"],["79858.01000000","0.00007000"],["79858.00000000","0.02435000"],["79857.50000000","0.00407000"],["79857.45000000","0.00014000"],["79857.31000000","0.00076000"],["79856.94000000","0.00704000"],["79856.88000000","0.00007000"],["79856.56000000","0.00007000"],["79856.55000000","0.05254000"]],"asks":[["79859.22000000","0.12199000"],["79859.23000000","0.00097000"],["79859.24000000","0.00013000"],["79859.69000000","0.00007000"],["79860.25000000","0.00021000"],["79860.49000000","0.00014000"],["79860.50000000","0.01916000"],["79861.04000000","0.00007000"],["79861.05000000","0.06074000"],["79861.29000000","0.00007000"],["79861.32000000","0.00007000"],["79861.44000000","0.00007000"],["79861.65000000","0.00007000"],["79861.66000000","0.06067000"],["79861.77000000","0.00007000"],["79861.78000000","0.02286000"],["79862.01000000","0.00007000"],["79862.12000000","0.00007000"],["79862.13000000","0.06074000"],["79862.14000000","0.04807000"]]}}}
{"rx_ns": 13957798549900, "frame": {"stream":"btcusdt@depth@100ms","data":{"e":"depthUpdate","E":1787650953014,"s":"BTCUSDT","U":99118676750,"u":99118676770,"b":[["79859.21000000","4.02275000"],["79840.09000000","0.00000000"],["78661.32000000","0.00030000"],["71873.29000000","0.00448000"],["63887.37000000","0.00031000"]],"a":[["79871.19000000","0.00026000"],["79872.57000000","0.00000000"],["79875.95000000","0.00000000"],["79883.44000000","0.02000000"],["79883.52000000","0.02000000"],["79892.74000000","0.00000000"],["79933.32000000","0.02000000"],["79933.44000000","0.02000000"],["81057.11000000","0.00030000"]]}}}
{"rx_ns": 13957892725100, "frame": {"stream":"btcusdt@depth@100ms","data":{"e":"depthUpdate","E":1787650953114,"s":"BTCUSDT","U":99118676771,"u":99118676787,"b":[["79859.21000000","4.01649000"],["79858.65000000","0.08178000"],["79858.17000000","0.00626000"],["79844.00000000","0.02400000"],["79839.59000000","0.00000000"],["79703.36000000","0.00000000"],["71873.29000000","0.00432000"],["63887.37000000","0.00031000"]],"a":[["79871.86000000","0.19019000"],["79872.28000000","0.00687000"],["79874.27000000","0.00626000"],["79875.96000000","1.21958000"],["79878.78000000","0.00000000"],["79889.19000000","0.00626000"],["79893.35000000","0.00000000"],["79893.46000000","0.00000000"],["79906.00000000","0.72400000"],["79933.75000000","0.00400000"],["80016.11000000","0.00000000"]]}}}
{"rx_ns": 13957992230600, "frame": {"stream":"btcusdt@depth@100ms","data":{"e":"depthUpdate","E":1787650953214,"s":"BTCUSDT","U":99118676788,"u":99118676799,"b":[["79858.65000000","0.08178000"],["79851.77000000","0.02000000"],["79844.00000000","0.02407000"],["71873.29000000","0.00432000"],["63887.37000000","0.00000000"]],"a":[["79872.18000000","0.12199000"],["79875.96000000","1.21965000"],["79933.75000000","0.00000000"]]}}}
{"rx_ns": 13958094764600, "frame": {"stream":"btcusdt@depth@100ms","data":{"e":"depthUpdate","E":1787650953314,"s":"BTCUSDT","U":99118676800,"u":99118676819,"b":[["79859.21000000","3.99549000"],["79837.33000000","0.12525000"],["71873.29000000","0.00416000"],["71873.28000000","0.00000000"],["63887.00000000","0.01877000"]],"a":[["79859.22000000","0.12188000"],["79869.28000000","0.12520000"],["79872.18000000","0.00000000"],["79872.27000000","0.00000000"],["79933.72000000","0.00400000"]]}}}
{"rx_ns": 13958192553000, "frame": {"stream":"btcusdt@depth@100ms","data":{"e":"depthUpdate","E":1787650953414,"s":"BTCUSDT","U":99118676820,"u":99118676838,"b":[["79858.58000000","0.00026000"],["79843.28000000","0.00000000"],["79731.44000000","0.00000000"],["71873.29000000","0.00432000"]],"a":[["79859.22000000","0.12171000"],["79864.71000000","0.06053000"],["79865.31000000","0.00000000"],["79865.92000000","0.06060000"],["79866.02000000","0.00000000"],["79866.34000000","0.00000000"],["79870.01000000","0.42275000"],["79874.25000000","0.00000000"],["79907.76000000","0.00007000"],["79933.72000000","0.00000000"],["79960.31000000","1.95360000"]]}}}
{"rx_ns": 13958293224800, "frame": {"stream":"btcusdt@depth@100ms","data":{"e":"depthUpdate","E":1787650953514,"s":"BTCUSDT","U":99118676839,"u":99118676853,"b":[["79853.73000000","0.00000000"],["79811.61000000","0.00621000"],["79800.19000000","0.00000000"],["71873.29000000","0.00416000"],["63887.37000000","0.00031000"]],"a":[["79868.28000000","0.26975000"],["79871.82000000","0.12171000"],["79871.86000000","0.00000000"],["79871.92000000","0.76858000"],["79872.02000000","0.00007000"],["79883.54000000","0.19019000"],["79933.76000000","0.00400000"],["79960.31000000","0.00000000"]]}}}
{"rx_ns": 13958393186000, "frame": {"stream":"btcusdt@depth@100ms","data":{"e":"depthUpdate","E":1787650953614,"s":"BTCUSDT","U":99118676854,"u":99118676877,"b":[["79858.58000000","0.00000000"],["79854.05000000","0.00695000"],["79827.84000000","0.02000000"],["79691.57000000","0.00000000"],["71873.29000000","0.00416000"],["63887.37000000","0.00000000"]],"a":[["79859.22000000","0.12172000"],["79860.43000000","0.00007000"],["79860.44000000","0.06053000"],["79864.71000000","0.06060000"],["79865.28000000","0.00026000"],["79865.31000000","0.15202000"],["79868.28000000","0.22648000"],["79871.72000000","0.00000000"],["79871.79000000","0.00000000"],["79871.82000000","0.00000000"],["79907.76000000","0.00000000"],["79933.76000000","0.00000000"]]}}}
{"rx_ns": 13958491914100, "frame": {"stream":"btcusdt@depth@100ms","data":{"e":"depthUpdate","E":1787650953714,"s":"BTCUSDT","U":99118676878,"u":99118676901,"b":[["79789.27000000","0.02000000"],["71873.29000000","0.00416000"]],"a":[["79859.22000000","0.12193000"],["79859.23000000","0.00104000"],["79863.06000000","0.02286000"],["79871.87000000","0.00000000"],["79872.12000000","0.00000000"],["79872.16000000","0.00000000"],["79875.95000000","0.01600000"],["79933.74000000","0.00400000"]]}}}
{"rx_ns": 13958591952400, "frame": {"stream":"btcusdt@depth@100ms","data":{"e":"depthUpdate","E":1787650953814,"s":"BTCUSDT","U":99118676902,"u":99118676912,"b":[["71873.29000000","0.00416000"],["71873.00000000","0.00020000"]],"a":[["79870.54000000","0.16768000"],["79872.18000000","0.12193000"],["79899.98000000","1.13468000"],["79933.74000000","0.00000000"]]}}}
{"rx_ns": 13958700846500, "frame": {"stream":"btcusdt@depth@100ms","data":{"e":"depthUpdate","E":1787650953914,"s":"BTCUSDT","U":99118676913,"u":99118676937,"b":[["79858.65000000","0.08185000"],["79858.19000000","0.00007000"],["79858.18000000","0.02100000"],["79856.40000000","0.00007000"],["79856.01000000","0.00007000"],["79854.73000000","0.00000000"],["79853.90000000","0.00000000"],["79828.61000000","0.02400000"],["79787.85000000","0.00007000"],["79787.22000000","0.00000000"],["71873.29000000","0.00400000"],["71873.00000000","0.00000000"]],"a":[["79869.74000000","0.06051000"],["79870.54000000","0.00000000"],["79872.18000000","0.00000000"],["79872.23000000","0.00000000"],["79872.25000000","0.00000000"],["79872.29000000","0.12193000"],["79933.75000000","0.00400000"],["79986.98000000","0.00000000"]]}}}
{"rx_ns": 13958793026900, "frame": {"stream":"btcusdt@depth20","data":{"lastUpdateId":99118676970,"bids":[["79859.21000000","3.99541000"],["79859.20000000","0.00027000"],["79859.19000000","0.00013000"],["79858.67000000","0.00007000"],["79858.66000000","0.09316000"],["79858.65000000","0.08185000"],["79858.19000000","0.00007000"],["79858.18000000","0.02114000"],["79858.17000000","0.00640000"],["79858.16000000","0.00133000"],["79858.15000000","0.03238000"],["79858.04000000","0.00923000"],["79858.03000000","0.00007000"],["79858.02000000","0.04056000"],["79858.01000000","0.00007000"],["79858.00000000","0.02435000"],["79857.50000000","0.00407000"],["79857.45000000","0.00014000"],["79857.31000000","0.00076000"],["79856.94000000","0.00690000"]],"asks":[["79859.22000000","0.12165000"],["79859.23000000","0.00104000"],["79859.24000000","0.00013000"],["79859.69000000","0.00007000"],["79860.25000000","0.00021000"],["79860.43000000","0.00007000"],["79860.44000000","0.06067000"],["79860.49000000","0.00014000"],["79860.50000000","0.01916000"],["79861.04000000","0.00007000"],["79861.05000000","0.06074000"],["79861.29000000","0.00007000"],["79861.32000000","0.00007000"],["79861.44000000","0.00007000"],["79861.65000000","0.00007000"],["79861.66000000","0.06067000"],["79861.77000000","0.00007000"],["79861.78000000","0.02286000"],["79862.01000000","0.00007000"],["79862.12000000","0.00007000"]]}}}
{"rx_ns": 13958793119100, "frame": {"stream":"btcusdt@depth@100ms","data":{"e":"depthUpdate","E":1787650954015,"s":"BTCUSDT","U":99118676938,"u":99118676970,"b":[["79859.21000000","3.99541000"],["79858.65000000","0.08185000"],["79858.18000000","0.02114000"],["79858.17000000","0.00640000"],["79856.94000000","0.00690000"],["79854.05000000","0.00688000"],["78661.32000000","0.00030000"],["71873.29000000","0.00416000"],["63887.37000000","0.00031000"]],"a":[["79859.22000000","0.12165000"],["79860.44000000","0.06067000"],["79872.02000000","0.00000000"],["79872.14000000","0.00000000"],["79872.29000000","0.00000000"],["79872.36000000","0.12193000"],["81057.11000000","0.00030000"]]}}}
{"rx_ns": 13958892240300, "frame": {"stream":"btcusdt@depth@100ms","data":{"e":"depthUpdate","E":1787650954114,"s":"BTCUSDT","U":99118676971,"u":99118676978,"b":[["71873.29000000","0.00432000"],["63887.37000000","0.00031000"]],"a":[["79887.80000000","0.00000000"],["79887.82000000","0.00000000"],["80026.97000000","0.00000000"]]}}}
{"rx_ns": 13958994944200, "frame": {"stream":"btcusdt@depth@100ms","data":{"e":"depthUpdate","E":1787650954214,"s":"BTCUSDT","U":99118676979,"u":99118676987,"b":[["79844.00000000","0.02407000"],["79831.79000000","0.02000000"],["71873.29000000","0.00400000"],["63887.37000000","0.00000000"]],"a":[["79872.36000000","0.00000000"],["79875.96000000","1.21965000"],["79910.00000000","0.02973000"]]}}}
{"rx_ns": 13959092216100, "frame": {"stream":"btcusdt@depth@100ms","data":{"e":"depthUpdate","E":1787650954314,"s":"BTCUSDT","U":99118676988,"u":99118676996,"b":[["79855.14000000","0.15777000"],["79824.67000000","0.00000000"],["79581.94000000","0.00000000"],["71873.29000000","0.00432000"],["63887.00000000","0.01877000"]],"a":[["79859.22000000","0.12470000"]]}}}
{"rx_ns": 13959194055900, "frame": {"stream":"btcusdt@depth@100ms","data":{"e":"depthUpdate","E":1787650954414,"s":"BTCUSDT","U":99118676997,"u":99118677018,"b":[["79858.19000000","0.00000000"],["79858.18000000","0.00014000"],["79856.40000000","0.00007000"],["79856.01000000","0.00007000"],["79855.15000000","0.00007000"],["79792.03000000","0.00007000"],["71873.29000000","0.00416000"]],"a":[["79862.13000000","0.06074000"],["79862.87000000","0.00007000"],["79863.05000000","0.00007000"],["79863.48000000","0.00000000"],["79897.25000000","0.49906000"]]}}}
{"rx_ns": 13959294595200, "frame": {"stream":"btcusdt@depth@100ms","data":{"e":"depthUpdate","E":1787650954514,"s":"BTCUSDT","U":99118677019,"u":99118677033,"b":[["79858.65000000","0.08178000"],["79858.18000000","0.00000000"],["79856.94000000","0.00704000"],["79791.26000000","0.00000000"],["78887.84000000","0.00000000"],["78408.76000000","0.00000000"],["77929.69000000","0.00000000"],["77450.61000000","0.00000000"],["76971.53000000","0.00000000"],["76492.46000000","0.00000000"],["76013.38000000","0.00000000"],["75534.31000000","0.00000000"],["75055.23000000","0.00000000"],["74576.15000000","0.00000000"],["71873.29000000","0.00432000"],["63887.37000000","0.00031000"]],"a":[]}}}
{"rx_ns": 13959392093700, "frame": {"stream":"btcusdt@depth@100ms","data":{"e":"depthUpdate","E":1787650954614,"s":"BTCUSDT","U":99118677034,"u":99118677040,"b":[["71873.29000000","0.00416000"],["63887.37000000","0.00000000"]],"a":[["79859.22000000","0.12449000"],["79872.02000000","0.00000000"],["79872.07000000","0.00000000"]]}}}
{"rx_ns": 13959496173900, "frame": {"stream":"btcusdt@depth@100ms","data":{"e":"depthUpdate","E":1787650954714,"s":"BTCUSDT","U":99118677041,"u":99118677946,"b":[["79861.77000000","6.45198000"],["79861.76000000","0.00013000"],["79861.75000000","0.00013000"],["79861.67000000","0.63951000"],["79861.66000000","0.71360000"],["79861.65000000","2.88724000"],["79861.64000000","0.00000000"],["79861.63000000","0.00000000"],["79861.43000000","0.00000000"],["79861.32000000","0.00014000"],["79861.31000000","0.00000000"],["79861.28000000","0.00000000"],["79861.05000000","0.00007000"],["79861.04000000","0.96237000"],["79861.03000000","0.00000000"],["79861.02000000","0.00000000"],["79860.50000000","0.07507000"],["79860.49000000","0.00000000"],["79860.48000000","0.00000000"],["79860.44000000","0.00007000"],["79860.43000000","1.26036000"],["79860.42000000","1.04939000"],["79860.41000000","0.00000000"],["79860.24000000","0.00000000"],["79860.18000000","0.00400000"],["79859.82000000","0.00000000"],["79859.68000000","0.00000000"],["79859.23000000","0.00000000"],["79859.22000000","0.20250000"],["79859.21000000","0.33705000"],["79859.20000000","0.00000000"],["79859.19000000","0.00000000"],["79859.00000000","0.05247000"],["79858.67000000","0.00000000"],["79858.66000000","0.00093000"],["79858.65000000","0.00035000"],["79858.39000000","0.00000000"],["79858.17000000","0.00014000"],["79858.16000000","0.00126000"],["79858.15000000","0.03358000"],["79858.04000000","0.00909000"],["79858.03000000","0.00000000"],["79858.02000000","0.04042000"],["79858.01000000","0.00000000"],["79858.00000000","0.02421000"],["79857.78000000","0.00000000"],["79857.54000000","0.00026000"],["79857.31000000","0.00069000"],["79856.94000000","0.00690000"],["79856.56000000","0.00000000"],["79856.55000000","0.00007000"],["79856.40000000","0.00000000"],["79856.34000000","0.00007000"],["79856.27000000","0.00007000"],["79856.10000000","0.00000000"],["79856.01000000","0.00000000"],["79856.00000000","0.02414000"],["79855.67000000","0.00013000"],["79855.15000000","0.00000000"],["79855.01000000","0.00000000"],["79854.97000000","0.02254000"],["79854.93000000","0.00000000"],["79854.92000000","0.00007000"],["79854.82000000","0.00014000"],["79854.67000000","0.12522000"],["79854.43000000","0.00000000"],["79853.66000000","0.00008000"],["79853.54000000","0.00000000"],["79853.23000000","0.00000000"],["79852.26000000","0.00000000"],["79851.22000000","0.00000000"],["79850.26000000","0.00007000"],["79850.14000000","0.00000000"],["79849.71000000","0.33836000"],["79849.59000000","0.08566000"],["79847.23000000","0.00000000"],["79846.66000000","0.12524000"],["79837.90000000","0.00000000"],["79837.33000000","0.00000000"],["79833.36000000","0.09496000"],["79832.00000000","0.02800000"],["79820.37000000","0.00008000"],["79820.00000000","0.03400000"],["79819.00000000","0.00000000"],["79799.85000000","0.00007000"],["79798.74000000","0.00000000"],["79798.65000000","0.49664000"],["79796.15000000","0.00000000"],["79794.58000000","0.00000000"],["79789.06000000","0.00000000"],["79779.47000000","0.00000000"],["79779.46000000","0.00000000"],["79775.71000000","0.38099000"],["79769.87000000","0.00000000"],["79762.27000000","0.00000000"],["79757.48000000","0.00000000"],["79749.49000000","0.00000000"],["79747.89000000","0.00000000"],["79741.50000000","0.00000000"],["79710.60000000","0.00202000"],["79636.33000000","0.00007000"],["79633.77000000","0.00000000"],["71875.49000000","0.00000000"],["71873.29000000","0.00008000"]],"a":[["79859.22000000","0.00000000"],["79859.23000000","0.00000000"],["79859.24000000","0.00000000"],["79859.69000000","0.00000000"],["79860.25000000","0.00000000"],["79860.43000000","0.00000000"],["79860.44000000","0.00000000"],["79860.45000000","0.00000000"],["79860.49000000","0.00000000"],["79860.50000000","0.00000000"],["79861.04000000","0.00000000"],["79861.05000000","0.00000000"],["79861.29000000","0.00000000"],["79861.32000000","0.00000000"],["79861.44000000","0.00000000"],["79861.65000000","0.00000000"],["79861.66000000","0.00000000"],["79861.67000000","0.00000000"],["79861.77000000","0.00000000"],["79861.78000000","0.00094000"],["79861.79000000","0.00042000"],["79862.09000000","0.00007000"],["79862.12000000","0.00000000"],["79862.13000000","0.00014000"],["79862.14000000","0.00028000"],["79862.56000000","0.00000000"],["79862.87000000","0.00000000"],["79862.88000000","0.00014000"],["79863.05000000","0.00000000"],["79863.06000000","0.00042000"],["79863.37000000","0.00000000"],["79863.48000000","0.00000000"],["79863.49000000","0.00021000"],["79863.98000000","0.00000000"],["79864.00000000","0.00000000"],["79864.09000000","0.00000000"],["79864.10000000","0.00014000"],["79864.14000000","0.00074000"],["79864.18000000","0.00370000"],["79864.58000000","0.00007000"],["79864.59000000","0.04772000"],["79864.63000000","0.00000000"],["79864.70000000","0.00000000"],["79864.71000000","0.00021000"],["79865.20000000","0.00000000"],["79865.30000000","0.00000000"],["79865.31000000","0.00014000"],["79865.32000000","0.00021000"],["79865.91000000","0.00000000"],["79865.92000000","0.00007000"],["79866.53000000","0.00007000"],["79867.14000000","0.00007000"],["79867.21000000","0.00007000"],["79867.64000000","0.00013000"],["79867.75000000","0.00007000"],["79867.99000000","0.00007000"],["79868.00000000","0.02414000"],["79868.27000000","0.06060000"],["79868.37000000","0.00000000"],["79868.97000000","0.00000000"],["79868.98000000","0.00000000"],["79869.10000000","0.06053000"],["79869.28000000","0.00000000"],["79869.40000000","0.00000000"],["79869.58000000","0.00007000"],["79869.59000000","0.06053000"],["79869.65000000","0.00008000"],["79869.73000000","0.00000000"],["79869.74000000","0.00000000"],["79869.98000000","0.00007000"],["79869.99000000","0.06053000"],["79870.00000000","0.02407000"],["79870.20000000","0.00000000"],["79870.23000000","0.00000000"],["79870.81000000","0.00000000"],["79870.93000000","0.06053000"],["79871.19000000","0.00000000"],["79871.20000000","0.00000000"],["79871.42000000","0.05753000"],["79871.88000000","0.00000000"],["79871.89000000","0.00000000"],["79871.91000000","0.06053000"],["79872.28000000","0.00000000"],["79872.92000000","0.00000000"],["79874.17000000","0.00024000"],["79874.25000000","0.08576000"],["79874.27000000","0.00000000"],["79875.59000000","0.00000000"],["79875.94000000","0.00000000"],["79875.95000000","0.00000000"],["79876.75000000","0.00000000"],["79877.20000000","0.00000000"],["79877.24000000","0.00000000"],["79878.27000000","0.00000000"],["79878.29000000","0.00000000"],["79878.31000000","0.00000000"],["79878.60000000","0.00000000"],["79878.61000000","0.00000000"],["79878.85000000","0.00000000"],["79878.88000000","0.00626000"],["79879.18000000","0.00158000"],["79882.73000000","0.00000000"],["79883.54000000","0.00000000"],["79883.95000000","1.34063000"],["79883.97000000","0.00000000"],["79884.00000000","0.43288000"],["79884.02000000","0.00000000"],["79884.03000000","0.00007000"],["79884.07000000","0.00000000"],["79888.08000000","0.19019000"],["79888.20000000","0.00000000"],["79891.01000000","0.00000000"],["79894.82000000","0.00000000"],["79895.13000000","0.00000000"],["79895.25000000","0.09403000"],["79900.00000000","0.07657000"],["79900.02000000","0.00014000"],["79901.00000000","0.00000000"],["79902.00000000","0.03400000"],["79902.15000000","0.00190000"],["79902.69000000","0.00000000"],["79903.82000000","0.04000000"],["79905.54000000","0.00000000"],["79907.76000000","0.00007000"],["79909.58000000","0.10000000"],["79912.81000000","0.00629000"],["79922.80000000","0.00000000"],["79925.99000000","0.00000000"],["79927.01000000","0.00000000"],["79927.36000000","0.00312000"],["79928.15000000","0.00312000"],["80023.19000000","0.00202000"],["80096.00000000","0.00007000"],["81057.11000000","0.00000000"]]}}}
{"rx_ns": 13959601347500, "frame": {"stream":"btcusdt@depth@100ms","data":{"e":"depthUpdate","E":1787650954814,"s":"BTCUSDT","U":99118677947,"u":99118678107,"b":[["79861.77000000","7.26633000"],["79861.76000000","0.00027000"],["79861.67000000","0.63965000"],["79861.66000000","0.25284000"],["79861.04000000","0.96237000"],["79860.50000000","0.07528000"],["79860.43000000","1.05786000"],["79860.42000000","1.04953000"],["79859.38000000","0.00802000"],["79859.22000000","0.00000000"],["79859.21000000","0.33675000"],["79858.66000000","0.00079000"],["79858.65000000","0.00014000"],["79858.17000000","0.00000000"],["79858.15000000","0.03365000"],["79858.10000000","0.01336000"],["79856.94000000","0.00697000"],["79856.82000000","0.01604000"],["79855.54000000","0.01604000"],["79854.82000000","0.00007000"],["79821.00000000","0.01000000"],["79820.00000000","0.02400000"],["79757.48000000","0.20250000"],["79684.52000000","0.00000000"],["71875.60000000","0.00016000"]],"a":[["79861.78000000","0.01212000"],["79861.79000000","0.00070000"],["79862.13000000","0.00000000"],["79862.14000000","0.00007000"],["79862.88000000","0.00000000"],["79863.05000000","0.00007000"],["79863.06000000","0.01814000"],["79863.49000000","0.00000000"],["79864.10000000","0.00000000"],["79864.33000000","0.00007000"],["79864.34000000","0.02152000"],["79864.59000000","0.04800000"],["79864.71000000","0.00000000"],["79865.31000000","0.00000000"],["79865.32000000","0.00007000"],["79865.44000000","0.05495000"],["79865.61000000","0.00007000"],["79865.62000000","0.02152000"],["79866.04000000","0.00007000"],["79866.05000000","0.05483000"],["79866.54000000","0.06074000"],["79867.15000000","0.06074000"],["79867.76000000","0.06067000"],["79868.00000000","0.02428000"],["79868.26000000","0.00007000"],["79868.27000000","0.06067000"],["79868.28000000","0.22669000"],["79869.09000000","0.00000000"],["79869.10000000","0.06074000"],["79869.58000000","0.00000000"],["79869.59000000","0.06053000"],["79869.98000000","0.00000000"],["79870.00000000","0.02400000"],["79879.54000000","0.00187000"],["79889.72000000","0.46445000"],["79905.07000000","0.00060000"],["79907.76000000","0.00000000"],["79914.06000000","0.00427000"],["79915.73000000","0.00431000"],["80050.62000000","0.00000000"]]}}}
{"rx_ns": 13959704552900, "frame": {"stream":"btcusdt@depth@100ms","data":{"e":"depthUpdate","E":1787650954914,"s":"BTCUSDT","U":99118678108,"u":99118678169,"b":[["79861.77000000","7.26516000"],["79861.65000000","2.19903000"],["79861.04000000","0.47744000"],["79860.50000000","0.07521000"],["79860.44000000","0.00000000"],["79860.43000000","0.57287000"],["79860.42000000","1.04953000"],["79859.00000000","0.05254000"],["79858.17000000","0.02100000"],["79813.47000000","0.00012000"],["79810.93000000","0.00000000"],["79749.49000000","0.20250000"],["71875.60000000","0.00032000"]],"a":[["79861.78000000","0.01219000"],["79861.79000000","0.00077000"],["79863.06000000","0.01828000"],["79864.34000000","0.02166000"],["79864.59000000","0.04807000"],["79865.43000000","0.00007000"],["79865.44000000","0.05509000"],["79865.62000000","0.02166000"],["79866.05000000","0.05497000"],["79867.76000000","0.06053000"],["79868.00000000","0.02414000"],["79868.26000000","0.00000000"],["79868.27000000","0.06053000"],["79868.28000000","0.22655000"],["79869.10000000","0.06060000"],["79871.21000000","0.00000000"],["79871.53000000","0.01212000"],["79888.09000000","0.00000000"],["79890.63000000","0.00012000"],["79906.00000000","0.02400000"],["79907.76000000","0.00000000"]]}}}
