{"rx_ns": 173334639768200, "frame": {"stream":"btcusdt@depth20@100ms","data":{"lastUpdateId":99076747442,"bids":[["78667.99000000","5.42807000"],["78667.98000000","0.00020000"],["78667.97000000","0.00013000"],["78667.96000000","0.00014000"],["78667.95000000","0.05014000"],["78667.91000000","0.00014000"],["78667.90000000","0.05007000"],["78667.19000000","0.00007000"],["78666.99000000","0.00683000"],["78666.74000000","0.00014000"],["78666.73000000","0.04066000"],["78666.01000000","0.00014000"],["78666.00000000","3.47414000"],["78665.99000000","0.03781000"],["78665.61000000","0.00400000"],["78665.49000000","0.00014000"],["78665.48000000","0.00007000"],["78665.47000000","0.04878000"],["78665.20000000","0.07500000"],["78665.19000000","0.00007000"]],"asks":[["78668.00000000","0.02719000"],["78668.01000000","0.00063000"],["78669.32000000","0.00013000"],["78669.33000000","0.00007000"],["78669.36000000","0.00007000"],["78669.41000000","0.00007000"],["78669.44000000","0.00007000"],["78669.99000000","0.00014000"],["78670.00000000","0.02407000"],["78670.65000000","0.00014000"],["78670.66000000","0.05261000"],["78670.88000000","0.00007000"],["78671.11000000","0.00007000"],["78671.30000000","0.00034000"],["78671.37000000","0.00007000"],["78671.90000000","0.00014000"],["78671.91000000","0.01384000"],["78671.99000000","0.00014000"],["78672.00000000","0.02407000"],["78673.00000000","0.00007000"]]}}}
{"rx_ns": 173334639928200, "frame": {"stream":"btcusdt@depth@100ms","data":{"e":"depthUpdate","E":1787603273814,"s":"BTCUSDT","U":99076747402,"u":99076747442,"b":[["78667.19000000","0.00007000"],["78666.73000000","0.04066000"],["78666.01000000","0.00014000"],["78665.47000000","0.04878000"],["78664.05000000","0.00000000"],["78659.24000000","0.00007000"],["78642.35000000","0.00000000"],["78635.96000000","0.00000000"],["78602.12000000","0.00406000"],["78272.67000000","0.00000000"],["77881.30000000","0.00000000"],["77491.90000000","0.00000000"],["77241.58000000","0.00011000"],["77104.44000000","0.00000000"],["76718.91000000","0.00000000"],["76335.32000000","0.00000000"],["75953.64000000","0.00000000"],["75573.87000000","0.00000000"],["75196.00000000","0.00000000"],["74820.02000000","0.00000000"],["74445.92000000","0.00000000"],["74073.69000000","0.00000000"],["73703.33000000","0.00000000"],["73334.81000000","0.00000000"],["72968.14000000","0.00000000"]],"a":[["78668.00000000","0.02719000"],["78668.01000000","0.00063000"],["78669.32000000","0.00013000"],["78669.54000000","0.00000000"],["78671.07000000","0.00000000"],["78671.11000000","0.00007000"],["78671.30000000","0.00034000"],["78673.17000000","0.02303000"],["78673.46000000","0.02168000"],["78673.47000000","0.00000000"],["78673.50000000","0.00007000"],["78674.25000000","0.02294000"],["78683.74000000","0.00000000"],["78689.56000000","0.00000000"]]}}}
{"rx_ns": 173334739554700, "frame": {"stream":"btcusdt@depth20@100ms","data":{"lastUpdateId":99076747472,"bids":[["78667.99000000","5.42807000"],["78667.98000000","0.00020000"],["78667.97000000","0.00013000"],["78667.96000000","0.00014000"],["78667.95000000","0.05014000"],["78667.91000000","0.00014000"],["78667.90000000","0.05007000"],["78667.19000000","0.00007000"],["78666.99000000","0.00683000"],["78666.74000000","0.00014000"],["78666.73000000","0.04066000"],["78666.01000000","0.00014000"],["78666.00000000","3.47414000"],["78665.99000000","0.03781000"],["78665.71000000","0.00254000"],["78665.61000000","0.00400000"],["78665.49000000","0.00014000"],["78665.48000000","0.00007000"],["78665.47000000","0.04878000"],["78665.20000000","0.07500000"]],"asks":[["78668.00000000","0.02726000"],["78668.01000000","0.00070000"],["78669.32000000","0.00013000"],["78669.33000000","0.00007000"],["78669.36000000","0.00007000"],["78669.41000000","0.00007000"],["78669.44000000","0.00007000"],["78669.99000000","0.00014000"],["78670.00000000","0.02407000"],["78670.65000000","0.00014000"],["78670.66000000","0.05268000"],["78670.88000000","0.00007000"],["78671.11000000","0.00007000"],["78671.30000000","0.00034000"],["78671.34000000","0.02719000"],["78671.37000000","0.00007000"],["78671.90000000","0.00014000"],["78671.91000000","0.01384000"],["78671.99000000","0.00014000"],["78672.00000000","0.02407000"]]}}}
{"rx_ns": 173334739638600, "frame": {"stream":"btcusdt@depth@100ms","data":{"e":"depthUpdate","E":1787603273914,"s":"BTCUSDT","U":99076747443,"u":99076747472,"b":[["78665.71000000","0.00254000"],["78664.73000000","0.00000000"],["78644.35000000","0.00007000"],["78626.41000000","0.00000000"],["78619.67000000","0.09693000"],["78618.66000000","0.02776000"],["78599.87000000","0.02383000"],["70801.20000000","0.00105000"]],"a":[["78668.00000000","0.02726000"],["78668.01000000","0.00070000"],["78670.66000000","0.05268000"],["78671.09000000","0.00000000"],["78671.11000000","0.00007000"],["78671.34000000","0.02719000"],["78671.35000000","0.00000000"],["78673.93000000","0.19254000"],["78680.46000000","0.00000000"],["78681.44000000","0.00254000"],["78691.56000000","0.00007000"],["78697.28000000","0.00000000"],["78698.81000000","0.09624000"],["78708.82000000","0.00000000"],["78727.61000000","0.00000000"],["78823.23000000","0.00160000"]]}}}
{"rx_ns": 173334851472600, "frame": {"stream":"btcusdt@depth20@100ms","data":{"lastUpdateId":99076747507,"bids":[["78667.99000000","5.42807000"],["78667.98000000","0.00020000"],["78667.97000000","0.00013000"],["78667.96000000","0.00014000"],["78667.95000000","0.05014000"],["78667.91000000","0.00014000"],["78667.90000000","0.05007000"],["78667.19000000","0.00007000"],["78666.99000000","0.00683000"],["78666.74000000","0.00014000"],["78666.73000000","0.04066000"],["78666.01000000","0.00014000"],["78666.00000000","3.47414000"],["78665.99000000","0.03781000"],["78665.71000000","0.00254000"],["78665.61000000","0.00400000"],["78665.49000000","0.00014000"],["78665.48000000","0.00007000"],["78665.47000000","0.04878000"],["78665.20000000","0.07500000"]],"asks":[["78668.00000000","0.02726000"],["78668.01000000","0.00070000"],["78669.32000000","0.00013000"],["78669.33000000","0.00007000"],["78669.36000000","0.00007000"],["78669.41000000","0.00007000"],["78669.44000000","0.00007000"],["78669.99000000","0.00014000"],["78670.00000000","0.02407000"],["78670.65000000","0.00014000"],["78670.66000000","0.05268000"],["78670.88000000","0.00007000"],["78671.11000000","0.00007000"],["78671.30000000","0.00034000"],["78671.34000000","0.00007000"],["78671.37000000","0.00007000"],["78671.90000000","0.00014000"],["78671.91000000","0.01384000"],["78671.99000000","0.00014000"],["78672.00000000","0.02407000"]]}}}
{"rx_ns": 173334851555500, "frame": {"stream":"btcusdt@depth@100ms","data":{"e":"depthUpdate","E":1787603274014,"s":"BTCUSDT","U":99076747473,"u":99076747507,"b":[["78651.54000000","0.63561000"],["78648.02000000","0.00000000"],["78604.23000000","0.02400000"],["70801.20000000","0.00121000"],["70801.00000000","0.30423000"],["62934.40000000","0.00031000"],["62934.39000000","0.00000000"]],"a":[["78668.00000000","0.02726000"],["78668.01000000","0.00070000"],["78670.66000000","0.05268000"],["78671.33000000","0.00000000"],["78671.34000000","0.00007000"],["78671.43000000","0.00000000"],["78671.56000000","0.00000000"],["78673.16000000","0.00007000"],["78673.46000000","0.02168000"],["78673.93000000","0.19261000"],["78674.00000000","0.02400000"],["78674.25000000","0.02287000"],["78683.85000000","0.00324000"],["78761.98000000","0.00406000"]]}}}
{"rx_ns": 173334938197500, "frame": {"stream":"btcusdt@depth20@100ms","data":{"lastUpdateId":99076747524,"bids":[["78667.99000000","5.44151000"],["78667.98000000","0.00020000"],["78667.97000000","0.00013000"],["78667.96000000","0.00014000"],["78667.95000000","0.05014000"],["78667.91000000","0.00014000"],["78667.90000000","0.05007000"],["78667.19000000","0.00007000"],["78666.99000000","0.00683000"],["78666.74000000","0.00014000"],["78666.73000000","0.04066000"],["78666.01000000","0.00014000"],["78666.00000000","3.47414000"],["78665.99000000","0.03781000"],["78665.71000000","0.00254000"],["78665.61000000","0.00400000"],["78665.49000000","0.00014000"],["78665.48000000","0.00007000"],["78665.47000000","0.04878000"],["78665.20000000","0.07500000"]],"asks":[["78668.00000000","0.02736000"],["78668.01000000","0.00070000"],["78669.32000000","0.00013000"],["78669.33000000","0.00007000"],["78669.36000000","0.00007000"],["78669.41000000","0.00007000"],["78669.44000000","0.00007000"],["78669.99000000","0.00014000"],["78670.00000000","0.02407000"],["78670.65000000","0.00014000"],["78670.66000000","0.05268000"],["78670.88000000","0.00007000"],["78671.11000000","0.00007000"],["78671.30000000","0.00034000"],["78671.37000000","0.00007000"],["78671.90000000","0.00014000"],["78671.91000000","0.01384000"],["78671.99000000","0.00014000"],["78672.00000000","0.02407000"],["78673.00000000","0.00007000"]]}}}
{"rx_ns": 173334938340600, "frame": {"stream":"btcusdt@depth@100ms","data":{"e":"depthUpdate","E":1787603274114,"s":"BTCUSDT","U":99076747508,"u":99076747524,"b":[["78667.99000000","5.44151000"],["78603.44000000","0.02200000"],["78533.82000000","0.52842000"],["77959.98000000","0.00010000"],["77087.09000000","0.00032000"],["70801.20000000","0.00137000"]],"a":[["78668.00000000","0.02736000"],["78670.66000000","0.05268000"],["78671.34000000","0.00000000"],["78671.36000000","0.00000000"],["78674.00000000","0.02407000"],["78683.39000000","0.00007000"],["78740.45000000","0.58460000"]]}}}
{"rx_ns": 173335045855600, "frame": {"stream":"btcusdt@depth20@100ms","data":{"lastUpdateId":99076748708,"bids":[["78674.42000000","4.46823000"],["78674.41000000","0.00013000"],["78674.40000000","0.00013000"],["78674.25000000","0.07500000"],["78674.24000000","0.00007000"],["78674.14000000","0.43922000"],["78673.99000000","2.70747000"],["78673.23000000","0.00014000"],["78673.16000000","0.07500000"],["78673.15000000","0.03513000"],["78672.99000000","0.00021000"],["78672.00000000","0.07500000"],["78671.99000000","0.22044000"],["78671.90000000","1.55883000"],["78671.89000000","0.25064000"],["78671.80000000","0.05000000"],["78671.62000000","0.04978000"],["78671.19000000","0.00400000"],["78670.77000000","0.03224000"],["78670.64000000","0.00007000"]],"asks":[["78674.43000000","0.00079000"],["78674.44000000","0.00035000"],["78674.76000000","0.00007000"],["78675.31000000","0.00010000"],["78675.60000000","0.00007000"],["78675.69000000","0.00007000"],["78675.83000000","0.00007000"],["78675.85000000","0.00014000"],["78675.86000000","0.00007000"],["78675.99000000","0.00014000"],["78676.00000000","0.02407000"],["78676.30000000","0.00007000"],["78677.10000000","0.00007000"],["78677.13000000","0.05191000"],["78677.17000000","0.00010000"],["78677.51000000","0.00007000"],["78677.90000000","0.00007000"],["78677.99000000","0.00014000"],["78678.00000000","0.02407000"],["78678.60000000","0.00008000"]]}}}
{"rx_ns": 173335045952800, "frame": {"stream":"btcusdt@depth@100ms","data":{"e":"depthUpdate","E":1787603274214,"s":"BTCUSDT","U":99076747525,"u":99076748708,"b":[["78674.42000000","4.46823000"],["78674.41000000","0.00013000"],["78674.40000000","0.00013000"],["78674.25000000","0.07500000"],["78674.24000000","0.00007000"],["78674.14000000","0.43922000"],["78673.99000000","2.70747000"],["78673.98000000","0.00000000"],["78673.97000000","0.00000000"],["78673.92000000","0.00000000"],["78673.57000000","0.00000000"],["78673.49000000","0.00000000"],["78673.45000000","0.00000000"],["78673.41000000","0.00000000"],["78673.23000000","0.00014000"],["78673.22000000","0.00000000"],["78673.16000000","0.07500000"],["78673.15000000","0.03513000"],["78673.14000000","0.00000000"],["78673.13000000","0.00000000"],["78673.10000000","0.00000000"],["78673.00000000","0.00000000"],["78672.99000000","0.00021000"],["78672.00000000","0.07500000"],["78671.99000000","0.22044000"],["78671.98000000","0.00000000"],["78671.91000000","0.00000000"],["78671.90000000","1.55883000"],["78671.89000000","0.25064000"],["78671.88000000","0.00000000"],["78671.87000000","0.00000000"],["78671.80000000","0.05000000"],["78671.62000000","0.04978000"],["78671.36000000","0.00000000"],["78671.29000000","0.00000000"],["78671.19000000","0.00400000"],["78671.10000000","0.00000000"],["78670.87000000","0.00000000"],["78670.77000000","0.03224000"],["78670.74000000","0.00000000"],["78670.65000000","0.00000000"],["78670.64000000","0.00007000"],["78670.35000000","0.00000000"],["78669.99000000","0.00000000"],["78669.98000000","0.00000000"],["78669.43000000","0.00000000"],["78669.40000000","0.00000000"],["78669.36000000","0.00014000"],["78669.35000000","0.00000000"],["78669.32000000","0.00000000"],["78669.31000000","0.00000000"],["78669.09000000","0.00000000"],["78668.96000000","0.00000000"],["78668.89000000","0.00007000"],["78668.66000000","0.00027000"],["78668.56000000","0.00400000"],["78668.12000000","0.00000000"],["78668.00000000","0.05014000"],["78667.99000000","0.04216000"],["78667.98000000","0.00000000"],["78667.97000000","0.00000000"],["78667.96000000","0.00000000"],["78667.95000000","0.00014000"],["78667.91000000","0.00000000"],["78667.90000000","0.00000000"],["78667.19000000","0.00657000"],["78666.99000000","0.00007000"],["78666.84000000","0.00319000"],["78666.74000000","0.00000000"],["78666.73000000","0.00000000"],["78666.01000000","1.90515000"],["78666.00000000","1.21966000"],["78665.99000000","0.03767000"],["78665.71000000","0.00000000"],["78665.61000000","0.00000000"],["78665.47000000","0.00000000"],["78665.20000000","0.00000000"],["78665.17000000","0.00007000"],["78665.16000000","0.03000000"],["78665.09000000","0.12719000"],["78664.66000000","0.00000000"],["78664.32000000","0.38141000"],["78664.21000000","0.00000000"],["78663.99000000","0.02847000"],["78663.61000000","0.00007000"],["78663.50000000","0.08576000"],["78663.42000000","0.00010000"],["78663.33000000","0.00007000"],["78663.12000000","0.00007000"],["78663.11000000","0.00000000"],["78662.24000000","0.34328000"],["78662.00000000","1.22652000"],["78661.99000000","0.00000000"],["78661.86000000","0.08000000"],["78661.44000000","0.00318000"],["78661.15000000","0.00007000"],["78661.13000000","0.00000000"],["78660.46000000","0.00007000"],["78660.32000000","0.00000000"],["78660.00000000","0.08052000"],["78659.99000000","0.00000000"],["78659.88000000","0.00000000"],["78658.54000000","0.63561000"],["78658.53000000","0.00000000"],["78658.00000000","0.00700000"],["78657.37000000","0.00000000"],["78656.95000000","0.00000000"],["78656.86000000","0.04000000"],["78656.11000000","0.00000000"],["78656.00000000","0.00700000"],["78655.58000000","0.00000000"],["78654.16000000","0.00000000"],["78654.04000000","0.06594000"],["78654.00000000","0.00700000"],["78652.33000000","0.04479000"],["78652.07000000","0.07619000"],["78652.00000000","0.00707000"],["78651.99000000","0.00000000"],["78651.54000000","0.00000000"],["78651.37000000","0.00000000"],["78651.01000000","0.00000000"],["78650.39000000","0.00126000"],["78650.00000000","0.10236000"],["78648.00000000","0.01200000"],["78647.49000000","0.00000000"],["78646.00000000","0.02067000"],["78645.86000000","0.29358000"],["78645.57000000","0.00254000"],["78645.52000000","0.00000000"],["78645.15000000","0.00000000"],["78645.00000000","0.00000000"],["78643.67000000","0.00000000"],["78642.96000000","0.00000000"],["78641.71000000","0.00000000"],["78639.99000000","0.00000000"],["78639.41000000","0.00000000"],["78638.64000000","0.00000000"],["78634.53000000","0.00000000"],["78634.07000000","0.02000000"],["78634.06000000","0.00000000"],["78633.98000000","0.68344000"],["78631.98000000","0.09534000"],["78631.88000000","0.00010000"],["78631.33000000","0.00000000"],["78631.00000000","0.00000000"],["78630.66000000","0.00000000"],["78629.86000000","0.00000000"],["78629.76000000","0.00000000"],["78628.00000000","0.02400000"],["78627.33000000","0.38173000"],["78625.01000000","0.00425000"],["78621.94000000","0.00000000"],["78619.67000000","0.00000000"],["78612.35000000","0.00000000"],["78610.33000000","0.00000000"],["78609.07000000","0.00000000"],["78608.05000000","0.00000000"],["78603.91000000","0.00000000"],["78603.45000000","0.00274000"],["78602.64000000","0.00000000"],["78591.65000000","0.00007000"],["78589.59000000","0.00000000"],["78588.54000000","0.00014000"],["78570.61000000","0.00000000"],["78550.39000000","0.00000000"],["78538.96000000","0.00000000"],["78535.45000000","0.00000000"],["78533.82000000","4.09058000"],["78533.07000000","1.52347000"],["78517.95000000","0.00000000"],["78452.71000000","0.00406000"],["78444.73000000","0.00000000"],["78348.91000000","0.00027000"],["78335.06000000","0.00000000"],["78333.61000000","1.76841000"],["78297.87000000","0.00000000"],["78278.22000000","0.00000000"],["76932.91000000","0.00046000"],["76779.04000000","0.00053000"],["74739.42000000","0.00010000"],["74738.30000000","0.00010000"],["74734.60000000","0.00010000"],["74702.50000000","0.00000000"],["74700.96000000","0.00000000"],["70801.20000000","0.00000000"],["70801.19000000","0.00009000"],["62934.40000000","0.00000000"]],"a":[["78668.00000000","0.00000000"],["78668.01000000","0.00000000"],["78669.32000000","0.00000000"],["78669.33000000","0.00000000"],["78669.36000000","0.00000000"],["78669.41000000","0.00000000"],["78669.44000000","0.00000000"],["78669.99000000","0.00000000"],["78670.00000000","0.00000000"],["78670.65000000","0.00000000"],["78670.66000000","0.00000000"],["78670.88000000","0.00000000"],["78671.11000000","0.00000000"],["78671.30000000","0.00000000"],["78671.37000000","0.00000000"],["78671.90000000","0.00000000"],["78671.91000000","0.00000000"],["78671.99000000","0.00000000"],["78672.00000000","0.00000000"],["78673.00000000","0.00000000"],["78673.08000000","0.00000000"],["78673.16000000","0.00000000"],["78673.17000000","0.00000000"],["78673.23000000","0.00000000"],["78673.42000000","0.00000000"],["78673.46000000","0.00000000"],["78673.50000000","0.00000000"],["78673.93000000","0.00000000"],["78673.99000000","0.00000000"],["78674.00000000","0.00000000"],["78674.01000000","0.00000000"],["78674.15000000","0.00000000"],["78674.20000000","0.00000000"],["78674.24000000","0.00000000"],["78674.25000000","0.00000000"],["78674.42000000","0.00000000"],["78674.43000000","0.00079000"],["78674.44000000","0.00035000"],["78674.60000000","0.00000000"],["78675.46000000","0.00000000"],["78675.60000000","0.00007000"],["78675.68000000","0.00000000"],["78675.69000000","0.00007000"],["78675.85000000","0.00014000"],["78675.86000000","0.00007000"],["78675.99000000","0.00014000"],["78676.00000000","0.02407000"],["78676.23000000","0.00000000"],["78676.30000000","0.00007000"],["78676.50000000","0.00000000"],["78676.70000000","0.00000000"],["78677.10000000","0.00007000"],["78677.13000000","0.05191000"],["78677.84000000","0.00000000"],["78677.90000000","0.00007000"],["78677.94000000","0.00000000"],["78677.99000000","0.00014000"],["78678.00000000","0.02407000"],["78678.59000000","0.00000000"],["78678.77000000","0.00000000"],["78678.78000000","0.00000000"],["78679.39000000","0.00000000"],["78679.43000000","0.00000000"],["78679.57000000","0.00000000"],["78679.62000000","0.00000000"],["78679.83000000","0.00000000"],["78679.99000000","0.00014000"],["78680.34000000","0.00000000"],["78680.35000000","0.00000000"],["78680.97000000","0.00007000"],["78681.44000000","0.00000000"],["78681.49000000","0.00000000"],["78681.81000000","0.00000000"],["78681.99000000","0.00007000"],["78682.53000000","0.00007000"],["78683.00000000","0.00000000"],["78683.53000000","0.00000000"],["78683.66000000","0.12709000"],["78683.85000000","0.00000000"],["78683.95000000","0.00000000"],["78684.00000000","0.02400000"],["78684.08000000","0.00000000"],["78684.83000000","0.00000000"],["78684.91000000","0.01000000"],["78685.60000000","0.00000000"],["78685.68000000","0.00007000"],["78685.99000000","0.00000000"],["78686.11000000","0.00000000"],["78686.29000000","0.00000000"],["78686.36000000","0.00000000"],["78686.50000000","0.00000000"],["78686.60000000","0.00000000"],["78686.81000000","0.02000000"],["78687.12000000","0.00000000"],["78687.31000000","0.04000000"],["78687.39000000","0.00000000"],["78687.66000000","0.00000000"],["78687.69000000","0.00000000"],["78687.78000000","0.00000000"],["78687.93000000","0.00000000"],["78688.42000000","0.00254000"],["78688.43000000","0.00000000"],["78688.53000000","0.00254000"],["78688.54000000","0.00000000"],["78688.55000000","0.00000000"],["78688.77000000","0.00000000"],["78688.83000000","0.00000000"],["78689.21000000","0.08000000"],["78689.64000000","0.00000000"],["78689.66000000","0.04857000"],["78689.82000000","0.00000000"],["78689.99000000","0.00400000"],["78690.19000000","0.00000000"],["78690.24000000","0.00000000"],["78690.28000000","0.00007000"],["78690.54000000","0.00000000"],["78690.56000000","0.00000000"],["78690.85000000","0.31778000"],["78691.09000000","0.02287000"],["78691.36000000","0.00000000"],["78691.58000000","0.00000000"],["78692.61000000","0.00000000"],["78693.35000000","0.00000000"],["78693.80000000","0.00321000"],["78693.81000000","0.00635000"],["78694.15000000","1.21952000"],["78694.16000000","0.00007000"],["78694.18000000","0.00000000"],["78694.19000000","0.00000000"],["78694.23000000","0.00324000"],["78694.36000000","0.02000000"],["78695.28000000","0.00000000"],["78695.67000000","0.06591000"],["78696.55000000","0.00325000"],["78697.64000000","0.07615000"],["78698.80000000","0.00227000"],["78698.81000000","0.00000000"],["78699.36000000","0.00000000"],["78700.00000000","0.03207000"],["78700.46000000","1.21952000"],["78700.49000000","0.00322000"],["78700.73000000","1.90515000"],["78700.74000000","0.00000000"],["78700.94000000","0.00000000"],["78701.23000000","0.00000000"],["78701.51000000","0.00000000"],["78702.10000000","0.00322000"],["78702.99000000","0.00000000"],["78703.39000000","0.00000000"],["78703.82000000","0.00000000"],["78704.01000000","0.00000000"],["78704.25000000","0.00000000"],["78704.38000000","0.09751000"],["78704.43000000","0.00419000"],["78704.68000000","0.00000000"],["78704.89000000","0.00000000"],["78705.94000000","0.36224000"],["78705.95000000","0.00000000"],["78706.02000000","0.00000000"],["78707.74000000","0.00000000"],["78708.00000000","0.02407000"],["78708.06000000","0.00014000"],["78708.17000000","0.00000000"],["78708.37000000","0.00326000"],["78708.89000000","0.00000000"],["78709.39000000","0.43600000"],["78709.66000000","0.00000000"],["78709.97000000","0.00321000"],["78710.59000000","0.04454000"],["78711.02000000","0.34306000"],["78711.93000000","0.00014000"],["78712.00000000","0.02400000"],["78712.81000000","0.63530000"],["78712.99000000","0.00000000"],["78713.00000000","0.00000000"],["78713.40000000","0.00000000"],["78714.00000000","0.03400000"],["78714.19000000","0.00000000"],["78714.40000000","0.00000000"],["78714.51000000","0.00000000"],["78714.60000000","0.02772000"],["78715.80000000","0.00007000"],["78717.18000000","0.02161000"],["78717.19000000","0.00000000"],["78717.84000000","0.00334000"],["78718.35000000","0.34303000"],["78718.69000000","0.00000000"],["78719.67000000","0.00007000"],["78720.00000000","0.09746000"],["78720.22000000","0.00661000"],["78721.16000000","0.00400000"],["78721.99000000","0.00315000"],["78726.42000000","0.00400000"],["78727.69000000","0.00007000"],["78728.46000000","0.00000000"],["78731.79000000","0.00000000"],["78732.20000000","0.00000000"],["78732.99000000","0.00000000"],["78733.19000000","0.00000000"],["78733.31000000","0.00000000"],["78733.40000000","0.02418000"],["78739.34000000","0.00000000"],["78745.99000000","0.00315000"],["78750.44000000","1.25729000"],["78755.77000000","0.00010000"],["78756.19000000","0.00000000"],["78774.85000000","0.21930000"],["78776.75000000","1.90515000"],["78780.27000000","1.21952000"],["78786.93000000","0.04602000"],["78790.50000000","0.00000000"],["78816.88000000","0.00000000"],["78832.05000000","1.52347000"],["78876.00000000","0.00007000"],["78883.72000000","0.00007000"],["78887.65000000","0.00007000"],["78924.37000000","0.00000000"],["78934.31000000","0.00027000"]]}}}
{"rx_ns": 173335143405300, "frame": {"stream":"btcusdt@depth20@100ms","data":{"lastUpdateId":99076749199,"bids":[["78675.99000000","4.54364000"],["78675.98000000","0.00020000"],["78675.97000000","0.00013000"],["78674.43000000","0.31794000"],["78674.42000000","1.96113000"],["78674.40000000","0.05000000"],["78674.25000000","0.00007000"],["78674.14000000","0.00014000"],["78674.00000000","0.00014000"],["78673.99000000","0.36056000"],["78673.82000000","0.00400000"],["78673.23000000","0.00014000"],["78673.19000000","0.04978000"],["78673.16000000","0.04109000"],["78673.15000000","0.03014000"],["78672.99000000","0.00014000"],["78672.31000000","0.00400000"],["78672.15000000","0.00335000"],["78672.00000000","0.00007000"],["78671.99000000","0.22044000"]],"asks":[["78676.00000000","0.44544000"],["78676.01000000","0.00056000"],["78677.10000000","0.00007000"],["78677.12000000","0.00014000"],["78677.13000000","0.00014000"],["78677.41000000","0.00007000"],["78677.51000000","0.00007000"],["78677.99000000","0.00014000"],["78678.00000000","0.02407000"],["78678.49000000","0.00014000"],["78678.50000000","0.01351000"],["78678.64000000","0.00007000"],["78678.70000000","0.05191000"],["78679.48000000","0.00027000"],["78679.55000000","0.00007000"],["78679.75000000","0.00014000"],["78679.76000000","0.02252000"],["78679.99000000","0.00007000"],["78680.00000000","0.02414000"],["78680.77000000","0.00070000"]]}}}
{"rx_ns": 173335143508200, "frame": {"stream":"btcusdt@depth@100ms","data":{"e":"depthUpdate","E":1787603274314,"s":"BTCUSDT","U":99076748709,"u":99076749199,"b":[["78675.99000000","4.54364000"],["78675.98000000","0.00020000"],["78675.97000000","0.00013000"],["78675.85000000","0.00000000"],["78675.84000000","0.00000000"],["78675.82000000","0.00000000"],["78675.68000000","0.00000000"],["78675.59000000","0.00000000"],["78675.30000000","0.00000000"],["78674.75000000","0.00000000"],["78674.74000000","0.00000000"],["78674.43000000","0.31794000"],["78674.42000000","1.96113000"],["78674.41000000","0.00000000"],["78674.40000000","0.05000000"],["78674.26000000","0.00000000"],["78674.25000000","0.00007000"],["78674.24000000","0.00000000"],["78674.14000000","0.00014000"],["78674.00000000","0.00014000"],["78673.99000000","0.36056000"],["78673.82000000","0.00400000"],["78673.19000000","0.04978000"],["78673.16000000","0.04109000"],["78673.15000000","0.03014000"],["78673.05000000","0.00000000"],["78672.99000000","0.00014000"],["78672.54000000","0.00000000"],["78672.31000000","0.00400000"],["78672.15000000","0.00335000"],["78672.00000000","0.00007000"],["78671.91000000","0.00014000"],["78671.90000000","1.60798000"],["78671.89000000","0.16667000"],["78671.80000000","0.00000000"],["78671.62000000","0.00000000"],["78670.90000000","0.00008000"],["78670.64000000","0.04929000"],["78670.58000000","0.00326000"],["78669.34000000","0.02000000"],["78668.00000000","0.00014000"],["78667.99000000","0.00328000"],["78667.95000000","0.00000000"],["78666.76000000","0.00007000"],["78665.99000000","0.03754000"],["78664.96000000","0.08576000"],["78663.99000000","0.00331000"],["78663.50000000","0.00000000"],["78660.67000000","0.00007000"],["78657.31000000","0.21930000"],["78653.98000000","0.00000000"],["78649.43000000","0.14073000"],["78645.57000000","0.00000000"],["78643.99000000","0.00000000"],["78634.27000000","0.00000000"],["78634.00000000","0.03400000"],["78633.35000000","0.00000000"],["78632.00000000","0.02400000"],["78630.00000000","0.02400000"],["78626.91000000","0.01159000"],["78624.36000000","0.00000000"],["78618.54000000","0.00000000"],["78610.04000000","0.00000000"],["78609.34000000","0.01714000"],["78607.28000000","0.00536000"],["78606.25000000","0.00112000"],["78575.28000000","0.00000000"],["78575.20000000","0.04634000"],["78552.84000000","0.00000000"],["78539.89000000","0.00000000"],["78537.12000000","0.00000000"],["78524.16000000","0.00000000"],["78521.40000000","0.00000000"],["78508.43000000","0.00013000"],["78492.70000000","0.00000000"],["78476.97000000","0.00000000"],["78461.24000000","0.00000000"],["78447.84000000","0.00000000"],["78445.51000000","0.00000000"],["78429.78000000","0.00000000"],["78414.05000000","0.00000000"],["78281.04000000","0.01000000"],["77899.63000000","0.00154000"],["77889.64000000","0.01000000"],["77500.19000000","0.01000000"],["77112.69000000","0.01000000"],["76727.13000000","0.01000000"],["76343.49000000","0.01000000"],["75961.77000000","0.01000000"],["75581.96000000","0.01000000"],["75204.05000000","0.01000000"],["74828.03000000","0.01000000"],["74453.89000000","0.01000000"],["74081.62000000","0.01000000"],["73711.22000000","0.01000000"],["73342.66000000","0.01000000"],["72975.95000000","0.01000000"],["70806.98000000","0.00000000"],["62939.00000000","0.00000000"]],"a":[["78674.43000000","0.00000000"],["78674.44000000","0.00000000"],["78674.76000000","0.00000000"],["78675.31000000","0.00000000"],["78675.60000000","0.00000000"],["78675.69000000","0.00000000"],["78675.83000000","0.00000000"],["78675.85000000","0.00000000"],["78675.86000000","0.00000000"],["78675.99000000","0.00000000"],["78676.00000000","0.44544000"],["78676.01000000","0.00056000"],["78676.30000000","0.00000000"],["78677.12000000","0.00014000"],["78677.13000000","0.00014000"],["78677.17000000","0.00000000"],["78677.41000000","0.00007000"],["78677.44000000","0.00000000"],["78677.90000000","0.00000000"],["78678.00000000","0.02407000"],["78678.49000000","0.00014000"],["78678.50000000","0.01351000"],["78678.60000000","0.00000000"],["78678.70000000","0.05191000"],["78679.38000000","0.00000000"],["78679.48000000","0.00027000"],["78679.75000000","0.00014000"],["78679.76000000","0.02252000"],["78679.99000000","0.00007000"],["78680.00000000","0.02414000"],["78680.97000000","0.00014000"],["78681.02000000","0.02703000"],["78681.79000000","0.00000000"],["78681.96000000","0.00000000"],["78681.97000000","0.20866000"],["78681.99000000","0.00000000"],["78682.00000000","0.02407000"],["78682.28000000","0.02703000"],["78682.80000000","0.00000000"],["78683.65000000","0.02161000"],["78683.66000000","0.12716000"],["78683.87000000","0.21930000"],["78684.00000000","0.02407000"],["78684.91000000","0.00000000"],["78686.61000000","0.01000000"],["78687.31000000","0.00000000"],["78687.99000000","0.31777000"],["78688.31000000","0.04000000"],["78688.83000000","0.00007000"],["78689.02000000","0.00254000"],["78689.21000000","0.00000000"],["78689.66000000","0.00000000"],["78690.11000000","0.00000000"],["78690.21000000","0.00000000"],["78690.85000000","0.00000000"],["78690.91000000","0.08000000"],["78691.12000000","0.04857000"],["78691.21000000","0.00048000"],["78691.74000000","0.00000000"],["78693.82000000","0.00000000"],["78694.14000000","3.12467000"],["78694.15000000","0.00000000"],["78701.44000000","0.41236000"],["78702.18000000","0.02000000"],["78704.38000000","0.00000000"],["78705.00000000","0.00000000"],["78705.93000000","0.02161000"],["78706.00000000","0.02400000"],["78713.92000000","0.02497000"],["78714.00000000","0.02400000"],["78714.60000000","0.00000000"],["78714.67000000","0.00000000"],["78714.91000000","0.00000000"],["78715.12000000","0.00000000"],["78715.22000000","0.00000000"],["78715.26000000","0.00000000"],["78715.73000000","0.00000000"],["78715.97000000","0.02838000"],["78716.00000000","0.03400000"],["78717.50000000","0.00000000"],["78717.73000000","1.22098000"],["78718.44000000","0.00000000"],["78723.79000000","0.00400000"],["78729.38000000","0.00430000"],["78729.98000000","0.00432000"],["78733.40000000","0.00000000"],["78733.46000000","0.00000000"],["78733.50000000","0.01159000"],["78733.91000000","0.00000000"],["78734.01000000","0.00000000"],["78734.05000000","0.00000000"],["78734.53000000","0.00000000"],["78734.76000000","0.02348000"],["78752.44000000","0.02000000"],["78776.75000000","0.00000000"],["78807.30000000","0.00000000"],["78823.03000000","0.00000000"],["78838.76000000","0.00000000"],["78854.49000000","0.00000000"],["78870.22000000","0.00000000"],["78885.95000000","0.00000000"],["79067.81000000","0.00000000"],["79463.15000000","0.00000000"],["79860.46000000","0.00029000"],["80259.76000000","0.00000000"],["80661.06000000","0.00000000"],["81064.37000000","0.00024000"],["81469.69000000","0.00000000"],["81877.04000000","0.00000000"],["82286.42000000","0.00000000"],["82697.86000000","0.00000000"],["83111.34000000","0.00000000"],["83526.90000000","0.00000000"],["83944.54000000","0.00000000"],["84364.26000000","0.00000000"],["84786.08000000","0.00000000"]]}}}
{"rx_ns": 173335240150300, "frame": {"stream":"btcusdt@depth20@100ms","data":{"lastUpdateId":99076749354,"bids":[["78675.99000000","4.75608000"],["78675.98000000","0.00020000"],["78675.97000000","0.00013000"],["78674.44000000","0.00014000"],["78674.43000000","0.31801000"],["78674.42000000","1.93049000"],["78674.40000000","0.00007000"],["78674.27000000","0.00007000"],["78674.14000000","0.00007000"],["78674.00000000","0.00014000"],["78673.99000000","0.03014000"],["78673.82000000","0.00400000"],["78673.23000000","0.00014000"],["78673.19000000","0.04978000"],["78673.16000000","0.00007000"],["78673.15000000","0.03007000"],["78672.99000000","0.00007000"],["78672.31000000","0.00400000"],["78672.15000000","0.00335000"],["78672.00000000","0.00007000"]],"asks":[["78676.00000000","0.44649000"],["78676.01000000","0.00049000"],["78676.11000000","0.00007000"],["78676.12000000","0.20859000"],["78677.10000000","0.00014000"],["78677.13000000","0.00007000"],["78677.31000000","0.00014000"],["78677.32000000","0.21534000"],["78677.41000000","0.00007000"],["78677.51000000","0.00007000"],["78677.99000000","0.00014000"],["78678.00000000","0.02407000"],["78678.50000000","0.00007000"],["78678.64000000","0.00007000"],["78678.69000000","0.00014000"],["78678.70000000","0.05198000"],["78679.48000000","0.00027000"],["78679.55000000","0.00007000"],["78679.76000000","0.00007000"],["78679.99000000","0.00014000"]]}}}
{"rx_ns": 173335240281100, "frame": {"stream":"btcusdt@depth@100ms","data":{"e":"depthUpdate","E":1787603274414,"s":"BTCUSDT","U":99076749200,"u":99076749354,"b":[["78675.99000000","4.75608000"],["78674.44000000","0.00014000"],["78674.43000000","0.31801000"],["78674.42000000","1.93049000"],["78674.40000000","0.00007000"],["78674.27000000","0.00007000"],["78674.25000000","0.00000000"],["78674.14000000","0.00007000"],["78673.99000000","0.03014000"],["78673.16000000","0.00007000"],["78673.15000000","0.03007000"],["78672.99000000","0.00007000"],["78672.17000000","0.00000000"],["78672.10000000","0.00000000"],["78672.00000000","0.00007000"],["78671.99000000","0.21944000"],["78671.90000000","1.21959000"],["78670.64000000","0.00007000"],["78668.71000000","0.00254000"],["78667.19000000","0.00650000"],["78666.17000000","0.00007000"],["78665.48000000","0.00000000"],["78665.19000000","0.00000000"],["78665.18000000","0.00000000"],["78665.17000000","0.00000000"],["78665.09000000","0.12712000"],["78664.65000000","0.00000000"],["78636.00000000","0.03400000"],["78635.00000000","0.00000000"],["78634.00000000","0.02400000"],["78632.67000000","0.02540000"],["78621.61000000","0.00436000"],["78610.91000000","0.00000000"],["78577.84000000","0.00000000"],["78450.33000000","0.00000000"],["78416.84000000","0.00000000"],["76625.48000000","0.00061000"],["76472.22000000","0.00076000"],["70808.40000000","0.00016000"]],"a":[["78676.00000000","0.44649000"],["78676.01000000","0.00049000"],["78676.11000000","0.00007000"],["78676.12000000","0.20859000"],["78677.10000000","0.00014000"],["78677.12000000","0.00000000"],["78677.13000000","0.00007000"],["78677.31000000","0.00014000"],["78677.32000000","0.21534000"],["78678.00000000","0.02407000"],["78678.49000000","0.00000000"],["78678.50000000","0.00007000"],["78678.69000000","0.00014000"],["78678.70000000","0.05198000"],["78679.75000000","0.00000000"],["78679.76000000","0.00007000"],["78679.99000000","0.00014000"],["78680.00000000","0.02414000"],["78681.01000000","0.00000000"],["78681.02000000","0.00007000"],["78681.97000000","0.00014000"],["78681.99000000","0.00000000"],["78682.00000000","0.02407000"],["78682.28000000","0.00000000"],["78683.66000000","0.12716000"],["78684.00000000","0.02400000"],["78684.44000000","0.00254000"],["78687.04000000","0.00000000"],["78689.02000000","0.00000000"],["78690.19000000","1.21952000"],["78691.15000000","0.00406000"],["78699.03000000","0.02000000"],["78709.91000000","0.00000000"],["78714.03000000","0.00180000"],["78715.80000000","0.00000000"],["78719.67000000","0.00000000"],["78737.69000000","0.00000000"],["78749.30000000","0.02000000"],["78780.27000000","0.00000000"],["78890.17000000","0.00007000"],["78894.10000000","0.00007000"]]}}}
{"rx_ns": 173335337783500, "frame": {"stream":"btcusdt@depth20@100ms","data":{"lastUpdateId":99076749450,"bids":[["78675.99000000","5.05507000"],["78675.98000000","0.00020000"],["78675.97000000","0.00013000"],["78675.96000000","0.00014000"],["78675.95000000","0.05000000"],["78675.91000000","0.00014000"],["78675.90000000","0.05000000"],["78674.73000000","0.04102000"],["78674.44000000","0.00014000"],["78674.43000000","0.31801000"],["78674.42000000","1.90679000"],["78674.27000000","0.00007000"],["78673.99000000","0.03014000"],["78673.82000000","0.00400000"],["78673.47000000","0.04922000"],["78673.23000000","0.00014000"],["78673.19000000","0.04985000"],["78673.15000000","0.03014000"],["78672.99000000","0.00007000"],["78672.31000000","0.00400000"]],"asks":[["78676.00000000","0.44663000"],["78676.01000000","0.00063000"],["78676.11000000","0.00014000"],["78676.12000000","0.20866000"],["78677.10000000","0.00014000"],["78677.13000000","0.00007000"],["78677.31000000","0.00014000"],["78677.32000000","0.21541000"],["78677.41000000","0.00007000"],["78677.51000000","0.00007000"],["78677.99000000","0.00014000"],["78678.00000000","0.02407000"],["78678.64000000","0.00007000"],["78678.69000000","0.00014000"],["78678.70000000","0.05198000"],["78679.48000000","0.00027000"],["78679.55000000","0.00007000"],["78679.99000000","0.00014000"],["78680.00000000","0.02414000"],["78680.08000000","0.01351000"]]}}}
{"rx_ns": 173335337877000, "frame": {"stream":"btcusdt@depth@100ms","data":{"e":"depthUpdate","E":1787603274514,"s":"BTCUSDT","U":99076749355,"u":99076749450,"b":[["78675.99000000","5.05507000"],["78675.96000000","0.00014000"],["78675.95000000","0.05000000"],["78675.91000000","0.00014000"],["78675.90000000","0.05000000"],["78674.73000000","0.04102000"],["78674.42000000","1.90679000"],["78674.40000000","0.00000000"],["78674.14000000","0.00000000"],["78674.00000000","0.00000000"],["78673.47000000","0.04922000"],["78673.19000000","0.04985000"],["78673.16000000","0.00000000"],["78673.15000000","0.03014000"],["78672.21000000","0.04922000"],["78672.00000000","0.00000000"],["78671.99000000","0.00014000"],["78671.91000000","0.00000000"],["78669.49000000","0.00254000"],["78668.71000000","0.00000000"],["78667.19000000","0.00000000"],["78667.00000000","0.00007000"],["78660.32000000","0.12712000"],["78643.72000000","1.21952000"],["78494.87000000","0.00181000"],["78490.62000000","0.00779000"],["78440.14000000","0.01991000"],["70808.40000000","0.00032000"],["62940.80000000","0.00031000"]],"a":[["78676.00000000","0.44663000"],["78676.01000000","0.00063000"],["78676.11000000","0.00014000"],["78676.12000000","0.20866000"],["78677.10000000","0.00014000"],["78677.32000000","0.21541000"],["78678.00000000","0.02407000"],["78678.50000000","0.00000000"],["78678.70000000","0.05198000"],["78679.76000000","0.00000000"],["78680.00000000","0.02414000"],["78680.08000000","0.01351000"],["78680.24000000","0.00000000"],["78681.02000000","0.00000000"],["78681.33000000","0.02252000"],["78681.97000000","0.00007000"],["78682.00000000","0.02407000"],["78682.59000000","0.02703000"],["78683.65000000","0.02168000"],["78683.66000000","0.12723000"],["78683.85000000","0.02703000"],["78684.44000000","0.00000000"],["78685.21000000","0.00254000"],["78702.68000000","0.02600000"],["78713.04000000","0.00000000"],["78715.80000000","0.00000000"],["78718.24000000","0.34303000"],["78752.44000000","0.00000000"],["78752.91000000","0.02600000"]]}}}
{"rx_ns": 173335437982100, "frame": {"stream":"btcusdt@depth20@100ms","data":{"lastUpdateId":99076749489,"bids":[["78675.99000000","5.05521000"],["78675.98000000","0.00020000"],["78675.97000000","0.00013000"],["78675.96000000","0.00014000"],["78675.95000000","0.05014000"],["78675.91000000","0.00014000"],["78675.90000000","0.05007000"],["78674.74000000","0.00007000"],["78674.73000000","0.04102000"],["78674.44000000","0.00014000"],["78674.43000000","0.31801000"],["78674.42000000","1.90679000"],["78674.27000000","0.00007000"],["78673.99000000","0.03007000"],["78673.82000000","0.00400000"],["78673.47000000","0.04922000"],["78673.23000000","0.00014000"],["78673.19000000","0.04985000"],["78673.15000000","0.03007000"],["78672.99000000","0.00007000"]],"asks":[["78676.00000000","0.62067000"],["78676.01000000","0.00056000"],["78676.11000000","0.00014000"],["78676.12000000","0.20866000"],["78677.10000000","0.00014000"],["78677.13000000","0.00007000"],["78677.32000000","0.00007000"],["78677.41000000","0.00007000"],["78677.51000000","0.00007000"],["78677.99000000","0.00014000"],["78678.00000000","0.02407000"],["78678.64000000","0.00007000"],["78678.69000000","0.00014000"],["78678.70000000","0.05198000"],["78679.48000000","0.00027000"],["78679.55000000","0.00007000"],["78679.99000000","0.00014000"],["78680.00000000","0.02414000"],["78680.08000000","0.01358000"],["78680.12000000","0.12718000"]]}}}
{"rx_ns": 173335438116800, "frame": {"stream":"btcusdt@depth@100ms","data":{"e":"depthUpdate","E":1787603274614,"s":"BTCUSDT","U":99076749451,"u":99076749489,"b":[["78675.99000000","5.05521000"],["78675.95000000","0.05014000"],["78675.90000000","0.05007000"],["78674.74000000","0.00007000"],["78673.99000000","0.03007000"],["78673.15000000","0.03007000"],["78671.99000000","0.00007000"],["78595.16000000","0.02117000"],["70808.40000000","0.00048000"],["62940.80000000","0.00000000"]],"a":[["78676.00000000","0.62067000"],["78676.01000000","0.00056000"],["78677.31000000","0.00000000"],["78677.32000000","0.00007000"],["78680.00000000","0.02414000"],["78680.08000000","0.01358000"],["78680.12000000","0.12718000"],["78681.32000000","0.00007000"],["78681.33000000","0.02259000"],["78682.00000000","0.02407000"],["78683.65000000","0.02161000"],["78683.66000000","0.12716000"],["78699.66000000","0.12706000"],["78713.51000000","0.00000000"],["78730.50000000","0.00406000"],["78769.79000000","0.93649000"],["78770.51000000","0.00000000"],["78776.64000000","0.00000000"],["78782.74000000","0.00000000"]]}}}
{"rx_ns": 173335540406900, "frame": {"stream":"btcusdt@depth20@100ms","data":{"lastUpdateId":99076749524,"bids":[["78675.99000000","5.05555000"],["78675.98000000","0.00020000"],["78675.97000000","0.00013000"],["78675.96000000","0.00014000"],["78675.95000000","0.05014000"],["78675.91000000","0.00014000"],["78675.90000000","0.05007000"],["78674.74000000","0.00042000"],["78674.73000000","0.04109000"],["78674.44000000","0.00014000"],["78674.43000000","0.31801000"],["78674.42000000","1.90679000"],["78674.27000000","0.00007000"],["78673.99000000","0.03014000"],["78673.82000000","0.00400000"],["78673.47000000","0.04922000"],["78673.23000000","0.00014000"],["78673.19000000","0.04985000"],["78673.15000000","0.03007000"],["78672.99000000","0.00007000"]],"asks":[["78676.00000000","0.58948000"],["78676.01000000","0.00063000"],["78676.11000000","0.00014000"],["78676.12000000","0.20866000"],["78677.10000000","0.00014000"],["78677.13000000","0.00007000"],["78677.41000000","0.00007000"],["78677.51000000","0.00007000"],["78677.99000000","0.00014000"],["78678.00000000","0.02407000"],["78678.64000000","0.00007000"],["78678.69000000","0.00014000"],["78678.70000000","0.05205000"],["78679.48000000","0.00027000"],["78679.55000000","0.00007000"],["78679.99000000","0.00014000"],["78680.00000000","0.02414000"],["78680.08000000","0.01358000"],["78680.12000000","0.00007000"],["78680.77000000","0.00070000"]]}}}
{"rx_ns": 173335540490400, "frame": {"stream":"btcusdt@depth@100ms","data":{"e":"depthUpdate","E":1787603274714,"s":"BTCUSDT","U":99076749490,"u":99076749524,"b":[["78675.99000000","5.05555000"],["78674.74000000","0.00042000"],["78674.73000000","0.04109000"],["78673.99000000","0.03014000"],["78668.00000000","0.00007000"],["78665.69000000","0.00007000"],["78660.25000000","0.00007000"],["78659.11000000","0.00007000"],["78647.98000000","0.00000000"],["78642.08000000","0.00000000"],["78640.93000000","0.00000000"],["70808.40000000","0.00080000"]],"a":[["78676.00000000","0.58948000"],["78676.01000000","0.00063000"],["78676.12000000","0.20866000"],["78677.32000000","0.00000000"],["78678.70000000","0.05205000"],["78680.08000000","0.01358000"],["78680.12000000","0.00007000"]]}}}
{"rx_ns": 173335637949800, "frame": {"stream":"btcusdt@depth20@100ms","data":{"lastUpdateId":99076749581,"bids":[["78675.99000000","5.05562000"],["78675.98000000","0.00020000"],["78675.97000000","0.00013000"],["78675.96000000","0.00014000"],["78675.95000000","0.05014000"],["78675.91000000","0.00014000"],["78675.90000000","0.05007000"],["78674.74000000","0.00042000"],["78674.73000000","0.04818000"],["78674.44000000","0.00014000"],["78674.43000000","0.31801000"],["78674.42000000","1.90679000"],["78674.27000000","0.00007000"],["78673.99000000","0.03014000"],["78673.82000000","0.00400000"],["78673.47000000","0.04922000"],["78673.23000000","0.00014000"],["78673.19000000","0.04985000"],["78673.15000000","0.03007000"],["78672.99000000","0.00007000"]],"asks":[["78676.00000000","0.41430000"],["78676.01000000","0.00056000"],["78676.11000000","0.00014000"],["78676.12000000","0.20866000"],["78677.10000000","0.00014000"],["78677.13000000","0.00007000"],["78677.41000000","0.00007000"],["78677.51000000","0.00007000"],["78677.99000000","0.00014000"],["78678.00000000","0.02407000"],["78678.64000000","0.00007000"],["78678.69000000","0.00014000"],["78678.70000000","0.05198000"],["78679.55000000","0.00007000"],["78679.99000000","0.00014000"],["78680.00000000","0.02414000"],["78680.08000000","0.01358000"],["78680.77000000","0.00070000"],["78680.97000000","0.00014000"],["78681.32000000","0.00007000"]]}}}
{"rx_ns": 173335638060900, "frame": {"stream":"btcusdt@depth@100ms","data":{"e":"depthUpdate","E":1787603274814,"s":"BTCUSDT","U":99076749525,"u":99076749581,"b":[["78675.99000000","5.05562000"],["78674.73000000","0.04818000"],["78641.45000000","0.00000000"],["78602.12000000","0.00000000"],["78595.16000000","0.00000000"],["78570.67000000","0.00000000"],["78523.48000000","0.00000000"],["78452.71000000","0.00000000"],["78281.04000000","0.00000000"],["77889.64000000","0.00000000"],["77500.19000000","0.00000000"],["77112.69000000","0.00000000"],["76727.13000000","0.00000000"],["76343.49000000","0.00000000"],["75961.77000000","0.00000000"],["75581.96000000","0.00000000"],["75204.05000000","0.00000000"],["74828.03000000","0.00000000"],["74453.89000000","0.00000000"],["74081.62000000","0.00000000"],["73711.22000000","0.00000000"],["73342.66000000","0.00000000"],["72975.95000000","0.00000000"],["62941.00000000","0.00000000"]],"a":[["78676.00000000","0.41430000"],["78676.01000000","0.00056000"],["78678.70000000","0.05198000"],["78679.48000000","0.00000000"],["78680.08000000","0.01358000"],["78680.12000000","0.00000000"],["78682.59000000","0.02710000"],["78687.99000000","0.00000000"],["78689.74000000","0.31778000"],["78690.19000000","0.00000000"],["78691.15000000","0.00000000"],["78694.14000000","1.21952000"],["78704.65000000","0.09603000"],["78730.50000000","0.00000000"],["78761.98000000","0.00000000"],["78776.75000000","1.90515000"],["78809.19000000","0.00000000"],["78880.01000000","0.00000000"],["80000.00000000","103.80929000"]]}}}
{"rx_ns": 173335739376800, "frame": {"stream":"btcusdt@depth20@100ms","data":{"lastUpdateId":99076749618,"bids":[["78675.99000000","4.79494000"],["78675.98000000","0.00020000"],["78675.97000000","0.00013000"],["78675.96000000","0.00014000"],["78675.95000000","0.05014000"],["78675.91000000","0.00014000"],["78675.90000000","0.05007000"],["78674.74000000","0.00042000"],["78674.73000000","0.04818000"],["78674.44000000","0.00014000"],["78674.43000000","0.31801000"],["78674.42000000","1.90679000"],["78674.27000000","0.00007000"],["78673.99000000","0.03014000"],["78673.82000000","0.00400000"],["78673.47000000","0.04922000"],["78673.23000000","0.00014000"],["78673.19000000","0.04985000"],["78673.15000000","0.03007000"],["78672.99000000","0.00007000"]],"asks":[["78676.00000000","0.00842000"],["78676.01000000","0.00056000"],["78676.11000000","0.00014000"],["78676.12000000","0.20866000"],["78676.62000000","0.00007000"],["78677.10000000","0.00007000"],["78677.13000000","0.00007000"],["78677.51000000","0.00007000"],["78677.99000000","0.00014000"],["78678.00000000","0.02407000"],["78678.64000000","0.00007000"],["78678.69000000","0.00014000"],["78678.70000000","0.05198000"],["78678.98000000","0.00007000"],["78679.55000000","0.00007000"],["78679.99000000","0.00014000"],["78680.00000000","0.02414000"],["78680.08000000","0.01358000"],["78680.77000000","0.00070000"],["78680.97000000","0.00014000"]]}}}
{"rx_ns": 173335739503700, "frame": {"stream":"btcusdt@depth@100ms","data":{"e":"depthUpdate","E":1787603274914,"s":"BTCUSDT","U":99076749582,"u":99076749618,"b":[["78675.99000000","4.79494000"],["78671.51000000","0.00254000"],["78670.44000000","0.00000000"],["78669.49000000","0.00000000"],["78664.69000000","0.02600000"],["78663.91000000","0.03132000"],["78652.35000000","0.00007000"],["78644.35000000","0.00000000"],["78595.16000000","0.02117000"],["78548.47000000","0.00000000"],["70808.40000000","0.00112000"]],"a":[["78676.00000000","0.00842000"],["78676.62000000","0.00007000"],["78677.10000000","0.00007000"],["78677.41000000","0.00000000"],["78678.98000000","0.00007000"],["78685.21000000","0.00000000"],["78686.16000000","0.00000000"],["78687.24000000","0.00254000"],["78691.56000000","0.00000000"],["78698.28000000","0.02000000"],["78699.07000000","0.02000000"],["78699.56000000","0.00007000"],["78715.80000000","0.00007000"],["78748.44000000","0.02000000"],["78780.52000000","0.00012000"],["78786.66000000","0.00019000"],["78792.75000000","0.00031000"]]}}}
{"rx_ns": 173335838900800, "frame": {"stream":"btcusdt@depth20@100ms","data":{"lastUpdateId":99076749658,"bids":[["78675.99000000","5.05656000"],["78675.98000000","0.00020000"],["78675.97000000","0.00013000"],["78675.96000000","0.00014000"],["78675.95000000","0.05014000"],["78675.91000000","0.00014000"],["78675.90000000","0.05007000"],["78674.74000000","0.00042000"],["78674.73000000","0.04818000"],["78674.44000000","0.00014000"],["78674.43000000","0.31801000"],["78674.42000000","1.90679000"],["78674.27000000","0.00007000"],["78674.00000000","0.00500000"],["78673.99000000","0.03014000"],["78673.82000000","0.00400000"],["78673.47000000","0.04922000"],["78673.23000000","0.00014000"],["78673.19000000","0.04985000"],["78673.15000000","0.03007000"]],"asks":[["78676.00000000","0.00242000"],["78676.01000000","0.00056000"],["78676.11000000","0.00014000"],["78676.12000000","0.20866000"],["78676.62000000","0.00007000"],["78677.10000000","0.00007000"],["78677.13000000","0.00007000"],["78677.51000000","0.00007000"],["78677.99000000","0.00014000"],["78678.00000000","0.02407000"],["78678.64000000","0.00007000"],["78678.69000000","0.00014000"],["78678.70000000","0.05198000"],["78678.98000000","0.00007000"],["78679.55000000","0.00007000"],["78679.71000000","0.22573000"],["78679.99000000","0.00014000"],["78680.00000000","0.02414000"],["78680.08000000","0.01358000"],["78680.77000000","0.00070000"]]}}}
{"rx_ns": 173335838983300, "frame": {"stream":"btcusdt@depth@100ms","data":{"e":"depthUpdate","E":1787603275014,"s":"BTCUSDT","U":99076749619,"u":99076749658,"b":[["78675.99000000","5.05656000"],["78674.00000000","0.00500000"],["78672.00000000","0.00500000"],["78670.00000000","0.00500000"],["78669.34000000","0.00000000"],["78668.00000000","0.00507000"],["78666.00000000","1.22466000"],["78664.00000000","0.00500000"],["78663.92000000","0.02800000"],["78662.00000000","1.23152000"],["78660.00000000","0.08552000"],["78658.00000000","0.01200000"],["78656.00000000","0.01200000"],["78654.00000000","0.01200000"],["78652.00000000","0.01207000"],["78651.45000000","0.00000000"],["78650.00000000","0.10736000"],["78595.16000000","0.00000000"],["70808.40000000","0.00144000"],["70808.00000000","0.00606000"],["62941.00000000","0.00000000"],["62940.80000000","0.00031000"],["62940.79000000","0.00000000"]],"a":[["78676.00000000","0.00242000"],["78679.71000000","0.22573000"],["78699.07000000","0.04000000"],["78707.38000000","0.00000000"],["78748.44000000","0.04000000"],["78756.71000000","0.02000000"],["78893.13000000","0.00406000"]]}}}
{"rx_ns": 173335942539700, "frame": {"stream":"btcusdt@depth20@100ms","data":{"lastUpdateId":99076749861,"bids":[["78676.11000000","6.52468000"],["78676.10000000","0.00020000"],["78676.09000000","0.00013000"],["78676.06000000","0.00014000"],["78676.05000000","0.05000000"],["78676.01000000","0.00014000"],["78676.00000000","0.74981000"],["78675.99000000","2.39884000"],["78675.95000000","0.00014000"],["78675.90000000","0.00007000"],["78674.74000000","0.00035000"],["78674.73000000","0.04109000"],["78674.43000000","0.00007000"],["78674.42000000","0.00164000"],["78674.27000000","0.00007000"],["78674.00000000","0.00500000"],["78673.99000000","0.03014000"],["78673.82000000","0.00400000"],["78673.47000000","0.04922000"],["78673.23000000","0.00014000"]],"asks":[["78676.12000000","0.00827000"],["78676.13000000","0.00076000"],["78676.14000000","0.00013000"],["78676.62000000","0.00007000"],["78677.10000000","0.00007000"],["78677.13000000","0.00007000"],["78677.51000000","0.00007000"],["78677.99000000","0.00014000"],["78678.00000000","0.02407000"],["78678.64000000","0.00007000"],["78678.69000000","0.00014000"],["78678.70000000","0.05205000"],["78678.98000000","0.00007000"],["78679.16000000","0.00027000"],["78679.55000000","0.00007000"],["78679.70000000","0.00014000"],["78679.71000000","0.22580000"],["78679.99000000","0.00014000"],["78680.00000000","0.02414000"],["78680.08000000","0.01358000"]]}}}
{"rx_ns": 173335942623500, "frame": {"stream":"btcusdt@depth@100ms","data":{"e":"depthUpdate","E":1787603275114,"s":"BTCUSDT","U":99076749659,"u":99076749861,"b":[["78676.11000000","6.52468000"],["78676.10000000","0.00020000"],["78676.09000000","0.00013000"],["78676.06000000","0.00014000"],["78676.05000000","0.05000000"],["78676.01000000","0.00014000"],["78676.00000000","0.74981000"],["78675.99000000","2.39884000"],["78675.98000000","0.00000000"],["78675.97000000","0.00000000"],["78675.96000000","0.00000000"],["78675.95000000","0.00014000"],["78675.91000000","0.00000000"],["78675.90000000","0.00007000"],["78674.74000000","0.00035000"],["78674.73000000","0.04109000"],["78674.44000000","0.00000000"],["78674.43000000","0.00007000"],["78674.42000000","0.00164000"],["78673.19000000","0.04978000"],["78671.91000000","0.00014000"],["78666.99000000","0.00000000"],["78666.00000000","1.22459000"],["78651.43000000","0.00000000"],["78626.97000000","0.00000000"],["77959.98000000","0.00000000"],["70808.40000000","0.00000000"]],"a":[["78676.00000000","0.00000000"],["78676.01000000","0.00000000"],["78676.11000000","0.00000000"],["78676.12000000","0.00827000"],["78676.13000000","0.00076000"],["78676.14000000","0.00013000"],["78678.70000000","0.05205000"],["78679.16000000","0.00027000"],["78679.26000000","0.00000000"],["78679.70000000","0.00014000"],["78679.71000000","0.22580000"],["78679.76000000","0.00000000"],["78679.83000000","0.00000000"],["78681.32000000","0.00007000"],["78683.65000000","0.02161000"],["78698.96000000","0.02000000"],["78701.30000000","0.02000000"],["78704.65000000","0.00000000"],["78707.47000000","0.34308000"],["78715.97000000","0.00000000"],["78734.76000000","0.00000000"],["78748.33000000","0.02000000"],["78748.96000000","0.02000000"],["78763.54000000","0.00000000"],["78773.55000000","0.00025000"]]}}}
{"rx_ns": 173336038856900, "frame": {"stream":"btcusdt@depth20@100ms","data":{"lastUpdateId":99076749915,"bids":[["78676.11000000","6.55299000"],["78676.10000000","0.00020000"],["78676.09000000","0.00013000"],["78676.06000000","0.00014000"],["78676.05000000","0.05007000"],["78676.01000000","0.00014000"],["78676.00000000","0.69988000"],["78675.99000000","2.16577000"],["78674.74000000","0.00035000"],["78674.73000000","0.04109000"],["78674.42000000","0.00157000"],["78674.27000000","0.00007000"],["78674.00000000","0.00507000"],["78673.99000000","0.03014000"],["78673.82000000","0.00400000"],["78673.47000000","0.04929000"],["78673.23000000","0.00014000"],["78673.19000000","0.04978000"],["78673.15000000","0.03007000"],["78672.99000000","0.00007000"]],"asks":[["78676.12000000","0.00854000"],["78676.13000000","0.00083000"],["78676.14000000","0.00013000"],["78676.62000000","0.00007000"],["78677.10000000","0.00007000"],["78677.13000000","0.00007000"],["78677.51000000","0.00007000"],["78677.99000000","0.00014000"],["78678.00000000","0.02407000"],["78678.01000000","0.00014000"],["78678.02000000","0.20852000"],["78678.64000000","0.00007000"],["78678.69000000","0.00014000"],["78678.70000000","0.05205000"],["78678.98000000","0.00007000"],["78679.16000000","0.00027000"],["78679.55000000","0.00007000"],["78679.69000000","0.00014000"],["78679.70000000","0.02175000"],["78679.71000000","0.22580000"]]}}}
{"rx_ns": 173336038941400, "frame": {"stream":"btcusdt@depth@100ms","data":{"e":"depthUpdate","E":1787603275214,"s":"BTCUSDT","U":99076749862,"u":99076749915,"b":[["78676.11000000","6.55299000"],["78676.05000000","0.05007000"],["78676.00000000","0.69988000"],["78675.99000000","2.16577000"],["78675.95000000","0.00000000"],["78675.90000000","0.00000000"],["78674.73000000","0.04109000"],["78674.43000000","0.00000000"],["78674.42000000","0.00157000"],["78674.00000000","0.00507000"],["78673.47000000","0.04929000"],["78672.00000000","0.01200000"],["78663.20000000","0.00015000"],["78659.79000000","0.00007000"],["78652.23000000","0.00000000"],["78536.54000000","0.00406000"],["70808.50000000","0.00032000"],["62940.80000000","0.00000000"]],"a":[["78676.12000000","0.00854000"],["78676.13000000","0.00083000"],["78678.01000000","0.00014000"],["78678.02000000","0.20852000"],["78679.69000000","0.00014000"],["78679.70000000","0.02175000"],["78679.99000000","0.00000000"],["78681.32000000","0.00000000"],["78683.39000000","0.00000000"],["78711.00000000","0.70000000"],["78717.25000000","0.63526000"],["78721.99000000","0.00000000"],["78725.99000000","0.00315000"],["78748.33000000","0.00000000"],["78795.99000000","0.00000000"],["78804.29000000","0.00127000"]]}}}
{"rx_ns": 173336137991900, "frame": {"stream":"btcusdt@depth20@100ms","data":{"lastUpdateId":99076749992,"bids":[["78676.11000000","6.55299000"],["78676.10000000","0.05020000"],["78676.09000000","0.00013000"],["78676.06000000","0.00014000"],["78676.05000000","0.05007000"],["78676.01000000","0.00014000"],["78676.00000000","0.69988000"],["78675.99000000","2.16577000"],["78675.34000000","0.03224000"],["78674.74000000","0.00035000"],["78674.73000000","0.04109000"],["78674.42000000","0.00157000"],["78674.27000000","0.00007000"],["78674.00000000","0.00507000"],["78673.99000000","0.03014000"],["78673.82000000","0.00400000"],["78673.47000000","0.04929000"],["78673.23000000","0.00014000"],["78673.19000000","0.04978000"],["78673.15000000","0.03007000"]],"asks":[["78676.12000000","0.00868000"],["78676.13000000","0.00090000"],["78676.14000000","0.00013000"],["78676.62000000","0.00007000"],["78677.10000000","0.00007000"],["78677.13000000","0.00007000"],["78677.51000000","0.00007000"],["78677.99000000","0.00014000"],["78678.00000000","0.02407000"],["78678.01000000","0.00014000"],["78678.02000000","0.20859000"],["78678.64000000","0.00007000"],["78678.69000000","0.00014000"],["78678.70000000","0.05205000"],["78678.98000000","0.00007000"],["78679.16000000","0.00027000"],["78679.55000000","0.00007000"],["78679.60000000","0.00854000"],["78679.69000000","0.00014000"],["78679.70000000","0.02182000"]]}}}
{"rx_ns": 173336138077500, "frame": {"stream":"btcusdt@depth@100ms","data":{"e":"depthUpdate","E":1787603275314,"s":"BTCUSDT","U":99076749916,"u":99076749992,"b":[["78676.10000000","0.05020000"],["78675.34000000","0.03224000"],["78672.47000000","0.00254000"],["78671.51000000","0.00000000"],["78670.00000000","0.01200000"],["78668.00000000","0.01207000"],["78666.00000000","1.23159000"],["78665.99000000","0.00000000"],["78664.00000000","0.01200000"],["78662.00000000","1.23852000"],["78660.00000000","0.09252000"],["78658.96000000","0.11607000"],["78658.00000000","0.01900000"],["78656.00000000","0.01900000"],["78654.00000000","0.01900000"],["78652.00000000","0.01907000"],["78650.00000000","0.11436000"],["78648.00000000","0.01900000"],["78282.72000000","0.01000000"],["77891.31000000","0.01000000"],["77501.85000000","0.01000000"],["77114.34000000","0.01000000"],["76728.77000000","0.01000000"],["76345.13000000","0.01000000"],["75963.40000000","0.01000000"],["75583.59000000","0.01000000"],["75205.67000000","0.01000000"],["74829.64000000","0.01172000"],["74455.49000000","0.01000000"],["74083.21000000","0.01000000"],["73712.80000000","0.01000000"],["73344.23000000","0.01000000"],["72977.51000000","0.01000000"],["70808.50000000","0.00048000"],["62933.00000000","0.00000000"]],"a":[["78676.12000000","0.00868000"],["78676.13000000","0.00090000"],["78678.00000000","0.02407000"],["78678.02000000","0.20859000"],["78678.70000000","0.05205000"],["78679.60000000","0.00854000"],["78679.70000000","0.02182000"],["78679.77000000","0.00000000"],["78682.00000000","0.02400000"],["78682.59000000","0.02703000"],["78685.33000000","0.00341000"],["78685.37000000","0.01705000"],["78687.24000000","0.00000000"],["78688.19000000","0.00254000"],["78708.12000000","0.00000000"],["78709.57000000","0.00000000"],["78752.44000000","0.02000000"],["78756.71000000","0.00000000"],["79069.51000000","0.01000000"],["79464.85000000","0.01000000"],["79862.18000000","0.01000000"],["80261.49000000","0.01000000"],["80662.80000000","0.01000000"],["81066.11000000","0.01000000"],["81471.44000000","0.01000000"],["81878.80000000","0.01000000"],["82288.19000000","0.01000000"],["82699.63000000","0.01000000"],["83113.13000000","0.01000000"],["83528.70000000","0.01000000"],["83946.34000000","0.01000000"],["84366.07000000","0.01000000"],["84787.90000000","0.01000000"]]}}}
{"rx_ns": 173336238476800, "frame": {"stream":"btcusdt@depth20@100ms","data":{"lastUpdateId":99076750047,"bids":[["78676.11000000","6.51992000"],["78676.10000000","0.05027000"],["78676.09000000","0.00013000"],["78676.06000000","0.00014000"],["78676.05000000","0.05007000"],["78676.01000000","0.00014000"],["78676.00000000","0.31800000"],["78675.99000000","2.16577000"],["78675.34000000","0.03224000"],["78675.06000000","0.00007000"],["78674.74000000","0.00035000"],["78674.73000000","0.04109000"],["78674.42000000","0.00157000"],["78674.27000000","0.00007000"],["78674.00000000","0.00507000"],["78673.99000000","0.03014000"],["78673.82000000","0.00400000"],["78673.47000000","0.04922000"],["78673.23000000","0.00014000"],["78673.19000000","0.04978000"]],"asks":[["78676.12000000","0.42071000"],["78676.13000000","0.00090000"],["78676.14000000","0.00013000"],["78677.10000000","0.00007000"],["78677.13000000","0.00007000"],["78677.51000000","0.00007000"],["78677.99000000","0.00014000"],["78678.00000000","0.02407000"],["78678.01000000","0.00014000"],["78678.02000000","0.20866000"],["78678.27000000","0.00014000"],["78678.28000000","0.21798000"],["78678.64000000","0.00007000"],["78678.69000000","0.00014000"],["78678.70000000","0.05205000"],["78678.98000000","0.00007000"],["78679.16000000","0.00027000"],["78679.55000000","0.00007000"],["78679.60000000","0.00007000"],["78679.69000000","0.00014000"]]}}}
{"rx_ns": 173336238565300, "frame": {"stream":"btcusdt@depth@100ms","data":{"e":"depthUpdate","E":1787603275414,"s":"BTCUSDT","U":99076749993,"u":99076750047,"b":[["78676.11000000","6.51992000"],["78676.10000000","0.05027000"],["78676.00000000","0.31800000"],["78675.99000000","2.16577000"],["78675.06000000","0.00007000"],["78673.47000000","0.04922000"],["78672.00000000","0.01700000"],["78670.00000000","0.01700000"],["78668.00000000","0.01707000"],["78666.00000000","1.23659000"],["78664.00000000","0.01700000"],["78662.00000000","1.24352000"],["78660.00000000","0.09752000"],["78658.00000000","0.02400000"],["78656.00000000","0.02400000"],["78654.82000000","0.51404000"],["78654.00000000","0.02400000"],["78652.00000000","0.02407000"],["78638.58000000","0.00000000"],["78570.23000000","0.02541000"],["70808.50000000","0.00064000"]],"a":[["78676.12000000","0.42071000"],["78676.13000000","0.00090000"],["78676.62000000","0.00000000"],["78678.02000000","0.20866000"],["78678.27000000","0.00014000"],["78678.28000000","0.21798000"],["78678.70000000","0.05205000"],["78679.60000000","0.00007000"],["78679.70000000","0.02168000"],["78679.71000000","0.00007000"],["78681.33000000","0.02252000"],["78743.59000000","0.00406000"],["78777.14000000","0.00529000"],["79063.99000000","0.00000000"]]}}}
{"rx_ns": 173336338163900, "frame": {"stream":"btcusdt@depth20@100ms","data":{"lastUpdateId":99076750093,"bids":[["78676.11000000","6.51999000"],["78676.10000000","0.05027000"],["78676.09000000","0.00013000"],["78676.06000000","0.00014000"],["78676.05000000","0.05007000"],["78676.01000000","0.00014000"],["78676.00000000","0.31800000"],["78675.99000000","2.16577000"],["78675.34000000","0.03224000"],["78675.06000000","0.00007000"],["78674.74000000","0.00035000"],["78674.73000000","0.04109000"],["78674.42000000","0.00157000"],["78674.27000000","0.00007000"],["78674.00000000","0.00507000"],["78673.99000000","0.03014000"],["78673.82000000","0.00400000"],["78673.47000000","0.04922000"],["78673.23000000","0.00014000"],["78673.19000000","0.04978000"]],"asks":[["78676.12000000","0.44407000"],["78676.13000000","0.00090000"],["78676.14000000","0.00013000"],["78677.10000000","0.00007000"],["78677.13000000","0.00007000"],["78677.21000000","0.19392000"],["78677.51000000","0.00007000"],["78677.99000000","0.00014000"],["78678.00000000","0.02407000"],["78678.01000000","0.00014000"],["78678.02000000","0.20866000"],["78678.27000000","0.00014000"],["78678.28000000","0.00007000"],["78678.64000000","0.00007000"],["78678.69000000","0.00014000"],["78678.70000000","0.05198000"],["78679.16000000","0.00027000"],["78679.55000000","0.00007000"],["78679.69000000","0.00014000"],["78679.70000000","0.02168000"]]}}}
{"rx_ns": 173336338254000, "frame": {"stream":"btcusdt@depth@100ms","data":{"e":"depthUpdate","E":1787603275514,"s":"BTCUSDT","U":99076750048,"u":99076750093,"b":[["78676.11000000","6.51999000"],["78650.00000000","0.11936000"],["78648.00000000","0.02400000"],["78646.00000000","0.02400000"],["70808.50000000","0.00080000"],["70801.19000000","0.00000000"],["62940.89000000","0.00031000"]],"a":[["78676.12000000","0.44407000"],["78677.21000000","0.19392000"],["78678.02000000","0.20866000"],["78678.28000000","0.00007000"],["78678.70000000","0.05198000"],["78678.98000000","0.00000000"],["78679.60000000","0.00000000"],["78679.70000000","0.02168000"],["78679.71000000","0.00000000"],["78681.33000000","0.02259000"],["78705.62000000","0.00879000"]]}}}
{"rx_ns": 173336437928800, "frame": {"stream":"btcusdt@depth20@100ms","data":{"lastUpdateId":99076750120,"bids":[["78676.11000000","6.51999000"],["78676.10000000","0.05027000"],["78676.09000000","0.00013000"],["78676.06000000","0.00014000"],["78676.05000000","0.05007000"],["78676.01000000","0.00014000"],["78676.00000000","0.31800000"],["78675.99000000","2.16577000"],["78675.34000000","0.03224000"],["78675.06000000","0.00007000"],["78674.74000000","0.00035000"],["78674.73000000","0.04109000"],["78674.42000000","0.00157000"],["78674.27000000","0.00007000"],["78674.00000000","0.00507000"],["78673.99000000","0.03014000"],["78673.82000000","0.00400000"],["78673.47000000","0.04922000"],["78673.23000000","0.00014000"],["78673.19000000","0.04978000"]],"asks":[["78676.12000000","0.44435000"],["78676.13000000","0.00090000"],["78676.14000000","0.00013000"],["78677.10000000","0.00007000"],["78677.13000000","0.00007000"],["78677.20000000","0.00014000"],["78677.21000000","0.19399000"],["78677.51000000","0.00007000"],["78677.99000000","0.00014000"],["78678.00000000","0.02407000"],["78678.01000000","0.00014000"],["78678.02000000","0.20852000"],["78678.64000000","0.00007000"],["78678.69000000","0.00014000"],["78678.70000000","0.05198000"],["78679.16000000","0.00027000"],["78679.55000000","0.00007000"],["78679.69000000","0.00014000"],["78679.70000000","0.02168000"],["78680.00000000","0.02414000"]]}}}
{"rx_ns": 173336438053000, "frame": {"stream":"btcusdt@depth@100ms","data":{"e":"depthUpdate","E":1787603275614,"s":"BTCUSDT","U":99076750094,"u":99076750120,"b":[["78657.72000000","0.00000000"],["78623.13000000","0.00000000"],["78603.44000000","0.00000000"],["78465.75000000","0.00406000"],["70808.50000000","0.00112000"],["62940.89000000","0.00000000"]],"a":[["78676.12000000","0.44435000"],["78676.13000000","0.00090000"],["78677.20000000","0.00014000"],["78677.21000000","0.19399000"],["78678.02000000","0.20852000"],["78678.27000000","0.00000000"],["78678.28000000","0.00000000"],["78681.19000000","0.12717000"],["78688.30000000","0.31777000"],["78689.74000000","0.00000000"],["78698.96000000","0.00000000"],["78704.67000000","0.09432000"],["78715.99000000","0.02844000"],["78728.63000000","0.00000000"],["78734.78000000","0.02358000"]]}}}
{"rx_ns": 173336538514200, "frame": {"stream":"btcusdt@depth20@100ms","data":{"lastUpdateId":99076750138,"bids":[["78676.11000000","6.51999000"],["78676.10000000","0.05027000"],["78676.09000000","0.00013000"],["78676.06000000","0.00014000"],["78676.05000000","0.05007000"],["78676.01000000","0.00014000"],["78676.00000000","0.31800000"],["78675.99000000","2.16577000"],["78675.34000000","0.03224000"],["78675.06000000","0.00007000"],["78674.74000000","0.00035000"],["78674.73000000","0.04109000"],["78674.42000000","0.00157000"],["78674.27000000","0.00007000"],["78674.00000000","0.00507000"],["78673.99000000","0.03014000"],["78673.82000000","0.00400000"],["78673.47000000","0.04922000"],["78673.23000000","0.00014000"],["78673.19000000","0.04978000"]],"asks":[["78676.12000000","0.44435000"],["78676.13000000","0.00090000"],["78676.14000000","0.00013000"],["78677.10000000","0.00014000"],["78677.13000000","0.00007000"],["78677.20000000","0.00014000"],["78677.21000000","0.19399000"],["78677.51000000","0.00007000"],["78677.99000000","0.00014000"],["78678.00000000","0.02407000"],["78678.01000000","0.00014000"],["78678.02000000","0.20859000"],["78678.64000000","0.00007000"],["78678.69000000","0.00014000"],["78678.70000000","0.05198000"],["78679.16000000","0.00027000"],["78679.55000000","0.00007000"],["78679.69000000","0.00014000"],["78679.70000000","0.02168000"],["78680.00000000","0.02414000"]]}}}
{"rx_ns": 173336538607500, "frame": {"stream":"btcusdt@depth@100ms","data":{"e":"depthUpdate","E":1787603275714,"s":"BTCUSDT","U":99076750121,"u":99076750138,"b":[["78672.47000000","0.00000000"],["78671.09000000","0.00254000"],["78655.02000000","0.00007000"],["78494.87000000","0.00960000"],["78490.62000000","0.00000000"]],"a":[["78676.12000000","0.44435000"],["78677.10000000","0.00014000"],["78678.02000000","0.20859000"],["78678.70000000","0.05198000"],["78680.08000000","0.01358000"],["78681.19000000","0.00000000"],["78681.33000000","0.02252000"],["78686.82000000","0.00254000"],["78688.19000000","0.00000000"],["78715.80000000","0.00007000"]]}}}
{"rx_ns": 173336637921400, "frame": {"stream":"btcusdt@depth20@100ms","data":{"lastUpdateId":99076750178,"bids":[["78676.11000000","6.28688000"],["78676.10000000","0.05027000"],["78676.09000000","0.00013000"],["78676.06000000","0.00014000"],["78676.05000000","0.05007000"],["78676.01000000","0.00014000"],["78676.00000000","0.31800000"],["78675.99000000","2.16577000"],["78675.34000000","0.03224000"],["78675.06000000","0.00007000"],["78674.74000000","0.00035000"],["78674.73000000","0.04109000"],["78674.42000000","0.00157000"],["78674.27000000","0.00007000"],["78674.00000000","0.00507000"],["78673.99000000","0.03014000"],["78673.82000000","0.00400000"],["78673.47000000","0.04922000"],["78673.23000000","0.00014000"],["78673.19000000","0.04978000"]],"asks":[["78676.12000000","0.44435000"],["78676.13000000","0.00090000"],["78676.14000000","0.00013000"],["78677.10000000","0.00014000"],["78677.13000000","0.00007000"],["78677.20000000","0.00014000"],["78677.21000000","0.19399000"],["78677.51000000","0.00007000"],["78677.99000000","0.00014000"],["78678.00000000","0.02407000"],["78678.01000000","0.00014000"],["78678.02000000","0.20859000"],["78678.64000000","0.00007000"],["78678.69000000","0.00014000"],["78678.70000000","0.05198000"],["78679.16000000","0.00027000"],["78679.55000000","0.00007000"],["78679.69000000","0.00014000"],["78679.70000000","0.02168000"],["78680.00000000","0.02414000"]]}}}
{"rx_ns": 173336638013000, "frame": {"stream":"btcusdt@depth@100ms","data":{"e":"depthUpdate","E":1787603275814,"s":"BTCUSDT","U":99076750139,"u":99076750178,"b":[["78676.11000000","6.28688000"],["78583.74000000","0.00406000"],["78566.55000000","0.02541000"],["78282.72000000","0.00000000"],["77891.31000000","0.00000000"],["77501.85000000","0.00000000"],["77114.34000000","0.00000000"],["76728.77000000","0.00000000"],["76345.13000000","0.00000000"],["75963.40000000","0.00000000"],["75583.59000000","0.00000000"],["75205.67000000","0.00000000"],["74829.64000000","0.00172000"],["74455.49000000","0.00000000"],["74083.21000000","0.00000000"],["73712.80000000","0.00000000"],["73344.23000000","0.00000000"],["72977.51000000","0.00000000"],["70808.50000000","0.00144000"]],"a":[["78680.08000000","0.01358000"],["78683.39000000","0.00007000"],["79069.51000000","0.00000000"],["79464.85000000","0.00000000"],["79862.18000000","0.00000000"],["80261.49000000","0.00000000"],["80662.80000000","0.00000000"],["81066.11000000","0.00000000"],["81471.44000000","0.00000000"],["81878.80000000","0.00000000"],["82288.19000000","0.00000000"],["82699.63000000","0.00000000"],["83113.13000000","0.00000000"],["83528.70000000","0.00000000"],["83946.34000000","0.00000000"],["84366.07000000","0.00000000"],["84787.90000000","0.00000000"]]}}}
{"rx_ns": 173336738250700, "frame": {"stream":"btcusdt@depth20@100ms","data":{"lastUpdateId":99076750200,"bids":[["78676.11000000","6.28695000"],["78676.10000000","0.05027000"],["78676.09000000","0.00013000"],["78676.06000000","0.00014000"],["78676.05000000","0.05007000"],["78676.01000000","0.00014000"],["78676.00000000","0.31800000"],["78675.99000000","2.16577000"],["78675.34000000","0.03224000"],["78675.06000000","0.00007000"],["78674.74000000","0.00035000"],["78674.73000000","0.04109000"],["78674.42000000","0.00157000"],["78674.27000000","0.00007000"],["78674.00000000","0.00507000"],["78673.99000000","0.00014000"],["78673.82000000","0.00400000"],["78673.47000000","0.04922000"],["78673.23000000","0.00014000"],["78673.19000000","0.04978000"]],"asks":[["78676.12000000","0.92619000"],["78676.13000000","0.00097000"],["78676.14000000","0.00013000"],["78677.10000000","0.00014000"],["78677.13000000","0.00007000"],["78677.21000000","0.00007000"],["78677.51000000","0.00007000"],["78677.99000000","0.00014000"],["78678.00000000","0.02407000"],["78678.01000000","0.00014000"],["78678.02000000","0.20859000"],["78678.64000000","0.00007000"],["78678.69000000","0.00014000"],["78678.70000000","0.05205000"],["78679.16000000","0.00027000"],["78679.55000000","0.00007000"],["78679.61000000","0.00007000"],["78679.62000000","0.12717000"],["78679.70000000","0.02168000"],["78680.00000000","0.02414000"]]}}}
{"rx_ns": 173336738383800, "frame": {"stream":"btcusdt@depth@100ms","data":{"e":"depthUpdate","E":1787603275914,"s":"BTCUSDT","U":99076750179,"u":99076750200,"b":[["78676.11000000","6.28695000"],["78673.99000000","0.00014000"],["78652.47000000","0.00007000"],["78652.35000000","0.00000000"],["78644.17000000","0.02800000"],["70808.50000000","0.00144000"]],"a":[["78676.12000000","0.92619000"],["78676.13000000","0.00097000"],["78677.20000000","0.00000000"],["78677.21000000","0.00007000"],["78678.70000000","0.05205000"],["78679.61000000","0.00007000"],["78679.62000000","0.12717000"],["78679.69000000","0.00000000"],["78699.56000000","0.00000000"],["78699.68000000","0.00007000"]]}}}
{"rx_ns": 173336837718200, "frame": {"stream":"btcusdt@depth20@100ms","data":{"lastUpdateId":99076750236,"bids":[["78676.11000000","6.54306000"],["78676.10000000","0.05027000"],["78676.09000000","0.00013000"],["78676.06000000","0.00014000"],["78676.05000000","0.05007000"],["78676.01000000","0.00014000"],["78676.00000000","0.31800000"],["78675.99000000","2.16577000"],["78675.34000000","0.03231000"],["78675.06000000","0.00007000"],["78674.74000000","0.00035000"],["78674.73000000","0.04109000"],["78674.42000000","0.00157000"],["78674.27000000","0.00007000"],["78674.00000000","0.00500000"],["78673.99000000","0.00007000"],["78673.82000000","0.00400000"],["78673.47000000","0.04922000"],["78673.23000000","0.00014000"],["78673.19000000","0.04978000"]],"asks":[["78676.12000000","0.92605000"],["78676.13000000","0.00090000"],["78676.14000000","0.00013000"],["78677.10000000","0.00014000"],["78677.13000000","0.00007000"],["78677.51000000","0.00007000"],["78677.99000000","0.00014000"],["78678.00000000","0.02407000"],["78678.01000000","0.00014000"],["78678.02000000","0.20859000"],["78678.19000000","0.00007000"],["78678.64000000","0.00007000"],["78678.69000000","0.00014000"],["78678.70000000","0.05205000"],["78679.16000000","0.00027000"],["78679.55000000","0.00007000"],["78679.62000000","0.00007000"],["78679.69000000","0.00014000"],["78679.70000000","0.02168000"],["78679.99000000","0.00007000"]]}}}
{"rx_ns": 173336837796700, "frame": {"stream":"btcusdt@depth@100ms","data":{"e":"depthUpdate","E":1787603276014,"s":"BTCUSDT","U":99076750201,"u":99076750236,"b":[["78676.11000000","6.54306000"],["78675.34000000","0.03231000"],["78674.00000000","0.00500000"],["78673.99000000","0.00007000"],["78658.54000000","0.00000000"],["78657.71000000","0.63556000"],["78644.95000000","0.02600000"],["78644.19000000","0.02800000"],["78595.16000000","0.02117000"],["70808.50000000","0.00144000"],["62940.89000000","0.00031000"]],"a":[["78676.12000000","0.92605000"],["78676.13000000","0.00090000"],["78677.21000000","0.00000000"],["78678.19000000","0.00007000"],["78678.70000000","0.05205000"],["78679.61000000","0.00000000"],["78679.62000000","0.00007000"],["78679.69000000","0.00014000"],["78679.99000000","0.00007000"],["78681.33000000","0.02259000"],["78775.07000000","0.00406000"],["78844.24000000","0.00000000"]]}}}
{"rx_ns": 173336938416700, "frame": {"stream":"btcusdt@depth20@100ms","data":{"lastUpdateId":99076750264,"bids":[["78676.11000000","6.54313000"],["78676.10000000","0.05027000"],["78676.09000000","0.00013000"],["78676.06000000","0.00014000"],["78676.05000000","0.05007000"],["78676.01000000","0.00014000"],["78676.00000000","0.31800000"],["78675.99000000","2.16577000"],["78675.34000000","0.03231000"],["78675.06000000","0.00007000"],["78674.74000000","0.00035000"],["78674.73000000","0.04109000"],["78674.42000000","0.00157000"],["78674.27000000","0.00007000"],["78674.00000000","0.00500000"],["78673.99000000","0.00007000"],["78673.82000000","0.00400000"],["78673.47000000","0.04922000"],["78673.23000000","0.00014000"],["78673.19000000","0.04978000"]],"asks":[["78676.12000000","0.41404000"],["78676.13000000","0.00083000"],["78676.14000000","0.00013000"],["78677.10000000","0.00014000"],["78677.13000000","0.00007000"],["78677.51000000","0.00007000"],["78677.99000000","0.00014000"],["78678.00000000","0.02407000"],["78678.01000000","0.00014000"],["78678.02000000","0.20859000"],["78678.19000000","0.00007000"],["78678.64000000","0.00007000"],["78678.69000000","0.00014000"],["78678.70000000","0.05198000"],["78679.16000000","0.00027000"],["78679.55000000","0.00007000"],["78679.69000000","0.00014000"],["78679.70000000","0.02168000"],["78679.99000000","0.00007000"],["78680.00000000","0.02414000"]]}}}
{"rx_ns": 173336938497300, "frame": {"stream":"btcusdt@depth@100ms","data":{"e":"depthUpdate","E":1787603276114,"s":"BTCUSDT","U":99076750237,"u":99076750264,"b":[["78676.11000000","6.54313000"],["78663.99000000","0.02531000"],["78624.59000000","0.02200000"],["78595.16000000","0.00000000"],["77968.02000000","0.00010000"],["72358.00000000","0.01396000"],["70808.50000000","0.00160000"],["70808.00000000","0.00626000"]],"a":[["78676.12000000","0.41404000"],["78676.13000000","0.00083000"],["78678.70000000","0.05198000"],["78679.62000000","0.00000000"],["78682.00000000","0.02407000"],["78688.30000000","0.00000000"],["78689.74000000","0.31778000"],["78691.02000000","0.00324000"],["78698.86000000","0.02000000"],["78718.56000000","0.02000000"],["78738.26000000","0.02000000"],["78807.56000000","0.01991000"]]}}}
{"rx_ns": 173337038025700, "frame": {"stream":"btcusdt@depth20@100ms","data":{"lastUpdateId":99076750279,"bids":[["78676.11000000","6.54313000"],["78676.10000000","0.05027000"],["78676.09000000","0.00013000"],["78676.06000000","0.00014000"],["78676.05000000","0.05007000"],["78676.01000000","0.00014000"],["78676.00000000","0.31800000"],["78675.99000000","2.16577000"],["78675.34000000","0.03231000"],["78675.06000000","0.00007000"],["78674.74000000","0.00035000"],["78674.73000000","0.04109000"],["78674.42000000","0.00157000"],["78674.27000000","0.00007000"],["78674.00000000","0.00500000"],["78673.99000000","0.00007000"],["78673.82000000","0.00400000"],["78673.47000000","0.04922000"],["78673.23000000","0.00014000"],["78673.19000000","0.04978000"]],"asks":[["78676.12000000","0.00879000"],["78676.13000000","0.00083000"],["78676.14000000","0.00013000"],["78677.10000000","0.00014000"],["78677.13000000","0.00007000"],["78677.51000000","0.00007000"],["78677.99000000","0.00014000"],["78678.00000000","0.02407000"],["78678.01000000","0.00014000"],["78678.02000000","0.20859000"],["78678.19000000","0.00007000"],["78678.64000000","0.00007000"],["78678.69000000","0.00014000"],["78678.70000000","0.05198000"],["78679.55000000","0.00007000"],["78679.69000000","0.00014000"],["78679.70000000","0.02168000"],["78679.99000000","0.00007000"],["78680.00000000","0.02414000"],["78680.08000000","0.01358000"]]}}}
{"rx_ns": 173337038119500, "frame": {"stream":"btcusdt@depth@100ms","data":{"e":"depthUpdate","E":1787603276214,"s":"BTCUSDT","U":99076750265,"u":99076750279,"b":[["78665.25000000","0.00007000"],["70808.50000000","0.00176000"],["70808.00000000","0.00606000"],["62940.89000000","0.00000000"]],"a":[["78676.12000000","0.00879000"],["78679.16000000","0.00000000"],["78704.23000000","0.00406000"]]}}}
{"rx_ns": 173337138409200, "frame": {"stream":"btcusdt@depth20@100ms","data":{"lastUpdateId":99076750291,"bids":[["78676.11000000","6.54313000"],["78676.10000000","0.05027000"],["78676.09000000","0.00013000"],["78676.06000000","0.00014000"],["78676.05000000","0.05007000"],["78676.01000000","0.00014000"],["78676.00000000","0.31800000"],["78675.99000000","2.16577000"],["78675.34000000","0.03231000"],["78675.06000000","0.00007000"],["78674.74000000","0.00035000"],["78674.73000000","0.04109000"],["78674.42000000","0.00157000"],["78674.27000000","0.00007000"],["78674.00000000","0.00500000"],["78673.99000000","0.00007000"],["78673.82000000","0.00400000"],["78673.47000000","0.04922000"],["78673.23000000","0.00014000"],["78673.19000000","0.04978000"]],"asks":[["78676.12000000","0.00879000"],["78676.13000000","0.00083000"],["78676.14000000","0.00013000"],["78677.10000000","0.00014000"],["78677.13000000","0.00007000"],["78677.51000000","0.00007000"],["78677.99000000","0.00014000"],["78678.00000000","0.02407000"],["78678.01000000","0.00014000"],["78678.02000000","0.20859000"],["78678.19000000","0.00007000"],["78678.64000000","0.00007000"],["78678.69000000","0.00014000"],["78678.70000000","0.05198000"],["78679.55000000","0.00007000"],["78679.69000000","0.00014000"],["78679.70000000","0.02168000"],["78679.99000000","0.00007000"],["78680.00000000","0.02414000"],["78680.08000000","0.01358000"]]}}}
{"rx_ns": 173337138483800, "frame": {"stream":"btcusdt@depth@100ms","data":{"e":"depthUpdate","E":1787603276314,"s":"BTCUSDT","U":99076750280,"u":99076750291,"b":[["78598.68000000","0.00000000"],["78592.42000000","0.00000000"],["70808.50000000","0.00176000"],["62939.00000000","0.00000000"]],"a":[["78678.21000000","0.00000000"],["78683.39000000","0.00000000"],["78689.29000000","0.00007000"],["78807.56000000","0.00000000"],["78817.38000000","0.01991000"]]}}}
{"rx_ns": 173337240474500, "frame": {"stream":"btcusdt@depth20@100ms","data":{"lastUpdateId":99076750335,"bids":[["78676.11000000","6.52852000"],["78676.10000000","0.05027000"],["78676.09000000","0.00013000"],["78676.06000000","0.00014000"],["78676.05000000","0.05007000"],["78676.01000000","0.00014000"],["78676.00000000","0.31800000"],["78675.99000000","2.16577000"],["78675.34000000","0.03231000"],["78675.06000000","0.00007000"],["78674.74000000","0.00035000"],["78674.73000000","0.04109000"],["78674.42000000","0.00157000"],["78674.27000000","0.00007000"],["78674.00000000","0.00500000"],["78673.99000000","0.00007000"],["78673.82000000","0.00400000"],["78673.47000000","0.04922000"],["78673.23000000","0.00014000"],["78673.19000000","0.04978000"]],"asks":[["78676.12000000","0.00886000"],["78676.13000000","0.00090000"],["78676.14000000","0.00013000"],["78677.10000000","0.00014000"],["78677.13000000","0.00007000"],["78677.51000000","0.00007000"],["78677.99000000","0.00014000"],["78678.00000000","0.02407000"],["78678.01000000","0.00014000"],["78678.02000000","0.20859000"],["78678.19000000","0.00007000"],["78678.64000000","0.00007000"],["78678.69000000","0.00014000"],["78678.70000000","0.05198000"],["78678.86000000","0.00879000"],["78679.55000000","0.00007000"],["78679.69000000","0.00014000"],["78679.70000000","0.02168000"],["78679.99000000","0.00007000"],["78680.00000000","0.02414000"]]}}}
{"rx_ns": 173337240558200, "frame": {"stream":"btcusdt@depth@100ms","data":{"e":"depthUpdate","E":1787603276414,"s":"BTCUSDT","U":99076750292,"u":99076750335,"b":[["78676.11000000","6.52852000"],["78615.20000000","0.00406000"],["78598.69000000","0.00000000"],["78282.72000000","0.01000000"],["77891.31000000","0.01000000"],["77501.85000000","0.01000000"],["77114.34000000","0.01000000"],["76728.77000000","0.01000000"],["76345.13000000","0.01000000"],["75963.40000000","0.01000000"],["75583.59000000","0.01000000"],["75205.67000000","0.01000000"],["74829.64000000","0.01172000"],["74455.49000000","0.01000000"],["74083.21000000","0.01000000"],["73712.80000000","0.01000000"],["73344.23000000","0.01000000"],["72977.51000000","0.01000000"],["70808.50000000","0.00192000"]],"a":[["78676.12000000","0.00886000"],["78676.13000000","0.00090000"],["78678.35000000","0.00000000"],["78678.42000000","0.00000000"],["78678.86000000","0.00879000"],["78817.38000000","0.00000000"],["78859.74000000","0.00000000"],["79069.51000000","0.01000000"],["79464.85000000","0.01000000"],["79862.18000000","0.01000000"],["80261.49000000","0.01000000"],["80662.80000000","0.01000000"],["81066.11000000","0.01000000"],["81471.44000000","0.01000000"],["81878.80000000","0.01000000"],["82288.19000000","0.01000000"],["82699.63000000","0.01000000"],["83113.13000000","0.01000000"],["83528.70000000","0.01000000"],["83946.34000000","0.01000000"],["84366.07000000","0.01000000"],["84787.90000000","0.01000000"]]}}}
{"rx_ns": 173337340124500, "frame": {"stream":"btcusdt@depth20@100ms","data":{"lastUpdateId":99076750358,"bids":[["78676.11000000","6.52852000"],["78676.10000000","0.05027000"],["78676.09000000","0.00013000"],["78676.06000000","0.00014000"],["78676.05000000","0.05007000"],["78676.01000000","0.00014000"],["78676.00000000","0.31800000"],["78675.99000000","2.16577000"],["78675.34000000","0.03231000"],["78675.06000000","0.00007000"],["78674.74000000","0.00035000"],["78674.73000000","0.04109000"],["78674.42000000","0.00157000"],["78674.27000000","0.00007000"],["78674.00000000","0.00500000"],["78673.99000000","0.00007000"],["78673.82000000","0.00400000"],["78673.47000000","0.04922000"],["78673.23000000","0.00014000"],["78673.19000000","0.04978000"]],"asks":[["78676.12000000","0.00879000"],["78676.13000000","0.00083000"],["78676.14000000","0.00013000"],["78677.10000000","0.00014000"],["78677.13000000","0.00007000"],["78677.51000000","0.00007000"],["78677.99000000","0.00014000"],["78678.00000000","0.02407000"],["78678.01000000","0.00014000"],["78678.02000000","0.20859000"],["78678.19000000","0.00007000"],["78678.64000000","0.00007000"],["78678.69000000","0.00014000"],["78678.70000000","0.05198000"],["78678.86000000","0.00007000"],["78679.55000000","0.00007000"],["78679.69000000","0.00014000"],["78679.70000000","0.02168000"],["78679.99000000","0.00007000"],["78680.00000000","0.02414000"]]}}}
{"rx_ns": 173337340215100, "frame": {"stream":"btcusdt@depth@100ms","data":{"e":"depthUpdate","E":1787603276514,"s":"BTCUSDT","U":99076750336,"u":99076750358,"b":[["78663.92000000","0.00000000"],["78654.82000000","0.00000000"],["78646.22000000","0.00000000"],["78644.19000000","0.00000000"],["78628.00000000","0.02600000"],["78623.04000000","0.00000000"],["78609.35000000","0.00200000"],["70808.50000000","0.00208000"],["62940.89000000","0.00031000"]],"a":[["78676.12000000","0.00879000"],["78676.13000000","0.00083000"],["78678.38000000","0.00000000"],["78678.70000000","0.05198000"],["78678.86000000","0.00007000"],["78682.00000000","0.02400000"],["78699.07000000","0.02000000"],["78728.74000000","0.02000000"],["78748.44000000","0.02000000"],["78870.80000000","0.01991000"]]}}}
{"rx_ns": 173337442818700, "frame": {"stream":"btcusdt@depth20@100ms","data":{"lastUpdateId":99076750376,"bids":[["78676.11000000","6.52852000"],["78676.10000000","0.05027000"],["78676.09000000","0.00013000"],["78676.06000000","0.00014000"],["78676.05000000","0.05007000"],["78676.01000000","0.00014000"],["78676.00000000","0.31800000"],["78675.99000000","2.16577000"],["78675.34000000","0.03231000"],["78675.06000000","0.00007000"],["78674.74000000","0.00035000"],["78674.73000000","0.04109000"],["78674.42000000","0.00157000"],["78674.27000000","0.00007000"],["78674.00000000","0.00500000"],["78673.99000000","0.00007000"],["78673.82000000","0.00400000"],["78673.47000000","0.04922000"],["78673.23000000","0.00014000"],["78673.19000000","0.04978000"]],"asks":[["78676.12000000","0.00879000"],["78676.13000000","0.00083000"],["78676.14000000","0.00013000"],["78677.10000000","0.00014000"],["78677.13000000","0.00007000"],["78677.51000000","0.00007000"],["78677.99000000","0.00014000"],["78678.00000000","0.02407000"],["78678.01000000","0.00014000"],["78678.02000000","0.20859000"],["78678.19000000","0.00007000"],["78678.64000000","0.00007000"],["78678.69000000","0.00014000"],["78678.70000000","0.05198000"],["78679.55000000","0.00007000"],["78679.69000000","0.00014000"],["78679.70000000","0.02168000"],["78679.99000000","0.00007000"],["78680.00000000","0.02414000"],["78680.08000000","0.01358000"]]}}}
{"rx_ns": 173337442989700, "frame": {"stream":"btcusdt@depth@100ms","data":{"e":"depthUpdate","E":1787603276614,"s":"BTCUSDT","U":99076750359,"u":99076750376,"b":[["78574.06000000","2.77326000"],["78568.84000000","0.00000000"],["72358.00000000","0.01382000"],["70808.50000000","0.00208000"],["62940.89000000","0.00000000"]],"a":[["78678.10000000","0.00000000"],["78678.35000000","0.00000000"],["78678.70000000","0.05198000"],["78678.86000000","0.00000000"],["78682.00000000","0.02407000"],["78710.00000000","0.81929000"],["78711.00000000","0.00000000"],["78769.79000000","0.00000000"],["78822.29000000","0.00406000"]]}}}
{"rx_ns": 173337539529200, "frame": {"stream":"btcusdt@depth20@100ms","data":{"lastUpdateId":99076750379,"bids":[["78676.11000000","6.52852000"],["78676.10000000","0.05027000"],["78676.09000000","0.00013000"],["78676.06000000","0.00014000"],["78676.05000000","0.05007000"],["78676.01000000","0.00014000"],["78676.00000000","0.31800000"],["78675.99000000","2.16577000"],["78675.34000000","0.03231000"],["78675.06000000","0.00007000"],["78674.74000000","0.00035000"],["78674.73000000","0.04109000"],["78674.42000000","0.00157000"],["78674.27000000","0.00007000"],["78674.00000000","0.00500000"],["78673.99000000","0.00007000"],["78673.82000000","0.00400000"],["78673.47000000","0.04922000"],["78673.23000000","0.00014000"],["78673.19000000","0.04978000"]],"asks":[["78676.12000000","0.00879000"],["78676.13000000","0.00083000"],["78676.14000000","0.00013000"],["78677.10000000","0.00014000"],["78677.13000000","0.00007000"],["78677.51000000","0.00007000"],["78677.99000000","0.00014000"],["78678.00000000","0.02407000"],["78678.01000000","0.00014000"],["78678.02000000","0.20859000"],["78678.19000000","0.00007000"],["78678.54000000","0.00879000"],["78678.64000000","0.00007000"],["78678.69000000","0.00014000"],["78678.70000000","0.05198000"],["78679.55000000","0.00007000"],["78679.69000000","0.00014000"],["78679.70000000","0.02168000"],["78679.99000000","0.00007000"],["78680.00000000","0.02414000"]]}}}
{"rx_ns": 173337539628600, "frame": {"stream":"btcusdt@depth@100ms","data":{"e":"depthUpdate","E":1787603276714,"s":"BTCUSDT","U":99076750377,"u":99076750379,"b":[["78648.88000000","0.00007000"],["70808.50000000","0.00224000"]],"a":[["78678.54000000","0.00879000"]]}}}
{"rx_ns": 173337639646000, "frame": {"stream":"btcusdt@depth20@100ms","data":{"lastUpdateId":99076750392,"bids":[["78676.11000000","6.52852000"],["78676.10000000","0.05027000"],["78676.09000000","0.00013000"],["78676.06000000","0.00014000"],["78676.05000000","0.05007000"],["78676.01000000","0.00014000"],["78676.00000000","0.31800000"],["78675.99000000","2.16577000"],["78675.34000000","0.03231000"],["78675.06000000","0.00007000"],["78674.74000000","0.00035000"],["78674.73000000","0.04109000"],["78674.42000000","0.00157000"],["78674.27000000","0.00007000"],["78674.00000000","0.00500000"],["78673.99000000","0.00007000"],["78673.82000000","0.00400000"],["78673.47000000","0.04922000"],["78673.23000000","0.00014000"],["78673.19000000","0.04978000"]],"asks":[["78676.12000000","0.00879000"],["78676.13000000","0.00083000"],["78676.14000000","0.00013000"],["78677.10000000","0.00014000"],["78677.13000000","0.00007000"],["78677.51000000","0.00007000"],["78677.99000000","0.00014000"],["78678.00000000","0.02407000"],["78678.01000000","0.00014000"],["78678.02000000","0.20859000"],["78678.19000000","0.00007000"],["78678.54000000","0.00007000"],["78678.64000000","0.00007000"],["78678.69000000","0.00014000"],["78678.70000000","0.05198000"],["78679.55000000","0.00007000"],["78679.69000000","0.00014000"],["78679.70000000","0.02168000"],["78679.99000000","0.00007000"],["78680.00000000","0.02414000"]]}}}
{"rx_ns": 173337639728000, "frame": {"stream":"btcusdt@depth@100ms","data":{"e":"depthUpdate","E":1787603276814,"s":"BTCUSDT","U":99076750380,"u":99076750392,"b":[["78654.53000000","0.00406000"],["78654.30000000","0.50961000"],["78630.61000000","1.00792000"],["78537.68000000","0.00000000"],["70808.50000000","0.00224000"]],"a":[["78678.02000000","0.20859000"],["78678.54000000","0.00007000"],["78682.00000000","0.02400000"],["78704.23000000","0.00000000"],["78775.07000000","0.00000000"]]}}}
{"rx_ns": 173337743929500, "frame": {"stream":"btcusdt@depth20@100ms","data":{"lastUpdateId":99076750433,"bids":[["78676.11000000","6.52852000"],["78676.10000000","0.05027000"],["78676.09000000","0.00013000"],["78676.06000000","0.00014000"],["78676.05000000","0.05007000"],["78676.01000000","0.00014000"],["78676.00000000","0.31800000"],["78675.99000000","2.16577000"],["78675.34000000","0.03231000"],["78675.06000000","0.00007000"],["78674.74000000","0.00035000"],["78674.73000000","0.04109000"],["78674.42000000","0.00157000"],["78674.27000000","0.00007000"],["78674.00000000","0.00500000"],["78673.99000000","0.00007000"],["78673.82000000","0.00400000"],["78673.47000000","0.04922000"],["78673.23000000","0.00014000"],["78673.19000000","0.04978000"]],"asks":[["78676.12000000","0.00879000"],["78676.13000000","0.00083000"],["78676.14000000","0.00013000"],["78677.10000000","0.00014000"],["78677.13000000","0.00007000"],["78677.51000000","0.00007000"],["78677.99000000","0.00014000"],["78678.00000000","0.02407000"],["78678.01000000","0.00014000"],["78678.02000000","0.20859000"],["78678.19000000","0.00007000"],["78678.64000000","0.00007000"],["78678.69000000","0.00014000"],["78678.70000000","0.05198000"],["78679.55000000","0.00007000"],["78679.69000000","0.00014000"],["78679.70000000","0.02168000"],["78679.99000000","0.00007000"],["78680.00000000","0.02414000"],["78680.08000000","0.01358000"]]}}}
{"rx_ns": 173337744016400, "frame": {"stream":"btcusdt@depth@100ms","data":{"e":"depthUpdate","E":1787603276914,"s":"BTCUSDT","U":99076750393,"u":99076750433,"b":[["78652.47000000","0.00000000"],["78282.72000000","0.00000000"],["77891.31000000","0.00000000"],["77501.85000000","0.00000000"],["77114.34000000","0.00000000"],["76728.77000000","0.00000000"],["76345.13000000","0.00000000"],["75963.40000000","0.00000000"],["75583.59000000","0.00000000"],["75205.67000000","0.00000000"],["74829.64000000","0.00172000"],["74455.49000000","0.00000000"],["74083.21000000","0.00000000"],["73712.80000000","0.00000000"],["73344.23000000","0.00000000"],["72977.51000000","0.00000000"],["70808.50000000","0.00240000"]],"a":[["78678.02000000","0.20859000"],["78678.26000000","0.00000000"],["78678.54000000","0.00000000"],["78682.00000000","0.02407000"],["78695.19000000","0.00007000"],["78699.68000000","0.00000000"],["79069.51000000","0.00000000"],["79464.85000000","0.00000000"],["79862.18000000","0.00000000"],["80261.49000000","0.00000000"],["80662.80000000","0.00000000"],["81066.11000000","0.00000000"],["81471.44000000","0.00000000"],["81878.80000000","0.00000000"],["82288.19000000","0.00000000"],["82699.63000000","0.00000000"],["83113.13000000","0.00000000"],["83528.70000000","0.00000000"],["83946.34000000","0.00000000"],["84366.07000000","0.00000000"],["84787.90000000","0.00000000"]]}}}
{"rx_ns": 173337841497500, "frame": {"stream":"btcusdt@depth20@100ms","data":{"lastUpdateId":99076750445,"bids":[["78676.11000000","6.52852000"],["78676.10000000","0.05027000"],["78676.09000000","0.00013000"],["78676.06000000","0.00014000"],["78676.05000000","0.05007000"],["78676.01000000","0.00014000"],["78676.00000000","0.31800000"],["78675.99000000","2.16577000"],["78675.34000000","0.03231000"],["78675.06000000","0.00007000"],["78674.74000000","0.00035000"],["78674.73000000","0.04109000"],["78674.42000000","0.00157000"],["78674.27000000","0.00007000"],["78674.00000000","0.00500000"],["78673.99000000","0.00007000"],["78673.82000000","0.00400000"],["78673.47000000","0.04922000"],["78673.23000000","0.00014000"],["78673.19000000","0.04978000"]],"asks":[["78676.12000000","0.00879000"],["78676.13000000","0.00083000"],["78676.14000000","0.00013000"],["78677.10000000","0.00014000"],["78677.13000000","0.00007000"],["78677.51000000","0.00007000"],["78677.99000000","0.00014000"],["78678.00000000","0.02407000"],["78678.01000000","0.00014000"],["78678.02000000","0.20859000"],["78678.19000000","0.00007000"],["78678.64000000","0.00007000"],["78678.69000000","0.00014000"],["78678.70000000","0.05198000"],["78679.55000000","0.00007000"],["78679.69000000","0.00014000"],["78679.70000000","0.02168000"],["78679.99000000","0.00007000"],["78680.00000000","0.02414000"],["78680.08000000","0.01358000"]]}}}
{"rx_ns": 173337841589900, "frame": {"stream":"btcusdt@depth@100ms","data":{"e":"depthUpdate","E":1787603277014,"s":"BTCUSDT","U":99076750434,"u":99076750445,"b":[["78663.85000000","0.02800000"],["78652.47000000","0.00007000"],["78624.45000000","0.02800000"],["62940.89000000","0.00031000"]],"a":[["78698.80000000","0.02227000"],["78699.68000000","0.00007000"],["78704.35000000","0.00406000"],["78709.38000000","1.21952000"],["78718.51000000","0.02000000"],["78738.21000000","0.02000000"]]}}}
{"rx_ns": 173337938223800, "frame": {"stream":"btcusdt@depth20@100ms","data":{"lastUpdateId":99076750468,"bids":[["78676.11000000","6.52852000"],["78676.10000000","0.05027000"],["78676.09000000","0.00013000"],["78676.06000000","0.00014000"],["78676.05000000","0.05007000"],["78676.01000000","0.00014000"],["78676.00000000","0.31800000"],["78675.99000000","2.16577000"],["78675.34000000","0.03231000"],["78675.06000000","0.00007000"],["78674.74000000","0.00035000"],["78674.73000000","0.04109000"],["78674.42000000","0.00157000"],["78674.27000000","0.00007000"],["78674.00000000","0.00500000"],["78673.99000000","0.00007000"],["78673.82000000","0.00400000"],["78673.47000000","0.04922000"],["78673.23000000","0.00014000"],["78673.19000000","0.04978000"]],"asks":[["78676.12000000","1.07557000"],["78676.13000000","0.00083000"],["78676.14000000","0.00013000"],["78677.10000000","0.00014000"],["78677.13000000","0.00007000"],["78677.51000000","0.00007000"],["78677.67000000","0.17956000"],["78677.99000000","0.00014000"],["78678.00000000","0.02407000"],["78678.01000000","0.00014000"],["78678.02000000","0.20859000"],["78678.19000000","0.00007000"],["78678.64000000","0.00007000"],["78678.69000000","0.00014000"],["78678.70000000","0.05198000"],["78679.55000000","0.00007000"],["78679.59000000","0.00027000"],["78679.69000000","0.00014000"],["78679.70000000","0.02168000"],["78679.99000000","0.00007000"]]}}}
{"rx_ns": 173337938315800, "frame": {"stream":"btcusdt@depth@100ms","data":{"e":"depthUpdate","E":1787603277114,"s":"BTCUSDT","U":99076750446,"u":99076750468,"b":[["78604.89000000","0.02200000"],["70808.50000000","0.00256000"],["62940.89000000","0.00031000"]],"a":[["78676.12000000","1.07557000"],["78677.67000000","0.17956000"],["78679.59000000","0.00027000"],["78687.99000000","0.31777000"],["78689.45000000","0.00321000"],["78689.74000000","0.00000000"],["78694.13000000","1.90515000"],["78773.55000000","0.00000000"],["78773.67000000","0.00025000"],["78776.75000000","0.00000000"]]}}}
{"rx_ns": 173338038046100, "frame": {"stream":"btcusdt@depth20@100ms","data":{"lastUpdateId":99076750608,"bids":[["78676.11000000","5.96655000"],["78676.10000000","0.05062000"],["78676.09000000","0.00013000"],["78676.06000000","0.00014000"],["78676.05000000","0.05007000"],["78676.01000000","0.00014000"],["78676.00000000","0.31800000"],["78675.99000000","0.05210000"],["78675.34000000","0.00007000"],["78674.74000000","0.00042000"],["78674.73000000","0.04109000"],["78674.42000000","0.00157000"],["78674.27000000","0.00007000"],["78674.00000000","0.00500000"],["78673.99000000","0.00007000"],["78673.82000000","0.00400000"],["78673.47000000","0.04922000"],["78673.23000000","0.00007000"],["78673.19000000","0.04978000"],["78673.15000000","0.00007000"]],"asks":[["78676.12000000","1.45456000"],["78676.13000000","0.00076000"],["78676.14000000","0.00013000"],["78677.10000000","0.00014000"],["78677.13000000","0.00007000"],["78677.51000000","0.00007000"],["78677.99000000","0.00014000"],["78678.00000000","0.02407000"],["78678.02000000","0.00007000"],["78678.64000000","0.00007000"],["78678.69000000","0.00014000"],["78678.70000000","0.05198000"],["78679.55000000","0.00007000"],["78679.59000000","0.00027000"],["78679.69000000","0.00014000"],["78679.70000000","0.02168000"],["78679.99000000","0.00014000"],["78680.00000000","0.02414000"],["78680.07000000","0.00007000"],["78680.08000000","0.01358000"]]}}}
{"rx_ns": 173338038132400, "frame": {"stream":"btcusdt@depth@100ms","data":{"e":"depthUpdate","E":1787603277214,"s":"BTCUSDT","U":99076750469,"u":99076750608,"b":[["78676.11000000","5.96655000"],["78676.10000000","0.05062000"],["78675.99000000","0.05210000"],["78675.34000000","0.00007000"],["78675.06000000","0.00000000"],["78674.74000000","0.00042000"],["78673.23000000","0.00007000"],["78673.15000000","0.00007000"],["78672.94000000","0.00000000"],["78672.31000000","0.00000000"],["78672.00000000","0.02400000"],["78671.91000000","0.00000000"],["78671.89000000","0.04667000"],["78671.09000000","0.00000000"],["78670.00000000","0.02400000"],["78669.36000000","0.00014000"],["78669.12000000","0.00000000"],["78668.74000000","0.00000000"],["78668.24000000","0.21930000"],["78668.20000000","0.00000000"],["78668.00000000","0.02407000"],["78667.32000000","0.00254000"],["78666.00000000","1.24359000"],["78665.93000000","0.02000000"],["78665.65000000","0.00191000"],["78664.00000000","0.02400000"],["78663.13000000","0.00400000"],["78662.24000000","0.00000000"],["78657.71000000","0.00000000"],["78656.94000000","0.00000000"],["78654.60000000","0.63555000"],["78639.42000000","0.34338000"],["78634.53000000","0.00007000"],["78621.01000000","0.00000000"],["78613.93000000","1.25947000"],["78574.06000000","0.00000000"],["70808.50000000","0.00256000"],["70808.00000000","0.00606000"],["62940.89000000","0.00000000"]],"a":[["78676.12000000","1.45456000"],["78676.13000000","0.00076000"],["78677.66000000","0.00000000"],["78677.67000000","0.00000000"],["78678.01000000","0.00000000"],["78678.02000000","0.00007000"],["78678.19000000","0.00000000"],["78679.99000000","0.00014000"],["78680.07000000","0.00007000"],["78680.77000000","0.00000000"],["78682.00000000","0.02400000"],["78683.04000000","0.00254000"],["78683.84000000","0.00254000"],["78683.93000000","0.00000000"],["78684.83000000","0.00254000"],["78685.04000000","0.31777000"],["78685.08000000","0.02000000"],["78685.33000000","0.00000000"],["78685.37000000","0.00000000"],["78686.82000000","0.00000000"],["78687.99000000","0.00000000"],["78688.00000000","0.02580000"],["78688.42000000","0.00000000"],["78688.53000000","0.00000000"],["78694.12000000","0.36224000"],["78694.36000000","0.00000000"],["78698.07000000","0.34312000"],["78703.16000000","0.63537000"],["78704.35000000","0.00000000"],["78711.39000000","0.02446000"],["78714.03000000","0.00000000"],["78715.80000000","0.00000000"],["78718.35000000","0.00000000"],["78750.44000000","0.00000000"],["78774.85000000","0.00000000"],["78775.19000000","0.00406000"]]}}}
{"rx_ns": 173338137895500, "frame": {"stream":"btcusdt@depth20@100ms","data":{"lastUpdateId":99076750638,"bids":[["78676.11000000","4.06389000"],["78676.10000000","0.05062000"],["78676.09000000","0.00013000"],["78676.06000000","0.00014000"],["78676.05000000","0.05007000"],["78676.01000000","0.00014000"],["78676.00000000","0.31800000"],["78675.99000000","0.05210000"],["78674.74000000","0.00042000"],["78674.73000000","0.04109000"],["78674.42000000","0.00157000"],["78674.27000000","0.00007000"],["78674.00000000","0.00500000"],["78673.99000000","0.00007000"],["78673.82000000","0.00400000"],["78673.47000000","0.04922000"],["78673.23000000","0.00007000"],["78673.19000000","0.04978000"],["78673.15000000","0.00007000"],["78672.99000000","0.00007000"]],"asks":[["78676.12000000","1.45449000"],["78676.13000000","0.00076000"],["78676.14000000","0.00013000"],["78677.10000000","0.00014000"],["78677.13000000","0.00007000"],["78677.51000000","0.00007000"],["78677.99000000","0.00014000"],["78678.00000000","0.02407000"],["78678.64000000","0.00007000"],["78678.69000000","0.00014000"],["78678.70000000","0.05198000"],["78679.55000000","0.00007000"],["78679.59000000","0.00027000"],["78679.69000000","0.00014000"],["78679.70000000","0.02168000"],["78679.99000000","0.00014000"],["78680.00000000","0.02414000"],["78680.07000000","0.00007000"],["78680.08000000","0.01358000"],["78680.97000000","0.00014000"]]}}}
{"rx_ns": 173338137977800, "frame": {"stream":"btcusdt@depth@100ms","data":{"e":"depthUpdate","E":1787603277314,"s":"BTCUSDT","U":99076750609,"u":99076750638,"b":[["78676.11000000","4.06389000"],["78675.99000000","0.05210000"],["78675.34000000","0.00000000"],["78667.29000000","0.00007000"],["78665.65000000","0.00000000"],["78665.51000000","0.00188000"],["70808.50000000","0.00256000"],["62941.00000000","0.00000000"]],"a":[["78676.12000000","1.45449000"],["78678.00000000","0.02407000"],["78678.02000000","0.00000000"],["78679.27000000","0.00000000"],["78682.00000000","0.02407000"],["78682.59000000","0.02710000"],["78684.54000000","0.00341000"],["78684.58000000","0.01705000"],["78700.00000000","0.10478000"]]}}}
{"rx_ns": 173338244935600, "frame": {"stream":"btcusdt@depth20@100ms","data":{"lastUpdateId":99076750683,"bids":[["78676.11000000","4.06342000"],["78676.10000000","0.05062000"],["78676.09000000","0.00013000"],["78676.06000000","0.00014000"],["78676.05000000","0.05007000"],["78676.01000000","0.00014000"],["78676.00000000","0.31800000"],["78675.99000000","0.05210000"],["78674.74000000","0.00042000"],["78674.73000000","0.04109000"],["78674.42000000","0.00157000"],["78674.27000000","0.00007000"],["78674.00000000","0.00500000"],["78673.99000000","0.00007000"],["78673.82000000","0.00400000"],["78673.47000000","0.04922000"],["78673.23000000","0.00007000"],["78673.19000000","0.04978000"],["78673.15000000","0.00007000"],["78672.99000000","0.00007000"]],"asks":[["78676.12000000","1.45496000"],["78676.13000000","0.00076000"],["78676.14000000","0.00013000"],["78677.10000000","0.00014000"],["78677.13000000","0.00007000"],["78677.51000000","0.00007000"],["78677.99000000","0.00014000"],["78678.00000000","0.02407000"],["78678.64000000","0.00007000"],["78678.69000000","0.00014000"],["78678.70000000","0.05198000"],["78679.55000000","0.00007000"],["78679.59000000","0.00027000"],["78679.69000000","0.00014000"],["78679.70000000","0.02168000"],["78679.73000000","0.12718000"],["78679.99000000","0.00014000"],["78680.00000000","0.02414000"],["78680.07000000","0.00007000"],["78680.08000000","0.01358000"]]}}}
{"rx_ns": 173338245038000, "frame": {"stream":"btcusdt@depth@100ms","data":{"e":"depthUpdate","E":1787603277414,"s":"BTCUSDT","U":99076750639,"u":99076750683,"b":[["78676.11000000","4.06342000"],["78667.32000000","0.00000000"],["78666.05000000","0.00048000"],["78631.98000000","0.00000000"],["78627.60000000","0.09510000"],["78282.72000000","0.01000000"],["77891.31000000","0.01000000"],["77501.85000000","0.01000000"],["77114.34000000","0.01000000"],["76728.77000000","0.01000000"],["76345.13000000","0.01000000"],["75963.40000000","0.01000000"],["75583.59000000","0.01000000"],["75205.67000000","0.01000000"],["74829.64000000","0.01172000"],["74455.49000000","0.01000000"],["74083.21000000","0.01000000"],["73712.80000000","0.01000000"],["73344.23000000","0.01000000"],["72977.51000000","0.01000000"],["70808.50000000","0.00272000"]],"a":[["78676.12000000","1.45496000"],["78679.73000000","0.12718000"],["78683.04000000","0.00000000"],["78683.39000000","0.00007000"],["78691.21000000","0.00000000"],["78704.35000000","0.00406000"],["78704.67000000","0.00000000"],["78706.14000000","0.09347000"],["78775.19000000","0.00000000"],["79069.51000000","0.01000000"],["79464.85000000","0.01000000"],["79862.18000000","0.01000000"],["80261.49000000","0.01000000"],["80662.80000000","0.01000000"],["81066.11000000","0.01000000"],["81471.44000000","0.01000000"],["81878.80000000","0.01000000"],["82288.19000000","0.01000000"],["82699.63000000","0.01000000"],["83113.13000000","0.01000000"],["83528.70000000","0.01000000"],["83946.34000000","0.01000000"],["84366.07000000","0.01000000"],["84787.90000000","0.01000000"]]}}}
{"rx_ns": 173338343640600, "frame": {"stream":"btcusdt@depth20@100ms","data":{"lastUpdateId":99076750889,"bids":[["78676.11000000","6.62023000"],["78676.10000000","0.05027000"],["78676.09000000","0.00013000"],["78676.06000000","0.00014000"],["78676.05000000","0.05007000"],["78676.01000000","0.00014000"],["78676.00000000","0.32200000"],["78675.99000000","0.05210000"],["78675.19000000","0.00254000"],["78674.74000000","0.00042000"],["78674.73000000","0.04109000"],["78674.42000000","0.00007000"],["78674.27000000","0.00007000"],["78674.00000000","0.00500000"],["78673.99000000","0.00007000"],["78673.82000000","0.00400000"],["78673.47000000","0.04922000"],["78673.23000000","0.00014000"],["78673.19000000","0.04978000"],["78673.15000000","0.00007000"]],"asks":[["78676.12000000","0.00191000"],["78676.13000000","0.00069000"],["78676.14000000","0.00013000"],["78677.10000000","0.00007000"],["78677.13000000","0.00007000"],["78677.51000000","0.00007000"],["78677.99000000","0.00014000"],["78678.00000000","0.02407000"],["78678.64000000","0.00007000"],["78678.69000000","0.00014000"],["78678.70000000","0.05205000"],["78679.55000000","0.00007000"],["78679.70000000","0.00007000"],["78679.73000000","0.00007000"],["78679.99000000","0.00014000"],["78680.00000000","0.02414000"],["78680.07000000","0.00014000"],["78680.08000000","0.01358000"],["78680.97000000","0.00007000"],["78681.32000000","0.00007000"]]}}}
{"rx_ns": 173338343792400, "frame": {"stream":"btcusdt@depth@100ms","data":{"e":"depthUpdate","E":1787603277514,"s":"BTCUSDT","U":99076750684,"u":99076750889,"b":[["78676.11000000","6.62023000"],["78676.10000000","0.05027000"],["78676.00000000","0.32200000"],["78675.19000000","0.00254000"],["78674.42000000","0.00007000"],["78673.25000000","0.00000000"],["78673.23000000","0.00014000"],["78672.94000000","0.00000000"],["78668.19000000","0.00000000"],["78666.05000000","0.00000000"],["78665.93000000","0.00000000"],["78665.51000000","0.00000000"],["78663.91000000","0.00332000"],["78662.13000000","0.34328000"],["78644.17000000","0.00000000"],["78639.42000000","0.00000000"],["78635.70000000","0.00000000"],["78634.53000000","0.00000000"],["78623.06000000","0.00000000"],["78595.16000000","0.02117000"],["78494.87000000","0.00181000"],["78490.62000000","0.00779000"],["70808.50000000","0.00297000"],["62940.89000000","0.00031000"]],"a":[["78676.12000000","0.00191000"],["78676.13000000","0.00069000"],["78677.10000000","0.00007000"],["78678.70000000","0.05205000"],["78679.59000000","0.00000000"],["78679.69000000","0.00000000"],["78679.70000000","0.00007000"],["78679.72000000","0.00000000"],["78679.73000000","0.00007000"],["78680.07000000","0.00014000"],["78680.97000000","0.00007000"],["78681.32000000","0.00007000"],["78682.59000000","0.02703000"],["78683.65000000","0.00000000"],["78683.66000000","0.12716000"],["78683.84000000","0.00000000"],["78683.87000000","0.00000000"],["78683.91000000","0.00000000"],["78683.99000000","0.21930000"],["78684.54000000","0.00000000"],["78684.58000000","0.00000000"],["78684.83000000","0.00000000"],["78685.04000000","0.00000000"],["78685.05000000","0.00000000"],["78685.08000000","0.00000000"],["78687.99000000","0.00254000"],["78688.68000000","0.02000000"],["78688.98000000","0.00000000"],["78689.44000000","0.00254000"],["78690.20000000","0.00047000"],["78690.85000000","0.31779000"],["78690.90000000","0.02161000"],["78690.91000000","0.08254000"],["78691.08000000","0.00000000"],["78694.11000000","0.02161000"],["78694.12000000","0.00000000"],["78694.13000000","0.00000000"],["78694.14000000","0.00000000"],["78694.17000000","0.00000000"],["78698.07000000","0.00000000"],["78698.52000000","0.00163000"],["78699.07000000","0.00000000"],["78699.40000000","0.00400000"],["78700.00000000","0.03207000"],["78700.45000000","1.24113000"],["78700.46000000","0.00000000"],["78700.72000000","1.90515000"],["78700.73000000","0.00000000"],["78701.22000000","0.00000000"],["78703.11000000","0.00000000"],["78703.16000000","0.00000000"],["78704.42000000","0.00000000"],["78704.76000000","0.02161000"],["78705.93000000","0.00000000"],["78705.94000000","0.00000000"],["78707.46000000","1.90515000"],["78708.20000000","0.02168000"],["78709.37000000","1.21952000"],["78709.38000000","0.00000000"],["78710.59000000","0.00000000"],["78710.78000000","0.00000000"],["78711.19000000","0.00000000"],["78713.39000000","0.04504000"],["78713.87000000","0.02161000"],["78713.88000000","0.00000000"],["78714.64000000","1.58176000"],["78714.65000000","0.00000000"],["78715.80000000","0.00007000"],["78715.99000000","0.00000000"],["78716.44000000","0.02848000"],["78717.18000000","0.00000000"],["78719.67000000","0.00007000"],["78720.50000000","3.12467000"],["78720.51000000","0.00000000"],["78720.52000000","0.00000000"],["78720.53000000","0.00000000"],["78721.99000000","0.34302000"],["78724.87000000","1.21952000"],["78724.89000000","0.02161000"],["78726.42000000","0.00000000"],["78728.74000000","0.00000000"],["78730.46000000","3.14628000"],["78730.47000000","0.00000000"],["78733.20000000","0.00400000"],["78734.78000000","0.00000000"],["78735.24000000","0.02393000"],["78739.34000000","3.14628000"],["78739.35000000","0.00000000"],["78739.36000000","0.00000000"],["78743.67000000","0.02161000"],["78748.44000000","0.00000000"],["78748.74000000","1.25732000"],["78776.75000000","1.90515000"],["78777.14000000","0.00000000"],["78780.27000000","0.00000000"],["78786.72000000","0.00000000"],["78790.50000000","0.00000000"],["78796.69000000","0.00000000"],["78800.73000000","0.00000000"],["78806.66000000","0.00000000"],["78810.96000000","1.21952000"]]}}}
{"rx_ns": 173338440166100, "frame": {"stream":"btcusdt@depth20@100ms","data":{"lastUpdateId":99076751178,"bids":[["78677.99000000","4.91398000"],["78677.98000000","1.90535000"],["78677.97000000","0.00013000"],["78677.95000000","0.05000000"],["78677.90000000","0.05000000"],["78677.10000000","0.00014000"],["78676.14000000","0.00635000"],["78676.13000000","0.00014000"],["78676.12000000","1.41910000"],["78676.11000000","1.39637000"],["78676.10000000","0.00007000"],["78676.05000000","0.00007000"],["78676.00000000","0.00407000"],["78675.99000000","0.05217000"],["78675.20000000","0.00635000"],["78675.19000000","0.04978000"],["78674.74000000","0.00035000"],["78674.73000000","0.04109000"],["78674.42000000","0.00007000"],["78674.27000000","0.00261000"]],"asks":[["78678.00000000","0.48165000"],["78678.01000000","0.00070000"],["78678.64000000","0.00007000"],["78678.70000000","0.00007000"],["78679.55000000","0.00007000"],["78679.99000000","0.00014000"],["78680.00000000","0.02407000"],["78680.07000000","0.00014000"],["78680.08000000","0.01358000"],["78680.69000000","0.00014000"],["78680.70000000","0.05198000"],["78680.97000000","0.00014000"],["78681.32000000","0.00014000"],["78681.33000000","0.02259000"],["78681.46000000","0.00007000"],["78681.60000000","0.00007000"],["78681.74000000","0.00007000"],["78681.95000000","0.00007000"],["78681.96000000","0.20852000"],["78681.97000000","0.00007000"]]}}}
{"rx_ns": 173338440263900, "frame": {"stream":"btcusdt@depth@100ms","data":{"e":"depthUpdate","E":1787603277614,"s":"BTCUSDT","U":99076750890,"u":99076751178,"b":[["78677.99000000","4.91398000"],["78677.98000000","1.90535000"],["78677.97000000","0.00013000"],["78677.95000000","0.05000000"],["78677.90000000","0.05000000"],["78677.66000000","0.00000000"],["78677.50000000","0.00000000"],["78677.20000000","0.00000000"],["78677.12000000","0.00000000"],["78677.10000000","0.00014000"],["78677.09000000","0.00000000"],["78676.14000000","0.00635000"],["78676.13000000","0.00014000"],["78676.12000000","1.41910000"],["78676.11000000","1.39637000"],["78676.10000000","0.00007000"],["78676.09000000","0.00000000"],["78676.06000000","0.00000000"],["78676.05000000","0.00007000"],["78676.01000000","0.00000000"],["78676.00000000","0.00407000"],["78675.99000000","0.05217000"],["78675.20000000","0.00635000"],["78675.19000000","0.04978000"],["78674.74000000","0.00035000"],["78674.27000000","0.00261000"],["78674.00000000","0.00507000"],["78673.19000000","0.00000000"],["78673.00000000","0.00007000"],["78671.89000000","0.00570000"],["78669.91000000","0.00007000"],["78669.50000000","0.12711000"],["78668.17000000","0.00007000"],["78667.99000000","0.00321000"],["78666.96000000","0.08576000"],["78664.96000000","0.00000000"],["78660.46000000","0.00000000"],["78660.32000000","0.00000000"],["78653.29000000","0.00254000"],["78649.43000000","0.00000000"],["78639.20000000","0.00000000"],["78638.40000000","0.00000000"],["78616.15000000","0.00316000"],["78610.00000000","0.02468000"],["78606.12000000","0.00000000"],["78595.16000000","0.00000000"],["78594.75000000","0.00317000"],["78584.09000000","0.00000000"],["78504.90000000","1.20000000"],["78486.94000000","0.00000000"],["70808.50000000","0.00009000"],["62940.89000000","0.00000000"]],"a":[["78676.12000000","0.00000000"],["78676.13000000","0.00000000"],["78676.14000000","0.00000000"],["78677.10000000","0.00000000"],["78677.13000000","0.00000000"],["78677.51000000","0.00000000"],["78677.99000000","0.00000000"],["78678.00000000","0.48165000"],["78678.01000000","0.00070000"],["78678.69000000","0.00000000"],["78678.70000000","0.00007000"],["78679.70000000","0.00000000"],["78679.73000000","0.00000000"],["78680.00000000","0.02407000"],["78680.69000000","0.00014000"],["78680.70000000","0.05198000"],["78680.97000000","0.00014000"],["78681.32000000","0.00014000"],["78681.95000000","0.00007000"],["78681.96000000","0.20852000"],["78681.99000000","0.00007000"],["78682.53000000","0.00000000"],["78682.59000000","0.02710000"],["78683.66000000","0.12723000"],["78683.85000000","0.02710000"],["78683.97000000","0.00000000"],["78689.74000000","0.00137000"],["78690.00000000","0.02654000"],["78690.91000000","0.08000000"],["78691.08000000","0.00635000"],["78691.12000000","0.00000000"],["78691.98000000","0.00007000"],["78693.06000000","0.00000000"],["78693.12000000","0.04857000"],["78701.00000000","0.00007000"],["78714.63000000","1.90515000"],["78715.80000000","0.00014000"],["78716.00000000","0.02400000"],["78716.44000000","0.00000000"],["78718.00000000","0.03400000"],["78719.67000000","0.00000000"],["78735.24000000","0.00000000"],["78775.15000000","0.00000000"],["78776.75000000","0.00000000"],["78819.87000000","0.00000000"],["78828.81000000","0.00127000"],["78896.10000000","0.00007000"],["78900.03000000","0.00007000"],["79069.51000000","0.00000000"],["79464.85000000","0.00000000"],["79862.18000000","0.00000000"],["80261.49000000","0.00000000"],["80662.80000000","0.00000000"],["81066.11000000","0.00000000"],["81471.44000000","0.00000000"],["81878.80000000","0.00000000"],["82288.19000000","0.00000000"],["82699.63000000","0.00000000"],["83113.13000000","0.00000000"],["83528.70000000","0.00000000"],["83946.34000000","0.00000000"],["84366.07000000","0.00000000"],["84787.90000000","0.00000000"]]}}}
{"rx_ns": 173338538306300, "frame": {"stream":"btcusdt@depth20@100ms","data":{"lastUpdateId":99076751420,"bids":[["78677.99000000","1.81903000"],["78677.98000000","0.00048000"],["78677.97000000","0.00013000"],["78677.96000000","0.00014000"],["78677.95000000","0.05014000"],["78677.91000000","0.00014000"],["78677.90000000","0.05014000"],["78677.10000000","0.00007000"],["78676.14000000","0.00007000"],["78676.13000000","0.00014000"],["78676.12000000","0.31800000"],["78676.11000000","0.00171000"],["78676.00000000","0.00007000"],["78675.99000000","0.02749000"],["78675.19000000","0.04978000"],["78674.74000000","0.00035000"],["78674.42000000","0.00007000"],["78674.00000000","0.00500000"],["78673.99000000","0.00007000"],["78673.82000000","0.00400000"]],"asks":[["78678.00000000","1.96838000"],["78678.01000000","0.00021000"],["78678.64000000","0.00007000"],["78679.55000000","0.00007000"],["78679.99000000","0.00014000"],["78680.00000000","0.02407000"],["78680.08000000","0.00007000"],["78680.55000000","0.00007000"],["78680.69000000","0.00014000"],["78680.70000000","0.05212000"],["78680.87000000","0.00014000"],["78680.88000000","0.21027000"],["78680.96000000","0.00254000"],["78680.97000000","0.00014000"],["78681.33000000","0.00007000"],["78681.46000000","0.00007000"],["78681.60000000","0.00007000"],["78681.74000000","0.00007000"],["78681.96000000","0.00007000"],["78681.97000000","0.00007000"]]}}}
{"rx_ns": 173338538414000, "frame": {"stream":"btcusdt@depth@100ms","data":{"e":"depthUpdate","E":1787603277714,"s":"BTCUSDT","U":99076751179,"u":99076751420,"b":[["78677.99000000","1.81903000"],["78677.98000000","0.00048000"],["78677.96000000","0.00014000"],["78677.95000000","0.05014000"],["78677.91000000","0.00014000"],["78677.90000000","0.05014000"],["78677.10000000","0.00007000"],["78676.14000000","0.00007000"],["78676.12000000","0.31800000"],["78676.11000000","0.00171000"],["78676.10000000","0.00000000"],["78676.05000000","0.00000000"],["78676.00000000","0.00007000"],["78675.99000000","0.02749000"],["78675.20000000","0.00000000"],["78674.73000000","0.00000000"],["78674.27000000","0.00000000"],["78674.06000000","0.00000000"],["78674.00000000","0.00500000"],["78673.47000000","0.00000000"],["78673.23000000","0.00007000"],["78673.04000000","0.00000000"],["78672.73000000","0.00000000"],["78672.21000000","0.00000000"],["78671.91000000","0.00000000"],["78671.20000000","0.00000000"],["78670.77000000","0.00000000"],["78670.01000000","0.00635000"],["78669.34000000","0.00007000"],["78667.01000000","0.00635000"],["78666.03000000","0.02000000"],["78664.32000000","0.00000000"],["78662.13000000","0.00000000"],["78656.89000000","0.38145000"],["78656.65000000","0.00000000"],["78653.29000000","0.14131000"],["78639.84000000","0.34345000"],["78639.76000000","0.00000000"],["78639.36000000","0.09507000"],["78638.40000000","0.00007000"],["78638.00000000","0.03407000"],["78636.00000000","0.02400000"],["78634.53000000","0.00007000"],["78629.20000000","0.00400000"],["78627.60000000","0.00000000"],["78613.93000000","0.00000000"],["78609.34000000","1.27668000"],["78597.60000000","0.00000000"],["78585.46000000","3.81797000"],["78533.07000000","0.00000000"],["78454.26000000","0.00000000"],["78407.77000000","0.00000000"],["70810.20000000","0.00032000"]],"a":[["78678.00000000","1.96838000"],["78678.01000000","0.00021000"],["78678.70000000","0.00000000"],["78680.07000000","0.00000000"],["78680.08000000","0.00007000"],["78680.55000000","0.00007000"],["78680.70000000","0.05212000"],["78680.87000000","0.00014000"],["78680.88000000","0.21027000"],["78680.96000000","0.00254000"],["78681.32000000","0.00000000"],["78681.33000000","0.00007000"],["78681.95000000","0.00000000"],["78681.96000000","0.00007000"],["78681.99000000","0.00014000"],["78682.59000000","0.00007000"],["78683.64000000","0.00014000"],["78683.65000000","0.33938000"],["78683.66000000","0.12716000"],["78683.80000000","0.00400000"],["78683.85000000","0.00000000"],["78683.99000000","0.00000000"],["78686.94000000","0.02161000"],["78689.44000000","0.00000000"],["78690.00000000","0.02400000"],["78690.57000000","0.00163000"],["78690.84000000","1.90515000"],["78690.85000000","0.00000000"],["78694.67000000","1.21952000"],["78698.52000000","0.00000000"],["78700.71000000","0.36224000"],["78715.00000000","0.00400000"],["78716.70000000","0.00000000"],["78716.87000000","0.02738000"],["78717.40000000","0.00000000"],["78719.67000000","0.00000000"],["78723.79000000","0.00000000"],["78730.60000000","0.00000000"],["78733.20000000","0.00000000"],["78735.49000000","0.00000000"],["78735.66000000","0.02428000"],["78739.34000000","3.12467000"],["78743.67000000","0.00000000"],["78766.77000000","0.00000000"],["78766.78000000","0.00000000"],["78810.96000000","0.00000000"],["78832.05000000","0.00000000"],["78900.03000000","0.00000000"]]}}}
{"rx_ns": 173338639132100, "frame": {"stream":"btcusdt@depth20@100ms","data":{"lastUpdateId":99076751520,"bids":[["78677.99000000","2.07388000"],["78677.98000000","0.00048000"],["78677.97000000","0.00013000"],["78677.96000000","0.00014000"],["78677.95000000","0.05014000"],["78677.91000000","0.00014000"],["78677.90000000","0.05014000"],["78677.10000000","0.00007000"],["78676.74000000","0.00007000"],["78676.73000000","0.04102000"],["78676.13000000","0.00666000"],["78676.12000000","0.31786000"],["78676.11000000","0.00164000"],["78676.00000000","0.00014000"],["78675.99000000","0.02756000"],["78675.47000000","0.04922000"],["78675.19000000","0.04985000"],["78674.74000000","0.00035000"],["78674.42000000","0.00007000"],["78674.21000000","0.04922000"]],"asks":[["78678.00000000","2.14678000"],["78678.01000000","0.00028000"],["78678.64000000","0.00007000"],["78679.55000000","0.00007000"],["78679.99000000","0.00014000"],["78680.00000000","0.02407000"],["78680.55000000","0.00007000"],["78680.69000000","0.00014000"],["78680.70000000","0.05205000"],["78680.88000000","0.00014000"],["78680.96000000","0.00254000"],["78680.97000000","0.00014000"],["78681.46000000","0.00007000"],["78681.60000000","0.00007000"],["78681.74000000","0.00007000"],["78681.97000000","0.00007000"],["78681.99000000","0.00014000"],["78682.00000000","0.02407000"],["78682.07000000","0.00014000"],["78682.08000000","0.01351000"]]}}}
{"rx_ns": 173338639237800, "frame": {"stream":"btcusdt@depth@100ms","data":{"e":"depthUpdate","E":1787603277815,"s":"BTCUSDT","U":99076751421,"u":99076751520,"b":[["78677.99000000","2.07388000"],["78677.98000000","0.00048000"],["78677.90000000","0.05014000"],["78676.74000000","0.00007000"],["78676.73000000","0.04102000"],["78676.14000000","0.00000000"],["78676.13000000","0.00666000"],["78676.12000000","0.31786000"],["78676.11000000","0.00164000"],["78676.00000000","0.00014000"],["78675.99000000","0.02756000"],["78675.47000000","0.04922000"],["78675.20000000","0.00000000"],["78675.19000000","0.04985000"],["78674.21000000","0.04922000"],["78666.98000000","0.00048000"],["78666.49000000","0.00048000"],["78665.31000000","0.00191000"],["70810.20000000","0.00048000"]],"a":[["78678.00000000","2.14678000"],["78678.01000000","0.00028000"],["78680.00000000","0.02407000"],["78680.08000000","0.00000000"],["78680.70000000","0.05205000"],["78680.87000000","0.00000000"],["78680.88000000","0.00014000"],["78681.33000000","0.00000000"],["78681.96000000","0.00000000"],["78682.00000000","0.02407000"],["78682.07000000","0.00014000"],["78682.08000000","0.01351000"],["78682.59000000","0.00000000"],["78683.33000000","0.02252000"],["78683.64000000","0.00014000"],["78683.65000000","0.33945000"],["78683.66000000","0.12716000"],["78683.86000000","0.00000000"],["78684.00000000","0.02407000"],["78684.59000000","0.02702000"],["78685.85000000","0.02702000"],["78686.00000000","0.02407000"],["78690.20000000","0.00000000"],["78775.15000000","0.00406000"]]}}}
{"rx_ns": 173338740040800, "frame": {"stream":"btcusdt@depth20@100ms","data":{"lastUpdateId":99076751566,"bids":[["78677.99000000","2.07388000"],["78677.98000000","0.00048000"],["78677.97000000","0.00013000"],["78677.96000000","0.00014000"],["78677.95000000","0.05014000"],["78677.91000000","0.00014000"],["78677.90000000","0.05007000"],["78677.10000000","0.00007000"],["78676.74000000","0.00007000"],["78676.73000000","0.04102000"],["78676.13000000","0.00666000"],["78676.12000000","0.31786000"],["78676.11000000","0.00164000"],["78676.00000000","0.00014000"],["78675.99000000","0.02749000"],["78675.47000000","0.04922000"],["78675.19000000","0.04978000"],["78674.74000000","0.00035000"],["78674.42000000","0.00007000"],["78674.21000000","0.04922000"]],"asks":[["78678.00000000","2.07708000"],["78678.01000000","0.00028000"],["78678.64000000","0.00007000"],["78679.55000000","0.00007000"],["78679.99000000","0.00014000"],["78680.00000000","0.02407000"],["78680.55000000","0.00007000"],["78680.69000000","0.00014000"],["78680.70000000","0.05205000"],["78680.88000000","0.00007000"],["78680.96000000","0.00254000"],["78680.97000000","0.00014000"],["78681.46000000","0.00007000"],["78681.60000000","0.00007000"],["78681.74000000","0.00007000"],["78681.97000000","0.00007000"],["78681.99000000","0.00014000"],["78682.00000000","0.02407000"],["78682.07000000","0.00014000"],["78682.08000000","0.01351000"]]}}}
{"rx_ns": 173338740143400, "frame": {"stream":"btcusdt@depth@100ms","data":{"e":"depthUpdate","E":1787603277914,"s":"BTCUSDT","U":99076751521,"u":99076751566,"b":[["78677.90000000","0.05007000"],["78675.99000000","0.02749000"],["78675.19000000","0.04978000"],["78671.91000000","1.90515000"],["78666.04000000","0.00000000"],["78664.12000000","0.02800000"],["78663.13000000","0.00000000"],["78624.72000000","0.02800000"],["78603.83000000","0.86906000"],["78570.23000000","0.00000000"],["78282.72000000","0.00000000"],["77891.31000000","0.00000000"],["77501.85000000","0.00000000"],["77114.34000000","0.00000000"],["76728.77000000","0.00000000"],["76345.13000000","0.00000000"],["75963.40000000","0.00000000"],["75583.59000000","0.00000000"],["75205.67000000","0.00000000"],["74829.64000000","0.00172000"],["74455.49000000","0.00000000"],["74083.21000000","0.00000000"],["73712.80000000","0.00000000"],["73344.23000000","0.00000000"],["72977.51000000","0.00000000"],["70810.20000000","0.00080000"]],"a":[["78678.00000000","2.07708000"],["78680.70000000","0.05205000"],["78680.88000000","0.00007000"],["78682.00000000","0.02407000"],["78684.00000000","0.02407000"],["78686.00000000","0.02400000"],["78697.44000000","0.02000000"],["78700.00000000","0.10779000"],["78703.35000000","0.63537000"],["78717.14000000","0.02000000"],["78723.63000000","0.86773000"],["78736.84000000","0.02000000"],["78748.74000000","0.00000000"],["78775.15000000","0.00000000"],["78800.00000000","0.12697000"]]}}}
{"rx_ns": 173338838116200, "frame": {"stream":"btcusdt@depth20@100ms","data":{"lastUpdateId":99076751585,"bids":[["78677.99000000","2.07402000"],["78677.98000000","0.00055000"],["78677.97000000","0.00013000"],["78677.96000000","0.00014000"],["78677.95000000","0.05014000"],["78677.91000000","0.00014000"],["78677.90000000","0.05007000"],["78677.10000000","0.00007000"],["78676.74000000","0.00007000"],["78676.73000000","0.04102000"],["78676.13000000","0.00666000"],["78676.12000000","0.31786000"],["78676.11000000","0.00164000"],["78676.00000000","0.00014000"],["78675.99000000","0.02749000"],["78675.47000000","0.04922000"],["78675.19000000","0.04978000"],["78674.74000000","0.00035000"],["78674.42000000","0.00007000"],["78674.21000000","0.04922000"]],"asks":[["78678.00000000","2.07708000"],["78678.01000000","0.00028000"],["78678.64000000","0.00007000"],["78679.55000000","0.00007000"],["78679.99000000","0.00014000"],["78680.00000000","0.02407000"],["78680.55000000","0.00007000"],["78680.69000000","0.00014000"],["78680.70000000","0.05205000"],["78680.88000000","0.00007000"],["78680.96000000","0.00254000"],["78680.97000000","0.00014000"],["78681.46000000","0.00007000"],["78681.60000000","0.00007000"],["78681.74000000","0.00007000"],["78681.97000000","0.00007000"],["78681.99000000","0.00014000"],["78682.00000000","0.02407000"],["78682.06000000","0.00254000"],["78682.07000000","0.00014000"]]}}}
{"rx_ns": 173338838202300, "frame": {"stream":"btcusdt@depth@100ms","data":{"e":"depthUpdate","E":1787603278014,"s":"BTCUSDT","U":99076751567,"u":99076751585,"b":[["78677.99000000","2.07402000"],["78677.98000000","0.00055000"],["78671.59000000","0.00007000"],["78670.01000000","0.00000000"],["78668.90000000","0.00635000"],["78668.67000000","0.00635000"],["78668.00000000","0.02400000"],["78667.01000000","0.00000000"],["78666.02000000","0.00400000"],["78654.35000000","0.00007000"],["78652.47000000","0.00000000"],["78604.75000000","0.02800000"],["62942.40000000","0.00031000"]],"a":[["78682.06000000","0.00254000"],["78683.32000000","0.00635000"],["78683.39000000","0.00000000"],["78683.63000000","0.00137000"],["78683.65000000","0.02168000"],["78684.58000000","0.31779000"],["78687.99000000","0.00000000"],["78689.74000000","0.00000000"],["78691.08000000","0.00000000"],["78699.68000000","0.00000000"],["78701.56000000","0.00007000"],["78776.33000000","0.00406000"]]}}}
{"rx_ns": 173338938520300, "frame": {"stream":"btcusdt@depth20@100ms","data":{"lastUpdateId":99076751609,"bids":[["78677.99000000","2.07402000"],["78677.98000000","0.00055000"],["78677.97000000","0.00013000"],["78677.96000000","0.00014000"],["78677.95000000","0.05014000"],["78677.91000000","0.00014000"],["78677.90000000","0.05007000"],["78677.10000000","0.00007000"],["78676.74000000","0.00014000"],["78676.73000000","0.04102000"],["78676.13000000","0.00014000"],["78676.12000000","0.31786000"],["78676.11000000","0.00164000"],["78676.00000000","0.00014000"],["78675.99000000","0.02749000"],["78675.47000000","0.04922000"],["78675.19000000","0.04978000"],["78674.74000000","0.00035000"],["78674.42000000","0.00007000"],["78674.21000000","0.04922000"]],"asks":[["78678.00000000","2.07701000"],["78678.01000000","0.00021000"],["78678.64000000","0.00007000"],["78679.55000000","0.00007000"],["78679.99000000","0.00014000"],["78680.00000000","0.02407000"],["78680.55000000","0.00007000"],["78680.69000000","0.00014000"],["78680.70000000","0.05205000"],["78680.88000000","0.00007000"],["78680.97000000","0.00014000"],["78681.46000000","0.00007000"],["78681.60000000","0.00007000"],["78681.74000000","0.00007000"],["78681.97000000","0.00007000"],["78681.99000000","0.00014000"],["78682.00000000","0.02407000"],["78682.06000000","0.00254000"],["78682.07000000","0.00014000"],["78682.08000000","0.01351000"]]}}}
{"rx_ns": 173338938609400, "frame": {"stream":"btcusdt@depth@100ms","data":{"e":"depthUpdate","E":1787603278114,"s":"BTCUSDT","U":99076751586,"u":99076751609,"b":[["78676.74000000","0.00014000"],["78676.13000000","0.00014000"],["78671.89000000","0.00563000"],["78670.64000000","0.00000000"],["78668.89000000","0.00000000"],["77968.02000000","0.00000000"],["70810.20000000","0.00096000"],["62942.39000000","0.00000000"]],"a":[["78678.00000000","2.07701000"],["78678.01000000","0.00021000"],["78679.31000000","0.00000000"],["78680.13000000","0.00000000"],["78680.96000000","0.00000000"],["78682.51000000","0.00254000"],["78683.64000000","0.00007000"],["78683.66000000","0.12723000"],["78684.00000000","0.02400000"],["78776.33000000","0.00000000"]]}}}
{"rx_ns": 173339040990000, "frame": {"stream":"btcusdt@depth20@100ms","data":{"lastUpdateId":99076751624,"bids":[["78677.99000000","2.07370000"],["78677.98000000","0.00048000"],["78677.97000000","0.00013000"],["78677.96000000","0.00014000"],["78677.95000000","0.05014000"],["78677.91000000","0.00014000"],["78677.90000000","0.05007000"],["78677.10000000","0.00007000"],["78676.74000000","0.00014000"],["78676.73000000","0.04102000"],["78676.13000000","0.00014000"],["78676.12000000","0.31786000"],["78676.11000000","0.00164000"],["78676.00000000","0.00014000"],["78675.99000000","0.02749000"],["78675.47000000","0.04922000"],["78675.19000000","0.04978000"],["78674.74000000","0.00035000"],["78674.42000000","0.00007000"],["78674.27000000","0.00007000"]],"asks":[["78678.00000000","2.07701000"],["78678.01000000","0.00021000"],["78678.64000000","0.00007000"],["78679.55000000","0.00007000"],["78679.80000000","0.12718000"],["78679.99000000","0.00014000"],["78680.00000000","0.02407000"],["78680.55000000","0.00007000"],["78680.69000000","0.00014000"],["78680.70000000","0.05205000"],["78680.88000000","0.00007000"],["78680.97000000","0.00014000"],["78681.46000000","0.00007000"],["78681.60000000","0.00007000"],["78681.74000000","0.00007000"],["78681.97000000","0.00007000"],["78681.99000000","0.00014000"],["78682.00000000","0.02407000"],["78682.06000000","0.00254000"],["78682.07000000","0.00014000"]]}}}
{"rx_ns": 173339041073600, "frame": {"stream":"btcusdt@depth@100ms","data":{"e":"depthUpdate","E":1787603278214,"s":"BTCUSDT","U":99076751610,"u":99076751624,"b":[["78677.99000000","2.07370000"],["78677.98000000","0.00048000"],["78674.27000000","0.00007000"],["78673.23000000","0.00014000"],["70810.20000000","0.00128000"],["62942.40000000","0.00000000"]],"a":[["78679.80000000","0.12718000"],["78680.12000000","0.00000000"],["78715.15000000","0.68274000"],["78728.52000000","0.88740000"],["78776.40000000","0.00000000"]]}}}
{"rx_ns": 173339148594200, "frame": {"stream":"btcusdt@depth20@100ms","data":{"lastUpdateId":99076751651,"bids":[["78677.99000000","2.07370000"],["78677.98000000","0.00048000"],["78677.97000000","0.00013000"],["78677.96000000","0.00014000"],["78677.95000000","0.05021000"],["78677.92000000","0.00014000"],["78677.91000000","0.20866000"],["78677.90000000","0.05007000"],["78677.10000000","0.00007000"],["78676.74000000","0.00014000"],["78676.73000000","0.04102000"],["78676.63000000","0.00007000"],["78676.13000000","0.00014000"],["78676.12000000","0.31786000"],["78676.11000000","0.00157000"],["78675.99000000","0.02749000"],["78675.47000000","0.04922000"],["78675.19000000","0.04978000"],["78674.74000000","0.00035000"],["78674.42000000","0.00007000"]],"asks":[["78678.00000000","2.07701000"],["78678.01000000","0.00021000"],["78678.64000000","0.00007000"],["78679.55000000","0.00007000"],["78679.99000000","0.00014000"],["78680.00000000","0.02407000"],["78680.55000000","0.00007000"],["78680.69000000","0.00014000"],["78680.70000000","0.05205000"],["78680.88000000","0.00007000"],["78680.97000000","0.00014000"],["78681.46000000","0.00007000"],["78681.60000000","0.00007000"],["78681.74000000","0.00007000"],["78681.97000000","0.00007000"],["78681.99000000","0.00014000"],["78682.00000000","0.02407000"],["78682.06000000","0.00254000"],["78682.07000000","0.00014000"],["78682.08000000","0.01351000"]]}}}
{"rx_ns": 173339148761700, "frame": {"stream":"btcusdt@depth@100ms","data":{"e":"depthUpdate","E":1787603278314,"s":"BTCUSDT","U":99076751625,"u":99076751651,"b":[["78677.95000000","0.05021000"],["78677.92000000","0.00014000"],["78677.91000000","0.20866000"],["78676.63000000","0.00007000"],["78676.11000000","0.00157000"],["78676.00000000","0.00000000"],["78671.38000000","0.00007000"],["70810.00000000","0.01283000"],["62942.00000000","0.00000000"]],"a":[["78678.00000000","2.07701000"],["78678.01000000","0.00021000"],["78679.80000000","0.00000000"],["78679.99000000","0.00014000"],["78683.66000000","0.12716000"]]}}}
{"rx_ns": 173339238378300, "frame": {"stream":"btcusdt@depth20@100ms","data":{"lastUpdateId":99076751669,"bids":[["78677.99000000","2.07370000"],["78677.98000000","0.00048000"],["78677.97000000","0.00013000"],["78677.96000000","0.00014000"],["78677.95000000","0.05014000"],["78677.92000000","0.00014000"],["78677.91000000","0.20866000"],["78677.90000000","0.05007000"],["78677.10000000","0.00665000"],["78676.74000000","0.00014000"],["78676.73000000","0.04102000"],["78676.63000000","0.00007000"],["78676.13000000","0.00014000"],["78676.12000000","0.31786000"],["78676.11000000","0.00157000"],["78675.99000000","0.02749000"],["78675.47000000","0.04922000"],["78675.19000000","0.04978000"],["78674.74000000","0.00035000"],["78674.42000000","0.00007000"]],"asks":[["78678.00000000","2.07701000"],["78678.01000000","0.00021000"],["78678.64000000","0.00007000"],["78679.55000000","0.00007000"],["78679.99000000","0.00014000"],["78680.00000000","0.02407000"],["78680.55000000","0.00007000"],["78680.69000000","0.00014000"],["78680.70000000","0.05205000"],["78680.88000000","0.00007000"],["78680.97000000","0.00014000"],["78681.46000000","0.00007000"],["78681.60000000","0.00007000"],["78681.74000000","0.00007000"],["78681.97000000","0.00007000"],["78681.99000000","0.00014000"],["78682.00000000","0.02407000"],["78682.06000000","0.00254000"],["78682.07000000","0.00014000"],["78682.08000000","0.01351000"]]}}}
{"rx_ns": 173339238458600, "frame": {"stream":"btcusdt@depth@100ms","data":{"e":"depthUpdate","E":1787603278414,"s":"BTCUSDT","U":99076751652,"u":99076751669,"b":[["78677.99000000","2.07370000"],["78677.95000000","0.05014000"],["78677.10000000","0.00665000"],["78668.67000000","0.00000000"],["78668.25000000","0.00635000"],["78564.73000000","0.00400000"],["78537.68000000","0.00127000"],["78527.78000000","0.00000000"],["78516.13000000","0.00127000"],["78508.99000000","0.00000000"],["78506.11000000","0.00000000"],["70810.20000000","0.00144000"]],"a":[["78678.00000000","2.07701000"],["78725.99000000","0.00000000"],["78727.12000000","0.00317000"],["78745.99000000","0.00000000"],["78749.29000000","0.00317000"],["78772.51000000","0.00406000"],["78804.29000000","0.00000000"],["78809.43000000","0.00127000"]]}}}
{"rx_ns": 173339338107400, "frame": {"stream":"btcusdt@depth20@100ms","data":{"lastUpdateId":99076751706,"bids":[["78677.99000000","2.08546000"],["78677.98000000","0.00048000"],["78677.97000000","0.00013000"],["78677.96000000","0.00014000"],["78677.95000000","0.05014000"],["78677.92000000","0.00014000"],["78677.91000000","0.20866000"],["78677.90000000","0.05007000"],["78677.10000000","0.00665000"],["78676.74000000","0.00014000"],["78676.73000000","0.04102000"],["78676.63000000","0.00007000"],["78676.13000000","0.00014000"],["78676.12000000","0.31786000"],["78676.11000000","0.00157000"],["78675.99000000","0.02749000"],["78675.47000000","0.04922000"],["78675.19000000","0.04978000"],["78674.74000000","0.00035000"],["78674.42000000","0.00007000"]],"asks":[["78678.00000000","2.07701000"],["78678.01000000","0.00021000"],["78678.64000000","0.00007000"],["78679.55000000","0.00007000"],["78679.99000000","0.00014000"],["78680.00000000","0.02407000"],["78680.55000000","0.00007000"],["78680.69000000","0.00014000"],["78680.70000000","0.05205000"],["78680.88000000","0.00007000"],["78680.97000000","0.00014000"],["78681.46000000","0.00007000"],["78681.60000000","0.00007000"],["78681.74000000","0.00007000"],["78681.97000000","0.00007000"],["78681.99000000","0.00014000"],["78682.00000000","0.02407000"],["78682.06000000","0.00254000"],["78682.07000000","0.00014000"],["78682.08000000","0.01351000"]]}}}
{"rx_ns": 173339338189400, "frame": {"stream":"btcusdt@depth@100ms","data":{"e":"depthUpdate","E":1787603278514,"s":"BTCUSDT","U":99076751670,"u":99076751706,"b":[["78677.99000000","2.08546000"],["78664.69000000","0.00000000"],["78644.95000000","0.00000000"],["78623.84000000","0.00000000"],["78410.67000000","0.00000000"],["78284.60000000","0.01000000"],["77893.17000000","0.01000000"],["77503.71000000","0.01000000"],["77116.19000000","0.01000000"],["76730.61000000","0.01000000"],["76346.95000000","0.01000000"],["75965.22000000","0.01000000"],["75585.39000000","0.01000000"],["75207.47000000","0.01000000"],["74831.43000000","0.01000000"],["74457.27000000","0.01000000"],["74084.98000000","0.01000000"],["73714.56000000","0.01000000"],["73345.99000000","0.01000000"],["72979.26000000","0.01000000"],["70810.20000000","0.00144000"],["62942.40000000","0.00031000"]],"a":[["78698.28000000","0.00000000"],["78717.31000000","0.00425000"],["78737.01000000","0.00000000"],["79071.39000000","0.01000000"],["79466.75000000","0.01000000"],["79864.09000000","0.01000000"],["80263.41000000","0.01000000"],["80664.72000000","0.01010000"],["81068.05000000","0.01000000"],["81473.39000000","0.01000000"],["81880.75000000","0.01000000"],["82290.16000000","0.01000000"],["82701.61000000","0.01000000"],["83115.12000000","0.01000000"],["83530.69000000","0.01000000"],["83948.35000000","0.01000000"],["84368.09000000","0.01000000"],["84789.93000000","0.01000000"]]}}}
{"rx_ns": 173339442646400, "frame": {"stream":"btcusdt@depth20@100ms","data":{"lastUpdateId":99076751712,"bids":[["78677.99000000","2.08546000"],["78677.98000000","0.00048000"],["78677.97000000","0.00013000"],["78677.96000000","0.00014000"],["78677.95000000","0.05014000"],["78677.92000000","0.00014000"],["78677.91000000","0.20866000"],["78677.90000000","0.05007000"],["78677.10000000","0.00665000"],["78676.74000000","0.00014000"],["78676.73000000","0.04102000"],["78676.63000000","0.00007000"],["78676.13000000","0.00014000"],["78676.12000000","0.31786000"],["78676.11000000","0.00157000"],["78675.99000000","0.02749000"],["78675.47000000","0.04922000"],["78675.19000000","0.04978000"],["78674.74000000","0.00035000"],["78674.42000000","0.00007000"]],"asks":[["78678.00000000","2.07714000"],["78678.01000000","0.00034000"],["78678.02000000","0.00013000"],["78678.64000000","0.00007000"],["78679.55000000","0.00007000"],["78679.99000000","0.00014000"],["78680.00000000","0.02407000"],["78680.55000000","0.00007000"],["78680.69000000","0.00014000"],["78680.70000000","0.05205000"],["78680.88000000","0.00007000"],["78680.97000000","0.00014000"],["78681.46000000","0.00007000"],["78681.60000000","0.00007000"],["78681.74000000","0.00007000"],["78681.97000000","0.00007000"],["78681.99000000","0.00014000"],["78682.00000000","0.02407000"],["78682.06000000","0.00254000"],["78682.07000000","0.00014000"]]}}}
{"rx_ns": 173339442812700, "frame": {"stream":"btcusdt@depth@100ms","data":{"e":"depthUpdate","E":1787603278614,"s":"BTCUSDT","U":99076751707,"u":99076751712,"b":[["78671.59000000","0.00000000"],["70810.20000000","0.00160000"],["62942.40000000","0.00000000"]],"a":[["78678.00000000","2.07714000"],["78678.01000000","0.00034000"],["78678.02000000","0.00013000"]]}}}
{"rx_ns": 173339537944400, "frame": {"stream":"btcusdt@depth20@100ms","data":{"lastUpdateId":99076751722,"bids":[["78677.99000000","2.08560000"],["78677.98000000","0.00062000"],["78677.97000000","0.00013000"],["78677.96000000","0.00014000"],["78677.95000000","0.05014000"],["78677.92000000","0.00014000"],["78677.91000000","0.20866000"],["78677.90000000","0.05007000"],["78677.10000000","0.00665000"],["78676.74000000","0.00014000"],["78676.73000000","0.04102000"],["78676.63000000","0.00007000"],["78676.13000000","0.00014000"],["78676.12000000","0.31786000"],["78676.11000000","0.00157000"],["78675.99000000","0.02749000"],["78675.47000000","0.04922000"],["78675.19000000","0.04978000"],["78674.74000000","0.00035000"],["78674.42000000","0.00007000"]],"asks":[["78678.00000000","2.07714000"],["78678.01000000","0.00034000"],["78678.02000000","0.00013000"],["78678.64000000","0.00007000"],["78679.55000000","0.00007000"],["78679.99000000","0.00014000"],["78680.00000000","0.02407000"],["78680.55000000","0.00007000"],["78680.69000000","0.00014000"],["78680.70000000","0.05205000"],["78680.88000000","0.00007000"],["78680.97000000","0.00014000"],["78681.46000000","0.00007000"],["78681.60000000","0.00007000"],["78681.74000000","0.00007000"],["78681.97000000","0.00007000"],["78681.99000000","0.00014000"],["78682.00000000","0.02407000"],["78682.06000000","0.00254000"],["78682.07000000","0.00014000"]]}}}
{"rx_ns": 173339538029900, "frame": {"stream":"btcusdt@depth@100ms","data":{"e":"depthUpdate","E":1787603278714,"s":"BTCUSDT","U":99076751713,"u":99076751722,"b":[["78677.99000000","2.08560000"],["78677.98000000","0.00062000"],["78646.84000000","0.00007000"],["78625.53000000","1.03088000"],["78490.62000000","0.00000000"],["78486.67000000","0.00779000"],["78413.69000000","0.09948000"],["70810.20000000","0.00160000"]],"a":[]}}}
{"rx_ns": 173339638104600, "frame": {"stream":"btcusdt@depth20@100ms","data":{"lastUpdateId":99076751732,"bids":[["78677.99000000","2.08560000"],["78677.98000000","0.00062000"],["78677.97000000","0.00013000"],["78677.96000000","0.00014000"],["78677.95000000","0.05014000"],["78677.92000000","0.00014000"],["78677.91000000","0.20866000"],["78677.90000000","0.05007000"],["78677.10000000","0.00665000"],["78676.74000000","0.00014000"],["78676.73000000","0.04102000"],["78676.63000000","0.00007000"],["78676.13000000","0.00014000"],["78676.12000000","0.31786000"],["78676.11000000","0.00157000"],["78675.99000000","0.02749000"],["78675.84000000","0.00007000"],["78675.47000000","0.04922000"],["78675.19000000","0.04978000"],["78674.74000000","0.00035000"]],"asks":[["78678.00000000","2.07721000"],["78678.01000000","0.00034000"],["78678.02000000","0.00013000"],["78678.64000000","0.00007000"],["78679.55000000","0.00007000"],["78679.99000000","0.00014000"],["78680.00000000","0.02407000"],["78680.55000000","0.00007000"],["78680.69000000","0.00014000"],["78680.70000000","0.05205000"],["78680.88000000","0.00007000"],["78680.97000000","0.00014000"],["78681.46000000","0.00007000"],["78681.60000000","0.00007000"],["78681.74000000","0.00007000"],["78681.97000000","0.00007000"],["78681.99000000","0.00014000"],["78682.00000000","0.02407000"],["78682.06000000","0.00254000"],["78682.07000000","0.00014000"]]}}}
{"rx_ns": 173339638211800, "frame": {"stream":"btcusdt@depth@100ms","data":{"e":"depthUpdate","E":1787603278814,"s":"BTCUSDT","U":99076751723,"u":99076751732,"b":[["78675.84000000","0.00007000"],["78624.17000000","0.00664000"],["78566.23000000","2.77319000"],["70810.20000000","0.00176000"]],"a":[["78678.00000000","2.07721000"],["78679.64000000","0.00000000"],["78687.99000000","0.00158000"]]}}}
{"rx_ns": 173339738515200, "frame": {"stream":"btcusdt@depth20@100ms","data":{"lastUpdateId":99076751737,"bids":[["78677.99000000","2.08560000"],["78677.98000000","0.00062000"],["78677.97000000","0.00013000"],["78677.96000000","0.00014000"],["78677.95000000","0.05014000"],["78677.92000000","0.00014000"],["78677.91000000","0.20866000"],["78677.90000000","0.05007000"],["78677.10000000","0.00665000"],["78676.74000000","0.00014000"],["78676.73000000","0.04102000"],["78676.63000000","0.00007000"],["78676.13000000","0.00014000"],["78676.12000000","0.31786000"],["78676.11000000","0.00157000"],["78675.99000000","0.02749000"],["78675.84000000","0.00007000"],["78675.47000000","0.04922000"],["78675.19000000","0.04978000"],["78674.74000000","0.00035000"]],"asks":[["78678.00000000","2.07714000"],["78678.01000000","0.00034000"],["78678.02000000","0.00013000"],["78678.64000000","0.00007000"],["78679.55000000","0.00007000"],["78679.99000000","0.00014000"],["78680.00000000","0.02407000"],["78680.55000000","0.00007000"],["78680.69000000","0.00014000"],["78680.70000000","0.05205000"],["78680.88000000","0.00007000"],["78680.97000000","0.00014000"],["78681.46000000","0.00007000"],["78681.60000000","0.00007000"],["78681.74000000","0.00007000"],["78681.97000000","0.00007000"],["78681.99000000","0.00014000"],["78682.00000000","0.02407000"],["78682.06000000","0.00254000"],["78682.07000000","0.00014000"]]}}}
{"rx_ns": 173339738591700, "frame": {"stream":"btcusdt@depth@100ms","data":{"e":"depthUpdate","E":1787603278914,"s":"BTCUSDT","U":99076751733,"u":99076751737,"b":[["78605.02000000","0.02800000"],["70810.20000000","0.00160000"]],"a":[["78678.00000000","2.07714000"],["78698.33000000","0.34312000"],["78721.99000000","0.00000000"]]}}}
{"rx_ns": 173339838172900, "frame": {"stream":"btcusdt@depth20@100ms","data":{"lastUpdateId":99076751782,"bids":[["78677.99000000","2.08560000"],["78677.98000000","0.00062000"],["78677.97000000","0.00013000"],["78677.96000000","0.00014000"],["78677.95000000","0.05014000"],["78677.92000000","0.00014000"],["78677.91000000","0.20866000"],["78677.90000000","0.05007000"],["78677.10000000","0.00665000"],["78676.74000000","0.00014000"],["78676.73000000","0.04102000"],["78676.63000000","0.00007000"],["78676.13000000","0.00014000"],["78676.12000000","0.31786000"],["78676.11000000","0.00157000"],["78675.99000000","0.02749000"],["78675.84000000","0.00007000"],["78675.47000000","0.04922000"],["78675.19000000","0.04978000"],["78674.74000000","0.00035000"]],"asks":[["78678.00000000","2.48231000"],["78678.01000000","0.00034000"],["78678.02000000","0.00013000"],["78678.64000000","0.00007000"],["78679.55000000","0.00007000"],["78679.99000000","0.00014000"],["78680.00000000","0.02407000"],["78680.55000000","0.00007000"],["78680.69000000","0.00014000"],["78680.70000000","0.05205000"],["78680.88000000","0.00007000"],["78680.97000000","0.00014000"],["78681.46000000","0.00007000"],["78681.60000000","0.00007000"],["78681.74000000","0.00007000"],["78681.97000000","0.00007000"],["78681.99000000","0.00014000"],["78682.00000000","0.02407000"],["78682.06000000","0.00254000"],["78682.07000000","0.00014000"]]}}}
{"rx_ns": 173339838318600, "frame": {"stream":"btcusdt@depth@100ms","data":{"e":"depthUpdate","E":1787603279014,"s":"BTCUSDT","U":99076751738,"u":99076751782,"b":[["78664.86000000","0.02600000"],["78654.35000000","0.00007000"],["78625.46000000","0.02600000"],["78595.16000000","0.02117000"],["78284.60000000","0.00000000"],["77893.17000000","0.00000000"],["77503.71000000","0.00000000"],["77116.19000000","0.00000000"],["76730.61000000","0.00000000"],["76346.95000000","0.00000000"],["75965.22000000","0.00000000"],["75585.39000000","0.00000000"],["75207.47000000","0.00000000"],["74831.43000000","0.00000000"],["74457.27000000","0.00000000"],["74084.98000000","0.00000000"],["73714.56000000","0.00000000"],["73345.99000000","0.00000000"],["72979.26000000","0.00000000"],["70810.20000000","0.00192000"],["62942.40000000","0.00031000"]],"a":[["78678.00000000","2.48231000"],["78682.50000000","0.00635000"],["78683.32000000","0.00000000"],["78693.89000000","0.02000000"],["78701.56000000","0.00007000"],["78713.59000000","0.02000000"],["78733.29000000","0.02000000"],["79071.39000000","0.00000000"],["79466.75000000","0.00000000"],["79864.09000000","0.00000000"],["80263.41000000","0.00000000"],["80664.72000000","0.00010000"],["81068.05000000","0.00000000"],["81473.39000000","0.00000000"],["81880.75000000","0.00000000"],["82290.16000000","0.00000000"],["82701.61000000","0.00000000"],["83115.12000000","0.00000000"],["83530.69000000","0.00000000"],["83948.35000000","0.00000000"],["84368.09000000","0.00000000"],["84789.93000000","0.00000000"]]}}}
{"rx_ns": 173339952691700, "frame": {"stream":"btcusdt@depth20@100ms","data":{"lastUpdateId":99076751797,"bids":[["78677.99000000","2.08560000"],["78677.98000000","0.00062000"],["78677.97000000","0.00013000"],["78677.96000000","0.00014000"],["78677.95000000","0.05014000"],["78677.92000000","0.00014000"],["78677.91000000","0.20866000"],["78677.90000000","0.05007000"],["78677.10000000","0.00665000"],["78676.74000000","0.00014000"],["78676.73000000","0.04102000"],["78676.63000000","0.00007000"],["78676.13000000","0.00014000"],["78676.12000000","0.31786000"],["78676.11000000","0.00157000"],["78675.99000000","0.02749000"],["78675.84000000","0.00007000"],["78675.47000000","0.04922000"],["78675.19000000","0.04978000"],["78674.74000000","0.00035000"]],"asks":[["78678.00000000","2.07731000"],["78678.01000000","0.00034000"],["78678.02000000","0.00013000"],["78678.64000000","0.00007000"],["78679.55000000","0.00007000"],["78679.99000000","0.00014000"],["78680.00000000","0.02407000"],["78680.55000000","0.00007000"],["78680.69000000","0.00014000"],["78680.70000000","0.05205000"],["78680.88000000","0.00007000"],["78680.97000000","0.00014000"],["78681.46000000","0.00007000"],["78681.60000000","0.00007000"],["78681.74000000","0.00007000"],["78681.97000000","0.00007000"],["78681.99000000","0.00014000"],["78682.00000000","0.02407000"],["78682.06000000","0.00254000"],["78682.07000000","0.00014000"]]}}}
{"rx_ns": 173339952779500, "frame": {"stream":"btcusdt@depth@100ms","data":{"e":"depthUpdate","E":1787603279115,"s":"BTCUSDT","U":99076751783,"u":99076751797,"b":[["78595.16000000","0.00000000"],["77969.89000000","0.00010000"],["70810.20000000","0.00192000"],["62942.39000000","0.00000000"]],"a":[["78678.00000000","2.07731000"],["78682.50000000","0.00000000"],["78683.32000000","0.00635000"],["78708.00000000","0.72407000"],["78710.00000000","0.11929000"],["78773.67000000","0.00000000"],["78775.55000000","0.00025000"]]}}}
{"rx_ns": 173340038718600, "frame": {"stream":"btcusdt@depth20@100ms","data":{"lastUpdateId":99076751805,"bids":[["78677.99000000","2.08546000"],["78677.98000000","0.00062000"],["78677.97000000","0.00013000"],["78677.96000000","0.00014000"],["78677.95000000","0.05014000"],["78677.92000000","0.00014000"],["78677.91000000","0.20866000"],["78677.90000000","0.05007000"],["78677.10000000","0.00665000"],["78676.74000000","0.00014000"],["78676.73000000","0.04102000"],["78676.63000000","0.00007000"],["78676.13000000","0.00014000"],["78676.12000000","0.31786000"],["78676.11000000","0.00157000"],["78675.99000000","0.02749000"],["78675.84000000","0.00007000"],["78675.47000000","0.04922000"],["78675.19000000","0.04978000"],["78674.74000000","0.00035000"]],"asks":[["78678.00000000","2.07721000"],["78678.01000000","0.00034000"],["78678.02000000","0.00013000"],["78678.64000000","0.00007000"],["78679.55000000","0.00007000"],["78679.99000000","0.00014000"],["78680.00000000","0.02407000"],["78680.55000000","0.00007000"],["78680.69000000","0.00014000"],["78680.70000000","0.05205000"],["78680.88000000","0.00007000"],["78680.97000000","0.00014000"],["78681.46000000","0.00007000"],["78681.60000000","0.00007000"],["78681.74000000","0.00007000"],["78681.97000000","0.00007000"],["78681.99000000","0.00014000"],["78682.00000000","0.02407000"],["78682.06000000","0.00254000"],["78682.07000000","0.00014000"]]}}}
{"rx_ns": 173340038829100, "frame": {"stream":"btcusdt@depth@100ms","data":{"e":"depthUpdate","E":1787603279214,"s":"BTCUSDT","U":99076751798,"u":99076751805,"b":[["78677.99000000","2.08546000"],["78495.86000000","0.00000000"],["77934.98000000","0.00000000"],["77834.98000000","0.00074000"],["70810.20000000","0.00192000"],["62942.40000000","0.00000000"]],"a":[["78678.00000000","2.07721000"]]}}}
{"rx_ns": 173340141558100, "frame": {"stream":"btcusdt@depth20@100ms","data":{"lastUpdateId":99076751811,"bids":[["78677.99000000","2.08546000"],["78677.98000000","0.00062000"],["78677.97000000","0.00013000"],["78677.96000000","0.00014000"],["78677.95000000","0.05014000"],["78677.92000000","0.00014000"],["78677.91000000","0.20866000"],["78677.90000000","0.05007000"],["78677.10000000","0.00665000"],["78676.74000000","0.00014000"],["78676.73000000","0.04102000"],["78676.63000000","0.00007000"],["78676.13000000","0.00014000"],["78676.12000000","0.31786000"],["78676.11000000","0.00157000"],["78675.99000000","0.02742000"],["78675.84000000","0.00007000"],["78675.47000000","0.04922000"],["78675.19000000","0.04978000"],["78674.74000000","0.00035000"]],"asks":[["78678.00000000","2.07721000"],["78678.01000000","0.00034000"],["78678.02000000","0.00013000"],["78678.64000000","0.00007000"],["78679.55000000","0.00007000"],["78679.99000000","0.00014000"],["78680.00000000","0.02407000"],["78680.55000000","0.00007000"],["78680.69000000","0.00014000"],["78680.70000000","0.05205000"],["78680.88000000","0.00007000"],["78680.97000000","0.00014000"],["78681.46000000","0.00007000"],["78681.60000000","0.00007000"],["78681.74000000","0.00007000"],["78681.97000000","0.00007000"],["78681.99000000","0.00014000"],["78682.00000000","0.02407000"],["78682.06000000","0.00254000"],["78682.07000000","0.00014000"]]}}}
{"rx_ns": 173340141641200, "frame": {"stream":"btcusdt@depth@100ms","data":{"e":"depthUpdate","E":1787603279314,"s":"BTCUSDT","U":99076751806,"u":99076751811,"b":[["78675.99000000","0.02742000"],["78673.43000000","0.00007000"],["78518.10000000","0.01991000"],["70810.20000000","0.00208000"],["62941.00000000","0.00000000"]],"a":[]}}}
{"rx_ns": 173340238628900, "frame": {"stream":"btcusdt@depth20@100ms","data":{"lastUpdateId":99076751825,"bids":[["78677.99000000","2.08546000"],["78677.98000000","0.00062000"],["78677.97000000","0.00013000"],["78677.96000000","0.00014000"],["78677.95000000","0.05014000"],["78677.92000000","0.00014000"],["78677.91000000","0.20866000"],["78677.90000000","0.05007000"],["78677.10000000","0.00665000"],["78676.74000000","0.00014000"],["78676.73000000","0.04102000"],["78676.63000000","0.00007000"],["78676.13000000","0.00014000"],["78676.12000000","0.31786000"],["78676.11000000","0.00157000"],["78675.99000000","0.02742000"],["78675.84000000","0.00007000"],["78675.47000000","0.04922000"],["78675.19000000","0.04978000"],["78674.74000000","0.00035000"]],"asks":[["78678.00000000","1.80412000"],["78678.01000000","0.00034000"],["78678.02000000","0.00013000"],["78678.64000000","0.00007000"],["78679.55000000","0.00007000"],["78679.99000000","0.00014000"],["78680.00000000","0.02407000"],["78680.55000000","0.00007000"],["78680.69000000","0.00014000"],["78680.70000000","0.05205000"],["78680.88000000","0.00007000"],["78680.97000000","0.00014000"],["78681.46000000","0.00007000"],["78681.60000000","0.00007000"],["78681.74000000","0.00007000"],["78681.97000000","0.00007000"],["78681.99000000","0.00014000"],["78682.00000000","0.02407000"],["78682.06000000","0.00254000"],["78682.07000000","0.00014000"]]}}}
{"rx_ns": 173340238714700, "frame": {"stream":"btcusdt@depth@100ms","data":{"e":"depthUpdate","E":1787603279414,"s":"BTCUSDT","U":99076751812,"u":99076751825,"b":[["78669.51000000","0.00635000"],["78668.90000000","0.00000000"],["78666.04000000","0.00400000"],["78557.94000000","0.00315000"],["70810.20000000","0.00224000"],["70810.00000000","0.01283000"]],"a":[["78678.00000000","1.80412000"],["78684.58000000","0.00000000"],["78685.33000000","0.00308000"],["78685.37000000","0.01540000"],["78685.84000000","0.31779000"],["78687.74000000","0.00317000"],["78687.99000000","0.00558000"]]}}}
{"rx_ns": 173340338138200, "frame": {"stream":"btcusdt@depth20@100ms","data":{"lastUpdateId":99076751863,"bids":[["78677.99000000","2.08546000"],["78677.98000000","0.00062000"],["78677.97000000","0.00013000"],["78677.96000000","0.00014000"],["78677.95000000","0.05014000"],["78677.92000000","0.00014000"],["78677.91000000","0.20866000"],["78677.90000000","0.05007000"],["78677.10000000","0.00665000"],["78676.74000000","0.00014000"],["78676.73000000","0.04102000"],["78676.63000000","0.00007000"],["78676.13000000","0.00014000"],["78676.12000000","0.31786000"],["78676.11000000","0.00157000"],["78675.99000000","0.02742000"],["78675.84000000","0.00007000"],["78675.47000000","0.04922000"],["78675.19000000","0.04978000"],["78674.74000000","0.00035000"]],"asks":[["78678.00000000","1.80295000"],["78678.01000000","0.00034000"],["78678.02000000","0.00013000"],["78678.64000000","0.00007000"],["78679.55000000","0.00007000"],["78679.99000000","0.00014000"],["78680.00000000","0.02407000"],["78680.55000000","0.00007000"],["78680.69000000","0.00014000"],["78680.70000000","0.05205000"],["78680.88000000","0.00007000"],["78680.97000000","0.00014000"],["78681.46000000","0.00007000"],["78681.60000000","0.00007000"],["78681.74000000","0.00007000"],["78681.97000000","0.00007000"],["78681.99000000","0.00014000"],["78682.00000000","0.02407000"],["78682.07000000","0.00014000"],["78682.08000000","0.01351000"]]}}}
{"rx_ns": 173340338220200, "frame": {"stream":"btcusdt@depth@100ms","data":{"e":"depthUpdate","E":1787603279514,"s":"BTCUSDT","U":99076751826,"u":99076751863,"b":[["78669.03000000","0.03224000"],["78284.60000000","0.01000000"],["77893.17000000","0.01000000"],["77503.71000000","0.01000000"],["77116.19000000","0.01000000"],["76730.61000000","0.01000000"],["76346.95000000","0.01000000"],["75965.22000000","0.01000000"],["75585.39000000","0.01000000"],["75207.47000000","0.01000000"],["74831.43000000","0.01000000"],["74457.27000000","0.01000000"],["74084.98000000","0.01000000"],["73714.56000000","0.01000000"],["73345.99000000","0.01000000"],["72979.26000000","0.01000000"],["70810.20000000","0.00224000"],["62942.40000000","0.00031000"]],"a":[["78678.00000000","1.80295000"],["78682.06000000","0.00000000"],["78683.31000000","0.00254000"],["78683.66000000","0.12716000"],["79071.39000000","0.01000000"],["79466.75000000","0.01000000"],["79864.09000000","0.01000000"],["80263.41000000","0.01000000"],["80664.72000000","0.01010000"],["81068.05000000","0.01000000"],["81473.39000000","0.01000000"],["81880.75000000","0.01000000"],["82290.16000000","0.01000000"],["82701.61000000","0.01000000"],["83115.12000000","0.01000000"],["83530.69000000","0.01000000"],["83948.35000000","0.01000000"],["84368.09000000","0.01000000"],["84789.93000000","0.01000000"]]}}}
{"rx_ns": 173340437808900, "frame": {"stream":"btcusdt@depth20@100ms","data":{"lastUpdateId":99076751869,"bids":[["78677.99000000","2.08788000"],["78677.98000000","0.00062000"],["78677.97000000","0.00013000"],["78677.96000000","0.00014000"],["78677.95000000","0.05014000"],["78677.92000000","0.00014000"],["78677.91000000","0.20866000"],["78677.90000000","0.05007000"],["78677.10000000","0.00665000"],["78676.74000000","0.00014000"],["78676.73000000","0.04102000"],["78676.63000000","0.00007000"],["78676.13000000","0.00014000"],["78676.12000000","0.31786000"],["78676.11000000","0.00157000"],["78675.99000000","0.02742000"],["78675.84000000","0.00007000"],["78675.47000000","0.04922000"],["78675.19000000","0.04978000"],["78674.74000000","0.00035000"]],"asks":[["78678.00000000","1.80295000"],["78678.01000000","0.00034000"],["78678.02000000","0.00013000"],["78678.64000000","0.00007000"],["78679.55000000","0.00007000"],["78679.99000000","0.00014000"],["78680.00000000","0.02407000"],["78680.55000000","0.00007000"],["78680.69000000","0.00014000"],["78680.70000000","0.05205000"],["78680.88000000","0.00007000"],["78680.97000000","0.00014000"],["78681.46000000","0.00007000"],["78681.60000000","0.00007000"],["78681.74000000","0.00007000"],["78681.97000000","0.00007000"],["78681.99000000","0.00014000"],["78682.00000000","0.02407000"],["78682.07000000","0.00014000"],["78682.08000000","0.01351000"]]}}}
{"rx_ns": 173340437890700, "frame": {"stream":"btcusdt@depth@100ms","data":{"e":"depthUpdate","E":1787603279614,"s":"BTCUSDT","U":99076751864,"u":99076751869,"b":[["78677.99000000","2.08788000"],["78669.51000000","0.00000000"],["78669.04000000","0.00635000"],["70810.20000000","0.00240000"],["62942.40000000","0.00000000"]],"a":[["78705.00000000","0.70000000"],["78708.00000000","0.02407000"]]}}}
{"rx_ns": 173340538268900, "frame": {"stream":"btcusdt@depth20@100ms","data":{"lastUpdateId":99076751882,"bids":[["78677.99000000","2.08788000"],["78677.98000000","0.00062000"],["78677.97000000","0.00013000"],["78677.96000000","0.00014000"],["78677.95000000","0.05014000"],["78677.92000000","0.00014000"],["78677.91000000","0.20866000"],["78677.90000000","0.05007000"],["78677.10000000","0.00665000"],["78676.74000000","0.00014000"],["78676.73000000","0.04102000"],["78676.63000000","0.00007000"],["78676.13000000","0.00014000"],["78676.12000000","0.31786000"],["78676.11000000","0.00157000"],["78675.99000000","0.02742000"],["78675.84000000","0.00007000"],["78675.47000000","0.04922000"],["78675.19000000","0.04978000"],["78674.74000000","0.00035000"]],"asks":[["78678.00000000","2.07609000"],["78678.01000000","0.00027000"],["78678.02000000","0.00013000"],["78678.64000000","0.00007000"],["78679.55000000","0.00007000"],["78679.99000000","0.00014000"],["78680.00000000","0.02407000"],["78680.55000000","0.00007000"],["78680.69000000","0.00014000"],["78680.70000000","0.05205000"],["78680.88000000","0.00007000"],["78680.97000000","0.00014000"],["78681.46000000","0.00007000"],["78681.60000000","0.00007000"],["78681.74000000","0.00007000"],["78681.96000000","0.00635000"],["78681.97000000","0.00007000"],["78681.99000000","0.00014000"],["78682.00000000","0.02407000"],["78682.07000000","0.00014000"]]}}}
{"rx_ns": 173340538426100, "frame": {"stream":"btcusdt@depth@100ms","data":{"e":"depthUpdate","E":1787603279714,"s":"BTCUSDT","U":99076751870,"u":99076751882,"b":[["78669.04000000","0.00000000"],["78668.57000000","0.00635000"],["78668.25000000","0.00000000"],["78667.30000000","0.00635000"],["70810.20000000","0.00256000"]],"a":[["78678.00000000","2.07609000"],["78678.01000000","0.00027000"],["78681.96000000","0.00635000"],["78683.32000000","0.00000000"],["78683.66000000","0.12716000"],["78684.58000000","0.31779000"],["78685.84000000","0.00000000"],["78726.62000000","0.00007000"]]}}}
{"rx_ns": 173340640635100, "frame": {"stream":"btcusdt@depth20@100ms","data":{"lastUpdateId":99076751888,"bids":[["78677.99000000","2.08788000"],["78677.98000000","0.00062000"],["78677.97000000","0.00013000"],["78677.96000000","0.00014000"],["78677.95000000","0.05014000"],["78677.92000000","0.00014000"],["78677.91000000","0.20866000"],["78677.90000000","0.05007000"],["78677.10000000","0.00665000"],["78676.74000000","0.00014000"],["78676.73000000","0.04102000"],["78676.63000000","0.00007000"],["78676.13000000","0.00014000"],["78676.12000000","0.31786000"],["78676.11000000","0.00157000"],["78675.99000000","0.02742000"],["78675.84000000","0.00007000"],["78675.47000000","0.04922000"],["78675.19000000","0.04978000"],["78674.74000000","0.00035000"]],"asks":[["78678.00000000","2.07602000"],["78678.01000000","0.00020000"],["78678.02000000","0.00013000"],["78678.64000000","0.00007000"],["78679.55000000","0.00007000"],["78679.99000000","0.00014000"],["78680.00000000","0.02407000"],["78680.55000000","0.00007000"],["78680.69000000","0.00014000"],["78680.70000000","0.05198000"],["78680.88000000","0.00007000"],["78680.97000000","0.00014000"],["78681.46000000","0.00007000"],["78681.60000000","0.00007000"],["78681.74000000","0.00007000"],["78681.96000000","0.00635000"],["78681.97000000","0.00007000"],["78681.99000000","0.00014000"],["78682.00000000","0.02407000"],["78682.07000000","0.00014000"]]}}}
{"rx_ns": 173340640716600, "frame": {"stream":"btcusdt@depth@100ms","data":{"e":"depthUpdate","E":1787603279815,"s":"BTCUSDT","U":99076751883,"u":99076751888,"b":[["77116.50000000","0.00017000"],["70810.20000000","0.00256000"]],"a":[["78678.00000000","2.07602000"],["78678.01000000","0.00020000"],["78680.70000000","0.05198000"]]}}}
{"rx_ns": 173340743601600, "frame": {"stream":"btcusdt@depth20@100ms","data":{"lastUpdateId":99076751929,"bids":[["78677.99000000","0.83824000"],["78677.98000000","0.00062000"],["78677.97000000","0.00013000"],["78677.96000000","0.00014000"],["78677.95000000","0.05014000"],["78677.92000000","0.00014000"],["78677.91000000","0.20866000"],["78677.90000000","0.05007000"],["78677.10000000","0.00665000"],["78676.74000000","0.00014000"],["78676.73000000","0.04102000"],["78676.63000000","0.00007000"],["78676.13000000","0.00014000"],["78676.12000000","0.31786000"],["78676.11000000","0.00157000"],["78675.99000000","0.02742000"],["78675.84000000","0.00007000"],["78675.47000000","0.04922000"],["78675.19000000","0.04978000"],["78674.74000000","0.00035000"]],"asks":[["78678.00000000","2.31253000"],["78678.01000000","0.00020000"],["78678.02000000","0.00013000"],["78678.64000000","0.00007000"],["78679.55000000","0.00007000"],["78679.99000000","0.00014000"],["78680.00000000","0.02407000"],["78680.55000000","0.00007000"],["78680.69000000","0.00014000"],["78680.70000000","0.05205000"],["78680.88000000","0.00007000"],["78680.97000000","0.00014000"],["78681.46000000","0.00007000"],["78681.60000000","0.00007000"],["78681.74000000","0.00007000"],["78681.97000000","0.00007000"],["78681.99000000","0.00014000"],["78682.00000000","0.02407000"],["78682.07000000","0.00014000"],["78682.08000000","0.01351000"]]}}}
{"rx_ns": 173340743713700, "frame": {"stream":"btcusdt@depth@100ms","data":{"e":"depthUpdate","E":1787603279914,"s":"BTCUSDT","U":99076751889,"u":99076751929,"b":[["78677.99000000","0.83824000"],["78673.82000000","0.00000000"],["78668.57000000","0.00000000"],["78667.31000000","0.00000000"],["78667.30000000","0.00000000"],["78666.05000000","0.00635000"],["78666.04000000","0.00000000"],["78665.70000000","0.00000000"],["78664.01000000","0.00635000"],["78662.01000000","0.00400000"],["78654.60000000","0.00000000"],["78653.71000000","0.00000000"],["78652.34000000","0.00000000"],["78634.40000000","0.00400000"],["78595.16000000","0.02117000"],["77135.28000000","0.00000000"],["76962.26000000","0.00025000"],["70810.20000000","0.00272000"]],"a":[["78678.00000000","2.31253000"],["78680.70000000","0.05205000"],["78681.96000000","0.00000000"],["78683.32000000","0.00000000"],["78683.66000000","0.12709000"],["78684.58000000","0.00000000"],["78688.00000000","0.02400000"],["78693.74000000","0.01299000"],["78699.75000000","0.34311000"],["78718.24000000","0.00000000"]]}}}
{"rx_ns": 173340839525400, "frame": {"stream":"btcusdt@depth20@100ms","data":{"lastUpdateId":99076752121,"bids":[["78677.99000000","0.13453000"],["78677.98000000","0.00055000"],["78677.97000000","0.00013000"],["78677.96000000","0.00014000"],["78677.95000000","0.05014000"],["78677.91000000","0.00014000"],["78677.90000000","0.05007000"],["78677.10000000","0.00007000"],["78676.74000000","0.00014000"],["78676.73000000","0.04102000"],["78676.63000000","0.00007000"],["78676.13000000","0.00014000"],["78676.12000000","0.00007000"],["78676.11000000","0.00007000"],["78676.00000000","0.00007000"],["78675.99000000","0.00226000"],["78675.84000000","0.00007000"],["78675.47000000","0.04922000"],["78675.19000000","0.04978000"],["78674.74000000","0.00035000"]],"asks":[["78678.00000000","2.09261000"],["78678.01000000","0.00020000"],["78678.02000000","0.00013000"],["78678.37000000","0.00254000"],["78678.64000000","0.00007000"],["78679.55000000","0.00007000"],["78679.99000000","0.00014000"],["78680.00000000","0.02407000"],["78680.55000000","0.00007000"],["78680.69000000","0.00014000"],["78680.70000000","0.05198000"],["78680.88000000","0.00007000"],["78680.97000000","0.00014000"],["78681.20000000","0.00400000"],["78681.45000000","0.00635000"],["78681.46000000","0.00007000"],["78681.60000000","0.00007000"],["78681.74000000","0.00007000"],["78681.97000000","0.00007000"],["78681.99000000","0.00014000"]]}}}
{"rx_ns": 173340839622300, "frame": {"stream":"btcusdt@depth@100ms","data":{"e":"depthUpdate","E":1787603280014,"s":"BTCUSDT","U":99076751930,"u":99076752121,"b":[["78677.99000000","0.13453000"],["78677.98000000","0.00055000"],["78677.92000000","0.00000000"],["78677.91000000","0.00014000"],["78677.10000000","0.00007000"],["78676.12000000","0.00007000"],["78676.11000000","0.00007000"],["78676.00000000","0.00007000"],["78675.99000000","0.00226000"],["78673.23000000","0.00007000"],["78673.09000000","0.00000000"],["78672.83000000","0.20852000"],["78672.76000000","0.00636000"],["78672.15000000","0.00000000"],["78671.91000000","0.00000000"],["78671.90000000","0.00007000"],["78671.19000000","0.00000000"],["78670.58000000","0.00000000"],["78670.15000000","0.00320000"],["78669.50000000","0.00000000"],["78669.36000000","0.00007000"],["78669.03000000","0.00000000"],["78668.72000000","0.31782000"],["78667.92000000","0.00150000"],["78666.96000000","0.00000000"],["78666.05000000","0.00000000"],["78666.02000000","0.36224000"],["78665.69000000","0.08583000"],["78665.62000000","0.00007000"],["78665.16000000","0.00000000"],["78664.06000000","0.03000000"],["78664.01000000","0.00000000"],["78663.43000000","0.00000000"],["78662.65000000","0.00254000"],["78662.01000000","0.00000000"],["78661.86000000","0.00000000"],["78661.63000000","0.00635000"],["78661.56000000","0.00635000"],["78661.12000000","0.00000000"],["78660.80000000","0.00000000"],["78660.00000000","0.02400000"],["78656.90000000","0.00400000"],["78656.89000000","0.00000000"],["78656.26000000","0.08000000"],["78654.35000000","0.00000000"],["78654.31000000","0.36224000"],["78654.30000000","0.00000000"],["78654.26000000","0.00000000"],["78652.78000000","0.00007000"],["78650.96000000","0.00000000"],["78647.81000000","0.13252000"],["78645.37000000","0.63584000"],["78644.00000000","1.92915000"],["78642.76000000","0.00635000"],["78642.38000000","0.00000000"],["78638.88000000","0.34338000"],["78637.04000000","0.00007000"],["78630.76000000","0.00000000"],["78630.66000000","0.00007000"],["78630.61000000","0.00000000"],["78628.14000000","1.25924000"],["78627.33000000","0.38166000"],["78624.00000000","0.02807000"],["78621.30000000","0.00007000"],["78605.76000000","0.02600000"],["78599.87000000","0.00000000"],["78595.16000000","0.00000000"],["78577.63000000","0.00000000"],["78574.08000000","0.00007000"],["78558.34000000","0.00007000"],["78542.60000000","0.00007000"],["78526.86000000","0.00007000"],["78521.04000000","1.52347000"],["78511.12000000","0.00007000"],["78495.38000000","0.00007000"],["78479.64000000","0.00133000"],["78463.90000000","0.00007000"],["78448.16000000","0.00007000"],["78432.42000000","0.00007000"],["78427.53000000","0.00000000"],["78413.37000000","0.00000000"],["78363.69000000","7.65756000"],["78284.60000000","0.00000000"],["78278.22000000","0.00007000"],["77893.17000000","0.00000000"],["77503.71000000","0.00000000"],["77116.19000000","0.00000000"],["76730.61000000","0.00000000"],["76346.95000000","0.00000000"],["75965.22000000","0.00000000"],["75585.39000000","0.00000000"],["75207.47000000","0.00000000"],["74831.43000000","0.00000000"],["74457.27000000","0.00000000"],["74084.98000000","0.00000000"],["73714.56000000","0.00000000"],["73345.99000000","0.00000000"],["72979.26000000","0.00000000"],["70810.20000000","0.00272000"],["62942.40000000","0.00031000"]],"a":[["78678.00000000","2.09261000"],["78678.37000000","0.00254000"],["78679.54000000","0.00000000"],["78679.59000000","0.00000000"],["78680.54000000","0.00000000"],["78680.70000000","0.05198000"],["78681.20000000","0.00400000"],["78681.45000000","0.00635000"],["78682.51000000","0.00000000"],["78682.90000000","0.02000000"],["78683.31000000","0.00000000"],["78683.63000000","0.00000000"],["78686.45000000","0.00000000"],["78686.99000000","0.00000000"],["78687.39000000","0.00227000"],["78688.50000000","0.00330000"],["78688.68000000","0.00000000"],["78690.23000000","1.21952000"],["78691.85000000","0.04857000"],["78691.87000000","0.36224000"],["78693.12000000","0.00000000"],["78693.74000000","0.10043000"],["78693.81000000","0.00000000"],["78697.63000000","0.43607000"],["78698.80000000","0.02000000"],["78701.56000000","0.00000000"],["78704.99000000","1.21952000"],["78708.37000000","0.00000000"],["78709.39000000","0.00000000"],["78717.60000000","0.00400000"],["78717.95000000","0.00000000"],["78721.16000000","0.00000000"],["78731.48000000","0.00007000"],["78739.99000000","0.00190000"],["78747.22000000","0.00007000"],["78759.81000000","0.00000000"],["78762.96000000","0.00007000"],["78770.04000000","0.00000000"],["78778.70000000","0.00007000"],["78794.44000000","0.00007000"],["78810.18000000","0.00007000"],["78819.87000000","0.00076000"],["78819.98000000","1.52347000"],["78825.92000000","0.00007000"],["78841.66000000","0.00007000"],["78857.40000000","0.00007000"],["78873.14000000","0.00007000"],["78888.88000000","0.00017000"],["79071.39000000","0.00000000"],["79466.75000000","0.00000000"],["79864.09000000","0.00000000"],["80251.56000000","0.00008000"],["80263.41000000","0.00000000"],["80664.72000000","0.00010000"],["81068.05000000","0.00000000"],["81473.39000000","0.00000000"],["81880.75000000","0.00000000"],["82290.16000000","0.00000000"],["82701.61000000","0.00000000"],["83115.12000000","0.00000000"],["83530.69000000","0.00000000"],["83948.35000000","0.00000000"],["84368.09000000","0.00000000"],["84789.93000000","0.00000000"]]}}}
{"rx_ns": 173340941833500, "frame": {"stream":"btcusdt@depth20@100ms","data":{"lastUpdateId":99076752237,"bids":[["78677.99000000","0.10676000"],["78677.98000000","0.00041000"],["78677.97000000","0.00013000"],["78677.96000000","0.00014000"],["78677.95000000","0.05014000"],["78677.91000000","0.00014000"],["78677.90000000","0.05000000"],["78677.10000000","0.00007000"],["78676.74000000","0.00014000"],["78676.73000000","0.04102000"],["78676.63000000","0.00007000"],["78676.11000000","0.00007000"],["78675.99000000","0.00219000"],["78675.84000000","0.00007000"],["78675.48000000","0.00014000"],["78675.47000000","0.04922000"],["78675.20000000","0.00007000"],["78675.19000000","0.04978000"],["78674.74000000","0.00035000"],["78674.42000000","0.00007000"]],"asks":[["78678.00000000","2.35440000"],["78678.01000000","0.00020000"],["78678.02000000","0.00013000"],["78678.60000000","0.00008000"],["78678.64000000","0.00007000"],["78679.55000000","0.00007000"],["78679.99000000","0.00014000"],["78680.00000000","0.02407000"],["78680.55000000","0.00007000"],["78680.69000000","0.00014000"],["78680.70000000","0.05205000"],["78680.88000000","0.00007000"],["78680.97000000","0.00014000"],["78681.20000000","0.00400000"],["78681.45000000","0.00635000"],["78681.46000000","0.00007000"],["78681.60000000","0.00007000"],["78681.74000000","0.00007000"],["78681.97000000","0.00007000"],["78681.99000000","0.00014000"]]}}}
{"rx_ns": 173340941935000, "frame": {"stream":"btcusdt@depth@100ms","data":{"e":"depthUpdate","E":1787603280114,"s":"BTCUSDT","U":99076752122,"u":99076752237,"b":[["78677.99000000","0.10676000"],["78677.98000000","0.00041000"],["78677.90000000","0.05000000"],["78676.13000000","0.00000000"],["78676.12000000","0.00000000"],["78676.00000000","0.00000000"],["78675.99000000","0.00219000"],["78675.48000000","0.00014000"],["78675.20000000","0.00007000"],["78673.64000000","0.04017000"],["78672.83000000","0.00000000"],["78668.56000000","0.00000000"],["78668.39000000","0.00069000"],["78666.52000000","0.02516000"],["78666.03000000","0.00000000"],["78664.86000000","0.00000000"],["78664.71000000","0.00047000"],["78664.12000000","0.00000000"],["78663.99000000","0.00331000"],["78663.85000000","0.00000000"],["78662.65000000","0.00000000"],["78662.13000000","0.02000000"],["78662.05000000","0.00000000"],["78661.63000000","0.00000000"],["78661.35000000","0.00254000"],["78660.80000000","0.00635000"],["78658.01000000","0.00800000"],["78655.53000000","0.02200000"],["78654.53000000","0.00000000"],["78654.35000000","0.00007000"],["78652.33000000","0.00000000"],["78651.89000000","0.05057000"],["78645.86000000","0.00000000"],["78642.76000000","0.00000000"],["78640.41000000","0.00635000"],["78631.80000000","0.00400000"],["78630.50000000","0.00000000"],["78630.29000000","0.00000000"],["78629.89000000","0.29356000"],["78629.06000000","0.00000000"],["78628.95000000","0.00000000"],["78628.70000000","0.00000000"],["78628.56000000","0.00000000"],["78626.79000000","0.00007000"],["78619.09000000","0.00624000"],["78615.20000000","0.00000000"],["78612.56000000","0.00406000"],["78607.29000000","0.00317000"],["78585.19000000","0.02200000"],["78583.74000000","0.00000000"],["78581.10000000","0.00406000"],["78566.23000000","0.00000000"],["78543.56000000","0.04094000"],["78536.54000000","0.00000000"],["78533.91000000","0.00406000"],["78528.01000000","0.00127000"],["78465.75000000","0.00000000"],["78463.12000000","0.00406000"],["70810.20000000","0.00288000"],["62942.39000000","0.00000000"]],"a":[["78678.00000000","2.35440000"],["78678.37000000","0.00000000"],["78678.60000000","0.00008000"],["78680.70000000","0.05205000"],["78682.89000000","0.00007000"],["78683.64000000","0.36231000"],["78683.74000000","0.00334000"],["78685.31000000","0.00319000"],["78701.56000000","0.00007000"],["78704.43000000","0.00100000"],["78708.25000000","0.00000000"],["78718.48000000","0.00434000"],["78729.38000000","0.00000000"],["78729.98000000","0.00000000"],["78779.56000000","0.02789000"],["80251.56000000","0.00000000"],["86422.88000000","0.20801000"]]}}}
{"rx_ns": 173341042641000, "frame": {"stream":"btcusdt@depth20@100ms","data":{"lastUpdateId":99076752390,"bids":[["78677.99000000","1.25219000"],["78677.98000000","0.00048000"],["78677.97000000","0.00013000"],["78677.80000000","0.00027000"],["78677.51000000","0.00014000"],["78677.50000000","0.05000000"],["78677.46000000","0.00007000"],["78677.45000000","0.05000000"],["78677.10000000","0.00007000"],["78676.74000000","0.00014000"],["78676.73000000","0.04102000"],["78676.63000000","0.00007000"],["78676.11000000","0.00007000"],["78675.99000000","0.00219000"],["78675.84000000","0.00007000"],["78675.48000000","0.00014000"],["78675.47000000","0.04922000"],["78675.20000000","0.00014000"],["78675.19000000","0.04978000"],["78674.74000000","0.00035000"]],"asks":[["78678.00000000","1.69962000"],["78678.01000000","0.00069000"],["78678.02000000","0.00013000"],["78678.60000000","0.00008000"],["78678.64000000","0.00007000"],["78679.55000000","0.00007000"],["78679.99000000","0.00014000"],["78680.00000000","0.02407000"],["78680.41000000","0.00014000"],["78680.42000000","0.04041000"],["78680.55000000","0.00007000"],["78680.69000000","0.00014000"],["78680.70000000","0.05205000"],["78680.88000000","0.00007000"],["78680.97000000","0.00014000"],["78681.20000000","0.00400000"],["78681.46000000","0.00007000"],["78681.60000000","0.00007000"],["78681.74000000","0.00007000"],["78681.97000000","0.00007000"]]}}}
{"rx_ns": 173341042731300, "frame": {"stream":"btcusdt@depth@100ms","data":{"e":"depthUpdate","E":1787603280214,"s":"BTCUSDT","U":99076752238,"u":99076752390,"b":[["78677.99000000","1.25219000"],["78677.98000000","0.00048000"],["78677.96000000","0.00000000"],["78677.95000000","0.00000000"],["78677.91000000","0.00000000"],["78677.90000000","0.00000000"],["78677.80000000","0.00027000"],["78677.51000000","0.00014000"],["78677.50000000","0.05000000"],["78677.46000000","0.00007000"],["78677.45000000","0.05000000"],["78675.20000000","0.00014000"],["78674.22000000","0.00000000"],["78673.64000000","0.00000000"],["78672.81000000","0.00000000"],["78672.01000000","0.00000000"],["78670.74000000","0.02000000"],["78669.95000000","1.21952000"],["78669.36000000","0.00014000"],["78667.30000000","0.00635000"],["78666.80000000","0.00254000"],["78665.50000000","0.00635000"],["78664.01000000","0.00000000"],["78663.79000000","0.00000000"],["78662.13000000","0.00000000"],["78662.06000000","0.00000000"],["78661.56000000","0.00000000"],["78661.35000000","0.00000000"],["78660.80000000","0.00000000"],["78658.01000000","0.01200000"],["78653.19000000","0.00000000"],["78651.89000000","0.05057000"],["78630.74000000","0.34342000"],["78630.66000000","0.00000000"],["78628.53000000","0.02386000"],["78627.33000000","0.38173000"],["78626.79000000","0.00000000"],["78626.60000000","0.00400000"],["78624.00000000","0.02407000"],["78585.19000000","0.00000000"],["78581.10000000","0.00406000"],["78533.91000000","0.00406000"],["78278.22000000","0.00000000"],["62942.40000000","0.00000000"]],"a":[["78678.00000000","1.69962000"],["78678.01000000","0.00069000"],["78679.54000000","0.00000000"],["78679.98000000","0.00000000"],["78680.41000000","0.00014000"],["78680.42000000","0.04041000"],["78680.87000000","0.00000000"],["78681.45000000","0.00000000"],["78681.95000000","0.00000000"],["78681.96000000","0.00000000"],["78682.06000000","0.00254000"],["78682.38000000","0.00254000"],["78682.39000000","0.00000000"],["78682.53000000","0.00254000"],["78682.74000000","0.00000000"],["78682.89000000","0.00000000"],["78683.32000000","0.00000000"],["78683.63000000","0.00000000"],["78683.64000000","0.00007000"],["78683.65000000","0.02161000"],["78683.99000000","0.00000000"],["78684.58000000","0.00137000"],["78686.29000000","0.00635000"],["78687.38000000","0.00635000"],["78687.39000000","0.00000000"],["78687.99000000","0.00158000"],["78688.82000000","0.00000000"],["78690.23000000","0.00000000"],["78690.57000000","0.00000000"],["78690.68000000","0.00163000"],["78690.84000000","0.00000000"],["78691.87000000","0.00000000"],["78694.66000000","1.90515000"],["78696.54000000","0.00227000"],["78697.63000000","0.00000000"],["78700.49000000","0.00000000"],["78707.40000000","0.43601000"],["78756.81000000","1.90515000"],["78756.82000000","0.00000000"],["78774.85000000","0.21930000"]]}}}
{"rx_ns": 173341142373100, "frame": {"stream":"btcusdt@depth20@100ms","data":{"lastUpdateId":99076752545,"bids":[["78677.99000000","0.83033000"],["78677.98000000","0.00041000"],["78677.97000000","0.00013000"],["78677.96000000","0.00014000"],["78677.95000000","0.05000000"],["78677.91000000","0.00007000"],["78677.90000000","0.05000000"],["78677.28000000","0.00014000"],["78677.27000000","0.21550000"],["78677.10000000","0.00007000"],["78676.74000000","0.00014000"],["78676.73000000","0.04102000"],["78676.63000000","0.00007000"],["78676.11000000","0.00007000"],["78675.99000000","0.00219000"],["78675.84000000","0.00007000"],["78675.48000000","0.00014000"],["78675.47000000","0.04922000"],["78675.19000000","0.04978000"],["78674.74000000","0.00035000"]],"asks":[["78678.00000000","2.40485000"],["78678.01000000","0.00020000"],["78678.02000000","0.00013000"],["78678.60000000","0.00008000"],["78678.64000000","0.00007000"],["78679.55000000","0.00007000"],["78679.98000000","0.00508000"],["78679.99000000","0.00014000"],["78680.00000000","0.02400000"],["78680.41000000","0.00014000"],["78680.42000000","0.04041000"],["78680.55000000","0.00007000"],["78680.69000000","0.00014000"],["78680.70000000","0.05205000"],["78680.88000000","0.00007000"],["78680.97000000","0.00014000"],["78681.20000000","0.00400000"],["78681.46000000","0.00007000"],["78681.60000000","0.00007000"],["78681.74000000","0.00007000"]]}}}
{"rx_ns": 173341142823200, "frame": {"stream":"btcusdt@depth@100ms","data":{"e":"depthUpdate","E":1787603280314,"s":"BTCUSDT","U":99076752391,"u":99076752545,"b":[["78677.99000000","0.83033000"],["78677.98000000","0.00041000"],["78677.96000000","0.00014000"],["78677.95000000","0.05000000"],["78677.91000000","0.00007000"],["78677.90000000","0.05000000"],["78677.80000000","0.00000000"],["78677.51000000","0.00000000"],["78677.50000000","0.00000000"],["78677.46000000","0.00000000"],["78677.45000000","0.00000000"],["78677.28000000","0.00014000"],["78677.27000000","0.21550000"],["78675.20000000","0.00000000"],["78674.22000000","0.00000000"],["78673.23000000","0.00014000"],["78672.76000000","0.00000000"],["78670.74000000","0.00000000"],["78669.30000000","0.00254000"],["78668.39000000","0.00000000"],["78666.80000000","0.00000000"],["78666.03000000","0.01200000"],["78664.71000000","0.00000000"],["78663.73000000","0.02000000"],["78658.01000000","0.00400000"],["78644.96000000","0.51692000"],["78634.53000000","0.00000000"],["78621.28000000","1.06442000"],["78586.66000000","0.02117000"],["76808.33000000","0.00028000"],["76654.71000000","0.00032000"],["76501.40000000","0.00041000"],["70810.20000000","0.00304000"],["62942.00000000","0.00000000"]],"a":[["78678.00000000","2.40485000"],["78678.01000000","0.00020000"],["78679.98000000","0.00508000"],["78680.00000000","0.02400000"],["78682.06000000","0.00000000"],["78682.38000000","0.00000000"],["78682.53000000","0.00000000"],["78682.90000000","0.00000000"],["78683.74000000","0.00000000"],["78685.02000000","0.00254000"],["78685.08000000","0.00320000"],["78685.30000000","0.02000000"],["78685.31000000","0.00000000"],["78688.18000000","0.00189000"],["78688.82000000","0.00400000"],["78691.84000000","0.36224000"],["78693.19000000","0.02000000"],["78693.66000000","0.00180000"],["78704.35000000","0.00000000"],["78719.07000000","0.00435000"],["78730.71000000","0.00007000"],["78743.59000000","0.00000000"],["78822.29000000","0.00000000"],["78889.32000000","0.00406000"],["78893.13000000","0.00000000"],["84202.54000000","0.00442000"]]}}}
{"rx_ns": 173341239163800, "frame": {"stream":"btcusdt@depth20@100ms","data":{"lastUpdateId":99076752626,"bids":[["78677.99000000","1.04977000"],["78677.98000000","0.00055000"],["78677.97000000","0.00013000"],["78677.28000000","0.00014000"],["78677.27000000","0.21550000"],["78677.10000000","0.00007000"],["78676.74000000","0.00014000"],["78676.73000000","0.04102000"],["78676.63000000","0.00007000"],["78676.46000000","0.00014000"],["78676.45000000","0.05000000"],["78676.41000000","0.00007000"],["78676.40000000","0.05000000"],["78676.11000000","0.00007000"],["78675.99000000","0.00219000"],["78675.84000000","0.00007000"],["78675.48000000","0.00014000"],["78675.47000000","0.04922000"],["78675.19000000","0.04978000"],["78674.74000000","0.00035000"]],"asks":[["78678.00000000","1.91521000"],["78678.01000000","0.00069000"],["78678.02000000","0.00013000"],["78678.60000000","0.00008000"],["78678.64000000","0.00007000"],["78679.55000000","0.00007000"],["78679.98000000","0.00508000"],["78679.99000000","0.00014000"],["78680.00000000","0.02400000"],["78680.41000000","0.00014000"],["78680.42000000","0.04041000"],["78680.55000000","0.00007000"],["78680.69000000","0.00014000"],["78680.70000000","0.05205000"],["78680.88000000","0.00007000"],["78680.97000000","0.00014000"],["78681.20000000","0.00400000"],["78681.46000000","0.00007000"],["78681.60000000","0.00007000"],["78681.74000000","0.00007000"]]}}}
{"rx_ns": 173341239247800, "frame": {"stream":"btcusdt@depth@100ms","data":{"e":"depthUpdate","E":1787603280414,"s":"BTCUSDT","U":99076752546,"u":99076752626,"b":[["78677.99000000","1.04977000"],["78677.98000000","0.00055000"],["78677.96000000","0.00000000"],["78677.95000000","0.00000000"],["78677.91000000","0.00000000"],["78677.90000000","0.00000000"],["78676.46000000","0.00014000"],["78676.45000000","0.05000000"],["78676.41000000","0.00007000"],["78676.40000000","0.05000000"],["78675.20000000","0.00000000"],["78674.22000000","0.00000000"],["78673.23000000","0.00007000"],["78672.64000000","0.00000000"],["78672.21000000","0.00335000"],["78669.30000000","0.00000000"],["78668.74000000","0.00000000"],["78668.56000000","0.00400000"],["78667.99000000","0.00575000"],["78666.53000000","0.00000000"],["78663.73000000","0.02000000"],["78634.53000000","0.00007000"],["78586.66000000","0.00000000"],["78486.67000000","0.00000000"],["78486.13000000","0.00977000"],["70810.20000000","0.00304000"]],"a":[["78678.00000000","1.91521000"],["78678.01000000","0.00069000"],["78683.72000000","0.00254000"],["78685.02000000","0.00000000"],["78685.33000000","0.00000000"],["78685.37000000","0.00000000"],["78688.18000000","0.00000000"],["78688.82000000","0.00000000"],["78690.08000000","0.02000000"],["78705.00000000","0.00000000"],["78739.79000000","0.00406000"],["84202.54000000","0.00884000"]]}}}
