{"rx_ns": 13994797170500, "frame": {"stream":"btcusdt@depth20","data":{"lastUpdateId":99118697207,"bids":[["79838.00000000","0.19796000"],["79837.99000000","0.00076000"],["79837.98000000","0.00013000"],["79837.75000000","0.00007000"],["79837.04000000","0.00007000"],["79836.88000000","0.00007000"],["79836.69000000","0.00007000"],["79836.28000000","0.00007000"],["79836.03000000","0.00007000"],["79836.01000000","0.00007000"],["79836.00000000","0.02442000"],["79835.25000000","0.00007000"],["79835.24000000","0.05079000"],["79834.88000000","0.00007000"],["79834.52000000","0.00661000"],["79834.23000000","0.00007000"],["79834.16000000","0.00109000"],["79834.01000000","0.00135000"],["79834.00000000","0.02414000"],["79833.84000000","0.00021000"]],"asks":[["79838.01000000","7.53132000"],["79838.02000000","0.00027000"],["79838.03000000","0.00013000"],["79838.10000000","0.00414000"],["79838.88000000","1.48792000"],["79838.89000000","0.50955000"],["79838.90000000","0.10519000"],["79839.10000000","0.00007000"],["79839.29000000","0.02065000"],["79839.65000000","0.10480000"],["79839.72000000","0.00007000"],["79839.85000000","0.84060000"],["79840.01000000","0.00007000"],["79840.25000000","0.00400000"],["79840.57000000","0.02475000"],["79840.82000000","0.04970000"],["79840.99000000","0.28969000"],["79841.14000000","0.04026000"],["79841.69000000","0.00400000"],["79841.79000000","0.00400000"]]}}}
{"rx_ns": 13994797283600, "frame": {"stream":"btcusdt@depth@100ms","data":{"e":"depthUpdate","E":1787650990014,"s":"BTCUSDT","U":99118697200,"u":99118697207,"b":[["79838.00000000","0.19796000"],["79837.99000000","0.00076000"],["79822.80000000","0.00007000"],["71854.20000000","0.00336000"],["71854.00000000","0.00181000"],["63870.40000000","0.00031000"]],"a":[["79854.74000000","0.00007000"]]}}}
{"rx_ns": 13994892217900, "frame": {"stream":"btcusdt@depth@100ms","data":{"e":"depthUpdate","E":1787650990114,"s":"BTCUSDT","U":99118697208,"u":99118697754,"b":[["79838.00000000","0.00000000"],["79837.99000000","0.00000000"],["79837.98000000","0.00000000"],["79837.75000000","0.00000000"],["79837.04000000","0.00000000"],["79836.88000000","0.00000000"],["79836.69000000","0.00000000"],["79836.28000000","0.00000000"],["79836.03000000","0.00000000"],["79836.01000000","0.00000000"],["79836.00000000","0.00000000"],["79835.99000000","0.00000000"],["79835.25000000","0.00000000"],["79835.24000000","0.00000000"],["79834.88000000","0.00000000"],["79834.52000000","0.00675000"],["79834.16000000","0.00083000"],["79833.24000000","0.06165000"],["79833.13000000","0.00021000"],["79832.85000000","0.00007000"],["79832.39000000","0.00000000"],["79832.24000000","0.00014000"],["79832.02000000","0.00000000"],["79832.00000000","0.02435000"],["79831.86000000","0.00000000"],["79831.45000000","0.00000000"],["79830.02000000","0.00013000"],["79829.75000000","0.12533000"],["79829.58000000","0.00942000"],["79828.02000000","0.00008000"],["79828.00000000","0.02407000"],["79826.49000000","0.00014000"],["79826.11000000","0.31326000"],["79825.71000000","0.00000000"],["79825.61000000","0.00000000"],["79823.92000000","0.00000000"],["79823.08000000","0.00000000"],["79823.00000000","0.00000000"],["79822.82000000","0.00007000"],["79822.63000000","0.00000000"],["79822.17000000","0.00000000"],["79822.16000000","0.00000000"],["79822.11000000","0.00000000"],["79821.68000000","0.07000000"],["79821.60000000","0.08566000"],["79821.02000000","0.00000000"],["79820.46000000","0.00626000"],["79820.23000000","0.00000000"],["79818.62000000","0.00800000"],["79817.69000000","0.00000000"],["79817.03000000","0.00000000"],["79816.04000000","0.00008000"],["79813.04000000","0.00000000"],["79812.05000000","0.00008000"],["79810.61000000","0.00000000"],["79810.60000000","0.00000000"],["79809.04000000","0.00000000"],["79808.44000000","0.37209000"],["79808.06000000","0.00008000"],["79806.64000000","0.00000000"],["79804.07000000","0.00008000"],["79803.03000000","0.00000000"],["79798.00000000","0.02400000"],["79797.68000000","0.33844000"],["79796.00000000","0.03400000"],["79787.79000000","0.00007000"],["79777.48000000","0.00007000"],["79773.48000000","0.00000000"],["79768.45000000","0.00312000"],["79758.22000000","0.00000000"],["79757.88000000","0.00010000"],["79750.71000000","1.04939000"],["79749.13000000","0.00000000"],["79721.92000000","1.87677000"],["79709.54000000","0.20250000"],["79686.31000000","0.00000000"],["79678.99000000","0.00000000"],["79678.31000000","0.00008000"],["79677.62000000","1.50097000"],["79660.65000000","1.20000000"],["79606.46000000","0.00000000"],["79596.49000000","0.00008000"],["79594.48000000","0.00007000"],["79530.52000000","0.00250000"],["79526.62000000","0.00000000"],["79516.66000000","0.00008000"],["79446.77000000","0.00000000"],["79436.82000000","0.00008000"],["79366.92000000","0.00000000"],["79356.98000000","0.00008000"],["79287.08000000","0.00000000"],["79277.15000000","0.00008000"],["78640.43000000","0.00000000"],["78638.46000000","0.00030000"],["71854.20000000","0.00000000"],["71854.19000000","0.00008000"],["71854.00000000","0.00181000"]],"a":[["79834.53000000","1.24673000"],["79834.89000000","0.50037000"],["79835.19000000","0.45230000"],["79835.25000000","1.23859000"],["79835.26000000","1.59394000"],["79835.66000000","0.06215000"],["79835.67000000","0.56922000"],["79836.01000000","5.70267000"],["79836.02000000","0.00027000"],["79836.03000000","0.00013000"],["79836.04000000","0.00000000"],["79836.29000000","2.50327000"],["79836.70000000","0.00000000"],["79836.89000000","0.00000000"],["79836.92000000","0.00000000"],["79837.05000000","0.00000000"],["79837.55000000","0.00000000"],["79837.76000000","0.00000000"],["79837.99000000","0.00000000"],["79838.00000000","1.70258000"],["79838.01000000","0.57599000"],["79838.02000000","0.00000000"],["79838.03000000","0.00000000"],["79838.82000000","0.04956000"],["79838.88000000","0.00014000"],["79838.89000000","0.17126000"],["79839.72000000","0.00014000"],["79839.85000000","0.84046000"],["79840.27000000","0.00026000"],["79840.57000000","0.02461000"],["79840.82000000","0.00000000"],["79841.14000000","0.00007000"],["79841.69000000","0.00000000"],["79843.99000000","0.00021000"],["79844.39000000","0.00007000"],["79845.89000000","0.00010000"],["79846.25000000","0.08576000"],["79847.65000000","0.00000000"],["79847.83000000","0.00000000"],["79848.00000000","2.00742000"],["79848.01000000","0.27061000"],["79848.46000000","0.00000000"],["79848.74000000","0.00000000"],["79850.00000000","0.13800000"],["79850.01000000","0.76187000"],["79850.45000000","0.00000000"],["79850.46000000","0.00000000"],["79851.71000000","0.00000000"],["79851.72000000","0.00000000"],["79851.98000000","0.00008000"],["79852.01000000","0.00000000"],["79853.96000000","0.00000000"],["79854.57000000","0.30000000"],["79855.97000000","0.00008000"],["79856.66000000","0.62628000"],["79856.96000000","0.00000000"],["79859.04000000","0.12522000"],["79859.96000000","0.00008000"],["79860.95000000","0.00000000"],["79862.62000000","0.09563000"],["79863.06000000","0.00000000"],["79863.95000000","0.00008000"],["79864.94000000","0.00000000"],["79867.94000000","0.00008000"],["79868.93000000","0.00000000"],["79871.43000000","0.00000000"],["79871.94000000","0.00008000"],["79872.93000000","0.00014000"],["79875.93000000","1.04947000"],["79876.80000000","0.00000000"],["79876.92000000","0.00000000"],["79880.91000000","0.00000000"],["79899.97000000","0.00000000"],["79902.86000000","0.00312000"],["79915.00000000","0.00000000"],["79916.06000000","0.00000000"],["79938.18000000","0.00000000"],["79958.89000000","0.00000000"],["79980.96000000","1.50097000"],["80089.55000000","0.00000000"],["80404.02000000","0.00250000"],["81035.59000000","0.00000000"]]}}}
{"rx_ns": 13994996471700, "frame": {"stream":"btcusdt@depth@100ms","data":{"e":"depthUpdate","E":1787650990214,"s":"BTCUSDT","U":99118697755,"u":99118699789,"b":[["79834.52000000","0.00000000"],["79834.51000000","0.00000000"],["79834.23000000","0.00000000"],["79834.16000000","0.00000000"],["79834.01000000","0.00000000"],["79834.00000000","0.00000000"],["79833.84000000","0.00000000"],["79833.80000000","0.00000000"],["79833.50000000","0.00000000"],["79833.25000000","0.00000000"],["79833.24000000","0.00000000"],["79833.23000000","0.00000000"],["79833.14000000","0.00000000"],["79833.13000000","0.00000000"],["79833.04000000","0.00000000"],["79832.85000000","0.00000000"],["79832.84000000","0.00000000"],["79832.25000000","0.00000000"],["79832.24000000","0.00000000"],["79832.16000000","0.00000000"],["79832.12000000","0.00000000"],["79832.08000000","0.00000000"],["79832.01000000","0.00000000"],["79832.00000000","0.00000000"],["79831.97000000","0.00000000"],["79831.96000000","0.00000000"],["79831.75000000","0.00000000"],["79831.43000000","0.00000000"],["79831.00000000","0.00000000"],["79830.69000000","0.00000000"],["79830.68000000","0.00000000"],["79830.49000000","0.00000000"],["79830.48000000","0.00000000"],["79830.36000000","0.00000000"],["79830.26000000","0.00000000"],["79830.25000000","0.00000000"],["79830.24000000","0.00000000"],["79830.02000000","0.00000000"],["79830.01000000","0.00000000"],["79830.00000000","0.00000000"],["79829.99000000","0.00000000"],["79829.98000000","0.00000000"],["79829.82000000","0.00000000"],["79829.76000000","0.00000000"],["79829.75000000","0.00000000"],["79829.70000000","0.00000000"],["79829.58000000","0.00000000"],["79829.35000000","0.00000000"],["79829.20000000","0.00000000"],["79828.31000000","0.00000000"],["79828.28000000","0.00000000"],["79828.02000000","0.00000000"],["79828.01000000","0.00000000"],["79828.00000000","0.02340000"],["79827.99000000","0.00042000"],["79827.77000000","0.00000000"],["79827.76000000","0.00000000"],["79827.48000000","0.00007000"],["79827.47000000","0.00000000"],["79827.28000000","0.00000000"],["79826.49000000","0.00007000"],["79826.38000000","0.00000000"],["79826.32000000","0.00125000"],["79826.12000000","0.00000000"],["79826.11000000","0.00007000"],["79826.04000000","0.00000000"],["79826.02000000","0.00000000"],["79826.01000000","0.00007000"],["79826.00000000","0.02414000"],["79825.82000000","0.00000000"],["79825.39000000","0.00000000"],["79825.31000000","0.00000000"],["79824.92000000","0.00007000"],["79824.86000000","0.00567000"],["79824.45000000","0.00007000"],["79824.44000000","0.00000000"],["79824.40000000","0.00007000"],["79824.39000000","0.07969000"],["79824.01000000","0.00007000"],["79824.00000000","0.02421000"],["79823.58000000","0.00945000"],["79823.52000000","0.00007000"],["79822.92000000","0.00000000"],["79822.86000000","0.00000000"],["79822.82000000","0.00014000"],["79822.81000000","0.02268000"],["79822.80000000","0.00000000"],["79822.62000000","0.00007000"],["79822.60000000","0.00000000"],["79822.32000000","0.00000000"],["79822.30000000","0.01134000"],["79822.27000000","0.00008000"],["79822.26000000","0.00000000"],["79822.03000000","0.00111000"],["79822.01000000","0.00007000"],["79822.00000000","0.02407000"],["79821.77000000","0.00007000"],["79821.76000000","0.12534000"],["79821.68000000","0.00000000"],["79821.61000000","0.00000000"],["79821.60000000","0.00000000"],["79821.28000000","0.00000000"],["79821.06000000","0.00000000"],["79821.02000000","0.01141000"],["79820.72000000","0.02007000"],["79820.59000000","0.00000000"],["79820.46000000","0.00000000"],["79820.45000000","0.00000000"],["79820.37000000","0.00000000"],["79820.02000000","0.00008000"],["79820.01000000","0.00007000"],["79820.00000000","0.02407000"],["79819.63000000","0.00007000"],["79819.61000000","0.00007000"],["79819.60000000","0.31728000"],["79819.13000000","0.00000000"],["79818.91000000","0.00000000"],["79818.89000000","0.00000000"],["79818.75000000","0.00007000"],["79818.62000000","0.00000000"],["79818.61000000","0.00000000"],["79818.17000000","0.00000000"],["79817.91000000","0.00000000"],["79817.90000000","0.00000000"],["79817.89000000","0.00000000"],["79817.83000000","0.00000000"],["79817.73000000","0.00000000"],["79817.18000000","0.00000000"],["79817.02000000","0.00000000"],["79816.44000000","0.00007000"],["79816.39000000","0.00000000"],["79816.10000000","0.00000000"],["79816.04000000","0.00000000"],["79815.76000000","0.00000000"],["79815.55000000","0.00000000"],["79815.54000000","0.00400000"],["79815.28000000","0.00000000"],["79815.27000000","0.00000000"],["79815.06000000","0.00007000"],["79815.05000000","0.00007000"],["79814.88000000","0.00007000"],["79814.80000000","0.08566000"],["79814.61000000","0.00000000"],["79814.57000000","0.00000000"],["79814.50000000","0.00000000"],["79814.49000000","0.00000000"],["79814.36000000","0.00000000"],["79814.34000000","0.00000000"],["79814.25000000","0.06215000"],["79814.08000000","0.00000000"],["79814.07000000","0.02000000"],["79814.05000000","0.00626000"],["79814.04000000","0.00111000"],["79814.03000000","0.00156000"],["79813.78000000","0.00000000"],["79813.66000000","0.53457000"],["79813.65000000","0.00000000"],["79813.64000000","0.00000000"],["79813.63000000","0.00000000"],["79813.60000000","0.00000000"],["79813.37000000","0.01000000"],["79813.27000000","0.00000000"],["79812.84000000","0.00000000"],["79812.76000000","0.00626000"],["79812.75000000","0.00007000"],["79812.51000000","0.00000000"],["79812.50000000","0.00000000"],["79812.31000000","0.00199000"],["79812.05000000","0.00000000"],["79811.41000000","0.00000000"],["79811.27000000","0.12000000"],["79810.29000000","0.00008000"],["79810.01000000","0.00000000"],["79810.00000000","0.02400000"],["79809.67000000","0.12529000"],["79809.60000000","0.00000000"],["79809.55000000","1.05189000"],["79809.29000000","0.00125000"],["79809.05000000","0.00000000"],["79808.45000000","1.87677000"],["79808.44000000","0.00000000"],["79808.43000000","0.00000000"],["79808.06000000","0.00000000"],["79807.72000000","0.00000000"],["79807.68000000","0.00000000"],["79807.22000000","0.00000000"],["79806.66000000","0.11020000"],["79806.65000000","0.00000000"],["79806.30000000","0.00008000"],["79806.02000000","0.00000000"],["79804.46000000","0.00000000"],["79804.35000000","0.00000000"],["79804.07000000","0.00000000"],["79803.53000000","0.00000000"],["79803.28000000","0.00000000"],["79802.55000000","0.00000000"],["79802.31000000","0.00008000"],["79802.07000000","0.00000000"],["79802.04000000","0.36893000"],["79802.03000000","0.00000000"],["79802.02000000","0.00000000"],["79801.36000000","0.00000000"],["79800.94000000","0.00000000"],["79800.50000000","0.00626000"],["79800.02000000","0.00000000"],["79800.01000000","0.00000000"],["79800.00000000","1.62269000"],["79799.97000000","0.00000000"],["79799.54000000","0.00000000"],["79799.06000000","0.79567000"],["79798.75000000","0.00000000"],["79798.71000000","0.00000000"],["79798.44000000","0.00000000"],["79798.32000000","0.00008000"],["79798.08000000","0.00000000"],["79798.05000000","0.00000000"],["79797.87000000","0.00000000"],["79797.58000000","0.00000000"],["79797.44000000","0.62656000"],["79796.99000000","0.00000000"],["79796.96000000","0.04550000"],["79796.00000000","0.02400000"],["79795.87000000","0.00000000"],["79795.53000000","0.00014000"],["79795.39000000","0.00000000"],["79795.15000000","0.00000000"],["79794.78000000","0.00000000"],["79794.00000000","0.02400000"],["79793.88000000","0.00000000"],["79793.00000000","0.00000000"],["79792.36000000","0.00008000"],["79791.66000000","0.00014000"],["79791.22000000","0.62679000"],["79791.17000000","0.00000000"],["79791.03000000","0.00000000"],["79790.00000000","0.12800000"],["79789.08000000","0.00000000"],["79788.96000000","0.33847000"],["79788.60000000","0.00400000"],["79788.56000000","0.00000000"],["79788.37000000","0.00008000"],["79784.04000000","0.00407000"],["79783.92000000","0.00007000"],["79783.28000000","0.00000000"],["79780.05000000","0.00007000"],["79779.48000000","0.00400000"],["79779.15000000","0.51013000"],["79776.18000000","0.00000000"],["79775.06000000","0.34841000"],["79773.43000000","0.00000000"],["79770.54000000","0.00000000"],["79768.45000000","0.00000000"],["79768.44000000","0.00000000"],["79768.43000000","0.00000000"],["79764.01000000","0.00312000"],["79762.50000000","0.00312000"],["79760.00000000","0.02632000"],["79759.16000000","1.24155000"],["79758.01000000","0.00311000"],["79756.70000000","0.00000000"],["79756.00000000","0.02400000"],["79755.01000000","0.03646000"],["79754.80000000","0.00000000"],["79754.09000000","0.00000000"],["79753.98000000","0.00000000"],["79753.75000000","0.00000000"],["79753.24000000","0.00000000"],["79752.96000000","0.00000000"],["79752.69000000","0.00000000"],["79752.17000000","0.00000000"],["79750.80000000","0.00000000"],["79750.43000000","0.00000000"],["79750.42000000","0.00008000"],["79749.90000000","0.00010000"],["79749.87000000","0.00000000"],["79744.11000000","0.00000000"],["79741.92000000","0.00010000"],["79741.11000000","1.04939000"],["79739.35000000","3.40245000"],["79732.40000000","1.04939000"],["79726.70000000","0.56076000"],["79726.24000000","0.00007000"],["79700.01000000","0.02289000"],["79695.22000000","0.00000000"],["79694.19000000","0.00394000"],["79678.28000000","0.00125000"],["79675.66000000","0.00000000"],["79668.62000000","0.00008000"],["79608.80000000","0.00007000"],["79604.81000000","0.00007000"],["79602.65000000","0.00007000"],["79599.02000000","0.00035000"],["79598.66000000","0.00007000"],["79593.64000000","3.40879000"],["79566.43000000","0.00000000"],["79556.74000000","0.03132000"],["79509.62000000","0.00000000"],["79502.22000000","0.01947000"],["79203.28000000","0.00000000"],["79195.13000000","0.00008000"],["78638.46000000","0.00000000"],["71854.00000000","0.00171000"],["63870.40000000","0.00000000"]],"a":[["79828.01000000","5.76858000"],["79828.02000000","0.00014000"],["79828.03000000","0.14130000"],["79828.28000000","1.47776000"],["79828.29000000","4.01485000"],["79828.92000000","0.06216000"],["79829.36000000","0.13860000"],["79829.55000000","0.06216000"],["79829.59000000","2.68471000"],["79829.71000000","0.00000000"],["79829.76000000","0.00000000"],["79829.77000000","0.00000000"],["79829.83000000","0.14790000"],["79829.98000000","0.07500000"],["79829.99000000","1.03360000"],["79830.00000000","3.71799000"],["79830.01000000","0.65165000"],["79830.02000000","0.04685000"],["79830.03000000","0.00000000"],["79830.23000000","0.07500000"],["79830.24000000","0.00000000"],["79830.25000000","0.46405000"],["79830.26000000","0.61389000"],["79830.27000000","0.00000000"],["79830.28000000","0.00000000"],["79830.36000000","0.00014000"],["79830.45000000","0.04026000"],["79830.49000000","0.00000000"],["79830.69000000","0.00000000"],["79831.52000000","0.00000000"],["79831.76000000","0.00000000"],["79831.92000000","0.00400000"],["79831.97000000","0.00000000"],["79832.01000000","0.00000000"],["79832.07000000","0.00000000"],["79832.17000000","0.00000000"],["79832.25000000","0.00026000"],["79832.78000000","0.00000000"],["79832.85000000","0.00000000"],["79832.86000000","0.00000000"],["79833.05000000","0.00007000"],["79833.14000000","0.00000000"],["79833.15000000","0.00000000"],["79833.24000000","0.00007000"],["79833.25000000","0.72685000"],["79833.26000000","0.00000000"],["79833.27000000","0.00000000"],["79833.51000000","0.00000000"],["79833.56000000","0.00000000"],["79833.81000000","0.37657000"],["79833.85000000","0.00000000"],["79833.99000000","0.98543000"],["79834.00000000","1.41525000"],["79834.01000000","0.00000000"],["79834.02000000","0.00000000"],["79834.17000000","0.00000000"],["79834.20000000","0.00400000"],["79834.23000000","0.00014000"],["79834.24000000","0.00000000"],["79834.52000000","0.00000000"],["79834.53000000","0.76859000"],["79834.54000000","0.00000000"],["79834.55000000","0.00000000"],["79834.88000000","0.00000000"],["79834.89000000","0.00007000"],["79835.18000000","1.87677000"],["79835.19000000","0.00007000"],["79835.24000000","0.00000000"],["79835.25000000","0.51689000"],["79835.26000000","0.39648000"],["79835.66000000","0.00007000"],["79835.67000000","0.00000000"],["79835.99000000","0.00008000"],["79836.00000000","0.42331000"],["79836.01000000","1.02096000"],["79836.02000000","0.00000000"],["79836.03000000","0.00000000"],["79836.06000000","0.00007000"],["79836.29000000","0.00007000"],["79836.51000000","0.00008000"],["79837.70000000","0.00000000"],["79837.75000000","0.00000000"],["79837.76000000","0.02000000"],["79837.91000000","0.00010000"],["79838.00000000","1.25196000"],["79838.01000000","0.16331000"],["79838.24000000","0.00008000"],["79838.63000000","0.02254000"],["79838.82000000","0.00000000"],["79838.88000000","0.00000000"],["79838.89000000","0.00021000"],["79838.90000000","0.00014000"],["79839.12000000","0.12525000"],["79839.24000000","0.00250000"],["79839.29000000","0.00000000"],["79839.45000000","0.08576000"],["79839.46000000","0.33826000"],["79839.65000000","0.10466000"],["79839.85000000","0.78000000"],["79840.00000000","0.09401000"],["79840.01000000","0.00000000"],["79840.23000000","0.00007000"],["79840.57000000","0.00000000"],["79840.74000000","0.00000000"],["79840.75000000","0.00000000"],["79840.99000000","0.01640000"],["79841.14000000","0.00000000"],["79841.20000000","0.00007000"],["79841.23000000","0.00000000"],["79841.79000000","0.00000000"],["79841.85000000","0.00000000"],["79842.00000000","0.00000000"],["79842.01000000","1.03100000"],["79842.03000000","0.00000000"],["79842.27000000","0.00000000"],["79842.45000000","0.00000000"],["79842.46000000","0.00000000"],["79842.64000000","0.00007000"],["79842.70000000","0.00000000"],["79842.71000000","0.00000000"],["79842.77000000","0.00000000"],["79843.39000000","0.00000000"],["79843.99000000","0.00000000"],["79844.00000000","0.31203000"],["79844.01000000","0.69827000"],["79844.02000000","0.00000000"],["79844.03000000","0.14000000"],["79844.04000000","0.00000000"],["79844.49000000","0.00007000"],["79844.83000000","0.01000000"],["79844.98000000","0.00626000"],["79844.99000000","0.00701000"],["79845.70000000","0.00000000"],["79845.99000000","0.02000000"],["79846.01000000","0.22284000"],["79846.02000000","0.35823000"],["79846.23000000","0.00008000"],["79846.25000000","0.00000000"],["79846.98000000","0.00000000"],["79846.99000000","0.62642000"],["79847.00000000","0.62652000"],["79847.01000000","0.33823000"],["79847.14000000","0.09531000"],["79847.34000000","0.00000000"],["79847.58000000","0.00000000"],["79847.99000000","1.28183000"],["79848.00000000","1.90283000"],["79848.01000000","0.00000000"],["79848.12000000","0.00000000"],["79848.77000000","0.00000000"],["79849.13000000","0.10378000"],["79849.26000000","0.00000000"],["79849.56000000","0.00000000"],["79849.59000000","0.12523000"],["79850.01000000","0.41811000"],["79850.22000000","0.00008000"],["79850.70000000","0.00000000"],["79850.77000000","0.00000000"],["79850.85000000","0.00000000"],["79851.98000000","0.00000000"],["79852.64000000","0.00000000"],["79852.65000000","0.00008000"],["79852.70000000","0.00000000"],["79853.04000000","0.00000000"],["79853.72000000","0.00000000"],["79854.21000000","0.00008000"],["79854.74000000","0.00000000"],["79855.97000000","0.00000000"],["79856.62000000","0.00000000"],["79856.74000000","0.00000000"],["79857.61000000","0.00250000"],["79858.20000000","0.00008000"],["79859.04000000","0.00000000"],["79859.70000000","0.00000000"],["79859.96000000","0.00000000"],["79860.08000000","0.00000000"],["79860.09000000","0.00000000"],["79860.34000000","0.00000000"],["79860.48000000","0.00067000"],["79861.47000000","0.00000000"],["79862.04000000","0.00000000"],["79862.19000000","0.00008000"],["79863.95000000","0.00000000"],["79864.00000000","0.02400000"],["79864.98000000","0.65386000"],["79866.15000000","0.00000000"],["79866.18000000","0.00008000"],["79866.58000000","0.00000000"],["79867.94000000","0.00000000"],["79868.00000000","0.02400000"],["79868.20000000","1.23985000"],["79869.06000000","0.00000000"],["79870.00000000","0.81791000"],["79870.18000000","0.00008000"],["79871.00000000","0.01000000"],["79871.90000000","0.98057000"],["79871.94000000","0.00000000"],["79872.93000000","0.00000000"],["79874.64000000","0.00000000"],["79875.93000000","1.04939000"],["79877.55000000","0.00000000"],["79877.71000000","0.00000000"],["79878.00000000","0.02400000"],["79879.41000000","0.00000000"],["79888.00000000","0.02407000"],["79891.99000000","1.10030000"],["79893.71000000","0.00000000"],["79894.40000000","0.00000000"],["79897.86000000","0.00000000"],["79899.94000000","0.00000000"],["79910.09000000","0.00008000"],["79916.05000000","0.47954000"],["79919.69000000","0.00000000"],["79922.37000000","0.25000000"],["79925.46000000","0.01161000"],["79925.77000000","0.00000000"],["79931.01000000","0.00000000"],["79931.94000000","0.00000000"],["79933.60000000","0.00000000"],["79935.81000000","0.00000000"],["79935.82000000","0.00000000"],["79937.38000000","0.00000000"],["79947.63000000","0.00000000"],["79951.52000000","0.00000000"],["79951.70000000","0.00000000"],["79956.44000000","0.11108000"],["79979.99000000","0.87220000"],["79989.92000000","0.00008000"],["79997.51000000","0.00000000"],["79999.53000000","0.00000000"],["80049.26000000","0.00000000"],["80068.90000000","0.00000000"],["80069.75000000","0.00008000"],["80071.42000000","0.00010000"],["80079.37000000","0.00000000"],["80204.21000000","0.00000000"],["80218.46000000","0.54998000"],["80222.81000000","0.00626000"],["80229.41000000","0.00008000"],["80239.05000000","0.00000000"],["80246.94000000","0.00000000"],["80257.40000000","0.00000000"],["80389.07000000","0.00008000"],["80398.73000000","0.00000000"],["80468.90000000","0.00008000"],["80478.57000000","0.00000000"],["80553.03000000","0.00010000"],["80620.81000000","0.00000000"],["80621.00000000","0.00000000"],["80621.03000000","0.00000000"],["80621.14000000","0.00000000"]]}}}
{"rx_ns": 13995094948100, "frame": {"stream":"btcusdt@depth@100ms","data":{"e":"depthUpdate","E":1787650990314,"s":"BTCUSDT","U":99118699790,"u":99118700182,"b":[["79828.00000000","0.05386000"],["79827.99000000","0.00070000"],["79827.48000000","0.00000000"],["79826.00000000","0.02435000"],["79825.22000000","0.00007000"],["79825.21000000","0.05015000"],["79824.86000000","0.00014000"],["79824.39000000","0.07983000"],["79824.00000000","0.02435000"],["79823.58000000","0.00014000"],["79822.91000000","0.00000000"],["79822.81000000","0.02282000"],["79822.30000000","0.00014000"],["79822.27000000","0.00000000"],["79822.00000000","0.02421000"],["79821.72000000","0.00000000"],["79821.02000000","0.00007000"],["79820.73000000","0.00000000"],["79820.72000000","0.00007000"],["79819.60000000","0.31335000"],["79819.39000000","0.00000000"],["79819.02000000","0.02000000"],["79818.83000000","0.00000000"],["79818.16000000","0.00000000"],["79817.92000000","0.00000000"],["79817.72000000","0.00000000"],["79817.57000000","0.00000000"],["79817.29000000","0.00000000"],["79816.96000000","0.00000000"],["79816.93000000","0.00000000"],["79816.88000000","0.00000000"],["79816.79000000","0.00000000"],["79816.66000000","0.00000000"],["79816.03000000","0.06216000"],["79815.73000000","0.00000000"],["79815.40000000","0.06216000"],["79815.06000000","0.00000000"],["79814.88000000","0.00014000"],["79814.86000000","0.00000000"],["79814.81000000","0.06216000"],["79814.80000000","0.00000000"],["79814.57000000","0.00000000"],["79814.56000000","0.00000000"],["79814.10000000","0.06216000"],["79814.09000000","0.42558000"],["79814.08000000","0.00000000"],["79814.07000000","0.00000000"],["79813.83000000","0.00007000"],["79813.82000000","0.00000000"],["79813.67000000","1.04939000"],["79813.66000000","0.00000000"],["79813.37000000","0.00000000"],["79812.95000000","0.08566000"],["79812.94000000","0.00000000"],["79812.31000000","0.00008000"],["79811.37000000","0.01000000"],["79811.32000000","0.00800000"],["79811.27000000","0.14000000"],["79809.28000000","0.00048000"],["79809.27000000","0.00250000"],["79808.86000000","0.00047000"],["79808.39000000","0.00000000"],["79806.96000000","0.00188000"],["79804.34000000","0.00000000"],["79803.97000000","0.09537000"],["79803.74000000","0.02480000"],["79802.04000000","0.00000000"],["79801.98000000","0.10384000"],["79801.79000000","1.20251000"],["79800.70000000","0.00060000"],["79800.49000000","0.00000000"],["79800.28000000","0.00000000"],["79800.00000000","0.92269000"],["79799.95000000","0.00000000"],["79799.07000000","0.32082000"],["79799.06000000","0.42981000"],["79798.99000000","0.00012000"],["79797.82000000","0.00192000"],["79797.44000000","0.00000000"],["79796.96000000","0.00000000"],["79795.90000000","0.04568000"],["79794.12000000","0.00000000"],["79793.98000000","0.62656000"],["79793.97000000","0.29835000"],["79793.62000000","0.00000000"],["79792.50000000","0.00000000"],["79790.00000000","0.11800000"],["79789.67000000","0.00000000"],["79788.00000000","0.03400000"],["79786.32000000","0.00400000"],["79783.59000000","0.18666000"],["79783.47000000","0.04928000"],["79781.76000000","0.00400000"],["79778.93000000","0.00000000"],["79777.84000000","0.02445000"],["79776.18000000","0.00000000"],["79773.34000000","0.00000000"],["79769.89000000","0.00000000"],["79769.72000000","0.00000000"],["79764.01000000","0.00000000"],["79760.37000000","0.00000000"],["79758.02000000","0.00310000"],["79749.30000000","0.00000000"],["79749.23000000","0.00000000"],["79747.97000000","0.00000000"],["79747.50000000","0.00000000"],["79747.30000000","0.12176000"],["79728.44000000","0.00000000"],["79725.27000000","0.04651000"],["79696.01000000","0.00000000"],["79692.27000000","0.00000000"],["79689.20000000","0.00000000"],["79680.59000000","0.00654000"],["79680.57000000","0.00000000"],["79678.31000000","0.00000000"],["79678.29000000","0.00125000"],["79608.75000000","0.00000000"],["79598.66000000","0.00000000"],["79498.06000000","0.00035000"],["71847.00000000","0.00010000"],["71845.20000000","0.00032000"],["63870.00000000","0.00030000"],["63862.00000000","0.00000000"]],"a":[["79828.01000000","5.83479000"],["79828.02000000","0.00027000"],["79828.03000000","0.00027000"],["79828.28000000","0.00014000"],["79828.29000000","1.15197000"],["79828.44000000","0.00008000"],["79828.92000000","0.00014000"],["79829.29000000","0.02186000"],["79829.36000000","0.00014000"],["79829.55000000","0.00014000"],["79829.59000000","0.00014000"],["79829.64000000","0.00400000"],["79829.83000000","0.00007000"],["79829.98000000","0.07500000"],["79829.99000000","0.00000000"],["79830.00000000","3.57963000"],["79830.01000000","0.64525000"],["79830.02000000","0.04671000"],["79830.25000000","0.46391000"],["79830.26000000","0.45313000"],["79830.45000000","0.04040000"],["79830.57000000","0.02624000"],["79830.80000000","0.05015000"],["79831.85000000","0.02624000"],["79833.25000000","0.72671000"],["79833.81000000","0.17414000"],["79834.53000000","0.76845000"],["79835.26000000","0.19398000"],["79836.01000000","0.51068000"],["79836.29000000","0.00000000"],["79836.48000000","0.00400000"],["79837.61000000","0.08576000"],["79837.98000000","0.00007000"],["79838.00000000","1.04939000"],["79838.01000000","0.16310000"],["79838.24000000","0.00000000"],["79838.89000000","0.00000000"],["79838.90000000","0.00000000"],["79839.10000000","0.00000000"],["79839.45000000","0.00000000"],["79839.65000000","0.10459000"],["79839.72000000","0.00007000"],["79840.46000000","0.00007000"],["79842.57000000","0.09532000"],["79844.56000000","0.10378000"],["79847.14000000","0.00000000"],["79849.13000000","0.00000000"],["79853.75000000","0.00250000"],["79853.99000000","0.00000000"],["79854.02000000","0.00012000"],["79854.33000000","0.09512000"],["79857.61000000","0.00000000"],["79860.00000000","0.81792000"],["79862.62000000","0.00000000"],["79864.26000000","0.00000000"],["79866.00000000","0.02400000"],["79866.08000000","0.00430000"],["79866.20000000","0.00427000"],["79866.81000000","0.00000000"],["79866.94000000","0.00000000"],["79868.28000000","0.00000000"],["79870.00000000","0.73400000"],["79871.00000000","0.00000000"],["79873.98000000","0.82312000"],["79874.88000000","0.00000000"],["79874.96000000","0.00000000"],["79875.38000000","0.00000000"],["79876.24000000","0.00000000"],["79876.76000000","0.00007000"],["79879.18000000","0.00000000"],["79884.41000000","0.01132000"],["79887.55000000","0.82298000"],["79887.98000000","0.51223000"],["79888.22000000","0.00000000"],["79893.10000000","0.00112000"],["79899.98000000","0.00000000"],["79901.79000000","0.00000000"],["79906.88000000","0.00000000"],["79906.97000000","0.00000000"],["79907.37000000","0.00000000"],["79924.06000000","0.00000000"],["79932.86000000","0.00400000"],["79933.19000000","0.02811000"],["79938.83000000","0.00000000"],["79953.21000000","0.00000000"],["79986.75000000","0.00000000"],["80052.65000000","0.00400000"],["80058.63000000","0.00000000"],["80066.09000000","0.00000000"],["80078.65000000","0.02746000"],["80083.09000000","0.01899000"],["80103.96000000","0.00000000"],["80131.91000000","0.00000000"],["80136.41000000","0.00000000"],["80180.24000000","0.00000000"]]}}}
{"rx_ns": 13995191649600, "frame": {"stream":"btcusdt@depth@100ms","data":{"e":"depthUpdate","E":1787650990414,"s":"BTCUSDT","U":99118700183,"u":99118700298,"b":[["79828.00000000","0.05400000"],["79827.99000000","0.00077000"],["79826.00000000","0.02428000"],["79825.21000000","0.05029000"],["79824.92000000","0.00000000"],["79824.86000000","0.00000000"],["79824.00000000","0.02428000"],["79823.58000000","0.00000000"],["79822.81000000","0.02282000"],["79822.61000000","0.00567000"],["79822.30000000","0.00000000"],["79821.76000000","0.12555000"],["79821.33000000","0.00952000"],["79820.05000000","0.01134000"],["79820.00000000","0.02421000"],["79819.02000000","0.02014000"],["79818.77000000","0.01134000"],["79817.81000000","0.00000000"],["79817.29000000","0.06216000"],["79816.66000000","0.06216000"],["79813.34000000","0.00000000"],["79813.01000000","0.00000000"],["79809.31000000","0.00250000"],["79809.27000000","0.00000000"],["79789.78000000","0.01136000"],["79780.26000000","0.00012000"],["79771.92000000","0.83285000"],["79758.86000000","0.00425000"],["79728.72000000","1.99721000"],["79698.34000000","0.00020000"],["79684.56000000","0.04543000"],["71847.00000000","0.00000000"],["71845.20000000","0.00048000"],["71845.00000000","0.00030000"]],"a":[["79828.01000000","5.83506000"],["79828.03000000","0.00013000"],["79828.28000000","0.00000000"],["79828.29000000","1.15197000"],["79828.92000000","0.00000000"],["79829.29000000","0.02200000"],["79829.36000000","0.00000000"],["79829.55000000","0.00000000"],["79829.59000000","0.00000000"],["79829.98000000","0.07514000"],["79830.00000000","3.37727000"],["79830.01000000","0.64539000"],["79830.02000000","0.04685000"],["79830.25000000","0.26141000"],["79832.25000000","0.00000000"],["79833.25000000","0.52421000"],["79835.25000000","0.00007000"],["79836.00000000","0.62581000"],["79836.58000000","0.00410000"],["79854.33000000","0.39512000"],["79854.97000000","1.04939000"],["79857.39000000","0.00012000"],["79864.36000000","0.02495000"],["79868.00000000","0.03400000"],["79868.03000000","0.83185000"],["79870.00000000","0.72400000"],["79898.04000000","0.00375000"],["79911.25000000","1.99265000"],["79923.98000000","0.02804000"],["79930.01000000","0.04557000"],["79933.19000000","0.00007000"],["79977.77000000","0.00020000"],["80036.10000000","0.01962000"],["80071.39000000","0.00000000"],["80094.22000000","0.00036000"]]}}}
{"rx_ns": 13995292262000, "frame": {"stream":"btcusdt@depth@100ms","data":{"e":"depthUpdate","E":1787650990514,"s":"BTCUSDT","U":99118700299,"u":99118700696,"b":[["79828.00000000","0.00000000"],["79827.99000000","0.00000000"],["79827.80000000","0.00000000"],["79827.73000000","0.00000000"],["79827.12000000","0.00000000"],["79826.49000000","0.00000000"],["79826.33000000","0.00000000"],["79826.32000000","0.00000000"],["79826.30000000","0.00000000"],["79826.11000000","0.00000000"],["79826.01000000","0.00000000"],["79826.00000000","0.00000000"],["79825.22000000","0.00000000"],["79825.21000000","0.21533000"],["79825.20000000","0.00063000"],["79824.00000000","0.02421000"],["79823.16000000","0.00000000"],["79823.13000000","0.00000000"],["79822.82000000","0.00007000"],["79822.81000000","0.02282000"],["79822.61000000","0.00588000"],["79822.42000000","0.00007000"],["79822.41000000","0.05009000"],["79822.03000000","0.00000000"],["79821.77000000","0.00000000"],["79821.76000000","0.00028000"],["79821.33000000","0.00966000"],["79820.05000000","0.01148000"],["79820.02000000","0.00000000"],["79820.01000000","0.00073000"],["79820.00000000","0.02414000"],["79819.72000000","0.00946000"],["79818.77000000","0.01141000"],["79818.05000000","0.00007000"],["79818.04000000","0.33829000"],["79818.00000000","0.02414000"],["79817.65000000","0.00202000"],["79817.31000000","0.00007000"],["79817.30000000","0.12528000"],["79817.29000000","0.00007000"],["79817.23000000","0.00008000"],["79816.67000000","0.00000000"],["79816.66000000","0.00007000"],["79816.45000000","0.00696000"],["79815.48000000","0.00007000"],["79814.04000000","0.00000000"],["79813.25000000","0.00007000"],["79812.95000000","0.00000000"],["79812.03000000","0.00066000"],["79810.49000000","0.08566000"],["79810.29000000","0.00000000"],["79809.36000000","0.00250000"],["79809.31000000","0.00000000"],["79806.30000000","0.00000000"],["79806.06000000","0.00000000"],["79805.25000000","0.00008000"],["79802.31000000","0.00000000"],["79801.26000000","0.00008000"],["79800.00000000","0.92276000"],["79798.65000000","0.36586000"],["79798.32000000","0.00000000"],["79797.27000000","0.00008000"],["79793.28000000","0.00008000"],["79792.09000000","0.09564000"],["79788.00000000","0.02400000"],["79787.79000000","0.00014000"],["79786.75000000","0.33848000"],["79786.63000000","0.33848000"],["79785.00000000","0.01000000"],["79760.96000000","0.00000000"],["79754.43000000","0.00400000"],["79747.30000000","0.00000000"],["79746.89000000","0.12449000"],["79690.53000000","0.00000000"],["79677.63000000","0.00125000"],["79599.77000000","0.00007000"],["79596.49000000","0.00000000"],["79595.78000000","0.00007000"],["79585.73000000","0.00008000"],["79516.66000000","0.00000000"],["79505.91000000","0.00008000"],["79436.82000000","0.00000000"],["79426.08000000","0.00008000"],["79356.98000000","0.00000000"],["79346.26000000","0.00008000"],["79277.15000000","0.00000000"],["79266.43000000","0.00008000"],["79195.13000000","0.00000000"],["79186.61000000","0.00008000"],["71854.19000000","0.00000000"],["71854.18000000","0.00008000"],["71845.20000000","0.00000000"],["71842.69000000","0.00016000"],["63860.17000000","0.00031000"]],"a":[["79825.22000000","6.30519000"],["79825.23000000","0.00027000"],["79825.24000000","0.00013000"],["79825.86000000","0.00000000"],["79825.99000000","0.10925000"],["79826.00000000","0.36586000"],["79826.01000000","0.08494000"],["79826.12000000","0.00000000"],["79826.49000000","0.00014000"],["79826.50000000","0.00000000"],["79827.13000000","0.00000000"],["79827.14000000","0.00000000"],["79827.36000000","0.00400000"],["79827.74000000","0.00000000"],["79827.78000000","0.00000000"],["79827.81000000","0.00000000"],["79828.00000000","1.20043000"],["79828.01000000","2.35629000"],["79828.02000000","0.00000000"],["79828.03000000","0.00000000"],["79828.29000000","0.00021000"],["79830.00000000","1.50050000"],["79830.02000000","0.04678000"],["79830.23000000","0.00000000"],["79830.25000000","0.26141000"],["79830.45000000","0.00021000"],["79830.80000000","0.00007000"],["79831.72000000","0.00026000"],["79832.00000000","0.00007000"],["79833.20000000","0.00008000"],["79833.25000000","0.44421000"],["79834.53000000","0.72845000"],["79834.82000000","0.00007000"],["79835.15000000","0.08576000"],["79835.19000000","0.00014000"],["79835.26000000","0.00007000"],["79835.99000000","0.00000000"],["79836.00000000","0.95553000"],["79836.06000000","0.00000000"],["79837.61000000","0.00000000"],["79837.67000000","0.00007000"],["79838.76000000","0.00007000"],["79840.00000000","0.09901000"],["79840.40000000","0.33826000"],["79840.46000000","0.00000000"],["79841.19000000","0.00008000"],["79841.81000000","0.22161000"],["79842.00000000","0.00500000"],["79843.20000000","0.02480000"],["79844.00000000","0.31703000"],["79844.39000000","0.00000000"],["79845.18000000","0.00008000"],["79846.00000000","0.01864000"],["79846.23000000","0.00000000"],["79847.16000000","0.00007000"],["79849.17000000","0.00008000"],["79849.89000000","0.00250000"],["79850.22000000","0.00000000"],["79853.16000000","0.00008000"],["79853.75000000","0.00000000"],["79854.21000000","0.00000000"],["79854.75000000","0.30000000"],["79857.15000000","0.00008000"],["79858.20000000","0.00000000"],["79861.14000000","0.00008000"],["79862.19000000","0.00000000"],["79862.23000000","0.00000000"],["79865.13000000","0.00008000"],["79865.19000000","0.00000000"],["79866.18000000","0.00000000"],["79868.61000000","0.00014000"],["79870.18000000","0.00000000"],["79891.63000000","0.00000000"],["79917.32000000","0.25000000"],["79921.73000000","0.00000000"],["79922.37000000","0.00000000"],["80032.15000000","0.02278000"],["80034.88000000","0.00000000"],["80127.04000000","0.00000000"],["80128.55000000","1.19998000"],["80159.47000000","0.00000000"],["80384.00000000","0.00052000"],["83819.19000000","0.00124000"]]}}}
{"rx_ns": 13995394480000, "frame": {"stream":"btcusdt@depth@100ms","data":{"e":"depthUpdate","E":1787650990614,"s":"BTCUSDT","U":99118700697,"u":99118700791,"b":[["79825.21000000","0.00852000"],["79825.20000000","0.00063000"],["79822.61000000","0.00021000"],["79822.41000000","0.05023000"],["79822.00000000","0.02421000"],["79821.76000000","0.00014000"],["79821.33000000","0.00021000"],["79820.05000000","0.00014000"],["79818.77000000","0.00007000"],["79814.11000000","0.00000000"],["79811.04000000","0.00070000"],["79809.36000000","0.00000000"],["79809.34000000","0.00250000"],["79806.02000000","0.00000000"],["79805.77000000","0.00800000"],["79804.05000000","0.00066000"],["79798.17000000","0.49733000"],["79796.06000000","0.00066000"],["79774.24000000","1.00905000"],["79769.27000000","0.00000000"],["79762.03000000","0.00962000"],["79746.89000000","0.00160000"],["79735.99000000","0.04550000"],["79602.31000000","0.00000000"],["79599.03000000","0.00771000"],["79595.78000000","0.00000000"],["63860.17000000","0.00000000"]],"a":[["79825.22000000","6.30827000"],["79825.99000000","0.10939000"],["79826.00000000","0.36600000"],["79826.01000000","0.08515000"],["79827.99000000","0.00800000"],["79828.00000000","1.20057000"],["79828.01000000","2.34303000"],["79828.29000000","0.00007000"],["79829.29000000","0.00014000"],["79830.01000000","0.64525000"],["79830.02000000","0.04664000"],["79830.45000000","0.00007000"],["79830.57000000","0.00000000"],["79830.80000000","0.00000000"],["79831.85000000","0.00000000"],["79834.53000000","0.72852000"],["79842.02000000","1.41532000"],["79860.85000000","0.00627000"],["79866.00000000","0.03400000"],["79868.00000000","0.02400000"],["79871.33000000","0.00000000"],["79906.02000000","0.00375000"],["80059.43000000","0.00000000"],["80062.10000000","0.00000000"]]}}}
{"rx_ns": 13995491883200, "frame": {"stream":"btcusdt@depth@100ms","data":{"e":"depthUpdate","E":1787650990714,"s":"BTCUSDT","U":99118700792,"u":99118700924,"b":[["79825.21000000","0.00850000"],["79825.20000000","0.00070000"],["79822.81000000","0.02282000"],["79822.61000000","0.00007000"],["79822.00000000","0.02421000"],["79821.76000000","0.00007000"],["79821.33000000","0.00000000"],["79820.05000000","0.00000000"],["79820.00000000","0.02435000"],["79819.99000000","0.00000000"],["79819.82000000","0.00567000"],["79819.72000000","0.00960000"],["79819.61000000","0.00000000"],["79819.60000000","0.00021000"],["79819.03000000","0.00007000"],["79819.02000000","0.02014000"],["79818.77000000","0.00000000"],["79818.54000000","0.00945000"],["79818.05000000","0.00000000"],["79818.04000000","0.00000000"],["79818.01000000","0.00007000"],["79817.30000000","0.12535000"],["79817.26000000","0.01134000"],["79816.25000000","0.06276000"],["79815.98000000","0.01134000"],["79814.88000000","0.00007000"],["79814.11000000","0.01200000"],["79814.05000000","0.00000000"],["79814.02000000","0.00000000"],["79812.77000000","0.00007000"],["79812.48000000","0.31331000"],["79811.30000000","0.00000000"],["79809.34000000","0.00000000"],["79807.58000000","0.00250000"],["79805.77000000","0.00000000"],["79805.26000000","0.00000000"],["79804.31000000","0.02000000"],["79803.13000000","0.00000000"],["79798.85000000","0.00000000"],["79797.68000000","0.00000000"],["79795.90000000","0.00000000"],["79794.33000000","0.00400000"],["79792.87000000","0.04471000"],["79792.09000000","0.00000000"],["79787.35000000","0.62682000"],["79780.26000000","0.00000000"],["79777.41000000","0.00000000"],["79776.18000000","0.00007000"],["79757.40000000","0.00429000"],["79757.33000000","0.02200000"],["79757.17000000","1.24158000"],["79749.30000000","0.02000000"],["79746.56000000","0.12065000"],["79709.31000000","0.00000000"],["79703.11000000","0.00000000"],["79701.55000000","0.20250000"],["79696.53000000","0.00012000"],["79594.48000000","0.00014000"],["79590.49000000","0.00000000"],["71842.69000000","0.00048000"],["71842.00000000","0.00000000"],["63860.17000000","0.00000000"]],"a":[["79825.22000000","6.66023000"],["79826.01000000","0.08522000"],["79826.50000000","0.02193000"],["79827.78000000","0.02624000"],["79827.99000000","0.01221000"],["79828.01000000","2.14046000"],["79829.06000000","0.02624000"],["79829.29000000","0.00000000"],["79838.41000000","0.02000000"],["79839.23000000","0.02000000"],["79840.45000000","0.02000000"],["79848.75000000","0.00000000"],["79850.79000000","0.00000000"],["79857.39000000","0.00000000"],["79862.79000000","0.00434000"],["79954.63000000","0.00000000"],["79957.32000000","0.00000000"],["79961.48000000","0.00000000"]]}}}
{"rx_ns": 13995596416200, "frame": {"stream":"btcusdt@depth@100ms","data":{"e":"depthUpdate","E":1787650990814,"s":"BTCUSDT","U":99118700925,"u":99118701274,"b":[["79825.21000000","0.00000000"],["79825.20000000","0.00000000"],["79824.45000000","0.00000000"],["79824.40000000","0.00000000"],["79824.39000000","0.08125000"],["79824.38000000","0.00076000"],["79824.37000000","0.00013000"],["79823.12000000","0.00000000"],["79822.42000000","0.00000000"],["79822.41000000","0.00014000"],["79822.00000000","0.02428000"],["79821.61000000","0.00007000"],["79821.60000000","0.05009000"],["79820.00000000","0.02435000"],["79819.82000000","0.00581000"],["79819.72000000","0.00014000"],["79819.63000000","0.00000000"],["79819.60000000","0.00007000"],["79819.02000000","0.02028000"],["79818.01000000","0.06284000"],["79817.65000000","0.00000000"],["79817.35000000","0.06277000"],["79816.72000000","0.00007000"],["79816.71000000","0.05710000"],["79816.45000000","0.00689000"],["79816.32000000","0.00007000"],["79816.31000000","0.05628000"],["79816.30000000","0.33829000"],["79816.26000000","0.00000000"],["79816.25000000","0.00000000"],["79816.03000000","0.00000000"],["79815.43000000","0.06276000"],["79815.40000000","0.00000000"],["79814.12000000","0.06276000"],["79814.10000000","0.00000000"],["79814.09000000","0.00000000"],["79813.67000000","0.00000000"],["79812.87000000","0.06276000"],["79812.49000000","0.06276000"],["79811.59000000","0.06276000"],["79811.33000000","0.06276000"],["79810.49000000","0.00000000"],["79810.06000000","0.00007000"],["79809.65000000","0.08566000"],["79808.43000000","0.00007000"],["79807.58000000","0.00000000"],["79807.39000000","0.00250000"],["79806.57000000","0.00000000"],["79791.60000000","0.00000000"],["79785.00000000","0.00000000"],["79784.00000000","0.03400000"],["79777.47000000","0.00012000"],["79774.38000000","0.00000000"],["79771.43000000","1.24136000"],["79768.08000000","0.00007000"],["79763.21000000","0.00432000"],["79759.16000000","0.00000000"],["79752.12000000","0.00007000"],["79749.30000000","0.00000000"],["79746.56000000","0.00000000"],["79736.16000000","0.00007000"],["79720.20000000","0.00007000"],["79718.48000000","0.00007000"],["79704.24000000","0.00007000"],["79690.30000000","0.00000000"],["79688.28000000","0.00007000"],["79677.62000000","0.00000000"],["79674.33000000","0.00000000"],["79672.32000000","0.00007000"],["79662.10000000","1.50097000"],["79658.36000000","0.00000000"],["79656.36000000","0.00007000"],["79653.40000000","0.00000000"],["79642.39000000","0.00000000"],["79640.67000000","0.01962000"],["79640.40000000","0.00007000"],["79626.42000000","0.00000000"],["79624.44000000","0.00007000"],["79610.45000000","0.00000000"],["79608.48000000","0.00007000"],["79598.75000000","0.00000000"],["79594.48000000","0.00007000"],["79589.04000000","0.01962000"],["71854.18000000","0.00000000"],["71842.69000000","0.00000000"],["71841.96000000","0.00016000"],["71841.00000000","0.00000000"]],"a":[["79824.40000000","5.53404000"],["79824.41000000","0.00027000"],["79824.42000000","0.00013000"],["79824.46000000","0.20257000"],["79825.04000000","0.00000000"],["79825.20000000","0.86555000"],["79825.21000000","1.12439000"],["79825.22000000","2.69628000"],["79825.23000000","0.00000000"],["79825.24000000","0.00000000"],["79825.99000000","0.00014000"],["79826.01000000","0.00035000"],["79826.13000000","0.00007000"],["79826.50000000","0.02214000"],["79827.18000000","0.05014000"],["79827.78000000","0.02638000"],["79827.99000000","0.01228000"],["79828.00000000","1.15043000"],["79828.01000000","0.26369000"],["79829.98000000","0.07500000"],["79830.00000000","1.42536000"],["79834.30000000","0.08576000"],["79834.53000000","0.62440000"],["79834.88000000","0.00007000"],["79834.89000000","0.00000000"],["79835.15000000","0.00000000"],["79835.19000000","0.00007000"],["79835.25000000","0.00000000"],["79835.26000000","0.00000000"],["79835.66000000","0.00000000"],["79836.85000000","0.00007000"],["79837.67000000","0.00000000"],["79838.00000000","1.05639000"],["79838.01000000","0.14918000"],["79840.00000000","0.10601000"],["79842.00000000","0.01200000"],["79842.35000000","0.00007000"],["79844.00000000","0.32403000"],["79846.00000000","0.02564000"],["79847.88000000","0.00007000"],["79854.28000000","0.00000000"],["79854.60000000","0.00012000"],["79863.84000000","0.00007000"],["79865.00000000","0.01000000"],["79866.00000000","0.02400000"],["79879.80000000","0.00007000"],["79895.76000000","0.00007000"],["79902.04000000","0.00000000"],["79911.72000000","0.00007000"],["79917.32000000","0.00000000"],["79927.68000000","0.00007000"],["79931.96000000","0.00000000"],["79945.82000000","0.00000000"],["79947.94000000","0.00000000"],["79950.55000000","0.25000000"],["79959.04000000","0.00000000"],["79959.60000000","0.00007000"],["79961.79000000","0.00000000"],["79963.92000000","0.00000000"],["79965.39000000","1.50097000"],["79975.56000000","0.00007000"],["79977.76000000","0.00000000"],["79979.90000000","0.00000000"],["79979.99000000","0.50215000"],["79980.96000000","0.00000000"],["79991.52000000","0.00007000"],["79993.73000000","0.00000000"],["79995.88000000","0.00000000"],["80007.48000000","0.00007000"],["80009.70000000","0.00000000"],["80023.44000000","0.00007000"],["80025.67000000","0.00000000"],["80039.40000000","0.00007000"],["80041.64000000","0.00000000"],["80055.36000000","0.00007000"],["80057.25000000","0.00067000"],["80057.61000000","0.00000000"],["80071.32000000","0.00007000"],["80073.58000000","0.00000000"],["80087.51000000","2.50000000"],["80222.88000000","0.00000000"],["81021.77000000","0.00030000"]]}}}
{"rx_ns": 13995692192200, "frame": {"stream":"btcusdt@depth@100ms","data":{"e":"depthUpdate","E":1787650990914,"s":"BTCUSDT","U":99118701275,"u":99118701408,"b":[["79824.39000000","0.08215000"],["79822.81000000","0.02275000"],["79822.61000000","0.00000000"],["79822.41000000","0.00000000"],["79822.00000000","0.02428000"],["79821.60000000","0.05023000"],["79820.01000000","0.00007000"],["79820.00000000","0.02428000"],["79819.82000000","0.00581000"],["79819.72000000","0.00000000"],["79818.54000000","0.00973000"],["79818.10000000","0.00007000"],["79818.09000000","0.06179000"],["79818.02000000","0.00007000"],["79818.00000000","0.02421000"],["79817.36000000","0.00007000"],["79817.31000000","0.00000000"],["79817.26000000","0.01141000"],["79816.72000000","0.00000000"],["79816.40000000","0.00066000"],["79816.32000000","0.00000000"],["79814.12000000","0.00000000"],["79814.11000000","0.00000000"],["79813.05000000","0.05626000"],["79812.49000000","0.00000000"],["79812.03000000","0.00000000"],["79811.34000000","0.01200000"],["79811.33000000","0.00000000"],["79808.73000000","0.02800000"],["79808.65000000","0.02600000"],["79808.42000000","0.00066000"],["79807.86000000","0.02000000"],["79807.39000000","0.00000000"],["79804.23000000","0.02208000"],["79804.05000000","0.00000000"],["79803.85000000","0.02200000"],["79803.83000000","0.02200000"],["79800.44000000","0.00066000"],["79796.06000000","0.00000000"],["79793.99000000","0.51639000"],["79793.97000000","0.00000000"],["79792.46000000","0.00066000"],["79789.27000000","0.00000000"],["79777.47000000","0.00000000"],["79771.44000000","1.41645000"],["79754.11000000","0.02800000"],["79749.67000000","0.02200000"],["79749.27000000","0.02200000"],["79749.26000000","0.00000000"],["79748.62000000","0.02000000"],["79746.37000000","0.02607000"],["79690.75000000","0.00016000"],["79640.67000000","0.00000000"],["79597.51000000","0.00007000"],["79594.48000000","0.00000000"],["71841.96000000","0.00032000"],["71841.00000000","0.00010000"]],"a":[["79824.40000000","5.53418000"],["79824.46000000","0.20271000"],["79825.20000000","0.86569000"],["79825.21000000","1.12453000"],["79825.22000000","2.69621000"],["79825.99000000","0.00000000"],["79826.00000000","0.36600000"],["79826.01000000","0.00021000"],["79826.50000000","0.02214000"],["79827.99000000","0.01214000"],["79828.00000000","1.15029000"],["79835.65000000","0.02000000"],["79835.71000000","0.02000000"],["79836.51000000","0.02008000"],["79838.01000000","0.13526000"],["79839.66000000","0.02000000"],["79840.14000000","0.02000000"],["79840.53000000","0.02000000"],["79840.54000000","0.02000000"],["79849.57000000","0.00000000"],["79849.62000000","0.51270000"],["79854.60000000","0.00000000"],["79860.98000000","0.00400000"],["79886.58000000","0.00500000"],["79902.87000000","0.00000000"],["79903.73000000","0.00000000"],["79941.82000000","0.00012000"]]}}}
{"rx_ns": 13995798645400, "frame": {"stream":"btcusdt@depth20","data":{"lastUpdateId":99118701970,"bids":[["79818.00000000","0.79858000"],["79817.99000000","0.00063000"],["79817.36000000","0.00007000"],["79817.35000000","0.00014000"],["79817.31000000","0.00007000"],["79817.30000000","0.00021000"],["79817.29000000","0.00007000"],["79817.26000000","0.01155000"],["79816.90000000","0.00007000"],["79816.72000000","0.00007000"],["79816.71000000","0.00014000"],["79816.66000000","0.00007000"],["79816.45000000","0.00710000"],["79816.40000000","0.00066000"],["79816.32000000","0.00007000"],["79816.31000000","0.00028000"],["79816.30000000","0.00007000"],["79816.00000000","0.02407000"],["79815.98000000","0.01141000"],["79815.54000000","0.00400000"]],"asks":[["79818.01000000","3.41978000"],["79818.02000000","0.00027000"],["79818.03000000","0.00013000"],["79818.54000000","0.45246000"],["79818.55000000","0.00021000"],["79818.75000000","0.00014000"],["79819.03000000","0.00021000"],["79820.01000000","0.00021000"],["79820.56000000","0.04025000"],["79820.77000000","0.05057000"],["79821.52000000","0.00400000"],["79822.38000000","0.00400000"],["79822.45000000","0.00026000"],["79822.56000000","0.00250000"],["79822.62000000","0.00014000"],["79822.82000000","0.20631000"],["79824.00000000","0.00007000"],["79824.01000000","0.06205000"],["79824.39000000","2.99852000"],["79824.40000000","2.13328000"]]}}}
{"rx_ns": 13995798753000, "frame": {"stream":"btcusdt@depth@100ms","data":{"e":"depthUpdate","E":1787650991014,"s":"BTCUSDT","U":99118701409,"u":99118701970,"b":[["79824.39000000","0.00000000"],["79824.38000000","0.00000000"],["79824.37000000","0.00000000"],["79824.01000000","0.00000000"],["79824.00000000","0.00000000"],["79823.52000000","0.00000000"],["79823.24000000","0.00000000"],["79822.82000000","0.00000000"],["79822.81000000","0.00000000"],["79822.62000000","0.00000000"],["79822.01000000","0.00000000"],["79822.00000000","0.00000000"],["79821.76000000","0.00000000"],["79821.61000000","0.00000000"],["79821.60000000","0.00000000"],["79821.05000000","0.00000000"],["79821.02000000","0.00000000"],["79820.92000000","0.00000000"],["79820.72000000","0.00000000"],["79820.01000000","0.00000000"],["79820.00000000","0.00000000"],["79819.82000000","0.00000000"],["79819.60000000","0.00000000"],["79819.36000000","0.00000000"],["79819.03000000","0.00000000"],["79819.02000000","0.00000000"],["79818.75000000","0.00000000"],["79818.54000000","0.00000000"],["79818.10000000","0.00000000"],["79818.09000000","0.00000000"],["79818.06000000","0.00000000"],["79818.02000000","0.00000000"],["79818.01000000","0.00000000"],["79818.00000000","0.79858000"],["79817.99000000","0.00063000"],["79817.35000000","0.00014000"],["79817.31000000","0.00007000"],["79817.30000000","0.00021000"],["79817.26000000","0.01155000"],["79817.23000000","0.00000000"],["79817.15000000","0.00000000"],["79816.72000000","0.00007000"],["79816.71000000","0.00014000"],["79816.45000000","0.00710000"],["79816.44000000","0.00000000"],["79816.35000000","0.00000000"],["79816.32000000","0.00007000"],["79816.31000000","0.00028000"],["79816.30000000","0.00007000"],["79816.00000000","0.02407000"],["79815.98000000","0.01141000"],["79815.53000000","0.00925000"],["79815.44000000","0.00007000"],["79815.43000000","0.00007000"],["79815.05000000","0.00000000"],["79814.82000000","0.00014000"],["79814.81000000","0.00007000"],["79814.27000000","0.00000000"],["79814.26000000","0.00007000"],["79814.25000000","0.00007000"],["79813.83000000","0.00000000"],["79813.25000000","0.00000000"],["79813.06000000","0.00007000"],["79813.05000000","0.00007000"],["79812.87000000","0.00007000"],["79812.77000000","0.00000000"],["79812.76000000","0.00007000"],["79812.48000000","0.31338000"],["79812.31000000","0.00000000"],["79812.00000000","0.02407000"],["79811.59000000","0.00007000"],["79811.49000000","0.00013000"],["79811.38000000","0.00018000"],["79811.34000000","0.00000000"],["79811.32000000","0.00000000"],["79811.01000000","0.00007000"],["79810.06000000","0.00007000"],["79810.02000000","0.00008000"],["79809.68000000","0.00000000"],["79809.67000000","0.00000000"],["79808.30000000","0.02255000"],["79807.41000000","0.00000000"],["79807.14000000","0.00007000"],["79806.87000000","0.00007000"],["79805.77000000","0.00626000"],["79805.25000000","0.00000000"],["79804.12000000","0.00000000"],["79803.68000000","0.00007000"],["79803.53000000","0.01200000"],["79802.09000000","0.00000000"],["79802.04000000","0.00008000"],["79801.26000000","0.00000000"],["79800.50000000","0.00000000"],["79800.11000000","0.37603000"],["79799.07000000","0.00000000"],["79799.06000000","0.00000000"],["79798.66000000","0.36586000"],["79798.65000000","0.00000000"],["79798.05000000","0.00008000"],["79797.62000000","0.33844000"],["79797.27000000","0.00000000"],["79796.17000000","0.00626000"],["79795.11000000","0.42983000"],["79794.60000000","0.55157000"],["79794.07000000","0.00000000"],["79794.05000000","0.00008000"],["79793.98000000","0.00000000"],["79793.28000000","0.00000000"],["79792.87000000","0.00000000"],["79792.36000000","0.00000000"],["79791.23000000","0.62659000"],["79790.58000000","0.00000000"],["79790.27000000","0.09597000"],["79790.06000000","0.00008000"],["79789.63000000","0.00000000"],["79789.23000000","0.00000000"],["79789.22000000","0.00000000"],["79788.37000000","0.00000000"],["79787.35000000","0.00000000"],["79787.00000000","0.70000000"],["79786.07000000","0.00008000"],["79784.00000000","0.02400000"],["79783.92000000","0.00014000"],["79782.08000000","0.00008000"],["79781.87000000","0.38295000"],["79780.17000000","0.62688000"],["79780.05000000","0.00014000"],["79778.09000000","0.00008000"],["79778.00000000","0.03400000"],["79776.66000000","0.00012000"],["79762.50000000","0.00000000"],["79750.52000000","1.24175000"],["79750.42000000","0.00000000"],["79750.01000000","0.00311000"],["79748.62000000","0.00000000"],["79746.37000000","0.00007000"],["79745.30000000","0.11895000"],["79738.18000000","0.00008000"],["79726.71000000","1.87677000"],["79722.24000000","0.00000000"],["79706.27000000","0.00000000"],["79668.62000000","0.00000000"],["79658.36000000","0.00008000"],["79658.29000000","0.01962000"],["79584.00000000","0.00007000"],["71841.96000000","0.00000000"],["71841.00000000","0.00010000"],["71836.20000000","0.00008000"],["63859.52000000","0.00031000"]],"a":[["79818.01000000","3.41978000"],["79818.02000000","0.00027000"],["79818.03000000","0.00013000"],["79818.10000000","0.00000000"],["79818.54000000","0.45246000"],["79818.55000000","0.00021000"],["79818.75000000","0.00014000"],["79819.03000000","0.00021000"],["79819.61000000","0.00000000"],["79819.83000000","0.00000000"],["79819.90000000","0.00000000"],["79820.01000000","0.00021000"],["79820.18000000","0.00000000"],["79820.40000000","0.00000000"],["79820.56000000","0.04025000"],["79820.73000000","0.00000000"],["79820.77000000","0.05057000"],["79821.03000000","0.00000000"],["79821.16000000","0.00000000"],["79821.21000000","0.00000000"],["79821.52000000","0.00400000"],["79821.61000000","0.00000000"],["79821.77000000","0.00000000"],["79822.01000000","0.00000000"],["79822.38000000","0.00400000"],["79822.45000000","0.00026000"],["79822.56000000","0.00250000"],["79822.62000000","0.00014000"],["79822.82000000","0.20631000"],["79823.53000000","0.00000000"],["79823.68000000","0.00000000"],["79824.00000000","0.00007000"],["79824.01000000","0.06205000"],["79824.02000000","0.00000000"],["79824.39000000","2.99852000"],["79824.40000000","2.13328000"],["79824.41000000","0.00000000"],["79824.42000000","0.00000000"],["79824.43000000","0.00000000"],["79825.19000000","0.01200000"],["79825.20000000","0.00014000"],["79825.22000000","2.31753000"],["79825.99000000","0.00008000"],["79826.00000000","0.36586000"],["79826.50000000","0.02200000"],["79827.18000000","0.00000000"],["79827.78000000","0.02624000"],["79827.99000000","0.00014000"],["79828.01000000","0.26667000"],["79828.44000000","0.00015000"],["79829.55000000","0.02000000"],["79829.93000000","0.00010000"],["79829.98000000","0.00000000"],["79830.01000000","0.60525000"],["79830.22000000","0.00007000"],["79830.25000000","0.07122000"],["79830.26000000","0.44973000"],["79831.63000000","0.00007000"],["79831.92000000","0.00407000"],["79833.20000000","0.00000000"],["79833.25000000","0.44414000"],["79833.81000000","0.00007000"],["79833.97000000","0.00008000"],["79833.98000000","0.00000000"],["79834.53000000","0.56261000"],["79836.85000000","0.00000000"],["79837.75000000","0.00626000"],["79837.76000000","0.00000000"],["79837.96000000","0.00008000"],["79837.99000000","0.35456000"],["79838.01000000","0.13519000"],["79840.39000000","0.62659000"],["79841.19000000","0.00000000"],["79841.20000000","0.00000000"],["79841.96000000","0.00008000"],["79844.00000000","0.01200000"],["79844.98000000","0.00000000"],["79845.18000000","0.00000000"],["79845.83000000","0.42983000"],["79845.95000000","0.00015000"],["79845.99000000","0.00000000"],["79846.01000000","0.21570000"],["79846.66000000","0.00125000"],["79846.83000000","0.00000000"],["79846.99000000","0.62635000"],["79847.00000000","0.00000000"],["79848.00000000","1.90276000"],["79849.17000000","0.00000000"],["79849.59000000","0.00000000"],["79849.94000000","0.00008000"],["79850.49000000","0.00000000"],["79850.89000000","0.00000000"],["79853.16000000","0.00000000"],["79853.78000000","0.00012000"],["79853.93000000","0.00008000"],["79857.15000000","0.00000000"],["79857.92000000","0.00008000"],["79860.71000000","0.00000000"],["79861.14000000","0.00000000"],["79861.32000000","0.00000000"],["79863.23000000","0.00000000"],["79865.13000000","0.00000000"],["79885.83000000","0.00310000"],["79887.48000000","0.00000000"],["79893.45000000","0.00000000"],["79894.26000000","0.00000000"],["79897.83000000","0.00008000"],["79902.86000000","0.00000000"],["79910.09000000","0.00000000"],["79916.97000000","0.00000000"],["79944.51000000","0.00018000"],["79949.49000000","0.00000000"],["79977.65000000","0.00008000"],["79989.53000000","0.00000000"],["79989.92000000","0.00000000"],["80057.46000000","0.00008000"],["80069.75000000","0.00000000"],["80071.32000000","0.00000000"],["80121.75000000","0.00000000"],["80217.10000000","0.00008000"],["80217.72000000","0.00000000"],["80229.41000000","0.00000000"],["80376.74000000","0.00008000"],["80389.07000000","0.00000000"],["80456.55000000","0.00008000"],["80468.90000000","0.00000000"]]}}}
{"rx_ns": 13995909275300, "frame": {"stream":"btcusdt@depth@100ms","data":{"e":"depthUpdate","E":1787650991114,"s":"BTCUSDT","U":99118701971,"u":99118702320,"b":[["79818.00000000","0.78734000"],["79817.99000000","0.00063000"],["79817.36000000","0.00000000"],["79817.35000000","0.00000000"],["79817.31000000","0.00000000"],["79817.30000000","0.00007000"],["79817.27000000","0.00000000"],["79817.26000000","0.00014000"],["79816.72000000","0.00000000"],["79816.71000000","0.00000000"],["79816.45000000","0.00710000"],["79816.32000000","0.00000000"],["79816.31000000","0.00007000"],["79816.01000000","0.00007000"],["79816.00000000","0.02421000"],["79815.99000000","0.00000000"],["79815.98000000","0.00021000"],["79815.53000000","0.00946000"],["79815.44000000","0.00000000"],["79814.82000000","0.00007000"],["79814.26000000","0.00000000"],["79814.01000000","0.00014000"],["79814.00000000","0.02428000"],["79813.60000000","0.00007000"],["79813.59000000","0.06185000"],["79813.06000000","0.00000000"],["79812.97000000","0.00007000"],["79812.96000000","0.05898000"],["79812.50000000","0.00007000"],["79812.49000000","0.06185000"],["79812.48000000","0.31352000"],["79812.02000000","0.00013000"],["79812.01000000","0.00000000"],["79812.00000000","0.02428000"],["79811.71000000","0.00007000"],["79811.70000000","0.06178000"],["79811.49000000","0.00000000"],["79811.38000000","0.00000000"],["79811.37000000","0.01007000"],["79811.33000000","0.00007000"],["79811.32000000","0.06192000"],["79811.28000000","0.00000000"],["79811.04000000","0.00000000"],["79810.68000000","0.00031000"],["79809.70000000","0.01499000"],["79809.65000000","0.00000000"],["79808.91000000","0.00070000"],["79807.93000000","0.02200000"],["79807.85000000","0.02400000"],["79806.88000000","0.00400000"],["79805.54000000","0.02400000"],["79804.99000000","0.08566000"],["79803.97000000","0.00000000"],["79803.54000000","0.00800000"],["79802.80000000","0.00007000"],["79801.98000000","0.00000000"],["79795.12000000","0.62891000"],["79793.99000000","0.00000000"],["79788.01000000","0.45781000"],["79783.59000000","0.48019000"],["79776.66000000","0.00000000"],["79775.87000000","0.65459000"],["79775.07000000","0.49660000"],["79773.47000000","0.00000000"],["79765.48000000","0.06586000"],["79765.36000000","0.00000000"],["79762.50000000","1.61014000"],["79762.30000000","0.82427000"],["79762.27000000","0.00000000"],["79762.03000000","0.00627000"],["79759.70000000","0.45198000"],["79759.54000000","0.00000000"],["79758.02000000","0.00000000"],["79758.01000000","0.00000000"],["79755.81000000","0.00008000"],["79750.92000000","0.02400000"],["79750.70000000","0.93344000"],["79748.07000000","0.00310000"],["79746.05000000","0.00312000"],["79745.30000000","0.00000000"],["79745.12000000","0.00000000"],["79744.73000000","0.12410000"],["79744.49000000","0.02400000"],["79744.44000000","0.02200000"],["79743.25000000","0.00112000"],["79739.36000000","1.08540000"],["79738.01000000","0.00000000"],["79733.52000000","0.67241000"],["79732.01000000","1.11022000"],["79726.72000000","0.00000000"],["79726.70000000","0.00000000"],["79722.51000000","0.00400000"],["79700.01000000","0.00000000"],["79688.21000000","0.00000000"],["79660.65000000","0.00000000"],["79642.41000000","1.20000000"],["79592.56000000","0.00007000"],["79588.57000000","0.00007000"],["71841.00000000","0.00000000"],["71836.20000000","0.00040000"]],"a":[["79818.01000000","2.47356000"],["79818.53000000","0.00007000"],["79818.54000000","0.27203000"],["79818.55000000","0.00007000"],["79819.03000000","0.00007000"],["79820.01000000","0.00007000"],["79820.55000000","0.00007000"],["79820.56000000","0.04046000"],["79820.76000000","0.00007000"],["79820.77000000","0.05092000"],["79822.42000000","0.06178000"],["79822.80000000","0.00000000"],["79822.81000000","0.06178000"],["79822.82000000","0.20652000"],["79823.68000000","0.05619000"],["79823.99000000","0.00013000"],["79824.01000000","0.00014000"],["79824.31000000","0.06185000"],["79824.38000000","0.06178000"],["79824.39000000","1.47619000"],["79824.40000000","2.06729000"],["79824.46000000","0.20257000"],["79825.20000000","0.00000000"],["79825.21000000","1.12439000"],["79825.22000000","2.30441000"],["79826.01000000","0.00014000"],["79826.50000000","0.00000000"],["79827.78000000","0.00000000"],["79827.98000000","0.00007000"],["79828.01000000","0.26654000"],["79829.06000000","0.00007000"],["79829.64000000","0.08976000"],["79829.83000000","0.00000000"],["79830.00000000","1.42529000"],["79830.01000000","0.60518000"],["79830.02000000","0.04657000"],["79830.25000000","0.07115000"],["79830.26000000","0.44959000"],["79830.45000000","0.00000000"],["79831.97000000","0.00007000"],["79833.05000000","0.00000000"],["79833.24000000","0.00000000"],["79833.81000000","0.00000000"],["79834.30000000","0.00000000"],["79834.74000000","0.00007000"],["79834.86000000","0.02000000"],["79834.93000000","0.02000000"],["79836.51000000","0.11541000"],["79837.24000000","0.02000000"],["79838.51000000","0.10379000"],["79841.81000000","0.00000000"],["79842.17000000","0.00250000"],["79842.57000000","0.00000000"],["79844.56000000","0.00000000"],["79846.02000000","0.33823000"],["79849.89000000","0.00000000"],["79850.00000000","0.11800000"],["79853.78000000","0.00000000"],["79854.36000000","0.65395000"],["79855.59000000","0.00000000"],["79858.00000000","1.91077000"],["79858.11000000","1.20254000"],["79859.99000000","0.53871000"],["79864.98000000","0.00000000"],["79865.00000000","0.00000000"],["79880.35000000","0.41998000"],["79881.21000000","0.00000000"],["79885.83000000","0.00622000"],["79899.98000000","0.48238000"],["79902.10000000","0.00000000"],["79905.98000000","0.00000000"],["79907.81000000","1.47528000"],["79916.05000000","0.00000000"],["79917.43000000","0.15661000"],["79925.78000000","0.62854000"],["79934.70000000","0.56045000"],["79937.07000000","0.17686000"],["79944.14000000","0.19148000"],["79944.15000000","0.25000000"],["79945.22000000","0.00000000"],["79947.99000000","0.08822000"],["79950.55000000","0.00000000"],["79959.65000000","0.04633000"],["79963.99000000","0.46379000"],["79965.38000000","0.00125000"],["79986.64000000","0.00000000"],["79995.99000000","0.00000000"],["80047.77000000","0.00000000"],["80051.76000000","0.00000000"],["80053.81000000","0.00000000"]]}}}
{"rx_ns": 13995991512000, "frame": {"stream":"btcusdt@depth@100ms","data":{"e":"depthUpdate","E":1787650991214,"s":"BTCUSDT","U":99118702321,"u":99118702461,"b":[["79818.00000000","0.90302000"],["79817.99000000","0.00063000"],["79817.30000000","0.00000000"],["79817.26000000","0.00000000"],["79816.00000000","0.02421000"],["79815.98000000","0.00007000"],["79815.54000000","0.00000000"],["79814.03000000","0.00000000"],["79814.00000000","0.02428000"],["79813.59000000","0.06199000"],["79812.96000000","0.05912000"],["79812.49000000","0.06199000"],["79812.48000000","0.31359000"],["79812.25000000","0.00538000"],["79812.00000000","0.02421000"],["79811.92000000","0.00007000"],["79811.91000000","0.12529000"],["79811.01000000","0.00014000"],["79810.97000000","0.00898000"],["79809.69000000","0.01077000"],["79808.41000000","0.01077000"],["79807.42000000","0.00000000"],["79807.41000000","0.00250000"],["79807.14000000","0.00014000"],["79805.66000000","0.00156000"],["79803.92000000","0.12530000"],["79803.65000000","0.02415000"],["79790.88000000","0.00400000"],["79774.54000000","0.00400000"],["79770.27000000","0.00012000"],["79744.73000000","0.00000000"],["79744.44000000","0.00000000"],["79744.36000000","0.00000000"],["79696.53000000","0.00000000"],["79690.75000000","0.00000000"],["79689.34000000","0.00012000"],["79680.59000000","0.00000000"],["79673.90000000","0.00654000"],["79501.20000000","0.00007000"],["78620.73000000","0.00030000"],["71841.00000000","0.00000000"],["71836.20000000","0.00056000"],["63859.52000000","0.00000000"]],"a":[["79818.01000000","2.48688000"],["79818.54000000","0.27210000"],["79818.55000000","0.00000000"],["79819.03000000","0.00000000"],["79819.28000000","0.00007000"],["79819.29000000","0.02233000"],["79820.01000000","0.00000000"],["79820.56000000","0.04060000"],["79820.57000000","0.02680000"],["79820.77000000","0.05099000"],["79821.84000000","0.00007000"],["79821.85000000","0.02680000"],["79822.41000000","0.00007000"],["79822.42000000","0.06192000"],["79822.81000000","0.06192000"],["79822.82000000","0.20652000"],["79823.47000000","0.00400000"],["79823.68000000","0.05633000"],["79824.01000000","0.00000000"],["79824.39000000","1.27369000"],["79824.40000000","2.06715000"],["79824.46000000","0.00007000"],["79825.19000000","0.01207000"],["79825.36000000","0.00909000"],["79827.12000000","0.00007000"],["79827.87000000","0.12526000"],["79827.99000000","0.00007000"],["79828.01000000","0.26647000"],["79828.29000000","0.00000000"],["79829.06000000","0.00000000"],["79829.34000000","0.00007000"],["79831.42000000","0.00007000"],["79834.83000000","0.02000000"],["79843.83000000","0.12524000"],["79846.89000000","0.00000000"],["79847.39000000","0.00012000"],["79849.18000000","0.00000000"],["79854.36000000","0.95395000"],["79854.75000000","0.00000000"],["79860.20000000","0.00000000"],["79899.26000000","0.00000000"],["79941.82000000","0.00000000"],["79944.51000000","0.00000000"],["79948.67000000","0.00000000"],["79951.28000000","0.00000000"],["81021.77000000","0.00000000"]]}}}
{"rx_ns": 13996091645600, "frame": {"stream":"btcusdt@depth@100ms","data":{"e":"depthUpdate","E":1787650991314,"s":"BTCUSDT","U":99118702462,"u":99118702546,"b":[["79818.00000000","0.90351000"],["79816.40000000","0.00000000"],["79812.48000000","0.31345000"],["79812.00000000","0.02414000"],["79811.71000000","0.00000000"],["79811.70000000","0.00000000"],["79811.33000000","0.00000000"],["79811.32000000","0.00014000"],["79811.31000000","0.41543000"],["79811.28000000","0.00007000"],["79810.43000000","0.00000000"],["79810.01000000","0.00052000"],["79808.45000000","0.00000000"],["79808.42000000","0.00000000"],["79807.41000000","0.00000000"],["79806.26000000","0.00007000"],["79805.75000000","0.00250000"],["79802.03000000","0.00052000"],["79800.44000000","0.00000000"],["79795.12000000","0.60993000"],["79792.46000000","0.00000000"],["79790.27000000","0.00000000"],["79787.70000000","0.00000000"],["79777.84000000","0.01163000"],["79743.99000000","0.12334000"],["79737.42000000","0.00000000"],["79726.72000000","0.47586000"],["79717.44000000","0.00025000"],["79602.82000000","0.00400000"],["79592.52000000","0.00007000"],["79582.89000000","0.00100000"],["79576.56000000","0.00007000"],["71836.20000000","0.00072000"],["63854.00000000","0.00015000"]],"a":[["79818.01000000","2.48688000"],["79818.54000000","0.27210000"],["79819.29000000","0.02247000"],["79819.74000000","0.00007000"],["79820.56000000","0.04060000"],["79820.57000000","0.02694000"],["79820.77000000","0.05099000"],["79821.71000000","0.00250000"],["79821.85000000","0.02701000"],["79822.35000000","0.06080000"],["79822.41000000","0.00000000"],["79822.56000000","0.00000000"],["79822.81000000","0.00014000"],["79822.82000000","0.20645000"],["79823.59000000","0.06080000"],["79823.68000000","0.05619000"],["79824.31000000","0.06178000"],["79824.38000000","0.00000000"],["79826.13000000","0.00000000"],["79844.99000000","0.00000000"],["79846.80000000","0.00000000"],["79846.85000000","0.00000000"],["79869.56000000","0.00100000"],["79887.58000000","0.01710000"],["79901.73000000","0.00000000"],["79916.99000000","0.00025000"],["79937.01000000","0.00000000"],["80197.48000000","0.01508000"],["80260.76000000","0.00000000"],["80297.93000000","0.00000000"]]}}}
{"rx_ns": 13996193346500, "frame": {"stream":"btcusdt@depth@100ms","data":{"e":"depthUpdate","E":1787650991414,"s":"BTCUSDT","U":99118702547,"u":99118702582,"b":[["79818.00000000","0.90321000"],["79794.05000000","0.00060000"],["79789.81000000","0.00000000"],["79788.42000000","0.09512000"],["79786.07000000","0.00060000"],["79776.71000000","0.00626000"],["79761.63000000","0.00335000"],["79744.49000000","0.00000000"],["79743.99000000","0.00000000"],["79743.95000000","0.12092000"],["79682.56000000","0.00018000"],["71836.20000000","0.00104000"]],"a":[["79820.77000000","0.05092000"],["79821.85000000","0.02701000"],["79822.35000000","0.06094000"],["79822.42000000","0.06192000"],["79822.81000000","0.00000000"],["79824.39000000","2.04902000"],["79824.40000000","2.07435000"],["79833.97000000","0.00015000"],["79849.00000000","0.70000000"],["79854.33000000","0.30000000"],["79857.43000000","0.00000000"],["79861.28000000","0.09216000"],["79886.29000000","0.00625000"],["79890.00000000","0.02400000"],["79897.30000000","0.00000000"]]}}}
{"rx_ns": 13996294963100, "frame": {"stream":"btcusdt@depth@100ms","data":{"e":"depthUpdate","E":1787650991514,"s":"BTCUSDT","U":99118702583,"u":99118702664,"b":[["79818.00000000","1.12413000"],["79817.99000000","0.00084000"],["79815.53000000","0.00960000"],["79815.34000000","0.00202000"],["79815.17000000","0.00007000"],["79815.16000000","0.33829000"],["79814.29000000","0.00007000"],["79814.28000000","0.00000000"],["79814.00000000","0.02435000"],["79813.67000000","0.00007000"],["79813.66000000","0.06080000"],["79813.60000000","0.00000000"],["79813.59000000","0.00021000"],["79812.97000000","0.00007000"],["79812.50000000","0.00007000"],["79812.49000000","0.06199000"],["79811.92000000","0.00007000"],["79811.32000000","0.00007000"],["79811.28000000","0.00000000"],["79807.72000000","0.00007000"],["79795.71000000","0.12532000"],["79730.65000000","0.62625000"],["79674.63000000","0.00400000"],["63854.40000000","0.00031000"]],"a":[["79818.01000000","2.81636000"],["79821.52000000","0.00000000"],["79822.34000000","0.00000000"],["79822.35000000","0.00014000"],["79822.41000000","0.00000000"],["79822.42000000","0.00014000"],["79822.70000000","0.00400000"],["79822.81000000","0.00007000"],["79822.82000000","0.20638000"],["79823.59000000","0.00000000"],["79823.68000000","0.00007000"],["79824.30000000","0.00000000"],["79824.38000000","0.00000000"],["79831.00000000","0.00007000"],["79838.01000000","0.11014000"],["79846.52000000","0.00000000"],["79887.98000000","0.32833000"],["79934.60000000","0.00012000"]]}}}
{"rx_ns": 13996391001800, "frame": {"stream":"btcusdt@depth@100ms","data":{"e":"depthUpdate","E":1787650991614,"s":"BTCUSDT","U":99118702665,"u":99118702708,"b":[["79818.00000000","1.12406000"],["79817.99000000","0.00077000"],["79815.53000000","0.00953000"],["79815.16000000","0.33843000"],["79814.29000000","0.00000000"],["79814.00000000","0.02435000"],["79813.59000000","0.00007000"],["79811.32000000","0.00014000"],["71836.20000000","0.00136000"],["63854.40000000","0.00000000"],["63854.00000000","0.00215000"]],"a":[["79820.77000000","0.05085000"],["79821.85000000","0.02694000"],["79822.35000000","0.00000000"],["79822.42000000","0.00000000"],["79822.82000000","0.20652000"],["79824.31000000","0.06192000"],["79826.00000000","0.37086000"],["79828.00000000","1.15529000"],["79830.00000000","1.43029000"],["79838.01000000","0.06004000"]]}}}
{"rx_ns": 13996496174800, "frame": {"stream":"btcusdt@depth@100ms","data":{"e":"depthUpdate","E":1787650991714,"s":"BTCUSDT","U":99118702709,"u":99118702737,"b":[["79749.31000000","0.02000000"],["71836.20000000","0.00152000"],["63854.40000000","0.00000000"],["63854.00000000","0.00015000"]],"a":[["79826.00000000","0.37210000"],["79828.00000000","1.16229000"],["79830.00000000","1.43729000"],["79832.00000000","0.01207000"],["79834.00000000","1.42725000"],["79836.00000000","0.96753000"],["79838.00000000","1.06839000"],["79840.00000000","0.11801000"],["79842.00000000","0.02400000"],["79844.00000000","0.02400000"],["79846.00000000","0.02800000"],["79900.92000000","0.00400000"],["79902.04000000","0.02000000"],["79937.29000000","0.00018000"],["79941.46000000","0.00031000"],["81000.00000000","31.68359000"]]}}}
{"rx_ns": 13996599231400, "frame": {"stream":"btcusdt@depth@100ms","data":{"e":"depthUpdate","E":1787650991814,"s":"BTCUSDT","U":99118702738,"u":99118703138,"b":[["79818.00000000","1.79673000"],["79817.99000000","0.00084000"],["79817.74000000","0.00000000"],["79817.39000000","0.00000000"],["79817.38000000","0.00007000"],["79816.78000000","0.00007000"],["79816.77000000","0.00656000"],["79816.76000000","0.00000000"],["79816.45000000","0.00710000"],["79816.15000000","0.00000000"],["79816.14000000","0.00000000"],["79816.00000000","0.02421000"],["79815.68000000","0.00000000"],["79815.55000000","0.00000000"],["79815.54000000","0.00000000"],["79815.53000000","0.00960000"],["79815.34000000","0.00000000"],["79815.18000000","0.00007000"],["79815.17000000","0.48737000"],["79815.16000000","0.00014000"],["79814.88000000","0.00014000"],["79814.29000000","0.00013000"],["79814.28000000","0.00000000"],["79814.01000000","0.00007000"],["79813.95000000","0.00400000"],["79813.68000000","0.00007000"],["79813.67000000","1.04939000"],["79813.66000000","0.00007000"],["79813.62000000","0.00000000"],["79813.61000000","0.03224000"],["79813.06000000","0.00019000"],["79813.05000000","0.00000000"],["79813.04000000","0.00000000"],["79812.97000000","0.00000000"],["79812.96000000","0.00014000"],["79812.87000000","0.00000000"],["79812.76000000","0.00000000"],["79812.50000000","0.00000000"],["79812.49000000","0.00021000"],["79812.48000000","0.31331000"],["79812.00000000","0.02400000"],["79811.92000000","0.00007000"],["79811.59000000","0.00000000"],["79811.39000000","0.00000000"],["79811.37000000","0.01000000"],["79811.32000000","0.00000000"],["79811.31000000","0.92462000"],["79810.68000000","0.00000000"],["79810.04000000","0.00250000"],["79809.56000000","1.87677000"],["79808.91000000","0.00000000"],["79808.28000000","0.00000000"],["79806.88000000","0.00000000"],["79806.68000000","0.25166000"],["79806.67000000","0.36586000"],["79806.66000000","0.00000000"],["79805.75000000","0.00000000"],["79800.01000000","0.25078000"],["79799.96000000","0.00007000"],["79795.61000000","0.33845000"],["79794.60000000","0.00000000"],["79786.63000000","0.00000000"],["79779.45000000","1.24123000"],["79777.62000000","0.00400000"],["79776.18000000","0.00000000"],["79775.28000000","0.00000000"],["79774.54000000","0.00000000"],["79750.72000000","0.96244000"],["79750.70000000","0.00000000"],["79750.52000000","0.00007000"],["79599.03000000","0.00000000"],["79589.96000000","0.00771000"],["71836.20000000","0.00152000"],["63854.00000000","0.00015000"]],"a":[["79818.01000000","2.08130000"],["79818.54000000","0.13445000"],["79821.71000000","0.00000000"],["79822.38000000","0.00000000"],["79822.45000000","0.00000000"],["79822.70000000","0.00000000"],["79822.81000000","0.00007000"],["79822.82000000","0.20666000"],["79824.13000000","0.00000000"],["79824.20000000","0.00007000"],["79824.21000000","0.06087000"],["79824.24000000","0.00000000"],["79824.30000000","0.00000000"],["79824.31000000","0.00014000"],["79824.37000000","0.00007000"],["79824.38000000","0.06087000"],["79824.39000000","1.00850000"],["79824.40000000","0.19758000"],["79824.84000000","0.00000000"],["79825.22000000","0.42764000"],["79825.79000000","0.00400000"],["79826.00000000","0.57717000"],["79826.20000000","0.00000000"],["79827.72000000","0.00000000"],["79827.95000000","0.00192000"],["79829.65000000","0.00400000"],["79829.99000000","1.87677000"],["79833.98000000","0.19019000"],["79839.46000000","0.00000000"],["79854.46000000","0.33820000"],["79871.55000000","0.51636000"],["79904.47000000","1.55815000"],["79906.72000000","2.31342000"],["81015.29000000","0.00030000"]]}}}
{"rx_ns": 13996700443100, "frame": {"stream":"btcusdt@depth@100ms","data":{"e":"depthUpdate","E":1787650991914,"s":"BTCUSDT","U":99118703139,"u":99118703323,"b":[["79818.00000000","1.79679000"],["79817.99000000","0.00077000"],["79816.78000000","0.00000000"],["79816.77000000","0.00670000"],["79816.45000000","0.00724000"],["79816.16000000","0.00007000"],["79816.15000000","0.01905000"],["79816.14000000","0.00000000"],["79816.00000000","0.02428000"],["79815.55000000","0.00007000"],["79815.54000000","0.00000000"],["79815.53000000","0.00953000"],["79815.43000000","0.00000000"],["79815.19000000","0.00007000"],["79815.18000000","0.00007000"],["79815.17000000","0.48751000"],["79815.16000000","0.00000000"],["79814.81000000","0.00000000"],["79814.25000000","0.00000000"],["79814.01000000","0.00007000"],["79814.00000000","0.02435000"],["79813.69000000","0.00000000"],["79813.68000000","0.00007000"],["79813.61000000","0.03231000"],["79813.59000000","0.00000000"],["79812.96000000","0.00000000"],["79812.49000000","0.00007000"],["79812.48000000","0.31338000"],["79812.25000000","0.00545000"],["79812.00000000","0.02407000"],["79811.92000000","0.00007000"],["79811.32000000","0.00000000"],["79810.95000000","0.00250000"],["79810.04000000","0.00000000"],["79809.57000000","0.01200000"],["79803.54000000","0.00000000"],["79803.53000000","0.00800000"],["79794.33000000","0.00000000"],["79754.43000000","0.00000000"],["79749.27000000","0.04400000"],["79722.51000000","0.00000000"],["79674.63000000","0.00000000"],["79602.82000000","0.00000000"],["71836.20000000","0.00168000"]],"a":[["79818.01000000","1.58046000"],["79818.75000000","0.00007000"],["79818.94000000","0.00007000"],["79822.81000000","0.06087000"],["79822.82000000","0.20666000"],["79823.58000000","0.00007000"],["79823.59000000","0.06080000"],["79823.68000000","0.00000000"],["79823.69000000","0.00026000"],["79824.20000000","0.00007000"],["79824.21000000","0.06108000"],["79824.31000000","0.00000000"],["79824.37000000","0.02007000"],["79824.38000000","0.06080000"],["79825.15000000","0.00000000"],["79825.19000000","0.00007000"],["79825.21000000","1.04939000"],["79825.79000000","0.00000000"],["79826.00000000","0.57467000"],["79826.22000000","0.00000000"],["79826.34000000","0.00400000"],["79826.35000000","0.00000000"],["79826.37000000","0.00000000"],["79826.42000000","0.00000000"],["79826.91000000","0.00250000"],["79827.81000000","0.00187000"],["79827.95000000","0.00000000"],["79828.22000000","0.00000000"],["79828.91000000","0.00400000"],["79829.65000000","0.00000000"],["79830.00000000","1.26078000"],["79836.01000000","0.47049000"],["79846.00000000","0.02400000"],["79847.98000000","0.00000000"],["79854.46000000","0.63820000"],["79854.68000000","0.00000000"],["79860.98000000","0.00000000"],["79893.44000000","0.02000000"],["79894.25000000","0.02000000"],["79900.92000000","0.00000000"],["79902.87000000","0.02000000"],["79903.73000000","0.02000000"],["79932.86000000","0.00000000"],["79980.78000000","0.00000000"],["80052.65000000","0.00000000"],["80217.72000000","0.00007000"]]}}}
{"rx_ns": 13996795469000, "frame": {"stream":"btcusdt@depth20","data":{"lastUpdateId":99118703401,"bids":[["79818.00000000","1.79602000"],["79817.99000000","0.00070000"],["79817.38000000","0.00007000"],["79817.29000000","0.00007000"],["79816.90000000","0.00007000"],["79816.77000000","0.00670000"],["79816.66000000","0.00007000"],["79816.45000000","0.00710000"],["79816.31000000","0.00007000"],["79816.30000000","0.00007000"],["79816.01000000","0.00007000"],["79816.00000000","0.02421000"],["79815.98000000","0.00007000"],["79815.53000000","0.00953000"],["79815.48000000","0.00007000"],["79815.18000000","0.00007000"],["79815.17000000","0.48751000"],["79814.88000000","0.00014000"],["79814.82000000","0.00007000"],["79814.01000000","0.00014000"]],"asks":[["79818.01000000","1.58059000"],["79818.02000000","0.00027000"],["79818.03000000","0.00013000"],["79818.53000000","0.00007000"],["79818.54000000","0.19405000"],["79818.75000000","0.00007000"],["79818.94000000","0.00007000"],["79819.28000000","0.00007000"],["79819.29000000","0.02247000"],["79819.74000000","0.00007000"],["79820.55000000","0.00007000"],["79820.56000000","0.04060000"],["79820.57000000","0.02694000"],["79820.76000000","0.00007000"],["79820.77000000","0.05085000"],["79821.84000000","0.00007000"],["79821.85000000","0.02701000"],["79822.62000000","0.00014000"],["79822.80000000","0.00007000"],["79822.81000000","0.06101000"]]}}}
{"rx_ns": 13996795655100, "frame": {"stream":"btcusdt@depth@100ms","data":{"e":"depthUpdate","E":1787650992014,"s":"BTCUSDT","U":99118703324,"u":99118703401,"b":[["79818.00000000","1.79602000"],["79817.99000000","0.00070000"],["79816.45000000","0.00710000"],["79816.16000000","0.00000000"],["79816.15000000","0.00000000"],["79816.00000000","0.02421000"],["79815.55000000","0.00000000"],["79815.19000000","0.00000000"],["79814.29000000","0.00000000"],["79814.01000000","0.00014000"],["79813.62000000","0.00014000"],["79813.07000000","0.00626000"],["79811.91000000","0.12536000"],["79811.32000000","0.00007000"],["79810.98000000","0.00626000"],["79805.77000000","0.00000000"],["79803.36000000","0.00400000"],["79779.96000000","0.00400000"],["79779.48000000","0.00000000"],["79777.62000000","0.00000000"],["79678.29000000","0.00000000"],["79677.63000000","0.00000000"],["79670.59000000","0.00125000"],["79668.90000000","0.00125000"],["71836.20000000","0.00184000"],["63854.40000000","0.00031000"]],"a":[["79818.01000000","1.58059000"],["79818.54000000","0.19405000"],["79821.85000000","0.02701000"],["79822.80000000","0.00007000"],["79822.81000000","0.06101000"],["79822.82000000","0.20666000"],["79823.09000000","0.03806000"],["79823.58000000","0.00007000"],["79823.59000000","0.06087000"],["79823.93000000","0.00000000"],["79824.20000000","0.00000000"],["79824.21000000","0.06094000"],["79824.37000000","0.02000000"],["79826.01000000","0.00007000"],["79827.80000000","0.00626000"],["79827.99000000","0.00000000"],["79964.77000000","0.00125000"],["79994.54000000","0.00000000"]]}}}
{"rx_ns": 13996891427800, "frame": {"stream":"btcusdt@depth@100ms","data":{"e":"depthUpdate","E":1787650992114,"s":"BTCUSDT","U":99118703402,"u":99118703431,"b":[["79818.00000000","1.79595000"],["79816.45000000","0.00710000"],["79813.67000000","1.04953000"],["79813.61000000","0.03238000"],["79811.37000000","0.01007000"],["79802.80000000","0.00007000"],["79662.62000000","0.00400000"],["71836.20000000","0.00160000"],["71836.19000000","0.00008000"]],"a":[["79818.01000000","1.57963000"],["79822.82000000","0.20673000"],["79823.08000000","0.00007000"],["79823.59000000","0.06080000"],["79824.38000000","0.25099000"],["79825.22000000","0.42757000"],["79826.01000000","0.00000000"],["79833.98000000","0.00000000"],["79834.74000000","0.00007000"],["79899.25000000","0.02000000"],["79902.09000000","0.02000000"]]}}}
{"rx_ns": 13997001545200, "frame": {"stream":"btcusdt@depth@100ms","data":{"e":"depthUpdate","E":1787650992214,"s":"BTCUSDT","U":99118703432,"u":99118703446,"b":[["79818.00000000","1.79595000"],["79816.77000000","0.00014000"],["79816.31000000","0.00674000"],["79813.62000000","0.00000000"],["79813.08000000","0.00015000"],["78620.73000000","0.00030000"],["71836.20000000","0.00192000"],["63854.40000000","0.00000000"]],"a":[["79818.01000000","1.58459000"],["79827.27000000","0.00007000"],["79833.49000000","0.00007000"],["80232.65000000","0.00000000"],["80553.03000000","0.00000000"]]}}}
{"rx_ns": 13997092025200, "frame": {"stream":"btcusdt@depth@100ms","data":{"e":"depthUpdate","E":1787650992314,"s":"BTCUSDT","U":99118703447,"u":99118703478,"b":[["79818.00000000","1.79588000"],["79817.99000000","0.00070000"],["79817.38000000","0.00000000"],["79816.77000000","0.00000000"],["79816.45000000","0.00710000"],["79816.31000000","0.00688000"],["79813.95000000","0.00000000"],["79813.04000000","0.00400000"],["79593.65000000","0.00771000"],["79589.96000000","0.00000000"],["71836.20000000","0.00192000"],["71836.00000000","0.00000000"],["63854.00000000","0.00015000"]],"a":[["79888.88000000","0.00400000"]]}}}
{"rx_ns": 13997191499200, "frame": {"stream":"btcusdt@depth@100ms","data":{"e":"depthUpdate","E":1787650992414,"s":"BTCUSDT","U":99118703479,"u":99118703484,"b":[["79818.00000000","1.79596000"],["79790.00000000","0.12051000"],["71836.20000000","0.00208000"]],"a":[["79850.00000000","0.12051000"]]}}}
{"rx_ns": 13997291449700, "frame": {"stream":"btcusdt@depth@100ms","data":{"e":"depthUpdate","E":1787650992514,"s":"BTCUSDT","U":99118703485,"u":99118703497,"b":[["79818.00000000","1.79598000"],["79816.31000000","0.00021000"],["79790.00000000","0.82051000"],["79745.04000000","0.02088000"],["65146.32000000","0.00000000"],["63854.40000000","0.00031000"]],"a":[["79824.21000000","0.06101000"],["79824.36000000","0.19019000"],["79824.38000000","0.06080000"],["79826.00000000","0.57460000"],["79833.98000000","0.00000000"],["79848.00000000","1.90209000"],["80040.59000000","0.00400000"]]}}}
{"rx_ns": 13997391488400, "frame": {"stream":"btcusdt@depth@100ms","data":{"e":"depthUpdate","E":1787650992614,"s":"BTCUSDT","U":99118703498,"u":99118703526,"b":[["79818.00000000","1.79604000"],["79817.99000000","0.00083000"],["79817.98000000","0.00013000"],["79816.45000000","0.00710000"],["79816.31000000","0.00007000"],["79813.61000000","0.03252000"],["79745.04000000","0.00000000"],["71836.20000000","0.00224000"],["63854.40000000","0.00000000"]],"a":[["79818.01000000","1.65964000"]]}}}
{"rx_ns": 13997492708500, "frame": {"stream":"btcusdt@depth@100ms","data":{"e":"depthUpdate","E":1787650992714,"s":"BTCUSDT","U":99118703527,"u":99118703561,"b":[["79818.00000000","1.59347000"],["79813.61000000","0.03245000"],["79813.07000000","0.00000000"],["79813.04000000","0.00000000"],["79811.91000000","0.12543000"],["79811.83000000","0.00400000"],["79811.61000000","0.00626000"],["79810.98000000","0.00000000"],["79810.07000000","0.00626000"],["79809.57000000","0.00000000"],["79805.40000000","0.01200000"],["79788.01000000","0.15268000"],["79787.00000000","0.00000000"],["79710.49000000","0.00400000"],["71836.20000000","0.00240000"],["63854.40000000","0.00000000"]],"a":[["79818.01000000","1.87566000"],["79825.20000000","1.87677000"]]}}}
{"rx_ns": 13997591223000, "frame": {"stream":"btcusdt@depth@100ms","data":{"e":"depthUpdate","E":1787650992814,"s":"BTCUSDT","U":99118703562,"u":99118703574,"b":[["79818.00000000","1.59334000"],["79813.61000000","0.03245000"],["79632.50000000","0.01151000"],["65146.32000000","0.01188000"]],"a":[["79921.78000000","0.00000000"],["79994.45000000","0.02256000"],["81015.29000000","0.00030000"]]}}}
{"rx_ns": 13997700045300, "frame": {"stream":"btcusdt@depth@100ms","data":{"e":"depthUpdate","E":1787650992914,"s":"BTCUSDT","U":99118703575,"u":99118703668,"b":[["79818.00000000","1.79306000"],["79817.99000000","0.00027000"],["79817.39000000","0.06401000"],["79817.38000000","0.00007000"],["79816.77000000","0.00007000"],["79816.76000000","0.00000000"],["79816.45000000","0.00717000"],["79816.15000000","0.00007000"],["79816.14000000","0.06080000"],["79816.00000000","0.02428000"],["79815.55000000","0.00007000"],["79815.54000000","0.06080000"],["79815.19000000","0.00007000"],["79815.18000000","0.06087000"],["79815.17000000","0.48758000"],["79814.29000000","0.00007000"],["79814.28000000","0.00000000"],["79814.01000000","0.00007000"],["79813.69000000","0.00007000"],["79813.68000000","0.00000000"],["79813.08000000","0.00000000"],["79812.49000000","0.00000000"],["79811.92000000","0.00000000"],["79811.32000000","0.00000000"],["79788.01000000","0.13370000"],["71836.20000000","0.00256000"],["71836.19000000","0.00000000"]],"a":[["79818.01000000","1.68457000"],["79818.54000000","0.12507000"],["79822.61000000","0.00008000"],["79822.80000000","0.00000000"],["79822.81000000","0.00021000"],["79822.82000000","0.20666000"],["79823.08000000","0.00007000"],["79823.58000000","0.00000000"],["79823.59000000","0.00000000"],["79824.21000000","0.00014000"],["79824.35000000","0.00007000"],["79824.36000000","0.00000000"],["79824.38000000","0.00000000"],["79825.20000000","0.00000000"],["79833.98000000","0.19019000"],["79905.99000000","0.00007000"],["79968.73000000","0.00400000"],["79992.84000000","0.00000000"]]}}}
{"rx_ns": 13997796497000, "frame": {"stream":"btcusdt@depth20","data":{"lastUpdateId":99118703761,"bids":[["79818.00000000","1.79357000"],["79817.99000000","0.00034000"],["79817.98000000","0.00013000"],["79817.39000000","0.00014000"],["79817.29000000","0.00007000"],["79816.90000000","0.00007000"],["79816.66000000","0.00007000"],["79816.45000000","0.00717000"],["79816.31000000","0.00007000"],["79816.30000000","0.00007000"],["79816.14000000","0.00014000"],["79816.01000000","0.00007000"],["79816.00000000","0.02428000"],["79815.98000000","0.00007000"],["79815.54000000","0.00014000"],["79815.53000000","0.00939000"],["79815.48000000","0.00007000"],["79815.19000000","0.00007000"],["79815.18000000","0.06087000"],["79815.17000000","0.48751000"]],"asks":[["79818.01000000","1.68457000"],["79818.02000000","0.00027000"],["79818.03000000","0.00013000"],["79818.53000000","0.00007000"],["79818.54000000","0.12507000"],["79818.75000000","0.00007000"],["79818.94000000","0.00007000"],["79819.28000000","0.00007000"],["79819.29000000","0.02247000"],["79819.74000000","0.00007000"],["79820.55000000","0.00007000"],["79820.56000000","0.04060000"],["79820.57000000","0.02694000"],["79820.76000000","0.00007000"],["79820.77000000","0.05085000"],["79821.84000000","0.00007000"],["79821.85000000","0.02701000"],["79822.62000000","0.00014000"],["79822.81000000","0.00007000"],["79822.82000000","0.20666000"]]}}}
{"rx_ns": 13997796669800, "frame": {"stream":"btcusdt@depth@100ms","data":{"e":"depthUpdate","E":1787650993014,"s":"BTCUSDT","U":99118703669,"u":99118703761,"b":[["79818.00000000","1.79357000"],["79817.99000000","0.00034000"],["79817.40000000","0.00000000"],["79817.39000000","0.00014000"],["79817.38000000","0.00000000"],["79816.77000000","0.00000000"],["79816.45000000","0.00717000"],["79816.15000000","0.00000000"],["79816.14000000","0.00014000"],["79816.00000000","0.02428000"],["79815.55000000","0.00000000"],["79815.54000000","0.00014000"],["79815.53000000","0.00939000"],["79815.17000000","0.48751000"],["79814.29000000","0.00000000"],["79814.00000000","0.02407000"],["79813.69000000","0.00000000"],["79813.68000000","0.00007000"],["79813.67000000","1.04939000"],["79813.61000000","0.03231000"],["79813.07000000","0.00626000"],["79812.49000000","0.00007000"],["79811.92000000","0.00007000"],["79811.61000000","0.00000000"],["79811.32000000","0.00007000"],["79811.02000000","0.00626000"],["79810.07000000","0.00000000"],["79809.28000000","0.00000000"],["79808.58000000","0.00048000"],["71836.20000000","0.00256000"],["63854.40000000","0.00031000"]],"a":[["79821.85000000","0.02701000"],["79822.61000000","0.00000000"],["79822.81000000","0.00007000"],["79823.08000000","0.00016000"],["79823.09000000","0.03820000"],["79824.20000000","0.00007000"],["79824.21000000","0.05747000"],["79824.35000000","0.00000000"],["79824.36000000","0.06080000"],["79824.38000000","0.19026000"],["79824.40000000","0.19038000"],["79829.55000000","0.00000000"],["79833.98000000","0.00000000"],["79835.06000000","0.02000000"],["79881.24000000","0.00190000"],["79960.99000000","0.00076000"]]}}}
{"rx_ns": 13997891263600, "frame": {"stream":"btcusdt@depth@100ms","data":{"e":"depthUpdate","E":1787650993114,"s":"BTCUSDT","U":99118703762,"u":99118703838,"b":[["79818.00000000","1.71601000"],["79817.99000000","0.00027000"],["79817.39000000","0.00000000"],["79816.45000000","0.00710000"],["79816.14000000","0.00000000"],["79816.00000000","0.02421000"],["79815.54000000","0.00000000"],["79815.53000000","0.00953000"],["79815.18000000","0.06101000"],["79814.00000000","0.02421000"],["79813.61000000","0.03238000"],["79813.07000000","0.00000000"],["79812.50000000","0.00626000"],["79811.91000000","0.12536000"],["79811.02000000","0.00000000"],["79810.39000000","0.00626000"],["79802.80000000","0.00007000"],["79593.65000000","0.00000000"],["79589.96000000","0.00771000"],["71836.20000000","0.00272000"]],"a":[["79818.54000000","0.18026000"],["79820.77000000","0.05092000"],["79821.25000000","0.00007000"],["79821.26000000","0.15485000"],["79822.80000000","0.00007000"],["79822.81000000","0.06087000"],["79822.82000000","0.20673000"],["79823.08000000","0.00009000"],["79823.09000000","0.00014000"],["79823.59000000","0.06080000"],["79824.37000000","0.02007000"],["79824.38000000","0.19019000"],["79834.74000000","0.00007000"],["79848.95000000","0.00400000"],["79912.79000000","1.95361000"],["79927.99000000","1.15450000"],["79931.27000000","0.00000000"]]}}}
{"rx_ns": 13997997007400, "frame": {"stream":"btcusdt@depth@100ms","data":{"e":"depthUpdate","E":1787650993214,"s":"BTCUSDT","U":99118703839,"u":99118703879,"b":[["79818.00000000","1.91847000"],["79813.67000000","1.04953000"],["78620.73000000","0.00030000"],["71836.20000000","0.00272000"],["63854.40000000","0.00000000"]],"a":[["79818.01000000","1.66618000"],["79818.02000000","0.00034000"],["79820.77000000","0.05092000"],["79821.26000000","0.15499000"],["79821.85000000","0.02701000"],["79822.81000000","0.06101000"],["79822.82000000","0.20652000"],["79823.09000000","0.00000000"],["79825.19000000","0.00014000"],["79835.57000000","0.00007000"],["80536.36000000","0.00020000"]]}}}
{"rx_ns": 13998093118400, "frame": {"stream":"btcusdt@depth@100ms","data":{"e":"depthUpdate","E":1787650993314,"s":"BTCUSDT","U":99118703880,"u":99118703891,"b":[["79818.00000000","1.91809000"],["79590.82000000","0.00400000"],["71836.20000000","0.00288000"],["63854.00000000","0.00015000"]],"a":[["79824.38000000","0.00000000"],["79824.63000000","0.00701000"],["79833.98000000","0.19019000"],["79860.36000000","0.01270000"],["79905.11000000","0.12156000"],["79911.94000000","0.00000000"]]}}}
{"rx_ns": 13998191209000, "frame": {"stream":"btcusdt@depth@100ms","data":{"e":"depthUpdate","E":1787650993414,"s":"BTCUSDT","U":99118703892,"u":99118703900,"b":[["71836.20000000","0.00280000"],["71836.00000000","0.00000000"]],"a":[["79818.01000000","1.66185000"],["79824.37000000","0.02000000"],["79824.40000000","0.19045000"],["79975.76000000","0.00000000"]]}}}
{"rx_ns": 13998292444400, "frame": {"stream":"btcusdt@depth@100ms","data":{"e":"depthUpdate","E":1787650993514,"s":"BTCUSDT","U":99118703901,"u":99118703939,"b":[["79818.00000000","1.91815000"],["79817.99000000","0.00076000"],["79815.18000000","0.00021000"],["79782.30000000","0.00400000"],["79761.97000000","0.02541000"],["79745.04000000","0.02088000"],["71836.20000000","0.00312000"],["63854.40000000","0.00031000"]],"a":[["79818.01000000","1.66171000"],["79822.81000000","0.00021000"],["79823.59000000","0.00000000"],["79824.35000000","0.19019000"],["79824.36000000","0.00000000"],["79826.00000000","0.57960000"],["79828.00000000","1.16729000"],["79830.00000000","1.26578000"],["79832.00000000","0.01707000"],["79833.98000000","0.00000000"],["79834.00000000","1.43225000"],["79836.00000000","0.97253000"],["79838.00000000","1.07339000"],["80986.00000000","0.00007000"]]}}}
{"rx_ns": 13998391983000, "frame": {"stream":"btcusdt@depth@100ms","data":{"e":"depthUpdate","E":1787650993614,"s":"BTCUSDT","U":99118703940,"u":99118703991,"b":[["79818.00000000","1.63235000"],["79817.99000000","0.00076000"],["79815.53000000","0.00953000"],["79815.19000000","0.00000000"],["79815.18000000","0.00007000"],["79814.01000000","0.00014000"],["79813.61000000","0.03245000"],["79812.50000000","0.00000000"],["79811.91000000","0.12543000"],["79811.61000000","0.00626000"],["79745.04000000","0.00000000"],["79593.65000000","0.00771000"],["79589.96000000","0.00000000"],["71836.20000000","0.00312000"],["63854.40000000","0.00020000"]],"a":[["79818.01000000","1.87588000"],["79821.85000000","0.02701000"],["79822.80000000","0.00000000"],["79822.81000000","0.00007000"],["79822.82000000","0.20659000"],["79824.21000000","0.05740000"],["79824.33000000","0.00000000"],["79824.34000000","0.00000000"],["79824.35000000","0.00000000"],["79833.98000000","0.19019000"],["80015.74000000","1.54613000"],["80035.76000000","0.01000000"],["80257.64000000","0.00018000"]]}}}
{"rx_ns": 13998491184700, "frame": {"stream":"btcusdt@depth@100ms","data":{"e":"depthUpdate","E":1787650993714,"s":"BTCUSDT","U":99118703992,"u":99118704003,"b":[["79813.61000000","0.03245000"],["71836.20000000","0.00312000"],["63854.40000000","0.00000000"]],"a":[["79920.82000000","0.00400000"],["79977.65000000","0.01008000"],["81000.00000000","31.68464000"]]}}}
{"rx_ns": 13998591852700, "frame": {"stream":"btcusdt@depth@100ms","data":{"e":"depthUpdate","E":1787650993814,"s":"BTCUSDT","U":99118704004,"u":99118704017,"b":[["79818.00000000","1.83485000"],["71836.20000000","0.00328000"]],"a":[["79818.01000000","1.66164000"],["79826.00000000","0.58660000"],["79828.00000000","1.17429000"],["79830.00000000","1.27278000"],["79832.00000000","0.02407000"],["79834.00000000","1.43925000"],["79836.00000000","0.97953000"],["81015.29000000","0.00030000"]]}}}
{"rx_ns": 13998700466200, "frame": {"stream":"btcusdt@depth@100ms","data":{"e":"depthUpdate","E":1787650993914,"s":"BTCUSDT","U":99118704018,"u":99118704027,"b":[["79742.40000000","0.00400000"],["71836.20000000","0.00344000"],["57864.34000000","0.00953000"]],"a":[["79818.75000000","0.00014000"],["79848.95000000","0.00000000"],["79920.82000000","0.00000000"],["80035.76000000","0.00000000"],["80217.72000000","0.00000000"]]}}}
{"rx_ns": 13998791553200, "frame": {"stream":"btcusdt@depth20","data":{"lastUpdateId":99118704036,"bids":[["79818.00000000","1.83485000"],["79817.99000000","0.00076000"],["79817.98000000","0.00013000"],["79817.29000000","0.00007000"],["79816.90000000","0.00007000"],["79816.66000000","0.00007000"],["79816.45000000","0.00710000"],["79816.31000000","0.00007000"],["79816.30000000","0.00007000"],["79816.01000000","0.00007000"],["79816.00000000","0.02421000"],["79815.98000000","0.00007000"],["79815.53000000","0.00953000"],["79815.48000000","0.00007000"],["79815.18000000","0.00007000"],["79815.17000000","0.48751000"],["79814.88000000","0.00014000"],["79814.82000000","0.00007000"],["79814.01000000","0.00014000"],["79814.00000000","0.02421000"]],"asks":[["79818.01000000","1.66058000"],["79818.02000000","0.00034000"],["79818.03000000","0.00013000"],["79818.53000000","0.00007000"],["79818.54000000","0.18026000"],["79818.75000000","0.00014000"],["79818.94000000","0.00007000"],["79819.28000000","0.00007000"],["79819.29000000","0.02247000"],["79819.74000000","0.00007000"],["79820.55000000","0.00007000"],["79820.56000000","0.04060000"],["79820.57000000","0.02694000"],["79820.76000000","0.00007000"],["79820.77000000","0.05092000"],["79821.25000000","0.00007000"],["79821.26000000","0.15499000"],["79821.84000000","0.00007000"],["79821.85000000","0.02701000"],["79822.62000000","0.00014000"]]}}}
{"rx_ns": 13998791646900, "frame": {"stream":"btcusdt@depth@100ms","data":{"e":"depthUpdate","E":1787650994014,"s":"BTCUSDT","U":99118704028,"u":99118704036,"b":[["79812.76000000","0.00626000"],["79811.61000000","0.00000000"],["71836.20000000","0.00336000"],["71836.19000000","0.00008000"],["63854.40000000","0.00031000"]],"a":[["79818.01000000","1.66058000"],["79832.25000000","0.12536000"],["79877.14000000","0.00000000"],["79977.65000000","0.02008000"]]}}}
{"rx_ns": 13998893512000, "frame": {"stream":"btcusdt@depth@100ms","data":{"e":"depthUpdate","E":1787650994114,"s":"BTCUSDT","U":99118704037,"u":99118704054,"b":[["79813.61000000","0.03252000"],["79811.91000000","0.12536000"],["79802.80000000","0.00000000"],["71836.20000000","0.00352000"]],"a":[["79818.01000000","1.66045000"],["79824.36000000","0.25096000"],["79832.05000000","0.00000000"],["79832.25000000","0.00000000"],["79832.31000000","0.12536000"],["79833.98000000","0.00000000"],["79834.74000000","0.00000000"],["79848.89000000","0.00400000"]]}}}
{"rx_ns": 13998994390600, "frame": {"stream":"btcusdt@depth@100ms","data":{"e":"depthUpdate","E":1787650994214,"s":"BTCUSDT","U":99118704055,"u":99118704071,"b":[["79802.80000000","0.00007000"],["78620.73000000","0.00030000"],["71836.20000000","0.00368000"],["63854.40000000","0.00000000"]],"a":[["79818.01000000","1.66058000"],["79818.75000000","0.00007000"],["79823.12000000","0.00007000"],["79824.21000000","0.05747000"],["79824.36000000","0.06077000"],["79833.98000000","0.19019000"],["79834.74000000","0.00007000"],["79837.64000000","0.00007000"],["79848.00000000","1.90077000"],["80137.28000000","0.00124000"],["80217.72000000","0.00007000"]]}}}
{"rx_ns": 13999091170800, "frame": {"stream":"btcusdt@depth@100ms","data":{"e":"depthUpdate","E":1787650994314,"s":"BTCUSDT","U":99118704072,"u":99118704088,"b":[["79818.00000000","1.83492000"],["79817.99000000","0.00083000"],["79816.30000000","0.00611000"],["79814.01000000","0.00007000"],["79813.06000000","0.00000000"],["79811.31000000","0.92469000"],["71836.20000000","0.00368000"],["71836.19000000","0.00000000"],["63854.00000000","0.00015000"]],"a":[["79818.01000000","1.65868000"],["79823.46000000","0.00017000"],["79824.40000000","0.19038000"],["79824.63000000","0.00000000"],["79848.89000000","0.00000000"],["79920.76000000","0.00400000"]]}}}
{"rx_ns": 13999191449900, "frame": {"stream":"btcusdt@depth@100ms","data":{"e":"depthUpdate","E":1787650994414,"s":"BTCUSDT","U":99118704089,"u":99118704106,"b":[["79816.45000000","0.00710000"],["79756.04000000","0.00072000"],["79747.84000000","0.00000000"],["79745.04000000","0.02088000"],["79676.22000000","0.00090000"],["79667.95000000","0.00000000"],["79596.40000000","0.00090000"],["79588.06000000","0.00000000"],["79516.58000000","0.00090000"],["79508.17000000","0.00000000"],["79436.76000000","0.00090000"],["71836.20000000","0.00384000"]],"a":[["79883.77000000","0.00072000"],["79945.71000000","0.00160000"],["79955.57000000","0.00000000"],["79963.59000000","0.00090000"],["80035.46000000","0.00000000"],["80043.41000000","0.00090000"],["80115.35000000","0.00000000"],["80123.23000000","0.00090000"],["80195.24000000","0.00000000"],["80203.05000000","0.00090000"],["80275.13000000","0.00012000"]]}}}
{"rx_ns": 13999293779000, "frame": {"stream":"btcusdt@depth@100ms","data":{"e":"depthUpdate","E":1787650994515,"s":"BTCUSDT","U":99118704107,"u":99118704117,"b":[["79745.04000000","0.00000000"],["71836.20000000","0.00384000"],["71836.00000000","0.00000000"],["63854.40000000","0.00031000"]],"a":[["79824.38000000","0.00000000"],["79824.64000000","0.00708000"],["79832.31000000","0.00000000"],["79833.97000000","0.19034000"],["79833.98000000","0.00000000"],["79848.89000000","0.00400000"]]}}}
{"rx_ns": 13999391434100, "frame": {"stream":"btcusdt@depth@100ms","data":{"e":"depthUpdate","E":1787650994614,"s":"BTCUSDT","U":99118704118,"u":99118704164,"b":[["79818.00000000","1.83421000"],["79817.99000000","0.00027000"],["79815.54000000","0.06077000"],["79815.18000000","0.06084000"],["79811.92000000","0.00000000"],["79811.38000000","0.00626000"],["79811.32000000","0.00000000"],["79810.39000000","0.00000000"],["71836.20000000","0.00400000"],["63854.40000000","0.00000000"]],"a":[["79818.01000000","1.42346000"],["79821.26000000","0.00014000"],["79823.08000000","0.00000000"],["79823.68000000","0.00010000"],["79824.21000000","0.00014000"],["79824.36000000","0.00000000"],["79824.37000000","0.00400000"],["79824.40000000","0.19045000"],["79836.58000000","0.00000000"],["79848.89000000","0.00000000"],["79985.68000000","0.00160000"]]}}}
{"rx_ns": 13999494642800, "frame": {"stream":"btcusdt@depth@100ms","data":{"e":"depthUpdate","E":1787650994714,"s":"BTCUSDT","U":99118704165,"u":99118704492,"b":[["79818.00000000","1.88481000"],["79817.99000000","0.00034000"],["79817.40000000","0.00007000"],["79817.39000000","0.04805000"],["79817.38000000","0.00000000"],["79816.77000000","0.00007000"],["79816.76000000","0.06077000"],["79816.75000000","0.00400000"],["79816.45000000","0.00779000"],["79816.30000000","0.00028000"],["79816.15000000","0.00007000"],["79816.14000000","0.06077000"],["79816.00000000","0.02435000"],["79815.55000000","0.00633000"],["79815.54000000","0.06091000"],["79815.53000000","0.00960000"],["79815.49000000","0.00000000"],["79815.48000000","0.00134000"],["79815.20000000","0.00007000"],["79815.19000000","1.04880000"],["79815.18000000","1.87691000"],["79815.17000000","0.00014000"],["79814.29000000","0.00000000"],["79814.28000000","0.00000000"],["79814.02000000","0.00626000"],["79814.00000000","0.02428000"],["79813.68000000","0.00007000"],["79813.67000000","1.04939000"],["79813.61000000","0.03231000"],["79812.76000000","0.00000000"],["79812.49000000","0.00007000"],["79811.91000000","0.12536000"],["79811.83000000","0.00000000"],["79811.38000000","0.00000000"],["79811.32000000","0.00400000"],["79808.86000000","0.00000000"],["79808.58000000","0.00000000"],["79807.96000000","0.37599000"],["79806.96000000","0.00000000"],["79806.68000000","0.42203000"],["79805.40000000","0.00800000"],["79804.68000000","0.33841000"],["79804.24000000","0.33841000"],["79798.18000000","0.62658000"],["79797.03000000","0.33844000"],["79795.61000000","0.00000000"],["79791.23000000","0.00000000"],["79788.01000000","0.05165000"],["79786.75000000","0.00000000"],["79781.87000000","0.04445000"],["79776.71000000","0.00000000"],["79759.70000000","0.09556000"],["79757.17000000","0.00000000"],["79735.93000000","0.62625000"],["79730.65000000","0.00000000"],["71836.20000000","0.00408000"],["63854.40000000","0.00000000"]],"a":[["79818.01000000","0.62754000"],["79818.02000000","0.00041000"],["79818.53000000","0.00000000"],["79818.54000000","0.00028000"],["79820.56000000","0.19382000"],["79820.77000000","0.05092000"],["79821.25000000","0.00000000"],["79821.26000000","0.00000000"],["79821.72000000","0.00007000"],["79821.73000000","0.06077000"],["79821.85000000","0.02708000"],["79822.34000000","0.00007000"],["79822.35000000","0.06077000"],["79822.80000000","0.00007000"],["79822.81000000","0.06084000"],["79822.82000000","0.20666000"],["79823.46000000","0.00000000"],["79823.59000000","0.05546000"],["79823.68000000","0.00000000"],["79824.20000000","0.00000000"],["79824.21000000","0.06084000"],["79824.33000000","0.00410000"],["79824.35000000","0.00000000"],["79824.37000000","0.06077000"],["79824.38000000","0.01200000"],["79824.39000000","1.00864000"],["79824.40000000","0.19038000"],["79824.64000000","0.00000000"],["79825.18000000","0.00000000"],["79825.19000000","0.00007000"],["79825.20000000","0.00000000"],["79825.36000000","0.00000000"],["79826.00000000","0.59236000"],["79826.34000000","0.00000000"],["79826.90000000","0.00028000"],["79827.27000000","0.00007000"],["79827.80000000","0.00000000"],["79828.01000000","0.25949000"],["79828.20000000","0.00000000"],["79828.43000000","0.00000000"],["79828.91000000","0.00000000"],["79829.88000000","0.00000000"],["79829.97000000","0.00000000"],["79829.98000000","0.00000000"],["79830.00000000","1.07339000"],["79830.02000000","0.00000000"],["79830.05000000","0.00000000"],["79830.06000000","0.00000000"],["79830.07000000","0.00000000"],["79830.08000000","0.00000000"],["79830.09000000","0.00000000"],["79830.15000000","0.00000000"],["79830.25000000","0.00000000"],["79830.93000000","0.00000000"],["79831.91000000","0.00626000"],["79832.04000000","0.00000000"],["79832.05000000","0.00000000"],["79833.97000000","0.00015000"],["79835.06000000","0.00000000"],["79837.75000000","0.00000000"],["79837.99000000","0.00000000"],["79838.06000000","0.02000000"],["79839.84000000","0.19019000"],["79840.39000000","0.00000000"],["79840.40000000","0.00000000"],["79840.52000000","0.00626000"],["79842.00000000","0.39169000"],["79843.17000000","0.00000000"],["79845.82000000","0.62658000"],["79846.99000000","0.00000000"],["79848.93000000","0.00400000"],["79861.87000000","0.33816000"],["79886.29000000","0.00000000"],["79893.94000000","1.23945000"],["79912.79000000","0.00000000"]]}}}
{"rx_ns": 13999596955800, "frame": {"stream":"btcusdt@depth@100ms","data":{"e":"depthUpdate","E":1787650994814,"s":"BTCUSDT","U":99118704493,"u":99118704582,"b":[["79818.00000000","1.88497000"],["79817.99000000","0.00034000"],["79817.39000000","0.04819000"],["79816.76000000","0.06091000"],["79816.45000000","0.00779000"],["79816.30000000","0.00014000"],["79816.14000000","0.06091000"],["79816.00000000","0.02435000"],["79815.55000000","0.00647000"],["79815.53000000","0.00946000"],["79815.20000000","0.00407000"],["79815.18000000","1.87677000"],["79815.17000000","0.00000000"],["79814.90000000","0.04003000"],["79814.00000000","0.02414000"],["79811.32000000","0.00000000"],["79810.95000000","0.00000000"],["79805.40000000","0.00000000"],["79802.81000000","0.00626000"],["79796.17000000","0.00000000"],["79767.72000000","0.00626000"],["79662.10000000","0.00000000"],["71836.20000000","0.00424000"]],"a":[["79818.01000000","0.62721000"],["79818.54000000","0.00014000"],["79820.56000000","0.15357000"],["79820.77000000","0.05092000"],["79821.73000000","0.06091000"],["79821.85000000","0.02708000"],["79822.35000000","0.06091000"],["79822.81000000","0.06098000"],["79822.82000000","0.20652000"],["79824.39000000","1.00850000"],["79826.91000000","0.00000000"],["79827.70000000","0.00047000"],["79833.25000000","0.44414000"],["79877.28000000","0.00625000"],["79905.11000000","0.00000000"],["79963.99000000","0.01674000"],["79965.39000000","0.00000000"],["81015.29000000","0.00030000"]]}}}
{"rx_ns": 13999691168600, "frame": {"stream":"btcusdt@depth@100ms","data":{"e":"depthUpdate","E":1787650994914,"s":"BTCUSDT","U":99118704583,"u":99118704692,"b":[["79818.00000000","1.98911000"],["79817.99000000","0.00027000"],["79817.41000000","0.00007000"],["79817.40000000","0.06084000"],["79815.55000000","0.00021000"],["79815.53000000","0.00953000"],["79815.22000000","0.00007000"],["79815.21000000","0.06077000"],["79814.00000000","0.02407000"],["79813.68000000","0.00000000"],["79812.49000000","0.00000000"],["79782.30000000","0.00000000"],["79742.40000000","0.00000000"],["79728.30000000","0.00000000"],["79714.49000000","0.00400000"],["79710.49000000","0.00000000"],["79662.62000000","0.00000000"],["79648.39000000","0.00007000"],["79590.82000000","0.00000000"],["73475.18000000","0.00014000"],["71836.20000000","0.00424000"]],"a":[["79818.01000000","0.31230000"],["79818.02000000","0.00048000"],["79819.29000000","0.02254000"],["79820.54000000","0.00007000"],["79820.55000000","0.00000000"],["79820.56000000","0.00035000"],["79822.62000000","0.00007000"],["79822.81000000","0.06091000"],["79822.82000000","0.00014000"],["79823.47000000","0.00000000"],["79823.58000000","0.00007000"],["79824.36000000","0.00400000"],["79824.38000000","0.00000000"],["79824.39000000","0.56097000"],["79825.21000000","0.00000000"],["79827.05000000","0.18621000"],["79829.99000000","0.00000000"],["79831.91000000","0.00000000"],["79833.98000000","0.00400000"],["79838.01000000","0.05992000"],["79839.84000000","0.00000000"],["79849.01000000","0.00000000"],["79851.86000000","0.09483000"],["79861.28000000","0.00000000"],["79861.32000000","0.00007000"],["79866.54000000","0.00400000"]]}}}
{"rx_ns": 13999797063500, "frame": {"stream":"btcusdt@depth20","data":{"lastUpdateId":99118704777,"bids":[["79818.00000000","1.88474000"],["79817.99000000","0.00027000"],["79817.98000000","0.00013000"],["79817.41000000","0.00007000"],["79817.40000000","0.06098000"],["79817.39000000","0.04819000"],["79817.29000000","0.00007000"],["79816.90000000","0.00007000"],["79816.78000000","0.00626000"],["79816.77000000","0.00007000"],["79816.76000000","0.06091000"],["79816.75000000","0.00400000"],["79816.66000000","0.00007000"],["79816.45000000","0.00779000"],["79816.31000000","0.00007000"],["79816.30000000","0.00014000"],["79816.15000000","0.00007000"],["79816.14000000","0.06091000"],["79816.01000000","0.00007000"],["79816.00000000","0.02435000"]],"asks":[["79818.01000000","0.31414000"],["79818.02000000","0.00062000"],["79818.03000000","0.00013000"],["79818.54000000","0.00014000"],["79818.75000000","0.00007000"],["79818.94000000","0.00007000"],["79819.28000000","0.00007000"],["79819.29000000","0.02254000"],["79819.74000000","0.00007000"],["79820.48000000","0.00007000"],["79820.49000000","0.06077000"],["79820.56000000","0.00021000"],["79820.57000000","0.02701000"],["79820.75000000","0.00007000"],["79820.76000000","0.09472000"],["79820.77000000","0.05099000"],["79821.10000000","0.00007000"],["79821.11000000","0.06077000"],["79821.72000000","0.00007000"],["79821.73000000","0.06091000"]]}}}
{"rx_ns": 13999797211300, "frame": {"stream":"btcusdt@depth@100ms","data":{"e":"depthUpdate","E":1787650995014,"s":"BTCUSDT","U":99118704693,"u":99118704777,"b":[["79818.00000000","1.88474000"],["79817.40000000","0.06098000"],["79816.78000000","0.00626000"],["79816.00000000","0.02435000"],["79815.56000000","0.00626000"],["79815.55000000","0.00007000"],["79815.22000000","0.00007000"],["79815.20000000","0.00407000"],["79815.19000000","1.04880000"],["79814.02000000","0.00000000"],["79797.95000000","0.09537000"],["79795.95000000","0.10385000"],["79638.21000000","0.03032000"],["79558.39000000","0.03032000"],["71836.20000000","0.00424000"],["63854.40000000","0.00031000"]],"a":[["79818.01000000","0.31414000"],["79818.02000000","0.00062000"],["79819.29000000","0.02254000"],["79820.48000000","0.00007000"],["79820.49000000","0.06077000"],["79820.54000000","0.00000000"],["79820.56000000","0.00021000"],["79820.57000000","0.02701000"],["79820.75000000","0.00007000"],["79820.76000000","0.09472000"],["79820.77000000","0.05099000"],["79821.10000000","0.00007000"],["79821.11000000","0.06077000"],["79821.72000000","0.00007000"],["79821.84000000","0.00007000"],["79822.34000000","0.00007000"],["79822.62000000","0.00014000"],["79822.80000000","0.00000000"],["79822.81000000","0.06091000"],["79823.58000000","0.00000000"],["79823.59000000","0.05560000"],["79824.20000000","0.00000000"],["79824.37000000","0.06084000"],["79824.82000000","0.16464000"],["79825.62000000","0.00000000"],["79826.90000000","0.00000000"],["79827.05000000","0.00000000"],["79827.69000000","0.00041000"],["79827.92000000","0.00048000"],["79833.24000000","0.00626000"],["79833.98000000","0.19419000"]]}}}
{"rx_ns": 13999891133300, "frame": {"stream":"btcusdt@depth@100ms","data":{"e":"depthUpdate","E":1787650995114,"s":"BTCUSDT","U":99118704778,"u":99118704838,"b":[["79817.39000000","0.04826000"],["79816.78000000","0.00640000"],["79816.00000000","0.02442000"],["79815.54000000","0.06077000"],["79815.53000000","0.00946000"],["79786.30000000","0.00400000"],["71836.20000000","0.00440000"],["71836.00000000","0.00000000"],["63854.00000000","0.00015000"]],"a":[["79818.01000000","0.31414000"],["79819.29000000","0.02254000"],["79820.49000000","0.06091000"],["79820.57000000","0.02701000"],["79820.76000000","0.09486000"],["79820.77000000","0.05099000"],["79821.11000000","0.06091000"],["79822.35000000","0.06077000"],["79822.81000000","0.06077000"],["79823.59000000","0.05546000"],["79824.40000000","0.19045000"],["79832.08000000","0.00000000"],["79832.19000000","0.00000000"],["79833.98000000","0.00400000"],["79840.98000000","0.19019000"],["79864.20000000","0.00400000"],["79866.54000000","0.00000000"]]}}}
{"rx_ns": 14000021785100, "frame": {"stream":"btcusdt@depth@100ms","data":{"e":"depthUpdate","E":1787650995214,"s":"BTCUSDT","U":99118704839,"u":99118704861,"b":[["79818.00000000","1.87193000"],["79815.56000000","0.00640000"],["79802.80000000","0.00007000"],["79767.11000000","0.00007000"],["79760.89000000","0.00007000"],["78620.73000000","0.00030000"],["71836.20000000","0.00432000"],["71836.19000000","0.00008000"],["63854.40000000","0.00000000"]],"a":[["79818.01000000","0.31400000"],["79818.94000000","0.00000000"],["79827.69000000","0.00000000"],["79828.43000000","0.00041000"],["79832.44000000","0.00000000"],["79834.74000000","0.00007000"]]}}}
{"rx_ns": 14000091239600, "frame": {"stream":"btcusdt@depth@100ms","data":{"e":"depthUpdate","E":1787650995314,"s":"BTCUSDT","U":99118704862,"u":99118704884,"b":[["79817.40000000","0.00021000"],["79816.35000000","0.02480000"],["79803.74000000","0.00000000"],["79594.81000000","0.00400000"],["71836.20000000","0.00416000"],["71836.00000000","0.00010000"],["63854.00000000","0.00015000"]],"a":[["79819.87000000","0.06077000"],["79832.04000000","0.00000000"],["79832.11000000","0.00000000"],["79832.77000000","0.00000000"],["79861.32000000","0.00000000"],["79905.51000000","0.11931000"]]}}}
{"rx_ns": 14000192616400, "frame": {"stream":"btcusdt@depth@100ms","data":{"e":"depthUpdate","E":1787650995414,"s":"BTCUSDT","U":99118704885,"u":99118704944,"b":[["79818.00000000","1.87193000"],["79817.41000000","0.00000000"],["79817.40000000","0.00007000"],["79816.45000000","0.00786000"],["79816.36000000","0.00007000"],["79815.56000000","0.00014000"],["79815.22000000","0.00007000"],["79815.21000000","0.06084000"],["79815.20000000","0.00407000"],["79815.19000000","1.04880000"],["79814.91000000","0.00626000"],["79813.68000000","0.00000000"],["79811.37000000","0.01000000"],["79811.31000000","0.92462000"],["79793.00000000","0.70000000"],["73475.18000000","0.00000000"],["71836.20000000","0.00416000"],["71836.00000000","0.00000000"]],"a":[["79818.01000000","0.31397000"],["79818.02000000","0.00069000"],["79819.29000000","0.02261000"],["79819.86000000","0.00007000"],["79819.87000000","0.06091000"],["79821.10000000","0.00007000"],["79821.72000000","0.00007000"],["79821.84000000","0.00007000"],["79821.85000000","0.02694000"],["79822.34000000","0.00000000"],["79829.98000000","0.19019000"],["79829.99000000","1.87677000"],["79833.99000000","0.98543000"],["79840.98000000","0.00000000"],["79888.27000000","0.04698000"],["79936.45000000","0.00000000"]]}}}
{"rx_ns": 14000303917900, "frame": {"stream":"btcusdt@depth@100ms","data":{"e":"depthUpdate","E":1787650995514,"s":"BTCUSDT","U":99118704945,"u":99118704988,"b":[["79818.00000000","1.87201000"],["79816.78000000","0.00014000"],["79816.77000000","0.00000000"],["79816.76000000","0.00014000"],["79816.35000000","0.02494000"],["79816.00000000","0.02442000"],["79815.56000000","0.00626000"],["79815.54000000","0.06091000"],["79813.68000000","0.00007000"],["79666.62000000","0.00400000"],["72000.00000000","74.34194000"],["71836.20000000","0.00416000"],["63854.40000000","0.00031000"]],"a":[["79818.01000000","0.51641000"],["79818.02000000","0.00069000"],["79819.24000000","0.00007000"],["79819.25000000","0.06077000"],["79819.87000000","0.06098000"],["79820.47000000","0.00007000"],["79820.48000000","0.15778000"],["79820.75000000","0.00000000"],["79820.76000000","0.00021000"],["79823.59000000","0.05553000"],["79823.90000000","0.06230000"],["79824.39000000","0.76034000"],["79824.40000000","0.19038000"],["79824.82000000","0.00000000"],["79825.99000000","1.04947000"],["79829.98000000","0.00000000"],["79830.35000000","0.00626000"],["79833.24000000","0.00000000"],["79839.84000000","0.19019000"]]}}}
{"rx_ns": 14000391793800, "frame": {"stream":"btcusdt@depth@100ms","data":{"e":"depthUpdate","E":1787650995614,"s":"BTCUSDT","U":99118704989,"u":99118705053,"b":[["79818.00000000","1.87400000"],["79817.39000000","0.04819000"],["79816.78000000","0.00000000"],["79816.76000000","0.00000000"],["79816.00000000","0.02442000"],["79815.56000000","0.00640000"],["79815.21000000","0.06077000"],["79814.91000000","0.00000000"],["79814.90000000","0.04010000"],["79814.02000000","0.00626000"],["79780.14000000","0.00400000"],["79779.96000000","0.00000000"],["71836.20000000","0.00416000"],["71836.00000000","0.00000000"],["63854.40000000","0.00000000"]],"a":[["79818.01000000","0.51682000"],["79818.02000000","0.00076000"],["79819.25000000","0.06091000"],["79819.87000000","0.06098000"],["79820.48000000","0.15792000"],["79820.57000000","0.02701000"],["79820.76000000","0.00007000"],["79821.73000000","0.06077000"],["79822.35000000","0.06084000"],["79822.79000000","0.15226000"],["79823.59000000","0.05546000"],["79823.90000000","0.00000000"],["79827.46000000","0.00048000"],["79827.92000000","0.00000000"],["79833.93000000","0.00000000"],["79862.28000000","0.00400000"],["79864.20000000","0.00000000"]]}}}
{"rx_ns": 14000491387200, "frame": {"stream":"btcusdt@depth@100ms","data":{"e":"depthUpdate","E":1787650995714,"s":"BTCUSDT","U":99118705054,"u":99118705077,"b":[["79818.00000000","1.87408000"],["79786.30000000","0.00000000"],["79746.40000000","0.00400000"],["79745.04000000","0.02088000"],["79594.81000000","0.00000000"],["71836.20000000","0.00432000"],["71836.19000000","0.00000000"],["71836.00000000","0.00000000"],["63854.40000000","0.00000000"]],"a":[["79818.01000000","0.63052000"],["79827.46000000","0.00000000"],["79848.93000000","0.00000000"],["79888.88000000","0.00000000"],["79916.99000000","0.00581000"],["79920.76000000","0.00000000"],["79929.74000000","0.00000000"],["79968.73000000","0.00000000"],["80040.59000000","0.00000000"]]}}}
{"rx_ns": 14000591839300, "frame": {"stream":"btcusdt@depth@100ms","data":{"e":"depthUpdate","E":1787650995814,"s":"BTCUSDT","U":99118705078,"u":99118705132,"b":[["79818.00000000","1.92450000"],["79817.99000000","0.00027000"],["79815.20000000","0.00400000"],["79815.19000000","1.04873000"],["79813.68000000","0.00000000"],["79745.04000000","0.00000000"],["71836.20000000","0.00416000"],["71836.00000000","0.00000000"],["63854.40000000","0.00000000"]],"a":[["79818.01000000","0.31461000"],["79818.02000000","0.00069000"],["79819.24000000","0.00000000"],["79819.25000000","0.00014000"],["79820.48000000","0.15785000"],["79820.49000000","0.00014000"],["79821.10000000","0.00000000"],["79821.11000000","0.00014000"],["79821.84000000","0.00007000"],["79822.34000000","0.00007000"],["79822.78000000","0.00000000"],["79830.35000000","0.00000000"],["79831.62000000","0.00626000"],["81015.29000000","0.00030000"]]}}}
{"rx_ns": 14000691265800, "frame": {"stream":"btcusdt@depth@100ms","data":{"e":"depthUpdate","E":1787650995914,"s":"BTCUSDT","U":99118705133,"u":99118705192,"b":[["79817.39000000","0.04826000"],["79816.77000000","0.00007000"],["79816.76000000","0.06077000"],["79815.22000000","0.00007000"],["79815.20000000","0.00407000"],["79815.19000000","1.04880000"],["79813.68000000","0.00000000"],["71836.20000000","0.00432000"],["71836.00000000","0.00010000"]],"a":[["79818.01000000","0.31392000"],["79818.02000000","0.00055000"],["79819.25000000","0.00000000"],["79819.29000000","0.02254000"],["79819.87000000","0.06105000"],["79820.46000000","0.00007000"],["79820.47000000","0.06084000"],["79820.48000000","0.15785000"],["79820.49000000","0.00000000"],["79820.77000000","0.05092000"],["79821.11000000","0.00000000"],["79821.73000000","0.06091000"],["79821.84000000","0.00007000"],["79821.85000000","0.02708000"],["79822.34000000","0.00007000"],["79822.35000000","0.06098000"],["79822.78000000","0.00000000"],["79827.48000000","0.00000000"],["79827.51000000","0.00047000"],["79924.83000000","0.00400000"]]}}}
{"rx_ns": 14000792928000, "frame": {"stream":"btcusdt@depth20","data":{"lastUpdateId":99118705213,"bids":[["79818.00000000","1.92458000"],["79817.99000000","0.00027000"],["79817.98000000","0.00013000"],["79817.40000000","0.00007000"],["79817.39000000","0.04826000"],["79817.29000000","0.00007000"],["79816.90000000","0.00007000"],["79816.77000000","0.00007000"],["79816.76000000","0.06077000"],["79816.75000000","0.00400000"],["79816.66000000","0.00007000"],["79816.45000000","0.00786000"],["79816.36000000","0.00007000"],["79816.35000000","0.02494000"],["79816.31000000","0.00007000"],["79816.30000000","0.00014000"],["79816.15000000","0.00007000"],["79816.14000000","0.06091000"],["79816.01000000","0.00007000"],["79816.00000000","0.02442000"]],"asks":[["79818.01000000","0.31392000"],["79818.02000000","0.00055000"],["79818.03000000","0.00013000"],["79818.54000000","0.00014000"],["79818.75000000","0.00007000"],["79819.28000000","0.00007000"],["79819.29000000","0.02254000"],["79819.74000000","0.00007000"],["79819.86000000","0.00007000"],["79819.87000000","0.06105000"],["79820.46000000","0.00007000"],["79820.47000000","0.06098000"],["79820.48000000","0.15785000"],["79820.56000000","0.00021000"],["79820.57000000","0.02701000"],["79820.76000000","0.00007000"],["79820.77000000","0.05092000"],["79821.72000000","0.00007000"],["79821.73000000","0.06091000"],["79821.84000000","0.00007000"]]}}}
{"rx_ns": 14000793162600, "frame": {"stream":"btcusdt@depth@100ms","data":{"e":"depthUpdate","E":1787650996015,"s":"BTCUSDT","U":99118705193,"u":99118705213,"b":[["79818.00000000","1.92458000"],["79817.39000000","0.04826000"],["79766.01000000","0.10025000"],["79765.48000000","0.00000000"],["79745.04000000","0.02088000"],["71836.20000000","0.00416000"],["71836.00000000","0.00010000"],["63854.40000000","0.00031000"]],"a":[["79819.87000000","0.06105000"],["79820.47000000","0.06098000"],["79822.35000000","0.06084000"]]}}}
{"rx_ns": 14000891529400, "kind": "rest", "req": {"method": "GET", "url": "https://data-api.binance.vision/api/v3/depth?symbol=BTCUSDT&limit=1000", "limit": 1000, "weight": 50, "sent_ns": 13999391839700, "status": 200, "used_weight_1m": "50", "recv_ns": 14000885230900}, "frame": {"lastUpdateId":99118704988,"bids":[["79818.00000000","1.87201000"],["79817.99000000","0.00027000"],["79817.98000000","0.00013000"],["79817.40000000","0.00007000"],["79817.39000000","0.04826000"],["79817.29000000","0.00007000"],["79816.90000000","0.00007000"],["79816.78000000","0.00014000"],["79816.76000000","0.00014000"],["79816.75000000","0.00400000"],["79816.66000000","0.00007000"],["79816.45000000","0.00786000"],["79816.36000000","0.00007000"],["79816.35000000","0.02494000"],["79816.31000000","0.00007000"],["79816.30000000","0.00014000"],["79816.15000000","0.00007000"],["79816.14000000","0.06091000"],["79816.01000000","0.00007000"],["79816.00000000","0.02442000"],["79815.98000000","0.00007000"],["79815.56000000","0.00626000"],["79815.55000000","0.00007000"],["79815.54000000","0.06091000"],["79815.53000000","0.00946000"],["79815.48000000","0.00134000"],["79815.22000000","0.00007000"],["79815.21000000","0.06084000"],["79815.20000000","0.00407000"],["79815.19000000","1.04880000"],["79815.18000000","1.87677000"],["79814.91000000","0.00626000"],["79814.90000000","0.04003000"],["79814.88000000","0.00014000"],["79814.82000000","0.00007000"],["79814.01000000","0.00007000"],["79814.00000000","0.02407000"],["79813.74000000","0.00010000"],["79813.68000000","0.00007000"],["79813.67000000","1.04939000"],["79813.66000000","0.00007000"],["79813.61000000","0.03231000"],["79813.51000000","0.00400000"],["79812.98000000","0.00010000"],["79812.75000000","0.00007000"],["79812.48000000","0.31338000"],["79812.30000000","0.00008000"],["79812.25000000","0.00545000"],["79812.02000000","0.00013000"],["79812.00000000","0.02407000"],["79811.91000000","0.12536000"],["79811.60000000","0.00007000"],["79811.48000000","0.00400000"],["79811.37000000","0.01000000"],["79811.31000000","0.92462000"],["79811.27000000","0.14000000"],["79811.24000000","0.02000000"],["79811.01000000","0.00014000"],["79810.97000000","0.00898000"],["79810.67000000","0.00007000"],["79810.38000000","0.00007000"],["79810.28000000","0.00007000"],["79810.06000000","0.00007000"],["79810.02000000","0.00008000"],["79810.01000000","0.00052000"],["79810.00000000","0.02400000"],["79809.70000000","0.01499000"],["79809.69000000","0.01077000"],["79809.56000000","1.87677000"],["79809.55000000","1.05189000"],["79809.45000000","0.00400000"],["79809.29000000","0.00125000"],["79809.16000000","0.00026000"],["79808.73000000","0.02800000"],["79808.65000000","0.02600000"],["79808.43000000","0.00007000"],["79808.41000000","0.01077000"],["79808.30000000","0.02255000"],["79808.00000000","0.02407000"],["79807.96000000","0.37599000"],["79807.93000000","0.02200000"],["79807.86000000","0.02000000"],["79807.85000000","0.02400000"],["79807.83000000","0.02400000"],["79807.72000000","0.00007000"],["79807.54000000","0.00935000"],["79807.21000000","0.02000000"],["79807.19000000","0.00007000"],["79807.14000000","0.00014000"],["79806.87000000","0.00007000"],["79806.68000000","0.42203000"],["79806.67000000","0.36586000"],["79806.61000000","0.00125000"],["79806.60000000","0.06139000"],["79806.52000000","0.00007000"],["79806.44000000","0.00013000"],["79806.26000000","0.00007000"],["79806.01000000","0.20250000"],["79806.00000000","0.02400000"],["79805.76000000","0.00010000"],["79805.66000000","0.00156000"],["79805.54000000","0.02400000"],["79805.39000000","0.00400000"],["79804.99000000","0.08566000"],["79804.68000000","0.33841000"],["79804.45000000","0.00007000"],["79804.31000000","0.02000000"],["79804.24000000","0.33841000"],["79804.23000000","0.02208000"],["79804.02000000","0.00007000"],["79804.00000000","0.02400000"],["79803.92000000","0.12530000"],["79803.85000000","0.02200000"],["79803.84000000","0.00007000"],["79803.83000000","0.02200000"],["79803.68000000","0.00007000"],["79803.65000000","0.02415000"],["79803.53000000","0.00800000"],["79803.52000000","1.36940000"],["79803.51000000","1.87677000"],["79803.49000000","1.04939000"],["79803.36000000","0.00400000"],["79803.27000000","0.00014000"],["79802.81000000","0.00626000"],["79802.80000000","0.00007000"],["79802.37000000","0.00007000"],["79802.04000000","0.00008000"],["79802.03000000","0.00052000"],["79802.00000000","0.02400000"],["79801.79000000","1.20251000"],["79801.55000000","0.00400000"],["79800.92000000","0.00007000"],["79800.86000000","0.00026000"],["79800.70000000","0.00060000"],["79800.30000000","0.00007000"],["79800.11000000","0.37603000"],["79800.01000000","0.25078000"],["79800.00000000","0.92276000"],["79799.96000000","0.00007000"],["79799.85000000","0.00007000"],["79799.40000000","0.00414000"],["79799.05000000","1.43056000"],["79798.99000000","0.00012000"],["79798.66000000","0.36586000"],["79798.64000000","1.87677000"],["79798.62000000","1.04939000"],["79798.18000000","0.62658000"],["79798.17000000","0.49733000"],["79798.06000000","0.00007000"],["79798.05000000","0.00008000"],["79798.00000000","0.02400000"],["79797.99000000","0.00200000"],["79797.95000000","0.09537000"],["79797.82000000","0.00192000"],["79797.78000000","0.00010000"],["79797.62000000","0.33844000"],["79797.43000000","0.20250000"],["79797.29000000","0.02200000"],["79797.25000000","0.00400000"],["79797.03000000","0.33844000"],["79796.16000000","0.00008000"],["79796.08000000","0.00007000"],["79796.05000000","0.00007000"],["79796.00000000","0.02400000"],["79795.95000000","0.10385000"],["79795.71000000","0.12532000"],["79795.53000000","0.00014000"],["79795.12000000","0.60993000"],["79795.11000000","0.42983000"],["79795.10000000","0.00400000"],["79795.07000000","0.00253000"],["79794.59000000","0.03224000"],["79794.08000000","0.00007000"],["79794.05000000","0.00060000"],["79794.03000000","0.00007000"],["79794.00000000","0.02400000"],["79793.96000000","1.04939000"],["79793.00000000","0.70000000"],["79792.95000000","0.00400000"],["79792.66000000","0.00026000"],["79792.23000000","0.00413000"],["79792.03000000","0.00007000"],["79792.00000000","0.02414000"],["79791.66000000","0.00014000"],["79791.26000000","0.02000000"],["79791.22000000","0.62679000"],["79791.18000000","1.48843000"],["79790.96000000","0.08703000"],["79790.88000000","0.00400000"],["79790.43000000","0.13295000"],["79790.06000000","0.00008000"],["79790.00000000","0.82051000"],["79789.93000000","0.00007000"],["79789.80000000","0.00010000"],["79789.78000000","0.01136000"],["79789.44000000","0.20250000"],["79789.05000000","1.87677000"],["79788.96000000","0.33847000"],["79788.77000000","0.00011000"],["79788.60000000","0.00400000"],["79788.59000000","0.36586000"],["79788.58000000","0.02000000"],["79788.53000000","0.00007000"],["79788.42000000","0.09512000"],["79788.32000000","0.00007000"],["79788.23000000","1.04939000"],["79788.14000000","0.00007000"],["79788.09000000","0.00008000"],["79788.01000000","0.05165000"],["79788.00000000","0.02400000"],["79787.85000000","0.00007000"],["79787.79000000","0.00014000"],["79786.33000000","0.02600000"],["79786.32000000","0.00400000"],["79786.30000000","0.00400000"],["79786.12000000","0.00014000"],["79786.07000000","0.00060000"],["79786.00000000","0.02400000"],["79785.97000000","0.02400000"],["79785.17000000","0.02000000"],["79784.45000000","0.02400000"],["79784.40000000","0.02200000"],["79784.04000000","0.00407000"],["79784.00000000","0.02400000"],["79783.92000000","0.00014000"],["79783.70000000","0.00007000"],["79783.59000000","0.48019000"],["79783.47000000","0.04928000"],["79782.80000000","0.00007000"],["79782.08000000","0.00008000"],["79782.00000000","0.02426000"],["79781.87000000","0.04445000"],["79781.82000000","0.00010000"],["79781.80000000","0.03224000"],["79781.76000000","0.00400000"],["79781.45000000","0.20250000"],["79780.99000000","0.00014000"],["79780.57000000","0.00007000"],["79780.56000000","0.00007000"],["79780.48000000","0.36586000"],["79780.17000000","0.62688000"],["79780.05000000","0.00014000"],["79780.02000000","0.00008000"],["79780.00000000","0.02400000"],["79779.96000000","0.00400000"],["79779.47000000","1.20785000"],["79779.46000000","1.87677000"],["79779.45000000","1.24123000"],["79779.15000000","0.51013000"],["79778.96000000","1.04939000"],["79778.86000000","0.00100000"],["79778.18000000","0.00067000"],["79778.16000000","0.00007000"],["79778.09000000","0.00008000"],["79778.00000000","0.03400000"],["79777.84000000","0.01163000"],["79777.48000000","0.00007000"],["79777.30000000","0.02200000"],["79777.06000000","0.03224000"],["79777.00000000","0.00012000"],["79776.11000000","0.00007000"],["79776.00000000","0.02407000"],["79775.87000000","0.65459000"],["79775.41000000","0.00007000"],["79775.07000000","0.49660000"],["79775.06000000","0.34841000"],["79774.24000000","1.00905000"],["79774.09000000","0.02800000"],["79774.00000000","0.02400000"],["79773.97000000","0.00026000"],["79773.84000000","0.02551000"],["79773.61000000","0.00010000"],["79773.46000000","0.20250000"],["79773.13000000","0.00007000"],["79772.80000000","0.00007000"],["79772.69000000","0.02561000"],["79772.16000000","0.00007000"],["79772.00000000","0.02400000"],["79771.95000000","0.00008000"],["79771.92000000","0.83285000"],["79771.44000000","1.41645000"],["79771.43000000","1.24136000"],["79771.28000000","0.02000000"],["79771.26000000","0.00007000"],["79770.99000000","0.00007000"],["79770.90000000","0.02400000"],["79770.39000000","0.36586000"],["79770.27000000","0.00012000"],["79770.15000000","0.00007000"],["79770.00000000","0.02917000"],["79769.88000000","1.04939000"],["79769.87000000","1.87677000"],["79769.65000000","0.02200000"],["79769.41000000","0.03224000"],["79769.28000000","0.02000000"],["79769.25000000","0.02200000"],["79769.24000000","0.02200000"],["79769.12000000","0.00010000"],["79768.85000000","0.00007000"],["79768.60000000","0.02000000"],["79768.08000000","0.00007000"],["79768.00000000","0.02400000"],["79767.72000000","0.00626000"],["79767.11000000","0.00007000"],["79766.71000000","0.00007000"],["79766.66000000","0.00016000"],["79766.35000000","0.02600000"],["79766.00000000","0.02482000"],["79765.99000000","0.02426000"],["79765.86000000","0.00010000"],["79765.48000000","0.06586000"],["79765.47000000","0.20250000"],["79765.25000000","0.01253000"],["79765.19000000","0.02000000"],["79765.04000000","0.00014000"],["79764.70000000","0.00541000"],["79764.51000000","0.00007000"],["79764.47000000","0.02400000"],["79764.42000000","0.02200000"],["79764.00000000","0.02400000"],["79763.88000000","0.00008000"],["79763.45000000","0.04697000"],["79763.21000000","0.00432000"],["79762.96000000","0.00007000"],["79762.50000000","1.61014000"],["79762.49000000","1.24150000"],["79762.30000000","0.82427000"],["79762.26000000","0.36586000"],["79762.12000000","0.00007000"],["79762.03000000","0.00627000"],["79762.00000000","0.02400000"],["79761.97000000","0.02541000"],["79761.89000000","0.00200000"],["79761.88000000","0.00008000"],["79761.63000000","0.00335000"],["79760.89000000","0.00007000"],["79760.29000000","1.04939000"],["79760.28000000","1.87677000"],["79760.16000000","0.00390000"],["79760.08000000","0.00007000"],["79760.00000000","0.02632000"],["79759.70000000","0.09556000"],["79759.60000000","0.00544000"],["79758.86000000","0.00425000"],["79758.00000000","0.02400000"],["79757.99000000","0.00007000"],["79757.88000000","0.00010000"],["79757.62000000","0.00007000"],["79757.59000000","0.01710000"],["79757.52000000","0.00026000"],["79757.48000000","0.20250000"],["79757.41000000","0.00231000"],["79757.40000000","0.00429000"],["79757.38000000","0.00034000"],["79757.33000000","0.02200000"],["79757.28000000","0.00007000"],["79756.79000000","0.03224000"],["79756.43000000","0.00501000"],["79756.18000000","0.00007000"],["79756.04000000","0.00072000"],["79756.00000000","0.02400000"],["79755.93000000","0.00007000"],["79755.81000000","0.00008000"],["79755.01000000","0.03646000"],["79755.00000000","0.09659000"],["79754.67000000","0.00007000"],["79754.20000000","0.00126000"],["79754.18000000","0.00007000"],["79754.11000000","0.02800000"],["79754.00000000","0.02400000"],["79752.24000000","0.00014000"],["79752.12000000","0.00007000"],["79752.06000000","0.00007000"],["79752.00000000","0.02400000"],["79751.41000000","0.00270000"],["79750.92000000","0.02400000"],["79750.72000000","0.96244000"],["79750.71000000","1.04939000"],["79750.69000000","1.87677000"],["79750.52000000","0.00007000"],["79750.01000000","0.00311000"],["79750.00000000","0.02799000"],["79749.90000000","0.00010000"],["79749.67000000","0.02200000"],["79749.52000000","0.00007000"],["79749.49000000","0.20250000"],["79749.37000000","0.00026000"],["79749.31000000","0.02000000"],["79749.27000000","0.04400000"],["79748.08000000","0.00007000"],["79748.07000000","0.00310000"],["79748.06000000","0.89737000"],["79748.05000000","2.32384000"],["79748.00000000","0.02400000"],["79747.88000000","0.36586000"],["79747.75000000","0.07560000"],["79747.74000000","0.00008000"],["79747.37000000","0.05661000"],["79746.89000000","0.00160000"],["79746.37000000","0.00007000"],["79746.05000000","0.00312000"],["79746.04000000","0.08730000"],["79746.00000000","0.02400000"],["79745.46000000","0.00016000"],["79744.74000000","0.00007000"],["79744.00000000","0.02407000"],["79743.95000000","0.12092000"],["79743.94000000","0.00752000"],["79743.29000000","0.68435000"],["79743.28000000","0.25000000"],["79743.25000000","0.00112000"],["79742.19000000","0.00007000"],["79742.00000000","0.02400000"],["79741.92000000","0.00010000"],["79741.76000000","0.00007000"],["79741.50000000","0.20250000"],["79741.11000000","1.04939000"],["79741.10000000","1.87677000"],["79740.15000000","0.00026000"],["79740.00000000","0.05014000"],["79739.48000000","0.00007000"],["79739.36000000","1.08540000"],["79739.35000000","3.40245000"],["79738.93000000","0.00100000"],["79738.83000000","0.00016000"],["79738.21000000","0.00007000"],["79738.18000000","0.00008000"],["79738.00000000","0.02400000"],["79737.27000000","0.12897000"],["79736.72000000","0.07529000"],["79736.67000000","0.00007000"],["79736.47000000","0.00376000"],["79736.16000000","0.00007000"],["79736.04000000","0.00007000"],["79736.01000000","0.00007000"],["79736.00000000","0.02400000"],["79735.99000000","0.04550000"],["79735.93000000","0.62625000"],["79734.24000000","0.00010000"],["79734.00000000","0.02407000"],["79733.69000000","0.00007000"],["79733.52000000","0.67241000"],["79733.51000000","0.20250000"],["79733.50000000","0.36586000"],["79732.48000000","0.00059000"],["79732.40000000","1.04939000"],["79732.39000000","0.80000000"],["79732.01000000","1.11022000"],["79732.00000000","0.02400000"],["79731.98000000","0.00026000"],["79731.70000000","0.00007000"],["79731.60000000","0.00008000"],["79731.51000000","1.87677000"],["79730.76000000","0.00035000"],["79730.00000000","0.03474000"],["79729.79000000","0.00007000"],["79729.72000000","0.00111000"],["79729.70000000","0.00007000"],["79729.04000000","0.00042000"],["79728.72000000","1.99721000"],["79728.65000000","0.00012000"],["79728.64000000","0.00007000"],["79728.57000000","0.00020000"],["79728.40000000","0.00413000"],["79728.00000000","0.02400000"],["79727.14000000","0.00009000"],["79727.11000000","0.00048000"],["79727.00000000","0.00251000"],["79726.86000000","0.00007000"],["79726.72000000","0.47586000"],["79726.71000000","1.87677000"],["79726.69000000","3.76373000"],["79726.24000000","0.00007000"],["79726.00000000","0.02400000"],["79725.64000000","0.00007000"],["79725.52000000","0.20250000"],["79725.27000000","0.04651000"],["79724.07000000","0.00007000"],["79724.01000000","0.02498000"],["79724.00000000","0.02426000"],["79723.98000000","0.00260000"],["79723.52000000","0.00010000"],["79723.40000000","0.00009000"],["79722.00000000","0.02400000"],["79721.94000000","0.00007000"],["79721.92000000","1.87677000"],["79721.64000000","0.00007000"],["79721.57000000","0.00007000"],["79721.30000000","0.03224000"],["79720.20000000","0.00007000"],["79720.00000000","0.02550000"],["79719.42000000","0.00007000"],["79719.13000000","0.09012000"],["79719.12000000","0.36586000"],["79718.52000000","0.00007000"],["79718.48000000","0.00007000"],["79718.16000000","0.00009000"],["79718.00000000","0.02400000"],["79717.58000000","0.00023000"],["79717.53000000","0.20250000"],["79717.44000000","0.00025000"],["79717.43000000","0.00170000"],["79717.34000000","0.00007000"],["79716.78000000","0.00062000"],["79716.66000000","0.00010000"],["79716.45000000","0.00007000"],["79716.03000000","0.00008000"],["79716.00000000","0.02400000"],["79715.91000000","0.00026000"],["79715.53000000","0.00017000"],["79715.46000000","0.00008000"],["79715.28000000","0.00007000"],["79714.49000000","0.00400000"],["79714.36000000","0.00007000"],["79714.28000000","0.00013000"],["79714.25000000","0.06000000"],["79714.20000000","0.00016000"],["79714.00000000","0.02400000"],["79713.90000000","0.00165000"],["79713.76000000","0.00010000"],["79713.56000000","0.00007000"],["79713.45000000","0.00014000"],["79712.53000000","0.00008000"],["79712.00000000","0.02407000"],["79711.26000000","0.00035000"],["79711.23000000","0.05082000"],["79711.00000000","0.00270000"],["79710.76000000","0.00011000"],["79710.75000000","0.00030000"],["79710.72000000","0.00007000"],["79710.54000000","0.00007000"],["79710.00000000","0.02467000"],["79709.77000000","0.03499000"],["79709.57000000","0.00007000"],["79709.54000000","0.20250000"],["79709.06000000","0.00007000"],["79708.33000000","0.00007000"],["79708.00000000","0.02400000"],["79707.66000000","0.00015000"],["79707.50000000","0.00026000"],["79707.44000000","0.00021000"],["79706.59000000","0.03224000"],["79706.00000000","0.02400000"],["79705.88000000","0.00959000"],["79705.59000000","0.00007000"],["79705.45000000","0.00022000"],["79705.00000000","0.00010000"],["79704.92000000","0.00007000"],["79704.88000000","0.00007000"],["79704.74000000","0.36586000"],["79704.24000000","0.00007000"],["79704.00000000","0.02462000"],["79703.75000000","0.00013000"],["79703.74000000","0.00091000"],["79703.71000000","0.00021000"],["79703.56000000","0.00023000"],["79703.52000000","0.00123000"],["79703.38000000","0.00007000"],["79703.19000000","0.00044000"],["79702.92000000","0.00008000"],["79702.82000000","0.00015000"],["79702.64000000","0.00007000"],["79702.54000000","0.00024000"],["79702.00000000","0.02424000"],["79701.79000000","0.00008000"],["79701.66000000","0.00013000"],["79701.60000000","0.00007000"],["79701.55000000","0.20250000"],["79701.33000000","0.00010000"],["79701.32000000","0.00034000"],["79700.91000000","0.00023000"],["79700.90000000","0.01267000"],["79700.89000000","0.00024000"],["79700.88000000","0.00010000"],["79700.85000000","0.00109000"],["79700.51000000","0.00033000"],["79700.48000000","0.00016000"],["79700.29000000","0.00013000"],["79700.28000000","0.05082000"],["79700.15000000","0.00093000"],["79700.10000000","0.00012000"],["79700.00000000","1.18142000"],["79699.86000000","0.00079000"],["79699.77000000","0.00010000"],["79699.72000000","0.00012000"],["79699.59000000","0.00043000"],["79699.51000000","0.00026000"],["79699.39000000","0.00007000"],["79699.32000000","0.00008000"],["79699.20000000","0.00007000"],["79699.02000000","0.00015000"],["79699.00000000","0.13279000"],["79698.79000000","0.00013000"],["79698.70000000","0.00007000"],["79698.63000000","0.00008000"],["79698.48000000","0.00007000"],["79698.34000000","0.00020000"],["79697.89000000","0.00007000"],["79697.86000000","0.00012000"],["79697.56000000","0.00007000"],["79697.09000000","0.00010000"],["79696.96000000","0.00010000"],["79696.91000000","0.00007000"],["79696.86000000","0.00013000"],["79696.59000000","0.00015000"],["79696.55000000","0.00380000"],["79696.39000000","0.00032000"],["79696.10000000","0.00007000"],["79695.64000000","0.00012000"],["79695.39000000","0.00011000"],["79695.21000000","0.03224000"],["79695.12000000","0.00010000"],["79694.87000000","0.00010000"],["79694.84000000","0.00134000"],["79694.71000000","0.00009000"],["79694.66000000","0.00007000"],["79694.44000000","0.00031000"],["79694.34000000","0.00035000"],["79694.22000000","0.00048000"],["79694.19000000","0.00394000"],["79694.05000000","0.00050000"],["79694.00000000","0.00087000"],["79693.69000000","0.00012000"],["79693.58000000","0.00020000"],["79693.43000000","0.00118000"],["79693.33000000","0.00019000"],["79693.13000000","0.00072000"],["79692.59000000","0.00025000"],["79692.48000000","0.00007000"],["79692.41000000","0.00007000"],["79692.35000000","0.09249000"],["79692.32000000","0.00951000"],["79692.30000000","0.00056000"],["79692.22000000","0.00028000"],["79692.07000000","0.00530000"],["79691.34000000","0.00009000"],["79691.01000000","0.00100000"],["79690.79000000","0.00020000"],["79690.52000000","0.00159000"],["79690.50000000","0.00022000"],["79690.37000000","0.00008000"],["79690.36000000","0.36586000"],["79690.31000000","0.00009000"],["79690.00000000","0.00050000"],["79689.80000000","0.00026000"],["79689.65000000","0.00007000"],["79689.59000000","0.00030000"],["79689.44000000","0.00026000"],["79689.35000000","0.00007000"],["79689.34000000","0.00012000"],["79689.19000000","0.00028000"],["79689.16000000","0.00122000"],["79689.00000000","0.00125000"],["79688.88000000","0.00013000"],["79688.76000000","0.00012000"],["79688.63000000","0.00098000"],["79688.40000000","0.00019000"],["79688.34000000","0.00007000"],["79688.28000000","0.00007000"],["79688.20000000","3.76555000"],["79687.85000000","0.00009000"],["79687.77000000","0.00023000"],["79687.55000000","0.00007000"],["79687.50000000","0.00685000"],["79687.44000000","0.00007000"],["79687.36000000","0.00023000"],["79687.12000000","0.00012000"],["79687.03000000","0.00010000"],["79686.99000000","0.00023000"],["79686.89000000","0.01000000"],["79686.72000000","0.00014000"],["79685.71000000","0.00008000"],["79685.56000000","0.00013000"],["79685.36000000","0.00007000"],["79684.94000000","0.00045000"],["79684.66000000","0.00025000"],["79684.65000000","0.00501000"],["79684.56000000","0.04543000"],["79684.21000000","0.00457000"],["79684.15000000","0.00013000"],["79683.74000000","0.00007000"],["79683.66000000","0.11607000"],["79683.58000000","0.00021000"],["79683.54000000","0.00007000"],["79683.48000000","0.00023000"],["79683.18000000","0.00008000"],["79683.15000000","0.00374000"],["79683.07000000","0.00008000"],["79682.96000000","0.00007000"],["79682.75000000","0.00020000"],["79682.72000000","0.00007000"],["79682.56000000","0.00018000"],["79682.12000000","0.00007000"],["79681.94000000","0.36586000"],["79681.93000000","4.39167000"],["79681.92000000","0.00007000"],["79681.81000000","0.00010000"],["79681.62000000","0.00025000"],["79681.51000000","0.00132000"],["79681.46000000","0.00026000"],["79681.39000000","0.00011000"],["79680.97000000","0.00010000"],["79680.88000000","0.00014000"],["79680.85000000","0.00007000"],["79680.82000000","0.00010000"],["79680.56000000","0.00007000"],["79680.38000000","0.00023000"],["79680.36000000","0.00148000"],["79680.32000000","0.00050000"],["79680.11000000","0.00019000"],["79680.00000000","0.02056000"],["79679.90000000","0.00144000"],["79679.89000000","0.00033000"],["79679.17000000","0.00010000"],["79679.06000000","0.00010000"],["79679.02000000","0.00009000"],["79678.57000000","0.00028000"],["79678.55000000","0.00007000"],["79678.28000000","0.00125000"],["79678.27000000","0.00048000"],["79678.17000000","0.00007000"],["79677.97000000","0.00010000"],["79677.58000000","0.00012000"],["79677.53000000","0.00009000"],["79677.47000000","0.00454000"],["79677.41000000","0.00130000"],["79677.21000000","0.00011000"],["79677.06000000","0.00007000"],["79676.94000000","0.01389000"],["79676.89000000","0.00245000"],["79676.76000000","0.00039000"],["79676.60000000","0.00190000"],["79676.47000000","0.00653000"],["79676.40000000","0.00091000"],["79676.22000000","0.00090000"],["79676.19000000","0.00007000"],["79675.91000000","0.00007000"],["79675.86000000","0.00053000"],["79675.78000000","0.00021000"],["79675.70000000","0.00008000"],["79675.67000000","0.00156000"],["79675.00000000","0.00012000"],["79674.66000000","0.00014000"],["79674.64000000","0.01572000"],["79674.47000000","0.00060000"],["79674.41000000","0.00094000"],["79674.14000000","0.00057000"],["79673.90000000","0.00654000"],["79673.70000000","0.00013000"],["79673.64000000","0.00007000"],["79673.37000000","0.00026000"],["79673.33000000","0.00025000"],["79673.20000000","0.00020000"],["79673.14000000","0.00008000"],["79672.84000000","0.00062000"],["79672.78000000","0.00007000"],["79672.69000000","0.00012000"],["79672.32000000","0.00007000"],["79672.31000000","0.00010000"],["79672.01000000","0.00270000"],["79671.91000000","0.00007000"],["79671.90000000","0.00200000"],["79671.39000000","0.00010000"],["79670.91000000","0.11607000"],["79670.66000000","0.00007000"],["79670.59000000","0.00125000"],["79670.58000000","0.00031000"],["79670.26000000","0.00012000"],["79670.14000000","0.00016000"],["79670.01000000","0.00013000"],["79670.00000000","0.00067000"],["79669.97000000","0.00008000"],["79669.86000000","0.00013000"],["79669.78000000","0.00078000"],["79669.77000000","0.00125000"],["79669.70000000","0.00007000"],["79669.48000000","0.00105000"],["79668.90000000","0.00125000"],["79668.89000000","0.00368000"],["79668.85000000","0.00007000"],["79668.59000000","0.00044000"],["79668.58000000","0.00065000"],["79668.49000000","0.00010000"],["79668.13000000","0.00864000"],["79668.00000000","0.03000000"],["79667.46000000","0.00009000"],["79667.45000000","0.00043000"],["79667.27000000","0.00269000"],["79667.17000000","0.00008000"],["79667.09000000","0.03229000"],["79667.04000000","0.00008000"],["79667.03000000","0.00029000"],["79666.66000000","0.03573000"],["79666.62000000","0.00400000"],["79666.60000000","0.00011000"],["79666.55000000","0.00124000"],["79666.52000000","0.00034000"],["79666.40000000","0.00010000"],["79666.28000000","0.00137000"],["79666.19000000","0.00602000"],["79666.10000000","0.00007000"],["79666.00000000","0.00215000"],["79665.88000000","0.00281000"],["79665.61000000","0.00007000"],["79665.36000000","0.00038000"],["79665.35000000","0.00011000"],["79665.25000000","0.01255000"],["79665.22000000","0.00007000"],["79664.86000000","0.00007000"],["79664.73000000","0.00009000"],["79664.62000000","0.00414000"],["79664.39000000","0.00055000"],["79664.16000000","0.00007000"],["79664.12000000","3.76684000"],["79664.01000000","0.00055000"],["79663.85000000","0.00048000"],["79663.55000000","0.00011000"],["79663.45000000","0.00062000"],["79663.37000000","0.00007000"],["79663.24000000","0.00022000"],["79663.14000000","0.00012000"],["79663.08000000","0.00020000"],["79663.03000000","0.00007000"],["79662.85000000","0.00183000"],["79662.83000000","0.00007000"],["79662.56000000","0.00007000"],["79662.33000000","0.00031000"],["79662.03000000","0.00031000"],["79661.66000000","0.00014000"],["79661.65000000","0.00012000"],["79661.30000000","0.00413000"],["79661.26000000","0.00007000"],["79661.19000000","0.00023000"],["79661.18000000","0.00007000"],["79661.15000000","0.00070000"],["79661.11000000","0.00011000"],["79660.69000000","0.00008000"],["79660.60000000","0.23795000"],["79660.56000000","0.00007000"],["79660.00000000","0.00390000"],["79659.82000000","0.00010000"],["79659.78000000","0.00012000"],["79659.77000000","0.00010000"],["79659.75000000","0.00011000"],["79659.53000000","0.00008000"],["79659.36000000","0.00007000"],["79659.09000000","0.00075000"],["79658.95000000","0.11607000"],["79658.92000000","0.00023000"],["79658.70000000","0.00036000"],["79658.36000000","0.00008000"],["79658.29000000","0.01962000"],["79658.26000000","0.00065000"],["79658.01000000","0.00087000"],["79657.99000000","0.00010000"],["79657.87000000","0.00010000"],["79657.78000000","0.00007000"],["79657.44000000","0.00011000"],["79657.35000000","0.00026000"],["79657.14000000","0.00134000"],["79656.71000000","0.00016000"],["79656.64000000","0.00065000"],["79656.61000000","0.00007000"],["79656.50000000","0.00048000"],["79656.49000000","0.00008000"],["79656.43000000","0.00009000"],["79656.36000000","0.00007000"],["79656.25000000","0.00023000"],["79656.22000000","0.00752000"],["79655.94000000","0.01762000"],["79655.50000000","0.00010000"],["79655.44000000","0.00014000"],["79655.17000000","0.00122000"],["79654.94000000","0.00017000"],["79654.67000000","0.00080000"],["79654.59000000","0.00007000"],["79654.56000000","0.00080000"],["79654.47000000","0.00007000"],["79654.27000000","0.00012000"],["79654.11000000","0.00008000"],["79653.84000000","0.00090000"],["79653.57000000","0.00044000"],["79652.73000000","0.00028000"],["79652.70000000","0.00280000"],["79652.52000000","0.00007000"],["79652.38000000","0.00007000"],["79652.36000000","0.00013000"],["79652.25000000","0.00007000"],["79652.15000000","0.00178000"],["79651.98000000","0.00181000"],["79651.21000000","0.00023000"],["79651.20000000","0.00010000"],["79651.15000000","0.00116000"],["79650.98000000","0.00009000"],["79650.97000000","0.00048000"],["79650.90000000","0.00008000"],["79650.01000000","0.00007000"],["79650.00000000","1.07934000"],["79649.55000000","0.00027000"],["79649.34000000","0.00034000"],["79649.28000000","0.00010000"],["79649.22000000","0.00009000"],["79648.83000000","0.00007000"],["79648.64000000","0.00008000"],["79648.39000000","0.00007000"],["79648.20000000","0.00038000"],["79648.12000000","0.00018000"],["79648.00000000","0.00007000"],["79647.88000000","0.00204000"],["79647.86000000","0.00019000"],["79647.38000000","0.00017000"],["79647.31000000","0.00015000"],["79647.26000000","0.00007000"],["79647.22000000","3.76749000"],["79647.05000000","0.01347000"],["79647.02000000","0.00007000"],["79647.00000000","0.11607000"],["79646.58000000","0.00009000"],["79646.49000000","0.00018000"],["79646.44000000","0.00013000"],["79646.31000000","0.00177000"],["79646.17000000","0.00015000"],["79646.15000000","0.00086000"],["79645.83000000","0.00021000"],["79645.74000000","0.00007000"],["79645.05000000","0.00458000"],["79644.70000000","0.00041000"],["79644.44000000","0.00007000"],["79644.35000000","0.00012000"],["79643.81000000","0.00008000"],["79643.68000000","3.76773000"],["79643.65000000","0.00018000"],["79643.18000000","0.00016000"],["79643.02000000","0.00010000"],["79642.85000000","0.00146000"],["79642.41000000","1.20000000"],["79642.24000000","0.00011000"],["79642.01000000","0.00007000"],["79641.95000000","0.00156000"],["79641.40000000","0.00094000"],["79641.33000000","0.00026000"],["79641.20000000","0.00290000"],["79640.88000000","0.00007000"],["79640.76000000","0.00052000"],["79640.65000000","0.00022000"],["79640.40000000","0.00007000"],["79640.34000000","0.00011000"],["79640.30000000","0.00012000"],["79640.28000000","0.00008000"],["79640.22000000","0.00046000"],["79640.00000000","0.00260000"],["79639.66000000","0.00007000"],["79639.44000000","0.01621000"],["79638.81000000","0.02182000"],["79638.73000000","0.00190000"],["79638.21000000","0.03032000"],["79637.85000000","0.00018000"],["79637.50000000","0.00028000"],["79637.06000000","0.00011000"],["79636.78000000","0.00007000"],["79636.75000000","0.00007000"],["79636.36000000","0.00495000"],["79636.34000000","0.00016000"],["79636.33000000","0.00007000"],["79636.24000000","0.00209000"],["79635.87000000","0.00014000"],["79635.81000000","0.00062000"],["79635.29000000","0.00104000"],["79635.05000000","0.11607000"],["79634.76000000","0.00008000"],["79634.61000000","0.00010000"],["79633.33000000","0.00387000"],["79633.32000000","0.00026000"],["79633.28000000","0.00032000"],["79633.16000000","0.00011000"],["79632.84000000","0.00007000"],["79632.50000000","0.01151000"],["79632.34000000","0.00020000"],["79632.27000000","0.00007000"],["79631.83000000","0.25115000"],["79631.81000000","0.00013000"],["79631.57000000","0.00007000"],["79631.53000000","0.00237000"],["79631.50000000","0.00007000"],["79630.94000000","0.00064000"],["79630.83000000","0.00019000"],["79630.79000000","0.00301000"],["79630.73000000","0.00270000"],["79630.00000000","0.00180000"],["79629.62000000","0.00068000"],["79629.45000000","0.00014000"],["79629.42000000","0.00019000"],["79629.13000000","0.00038000"],["79629.10000000","0.00009000"],["79628.85000000","0.00007000"],["79628.52000000","2.32712000"],["79627.84000000","0.00007000"],["79627.80000000","0.00013000"],["79627.73000000","0.00007000"],["79627.49000000","0.00028000"]],"asks":[["79818.01000000","0.51641000"],["79818.02000000","0.00069000"],["79818.03000000","0.00013000"],["79818.54000000","0.00014000"],["79818.75000000","0.00007000"],["79819.24000000","0.00007000"],["79819.25000000","0.06077000"],["79819.28000000","0.00007000"],["79819.29000000","0.02261000"],["79819.74000000","0.00007000"],["79819.86000000","0.00007000"],["79819.87000000","0.06098000"],["79820.47000000","0.00007000"],["79820.48000000","0.15778000"],["79820.49000000","0.06091000"],["79820.56000000","0.00021000"],["79820.57000000","0.02701000"],["79820.76000000","0.00021000"],["79820.77000000","0.05099000"],["79821.10000000","0.00007000"],["79821.11000000","0.06091000"],["79821.72000000","0.00007000"],["79821.73000000","0.06091000"],["79821.84000000","0.00007000"],["79821.85000000","0.02694000"],["79822.35000000","0.06077000"],["79822.62000000","0.00014000"],["79822.81000000","0.06077000"],["79822.82000000","0.00014000"],["79823.12000000","0.00007000"],["79823.59000000","0.05553000"],["79823.69000000","0.00026000"],["79823.90000000","0.06230000"],["79823.99000000","0.00013000"],["79824.00000000","0.00007000"],["79824.21000000","0.06084000"],["79824.33000000","0.00410000"],["79824.36000000","0.00400000"],["79824.37000000","0.06084000"],["79824.39000000","0.76034000"],["79824.40000000","0.19038000"],["79824.46000000","0.00007000"],["79825.19000000","0.00007000"],["79825.22000000","0.42757000"],["79825.99000000","1.04947000"],["79826.00000000","0.59236000"],["79826.49000000","0.00014000"],["79827.12000000","0.00007000"],["79827.27000000","0.00007000"],["79827.36000000","0.00400000"],["79827.70000000","0.00047000"],["79827.81000000","0.00187000"],["79827.87000000","0.12526000"],["79827.92000000","0.00048000"],["79827.98000000","0.00007000"],["79828.00000000","1.17429000"],["79828.01000000","0.25949000"],["79828.43000000","0.00041000"],["79828.44000000","0.00015000"],["79829.34000000","0.00007000"],["79829.64000000","0.08976000"],["79829.93000000","0.00010000"],["79829.99000000","1.87677000"],["79830.00000000","1.07339000"],["79830.01000000","0.60518000"],["79830.22000000","0.00007000"],["79830.26000000","0.44959000"],["79830.35000000","0.00626000"],["79830.36000000","0.00014000"],["79831.00000000","0.00007000"],["79831.42000000","0.00007000"],["79831.63000000","0.00007000"],["79831.72000000","0.00026000"],["79831.92000000","0.00407000"],["79831.97000000","0.00007000"],["79832.00000000","0.02407000"],["79833.25000000","0.44414000"],["79833.49000000","0.00007000"],["79833.97000000","0.00015000"],["79833.98000000","0.00400000"],["79833.99000000","0.98543000"],["79834.00000000","1.43925000"],["79834.20000000","0.00400000"],["79834.23000000","0.00014000"],["79834.53000000","0.56261000"],["79834.74000000","0.00007000"],["79834.82000000","0.00007000"],["79834.83000000","0.02000000"],["79834.86000000","0.02000000"],["79834.88000000","0.00007000"],["79834.93000000","0.02000000"],["79835.18000000","1.87677000"],["79835.19000000","0.00007000"],["79835.57000000","0.00007000"],["79835.65000000","0.02000000"],["79835.71000000","0.02000000"],["79836.00000000","0.97953000"],["79836.01000000","0.47049000"],["79836.48000000","0.00400000"],["79836.51000000","0.11541000"],["79837.24000000","0.02000000"],["79837.64000000","0.00007000"],["79837.91000000","0.00010000"],["79837.96000000","0.00008000"],["79837.98000000","0.00007000"],["79838.00000000","1.07339000"],["79838.01000000","0.05992000"],["79838.06000000","0.02000000"],["79838.10000000","0.00414000"],["79838.41000000","0.02000000"],["79838.51000000","0.10379000"],["79838.63000000","0.02254000"],["79838.76000000","0.00007000"],["79839.12000000","0.12525000"],["79839.23000000","0.02000000"],["79839.24000000","0.00250000"],["79839.65000000","0.10459000"],["79839.66000000","0.02000000"],["79839.72000000","0.00007000"],["79839.84000000","0.19019000"],["79839.85000000","0.78000000"],["79840.00000000","0.11801000"],["79840.14000000","0.02000000"],["79840.23000000","0.00007000"],["79840.25000000","0.00400000"],["79840.27000000","0.00026000"],["79840.45000000","0.02000000"],["79840.52000000","0.00626000"],["79840.53000000","0.02000000"],["79840.54000000","0.02000000"],["79840.99000000","0.01640000"],["79841.80000000","0.00007000"],["79841.96000000","0.00008000"],["79841.97000000","0.00014000"],["79842.00000000","0.39169000"],["79842.01000000","1.03100000"],["79842.02000000","1.41532000"],["79842.16000000","0.03224000"],["79842.17000000","0.00250000"],["79842.35000000","0.00007000"],["79842.40000000","0.00400000"],["79842.64000000","0.00007000"],["79843.18000000","1.87677000"],["79843.20000000","0.02480000"],["79843.83000000","0.12524000"],["79843.87000000","0.00007000"],["79844.00000000","0.02400000"],["79844.01000000","0.69827000"],["79844.03000000","0.14000000"],["79844.49000000","0.00007000"],["79844.55000000","0.00400000"],["79844.58000000","0.00008000"],["79844.83000000","0.01000000"],["79845.82000000","0.62658000"],["79845.83000000","0.42983000"],["79845.84000000","0.00014000"],["79845.89000000","0.00010000"],["79845.95000000","0.00015000"],["79846.00000000","0.02400000"],["79846.01000000","0.21570000"],["79846.02000000","0.33823000"],["79846.66000000","0.00125000"],["79846.70000000","0.00400000"],["79847.01000000","0.33823000"],["79847.16000000","0.00007000"],["79847.39000000","0.00012000"],["79847.88000000","0.00007000"],["79847.99000000","1.28183000"],["79848.00000000","1.90077000"],["79848.02000000","1.04946000"],["79848.31000000","0.00026000"],["79848.93000000","0.00400000"],["79849.00000000","0.70000000"],["79849.27000000","0.03224000"],["79849.62000000","0.51270000"],["79849.71000000","0.00014000"],["79849.82000000","0.00007000"],["79849.94000000","0.00008000"],["79850.00000000","0.12051000"],["79850.01000000","0.41811000"],["79850.05000000","0.00400000"],["79850.10000000","0.00007000"],["79850.33000000","0.36586000"],["79850.40000000","0.00007000"],["79851.86000000","0.09483000"],["79852.00000000","0.98927000"],["79852.08000000","0.00400000"],["79852.18000000","0.00007000"],["79852.65000000","0.00008000"],["79852.66000000","0.33820000"],["79852.85000000","0.00007000"],["79853.58000000","0.00014000"],["79853.87000000","0.00010000"],["79853.93000000","0.00008000"],["79854.00000000","0.02400000"],["79854.02000000","0.00012000"],["79854.11000000","0.00400000"],["79854.15000000","0.30000000"],["79854.25000000","0.00007000"],["79854.33000000","0.30000000"],["79854.36000000","0.95395000"],["79854.46000000","0.63820000"],["79854.57000000","0.30000000"],["79854.95000000","0.00007000"],["79854.97000000","1.04939000"],["79856.00000000","1.16883000"],["79856.09000000","0.03224000"],["79856.14000000","0.00400000"],["79856.33000000","0.00007000"],["79856.66000000","0.62628000"],["79856.79000000","0.00026000"],["79857.45000000","0.00014000"],["79857.92000000","0.00008000"],["79857.95000000","0.04522000"],["79857.98000000","0.00007000"],["79858.00000000","1.91077000"],["79858.11000000","1.20254000"],["79858.16000000","0.00007000"],["79858.17000000","0.00400000"],["79858.40000000","0.00007000"],["79859.38000000","1.41525000"],["79859.98000000","0.00007000"],["79859.99000000","0.53871000"],["79860.00000000","0.81792000"],["79860.36000000","0.01270000"],["79860.48000000","0.00067000"],["79860.72000000","0.00008000"],["79860.85000000","0.00627000"],["79860.88000000","0.49960000"],["79861.51000000","0.00189000"],["79861.66000000","0.03284000"],["79861.67000000","0.20250000"],["79861.69000000","0.20631000"],["79861.85000000","0.00010000"],["79861.87000000","0.33816000"],["79861.98000000","0.00007000"],["79862.00000000","0.02400000"],["79862.56000000","0.00007000"],["79862.79000000","0.00434000"],["79863.84000000","0.00007000"],["79863.93000000","1.37324000"],["79863.94000000","1.87677000"],["79864.00000000","0.02400000"],["79864.20000000","0.00400000"],["79864.33000000","1.04939000"],["79864.34000000","0.01878000"],["79864.35000000","0.01217000"],["79864.36000000","0.02495000"],["79864.63000000","0.00007000"],["79864.65000000","0.00007000"],["79865.92000000","0.00007000"],["79865.97000000","0.00007000"],["79866.00000000","0.02400000"],["79866.08000000","0.00430000"],["79866.12000000","0.00026000"],["79866.20000000","0.00427000"],["79866.41000000","0.03224000"],["79866.59000000","0.62620000"],["79866.71000000","0.00007000"],["79868.00000000","0.02400000"],["79868.03000000","0.83185000"],["79868.14000000","1.03647000"],["79868.16000000","0.36586000"],["79868.20000000","1.23985000"],["79868.61000000","0.00014000"],["79868.64000000","0.00007000"],["79868.79000000","0.00015000"],["79868.97000000","1.87677000"],["79869.56000000","0.00100000"],["79869.83000000","0.00010000"],["79870.00000000","0.72400000"],["79870.74000000","0.00007000"],["79870.86000000","0.00007000"],["79871.55000000","0.51636000"],["79871.90000000","0.98057000"],["79871.91000000","1.04939000"],["79872.00000000","0.02407000"],["79872.35000000","0.03224000"],["79872.94000000","0.00007000"],["79873.47000000","0.02000000"],["79873.68000000","0.00007000"],["79873.97000000","1.87677000"],["79873.98000000","0.82312000"],["79874.00000000","0.02400000"],["79874.18000000","0.00026000"],["79874.28000000","0.02000000"],["79874.74000000","0.00007000"],["79875.02000000","0.00007000"],["79875.20000000","0.20250000"],["79875.92000000","1.38380000"],["79875.93000000","1.04939000"],["79876.00000000","0.02400000"],["79876.21000000","0.62612000"],["79876.76000000","0.00007000"],["79876.86000000","0.00008000"],["79877.09000000","0.00007000"],["79877.28000000","0.00625000"],["79877.62000000","0.00573000"],["79877.81000000","0.00010000"],["79878.00000000","0.02400000"],["79878.07000000","0.36586000"],["79878.89000000","0.02000000"],["79879.01000000","1.87677000"],["79879.17000000","0.00007000"],["79879.28000000","0.02000000"],["79879.35000000","0.02000000"],["79879.70000000","0.02000000"],["79879.80000000","0.00007000"],["79880.00000000","0.02400000"],["79880.35000000","0.41998000"],["79880.36000000","1.04939000"],["79880.75000000","0.00007000"],["79881.24000000","0.00190000"],["79881.25000000","0.02007000"],["79881.44000000","0.00007000"],["79881.94000000","0.00007000"],["79882.00000000","0.02400000"],["79882.06000000","0.02000000"],["79882.12000000","0.02000000"],["79882.18000000","0.00026000"],["79882.51000000","0.03224000"],["79882.89000000","0.02000000"],["79883.32000000","0.00007000"],["79883.36000000","0.02000000"],["79883.70000000","0.02000000"],["79883.75000000","0.04000000"],["79883.77000000","0.00072000"],["79883.87000000","0.01270000"],["79883.95000000","1.29336000"],["79883.96000000","1.87677000"],["79884.00000000","0.43288000"],["79884.28000000","0.00654000"],["79884.41000000","0.01132000"],["79884.60000000","1.04939000"],["79884.93000000","0.00008000"],["79885.40000000","0.00007000"],["79885.79000000","0.00010000"],["79885.83000000","0.00622000"],["79885.84000000","0.62605000"],["79886.00000000","0.02400000"],["79886.25000000","0.36586000"],["79886.58000000","0.00500000"],["79886.62000000","0.00007000"],["79887.55000000","0.82298000"],["79887.58000000","0.01710000"],["79887.98000000","0.32833000"],["79888.00000000","0.02407000"],["79888.03000000","0.00200000"],["79888.27000000","0.04698000"],["79888.88000000","0.00400000"],["79889.20000000","0.00007000"],["79889.56000000","0.00007000"],["79889.71000000","0.00007000"],["79890.00000000","0.02400000"],["79891.22000000","0.00026000"],["79891.41000000","1.04939000"],["79891.82000000","0.04320000"],["79891.97000000","0.00007000"],["79891.99000000","1.10030000"],["79892.00000000","0.02400000"],["79893.00000000","0.00008000"],["79893.10000000","0.00112000"],["79893.22000000","0.01270000"],["79893.44000000","0.02000000"],["79893.77000000","0.00010000"],["79893.94000000","1.23945000"],["79893.99000000","0.00007000"],["79894.00000000","0.22650000"],["79894.25000000","0.02000000"],["79894.64000000","1.87677000"],["79895.50000000","1.04939000"],["79895.76000000","0.00007000"],["79895.78000000","0.00010000"],["79895.79000000","0.00007000"],["79896.00000000","0.02400000"],["79896.96000000","0.00007000"],["79896.99000000","0.92914000"],["79897.69000000","0.00007000"],["79897.83000000","0.00008000"],["79897.89000000","0.00300000"],["79897.91000000","0.00007000"],["79898.00000000","0.02400000"],["79898.04000000","0.00375000"],["79898.58000000","0.36586000"],["79898.76000000","0.20631000"],["79898.96000000","0.02000000"],["79899.25000000","0.02000000"],["79899.33000000","0.02000000"],["79899.40000000","0.00026000"],["79899.44000000","1.87677000"],["79899.98000000","0.48238000"],["79899.99000000","1.04939000"],["79900.00000000","0.02407000"],["79900.28000000","0.00007000"],["79900.53000000","0.03224000"],["79900.93000000","0.20631000"],["79901.07000000","0.00008000"],["79901.23000000","0.02000000"],["79901.75000000","0.00010000"],["79901.99000000","0.20250000"],["79902.00000000","0.02400000"],["79902.02000000","0.00007000"],["79902.04000000","0.02000000"],["79902.09000000","0.02000000"],["79902.87000000","0.02000000"],["79903.43000000","0.02000000"],["79903.73000000","0.02000000"],["79903.77000000","0.02000000"],["79903.82000000","0.02000000"],["79903.91000000","0.00536000"],["79903.97000000","0.00007000"],["79904.00000000","0.02407000"],["79904.47000000","1.55815000"],["79904.48000000","1.87677000"],["79904.50000000","1.04939000"],["79904.72000000","0.00007000"],["79905.51000000","0.11931000"],["79905.99000000","0.00007000"],["79906.00000000","0.02400000"],["79906.02000000","0.00375000"],["79906.17000000","0.00007000"],["79906.58000000","0.36586000"],["79906.66000000","0.02000000"],["79906.72000000","2.31342000"],["79907.40000000","0.00014000"],["79907.75000000","0.00026000"],["79907.81000000","1.47528000"],["79907.99000000","0.00007000"],["79908.00000000","0.02400000"],["79908.61000000","1.04939000"],["79908.62000000","0.20631000"],["79909.14000000","0.00008000"],["79909.54000000","1.87677000"],["79909.73000000","0.00010000"],["79909.97000000","0.00270000"],["79909.98000000","0.20250000"],["79909.99000000","0.00007000"],["79910.00000000","0.02400000"],["79910.81000000","0.00235000"],["79911.25000000","1.99265000"],["79911.72000000","0.00007000"],["79911.96000000","0.00667000"],["79911.99000000","1.14520000"],["79912.00000000","0.02400000"],["79912.41000000","0.00007000"],["79912.48000000","0.00007000"],["79912.72000000","1.04939000"],["79913.01000000","0.11316000"],["79913.58000000","0.00100000"],["79913.88000000","0.00007000"],["79914.00000000","0.02400000"],["79915.01000000","1.87677000"],["79915.07000000","0.00007000"],["79915.84000000","0.00026000"],["79915.98000000","0.00007000"],["79916.00000000","0.02400000"],["79916.56000000","0.00007000"],["79916.73000000","0.03224000"],["79916.99000000","0.00025000"],["79917.21000000","0.00008000"],["79917.43000000","0.15661000"],["79917.44000000","0.20631000"],["79917.71000000","0.00010000"],["79917.81000000","0.00007000"],["79918.00000000","0.02400000"],["79918.81000000","0.20250000"],["79918.86000000","0.09167000"],["79919.93000000","2.26910000"],["79919.94000000","1.87677000"],["79919.95000000","0.36586000"],["79920.00000000","1.01979000"],["79920.24000000","0.00007000"],["79920.76000000","0.00400000"],["79920.79000000","0.00007000"],["79920.95000000","0.00075000"],["79921.88000000","0.00884000"],["79922.00000000","0.02400000"],["79922.01000000","0.01876000"],["79922.42000000","0.00413000"],["79923.57000000","3.75454000"],["79923.88000000","0.00026000"],["79923.98000000","0.02804000"],["79924.00000000","0.02400000"],["79924.05000000","0.00200000"],["79924.60000000","0.00007000"],["79924.87000000","0.00007000"],["79925.14000000","0.03456000"],["79925.28000000","0.00008000"],["79925.46000000","0.01161000"],["79925.69000000","0.00010000"],["79925.78000000","0.62854000"],["79925.79000000","1.87677000"],["79926.00000000","0.02400000"],["79926.80000000","0.20250000"],["79926.95000000","0.00007000"],["79926.98000000","0.00007000"],["79927.53000000","0.00218000"],["79927.68000000","0.00007000"],["79927.99000000","1.15450000"],["79928.00000000","0.02407000"],["79928.51000000","0.36586000"],["79929.74000000","0.00556000"],["79929.85000000","0.00007000"],["79929.90000000","0.00007000"],["79930.00000000","0.02400000"],["79930.01000000","0.04557000"],["79931.47000000","3.44030000"],["79931.60000000","0.03224000"],["79931.97000000","0.00007000"],["79932.00000000","0.02400000"],["79932.09000000","0.00026000"],["79933.08000000","0.00007000"],["79933.19000000","0.00007000"],["79933.35000000","0.00008000"],["79933.67000000","0.00010000"],["79933.98000000","0.00007000"],["79934.00000000","0.02400000"],["79934.60000000","0.00012000"],["79934.70000000","0.56045000"],["79934.71000000","1.87677000"],["79935.15000000","0.00010000"],["79935.37000000","0.00070000"],["79935.76000000","0.00007000"],["79935.99000000","0.00007000"],["79936.00000000","0.02407000"],["79937.07000000","0.17686000"],["79937.08000000","0.36586000"],["79937.29000000","0.00018000"],["79938.00000000","0.02400000"],["79938.01000000","0.20250000"],["79938.07000000","0.00007000"],["79939.42000000","0.00007000"],["79939.78000000","0.85077000"],["79939.79000000","1.87677000"],["79939.99000000","0.00047000"],["79940.00000000","0.24051000"],["79941.06000000","0.00007000"],["79941.11000000","0.00026000"],["79941.42000000","0.00008000"],["79941.46000000","0.00031000"],["79941.65000000","0.00010000"],["79941.79000000","0.01662000"],["79942.00000000","0.02400000"],["79943.20000000","0.00200000"],["79943.52000000","0.00007000"],["79943.58000000","0.00007000"],["79943.64000000","0.00007000"],["79943.65000000","0.00007000"],["79943.84000000","0.03224000"],["79944.00000000","0.02400000"],["79944.14000000","0.19148000"],["79944.15000000","0.25000000"],["79945.23000000","0.36586000"],["79945.68000000","0.00021000"],["79945.71000000","0.00160000"],["79945.89000000","0.00100000"],["79945.99000000","0.00007000"],["79946.00000000","0.02400000"],["79946.19000000","0.00014000"],["79947.74000000","0.00007000"],["79947.99000000","0.08822000"],["79948.00000000","0.22650000"],["79949.32000000","0.00007000"],["79949.33000000","0.00026000"],["79949.63000000","0.00010000"],["79949.99000000","0.00270000"],["79950.00000000","0.03129000"],["79951.56000000","0.03456000"],["79952.00000000","0.02400000"],["79952.56000000","1.35811000"],["79952.57000000","3.75321000"],["79953.16000000","0.00007000"],["79953.97000000","0.00007000"],["79954.00000000","0.02400000"],["79954.41000000","0.36586000"],["79954.84000000","0.05741000"],["79955.00000000","0.00011000"],["79955.15000000","0.00007000"],["79955.45000000","0.00012000"],["79955.51000000","0.40000000"],["79956.00000000","0.02400000"],["79956.44000000","0.11108000"],["79957.15000000","0.00007000"],["79957.28000000","0.03224000"],["79957.39000000","0.00026000"],["79957.56000000","0.00008000"],["79957.61000000","0.00010000"],["79958.00000000","0.02400000"],["79958.13000000","0.00007000"],["79958.33000000","0.09823000"],["79958.40000000","0.00239000"],["79958.54000000","0.00500000"],["79959.18000000","0.20250000"],["79959.21000000","0.00197000"],["79959.22000000","0.00491000"],["79959.42000000","0.00007000"],["79959.60000000","0.00007000"],["79959.65000000","0.04633000"],["79959.88000000","0.31568000"],["79959.96000000","0.00390000"],["79960.00000000","1.02515000"],["79960.29000000","0.00200000"],["79960.96000000","0.00010000"],["79960.99000000","0.00076000"],["79961.00000000","0.00202000"],["79961.44000000","0.00007000"],["79962.00000000","0.02400000"],["79963.59000000","0.00090000"],["79963.65000000","0.00007000"],["79963.99000000","0.01674000"],["79964.00000000","0.02400000"],["79964.13000000","0.00078000"],["79964.37000000","0.00007000"],["79964.77000000","0.00125000"],["79964.78000000","0.00018000"],["79964.80000000","0.00017000"],["79964.96000000","0.00007000"],["79965.16000000","0.00070000"],["79965.33000000","0.00380000"],["79965.38000000","0.00125000"],["79965.59000000","0.00036000"],["79965.87000000","0.00088000"],["79966.00000000","0.02400000"],["79966.04000000","0.00032000"],["79966.29000000","0.00018000"],["79966.60000000","0.00012000"],["79966.80000000","0.00014000"],["79967.28000000","0.00394000"],["79967.46000000","0.00007000"],["79967.51000000","0.00016000"],["79967.61000000","0.00025000"],["79967.75000000","0.13066000"],["79967.83000000","0.36586000"],["79968.00000000","0.02420000"],["79968.01000000","0.00151000"],["79968.15000000","0.00007000"],["79968.73000000","0.00400000"],["79969.87000000","0.00176000"],["79970.00000000","0.02450000"],["79970.02000000","0.00011000"],["79970.50000000","0.00375000"],["79970.57000000","0.00010000"],["79970.58000000","0.00009000"],["79970.60000000","0.00053000"],["79971.08000000","0.00049000"],["79971.44000000","0.00007000"],["79972.00000000","0.02400000"],["79972.72000000","0.20250000"],["79972.95000000","0.29312000"],["79972.98000000","0.03224000"],["79973.25000000","0.00007000"],["79973.56000000","0.00007000"],["79973.57000000","0.00010000"],["79973.70000000","0.00008000"],["79974.00000000","0.02400000"],["79974.29000000","0.92475000"],["79974.34000000","0.00026000"],["79974.52000000","0.00010000"],["79975.00000000","0.00024000"],["79975.56000000","0.00007000"],["79975.99000000","0.01616000"],["79976.00000000","0.02400000"],["79976.12000000","0.00007000"],["79976.15000000","0.00007000"],["79976.26000000","0.00016000"],["79977.65000000","0.02008000"],["79977.77000000","0.00020000"],["79977.90000000","0.00011000"],["79978.00000000","0.02400000"],["79978.27000000","0.00104000"],["79978.47000000","0.00007000"],["79979.11000000","0.00055000"],["79979.99000000","0.50215000"],["79980.00000000","1.02719000"],["79980.70000000","0.20250000"],["79981.00000000","0.00007000"],["79981.55000000","0.00010000"],["79981.81000000","0.01580000"],["79982.00000000","0.02400000"],["79982.21000000","0.36586000"],["79982.38000000","0.00020000"],["79982.41000000","0.00026000"],["79982.45000000","0.00007000"],["79983.55000000","0.00117000"],["79983.99000000","0.93606000"],["79984.00000000","0.02400000"],["79984.98000000","0.00014000"],["79985.16000000","0.00007000"],["79985.34000000","0.00007000"],["79985.44000000","0.00040000"],["79985.45000000","0.00029000"],["79985.68000000","0.00160000"],["79985.71000000","0.00013000"],["79985.82000000","0.00100000"],["79986.00000000","0.02400000"],["79986.02000000","0.00375000"],["79986.41000000","0.00412000"],["79987.53000000","3.75154000"],["79987.54000000","0.09017000"],["79988.00000000","0.02400000"],["79988.17000000","0.03224000"],["79988.68000000","0.20250000"],["79989.32000000","0.00007000"],["79989.84000000","0.00008000"],["79989.96000000","0.00035000"],["79989.99000000","0.00270000"],["79990.00000000","0.02817000"],["79990.08000000","0.00007000"],["79990.65000000","0.00026000"],["79991.52000000","0.00007000"],["79991.97000000","0.02071000"],["79992.00000000","0.02400000"],["79992.16000000","0.00016000"],["79992.87000000","0.00007000"],["79994.00000000","0.02400000"],["79994.02000000","0.00375000"],["79994.15000000","0.00007000"],["79994.28000000","0.00011000"],["79994.45000000","0.02256000"],["79994.55000000","0.00036000"],["79994.94000000","0.00007000"],["79995.56000000","0.00007000"],["79996.00000000","0.02400000"],["79996.06000000","0.00038000"],["79996.18000000","0.18857000"],["79996.59000000","0.36586000"],["79996.66000000","0.20250000"],["79996.85000000","0.00007000"],["79997.44000000","0.00069000"],["79997.62000000","0.00041000"],["79998.00000000","0.02400000"],["79998.36000000","0.00378000"],["79998.83000000","0.00026000"],["79999.00000000","0.00461000"],["79999.01000000","0.01307000"],["79999.03000000","0.01059000"],["79999.10000000","0.00010000"],["79999.17000000","0.00007000"],["79999.38000000","0.00007000"],["79999.55000000","0.00022000"],["79999.60000000","0.00136000"],["79999.85000000","0.00010000"],["79999.90000000","1.02096000"],["79999.94000000","0.00010000"],["80000.00000000","3.41279000"],["80000.17000000","0.04451000"],["80001.80000000","0.00007000"],["80001.83000000","0.00010000"],["80002.12000000","0.00008000"],["80002.42000000","0.00007000"],["80002.51000000","0.00007000"],["80003.61000000","0.00124000"],["80003.99000000","0.00409000"],["80004.63000000","0.17095000"],["80004.64000000","0.20250000"],["80004.70000000","0.03132000"],["80004.85000000","0.00268000"],["80005.00000000","0.00025000"],["80005.04000000","0.00007000"],["80005.46000000","0.36586000"],["80005.54000000","0.00017000"],["80005.95000000","0.00009000"],["80005.98000000","0.00008000"],["80006.05000000","0.00007000"],["80006.59000000","0.00033000"],["80006.85000000","0.00026000"],["80007.19000000","0.00018000"],["80007.44000000","0.00010000"],["80007.48000000","0.00007000"],["80008.00000000","0.00087000"],["80008.04000000","0.00007000"],["80008.52000000","0.00022000"],["80008.56000000","0.00016000"],["80009.02000000","0.00007000"],["80010.00000000","0.00057000"],["80010.03000000","0.00065000"],["80011.59000000","0.00025000"],["80012.00000000","0.30955000"],["80012.23000000","0.00007000"],["80012.46000000","0.03224000"],["80012.61000000","0.00023000"],["80012.62000000","0.20250000"],["80012.68000000","0.00008000"],["80012.85000000","0.80000000"],["80013.36000000","0.00007000"],["80013.42000000","0.00007000"],["80013.72000000","0.00011000"],["80013.89000000","0.00010000"],["80013.94000000","0.00011000"],["80014.31000000","0.00010000"],["80014.71000000","0.00055000"],["80014.90000000","0.00026000"],["80015.29000000","0.00045000"],["80015.37000000","0.00008000"],["80015.74000000","1.54613000"],["80016.06000000","0.00007000"],["80016.21000000","0.00007000"],["80016.66000000","0.00010000"],["80017.15000000","0.00076000"],["80017.64000000","0.00027000"],["80018.81000000","0.00007000"],["80018.82000000","0.00007000"],["80019.08000000","0.36586000"],["80019.10000000","3.74998000"],["80019.33000000","0.00010000"],["80019.50000000","0.07720000"],["80019.99000000","0.00869000"],["80020.00000000","0.00078000"],["80020.60000000","0.20250000"],["80021.13000000","0.03224000"],["80021.19000000","0.00007000"],["80021.34000000","0.00007000"],["80021.42000000","0.00030000"],["80021.57000000","0.00024000"],["80021.85000000","0.00007000"],["80022.12000000","0.00008000"],["80022.22000000","0.00055000"],["80022.76000000","0.00014000"],["80023.13000000","0.00007000"],["80023.25000000","0.00094000"],["80023.28000000","0.00011000"],["80023.30000000","0.00026000"],["80023.44000000","0.00007000"],["80023.52000000","0.00030000"],["80023.74000000","0.02000000"],["80023.77000000","0.00014000"],["80024.59000000","3.74980000"],["80024.70000000","0.00011000"],["80024.83000000","0.00023000"],["80025.00000000","0.00043000"],["80025.16000000","0.00013000"],["80025.83000000","0.00007000"],["80026.29000000","0.02003000"],["80026.63000000","0.00007000"],["80027.39000000","0.00008000"],["80027.71000000","0.00226000"],["80028.29000000","0.06617000"],["80028.44000000","0.00039000"],["80028.57000000","0.00015000"],["80028.58000000","0.20250000"],["80029.22000000","0.00007000"],["80029.37000000","0.00011000"],["80029.38000000","0.00008000"],["80029.41000000","0.00156000"],["80029.98000000","0.00270000"],["80030.00000000","0.01142000"],["80030.01000000","0.00077000"],["80030.07000000","0.00013000"],["80030.10000000","0.00009000"],["80030.30000000","0.00010000"],["80031.25000000","0.00007000"],["80031.31000000","0.00026000"],["80031.35000000","0.00122000"],["80031.41000000","0.00007000"],["80031.91000000","0.00007000"],["80032.00000000","0.00007000"],["80032.15000000","0.02278000"],["80032.16000000","0.06930000"],["80032.69000000","0.00008000"],["80033.06000000","0.00010000"],["80033.17000000","0.00010000"],["80033.31000000","0.00265000"],["80033.33000000","0.00077000"],["80033.42000000","0.00139000"],["80033.52000000","0.00025000"],["80033.74000000","0.00100000"],["80034.28000000","0.00053000"],["80034.90000000","0.00007000"],["80035.45000000","0.00007000"],["80035.57000000","0.17543000"],["80035.58000000","0.34723000"],["80036.03000000","0.00012000"],["80036.10000000","0.01962000"],["80036.56000000","0.20250000"],["80036.64000000","0.00007000"],["80037.03000000","0.00043000"],["80037.19000000","0.00007000"],["80037.22000000","0.00015000"],["80037.44000000","0.00126000"],["80037.53000000","0.00007000"],["80037.64000000","0.00010000"],["80037.68000000","0.00041000"],["80038.18000000","0.00187000"],["80038.26000000","0.00008000"],["80038.52000000","0.03224000"],["80038.85000000","0.00072000"],["80038.93000000","0.00040000"],["80039.40000000","0.00007000"],["80039.79000000","0.00007000"],["80039.81000000","0.00050000"],["80039.84000000","0.00026000"],["80040.00000000","0.00195000"],["80040.01000000","0.00052000"],["80040.24000000","0.00009000"],["80040.55000000","0.00150000"],["80040.59000000","0.00400000"],["80040.78000000","0.01602000"],["80040.80000000","0.00010000"],["80040.93000000","0.00313000"],["80041.22000000","0.00016000"],["80041.77000000","0.00014000"],["80042.15000000","0.00050000"],["80042.47000000","0.00007000"],["80042.73000000","0.00109000"],["80042.85000000","0.00007000"],["80043.25000000","0.00010000"],["80043.41000000","0.00090000"],["80043.46000000","0.00010000"],["80043.78000000","0.00007000"],["80044.17000000","0.00012000"],["80044.54000000","0.20250000"],["80044.63000000","0.00028000"],["80045.29000000","0.00010000"],["80045.39000000","0.00007000"],["80045.42000000","0.00008000"],["80045.63000000","0.00007000"],["80045.95000000","0.00044000"],["80047.05000000","0.00031000"],["80047.75000000","0.00045000"],["80047.88000000","0.00026000"],["80048.04000000","0.00007000"],["80049.06000000","0.00007000"],["80049.25000000","0.44309000"],["80049.32000000","0.07334000"],["80049.44000000","4.51187000"],["80049.66000000","0.00125000"],["80049.87000000","0.00020000"],["80050.00000000","1.00087000"],["80050.28000000","0.00007000"],["80050.53000000","0.11607000"],["80051.13000000","0.00007000"],["80051.50000000","0.09345000"],["80051.51000000","0.10010000"],["80051.58000000","0.00007000"],["80051.92000000","0.00007000"],["80051.99000000","0.00007000"],["80052.13000000","0.00012000"],["80052.44000000","0.00011000"],["80052.52000000","0.20250000"],["80052.98000000","0.00040000"],["80053.04000000","0.00007000"],["80053.26000000","0.00010000"],["80053.50000000","0.00129000"],["80053.52000000","0.00018000"],["80053.58000000","0.00007000"],["80053.64000000","0.00057000"],["80054.31000000","0.00010000"],["80054.40000000","0.00058000"],["80054.46000000","0.00237000"],["80055.00000000","0.00007000"],["80055.26000000","0.00007000"],["80055.36000000","0.00007000"],["80055.92000000","0.00053000"],["80056.01000000","0.01234000"],["80056.27000000","0.00026000"],["80056.60000000","0.00025000"],["80056.73000000","0.00007000"],["80056.74000000","0.00164000"],["80057.14000000","0.00048000"],["80057.25000000","0.00067000"],["80057.46000000","0.00008000"],["80057.49000000","0.00256000"],["80057.59000000","0.00028000"],["80058.32000000","0.00007000"],["80058.82000000","0.00025000"],["80059.11000000","0.00042000"],["80059.92000000","0.00007000"],["80060.00000000","0.00176000"],["80060.24000000","0.00013000"],["80060.40000000","0.00034000"],["80060.50000000","0.20250000"],["80060.52000000","0.00007000"],["80060.58000000","0.00029000"],["80061.53000000","0.00046000"],["80062.54000000","0.11607000"],["80062.56000000","0.00014000"],["80062.82000000","0.00007000"],["80063.61000000","0.00007000"],["80063.82000000","0.00009000"],["80064.00000000","0.00007000"],["80064.15000000","0.00017000"],["80064.72000000","0.00026000"],["80064.91000000","3.74793000"],["80065.00000000","0.00018000"],["80065.15000000","0.00032000"],["80065.65000000","0.02105000"],["80066.66000000","0.00058000"],["80066.84000000","0.00381000"],["80067.46000000","0.00007000"],["80067.99000000","0.00007000"],["80068.00000000","0.00025000"],["80068.75000000","0.00019000"],["80068.89000000","0.00007000"],["80069.18000000","0.00223000"],["80069.99000000","0.00269000"],["80070.00000000","0.00057000"],["80071.26000000","0.00007000"],["80071.42000000","0.00010000"],["80072.13000000","0.00008000"],["80072.21000000","0.00107000"]]}}
{"rx_ns": 14000891529400, "frame": {"stream":"btcusdt@depth@100ms","data":{"e":"depthUpdate","E":1787650996114,"s":"BTCUSDT","U":99118705214,"u":99118705225,"b":[["79815.66000000","0.00400000"],["79782.36000000","0.00400000"],["79781.76000000","0.00000000"],["79780.14000000","0.00000000"],["71836.20000000","0.00432000"],["71836.00000000","0.00000000"]],"a":[["79818.01000000","0.31404000"],["79834.78000000","0.00000000"],["79892.89000000","0.00400000"]]}}}
{"rx_ns": 14000996106900, "frame": {"stream":"btcusdt@depth@100ms","data":{"e":"depthUpdate","E":1787650996214,"s":"BTCUSDT","U":99118705226,"u":99118705285,"b":[["79818.00000000","2.02947000"],["79817.39000000","0.01749000"],["79816.77000000","0.00000000"],["79816.76000000","0.06077000"],["79816.75000000","0.00000000"],["79816.15000000","0.00000000"],["79816.14000000","0.00014000"],["79815.55000000","0.00000000"],["79815.54000000","0.06091000"],["79815.53000000","0.00939000"],["79815.22000000","0.00000000"],["79815.21000000","0.00000000"],["79813.68000000","0.00000000"],["79812.49000000","0.00000000"],["79802.80000000","0.00007000"],["79769.18000000","0.00007000"],["79766.01000000","0.08127000"],["79758.82000000","0.00007000"],["79745.04000000","0.00000000"],["78620.73000000","0.00030000"],["71836.20000000","0.00416000"],["63854.40000000","0.00000000"]],"a":[["79818.01000000","0.44653000"],["79819.24000000","0.00007000"],["79819.25000000","0.00000000"],["79819.87000000","0.00028000"],["79820.47000000","0.00021000"],["79820.77000000","0.05099000"],["79821.10000000","0.00007000"],["79821.11000000","0.00000000"],["79821.73000000","0.00014000"],["79821.84000000","0.00000000"],["79822.34000000","0.00000000"],["79822.35000000","0.00007000"],["79822.81000000","0.00000000"],["79823.59000000","0.00007000"],["79825.98000000","0.00023000"],["79826.48000000","0.00015000"],["79827.51000000","0.00000000"],["79828.43000000","0.00000000"],["79834.74000000","0.00007000"]]}}}
