{"rx_ns": 13899811558200, "frame": {"stream":"btcusdt@depth20","data":{"lastUpdateId":99118617886,"bids":[["79910.80000000","1.45003000"],["79910.79000000","0.00090000"],["79910.78000000","0.00013000"],["79910.51000000","0.00007000"],["79910.50000000","0.07916000"],["79910.46000000","0.00202000"],["79910.35000000","0.00007000"],["79910.02000000","0.00007000"],["79910.01000000","0.42558000"],["79910.00000000","0.04835000"],["79909.90000000","0.00007000"],["79909.52000000","0.01768000"],["79909.25000000","0.00007000"],["79909.24000000","0.00007000"],["79909.20000000","0.00007000"],["79909.15000000","0.00007000"],["79909.14000000","0.00008000"],["79909.07000000","0.00007000"],["79908.60000000","0.00007000"],["79908.51000000","0.00007000"]],"asks":[["79910.81000000","1.32485000"],["79910.82000000","0.00069000"],["79910.83000000","0.00013000"],["79910.95000000","0.00007000"],["79911.28000000","0.00007000"],["79911.29000000","0.10695000"],["79911.63000000","0.00014000"],["79912.58000000","0.00400000"],["79912.86000000","0.00856000"],["79912.87000000","0.00007000"],["79912.88000000","0.03086000"],["79913.24000000","0.00007000"],["79913.25000000","0.06190000"],["79913.28000000","0.00007000"],["79913.56000000","0.00007000"],["79913.77000000","0.00007000"],["79913.78000000","0.06197000"],["79913.79000000","0.04673000"],["79913.91000000","0.00959000"],["79914.00000000","0.00007000"]]}}}
{"rx_ns": 13899811693100, "frame": {"stream":"btcusdt@depth@100ms","data":{"e":"depthUpdate","E":1787650895014,"s":"BTCUSDT","U":99118617854,"u":99118617886,"b":[["79910.80000000","1.45003000"],["79902.80000000","0.00020000"],["79894.81000000","0.00000000"],["79886.82000000","0.00000000"],["79879.59000000","0.55862000"],["79878.83000000","0.00000000"],["79877.00000000","0.70000000"],["79779.21000000","0.04908000"],["71919.72000000","0.00416000"],["63928.64000000","0.00031000"]],"a":[["79910.81000000","1.32485000"],["79912.88000000","0.03086000"],["79913.25000000","0.06190000"],["79914.14000000","0.01415000"],["79914.45000000","0.00000000"],["79914.47000000","0.06176000"]]}}}
{"rx_ns": 13899898160400, "frame": {"stream":"btcusdt@depth@100ms","data":{"e":"depthUpdate","E":1787650895114,"s":"BTCUSDT","U":99118617887,"u":99118617907,"b":[["79894.81000000","0.00020000"],["79893.57000000","0.02429000"],["79889.80000000","0.00000000"],["79886.82000000","0.00020000"],["79878.83000000","0.00020000"],["71919.72000000","0.00432000"],["63928.64000000","0.00031000"]],"a":[["79910.81000000","1.32926000"],["79914.14000000","0.01415000"]]}}}
{"rx_ns": 13900000739200, "frame": {"stream":"btcusdt@depth@100ms","data":{"e":"depthUpdate","E":1787650895214,"s":"BTCUSDT","U":99118617908,"u":99118617920,"b":[["79905.98000000","0.31308000"],["79905.82000000","0.00007000"],["79905.81000000","0.00659000"],["79893.57000000","0.00000000"],["79890.21000000","0.02411000"],["79832.83000000","0.02086000"],["71919.72000000","0.00416000"],["63928.64000000","0.00000000"]],"a":[["79910.81000000","1.12335000"],["80630.00000000","0.00050000"]]}}}
{"rx_ns": 13900109846200, "frame": {"stream":"btcusdt@depth@100ms","data":{"e":"depthUpdate","E":1787650895314,"s":"BTCUSDT","U":99118617921,"u":99118618166,"b":[["79910.80000000","1.58530000"],["79910.79000000","0.00027000"],["79910.50000000","0.07923000"],["79910.46000000","0.00000000"],["79910.39000000","0.00026000"],["79910.20000000","0.00007000"],["79910.19000000","0.06183000"],["79910.03000000","0.00007000"],["79910.02000000","0.06183000"],["79909.21000000","0.00007000"],["79909.20000000","0.03238000"],["79908.98000000","0.00007000"],["79908.97000000","0.06190000"],["79908.91000000","0.00250000"],["79908.61000000","0.00625000"],["79908.42000000","0.00007000"],["79908.41000000","0.06183000"],["79907.82000000","0.00714000"],["79906.97000000","0.00625000"],["79906.83000000","0.00000000"],["79906.58000000","0.00000000"],["79906.02000000","1.19074000"],["79906.01000000","1.88077000"],["79906.00000000","0.02407000"],["79905.99000000","0.00007000"],["79905.98000000","0.31294000"],["79905.82000000","0.00000000"],["79905.51000000","0.00000000"],["79904.99000000","0.00400000"],["79904.32000000","0.00000000"],["79904.00000000","0.02414000"],["79903.91000000","0.00000000"],["79903.53000000","0.00000000"],["79902.91000000","0.00000000"],["79902.73000000","0.90214000"],["79901.14000000","0.00000000"],["79900.56000000","0.00000000"],["79900.26000000","0.36586000"],["79900.25000000","0.00000000"],["79900.18000000","0.08576000"],["79900.08000000","0.33800000"],["79899.84000000","0.33800000"],["79898.67000000","0.00000000"],["79898.48000000","0.37557000"],["79896.32000000","0.25106000"],["79885.73000000","0.00000000"],["79882.15000000","0.00000000"],["79879.59000000","0.00000000"],["79879.58000000","0.00000000"],["79876.94000000","0.00000000"],["79864.51000000","0.00000000"],["79816.83000000","0.00000000"],["79779.21000000","0.00000000"],["79700.91000000","0.00023000"],["79688.21000000","0.00770000"],["71919.72000000","0.00432000"],["63929.00000000","0.00060000"]],"a":[["79910.81000000","0.06104000"],["79910.82000000","0.00055000"],["79911.28000000","0.00000000"],["79911.29000000","0.00014000"],["79912.58000000","0.00000000"],["79912.87000000","0.00000000"],["79912.88000000","0.00021000"],["79913.24000000","0.00007000"],["79913.91000000","0.00014000"],["79915.50000000","0.00007000"],["79915.68000000","0.00007000"],["79915.69000000","0.06190000"],["79915.92000000","0.06183000"],["79915.93000000","0.00000000"],["79915.94000000","0.00000000"],["79915.96000000","0.00000000"],["79916.14000000","0.00007000"],["79916.15000000","0.73394000"],["79916.16000000","0.31579000"],["79916.45000000","0.00000000"],["79916.76000000","0.00000000"],["79916.97000000","0.00007000"],["79918.07000000","0.00000000"],["79918.08000000","0.00000000"],["79918.44000000","0.00000000"],["79918.47000000","0.00000000"],["79918.61000000","0.00937000"],["79918.89000000","0.00000000"],["79919.36000000","0.00062000"],["79919.37000000","0.00007000"],["79919.89000000","0.00000000"],["79919.96000000","0.55925000"],["79919.97000000","0.00000000"],["79919.99000000","0.00000000"],["79920.78000000","0.00007000"],["79920.95000000","0.00000000"],["79921.74000000","0.00048000"],["79922.38000000","0.00048000"],["79922.55000000","0.00000000"],["79923.16000000","0.00625000"],["79923.56000000","0.00000000"],["79924.08000000","0.40880000"],["79924.09000000","1.04939000"],["79924.10000000","0.00000000"],["79924.12000000","0.00007000"],["79924.52000000","0.00000000"],["79924.85000000","0.08576000"],["79924.88000000","0.00250000"],["79925.59000000","0.00000000"],["79925.99000000","0.00000000"],["79927.87000000","0.01200000"],["79927.93000000","0.02000000"],["79929.45000000","2.92616000"],["79929.46000000","0.00000000"],["79929.62000000","0.00000000"],["79931.75000000","0.00000000"],["79931.96000000","0.88255000"],["79932.85000000","0.00000000"],["79933.60000000","1.23958000"],["79933.61000000","0.00000000"],["79933.62000000","0.00000000"],["79933.96000000","0.00000000"],["79934.71000000","1.87677000"],["79935.74000000","0.43114000"],["79935.75000000","0.00000000"],["79935.76000000","0.00007000"],["79938.00000000","0.64987000"],["79938.18000000","1.04939000"],["79938.52000000","0.00000000"],["79939.78000000","1.27160000"],["79939.79000000","1.87677000"],["79939.88000000","0.00000000"],["79939.89000000","0.00000000"],["79940.29000000","0.04513000"],["79940.56000000","0.00000000"],["79942.66000000","0.00000000"],["79943.80000000","0.31489000"],["79945.95000000","0.00000000"],["79954.06000000","0.33790000"],["79954.20000000","0.00007000"],["79958.12000000","0.00400000"],["79961.85000000","1.23840000"],["80007.82000000","0.41671000"],["80007.83000000","0.00000000"],["80013.89000000","0.00010000"]]}}}
{"rx_ns": 13900210500300, "frame": {"stream":"btcusdt@depth@100ms","data":{"e":"depthUpdate","E":1787650895414,"s":"BTCUSDT","U":99118618167,"u":99118619900,"b":[["79910.80000000","0.00000000"],["79910.79000000","0.00000000"],["79910.78000000","0.00000000"],["79910.51000000","0.00000000"],["79910.50000000","0.00000000"],["79910.39000000","0.00000000"],["79910.36000000","0.00000000"],["79910.35000000","0.00000000"],["79910.20000000","0.00000000"],["79910.19000000","0.00000000"],["79910.06000000","0.00000000"],["79910.03000000","0.00000000"],["79910.02000000","0.00000000"],["79910.01000000","0.00000000"],["79910.00000000","0.00000000"],["79909.90000000","0.00000000"],["79909.53000000","0.00000000"],["79909.52000000","0.00000000"],["79909.25000000","0.00000000"],["79909.24000000","0.00000000"],["79909.21000000","0.00000000"],["79909.20000000","0.00000000"],["79909.15000000","0.00000000"],["79909.14000000","0.00000000"],["79909.07000000","0.00000000"],["79908.98000000","0.00000000"],["79908.97000000","0.00000000"],["79908.91000000","0.00000000"],["79908.61000000","0.00000000"],["79908.60000000","0.00000000"],["79908.51000000","0.00000000"],["79908.44000000","0.00000000"],["79908.42000000","0.00000000"],["79908.41000000","0.00000000"],["79908.40000000","0.00000000"],["79908.33000000","0.00000000"],["79908.30000000","0.00000000"],["79908.24000000","0.00000000"],["79908.21000000","0.00000000"],["79908.20000000","0.00000000"],["79908.06000000","0.00000000"],["79908.00000000","0.00000000"],["79907.82000000","0.00000000"],["79907.76000000","0.00000000"],["79907.52000000","0.00000000"],["79906.97000000","0.00000000"],["79906.96000000","0.00000000"],["79906.85000000","0.00000000"],["79906.18000000","0.00000000"],["79906.03000000","0.00000000"],["79906.02000000","0.00000000"],["79906.01000000","0.00000000"],["79906.00000000","1.61153000"],["79905.99000000","0.00063000"],["79905.98000000","0.00021000"],["79905.89000000","0.00000000"],["79905.81000000","0.00000000"],["79905.52000000","0.00000000"],["79905.50000000","0.00000000"],["79905.38000000","0.00000000"],["79905.30000000","0.00000000"],["79904.99000000","0.00000000"],["79904.82000000","0.00000000"],["79904.81000000","0.00000000"],["79904.78000000","0.00000000"],["79904.32000000","0.00000000"],["79904.31000000","0.00000000"],["79904.30000000","0.00007000"],["79904.17000000","0.00000000"],["79904.11000000","0.00000000"],["79904.01000000","0.00007000"],["79904.00000000","0.02421000"],["79903.99000000","0.00000000"],["79903.89000000","0.00007000"],["79903.64000000","0.00000000"],["79903.63000000","0.00000000"],["79903.56000000","0.00007000"],["79903.55000000","0.05297000"],["79903.35000000","0.00000000"],["79903.31000000","0.00000000"],["79903.26000000","0.00026000"],["79903.02000000","0.00000000"],["79902.95000000","0.00000000"],["79902.90000000","0.00000000"],["79902.81000000","0.00000000"],["79902.74000000","0.00000000"],["79902.73000000","0.00000000"],["79902.72000000","0.00007000"],["79902.69000000","0.00000000"],["79902.46000000","0.00000000"],["79902.34000000","0.06179000"],["79902.01000000","0.00007000"],["79902.00000000","0.02414000"],["79901.73000000","0.06179000"],["79901.12000000","0.06179000"],["79901.10000000","0.00000000"],["79901.07000000","0.00000000"],["79901.02000000","0.00644000"],["79901.01000000","0.00020000"],["79900.83000000","0.00000000"],["79900.55000000","0.00000000"],["79900.51000000","0.06179000"],["79900.27000000","1.04939000"],["79900.26000000","0.00000000"],["79900.25000000","0.00000000"],["79900.24000000","0.00000000"],["79900.19000000","0.00000000"],["79900.18000000","0.00007000"],["79900.08000000","0.00000000"],["79900.02000000","0.00007000"],["79900.01000000","0.06183000"],["79900.00000000","0.02421000"],["79899.99000000","0.32573000"],["79899.84000000","0.00000000"],["79899.39000000","1.87677000"],["79899.38000000","0.00000000"],["79899.37000000","0.00000000"],["79899.29000000","0.06179000"],["79898.68000000","0.06176000"],["79898.63000000","0.02000000"],["79898.48000000","0.00000000"],["79898.42000000","0.00000000"],["79898.32000000","0.00000000"],["79898.19000000","0.00008000"],["79898.09000000","0.00000000"],["79898.07000000","0.05862000"],["79898.01000000","0.00007000"],["79898.00000000","0.22657000"],["79897.99000000","0.00000000"],["79897.79000000","0.00000000"],["79897.65000000","0.12516000"],["79897.47000000","0.00007000"],["79897.46000000","0.06183000"],["79897.09000000","0.00048000"],["79897.01000000","0.00000000"],["79896.86000000","0.00007000"],["79896.85000000","0.06176000"],["79896.32000000","0.00000000"],["79896.31000000","0.00000000"],["79896.29000000","0.00007000"],["79896.25000000","0.00007000"],["79896.24000000","0.06176000"],["79896.16000000","0.00000000"],["79896.15000000","0.00007000"],["79895.68000000","0.06176000"],["79895.67000000","0.00000000"],["79895.29000000","0.00693000"],["79895.04000000","0.00000000"],["79895.02000000","0.06176000"],["79894.58000000","0.00000000"],["79894.41000000","0.06176000"],["79894.07000000","0.06176000"],["79894.06000000","1.87677000"],["79894.05000000","0.19044000"],["79894.04000000","0.00000000"],["79894.01000000","0.00000000"],["79893.99000000","0.00934000"],["79893.87000000","0.00000000"],["79893.85000000","0.00000000"],["79893.78000000","0.00000000"],["79893.72000000","0.00007000"],["79893.67000000","0.00000000"],["79893.30000000","0.00000000"],["79893.23000000","0.00008000"],["79893.19000000","0.09400000"],["79893.09000000","0.00007000"],["79893.03000000","0.00000000"],["79893.01000000","0.00000000"],["79892.97000000","0.00000000"],["79892.84000000","0.00000000"],["79892.81000000","0.06176000"],["79892.80000000","0.07000000"],["79892.45000000","0.00000000"],["79892.28000000","0.00007000"],["79892.01000000","0.06225000"],["79892.00000000","0.02400000"],["79891.99000000","0.00000000"],["79891.57000000","0.00000000"],["79891.37000000","0.00000000"],["79891.36000000","0.06176000"],["79891.29000000","0.00697000"],["79891.17000000","0.00000000"],["79890.75000000","0.06176000"],["79890.59000000","0.00000000"],["79890.56000000","0.00000000"],["79890.20000000","0.00007000"],["79890.15000000","1.41525000"],["79890.14000000","0.06176000"],["79890.13000000","0.00000000"],["79890.02000000","0.00000000"],["79890.01000000","0.06183000"],["79890.00000000","0.11853000"],["79889.99000000","0.20250000"],["79889.92000000","0.00000000"],["79889.81000000","0.00400000"],["79889.78000000","0.00000000"],["79889.77000000","0.00000000"],["79889.74000000","0.00000000"],["79889.73000000","0.00000000"],["79889.66000000","0.12517000"],["79889.58000000","0.00625000"],["79889.57000000","0.00007000"],["79889.26000000","0.06280000"],["79889.23000000","0.00008000"],["79889.20000000","0.08007000"],["79888.92000000","0.06176000"],["79888.88000000","0.00163000"],["79888.42000000","0.00000000"],["79888.41000000","0.00007000"],["79888.31000000","0.06176000"],["79888.02000000","1.87677000"],["79888.01000000","0.00000000"],["79887.98000000","0.00000000"],["79887.70000000","0.06176000"],["79887.51000000","0.32813000"],["79887.50000000","0.00000000"],["79887.37000000","0.00000000"],["79887.29000000","0.00707000"],["79887.09000000","0.06176000"],["79886.95000000","0.00000000"],["79886.48000000","0.06176000"],["79886.02000000","0.00007000"],["79886.00000000","0.02400000"],["79885.87000000","0.00000000"],["79885.54000000","0.06280000"],["79885.26000000","0.00000000"],["79885.24000000","0.00008000"],["79885.22000000","0.06280000"],["79885.21000000","1.04939000"],["79885.01000000","0.00000000"],["79884.90000000","0.00000000"],["79884.54000000","0.00007000"],["79884.04000000","0.00000000"],["79883.95000000","0.00000000"],["79883.91000000","0.00026000"],["79883.88000000","0.00000000"],["79883.43000000","0.00000000"],["79883.33000000","0.00007000"],["79883.29000000","0.00709000"],["79882.82000000","0.00000000"],["79882.21000000","0.00000000"],["79882.16000000","0.93458000"],["79882.15000000","1.87677000"],["79882.14000000","0.00000000"],["79882.12000000","0.00000000"],["79882.11000000","0.00000000"],["79882.10000000","0.00000000"],["79882.09000000","0.36586000"],["79882.08000000","0.00000000"],["79882.02000000","0.00000000"],["79881.67000000","0.12518000"],["79881.43000000","0.00000000"],["79881.42000000","0.00000000"],["79881.24000000","0.00008000"],["79881.14000000","1.04939000"],["79880.67000000","0.00007000"],["79880.00000000","0.11790000"],["79879.29000000","0.00696000"],["79879.02000000","0.00000000"],["79878.92000000","0.00000000"],["79878.12000000","0.00000000"],["79878.03000000","0.02100000"],["79877.59000000","0.47020000"],["79877.25000000","0.00008000"],["79877.01000000","0.33914000"],["79876.80000000","0.00007000"],["79876.71000000","1.04939000"],["79876.60000000","0.00000000"],["79876.12000000","0.37567000"],["79875.67000000","0.09434000"],["79874.77000000","0.00000000"],["79874.03000000","0.00000000"],["79874.02000000","0.62599000"],["79874.01000000","2.24263000"],["79873.99000000","0.00000000"],["79873.98000000","0.00000000"],["79873.76000000","0.00000000"],["79873.34000000","0.00000000"],["79873.25000000","0.00008000"],["79873.04000000","0.00000000"],["79872.93000000","0.00007000"],["79872.39000000","1.04939000"],["79872.38000000","0.00000000"],["79872.01000000","0.30000000"],["79870.67000000","0.00000000"],["79870.00000000","0.12042000"],["79869.88000000","0.33813000"],["79869.26000000","0.20258000"],["79869.06000000","0.00007000"],["79868.61000000","0.00000000"],["79868.55000000","0.62618000"],["79867.69000000","1.04939000"],["79867.04000000","0.00400000"],["79866.00000000","0.03400000"],["79865.59000000","2.24263000"],["79865.58000000","0.00000000"],["79865.57000000","0.00000000"],["79865.56000000","0.00000000"],["79865.54000000","0.00000000"],["79865.50000000","0.00000000"],["79865.19000000","0.00007000"],["79864.65000000","0.00000000"],["79864.51000000","0.00400000"],["79864.36000000","0.00000000"],["79862.56000000","1.04939000"],["79862.23000000","0.00000000"],["79861.98000000","0.00400000"],["79861.32000000","0.00007000"],["79860.33000000","0.00000000"],["79860.14000000","0.00000000"],["79859.45000000","0.00400000"],["79858.92000000","0.00000000"],["79858.91000000","0.00000000"],["79857.47000000","0.50963000"],["79857.45000000","0.00007000"],["79857.25000000","0.36586000"],["79857.24000000","1.04939000"],["79856.93000000","0.00000000"],["79856.92000000","0.00400000"],["79856.00000000","1.90084000"],["79855.72000000","0.00000000"],["79855.65000000","0.00000000"],["79855.41000000","0.00000000"],["79854.39000000","0.00400000"],["79854.04000000","0.00000000"],["79853.58000000","0.00000000"],["79853.37000000","0.34807000"],["79852.08000000","1.04939000"],["79851.86000000","0.00400000"],["79851.32000000","0.60956000"],["79851.31000000","0.00000000"],["79849.71000000","0.00000000"],["79849.33000000","0.00000000"],["79848.06000000","1.87677000"],["79848.05000000","0.36586000"],["79847.10000000","0.00000000"],["79847.09000000","0.00000000"],["79846.85000000","0.00000000"],["79846.80000000","0.00000000"],["79845.96000000","0.00000000"],["79844.27000000","0.00000000"],["79842.89000000","0.00000000"],["79842.77000000","1.04939000"],["79842.75000000","0.00000000"],["79842.73000000","0.00000000"],["79841.69000000","1.87677000"],["79841.22000000","0.00000000"],["79841.07000000","1.24027000"],["79838.01000000","0.00312000"],["79837.72000000","1.04939000"],["79836.61000000","0.00312000"],["79836.60000000","1.24034000"],["79836.44000000","0.00000000"],["79836.02000000","0.00000000"],["79832.83000000","0.00000000"],["79832.10000000","1.87677000"],["79832.06000000","0.00000000"],["79829.97000000","0.00000000"],["79829.76000000","0.12208000"],["79828.01000000","1.04939000"],["79827.99000000","0.00000000"],["79826.42000000","0.00000000"],["79825.69000000","0.00000000"],["79823.82000000","1.04939000"],["79823.79000000","0.00000000"],["79823.53000000","0.67039000"],["79822.61000000","1.87677000"],["79822.60000000","0.00000000"],["79819.40000000","0.00000000"],["79816.83000000","1.87677000"],["79815.85000000","0.06678000"],["79809.01000000","1.04939000"],["79807.24000000","1.87677000"],["79798.63000000","1.05103000"],["79798.62000000","1.04939000"],["79797.65000000","1.87677000"],["79788.23000000","1.04939000"],["79788.06000000","0.00000000"],["79778.96000000","1.04939000"],["79778.47000000","0.00000000"],["79773.43000000","0.00000000"],["79771.84000000","0.04532000"],["79768.57000000","1.04939000"],["79766.68000000","0.60113000"],["79766.67000000","0.00000000"],["79758.18000000","0.00000000"],["79757.08000000","0.00000000"],["79753.45000000","0.00000000"],["79747.49000000","0.00000000"],["79743.29000000","0.08585000"],["79737.90000000","0.00000000"],["79728.31000000","0.00000000"],["79718.72000000","0.00000000"],["79593.81000000","0.00000000"],["79581.53000000","7.54135000"],["78712.13000000","0.00000000"],["71919.72000000","0.00000000"],["71915.56000000","0.00008000"]],"a":[["79906.01000000","3.45046000"],["79906.02000000","0.00034000"],["79906.03000000","0.00020000"],["79906.04000000","0.00000000"],["79906.18000000","0.00007000"],["79906.19000000","0.00007000"],["79906.79000000","0.00007000"],["79906.80000000","0.00007000"],["79906.95000000","0.00000000"],["79907.40000000","0.00007000"],["79907.41000000","0.00000000"],["79907.52000000","0.00400000"],["79907.76000000","0.00014000"],["79907.81000000","1.00497000"],["79907.82000000","0.00000000"],["79907.83000000","0.00967000"],["79908.07000000","0.00007000"],["79908.21000000","0.00007000"],["79908.25000000","0.00007000"],["79908.41000000","0.00007000"],["79908.51000000","0.00000000"],["79908.52000000","0.00007000"],["79908.61000000","0.00007000"],["79908.62000000","0.35330000"],["79908.92000000","0.00000000"],["79908.98000000","0.00007000"],["79908.99000000","0.00000000"],["79909.07000000","0.00000000"],["79909.08000000","0.00007000"],["79909.14000000","0.04716000"],["79909.15000000","0.00000000"],["79909.16000000","0.00000000"],["79909.19000000","0.00007000"],["79909.20000000","0.00007000"],["79909.21000000","0.00014000"],["79909.23000000","0.00000000"],["79909.25000000","0.00000000"],["79909.26000000","0.00007000"],["79909.41000000","0.00000000"],["79909.53000000","0.00021000"],["79909.77000000","0.00007000"],["79909.82000000","0.00000000"],["79909.91000000","0.00007000"],["79910.01000000","0.00021000"],["79910.02000000","0.00007000"],["79910.03000000","0.00007000"],["79910.05000000","0.00400000"],["79910.20000000","0.00021000"],["79910.22000000","0.00007000"],["79910.33000000","0.00007000"],["79910.36000000","0.00007000"],["79910.40000000","0.00007000"],["79910.43000000","0.00000000"],["79910.51000000","0.00014000"],["79910.52000000","0.00007000"],["79910.79000000","0.00007000"],["79910.80000000","0.07528000"],["79910.81000000","0.67434000"],["79910.82000000","0.00000000"],["79910.83000000","0.00000000"],["79911.15000000","0.00000000"],["79911.29000000","0.00000000"],["79911.42000000","0.00000000"],["79911.46000000","0.00000000"],["79911.47000000","0.00000000"],["79911.63000000","0.00021000"],["79912.03000000","0.00000000"],["79912.26000000","0.00000000"],["79912.41000000","0.00007000"],["79912.58000000","0.00400000"],["79912.63000000","0.00000000"],["79912.64000000","0.00000000"],["79912.86000000","0.00835000"],["79912.88000000","0.00007000"],["79912.91000000","0.02000000"],["79913.00000000","0.00013000"],["79913.23000000","0.15515000"],["79913.24000000","0.00000000"],["79913.25000000","0.00000000"],["79913.28000000","0.00000000"],["79913.32000000","0.00695000"],["79913.40000000","0.12513000"],["79913.55000000","0.00000000"],["79913.56000000","0.00000000"],["79913.76000000","0.00000000"],["79913.77000000","0.00000000"],["79913.78000000","0.00000000"],["79913.79000000","0.00000000"],["79913.89000000","0.00026000"],["79913.91000000","0.00000000"],["79913.99000000","0.00000000"],["79914.00000000","0.00000000"],["79914.13000000","0.00000000"],["79914.14000000","0.01380000"],["79914.18000000","0.00922000"],["79914.37000000","0.00000000"],["79914.46000000","0.00000000"],["79914.47000000","0.00000000"],["79914.67000000","0.00007000"],["79914.69000000","0.05000000"],["79915.07000000","0.00000000"],["79915.08000000","0.00000000"],["79915.09000000","0.02000000"],["79915.11000000","0.00400000"],["79915.15000000","0.00000000"],["79915.34000000","0.00710000"],["79915.41000000","0.00000000"],["79915.42000000","0.01657000"],["79915.50000000","0.00014000"],["79915.67000000","0.00000000"],["79915.68000000","0.00000000"],["79915.69000000","0.00000000"],["79915.82000000","0.00008000"],["79915.87000000","0.00000000"],["79915.91000000","0.00000000"],["79915.92000000","0.00000000"],["79915.97000000","0.00000000"],["79916.14000000","0.00000000"],["79916.15000000","1.36554000"],["79916.16000000","0.31572000"],["79916.36000000","0.00007000"],["79916.61000000","0.04009000"],["79916.70000000","0.01657000"],["79916.80000000","0.00000000"],["79916.91000000","0.00000000"],["79916.97000000","0.00000000"],["79916.98000000","0.98427000"],["79917.71000000","0.00010000"],["79917.81000000","0.00007000"],["79917.87000000","0.00007000"],["79918.13000000","0.00000000"],["79918.47000000","0.00007000"],["79918.61000000","0.00000000"],["79918.74000000","0.00000000"],["79918.76000000","0.00000000"],["79918.80000000","0.00000000"],["79918.91000000","0.00000000"],["79918.97000000","0.00000000"],["79919.02000000","0.00000000"],["79919.32000000","0.00912000"],["79919.34000000","0.00685000"],["79919.36000000","0.00000000"],["79919.37000000","0.00014000"],["79919.95000000","2.24263000"],["79919.99000000","0.08000000"],["79920.29000000","0.00000000"],["79920.62000000","0.00000000"],["79920.78000000","0.00000000"],["79920.80000000","0.03224000"],["79920.81000000","0.00000000"],["79921.34000000","0.00000000"],["79921.67000000","0.00000000"],["79921.74000000","1.04939000"],["79922.38000000","0.00000000"],["79922.69000000","0.00000000"],["79923.16000000","0.00000000"],["79923.17000000","0.00000000"],["79923.27000000","0.00000000"],["79924.06000000","0.94003000"],["79924.07000000","0.00000000"],["79924.08000000","0.00000000"],["79924.09000000","0.00000000"],["79924.11000000","0.00000000"],["79924.26000000","0.09617000"],["79924.27000000","0.00000000"],["79924.85000000","0.00000000"],["79924.88000000","0.00000000"],["79925.19000000","0.00008000"],["79925.77000000","1.04939000"],["79925.79000000","1.87677000"],["79926.26000000","0.10375000"],["79926.47000000","0.00000000"],["79926.89000000","0.00000000"],["79927.47000000","0.00000000"],["79927.87000000","0.00800000"],["79927.93000000","0.00000000"],["79928.59000000","0.00000000"],["79928.89000000","0.00000000"],["79929.02000000","0.00000000"],["79929.19000000","0.00008000"],["79929.45000000","0.00000000"],["79929.98000000","0.00000000"],["79930.00000000","0.11784000"],["79930.95000000","0.00250000"],["79930.97000000","0.42937000"],["79933.18000000","0.00008000"],["79933.39000000","0.33786000"],["79933.60000000","1.04939000"],["79933.98000000","0.00007000"],["79934.81000000","0.00000000"],["79935.73000000","0.00000000"],["79935.74000000","0.00000000"],["79936.60000000","0.00000000"],["79936.70000000","0.00000000"],["79936.94000000","0.09438000"],["79937.10000000","0.00000000"],["79937.18000000","0.00008000"],["79937.97000000","0.00000000"],["79938.00000000","0.02400000"],["79940.00000000","0.33685000"],["79940.26000000","0.62562000"],["79940.33000000","0.00000000"],["79941.17000000","0.00008000"],["79941.97000000","0.00000000"],["79942.17000000","0.67226000"],["79945.17000000","0.00008000"],["79945.33000000","0.00000000"],["79945.47000000","0.00400000"],["79945.53000000","0.00000000"],["79945.97000000","0.00000000"],["79946.46000000","0.00000000"],["79946.88000000","0.00000000"],["79947.97000000","0.00000000"],["79948.00000000","0.22650000"],["79948.52000000","0.00000000"],["79949.16000000","0.00008000"],["79949.96000000","0.00000000"],["79950.00000000","0.12761000"],["79950.33000000","0.00000000"],["79950.53000000","0.00000000"],["79951.61000000","0.00000000"],["79951.62000000","0.39399000"],["79952.03000000","0.00000000"],["79952.66000000","0.00000000"],["79953.06000000","0.00000000"],["79953.96000000","0.00000000"],["79954.06000000","0.00000000"],["79954.20000000","0.00000000"],["79954.26000000","0.00000000"],["79954.59000000","0.00000000"],["79955.59000000","0.00000000"],["79956.35000000","0.00000000"],["79957.46000000","0.00000000"],["79958.12000000","0.00000000"],["79959.50000000","0.00000000"],["79959.88000000","0.67544000"],["79961.70000000","0.00000000"],["79961.72000000","1.04939000"],["79961.73000000","0.00000000"],["79961.85000000","0.00000000"],["79964.97000000","0.00000000"],["79967.82000000","0.13292000"],["79969.09000000","0.00000000"],["79972.68000000","0.00000000"],["79973.83000000","1.23819000"],["79988.81000000","0.00000000"],["79992.10000000","0.00000000"],["79992.54000000","0.11799000"],["79993.19000000","0.00000000"],["80011.41000000","0.00000000"],["80013.72000000","0.00011000"],["80057.08000000","0.00000000"],["80157.41000000","0.00000000"],["81109.48000000","0.00000000"]]}}}
{"rx_ns": 13900302508200, "frame": {"stream":"btcusdt@depth@100ms","data":{"e":"depthUpdate","E":1787650895514,"s":"BTCUSDT","U":99118619901,"u":99118620628,"b":[["79906.00000000","0.27182000"],["79905.99000000","0.00070000"],["79905.98000000","0.00000000"],["79905.08000000","0.00917000"],["79904.76000000","0.00000000"],["79904.34000000","0.00000000"],["79904.33000000","0.00000000"],["79904.32000000","0.00000000"],["79904.15000000","0.00000000"],["79904.14000000","0.00000000"],["79904.01000000","0.00007000"],["79904.00000000","0.02442000"],["79903.82000000","0.00007000"],["79903.81000000","0.01529000"],["79903.63000000","0.00000000"],["79903.57000000","0.00000000"],["79903.56000000","0.06287000"],["79903.55000000","0.05325000"],["79903.54000000","0.00000000"],["79903.26000000","0.00000000"],["79902.91000000","0.00000000"],["79902.90000000","0.06280000"],["79902.80000000","0.00000000"],["79902.54000000","0.00007000"],["79902.53000000","0.01835000"],["79902.35000000","0.00000000"],["79902.34000000","0.00014000"],["79902.28000000","0.06280000"],["79902.01000000","0.00007000"],["79902.00000000","0.02449000"],["79901.74000000","0.00000000"],["79901.73000000","0.00021000"],["79901.67000000","0.00007000"],["79901.66000000","0.06280000"],["79901.52000000","0.00000000"],["79901.35000000","0.00000000"],["79901.26000000","0.00007000"],["79901.25000000","0.01842000"],["79901.13000000","0.00000000"],["79901.12000000","0.00014000"],["79901.07000000","0.00008000"],["79901.05000000","0.00007000"],["79901.04000000","0.06287000"],["79901.03000000","0.00007000"],["79901.02000000","0.00021000"],["79900.52000000","0.00000000"],["79900.51000000","0.00021000"],["79900.49000000","0.31121000"],["79900.47000000","0.00007000"],["79900.46000000","0.06287000"],["79900.45000000","0.31296000"],["79900.28000000","0.00000000"],["79900.27000000","0.00000000"],["79900.10000000","0.00000000"],["79900.02000000","0.00014000"],["79900.01000000","0.06280000"],["79900.00000000","0.02414000"],["79899.99000000","0.32566000"],["79899.39000000","0.00000000"],["79899.29000000","0.00000000"],["79899.18000000","0.06280000"],["79898.83000000","0.02000000"],["79898.77000000","0.00929000"],["79898.68000000","0.00000000"],["79898.63000000","0.00000000"],["79898.57000000","0.06280000"],["79898.56000000","0.00000000"],["79898.48000000","0.00000000"],["79898.20000000","0.00000000"],["79898.16000000","0.00000000"],["79898.07000000","0.00000000"],["79898.02000000","0.00000000"],["79898.01000000","0.06280000"],["79898.00000000","0.22670000"],["79897.92000000","0.00000000"],["79897.47000000","0.00000000"],["79897.46000000","0.00000000"],["79897.40000000","0.00400000"],["79897.09000000","0.00000000"],["79896.86000000","0.00000000"],["79896.85000000","0.00000000"],["79896.71000000","0.06280000"],["79896.70000000","0.00000000"],["79896.43000000","0.00048000"],["79896.30000000","0.00011000"],["79896.25000000","0.00000000"],["79896.24000000","0.00000000"],["79896.15000000","0.00014000"],["79896.08000000","0.06111000"],["79895.81000000","0.00000000"],["79895.68000000","0.00000000"],["79895.58000000","0.00000000"],["79895.46000000","0.06280000"],["79895.02000000","0.00000000"],["79895.00000000","0.00000000"],["79894.95000000","0.02478000"],["79894.87000000","0.00400000"],["79894.84000000","0.06280000"],["79894.81000000","0.00000000"],["79894.41000000","0.00000000"],["79894.23000000","0.66420000"],["79894.22000000","0.06280000"],["79894.09000000","0.06280000"],["79894.08000000","0.00400000"],["79894.07000000","0.00000000"],["79894.06000000","0.00000000"],["79894.05000000","0.00000000"],["79893.85000000","0.00000000"],["79893.24000000","0.00000000"],["79893.19000000","0.03224000"],["79892.98000000","0.06280000"],["79892.91000000","0.00000000"],["79892.83000000","0.06280000"],["79892.82000000","1.87677000"],["79892.81000000","0.00000000"],["79892.79000000","0.00000000"],["79892.36000000","0.00000000"],["79892.34000000","0.00400000"],["79892.28000000","0.00014000"],["79892.01000000","0.00026000"],["79891.74000000","0.00000000"],["79891.36000000","0.00000000"],["79891.12000000","0.00000000"],["79890.83000000","0.01250000"],["79890.78000000","0.00007000"],["79890.75000000","0.00000000"],["79890.50000000","0.00000000"],["79890.22000000","0.00400000"],["79890.21000000","0.00000000"],["79890.17000000","0.00000000"],["79890.16000000","1.20833000"],["79890.15000000","1.04939000"],["79890.14000000","0.00000000"],["79890.02000000","0.00007000"],["79890.01000000","0.00027000"],["79890.00000000","0.02400000"],["79889.58000000","0.00000000"],["79889.26000000","0.00000000"],["79888.92000000","0.00000000"],["79888.41000000","0.00014000"],["79888.31000000","0.00000000"],["79887.70000000","0.00000000"],["79887.09000000","0.00000000"],["79886.82000000","0.00000000"],["79886.48000000","0.00000000"],["79885.85000000","0.37563000"],["79885.54000000","0.00000000"],["79885.22000000","0.00000000"],["79884.54000000","0.00014000"],["79882.85000000","0.33808000"],["79882.69000000","0.00060000"],["79882.19000000","0.33808000"],["79882.02000000","0.00020000"],["79881.45000000","1.20165000"],["79880.93000000","0.00012000"],["79880.67000000","0.00014000"],["79878.83000000","0.00000000"],["79877.88000000","0.00000000"],["79877.73000000","0.00000000"],["79877.00000000","0.00000000"],["79876.80000000","0.00014000"],["79875.59000000","0.00400000"],["79874.03000000","0.00020000"],["79872.93000000","0.00014000"],["79869.06000000","0.00014000"],["79865.19000000","0.00007000"],["79861.32000000","0.00000000"],["79857.45000000","0.00000000"],["79856.92000000","0.00000000"],["79855.79000000","0.00000000"],["79854.59000000","0.83199000"],["79854.39000000","0.00000000"],["79853.21000000","0.00000000"],["79851.99000000","0.00000000"],["79851.86000000","0.00000000"],["79851.41000000","0.00012000"],["79846.20000000","0.00427000"],["79844.82000000","0.00426000"],["79837.79000000","0.00000000"],["79837.67000000","0.00000000"],["79836.67000000","0.00626000"],["79835.65000000","0.00400000"],["79829.21000000","0.06092000"],["79825.03000000","0.02086000"],["79805.84000000","0.00000000"],["79803.70000000","0.00400000"],["79766.68000000","0.00000000"],["79757.91000000","0.00000000"],["79755.77000000","0.00400000"],["79686.02000000","0.00000000"],["79683.88000000","0.00400000"],["79680.56000000","0.00007000"],["79676.57000000","0.00000000"],["79608.29000000","0.00000000"],["79581.35000000","0.00030000"],["78707.41000000","0.00030000"],["71915.40000000","0.00032000"],["63924.80000000","0.00031000"]],"a":[["79906.01000000","2.70371000"],["79906.18000000","0.00000000"],["79906.19000000","0.00000000"],["79906.54000000","0.00007000"],["79906.55000000","0.00007000"],["79906.56000000","0.04053000"],["79906.79000000","0.00000000"],["79906.80000000","0.00000000"],["79907.24000000","0.00007000"],["79907.25000000","0.00007000"],["79907.40000000","0.00000000"],["79907.76000000","0.00014000"],["79907.79000000","0.00007000"],["79907.80000000","0.00007000"],["79907.81000000","0.32585000"],["79907.83000000","0.00021000"],["79907.91000000","0.00000000"],["79908.48000000","0.00007000"],["79908.49000000","0.00007000"],["79908.51000000","0.00000000"],["79908.60000000","0.00007000"],["79908.61000000","0.00007000"],["79908.62000000","0.35344000"],["79908.70000000","0.00000000"],["79909.13000000","0.00007000"],["79909.14000000","0.04737000"],["79909.19000000","0.00000000"],["79909.20000000","0.00000000"],["79909.21000000","0.00000000"],["79909.30000000","0.00000000"],["79909.53000000","0.00000000"],["79909.61000000","0.00000000"],["79909.62000000","0.00000000"],["79909.73000000","0.00000000"],["79910.01000000","0.00000000"],["79910.20000000","0.00000000"],["79910.35000000","0.00000000"],["79910.51000000","0.00000000"],["79910.79000000","0.00007000"],["79910.80000000","0.00021000"],["79910.81000000","0.56927000"],["79911.63000000","0.00014000"],["79912.21000000","0.00000000"],["79912.83000000","0.00000000"],["79912.86000000","0.00007000"],["79912.88000000","0.00000000"],["79912.91000000","0.00000000"],["79912.99000000","0.00000000"],["79913.22000000","0.00000000"],["79913.23000000","0.65429000"],["79913.39000000","0.00000000"],["79913.89000000","0.00000000"],["79914.07000000","0.00000000"],["79914.14000000","0.00000000"],["79914.69000000","0.00000000"],["79915.01000000","1.87677000"],["79915.09000000","0.00000000"],["79915.22000000","0.00000000"],["79915.31000000","0.00000000"],["79915.42000000","0.00000000"],["79915.50000000","0.00014000"],["79915.59000000","0.00000000"],["79915.84000000","0.00026000"],["79915.93000000","0.00000000"],["79916.13000000","0.00000000"],["79916.14000000","0.00800000"],["79916.15000000","0.63167000"],["79916.18000000","0.00165000"],["79916.70000000","0.00000000"],["79916.97000000","1.04939000"],["79917.99000000","0.00000000"],["79918.82000000","0.02000000"],["79919.31000000","0.00000000"],["79919.36000000","0.00000000"],["79919.88000000","0.19019000"],["79919.89000000","0.07000000"],["79919.93000000","1.50371000"],["79919.94000000","1.87677000"],["79919.95000000","0.36586000"],["79919.96000000","0.00000000"],["79920.48000000","0.00192000"],["79920.80000000","0.00000000"],["79921.73000000","1.04939000"],["79921.74000000","0.00000000"],["79922.75000000","0.00007000"],["79924.59000000","0.00625000"],["79925.76000000","0.41540000"],["79927.56000000","0.00000000"],["79927.87000000","0.00000000"],["79927.88000000","0.00000000"],["79928.00000000","0.64999000"],["79930.00000000","0.11784000"],["79930.97000000","0.00000000"],["79932.99000000","0.00000000"],["79933.07000000","0.33786000"],["79935.56000000","0.00191000"],["79936.27000000","0.00012000"],["79936.94000000","0.00000000"],["79937.62000000","0.00400000"],["79938.18000000","1.04999000"],["79939.41000000","0.42933000"],["79940.29000000","0.00000000"],["79940.42000000","0.00000000"],["79942.52000000","0.00000000"],["79943.30000000","0.04601000"],["79946.00000000","0.03400000"],["79946.25000000","0.00627000"],["79946.46000000","0.00000000"],["79947.34000000","0.00426000"],["79947.81000000","0.00434000"],["79948.00000000","0.22650000"],["79949.43000000","0.00435000"],["79950.00000000","0.12510000"],["79950.33000000","0.00000000"],["79950.80000000","0.83099000"],["79951.00000000","0.00000000"],["79951.56000000","0.03456000"],["79951.62000000","0.00000000"],["79955.98000000","0.00000000"],["79975.39000000","0.00111000"],["79977.59000000","0.00400000"],["79982.50000000","0.00000000"],["79992.54000000","0.00000000"],["79993.15000000","0.00000000"],["79994.98000000","0.00000000"],["79995.03000000","0.11868000"],["80006.60000000","0.25000000"],["80057.53000000","0.00400000"],["80062.44000000","0.00000000"],["80129.48000000","0.00400000"],["80134.39000000","0.00000000"],["80181.35000000","0.00036000"],["80190.68000000","0.00000000"],["80237.26000000","0.03627000"]]}}}
{"rx_ns": 13900396251200, "frame": {"stream":"btcusdt@depth@100ms","data":{"e":"depthUpdate","E":1787650895614,"s":"BTCUSDT","U":99118620629,"u":99118620822,"b":[["79906.00000000","0.27413000"],["79905.99000000","0.00091000"],["79905.71000000","0.33793000"],["79905.08000000","0.00938000"],["79904.15000000","0.00007000"],["79904.14000000","0.06280000"],["79904.00000000","0.02442000"],["79903.81000000","0.01543000"],["79903.57000000","0.00007000"],["79903.56000000","0.06301000"],["79903.55000000","0.05325000"],["79902.91000000","0.00007000"],["79902.90000000","0.06294000"],["79902.53000000","0.01856000"],["79902.50000000","0.02776000"],["79902.34000000","0.00000000"],["79902.29000000","0.00007000"],["79902.28000000","0.06294000"],["79902.01000000","0.00007000"],["79902.00000000","0.02428000"],["79901.73000000","0.00000000"],["79901.67000000","0.00007000"],["79901.26000000","0.00000000"],["79901.12000000","0.00000000"],["79901.05000000","0.00000000"],["79901.04000000","0.06294000"],["79901.03000000","0.00000000"],["79901.02000000","0.00007000"],["79900.87000000","0.00000000"],["79900.51000000","0.66698000"],["79900.50000000","1.04939000"],["79900.47000000","0.00000000"],["79900.46000000","0.00000000"],["79900.11000000","0.00026000"],["79900.01000000","0.00000000"],["79899.99000000","0.32559000"],["79899.18000000","0.00000000"],["79898.57000000","0.00000000"],["79898.01000000","0.11580000"],["79897.69000000","0.00693000"],["79896.71000000","0.00000000"],["79896.08000000","0.00000000"],["79895.46000000","0.00000000"],["79894.84000000","0.00000000"],["79894.24000000","1.04939000"],["79894.22000000","0.00000000"],["79894.09000000","0.00000000"],["79892.98000000","0.00000000"],["79892.83000000","0.00000000"],["79892.66000000","0.00190000"],["79892.00000000","0.10966000"],["79891.70000000","0.00048000"],["79890.17000000","0.50945000"],["79889.86000000","0.02435000"],["79885.22000000","0.02200000"],["79884.41000000","0.02000000"],["79883.85000000","0.02000000"],["79882.16000000","1.29052000"],["79866.08000000","1.02161000"],["79864.70000000","1.23991000"],["79856.26000000","0.62628000"],["79842.87000000","0.04400000"],["79836.60000000","0.00000000"],["79825.03000000","0.00000000"],["79809.25000000","0.02000000"],["79797.28000000","0.02200000"],["79776.19000000","0.00000000"],["79748.77000000","0.01960000"],["79683.88000000","0.00000000"],["63925.00000000","0.00200000"],["63924.80000000","0.00000000"]],"a":[["79906.01000000","3.18317000"],["79906.38000000","0.00959000"],["79906.53000000","0.00000000"],["79906.54000000","0.00000000"],["79906.56000000","0.04074000"],["79907.24000000","0.00000000"],["79907.65000000","0.00007000"],["79907.66000000","0.01599000"],["79907.76000000","0.00014000"],["79907.79000000","0.00000000"],["79907.81000000","0.32585000"],["79907.83000000","0.00007000"],["79908.48000000","0.00000000"],["79908.60000000","0.00000000"],["79908.62000000","0.35351000"],["79908.94000000","0.01919000"],["79909.14000000","0.04730000"],["79909.77000000","0.00950000"],["79910.22000000","0.01926000"],["79910.80000000","0.00014000"],["79910.81000000","0.56913000"],["79910.95000000","0.00000000"],["79911.63000000","0.00021000"],["79912.86000000","0.00000000"],["79913.22000000","0.06280000"],["79913.23000000","0.65436000"],["79916.67000000","0.08576000"],["79920.48000000","0.00000000"],["79928.61000000","0.00012000"],["79937.82000000","0.50146000"],["79952.32000000","1.23855000"],["79961.92000000","1.00917000"],["80057.53000000","0.00400000"]]}}}
{"rx_ns": 13900495712200, "frame": {"stream":"btcusdt@depth@100ms","data":{"e":"depthUpdate","E":1787650895714,"s":"BTCUSDT","U":99118620823,"u":99118620927,"b":[["79906.00000000","0.79650000"],["79905.99000000","0.00098000"],["79905.72000000","0.00007000"],["79905.08000000","0.00917000"],["79904.15000000","0.00000000"],["79904.14000000","0.00000000"],["79903.82000000","0.00000000"],["79903.57000000","0.00000000"],["79903.56000000","0.00021000"],["79903.55000000","0.05332000"],["79903.49000000","0.00007000"],["79903.48000000","0.04000000"],["79902.91000000","0.00000000"],["79902.90000000","0.00014000"],["79902.54000000","0.00000000"],["79902.53000000","0.01835000"],["79902.50000000","0.00000000"],["79902.29000000","0.00000000"],["79902.28000000","0.00000000"],["79902.01000000","0.00007000"],["79901.05000000","0.00007000"],["79901.04000000","0.06287000"],["79900.52000000","0.00007000"],["79900.51000000","0.66705000"],["79880.75000000","0.04604000"],["79850.02000000","0.00342000"],["79842.87000000","0.00000000"],["79784.19000000","0.00000000"],["79774.11000000","0.00009000"],["79748.77000000","0.00000000"],["79710.37000000","0.01960000"],["71915.40000000","0.00064000"],["71915.00000000","0.00000000"],["63925.00000000","0.00000000"]],"a":[["79906.01000000","3.17755000"],["79906.38000000","0.00973000"],["79906.56000000","0.04074000"],["79907.66000000","0.01613000"],["79907.81000000","0.32585000"],["79908.58000000","0.00000000"],["79908.62000000","0.35351000"],["79908.94000000","0.01933000"],["79909.14000000","0.04737000"],["79909.76000000","0.00625000"],["79909.77000000","0.00964000"],["79910.81000000","0.56899000"],["79912.57000000","0.00800000"],["79913.22000000","0.00000000"],["79913.23000000","0.65429000"],["79916.14000000","0.00000000"],["80027.54000000","0.00000000"],["80030.23000000","0.00000000"],["80034.39000000","0.00000000"]]}}}
{"rx_ns": 13900595561700, "frame": {"stream":"btcusdt@depth@100ms","data":{"e":"depthUpdate","E":1787650895814,"s":"BTCUSDT","U":99118620928,"u":99118621003,"b":[["79906.00000000","0.79690000"],["79905.99000000","0.00077000"],["79905.71000000","0.33807000"],["79905.08000000","0.00931000"],["79904.45000000","0.00007000"],["79903.81000000","0.01543000"],["79903.56000000","0.00007000"],["79903.55000000","0.05311000"],["79903.49000000","0.00000000"],["79903.48000000","0.00000000"],["79902.90000000","0.00000000"],["79900.50000000","1.04946000"],["79888.92000000","0.02800000"],["79888.87000000","0.02600000"],["79888.08000000","0.02000000"],["79884.92000000","0.02400000"],["79884.45000000","0.02200000"],["79884.05000000","0.04400000"],["79875.59000000","0.00000000"],["79835.65000000","0.00000000"],["79814.05000000","0.02800000"],["79813.85000000","0.02600000"],["79813.02000000","0.02000000"],["79810.06000000","0.02400000"],["79809.61000000","0.02200000"],["79809.25000000","0.00000000"],["79809.21000000","0.04400000"],["79803.70000000","0.00000000"],["79797.28000000","0.00000000"],["79755.77000000","0.00000000"],["79683.88000000","0.00000000"],["71915.40000000","0.00080000"],["63925.00000000","0.00000000"]],"a":[["79909.14000000","0.04737000"],["79909.76000000","0.00639000"],["79909.77000000","0.00950000"],["79911.63000000","0.00014000"],["79918.24000000","0.02000000"],["79919.11000000","0.04000000"],["79920.00000000","1.57637000"],["79930.00000000","0.12035000"],["79931.76000000","0.02000000"],["79933.89000000","0.00000000"],["79943.80000000","0.00000000"],["79944.12000000","0.00000000"],["80012.37000000","0.00000000"]]}}}
{"rx_ns": 13900695611500, "frame": {"stream":"btcusdt@depth@100ms","data":{"e":"depthUpdate","E":1787650895914,"s":"BTCUSDT","U":99118621004,"u":99118621037,"b":[["79906.00000000","0.79693000"],["79903.89000000","0.00014000"],["79903.55000000","0.05311000"],["79902.05000000","0.00007000"],["79901.04000000","0.06280000"],["79900.50000000","1.04939000"],["79900.49000000","0.00000000"],["79900.46000000","0.00007000"],["79898.00000000","0.22650000"],["79890.01000000","0.00007000"],["79882.02000000","0.00000000"],["79874.03000000","0.00000000"],["79813.85000000","0.00000000"],["79813.02000000","0.00000000"],["71915.40000000","0.00096000"]],"a":[["79906.01000000","3.17754000"],["79908.62000000","0.35358000"],["79908.79000000","0.00708000"],["79913.23000000","0.65422000"],["79925.75000000","0.02478000"],["79931.76000000","0.00000000"],["79932.66000000","0.00000000"],["79941.05000000","1.20165000"],["80022.73000000","0.00012000"],["80025.42000000","0.00018000"],["81104.61000000","0.00030000"]]}}}
{"rx_ns": 13900795941800, "frame": {"stream":"btcusdt@depth20","data":{"lastUpdateId":99118621075,"bids":[["79906.00000000","0.99936000"],["79905.99000000","0.00077000"],["79905.72000000","0.00007000"],["79905.71000000","0.33807000"],["79905.08000000","0.00931000"],["79904.72000000","0.00007000"],["79904.45000000","0.00007000"],["79904.30000000","0.00007000"],["79904.01000000","0.00007000"],["79904.00000000","0.02442000"],["79903.89000000","0.00014000"],["79903.81000000","0.01543000"],["79903.56000000","0.00007000"],["79903.55000000","0.05311000"],["79902.72000000","0.00007000"],["79902.53000000","0.01835000"],["79902.05000000","0.00007000"],["79902.03000000","0.00007000"],["79902.01000000","0.00007000"],["79902.00000000","0.02428000"]],"asks":[["79906.01000000","3.17754000"],["79906.02000000","0.00034000"],["79906.03000000","0.00020000"],["79906.38000000","0.00973000"],["79906.55000000","0.00007000"],["79906.56000000","0.04074000"],["79907.25000000","0.00007000"],["79907.52000000","0.00400000"],["79907.65000000","0.00007000"],["79907.66000000","0.01613000"],["79907.76000000","0.00014000"],["79907.80000000","0.00007000"],["79907.81000000","0.32585000"],["79907.83000000","0.00007000"],["79908.07000000","0.00007000"],["79908.21000000","0.00007000"],["79908.25000000","0.00007000"],["79908.41000000","0.00007000"],["79908.49000000","0.00007000"],["79908.52000000","0.00007000"]]}}}
{"rx_ns": 13900796150300, "frame": {"stream":"btcusdt@depth@100ms","data":{"e":"depthUpdate","E":1787650896014,"s":"BTCUSDT","U":99118621038,"u":99118621075,"b":[["79906.00000000","0.99936000"],["79901.25000000","0.01849000"],["79901.19000000","0.00007000"],["79901.18000000","0.03901000"],["79898.00000000","0.22666000"],["79890.01000000","0.00023000"],["79888.13000000","0.02200000"],["79888.06000000","0.02400000"],["79885.75000000","0.02400000"],["79882.02000000","0.00016000"],["79880.00000000","0.11797000"],["79874.03000000","0.00016000"],["79870.01000000","0.00000000"],["79830.86000000","0.02400000"],["79828.65000000","0.00400000"],["79814.05000000","0.00000000"],["79813.78000000","0.02200000"],["79812.98000000","0.02410000"],["79810.10000000","0.00000000"],["79678.96000000","0.00000000"],["79670.82000000","0.01960000"],["71915.40000000","0.00112000"],["63924.80000000","0.00031000"]],"a":[["79908.62000000","0.35358000"],["79908.79000000","0.00722000"],["79909.76000000","0.00625000"],["79938.41000000","0.09332000"],["80029.58000000","0.00031000"]]}}}
{"rx_ns": 13900897474900, "frame": {"stream":"btcusdt@depth@100ms","data":{"e":"depthUpdate","E":1787650896114,"s":"BTCUSDT","U":99118621076,"u":99118621088,"b":[["79903.89000000","0.00007000"],["79896.01000000","0.00016000"],["79888.14000000","0.02000000"],["79884.03000000","0.00007000"],["79872.28000000","0.00000000"],["79866.04000000","0.00019000"],["79831.24000000","0.02000000"],["79813.78000000","0.00000000"],["79809.61000000","0.00000000"],["71915.40000000","0.00144000"],["63924.80000000","0.00031000"]],"a":[]}}}
{"rx_ns": 13900998346700, "frame": {"stream":"btcusdt@depth@100ms","data":{"e":"depthUpdate","E":1787650896214,"s":"BTCUSDT","U":99118621089,"u":99118621111,"b":[["79906.00000000","0.99946000"],["79905.99000000","0.00084000"],["79904.00000000","0.02435000"],["79902.53000000","0.01842000"],["79902.47000000","0.00007000"],["79902.46000000","0.03236000"],["79901.25000000","0.01842000"],["79901.19000000","0.00000000"],["79901.18000000","0.00000000"],["79893.08000000","0.08097000"],["79879.29000000","0.00000000"],["79874.78000000","0.00000000"],["79828.62000000","1.24047000"],["79823.05000000","0.62553000"],["79809.21000000","0.02200000"],["79796.70000000","0.00400000"],["71915.40000000","0.00160000"],["63924.80000000","0.00000000"]],"a":[["80625.15000000","0.00010000"]]}}}
{"rx_ns": 13901096534800, "frame": {"stream":"btcusdt@depth@100ms","data":{"e":"depthUpdate","E":1787650896314,"s":"BTCUSDT","U":99118621112,"u":99118621251,"b":[["79906.00000000","0.04672000"],["79905.99000000","0.00070000"],["79905.71000000","0.00014000"],["79905.08000000","0.00938000"],["79904.45000000","0.00014000"],["79904.44000000","0.00000000"],["79902.53000000","0.01842000"],["79902.47000000","0.00000000"],["79902.46000000","0.00000000"],["79902.29000000","0.00007000"],["79902.28000000","0.00000000"],["79902.01000000","0.00000000"],["79901.66000000","0.00000000"],["79901.04000000","0.00007000"],["79900.56000000","0.00000000"],["79900.51000000","0.00014000"],["79900.50000000","0.00000000"],["79900.46000000","0.00000000"],["79900.11000000","0.00000000"],["79900.02000000","0.00007000"],["79898.01000000","0.00000000"],["79897.80000000","0.00000000"],["79896.70000000","0.04000000"],["79896.16000000","0.00000000"],["79894.25000000","1.04939000"],["79894.24000000","0.00000000"],["79893.24000000","0.00625000"],["79892.82000000","0.00000000"],["79892.80000000","0.00000000"],["79891.40000000","0.03000000"],["79890.83000000","0.00625000"],["79889.76000000","0.00000000"],["79888.02000000","0.00000000"],["79882.09000000","0.00000000"],["79875.94000000","0.33811000"],["79869.88000000","0.00000000"],["79868.82000000","0.33814000"],["79856.26000000","0.00000000"],["79823.05000000","0.00000000"],["79812.98000000","0.00010000"],["79810.06000000","0.00000000"],["79809.21000000","0.00000000"],["79589.95000000","7.54056000"],["63925.00000000","0.00000000"]],"a":[["79906.01000000","5.05368000"],["79906.55000000","0.00000000"],["79906.84000000","0.00007000"],["79907.25000000","0.00007000"],["79907.65000000","0.00000000"],["79907.66000000","0.01639000"],["79907.80000000","0.00000000"],["79908.49000000","0.00007000"],["79908.61000000","1.04939000"],["79909.13000000","0.00000000"],["79909.73000000","0.00000000"],["79910.35000000","0.00000000"],["79910.80000000","0.00007000"],["79910.81000000","0.56202000"],["79912.21000000","0.00000000"],["79912.72000000","1.04939000"],["79912.83000000","0.00000000"],["79913.22000000","0.00000000"],["79913.39000000","0.00000000"],["79916.73000000","0.03224000"],["79926.30000000","0.33789000"],["79927.47000000","0.33789000"],["79934.00000000","0.72400000"],["80060.38000000","0.00000000"]]}}}
{"rx_ns": 13901197259900, "frame": {"stream":"btcusdt@depth@100ms","data":{"e":"depthUpdate","E":1787650896414,"s":"BTCUSDT","U":99118621252,"u":99118621431,"b":[["79906.00000000","0.02329000"],["79905.99000000","0.00063000"],["79905.72000000","0.00000000"],["79905.71000000","0.00000000"],["79905.08000000","0.00931000"],["79904.45000000","0.00007000"],["79903.82000000","0.00007000"],["79903.55000000","0.05318000"],["79902.54000000","0.00007000"],["79902.53000000","0.01842000"],["79902.29000000","0.00000000"],["79902.01000000","0.00007000"],["79902.00000000","0.02421000"],["79901.67000000","0.00000000"],["79901.29000000","0.00285000"],["79901.26000000","0.00007000"],["79901.25000000","0.01842000"],["79901.07000000","0.00000000"],["79901.05000000","0.00000000"],["79901.04000000","0.00000000"],["79900.52000000","0.00000000"],["79900.51000000","0.00007000"],["79900.47000000","0.00000000"],["79900.46000000","0.00007000"],["79900.01000000","0.00007000"],["79900.00000000","0.02421000"],["79899.99000000","0.32573000"],["79899.53000000","0.00202000"],["79899.21000000","0.33793000"],["79898.83000000","0.00007000"],["79898.01000000","0.00000000"],["79898.00000000","0.22666000"],["79897.69000000","0.00000000"],["79897.67000000","0.00709000"],["79897.40000000","0.00000000"],["79897.13000000","0.00000000"],["79896.71000000","0.00000000"],["79896.70000000","0.00000000"],["79896.30000000","0.00000000"],["79896.15000000","0.00014000"],["79896.08000000","0.00000000"],["79895.93000000","0.02000000"],["79895.46000000","0.06280000"],["79894.98000000","0.00070000"],["79894.87000000","0.00047000"],["79894.84000000","0.06280000"],["79894.27000000","0.06280000"],["79894.26000000","0.40190000"],["79894.23000000","0.00000000"],["79893.25000000","0.00013000"],["79893.24000000","0.00000000"],["79893.19000000","0.00000000"],["79892.34000000","0.00000000"],["79891.40000000","0.00000000"],["79890.83000000","0.00000000"],["79890.16000000","0.50087000"],["79889.86000000","0.00000000"],["79889.82000000","0.00625000"],["79889.20000000","0.15007000"],["79887.51000000","0.45510000"],["79885.86000000","0.00625000"],["79885.85000000","0.00000000"],["79874.03000000","0.36602000"],["79874.01000000","1.87677000"],["79870.00000000","0.82042000"],["79864.70000000","0.00000000"],["79864.52000000","0.62621000"],["79861.32000000","0.00007000"],["79857.45000000","0.00000000"],["79856.67000000","0.00000000"],["79855.10000000","0.00400000"],["79851.72000000","0.00000000"],["79849.80000000","0.00400000"],["79844.50000000","0.00400000"],["79841.99000000","0.00007000"],["79839.68000000","0.00425000"],["79829.76000000","0.00000000"],["79782.94000000","0.00000000"],["79773.43000000","0.20250000"],["79676.90000000","0.00400000"],["71915.56000000","0.00000000"],["71915.55000000","0.00008000"],["71915.40000000","0.00176000"]],"a":[["79906.01000000","5.05998000"],["79906.56000000","0.04067000"],["79907.25000000","0.00000000"],["79907.54000000","0.00165000"],["79907.81000000","0.57935000"],["79908.60000000","0.36586000"],["79908.61000000","1.04953000"],["79909.14000000","0.04724000"],["79909.76000000","0.00000000"],["79916.15000000","0.90936000"],["79916.18000000","0.00000000"],["79916.61000000","0.00000000"],["79918.31000000","0.33793000"],["79921.21000000","0.12512000"],["79928.02000000","0.62572000"],["79939.80000000","0.00000000"],["79940.00000000","0.33434000"],["79942.22000000","1.23871000"],["79945.21000000","0.02434000"],["79951.95000000","0.00000000"],["79952.32000000","0.00000000"],["79968.55000000","0.00007000"],["79990.45000000","0.09322000"],["80008.30000000","0.00000000"],["80106.32000000","0.00000000"]]}}}
{"rx_ns": 13901305997900, "frame": {"stream":"btcusdt@depth@100ms","data":{"e":"depthUpdate","E":1787650896514,"s":"BTCUSDT","U":99118621432,"u":99118621677,"b":[["79906.00000000","0.00000000"],["79905.99000000","0.00000000"],["79905.08000000","0.01094000"],["79905.07000000","0.00076000"],["79905.06000000","0.00013000"],["79903.56000000","0.00000000"],["79903.55000000","0.00021000"],["79902.53000000","0.01856000"],["79902.46000000","0.00007000"],["79902.45000000","0.05297000"],["79902.00000000","0.02435000"],["79901.25000000","0.01856000"],["79900.45000000","0.31310000"],["79900.09000000","0.00026000"],["79900.00000000","0.02435000"],["79897.67000000","0.00000000"],["79893.23000000","0.00000000"],["79893.08000000","0.00257000"],["79892.00000000","0.02400000"],["79890.78000000","0.00007000"],["79890.72000000","0.08566000"],["79889.23000000","0.00000000"],["79889.10000000","0.00008000"],["79886.72000000","0.03224000"],["79885.24000000","0.00000000"],["79885.10000000","0.00008000"],["79881.24000000","0.00000000"],["79881.11000000","0.00008000"],["79877.25000000","0.00000000"],["79877.11000000","0.00008000"],["79873.25000000","0.00000000"],["79873.12000000","0.00008000"],["79870.00000000","0.12042000"],["79869.26000000","0.20250000"],["79869.12000000","0.00008000"],["79866.00000000","0.02400000"],["79865.19000000","0.00014000"],["79865.13000000","0.00008000"],["79865.00000000","0.01000000"],["79858.93000000","1.24000000"],["79845.08000000","0.00618000"],["79832.58000000","1.24041000"],["79829.71000000","0.00000000"],["79829.43000000","0.12293000"],["79828.62000000","0.00000000"],["78707.41000000","0.00000000"],["78706.50000000","0.00030000"],["71915.40000000","0.00000000"],["71914.58000000","0.00016000"],["63924.07000000","0.00031000"]],"a":[["79905.09000000","4.47640000"],["79905.10000000","0.00027000"],["79905.11000000","0.00013000"],["79905.45000000","0.00400000"],["79905.71000000","0.00000000"],["79905.72000000","0.00007000"],["79905.99000000","0.00007000"],["79906.00000000","1.04204000"],["79906.01000000","3.32692000"],["79906.02000000","0.00007000"],["79906.03000000","0.00007000"],["79907.54000000","0.00000000"],["79907.66000000","0.01613000"],["79907.81000000","0.57942000"],["79908.04000000","0.04716000"],["79908.43000000","0.00007000"],["79908.60000000","0.36600000"],["79908.62000000","0.20673000"],["79908.79000000","0.00708000"],["79908.94000000","0.01919000"],["79909.14000000","0.00008000"],["79913.08000000","0.00008000"],["79915.07000000","0.00007000"],["79915.39000000","0.08576000"],["79915.82000000","0.00000000"],["79916.67000000","0.00000000"],["79917.55000000","0.00007000"],["79918.47000000","0.00000000"],["79920.96000000","0.00075000"],["79921.07000000","0.00015000"],["79922.75000000","0.00007000"],["79925.07000000","0.00008000"],["79925.19000000","0.00000000"],["79929.06000000","0.00008000"],["79929.19000000","0.00000000"],["79933.06000000","0.00008000"],["79933.18000000","0.00000000"],["79937.05000000","0.00008000"],["79937.18000000","0.00000000"],["79941.05000000","1.20173000"],["79941.17000000","0.00000000"],["79945.04000000","0.00008000"],["79945.17000000","0.00000000"],["79945.47000000","0.00000000"],["79949.16000000","0.00000000"],["79950.00000000","0.03129000"],["80153.42000000","0.00000000"],["81104.61000000","0.00000000"]]}}}
{"rx_ns": 13901416024800, "frame": {"stream":"btcusdt@depth@100ms","data":{"e":"depthUpdate","E":1787650896614,"s":"BTCUSDT","U":99118621678,"u":99118622559,"b":[["79905.08000000","0.00000000"],["79905.07000000","0.00000000"],["79905.06000000","0.00000000"],["79904.72000000","0.00000000"],["79904.45000000","0.00000000"],["79904.30000000","0.00000000"],["79904.01000000","0.00000000"],["79904.00000000","0.00000000"],["79903.99000000","0.00000000"],["79903.89000000","0.00000000"],["79903.82000000","0.00000000"],["79903.81000000","0.00000000"],["79903.55000000","0.00000000"],["79902.72000000","0.00000000"],["79902.54000000","0.00000000"],["79902.53000000","0.00000000"],["79902.46000000","0.00000000"],["79902.45000000","0.00000000"],["79902.05000000","0.00000000"],["79902.03000000","0.00000000"],["79902.01000000","0.00000000"],["79902.00000000","0.02507000"],["79901.99000000","0.00028000"],["79901.37000000","0.00000000"],["79901.29000000","0.00000000"],["79901.26000000","0.00000000"],["79901.25000000","0.00021000"],["79901.01000000","0.00007000"],["79900.45000000","0.00014000"],["79900.09000000","0.00000000"],["79900.00000000","0.02428000"],["79899.99000000","0.00028000"],["79899.95000000","0.00000000"],["79899.53000000","0.00000000"],["79899.49000000","0.00000000"],["79899.22000000","0.00007000"],["79899.21000000","0.00014000"],["79898.77000000","0.00021000"],["79898.19000000","0.00000000"],["79898.01000000","0.00007000"],["79898.00000000","0.02437000"],["79897.66000000","0.00007000"],["79897.65000000","0.00007000"],["79897.60000000","0.00000000"],["79897.23000000","0.00007000"],["79896.43000000","0.00000000"],["79896.15000000","0.00007000"],["79896.01000000","0.00024000"],["79896.00000000","0.02414000"],["79895.93000000","0.00007000"],["79895.47000000","0.00007000"],["79895.46000000","0.00007000"],["79895.29000000","0.00000000"],["79894.95000000","0.00000000"],["79894.84000000","0.00000000"],["79894.27000000","0.00007000"],["79894.26000000","0.00007000"],["79894.25000000","0.00000000"],["79894.22000000","0.31299000"],["79894.08000000","0.00000000"],["79893.25000000","0.00000000"],["79893.02000000","0.02007000"],["79893.00000000","0.00000000"],["79892.28000000","0.00007000"],["79892.01000000","0.00000000"],["79891.71000000","0.00000000"],["79890.72000000","0.00000000"],["79890.22000000","0.00000000"],["79890.17000000","0.00000000"],["79890.16000000","0.00000000"],["79890.15000000","0.00000000"],["79889.89000000","0.00007000"],["79889.82000000","0.00000000"],["79889.81000000","0.00000000"],["79889.69000000","0.08566000"],["79889.66000000","0.00000000"],["79889.20000000","0.00007000"],["79888.88000000","0.00000000"],["79888.87000000","0.00000000"],["79888.41000000","0.00007000"],["79888.14000000","0.00000000"],["79888.13000000","0.00000000"],["79888.08000000","0.00000000"],["79887.37000000","0.00625000"],["79887.20000000","0.15000000"],["79886.98000000","0.00048000"],["79886.72000000","0.00000000"],["79886.60000000","0.00000000"],["79885.32000000","0.00007000"],["79885.22000000","0.00000000"],["79885.21000000","0.00000000"],["79884.55000000","0.00021000"],["79884.54000000","0.00007000"],["79884.05000000","0.02200000"],["79883.86000000","0.00000000"],["79883.85000000","0.00000000"],["79882.85000000","0.00000000"],["79882.42000000","0.00163000"],["79882.20000000","1.04939000"],["79882.19000000","0.00000000"],["79882.15000000","0.00000000"],["79881.67000000","0.00000000"],["79881.14000000","0.00000000"],["79880.75000000","0.00000000"],["79880.67000000","0.00007000"],["79877.59000000","0.46395000"],["79876.71000000","0.00000000"],["79876.13000000","1.04939000"],["79875.67000000","0.00000000"],["79874.04000000","1.87677000"],["79874.03000000","0.00016000"],["79874.01000000","0.00000000"],["79873.20000000","0.33812000"],["79872.65000000","0.00625000"],["79872.39000000","0.00000000"],["79871.90000000","0.00000000"],["79871.47000000","1.04939000"],["79871.08000000","0.00000000"],["79868.65000000","0.33814000"],["79868.59000000","0.00400000"],["79868.28000000","1.87677000"],["79867.69000000","0.00000000"],["79866.69000000","1.04939000"],["79866.08000000","0.00000000"],["79865.60000000","0.36586000"],["79865.59000000","0.00000000"],["79865.00000000","0.00000000"],["79864.00000000","0.02400000"],["79862.91000000","1.87677000"],["79860.27000000","0.33817000"],["79857.45000000","0.00007000"],["79856.64000000","0.04497000"],["79856.00000000","0.02407000"],["79854.59000000","0.00000000"],["79853.58000000","0.00007000"],["79853.32000000","1.87677000"],["79850.02000000","0.00007000"],["79849.71000000","0.00007000"],["79842.88000000","0.00000000"],["79841.85000000","0.03624000"],["79841.81000000","0.00000000"],["79833.58000000","1.04939000"],["79830.89000000","0.00000000"],["79829.43000000","0.00000000"],["79828.77000000","0.00000000"],["79825.54000000","0.00000000"],["79824.83000000","0.00000000"],["79823.52000000","0.00000000"],["79822.82000000","0.00008000"],["79817.67000000","0.04636000"],["79813.43000000","1.04939000"],["79788.60000000","1.87677000"],["79779.01000000","1.87677000"],["79769.42000000","1.87677000"],["79760.01000000","0.00000000"],["79752.25000000","0.00125000"],["79750.98000000","0.00000000"],["79743.04000000","0.00000000"],["79742.91000000","0.00008000"],["79688.21000000","0.00000000"],["79683.67000000","0.00770000"],["79671.07000000","0.00000000"],["79663.01000000","0.00008000"],["79591.16000000","0.00000000"],["79583.11000000","0.00008000"],["79581.35000000","0.00000000"],["79511.25000000","0.00000000"],["79503.21000000","0.00008000"],["79431.34000000","0.00000000"],["79423.30000000","0.00008000"],["79351.42000000","0.00000000"],["79343.40000000","0.00008000"],["79273.70000000","0.00000000"],["79264.77000000","0.00008000"],["78706.50000000","0.00000000"],["71915.55000000","0.00000000"],["71914.58000000","0.00000000"],["63924.07000000","0.00000000"]],"a":[["79902.01000000","4.83580000"],["79902.02000000","1.87697000"],["79902.03000000","0.00013000"],["79902.04000000","0.23619000"],["79902.06000000","0.00000000"],["79902.45000000","0.46535000"],["79902.46000000","0.39872000"],["79902.47000000","5.18541000"],["79902.52000000","0.00000000"],["79902.53000000","0.07500000"],["79902.54000000","0.00000000"],["79902.72000000","0.46565000"],["79902.73000000","0.98103000"],["79902.74000000","0.00000000"],["79902.75000000","0.00000000"],["79903.35000000","0.00000000"],["79903.47000000","1.04939000"],["79903.48000000","0.00021000"],["79903.54000000","0.00000000"],["79903.56000000","0.00021000"],["79903.82000000","0.00014000"],["79903.83000000","0.00000000"],["79903.89000000","0.00014000"],["79903.90000000","0.20250000"],["79903.97000000","0.00000000"],["79904.00000000","0.07500000"],["79904.01000000","1.02626000"],["79904.02000000","0.00000000"],["79904.03000000","0.00000000"],["79904.31000000","0.00000000"],["79904.46000000","0.00000000"],["79904.63000000","0.00000000"],["79904.73000000","0.00000000"],["79904.96000000","0.04716000"],["79905.07000000","0.00000000"],["79905.08000000","0.07500000"],["79905.09000000","0.56833000"],["79905.10000000","0.00000000"],["79905.11000000","0.00000000"],["79905.68000000","0.00000000"],["79906.00000000","0.10473000"],["79906.01000000","0.97747000"],["79906.38000000","0.00000000"],["79906.56000000","0.04053000"],["79906.96000000","0.00000000"],["79907.66000000","0.12514000"],["79907.75000000","0.00026000"],["79907.81000000","0.57928000"],["79907.83000000","0.03231000"],["79908.04000000","0.00000000"],["79908.60000000","0.36586000"],["79908.61000000","1.04939000"],["79908.62000000","0.20652000"],["79908.94000000","0.00000000"],["79909.83000000","0.02000000"],["79910.00000000","0.00013000"],["79910.22000000","0.00007000"],["79910.40000000","0.00000000"],["79910.52000000","0.00000000"],["79910.72000000","0.00008000"],["79910.79000000","0.00000000"],["79910.80000000","0.00000000"],["79910.81000000","0.55959000"],["79911.47000000","0.00007000"],["79911.69000000","0.03000000"],["79912.48000000","0.00007000"],["79913.00000000","0.00000000"],["79913.08000000","0.00000000"],["79914.37000000","0.08576000"],["79914.47000000","0.00007000"],["79914.92000000","0.00000000"],["79915.19000000","0.00000000"],["79915.39000000","0.00000000"],["79915.98000000","0.00007000"],["79916.40000000","0.02000000"],["79916.47000000","0.00000000"],["79917.19000000","0.02000000"],["79917.20000000","0.02000000"],["79917.55000000","0.00000000"],["79918.82000000","0.00000000"],["79919.89000000","0.04000000"],["79920.00000000","1.26477000"],["79920.18000000","0.33792000"],["79921.07000000","0.00008000"],["79921.21000000","0.00000000"],["79927.98000000","0.00125000"],["79928.01000000","0.00000000"],["79931.71000000","0.00000000"],["79931.88000000","0.00000000"],["79933.39000000","0.00000000"],["79939.97000000","0.00000000"],["79942.59000000","0.00000000"],["79943.98000000","0.00000000"],["79946.19000000","0.00014000"],["79968.52000000","0.00000000"],["79968.55000000","0.00000000"],["79976.81000000","0.00000000"],["79982.63000000","0.00008000"],["79990.72000000","0.00000000"],["80049.99000000","1.87677000"],["80050.69000000","0.00125000"],["80059.58000000","0.00000000"],["80062.54000000","0.11615000"],["80066.83000000","0.00000000"],["80070.63000000","0.00000000"],["80142.44000000","0.00015000"],["80150.54000000","0.00000000"],["80181.35000000","0.00000000"],["80302.24000000","0.00008000"],["80310.36000000","0.00147000"],["80462.05000000","0.00008000"],["80470.19000000","0.00000000"],["80541.95000000","0.00008000"],["80550.10000000","0.00000000"]]}}}
{"rx_ns": 13901496348300, "frame": {"stream":"btcusdt@depth@100ms","data":{"e":"depthUpdate","E":1787650896714,"s":"BTCUSDT","U":99118622560,"u":99118623038,"b":[["79902.00000000","0.03238000"],["79901.99000000","0.00077000"],["79901.25000000","0.00000000"],["79901.02000000","0.00000000"],["79900.92000000","0.00904000"],["79900.51000000","0.00000000"],["79900.46000000","0.00000000"],["79900.45000000","0.00000000"],["79900.00000000","0.02435000"],["79899.99000000","0.00007000"],["79899.65000000","0.00007000"],["79899.64000000","0.01507000"],["79899.38000000","0.00007000"],["79899.37000000","0.05304000"],["79899.22000000","0.00000000"],["79899.21000000","0.00000000"],["79898.77000000","0.00007000"],["79898.37000000","0.00007000"],["79898.36000000","0.01809000"],["79898.00000000","0.02444000"],["79897.66000000","0.00000000"],["79897.24000000","0.00000000"],["79897.09000000","0.00007000"],["79897.08000000","0.01809000"],["79896.42000000","0.05673000"],["79896.02000000","0.00007000"],["79896.01000000","0.00024000"],["79896.00000000","0.02442000"],["79895.93000000","0.00000000"],["79895.80000000","0.06287000"],["79895.47000000","0.00000000"],["79895.46000000","0.00000000"],["79895.19000000","0.00007000"],["79895.18000000","0.06280000"],["79894.96000000","0.00000000"],["79894.85000000","0.00000000"],["79894.57000000","0.00007000"],["79894.56000000","0.06280000"],["79894.28000000","0.00000000"],["79894.27000000","0.00000000"],["79894.26000000","0.00000000"],["79894.24000000","0.00007000"],["79894.23000000","0.06287000"],["79894.22000000","0.31320000"],["79894.01000000","0.00000000"],["79894.00000000","0.02414000"],["79893.99000000","0.00021000"],["79893.32000000","0.06280000"],["79893.01000000","0.00000000"],["79892.83000000","0.00202000"],["79892.71000000","0.00000000"],["79892.70000000","0.06110000"],["79892.66000000","0.00000000"],["79892.51000000","0.33793000"],["79892.31000000","0.00000000"],["79892.09000000","0.00000000"],["79892.08000000","0.06280000"],["79891.99000000","0.00026000"],["79891.92000000","0.00000000"],["79891.70000000","0.00000000"],["79891.46000000","0.06280000"],["79890.84000000","0.06280000"],["79890.34000000","0.02478000"],["79890.22000000","0.06280000"],["79890.10000000","0.00000000"],["79890.01000000","0.06303000"],["79889.69000000","0.00000000"],["79888.98000000","0.06280000"],["79888.92000000","0.00000000"],["79888.41000000","0.00014000"],["79888.36000000","0.06280000"],["79888.06000000","0.00000000"],["79887.74000000","0.06280000"],["79887.53000000","0.46076000"],["79887.52000000","1.11219000"],["79887.51000000","0.00000000"],["79887.37000000","0.00000000"],["79887.36000000","0.00000000"],["79886.50000000","0.00000000"],["79886.45000000","0.08566000"],["79885.88000000","0.00000000"],["79885.86000000","0.00000000"],["79885.75000000","0.00000000"],["79885.26000000","0.00000000"],["79885.02000000","0.00928000"],["79884.92000000","0.00000000"],["79884.64000000","0.06280000"],["79884.54000000","0.00014000"],["79884.45000000","0.00000000"],["79884.41000000","0.00000000"],["79884.06000000","0.06280000"],["79884.05000000","0.00000000"],["79883.40000000","0.06280000"],["79883.34000000","0.00625000"],["79882.78000000","0.06280000"],["79882.70000000","0.00625000"],["79882.57000000","0.00191000"],["79882.22000000","1.32579000"],["79882.21000000","1.88477000"],["79882.16000000","0.00000000"],["79881.84000000","0.00048000"],["79880.67000000","0.00014000"],["79880.00000000","0.02407000"],["79879.90000000","0.09623000"],["79877.91000000","0.10382000"],["79877.60000000","0.54672000"],["79877.59000000","0.03456000"],["79877.03000000","0.00904000"],["79877.01000000","0.00000000"],["79874.05000000","1.14276000"],["79874.02000000","0.00000000"],["79871.95000000","0.00188000"],["79871.51000000","1.47333000"],["79870.01000000","0.32107000"],["79870.00000000","0.11791000"],["79869.35000000","0.09619000"],["79869.04000000","0.00916000"],["79868.29000000","0.42944000"],["79866.70000000","0.82156000"],["79866.09000000","0.62597000"],["79862.92000000","1.05809000"],["79862.00000000","0.03400000"],["79861.05000000","0.00905000"],["79860.00000000","0.11792000"],["79858.94000000","1.22829000"],["79857.87000000","0.67297000"],["79855.95000000","0.00000000"],["79853.33000000","0.92205000"],["79851.41000000","0.00000000"],["79851.32000000","1.09306000"],["79849.71000000","0.00000000"],["79847.41000000","0.00012000"],["79846.40000000","0.27468000"],["79846.39000000","0.83208000"],["79845.88000000","0.00000000"],["79845.87000000","0.00000000"],["79844.82000000","0.00000000"],["79841.21000000","0.00000000"],["79839.47000000","0.00000000"],["79839.20000000","0.00400000"],["79837.71000000","0.95553000"],["79833.58000000","2.69325000"],["79832.55000000","0.00434000"],["79831.81000000","0.85523000"],["79827.84000000","0.08607000"],["79823.83000000","1.05762000"],["79823.53000000","0.00000000"],["79823.35000000","0.00000000"],["79823.10000000","0.00538000"],["79822.82000000","0.00008000"],["79822.75000000","0.00000000"],["79821.48000000","0.00112000"],["79816.84000000","0.56740000"],["79815.51000000","0.49793000"],["79809.02000000","0.32043000"],["79807.25000000","0.00000000"],["79803.16000000","1.99535000"],["79800.33000000","0.00000000"],["79798.63000000","0.00000000"],["79788.61000000","0.00000000"],["79779.02000000","0.00000000"],["79778.54000000","0.00000000"],["79771.84000000","0.00000000"],["79769.43000000","0.00000000"],["79769.42000000","0.00000000"],["79743.29000000","0.00000000"],["79736.20000000","0.00000000"],["79728.10000000","0.00000000"],["79573.18000000","0.00027000"],["71911.80000000","0.00016000"]],"a":[["79902.01000000","5.40041000"],["79902.02000000","1.87718000"],["79902.04000000","0.05659000"],["79902.22000000","0.00972000"],["79902.45000000","0.00014000"],["79902.46000000","0.15102000"],["79902.47000000","0.87132000"],["79902.53000000","0.07521000"],["79902.72000000","0.00021000"],["79902.73000000","0.51535000"],["79902.80000000","0.00400000"],["79903.48000000","0.00000000"],["79903.50000000","0.01621000"],["79903.56000000","0.00000000"],["79903.82000000","0.00000000"],["79903.90000000","0.20257000"],["79904.00000000","0.07514000"],["79904.01000000","1.01987000"],["79904.78000000","0.01945000"],["79904.96000000","0.04723000"],["79905.09000000","0.06136000"],["79906.00000000","0.10459000"],["79906.01000000","0.97747000"],["79906.06000000","0.01945000"],["79906.56000000","0.00014000"],["79907.81000000","0.57921000"],["79908.62000000","0.20638000"],["79908.98000000","0.00000000"],["79909.08000000","0.00000000"],["79909.26000000","0.00000000"],["79909.77000000","0.00943000"],["79909.91000000","0.00000000"],["79909.93000000","0.02252000"],["79910.00000000","0.09399000"],["79910.02000000","0.00000000"],["79910.03000000","0.00000000"],["79910.17000000","0.00250000"],["79910.22000000","0.00000000"],["79910.36000000","0.00000000"],["79910.80000000","0.26969000"],["79910.81000000","0.55945000"],["79911.12000000","0.08576000"],["79911.99000000","0.00007000"],["79914.37000000","0.00000000"],["79917.62000000","0.09618000"],["79919.04000000","0.04431000"],["79919.34000000","0.00000000"],["79919.62000000","0.10376000"],["79924.26000000","0.00000000"],["79925.53000000","0.00000000"],["79925.76000000","0.00200000"],["79926.22000000","0.00000000"],["79926.26000000","0.00000000"],["79926.29000000","0.00000000"],["79927.09000000","0.00250000"],["79927.99000000","0.53751000"],["79928.61000000","0.00000000"],["79930.95000000","0.00000000"],["79932.01000000","0.00000000"],["79937.11000000","0.00429000"],["79937.81000000","0.68681000"],["79938.63000000","0.02490000"],["79939.78000000","1.86863000"],["79942.59000000","0.83107000"],["79943.30000000","0.00000000"],["79943.68000000","0.00000000"],["79944.00000000","0.03400000"],["79945.20000000","0.13030000"],["79945.21000000","0.00000000"],["79946.00000000","0.02400000"],["79949.11000000","0.82387000"],["79949.43000000","0.00000000"],["79950.80000000","0.00000000"],["79954.40000000","0.22891000"],["79959.05000000","0.01151000"],["79959.88000000","1.08221000"],["79962.69000000","0.82373000"],["79963.75000000","0.89024000"],["79965.20000000","0.00000000"],["79966.50000000","0.01694000"],["79967.75000000","0.20913000"],["79967.76000000","0.25000000"],["79967.82000000","0.00000000"],["79968.78000000","0.00538000"],["79975.99000000","0.26684000"],["79978.78000000","0.00000000"],["79983.99000000","0.93606000"],["79984.95000000","0.00000000"],["79985.29000000","0.00000000"],["79985.85000000","1.99079000"],["79987.28000000","0.00000000"],["80004.63000000","0.17095000"],["80005.32000000","0.04625000"],["80006.60000000","0.00000000"],["80006.66000000","0.00000000"],["80015.30000000","0.00000000"],["80022.73000000","0.00000000"],["80025.42000000","0.00000000"],["80029.58000000","0.00000000"],["80032.86000000","0.00000000"],["80150.42000000","0.00010000"],["80169.90000000","0.00033000"],["80297.01000000","0.00626000"],["80323.04000000","0.00000000"]]}}}
{"rx_ns": 13901600253500, "frame": {"stream":"btcusdt@depth@100ms","data":{"e":"depthUpdate","E":1787650896814,"s":"BTCUSDT","U":99118623039,"u":99118623163,"b":[["79902.00000000","0.03420000"],["79900.92000000","0.00918000"],["79900.00000000","0.02435000"],["79899.64000000","0.01521000"],["79899.37000000","0.05318000"],["79898.36000000","0.01823000"],["79898.00000000","0.02428000"],["79897.08000000","0.01830000"],["79896.43000000","0.00007000"],["79896.42000000","0.05687000"],["79896.00000000","0.02428000"],["79895.81000000","0.00007000"],["79894.57000000","0.00000000"],["79894.24000000","0.00000000"],["79894.22000000","0.31306000"],["79894.00000000","0.02412000"],["79893.99000000","0.00007000"],["79893.55000000","0.03810000"],["79892.83000000","0.00000000"],["79892.75000000","0.00939000"],["79892.51000000","0.00000000"],["79892.08000000","0.00000000"],["79891.29000000","0.00000000"],["79890.01000000","0.06287000"],["79888.37000000","0.00029000"],["79887.52000000","1.04939000"],["79884.64000000","0.00000000"],["79884.55000000","0.00000000"],["79884.06000000","0.00000000"],["79883.40000000","0.00000000"],["79882.78000000","0.00000000"],["79882.23000000","0.00800000"],["79882.21000000","1.87677000"],["79882.02000000","0.00000000"],["79877.87000000","0.02800000"],["79877.78000000","0.02600000"],["79876.99000000","0.02000000"],["79874.03000000","0.00000000"],["79873.87000000","0.02400000"],["79873.41000000","0.02200000"],["79873.01000000","0.02200000"],["79873.00000000","0.02200000"],["79814.06000000","0.02800000"],["79813.85000000","0.02600000"],["79813.02000000","0.02000000"],["79810.06000000","0.02400000"],["79809.61000000","0.02200000"],["79809.21000000","0.04400000"],["79759.87000000","0.04533000"],["79748.78000000","0.00400000"],["79704.57000000","0.01679000"],["79682.96000000","0.00007000"],["79674.98000000","0.00000000"],["71911.80000000","0.00048000"]],"a":[["79902.01000000","5.54162000"],["79902.04000000","0.05652000"],["79902.22000000","0.00986000"],["79902.45000000","0.00000000"],["79902.53000000","0.07521000"],["79902.72000000","0.00007000"],["79902.73000000","0.31285000"],["79903.90000000","0.00007000"],["79904.01000000","0.30751000"],["79905.09000000","0.00934000"],["79912.40000000","0.02000000"],["79912.51000000","0.02000000"],["79913.32000000","0.02695000"],["79916.85000000","0.02000000"],["79920.00000000","1.26728000"],["79924.60000000","0.00019000"],["79926.33000000","0.00000000"],["79942.00000000","0.03400000"],["79944.00000000","0.02400000"],["79946.25000000","0.00000000"],["79999.52000000","0.02804000"],["80066.83000000","0.00900000"],["80202.77000000","0.00000000"]]}}}
{"rx_ns": 13901696288900, "frame": {"stream":"btcusdt@depth@100ms","data":{"e":"depthUpdate","E":1787650896914,"s":"BTCUSDT","U":99118623164,"u":99118623561,"b":[["79902.00000000","0.00000000"],["79901.99000000","0.00000000"],["79901.36000000","0.00000000"],["79901.01000000","0.00000000"],["79900.92000000","0.01040000"],["79900.91000000","0.00063000"],["79900.45000000","0.00007000"],["79899.38000000","0.00000000"],["79899.37000000","0.00021000"],["79898.36000000","0.01830000"],["79898.30000000","0.00007000"],["79898.29000000","0.05297000"],["79896.43000000","0.00000000"],["79896.42000000","0.00014000"],["79896.29000000","0.00000000"],["79896.01000000","0.00016000"],["79896.00000000","0.02428000"],["79895.81000000","0.00000000"],["79895.80000000","0.00007000"],["79895.19000000","0.00000000"],["79895.18000000","0.00000000"],["79894.57000000","0.00000000"],["79894.56000000","0.00000000"],["79894.24000000","0.00000000"],["79894.23000000","0.06295000"],["79894.01000000","0.00007000"],["79894.00000000","0.02420000"],["79893.55000000","0.00000000"],["79893.32000000","0.00000000"],["79893.18000000","0.12516000"],["79893.08000000","0.00007000"],["79893.02000000","0.00007000"],["79892.70000000","0.00000000"],["79892.31000000","0.06281000"],["79891.62000000","0.06281000"],["79891.18000000","0.00693000"],["79890.01000000","0.00007000"],["79889.14000000","0.06281000"],["79889.10000000","0.00000000"],["79889.02000000","0.00000000"],["79888.41000000","0.00007000"],["79887.54000000","0.00000000"],["79887.12000000","0.02000000"],["79886.69000000","0.00007000"],["79886.45000000","0.00000000"],["79886.01000000","0.00012000"],["79885.66000000","0.08566000"],["79885.19000000","0.12517000"],["79885.10000000","0.00000000"],["79884.94000000","0.00008000"],["79881.11000000","0.00000000"],["79880.94000000","0.00008000"],["79878.02000000","0.00012000"],["79877.20000000","0.12519000"],["79877.11000000","0.00000000"],["79876.95000000","0.00008000"],["79876.85000000","0.00250000"],["79873.79000000","0.50814000"],["79873.12000000","0.00000000"],["79872.95000000","0.00015000"],["79870.03000000","0.00012000"],["79869.35000000","0.00000000"],["79869.12000000","0.00000000"],["79868.96000000","0.00008000"],["79865.13000000","0.00000000"],["79864.96000000","0.00008000"],["79862.00000000","0.02400000"],["79861.32000000","0.00014000"],["79860.97000000","0.00008000"],["79860.00000000","0.13043000"],["79858.94000000","0.81363000"],["79858.93000000","0.00000000"],["79849.71000000","1.02582000"],["79827.84000000","0.44536000"],["79826.22000000","1.24051000"],["79822.58000000","0.11996000"],["79813.85000000","0.00000000"],["79813.02000000","0.00000000"],["79773.20000000","0.00012000"],["71911.80000000","0.00008000"],["71911.00000000","0.00000000"]],"a":[["79900.93000000","5.92877000"],["79900.94000000","0.00027000"],["79900.95000000","0.00013000"],["79901.02000000","0.00000000"],["79901.07000000","0.00008000"],["79901.36000000","0.81815000"],["79901.37000000","1.87900000"],["79901.99000000","0.00000000"],["79902.00000000","0.41774000"],["79902.01000000","0.86016000"],["79902.02000000","0.00014000"],["79902.03000000","0.00000000"],["79902.47000000","0.20168000"],["79902.73000000","0.20812000"],["79903.47000000","1.04939000"],["79903.50000000","0.01628000"],["79903.88000000","0.04716000"],["79904.00000000","0.00014000"],["79904.96000000","0.00000000"],["79905.08000000","0.00000000"],["79906.00000000","0.44082000"],["79906.84000000","0.00000000"],["79907.81000000","0.57907000"],["79908.21000000","0.00000000"],["79908.25000000","0.00000000"],["79908.41000000","0.00000000"],["79908.49000000","0.00000000"],["79908.52000000","0.00000000"],["79908.62000000","0.20631000"],["79909.73000000","0.00010000"],["79910.00000000","0.09386000"],["79910.79000000","0.19019000"],["79910.81000000","0.36062000"],["79913.39000000","0.00007000"],["79913.83000000","0.00000000"],["79914.47000000","0.00000000"],["79914.54000000","0.03130000"],["79916.91000000","0.00008000"],["79916.98000000","0.34661000"],["79919.88000000","0.00000000"],["79920.00000000","1.08777000"],["79920.56000000","0.00000000"],["79920.91000000","0.00008000"],["79921.07000000","0.00000000"],["79924.90000000","0.00008000"],["79925.07000000","0.00000000"],["79926.01000000","0.00007000"],["79928.90000000","0.00008000"],["79929.06000000","0.00000000"],["79932.89000000","0.00008000"],["79933.06000000","0.00000000"],["79936.77000000","0.00621000"],["79936.89000000","0.00008000"],["79937.05000000","0.00000000"],["79940.88000000","0.00008000"],["79941.05000000","1.20165000"],["79945.04000000","0.00000000"],["79960.50000000","0.00000000"],["79961.35000000","0.00000000"],["79961.92000000","0.00000000"],["80018.72000000","0.00012000"],["81099.45000000","0.00030000"]]}}}
{"rx_ns": 13901801818800, "frame": {"stream":"btcusdt@depth20","data":{"lastUpdateId":99118624004,"bids":[["79900.00000000","0.02715000"],["79899.99000000","0.00063000"],["79899.64000000","0.00014000"],["79899.37000000","0.00007000"],["79899.03000000","0.00007000"],["79898.83000000","0.00007000"],["79898.77000000","0.00007000"],["79898.36000000","0.00021000"],["79898.29000000","0.00014000"],["79898.01000000","0.00007000"],["79898.00000000","0.02435000"],["79897.87000000","0.00007000"],["79897.65000000","0.00007000"],["79897.38000000","0.00007000"],["79897.37000000","0.05297000"],["79897.26000000","0.00007000"],["79897.23000000","0.00007000"],["79897.08000000","0.00014000"],["79896.96000000","0.00007000"],["79896.15000000","0.00007000"]],"asks":[["79900.01000000","5.24830000"],["79900.02000000","0.00027000"],["79900.03000000","0.00013000"],["79900.92000000","1.58928000"],["79900.93000000","2.94479000"],["79901.07000000","0.00008000"],["79901.36000000","0.07521000"],["79901.37000000","0.00021000"],["79902.00000000","0.21538000"],["79902.01000000","0.52902000"],["79902.04000000","0.05652000"],["79902.22000000","0.00014000"],["79902.46000000","0.15102000"],["79902.47000000","0.20154000"],["79902.53000000","0.00007000"],["79902.72000000","0.00007000"],["79902.73000000","0.20819000"],["79902.80000000","0.00400000"],["79902.96000000","0.04716000"],["79903.31000000","0.02007000"]]}}}
{"rx_ns": 13901801950100, "frame": {"stream":"btcusdt@depth@100ms","data":{"e":"depthUpdate","E":1787650897014,"s":"BTCUSDT","U":99118623562,"u":99118624004,"b":[["79900.92000000","0.00000000"],["79900.91000000","0.00000000"],["79900.84000000","0.00000000"],["79900.45000000","0.00000000"],["79900.18000000","0.00000000"],["79900.02000000","0.00000000"],["79900.01000000","0.00000000"],["79900.00000000","0.02715000"],["79899.99000000","0.00063000"],["79899.65000000","0.00000000"],["79899.64000000","0.00014000"],["79899.37000000","0.00007000"],["79898.37000000","0.00000000"],["79898.36000000","0.00021000"],["79898.30000000","0.00000000"],["79898.29000000","0.00014000"],["79898.00000000","0.02435000"],["79897.38000000","0.00007000"],["79897.37000000","0.05297000"],["79897.26000000","0.00007000"],["79897.09000000","0.00000000"],["79897.08000000","0.00014000"],["79896.42000000","0.00000000"],["79896.00000000","0.02428000"],["79895.35000000","0.00000000"],["79895.34000000","0.00000000"],["79894.98000000","0.00000000"],["79894.87000000","0.00000000"],["79894.73000000","0.00000000"],["79894.72000000","0.00000000"],["79894.24000000","0.00000000"],["79894.23000000","0.00028000"],["79894.22000000","0.31320000"],["79894.15000000","0.00000000"],["79894.01000000","0.00007000"],["79894.00000000","0.02427000"],["79893.99000000","0.00000000"],["79893.92000000","0.00000000"],["79893.91000000","0.00000000"],["79893.49000000","0.00000000"],["79893.48000000","0.00000000"],["79893.20000000","0.00000000"],["79893.19000000","0.00007000"],["79892.75000000","0.00000000"],["79892.52000000","0.00000000"],["79892.31000000","0.00000000"],["79891.62000000","0.00000000"],["79891.46000000","0.00000000"],["79891.38000000","0.00907000"],["79891.18000000","0.00000000"],["79890.84000000","0.00000000"],["79890.70000000","0.06281000"],["79890.22000000","0.00000000"],["79890.08000000","0.06281000"],["79890.01000000","0.06288000"],["79889.83000000","0.00702000"],["79889.40000000","0.00007000"],["79889.14000000","0.00000000"],["79888.98000000","0.00000000"],["79888.84000000","0.06281000"],["79888.41000000","0.00014000"],["79888.37000000","0.00000000"],["79888.36000000","0.00000000"],["79888.22000000","0.06281000"],["79887.74000000","0.00000000"],["79887.60000000","0.06281000"],["79887.54000000","1.11220000"],["79887.53000000","0.01252000"],["79887.52000000","0.00000000"],["79887.20000000","0.00000000"],["79886.99000000","0.00000000"],["79885.66000000","0.00000000"],["79885.29000000","0.07000000"],["79885.20000000","0.00030000"],["79885.12000000","0.00000000"],["79884.41000000","0.08566000"],["79882.22000000","0.74041000"],["79882.21000000","0.00000000"],["79881.49000000","0.08000000"],["79878.03000000","0.00000000"],["79877.09000000","0.02200000"],["79877.03000000","0.03304000"],["79876.03000000","0.00125000"],["79874.70000000","0.02400000"],["79872.23000000","0.00000000"],["79869.02000000","0.00000000"],["79868.59000000","0.00000000"],["79867.75000000","0.09507000"],["79836.55000000","0.00400000"],["79828.65000000","0.00000000"],["79822.58000000","0.00000000"],["79822.02000000","0.00000000"],["79821.37000000","0.12302000"],["79819.60000000","0.00000000"],["79814.06000000","0.00000000"],["79813.79000000","0.02200000"],["79812.98000000","0.02410000"],["79810.87000000","0.02400000"],["79796.70000000","0.00000000"],["79748.78000000","0.00000000"],["79676.90000000","0.00000000"],["71910.83000000","0.00000000"],["63920.74000000","0.00000000"],["63920.00000000","0.05035000"]],"a":[["79900.01000000","5.24830000"],["79900.02000000","0.00027000"],["79900.03000000","0.00013000"],["79900.19000000","0.00000000"],["79900.46000000","0.00000000"],["79900.63000000","0.00000000"],["79900.85000000","0.00000000"],["79900.92000000","1.58928000"],["79900.93000000","2.94479000"],["79900.94000000","0.00000000"],["79900.95000000","0.00000000"],["79901.36000000","0.07521000"],["79901.37000000","0.00021000"],["79902.00000000","0.21538000"],["79902.01000000","0.52902000"],["79902.02000000","0.00000000"],["79902.22000000","0.00014000"],["79902.47000000","0.20154000"],["79902.53000000","0.00007000"],["79902.73000000","0.20819000"],["79902.96000000","0.04716000"],["79903.31000000","0.02007000"],["79903.38000000","0.02000000"],["79903.50000000","0.00000000"],["79903.88000000","0.00000000"],["79904.00000000","0.00007000"],["79904.78000000","0.00000000"],["79905.72000000","0.02007000"],["79906.01000000","0.97740000"],["79906.06000000","0.00000000"],["79907.81000000","0.84776000"],["79907.83000000","0.03224000"],["79908.00000000","0.00008000"],["79908.07000000","0.00000000"],["79908.27000000","0.00007000"],["79908.43000000","0.00000000"],["79908.60000000","0.36593000"],["79909.09000000","0.08576000"],["79909.99000000","0.00007000"],["79910.10000000","0.00000000"],["79910.72000000","0.00000000"],["79911.12000000","0.00000000"],["79911.44000000","0.33796000"],["79912.47000000","0.00007000"],["79913.39000000","0.00000000"],["79915.34000000","0.00000000"],["79917.87000000","0.00000000"],["79920.51000000","0.00000000"],["79921.35000000","0.00000000"],["79928.15000000","0.62572000"],["79930.00000000","0.11784000"],["79933.07000000","0.00000000"],["79937.62000000","0.00000000"],["79941.00000000","0.71000000"],["79942.00000000","0.02400000"],["79947.34000000","0.00000000"],["79947.81000000","0.00000000"],["79966.45000000","0.00000000"],["79973.83000000","0.00000000"],["79977.59000000","0.00000000"],["80007.28000000","0.00000000"],["80021.41000000","0.00018000"],["80057.53000000","0.00000000"],["80129.48000000","0.00000000"]]}}}
{"rx_ns": 13901897095600, "frame": {"stream":"btcusdt@depth@100ms","data":{"e":"depthUpdate","E":1787650897114,"s":"BTCUSDT","U":99118624005,"u":99118624160,"b":[["79900.00000000","0.02771000"],["79899.99000000","0.00098000"],["79899.64000000","0.00000000"],["79899.37000000","0.00000000"],["79898.75000000","0.00891000"],["79898.36000000","0.00000000"],["79898.29000000","0.00000000"],["79898.00000000","0.02435000"],["79897.48000000","0.00007000"],["79897.47000000","0.01485000"],["79897.37000000","0.05318000"],["79897.08000000","0.00000000"],["79896.20000000","0.00007000"],["79896.19000000","0.01783000"],["79896.00000000","0.02435000"],["79894.92000000","0.00007000"],["79894.91000000","0.01790000"],["79894.43000000","0.00007000"],["79894.42000000","0.06280000"],["79894.24000000","0.00007000"],["79894.23000000","0.06194000"],["79894.01000000","0.00000000"],["79894.00000000","0.02441000"],["79893.54000000","0.00000000"],["79893.18000000","0.12544000"],["79892.57000000","0.00000000"],["79892.56000000","0.06280000"],["79892.30000000","0.02281000"],["79892.02000000","0.00000000"],["79892.01000000","0.06280000"],["79892.00000000","0.02414000"],["79891.40000000","0.03348000"],["79891.33000000","0.00000000"],["79891.32000000","0.06280000"],["79890.71000000","0.00000000"],["79890.09000000","0.00000000"],["79890.02000000","0.00007000"],["79884.85000000","0.00048000"],["79884.60000000","0.00070000"],["79883.26000000","0.06271000"],["79882.64000000","0.06280000"],["79882.25000000","1.32176000"],["79882.24000000","1.87677000"],["79882.22000000","0.00000000"],["79875.72000000","0.02000000"],["79849.37000000","0.01136000"],["79847.41000000","0.00000000"],["79845.41000000","0.00012000"],["79824.84000000","0.00000000"],["79821.37000000","0.00000000"],["79821.12000000","0.00000000"],["79820.39000000","0.00000000"],["79813.79000000","0.00000000"],["79811.24000000","0.02000000"],["79809.61000000","0.00000000"],["79796.75000000","0.04543000"],["79676.19000000","0.00007000"],["79672.20000000","0.00000000"],["71910.00000000","0.13922000"]],"a":[["79900.01000000","5.29415000"],["79900.05000000","0.00992000"],["79900.92000000","1.58942000"],["79900.93000000","2.43807000"],["79901.33000000","0.01642000"],["79901.36000000","0.07521000"],["79901.37000000","0.00007000"],["79902.01000000","0.18551000"],["79902.04000000","0.05631000"],["79902.22000000","0.00000000"],["79902.47000000","0.20161000"],["79902.61000000","0.01971000"],["79903.31000000","0.04007000"],["79903.38000000","0.02007000"],["79903.89000000","0.01985000"],["79916.91000000","0.00015000"],["79924.60000000","0.00007000"],["79928.99000000","0.00000000"],["79937.55000000","0.00430000"],["79937.58000000","0.00429000"],["79940.00000000","0.34434000"],["79941.00000000","0.70000000"],["79962.33000000","0.00000000"],["79993.50000000","0.00556000"],["80146.43000000","0.00000000"]]}}}
{"rx_ns": 13901998739300, "frame": {"stream":"btcusdt@depth@100ms","data":{"e":"depthUpdate","E":1787650897214,"s":"BTCUSDT","U":99118624161,"u":99118624228,"b":[["79900.00000000","0.02792000"],["79898.75000000","0.00905000"],["79898.00000000","0.02435000"],["79897.47000000","0.01499000"],["79897.37000000","0.05318000"],["79896.19000000","0.01797000"],["79896.02000000","0.00000000"],["79896.00000000","0.02435000"],["79894.91000000","0.01804000"],["79894.42000000","0.06294000"],["79894.22000000","0.31306000"],["79894.00000000","0.02427000"],["79893.18000000","0.12537000"],["79892.79000000","0.33793000"],["79892.30000000","0.02267000"],["79892.00000000","0.02400000"],["79890.02000000","0.00000000"],["79886.98000000","0.01144000"],["79883.26000000","0.00000000"],["79878.03000000","0.00007000"],["79810.13000000","0.00000000"],["79809.21000000","0.02200000"],["79774.11000000","0.00000000"],["79768.46000000","0.00008000"],["79743.72000000","0.00400000"],["71910.00000000","0.13938000"],["63920.00000000","0.05004000"]],"a":[["79900.01000000","5.29415000"],["79900.05000000","0.01006000"],["79900.93000000","2.43793000"],["79902.46000000","0.15088000"],["79913.32000000","0.05173000"],["79922.60000000","0.00012000"],["79925.75000000","0.00000000"],["80025.57000000","0.00031000"],["80625.15000000","0.00000000"]]}}}
{"rx_ns": 13902099055800, "frame": {"stream":"btcusdt@depth@100ms","data":{"e":"depthUpdate","E":1787650897314,"s":"BTCUSDT","U":99118624229,"u":99118624311,"b":[["79900.00000000","0.59070000"],["79899.99000000","0.00105000"],["79899.03000000","0.00000000"],["79897.37000000","0.05325000"],["79896.29000000","0.00007000"],["79896.28000000","0.06280000"],["79896.00000000","0.02442000"],["79895.67000000","0.00007000"],["79895.66000000","0.06287000"],["79895.05000000","0.00007000"],["79895.04000000","0.06280000"],["79894.92000000","0.00000000"],["79894.23000000","0.06187000"],["79894.00000000","0.02422000"],["79893.19000000","0.06280000"],["79893.18000000","0.12544000"],["79893.09000000","0.03214000"],["79892.79000000","0.00000000"],["79892.56000000","0.00000000"],["79892.28000000","0.00014000"],["79891.40000000","0.00000000"],["79890.35000000","0.00031000"],["79887.55000000","0.44525000"],["79887.54000000","1.04939000"],["79887.53000000","0.00000000"],["79886.01000000","0.00000000"],["79885.20000000","0.00000000"],["79882.64000000","0.00000000"],["79878.02000000","0.00000000"],["79870.03000000","0.00000000"],["79847.15000000","0.00400000"],["79836.55000000","0.00000000"],["79812.98000000","0.00010000"],["79810.06000000","0.00000000"],["79809.21000000","0.00000000"],["79799.34000000","0.00025000"],["79678.55000000","0.00007000"],["71910.00000000","0.13954000"],["63929.00000000","0.00060000"]],"a":[["79900.01000000","4.90350000"],["79900.91000000","0.00007000"],["79900.92000000","1.51449000"],["79901.36000000","0.00021000"],["79902.00000000","0.10473000"],["79902.01000000","0.19241000"],["79902.04000000","0.00000000"],["79902.46000000","0.10087000"],["79902.47000000","0.00007000"],["79903.46000000","0.00007000"],["79910.80000000","0.00000000"],["79911.44000000","0.00000000"],["79912.71000000","1.02090000"],["79913.23000000","0.00000000"],["79913.32000000","0.04478000"],["79915.00000000","0.27916000"],["79923.90000000","0.51450000"],["79931.97000000","0.00007000"],["79932.70000000","0.33787000"],["79941.19000000","0.34687000"],["79945.20000000","0.25424000"],["79945.32000000","0.51589000"],["79961.45000000","0.00000000"],["79979.89000000","1.63272000"],["79980.52000000","2.31135000"],["79993.50000000","0.00000000"],["79999.09000000","0.00025000"],["80009.90000000","0.00000000"]]}}}
{"rx_ns": 13902195560700, "frame": {"stream":"btcusdt@depth@100ms","data":{"e":"depthUpdate","E":1787650897414,"s":"BTCUSDT","U":99118624312,"u":99118624371,"b":[["79900.00000000","0.58633000"],["79899.99000000","0.00105000"],["79897.37000000","0.05325000"],["79896.00000000","0.02428000"],["79894.91000000","0.01797000"],["79894.76000000","0.00007000"],["79894.75000000","0.04165000"],["79894.42000000","0.06280000"],["79894.24000000","0.00000000"],["79893.18000000","0.12530000"],["79893.09000000","0.00007000"],["79892.01000000","0.06289000"],["79887.56000000","0.06280000"],["79884.02000000","0.00016000"],["79876.03000000","0.00134000"],["79868.04000000","0.00016000"],["79853.58000000","0.00000000"],["79811.24000000","0.00000000"],["79810.87000000","0.00000000"],["79791.64000000","0.00400000"],["71910.00000000","0.13986000"]],"a":[["79900.01000000","4.91047000"],["79900.93000000","2.43807000"],["79901.33000000","0.01656000"],["79901.36000000","0.00007000"],["79902.01000000","0.19241000"],["79902.46000000","0.10101000"],["79902.61000000","0.01985000"],["79906.17000000","0.00007000"],["79908.25000000","0.00007000"],["79914.54000000","0.00000000"],["79923.90000000","0.00000000"],["79924.46000000","0.12511000"],["79972.86000000","0.00000000"],["79980.22000000","0.00000000"]]}}}
{"rx_ns": 13902296233700, "frame": {"stream":"btcusdt@depth@100ms","data":{"e":"depthUpdate","E":1787650897514,"s":"BTCUSDT","U":99118624372,"u":99118624391,"b":[["79900.00000000","0.58640000"],["79898.06000000","0.00007000"],["79894.01000000","0.00013000"],["79890.78000000","0.00000000"],["79884.78000000","0.00007000"],["79847.14000000","0.00012000"],["79845.41000000","0.00000000"],["79790.96000000","0.08703000"],["63920.00000000","0.05035000"]],"a":[["79900.01000000","4.91074000"],["79906.00000000","0.44095000"],["79916.75000000","0.00007000"],["79920.00000000","1.08526000"],["79922.60000000","0.00000000"],["79922.75000000","0.00000000"],["79930.00000000","0.12035000"],["79938.41000000","0.00000000"],["79942.22000000","0.00000000"],["79983.99000000","1.98724000"],["79987.53000000","3.75154000"]]}}}
{"rx_ns": 13902395753100, "frame": {"stream":"btcusdt@depth@100ms","data":{"e":"depthUpdate","E":1787650897614,"s":"BTCUSDT","U":99118624392,"u":99118624430,"b":[["79897.26000000","0.00000000"],["79895.37000000","0.00312000"],["79890.71000000","0.17837000"],["79887.55000000","0.43273000"],["79886.98000000","0.00048000"],["79872.57000000","0.02200000"],["79871.76000000","0.04000000"],["79863.52000000","0.00400000"],["79852.45000000","0.00400000"],["79839.20000000","0.00000000"],["79838.01000000","0.00000000"],["79836.61000000","0.00000000"],["79832.11000000","0.00312000"],["79830.87000000","0.00312000"],["79820.38000000","0.12210000"],["79809.26000000","0.02000000"],["79809.25000000","0.00000000"],["79797.28000000","0.02200000"],["79762.28000000","0.00000000"],["79752.26000000","0.00125000"],["71910.00000000","0.14018000"],["63920.00000000","0.05004000"]],"a":[["79905.89000000","0.02000000"],["79906.01000000","0.97747000"],["79906.68000000","0.02000000"],["79906.69000000","0.02000000"],["79908.00000000","0.00508000"],["79910.00000000","0.09886000"],["79912.00000000","0.00500000"],["79913.62000000","0.03818000"],["79917.20000000","0.00000000"],["79924.00000000","0.72400000"],["79924.33000000","0.00012000"],["79924.44000000","0.49345000"],["79966.83000000","0.00312000"],["79967.99000000","0.00312000"],["79976.80000000","0.00000000"],["79977.99000000","0.00000000"],["79979.10000000","0.00000000"]]}}}
