{"rx_ns": 13872795995200, "frame": {"stream":"btcusdt@depth20","data":{"lastUpdateId":99118593032,"bids":[["79889.99000000","3.74825000"],["79889.98000000","0.00027000"],["79889.97000000","0.00013000"],["79889.73000000","0.00007000"],["79889.53000000","0.00007000"],["79889.28000000","0.00042000"],["79889.05000000","0.00007000"],["79888.72000000","0.00007000"],["79888.71000000","0.02039000"],["79888.47000000","0.00007000"],["79888.45000000","0.00007000"],["79888.41000000","0.00014000"],["79888.39000000","0.00007000"],["79888.02000000","0.00014000"],["79888.01000000","0.47352000"],["79888.00000000","0.31322000"],["79887.99000000","0.22288000"],["79887.98000000","1.04953000"],["79887.43000000","0.02426000"],["79887.36000000","0.05709000"]],"asks":[["79890.00000000","0.55027000"],["79890.01000000","0.00083000"],["79890.02000000","0.00013000"],["79891.85000000","0.00007000"],["79891.86000000","0.06320000"],["79891.98000000","0.00014000"],["79891.99000000","0.00007000"],["79892.00000000","0.02428000"],["79892.28000000","0.00007000"],["79892.45000000","0.00007000"],["79892.46000000","0.00007000"],["79892.47000000","0.00007000"],["79892.48000000","0.06320000"],["79892.81000000","0.00112000"],["79892.94000000","0.00007000"],["79892.95000000","0.06327000"],["79892.96000000","0.04741000"],["79893.08000000","0.00137000"],["79893.70000000","0.00007000"],["79893.71000000","0.00014000"]]}}}
{"rx_ns": 13872796088300, "frame": {"stream":"btcusdt@depth@100ms","data":{"e":"depthUpdate","E":1787650868014,"s":"BTCUSDT","U":99118593026,"u":99118593032,"b":[["79844.24000000","0.00000000"],["71901.00000000","0.00432000"],["63912.00000000","0.00046000"]],"a":[["81088.35000000","0.00030000"]]}}}
{"rx_ns": 13872896093200, "frame": {"stream":"btcusdt@depth@100ms","data":{"e":"depthUpdate","E":1787650868114,"s":"BTCUSDT","U":99118593033,"u":99118593041,"b":[["79889.99000000","3.74661000"],["79826.19000000","0.00007000"],["79702.97000000","0.02163000"],["71901.00000000","0.00448000"],["71900.99000000","0.00000000"]],"a":[["79945.66000000","0.00007000"],["80065.23000000","0.02288000"]]}}}
{"rx_ns": 13872996332700, "frame": {"stream":"btcusdt@depth@100ms","data":{"e":"depthUpdate","E":1787650868214,"s":"BTCUSDT","U":99118593042,"u":99118593055,"b":[["79889.99000000","3.74653000"],["79888.02000000","1.87691000"],["79885.02000000","0.00000000"],["79874.78000000","0.00007000"],["78691.64000000","0.00125000"],["71901.00000000","0.00416000"],["63912.00000000","0.00015000"]],"a":[["79890.00000000","0.22969000"],["79894.95000000","0.00007000"],["79900.38000000","0.00000000"],["79900.98000000","0.00071000"],["79906.74000000","0.00007000"]]}}}
{"rx_ns": 13873096321700, "frame": {"stream":"btcusdt@depth@100ms","data":{"e":"depthUpdate","E":1787650868314,"s":"BTCUSDT","U":99118593056,"u":99118593084,"b":[["79889.99000000","3.75278000"],["79889.74000000","0.00625000"],["79888.71000000","0.02039000"],["79888.04000000","0.00007000"],["79888.03000000","1.03370000"],["79888.02000000","1.87691000"],["79888.01000000","0.00021000"],["79886.60000000","0.00000000"],["79886.59000000","0.00000000"],["79886.15000000","0.02405000"],["79886.02000000","0.00000000"],["79886.01000000","0.00007000"],["79826.63000000","0.02087000"],["79568.70000000","0.00000000"],["71901.00000000","0.00448000"],["63912.00000000","0.00015000"]],"a":[["79890.00000000","0.22969000"],["79894.94000000","0.00000000"],["79900.98000000","0.00000000"],["79901.74000000","0.00073000"],["80165.39000000","0.00000000"]]}}}
{"rx_ns": 13873202178700, "frame": {"stream":"btcusdt@depth@100ms","data":{"e":"depthUpdate","E":1787650868414,"s":"BTCUSDT","U":99118593085,"u":99118593124,"b":[["79889.99000000","5.62968000"],["79889.74000000","0.00639000"],["79888.71000000","0.02032000"],["79888.03000000","1.03377000"],["79888.02000000","1.87684000"],["79888.01000000","0.00007000"],["79887.36000000","0.05695000"],["79826.63000000","0.00000000"],["79762.17000000","0.00009000"],["79576.97000000","0.00036000"],["71901.00000000","0.00432000"]],"a":[["79890.00000000","0.02749000"],["79891.86000000","0.00014000"],["79892.48000000","0.00014000"],["79892.95000000","0.00021000"],["79893.72000000","0.00007000"],["79896.81000000","0.00000000"],["79897.99000000","0.06306000"],["79900.35000000","0.00000000"],["79901.12000000","0.15876000"],["79901.74000000","0.00000000"],["79901.80000000","0.00000000"],["79901.87000000","0.00699000"],["79902.78000000","0.00073000"],["79903.64000000","0.00000000"],["79904.09000000","0.00000000"],["79905.97000000","0.00625000"],["80173.72000000","0.00029000"]]}}}
{"rx_ns": 13873305500100, "frame": {"stream":"btcusdt@depth@100ms","data":{"e":"depthUpdate","E":1787650868514,"s":"BTCUSDT","U":99118593125,"u":99118593647,"b":[["79891.99000000","6.87822000"],["79891.98000000","0.00027000"],["79891.97000000","0.00013000"],["79891.85000000","0.00000000"],["79891.84000000","0.00000000"],["79891.37000000","0.00000000"],["79890.75000000","0.00000000"],["79890.13000000","0.00000000"],["79890.01000000","0.31307000"],["79890.00000000","1.44078000"],["79889.99000000","2.75031000"],["79889.98000000","0.00000000"],["79889.97000000","0.00000000"],["79889.74000000","0.00014000"],["79889.36000000","0.05294000"],["79888.72000000","0.00000000"],["79888.71000000","0.02039000"],["79888.04000000","0.00000000"],["79888.03000000","0.00014000"],["79888.02000000","0.00007000"],["79888.01000000","0.00000000"],["79888.00000000","0.00014000"],["79887.99000000","0.22281000"],["79887.43000000","0.02412000"],["79887.36000000","0.00400000"],["79886.58000000","0.32167000"],["79886.57000000","0.06425000"],["79886.37000000","0.37562000"],["79886.00000000","0.17972000"],["79885.01000000","0.44416000"],["79884.10000000","0.08576000"],["79884.00000000","0.00008000"],["79883.49000000","0.00007000"],["79882.53000000","0.00000000"],["79882.07000000","0.22907000"],["79882.04000000","0.39207000"],["79881.68000000","0.00000000"],["79880.76000000","0.04200000"],["79880.00000000","0.11797000"],["79879.44000000","0.51587000"],["79878.47000000","0.00000000"],["79878.21000000","0.25774000"],["79877.26000000","0.33809000"],["79876.01000000","0.00008000"],["79874.00000000","0.02400000"],["79873.89000000","0.00000000"],["79872.02000000","0.00008000"],["79871.18000000","0.00000000"],["79870.59000000","0.00000000"],["79869.14000000","0.00000000"],["79868.02000000","0.00008000"],["79867.65000000","0.09357000"],["79866.60000000","0.00000000"],["79864.03000000","0.00008000"],["79862.60000000","0.00000000"],["79860.03000000","0.00008000"],["79858.61000000","0.00000000"],["79858.59000000","0.00000000"],["79858.13000000","0.50969000"],["79856.04000000","0.00008000"],["79854.62000000","0.00000000"],["79854.03000000","0.34811000"],["79852.35000000","0.00010000"],["79852.04000000","0.00008000"],["79850.62000000","0.00000000"],["79846.86000000","0.00335000"],["79846.79000000","0.00000000"],["79846.63000000","0.00000000"],["79842.26000000","0.00000000"],["79838.16000000","0.00000000"],["79834.38000000","0.00000000"],["79834.37000000","0.00000000"],["79826.19000000","0.00000000"],["79824.39000000","0.12161000"],["79812.22000000","0.00000000"],["79812.10000000","0.00008000"],["79807.25000000","0.00000000"],["79802.16000000","0.00000000"],["79793.78000000","0.00000000"],["79732.21000000","0.00008000"],["79722.28000000","0.00000000"],["79691.61000000","0.00000000"],["79675.66000000","3.40571000"],["79652.31000000","0.00008000"],["79642.39000000","0.00000000"],["79593.12000000","0.00000000"],["79581.51000000","0.00000000"],["79572.42000000","0.00008000"],["79562.51000000","0.00000000"],["79492.53000000","0.00008000"],["79482.63000000","0.00000000"],["79412.64000000","0.00008000"],["79402.75000000","0.00000000"],["79332.75000000","0.00008000"],["79322.87000000","0.00000000"],["79252.85000000","0.00008000"],["79242.98000000","0.00000000"],["78691.64000000","0.00095000"],["71902.80000000","0.00016000"],["71901.00000000","0.00008000"],["63913.60000000","0.00031000"]],"a":[["79890.00000000","0.00000000"],["79890.01000000","0.00000000"],["79890.02000000","0.00000000"],["79891.85000000","0.00000000"],["79891.86000000","0.00000000"],["79891.98000000","0.00000000"],["79891.99000000","0.00000000"],["79892.00000000","0.02527000"],["79892.01000000","0.00042000"],["79892.47000000","0.00000000"],["79892.48000000","0.00000000"],["79892.94000000","0.00000000"],["79892.95000000","0.00000000"],["79892.96000000","0.00014000"],["79893.71000000","0.00007000"],["79893.72000000","0.00000000"],["79894.01000000","0.00702000"],["79894.33000000","0.00000000"],["79894.34000000","0.00014000"],["79894.74000000","0.00000000"],["79894.95000000","0.00007000"],["79894.96000000","0.04734000"],["79895.29000000","0.01145000"],["79895.47000000","0.00000000"],["79895.57000000","0.00000000"],["79895.58000000","0.00014000"],["79895.99000000","0.00007000"],["79896.00000000","0.02428000"],["79896.19000000","0.00000000"],["79896.20000000","0.00000000"],["79896.56000000","0.00007000"],["79896.57000000","0.01349000"],["79896.81000000","0.00000000"],["79896.82000000","0.00000000"],["79897.24000000","0.00000000"],["79897.29000000","0.00000000"],["79897.85000000","0.01349000"],["79897.99000000","0.00020000"],["79898.00000000","0.02415000"],["79898.67000000","0.00007000"],["79898.68000000","0.00007000"],["79899.17000000","0.00000000"],["79899.18000000","0.00007000"],["79899.28000000","0.00000000"],["79899.48000000","0.00026000"],["79899.91000000","0.00007000"],["79899.92000000","0.06306000"],["79899.96000000","0.00000000"],["79899.97000000","0.00000000"],["79899.98000000","0.00000000"],["79899.99000000","0.00007000"],["79900.02000000","0.00007000"],["79900.14000000","0.00000000"],["79900.39000000","0.00000000"],["79900.92000000","0.00000000"],["79900.98000000","0.00007000"],["79901.07000000","0.00000000"],["79901.12000000","0.00000000"],["79901.87000000","0.00007000"],["79902.78000000","0.00000000"],["79903.76000000","0.23953000"],["79903.88000000","0.00000000"],["79903.89000000","0.00014000"],["79904.88000000","0.06258000"],["79905.07000000","0.00007000"],["79905.23000000","0.00078000"],["79905.50000000","0.06125000"],["79905.75000000","0.42254000"],["79905.97000000","0.00000000"],["79906.12000000","0.00000000"],["79906.55000000","0.00000000"],["79906.74000000","0.00007000"],["79907.36000000","0.06306000"],["79907.94000000","0.06931000"],["79907.95000000","0.00000000"],["79907.96000000","0.15873000"],["79907.97000000","0.00000000"],["79908.53000000","0.00000000"],["79910.55000000","0.00000000"],["79911.08000000","0.06306000"],["79911.70000000","0.05951000"],["79911.97000000","0.00008000"],["79911.98000000","0.25332000"],["79913.49000000","0.00000000"],["79913.54000000","1.04939000"],["79913.55000000","0.00000000"],["79914.54000000","0.00000000"],["79914.59000000","0.00000000"],["79915.79000000","0.07007000"],["79915.97000000","0.00008000"],["79916.60000000","0.00000000"],["79916.76000000","0.00000000"],["79918.33000000","0.36586000"],["79918.35000000","0.00625000"],["79918.53000000","0.00000000"],["79919.96000000","0.00008000"],["79919.98000000","0.41762000"],["79920.71000000","0.00000000"],["79922.53000000","0.00000000"],["79923.28000000","0.62596000"],["79923.96000000","0.00008000"],["79925.27000000","0.00000000"],["79926.52000000","0.00000000"],["79927.95000000","0.00008000"],["79930.00000000","0.12035000"],["79930.98000000","0.00014000"],["79931.95000000","0.00008000"],["79932.00000000","0.73400000"],["79932.80000000","0.42936000"],["79937.10000000","0.17287000"],["79937.11000000","0.33784000"],["79937.99000000","0.00000000"],["79938.72000000","0.00007000"],["79941.44000000","0.00000000"],["79942.59000000","0.00007000"],["79946.19000000","0.00007000"],["79961.96000000","0.00000000"],["79971.89000000","0.00008000"],["79984.08000000","0.00000000"],["80019.43000000","0.00000000"],["80041.84000000","0.00000000"],["80051.78000000","0.00008000"],["80056.64000000","0.00000000"],["80121.73000000","0.00000000"],["80125.11000000","0.00007000"],["80129.10000000","0.00007000"],["80131.68000000","0.00008000"],["80281.49000000","0.00000000"],["80291.46000000","0.00008000"],["80441.25000000","0.00000000"],["80451.24000000","0.00008000"],["80521.14000000","0.00000000"],["80531.14000000","0.00008000"],["81088.35000000","0.00000000"]]}}}
{"rx_ns": 13873398740600, "frame": {"stream":"btcusdt@depth@100ms","data":{"e":"depthUpdate","E":1787650868614,"s":"BTCUSDT","U":99118593648,"u":99118594041,"b":[["79893.99000000","4.96556000"],["79893.98000000","0.00027000"],["79893.97000000","0.00013000"],["79893.87000000","0.00000000"],["79893.72000000","0.00000000"],["79893.69000000","0.00000000"],["79893.37000000","0.00000000"],["79893.07000000","0.00000000"],["79893.00000000","0.00008000"],["79892.75000000","0.00000000"],["79892.45000000","0.34681000"],["79892.28000000","0.00014000"],["79892.27000000","0.00000000"],["79892.13000000","0.00000000"],["79892.01000000","0.99627000"],["79892.00000000","1.12439000"],["79891.99000000","2.82106000"],["79891.98000000","0.00000000"],["79891.97000000","0.00000000"],["79891.36000000","0.05294000"],["79890.01000000","0.31328000"],["79890.00000000","0.59722000"],["79889.99000000","0.43315000"],["79889.74000000","0.00000000"],["79889.36000000","0.00014000"],["79889.28000000","0.00035000"],["79889.23000000","0.12517000"],["79889.05000000","0.00000000"],["79888.71000000","0.00014000"],["79888.47000000","0.00000000"],["79888.45000000","0.00000000"],["79888.39000000","0.00000000"],["79888.03000000","0.00000000"],["79888.02000000","0.00000000"],["79888.00000000","0.00020000"],["79887.43000000","0.00007000"],["79886.57000000","0.06418000"],["79886.15000000","0.00000000"],["79886.00000000","0.17959000"],["79885.99000000","0.09024000"],["79885.78000000","0.01761000"],["79885.65000000","0.00000000"],["79885.56000000","0.00010000"],["79885.32000000","0.00007000"],["79885.01000000","0.31899000"],["79884.10000000","0.00000000"],["79882.07000000","0.22894000"],["79882.01000000","0.00007000"],["79880.75000000","0.02000000"],["79880.00000000","0.12048000"],["79879.24000000","0.33808000"],["79873.03000000","0.12519000"],["79872.42000000","0.01146000"],["79872.03000000","0.52907000"],["79869.03000000","0.00000000"],["79861.99000000","0.00000000"],["79861.03000000","0.00000000"],["79853.58000000","0.00000000"],["79852.00000000","0.03400000"],["79850.00000000","0.02699000"],["79838.86000000","0.00000000"],["79836.78000000","0.00000000"],["79828.33000000","0.01718000"],["79827.28000000","0.00000000"],["79816.47000000","0.02000000"],["79725.96000000","0.00000000"],["79722.28000000","0.00009000"],["79663.92000000","0.00000000"],["79637.49000000","0.11582000"],["79554.18000000","0.02413000"],["79482.30000000","0.00000000"],["71902.80000000","0.00000000"],["63913.60000000","0.00000000"],["63913.59000000","0.00000000"]],"a":[["79892.00000000","0.00000000"],["79892.01000000","0.00000000"],["79892.28000000","0.00000000"],["79892.45000000","0.00000000"],["79892.46000000","0.00000000"],["79892.81000000","0.00000000"],["79892.96000000","0.00000000"],["79893.08000000","0.00000000"],["79893.25000000","0.00000000"],["79893.70000000","0.00000000"],["79893.71000000","0.00000000"],["79893.73000000","0.00000000"],["79893.88000000","0.00000000"],["79893.99000000","0.00000000"],["79894.00000000","0.02485000"],["79894.01000000","0.00070000"],["79894.34000000","0.00000000"],["79894.69000000","0.00000000"],["79894.95000000","0.00000000"],["79894.96000000","0.00014000"],["79895.29000000","0.00014000"],["79895.58000000","0.00000000"],["79895.78000000","0.00000000"],["79896.00000000","0.02442000"],["79896.56000000","0.00000000"],["79896.57000000","0.00014000"],["79896.95000000","0.00007000"],["79896.96000000","0.04727000"],["79897.84000000","0.00000000"],["79897.85000000","0.00014000"],["79897.99000000","0.00007000"],["79898.00000000","0.02421000"],["79898.45000000","0.00000000"],["79898.67000000","0.00000000"],["79899.43000000","0.00000000"],["79899.44000000","0.00000000"],["79899.92000000","0.06320000"],["79899.99000000","0.00020000"],["79900.98000000","0.00000000"],["79900.99000000","0.00007000"],["79901.99000000","0.00008000"],["79902.00000000","0.02407000"],["79902.18000000","0.00000000"],["79903.41000000","0.02007000"],["79903.74000000","0.00000000"],["79903.75000000","0.00014000"],["79903.76000000","0.16511000"],["79903.98000000","0.00000000"],["79904.00000000","0.02414000"],["79904.88000000","0.00000000"],["79905.50000000","0.00000000"],["79905.74000000","0.00000000"],["79907.36000000","0.00000000"],["79907.62000000","0.06305000"],["79907.94000000","0.06306000"],["79908.27000000","0.00007000"],["79908.78000000","0.06305000"],["79908.99000000","0.00000000"],["79909.98000000","0.00008000"],["79910.12000000","0.06305000"],["79910.28000000","0.00625000"],["79910.60000000","0.06306000"],["79910.62000000","0.00000000"],["79913.02000000","0.00000000"],["79915.62000000","0.02000000"],["79921.19000000","0.12512000"],["79923.29000000","1.87677000"],["79925.90000000","0.00000000"],["79928.20000000","0.00000000"],["79932.00000000","0.02400000"],["79933.08000000","0.00000000"],["79933.98000000","0.00007000"],["79934.00000000","0.03400000"],["79938.03000000","0.02479000"],["79940.91000000","0.62560000"],["79941.71000000","0.00000000"],["79942.59000000","0.00007000"],["79945.28000000","0.33781000"],["79946.19000000","0.00007000"],["79948.80000000","0.00396000"],["79950.70000000","0.00000000"],["79956.79000000","0.00190000"],["79956.80000000","0.00000000"],["79958.32000000","0.00000000"],["79959.88000000","0.67544000"],["79960.14000000","0.00000000"],["79960.99000000","0.00312000"],["79962.17000000","0.00312000"],["79973.83000000","1.23819000"],["79989.51000000","0.25000000"],["79998.59000000","0.00000000"],["79999.90000000","1.99263000"],["79999.91000000","1.95350000"],["80024.82000000","0.00000000"],["80037.01000000","0.00076000"],["80046.18000000","0.04561000"],["80081.75000000","0.05812000"],["80107.91000000","0.00000000"],["80109.71000000","0.00000000"],["80113.25000000","0.00000000"],["80115.93000000","0.01960000"],["80129.10000000","0.00000000"],["80133.92000000","0.00017000"],["80161.52000000","0.02743000"],["80166.62000000","0.01901000"]]}}}
{"rx_ns": 13873497651300, "frame": {"stream":"btcusdt@depth@100ms","data":{"e":"depthUpdate","E":1787650868714,"s":"BTCUSDT","U":99118594042,"u":99118594629,"b":[["79899.99000000","4.02223000"],["79899.98000000","0.00027000"],["79899.97000000","0.00013000"],["79899.91000000","0.00000000"],["79899.37000000","0.00000000"],["79899.17000000","0.00000000"],["79898.75000000","0.00000000"],["79898.67000000","0.00000000"],["79898.13000000","0.00000000"],["79897.99000000","0.00000000"],["79897.91000000","0.00000000"],["79897.40000000","0.00007000"],["79897.39000000","0.01605000"],["79897.38000000","0.05341000"],["79897.29000000","0.00000000"],["79896.95000000","0.00000000"],["79896.27000000","0.00000000"],["79896.15000000","0.00014000"],["79895.99000000","0.00000000"],["79895.98000000","0.00000000"],["79895.28000000","0.00000000"],["79895.04000000","0.00400000"],["79895.03000000","0.00000000"],["79894.95000000","0.00000000"],["79894.41000000","0.00000000"],["79894.05000000","0.31305000"],["79894.00000000","1.03063000"],["79893.99000000","2.53718000"],["79893.98000000","0.00000000"],["79893.97000000","0.00000000"],["79892.84000000","0.00026000"],["79892.71000000","0.02004000"],["79892.45000000","0.16311000"],["79892.01000000","0.00021000"],["79892.00000000","1.12461000"],["79891.99000000","2.22932000"],["79891.43000000","0.02411000"],["79891.36000000","0.00014000"],["79890.53000000","0.08576000"],["79890.15000000","0.02404000"],["79890.01000000","0.31328000"],["79889.99000000","0.37276000"],["79889.92000000","0.00400000"],["79889.89000000","0.00007000"],["79889.36000000","0.00000000"],["79888.71000000","0.00007000"],["79888.00000000","0.00007000"],["79887.99000000","0.14267000"],["79887.98000000","1.04939000"],["79886.69000000","0.00007000"],["79886.02000000","0.00007000"],["79886.00000000","0.10459000"],["79885.99000000","0.00448000"],["79885.78000000","0.01754000"],["79885.01000000","0.31871000"],["79884.77000000","0.00007000"],["79884.01000000","0.00015000"],["79884.00000000","0.00000000"],["79882.04000000","0.22193000"],["79880.29000000","0.00000000"],["79880.02000000","0.00008000"],["79877.09000000","0.00000000"],["79876.02000000","0.00133000"],["79876.01000000","0.00000000"],["79874.78000000","0.00000000"],["79873.03000000","0.00000000"],["79872.48000000","0.00000000"],["79872.03000000","0.52212000"],["79872.02000000","0.00000000"],["79871.51000000","0.62013000"],["79870.81000000","0.00000000"],["79868.03000000","0.00008000"],["79868.02000000","0.00000000"],["79867.08000000","0.00595000"],["79864.04000000","0.00008000"],["79864.03000000","0.00000000"],["79863.99000000","0.00000000"],["79862.33000000","0.00000000"],["79860.67000000","0.00400000"],["79860.04000000","0.00008000"],["79860.03000000","0.00000000"],["79858.17000000","0.00000000"],["79857.45000000","0.00000000"],["79857.42000000","0.00000000"],["79856.04000000","0.00000000"],["79856.00000000","0.02407000"],["79854.78000000","0.00000000"],["79854.00000000","0.02400000"],["79853.55000000","0.00000000"],["79852.04000000","0.00000000"],["79852.00000000","0.02400000"],["79848.26000000","0.00433000"],["79839.93000000","0.00012000"],["79835.93000000","0.00000000"],["79833.50000000","0.00000000"],["79831.71000000","0.00270000"],["79829.35000000","0.00000000"],["79798.07000000","0.00000000"],["79788.79000000","0.00400000"],["79785.54000000","0.00000000"],["79737.63000000","0.00000000"],["79669.00000000","0.00400000"],["79667.91000000","0.00000000"],["79665.76000000","0.00000000"],["79644.18000000","0.11398000"],["79599.97000000","0.00000000"],["79584.23000000","0.00000000"],["71910.00000000","0.13938000"],["63915.19000000","0.00128000"]],"a":[["79894.00000000","0.00000000"],["79894.01000000","0.00000000"],["79894.96000000","0.00000000"],["79895.29000000","0.00000000"],["79895.99000000","0.00000000"],["79896.00000000","0.00000000"],["79896.15000000","0.00000000"],["79896.57000000","0.00000000"],["79896.95000000","0.00000000"],["79896.96000000","0.00000000"],["79897.30000000","0.00000000"],["79897.85000000","0.00000000"],["79897.86000000","0.00000000"],["79897.92000000","0.00000000"],["79897.99000000","0.00000000"],["79898.00000000","0.00000000"],["79898.01000000","0.00000000"],["79898.04000000","0.00000000"],["79898.68000000","0.00000000"],["79899.18000000","0.00000000"],["79899.48000000","0.00000000"],["79899.91000000","0.00000000"],["79899.92000000","0.00000000"],["79899.94000000","0.00000000"],["79899.99000000","0.00000000"],["79900.00000000","1.78311000"],["79900.01000000","0.00035000"],["79900.02000000","0.00000000"],["79900.26000000","0.00000000"],["79900.46000000","0.00000000"],["79900.56000000","0.00007000"],["79900.57000000","0.01356000"],["79901.26000000","0.00245000"],["79901.84000000","0.00007000"],["79901.85000000","0.01349000"],["79901.87000000","0.00000000"],["79901.99000000","0.00007000"],["79902.00000000","0.02428000"],["79902.79000000","0.00000000"],["79902.97000000","0.00007000"],["79902.98000000","0.04679000"],["79903.40000000","0.00007000"],["79903.41000000","0.02021000"],["79903.75000000","0.00007000"],["79903.76000000","0.00021000"],["79903.89000000","0.00007000"],["79903.99000000","0.00007000"],["79904.00000000","0.02428000"],["79904.25000000","0.00007000"],["79904.26000000","0.02021000"],["79904.34000000","0.00007000"],["79904.35000000","0.02028000"],["79904.36000000","0.02007000"],["79905.23000000","0.00000000"],["79905.31000000","0.00007000"],["79905.73000000","0.00000000"],["79905.74000000","0.20065000"],["79905.75000000","0.42261000"],["79906.04000000","0.00000000"],["79906.13000000","0.00941000"],["79906.72000000","0.00081000"],["79906.73000000","0.19669000"],["79906.74000000","0.00000000"],["79907.02000000","0.00000000"],["79907.07000000","0.00702000"],["79907.62000000","0.00007000"],["79907.63000000","0.00807000"],["79907.94000000","0.00000000"],["79907.95000000","0.00000000"],["79907.96000000","0.15880000"],["79907.99000000","0.00008000"],["79908.00000000","0.02407000"],["79908.78000000","0.00000000"],["79908.98000000","0.00000000"],["79909.98000000","0.00000000"],["79910.00000000","0.14914000"],["79910.12000000","0.00000000"],["79910.60000000","0.00000000"],["79911.07000000","0.00705000"],["79911.47000000","0.00007000"],["79911.97000000","0.00000000"],["79911.98000000","0.00007000"],["79913.11000000","0.00000000"],["79915.07000000","0.00690000"],["79915.51000000","0.00000000"],["79915.97000000","0.00000000"],["79915.98000000","0.00022000"],["79916.74000000","0.00007000"],["79917.07000000","0.00000000"],["79918.35000000","0.00000000"],["79919.07000000","0.00689000"],["79919.36000000","0.00075000"],["79919.96000000","0.00000000"],["79919.97000000","0.19019000"],["79919.98000000","0.41770000"],["79921.19000000","0.00000000"],["79921.99000000","0.00625000"],["79923.07000000","0.00701000"],["79923.96000000","0.00000000"],["79923.97000000","0.00133000"],["79924.01000000","0.00000000"],["79924.58000000","0.00000000"],["79925.98000000","0.12511000"],["79926.55000000","0.00000000"],["79927.40000000","0.00400000"],["79927.95000000","0.00000000"],["79927.97000000","0.00008000"],["79929.00000000","0.00000000"],["79930.00000000","0.11784000"],["79931.95000000","0.00000000"],["79931.96000000","0.00015000"],["79934.00000000","0.02400000"],["79934.85000000","0.00014000"],["79935.96000000","0.00008000"],["79936.88000000","0.04414000"],["79938.31000000","0.00000000"],["79938.56000000","0.00012000"],["79938.72000000","0.00014000"],["79939.12000000","0.00000000"],["79939.90000000","0.00200000"],["79939.95000000","0.00008000"],["79940.00000000","0.25302000"],["79940.56000000","0.00059000"],["79941.01000000","0.00000000"],["79941.33000000","0.00000000"],["79942.33000000","0.00000000"],["79945.56000000","0.00000000"],["79948.54000000","0.00431000"],["79949.28000000","0.00622000"],["79951.68000000","0.00429000"],["79951.89000000","0.00430000"],["79963.70000000","0.00000000"],["79963.98000000","0.00000000"],["79965.63000000","0.00008000"],["79971.89000000","0.00000000"],["79979.90000000","0.00015000"],["79989.51000000","0.00000000"],["79995.95000000","0.00000000"],["79999.91000000","0.00000000"],["80005.60000000","0.00007000"],["80032.58000000","0.00000000"],["80043.90000000","0.00000000"],["80047.30000000","0.00400000"],["80049.25000000","0.44309000"],["80051.78000000","0.00000000"],["80059.80000000","0.00015000"],["80114.83000000","0.00000000"],["80115.83000000","0.00000000"],["80119.23000000","0.00400000"],["80130.17000000","0.00007000"],["80131.68000000","0.00000000"],["80133.42000000","0.00007000"],["80134.16000000","0.00000000"],["80137.41000000","0.00007000"],["80139.70000000","0.00008000"],["80291.46000000","0.00000000"],["80295.30000000","0.00014000"],["80299.50000000","0.00008000"],["80451.24000000","0.00000000"],["80459.30000000","0.00008000"],["80531.14000000","0.00000000"],["80539.20000000","0.00036000"]]}}}
{"rx_ns": 13873596106000, "frame": {"stream":"btcusdt@depth@100ms","data":{"e":"depthUpdate","E":1787650868814,"s":"BTCUSDT","U":99118594630,"u":99118594742,"b":[["79899.99000000","4.04730000"],["79898.26000000","0.00007000"],["79898.25000000","0.05216000"],["79898.24000000","0.12053000"],["79897.40000000","0.00000000"],["79897.39000000","0.00021000"],["79897.38000000","0.05355000"],["79894.05000000","0.31319000"],["79894.00000000","1.03077000"],["79893.99000000","2.01886000"],["79892.71000000","0.00007000"],["79892.45000000","0.16297000"],["79892.01000000","0.00007000"],["79891.99000000","2.22090000"],["79891.43000000","0.00007000"],["79891.36000000","0.00000000"],["79890.15000000","0.00000000"],["79890.01000000","0.31314000"],["79890.00000000","0.59708000"],["79889.99000000","0.34796000"],["79885.77000000","0.00060000"],["79883.67000000","0.00012000"],["79871.73000000","0.00000000"],["79869.92000000","0.00000000"],["79860.00000000","0.12792000"],["79832.07000000","0.00312000"],["79830.34000000","0.00311000"],["79830.33000000","0.02087000"],["79822.17000000","0.00000000"],["79820.38000000","0.00000000"],["79675.51000000","0.00000000"],["79672.02000000","0.00000000"],["79670.00000000","0.00067000"],["71910.00000000","0.13954000"]],"a":[["79900.00000000","1.25712000"],["79900.56000000","0.00000000"],["79900.57000000","0.00021000"],["79901.26000000","0.00000000"],["79901.84000000","0.00000000"],["79901.85000000","0.00014000"],["79902.00000000","0.02428000"],["79902.98000000","0.04686000"],["79903.41000000","0.02014000"],["79903.76000000","0.00007000"],["79905.73000000","0.00007000"],["79906.73000000","0.19669000"],["79907.07000000","0.00000000"],["79907.95000000","0.00007000"],["79910.28000000","0.00000000"],["79911.98000000","0.05932000"],["79912.47000000","0.00625000"],["79917.12000000","0.00012000"],["79927.09000000","0.00250000"],["79928.91000000","0.00000000"],["79936.80000000","0.00653000"],["79943.68000000","0.00400000"],["79960.99000000","0.00000000"],["79962.17000000","0.00000000"],["79967.45000000","0.00311000"],["79969.12000000","0.00310000"],["79978.37000000","0.00111000"],["79997.52000000","0.25000000"],["79999.34000000","0.00400000"],["80017.81000000","0.00150000"],["80036.00000000","0.10012000"],["80037.02000000","0.00000000"],["80038.51000000","0.00000000"],["80047.29000000","0.00125000"],["80049.24000000","0.00125000"],["80134.74000000","0.00000000"],["80167.76000000","0.01907000"],["80190.88000000","0.07571000"],["81888.00000000","11.28772000"]]}}}
{"rx_ns": 13873696518300, "frame": {"stream":"btcusdt@depth@100ms","data":{"e":"depthUpdate","E":1787650868914,"s":"BTCUSDT","U":99118594743,"u":99118594804,"b":[["79899.99000000","4.05962000"],["79898.72000000","0.00007000"],["79898.71000000","0.02003000"],["79898.25000000","0.05230000"],["79898.24000000","0.12067000"],["79897.44000000","0.00007000"],["79897.43000000","0.02404000"],["79897.39000000","0.00007000"],["79897.38000000","0.05362000"],["79896.16000000","0.00007000"],["79896.15000000","0.02418000"],["79894.00000000","0.98928000"],["79893.99000000","2.01872000"],["79892.71000000","0.00000000"],["79892.00000000","1.12470000"],["79889.99000000","0.34787000"],["79886.57000000","0.06411000"],["79885.99000000","0.00441000"],["79882.00000000","0.02400000"],["79864.31000000","0.00000000"],["79845.93000000","0.00012000"],["79839.93000000","0.00000000"],["79830.33000000","0.00000000"],["79688.21000000","0.00770000"],["79681.02000000","0.00000000"]],"a":[["79900.00000000","1.25712000"],["79900.57000000","0.00000000"],["79901.85000000","0.00000000"],["79902.98000000","0.04693000"],["79904.00000000","0.02435000"],["79904.01000000","0.00674000"],["79904.36000000","0.02021000"],["79905.29000000","0.01124000"],["79905.74000000","0.20072000"],["79906.13000000","0.00948000"],["79906.57000000","0.01349000"],["79907.26000000","0.00245000"],["79907.85000000","0.01349000"],["79910.98000000","0.06196000"],["79917.12000000","0.00000000"],["79919.98000000","0.00008000"],["79923.28000000","0.98414000"],["80427.41000000","0.00373000"]]}}}
{"rx_ns": 13873797999600, "frame": {"stream":"btcusdt@depth20","data":{"lastUpdateId":99118594924,"bids":[["79899.99000000","3.22914000"],["79899.98000000","0.00027000"],["79899.97000000","0.00013000"],["79898.72000000","0.00007000"],["79898.71000000","0.02017000"],["79898.26000000","0.00007000"],["79898.25000000","0.03066000"],["79898.24000000","0.00014000"],["79897.44000000","0.00007000"],["79897.43000000","0.02411000"],["79897.39000000","0.00007000"],["79897.38000000","0.05355000"],["79897.26000000","0.00007000"],["79896.16000000","0.00007000"],["79896.15000000","0.02425000"],["79895.04000000","0.00400000"],["79894.06000000","0.00007000"],["79894.05000000","0.31319000"],["79894.01000000","0.00007000"],["79894.00000000","1.43812000"]],"asks":[["79900.00000000","1.25742000"],["79900.01000000","0.00042000"],["79900.84000000","0.00007000"],["79900.99000000","0.00007000"],["79901.75000000","0.00010000"],["79901.99000000","0.00007000"],["79902.00000000","0.02428000"],["79902.02000000","0.00007000"],["79902.97000000","0.00007000"],["79902.98000000","0.04693000"],["79903.40000000","0.00007000"],["79903.41000000","0.02014000"],["79903.75000000","0.00007000"],["79903.76000000","0.00007000"],["79903.89000000","0.00007000"],["79903.99000000","0.00007000"],["79904.00000000","0.02428000"],["79904.01000000","0.00688000"],["79904.10000000","0.00007000"],["79904.24000000","0.00007000"]]}}}
{"rx_ns": 13873798129100, "frame": {"stream":"btcusdt@depth@100ms","data":{"e":"depthUpdate","E":1787650869014,"s":"BTCUSDT","U":99118594805,"u":99118594924,"b":[["79899.99000000","3.22914000"],["79898.71000000","0.02017000"],["79898.25000000","0.03066000"],["79898.24000000","0.00014000"],["79897.43000000","0.02411000"],["79897.38000000","0.05355000"],["79897.26000000","0.00007000"],["79896.15000000","0.02425000"],["79894.06000000","0.00007000"],["79894.01000000","0.00007000"],["79894.00000000","1.43812000"],["79893.99000000","2.02792000"],["79892.45000000","0.16290000"],["79892.00000000","1.12456000"],["79889.20000000","0.00007000"],["79886.57000000","0.06397000"],["79886.01000000","0.00000000"],["79884.02000000","0.00625000"],["79882.39000000","0.00000000"],["79880.01000000","0.62600000"],["79876.17000000","0.00000000"],["79872.39000000","0.00000000"],["79868.44000000","0.00000000"],["79862.04000000","0.00000000"],["79771.95000000","0.00000000"],["79771.20000000","0.00012000"],["79765.04000000","0.00007000"],["79761.22000000","0.00000000"],["79755.43000000","0.00000000"],["79740.87000000","0.00400000"],["79501.20000000","0.00000000"],["71910.00000000","0.13970000"],["71909.00000000","0.00000000"],["63920.00000000","0.05035000"]],"a":[["79900.00000000","1.25742000"],["79900.01000000","0.00042000"],["79902.01000000","0.00000000"],["79904.00000000","0.02428000"],["79904.01000000","0.00688000"],["79904.24000000","0.00007000"],["79904.25000000","0.06203000"],["79904.34000000","0.00007000"],["79904.35000000","0.02028000"],["79904.36000000","0.02028000"],["79904.87000000","0.00007000"],["79904.88000000","0.06196000"],["79905.29000000","0.01131000"],["79905.49000000","0.06203000"],["79905.73000000","0.06196000"],["79905.74000000","0.20058000"],["79906.72000000","0.00000000"],["79907.63000000","0.00814000"],["79907.96000000","0.23098000"],["79908.00000000","0.02400000"],["79908.01000000","0.00000000"],["79908.53000000","0.00085000"],["79908.78000000","0.06196000"],["79909.76000000","0.00000000"],["79909.99000000","0.00000000"],["79911.08000000","0.00000000"],["79911.99000000","0.80346000"],["79913.54000000","0.00000000"],["79913.69000000","1.04939000"],["79914.01000000","0.00007000"],["79923.12000000","0.00012000"],["79923.28000000","0.35818000"],["79925.97000000","0.62593000"],["79926.20000000","0.00000000"],["79926.21000000","0.00000000"],["79938.03000000","0.00000000"],["79946.46000000","0.00007000"],["79999.70000000","0.00000000"],["80004.03000000","0.02445000"],["80006.70000000","0.00000000"],["80009.39000000","0.00000000"],["80009.55000000","0.00000000"],["80222.88000000","0.00007000"],["81098.50000000","0.00030000"]]}}}
{"rx_ns": 13873900912400, "frame": {"stream":"btcusdt@depth@100ms","data":{"e":"depthUpdate","E":1787650869114,"s":"BTCUSDT","U":99118594925,"u":99118594953,"b":[["79898.25000000","0.03066000"],["79898.24000000","0.00007000"],["79898.06000000","0.00007000"],["79893.99000000","2.02799000"],["79891.64000000","0.00007000"],["79889.57000000","0.00007000"],["79887.99000000","0.14253000"],["79882.10000000","2.39084000"],["79876.22000000","0.00000000"],["79831.75000000","0.00375000"],["79789.34000000","0.00000000"],["71910.00000000","0.14002000"]],"a":[["79904.01000000","0.00688000"],["79904.25000000","0.06210000"],["79904.36000000","0.02021000"],["79906.73000000","0.19676000"],["79907.20000000","0.00691000"],["79907.96000000","0.23091000"],["79935.97000000","0.49646000"],["79939.95000000","0.02487000"],["79944.20000000","1.20212000"],["79989.07000000","0.00000000"],["80057.81000000","0.00150000"]]}}}
{"rx_ns": 13873998826600, "frame": {"stream":"btcusdt@depth@100ms","data":{"e":"depthUpdate","E":1787650869214,"s":"BTCUSDT","U":99118594954,"u":99118594990,"b":[["79899.99000000","3.23234000"],["79894.06000000","0.00000000"],["79894.01000000","0.00000000"],["79894.00000000","1.43805000"],["79889.99000000","0.34777000"],["79885.79000000","0.33806000"],["79877.26000000","0.00000000"],["79875.00000000","0.70000000"],["79860.67000000","0.00000000"],["79832.83000000","0.02087000"],["79817.68000000","0.00000000"],["79799.33000000","0.00025000"],["79788.79000000","0.00000000"],["79765.82000000","0.00015000"],["79740.87000000","0.00000000"],["79669.00000000","0.00000000"],["63920.00000000","0.05004000"]],"a":[["79908.78000000","0.00000000"],["79908.79000000","0.00000000"],["79913.69000000","0.00000000"],["79913.70000000","0.00000000"],["79927.40000000","0.00000000"],["79942.00000000","0.72400000"],["79967.37000000","0.00000000"],["79974.48000000","1.23818000"],["79988.33000000","0.00000000"],["79999.08000000","0.00025000"],["79999.34000000","0.00000000"],["80016.71000000","0.00012000"],["80019.40000000","0.00018000"],["80035.27000000","0.00394000"],["80047.30000000","0.00000000"],["80119.23000000","0.00000000"],["80260.14000000","0.20250000"],["80609.00000000","0.00000000"]]}}}
{"rx_ns": 13874101095600, "frame": {"stream":"btcusdt@depth@100ms","data":{"e":"depthUpdate","E":1787650869314,"s":"BTCUSDT","U":99118594991,"u":99118595028,"b":[["79899.99000000","3.23241000"],["79899.31000000","0.00007000"],["79899.30000000","0.02152000"],["79894.06000000","0.00000000"],["79894.01000000","0.00000000"],["79894.00000000","1.43805000"],["79880.22000000","0.00000000"],["79832.83000000","0.00000000"],["78701.49000000","0.00030000"],["71910.00000000","0.14034000"],["63920.00000000","0.05004000"],["63912.00000000","0.00015000"]],"a":[["79907.96000000","0.16317000"],["79907.99000000","0.20258000"],["79911.99000000","0.24324000"],["79916.47000000","0.06203000"],["79916.76000000","0.06203000"],["79916.77000000","1.01005000"],["79917.88000000","1.87677000"],["79946.46000000","0.00000000"],["80115.93000000","0.00000000"],["80127.77000000","0.01960000"]]}}}
{"rx_ns": 13874200537300, "frame": {"stream":"btcusdt@depth@100ms","data":{"e":"depthUpdate","E":1787650869414,"s":"BTCUSDT","U":99118595029,"u":99118595042,"b":[["79899.99000000","3.23248000"],["79893.99000000","2.02792000"],["71910.00000000","0.14050000"]],"a":[["79916.36000000","0.00007000"],["80004.03000000","0.00000000"],["80023.56000000","0.00031000"],["80029.13000000","0.02467000"],["80052.48000000","0.00400000"],["80081.75000000","0.00000000"],["80109.16000000","0.05620000"]]}}}
{"rx_ns": 13874298224800, "frame": {"stream":"btcusdt@depth@100ms","data":{"e":"depthUpdate","E":1787650869514,"s":"BTCUSDT","U":99118595043,"u":99118595058,"b":[["79894.06000000","0.00007000"],["79894.01000000","0.00000000"],["79894.00000000","1.43805000"],["79888.71000000","0.00000000"],["79887.43000000","0.00000000"],["79832.07000000","0.32353000"],["63920.00000000","0.05035000"]],"a":[["79907.96000000","0.18169000"],["79907.99000000","0.20258000"],["79911.59000000","0.06203000"],["79920.01000000","0.00007000"],["79941.10000000","1.21750000"]]}}}
{"rx_ns": 13874401153800, "frame": {"stream":"btcusdt@depth@100ms","data":{"e":"depthUpdate","E":1787650869614,"s":"BTCUSDT","U":99118595059,"u":99118595075,"b":[["79897.26000000","0.00000000"],["79894.06000000","0.00000000"],["79889.28000000","0.00028000"],["79884.94000000","0.12518000"],["79865.85000000","0.00400000"],["79829.25000000","0.02000000"],["71910.00000000","0.14066000"],["63920.00000000","0.05004000"],["63919.99000000","0.00000000"]],"a":[["79900.00000000","1.25755000"],["79900.01000000","0.00055000"],["79900.02000000","0.00013000"],["79903.64000000","0.00007000"],["79916.94000000","0.12512000"]]}}}
{"rx_ns": 13874508170600, "frame": {"stream":"btcusdt@depth@100ms","data":{"e":"depthUpdate","E":1787650869714,"s":"BTCUSDT","U":99118595076,"u":99118595087,"b":[["79898.86000000","0.00007000"],["79890.00000000","0.76409000"],["79889.23000000","0.59242000"],["79884.77000000","0.00007000"],["79758.60000000","0.00000000"],["71910.00000000","0.14066000"],["63919.99000000","0.00000000"]],"a":[["79916.74000000","0.00007000"],["79998.24000000","0.00000000"]]}}}
{"rx_ns": 13874620803700, "frame": {"stream":"btcusdt@depth@100ms","data":{"e":"depthUpdate","E":1787650869815,"s":"BTCUSDT","U":99118595088,"u":99118595119,"b":[["79899.99000000","3.23911000"],["79899.30000000","0.02166000"],["79897.43000000","0.02418000"],["79897.38000000","0.05362000"],["79896.15000000","0.02432000"],["79895.99000000","0.00689000"],["79864.00000000","0.02400000"],["79771.26000000","0.04415000"],["71910.00000000","0.14066000"],["71901.00000000","0.00000000"],["71900.99000000","0.00008000"]],"a":[["79900.00000000","1.25731000"],["79903.41000000","0.02021000"],["79904.00000000","0.02435000"],["79904.01000000","0.00695000"],["79905.74000000","0.08174000"],["79905.75000000","0.00007000"],["79911.98000000","0.00007000"],["79915.58000000","0.06204000"],["80004.52000000","0.00400000"],["80010.94000000","0.02804000"]]}}}
{"rx_ns": 13874704049000, "frame": {"stream":"btcusdt@depth@100ms","data":{"e":"depthUpdate","E":1787650869914,"s":"BTCUSDT","U":99118595120,"u":99118595133,"b":[["79896.15000000","0.02439000"],["79895.99000000","0.00696000"],["79894.06000000","0.00400000"],["79894.00000000","1.43791000"],["79824.68000000","0.00626000"],["79811.69000000","0.00000000"],["71910.00000000","0.14082000"]],"a":[["79909.76000000","0.06204000"],["79909.99000000","0.05575000"],["79915.25000000","0.05601000"],["79915.57000000","0.00400000"]]}}}
{"rx_ns": 13874798738900, "frame": {"stream":"btcusdt@depth20","data":{"lastUpdateId":99118595140,"bids":[["79899.99000000","3.23911000"],["79899.98000000","0.00027000"],["79899.97000000","0.00013000"],["79899.31000000","0.00007000"],["79899.30000000","0.02166000"],["79898.86000000","0.00007000"],["79898.72000000","0.00007000"],["79898.71000000","0.02017000"],["79898.26000000","0.00007000"],["79898.25000000","0.03066000"],["79898.24000000","0.00007000"],["79898.06000000","0.00007000"],["79897.44000000","0.00007000"],["79897.43000000","0.02418000"],["79897.39000000","0.00007000"],["79897.38000000","0.05362000"],["79896.16000000","0.00007000"],["79896.15000000","0.02439000"],["79895.99000000","0.00696000"],["79895.04000000","0.00400000"]],"asks":[["79900.00000000","1.25731000"],["79900.01000000","0.00055000"],["79900.02000000","0.00013000"],["79900.84000000","0.00007000"],["79900.99000000","0.00007000"],["79901.75000000","0.00010000"],["79901.99000000","0.00007000"],["79902.00000000","0.02428000"],["79902.02000000","0.00007000"],["79902.97000000","0.00007000"],["79902.98000000","0.04693000"],["79903.40000000","0.00007000"],["79903.41000000","0.02021000"],["79903.64000000","0.00007000"],["79903.75000000","0.00007000"],["79903.76000000","0.00007000"],["79903.89000000","0.00007000"],["79903.99000000","0.00007000"],["79904.00000000","0.02435000"],["79904.01000000","0.00695000"]]}}}
{"rx_ns": 13874798901600, "frame": {"stream":"btcusdt@depth@100ms","data":{"e":"depthUpdate","E":1787650870014,"s":"BTCUSDT","U":99118595134,"u":99118595140,"b":[["79746.05000000","0.00400000"],["71910.00000000","0.14098000"],["63920.00000000","0.05035000"]],"a":[["81098.50000000","0.00030000"]]}}}
{"rx_ns": 13874901829000, "frame": {"stream":"btcusdt@depth@100ms","data":{"e":"depthUpdate","E":1787650870114,"s":"BTCUSDT","U":99118595141,"u":99118595152,"b":[["79893.72000000","0.00007000"],["79888.47000000","0.00007000"],["79887.99000000","0.14246000"],["79887.49000000","0.00007000"],["79884.02000000","0.00632000"],["79755.86000000","1.50235000"],["71910.00000000","0.14082000"]],"a":[["79900.00000000","1.26983000"],["79905.99000000","0.00013000"],["79915.57000000","0.00400000"],["80059.49000000","1.50235000"]]}}}
{"rx_ns": 13874995902300, "frame": {"stream":"btcusdt@depth@100ms","data":{"e":"depthUpdate","E":1787650870214,"s":"BTCUSDT","U":99118595153,"u":99118595168,"b":[["79899.99000000","3.23921000"],["79885.06000000","0.00650000"],["79867.08000000","0.00000000"],["79674.17000000","0.00400000"],["71910.00000000","0.14114000"],["71909.00000000","0.00000000"],["63920.00000000","0.05004000"]],"a":[["79900.00000000","1.27046000"],["79902.04000000","0.00007000"],["79904.25000000","0.00014000"],["79904.88000000","0.00000000"],["79907.63000000","0.00807000"],["79907.95000000","0.00000000"],["79908.52000000","0.00010000"],["80619.09000000","0.00010000"]]}}}
{"rx_ns": 13875096538200, "frame": {"stream":"btcusdt@depth@100ms","data":{"e":"depthUpdate","E":1787650870314,"s":"BTCUSDT","U":99118595169,"u":99118595202,"b":[["79899.99000000","3.23867000"],["79848.00000000","0.02400000"],["79778.13000000","0.00000000"],["79700.91000000","0.00793000"],["79688.21000000","0.00000000"],["79000.00000000","25.03202000"],["78701.49000000","0.00030000"],["71910.00000000","0.14114000"],["63912.00000000","0.00015000"]],"a":[["79900.00000000","1.27032000"],["79900.01000000","0.00048000"],["79904.01000000","0.00695000"],["79904.24000000","0.00000000"],["79904.25000000","0.00007000"],["79904.36000000","0.02028000"],["79904.87000000","0.00000000"],["79905.27000000","0.00007000"],["79905.28000000","0.11884000"],["79905.48000000","0.00007000"],["79905.49000000","0.06196000"],["79905.72000000","0.00000000"],["79905.73000000","0.00000000"],["79905.74000000","0.00007000"],["79907.93000000","0.06204000"],["79907.95000000","0.06204000"]]}}}
{"rx_ns": 13875203008100, "frame": {"stream":"btcusdt@depth@100ms","data":{"e":"depthUpdate","E":1787650870414,"s":"BTCUSDT","U":99118595203,"u":99118595225,"b":[["79894.99000000","0.00017000"],["79889.99000000","0.34770000"],["79877.39000000","0.09464000"],["79875.39000000","0.10368000"],["79872.09000000","0.00000000"],["79870.09000000","0.00000000"],["79841.73000000","0.82225000"],["79832.83000000","0.00000000"],["79828.14000000","0.82239000"],["79827.48000000","0.00000000"],["79825.91000000","0.00400000"],["79820.09000000","0.00012000"],["79813.90000000","0.00000000"],["71910.00000000","0.14130000"]],"a":[["79904.36000000","0.02028000"],["79908.52000000","0.00000000"],["79912.82000000","0.00000000"],["79914.82000000","0.00000000"],["79946.46000000","0.00007000"]]}}}
{"rx_ns": 13875296766300, "frame": {"stream":"btcusdt@depth@100ms","data":{"e":"depthUpdate","E":1787650870514,"s":"BTCUSDT","U":99118595226,"u":99118595241,"b":[["71900.99000000","0.00000000"],["63920.00000000","0.05035000"]],"a":[["79900.00000000","1.27011000"],["79904.36000000","0.02021000"],["79905.27000000","0.00000000"],["79905.28000000","0.00000000"],["79905.99000000","0.00020000"],["79906.13000000","0.00014000"],["79906.57000000","0.01356000"],["79906.71000000","0.05690000"],["79907.20000000","0.00000000"],["79925.53000000","0.40590000"],["79972.97000000","1.48825000"]]}}}
{"rx_ns": 13875402461000, "frame": {"stream":"btcusdt@depth@100ms","data":{"e":"depthUpdate","E":1787650870614,"s":"BTCUSDT","U":99118595242,"u":99118595351,"b":[["79895.99000000","0.00703000"],["79894.06000000","0.01207000"],["79894.01000000","0.00007000"],["79894.00000000","1.43798000"],["79893.30000000","0.00400000"],["79857.15000000","0.00000000"],["71910.00000000","0.14146000"],["63920.00000000","0.05004000"],["63919.99000000","0.00000000"]],"a":[["79900.00000000","1.27161000"],["79900.01000000","0.00062000"],["79902.00000000","0.02435000"],["79902.96000000","0.00007000"],["79902.97000000","0.06211000"],["79902.98000000","0.04700000"],["79903.40000000","0.00000000"],["79903.41000000","0.00021000"],["79903.65000000","0.00007000"],["79903.66000000","0.06204000"],["79904.01000000","0.00695000"],["79904.25000000","0.00000000"],["79904.26000000","0.00028000"],["79904.27000000","0.06211000"],["79904.34000000","0.00000000"],["79904.35000000","0.00021000"],["79904.36000000","0.00021000"],["79904.87000000","0.00007000"],["79904.88000000","0.06204000"],["79905.29000000","0.01138000"],["79905.40000000","0.00007000"],["79905.41000000","0.04617000"],["79905.47000000","0.00007000"],["79905.48000000","0.08618000"],["79905.49000000","0.06203000"],["79905.99000000","0.00013000"],["79906.09000000","0.00000000"],["79906.10000000","0.06151000"],["79906.70000000","0.00000000"],["79906.71000000","0.05697000"],["79906.72000000","0.06204000"],["79906.73000000","0.00007000"],["79907.63000000","0.00800000"],["79907.78000000","0.00000000"],["79908.33000000","0.00000000"],["79908.89000000","0.00000000"],["79909.15000000","0.05672000"],["79912.99000000","0.05590000"],["79914.64000000","0.06204000"],["79915.49000000","0.00400000"],["79915.57000000","0.00800000"],["79925.53000000","0.28706000"],["79946.46000000","0.00000000"],["79948.52000000","0.00400000"],["79948.80000000","0.00000000"],["80124.42000000","0.00400000"]]}}}
{"rx_ns": 13875516266000, "frame": {"stream":"btcusdt@depth@100ms","data":{"e":"depthUpdate","E":1787650870714,"s":"BTCUSDT","U":99118595352,"u":99118596103,"b":[["79902.72000000","4.07667000"],["79902.71000000","0.00027000"],["79902.70000000","0.00013000"],["79902.45000000","0.00007000"],["79902.44000000","0.04124000"],["79902.43000000","0.00028000"],["79902.42000000","0.09089000"],["79902.03000000","0.00000000"],["79902.01000000","0.00000000"],["79902.00000000","0.00000000"],["79901.99000000","0.00014000"],["79901.98000000","0.20257000"],["79901.82000000","0.00000000"],["79901.81000000","0.00000000"],["79901.74000000","0.00000000"],["79901.36000000","0.00183000"],["79901.21000000","0.00000000"],["79901.20000000","0.00000000"],["79900.98000000","0.00000000"],["79900.83000000","0.00000000"],["79900.64000000","0.12053000"],["79900.60000000","0.00000000"],["79900.59000000","0.00000000"],["79900.45000000","0.00007000"],["79900.44000000","0.03231000"],["79900.12000000","0.00007000"],["79900.11000000","0.05341000"],["79900.02000000","0.00014000"],["79900.01000000","0.75008000"],["79900.00000000","2.02489000"],["79899.99000000","0.72566000"],["79899.98000000","0.00000000"],["79899.97000000","0.00000000"],["79899.31000000","0.00000000"],["79899.30000000","0.00021000"],["79899.21000000","0.00711000"],["79898.87000000","0.00625000"],["79898.72000000","0.00000000"],["79898.26000000","0.00000000"],["79898.25000000","0.01678000"],["79897.44000000","0.00000000"],["79897.39000000","0.00000000"],["79897.38000000","0.00014000"],["79896.16000000","0.00000000"],["79896.15000000","0.02425000"],["79896.00000000","0.00007000"],["79895.99000000","0.00696000"],["79895.73000000","0.12523000"],["79894.73000000","0.00008000"],["79894.43000000","0.00250000"],["79894.20000000","0.02259000"],["79894.07000000","0.01600000"],["79894.06000000","0.00000000"],["79894.05000000","0.00007000"],["79894.01000000","0.00000000"],["79894.00000000","1.43778000"],["79893.99000000","2.02167000"],["79893.54000000","0.00010000"],["79893.09000000","0.00007000"],["79893.08000000","0.00007000"],["79892.92000000","0.08576000"],["79892.01000000","0.00000000"],["79892.00000000","1.12448000"],["79891.99000000","2.22076000"],["79891.43000000","0.00000000"],["79891.20000000","0.00007000"],["79890.53000000","0.00000000"],["79890.01000000","0.00007000"],["79890.00000000","0.68909000"],["79889.99000000","0.34756000"],["79889.73000000","0.00000000"],["79889.53000000","0.00000000"],["79889.23000000","0.46725000"],["79888.47000000","0.00000000"],["79884.95000000","0.25398000"],["79884.77000000","0.00000000"],["79884.30000000","0.09463000"],["79884.02000000","0.00007000"],["79883.49000000","0.00000000"],["79882.30000000","0.10367000"],["79882.07000000","0.20567000"],["79882.02000000","0.00625000"],["79880.58000000","0.00000000"],["79878.21000000","0.00000000"],["79877.39000000","0.00000000"],["79876.63000000","0.00000000"],["79876.32000000","0.00000000"],["79875.39000000","0.00000000"],["79869.45000000","0.00000000"],["79867.88000000","0.33813000"],["79862.22000000","0.64119000"],["79861.32000000","0.00000000"],["79850.02000000","0.00007000"],["79823.80000000","0.00000000"],["79822.82000000","0.00008000"],["79812.10000000","0.00000000"],["79765.44000000","0.00000000"],["79757.45000000","0.00000000"],["79743.09000000","0.00000000"],["79742.91000000","0.00008000"],["79733.94000000","0.00000000"],["79732.21000000","0.00000000"],["79663.01000000","0.00008000"],["79652.31000000","0.00000000"],["79644.32000000","0.00000000"],["79583.11000000","0.00008000"],["79572.42000000","0.00000000"],["79528.77000000","0.00250000"],["79503.21000000","0.00008000"],["79492.53000000","0.00000000"],["79423.30000000","0.00008000"],["79412.64000000","0.00000000"],["79343.40000000","0.00008000"],["79332.75000000","0.00000000"],["79263.50000000","0.00008000"],["79252.85000000","0.00000000"],["78701.49000000","0.00000000"],["71912.45000000","0.00016000"],["71910.00000000","0.13906000"],["63919.99000000","0.00000000"]],"a":[["79900.00000000","0.00000000"],["79900.01000000","0.00000000"],["79900.02000000","0.00000000"],["79900.60000000","0.00000000"],["79900.61000000","0.00000000"],["79900.84000000","0.00000000"],["79900.99000000","0.00000000"],["79901.21000000","0.00000000"],["79901.22000000","0.00000000"],["79901.75000000","0.00000000"],["79901.82000000","0.00000000"],["79901.83000000","0.00000000"],["79901.99000000","0.00000000"],["79902.00000000","0.00000000"],["79902.02000000","0.00000000"],["79902.04000000","0.00000000"],["79902.42000000","0.00000000"],["79902.43000000","0.00000000"],["79902.44000000","0.00000000"],["79902.72000000","0.00000000"],["79902.73000000","0.58572000"],["79902.74000000","0.00049000"],["79902.96000000","0.00000000"],["79902.97000000","0.00021000"],["79902.98000000","0.00021000"],["79903.41000000","0.00007000"],["79903.64000000","0.00014000"],["79903.65000000","0.00000000"],["79903.66000000","0.00014000"],["79903.89000000","0.00007000"],["79903.99000000","0.00007000"],["79904.01000000","0.00695000"],["79904.10000000","0.00000000"],["79904.26000000","0.00007000"],["79904.27000000","0.00021000"],["79904.35000000","0.00007000"],["79904.36000000","0.00014000"],["79904.87000000","0.00000000"],["79904.88000000","0.00014000"],["79905.07000000","0.00000000"],["79905.17000000","0.05553000"],["79905.29000000","0.01145000"],["79905.31000000","0.00000000"],["79905.33000000","0.00000000"],["79905.40000000","0.00000000"],["79905.41000000","0.00000000"],["79905.47000000","0.00000000"],["79905.48000000","0.12238000"],["79905.49000000","0.06210000"],["79905.70000000","0.00007000"],["79905.71000000","0.04679000"],["79905.74000000","0.00000000"],["79905.75000000","0.00000000"],["79905.98000000","0.00000000"],["79905.99000000","0.00007000"],["79906.09000000","0.00007000"],["79906.10000000","0.06158000"],["79906.13000000","0.00000000"],["79906.56000000","0.00000000"],["79906.57000000","0.01356000"],["79906.70000000","0.00007000"],["79906.71000000","0.05704000"],["79906.72000000","0.06218000"],["79906.73000000","0.00000000"],["79907.60000000","0.00007000"],["79907.61000000","0.06204000"],["79907.62000000","0.00000000"],["79907.63000000","0.00807000"],["79907.85000000","0.01356000"],["79907.91000000","0.19955000"],["79907.92000000","0.00000000"],["79907.93000000","0.00000000"],["79907.95000000","0.00000000"],["79907.96000000","0.00000000"],["79907.99000000","0.20250000"],["79908.53000000","0.00000000"],["79908.79000000","0.00000000"],["79909.13000000","0.00091000"],["79909.15000000","0.00000000"],["79909.72000000","0.00007000"],["79909.76000000","0.00000000"],["79909.99000000","0.00000000"],["79910.01000000","0.00258000"],["79910.82000000","0.00000000"],["79910.98000000","0.00000000"],["79911.59000000","0.00000000"],["79911.70000000","0.00000000"],["79911.99000000","0.82425000"],["79912.39000000","0.00000000"],["79912.81000000","0.00000000"],["79912.85000000","1.87677000"],["79912.98000000","1.04939000"],["79912.99000000","0.00000000"],["79913.04000000","0.00000000"],["79913.14000000","0.00000000"],["79913.27000000","0.00000000"],["79913.28000000","0.00000000"],["79913.44000000","0.00000000"],["79913.45000000","0.00400000"],["79913.66000000","0.00000000"],["79913.99000000","0.00007000"],["79914.64000000","0.00000000"],["79914.67000000","0.00007000"],["79915.25000000","0.00000000"],["79915.49000000","0.00000000"],["79915.57000000","0.00000000"],["79915.58000000","0.00000000"],["79916.46000000","0.00400000"],["79916.47000000","0.00000000"],["79916.74000000","0.00000000"],["79916.75000000","0.01200000"],["79916.76000000","0.00000000"],["79919.97000000","0.00000000"],["79921.10000000","0.09459000"],["79923.09000000","0.10362000"],["79923.28000000","0.00000000"],["79924.86000000","0.19019000"],["79925.51000000","0.55728000"],["79925.52000000","0.50716000"],["79925.53000000","0.00000000"],["79925.97000000","0.00000000"],["79928.12000000","0.62594000"],["79930.71000000","0.00000000"],["79935.96000000","0.34694000"],["79936.86000000","0.00000000"],["79937.10000000","0.00000000"],["79940.00000000","0.24302000"],["79942.59000000","0.00014000"],["79943.00000000","0.01000000"],["79943.83000000","1.42277000"],["79945.84000000","1.23862000"],["79946.19000000","0.00000000"],["79950.71000000","0.00000000"],["79973.64000000","1.04939000"],["79974.48000000","0.00000000"],["79981.55000000","0.00010000"],["80044.53000000","0.08419000"],["80055.48000000","0.00000000"],["80128.17000000","0.00007000"],["80140.14000000","0.00021000"],["80402.58000000","0.00250000"],["81098.50000000","0.00000000"]]}}}
{"rx_ns": 13875604214500, "frame": {"stream":"btcusdt@depth@100ms","data":{"e":"depthUpdate","E":1787650870814,"s":"BTCUSDT","U":99118596104,"u":99118596382,"b":[["79902.72000000","4.07879000"],["79902.44000000","0.04138000"],["79902.43000000","0.00014000"],["79902.42000000","0.09089000"],["79901.99000000","0.00007000"],["79901.98000000","0.20278000"],["79900.65000000","0.00007000"],["79900.64000000","0.12067000"],["79900.44000000","0.03245000"],["79900.11000000","0.05362000"],["79900.02000000","0.00021000"],["79900.01000000","0.75022000"],["79900.00000000","1.56556000"],["79899.99000000","0.71329000"],["79899.30000000","0.00007000"],["79898.71000000","0.00000000"],["79898.25000000","0.00000000"],["79898.24000000","0.00000000"],["79897.43000000","0.00000000"],["79896.15000000","0.00021000"],["79893.99000000","2.02153000"],["79892.45000000","0.16283000"],["79887.50000000","0.00007000"],["79886.58000000","0.46895000"],["79862.00000000","0.03400000"],["79860.00000000","0.11792000"],["79819.44000000","0.04455000"],["79771.26000000","0.00007000"],["79628.99000000","0.03134000"],["71912.45000000","0.00032000"]],"a":[["79902.73000000","0.25875000"],["79902.74000000","0.00049000"],["79902.97000000","0.00000000"],["79902.98000000","0.00000000"],["79903.64000000","0.00007000"],["79903.66000000","0.00000000"],["79904.01000000","0.00021000"],["79904.27000000","0.00000000"],["79904.36000000","0.00007000"],["79904.88000000","0.00000000"],["79905.16000000","0.00007000"],["79905.17000000","0.05567000"],["79905.29000000","0.00028000"],["79905.47000000","0.00007000"],["79905.48000000","0.12252000"],["79905.49000000","0.06224000"],["79905.71000000","0.04700000"],["79906.00000000","0.02414000"],["79906.09000000","0.00007000"],["79906.57000000","0.00007000"],["79906.70000000","0.00007000"],["79906.71000000","0.05704000"],["79907.60000000","0.00000000"],["79907.85000000","0.00007000"],["79907.91000000","0.06211000"],["79907.98000000","0.20705000"],["79909.13000000","0.00000000"],["79909.26000000","0.00931000"],["79909.44000000","0.05632000"],["79909.99000000","0.06204000"],["79910.66000000","0.06204000"],["79911.06000000","0.00110000"],["79911.27000000","0.06204000"],["79911.88000000","0.06204000"],["79911.98000000","0.07411000"],["79911.99000000","0.71440000"],["79912.85000000","0.00000000"],["79912.97000000","1.87677000"],["79912.98000000","0.00000000"],["79913.45000000","0.00000000"],["79913.50000000","0.00000000"],["79913.54000000","0.00400000"],["79913.57000000","0.00000000"],["79913.60000000","0.00000000"],["79913.63000000","0.00000000"],["79914.80000000","0.02000000"],["79915.54000000","0.02000000"],["79916.46000000","0.00000000"],["79916.75000000","0.00000000"],["79919.47000000","0.00007000"],["79921.99000000","0.00000000"],["79924.85000000","0.00625000"],["79925.51000000","0.37044000"],["79928.13000000","0.59670000"],["79969.52000000","0.02000000"],["79970.33000000","0.02000000"],["79972.55000000","0.00400000"],["80010.94000000","0.00000000"],["80011.34000000","0.00556000"],["80140.14000000","0.00014000"]]}}}
{"rx_ns": 13875696138500, "frame": {"stream":"btcusdt@depth@100ms","data":{"e":"depthUpdate","E":1787650870914,"s":"BTCUSDT","U":99118596383,"u":99118596445,"b":[["79902.72000000","4.09081000"],["79902.42000000","0.09089000"],["79901.99000000","0.00000000"],["79901.98000000","0.00028000"],["79901.45000000","0.00007000"],["79901.44000000","0.02003000"],["79900.44000000","0.03252000"],["79900.17000000","0.00007000"],["79900.16000000","0.02404000"],["79900.01000000","0.51050000"],["79900.00000000","1.56549000"],["79899.99000000","0.51079000"],["79899.21000000","0.00718000"],["79898.88000000","0.02404000"],["79896.11000000","0.00153000"],["79887.99000000","0.14084000"],["79886.74000000","0.00007000"],["79874.01000000","0.00000000"],["79845.93000000","0.00000000"],["79765.43000000","0.20250000"],["79763.46000000","0.04532000"],["71912.45000000","0.00064000"]],"a":[["79903.95000000","0.06204000"],["79904.00000000","0.02435000"],["79904.01000000","0.00007000"],["79904.56000000","0.06204000"],["79905.17000000","0.05567000"],["79905.29000000","0.00014000"],["79906.10000000","0.06172000"],["79906.71000000","0.05718000"],["79906.72000000","0.06225000"],["79906.74000000","0.00674000"],["79908.02000000","0.01124000"],["79909.30000000","0.01349000"],["79909.72000000","0.00000000"],["79910.58000000","0.01349000"],["79911.98000000","0.06211000"],["79912.46000000","0.00013000"],["79913.54000000","0.00000000"],["79914.96000000","0.00400000"],["79916.76000000","0.00400000"],["79923.12000000","0.00000000"],["79924.24000000","0.00000000"],["79969.52000000","0.00000000"],["79970.33000000","0.00000000"],["80003.12000000","0.02804000"]]}}}
{"rx_ns": 13875808506400, "frame": {"stream":"btcusdt@depth20","data":{"lastUpdateId":99118596578,"bids":[["79902.72000000","4.12433000"],["79902.71000000","0.00027000"],["79902.70000000","0.00013000"],["79902.45000000","0.00007000"],["79902.44000000","0.04138000"],["79902.43000000","0.00014000"],["79902.42000000","0.09089000"],["79901.98000000","0.00014000"],["79901.45000000","0.00007000"],["79901.44000000","0.02017000"],["79901.36000000","0.00183000"],["79900.64000000","0.00014000"],["79900.45000000","0.00007000"],["79900.44000000","0.03245000"],["79900.17000000","0.00007000"],["79900.16000000","0.02411000"],["79900.12000000","0.00007000"],["79900.11000000","0.05362000"],["79900.02000000","0.00021000"],["79900.01000000","0.51050000"]],"asks":[["79902.73000000","0.60200000"],["79902.74000000","0.00049000"],["79903.41000000","0.00007000"],["79903.64000000","0.00007000"],["79903.75000000","0.00007000"],["79903.76000000","0.00007000"],["79903.89000000","0.00007000"],["79903.94000000","0.00007000"],["79903.95000000","0.06218000"],["79903.99000000","0.00007000"],["79904.00000000","0.02442000"],["79904.01000000","0.00007000"],["79904.26000000","0.00007000"],["79904.35000000","0.00007000"],["79904.36000000","0.00007000"],["79904.55000000","0.00007000"],["79904.56000000","0.06218000"],["79904.72000000","0.00007000"],["79905.15000000","0.00007000"],["79905.16000000","0.18443000"]]}}}
{"rx_ns": 13875808629900, "frame": {"stream":"btcusdt@depth@100ms","data":{"e":"depthUpdate","E":1787650871014,"s":"BTCUSDT","U":99118596446,"u":99118596578,"b":[["79902.72000000","4.12433000"],["79902.42000000","0.09089000"],["79901.98000000","0.00014000"],["79901.44000000","0.02017000"],["79900.65000000","0.00000000"],["79900.64000000","0.00014000"],["79900.44000000","0.03245000"],["79900.16000000","0.02411000"],["79900.12000000","0.00007000"],["79900.02000000","0.00021000"],["79900.01000000","0.51050000"],["79900.00000000","1.52229000"],["79899.99000000","0.51093000"],["79899.77000000","0.12053000"],["79899.35000000","0.00400000"],["79899.22000000","0.01389000"],["79894.00000000","1.44278000"],["79892.00000000","1.12948000"],["79890.00000000","0.69409000"],["79888.00000000","0.00507000"],["79886.00000000","0.10959000"],["79851.14000000","0.00100000"],["79848.65000000","0.00012000"],["79793.97000000","0.00400000"],["79347.62000000","0.02105000"],["71912.45000000","0.00080000"],["63922.18000000","0.00056000"]],"a":[["79902.73000000","0.60200000"],["79903.94000000","0.00007000"],["79903.95000000","0.06218000"],["79904.00000000","0.02442000"],["79904.55000000","0.00007000"],["79904.56000000","0.06218000"],["79905.15000000","0.00007000"],["79905.16000000","0.18443000"],["79905.47000000","0.00000000"],["79905.48000000","0.00021000"],["79905.70000000","0.00007000"],["79905.99000000","0.00007000"],["79906.09000000","0.00007000"],["79906.10000000","0.06158000"],["79906.70000000","0.00000000"],["79906.71000000","0.05697000"],["79907.66000000","0.15391000"],["79909.44000000","0.00000000"],["79910.66000000","0.00000000"],["79911.26000000","0.00000000"],["79911.77000000","0.00012000"],["79911.98000000","0.00007000"],["79912.46000000","0.00000000"],["79913.00000000","0.05000000"],["79913.09000000","0.00400000"],["79913.74000000","0.00000000"],["79913.78000000","0.00000000"],["79913.94000000","0.00000000"],["79914.96000000","0.00000000"],["79915.51000000","0.02000000"],["79915.58000000","0.02000000"],["79916.76000000","0.19419000"],["79923.39000000","0.00000000"],["79924.86000000","0.00000000"],["79925.85000000","0.00012000"],["79970.26000000","0.02000000"],["79970.32000000","0.02000000"],["80297.93000000","0.00100000"]]}}}
{"rx_ns": 13875896053000, "frame": {"stream":"btcusdt@depth@100ms","data":{"e":"depthUpdate","E":1787650871114,"s":"BTCUSDT","U":99118596579,"u":99118596633,"b":[["79902.72000000","4.12501000"],["79901.98000000","0.00007000"],["79901.44000000","0.02017000"],["79900.64000000","0.00000000"],["79900.44000000","0.03252000"],["79900.00000000","1.52236000"],["79899.77000000","0.00000000"],["79899.26000000","0.12053000"],["79897.87000000","0.00007000"],["79896.73000000","0.00013000"],["79895.80000000","0.00007000"],["79894.00000000","1.45478000"],["79892.00000000","1.14148000"],["79890.00000000","0.70609000"],["79888.00000000","0.01707000"],["79886.00000000","0.12159000"],["79884.00000000","0.01700000"],["79824.00000000","0.02400000"],["71912.45000000","0.00096000"]],"a":[["79902.73000000","0.60050000"],["79904.00000000","0.02435000"],["79904.56000000","0.06225000"],["79905.16000000","0.18457000"],["79905.17000000","0.05560000"],["79905.48000000","0.00007000"],["79908.72000000","0.00013000"],["79911.06000000","0.00000000"],["79911.97000000","0.00115000"],["79911.99000000","0.99099000"],["79912.96000000","1.04939000"],["79916.75000000","0.00000000"],["79916.76000000","0.00400000"],["79924.33000000","0.00000000"],["79924.34000000","0.00000000"],["79924.86000000","0.19019000"],["79970.26000000","0.00000000"],["81101.28000000","0.00074000"]]}}}
{"rx_ns": 13876001094700, "frame": {"stream":"btcusdt@depth@100ms","data":{"e":"depthUpdate","E":1787650871214,"s":"BTCUSDT","U":99118596634,"u":99118596689,"b":[["79902.72000000","4.12510000"],["79901.25000000","0.00007000"],["79900.02000000","0.00021000"],["79900.01000000","0.51050000"],["79900.00000000","1.52236000"],["79899.99000000","0.51084000"],["79899.27000000","0.04995000"],["79899.22000000","0.00000000"],["79898.86000000","0.00000000"],["79898.06000000","0.00000000"],["79894.72000000","0.00009000"],["79892.00000000","1.14139000"],["79885.01000000","0.31163000"],["79832.83000000","0.02086000"],["79802.06000000","0.00025000"],["79799.33000000","0.00000000"],["79793.97000000","0.00000000"],["71912.45000000","0.00112000"],["63922.18000000","0.00025000"]],"a":[["79902.73000000","0.60036000"],["79903.64000000","0.00000000"],["79905.15000000","0.00000000"],["79905.16000000","0.00021000"],["79905.24000000","0.00014000"],["79906.70000000","0.00007000"],["79907.63000000","0.00814000"],["79907.91000000","0.06204000"],["79907.98000000","0.00000000"],["79909.44000000","0.06204000"],["79910.66000000","0.06204000"],["79911.97000000","0.06319000"],["79911.98000000","0.00407000"],["79912.47000000","0.00000000"],["79912.95000000","0.19019000"],["79916.76000000","0.00000000"],["79924.86000000","0.00000000"],["79925.52000000","0.00000000"],["79928.12000000","0.00000000"],["79932.58000000","0.00000000"],["79932.80000000","0.00000000"],["79937.03000000","0.09264000"],["79972.55000000","0.00000000"],["79999.08000000","0.00000000"],["80001.81000000","0.00025000"],["80004.52000000","0.00000000"],["80052.48000000","0.00000000"],["80124.42000000","0.00000000"]]}}}
{"rx_ns": 13876101570100, "frame": {"stream":"btcusdt@depth@100ms","data":{"e":"depthUpdate","E":1787650871314,"s":"BTCUSDT","U":99118596690,"u":99118597333,"b":[["79903.99000000","4.38428000"],["79903.98000000","0.08514000"],["79903.97000000","0.00013000"],["79903.94000000","3.02094000"],["79903.93000000","0.00007000"],["79903.89000000","0.00014000"],["79903.88000000","0.00007000"],["79903.75000000","0.00007000"],["79903.74000000","0.00007000"],["79903.40000000","0.00000000"],["79902.77000000","0.00000000"],["79902.74000000","0.00000000"],["79902.73000000","0.18891000"],["79902.72000000","1.22056000"],["79902.71000000","0.00000000"],["79902.70000000","0.05000000"],["79902.65000000","0.05000000"],["79902.45000000","0.00000000"],["79902.43000000","0.00007000"],["79902.42000000","0.00035000"],["79901.47000000","0.00700000"],["79901.45000000","0.00000000"],["79901.38000000","0.05334000"],["79901.12000000","0.00026000"],["79900.83000000","0.00400000"],["79900.50000000","0.03000000"],["79900.45000000","0.00000000"],["79900.18000000","0.00000000"],["79900.17000000","1.87677000"],["79900.16000000","0.02418000"],["79900.12000000","0.36586000"],["79900.11000000","0.00028000"],["79900.02000000","0.00014000"],["79900.01000000","0.00000000"],["79900.00000000","1.12439000"],["79899.99000000","0.51077000"],["79899.35000000","0.00000000"],["79899.26000000","0.00000000"],["79898.87000000","0.00000000"],["79898.32000000","0.00400000"],["79897.38000000","0.00007000"],["79896.74000000","0.00000000"],["79895.73000000","0.00000000"],["79894.80000000","0.08576000"],["79894.41000000","0.37558000"],["79894.20000000","0.02252000"],["79894.07000000","0.00000000"],["79894.05000000","0.00000000"],["79893.99000000","2.01515000"],["79892.92000000","0.00000000"],["79892.47000000","0.00007000"],["79892.42000000","0.00000000"],["79892.01000000","0.62629000"],["79892.00000000","1.06639000"],["79891.99000000","0.31399000"],["79891.20000000","0.00000000"],["79890.00000000","1.25129000"],["79889.35000000","0.12517000"],["79888.42000000","0.00625000"],["79888.01000000","1.87677000"],["79886.60000000","0.76849000"],["79886.59000000","0.62589000"],["79886.58000000","0.00000000"],["79885.80000000","0.33806000"],["79884.95000000","0.00000000"],["79884.94000000","0.00000000"],["79882.07000000","0.17745000"],["79882.02000000","0.00000000"],["79880.01000000","0.00007000"],["79877.85000000","0.00000000"],["79877.19000000","0.09175000"],["79874.81000000","0.00000000"],["79874.77000000","0.50958000"],["79870.67000000","0.34804000"],["79870.21000000","0.00000000"],["79870.00000000","0.11791000"],["79867.88000000","0.00000000"],["79867.65000000","0.00000000"],["79862.99000000","0.00000000"],["79859.52000000","0.00000000"],["79858.13000000","0.00000000"],["79855.26000000","0.00335000"],["79854.03000000","0.00000000"],["79853.65000000","0.00000000"],["79840.12000000","0.00000000"],["79839.76000000","0.00000000"],["79837.70000000","3.39880000"],["79837.65000000","0.00000000"],["79833.57000000","2.32135000"],["79832.83000000","0.00000000"],["79831.70000000","0.00000000"],["79827.85000000","0.00000000"],["79822.60000000","3.75921000"],["79819.43000000","0.00000000"],["79811.34000000","0.00000000"],["79804.56000000","0.00000000"],["79800.43000000","0.00000000"],["79752.28000000","0.00202000"],["79704.74000000","0.00000000"],["79553.96000000","0.00000000"],["78705.43000000","0.00030000"],["71912.45000000","0.00008000"],["71912.00000000","0.00020000"],["63922.00000000","0.01030000"]],"a":[["79902.73000000","0.00000000"],["79902.74000000","0.00000000"],["79903.41000000","0.00000000"],["79903.75000000","0.00000000"],["79903.76000000","0.00000000"],["79903.89000000","0.00000000"],["79903.94000000","0.00000000"],["79903.95000000","0.00000000"],["79903.99000000","0.00000000"],["79904.00000000","0.02540000"],["79904.01000000","0.00069000"],["79904.02000000","0.00013000"],["79904.55000000","0.00000000"],["79904.56000000","0.00021000"],["79905.16000000","0.00000000"],["79905.17000000","0.00014000"],["79905.36000000","0.00000000"],["79905.48000000","0.00000000"],["79905.49000000","0.00028000"],["79905.71000000","0.00021000"],["79905.99000000","0.00007000"],["79906.09000000","0.00000000"],["79906.10000000","0.00021000"],["79906.70000000","0.00000000"],["79906.71000000","0.00021000"],["79906.72000000","0.00028000"],["79906.98000000","0.04679000"],["79907.52000000","0.00000000"],["79907.59000000","0.00000000"],["79907.61000000","0.00000000"],["79907.63000000","0.00007000"],["79907.66000000","0.00000000"],["79907.76000000","0.00007000"],["79907.85000000","0.00000000"],["79907.91000000","0.00007000"],["79907.99000000","0.00007000"],["79908.00000000","0.02407000"],["79908.02000000","0.01131000"],["79908.27000000","0.00000000"],["79908.68000000","0.00000000"],["79908.70000000","0.00007000"],["79908.71000000","0.00007000"],["79908.83000000","0.00000000"],["79908.95000000","0.00000000"],["79908.96000000","0.00000000"],["79909.14000000","0.00000000"],["79909.26000000","0.00000000"],["79909.30000000","0.01356000"],["79909.44000000","0.00000000"],["79909.99000000","0.00000000"],["79910.00000000","0.02400000"],["79910.29000000","0.00000000"],["79910.66000000","0.00000000"],["79911.07000000","0.00000000"],["79911.27000000","0.00000000"],["79911.63000000","0.00007000"],["79911.77000000","0.00000000"],["79911.78000000","0.00000000"],["79911.88000000","0.00000000"],["79911.97000000","0.00000000"],["79911.98000000","0.00007000"],["79911.99000000","0.20928000"],["79912.66000000","0.00000000"],["79912.67000000","0.00000000"],["79912.94000000","0.00000000"],["79912.95000000","0.00000000"],["79912.96000000","0.00000000"],["79912.97000000","0.00000000"],["79912.99000000","0.05725000"],["79913.09000000","0.00000000"],["79913.77000000","0.00000000"],["79914.03000000","0.12513000"],["79914.12000000","0.00000000"],["79914.23000000","0.00000000"],["79914.42000000","0.00000000"],["79914.47000000","0.00000000"],["79914.50000000","0.00000000"],["79914.53000000","0.00000000"],["79914.54000000","0.00000000"],["79915.03000000","0.42254000"],["79915.07000000","0.00000000"],["79915.19000000","0.00902000"],["79915.50000000","0.06218000"],["79915.59000000","0.00000000"],["79915.62000000","0.00000000"],["79915.63000000","0.00000000"],["79915.79000000","0.00007000"],["79915.93000000","0.00000000"],["79916.03000000","0.00000000"],["79916.15000000","0.06204000"],["79916.38000000","0.00693000"],["79916.76000000","0.06341000"],["79916.77000000","0.08485000"],["79916.80000000","0.00157000"],["79916.84000000","0.00000000"],["79916.94000000","0.00000000"],["79917.74000000","0.00000000"],["79917.87000000","0.00007000"],["79917.88000000","0.00000000"],["79917.89000000","0.00000000"],["79918.33000000","0.00000000"],["79919.06000000","0.00625000"],["79919.13000000","0.00000000"],["79919.67000000","0.00000000"],["79919.82000000","0.00000000"],["79920.00000000","1.02767000"],["79920.14000000","0.02000000"],["79920.31000000","0.00000000"],["79921.31000000","0.00000000"],["79922.37000000","0.00000000"],["79923.03000000","0.00000000"],["79923.49000000","0.00000000"],["79924.85000000","0.00000000"],["79925.50000000","0.00000000"],["79925.51000000","0.21909000"],["79925.97000000","0.00000000"],["79926.73000000","0.00000000"],["79926.77000000","0.00000000"],["79926.94000000","0.00000000"],["79927.31000000","0.19019000"],["79928.12000000","0.00000000"],["79928.69000000","0.00000000"],["79929.01000000","0.00000000"],["79930.71000000","0.00625000"],["79930.72000000","0.28170000"],["79930.73000000","0.00000000"],["79931.05000000","0.36586000"],["79933.28000000","0.00000000"],["79933.96000000","0.62589000"],["79933.97000000","0.42935000"],["79935.96000000","0.22640000"],["79935.97000000","0.00000000"],["79936.88000000","0.00000000"],["79937.03000000","0.00000000"],["79938.28000000","0.00000000"],["79939.95000000","0.02479000"],["79940.00000000","0.33685000"],["79940.34000000","0.00190000"],["79940.63000000","0.00000000"],["79942.53000000","0.09607000"],["79943.00000000","0.00000000"],["79943.95000000","0.00008000"],["79944.00000000","0.03400000"],["79944.06000000","0.33781000"],["79945.29000000","0.00000000"],["79945.36000000","0.62557000"],["79945.84000000","0.00000000"],["79946.46000000","0.00007000"],["79948.89000000","0.04450000"],["79949.41000000","0.00000000"],["79949.86000000","0.00000000"],["79950.33000000","0.04007000"],["79951.03000000","0.00400000"],["79953.54000000","0.00400000"],["79956.79000000","0.00000000"],["79975.99000000","0.38293000"],["79978.25000000","1.23812000"],["79983.79000000","0.00000000"],["79983.80000000","0.00000000"],["79985.97000000","0.04349000"],["79987.63000000","0.00000000"],["79993.80000000","0.00000000"],["79994.13000000","0.00000000"],["79994.90000000","0.00000000"],["79996.51000000","0.12172000"],["79997.52000000","0.00000000"],["80012.85000000","0.80000000"],["80037.01000000","0.00000000"],["80064.82000000","0.00202000"],["80106.32000000","3.74590000"],["80134.65000000","0.11607000"],["80173.72000000","0.00000000"],["80185.26000000","0.00029000"],["80287.66000000","0.00000000"],["81101.28000000","0.00044000"]]}}}
{"rx_ns": 13876205541000, "frame": {"stream":"btcusdt@depth@100ms","data":{"e":"depthUpdate","E":1787650871414,"s":"BTCUSDT","U":99118597334,"u":99118597752,"b":[["79903.99000000","6.58567000"],["79903.98000000","0.08535000"],["79903.95000000","0.05000000"],["79903.94000000","1.59210000"],["79903.93000000","0.00000000"],["79903.90000000","0.05000000"],["79903.88000000","0.00000000"],["79903.75000000","0.00000000"],["79903.74000000","0.00000000"],["79903.50000000","0.00000000"],["79903.34000000","0.00400000"],["79902.73000000","0.18912000"],["79902.72000000","1.20113000"],["79902.70000000","0.00021000"],["79902.65000000","0.00014000"],["79902.44000000","0.04138000"],["79902.42000000","0.00021000"],["79901.47000000","0.00707000"],["79901.44000000","0.00007000"],["79901.38000000","0.05334000"],["79901.07000000","0.00008000"],["79900.50000000","0.00000000"],["79900.44000000","0.03238000"],["79900.18000000","0.36586000"],["79900.16000000","0.00000000"],["79900.12000000","0.00000000"],["79900.11000000","0.00007000"],["79899.99000000","0.51063000"],["79899.27000000","0.00000000"],["79899.21000000","0.00704000"],["79898.88000000","0.00000000"],["79896.11000000","0.00000000"],["79895.99000000","0.00689000"],["79895.67000000","0.08576000"],["79894.80000000","0.00000000"],["79894.19000000","0.33802000"],["79894.00000000","1.46178000"],["79892.00000000","1.07339000"],["79891.99000000","0.19399000"],["79890.10000000","0.00189000"],["79890.00000000","1.35217000"],["79887.99000000","0.13381000"],["79881.94000000","0.05280000"],["79879.44000000","0.35797000"],["79878.20000000","0.00000000"],["79876.61000000","0.00000000"],["79876.44000000","0.00000000"],["79875.60000000","0.00000000"],["79873.97000000","0.00000000"],["79873.78000000","0.00000000"],["79872.14000000","0.00000000"],["79864.96000000","0.00000000"],["79863.00000000","0.01000000"],["79862.00000000","0.02400000"],["79860.00000000","0.02400000"],["79857.77000000","0.00619000"],["79853.21000000","0.00429000"],["79851.98000000","0.00429000"],["79846.86000000","0.00000000"],["79843.28000000","0.00000000"],["79841.21000000","0.00540000"],["79839.47000000","0.00111000"],["79837.69000000","0.00000000"],["79836.46000000","0.00000000"],["79823.96000000","0.00000000"],["79821.96000000","0.00000000"],["79820.37000000","0.00008000"],["79803.04000000","0.00000000"],["79790.57000000","0.00000000"],["79764.09000000","0.09365000"],["79763.46000000","0.00000000"],["79763.43000000","0.04532000"],["79752.28000000","0.00000000"],["79730.34000000","0.00000000"],["79576.97000000","0.00000000"],["71912.00000000","0.00000000"]],"a":[["79904.00000000","0.02536000"],["79904.01000000","0.00069000"],["79904.56000000","0.00000000"],["79905.17000000","0.00000000"],["79905.29000000","0.00007000"],["79905.49000000","0.00014000"],["79905.70000000","0.00000000"],["79905.71000000","0.00007000"],["79906.00000000","0.02414000"],["79906.10000000","0.00007000"],["79906.71000000","0.00007000"],["79906.72000000","0.00007000"],["79906.74000000","0.00021000"],["79906.97000000","0.00007000"],["79906.98000000","0.04693000"],["79907.26000000","0.00000000"],["79907.63000000","0.00000000"],["79908.00000000","0.02421000"],["79908.02000000","0.00021000"],["79908.70000000","0.00000000"],["79909.29000000","0.00000000"],["79909.30000000","0.00021000"],["79909.90000000","0.00000000"],["79909.91000000","0.00021000"],["79909.99000000","0.00007000"],["79910.00000000","0.02421000"],["79910.01000000","0.00008000"],["79910.58000000","0.00000000"],["79910.70000000","0.00007000"],["79910.71000000","0.05625000"],["79911.31000000","0.00007000"],["79911.32000000","0.06204000"],["79911.92000000","0.00007000"],["79911.93000000","0.06204000"],["79911.97000000","0.00007000"],["79911.98000000","0.06211000"],["79911.99000000","0.00007000"],["79912.00000000","0.02626000"],["79912.97000000","0.00026000"],["79912.98000000","0.25344000"],["79912.99000000","0.05659000"],["79913.76000000","0.06204000"],["79913.99000000","0.06211000"],["79914.24000000","0.00000000"],["79914.80000000","0.00000000"],["79914.98000000","0.06204000"],["79915.03000000","0.00000000"],["79915.19000000","0.00000000"],["79915.38000000","0.00000000"],["79915.50000000","0.06211000"],["79915.51000000","0.00000000"],["79915.54000000","0.00000000"],["79915.58000000","0.00000000"],["79916.32000000","0.00000000"],["79916.38000000","0.00000000"],["79916.46000000","0.00000000"],["79916.76000000","0.06204000"],["79916.78000000","0.00000000"],["79916.80000000","0.00000000"],["79917.42000000","0.06204000"],["79917.86000000","0.00125000"],["79917.99000000","0.06204000"],["79918.00000000","0.03304000"],["79918.63000000","0.00024000"],["79918.64000000","0.06211000"],["79919.06000000","0.00000000"],["79919.07000000","0.00000000"],["79919.25000000","0.06204000"],["79919.37000000","0.00696000"],["79919.86000000","0.06204000"],["79919.98000000","0.06612000"],["79920.14000000","0.00000000"],["79920.26000000","0.00000000"],["79920.75000000","0.00000000"],["79921.01000000","0.00000000"],["79921.21000000","0.00000000"],["79921.29000000","0.00000000"],["79921.47000000","0.00000000"],["79921.53000000","0.00625000"],["79921.54000000","0.00000000"],["79921.96000000","0.00000000"],["79923.24000000","0.00007000"],["79923.28000000","1.04939000"],["79926.22000000","0.00250000"],["79926.29000000","0.02252000"],["79926.35000000","0.02000000"],["79926.99000000","0.15000000"],["79927.11000000","0.00007000"],["79927.30000000","0.00400000"],["79928.12000000","0.00000000"],["79930.72000000","0.00000000"],["79930.98000000","0.00007000"],["79932.80000000","0.00000000"],["79932.81000000","0.00000000"],["79933.96000000","0.00000000"],["79933.97000000","0.00000000"],["79935.68000000","0.50221000"],["79935.95000000","0.54715000"],["79935.96000000","0.53467000"],["79937.10000000","0.62588000"],["79939.07000000","0.64057000"],["79939.95000000","0.00000000"],["79940.90000000","0.42932000"],["79940.91000000","0.00000000"],["79942.00000000","0.02400000"],["79942.53000000","0.00000000"],["79942.63000000","0.00000000"],["79943.30000000","0.00000000"],["79943.50000000","0.00000000"],["79944.77000000","0.00000000"],["79945.20000000","0.09595000"],["79947.99000000","0.12664000"],["79948.54000000","0.00000000"],["79954.20000000","0.00000000"],["79955.43000000","0.33776000"],["79958.24000000","0.00434000"],["79958.56000000","0.00347000"],["79967.46000000","0.00007000"],["79969.13000000","0.00000000"],["79984.95000000","0.01701000"],["79987.28000000","0.00540000"],["79996.51000000","0.00000000"],["79996.59000000","0.36586000"],["79997.16000000","0.00000000"],["79997.34000000","0.00000000"],["79998.65000000","0.00000000"],["79998.98000000","0.00000000"],["79999.63000000","0.00000000"],["79999.91000000","0.00000000"],["79999.96000000","0.00000000"],["79999.98000000","0.11792000"],["80001.52000000","0.25000000"],["80006.35000000","0.00400000"],["80011.34000000","0.00000000"],["80029.13000000","0.00000000"],["80052.51000000","0.06222000"],["80064.82000000","0.00000000"],["80109.16000000","0.00000000"],["80276.14000000","0.20250000"],["80312.29000000","0.00625000"]]}}}
{"rx_ns": 13876303627200, "frame": {"stream":"btcusdt@depth@100ms","data":{"e":"depthUpdate","E":1787650871514,"s":"BTCUSDT","U":99118597753,"u":99118598295,"b":[["79905.99000000","6.57540000"],["79905.98000000","0.00027000"],["79905.97000000","0.00013000"],["79905.95000000","0.05000000"],["79905.90000000","0.05000000"],["79905.85000000","0.00400000"],["79905.70000000","0.00000000"],["79905.48000000","0.00000000"],["79905.38000000","0.00000000"],["79905.28000000","0.00000000"],["79905.23000000","0.21123000"],["79904.77000000","0.00000000"],["79904.71000000","0.00000000"],["79904.55000000","0.00000000"],["79904.35000000","0.00000000"],["79904.34000000","0.00000000"],["79904.25000000","0.00000000"],["79904.16000000","0.00000000"],["79904.01000000","0.77917000"],["79904.00000000","1.12439000"],["79903.99000000","2.42396000"],["79903.98000000","0.00028000"],["79903.97000000","0.00000000"],["79903.95000000","0.00021000"],["79903.94000000","0.24652000"],["79903.90000000","0.00021000"],["79903.39000000","0.05334000"],["79902.73000000","0.18905000"],["79902.72000000","0.54643000"],["79902.71000000","0.02003000"],["79902.70000000","0.00000000"],["79902.65000000","0.00000000"],["79902.42000000","0.00014000"],["79901.47000000","0.00707000"],["79901.44000000","0.00000000"],["79901.43000000","0.02404000"],["79901.38000000","0.00000000"],["79900.19000000","0.36586000"],["79900.18000000","0.49536000"],["79900.17000000","0.00000000"],["79900.15000000","0.02404000"],["79899.21000000","0.00711000"],["79898.09000000","0.36105000"],["79898.08000000","1.20205000"],["79898.00000000","0.00008000"],["79897.99000000","0.20250000"],["79897.46000000","0.08576000"],["79896.96000000","0.00007000"],["79896.73000000","0.00000000"],["79896.29000000","0.00007000"],["79896.01000000","0.00007000"],["79895.67000000","0.00000000"],["79894.73000000","0.00000000"],["79894.47000000","0.00007000"],["79894.00000000","1.38678000"],["79892.47000000","0.00000000"],["79890.01000000","0.00015000"],["79890.00000000","1.35468000"],["79889.74000000","0.09463000"],["79889.38000000","0.04420000"],["79889.35000000","0.00000000"],["79888.00000000","0.02407000"],["79887.75000000","0.10367000"],["79886.69000000","0.00000000"],["79886.01000000","0.00008000"],["79886.00000000","0.12859000"],["79884.30000000","0.00000000"],["79884.01000000","0.00007000"],["79884.00000000","0.02400000"],["79882.30000000","0.00000000"],["79882.02000000","0.00008000"],["79880.02000000","0.00000000"],["79878.02000000","0.00008000"],["79877.56000000","0.00000000"],["79876.02000000","0.00125000"],["79874.03000000","0.00008000"],["79873.98000000","1.67268000"],["79872.03000000","0.30007000"],["79870.03000000","0.00008000"],["79868.03000000","0.00000000"],["79867.20000000","0.00000000"],["79866.77000000","0.83186000"],["79866.04000000","0.00008000"],["79865.19000000","0.00000000"],["79865.05000000","0.00000000"],["79864.04000000","0.00000000"],["79864.00000000","0.03400000"],["79863.00000000","0.00000000"],["79862.23000000","0.57953000"],["79861.20000000","0.00000000"],["79860.04000000","0.00000000"],["79854.10000000","0.82212000"],["79848.65000000","0.00000000"],["79848.26000000","0.00000000"],["79842.76000000","1.18407000"],["79841.73000000","0.00000000"],["79839.73000000","0.00000000"],["79837.71000000","0.38686000"],["79832.07000000","0.00312000"],["79823.52000000","1.99484000"],["79802.34000000","0.00000000"],["79775.19000000","0.00012000"],["79772.80000000","0.00000000"],["79765.82000000","0.00000000"],["79759.47000000","0.00202000"],["79700.91000000","0.00023000"],["79688.21000000","0.00770000"],["79605.22000000","0.00000000"],["79592.51000000","0.00035000"],["75000.00000000","113.37416000"],["71915.40000000","0.00016000"],["71913.60000000","0.00113000"],["71912.45000000","0.00000000"],["71912.44000000","0.00008000"],["63924.80000000","0.00031000"]],"a":[["79904.00000000","0.00000000"],["79904.01000000","0.00000000"],["79904.02000000","0.00000000"],["79904.26000000","0.00000000"],["79904.35000000","0.00000000"],["79904.36000000","0.00000000"],["79904.72000000","0.00000000"],["79905.24000000","0.00000000"],["79905.29000000","0.00000000"],["79905.49000000","0.00000000"],["79905.71000000","0.00000000"],["79905.99000000","0.00000000"],["79906.00000000","0.02529000"],["79906.01000000","0.00242000"],["79906.74000000","0.00007000"],["79906.97000000","0.00000000"],["79906.98000000","0.00014000"],["79908.00000000","0.02428000"],["79908.01000000","0.00681000"],["79908.02000000","0.00007000"],["79908.72000000","0.00000000"],["79908.97000000","0.00007000"],["79908.98000000","0.04686000"],["79909.29000000","0.01124000"],["79909.30000000","0.00007000"],["79909.91000000","0.00007000"],["79910.00000000","0.02435000"],["79910.01000000","0.00000000"],["79910.56000000","0.00007000"],["79910.57000000","0.01356000"],["79910.70000000","0.00000000"],["79910.71000000","0.00021000"],["79911.31000000","0.00000000"],["79911.32000000","0.00014000"],["79911.85000000","0.01349000"],["79911.92000000","0.00000000"],["79911.93000000","0.00007000"],["79911.97000000","0.00000000"],["79911.98000000","0.00014000"],["79911.99000000","0.00007000"],["79912.00000000","0.02633000"],["79912.71000000","0.06220000"],["79912.97000000","0.00026000"],["79912.98000000","0.00007000"],["79912.99000000","0.06234000"],["79913.00000000","0.19764000"],["79913.76000000","0.00000000"],["79913.99000000","0.00015000"],["79914.98000000","0.00000000"],["79915.15000000","0.06143000"],["79915.50000000","0.00007000"],["79915.76000000","0.06220000"],["79915.98000000","0.00014000"],["79916.15000000","0.00000000"],["79916.37000000","0.06220000"],["79916.76000000","0.06220000"],["79916.77000000","0.21539000"],["79917.02000000","0.06220000"],["79917.03000000","0.12167000"],["79917.06000000","0.42254000"],["79917.42000000","0.00000000"],["79917.86000000","0.00000000"],["79918.00000000","0.02400000"],["79919.37000000","0.00014000"],["79919.85000000","0.00126000"],["79919.98000000","0.00400000"],["79921.10000000","0.00000000"],["79921.98000000","0.00008000"],["79923.09000000","0.00000000"],["79923.24000000","0.00014000"],["79923.97000000","0.00125000"],["79924.12000000","0.00007000"],["79925.71000000","0.00157000"],["79925.85000000","0.00000000"],["79925.98000000","0.12519000"],["79927.11000000","0.00014000"],["79927.97000000","0.00000000"],["79929.97000000","0.00008000"],["79930.71000000","0.00000000"],["79930.98000000","0.00014000"],["79931.71000000","0.02000000"],["79931.96000000","0.00007000"],["79933.97000000","0.00633000"],["79935.68000000","0.00000000"],["79935.94000000","0.53566000"],["79935.96000000","0.00000000"],["79937.96000000","0.00008000"],["79939.07000000","0.00000000"],["79940.00000000","0.33434000"],["79941.96000000","0.00008000"],["79942.19000000","0.00000000"],["79944.00000000","0.02400000"],["79944.29000000","0.00000000"],["79945.20000000","0.00000000"],["79945.94000000","0.00000000"],["79946.00000000","0.03400000"],["79946.14000000","0.09276000"],["79949.28000000","0.00000000"],["79951.68000000","0.00000000"],["79954.20000000","0.00007000"],["79954.47000000","2.95095000"],["79956.05000000","0.00396000"],["79957.85000000","0.40155000"],["79957.87000000","0.00000000"],["79961.13000000","0.00000000"],["79962.99000000","0.83086000"],["79967.45000000","0.00000000"],["79969.12000000","0.00000000"],["79972.71000000","0.00312000"],["79974.28000000","0.00312000"],["79982.17000000","0.02000000"],["79999.98000000","0.00000000"],["80000.61000000","0.00000000"],["80000.79000000","0.12153000"],["80001.52000000","0.00000000"],["80016.71000000","0.00000000"],["80023.56000000","0.00000000"],["80040.45000000","0.25000000"],["80071.97000000","0.00202000"],["80080.22000000","0.02437000"],["80160.31000000","0.05606000"],["80291.68000000","0.00000000"]]}}}
{"rx_ns": 13876398871200, "frame": {"stream":"btcusdt@depth@100ms","data":{"e":"depthUpdate","E":1787650871614,"s":"BTCUSDT","U":99118598296,"u":99118598457,"b":[["79905.99000000","6.73986000"],["79905.95000000","0.05021000"],["79905.90000000","0.05014000"],["79905.23000000","0.21137000"],["79904.01000000","0.77931000"],["79904.00000000","1.12453000"],["79903.99000000","2.36407000"],["79903.98000000","0.00014000"],["79903.95000000","0.00007000"],["79903.94000000","0.24645000"],["79903.90000000","0.00007000"],["79903.39000000","0.05341000"],["79902.73000000","0.18891000"],["79902.72000000","0.54613000"],["79902.71000000","0.00000000"],["79902.44000000","0.04124000"],["79901.47000000","0.00700000"],["79901.43000000","0.00000000"],["79900.44000000","0.03245000"],["79900.18000000","0.49529000"],["79900.15000000","0.00000000"],["79899.99000000","0.51056000"],["79897.99000000","0.20259000"],["79897.38000000","0.00000000"],["79896.15000000","0.00014000"],["79894.72000000","0.00000000"],["79890.01000000","0.02215000"],["79889.23000000","0.00000000"],["79889.21000000","0.02000000"],["79872.23000000","0.01147000"],["79866.00000000","0.03400000"],["79864.00000000","0.02400000"],["79860.14000000","0.00425000"],["79850.27000000","0.00000000"],["79849.93000000","0.00012000"],["79829.25000000","0.00000000"],["79819.60000000","0.04588000"],["79800.32000000","0.80000000"],["79797.65000000","0.00000000"],["79763.43000000","0.00000000"],["79716.74000000","0.00000000"],["79679.31000000","0.00000000"],["71915.40000000","0.00032000"],["63925.00000000","0.00200000"],["63924.80000000","0.00000000"],["63924.79000000","0.00000000"]],"a":[["79906.00000000","0.02522000"],["79906.01000000","0.00242000"],["79906.10000000","0.00000000"],["79906.57000000","0.00000000"],["79906.71000000","0.00000000"],["79906.72000000","0.00000000"],["79906.74000000","0.00000000"],["79906.98000000","0.00000000"],["79908.00000000","0.02428000"],["79908.01000000","0.00021000"],["79908.98000000","0.04700000"],["79909.29000000","0.00014000"],["79910.00000000","0.02428000"],["79910.56000000","0.00000000"],["79910.57000000","0.00021000"],["79910.71000000","0.00000000"],["79911.32000000","0.00000000"],["79911.84000000","0.00000000"],["79911.85000000","0.00007000"],["79912.00000000","0.02647000"],["79912.70000000","0.00007000"],["79912.98000000","0.00014000"],["79913.00000000","0.19771000"],["79914.00000000","0.02407000"],["79914.02000000","0.00007000"],["79917.99000000","0.00000000"],["79927.12000000","0.00012000"],["79951.89000000","0.00000000"],["79959.88000000","0.68161000"],["79961.70000000","0.00436000"],["79962.02000000","0.00430000"],["79973.73000000","0.02000000"],["79976.80000000","0.02000000"],["79989.70000000","0.00000000"],["80000.79000000","0.00000000"],["80000.89000000","0.00000000"],["80001.01000000","0.00000000"],["80003.12000000","0.00000000"],["80016.10000000","0.01144000"],["80054.31000000","0.00410000"],["80315.81000000","0.00625000"]]}}}
{"rx_ns": 13876504995200, "frame": {"stream":"btcusdt@depth@100ms","data":{"e":"depthUpdate","E":1787650871714,"s":"BTCUSDT","U":99118598458,"u":99118598557,"b":[["79905.99000000","6.75551000"],["79905.23000000","0.21144000"],["79904.71000000","0.02003000"],["79903.99000000","2.33599000"],["79903.94000000","0.24652000"],["79903.43000000","0.02404000"],["79902.73000000","0.97527000"],["79902.44000000","0.04131000"],["79902.15000000","0.02404000"],["79901.47000000","0.00707000"],["79900.62000000","0.12515000"],["79900.44000000","0.03238000"],["79900.18000000","0.00000000"],["79880.75000000","0.00000000"],["79873.48000000","0.00000000"],["79849.93000000","0.00000000"],["79842.82000000","0.02086000"],["79771.54000000","0.00000000"],["78705.43000000","0.00000000"],["71915.40000000","0.00048000"],["63925.00000000","0.00000000"],["63924.79000000","0.00000000"]],"a":[["79906.00000000","0.02536000"],["79906.01000000","0.00270000"],["79908.00000000","0.02428000"],["79908.01000000","0.00007000"],["79908.98000000","0.04693000"],["79909.29000000","0.00000000"],["79910.00000000","0.02428000"],["79910.01000000","0.00681000"],["79910.57000000","0.00000000"],["79911.29000000","0.01124000"],["79911.30000000","0.00234000"],["79911.85000000","0.00000000"],["79912.00000000","0.02668000"],["79912.57000000","0.01349000"],["79912.59000000","0.00007000"],["79912.60000000","0.06118000"],["79912.71000000","0.06234000"],["79912.98000000","0.00007000"],["79912.99000000","0.00028000"],["79913.00000000","0.19785000"],["79913.01000000","0.34488000"],["79913.85000000","0.01349000"],["79914.03000000","0.12520000"],["79915.14000000","0.00000000"],["79916.76000000","0.00000000"],["79918.10000000","0.00936000"],["79919.45000000","0.00700000"],["79920.01000000","0.00000000"],["79926.01000000","0.00007000"],["79945.62000000","0.00000000"],["80011.23000000","0.00000000"],["80015.74000000","2.12931000"],["80015.75000000","1.95350000"],["80019.09000000","0.00000000"],["80020.72000000","0.00012000"],["80027.57000000","0.00031000"],["81104.59000000","0.00030000"]]}}}
{"rx_ns": 13876596579400, "frame": {"stream":"btcusdt@depth@100ms","data":{"e":"depthUpdate","E":1787650871814,"s":"BTCUSDT","U":99118598558,"u":99118598666,"b":[["79905.99000000","4.40787000"],["79905.96000000","0.00007000"],["79905.91000000","0.00007000"],["79905.24000000","0.00007000"],["79905.23000000","0.00028000"],["79904.72000000","0.00007000"],["79904.71000000","0.02010000"],["79904.02000000","0.00007000"],["79904.01000000","0.77938000"],["79904.00000000","1.12460000"],["79903.99000000","0.45922000"],["79903.94000000","0.24652000"],["79903.44000000","0.00625000"],["79903.39000000","0.05334000"],["79902.74000000","0.00007000"],["79902.73000000","0.97534000"],["79901.25000000","0.00000000"],["79900.20000000","1.87677000"],["79897.20000000","0.02800000"],["79897.12000000","0.02600000"],["79896.33000000","0.02000000"],["79893.21000000","0.02400000"],["79892.74000000","0.02200000"],["79892.35000000","0.02200000"],["79892.34000000","0.02200000"],["79890.77000000","0.00007000"],["79887.50000000","0.00000000"],["79875.74000000","0.00000000"],["79854.00000000","0.16565000"],["79851.92000000","0.00012000"],["79842.82000000","0.00000000"],["79795.78000000","0.00400000"],["79784.93000000","0.04258000"],["71915.40000000","0.00064000"],["63925.00000000","0.00000000"]],"a":[["79906.00000000","0.56999000"],["79906.04000000","0.00007000"],["79908.40000000","0.06118000"],["79908.43000000","0.00007000"],["79908.54000000","0.00000000"],["79908.97000000","0.06125000"],["79909.60000000","0.06118000"],["79910.00000000","0.02428000"],["79910.01000000","0.00695000"],["79910.20000000","0.06118000"],["79910.80000000","0.06118000"],["79911.29000000","0.01138000"],["79911.40000000","0.06118000"],["79911.99000000","0.06125000"],["79912.00000000","0.02668000"],["79912.57000000","0.01356000"],["79912.60000000","0.06125000"],["79912.70000000","0.18879000"],["79912.71000000","0.06220000"],["79912.99000000","0.00014000"],["79913.00000000","0.05021000"],["79913.01000000","0.34481000"],["79913.80000000","0.06118000"],["79913.99000000","0.06133000"],["79914.00000000","0.22657000"],["79915.00000000","0.06118000"],["79915.50000000","0.00014000"],["79915.81000000","0.05826000"],["79917.03000000","0.00000000"],["79917.99000000","0.06118000"],["79918.60000000","0.06118000"],["79919.47000000","0.00000000"],["79922.70000000","0.36586000"],["79922.74000000","0.00007000"],["79926.99000000","0.17000000"],["79927.12000000","0.00000000"],["79927.24000000","0.02000000"],["79927.79000000","0.02000000"],["79929.12000000","0.00012000"],["79931.76000000","0.04000000"],["79943.83000000","0.73573000"],["79968.92000000","0.02000000"],["79973.48000000","0.02000000"],["79974.36000000","0.02000000"],["79981.51000000","0.02000000"],["79981.92000000","0.02000000"],["80001.19000000","0.11886000"],["80024.66000000","0.02804000"]]}}}
{"rx_ns": 13876701837000, "frame": {"stream":"btcusdt@depth@100ms","data":{"e":"depthUpdate","E":1787650871914,"s":"BTCUSDT","U":99118598667,"u":99118598806,"b":[["79905.99000000","4.36402000"],["79905.90000000","0.05014000"],["79905.24000000","0.00000000"],["79905.23000000","0.00014000"],["79904.71000000","0.02017000"],["79904.01000000","0.54669000"],["79903.95000000","0.00007000"],["79903.94000000","0.04028000"],["79903.44000000","0.00632000"],["79903.39000000","0.05341000"],["79902.75000000","0.00625000"],["79902.74000000","0.00007000"],["79902.73000000","1.47955000"],["79900.21000000","0.00007000"],["79899.81000000","0.18053000"],["79899.21000000","0.00704000"],["79889.99000000","0.34062000"],["79815.96000000","0.00000000"],["79815.13000000","0.00000000"],["79784.93000000","0.00000000"],["79712.01000000","0.00770000"],["79688.21000000","0.00000000"],["73513.51000000","0.00014000"],["71915.40000000","0.00096000"]],"a":[["79906.00000000","0.57027000"],["79906.01000000","0.00291000"],["79908.00000000","0.02435000"],["79908.39000000","0.00007000"],["79908.40000000","0.06146000"],["79908.95000000","0.00007000"],["79908.96000000","0.11926000"],["79908.97000000","0.06139000"],["79908.98000000","0.04700000"],["79909.59000000","0.00007000"],["79909.60000000","0.06132000"],["79910.01000000","0.00695000"],["79910.19000000","0.00007000"],["79910.20000000","0.06132000"],["79910.79000000","0.00007000"],["79911.29000000","0.01131000"],["79911.39000000","0.00000000"],["79911.40000000","0.06125000"],["79911.99000000","0.06118000"],["79912.00000000","0.02654000"],["79912.57000000","0.01349000"],["79912.58000000","0.11533000"],["79912.59000000","0.00000000"],["79912.60000000","0.06118000"],["79912.70000000","0.27985000"],["79912.99000000","0.00007000"],["79913.00000000","0.05007000"],["79913.01000000","0.34474000"],["79913.80000000","0.00000000"],["79913.99000000","0.00015000"],["79914.00000000","0.22650000"],["79914.02000000","0.00000000"],["79914.03000000","0.12513000"],["79915.00000000","0.00000000"],["79915.15000000","0.00000000"],["79915.76000000","0.00000000"],["79915.81000000","0.00000000"],["79916.20000000","0.06118000"],["79916.36000000","0.19363000"],["79916.77000000","0.00000000"],["79917.02000000","0.00000000"],["79917.05000000","0.05865000"],["79917.99000000","0.00000000"],["79918.60000000","0.00000000"],["79918.64000000","0.00007000"],["79919.20000000","0.06118000"],["79919.25000000","0.00000000"],["79919.80000000","0.06118000"],["79919.86000000","0.00000000"],["79919.97000000","0.06118000"],["79941.94000000","0.00000000"],["79954.20000000","0.00000000"],["79958.48000000","0.00351000"],["79958.56000000","0.00000000"],["80024.66000000","0.00000000"],["80139.42000000","0.00603000"],["80143.41000000","0.00000000"]]}}}
{"rx_ns": 13876799993200, "frame": {"stream":"btcusdt@depth20","data":{"lastUpdateId":99118598855,"bids":[["79905.99000000","4.57106000"],["79905.98000000","0.00027000"],["79905.97000000","0.00013000"],["79905.96000000","0.00007000"],["79905.95000000","0.05021000"],["79905.91000000","0.00007000"],["79905.90000000","0.05014000"],["79905.85000000","0.00400000"],["79905.23000000","0.00014000"],["79904.72000000","0.00007000"],["79904.71000000","0.02017000"],["79904.02000000","0.00007000"],["79904.01000000","0.54669000"],["79904.00000000","1.12460000"],["79903.99000000","0.45922000"],["79903.98000000","0.00014000"],["79903.95000000","0.00007000"],["79903.94000000","0.04028000"],["79903.90000000","0.00007000"],["79903.89000000","0.00014000"]],"asks":[["79906.00000000","0.57034000"],["79906.01000000","0.00298000"],["79906.02000000","0.00375000"],["79906.04000000","0.00007000"],["79907.76000000","0.00007000"],["79907.91000000","0.00007000"],["79907.99000000","0.00007000"],["79908.00000000","0.02435000"],["79908.01000000","0.00007000"],["79908.02000000","0.00007000"],["79908.25000000","0.00007000"],["79908.39000000","0.00007000"],["79908.40000000","0.06146000"],["79908.43000000","0.00007000"],["79908.60000000","0.00007000"],["79908.71000000","0.00007000"],["79908.96000000","0.00014000"],["79908.97000000","0.06139000"],["79908.98000000","0.04700000"],["79909.30000000","0.00007000"]]}}}
{"rx_ns": 13876800116700, "frame": {"stream":"btcusdt@depth@100ms","data":{"e":"depthUpdate","E":1787650872014,"s":"BTCUSDT","U":99118598807,"u":99118598855,"b":[["79905.99000000","4.57106000"],["79902.74000000","0.00007000"],["79902.73000000","1.47955000"],["79900.21000000","0.00000000"],["79896.39000000","0.02200000"],["79896.33000000","0.04400000"],["79893.99000000","2.03915000"],["79892.29000000","0.42931000"],["79878.36000000","0.00000000"],["79875.00000000","0.00000000"],["79873.99000000","0.00000000"],["79821.28000000","0.00000000"],["79768.03000000","0.04532000"],["63924.80000000","0.00031000"]],"a":[["79906.00000000","0.57034000"],["79906.01000000","0.00298000"],["79908.40000000","0.06146000"],["79908.95000000","0.00000000"],["79908.96000000","0.00014000"],["79910.20000000","0.06125000"],["79911.39000000","0.00007000"],["79912.00000000","0.02647000"],["79912.98000000","0.00000000"],["79912.99000000","0.00000000"],["79913.00000000","0.05000000"],["79915.78000000","0.00148000"],["79918.63000000","0.00000000"],["79919.85000000","0.00000000"],["79923.58000000","0.02000000"],["79923.66000000","0.02000000"],["79925.99000000","0.02000000"],["79940.00000000","0.33685000"],["79940.24000000","0.00000000"],["79941.52000000","0.00000000"],["79945.53000000","0.00374000"],["79955.89000000","0.00373000"],["79956.05000000","0.00000000"],["79958.48000000","0.00000000"],["79974.37000000","0.00400000"],["79980.22000000","0.02000000"],["79990.32000000","0.02000000"],["80007.70000000","0.02804000"],["80019.40000000","0.00000000"]]}}}
{"rx_ns": 13876899042600, "frame": {"stream":"btcusdt@depth@100ms","data":{"e":"depthUpdate","E":1787650872114,"s":"BTCUSDT","U":99118598856,"u":99118599936,"b":[["79910.78000000","4.34506000"],["79910.77000000","0.00013000"],["79910.76000000","0.00013000"],["79910.50000000","0.00000000"],["79910.32000000","0.00000000"],["79910.20000000","0.45550000"],["79910.19000000","0.08178000"],["79910.18000000","0.00000000"],["79910.17000000","0.00000000"],["79910.00000000","0.53084000"],["79909.99000000","3.61091000"],["79909.98000000","0.03135000"],["79909.90000000","0.00000000"],["79909.72000000","0.08487000"],["79909.60000000","0.00000000"],["79909.59000000","0.37013000"],["79909.58000000","0.00000000"],["79909.29000000","0.00000000"],["79909.18000000","0.00026000"],["79908.98000000","0.07500000"],["79908.97000000","2.78177000"],["79908.96000000","0.00007000"],["79908.95000000","0.00000000"],["79908.90000000","0.05000000"],["79908.70000000","0.00000000"],["79908.59000000","0.00000000"],["79908.40000000","1.41525000"],["79908.39000000","0.00014000"],["79908.38000000","0.00000000"],["79908.24000000","0.00000000"],["79908.18000000","0.05337000"],["79908.01000000","0.00000000"],["79908.00000000","0.00000000"],["79907.99000000","0.20652000"],["79907.98000000","0.00000000"],["79907.90000000","0.00000000"],["79907.76000000","0.00014000"],["79907.75000000","0.08839000"],["79907.14000000","0.00000000"],["79906.99000000","0.00000000"],["79906.53000000","0.00000000"],["79906.37000000","0.00000000"],["79906.03000000","0.00000000"],["79906.02000000","0.00153000"],["79906.01000000","0.00021000"],["79906.00000000","0.07500000"],["79905.99000000","2.41798000"],["79905.98000000","0.00000000"],["79905.97000000","0.00000000"],["79905.96000000","0.00000000"],["79905.95000000","0.00007000"],["79905.91000000","0.00000000"],["79905.90000000","0.00000000"],["79904.72000000","0.00000000"],["79904.71000000","0.02003000"],["79904.16000000","0.00000000"],["79904.02000000","0.00000000"],["79904.01000000","0.00000000"],["79904.00000000","1.04946000"],["79903.99000000","0.45755000"],["79903.94000000","0.04021000"],["79903.44000000","0.00000000"],["79903.39000000","0.00007000"],["79902.75000000","0.00000000"],["79902.74000000","0.00000000"],["79902.73000000","1.40448000"],["79902.69000000","0.00007000"],["79902.44000000","0.00007000"],["79902.28000000","0.37554000"],["79902.03000000","0.00007000"],["79900.98000000","0.00008000"],["79900.84000000","0.00007000"],["79900.83000000","0.08976000"],["79900.44000000","0.00000000"],["79900.21000000","0.25908000"],["79900.11000000","0.00000000"],["79900.00000000","1.04939000"],["79899.99000000","0.51049000"],["79899.95000000","0.00007000"],["79899.49000000","0.00007000"],["79899.30000000","0.00000000"],["79898.47000000","0.00000000"],["79898.33000000","0.00625000"],["79898.00000000","0.00000000"],["79897.81000000","0.00655000"],["79897.46000000","0.00000000"],["79897.45000000","0.00000000"],["79896.39000000","0.04200000"],["79894.47000000","0.00000000"],["79894.42000000","0.62587000"],["79894.21000000","0.00008000"],["79893.99000000","2.03908000"],["79893.09000000","0.00000000"],["79892.01000000","0.36586000"],["79891.88000000","0.33803000"],["79891.75000000","0.51560000"],["79890.21000000","0.00008000"],["79890.01000000","0.02207000"],["79889.89000000","0.00000000"],["79888.42000000","0.00000000"],["79886.59000000","0.00000000"],["79886.57000000","0.00000000"],["79886.22000000","0.00008000"],["79886.06000000","0.09524000"],["79886.01000000","0.00000000"],["79885.99000000","0.00000000"],["79885.78000000","0.00904000"],["79885.06000000","0.00000000"],["79885.01000000","0.29828000"],["79882.22000000","0.00008000"],["79882.07000000","0.05227000"],["79882.02000000","0.00000000"],["79880.76000000","0.02000000"],["79880.72000000","0.00000000"],["79878.23000000","0.00008000"],["79878.02000000","0.00000000"],["79877.19000000","0.00000000"],["79874.23000000","0.00008000"],["79874.03000000","0.00000000"],["79870.23000000","0.00008000"],["79870.03000000","0.00000000"],["79869.06000000","0.00000000"],["79868.61000000","0.00014000"],["79866.77000000","0.00000000"],["79866.04000000","0.00000000"],["79864.65000000","0.00335000"],["79850.43000000","0.00000000"],["79843.88000000","0.00000000"],["79830.87000000","0.00008000"],["79824.23000000","0.00000000"],["79822.82000000","0.00000000"],["79815.15000000","0.00000000"],["79806.48000000","0.00000000"],["79802.62000000","0.00000000"],["79765.43000000","0.00000000"],["79759.70000000","0.00202000"],["79759.47000000","0.00000000"],["79755.86000000","0.00000000"],["79750.96000000","0.00008000"],["79742.91000000","0.00000000"],["79733.18000000","1.20000000"],["79719.12000000","0.00000000"],["79714.24000000","0.00000000"],["79671.05000000","0.00008000"],["79663.01000000","0.00000000"],["79610.48000000","0.00000000"],["79591.14000000","0.00008000"],["79583.11000000","0.00000000"],["79565.37000000","1.74103000"],["79543.11000000","0.01515000"],["79528.63000000","0.00000000"],["79511.23000000","0.00008000"],["79503.21000000","0.00000000"],["79480.86000000","0.00000000"],["79431.32000000","0.00008000"],["79423.30000000","0.00000000"],["79351.40000000","0.00008000"],["79343.40000000","0.00000000"],["71915.40000000","0.00000000"],["71912.44000000","0.00000000"],["67818.11000000","0.00314000"]],"a":[["79906.00000000","0.00000000"],["79906.01000000","0.00000000"],["79906.02000000","0.00000000"],["79906.04000000","0.00000000"],["79907.76000000","0.00000000"],["79907.91000000","0.00000000"],["79907.99000000","0.00000000"],["79908.00000000","0.00000000"],["79908.01000000","0.00000000"],["79908.02000000","0.00000000"],["79908.25000000","0.00000000"],["79908.39000000","0.00000000"],["79908.40000000","0.00000000"],["79908.43000000","0.00000000"],["79908.60000000","0.00000000"],["79908.71000000","0.00000000"],["79908.96000000","0.00000000"],["79908.97000000","0.00000000"],["79908.98000000","0.00000000"],["79908.99000000","0.00000000"],["79909.30000000","0.00000000"],["79909.59000000","0.00000000"],["79909.60000000","0.00000000"],["79909.73000000","0.00000000"],["79909.91000000","0.00000000"],["79909.99000000","0.00000000"],["79910.00000000","0.00000000"],["79910.01000000","0.00000000"],["79910.19000000","0.00000000"],["79910.20000000","0.00000000"],["79910.33000000","0.00000000"],["79910.51000000","0.00000000"],["79910.79000000","0.00100000"],["79910.80000000","0.00063000"],["79911.29000000","0.01145000"],["79911.40000000","0.00021000"],["79911.47000000","0.00000000"],["79911.72000000","0.00000000"],["79911.96000000","0.00000000"],["79911.98000000","0.00021000"],["79911.99000000","0.00021000"],["79912.00000000","0.02661000"],["79912.57000000","0.01377000"],["79912.58000000","0.00014000"],["79912.59000000","0.00007000"],["79912.60000000","0.00021000"],["79912.69000000","0.00007000"],["79912.70000000","0.00021000"],["79912.71000000","0.00007000"],["79912.97000000","0.00000000"],["79912.99000000","0.00007000"],["79913.00000000","0.05007000"],["79913.01000000","0.34481000"],["79913.77000000","0.04675000"],["79913.85000000","0.01356000"],["79913.88000000","0.00000000"],["79913.99000000","0.00000000"],["79914.00000000","0.02407000"],["79914.03000000","0.00007000"],["79914.67000000","0.00000000"],["79915.50000000","0.00007000"],["79915.76000000","0.00007000"],["79915.78000000","0.00000000"],["79916.00000000","0.02407000"],["79916.20000000","0.00007000"],["79916.36000000","0.00014000"],["79916.37000000","0.00007000"],["79917.05000000","0.00007000"],["79917.06000000","0.00007000"],["79917.19000000","0.00000000"],["79917.21000000","0.00000000"],["79918.00000000","0.02407000"],["79918.10000000","0.00000000"],["79918.72000000","0.00000000"],["79918.78000000","0.00008000"],["79919.20000000","0.00000000"],["79919.37000000","0.00007000"],["79919.45000000","0.00000000"],["79919.80000000","0.00000000"],["79919.97000000","0.00000000"],["79919.98000000","0.00000000"],["79919.99000000","0.00000000"],["79920.23000000","0.00007000"],["79921.07000000","0.00007000"],["79921.53000000","0.00000000"],["79921.98000000","0.00000000"],["79922.11000000","0.00000000"],["79922.70000000","0.00000000"],["79923.07000000","0.00000000"],["79923.24000000","0.00007000"],["79923.28000000","0.00000000"],["79923.29000000","0.00000000"],["79923.59000000","0.02000000"],["79923.97000000","0.01029000"],["79924.27000000","0.00007000"],["79924.98000000","0.20250000"],["79925.34000000","0.00708000"],["79925.54000000","0.00000000"],["79925.98000000","0.00000000"],["79925.99000000","0.02008000"],["79926.35000000","0.00000000"],["79926.98000000","0.00007000"],["79926.99000000","0.02000000"],["79927.09000000","0.00000000"],["79927.11000000","0.00007000"],["79927.30000000","0.00000000"],["79927.31000000","0.00000000"],["79928.14000000","0.00000000"],["79928.55000000","0.02000000"],["79929.34000000","0.00706000"],["79929.97000000","0.00000000"],["79929.99000000","0.00008000"],["79930.00000000","0.02400000"],["79930.98000000","0.00007000"],["79931.04000000","0.00000000"],["79931.05000000","0.00000000"],["79931.32000000","0.00000000"],["79931.97000000","1.88605000"],["79932.76000000","0.00000000"],["79932.88000000","0.02000000"],["79933.34000000","0.00704000"],["79933.97000000","0.00000000"],["79933.98000000","0.00015000"],["79934.20000000","0.15000000"],["79934.81000000","0.00250000"],["79935.78000000","1.04939000"],["79935.95000000","0.00000000"],["79937.09000000","2.24263000"],["79937.10000000","0.00000000"],["79937.11000000","0.00000000"],["79937.34000000","0.00703000"],["79937.96000000","0.00000000"],["79937.98000000","0.00008000"],["79939.81000000","1.04939000"],["79939.97000000","0.00926000"],["79940.00000000","0.33434000"],["79940.90000000","0.00000000"],["79941.11000000","0.00026000"],["79941.34000000","0.00707000"],["79941.70000000","0.00000000"],["79941.96000000","0.00000000"],["79941.97000000","0.00008000"],["79942.67000000","1.87677000"],["79943.81000000","1.04939000"],["79943.95000000","0.00000000"],["79944.06000000","0.00000000"],["79944.20000000","0.00000000"],["79944.97000000","0.00000000"],["79945.23000000","0.36586000"],["79945.36000000","0.00000000"],["79945.97000000","0.00008000"],["79946.00000000","0.02400000"],["79946.14000000","0.00000000"],["79946.46000000","0.00014000"],["79946.98000000","0.33780000"],["79947.66000000","1.87677000"],["79947.96000000","0.00008000"],["79947.97000000","0.00920000"],["79948.00000000","0.22650000"],["79948.51000000","1.04939000"],["79948.89000000","0.00000000"],["79948.97000000","0.10000000"],["79950.33000000","0.04014000"],["79950.49000000","0.00000000"],["79951.00000000","0.01000000"],["79951.44000000","0.00000000"],["79951.54000000","0.00000000"],["79951.94000000","0.09283000"],["79953.02000000","0.62551000"],["79953.91000000","1.04939000"],["79953.92000000","0.00000000"],["79954.20000000","0.00007000"],["79954.47000000","0.00000000"],["79955.97000000","0.00934000"],["79957.25000000","1.87677000"],["79958.07000000","0.00007000"],["79958.90000000","1.04939000"],["79959.11000000","0.00000000"],["79961.66000000","0.33774000"],["79961.94000000","0.00007000"],["79962.99000000","0.00000000"],["79966.25000000","0.00200000"],["79967.84000000","0.59240000"],["79969.58000000","0.00000000"],["79972.71000000","0.00000000"],["79972.86000000","0.02000000"],["79975.79000000","0.04482000"],["79977.99000000","0.00310000"],["79979.90000000","0.00007000"],["79987.92000000","0.00008000"],["79988.41000000","1.23797000"],["79989.53000000","0.00010000"],["79991.43000000","0.00000000"],["80001.19000000","0.00000000"],["80005.65000000","0.00000000"],["80005.93000000","0.00000000"],["80015.75000000","0.00000000"],["80047.29000000","0.00000000"],["80049.24000000","0.00000000"],["80049.99000000","2.92616000"],["80056.73000000","0.00132000"],["80059.48000000","0.00125000"],["80059.49000000","0.00000000"],["80059.80000000","0.00007000"],["80067.83000000","0.00008000"],["80071.97000000","0.00000000"],["80072.41000000","0.00202000"],["80139.70000000","0.00007000"],["80147.73000000","0.00008000"],["80155.68000000","0.00007000"],["80185.26000000","0.00000000"],["80263.83000000","0.00000000"],["80296.50000000","0.00000000"],["80299.50000000","0.00000000"],["80307.55000000","0.00008000"],["80459.30000000","0.00000000"],["80467.37000000","0.00008000"],["80539.20000000","0.00028000"],["80547.27000000","0.00008000"],["81104.59000000","0.00000000"]]}}}
{"rx_ns": 13876997152400, "frame": {"stream":"btcusdt@depth@100ms","data":{"e":"depthUpdate","E":1787650872214,"s":"BTCUSDT","U":99118599937,"u":99118600884,"b":[["79913.00000000","2.08508000"],["79912.99000000","0.08528000"],["79912.98000000","0.00013000"],["79912.80000000","0.14000000"],["79912.70000000","0.00000000"],["79912.69000000","0.00000000"],["79912.59000000","0.00000000"],["79912.57000000","0.00007000"],["79912.56000000","0.00000000"],["79912.04000000","0.02000000"],["79912.00000000","0.00007000"],["79911.99000000","0.08494000"],["79911.98000000","0.00000000"],["79911.97000000","0.00000000"],["79911.63000000","0.00014000"],["79911.39000000","0.00000000"],["79911.38000000","0.00000000"],["79911.29000000","0.00000000"],["79911.28000000","0.00007000"],["79910.80000000","0.00000000"],["79910.79000000","0.00014000"],["79910.78000000","0.43782000"],["79910.77000000","0.00000000"],["79910.76000000","0.00000000"],["79910.40000000","0.05337000"],["79910.21000000","0.00000000"],["79910.20000000","0.00014000"],["79910.19000000","0.00028000"],["79910.01000000","0.00000000"],["79910.00000000","0.00028000"],["79909.99000000","0.33508000"],["79909.98000000","0.00021000"],["79909.72000000","0.00014000"],["79909.60000000","0.00007000"],["79909.59000000","0.38626000"],["79909.27000000","0.00400000"],["79909.18000000","0.00000000"],["79909.14000000","0.00008000"],["79908.98000000","0.00014000"],["79908.97000000","0.39531000"],["79908.90000000","0.00007000"],["79908.50000000","0.01007000"],["79908.41000000","0.00007000"],["79908.40000000","1.04939000"],["79908.39000000","0.00000000"],["79908.18000000","0.00000000"],["79908.00000000","0.00000000"],["79907.99000000","0.00007000"],["79907.75000000","0.08846000"],["79906.03000000","0.00625000"],["79906.01000000","0.00014000"],["79906.00000000","0.46674000"],["79905.99000000","0.37861000"],["79905.95000000","0.00000000"],["79905.23000000","0.00000000"],["79905.01000000","0.00008000"],["79904.71000000","0.00000000"],["79904.27000000","0.00625000"],["79904.26000000","0.08576000"],["79903.99000000","0.41755000"],["79903.98000000","0.00000000"],["79903.95000000","0.00000000"],["79903.94000000","0.00000000"],["79903.90000000","0.00000000"],["79903.43000000","0.00000000"],["79903.39000000","0.00000000"],["79903.02000000","0.00007000"],["79902.72000000","0.54586000"],["79902.44000000","0.00000000"],["79902.43000000","0.00000000"],["79902.42000000","0.00000000"],["79902.15000000","0.00000000"],["79901.98000000","0.00000000"],["79901.52000000","0.00010000"],["79901.47000000","0.00700000"],["79900.98000000","0.00000000"],["79900.83000000","0.00400000"],["79900.55000000","0.00060000"],["79900.22000000","0.36586000"],["79900.21000000","0.00000000"],["79900.19000000","0.00000000"],["79899.99000000","0.48560000"],["79899.03000000","0.00007000"],["79898.42000000","0.00012000"],["79898.33000000","0.00000000"],["79898.09000000","0.50863000"],["79897.21000000","0.00000000"],["79895.11000000","0.00625000"],["79895.10000000","0.09462000"],["79894.42000000","0.28365000"],["79893.10000000","0.10366000"],["79891.99000000","0.18706000"],["79890.01000000","0.64787000"],["79889.74000000","0.00000000"],["79887.99000000","0.00000000"],["79887.75000000","0.00000000"],["79886.60000000","0.48133000"],["79885.77000000","0.00000000"],["79883.67000000","0.00000000"],["79881.77000000","0.00000000"],["79873.04000000","0.64110000"],["79873.00000000","0.01000000"],["79872.93000000","0.00000000"],["79871.77000000","0.00072000"],["79869.44000000","0.00000000"],["79869.26000000","0.20250000"],["79866.00000000","0.02400000"],["79862.23000000","0.38938000"],["79862.22000000","0.00000000"],["79855.73000000","0.00000000"],["79855.26000000","0.00000000"],["79847.50000000","0.00000000"],["79847.10000000","0.30737000"],["79846.85000000","0.01725000"],["79845.87000000","0.82220000"],["79844.10000000","0.12263000"],["79842.76000000","0.00000000"],["79837.71000000","1.72834000"],["79828.33000000","0.00000000"],["79828.14000000","0.00000000"],["79824.39000000","0.00000000"],["79819.44000000","0.00000000"],["79816.43000000","0.00000000"],["79815.80000000","0.00000000"],["79810.65000000","0.00000000"],["79810.30000000","0.00000000"],["79802.22000000","0.00000000"],["79773.43000000","0.00000000"],["79772.80000000","1.50235000"],["79759.70000000","0.00000000"],["79741.92000000","0.00000000"],["79717.59000000","0.00000000"],["79684.52000000","0.00000000"],["79681.85000000","0.00000000"],["79600.73000000","0.01915000"],["79592.51000000","0.00000000"],["79571.49000000","0.00499000"],["79532.42000000","0.00000000"],["79498.88000000","0.00000000"],["79273.70000000","0.00008000"],["79263.50000000","0.00000000"],["71921.70000000","0.00016000"],["67926.05000000","0.00017000"],["63924.80000000","0.00000000"]],"a":[["79910.79000000","0.00000000"],["79910.80000000","0.00000000"],["79911.28000000","0.00000000"],["79911.29000000","0.00000000"],["79911.30000000","0.00000000"],["79911.39000000","0.00000000"],["79911.40000000","0.00000000"],["79911.63000000","0.00000000"],["79911.93000000","0.00000000"],["79911.98000000","0.00000000"],["79911.99000000","0.00000000"],["79912.00000000","0.00000000"],["79912.48000000","0.00000000"],["79912.56000000","0.00000000"],["79912.57000000","0.00000000"],["79912.58000000","0.00000000"],["79912.59000000","0.00000000"],["79912.60000000","0.00000000"],["79912.69000000","0.00000000"],["79912.70000000","0.00000000"],["79912.71000000","0.00000000"],["79912.99000000","0.00000000"],["79913.00000000","0.00000000"],["79913.01000000","1.39380000"],["79913.02000000","0.00063000"],["79913.61000000","0.00007000"],["79913.62000000","0.06220000"],["79913.76000000","0.00000000"],["79913.77000000","0.00014000"],["79913.84000000","0.00000000"],["79913.85000000","0.00021000"],["79913.99000000","0.00007000"],["79914.00000000","0.02435000"],["79914.01000000","0.00000000"],["79914.02000000","0.00000000"],["79914.22000000","0.00007000"],["79914.23000000","0.06227000"],["79914.83000000","0.00007000"],["79914.84000000","0.06227000"],["79915.11000000","0.00074000"],["79915.15000000","0.00370000"],["79915.24000000","0.00026000"],["79915.44000000","0.00007000"],["79915.45000000","0.05593000"],["79915.50000000","0.00014000"],["79915.75000000","0.00000000"],["79915.97000000","0.00007000"],["79915.98000000","0.06227000"],["79915.99000000","0.04682000"],["79916.00000000","0.02435000"],["79916.10000000","0.00000000"],["79916.19000000","0.00000000"],["79916.66000000","0.00007000"],["79916.67000000","0.06227000"],["79917.28000000","0.06220000"],["79917.88000000","0.00000000"],["79917.89000000","0.06220000"],["79917.99000000","0.42254000"],["79918.00000000","0.02428000"],["79918.49000000","0.00000000"],["79918.50000000","0.06227000"],["79918.78000000","0.00000000"],["79919.10000000","0.00000000"],["79919.11000000","0.06220000"],["79919.32000000","0.00000000"],["79919.33000000","0.00007000"],["79919.37000000","0.00014000"],["79919.92000000","0.00139000"],["79919.93000000","0.00000000"],["79919.94000000","0.06227000"],["79919.98000000","0.00000000"],["79919.99000000","0.45212000"],["79920.22000000","0.00000000"],["79920.40000000","0.00215000"],["79920.94000000","0.00000000"],["79921.00000000","0.00008000"],["79921.55000000","0.00000000"],["79922.16000000","0.06220000"],["79922.77000000","0.06220000"],["79923.24000000","0.00014000"],["79923.38000000","0.06220000"],["79923.57000000","0.00000000"],["79923.58000000","0.02000000"],["79923.59000000","0.02000000"],["79923.66000000","0.02000000"],["79923.90000000","0.00000000"],["79923.97000000","0.01029000"],["79924.21000000","0.06220000"],["79924.59000000","0.00000000"],["79924.81000000","0.00000000"],["79924.82000000","0.06220000"],["79924.97000000","0.71315000"],["79925.50000000","0.00000000"],["79925.51000000","0.00000000"],["79925.82000000","0.00000000"],["79926.43000000","0.06220000"],["79926.65000000","0.00000000"],["79926.76000000","1.87677000"],["79927.11000000","0.00014000"],["79927.23000000","0.00000000"],["79927.87000000","0.00000000"],["79928.12000000","0.00000000"],["79928.13000000","0.52521000"],["79928.54000000","0.00625000"],["79928.87000000","0.00000000"],["79928.96000000","0.36586000"],["79928.99000000","0.00007000"],["79929.48000000","0.00000000"],["79929.70000000","0.00000000"],["79930.31000000","0.00000000"],["79930.70000000","0.00000000"],["79930.92000000","0.00000000"],["79930.98000000","0.00014000"],["79931.00000000","1.04939000"],["79931.31000000","0.00000000"],["79931.52000000","0.00000000"],["79931.53000000","0.00000000"],["79931.95000000","0.00000000"],["79931.96000000","0.65297000"],["79932.75000000","0.00000000"],["79933.71000000","0.09457000"],["79935.71000000","0.10360000"],["79935.76000000","0.19026000"],["79935.77000000","1.06942000"],["79935.94000000","0.00000000"],["79936.80000000","0.00000000"],["79938.56000000","0.00000000"],["79939.79000000","0.34439000"],["79939.80000000","0.98766000"],["79940.56000000","0.00000000"],["79941.10000000","0.00000000"],["79942.66000000","0.62580000"],["79943.80000000","0.64968000"],["79943.83000000","0.00000000"],["79947.65000000","1.44859000"],["79947.96000000","0.00000000"],["79947.99000000","0.00000000"],["79950.00000000","0.12761000"],["79951.00000000","0.00000000"],["79951.61000000","0.64047000"],["79951.94000000","0.00000000"],["79952.31000000","0.09586000"],["79952.81000000","0.00652000"],["79952.97000000","0.00008000"],["79953.00000000","0.01000000"],["79954.06000000","0.00012000"],["79956.17000000","0.02479000"],["79956.35000000","0.00060000"],["79957.24000000","0.98578000"],["79957.85000000","0.00000000"],["79958.07000000","0.00000000"],["79958.42000000","1.20202000"],["79961.94000000","0.00000000"],["79962.00000000","0.02400000"],["79965.20000000","0.82098000"],["79966.25000000","0.00000000"],["79967.84000000","0.35969000"],["79974.28000000","0.00000000"],["79975.99000000","0.58746000"],["79978.37000000","0.00000000"],["79978.78000000","0.82084000"],["79981.50000000","0.00311000"],["79983.99000000","0.02996000"],["79985.29000000","0.01131000"],["79985.97000000","0.00000000"],["79986.60000000","0.00000000"],["79993.19000000","0.00112000"],["80006.48000000","0.00000000"],["80006.78000000","0.00000000"],["80006.94000000","0.12141000"],["80008.30000000","0.09375000"],["80015.74000000","1.54613000"],["80021.12000000","0.00007000"],["80025.41000000","0.00018000"],["80036.00000000","0.00000000"],["80040.45000000","0.00000000"],["80047.47000000","0.25000000"],["80049.25000000","1.25990000"],["80051.51000000","0.10010000"],["80060.49000000","0.20463000"],["80072.41000000","0.00000000"],["80076.51000000","1.50235000"],["80080.22000000","0.00000000"],["80087.00000000","0.02470000"],["80126.25000000","0.00400000"],["80127.77000000","0.00000000"],["80137.39000000","0.01960000"],["80142.44000000","0.00007000"],["80146.43000000","0.00007000"],["80147.85000000","0.00000000"],["80150.42000000","0.00017000"],["80154.41000000","0.00007000"],["80197.51000000","0.00037000"],["80205.19000000","0.00499000"],["80256.69000000","0.00000000"],["80296.59000000","0.54998000"],["80323.04000000","0.00625000"],["80619.09000000","0.00000000"]]}}}
{"rx_ns": 13877100736400, "frame": {"stream":"btcusdt@depth@100ms","data":{"e":"depthUpdate","E":1787650872314,"s":"BTCUSDT","U":99118600885,"u":99118601215,"b":[["79913.00000000","1.60356000"],["79912.99000000","0.00062000"],["79912.95000000","0.05000000"],["79912.81000000","0.00000000"],["79912.80000000","0.00014000"],["79912.57000000","0.00000000"],["79912.05000000","0.00007000"],["79912.04000000","0.02021000"],["79912.00000000","0.00000000"],["79911.99000000","0.00021000"],["79911.73000000","0.00007000"],["79911.72000000","0.02102000"],["79911.64000000","0.00007000"],["79911.63000000","0.00014000"],["79911.41000000","0.03368000"],["79910.79000000","0.00014000"],["79910.78000000","0.22907000"],["79910.45000000","0.34573000"],["79910.44000000","0.02522000"],["79910.41000000","0.00007000"],["79910.40000000","0.05351000"],["79910.20000000","0.00000000"],["79910.19000000","0.00014000"],["79910.00000000","0.00007000"],["79909.99000000","0.33501000"],["79909.98000000","0.00000000"],["79909.72000000","0.00000000"],["79909.63000000","0.12053000"],["79909.60000000","0.00007000"],["79909.59000000","0.18376000"],["79909.22000000","0.00000000"],["79909.16000000","0.02522000"],["79908.98000000","0.00007000"],["79908.90000000","0.00000000"],["79908.50000000","0.00000000"],["79908.42000000","0.00007000"],["79908.41000000","1.04939000"],["79908.40000000","0.00000000"],["79907.75000000","0.00014000"],["79906.01000000","0.00007000"],["79906.00000000","0.46667000"],["79905.99000000","0.20796000"],["79905.56000000","0.12514000"],["79904.30000000","0.15007000"],["79904.26000000","0.00000000"],["79904.01000000","0.00400000"],["79903.99000000","0.41741000"],["79903.37000000","0.08576000"],["79902.28000000","0.00000000"],["79900.23000000","1.88077000"],["79900.22000000","0.00000000"],["79900.20000000","0.00000000"],["79895.81000000","0.00000000"],["79895.11000000","0.00000000"],["79892.46000000","0.37211000"],["79892.01000000","0.00000000"],["79889.58000000","0.12517000"],["79889.38000000","0.00000000"],["79880.77000000","0.00000000"],["79877.91000000","0.04457000"],["79851.92000000","0.00000000"],["79849.19000000","1.24012000"],["79847.10000000","0.53895000"],["79844.10000000","0.00000000"],["79842.76000000","1.24119000"],["79842.12000000","0.00000000"],["79841.97000000","0.12257000"],["79817.27000000","0.00000000"],["79773.94000000","0.04032000"],["79773.43000000","0.20250000"],["79768.03000000","0.00000000"],["79712.01000000","0.00000000"],["79709.78000000","0.00770000"],["79600.58000000","0.00036000"],["78714.30000000","0.00030000"],["71921.70000000","0.00048000"],["63930.00000000","0.00788000"]],"a":[["79913.01000000","1.39372000"],["79913.02000000","0.00035000"],["79913.60000000","0.00007000"],["79913.61000000","0.14262000"],["79913.62000000","0.06234000"],["79913.77000000","0.00000000"],["79913.85000000","0.00007000"],["79914.00000000","0.02435000"],["79914.23000000","0.06241000"],["79914.76000000","0.14400000"],["79914.84000000","0.06241000"],["79915.44000000","0.00007000"],["79915.45000000","0.05607000"],["79915.97000000","0.00007000"],["79915.98000000","0.06241000"],["79915.99000000","0.04689000"],["79916.00000000","0.02435000"],["79916.42000000","0.00007000"],["79916.61000000","0.06124000"],["79916.65000000","0.00131000"],["79916.66000000","0.22667000"],["79917.28000000","0.06227000"],["79917.78000000","0.00615000"],["79917.89000000","0.06227000"],["79918.00000000","0.02407000"],["79918.50000000","0.00000000"],["79919.06000000","0.01026000"],["79919.11000000","0.00000000"],["79919.92000000","0.00000000"],["79919.94000000","0.06220000"],["79919.98000000","0.36586000"],["79919.99000000","0.84362000"],["79920.34000000","0.01231000"],["79921.41000000","0.00000000"],["79921.53000000","1.87677000"],["79921.54000000","0.12512000"],["79921.62000000","0.01231000"],["79921.99000000","0.00000000"],["79922.16000000","0.00000000"],["79922.61000000","0.00000000"],["79922.77000000","0.00000000"],["79923.21000000","0.00000000"],["79923.38000000","0.00000000"],["79923.81000000","0.00000000"],["79924.21000000","0.00000000"],["79924.41000000","0.00000000"],["79924.82000000","0.00000000"],["79926.43000000","0.00000000"],["79926.75000000","1.04939000"],["79929.12000000","0.00000000"],["79929.54000000","0.12511000"],["79930.97000000","0.00625000"],["79931.75000000","0.30365000"],["79932.88000000","0.00000000"],["79939.79000000","0.00000000"],["79941.39000000","0.04493000"],["79954.20000000","0.00007000"],["79958.48000000","0.00198000"],["79975.79000000","0.00000000"],["79981.77000000","0.00008000"],["79990.32000000","0.00000000"],["80007.70000000","0.00000000"],["80013.63000000","0.02804000"],["80051.50000000","0.09345000"],["80052.51000000","0.00000000"],["80080.17000000","0.02449000"],["80087.00000000","0.00000000"],["80154.41000000","0.00000000"],["80346.96000000","0.00373000"]]}}}
{"rx_ns": 13877198150500, "frame": {"stream":"btcusdt@depth@100ms","data":{"e":"depthUpdate","E":1787650872414,"s":"BTCUSDT","U":99118601216,"u":99118601338,"b":[["79913.00000000","1.63684000"],["79912.99000000","0.00041000"],["79912.96000000","0.00007000"],["79912.95000000","0.05014000"],["79912.80000000","0.00000000"],["79912.04000000","0.02021000"],["79911.99000000","0.00007000"],["79911.72000000","0.02123000"],["79911.42000000","0.00000000"],["79911.41000000","0.00014000"],["79910.78000000","0.22907000"],["79910.46000000","0.00007000"],["79910.45000000","0.34573000"],["79910.44000000","0.02529000"],["79910.41000000","0.00007000"],["79910.19000000","0.00007000"],["79910.00000000","0.00007000"],["79909.99000000","0.33501000"],["79909.64000000","0.00007000"],["79909.60000000","0.00007000"],["79909.59000000","0.18362000"],["79909.27000000","0.00000000"],["79908.98000000","0.00000000"],["79908.42000000","0.00000000"],["79905.99000000","0.20734000"],["79903.36000000","0.00048000"],["79867.16000000","0.83186000"],["79865.85000000","0.00000000"],["79862.65000000","0.00400000"],["79858.92000000","0.92043000"],["79825.91000000","0.00000000"],["79795.78000000","0.00000000"],["79746.05000000","0.00000000"],["79674.17000000","0.00000000"],["73513.51000000","0.00000000"],["71921.70000000","0.00064000"]],"a":[["79913.01000000","1.39379000"],["79913.61000000","0.17528000"],["79913.62000000","0.00014000"],["79914.23000000","0.06241000"],["79914.75000000","0.00007000"],["79914.76000000","0.14407000"],["79914.83000000","0.00000000"],["79914.84000000","0.00021000"],["79915.44000000","0.00007000"],["79915.97000000","0.00007000"],["79915.98000000","0.06241000"],["79915.99000000","0.04675000"],["79916.00000000","0.02428000"],["79916.60000000","0.00007000"],["79916.65000000","0.00138000"],["79916.66000000","0.15726000"],["79916.67000000","0.00007000"],["79917.28000000","0.00007000"],["79921.52000000","1.04939000"],["79930.00000000","0.11784000"],["79934.40000000","0.00205000"],["79936.13000000","0.00012000"],["79948.05000000","0.51623000"],["79952.46000000","0.00653000"],["79959.88000000","0.99370000"],["79963.39000000","0.83086000"],["79972.66000000","1.01673000"],["79974.37000000","0.00000000"],["80004.63000000","0.78060000"],["80006.35000000","0.00000000"],["80006.66000000","1.99028000"],["80054.31000000","0.00010000"],["80126.25000000","0.00000000"]]}}}
{"rx_ns": 13877295884800, "frame": {"stream":"btcusdt@depth@100ms","data":{"e":"depthUpdate","E":1787650872514,"s":"BTCUSDT","U":99118601339,"u":99118601468,"b":[["79913.00000000","1.63713000"],["79911.72000000","0.02123000"],["79911.41000000","0.00000000"],["79910.81000000","0.00007000"],["79910.80000000","0.31292000"],["79910.78000000","0.22914000"],["79910.45000000","0.50928000"],["79910.44000000","0.02536000"],["79910.41000000","0.00007000"],["79910.00000000","0.00007000"],["79909.99000000","0.33508000"],["79909.64000000","0.00007000"],["79909.60000000","0.00000000"],["79909.22000000","0.00026000"],["79906.02000000","1.15758000"],["79906.01000000","1.87684000"],["79906.00000000","0.00000000"],["79905.99000000","0.20718000"],["79905.00000000","0.00009000"],["79904.72000000","0.00007000"],["79904.13000000","0.03224000"],["79903.36000000","0.00000000"],["79897.99000000","0.20250000"],["79893.80000000","0.02000000"],["79885.32000000","0.00000000"],["79872.93000000","0.00000000"],["79837.71000000","0.00000000"],["79831.75000000","0.00750000"],["79784.19000000","0.00012000"],["79775.19000000","0.00000000"],["79771.20000000","0.00000000"],["71921.70000000","0.00088000"],["63930.40000000","0.00031000"]],"a":[["79913.01000000","1.00153000"],["79913.02000000","0.00042000"],["79913.61000000","0.03280000"],["79913.62000000","0.00000000"],["79914.22000000","0.00000000"],["79914.23000000","0.00028000"],["79914.75000000","0.00000000"],["79914.76000000","0.00014000"],["79914.84000000","0.00007000"],["79915.24000000","0.00000000"],["79915.98000000","0.17014000"],["79915.99000000","0.04696000"],["79916.00000000","0.02435000"],["79916.60000000","0.00007000"],["79916.61000000","0.06117000"],["79916.65000000","0.00000000"],["79916.66000000","0.00000000"],["79917.78000000","0.00622000"],["79917.80000000","0.00007000"],["79917.81000000","0.06117000"],["79917.88000000","0.00007000"],["79917.89000000","0.06220000"],["79917.99000000","0.00000000"],["79918.35000000","0.00000000"],["79919.01000000","0.06117000"],["79919.61000000","0.06117000"],["79919.93000000","0.00000000"],["79920.71000000","0.00130000"],["79921.52000000","0.00000000"],["79921.53000000","0.00000000"],["79923.19000000","0.00687000"],["79930.97000000","0.00000000"],["79930.99000000","0.19019000"],["79931.75000000","0.00000000"],["79931.88000000","0.00007000"],["79934.19000000","0.26118000"],["79935.14000000","0.00625000"],["79935.76000000","0.00007000"],["79954.20000000","0.00000000"],["79959.83000000","0.33774000"],["80020.72000000","0.00000000"],["80025.41000000","0.00000000"],["80027.57000000","0.00000000"]]}}}
{"rx_ns": 13877395747500, "frame": {"stream":"btcusdt@depth@100ms","data":{"e":"depthUpdate","E":1787650872614,"s":"BTCUSDT","U":99118601469,"u":99118601569,"b":[["79913.00000000","1.71713000"],["79912.95000000","0.05021000"],["79912.40000000","0.00007000"],["79912.39000000","0.00000000"],["79912.05000000","0.00000000"],["79912.04000000","0.00021000"],["79911.72000000","0.02130000"],["79911.21000000","0.00007000"],["79911.20000000","0.06124000"],["79910.82000000","0.00007000"],["79910.81000000","0.06124000"],["79910.80000000","0.31299000"],["79910.41000000","0.00000000"],["79910.00000000","0.00007000"],["79909.99000000","0.33501000"],["79909.64000000","0.00000000"],["79909.60000000","0.00000000"],["79909.59000000","0.18369000"],["79909.53000000","0.00000000"],["79907.75000000","0.00007000"],["79904.30000000","0.15000000"],["79902.74000000","0.36586000"],["79901.79000000","0.37554000"],["79880.76000000","0.00000000"],["79880.00000000","0.12041000"],["79865.24000000","0.00400000"],["79862.65000000","0.00000000"],["79849.19000000","0.00000000"],["79829.25000000","0.02000000"],["71921.70000000","0.00120000"],["71921.00000000","0.00037000"],["63930.40000000","0.00000000"]],"a":[["79913.01000000","0.87767000"],["79913.02000000","0.00042000"],["79913.60000000","0.00000000"],["79913.61000000","0.00014000"],["79914.00000000","0.02435000"],["79914.23000000","0.00007000"],["79914.76000000","0.00000000"],["79915.98000000","0.06241000"],["79916.00000000","0.02442000"],["79916.61000000","0.06138000"],["79917.20000000","0.00007000"],["79917.21000000","0.06117000"],["79917.78000000","0.00629000"],["79917.80000000","0.00007000"],["79917.88000000","0.00007000"],["79917.99000000","0.00007000"],["79918.00000000","0.02421000"],["79918.02000000","0.42254000"],["79919.98000000","0.00000000"],["79919.99000000","0.45212000"],["79928.00000000","0.04407000"],["79954.20000000","0.00007000"],["79960.91000000","0.62545000"],["79976.80000000","0.00000000"],["79986.08000000","0.00400000"]]}}}
{"rx_ns": 13877497044700, "frame": {"stream":"btcusdt@depth@100ms","data":{"e":"depthUpdate","E":1787650872714,"s":"BTCUSDT","U":99118601570,"u":99118601632,"b":[["79913.00000000","1.71720000"],["79912.95000000","0.05014000"],["79912.40000000","0.00000000"],["79912.04000000","0.00007000"],["79911.72000000","0.02130000"],["79911.20000000","0.06138000"],["79910.81000000","0.06131000"],["79910.46000000","0.00007000"],["79910.41000000","0.00007000"],["79910.40000000","0.05337000"],["79910.00000000","0.00007000"],["79909.59000000","0.18362000"],["79902.74000000","0.00000000"],["79780.36000000","0.00011000"],["71921.00000000","0.00017000"]],"a":[["79913.01000000","0.87916000"],["79913.61000000","0.00000000"],["79914.00000000","0.02442000"],["79915.40000000","0.00007000"],["79915.41000000","0.06117000"],["79916.00000000","0.02449000"],["79916.59000000","0.00007000"],["79916.60000000","0.24886000"],["79916.61000000","0.06138000"],["79917.20000000","0.00007000"],["79917.21000000","0.06124000"],["79917.80000000","0.00000000"],["79917.81000000","0.20267000"],["79917.88000000","0.00000000"],["79917.99000000","0.00000000"],["79936.82000000","0.00000000"],["80029.74000000","0.00012000"],["80032.43000000","0.00018000"],["81111.71000000","0.00030000"]]}}}
{"rx_ns": 13877596854300, "frame": {"stream":"btcusdt@depth@100ms","data":{"e":"depthUpdate","E":1787650872815,"s":"BTCUSDT","U":99118601633,"u":99118601684,"b":[["79911.21000000","0.00000000"],["79911.20000000","0.00021000"],["79910.82000000","0.00000000"],["79910.81000000","0.00014000"],["79909.64000000","0.00007000"],["79909.60000000","0.00007000"],["79897.78000000","0.00007000"],["79890.77000000","0.00000000"],["79758.95000000","0.00202000"],["71921.70000000","0.00171000"],["71921.69000000","0.00008000"],["63930.40000000","0.00000000"]],"a":[["79913.01000000","0.87878000"],["79913.02000000","0.00056000"],["79914.00000000","0.02449000"],["79914.80000000","0.00007000"],["79914.81000000","0.05544000"],["79915.41000000","0.06131000"],["79916.00000000","0.02442000"],["79916.60000000","0.24893000"],["79917.21000000","0.06117000"],["79917.78000000","0.00622000"],["79918.00000000","0.02414000"],["79919.33000000","0.00000000"],["79922.74000000","0.00000000"],["79929.76000000","0.00007000"],["79946.10000000","0.00400000"],["79963.99000000","0.84983000"],["79964.97000000","0.34682000"],["79969.09000000","0.51583000"],["79969.52000000","0.02000000"],["79970.33000000","0.02000000"],["80036.59000000","0.00031000"],["80071.54000000","0.00202000"]]}}}
{"rx_ns": 13877695630600, "frame": {"stream":"btcusdt@depth@100ms","data":{"e":"depthUpdate","E":1787650872914,"s":"BTCUSDT","U":99118601685,"u":99118601720,"b":[["79911.72000000","0.02130000"],["79911.20000000","0.00007000"],["79910.84000000","0.00007000"],["79910.81000000","0.00007000"],["79910.80000000","0.31306000"],["79910.55000000","0.00000000"],["79910.40000000","0.05344000"],["79909.99000000","0.33508000"],["79845.62000000","0.02086000"],["79755.98000000","0.01960000"],["79737.59000000","0.00000000"],["79709.78000000","0.00000000"],["79700.91000000","0.00793000"],["71921.70000000","0.00171000"]],"a":[["79913.01000000","0.87722000"],["79914.00000000","0.02449000"],["79914.81000000","0.05558000"],["79915.50000000","0.00007000"],["79916.61000000","0.06124000"],["79918.00000000","0.02407000"],["79919.01000000","0.00000000"],["79948.05000000","0.00000000"],["79951.00000000","0.70000000"]]}}}
{"rx_ns": 13877804579400, "frame": {"stream":"btcusdt@depth20","data":{"lastUpdateId":99118601784,"bids":[["79913.00000000","1.71888000"],["79912.99000000","0.00041000"],["79912.98000000","0.00013000"],["79912.96000000","0.00007000"],["79912.95000000","0.05014000"],["79912.04000000","0.00007000"],["79911.99000000","0.00007000"],["79911.73000000","0.00007000"],["79911.72000000","0.02130000"],["79911.64000000","0.00007000"],["79911.63000000","0.00014000"],["79911.28000000","0.00007000"],["79911.21000000","0.00007000"],["79911.20000000","0.06124000"],["79910.84000000","0.00007000"],["79910.82000000","0.00007000"],["79910.81000000","0.06124000"],["79910.80000000","0.31306000"],["79910.79000000","0.00014000"],["79910.78000000","0.22914000"]],"asks":[["79913.01000000","0.87708000"],["79913.02000000","0.00042000"],["79913.85000000","0.00007000"],["79913.99000000","0.00007000"],["79914.00000000","0.02449000"],["79914.03000000","0.00007000"],["79914.23000000","0.00007000"],["79914.48000000","0.00007000"],["79914.81000000","0.00014000"],["79914.84000000","0.00007000"],["79915.11000000","0.00074000"],["79915.15000000","0.00370000"],["79915.40000000","0.00007000"],["79915.41000000","0.06131000"],["79915.45000000","0.00021000"],["79915.50000000","0.00007000"],["79915.76000000","0.00007000"],["79915.79000000","0.00007000"],["79915.97000000","0.00007000"],["79915.98000000","0.06241000"]]}}}
{"rx_ns": 13877804772600, "frame": {"stream":"btcusdt@depth@100ms","data":{"e":"depthUpdate","E":1787650873014,"s":"BTCUSDT","U":99118601721,"u":99118601784,"b":[["79913.00000000","1.71888000"],["79911.21000000","0.00007000"],["79911.20000000","0.06124000"],["79910.82000000","0.00007000"],["79910.81000000","0.06124000"],["79910.46000000","0.00007000"],["79910.41000000","0.00007000"],["79910.40000000","0.05351000"],["79910.13000000","0.03224000"],["79910.00000000","0.00007000"],["79909.99000000","0.33501000"],["79909.64000000","0.00000000"],["79909.63000000","0.00000000"],["79909.60000000","0.00000000"],["79908.97000000","0.39538000"],["79908.84000000","0.00000000"],["79907.01000000","0.00013000"],["79905.99000000","0.20711000"],["79867.71000000","0.00400000"],["79865.24000000","0.00000000"],["79845.62000000","0.00000000"],["79839.42000000","0.00400000"],["79835.11000000","0.02200000"],["79788.09000000","0.00000000"],["71921.70000000","0.00187000"],["65146.32000000","0.00000000"],["63930.40000000","0.00031000"]],"a":[["79913.01000000","0.87708000"],["79913.02000000","0.00042000"],["79914.80000000","0.00000000"],["79914.81000000","0.00014000"],["79915.44000000","0.00000000"],["79915.45000000","0.00021000"],["79916.00000000","0.02428000"],["79916.60000000","0.24886000"],["79916.61000000","0.00000000"],["79917.20000000","0.00000000"],["79917.21000000","0.00000000"],["79917.80000000","0.00007000"],["79917.89000000","0.00000000"],["79918.01000000","0.00007000"],["79918.02000000","0.42261000"],["79919.00000000","0.00013000"],["79919.61000000","0.00000000"],["79919.94000000","0.00000000"],["79919.98000000","0.00007000"],["79947.65000000","1.89621000"],["79947.93000000","0.51192000"],["79950.00000000","0.12510000"],["79970.27000000","0.02000000"]]}}}
{"rx_ns": 13877900244200, "frame": {"stream":"btcusdt@depth@100ms","data":{"e":"depthUpdate","E":1787650873114,"s":"BTCUSDT","U":99118601785,"u":99118602017,"b":[["79913.00000000","1.80620000"],["79912.95000000","0.05021000"],["79912.52000000","0.12053000"],["79912.41000000","0.00007000"],["79912.40000000","0.06124000"],["79911.81000000","0.00007000"],["79911.80000000","0.06117000"],["79911.72000000","0.02130000"],["79911.20000000","0.06138000"],["79910.84000000","0.00014000"],["79910.83000000","0.78728000"],["79910.82000000","0.00000000"],["79910.81000000","0.00014000"],["79910.79000000","0.00014000"],["79910.46000000","0.00000000"],["79910.45000000","0.00014000"],["79910.41000000","0.00000000"],["79910.40000000","0.05344000"],["79910.00000000","0.00007000"],["79909.99000000","0.33494000"],["79908.97000000","0.39531000"],["79908.26000000","0.00007000"],["79906.18000000","0.00007000"],["79905.99000000","0.20704000"],["79894.01000000","0.36586000"],["79892.46000000","0.00625000"],["79886.06000000","0.00000000"],["79885.11000000","0.09403000"],["79841.97000000","0.00000000"],["79833.36000000","0.00000000"],["79831.80000000","0.32628000"],["71921.70000000","0.00187000"]],"a":[["79913.01000000","0.90096000"],["79913.02000000","0.00049000"],["79914.00000000","0.02442000"],["79914.81000000","0.00000000"],["79915.40000000","0.00000000"],["79915.41000000","0.00014000"],["79915.45000000","0.00007000"],["79915.97000000","0.00000000"],["79915.98000000","0.00021000"],["79916.00000000","0.02442000"],["79916.58000000","0.00007000"],["79916.59000000","0.06124000"],["79916.60000000","0.00014000"],["79917.20000000","0.00007000"],["79917.21000000","0.05702000"],["79917.78000000","0.00636000"],["79917.79000000","0.00007000"],["79917.80000000","0.05600000"],["79917.81000000","0.00007000"],["79917.99000000","0.00007000"],["79918.00000000","0.02414000"],["79918.01000000","0.00000000"],["79918.02000000","0.00007000"],["79918.40000000","0.00007000"],["79918.41000000","0.06117000"],["79919.00000000","0.00020000"],["79919.01000000","0.06117000"],["79919.60000000","0.00000000"],["79919.61000000","0.05830000"],["79919.97000000","0.00000000"],["79919.98000000","0.06117000"],["79919.99000000","0.45212000"],["79920.71000000","0.00000000"],["79923.19000000","0.00145000"],["79924.96000000","0.06117000"],["79926.74000000","0.00400000"],["79926.75000000","0.00000000"],["79930.00000000","0.02400000"],["79930.99000000","0.00000000"],["79931.96000000","0.64897000"],["79934.19000000","0.00000000"],["79934.80000000","0.19019000"],["79937.08000000","0.37601000"],["79938.56000000","0.12509000"],["79941.39000000","0.00000000"],["79950.00000000","0.12761000"],["79952.31000000","0.00000000"],["79955.31000000","0.04572000"],["79958.07000000","0.00000000"],["80006.94000000","0.00000000"],["80013.09000000","0.00000000"],["80013.72000000","0.12054000"]]}}}
{"rx_ns": 13877998679100, "frame": {"stream":"btcusdt@depth@100ms","data":{"e":"depthUpdate","E":1787650873214,"s":"BTCUSDT","U":99118602018,"u":99118602129,"b":[["79913.00000000","1.72151000"],["79912.95000000","0.05028000"],["79912.54000000","0.00007000"],["79912.53000000","1.04939000"],["79912.52000000","0.00014000"],["79912.41000000","0.00000000"],["79912.40000000","0.00021000"],["79911.81000000","0.00000000"],["79911.80000000","0.00014000"],["79911.73000000","0.00000000"],["79911.49000000","0.12053000"],["79911.21000000","0.00000000"],["79911.20000000","0.00021000"],["79910.88000000","0.12521000"],["79910.83000000","0.78735000"],["79910.81000000","0.00007000"],["79910.78000000","0.22900000"],["79910.75000000","0.00007000"],["79910.74000000","0.00000000"],["79910.45000000","0.00000000"],["79910.44000000","0.02522000"],["79910.00000000","0.00007000"],["79909.60000000","0.00007000"],["79908.98000000","0.00007000"],["79908.42000000","0.00007000"],["79908.06000000","0.00635000"],["79906.01000000","1.87677000"],["79897.81000000","0.00000000"],["79885.11000000","0.00000000"],["79885.00000000","0.70000000"],["79875.00000000","0.09488000"],["71921.70000000","0.00203000"],["63930.40000000","0.00000000"]],"a":[["79913.01000000","0.90022000"],["79913.02000000","0.00056000"],["79914.00000000","0.02435000"],["79915.41000000","0.00000000"],["79915.97000000","0.00007000"],["79915.98000000","0.05601000"],["79916.00000000","0.02435000"],["79916.59000000","0.06138000"],["79916.60000000","0.00000000"],["79917.21000000","0.05716000"],["79917.78000000","0.00636000"],["79917.79000000","0.00007000"],["79917.80000000","0.05607000"],["79917.81000000","0.00000000"],["79917.99000000","0.00007000"],["79918.00000000","0.02421000"],["79918.40000000","0.00007000"],["79918.89000000","0.00000000"],["79919.00000000","0.00013000"],["79919.37000000","0.00014000"],["79924.26000000","0.00070000"],["79926.75000000","1.04939000"],["79927.32000000","0.00000000"],["79937.33000000","0.00014000"],["79954.12000000","0.09203000"],["80018.06000000","0.00400000"],["80632.22000000","0.00010000"]]}}}
{"rx_ns": 13878097481800, "frame": {"stream":"btcusdt@depth@100ms","data":{"e":"depthUpdate","E":1787650873314,"s":"BTCUSDT","U":99118602130,"u":99118602200,"b":[["79913.00000000","1.72151000"],["79912.95000000","0.05014000"],["79912.55000000","0.00007000"],["79912.54000000","1.18418000"],["79912.53000000","1.04953000"],["79912.52000000","0.00000000"],["79912.40000000","0.00000000"],["79911.80000000","0.00000000"],["79911.72000000","0.02137000"],["79911.50000000","0.00007000"],["79911.49000000","0.12074000"],["79911.20000000","0.00014000"],["79910.89000000","0.00007000"],["79910.88000000","0.12535000"],["79910.84000000","0.00007000"],["79910.83000000","0.00007000"],["79910.78000000","0.22900000"],["79910.75000000","0.00000000"],["79910.00000000","0.00007000"],["79909.60000000","0.00000000"],["79908.98000000","0.00007000"],["79908.97000000","0.39538000"],["79908.42000000","0.00000000"],["79812.32000000","0.00025000"],["79802.06000000","0.00000000"],["79700.91000000","0.00023000"],["79699.01000000","0.00770000"],["78714.30000000","0.00000000"],["71921.70000000","0.00187000"],["65146.32000000","0.01188000"],["63922.00000000","0.01030000"]],"a":[["79913.01000000","0.90022000"],["79914.00000000","0.02435000"],["79915.11000000","0.00000000"],["79915.15000000","0.00000000"],["79915.98000000","0.05608000"],["79918.00000000","0.02414000"],["79918.41000000","0.06124000"],["79920.01000000","0.00000000"],["80001.81000000","0.00000000"],["80012.11000000","0.00025000"]]}}}
{"rx_ns": 13878196066600, "frame": {"stream":"btcusdt@depth@100ms","data":{"e":"depthUpdate","E":1787650873414,"s":"BTCUSDT","U":99118602201,"u":99118602239,"b":[["79913.00000000","1.72151000"],["79912.95000000","0.05014000"],["79912.54000000","1.18432000"],["79911.20000000","0.00007000"],["79910.88000000","0.12528000"],["79910.83000000","0.00000000"],["79759.54000000","0.00400000"],["78714.30000000","0.00030000"],["71921.70000000","0.00219000"]],"a":[["79913.01000000","0.90036000"],["79913.02000000","0.00063000"],["79915.41000000","0.06117000"],["79916.59000000","0.06145000"],["79917.19000000","0.00007000"],["79917.20000000","0.26168000"],["79917.99000000","0.00000000"],["79918.41000000","0.06131000"],["79918.47000000","0.11757000"],["79918.75000000","0.42254000"],["79920.33000000","0.00145000"],["79920.92000000","0.00000000"],["79923.19000000","0.00000000"],["79924.96000000","0.00000000"],["80012.00000000","1.41666000"],["80013.11000000","1.95350000"],["80080.17000000","0.00000000"],["80107.95000000","0.02471000"],["80160.31000000","0.00000000"],["80188.06000000","0.05624000"]]}}}
{"rx_ns": 13878312909100, "frame": {"stream":"btcusdt@depth@100ms","data":{"e":"depthUpdate","E":1787650873514,"s":"BTCUSDT","U":99118602240,"u":99118602267,"b":[["79899.81000000","0.00000000"],["79895.99000000","0.00000000"],["79873.79000000","0.02000000"],["71921.70000000","0.00219000"],["63930.40000000","0.00031000"]],"a":[["79913.01000000","0.90043000"],["79913.02000000","0.00070000"],["79914.00000000","0.02442000"],["79915.40000000","0.00007000"],["79915.41000000","0.06131000"],["79915.98000000","0.05615000"],["79916.59000000","0.06138000"],["79917.20000000","0.26175000"],["79917.78000000","0.00622000"],["79917.80000000","0.05600000"],["79923.38000000","0.00048000"],["79929.58000000","0.00190000"]]}}}
{"rx_ns": 13878397290900, "frame": {"stream":"btcusdt@depth@100ms","data":{"e":"depthUpdate","E":1787650873614,"s":"BTCUSDT","U":99118602268,"u":99118602301,"b":[["79911.50000000","0.00000000"],["79911.49000000","0.00021000"],["79910.88000000","0.12535000"],["79910.86000000","0.00007000"],["79910.85000000","0.12053000"],["79910.00000000","0.00007000"],["79908.98000000","0.00007000"],["79908.42000000","0.00007000"],["79500.00000000","10.26043000"],["71921.70000000","0.00219000"],["63930.40000000","0.00000000"]],"a":[["79913.01000000","0.90049000"],["79913.02000000","0.00083000"],["79913.03000000","0.00013000"],["79917.19000000","0.00007000"],["79917.20000000","0.26175000"],["79917.79000000","0.00007000"],["79918.40000000","0.00000000"],["79918.41000000","0.06124000"],["79919.01000000","0.00000000"],["79925.99000000","0.02056000"],["79976.81000000","0.02000000"],["80047.45000000","0.01960000"],["80066.02000000","0.00400000"],["80092.15000000","0.00000000"]]}}}
{"rx_ns": 13878496553100, "frame": {"stream":"btcusdt@depth@100ms","data":{"e":"depthUpdate","E":1787650873714,"s":"BTCUSDT","U":99118602302,"u":99118602325,"b":[["79911.72000000","0.02137000"],["79911.49000000","0.00007000"],["79910.88000000","0.12542000"],["79910.85000000","0.12060000"],["79853.62000000","0.03129000"],["79773.94000000","0.00875000"],["79720.34000000","0.00000000"],["71921.70000000","0.00235000"],["63930.40000000","0.00000000"]],"a":[["79920.40000000","0.00215000"],["79925.70000000","0.00048000"],["80013.63000000","0.00000000"],["80087.31000000","0.00000000"],["81111.71000000","0.00030000"]]}}}
{"rx_ns": 13878621170100, "frame": {"stream":"btcusdt@depth@100ms","data":{"e":"depthUpdate","E":1787650873814,"s":"BTCUSDT","U":99118602326,"u":99118602340,"b":[["79903.63000000","0.26111000"],["79897.78000000","0.00000000"],["79853.62000000","0.00000000"],["79816.47000000","0.00000000"],["79773.94000000","0.00000000"],["71921.70000000","0.00251000"],["71921.00000000","0.00017000"],["63930.40000000","0.00000000"]],"a":[["79929.76000000","0.00000000"],["80024.72000000","0.02804000"],["80137.98000000","0.00400000"],["82000.00000000","122.76952000"]]}}}
{"rx_ns": 13878696222000, "frame": {"stream":"btcusdt@depth@100ms","data":{"e":"depthUpdate","E":1787650873914,"s":"BTCUSDT","U":99118602341,"u":99118602357,"b":[["79913.00000000","1.71858000"],["79911.72000000","0.02144000"],["79911.63000000","0.00014000"],["79897.78000000","0.00007000"],["79785.00000000","0.04407000"],["79739.28000000","4.62081000"],["71921.70000000","0.00240000"]],"a":[["79913.01000000","0.90049000"],["79919.61000000","0.00000000"],["79919.98000000","0.00000000"],["79929.76000000","0.00007000"],["80107.62000000","4.57464000"]]}}}
