{"captured_at": "2026-08-26T15:16:24.799051+00:00", "url": "wss://data-stream.binance.vision/ws/atomeur@depth@100ms", "venue": "binance", "symbol": "ATOMEUR", "streams": ["depth@100ms"], "combined": false, "rest_url": "https://data-api.binance.vision/api/v3/depth?symbol=ATOMEUR&limit=100", "rest_limit": 100, "rest_weight_per_fetch": 5, "snapshot_every_s": 0.0, "tool_version": "0.1.0", "clock": "perf_counter_ns", "capture_mode": "baseline", "cycles": 1, "origin_sent": null, "handshake_status": "HTTP/1.1 101 Switching Protocols"}
{"rx_ns": 120396662098800, "kind": "rest", "req": {"method": "GET", "url": "https://data-api.binance.vision/api/v3/depth?symbol=ATOMEUR&limit=100", "limit": 100, "weight": 5, "sent_ns": 120388799830200, "status": 200, "used_weight_1m": "5", "recv_ns": 120389838124200}, "frame": {"lastUpdateId":236593428,"bids":[["1.29500000","66.33000000"],["1.29100000","23.42000000"],["1.29000000","344.02000000"],["1.28900000","1387.06000000"],["1.28100000","87.78000000"],["1.24700000","40.75000000"],["1.06200000","10.00000000"],["1.00000000","436.41000000"],["0.93800000","10.77000000"],["0.62400000","8.02000000"],["0.50400000","11.90000000"],["0.50200000","36.79000000"],["0.50000000","180.00000000"]],"asks":[["1.29800000","66.15000000"],["1.29900000","290.59000000"],["1.30000000","66.07000000"],["1.30200000","65.98000000"],["1.30400000","247.68000000"],["1.34500000","323.46000000"],["1.34600000","149.35000000"],["1.38400000","65.21000000"],["1.39400000","46.85000000"],["1.45000000","5.00000000"],["1.50000000","82.43000000"],["1.52900000","47.82000000"],["1.53600000","100.00000000"],["1.55200000","10.00000000"],["1.70000000","80.00000000"],["1.72000000","20.00000000"],["1.80000000","60.00000000"],["1.86000000","10.00000000"],["1.90000000","180.00000000"],["1.93500000","10.00000000"],["1.95800000","9.45000000"],["2.00000000","780.00000000"],["2.04000000","299.93000000"],["2.04300000","20.00000000"],["2.10000000","60.00000000"],["2.17600000","10.00000000"],["2.20000000","82.69000000"],["2.24100000","10.00000000"],["2.29900000","10.00000000"],["2.30000000","60.00000000"],["2.40000000","75.00000000"],["2.43100000","10.00000000"],["2.46000000","5.00000000"],["2.50000000","11.22000000"],["2.58600000","10.00000000"],["2.60000000","286.18000000"],["2.70000000","105.00000000"],["2.72500000","10.00000000"],["2.80000000","60.00000000"],["2.88700000","10.00000000"],["2.90000000","50.00000000"],["2.99000000","16.72000000"],["3.00000000","50.00000000"],["3.02600000","10.00000000"],["3.07900000","105.48000000"],["3.10000000","90.25000000"],["3.16900000","20.00000000"],["3.20000000","50.00000000"],["3.27500000","99.17000000"],["3.30000000","54.42000000"],["3.40000000","50.00000000"],["3.45000000","44.95000000"],["3.45100000","20.00000000"],["3.46500000","93.72000000"],["3.50000000","52.52000000"],["3.54000000","1.42000000"],["3.60000000","30.00000000"],["3.66600000","88.57000000"],["3.70000000","30.00000000"],["3.80000000","30.00000000"],["3.85400000","20.00000000"],["3.85900000","84.15000000"],["3.90000000","30.00000000"],["3.92000000","28.11000000"],["3.94300000","23.79000000"],["4.00000000","65.94000000"],["4.05000000","50.00000000"],["4.14100000","20.00000000"],["4.21700000","4.65000000"],["4.25000000","236.83000000"],["4.30000000","30.00000000"],["4.38100000","9.15000000"],["4.41800000","24.90000000"],["4.45000000","3.00000000"],["4.49500000","20.00000000"],["4.50000000","43.72000000"],["4.50200000","2.22000000"],["4.60000000","3.00000000"],["4.68000000","2.00000000"],["4.80000000","25.00000000"],["4.81100000","20.00000000"],["4.82600000","2.07000000"],["4.83300000","25.47000000"],["4.92100000","8.13000000"],["5.00000000","77.37000000"],["5.30000000","20.00000000"],["5.48000000","23.72000000"],["5.50000000","20.91000000"],["5.70000000","588.29000000"],["5.77400000","1.03000000"],["5.80000000","20.00000000"],["6.00000000","20.00000000"],["6.02500000","1.65000000"],["6.10000000","34.90000000"],["6.30000000","20.00000000"],["6.50000000","20.00000000"],["6.60000000","6.37000000"],["6.65000000","61.87000000"],["6.80000000","20.00000000"],["6.81900000","1.00000000"]]}}
{"rx_ns": 120396662098800, "frame": {"e":"depthUpdate","E":1787757393791,"s":"ATOMEUR","U":236593429,"u":236593430,"b":[["1.29100000","0.00000000"]],"a":[["1.29800000","356.74000000"]]}}
{"rx_ns": 120396789863400, "frame": {"e":"depthUpdate","E":1787757393891,"s":"ATOMEUR","U":236593431,"u":236593431,"b":[],"a":[["1.29900000","0.00000000"]]}}
{"rx_ns": 120400056941600, "frame": {"e":"depthUpdate","E":1787757397191,"s":"ATOMEUR","U":236593432,"u":236593432,"b":[],"a":[["1.29800000","290.59000000"]]}}
{"rx_ns": 120409356933900, "frame": {"e":"depthUpdate","E":1787757406491,"s":"ATOMEUR","U":236593433,"u":236593433,"b":[],"a":[["1.29800000","0.00000000"]]}}
{"rx_ns": 120409456710600, "frame": {"e":"depthUpdate","E":1787757406591,"s":"ATOMEUR","U":236593434,"u":236593434,"b":[],"a":[["1.29900000","290.59000000"]]}}
{"rx_ns": 120413757007000, "kind": "control", "ctl": {"op": "ping", "recv_ns": 120411615406100, "pong_ns": 120411615506600, "payload_len": 13, "payload_b64": "MTc4Nzc1NzQwODc0Mw=="}, "frame": null}
{"rx_ns": 120413757007000, "frame": {"e":"depthUpdate","E":1787757410891,"s":"ATOMEUR","U":236593435,"u":236593436,"b":[["1.29700000","343.80000000"],["1.29600000","74.81000000"]],"a":[]}}
{"rx_ns": 120415566200300, "frame": {"e":"depthUpdate","E":1787757412691,"s":"ATOMEUR","U":236593437,"u":236593437,"b":[],"a":[["1.29900000","0.00000000"]]}}
{"rx_ns": 120415657648800, "frame": {"e":"depthUpdate","E":1787757412791,"s":"ATOMEUR","U":236593438,"u":236593438,"b":[],"a":[["1.29900000","290.59000000"]]}}
{"rx_ns": 120416656685700, "frame": {"e":"depthUpdate","E":1787757413791,"s":"ATOMEUR","U":236593439,"u":236593440,"b":[],"a":[["1.29900000","0.00000000"],["1.30000000","356.66000000"]]}}
{"rx_ns": 120416956964300, "frame": {"e":"depthUpdate","E":1787757414091,"s":"ATOMEUR","U":236593441,"u":236593441,"b":[],"a":[["1.29900000","290.59000000"]]}}
{"rx_ns": 120417055871500, "frame": {"e":"depthUpdate","E":1787757414191,"s":"ATOMEUR","U":236593442,"u":236593442,"b":[],"a":[["1.30000000","66.07000000"]]}}
{"rx_ns": 120417156636500, "frame": {"e":"depthUpdate","E":1787757414291,"s":"ATOMEUR","U":236593443,"u":236593444,"b":[],"a":[["1.29900000","0.00000000"],["1.30100000","290.59000000"]]}}
{"rx_ns": 120423559995800, "frame": {"e":"depthUpdate","E":1787757420691,"s":"ATOMEUR","U":236593445,"u":236593445,"b":[["1.29600000","0.00000000"]],"a":[]}}
{"rx_ns": 120423656484900, "frame": {"e":"depthUpdate","E":1787757420791,"s":"ATOMEUR","U":236593446,"u":236593449,"b":[["1.29700000","0.00000000"],["1.29600000","0.00000000"],["1.29000000","687.82000000"]],"a":[]}}
{"rx_ns": 120424259369900, "frame": {"e":"depthUpdate","E":1787757421391,"s":"ATOMEUR","U":236593450,"u":236593451,"b":[["1.29700000","343.80000000"],["1.29600000","650.85000000"]],"a":[]}}
{"rx_ns": 120429856667600, "frame": {"e":"depthUpdate","E":1787757426991,"s":"ATOMEUR","U":236593452,"u":236593452,"b":[["1.29500000","98.95000000"]],"a":[]}}
{"rx_ns": 120429959102800, "frame": {"e":"depthUpdate","E":1787757427091,"s":"ATOMEUR","U":236593453,"u":236593453,"b":[],"a":[["1.29900000","290.59000000"]]}}
{"rx_ns": 120430062439600, "frame": {"e":"depthUpdate","E":1787757427191,"s":"ATOMEUR","U":236593454,"u":236593454,"b":[],"a":[["1.30100000","0.00000000"]]}}
{"rx_ns": 120435256492700, "kind": "control", "ctl": {"op": "ping", "recv_ns": 120431572450800, "pong_ns": 120431572593500, "payload_len": 13, "payload_b64": "MTc4Nzc1NzQyODcwNQ=="}, "frame": null}
{"rx_ns": 120435256492700, "frame": {"e":"depthUpdate","E":1787757432391,"s":"ATOMEUR","U":236593455,"u":236593455,"b":[["1.29600000","0.00000000"]],"a":[]}}
{"rx_ns": 120435456232800, "frame": {"e":"depthUpdate","E":1787757432591,"s":"ATOMEUR","U":236593456,"u":236593458,"b":[["1.29700000","0.00000000"],["1.29600000","510.67000000"]],"a":[]}}
{"rx_ns": 120435764591800, "frame": {"e":"depthUpdate","E":1787757432891,"s":"ATOMEUR","U":236593459,"u":236593459,"b":[["1.29500000","66.33000000"]],"a":[]}}
{"rx_ns": 120440256298500, "frame": {"e":"depthUpdate","E":1787757437391,"s":"ATOMEUR","U":236593460,"u":236593461,"b":[["1.29000000","1030.56000000"],["1.28900000","1043.80000000"]],"a":[]}}
{"rx_ns": 120467064141400, "kind": "control", "ctl": {"op": "ping", "recv_ns": 120451630002100, "pong_ns": 120451630102000, "payload_len": 13, "payload_b64": "MTc4Nzc1NzQ0ODc2NQ=="}, "frame": null}
{"rx_ns": 120467064141400, "frame": {"e":"depthUpdate","E":1787757464191,"s":"ATOMEUR","U":236593462,"u":236593463,"b":[["1.29700000","66.11000000"]],"a":[["1.29900000","0.00000000"]]}}
{"rx_ns": 120467163592500, "frame": {"e":"depthUpdate","E":1787757464291,"s":"ATOMEUR","U":236593464,"u":236593464,"b":[],"a":[["1.30000000","356.66000000"]]}}
{"rx_ns": 120468159117300, "frame": {"e":"depthUpdate","E":1787757465291,"s":"ATOMEUR","U":236593465,"u":236593466,"b":[["1.29800000","343.80000000"],["1.29000000","686.54000000"]],"a":[["1.30000000","66.07000000"]]}}
{"rx_ns": 120468263693000, "frame": {"e":"depthUpdate","E":1787757465391,"s":"ATOMEUR","U":236593467,"u":236593467,"b":[],"a":[["1.30100000","290.59000000"]]}}
{"rx_ns": 120471867914100, "kind": "control", "ctl": {"op": "ping", "recv_ns": 120471593286100, "pong_ns": 120471593488600, "payload_len": 13, "payload_b64": "MTc4Nzc1NzQ2ODcyOA=="}, "frame": null}
{"rx_ns": 120471867914100, "frame": {"e":"depthUpdate","E":1787757468991,"s":"ATOMEUR","U":236593468,"u":236593468,"b":[["1.29600000","543.28000000"]],"a":[]}}
{"rx_ns": 120472256015400, "frame": {"e":"depthUpdate","E":1787757469391,"s":"ATOMEUR","U":236593469,"u":236593469,"b":[],"a":[["1.30000000","0.00000000"]]}}
{"rx_ns": 120473357866800, "frame": {"e":"depthUpdate","E":1787757470491,"s":"ATOMEUR","U":236593470,"u":236593470,"b":[],"a":[["1.30000000","18.30000000"]]}}
{"rx_ns": 120473570427700, "frame": {"e":"depthUpdate","E":1787757470691,"s":"ATOMEUR","U":236593471,"u":236593471,"b":[],"a":[["1.30000000","0.00000000"]]}}
{"rx_ns": 120483955951800, "frame": {"e":"depthUpdate","E":1787757481091,"s":"ATOMEUR","U":236593472,"u":236593472,"b":[["1.29600000","510.67000000"]],"a":[]}}
{"rx_ns": 120487757263700, "frame": {"e":"depthUpdate","E":1787757484891,"s":"ATOMEUR","U":236593473,"u":236593474,"b":[],"a":[["1.30100000","0.00000000"],["1.30300000","66.07000000"]]}}
{"rx_ns": 120488055708300, "frame": {"e":"depthUpdate","E":1787757485191,"s":"ATOMEUR","U":236593475,"u":236593475,"b":[],"a":[["1.30100000","290.59000000"]]}}
{"rx_ns": 120500254915200, "kind": "control", "ctl": {"op": "ping", "recv_ns": 120491568035100, "pong_ns": 120491568149200, "payload_len": 13, "payload_b64": "MTc4Nzc1NzQ4ODcwMg=="}, "frame": null}
{"rx_ns": 120500254915200, "frame": {"e":"depthUpdate","E":1787757497391,"s":"ATOMEUR","U":236593476,"u":236593477,"b":[["1.29100000","343.40000000"],["1.29000000","343.80000000"]],"a":[]}}
{"rx_ns": 120506462510700, "frame": {"e":"depthUpdate","E":1787757503591,"s":"ATOMEUR","U":236593478,"u":236593478,"b":[["1.29700000","98.71000000"]],"a":[]}}
{"rx_ns": 120511854897300, "kind": "control", "ctl": {"op": "ping", "recv_ns": 120511630861600, "pong_ns": 120511630946600, "payload_len": 13, "payload_b64": "MTc4Nzc1NzUwODc2NQ=="}, "frame": null}
{"rx_ns": 120511854897300, "frame": {"e":"depthUpdate","E":1787757508991,"s":"ATOMEUR","U":236593479,"u":236593481,"b":[],"a":[["1.30100000","0.00000000"],["1.30400000","0.00000000"],["1.30800000","247.68000000"]]}}
{"rx_ns": 120511954947800, "frame": {"e":"depthUpdate","E":1787757509091,"s":"ATOMEUR","U":236593482,"u":236593482,"b":[],"a":[["1.30100000","290.59000000"]]}}
{"rx_ns": 120514856747900, "frame": {"e":"depthUpdate","E":1787757511991,"s":"ATOMEUR","U":236593483,"u":236593486,"b":[["1.29900000","66.02000000"]],"a":[["1.30100000","0.00000000"]]}}
{"rx_ns": 120514967147500, "frame": {"e":"depthUpdate","E":1787757512091,"s":"ATOMEUR","U":236593487,"u":236593487,"b":[],"a":[["1.30200000","356.57000000"]]}}
{"rx_ns": 120524554357200, "frame": {"e":"depthUpdate","E":1787757521691,"s":"ATOMEUR","U":236593488,"u":236593488,"b":[],"a":[["1.30300000","156.06000000"]]}}
{"rx_ns": 120533955147900, "kind": "control", "ctl": {"op": "ping", "recv_ns": 120531587714600, "pong_ns": 120531587797700, "payload_len": 13, "payload_b64": "MTc4Nzc1NzUyODcyMw=="}, "frame": null}
{"rx_ns": 120533955147900, "frame": {"e":"depthUpdate","E":1787757531091,"s":"ATOMEUR","U":236593489,"u":236593491,"b":[["1.29900000","0.00000000"]],"a":[["1.30100000","356.57000000"]]}}
{"rx_ns": 120534099958100, "frame": {"e":"depthUpdate","E":1787757531191,"s":"ATOMEUR","U":236593492,"u":236593492,"b":[],"a":[["1.30200000","65.98000000"]]}}
{"rx_ns": 120544154337600, "frame": {"e":"depthUpdate","E":1787757541291,"s":"ATOMEUR","U":236593493,"u":236593494,"b":[],"a":[["1.30100000","446.57000000"],["1.30300000","66.07000000"]]}}
{"rx_ns": 120548067520800, "frame": {"e":"depthUpdate","E":1787757545191,"s":"ATOMEUR","U":236593495,"u":236593495,"b":[["1.29700000","66.11000000"]],"a":[]}}
{"rx_ns": 120549754349900, "frame": {"e":"depthUpdate","E":1787757546891,"s":"ATOMEUR","U":236593496,"u":236593497,"b":[],"a":[["1.30000000","311.47000000"]]}}
{"rx_ns": 120549854637000, "frame": {"e":"depthUpdate","E":1787757546991,"s":"ATOMEUR","U":236593498,"u":236593498,"b":[],"a":[["1.30100000","155.98000000"]]}}
{"rx_ns": 120550058892600, "frame": {"e":"depthUpdate","E":1787757547195,"s":"ATOMEUR","U":236593499,"u":236593499,"b":[["1.29800000","0.00000000"]],"a":[]}}
{"rx_ns": 120550155053100, "frame": {"e":"depthUpdate","E":1787757547291,"s":"ATOMEUR","U":236593500,"u":236593500,"b":[],"a":[["1.29900000","290.59000000"]]}}
{"rx_ns": 120550254139900, "frame": {"e":"depthUpdate","E":1787757547391,"s":"ATOMEUR","U":236593501,"u":236593502,"b":[],"a":[["1.30000000","86.90000000"]]}}
{"rx_ns": 120550355153700, "frame": {"e":"depthUpdate","E":1787757547491,"s":"ATOMEUR","U":236593503,"u":236593505,"b":[],"a":[["1.29900000","290.59000000"],["1.30000000","377.49000000"]]}}
{"rx_ns": 120550454360500, "frame": {"e":"depthUpdate","E":1787757547591,"s":"ATOMEUR","U":236593506,"u":236593506,"b":[],"a":[["1.30000000","86.90000000"]]}}
{"rx_ns": 120550554637600, "frame": {"e":"depthUpdate","E":1787757547691,"s":"ATOMEUR","U":236593507,"u":236593507,"b":[],"a":[["1.30000000","410.36000000"],["1.34500000","0.00000000"]]}}
{"rx_ns": 120551662723200, "kind": "control", "ctl": {"op": "ping", "recv_ns": 120551551679700, "pong_ns": 120551551786900, "payload_len": 13, "payload_b64": "MTc4Nzc1NzU0ODY4OA=="}, "frame": null}
{"rx_ns": 120551662723200, "frame": {"e":"depthUpdate","E":1787757548791,"s":"ATOMEUR","U":236593508,"u":236593508,"b":[],"a":[["1.30000000","86.90000000"],["1.34500000","323.46000000"]]}}
{"rx_ns": 120551753137400, "frame": {"e":"depthUpdate","E":1787757548891,"s":"ATOMEUR","U":236593509,"u":236593511,"b":[],"a":[["1.29900000","290.59000000"],["1.30000000","377.49000000"]]}}
{"rx_ns": 120551857809700, "frame": {"e":"depthUpdate","E":1787757548991,"s":"ATOMEUR","U":236593512,"u":236593512,"b":[],"a":[["1.30000000","86.90000000"]]}}
{"rx_ns": 120563354630800, "frame": {"e":"depthUpdate","E":1787757560491,"s":"ATOMEUR","U":236593513,"u":236593513,"b":[],"a":[["1.30100000","65.98000000"]]}}
{"rx_ns": 120569553720500, "frame": {"e":"depthUpdate","E":1787757566691,"s":"ATOMEUR","U":236593514,"u":236593514,"b":[["1.29600000","343.80000000"]],"a":[]}}
{"rx_ns": 120570453814900, "frame": {"e":"depthUpdate","E":1787757567591,"s":"ATOMEUR","U":236593515,"u":236593516,"b":[["1.29600000","0.00000000"],["1.29200000","343.80000000"]],"a":[]}}
{"rx_ns": 120576953781400, "kind": "control", "ctl": {"op": "ping", "recv_ns": 120571619655700, "pong_ns": 120571619736400, "payload_len": 13, "payload_b64": "MTc4Nzc1NzU2ODc1Nw=="}, "frame": null}
{"rx_ns": 120576953781400, "frame": {"e":"depthUpdate","E":1787757574091,"s":"ATOMEUR","U":236593517,"u":236593517,"b":[["1.29500000","98.96000000"]],"a":[]}}
{"rx_ns": 120579856081800, "frame": {"e":"depthUpdate","E":1787757576991,"s":"ATOMEUR","U":236593518,"u":236593520,"b":[["1.29800000","343.80000000"],["1.29500000","66.33000000"]],"a":[["1.29900000","0.00000000"]]}}
{"rx_ns": 120579953420300, "frame": {"e":"depthUpdate","E":1787757577091,"s":"ATOMEUR","U":236593521,"u":236593522,"b":[["1.29800000","0.00000000"]],"a":[["1.29900000","290.59000000"]]}}
{"rx_ns": 120583253341700, "frame": {"e":"depthUpdate","E":1787757580391,"s":"ATOMEUR","U":236593523,"u":236593523,"b":[],"a":[["1.29900000","0.00000000"]]}}
{"rx_ns": 120583375288800, "frame": {"e":"depthUpdate","E":1787757580491,"s":"ATOMEUR","U":236593524,"u":236593524,"b":[],"a":[["1.29900000","290.59000000"]]}}
{"rx_ns": 120585755888800, "frame": {"e":"depthUpdate","E":1787757582891,"s":"ATOMEUR","U":236593525,"u":236593525,"b":[],"a":[["1.29900000","0.00000000"]]}}
{"rx_ns": 120585854021800, "frame": {"e":"depthUpdate","E":1787757582991,"s":"ATOMEUR","U":236593526,"u":236593526,"b":[],"a":[["1.30000000","377.49000000"]]}}
{"rx_ns": 120586053958400, "frame": {"e":"depthUpdate","E":1787757583191,"s":"ATOMEUR","U":236593527,"u":236593527,"b":[],"a":[["1.29900000","290.59000000"]]}}
{"rx_ns": 120586156238100, "frame": {"e":"depthUpdate","E":1787757583291,"s":"ATOMEUR","U":236593528,"u":236593528,"b":[],"a":[["1.30000000","86.90000000"]]}}
{"rx_ns": 120586272491500, "frame": {"e":"depthUpdate","E":1787757583391,"s":"ATOMEUR","U":236593529,"u":236593531,"b":[],"a":[["1.29900000","290.59000000"],["1.30000000","377.49000000"]]}}
{"rx_ns": 120586355099000, "frame": {"e":"depthUpdate","E":1787757583491,"s":"ATOMEUR","U":236593532,"u":236593532,"b":[],"a":[["1.30000000","86.90000000"]]}}
{"rx_ns": 120588654020900, "frame": {"e":"depthUpdate","E":1787757585791,"s":"ATOMEUR","U":236593533,"u":236593533,"b":[],"a":[["1.29900000","0.00000000"]]}}
{"rx_ns": 120588757063600, "frame": {"e":"depthUpdate","E":1787757585891,"s":"ATOMEUR","U":236593534,"u":236593534,"b":[],"a":[["1.30000000","377.49000000"]]}}
{"rx_ns": 120596053670500, "kind": "control", "ctl": {"op": "ping", "recv_ns": 120591597124800, "pong_ns": 120591597253600, "payload_len": 13, "payload_b64": "MTc4Nzc1NzU4ODczNQ=="}, "frame": null}
{"rx_ns": 120596053670500, "frame": {"e":"depthUpdate","E":1787757593191,"s":"ATOMEUR","U":236593535,"u":236593535,"b":[["1.29600000","13.50000000"]],"a":[]}}
{"rx_ns": 120600358414500, "frame": {"e":"depthUpdate","E":1787757597491,"s":"ATOMEUR","U":236593536,"u":236593537,"b":[["1.29800000","343.68000000"]],"a":[["1.30000000","356.61000000"]]}}
{"rx_ns": 120600554143600, "frame": {"e":"depthUpdate","E":1787757597691,"s":"ATOMEUR","U":236593538,"u":236593538,"b":[["1.29800000","0.00000000"]],"a":[]}}
{"rx_ns": 120603363970600, "frame": {"e":"depthUpdate","E":1787757600491,"s":"ATOMEUR","U":236593539,"u":236593539,"b":[["1.29800000","343.57000000"]],"a":[]}}
{"rx_ns": 120604956427400, "frame": {"e":"depthUpdate","E":1787757602091,"s":"ATOMEUR","U":236593540,"u":236593542,"b":[["1.29100000","0.00000000"]],"a":[["1.30000000","0.00000000"]]}}
{"rx_ns": 120605053777900, "frame": {"e":"depthUpdate","E":1787757602191,"s":"ATOMEUR","U":236593543,"u":236593544,"b":[["1.29200000","687.98000000"]],"a":[["1.30100000","356.57000000"]]}}
{"rx_ns": 120614953855400, "kind": "control", "ctl": {"op": "ping", "recv_ns": 120611559702700, "pong_ns": 120611559848100, "payload_len": 13, "payload_b64": "MTc4Nzc1NzYwODY5Nw=="}, "frame": null}
{"rx_ns": 120614953855400, "frame": {"e":"depthUpdate","E":1787757612091,"s":"ATOMEUR","U":236593545,"u":236593547,"b":[],"a":[["1.30100000","0.00000000"],["1.30200000","356.57000000"]]}}
{"rx_ns": 120616272888500, "frame": {"e":"depthUpdate","E":1787757613391,"s":"ATOMEUR","U":236593548,"u":236593548,"b":[],"a":[["1.30100000","290.59000000"]]}}
{"rx_ns": 120616359286700, "frame": {"e":"depthUpdate","E":1787757613491,"s":"ATOMEUR","U":236593549,"u":236593553,"b":[],"a":[["1.30100000","290.59000000"],["1.30200000","446.53000000"]]}}
{"rx_ns": 120616459267700, "frame": {"e":"depthUpdate","E":1787757613591,"s":"ATOMEUR","U":236593554,"u":236593554,"b":[],"a":[["1.30200000","155.94000000"]]}}
{"rx_ns": 120617655190800, "frame": {"e":"depthUpdate","E":1787757614791,"s":"ATOMEUR","U":236593555,"u":236593556,"b":[],"a":[["1.30100000","0.00000000"],["1.30200000","65.98000000"]]}}
{"rx_ns": 120617754099400, "frame": {"e":"depthUpdate","E":1787757614891,"s":"ATOMEUR","U":236593557,"u":236593560,"b":[["1.30000000","343.34000000"],["1.29900000","395.99000000"],["1.29000000","0.00000000"]],"a":[["1.30200000","356.57000000"]]}}
