{"rx_ns": 173347159719600, "frame": {"stream":"btcusdt@depth20@100ms","data":{"lastUpdateId":99076754654,"bids":[["78677.99000000","0.85264000"],["78677.98000000","0.00048000"],["78677.97000000","0.00013000"],["78677.80000000","0.05000000"],["78677.27000000","0.00007000"],["78677.10000000","0.00007000"],["78676.74000000","0.00014000"],["78676.73000000","0.04109000"],["78676.63000000","0.00007000"],["78676.11000000","0.00007000"],["78676.00000000","0.00507000"],["78675.99000000","0.00219000"],["78675.84000000","0.00007000"],["78675.74000000","0.00014000"],["78675.73000000","0.31793000"],["78675.48000000","0.00014000"],["78675.47000000","0.04929000"],["78675.20000000","0.00014000"],["78675.19000000","0.04985000"],["78674.74000000","0.00035000"]],"asks":[["78678.00000000","2.08242000"],["78678.01000000","0.00020000"],["78678.02000000","0.00013000"],["78678.03000000","0.00014000"],["78678.04000000","0.02547000"],["78678.60000000","0.00008000"],["78678.64000000","0.00007000"],["78679.53000000","0.00508000"],["78679.54000000","0.00137000"],["78679.55000000","0.00007000"],["78679.77000000","0.00007000"],["78679.85000000","0.00254000"],["78679.99000000","0.00014000"],["78680.00000000","0.02407000"],["78680.41000000","0.00014000"],["78680.42000000","0.04048000"],["78680.48000000","0.00400000"],["78680.69000000","0.00014000"],["78680.70000000","0.05219000"],["78680.88000000","0.00007000"]]}}}
{"rx_ns": 173347159806400, "frame": {"stream":"btcusdt@depth@100ms","data":{"e":"depthUpdate","E":1787603286314,"s":"BTCUSDT","U":99076754629,"u":99076754654,"b":[["78677.99000000","0.85264000"],["78677.85000000","0.00000000"],["78677.80000000","0.05000000"],["78607.29000000","0.00317000"],["78528.01000000","0.00127000"],["78486.67000000","0.00779000"],["78482.12000000","0.00000000"],["77880.19000000","0.00469000"],["77144.55000000","0.00000000"],["70810.20000000","0.00448000"],["62942.00000000","0.00000000"]],"a":[["78678.00000000","2.08242000"],["78678.04000000","0.02547000"],["78679.53000000","0.00508000"],["78682.08000000","0.01358000"]]}}}
{"rx_ns": 173347249045900, "frame": {"stream":"btcusdt@depth20@100ms","data":{"lastUpdateId":99076754681,"bids":[["78677.99000000","0.85278000"],["78677.98000000","0.00055000"],["78677.97000000","0.00013000"],["78677.90000000","0.05000000"],["78677.81000000","0.00007000"],["78677.80000000","0.00007000"],["78677.27000000","0.00007000"],["78677.10000000","0.00007000"],["78676.74000000","0.00014000"],["78676.73000000","0.04109000"],["78676.63000000","0.00007000"],["78676.11000000","0.00007000"],["78676.00000000","0.00507000"],["78675.99000000","0.00219000"],["78675.84000000","0.00007000"],["78675.74000000","0.00014000"],["78675.73000000","0.31793000"],["78675.48000000","0.00014000"],["78675.47000000","0.04929000"],["78675.20000000","0.00014000"]],"asks":[["78678.00000000","2.08242000"],["78678.01000000","0.00020000"],["78678.02000000","0.00013000"],["78678.03000000","0.00014000"],["78678.04000000","0.02547000"],["78678.60000000","0.00008000"],["78678.64000000","0.00007000"],["78679.53000000","0.00515000"],["78679.54000000","0.00137000"],["78679.55000000","0.00007000"],["78679.77000000","0.00007000"],["78679.99000000","0.00014000"],["78680.00000000","0.02407000"],["78680.41000000","0.00014000"],["78680.42000000","0.04048000"],["78680.48000000","0.00400000"],["78680.69000000","0.00014000"],["78680.70000000","0.05219000"],["78680.88000000","0.00007000"],["78680.97000000","0.00014000"]]}}}
{"rx_ns": 173347249146000, "frame": {"stream":"btcusdt@depth@100ms","data":{"e":"depthUpdate","E":1787603286414,"s":"BTCUSDT","U":99076754655,"u":99076754681,"b":[["78677.99000000","0.85278000"],["78677.98000000","0.00055000"],["78677.90000000","0.05000000"],["78677.81000000","0.00007000"],["78677.80000000","0.00007000"],["78674.22000000","0.00000000"],["78672.86000000","0.20852000"],["78672.00000000","0.02400000"],["78664.13000000","0.00000000"],["78649.65000000","0.00400000"],["78608.09000000","1.25956000"],["70810.20000000","0.00432000"],["70810.00000000","0.01283000"]],"a":[["78678.04000000","0.02547000"],["78679.53000000","0.00515000"],["78679.85000000","0.00000000"],["78682.08000000","0.01351000"]]}}}
{"rx_ns": 173347348541700, "frame": {"stream":"btcusdt@depth20@100ms","data":{"lastUpdateId":99076754717,"bids":[["78677.99000000","0.14639000"],["78677.98000000","0.00048000"],["78677.97000000","0.00013000"],["78677.91000000","0.00007000"],["78677.90000000","0.05007000"],["78677.85000000","0.05000000"],["78677.27000000","0.00007000"],["78677.10000000","0.00007000"],["78676.74000000","0.00014000"],["78676.73000000","0.04109000"],["78676.63000000","0.00007000"],["78676.11000000","0.00007000"],["78676.00000000","0.00507000"],["78675.99000000","0.00219000"],["78675.84000000","0.00007000"],["78675.74000000","0.00014000"],["78675.73000000","0.31800000"],["78675.48000000","0.00014000"],["78675.47000000","0.04929000"],["78675.20000000","0.00014000"]],"asks":[["78678.00000000","2.09522000"],["78678.01000000","0.00020000"],["78678.02000000","0.00013000"],["78678.03000000","0.00014000"],["78678.04000000","0.02547000"],["78678.60000000","0.00008000"],["78678.64000000","0.00007000"],["78679.02000000","0.00254000"],["78679.53000000","0.00007000"],["78679.55000000","0.00007000"],["78679.77000000","0.00007000"],["78679.99000000","0.00014000"],["78680.00000000","0.02407000"],["78680.41000000","0.00014000"],["78680.42000000","0.04048000"],["78680.48000000","0.00400000"],["78680.69000000","0.00014000"],["78680.70000000","0.05219000"],["78680.88000000","0.00007000"],["78680.97000000","0.00014000"]]}}}
{"rx_ns": 173347348628300, "frame": {"stream":"btcusdt@depth@100ms","data":{"e":"depthUpdate","E":1787603286514,"s":"BTCUSDT","U":99076754682,"u":99076754717,"b":[["78677.99000000","0.14639000"],["78677.98000000","0.00048000"],["78677.91000000","0.00007000"],["78677.90000000","0.05007000"],["78677.85000000","0.05000000"],["78677.81000000","0.00000000"],["78677.80000000","0.00000000"],["78675.73000000","0.31800000"],["78674.00000000","0.00962000"],["78663.29000000","0.00254000"],["78584.56000000","0.00000000"],["77899.63000000","0.00000000"],["70810.20000000","0.00432000"],["62942.40000000","0.00031000"],["62942.00000000","0.00000000"]],"a":[["78678.00000000","2.09522000"],["78679.02000000","0.00254000"],["78679.53000000","0.00007000"],["78679.54000000","0.00000000"],["78681.19000000","0.00007000"],["78800.55000000","0.01991000"],["78870.80000000","0.00000000"]]}}}
{"rx_ns": 173347443851500, "frame": {"stream":"btcusdt@depth20@100ms","data":{"lastUpdateId":99076754748,"bids":[["78677.99000000","0.14639000"],["78677.98000000","0.00048000"],["78677.97000000","0.00013000"],["78677.96000000","0.00014000"],["78677.95000000","0.05000000"],["78677.90000000","0.00007000"],["78677.85000000","0.00007000"],["78677.27000000","0.00007000"],["78677.10000000","0.00007000"],["78676.74000000","0.00014000"],["78676.73000000","0.04109000"],["78676.63000000","0.00007000"],["78676.11000000","0.00007000"],["78676.00000000","0.00507000"],["78675.99000000","0.00219000"],["78675.84000000","0.00007000"],["78675.74000000","0.00014000"],["78675.73000000","0.31800000"],["78675.48000000","0.00014000"],["78675.47000000","0.04929000"]],"asks":[["78678.00000000","2.09522000"],["78678.01000000","0.00020000"],["78678.02000000","0.00013000"],["78678.03000000","0.00014000"],["78678.04000000","0.02547000"],["78678.60000000","0.00008000"],["78678.64000000","0.00007000"],["78679.02000000","0.00254000"],["78679.55000000","0.00007000"],["78679.77000000","0.00007000"],["78679.99000000","0.00014000"],["78680.00000000","0.02407000"],["78680.41000000","0.00014000"],["78680.42000000","0.04048000"],["78680.48000000","0.00400000"],["78680.69000000","0.00014000"],["78680.70000000","0.05219000"],["78680.88000000","0.00007000"],["78680.97000000","0.00014000"],["78681.20000000","0.00400000"]]}}}
{"rx_ns": 173347444049100, "frame": {"stream":"btcusdt@depth@100ms","data":{"e":"depthUpdate","E":1787603286614,"s":"BTCUSDT","U":99076754718,"u":99076754748,"b":[["78677.99000000","0.14639000"],["78677.96000000","0.00014000"],["78677.95000000","0.05000000"],["78677.91000000","0.00000000"],["78677.90000000","0.00007000"],["78677.86000000","0.00000000"],["78677.85000000","0.00007000"],["78675.20000000","0.00007000"],["78674.00000000","0.00955000"],["78566.23000000","0.00000000"],["70810.20000000","0.00416000"],["62942.40000000","0.00000000"]],"a":[["78678.04000000","0.02547000"],["78679.53000000","0.00000000"],["78680.70000000","0.05219000"],["78681.19000000","0.00000000"],["78682.08000000","0.01358000"],["78683.33000000","0.02259000"],["78761.96000000","0.93649000"]]}}}
{"rx_ns": 173347546685900, "frame": {"stream":"btcusdt@depth20@100ms","data":{"lastUpdateId":99076754806,"bids":[["78677.99000000","0.14632000"],["78677.98000000","0.00048000"],["78677.97000000","0.00013000"],["78677.95000000","0.00007000"],["78677.71000000","0.00014000"],["78677.70000000","0.05000000"],["78677.66000000","0.00007000"],["78677.65000000","0.05000000"],["78677.27000000","0.00007000"],["78677.10000000","0.00007000"],["78676.74000000","0.00014000"],["78676.73000000","0.04109000"],["78676.63000000","0.00007000"],["78676.11000000","0.00007000"],["78676.00000000","0.00507000"],["78675.99000000","0.00219000"],["78675.84000000","0.00007000"],["78675.74000000","0.00014000"],["78675.73000000","0.31800000"],["78675.48000000","0.00014000"]],"asks":[["78678.00000000","2.09522000"],["78678.01000000","0.00020000"],["78678.02000000","0.00013000"],["78678.03000000","0.00014000"],["78678.04000000","0.02547000"],["78678.60000000","0.00008000"],["78678.64000000","0.00007000"],["78679.02000000","0.00254000"],["78679.55000000","0.00007000"],["78679.77000000","0.00007000"],["78679.99000000","0.00014000"],["78680.00000000","0.02407000"],["78680.41000000","0.00014000"],["78680.42000000","0.04048000"],["78680.48000000","0.00400000"],["78680.69000000","0.00014000"],["78680.70000000","0.05219000"],["78680.88000000","0.00007000"],["78680.97000000","0.00014000"],["78681.20000000","0.00400000"]]}}}
{"rx_ns": 173347546770300, "frame": {"stream":"btcusdt@depth@100ms","data":{"e":"depthUpdate","E":1787603286714,"s":"BTCUSDT","U":99076754749,"u":99076754806,"b":[["78677.99000000","0.14632000"],["78677.96000000","0.00000000"],["78677.95000000","0.00007000"],["78677.90000000","0.00000000"],["78677.85000000","0.00000000"],["78677.71000000","0.00014000"],["78677.70000000","0.05000000"],["78677.66000000","0.00007000"],["78677.65000000","0.05000000"],["78675.20000000","0.00000000"],["78674.22000000","0.00000000"],["78674.00000000","0.00962000"],["78284.60000000","0.01000000"],["77893.17000000","0.01000000"],["77503.71000000","0.01000000"],["77116.19000000","0.01000000"],["76730.61000000","0.01000000"],["76346.95000000","0.01000000"],["75965.22000000","0.01000000"],["75585.39000000","0.01000000"],["75207.47000000","0.01000000"],["74831.43000000","0.01000000"],["74457.27000000","0.01000000"],["74084.98000000","0.01000000"],["73714.56000000","0.01000000"],["73345.99000000","0.01000000"],["72979.26000000","0.01000000"],["70810.20000000","0.00416000"]],"a":[["79071.39000000","0.01000000"],["79466.75000000","0.01000000"],["79864.09000000","0.01000000"],["80263.41000000","0.01000000"],["80664.72000000","0.01010000"],["81068.05000000","0.01000000"],["81473.39000000","0.01000000"],["81880.75000000","0.01000000"],["82290.16000000","0.01000000"],["82701.61000000","0.01000000"],["83115.12000000","0.01000000"],["83530.69000000","0.01000000"],["83948.35000000","0.01000000"],["84368.09000000","0.01000000"],["84789.93000000","0.01000000"]]}}}
{"rx_ns": 173347648574200, "frame": {"stream":"btcusdt@depth20@100ms","data":{"lastUpdateId":99076754839,"bids":[["78677.99000000","0.14646000"],["78677.98000000","0.00055000"],["78677.97000000","0.00013000"],["78677.70000000","0.00007000"],["78677.65000000","0.00007000"],["78677.27000000","0.00007000"],["78677.10000000","0.00007000"],["78676.74000000","0.00014000"],["78676.73000000","0.04109000"],["78676.63000000","0.00007000"],["78676.11000000","0.00007000"],["78676.00000000","0.00507000"],["78675.99000000","0.00219000"],["78675.84000000","0.00007000"],["78675.74000000","0.00014000"],["78675.73000000","0.31800000"],["78675.48000000","0.00014000"],["78675.47000000","0.04929000"],["78675.20000000","0.00014000"],["78675.19000000","0.04985000"]],"asks":[["78678.00000000","2.09522000"],["78678.01000000","0.00020000"],["78678.02000000","0.00013000"],["78678.03000000","0.00014000"],["78678.04000000","0.02547000"],["78678.60000000","0.00008000"],["78678.64000000","0.00007000"],["78679.02000000","0.00254000"],["78679.55000000","0.00007000"],["78679.77000000","0.00007000"],["78679.99000000","0.00014000"],["78680.00000000","0.02407000"],["78680.41000000","0.00014000"],["78680.42000000","0.04048000"],["78680.48000000","0.00400000"],["78680.69000000","0.00014000"],["78680.70000000","0.05219000"],["78680.88000000","0.00007000"],["78680.97000000","0.00014000"],["78681.20000000","0.00400000"]]}}}
{"rx_ns": 173347648687100, "frame": {"stream":"btcusdt@depth@100ms","data":{"e":"depthUpdate","E":1787603286814,"s":"BTCUSDT","U":99076754807,"u":99076754839,"b":[["78677.99000000","0.14646000"],["78677.98000000","0.00055000"],["78677.95000000","0.00000000"],["78677.71000000","0.00000000"],["78677.70000000","0.00007000"],["78677.66000000","0.00000000"],["78677.65000000","0.00007000"],["78675.20000000","0.00014000"],["78674.22000000","0.00007000"],["78674.00000000","0.00955000"],["78584.56000000","0.02117000"],["76503.35000000","0.00007000"],["70810.20000000","0.00416000"],["62942.00000000","0.00000000"]],"a":[]}}}
{"rx_ns": 173347738658700, "frame": {"stream":"btcusdt@depth20@100ms","data":{"lastUpdateId":99076754860,"bids":[["78677.99000000","0.14646000"],["78677.98000000","0.00055000"],["78677.97000000","0.00013000"],["78677.27000000","0.00007000"],["78677.10000000","0.00007000"],["78676.74000000","0.00014000"],["78676.73000000","0.04109000"],["78676.63000000","0.00007000"],["78676.11000000","0.00007000"],["78676.00000000","0.00507000"],["78675.99000000","0.00219000"],["78675.84000000","0.00007000"],["78675.74000000","0.00014000"],["78675.73000000","0.31800000"],["78675.48000000","0.00014000"],["78675.47000000","0.04929000"],["78675.20000000","0.00014000"],["78675.19000000","0.04985000"],["78674.74000000","0.00035000"],["78674.48000000","0.00293000"]],"asks":[["78678.00000000","2.47561000"],["78678.01000000","0.00020000"],["78678.02000000","0.00013000"],["78678.03000000","0.00014000"],["78678.04000000","0.02547000"],["78678.60000000","0.00008000"],["78678.64000000","0.00007000"],["78679.02000000","0.00254000"],["78679.04000000","0.00400000"],["78679.55000000","0.00007000"],["78679.77000000","0.00007000"],["78679.99000000","0.00014000"],["78680.00000000","0.02407000"],["78680.41000000","0.00014000"],["78680.42000000","0.04048000"],["78680.48000000","0.00400000"],["78680.69000000","0.00014000"],["78680.70000000","0.05219000"],["78680.88000000","0.00007000"],["78680.97000000","0.00014000"]]}}}
{"rx_ns": 173347738790200, "frame": {"stream":"btcusdt@depth@100ms","data":{"e":"depthUpdate","E":1787603286914,"s":"BTCUSDT","U":99076754840,"u":99076754860,"b":[["78677.99000000","0.14646000"],["78677.70000000","0.00000000"],["78677.65000000","0.00000000"],["78674.00000000","0.00962000"],["78672.86000000","0.20859000"],["70810.20000000","0.00416000"],["70810.18000000","0.00000000"],["62942.00000000","0.00300000"]],"a":[["78678.00000000","2.47561000"],["78679.04000000","0.00400000"],["78714.07000000","0.01270000"],["78717.44000000","0.00007000"]]}}}
{"rx_ns": 173347846208800, "frame": {"stream":"btcusdt@depth20@100ms","data":{"lastUpdateId":99076754876,"bids":[["78677.99000000","0.14639000"],["78677.98000000","0.00048000"],["78677.97000000","0.00013000"],["78677.27000000","0.00007000"],["78677.10000000","0.00007000"],["78676.74000000","0.00014000"],["78676.73000000","0.04109000"],["78676.63000000","0.00007000"],["78676.11000000","0.00007000"],["78676.00000000","0.00507000"],["78675.99000000","0.00219000"],["78675.84000000","0.00007000"],["78675.74000000","0.00014000"],["78675.73000000","0.31800000"],["78675.48000000","0.00014000"],["78675.47000000","0.04929000"],["78675.20000000","0.00014000"],["78675.19000000","0.04985000"],["78674.74000000","0.00035000"],["78674.48000000","0.00293000"]],"asks":[["78678.00000000","2.08875000"],["78678.01000000","0.00020000"],["78678.02000000","0.00013000"],["78678.03000000","0.00014000"],["78678.04000000","0.02547000"],["78678.60000000","0.00008000"],["78678.64000000","0.00007000"],["78679.02000000","0.00254000"],["78679.04000000","0.00400000"],["78679.55000000","0.00007000"],["78679.77000000","0.00007000"],["78679.99000000","0.00014000"],["78680.00000000","0.02407000"],["78680.40000000","0.00635000"],["78680.41000000","0.00014000"],["78680.42000000","0.04048000"],["78680.48000000","0.00400000"],["78680.69000000","0.00014000"],["78680.70000000","0.05219000"],["78680.88000000","0.00007000"]]}}}
{"rx_ns": 173347846286100, "frame": {"stream":"btcusdt@depth@100ms","data":{"e":"depthUpdate","E":1787603287014,"s":"BTCUSDT","U":99076754861,"u":99076754876,"b":[["78677.99000000","0.14639000"],["78677.98000000","0.00048000"],["78584.56000000","0.00000000"],["78566.23000000","2.77319000"],["70810.20000000","0.00432000"],["62942.40000000","0.00031000"],["62942.00000000","0.00000000"]],"a":[["78678.00000000","2.08875000"],["78680.40000000","0.00635000"],["78683.32000000","0.00635000"],["78685.27000000","0.00000000"],["78769.49000000","0.00529000"],["78772.04000000","0.00000000"]]}}}
{"rx_ns": 173347937917000, "frame": {"stream":"btcusdt@depth20@100ms","data":{"lastUpdateId":99076754895,"bids":[["78677.99000000","0.61782000"],["78677.98000000","0.00048000"],["78677.97000000","0.00013000"],["78677.27000000","0.00007000"],["78677.10000000","0.00007000"],["78676.74000000","0.00014000"],["78676.73000000","0.04109000"],["78676.63000000","0.00007000"],["78676.11000000","0.00007000"],["78676.00000000","0.00507000"],["78675.99000000","0.00219000"],["78675.84000000","0.00007000"],["78675.74000000","0.00014000"],["78675.73000000","0.31800000"],["78675.48000000","0.00014000"],["78675.47000000","0.04929000"],["78675.20000000","0.00014000"],["78675.19000000","0.04985000"],["78674.74000000","0.00035000"],["78674.48000000","0.00293000"]],"asks":[["78678.00000000","2.08244000"],["78678.01000000","0.00027000"],["78678.02000000","0.00013000"],["78678.03000000","0.00014000"],["78678.04000000","0.02547000"],["78678.59000000","0.00508000"],["78678.60000000","0.00008000"],["78678.64000000","0.00007000"],["78679.02000000","0.00254000"],["78679.04000000","0.00400000"],["78679.55000000","0.00007000"],["78679.77000000","0.00007000"],["78679.98000000","0.00137000"],["78679.99000000","0.00014000"],["78680.00000000","0.02407000"],["78680.40000000","0.00642000"],["78680.41000000","0.00014000"],["78680.42000000","0.04048000"],["78680.48000000","0.00400000"],["78680.69000000","0.00014000"]]}}}
{"rx_ns": 173347937997200, "frame": {"stream":"btcusdt@depth@100ms","data":{"e":"depthUpdate","E":1787603287114,"s":"BTCUSDT","U":99076754877,"u":99076754895,"b":[["78677.99000000","0.61782000"],["70810.20000000","0.00416000"]],"a":[["78678.00000000","2.08244000"],["78678.01000000","0.00027000"],["78678.59000000","0.00508000"],["78679.98000000","0.00137000"],["78680.00000000","0.02407000"],["78680.40000000","0.00642000"],["78682.08000000","0.01358000"],["78683.32000000","0.00000000"],["78683.33000000","0.02252000"],["78684.58000000","0.00635000"]]}}}
{"rx_ns": 173348038410400, "frame": {"stream":"btcusdt@depth20@100ms","data":{"lastUpdateId":99076754935,"bids":[["78677.99000000","0.61782000"],["78677.98000000","0.00048000"],["78677.97000000","0.00013000"],["78677.27000000","0.00007000"],["78677.10000000","0.00007000"],["78676.74000000","0.00014000"],["78676.73000000","0.04109000"],["78676.63000000","0.00007000"],["78676.11000000","0.00007000"],["78676.00000000","0.00507000"],["78675.99000000","0.00219000"],["78675.84000000","0.00007000"],["78675.74000000","0.00014000"],["78675.73000000","0.31800000"],["78675.48000000","0.00014000"],["78675.47000000","0.04929000"],["78675.20000000","0.00014000"],["78675.19000000","0.04985000"],["78674.74000000","0.00035000"],["78674.48000000","0.00293000"]],"asks":[["78678.00000000","2.08244000"],["78678.01000000","0.00027000"],["78678.02000000","0.00013000"],["78678.03000000","0.00014000"],["78678.04000000","0.02547000"],["78678.59000000","0.00515000"],["78678.60000000","0.00008000"],["78678.64000000","0.00007000"],["78679.02000000","0.00254000"],["78679.04000000","0.00400000"],["78679.55000000","0.00007000"],["78679.77000000","0.00007000"],["78679.98000000","0.00137000"],["78679.99000000","0.00014000"],["78680.00000000","0.02407000"],["78680.40000000","0.00007000"],["78680.41000000","0.00014000"],["78680.42000000","0.04048000"],["78680.48000000","0.00400000"],["78680.69000000","0.00014000"]]}}}
{"rx_ns": 173348038491700, "frame": {"stream":"btcusdt@depth@100ms","data":{"e":"depthUpdate","E":1787603287214,"s":"BTCUSDT","U":99076754896,"u":99076754935,"b":[["78654.35000000","0.00000000"],["78284.60000000","0.00000000"],["77893.17000000","0.00000000"],["77503.71000000","0.00000000"],["77116.19000000","0.00000000"],["76730.61000000","0.00000000"],["76346.95000000","0.00000000"],["75965.22000000","0.00000000"],["75585.39000000","0.00000000"],["75207.47000000","0.00000000"],["74831.43000000","0.00000000"],["74457.27000000","0.00000000"],["74084.98000000","0.00000000"],["73714.56000000","0.00000000"],["73345.99000000","0.00000000"],["72979.26000000","0.00000000"],["70810.20000000","0.00432000"],["62942.40000000","0.00000000"],["62942.39000000","0.00000000"]],"a":[["78678.04000000","0.02547000"],["78678.59000000","0.00515000"],["78680.40000000","0.00007000"],["78682.08000000","0.01351000"],["78682.51000000","0.00635000"],["78701.56000000","0.00000000"],["79071.39000000","0.00000000"],["79466.75000000","0.00000000"],["79864.09000000","0.00000000"],["80263.41000000","0.00000000"],["80664.72000000","0.00010000"],["81068.05000000","0.00000000"],["81473.39000000","0.00000000"],["81880.75000000","0.00000000"],["82290.16000000","0.00000000"],["82701.61000000","0.00000000"],["83115.12000000","0.00000000"],["83530.69000000","0.00000000"],["83948.35000000","0.00000000"],["84368.09000000","0.00000000"],["84789.93000000","0.00000000"]]}}}
{"rx_ns": 173348143115200, "frame": {"stream":"btcusdt@depth20@100ms","data":{"lastUpdateId":99076756638,"bids":[["78662.00000000","0.00453000"],["78661.99000000","0.00021000"],["78661.62000000","0.00007000"],["78660.01000000","0.00014000"],["78660.00000000","0.02400000"],["78659.79000000","0.00007000"],["78659.24000000","0.00007000"],["78659.14000000","0.00014000"],["78659.13000000","0.04867000"],["78658.01000000","0.00014000"],["78658.00000000","0.02400000"],["78657.75000000","0.00007000"],["78657.06000000","0.00007000"],["78656.01000000","0.00014000"],["78656.00000000","0.02400000"],["78655.55000000","0.00010000"],["78655.36000000","0.00014000"],["78655.02000000","0.00007000"],["78654.59000000","0.00007000"],["78654.16000000","0.00007000"]],"asks":[["78662.01000000","2.65272000"],["78662.02000000","0.00020000"],["78662.03000000","0.00013000"],["78662.47000000","0.00014000"],["78663.80000000","0.00400000"],["78663.99000000","0.00014000"],["78664.00000000","1.29466000"],["78664.01000000","0.14601000"],["78664.64000000","0.05311000"],["78665.09000000","0.00014000"],["78665.10000000","0.38224000"],["78665.11000000","0.00014000"],["78665.26000000","0.03014000"],["78665.49000000","0.00014000"],["78665.69000000","0.00007000"],["78665.70000000","2.29018000"],["78666.00000000","0.07741000"],["78666.01000000","0.33604000"],["78666.02000000","0.00539000"],["78666.03000000","0.00021000"]]}}}
{"rx_ns": 173348143235400, "frame": {"stream":"btcusdt@depth@100ms","data":{"e":"depthUpdate","E":1787603287314,"s":"BTCUSDT","U":99076754936,"u":99076756638,"b":[["78677.99000000","0.00000000"],["78677.98000000","0.00000000"],["78677.97000000","0.00000000"],["78677.27000000","0.00000000"],["78677.10000000","0.00000000"],["78676.74000000","0.00000000"],["78676.73000000","0.00000000"],["78676.63000000","0.00000000"],["78676.11000000","0.00000000"],["78676.00000000","0.00000000"],["78675.99000000","0.00000000"],["78675.84000000","0.00000000"],["78675.74000000","0.00000000"],["78675.73000000","0.00000000"],["78675.48000000","0.00000000"],["78675.47000000","0.00000000"],["78675.20000000","0.00000000"],["78675.19000000","0.00000000"],["78674.74000000","0.00000000"],["78674.48000000","0.00000000"],["78674.42000000","0.00000000"],["78674.27000000","0.00000000"],["78674.22000000","0.00000000"],["78674.21000000","0.00000000"],["78674.00000000","0.00000000"],["78673.99000000","0.00000000"],["78673.43000000","0.00000000"],["78673.23000000","0.00000000"],["78673.15000000","0.00000000"],["78673.00000000","0.00000000"],["78672.99000000","0.00000000"],["78672.86000000","0.00000000"],["78672.00000000","0.00000000"],["78671.99000000","0.00000000"],["78671.90000000","0.00000000"],["78671.89000000","0.00000000"],["78671.38000000","0.00000000"],["78670.90000000","0.00000000"],["78670.12000000","0.00000000"],["78670.00000000","0.00000000"],["78669.95000000","0.00000000"],["78669.91000000","0.00000000"],["78669.65000000","0.00000000"],["78669.36000000","0.00000000"],["78669.34000000","0.00000000"],["78668.66000000","0.00000000"],["78668.53000000","0.00000000"],["78668.35000000","0.00000000"],["78668.24000000","0.00000000"],["78668.17000000","0.00000000"],["78668.00000000","0.00000000"],["78667.99000000","0.00000000"],["78667.92000000","0.00000000"],["78667.29000000","0.00000000"],["78667.00000000","0.00000000"],["78666.98000000","0.00000000"],["78666.84000000","0.00000000"],["78666.76000000","0.00000000"],["78666.52000000","0.00000000"],["78666.49000000","0.00000000"],["78666.24000000","0.00000000"],["78666.17000000","0.00000000"],["78666.02000000","0.00000000"],["78666.01000000","0.00000000"],["78666.00000000","0.00000000"],["78665.69000000","0.00000000"],["78665.62000000","0.00000000"],["78665.49000000","0.00000000"],["78665.32000000","0.00000000"],["78665.31000000","0.00000000"],["78665.25000000","0.00000000"],["78665.10000000","0.00000000"],["78665.09000000","0.00000000"],["78664.14000000","0.00000000"],["78664.07000000","0.00000000"],["78664.06000000","0.00000000"],["78664.01000000","0.00000000"],["78664.00000000","0.00000000"],["78663.99000000","0.00000000"],["78663.91000000","0.00000000"],["78663.90000000","0.00000000"],["78663.78000000","0.00000000"],["78663.61000000","0.00000000"],["78663.42000000","0.00000000"],["78663.38000000","0.00000000"],["78663.33000000","0.00000000"],["78663.29000000","0.00000000"],["78663.20000000","0.00000000"],["78663.12000000","0.00000000"],["78662.91000000","0.00000000"],["78662.51000000","0.00000000"],["78662.23000000","0.00000000"],["78662.14000000","0.00000000"],["78662.13000000","0.00000000"],["78662.01000000","0.00000000"],["78662.00000000","0.00453000"],["78661.99000000","0.00021000"],["78661.91000000","0.00000000"],["78661.62000000","0.00007000"],["78661.55000000","0.00000000"],["78661.44000000","0.00000000"],["78661.15000000","0.00000000"],["78661.13000000","0.00000000"],["78660.79000000","0.00000000"],["78660.67000000","0.00000000"],["78660.46000000","0.00000000"],["78660.25000000","0.00000000"],["78660.08000000","0.00000000"],["78660.07000000","0.00000000"],["78660.01000000","0.00014000"],["78659.88000000","0.00000000"],["78659.87000000","0.00000000"],["78659.31000000","0.00000000"],["78659.28000000","0.00000000"],["78659.20000000","0.00000000"],["78659.14000000","0.00014000"],["78659.13000000","0.04867000"],["78659.11000000","0.00000000"],["78659.00000000","0.00000000"],["78658.97000000","0.00000000"],["78658.96000000","0.00000000"],["78658.68000000","0.00000000"],["78658.63000000","0.00000000"],["78658.53000000","0.00000000"],["78658.52000000","0.00000000"],["78658.46000000","0.00000000"],["78658.17000000","0.00000000"],["78658.01000000","0.00014000"],["78657.99000000","0.00000000"],["78657.86000000","0.00000000"],["78657.75000000","0.00007000"],["78657.70000000","0.00000000"],["78657.46000000","0.00000000"],["78657.31000000","0.00000000"],["78656.90000000","0.00000000"],["78656.89000000","0.00000000"],["78656.86000000","0.00000000"],["78656.85000000","0.00000000"],["78656.73000000","0.00000000"],["78656.26000000","0.00000000"],["78656.01000000","0.00014000"],["78655.57000000","0.00000000"],["78655.53000000","0.00000000"],["78655.50000000","0.00000000"],["78655.37000000","0.00000000"],["78654.59000000","0.00007000"],["78654.58000000","0.00000000"],["78654.50000000","0.00000000"],["78654.35000000","0.00000000"],["78654.31000000","0.00000000"],["78654.16000000","0.00007000"],["78654.09000000","0.00000000"],["78654.07000000","0.00000000"],["78654.04000000","0.00000000"],["78653.88000000","0.00007000"],["78653.87000000","0.00000000"],["78653.80000000","0.00000000"],["78653.79000000","0.00000000"],["78653.70000000","0.00000000"],["78653.69000000","0.00000000"],["78653.41000000","0.00000000"],["78653.29000000","0.00000000"],["78652.78000000","0.00000000"],["78652.07000000","0.00000000"],["78652.02000000","0.00000000"],["78651.93000000","0.00000000"],["78651.89000000","0.00000000"],["78651.53000000","0.00000000"],["78651.36000000","0.00000000"],["78651.25000000","0.00000000"],["78651.23000000","0.00000000"],["78651.12000000","0.00000000"],["78651.01000000","0.00007000"],["78650.02000000","0.00000000"],["78650.01000000","0.00007000"],["78650.00000000","0.02400000"],["78649.75000000","0.00000000"],["78649.35000000","0.00000000"],["78649.02000000","0.00000000"],["78648.85000000","0.03000000"],["78648.82000000","0.00000000"],["78648.67000000","0.00000000"],["78648.56000000","0.00000000"],["78648.38000000","0.00321000"],["78648.23000000","0.00000000"],["78648.19000000","0.00000000"],["78648.01000000","0.00000000"],["78647.86000000","0.00007000"],["78646.87000000","0.00000000"],["78646.72000000","0.02000000"],["78646.66000000","0.00000000"],["78646.27000000","0.00007000"],["78646.15000000","0.00000000"],["78646.14000000","0.00007000"],["78645.81000000","0.00325000"],["78645.44000000","0.00000000"],["78645.37000000","0.00000000"],["78645.00000000","0.00007000"],["78644.96000000","0.00000000"],["78644.51000000","0.00000000"],["78644.05000000","0.00007000"],["78644.01000000","1.90515000"],["78644.00000000","0.02400000"],["78643.72000000","0.00007000"],["78643.71000000","0.00000000"],["78643.42000000","0.00000000"],["78643.28000000","0.00000000"],["78643.25000000","0.02288000"],["78643.03000000","0.00000000"],["78642.84000000","0.00000000"],["78642.70000000","0.00000000"],["78642.41000000","0.00000000"],["78642.27000000","0.00007000"],["78641.87000000","0.00321000"],["78641.40000000","1.21952000"],["78641.30000000","0.00000000"],["78641.18000000","0.00254000"],["78640.95000000","0.00000000"],["78640.85000000","0.00000000"],["78640.35000000","0.00000000"],["78640.21000000","0.00000000"],["78640.20000000","0.00150000"],["78640.00000000","0.02400000"],["78639.84000000","0.00007000"],["78639.73000000","0.06531000"],["78639.60000000","0.00000000"],["78639.37000000","0.00000000"],["78639.36000000","0.00000000"],["78639.13000000","0.00000000"],["78639.12000000","1.90515000"],["78639.11000000","0.00000000"],["78638.88000000","0.00000000"],["78638.40000000","0.00007000"],["78638.36000000","0.00007000"],["78638.00000000","0.02407000"],["78637.93000000","0.00329000"],["78637.88000000","0.00000000"],["78637.85000000","0.13946000"],["78637.76000000","0.07537000"],["78637.20000000","0.00000000"],["78637.09000000","1.21952000"],["78637.04000000","0.00000000"],["78636.57000000","0.00000000"],["78636.55000000","0.12000000"],["78636.41000000","0.00000000"],["78635.81000000","0.00000000"],["78635.29000000","0.00000000"],["78634.53000000","0.00007000"],["78634.45000000","0.00000000"],["78634.23000000","0.36224000"],["78634.22000000","0.00000000"],["78634.21000000","0.00000000"],["78634.20000000","0.00000000"],["78633.98000000","0.00000000"],["78633.02000000","0.13254000"],["78633.01000000","0.00000000"],["78632.17000000","1.21959000"],["78632.12000000","0.00000000"],["78630.66000000","0.00007000"],["78630.44000000","0.00000000"],["78630.00000000","0.02400000"],["78629.98000000","0.00000000"],["78629.89000000","0.00000000"],["78629.38000000","0.00000000"],["78629.37000000","0.00000000"],["78628.62000000","0.00000000"],["78628.53000000","0.00000000"],["78628.18000000","1.90515000"],["78628.08000000","0.00000000"],["78627.33000000","0.38159000"],["78626.79000000","0.00007000"],["78626.64000000","0.00000000"],["78626.01000000","0.36224000"],["78625.98000000","0.00000000"],["78625.54000000","0.00000000"],["78625.52000000","0.00000000"],["78625.01000000","0.00000000"],["78625.00000000","0.00000000"],["78624.17000000","0.00000000"],["78624.05000000","0.00000000"],["78624.04000000","0.00000000"],["78623.91000000","0.09515000"],["78623.62000000","0.00000000"],["78623.16000000","0.00400000"],["78622.92000000","0.00007000"],["78622.54000000","1.90515000"],["78622.00000000","0.03400000"],["78621.94000000","1.21952000"],["78621.61000000","0.00000000"],["78621.30000000","0.00000000"],["78621.28000000","0.00000000"],["78620.51000000","0.00000000"],["78619.09000000","0.00000000"],["78619.05000000","0.00000000"],["78618.66000000","0.00000000"],["78618.21000000","0.00000000"],["78618.08000000","0.00400000"],["78617.64000000","0.00000000"],["78617.63000000","0.00000000"],["78617.62000000","0.00000000"],["78617.40000000","0.02000000"],["78616.98000000","0.00000000"],["78616.58000000","0.00000000"],["78616.41000000","0.51113000"],["78616.32000000","0.00000000"],["78616.15000000","0.00000000"],["78616.14000000","0.00000000"],["78615.54000000","0.00400000"],["78615.18000000","0.00000000"],["78615.09000000","0.00000000"],["78614.70000000","0.00000000"],["78614.56000000","0.63609000"],["78614.41000000","0.02758000"],["78613.88000000","0.00000000"],["78613.24000000","0.00007000"],["78613.09000000","1.90515000"],["78613.00000000","0.00400000"],["78612.53000000","0.02362000"],["78612.38000000","1.21952000"],["78612.37000000","0.00000000"],["78612.36000000","0.00000000"],["78612.09000000","0.00000000"],["78611.86000000","0.00000000"],["78611.31000000","0.00007000"],["78610.46000000","0.00400000"],["78610.00000000","0.02475000"],["78609.34000000","1.25954000"],["78608.69000000","0.00000000"],["78608.09000000","0.00000000"],["78607.92000000","0.00400000"],["78607.64000000","0.00000000"],["78607.62000000","0.29356000"],["78607.44000000","0.00007000"],["78607.30000000","0.00000000"],["78607.29000000","0.00000000"],["78607.28000000","0.00000000"],["78606.25000000","0.00000000"],["78605.56000000","0.00000000"],["78604.01000000","0.00000000"],["78603.83000000","0.00000000"],["78603.57000000","0.00007000"],["78602.32000000","0.04490000"],["78601.12000000","1.25975000"],["78594.75000000","0.00000000"],["78586.01000000","0.00316000"],["78585.46000000","0.00000000"],["78584.56000000","0.02117000"],["78574.01000000","0.00247000"],["78572.94000000","1.95796000"],["78571.39000000","1.21952000"],["78566.24000000","0.06656000"],["78566.23000000","0.00000000"],["78561.95000000","1.21952000"],["78558.34000000","0.00000000"],["78552.49000000","1.21952000"],["78542.60000000","0.00000000"],["78537.68000000","0.00000000"],["78535.44000000","1.90515000"],["78528.02000000","0.00127000"],["78528.01000000","0.00000000"],["78526.86000000","0.00000000"],["78525.99000000","1.90515000"],["78521.04000000","0.00000000"],["78516.13000000","0.00000000"],["78511.12000000","0.00000000"],["78506.67000000","0.00127000"],["78498.95000000","1.52347000"],["78495.38000000","0.00000000"],["78479.64000000","0.00126000"],["78463.90000000","0.00000000"],["78457.49000000","3.82420000"],["78455.34000000","0.00000000"],["78448.16000000","0.00000000"],["78432.42000000","0.00000000"],["78413.69000000","0.00000000"],["78360.60000000","0.21930000"],["78352.73000000","0.21930000"],["78348.91000000","0.00000000"],["78333.87000000","0.00000000"],["78278.22000000","0.00014000"],["78176.00000000","0.06588000"],["72358.00000000","0.01396000"],["70810.20000000","0.00000000"],["70810.19000000","0.00009000"],["63032.20000000","0.00018000"],["62942.39000000","0.00000000"],["62942.00000000","0.00000000"]],"a":[["78662.01000000","2.65272000"],["78662.02000000","0.00020000"],["78662.03000000","0.00013000"],["78662.14000000","0.00000000"],["78662.47000000","0.00014000"],["78662.48000000","0.00000000"],["78663.13000000","0.00000000"],["78663.32000000","0.00000000"],["78663.34000000","0.00000000"],["78663.43000000","0.00000000"],["78663.80000000","0.00400000"],["78663.99000000","0.00014000"],["78664.00000000","1.29466000"],["78664.01000000","0.14601000"],["78664.02000000","0.00000000"],["78664.03000000","0.00000000"],["78664.64000000","0.05311000"],["78665.09000000","0.00014000"],["78665.10000000","0.38224000"],["78665.11000000","0.00014000"],["78665.12000000","0.00000000"],["78665.25000000","0.00000000"],["78665.26000000","0.03014000"],["78665.27000000","0.00000000"],["78665.28000000","0.00000000"],["78665.31000000","0.00000000"],["78665.32000000","0.00000000"],["78665.33000000","0.00000000"],["78665.49000000","0.00014000"],["78665.63000000","0.00000000"],["78665.69000000","0.00007000"],["78665.70000000","2.29018000"],["78665.71000000","0.00000000"],["78665.99000000","0.00000000"],["78666.00000000","0.07741000"],["78666.01000000","0.33604000"],["78666.02000000","0.00539000"],["78666.03000000","0.00021000"],["78666.06000000","0.02625000"],["78666.16000000","0.00000000"],["78666.34000000","0.00400000"],["78666.64000000","0.00000000"],["78666.70000000","0.02000000"],["78667.01000000","0.00000000"],["78667.30000000","0.00000000"],["78667.73000000","0.00000000"],["78667.98000000","0.00007000"],["78667.99000000","0.00014000"],["78668.00000000","0.00000000"],["78668.01000000","0.05782000"],["78668.18000000","1.34561000"],["78668.20000000","0.01000000"],["78668.24000000","0.00000000"],["78668.25000000","0.00000000"],["78668.34000000","0.00000000"],["78668.73000000","0.00000000"],["78668.88000000","0.00400000"],["78669.17000000","0.00000000"],["78669.35000000","0.00000000"],["78669.36000000","0.00014000"],["78669.37000000","0.00000000"],["78669.44000000","0.00331000"],["78669.66000000","0.00000000"],["78669.88000000","0.21930000"],["78669.92000000","0.00000000"],["78669.93000000","0.00007000"],["78669.94000000","0.00000000"],["78669.95000000","0.37249000"],["78670.01000000","0.00000000"],["78670.11000000","0.00332000"],["78670.50000000","0.00000000"],["78670.83000000","0.00007000"],["78670.90000000","0.00008000"],["78671.42000000","0.00427000"],["78671.90000000","0.00000000"],["78671.91000000","0.00000000"],["78672.00000000","0.00000000"],["78672.01000000","0.21508000"],["78672.22000000","0.00000000"],["78672.23000000","0.00000000"],["78672.42000000","0.00326000"],["78672.68000000","0.00000000"],["78672.80000000","0.08007000"],["78673.00000000","0.00007000"],["78673.01000000","0.00000000"],["78673.08000000","0.00007000"],["78673.14000000","0.00000000"],["78673.16000000","0.36224000"],["78673.23000000","0.00014000"],["78673.83000000","0.00007000"],["78673.96000000","0.00400000"],["78674.00000000","0.00000000"],["78674.01000000","0.00000000"],["78674.22000000","0.00000000"],["78674.43000000","0.00000000"],["78674.49000000","0.00000000"],["78674.60000000","0.02287000"],["78674.71000000","0.00000000"],["78674.73000000","0.00000000"],["78674.75000000","0.00000000"],["78674.76000000","0.00007000"],["78674.88000000","0.12710000"],["78674.98000000","0.00000000"],["78675.20000000","0.00000000"],["78675.21000000","0.00000000"],["78675.40000000","0.04000000"],["78675.47000000","0.07500000"],["78675.48000000","0.21392000"],["78675.53000000","0.00000000"],["78675.74000000","0.00000000"],["78676.00000000","0.00000000"],["78676.01000000","0.00000000"],["78676.21000000","0.00332000"],["78676.23000000","0.00007000"],["78676.50000000","0.00400000"],["78676.64000000","0.00000000"],["78676.74000000","0.00000000"],["78676.75000000","0.00000000"],["78677.00000000","0.00000000"],["78677.10000000","0.00014000"],["78677.11000000","0.00000000"],["78677.17000000","0.00010000"],["78677.22000000","0.00000000"],["78677.28000000","0.00000000"],["78677.52000000","0.00000000"],["78677.97000000","0.01416000"],["78677.98000000","0.20899000"],["78677.99000000","3.38745000"],["78678.00000000","0.00667000"],["78678.01000000","0.00000000"],["78678.02000000","0.00000000"],["78678.03000000","0.00000000"],["78678.04000000","0.00000000"],["78678.15000000","0.00334000"],["78678.59000000","0.00000000"],["78679.00000000","0.00000000"],["78679.02000000","0.00000000"],["78679.38000000","0.00000000"],["78679.46000000","0.00027000"],["78679.49000000","0.00000000"],["78679.98000000","0.00000000"],["78679.99000000","0.00000000"],["78680.00000000","0.02407000"],["78680.15000000","0.00330000"],["78680.40000000","0.00000000"],["78680.41000000","0.00000000"],["78680.42000000","0.04041000"],["78680.48000000","0.00563000"],["78680.69000000","0.00000000"],["78680.70000000","0.00000000"],["78680.88000000","0.00000000"],["78681.44000000","0.00000000"],["78681.45000000","0.12719000"],["78681.68000000","0.00007000"],["78681.76000000","0.00000000"],["78681.97000000","0.00000000"],["78682.00000000","0.02400000"],["78682.08000000","0.01351000"],["78682.36000000","0.34319000"],["78682.51000000","0.00000000"],["78682.53000000","0.00000000"],["78682.70000000","0.06527000"],["78682.95000000","1.90515000"],["78683.57000000","0.34318000"],["78683.61000000","0.36224000"],["78683.66000000","0.00000000"],["78684.09000000","0.00321000"],["78684.58000000","0.00000000"],["78684.67000000","0.07532000"],["78684.89000000","0.04588000"],["78685.30000000","0.00000000"],["78685.57000000","0.00007000"],["78685.68000000","0.00000000"],["78685.69000000","0.10472000"],["78686.61000000","0.00000000"],["78686.69000000","0.00000000"],["78686.81000000","0.00000000"],["78687.00000000","0.00000000"],["78688.31000000","0.00000000"],["78688.50000000","0.00000000"],["78688.83000000","0.00000000"],["78689.22000000","0.43612000"],["78689.23000000","0.00000000"],["78689.99000000","0.09748000"],["78690.00000000","0.11932000"],["78690.48000000","0.34315000"],["78690.91000000","0.00000000"],["78691.02000000","0.00000000"],["78691.09000000","0.00000000"],["78691.25000000","0.00000000"],["78691.55000000","0.63547000"],["78691.85000000","0.00000000"],["78691.92000000","0.00000000"],["78691.98000000","0.00000000"],["78692.42000000","0.63546000"],["78693.19000000","1.24055000"],["78693.74000000","0.00000000"],["78693.80000000","0.00000000"],["78695.40000000","0.00000000"],["78695.67000000","0.00000000"],["78696.55000000","0.00000000"],["78697.64000000","0.00000000"],["78698.04000000","0.02730000"],["78698.33000000","0.00000000"],["78699.44000000","0.52001000"],["78699.66000000","0.00000000"],["78699.75000000","0.00000000"],["78700.35000000","0.32310000"],["78701.00000000","0.00000000"],["78701.27000000","0.02491000"],["78701.44000000","0.00000000"],["78701.56000000","0.00000000"],["78701.99000000","0.00000000"],["78702.00000000","0.69397000"],["78703.35000000","0.00000000"],["78703.85000000","0.00000000"],["78704.19000000","0.00000000"],["78704.45000000","1.25802000"],["78704.91000000","0.00014000"],["78705.83000000","0.02350000"],["78706.01000000","0.00000000"],["78706.14000000","0.00000000"],["78706.20000000","0.00000000"],["78707.41000000","0.00000000"],["78707.47000000","0.00000000"],["78708.06000000","0.00000000"],["78708.55000000","0.00000000"],["78709.97000000","0.00000000"],["78710.90000000","0.00000000"],["78711.93000000","0.00000000"],["78712.81000000","0.00000000"],["78713.25000000","0.00000000"],["78713.39000000","0.00000000"],["78713.87000000","0.00000000"],["78715.00000000","0.00000000"],["78715.15000000","0.00000000"],["78715.37000000","0.87080000"],["78715.80000000","0.00000000"],["78715.84000000","0.00000000"],["78716.87000000","0.00000000"],["78717.31000000","0.00000000"],["78717.73000000","0.00000000"],["78717.84000000","0.00000000"],["78718.48000000","0.00000000"],["78718.49000000","0.00000000"],["78719.06000000","0.00317000"],["78719.07000000","0.00000000"],["78720.00000000","0.02400000"],["78720.49000000","1.90515000"],["78720.50000000","1.21952000"],["78723.18000000","0.00000000"],["78723.63000000","0.00000000"],["78724.09000000","0.00000000"],["78724.87000000","0.00000000"],["78724.89000000","0.00000000"],["78726.62000000","0.00000000"],["78727.12000000","0.00000000"],["78727.62000000","0.00190000"],["78728.52000000","0.00000000"],["78730.46000000","0.00000000"],["78730.71000000","0.00000000"],["78734.15000000","0.00000000"],["78734.81000000","0.00000000"],["78735.66000000","0.00000000"],["78736.85000000","0.00000000"],["78737.85000000","0.00000000"],["78739.22000000","3.46499000"],["78739.34000000","0.00000000"],["78739.99000000","0.00406000"],["78740.44000000","0.00317000"],["78742.70000000","0.00000000"],["78743.04000000","0.00000000"],["78749.29000000","0.00000000"],["78749.31000000","0.00000000"],["78766.98000000","0.00000000"],["78770.36000000","0.00000000"],["78774.85000000","0.00000000"],["78778.70000000","0.00000000"],["78794.44000000","0.00000000"],["78797.80000000","1.52347000"],["78797.93000000","0.00127000"],["78809.43000000","0.00000000"],["78810.18000000","0.00000000"],["78819.87000000","0.00127000"],["78819.98000000","0.00000000"],["78825.92000000","0.00000000"],["78828.81000000","0.00000000"],["78841.66000000","0.00000000"],["78857.40000000","0.00000000"],["78873.14000000","0.00000000"],["78876.00000000","0.00000000"],["78883.72000000","0.00000000"],["78887.65000000","0.00000000"],["78888.88000000","0.00010000"],["78890.17000000","0.00000000"],["78894.10000000","0.00000000"],["78896.10000000","0.00000000"],["78917.31000000","0.00029000"],["78934.31000000","0.00000000"],["79282.35000000","0.00000000"],["82580.41000000","0.00010000"],["82599.15000000","0.00010000"]]}}}
{"rx_ns": 173348239923600, "frame": {"stream":"btcusdt@depth20@100ms","data":{"lastUpdateId":99076756954,"bids":[["78662.00000000","1.23416000"],["78661.99000000","0.00035000"],["78661.62000000","0.00007000"],["78660.75000000","0.00014000"],["78660.74000000","0.03590000"],["78660.01000000","0.00014000"],["78660.00000000","0.02407000"],["78659.79000000","0.00007000"],["78659.49000000","0.00014000"],["78659.48000000","0.04308000"],["78659.24000000","0.00007000"],["78659.14000000","0.00014000"],["78659.13000000","0.04874000"],["78658.22000000","0.04308000"],["78658.01000000","0.00007000"],["78658.00000000","0.02407000"],["78657.75000000","0.00007000"],["78657.06000000","0.00007000"],["78656.67000000","0.04000000"],["78656.00000000","0.02407000"]],"asks":[["78662.01000000","2.04861000"],["78662.02000000","0.00020000"],["78662.03000000","0.00013000"],["78663.19000000","0.00508000"],["78663.20000000","0.00008000"],["78663.80000000","0.00400000"],["78663.99000000","0.02561000"],["78664.00000000","0.00021000"],["78664.01000000","0.08805000"],["78664.63000000","0.00014000"],["78664.64000000","0.05318000"],["78665.10000000","0.00007000"],["78665.11000000","0.00007000"],["78665.26000000","0.00014000"],["78665.49000000","0.00014000"],["78665.55000000","0.00635000"],["78665.56000000","0.00334000"],["78665.69000000","0.00014000"],["78665.70000000","0.37765000"],["78666.00000000","0.00035000"]]}}}
{"rx_ns": 173348240044000, "frame": {"stream":"btcusdt@depth@100ms","data":{"e":"depthUpdate","E":1787603287414,"s":"BTCUSDT","U":99076756639,"u":99076756954,"b":[["78662.00000000","1.23416000"],["78661.99000000","0.00035000"],["78660.75000000","0.00014000"],["78660.74000000","0.03590000"],["78660.00000000","0.02407000"],["78659.49000000","0.00014000"],["78659.48000000","0.04308000"],["78659.13000000","0.04874000"],["78658.22000000","0.04308000"],["78658.01000000","0.00007000"],["78658.00000000","0.02407000"],["78656.68000000","0.00000000"],["78656.67000000","0.04000000"],["78656.01000000","0.00000000"],["78656.00000000","0.02407000"],["78655.78000000","0.20861000"],["78655.55000000","0.00000000"],["78655.50000000","0.00008000"],["78655.36000000","0.00007000"],["78654.59000000","0.00000000"],["78654.01000000","0.00000000"],["78654.00000000","0.02407000"],["78652.19000000","0.12714000"],["78652.00000000","0.02414000"],["78651.73000000","0.00000000"],["78651.72000000","0.00027000"],["78650.97000000","0.00000000"],["78650.01000000","0.00014000"],["78650.00000000","0.02407000"],["78649.99000000","0.00535000"],["78649.82000000","0.02000000"],["78649.45000000","1.21952000"],["78649.44000000","0.21930000"],["78648.81000000","0.00000000"],["78648.75000000","1.90515000"],["78648.65000000","0.00150000"],["78647.45000000","0.00400000"],["78646.82000000","0.00254000"],["78646.72000000","0.00000000"],["78646.28000000","0.00635000"],["78646.14000000","0.00014000"],["78645.61000000","0.00000000"],["78645.45000000","1.21952000"],["78645.12000000","0.00400000"],["78645.11000000","0.00635000"],["78644.02000000","0.37824000"],["78642.95000000","0.00406000"],["78642.78000000","0.00000000"],["78642.27000000","0.00014000"],["78640.72000000","0.00000000"],["78640.20000000","0.00000000"],["78639.00000000","0.00000000"],["78638.95000000","0.02510000"],["78638.40000000","0.00014000"],["78635.82000000","0.00000000"],["78634.53000000","0.00014000"],["78633.88000000","0.03224000"],["78633.76000000","1.22055000"],["78632.99000000","0.00188000"],["78630.66000000","0.00014000"],["78630.50000000","0.00060000"],["78630.00000000","0.11939000"],["78629.23000000","0.00012000"],["78628.19000000","1.21952000"],["78626.91000000","0.00000000"],["78626.79000000","0.00014000"],["78626.25000000","0.00400000"],["78622.92000000","0.00014000"],["78622.49000000","0.02459000"],["78620.00000000","0.16140000"],["78619.05000000","0.00007000"],["78615.18000000","0.00007000"],["78612.50000000","0.00000000"],["78611.80000000","0.00000000"],["78611.51000000","0.00000000"],["78611.31000000","0.00000000"],["78607.92000000","0.00000000"],["78607.44000000","0.00000000"],["78604.85000000","0.01129000"],["78603.62000000","0.00406000"],["78603.57000000","0.00000000"],["78602.72000000","0.00436000"],["78600.51000000","0.00015000"],["78600.30000000","0.02200000"],["78599.72000000","0.00625000"],["78597.57000000","0.00435000"],["78595.09000000","0.00424000"],["78590.31000000","0.00314000"],["78586.57000000","0.01706000"],["78584.56000000","0.00000000"],["78580.09000000","0.00530000"],["78580.05000000","0.00000000"],["78579.08000000","0.00110000"],["78575.20000000","0.00000000"],["78572.17000000","0.00406000"],["78557.17000000","0.00000000"],["78549.87000000","0.04544000"],["78532.86000000","0.00000000"],["78524.98000000","0.00406000"],["78512.36000000","0.00127000"],["78462.07000000","0.00000000"],["78454.20000000","0.00406000"],["78452.96000000","0.00007000"],["78449.03000000","0.00007000"],["78444.46000000","0.00007000"],["78440.53000000","0.00007000"],["78436.03000000","0.00007000"],["78432.10000000","0.00007000"],["78410.47000000","0.09951000"],["78325.30000000","0.00036000"],["70795.80000000","0.00032000"],["62929.60000000","0.00036000"]],"a":[["78662.01000000","2.04861000"],["78662.47000000","0.00000000"],["78663.19000000","0.00508000"],["78663.20000000","0.00008000"],["78663.99000000","0.02561000"],["78664.00000000","0.00021000"],["78664.01000000","0.08805000"],["78664.63000000","0.00014000"],["78664.64000000","0.05318000"],["78665.09000000","0.00000000"],["78665.10000000","0.00007000"],["78665.11000000","0.00007000"],["78665.26000000","0.00014000"],["78665.55000000","0.00635000"],["78665.56000000","0.00334000"],["78665.69000000","0.00014000"],["78665.70000000","0.37765000"],["78666.00000000","0.00035000"],["78666.01000000","0.32025000"],["78666.02000000","0.00532000"],["78666.03000000","0.00014000"],["78667.14000000","0.00324000"],["78667.86000000","0.00254000"],["78667.99000000","0.00007000"],["78668.01000000","0.00007000"],["78668.17000000","0.02161000"],["78668.18000000","0.00000000"],["78668.72000000","0.00635000"],["78668.73000000","0.00000000"],["78669.55000000","0.00163000"],["78669.87000000","0.00007000"],["78669.95000000","0.30952000"],["78671.51000000","0.02161000"],["78671.83000000","0.00007000"],["78672.00000000","0.00227000"],["78672.80000000","0.08000000"],["78674.68000000","0.02161000"],["78675.48000000","0.00000000"],["78677.75000000","0.09750000"],["78677.98000000","0.19483000"],["78677.99000000","3.38565000"],["78678.00000000","0.00017000"],["78679.27000000","0.02511000"],["78680.48000000","0.00000000"],["78682.08000000","0.00000000"],["78683.33000000","0.00000000"],["78684.33000000","0.00012000"],["78684.59000000","0.00000000"],["78685.16000000","0.00322000"],["78685.28000000","0.00000000"],["78685.69000000","0.00007000"],["78685.71000000","0.00060000"],["78685.85000000","0.00000000"],["78689.99000000","0.09348000"],["78691.55000000","0.00000000"],["78692.30000000","0.00406000"],["78692.66000000","0.00190000"],["78696.28000000","0.00000000"],["78698.17000000","0.00625000"],["78700.63000000","0.00000000"],["78701.08000000","0.00436000"],["78701.82000000","0.00000000"],["78702.00000000","0.70397000"],["78702.10000000","0.00000000"],["78702.45000000","0.00000000"],["78704.22000000","0.00430000"],["78704.76000000","0.00000000"],["78705.07000000","0.00434000"],["78708.20000000","0.00007000"],["78711.10000000","0.01129000"],["78718.00000000","0.02400000"],["78723.18000000","0.00111000"],["78723.51000000","1.25772000"],["78724.30000000","0.00541000"],["78727.01000000","0.01699000"],["78730.46000000","1.90515000"],["78730.47000000","1.21952000"],["78731.65000000","0.00406000"],["78733.50000000","0.00000000"],["78739.99000000","0.00000000"],["78740.58000000","0.09211000"],["78742.36000000","0.00000000"],["78743.62000000","0.00000000"],["78744.65000000","0.00000000"],["78758.79000000","0.00000000"],["78763.13000000","0.00406000"],["78772.51000000","0.00000000"],["78810.34000000","0.00406000"],["78818.49000000","0.00000000"],["78881.17000000","0.00406000"],["78884.04000000","0.00000000"],["78889.52000000","0.00000000"]]}}}
{"rx_ns": 173348340233500, "frame": {"stream":"btcusdt@depth20@100ms","data":{"lastUpdateId":99076757092,"bids":[["78662.00000000","1.23416000"],["78661.99000000","0.00035000"],["78661.62000000","0.00007000"],["78660.75000000","0.00014000"],["78660.74000000","0.03597000"],["78660.01000000","0.00014000"],["78660.00000000","0.02407000"],["78659.79000000","0.00007000"],["78659.59000000","0.00027000"],["78659.49000000","0.00014000"],["78659.48000000","0.04315000"],["78659.24000000","0.00007000"],["78659.14000000","0.00014000"],["78659.13000000","0.04874000"],["78658.63000000","0.02000000"],["78658.22000000","0.04315000"],["78658.01000000","0.00007000"],["78658.00000000","0.02407000"],["78657.75000000","0.00007000"],["78657.06000000","0.00007000"]],"asks":[["78662.01000000","1.77295000"],["78662.02000000","0.00020000"],["78662.03000000","0.00013000"],["78663.13000000","0.00254000"],["78663.19000000","0.00007000"],["78663.20000000","0.00008000"],["78663.80000000","0.00400000"],["78663.98000000","0.00014000"],["78663.99000000","0.02168000"],["78664.00000000","0.00014000"],["78664.01000000","0.08805000"],["78664.16000000","0.00014000"],["78664.17000000","0.01659000"],["78664.62000000","0.00508000"],["78664.63000000","0.00014000"],["78664.64000000","0.05311000"],["78665.11000000","0.00007000"],["78665.26000000","0.00007000"],["78665.43000000","0.02766000"],["78665.49000000","0.00014000"]]}}}
{"rx_ns": 173348340342200, "frame": {"stream":"btcusdt@depth@100ms","data":{"e":"depthUpdate","E":1787603287514,"s":"BTCUSDT","U":99076756955,"u":99076757092,"b":[["78662.00000000","1.23416000"],["78661.99000000","0.00035000"],["78660.74000000","0.03597000"],["78660.00000000","0.02407000"],["78659.59000000","0.00027000"],["78659.48000000","0.04315000"],["78659.13000000","0.04874000"],["78658.63000000","0.02000000"],["78658.22000000","0.04315000"],["78658.00000000","0.02407000"],["78657.58000000","0.00000000"],["78656.67000000","0.00007000"],["78656.00000000","0.02407000"],["78655.98000000","0.20861000"],["78655.78000000","0.00000000"],["78654.00000000","0.02400000"],["78653.56000000","1.90515000"],["78653.55000000","1.21952000"],["78652.98000000","0.00635000"],["78652.00000000","0.02407000"],["78650.00000000","0.02400000"],["78649.99000000","0.00528000"],["78649.82000000","0.00000000"],["78648.31000000","0.03224000"],["78647.88000000","0.00000000"],["78647.64000000","0.00000000"],["78647.43000000","0.00000000"],["78647.41000000","0.00254000"],["78646.92000000","0.50367000"],["78646.82000000","0.00000000"],["78645.11000000","0.00000000"],["78642.95000000","0.00000000"],["78642.05000000","0.04624000"],["78640.00000000","0.11938000"],["78639.74000000","0.38153000"],["78637.47000000","0.34339000"],["78634.24000000","1.90515000"],["78633.74000000","0.34340000"],["78623.24000000","1.03691000"],["78610.59000000","0.00400000"],["78610.46000000","0.00000000"],["78603.62000000","0.00000000"],["78602.32000000","0.00000000"],["78597.71000000","0.02000000"],["78547.91000000","0.00000000"],["78527.54000000","0.04595000"],["78457.49000000","0.00000000"],["78454.20000000","0.00000000"],["62929.60000000","0.00067000"]],"a":[["78662.01000000","1.77295000"],["78663.13000000","0.00254000"],["78663.19000000","0.00007000"],["78663.36000000","0.00000000"],["78663.60000000","0.00000000"],["78663.79000000","0.00000000"],["78663.98000000","0.00014000"],["78663.99000000","0.02168000"],["78664.00000000","0.00014000"],["78664.16000000","0.00014000"],["78664.17000000","0.01659000"],["78664.62000000","0.00508000"],["78664.64000000","0.05311000"],["78665.10000000","0.00000000"],["78665.26000000","0.00007000"],["78665.43000000","0.02766000"],["78665.54000000","0.00137000"],["78665.55000000","0.00007000"],["78665.69000000","0.00007000"],["78665.70000000","0.37765000"],["78666.00000000","0.00014000"],["78666.69000000","0.03319000"],["78667.85000000","0.00000000"],["78667.95000000","0.03319000"],["78669.87000000","0.00000000"],["78669.95000000","0.30945000"],["78670.83000000","0.00000000"],["78670.89000000","0.08576000"],["78671.40000000","0.00635000"],["78671.41000000","0.00400000"],["78671.83000000","0.00007000"],["78672.00000000","0.00000000"],["78672.01000000","0.21501000"],["78675.18000000","0.00000000"],["78675.83000000","0.02000000"],["78677.16000000","0.00227000"],["78680.42000000","0.00000000"],["78692.30000000","0.00000000"],["78698.02000000","0.34312000"],["78721.50000000","0.00000000"],["78731.65000000","0.00000000"],["78763.13000000","0.00000000"],["78763.49000000","0.02789000"],["78783.92000000","0.00000000"],["78810.34000000","0.00000000"]]}}}
{"rx_ns": 173348437462600, "frame": {"stream":"btcusdt@depth20@100ms","data":{"lastUpdateId":99076757186,"bids":[["78662.00000000","0.44738000"],["78661.99000000","0.00042000"],["78661.62000000","0.00007000"],["78660.75000000","0.00014000"],["78660.74000000","0.03597000"],["78660.12000000","0.00007000"],["78660.01000000","0.00014000"],["78660.00000000","0.02407000"],["78659.49000000","0.00014000"],["78659.48000000","0.04315000"],["78659.24000000","0.00007000"],["78659.14000000","0.00014000"],["78659.13000000","0.04874000"],["78658.63000000","0.00007000"],["78658.22000000","0.04315000"],["78658.00000000","0.02407000"],["78657.75000000","0.00007000"],["78657.06000000","0.00007000"],["78656.00000000","0.02400000"],["78655.50000000","0.00008000"]],"asks":[["78662.01000000","1.99225000"],["78662.02000000","0.00020000"],["78662.03000000","0.00013000"],["78663.20000000","0.00008000"],["78663.80000000","0.00400000"],["78663.98000000","0.00014000"],["78663.99000000","0.02168000"],["78664.00000000","0.00014000"],["78664.01000000","0.08805000"],["78664.04000000","0.00254000"],["78664.16000000","0.00014000"],["78664.17000000","0.01666000"],["78664.62000000","0.00515000"],["78664.63000000","0.00014000"],["78664.64000000","0.05311000"],["78665.11000000","0.00007000"],["78665.26000000","0.00007000"],["78665.42000000","0.00007000"],["78665.43000000","0.02773000"],["78665.49000000","0.00014000"]]}}}
{"rx_ns": 173348437551100, "frame": {"stream":"btcusdt@depth@100ms","data":{"e":"depthUpdate","E":1787603287614,"s":"BTCUSDT","U":99076757093,"u":99076757186,"b":[["78662.00000000","0.44738000"],["78661.99000000","0.00042000"],["78660.12000000","0.00007000"],["78659.79000000","0.00000000"],["78659.59000000","0.00000000"],["78659.13000000","0.04874000"],["78658.63000000","0.00007000"],["78658.01000000","0.00000000"],["78658.00000000","0.02407000"],["78656.67000000","0.00000000"],["78656.00000000","0.02400000"],["78655.98000000","0.00000000"],["78653.93000000","0.02000000"],["78653.88000000","0.00014000"],["78653.57000000","0.37424000"],["78652.47000000","0.00000000"],["78652.34000000","0.00400000"],["78648.32000000","0.00254000"],["78647.98000000","0.00007000"],["78647.41000000","0.00000000"],["78645.12000000","0.00000000"],["78644.02000000","0.36624000"],["78621.03000000","0.00400000"],["78613.20000000","0.00400000"],["78613.00000000","0.00000000"],["78610.59000000","0.00000000"],["78590.31000000","0.00000000"],["78586.26000000","0.86920000"],["78545.83000000","2.14293000"],["78527.54000000","0.00000000"],["78512.36000000","0.00000000"],["77889.50000000","0.00300000"],["70795.80000000","0.00064000"],["70795.00000000","0.00000000"],["62929.60000000","0.00036000"]],"a":[["78662.01000000","1.99225000"],["78663.13000000","0.00000000"],["78663.19000000","0.00000000"],["78664.01000000","0.08805000"],["78664.04000000","0.00254000"],["78664.17000000","0.01666000"],["78664.62000000","0.00515000"],["78664.64000000","0.05311000"],["78665.42000000","0.00007000"],["78665.43000000","0.02773000"],["78665.55000000","0.00000000"],["78666.83000000","0.02000000"],["78669.87000000","1.21952000"],["78670.88000000","0.00007000"],["78673.99000000","1.21952000"],["78675.83000000","0.00000000"],["78679.77000000","0.00000000"],["78690.28000000","0.00000000"],["78695.19000000","0.00000000"],["78706.06000000","0.86787000"],["78708.49000000","0.00635000"],["78730.47000000","0.00000000"],["78731.65000000","0.00406000"],["78763.49000000","0.00000000"]]}}}
{"rx_ns": 173348540837000, "frame": {"stream":"btcusdt@depth20@100ms","data":{"lastUpdateId":99076757248,"bids":[["78662.00000000","0.31772000"],["78661.99000000","0.00042000"],["78661.62000000","0.00007000"],["78660.75000000","0.00014000"],["78660.74000000","0.03597000"],["78660.12000000","0.00007000"],["78660.01000000","0.00014000"],["78660.00000000","0.02407000"],["78659.49000000","0.00014000"],["78659.48000000","0.04315000"],["78659.24000000","0.00007000"],["78659.14000000","0.00014000"],["78659.13000000","0.04874000"],["78658.22000000","0.04315000"],["78658.00000000","0.02407000"],["78657.75000000","0.00007000"],["78657.06000000","0.00007000"],["78656.00000000","0.02407000"],["78655.50000000","0.00008000"],["78655.36000000","0.00007000"]],"asks":[["78662.01000000","1.99617000"],["78662.02000000","0.00020000"],["78662.03000000","0.00013000"],["78663.20000000","0.00008000"],["78663.24000000","0.00254000"],["78663.80000000","0.00400000"],["78663.98000000","0.00014000"],["78663.99000000","0.02168000"],["78664.00000000","0.00014000"],["78664.01000000","0.08805000"],["78664.16000000","0.00014000"],["78664.17000000","0.01666000"],["78664.62000000","0.00515000"],["78664.63000000","0.00014000"],["78664.64000000","0.05311000"],["78665.11000000","0.00007000"],["78665.26000000","0.00007000"],["78665.42000000","0.00007000"],["78665.43000000","0.02773000"],["78665.49000000","0.00014000"]]}}}
{"rx_ns": 173348540988800, "frame": {"stream":"btcusdt@depth@100ms","data":{"e":"depthUpdate","E":1787603287714,"s":"BTCUSDT","U":99076757187,"u":99076757248,"b":[["78662.00000000","0.31772000"],["78659.13000000","0.04874000"],["78658.63000000","0.00000000"],["78656.00000000","0.02407000"],["78653.93000000","0.00000000"],["78653.88000000","0.00007000"],["78653.58000000","0.01200000"],["78653.57000000","0.36224000"],["78652.34000000","0.00000000"],["78652.28000000","0.00332000"],["78651.49000000","0.00400000"],["78651.43000000","0.02000000"],["78650.71000000","0.00320000"],["78648.32000000","0.00000000"],["78647.52000000","0.00254000"],["78615.18000000","0.00007000"],["78590.31000000","0.00314000"],["78573.07000000","0.02117000"],["78527.38000000","0.04095000"],["78512.36000000","0.00127000"],["78268.69000000","0.01000000"],["77877.34000000","0.01000000"],["77487.95000000","0.01000000"],["77100.52000000","0.01000000"],["76715.01000000","0.01000000"],["76331.44000000","0.01000000"],["75949.78000000","0.01000000"],["75570.03000000","0.01000000"],["75192.18000000","0.01000000"],["74816.22000000","0.01000000"],["74442.14000000","0.01000000"],["74069.93000000","0.01000000"],["73699.58000000","0.01000000"],["73331.08000000","0.01000000"],["72964.43000000","0.01000000"],["70795.80000000","0.00080000"]],"a":[["78662.01000000","1.99617000"],["78663.24000000","0.00254000"],["78664.04000000","0.00000000"],["78680.00000000","0.11940000"],["78763.33000000","0.02789000"],["79055.33000000","0.01000000"],["79450.60000000","0.01000000"],["79847.85000000","0.01000000"],["80247.09000000","0.01000000"],["80648.33000000","0.01120000"],["81051.57000000","0.01000000"],["81456.83000000","0.01000000"],["81864.11000000","0.01000000"],["82273.43000000","0.01000000"],["82684.80000000","0.01000000"],["83098.22000000","0.01000000"],["83513.72000000","0.01000000"],["83931.28000000","0.01000000"],["84350.94000000","0.01000000"],["84772.70000000","0.01000000"]]}}}
{"rx_ns": 173348637612700, "frame": {"stream":"btcusdt@depth20@100ms","data":{"lastUpdateId":99076757257,"bids":[["78662.00000000","0.31772000"],["78661.99000000","0.00042000"],["78661.62000000","0.00007000"],["78660.75000000","0.00014000"],["78660.74000000","0.03597000"],["78660.12000000","0.00007000"],["78660.01000000","0.00014000"],["78660.00000000","0.02407000"],["78659.49000000","0.00014000"],["78659.48000000","0.04315000"],["78659.24000000","0.00007000"],["78659.14000000","0.00014000"],["78659.13000000","0.04874000"],["78658.22000000","0.04315000"],["78658.00000000","0.02407000"],["78657.75000000","0.00007000"],["78657.06000000","0.00007000"],["78656.00000000","0.02407000"],["78655.50000000","0.00008000"],["78655.36000000","0.00007000"]],"asks":[["78662.01000000","2.00125000"],["78662.02000000","0.00020000"],["78662.03000000","0.00013000"],["78663.20000000","0.00008000"],["78663.24000000","0.00254000"],["78663.80000000","0.00400000"],["78663.98000000","0.00014000"],["78663.99000000","0.02168000"],["78664.00000000","0.00014000"],["78664.01000000","0.08805000"],["78664.16000000","0.00014000"],["78664.17000000","0.01666000"],["78664.62000000","0.00007000"],["78664.63000000","0.00014000"],["78664.64000000","0.05311000"],["78665.11000000","0.00007000"],["78665.26000000","0.00007000"],["78665.42000000","0.00007000"],["78665.43000000","0.02773000"],["78665.49000000","0.00014000"]]}}}
{"rx_ns": 173348637694500, "frame": {"stream":"btcusdt@depth@100ms","data":{"e":"depthUpdate","E":1787603287814,"s":"BTCUSDT","U":99076757249,"u":99076757257,"b":[["78652.98000000","0.00000000"],["78650.72000000","0.00635000"],["78646.92000000","0.00000000"],["78573.07000000","0.00000000"],["78486.67000000","0.00000000"],["78458.95000000","0.00779000"],["72358.00000000","0.01382000"],["70795.80000000","0.00096000"]],"a":[["78662.01000000","2.00125000"],["78664.62000000","0.00007000"],["78692.30000000","0.00406000"]]}}}
{"rx_ns": 173348738022700, "frame": {"stream":"btcusdt@depth20@100ms","data":{"lastUpdateId":99076757350,"bids":[["78662.00000000","0.32026000"],["78661.99000000","0.00042000"],["78661.62000000","0.00007000"],["78660.75000000","0.00014000"],["78660.74000000","0.03597000"],["78660.12000000","0.00007000"],["78660.01000000","0.00014000"],["78660.00000000","0.02407000"],["78659.49000000","0.00014000"],["78659.48000000","0.04315000"],["78659.24000000","0.00007000"],["78659.14000000","0.00014000"],["78659.13000000","0.04874000"],["78658.22000000","0.04315000"],["78658.00000000","0.02407000"],["78657.75000000","0.00007000"],["78657.06000000","0.00007000"],["78656.00000000","0.02407000"],["78655.77000000","0.20861000"],["78655.50000000","0.00008000"]],"asks":[["78662.01000000","2.00386000"],["78662.02000000","0.00020000"],["78662.03000000","0.00013000"],["78663.20000000","0.00008000"],["78663.80000000","0.00400000"],["78663.98000000","0.00014000"],["78663.99000000","0.02168000"],["78664.00000000","0.00014000"],["78664.01000000","0.08805000"],["78664.12000000","0.02000000"],["78664.16000000","0.00014000"],["78664.17000000","0.01666000"],["78664.63000000","0.00014000"],["78664.64000000","0.05311000"],["78665.11000000","0.00007000"],["78665.26000000","0.00007000"],["78665.42000000","0.00007000"],["78665.43000000","0.02773000"],["78665.49000000","0.00014000"],["78665.54000000","0.00137000"]]}}}
{"rx_ns": 173348738108500, "frame": {"stream":"btcusdt@depth@100ms","data":{"e":"depthUpdate","E":1787603287914,"s":"BTCUSDT","U":99076757258,"u":99076757350,"b":[["78662.00000000","0.32026000"],["78655.77000000","0.20861000"],["78653.59000000","0.00800000"],["78653.58000000","0.00000000"],["78653.57000000","0.00000000"],["78651.49000000","0.00000000"],["78651.43000000","0.00000000"],["78649.21000000","0.00000000"],["78649.17000000","0.00000000"],["78648.56000000","0.00000000"],["78648.55000000","0.00400000"],["78648.45000000","0.00000000"],["78648.28000000","0.00000000"],["78647.52000000","0.00000000"],["78646.39000000","0.00254000"],["78644.42000000","0.02000000"],["78590.42000000","1.25985000"],["78464.75000000","3.82385000"],["70795.80000000","0.00112000"]],"a":[["78662.01000000","2.00386000"],["78663.24000000","0.00000000"],["78664.12000000","0.02000000"],["78664.17000000","0.01666000"],["78664.62000000","0.00000000"],["78666.02000000","0.00539000"],["78666.83000000","0.00000000"],["78668.00000000","0.00112000"],["78669.86000000","1.90515000"],["78670.00000000","0.00500000"],["78672.00000000","0.00500000"],["78674.00000000","0.00500000"],["78674.03000000","0.00000000"],["78676.00000000","0.00500000"],["78678.00000000","0.00517000"],["78694.88000000","0.63544000"],["78730.46000000","0.00000000"],["78766.51000000","0.00012000"],["78772.65000000","0.00019000"],["78780.52000000","0.00000000"],["78786.66000000","0.00000000"],["78792.75000000","0.00000000"]]}}}
{"rx_ns": 173348838744900, "frame": {"stream":"btcusdt@depth20@100ms","data":{"lastUpdateId":99076757446,"bids":[["78662.00000000","0.03670000"],["78661.99000000","0.00042000"],["78661.62000000","0.00007000"],["78660.75000000","0.00014000"],["78660.74000000","0.03597000"],["78660.12000000","0.00007000"],["78660.01000000","0.00014000"],["78660.00000000","0.02407000"],["78659.49000000","0.00014000"],["78659.48000000","0.04315000"],["78659.24000000","0.00007000"],["78659.14000000","0.00014000"],["78659.13000000","0.04874000"],["78658.54000000","0.00007000"],["78658.23000000","0.00007000"],["78658.22000000","0.04315000"],["78658.00000000","0.02407000"],["78657.75000000","0.00007000"],["78657.06000000","0.00007000"],["78656.89000000","0.31787000"]],"asks":[["78662.01000000","2.03142000"],["78662.02000000","0.00020000"],["78662.03000000","0.00013000"],["78663.20000000","0.00008000"],["78663.80000000","0.00400000"],["78663.98000000","0.00014000"],["78663.99000000","0.02168000"],["78664.00000000","0.00014000"],["78664.01000000","0.08805000"],["78664.12000000","0.00007000"],["78664.16000000","0.00014000"],["78664.17000000","0.01666000"],["78664.63000000","0.00014000"],["78664.64000000","0.05311000"],["78665.11000000","0.00007000"],["78665.26000000","0.00007000"],["78665.42000000","0.00007000"],["78665.43000000","0.02773000"],["78665.49000000","0.00014000"],["78665.53000000","0.00635000"]]}}}
{"rx_ns": 173348838843200, "frame": {"stream":"btcusdt@depth@100ms","data":{"e":"depthUpdate","E":1787603288014,"s":"BTCUSDT","U":99076757351,"u":99076757446,"b":[["78662.00000000","0.03670000"],["78658.54000000","0.00007000"],["78658.23000000","0.00007000"],["78656.89000000","0.31787000"],["78656.00000000","0.02407000"],["78655.77000000","0.00000000"],["78653.59000000","0.00000000"],["78653.57000000","0.00000000"],["78650.72000000","0.00000000"],["78648.85000000","0.00000000"],["78648.55000000","0.00000000"],["78647.99000000","0.00965000"],["78646.40000000","0.00000000"],["78646.39000000","0.00000000"],["78643.06000000","0.02400000"],["78642.92000000","0.02600000"],["78642.17000000","0.02800000"],["78642.13000000","0.02800000"],["78642.05000000","0.00000000"],["78641.41000000","0.00400000"],["78638.35000000","0.03000000"],["78637.47000000","0.00000000"],["78635.96000000","0.04624000"],["78628.45000000","0.00635000"],["78624.78000000","0.34344000"],["78624.50000000","0.34344000"],["78609.00000000","0.00000000"],["78586.06000000","0.02600000"],["78586.01000000","0.00000000"],["78585.32000000","0.02800000"],["78585.05000000","0.02800000"],["78584.54000000","0.02400000"],["78578.01000000","0.00315000"],["78574.01000000","0.00000000"],["78570.41000000","0.00247000"],["78528.02000000","0.00000000"],["78506.67000000","0.00000000"],["78500.01000000","0.00127000"],["78492.31000000","0.00099000"],["75555.00000000","5.80936000"],["70795.80000000","0.00144000"],["62929.60000000","0.00067000"]],"a":[["78662.01000000","2.03142000"],["78664.01000000","0.08805000"],["78664.11000000","0.00000000"],["78664.12000000","0.00007000"],["78665.42000000","0.00007000"],["78665.53000000","0.00635000"],["78665.54000000","0.00000000"],["78665.69000000","0.00000000"],["78666.02000000","0.00532000"],["78668.72000000","0.00000000"],["78669.85000000","0.00227000"],["78671.40000000","0.00000000"],["78672.54000000","0.02000000"],["78672.61000000","0.02000000"],["78673.39000000","0.02000000"],["78673.44000000","0.02000000"],["78675.30000000","0.34322000"],["78677.16000000","0.00000000"],["78681.73000000","0.43616000"],["78682.80000000","0.63554000"],["78689.22000000","0.00000000"],["78689.74000000","0.34316000"],["78698.02000000","0.00000000"],["78711.88000000","0.00315000"],["78717.99000000","0.00317000"],["78719.06000000","0.00000000"],["78727.13000000","0.00000000"],["78740.44000000","0.00000000"],["78778.74000000","0.00031000"],["78789.93000000","0.00127000"],["78797.79000000","0.00127000"],["78797.93000000","0.00000000"],["78810.34000000","0.00406000"],["78819.87000000","0.00000000"]]}}}
{"rx_ns": 173348939095200, "frame": {"stream":"btcusdt@depth20@100ms","data":{"lastUpdateId":99076757587,"bids":[["78662.00000000","0.03654000"],["78661.99000000","0.00042000"],["78661.69000000","0.00007000"],["78661.62000000","0.00007000"],["78660.75000000","0.00014000"],["78660.74000000","0.03597000"],["78660.12000000","0.00007000"],["78660.01000000","0.00014000"],["78660.00000000","0.02407000"],["78659.49000000","0.00014000"],["78659.48000000","0.04315000"],["78659.24000000","0.00007000"],["78659.14000000","0.00014000"],["78659.13000000","0.04874000"],["78658.54000000","0.00007000"],["78658.23000000","0.00007000"],["78658.22000000","0.04315000"],["78658.00000000","0.02407000"],["78657.75000000","0.00007000"],["78657.06000000","0.00007000"]],"asks":[["78662.01000000","2.87644000"],["78662.02000000","0.00020000"],["78662.03000000","0.00013000"],["78663.20000000","0.00008000"],["78663.48000000","0.00027000"],["78663.80000000","0.00400000"],["78663.98000000","0.00014000"],["78663.99000000","0.02168000"],["78664.00000000","0.00014000"],["78664.01000000","0.08805000"],["78664.16000000","0.00014000"],["78664.17000000","0.01666000"],["78664.63000000","0.00014000"],["78664.64000000","0.05311000"],["78665.11000000","0.00007000"],["78665.26000000","0.00007000"],["78665.42000000","0.00007000"],["78665.43000000","0.02773000"],["78665.49000000","0.00014000"],["78665.53000000","0.00642000"]]}}}
{"rx_ns": 173348939192800, "frame": {"stream":"btcusdt@depth@100ms","data":{"e":"depthUpdate","E":1787603288114,"s":"BTCUSDT","U":99076757447,"u":99076757587,"b":[["78662.00000000","0.03654000"],["78661.99000000","0.00042000"],["78661.69000000","0.00007000"],["78658.00000000","0.02407000"],["78656.89000000","0.00007000"],["78656.00000000","0.02400000"],["78655.50000000","0.00000000"],["78653.89000000","0.00000000"],["78653.56000000","0.00000000"],["78653.55000000","0.00000000"],["78652.41000000","0.00000000"],["78652.28000000","0.00000000"],["78652.15000000","0.00000000"],["78650.71000000","0.00000000"],["78650.01000000","0.00007000"],["78649.19000000","0.20861000"],["78648.76000000","1.90515000"],["78648.75000000","0.00000000"],["78648.31000000","0.00000000"],["78647.99000000","0.00330000"],["78646.28000000","0.00000000"],["78646.14000000","0.00014000"],["78645.63000000","0.00000000"],["78644.42000000","0.00000000"],["78644.06000000","0.00635000"],["78644.02000000","0.00000000"],["78644.00000000","0.02400000"],["78643.26000000","0.00635000"],["78642.22000000","0.00000000"],["78642.08000000","0.00007000"],["78641.92000000","0.00000000"],["78641.41000000","0.00000000"],["78641.38000000","0.00254000"],["78641.32000000","0.02200000"],["78640.57000000","0.00000000"],["78640.00000000","0.02400000"],["78639.75000000","0.00400000"],["78639.74000000","0.00000000"],["78639.62000000","0.02000000"],["78639.13000000","0.00000000"],["78638.93000000","0.02400000"],["78638.33000000","0.02000000"],["78637.29000000","0.02000000"],["78635.96000000","0.00000000"],["78633.02000000","0.00000000"],["78628.45000000","0.00000000"],["78626.40000000","0.13891000"],["78623.91000000","0.00000000"],["78622.49000000","0.00000000"],["78621.35000000","0.04597000"],["78621.06000000","0.09717000"],["78614.41000000","0.00000000"],["78612.53000000","0.00000000"],["78611.97000000","0.00000000"],["78611.33000000","0.02793000"],["78611.31000000","0.00007000"],["78610.08000000","0.00000000"],["78609.44000000","0.02417000"],["78607.44000000","0.00000000"],["78605.37000000","0.00400000"],["78585.19000000","0.02200000"],["78584.54000000","0.00000000"],["78579.12000000","0.02400000"],["78577.47000000","0.02000000"],["78577.39000000","0.02000000"],["78462.64000000","0.00779000"],["78458.95000000","0.00000000"],["77969.89000000","0.00000000"],["70810.19000000","0.00000000"],["70810.18000000","0.00009000"],["70795.80000000","0.00144000"]],"a":[["78662.01000000","2.87644000"],["78663.48000000","0.00027000"],["78664.01000000","0.08805000"],["78664.12000000","0.00000000"],["78665.43000000","0.02773000"],["78665.53000000","0.00642000"],["78665.69000000","1.21952000"],["78666.70000000","0.00000000"],["78668.20000000","0.00000000"],["78669.71000000","0.08576000"],["78669.86000000","1.92515000"],["78670.89000000","0.00000000"],["78672.20000000","0.02000000"],["78672.80000000","0.00000000"],["78673.91000000","0.02000000"],["78675.40000000","0.00000000"],["78676.86000000","0.02000000"],["78678.00000000","0.00507000"],["78690.48000000","0.00000000"],["78696.50000000","0.02519000"],["78701.27000000","0.00000000"],["78710.00000000","0.02400000"],["78720.50000000","0.00000000"],["78730.26000000","0.00000000"],["78750.06000000","0.04643000"],["78757.86000000","0.04575000"],["78772.82000000","0.00000000"],["78786.93000000","0.00000000"]]}}}
{"rx_ns": 173349039222400, "frame": {"stream":"btcusdt@depth20@100ms","data":{"lastUpdateId":99076758049,"bids":[["78660.00000000","0.02535000"],["78659.99000000","0.00042000"],["78659.48000000","0.00007000"],["78659.24000000","0.00007000"],["78659.13000000","0.00007000"],["78658.54000000","0.00007000"],["78658.22000000","0.00007000"],["78658.01000000","0.00014000"],["78658.00000000","0.02407000"],["78657.75000000","0.00007000"],["78657.13000000","0.00014000"],["78657.12000000","0.04857000"],["78657.06000000","0.00007000"],["78656.01000000","0.00014000"],["78656.00000000","0.02407000"],["78655.36000000","0.00007000"],["78655.02000000","0.00007000"],["78654.16000000","0.00007000"],["78654.01000000","0.00014000"],["78654.00000000","0.02407000"]],"asks":[["78660.01000000","3.13819000"],["78660.02000000","0.00020000"],["78660.03000000","0.00013000"],["78660.18000000","0.00400000"],["78660.73000000","0.00007000"],["78660.74000000","0.10360000"],["78660.75000000","1.02983000"],["78661.62000000","0.00014000"],["78661.99000000","0.00014000"],["78662.00000000","0.43918000"],["78662.01000000","0.28739000"],["78662.63000000","0.05314000"],["78663.20000000","0.00008000"],["78663.80000000","0.00400000"],["78663.99000000","0.02168000"],["78664.01000000","0.08805000"],["78664.17000000","0.00007000"],["78664.64000000","0.00007000"],["78665.11000000","0.00007000"],["78665.26000000","0.00007000"]]}}}
{"rx_ns": 173349039314000, "frame": {"stream":"btcusdt@depth@100ms","data":{"e":"depthUpdate","E":1787603288215,"s":"BTCUSDT","U":99076757588,"u":99076758049,"b":[["78662.00000000","0.00000000"],["78661.99000000","0.00000000"],["78661.69000000","0.00000000"],["78661.62000000","0.00000000"],["78660.75000000","0.00000000"],["78660.74000000","0.00000000"],["78660.73000000","0.00000000"],["78660.72000000","0.00000000"],["78660.12000000","0.00000000"],["78660.01000000","0.00000000"],["78660.00000000","0.02535000"],["78659.99000000","0.00042000"],["78659.49000000","0.00000000"],["78659.48000000","0.00007000"],["78659.14000000","0.00000000"],["78659.13000000","0.00007000"],["78658.23000000","0.00000000"],["78658.22000000","0.00007000"],["78658.01000000","0.00014000"],["78658.00000000","0.02407000"],["78657.87000000","0.00000000"],["78657.86000000","0.00000000"],["78657.13000000","0.00014000"],["78657.12000000","0.04857000"],["78656.89000000","0.00000000"],["78656.01000000","0.00014000"],["78656.00000000","0.02407000"],["78654.01000000","0.00014000"],["78654.00000000","0.02407000"],["78652.20000000","0.00007000"],["78652.19000000","0.12728000"],["78652.00000000","0.02414000"],["78649.44000000","0.21937000"],["78642.57000000","0.00254000"],["78641.41000000","0.00000000"],["78641.38000000","0.00000000"],["78639.73000000","0.00000000"],["78638.15000000","0.02000000"],["78637.76000000","0.00000000"],["78637.30000000","0.02200000"],["78631.92000000","0.51586000"],["78622.00000000","0.02400000"],["78621.06000000","0.00000000"],["78621.00000000","0.00000000"],["78620.73000000","0.09705000"],["78620.00000000","0.17140000"],["78619.67000000","0.67067000"],["78614.06000000","0.00000000"],["78611.33000000","0.00000000"],["78611.04000000","0.02767000"],["78609.44000000","0.00000000"],["78609.16000000","0.02384000"],["78603.62000000","0.00406000"],["78592.92000000","0.90695000"],["78586.22000000","1.25992000"],["78585.19000000","0.00000000"],["78579.86000000","0.02000000"],["78577.47000000","0.00000000"],["78575.94000000","0.02000000"],["78575.05000000","0.02200000"],["78570.41000000","0.00000000"],["78568.01000000","0.00246000"],["78545.35000000","2.77319000"],["78504.90000000","0.00000000"],["78486.95000000","1.20000000"],["78268.69000000","0.00000000"],["77877.34000000","0.00000000"],["77487.95000000","0.00000000"],["77100.52000000","0.00000000"],["76715.01000000","0.00000000"],["76331.44000000","0.00000000"],["75949.78000000","0.00000000"],["75570.03000000","0.00000000"],["75192.18000000","0.00000000"],["74816.22000000","0.00000000"],["74442.14000000","0.00000000"],["74069.93000000","0.00000000"],["73699.58000000","0.00000000"],["73331.08000000","0.00000000"],["72964.43000000","0.00000000"],["70795.80000000","0.00000000"],["62929.60000000","0.00036000"]],"a":[["78660.01000000","3.13819000"],["78660.02000000","0.00020000"],["78660.03000000","0.00013000"],["78660.13000000","0.00000000"],["78660.18000000","0.00400000"],["78660.73000000","0.00007000"],["78660.74000000","0.10360000"],["78660.75000000","1.02983000"],["78660.76000000","0.00000000"],["78660.77000000","0.00000000"],["78661.62000000","0.00014000"],["78661.63000000","0.00000000"],["78661.69000000","0.00000000"],["78661.70000000","0.00000000"],["78661.99000000","0.00014000"],["78662.00000000","0.43918000"],["78662.01000000","0.28739000"],["78662.02000000","0.00000000"],["78662.03000000","0.00000000"],["78662.63000000","0.05314000"],["78663.37000000","0.00000000"],["78663.48000000","0.00000000"],["78663.98000000","0.00000000"],["78664.00000000","0.00000000"],["78664.16000000","0.00000000"],["78664.17000000","0.00007000"],["78664.63000000","0.00000000"],["78664.64000000","0.00007000"],["78665.42000000","0.00000000"],["78665.43000000","0.00007000"],["78665.53000000","0.00642000"],["78665.68000000","0.00014000"],["78665.69000000","1.21952000"],["78665.70000000","0.37758000"],["78666.01000000","0.32018000"],["78666.03000000","0.00007000"],["78666.69000000","0.00000000"],["78667.95000000","0.00000000"],["78667.99000000","0.00000000"],["78668.15000000","0.08576000"],["78669.71000000","0.00000000"],["78673.01000000","0.02000000"],["78673.78000000","0.02600000"],["78673.91000000","0.04000000"],["78676.49000000","0.09919000"],["78677.18000000","0.06527000"],["78677.75000000","0.00000000"],["78677.99000000","3.37565000"],["78679.15000000","0.07533000"],["78682.70000000","0.00000000"],["78684.67000000","0.00000000"],["78699.33000000","0.00400000"],["78699.40000000","0.00000000"],["78700.32000000","0.00000000"],["78700.45000000","1.21952000"],["78701.00000000","0.01000000"],["78701.50000000","0.00000000"],["78702.00000000","0.69397000"],["78724.57000000","0.00000000"],["78736.21000000","0.00000000"],["78738.26000000","0.00000000"],["78751.24000000","0.00000000"],["78759.11000000","0.00000000"],["79054.02000000","0.00000000"],["79055.33000000","0.00000000"],["79450.60000000","0.00000000"],["79847.85000000","0.00000000"],["80247.09000000","0.00000000"],["80648.33000000","0.00120000"],["81051.57000000","0.00000000"],["81456.83000000","0.00000000"],["81864.11000000","0.00000000"],["82273.43000000","0.00000000"],["82684.80000000","0.00000000"],["83098.22000000","0.00000000"],["83513.72000000","0.00000000"],["83931.28000000","0.00000000"],["84350.94000000","0.00000000"],["84772.70000000","0.00000000"]]}}}
{"rx_ns": 173349146465700, "frame": {"stream":"btcusdt@depth20@100ms","data":{"lastUpdateId":99076758141,"bids":[["78660.00000000","0.04606000"],["78659.99000000","0.00028000"],["78659.24000000","0.00007000"],["78658.75000000","0.00014000"],["78658.74000000","0.03522000"],["78658.54000000","0.00007000"],["78658.01000000","0.00014000"],["78658.00000000","0.02407000"],["78657.75000000","0.00007000"],["78657.49000000","0.00014000"],["78657.48000000","0.04227000"],["78657.13000000","0.00014000"],["78657.12000000","0.04864000"],["78657.06000000","0.00007000"],["78656.22000000","0.04227000"],["78656.01000000","0.00007000"],["78656.00000000","0.02407000"],["78655.36000000","0.00007000"],["78655.02000000","0.00007000"],["78654.16000000","0.00007000"]],"asks":[["78660.01000000","3.14643000"],["78660.02000000","0.00020000"],["78660.03000000","0.00013000"],["78660.18000000","0.00400000"],["78660.73000000","0.00007000"],["78660.74000000","0.09689000"],["78660.75000000","1.02990000"],["78661.62000000","0.00014000"],["78661.92000000","0.01700000"],["78661.99000000","0.00014000"],["78662.00000000","0.43745000"],["78662.01000000","0.06172000"],["78662.63000000","0.05314000"],["78663.18000000","0.02833000"],["78663.20000000","0.00008000"],["78663.80000000","0.00400000"],["78663.99000000","0.02168000"],["78664.01000000","0.08791000"],["78664.44000000","0.03400000"],["78665.11000000","0.00007000"]]}}}
{"rx_ns": 173349146584400, "frame": {"stream":"btcusdt@depth@100ms","data":{"e":"depthUpdate","E":1787603288314,"s":"BTCUSDT","U":99076758050,"u":99076758141,"b":[["78660.00000000","0.04606000"],["78659.99000000","0.00028000"],["78659.48000000","0.00000000"],["78659.13000000","0.00000000"],["78658.75000000","0.00014000"],["78658.74000000","0.03522000"],["78658.22000000","0.00000000"],["78658.00000000","0.02407000"],["78657.49000000","0.00014000"],["78657.48000000","0.04227000"],["78657.12000000","0.04864000"],["78656.22000000","0.04227000"],["78656.01000000","0.00007000"],["78654.01000000","0.00000000"],["78652.20000000","0.00000000"],["78650.00000000","0.02407000"],["78649.99000000","0.00535000"],["78643.44000000","0.12715000"],["78642.60000000","0.00254000"],["78642.57000000","0.00000000"],["78635.57000000","0.12716000"],["78586.06000000","0.00000000"],["78585.05000000","0.00000000"],["78575.05000000","0.00000000"],["78447.04000000","0.00007000"],["78432.10000000","0.00000000"],["70794.00000000","0.00016000"],["62942.00000000","0.00000000"],["62928.00000000","0.00508000"]],"a":[["78660.01000000","3.14643000"],["78660.74000000","0.09689000"],["78660.75000000","1.02990000"],["78661.92000000","0.01700000"],["78662.00000000","0.43745000"],["78662.01000000","0.06172000"],["78663.18000000","0.02833000"],["78664.01000000","0.08791000"],["78664.17000000","0.00000000"],["78664.44000000","0.03400000"],["78664.64000000","0.00000000"],["78665.43000000","0.00000000"],["78665.70000000","0.41158000"],["78666.01000000","0.32032000"],["78666.02000000","0.00007000"],["78666.06000000","0.00000000"],["78667.04000000","0.12711000"],["78669.33000000","0.00007000"],["78669.83000000","0.00007000"],["78671.37000000","0.00007000"],["78682.83000000","0.12709000"],["78685.54000000","0.00007000"],["78700.00000000","0.11779000"],["78701.00000000","0.00000000"],["78733.29000000","0.00000000"],["78736.20000000","0.00000000"],["78738.21000000","0.00000000"],["78876.36000000","0.00000000"],["78880.29000000","0.00000000"]]}}}
{"rx_ns": 173349245465000, "frame": {"stream":"btcusdt@depth20@100ms","data":{"lastUpdateId":99076758191,"bids":[["78660.00000000","0.04627000"],["78659.99000000","0.00049000"],["78659.24000000","0.00007000"],["78658.75000000","0.00014000"],["78658.74000000","0.03529000"],["78658.54000000","0.00007000"],["78658.01000000","0.00014000"],["78658.00000000","0.02407000"],["78657.75000000","0.00007000"],["78657.49000000","0.00014000"],["78657.48000000","0.04234000"],["78657.13000000","0.00014000"],["78657.12000000","0.04864000"],["78657.06000000","0.00007000"],["78656.23000000","0.00007000"],["78656.22000000","0.04234000"],["78656.01000000","0.00007000"],["78656.00000000","0.02407000"],["78655.36000000","0.00007000"],["78655.02000000","0.00007000"]],"asks":[["78660.01000000","3.14643000"],["78660.02000000","0.00020000"],["78660.03000000","0.00013000"],["78660.18000000","0.00400000"],["78660.73000000","0.00014000"],["78660.74000000","0.02189000"],["78660.75000000","0.49223000"],["78661.62000000","0.00014000"],["78661.92000000","0.01707000"],["78661.99000000","0.00014000"],["78662.00000000","0.43745000"],["78662.01000000","0.06172000"],["78662.63000000","0.05314000"],["78663.18000000","0.02833000"],["78663.20000000","0.00008000"],["78663.80000000","0.00400000"],["78663.99000000","0.02168000"],["78664.01000000","0.08791000"],["78664.44000000","0.03400000"],["78665.11000000","0.00007000"]]}}}
{"rx_ns": 173349245551100, "frame": {"stream":"btcusdt@depth@100ms","data":{"e":"depthUpdate","E":1787603288414,"s":"BTCUSDT","U":99076758142,"u":99076758191,"b":[["78660.00000000","0.04627000"],["78659.99000000","0.00049000"],["78658.74000000","0.03529000"],["78658.00000000","0.02407000"],["78657.48000000","0.04234000"],["78657.12000000","0.04864000"],["78656.23000000","0.00007000"],["78656.22000000","0.04234000"],["78652.00000000","0.02407000"],["78650.00000000","0.02400000"],["78649.99000000","0.00528000"],["78642.95000000","0.00406000"],["78642.64000000","0.00254000"],["78642.60000000","0.00000000"],["78638.36000000","0.00000000"],["78636.36000000","0.00007000"],["78595.44000000","0.02400000"],["78585.32000000","0.00000000"],["70794.00000000","0.00048000"],["62942.00000000","0.00300000"]],"a":[["78660.73000000","0.00014000"],["78660.74000000","0.02189000"],["78660.75000000","0.49223000"],["78661.92000000","0.01707000"],["78662.00000000","0.43745000"],["78665.53000000","0.00635000"],["78665.68000000","0.00000000"],["78669.52000000","0.02000000"],["78673.02000000","0.02000000"],["78683.57000000","0.34325000"],["78685.57000000","0.00000000"],["78736.84000000","0.00000000"],["78751.24000000","0.21930000"]]}}}
{"rx_ns": 173349347185700, "frame": {"stream":"btcusdt@depth20@100ms","data":{"lastUpdateId":99076758255,"bids":[["78660.00000000","0.04627000"],["78659.99000000","0.00049000"],["78659.24000000","0.00007000"],["78658.75000000","0.00014000"],["78658.74000000","0.03529000"],["78658.54000000","0.00007000"],["78658.01000000","0.00014000"],["78658.00000000","0.02407000"],["78657.75000000","0.00007000"],["78657.49000000","0.00014000"],["78657.48000000","0.04234000"],["78657.13000000","0.00014000"],["78657.12000000","0.04864000"],["78657.06000000","0.00007000"],["78656.23000000","0.00007000"],["78656.22000000","0.04234000"],["78656.01000000","0.00007000"],["78656.00000000","0.02407000"],["78655.36000000","0.00007000"],["78655.02000000","0.00007000"]],"asks":[["78660.01000000","3.40463000"],["78660.02000000","0.00020000"],["78660.03000000","0.00013000"],["78660.18000000","0.00400000"],["78660.72000000","0.00014000"],["78660.73000000","1.21952000"],["78660.74000000","0.02189000"],["78660.75000000","0.49223000"],["78661.62000000","0.00014000"],["78661.92000000","0.01707000"],["78661.99000000","0.00014000"],["78662.00000000","0.43731000"],["78662.01000000","0.06172000"],["78662.63000000","0.05314000"],["78663.15000000","0.00027000"],["78663.18000000","0.02833000"],["78663.20000000","0.00008000"],["78663.80000000","0.00400000"],["78663.95000000","0.00332000"],["78663.99000000","0.02168000"]]}}}
{"rx_ns": 173349347290000, "frame": {"stream":"btcusdt@depth@100ms","data":{"e":"depthUpdate","E":1787603288514,"s":"BTCUSDT","U":99076758192,"u":99076758255,"b":[["78652.19000000","0.12735000"],["78650.19000000","0.31790000"],["78649.65000000","0.00000000"],["78648.76000000","0.00000000"],["78648.38000000","0.00000000"],["78647.99000000","0.00000000"],["78647.65000000","0.00000000"],["78642.66000000","0.00254000"],["78642.64000000","0.00000000"],["78623.24000000","0.00000000"],["78617.48000000","0.34347000"],["78615.57000000","0.34348000"],["78611.04000000","0.00000000"],["78610.59000000","0.00000000"],["78610.44000000","0.00000000"],["78610.31000000","0.00000000"],["78610.23000000","0.02762000"],["78609.16000000","0.00000000"],["78609.14000000","0.00000000"],["78608.64000000","0.00000000"],["78608.43000000","0.00000000"],["78608.35000000","0.00000000"],["78602.13000000","0.00400000"],["78577.39000000","0.00000000"],["78575.94000000","0.00000000"],["78568.57000000","0.02117000"],["78456.51000000","0.00000000"],["78431.21000000","0.01991000"],["70794.00000000","0.00064000"],["62942.00000000","0.00000000"],["62928.00000000","0.00539000"]],"a":[["78660.01000000","3.40463000"],["78660.72000000","0.00014000"],["78660.73000000","1.21952000"],["78662.00000000","0.43731000"],["78663.15000000","0.00027000"],["78663.95000000","0.00332000"],["78666.03000000","0.00000000"],["78667.98000000","0.00000000"],["78668.01000000","0.00000000"],["78673.17000000","0.02600000"],["78676.37000000","0.34322000"],["78680.15000000","0.00000000"],["78684.09000000","0.00000000"],["78694.23000000","0.00000000"],["78714.64000000","0.36224000"],["78734.63000000","0.00000000"],["78735.61000000","0.00000000"],["78736.38000000","0.00000000"],["78752.44000000","0.00000000"]]}}}
{"rx_ns": 173349445598500, "frame": {"stream":"btcusdt@depth20@100ms","data":{"lastUpdateId":99076758283,"bids":[["78660.00000000","0.04627000"],["78659.99000000","0.00049000"],["78659.33000000","0.00007000"],["78659.24000000","0.00007000"],["78658.75000000","0.00014000"],["78658.74000000","0.03529000"],["78658.01000000","0.00014000"],["78658.00000000","0.02407000"],["78657.75000000","0.00007000"],["78657.49000000","0.00014000"],["78657.48000000","0.04234000"],["78657.13000000","0.00014000"],["78657.12000000","0.04864000"],["78657.06000000","0.00007000"],["78656.97000000","0.00007000"],["78656.23000000","0.00007000"],["78656.22000000","0.04234000"],["78656.01000000","0.00007000"],["78656.00000000","0.02407000"],["78655.36000000","0.00007000"]],"asks":[["78660.01000000","3.39325000"],["78660.02000000","0.00020000"],["78660.03000000","0.00013000"],["78660.18000000","0.00400000"],["78660.72000000","0.00014000"],["78660.73000000","1.21952000"],["78660.74000000","0.02189000"],["78660.75000000","0.49223000"],["78661.62000000","0.00014000"],["78661.92000000","0.01707000"],["78661.99000000","0.00014000"],["78662.00000000","0.43731000"],["78662.01000000","0.06172000"],["78662.63000000","0.05314000"],["78663.15000000","0.00027000"],["78663.18000000","0.02833000"],["78663.20000000","0.00008000"],["78663.80000000","0.00400000"],["78663.95000000","0.00332000"],["78663.99000000","0.02161000"]]}}}
{"rx_ns": 173349445725800, "frame": {"stream":"btcusdt@depth@100ms","data":{"e":"depthUpdate","E":1787603288614,"s":"BTCUSDT","U":99076758256,"u":99076758283,"b":[["78659.33000000","0.00007000"],["78658.54000000","0.00000000"],["78656.97000000","0.00007000"],["78647.77000000","0.00332000"],["78642.66000000","0.00000000"],["78642.05000000","0.00254000"],["78639.90000000","0.00326000"],["78632.03000000","0.00323000"],["78624.16000000","0.00322000"],["78616.29000000","0.00333000"],["78579.12000000","0.00000000"],["78568.57000000","0.00000000"],["78545.35000000","0.00000000"],["78527.38000000","0.08922000"],["78431.21000000","0.00000000"],["78416.25000000","0.01998000"],["70810.18000000","0.00000000"],["70794.00000000","0.00080000"],["62928.00000000","0.00508000"]],"a":[["78660.01000000","3.39325000"],["78663.99000000","0.02161000"],["78666.01000000","0.32025000"],["78666.02000000","0.00000000"],["78748.96000000","0.00000000"],["78749.30000000","0.00000000"],["78763.13000000","0.00406000"]]}}}
{"rx_ns": 173349549248100, "frame": {"stream":"btcusdt@depth20@100ms","data":{"lastUpdateId":99076758328,"bids":[["78660.00000000","0.04634000"],["78659.99000000","0.00049000"],["78659.33000000","0.00007000"],["78659.24000000","0.00007000"],["78658.75000000","0.00014000"],["78658.74000000","0.03529000"],["78658.01000000","0.00014000"],["78658.00000000","0.02407000"],["78657.75000000","0.00007000"],["78657.49000000","0.00014000"],["78657.48000000","0.04234000"],["78657.13000000","0.00014000"],["78657.12000000","0.04864000"],["78657.06000000","0.00007000"],["78656.97000000","0.00007000"],["78656.23000000","0.00007000"],["78656.22000000","0.04234000"],["78656.01000000","0.00007000"],["78656.00000000","0.02407000"],["78655.36000000","0.00007000"]],"asks":[["78660.01000000","3.39370000"],["78660.02000000","0.00020000"],["78660.03000000","0.00013000"],["78660.18000000","0.00400000"],["78660.72000000","0.00014000"],["78660.73000000","1.21952000"],["78660.74000000","0.02189000"],["78660.75000000","0.49223000"],["78661.62000000","0.00014000"],["78661.92000000","0.01707000"],["78661.99000000","0.00014000"],["78662.00000000","0.43731000"],["78662.01000000","0.06172000"],["78662.63000000","0.05314000"],["78663.15000000","0.00027000"],["78663.18000000","0.02833000"],["78663.20000000","0.00008000"],["78663.80000000","0.00400000"],["78663.95000000","0.00332000"],["78663.99000000","0.02161000"]]}}}
{"rx_ns": 173349549336400, "frame": {"stream":"btcusdt@depth@100ms","data":{"e":"depthUpdate","E":1787603288714,"s":"BTCUSDT","U":99076758284,"u":99076758328,"b":[["78660.00000000","0.04634000"],["78642.06000000","0.00254000"],["78642.05000000","0.00000000"],["78614.00000000","0.72400000"],["78266.70000000","0.01000000"],["77875.36000000","0.01000000"],["77485.98000000","0.01000000"],["77098.55000000","0.01000000"],["76713.06000000","0.01000000"],["76329.50000000","0.01000000"],["75947.85000000","0.01000000"],["75568.11000000","0.01000000"],["75190.27000000","0.01000000"],["74814.32000000","0.01000000"],["74440.25000000","0.01000000"],["74068.04000000","0.01000000"],["73697.70000000","0.01000000"],["73329.22000000","0.01000000"],["72962.57000000","0.01000000"],["70794.00000000","0.00112000"]],"a":[["78660.01000000","3.39370000"],["78665.68000000","0.00014000"],["78680.00000000","0.81940000"],["78689.29000000","0.00000000"],["78752.91000000","0.00000000"],["79053.32000000","0.01000000"],["79448.58000000","0.01000000"],["79845.82000000","0.01000000"],["80245.05000000","0.01000000"],["80646.28000000","0.01000000"],["81049.51000000","0.01000000"],["81454.76000000","0.01000000"],["81862.03000000","0.01000000"],["82271.34000000","0.01000000"],["82682.70000000","0.01000000"],["83096.11000000","0.01000000"],["83511.59000000","0.01000000"],["83929.15000000","0.01000000"],["84348.80000000","0.01000000"],["84770.54000000","0.01000000"]]}}}
{"rx_ns": 173349637808100, "frame": {"stream":"btcusdt@depth20@100ms","data":{"lastUpdateId":99076758348,"bids":[["78660.00000000","0.04634000"],["78659.99000000","0.00049000"],["78659.33000000","0.00007000"],["78659.24000000","0.00007000"],["78658.75000000","0.00014000"],["78658.74000000","0.03529000"],["78658.01000000","0.00014000"],["78658.00000000","0.02407000"],["78657.75000000","0.00007000"],["78657.49000000","0.00014000"],["78657.48000000","0.04234000"],["78657.13000000","0.00014000"],["78657.12000000","0.04864000"],["78657.06000000","0.00007000"],["78656.97000000","0.00007000"],["78656.23000000","0.00007000"],["78656.22000000","0.04234000"],["78656.01000000","0.00007000"],["78656.00000000","0.02407000"],["78655.36000000","0.00007000"]],"asks":[["78660.01000000","3.39370000"],["78660.02000000","0.00020000"],["78660.03000000","0.00013000"],["78660.18000000","0.00400000"],["78660.72000000","0.00014000"],["78660.73000000","1.21952000"],["78660.74000000","0.02189000"],["78660.75000000","0.49223000"],["78661.62000000","0.00014000"],["78661.92000000","0.01707000"],["78661.99000000","0.00014000"],["78662.00000000","0.43731000"],["78662.01000000","0.06172000"],["78662.63000000","0.05314000"],["78663.15000000","0.00027000"],["78663.18000000","0.02833000"],["78663.20000000","0.00008000"],["78663.80000000","0.00400000"],["78663.95000000","0.00332000"],["78663.99000000","0.02161000"]]}}}
{"rx_ns": 173349637895400, "frame": {"stream":"btcusdt@depth@100ms","data":{"e":"depthUpdate","E":1787603288814,"s":"BTCUSDT","U":99076758329,"u":99076758348,"b":[["78642.95000000","0.00000000"],["78603.62000000","0.00000000"],["78572.17000000","0.00000000"],["78524.98000000","0.00000000"],["78464.76000000","0.00779000"],["78462.64000000","0.00000000"],["78454.20000000","0.00000000"]],"a":[["78660.01000000","3.39370000"],["78692.30000000","0.00000000"],["78731.65000000","0.00000000"],["78763.13000000","0.00000000"],["78810.34000000","0.00000000"],["78881.17000000","0.00000000"]]}}}
{"rx_ns": 173349746195600, "frame": {"stream":"btcusdt@depth20@100ms","data":{"lastUpdateId":99076758368,"bids":[["78660.00000000","0.04627000"],["78659.99000000","0.00049000"],["78659.33000000","0.00007000"],["78659.24000000","0.00007000"],["78658.75000000","0.00014000"],["78658.74000000","0.03529000"],["78658.01000000","0.00014000"],["78658.00000000","0.02407000"],["78657.75000000","0.00007000"],["78657.49000000","0.00014000"],["78657.48000000","0.04234000"],["78657.13000000","0.00014000"],["78657.12000000","0.04864000"],["78657.06000000","0.00007000"],["78656.97000000","0.00007000"],["78656.23000000","0.00007000"],["78656.22000000","0.04234000"],["78656.01000000","0.00007000"],["78656.00000000","0.02407000"],["78655.36000000","0.00007000"]],"asks":[["78660.01000000","3.39386000"],["78660.02000000","0.00020000"],["78660.03000000","0.00013000"],["78660.18000000","0.00400000"],["78660.72000000","0.00014000"],["78660.73000000","1.21952000"],["78660.74000000","0.02189000"],["78660.75000000","0.49223000"],["78661.62000000","0.00014000"],["78661.92000000","0.01707000"],["78661.99000000","0.00014000"],["78662.00000000","0.36231000"],["78662.01000000","0.06172000"],["78662.63000000","0.05314000"],["78663.15000000","0.00027000"],["78663.18000000","0.02833000"],["78663.20000000","0.00008000"],["78663.80000000","0.00400000"],["78663.95000000","0.00332000"],["78663.99000000","0.02161000"]]}}}
{"rx_ns": 173349746319100, "frame": {"stream":"btcusdt@depth@100ms","data":{"e":"depthUpdate","E":1787603288914,"s":"BTCUSDT","U":99076758349,"u":99076758368,"b":[["78660.00000000","0.04627000"],["78649.46000000","1.90515000"],["78648.53000000","0.00000000"],["78648.32000000","0.04634000"],["78642.09000000","0.00254000"],["78642.06000000","0.00000000"],["78634.69000000","0.38155000"],["78614.56000000","0.00000000"],["78608.34000000","0.02333000"],["78603.03000000","1.01474000"],["70794.00000000","0.00144000"]],"a":[["78660.01000000","3.39386000"],["78662.00000000","0.36231000"]]}}}
{"rx_ns": 173349840593300, "frame": {"stream":"btcusdt@depth20@100ms","data":{"lastUpdateId":99076758391,"bids":[["78660.00000000","0.05334000"],["78659.99000000","0.00049000"],["78659.33000000","0.00007000"],["78659.24000000","0.00007000"],["78658.75000000","0.00014000"],["78658.74000000","0.03529000"],["78658.01000000","0.00014000"],["78658.00000000","0.02407000"],["78657.75000000","0.00007000"],["78657.49000000","0.00014000"],["78657.48000000","0.04234000"],["78657.13000000","0.00014000"],["78657.12000000","0.04864000"],["78657.06000000","0.00007000"],["78656.97000000","0.00007000"],["78656.23000000","0.00007000"],["78656.22000000","0.04234000"],["78656.01000000","0.00007000"],["78656.00000000","0.02407000"],["78655.36000000","0.00007000"]],"asks":[["78660.01000000","3.39386000"],["78660.02000000","0.00020000"],["78660.03000000","0.00013000"],["78660.18000000","0.00400000"],["78660.72000000","0.00014000"],["78660.73000000","1.21952000"],["78660.74000000","0.02189000"],["78660.75000000","0.49223000"],["78661.62000000","0.00014000"],["78661.92000000","0.01707000"],["78661.99000000","0.00014000"],["78662.00000000","0.36231000"],["78662.01000000","0.06172000"],["78662.63000000","0.05314000"],["78663.15000000","0.00027000"],["78663.18000000","0.02833000"],["78663.20000000","0.00008000"],["78663.80000000","0.00400000"],["78663.95000000","0.00332000"],["78663.99000000","0.02161000"]]}}}
{"rx_ns": 173349840703600, "frame": {"stream":"btcusdt@depth@100ms","data":{"e":"depthUpdate","E":1787603289014,"s":"BTCUSDT","U":99076758369,"u":99076758391,"b":[["78660.00000000","0.05334000"],["78649.72000000","0.02000000"],["78648.32000000","0.00000000"],["78642.10000000","0.00254000"],["78642.09000000","0.00000000"],["78639.62000000","0.00000000"],["78593.24000000","0.00406000"],["78562.87000000","0.02117000"],["70794.00000000","0.00144000"],["62928.00000000","0.00539000"]],"a":[["78660.01000000","3.39386000"],["78666.00000000","0.00469000"],["78668.00000000","0.00812000"],["78670.00000000","0.01200000"],["78672.00000000","0.01200000"],["78674.00000000","0.01200000"],["78676.00000000","0.01200000"],["78678.00000000","0.01207000"]]}}}
{"rx_ns": 173349937783000, "frame": {"stream":"btcusdt@depth20@100ms","data":{"lastUpdateId":99076758423,"bids":[["78660.00000000","0.06027000"],["78659.99000000","0.00049000"],["78659.33000000","0.00007000"],["78659.24000000","0.00007000"],["78658.75000000","0.00014000"],["78658.74000000","0.03529000"],["78658.01000000","0.00014000"],["78658.00000000","0.02407000"],["78657.75000000","0.00007000"],["78657.49000000","0.00014000"],["78657.48000000","0.04234000"],["78657.13000000","0.00014000"],["78657.12000000","0.04864000"],["78657.06000000","0.00007000"],["78656.97000000","0.00007000"],["78656.23000000","0.00007000"],["78656.22000000","0.04234000"],["78656.01000000","0.00007000"],["78656.00000000","0.02407000"],["78655.36000000","0.00007000"]],"asks":[["78660.01000000","3.14215000"],["78660.02000000","0.00020000"],["78660.03000000","0.00013000"],["78660.18000000","0.00400000"],["78660.72000000","0.00014000"],["78660.73000000","1.21959000"],["78660.74000000","0.02189000"],["78660.75000000","0.49223000"],["78661.62000000","0.00014000"],["78661.92000000","0.01707000"],["78661.99000000","0.00014000"],["78662.00000000","0.36231000"],["78662.01000000","0.06172000"],["78662.63000000","0.05321000"],["78663.15000000","0.00027000"],["78663.18000000","0.02833000"],["78663.20000000","0.00008000"],["78663.25000000","0.00007000"],["78663.80000000","0.00400000"],["78663.95000000","0.00332000"]]}}}
{"rx_ns": 173349937868800, "frame": {"stream":"btcusdt@depth@100ms","data":{"e":"depthUpdate","E":1787603289114,"s":"BTCUSDT","U":99076758392,"u":99076758423,"b":[["78660.00000000","0.06027000"],["78648.23000000","0.00317000"],["78642.21000000","0.36224000"],["78642.11000000","0.00254000"],["78642.10000000","0.00000000"],["78634.18000000","0.13254000"],["78630.71000000","0.34342000"],["78626.40000000","0.00635000"],["78615.57000000","0.00000000"],["78610.14000000","0.00400000"],["78602.13000000","0.00000000"],["77952.06000000","0.00010000"],["70794.00000000","0.00160000"]],"a":[["78660.01000000","3.14215000"],["78660.73000000","1.21959000"],["78662.63000000","0.05321000"],["78663.25000000","0.00007000"]]}}}
