{"rx_ns": 42254047500, "kind": "rest", "req": {"method": "GET", "url": "https://data-api.binance.vision/api/v3/depth?symbol=BTCUSDT&limit=100", "limit": 100, "weight": 5, "sent_ns": 41254576200, "status": 200, "used_weight_1m": "25", "recv_ns": 42249466900}, "frame": {"lastUpdateId":99076638968,"bids":[["78713.99000000","3.95356000"],["78713.98000000","0.00069000"],["78713.97000000","0.00013000"],["78713.16000000","0.00014000"],["78713.15000000","0.35479000"],["78713.14000000","0.00007000"],["78712.32000000","0.00400000"],["78712.02000000","0.00007000"],["78712.00000000","0.00514000"],["78711.99000000","0.04505000"],["78711.93000000","0.00014000"],["78711.92000000","0.00007000"],["78711.58000000","0.00400000"],["78711.39000000","0.00326000"],["78711.26000000","0.00014000"],["78711.25000000","0.04333000"],["78711.24000000","0.09101000"],["78710.62000000","0.00642000"],["78710.61000000","0.01470000"],["78710.58000000","0.00320000"],["78710.25000000","0.00007000"],["78710.01000000","0.00007000"],["78710.00000000","0.04414000"],["78709.99000000","0.12315000"],["78709.77000000","0.00400000"],["78709.40000000","0.00008000"],["78709.36000000","0.02439000"],["78709.08000000","0.00027000"],["78709.01000000","0.00321000"],["78708.80000000","0.00635000"],["78708.79000000","0.07105000"],["78708.78000000","1.58176000"],["78708.51000000","0.04010000"],["78708.21000000","0.00007000"],["78708.10000000","0.02927000"],["78708.06000000","0.00014000"],["78708.00000000","0.02407000"],["78707.53000000","0.19375000"],["78707.17000000","0.02000000"],["78707.16000000","0.00400000"],["78706.84000000","0.02927000"],["78706.30000000","0.01200000"],["78706.29000000","1.90515000"],["78706.28000000","0.30007000"],["78706.27000000","0.52864000"],["78706.26000000","0.30661000"],["78706.20000000","0.30000000"],["78706.16000000","0.00007000"],["78706.00000000","0.02400000"],["78705.80000000","0.00007000"],["78705.66000000","0.12705000"],["78705.01000000","0.00113000"],["78704.56000000","0.00007000"],["78704.55000000","0.00400000"],["78704.40000000","0.00254000"],["78704.21000000","0.00254000"],["78704.19000000","0.00014000"],["78704.17000000","0.00007000"],["78704.12000000","0.00007000"],["78704.05000000","0.03224000"],["78704.00000000","0.02400000"],["78703.88000000","0.12712000"],["78703.81000000","0.08576000"],["78703.71000000","0.00595000"],["78703.63000000","0.00326000"],["78703.58000000","0.00400000"],["78703.57000000","1.21952000"],["78703.18000000","0.02287000"],["78702.77000000","0.00010000"],["78702.29000000","0.00400000"],["78702.17000000","0.00007000"],["78702.07000000","0.00007000"],["78702.00000000","0.02400000"],["78701.92000000","0.00007000"],["78701.70000000","0.00408000"],["78701.59000000","0.00321000"],["78701.41000000","0.00007000"],["78701.14000000","0.00334000"],["78701.08000000","0.00027000"],["78701.00000000","0.00007000"],["78700.97000000","0.02600000"],["78700.49000000","0.02200000"],["78700.32000000","0.00414000"],["78700.17000000","0.00007000"],["78700.12000000","0.02800000"],["78700.04000000","0.02200000"],["78700.02000000","0.00007000"],["78700.00000000","0.05207000"],["78699.37000000","1.21952000"],["78699.00000000","0.00400000"],["78698.85000000","0.36224000"],["78698.28000000","1.90515000"],["78698.26000000","0.00014000"],["78698.17000000","0.00007000"],["78698.04000000","0.00007000"],["78698.00000000","0.02400000"],["78697.98000000","0.00007000"],["78697.92000000","0.03224000"],["78697.84000000","0.34712000"],["78697.66000000","0.00762000"]],"asks":[["78714.00000000","0.97172000"],["78714.01000000","0.00111000"],["78714.02000000","0.00013000"],["78714.47000000","0.00014000"],["78714.48000000","0.17967000"],["78714.58000000","0.00213000"],["78714.97000000","0.00014000"],["78714.98000000","0.20813000"],["78715.25000000","0.00014000"],["78715.26000000","0.03919000"],["78715.79000000","0.00007000"],["78715.80000000","0.00014000"],["78715.90000000","0.00323000"],["78715.94000000","0.00007000"],["78715.99000000","0.00014000"],["78716.00000000","0.02407000"],["78716.38000000","0.00007000"],["78716.51000000","0.00014000"],["78716.52000000","0.04701000"],["78716.58000000","0.05418000"],["78716.68000000","0.00333000"],["78717.10000000","0.00008000"],["78717.18000000","0.00007000"],["78717.44000000","0.00007000"],["78717.78000000","0.04701000"],["78717.88000000","0.04007000"],["78717.99000000","0.00007000"],["78718.00000000","0.02400000"],["78718.25000000","0.00325000"],["78718.43000000","0.00007000"],["78719.26000000","0.00230000"],["78719.67000000","0.00014000"],["78719.83000000","0.03000000"],["78719.89000000","0.00007000"],["78720.00000000","0.02400000"],["78720.10000000","0.00027000"],["78720.13000000","0.16711000"],["78720.14000000","0.00254000"],["78720.33000000","0.00007000"],["78720.48000000","0.00007000"],["78720.76000000","0.00007000"],["78720.89000000","0.00323000"],["78721.15000000","0.00316000"],["78721.32000000","0.00007000"],["78721.39000000","0.02161000"],["78721.40000000","0.12710000"],["78721.83000000","0.00007000"],["78721.99000000","0.00254000"],["78722.00000000","0.02407000"],["78722.03000000","0.08000000"],["78722.41000000","0.00047000"],["78722.52000000","0.00007000"],["78722.93000000","0.00254000"],["78722.94000000","0.00400000"],["78723.48000000","0.00007000"],["78723.50000000","0.00320000"],["78723.54000000","0.00014000"],["78723.94000000","0.00191000"],["78723.97000000","0.00007000"],["78724.00000000","0.02400000"],["78724.24000000","0.02286000"],["78724.45000000","0.00254000"],["78724.57000000","0.00007000"],["78724.59000000","0.02161000"],["78724.61000000","0.02057000"],["78724.62000000","0.02782000"],["78724.80000000","0.00008000"],["78725.10000000","0.31764000"],["78725.20000000","0.00007000"],["78725.29000000","0.00325000"],["78725.46000000","0.00400000"],["78725.50000000","0.00048000"],["78725.89000000","0.00137000"],["78726.00000000","0.02400000"],["78726.62000000","0.00007000"],["78726.63000000","0.00007000"],["78727.41000000","0.00014000"],["78727.44000000","0.00330000"],["78727.62000000","0.00400000"],["78727.76000000","0.00007000"],["78727.83000000","0.01035000"],["78727.84000000","0.02161000"],["78727.85000000","0.12701000"],["78727.89000000","0.21930000"],["78728.00000000","0.02400000"],["78728.01000000","0.04782000"],["78728.32000000","0.09414000"],["78728.44000000","0.38115000"],["78728.61000000","0.02000000"],["78728.66000000","0.00007000"],["78729.00000000","0.00007000"],["78729.08000000","0.00007000"],["78729.30000000","0.02000000"],["78729.37000000","0.00635000"],["78729.54000000","0.00160000"],["78729.60000000","0.00400000"],["78729.66000000","1.90515000"],["78729.67000000","1.21952000"],["78729.68000000","0.11793000"],["78729.83000000","0.00007000"]]}}
{"rx_ns": 42254047500, "frame": {"e":"depthUpdate","E":1787603099714,"s":"BTCUSDT","U":99076638969,"u":99076638981,"b":[["78626.36000000","0.00000000"],["70842.60000000","0.00416000"],["70842.59000000","0.00000000"],["70842.58000000","0.00009000"],["70842.00000000","0.00225000"]],"a":[["78714.00000000","0.94737000"]]}}
{"rx_ns": 42357488600, "frame": {"e":"depthUpdate","E":1787603099814,"s":"BTCUSDT","U":99076638982,"u":99076639025,"b":[["78713.99000000","3.95262000"],["78641.88000000","0.02600000"],["78320.42000000","0.01000000"],["77928.81000000","0.01010000"],["77539.17000000","0.01000000"],["77151.47000000","0.01000000"],["76765.72000000","0.01000000"],["76381.89000000","0.01000000"],["75999.98000000","0.01012000"],["75619.98000000","0.01000000"],["75241.88000000","0.01000000"],["74865.67000000","0.01009000"],["74491.34000000","0.01000000"],["74118.88000000","0.01000000"],["73748.29000000","0.01000000"],["73379.55000000","0.01000000"],["73012.65000000","0.01000000"],["70842.60000000","0.00432000"]],"a":[["78714.00000000","0.94750000"],["79107.57000000","0.01000000"],["79503.11000000","0.01000000"],["79900.63000000","0.01000000"],["80142.86000000","0.10277000"],["80300.13000000","0.01000000"],["80701.63000000","0.01000000"],["81105.14000000","0.01000000"],["81510.67000000","0.01000000"],["81918.22000000","0.01000000"],["82327.81000000","0.01000000"],["82739.45000000","0.01000000"],["83153.15000000","0.01111000"],["83568.91000000","0.01000000"],["83986.76000000","0.01000000"],["84406.69000000","0.01000000"],["84828.72000000","0.01000000"]]}}
{"rx_ns": 42453635300, "frame": {"e":"depthUpdate","E":1787603099915,"s":"BTCUSDT","U":99076639026,"u":99076639029,"b":[["78638.17000000","0.00663000"],["78626.36000000","0.02116000"],["78624.63000000","0.00000000"],["70842.60000000","0.00416000"]],"a":[]}}
{"rx_ns": 42558110500, "frame": {"e":"depthUpdate","E":1787603100014,"s":"BTCUSDT","U":99076639030,"u":99076639780,"b":[["78715.99000000","4.88735000"],["78715.98000000","2.04845000"],["78715.97000000","0.00013000"],["78715.93000000","0.00000000"],["78715.90000000","0.07500000"],["78715.89000000","0.00000000"],["78715.80000000","0.00014000"],["78715.79000000","0.00000000"],["78715.78000000","0.00000000"],["78715.27000000","0.00000000"],["78715.26000000","2.19959000"],["78715.25000000","0.56069000"],["78715.24000000","0.00000000"],["78715.23000000","0.00000000"],["78714.97000000","0.00000000"],["78714.57000000","0.00000000"],["78714.47000000","0.00000000"],["78714.46000000","0.00000000"],["78714.01000000","0.00000000"],["78714.00000000","1.21952000"],["78713.99000000","0.14071000"],["78713.98000000","0.00000000"],["78713.97000000","0.00000000"],["78713.48000000","0.00400000"],["78713.46000000","0.00325000"],["78713.16000000","0.00000000"],["78713.15000000","0.03561000"],["78712.92000000","0.03224000"],["78712.48000000","0.00000000"],["78712.30000000","0.00007000"],["78712.00000000","0.00500000"],["78711.93000000","0.00014000"],["78711.26000000","0.00000000"],["78711.25000000","0.04319000"],["78710.62000000","0.00000000"],["78710.61000000","0.01463000"],["78710.00000000","0.04407000"],["78709.70000000","0.00000000"],["78708.80000000","0.00000000"],["78707.71000000","0.00007000"],["78707.53000000","0.04200000"],["78707.17000000","0.00000000"],["78706.35000000","0.00000000"],["78706.27000000","0.30007000"],["78706.09000000","0.08576000"],["78705.77000000","0.03000000"],["78704.64000000","0.34309000"],["78704.63000000","0.00000000"],["78704.40000000","0.00000000"],["78703.88000000","0.12719000"],["78703.81000000","0.00000000"],["78701.71000000","0.02000000"],["78700.91000000","0.02000000"],["78700.84000000","0.02200000"],["78700.83000000","0.00000000"],["78700.72000000","0.38123000"],["78700.50000000","0.13243000"],["78700.00000000","0.14737000"],["78698.40000000","0.34312000"],["78698.26000000","0.00007000"],["78697.37000000","0.08000000"],["78695.37000000","0.00635000"],["78691.89000000","0.13453000"],["78689.91000000","0.00000000"],["78688.03000000","0.13390000"],["78685.90000000","0.50698000"],["78685.73000000","0.00000000"],["78684.94000000","0.00000000"],["78683.66000000","0.00000000"],["78681.38000000","0.00400000"],["78680.79000000","0.00000000"],["78680.03000000","0.09770000"],["78679.30000000","0.00000000"],["78679.24000000","0.00000000"],["78679.02000000","0.00000000"],["78676.69000000","0.02519000"],["78673.23000000","0.00000000"],["78672.73000000","0.00000000"],["78671.54000000","0.00000000"],["78671.23000000","0.00000000"],["78669.82000000","0.00000000"],["78654.76000000","0.00007000"],["78650.93000000","0.00000000"],["78645.41000000","0.00317000"],["78639.98000000","0.00000000"],["78632.01000000","0.00317000"],["78628.01000000","0.00000000"],["78626.36000000","0.00000000"],["78570.23000000","1.52223000"],["78565.62000000","0.00127000"],["78559.20000000","0.00000000"],["78553.15000000","0.00127000"],["78547.76000000","0.00000000"],["78380.20000000","0.00000000"],["70846.20000000","0.00000000"],["70844.40000000","0.00016000"],["70842.60000000","0.00000000"],["70842.58000000","0.00000000"],["62972.80000000","0.00031000"]],"a":[["78714.00000000","0.00000000"],["78714.01000000","0.00000000"],["78714.02000000","0.00000000"],["78714.47000000","0.00000000"],["78714.48000000","0.00000000"],["78714.58000000","0.00000000"],["78714.97000000","0.00000000"],["78714.98000000","0.00000000"],["78715.25000000","0.00000000"],["78715.26000000","0.00000000"],["78715.27000000","0.00000000"],["78715.79000000","0.00000000"],["78715.80000000","0.00000000"],["78715.90000000","0.00000000"],["78715.94000000","0.00000000"],["78715.99000000","0.00000000"],["78716.00000000","0.00135000"],["78716.01000000","0.00056000"],["78716.38000000","0.00000000"],["78716.57000000","0.00000000"],["78716.58000000","0.00021000"],["78716.68000000","0.00000000"],["78716.95000000","0.20799000"],["78717.10000000","0.00000000"],["78717.18000000","0.00000000"],["78717.77000000","0.00014000"],["78717.83000000","0.00014000"],["78717.84000000","0.00007000"],["78717.87000000","0.00014000"],["78717.99000000","0.00007000"],["78718.00000000","0.02407000"],["78718.25000000","0.00000000"],["78718.43000000","0.00000000"],["78718.58000000","0.05397000"],["78719.17000000","0.00204000"],["78719.67000000","0.00007000"],["78719.83000000","0.00007000"],["78719.89000000","0.00000000"],["78720.00000000","0.02407000"],["78720.10000000","0.00000000"],["78720.13000000","0.00014000"],["78720.14000000","0.00000000"],["78720.33000000","0.00000000"],["78720.89000000","0.00000000"],["78721.14000000","0.00000000"],["78721.15000000","0.00000000"],["78721.39000000","0.00007000"],["78721.40000000","0.00000000"],["78721.93000000","0.00000000"],["78721.99000000","0.00000000"],["78722.03000000","0.00000000"],["78722.08000000","0.00000000"],["78722.93000000","0.00000000"],["78723.09000000","0.00000000"],["78723.13000000","0.00000000"],["78723.50000000","0.00000000"],["78723.54000000","0.00014000"],["78723.93000000","0.00000000"],["78724.23000000","0.00000000"],["78724.59000000","0.00000000"],["78724.76000000","0.00329000"],["78725.10000000","0.00000000"],["78725.43000000","0.00000000"],["78725.45000000","0.00000000"],["78725.88000000","0.00000000"],["78725.89000000","0.00000000"],["78725.91000000","0.00048000"],["78725.99000000","0.00000000"],["78726.40000000","0.00069000"],["78726.61000000","0.00000000"],["78727.03000000","0.15000000"],["78727.39000000","0.00254000"],["78727.40000000","0.00254000"],["78727.66000000","0.00000000"],["78727.83000000","0.00000000"],["78727.84000000","0.00000000"],["78728.31000000","0.00000000"],["78728.44000000","0.00000000"],["78729.07000000","0.00000000"],["78729.29000000","0.00000000"],["78729.37000000","0.00000000"],["78729.59000000","0.31762000"],["78729.65000000","0.02561000"],["78729.66000000","0.00000000"],["78729.67000000","0.00000000"],["78729.78000000","0.00007000"],["78730.73000000","0.00000000"],["78730.84000000","0.00000000"],["78731.65000000","0.00000000"],["78732.32000000","0.00000000"],["78732.49000000","0.00000000"],["78732.61000000","0.00000000"],["78733.11000000","0.04857000"],["78733.39000000","0.00635000"],["78733.72000000","1.21952000"],["78733.73000000","0.00000000"],["78733.74000000","0.00000000"],["78733.76000000","0.00000000"],["78734.22000000","0.25410000"],["78734.75000000","0.00000000"],["78735.01000000","0.38115000"],["78735.03000000","0.02000000"],["78735.41000000","0.00000000"],["78736.18000000","0.00000000"],["78737.18000000","0.00000000"],["78737.48000000","0.00227000"],["78737.49000000","1.90515000"],["78737.50000000","0.00000000"],["78737.62000000","0.00000000"],["78738.45000000","0.00400000"],["78738.69000000","0.12700000"],["78739.58000000","0.00000000"],["78739.85000000","0.00000000"],["78740.00000000","0.02400000"],["78740.32000000","0.00000000"],["78740.65000000","0.00000000"],["78740.85000000","0.00000000"],["78741.39000000","0.09525000"],["78741.62000000","0.00000000"],["78742.43000000","0.00000000"],["78746.75000000","0.00000000"],["78747.01000000","0.00000000"],["78747.96000000","0.00000000"],["78749.24000000","0.00000000"],["78749.67000000","0.00000000"],["78749.88000000","0.00000000"],["78750.21000000","0.00000000"],["78750.25000000","0.00000000"],["78750.37000000","0.00000000"],["78750.57000000","0.43578000"],["78750.61000000","0.00000000"],["78750.65000000","0.00000000"],["78751.12000000","0.00000000"],["78753.53000000","0.34288000"],["78754.00000000","0.02400000"],["78754.03000000","0.00000000"],["78754.50000000","0.00014000"],["78755.00000000","0.00000000"],["78756.00000000","0.03400000"],["78757.54000000","0.00000000"],["78758.29000000","0.00000000"],["78758.37000000","0.00007000"],["78759.76000000","0.00000000"],["78763.15000000","1.25707000"],["78763.99000000","0.00000000"],["78765.99000000","0.00315000"],["78767.71000000","0.00435000"],["78768.75000000","0.00427000"],["78771.57000000","0.02192000"],["78777.99000000","0.00190000"],["78785.13000000","0.00000000"],["78785.77000000","1.25671000"],["78786.89000000","0.00316000"],["78790.14000000","0.00000000"],["78790.64000000","1.21952000"],["78797.82000000","1.90515000"],["78805.19000000","0.00000000"],["78806.33000000","0.00000000"],["78807.75000000","0.00000000"],["78808.94000000","0.93647000"],["78839.99000000","0.00000000"],["78843.01000000","0.00127000"],["78856.56000000","0.00076000"],["78858.29000000","0.00000000"],["78861.99000000","0.00000000"],["78864.85000000","0.00127000"],["78869.35000000","1.52223000"],["78926.22000000","0.00007000"],["78966.02000000","0.00000000"],["78975.75000000","0.00030000"],["79107.57000000","0.00000000"],["79503.11000000","0.00000000"],["79900.63000000","0.00000000"],["80300.13000000","0.00000000"],["80701.63000000","0.00000000"],["81105.14000000","0.00000000"],["81510.67000000","0.00000000"],["81918.22000000","0.00000000"],["82327.81000000","0.00000000"],["82739.45000000","0.00000000"],["83153.15000000","0.00111000"],["83568.91000000","0.00000000"],["83986.76000000","0.00000000"],["84406.69000000","0.00000000"],["84828.72000000","0.00000000"],["86422.88000000","0.18910000"]]}}
{"rx_ns": 42660119800, "frame": {"e":"depthUpdate","E":1787603100114,"s":"BTCUSDT","U":99076639781,"u":99076641323,"b":[["78721.99000000","5.46136000"],["78721.98000000","0.00020000"],["78721.97000000","0.00013000"],["78721.86000000","0.00000000"],["78721.84000000","0.00000000"],["78721.83000000","2.24018000"],["78721.82000000","2.36779000"],["78721.81000000","0.00000000"],["78721.80000000","0.00000000"],["78721.39000000","0.00000000"],["78721.38000000","0.05290000"],["78721.32000000","0.00007000"],["78721.31000000","0.04009000"],["78720.76000000","0.00007000"],["78720.75000000","0.45332000"],["78720.47000000","0.02317000"],["78720.12000000","0.00000000"],["78720.00000000","0.00007000"],["78719.99000000","0.03324000"],["78719.98000000","0.00000000"],["78719.97000000","0.00000000"],["78719.90000000","0.00400000"],["78719.67000000","0.00014000"],["78719.66000000","0.00007000"],["78719.27000000","0.00000000"],["78719.26000000","0.07500000"],["78719.25000000","0.34653000"],["78719.16000000","0.00000000"],["78719.09000000","0.00007000"],["78719.08000000","0.00007000"],["78719.02000000","0.00000000"],["78718.93000000","0.04818000"],["78718.67000000","0.00000000"],["78718.57000000","0.00007000"],["78718.00000000","0.00007000"],["78717.99000000","1.65960000"],["78717.98000000","0.00007000"],["78717.88000000","0.07500000"],["78717.87000000","0.25738000"],["78717.86000000","0.00000000"],["78717.85000000","0.00000000"],["78717.83000000","0.00000000"],["78717.82000000","0.36231000"],["78717.81000000","0.12710000"],["78717.78000000","0.00000000"],["78717.77000000","0.56115000"],["78717.76000000","0.00400000"],["78717.75000000","0.00000000"],["78717.43000000","0.00000000"],["78717.41000000","0.03224000"],["78717.10000000","0.00008000"],["78717.01000000","0.00027000"],["78716.94000000","0.00000000"],["78716.57000000","0.00000000"],["78716.52000000","1.90515000"],["78716.51000000","0.64513000"],["78716.50000000","0.00000000"],["78716.49000000","0.04007000"],["78716.36000000","0.00000000"],["78716.00000000","0.00007000"],["78715.99000000","0.61831000"],["78715.98000000","0.00000000"],["78715.97000000","0.00000000"],["78715.90000000","0.00000000"],["78715.81000000","0.00000000"],["78715.74000000","0.00000000"],["78715.62000000","0.00400000"],["78715.26000000","0.21937000"],["78715.25000000","0.40013000"],["78715.00000000","0.00007000"],["78714.29000000","0.00000000"],["78714.01000000","0.00007000"],["78714.00000000","1.21952000"],["78713.99000000","0.00020000"],["78713.78000000","0.11000000"],["78713.15000000","0.00007000"],["78713.14000000","0.00000000"],["78712.92000000","0.00000000"],["78712.68000000","0.00000000"],["78712.67000000","0.08576000"],["78712.28000000","0.04000000"],["78711.99000000","0.00532000"],["78711.92000000","0.00000000"],["78711.41000000","0.34306000"],["78711.25000000","0.00000000"],["78711.24000000","0.00000000"],["78710.93000000","0.00007000"],["78710.86000000","0.00007000"],["78710.64000000","0.00010000"],["78710.61000000","0.00000000"],["78710.01000000","0.00000000"],["78710.00000000","0.04400000"],["78709.99000000","0.04023000"],["78709.88000000","0.00007000"],["78709.71000000","0.00000000"],["78709.68000000","0.00007000"],["78709.36000000","0.00000000"],["78709.27000000","0.00000000"],["78709.20000000","0.00000000"],["78708.79000000","0.00000000"],["78708.64000000","0.00000000"],["78708.51000000","0.00000000"],["78708.10000000","0.00000000"],["78707.88000000","0.38119000"],["78707.53000000","0.00000000"],["78707.14000000","0.00000000"],["78706.93000000","0.00000000"],["78706.84000000","0.00000000"],["78706.30000000","0.00000000"],["78706.28000000","0.30000000"],["78706.27000000","0.30000000"],["78706.26000000","0.30654000"],["78706.20000000","0.00000000"],["78706.17000000","0.00007000"],["78706.09000000","0.00000000"],["78705.77000000","0.00000000"],["78705.76000000","0.00000000"],["78705.66000000","0.12705000"],["78704.56000000","0.00000000"],["78704.40000000","0.00000000"],["78703.88000000","0.12712000"],["78703.63000000","0.00000000"],["78702.76000000","0.06525000"],["78702.29000000","0.00000000"],["78701.59000000","0.00000000"],["78701.41000000","0.00000000"],["78700.79000000","0.07531000"],["78700.12000000","0.31428000"],["78698.40000000","0.00000000"],["78698.24000000","0.00000000"],["78697.37000000","0.00000000"],["78696.45000000","0.00014000"],["78696.28000000","0.00000000"],["78695.07000000","0.00000000"],["78694.29000000","0.00000000"],["78692.54000000","0.00000000"],["78692.33000000","0.00000000"],["78691.91000000","0.00400000"],["78691.89000000","0.13453000"],["78691.80000000","0.00000000"],["78690.98000000","0.00000000"],["78690.28000000","0.00000000"],["78690.11000000","0.00000000"],["78689.89000000","0.00400000"],["78689.85000000","0.00000000"],["78689.30000000","0.09622000"],["78688.03000000","0.00000000"],["78687.71000000","1.25828000"],["78686.28000000","0.00000000"],["78685.38000000","0.00000000"],["78683.58000000","0.00000000"],["78683.26000000","0.00000000"],["78682.74000000","0.67013000"],["78681.38000000","0.00000000"],["78680.97000000","0.00000000"],["78680.03000000","0.00000000"],["78677.50000000","0.00000000"],["78677.10000000","0.00000000"],["78677.00000000","0.01000000"],["78676.38000000","0.02343000"],["78675.00000000","0.70000000"],["78674.00000000","0.02400000"],["78672.65000000","0.00000000"],["78670.00000000","0.02400000"],["78669.35000000","0.87131000"],["78662.35000000","0.00000000"],["78657.74000000","0.00000000"],["78657.06000000","0.00000000"],["78655.89000000","0.00000000"],["78655.02000000","0.00000000"],["78654.76000000","0.00000000"],["78651.53000000","0.00000000"],["78645.64000000","0.00000000"],["78638.01000000","0.00317000"],["78632.01000000","0.00000000"],["78589.61000000","0.04092000"],["78575.60000000","0.00127000"],["78568.76000000","0.00000000"],["78501.75000000","0.00000000"],["78462.41000000","0.00000000"],["78389.86000000","0.00027000"],["78232.00000000","0.00008000"],["78005.56000000","0.00000000"],["77941.97000000","0.00400000"],["70849.16000000","0.00000000"],["70844.40000000","0.00000000"],["70844.00000000","0.00020000"],["62972.79000000","0.00000000"]],"a":[["78716.00000000","0.00000000"],["78716.01000000","0.00000000"],["78716.51000000","0.00000000"],["78716.52000000","0.00000000"],["78716.53000000","0.00000000"],["78716.58000000","0.00000000"],["78716.94000000","0.00000000"],["78716.95000000","0.00000000"],["78717.44000000","0.00000000"],["78717.77000000","0.00000000"],["78717.78000000","0.00000000"],["78717.79000000","0.00000000"],["78717.83000000","0.00000000"],["78717.84000000","0.00000000"],["78717.87000000","0.00000000"],["78717.88000000","0.00000000"],["78717.89000000","0.00000000"],["78717.99000000","0.00000000"],["78718.00000000","0.00000000"],["78718.57000000","0.00000000"],["78718.58000000","0.00000000"],["78719.09000000","0.00000000"],["78719.10000000","0.00000000"],["78719.17000000","0.00000000"],["78719.26000000","0.00000000"],["78719.44000000","0.00000000"],["78719.48000000","0.00000000"],["78719.67000000","0.00000000"],["78719.83000000","0.00000000"],["78719.99000000","0.00000000"],["78720.00000000","0.00000000"],["78720.13000000","0.00000000"],["78720.36000000","0.00000000"],["78720.48000000","0.00000000"],["78720.52000000","0.00000000"],["78720.59000000","0.00000000"],["78720.76000000","0.00000000"],["78720.95000000","0.00000000"],["78720.99000000","0.00000000"],["78721.32000000","0.00000000"],["78721.39000000","0.00000000"],["78721.83000000","0.00000000"],["78721.84000000","0.00000000"],["78721.85000000","0.00000000"],["78721.86000000","0.00000000"],["78721.87000000","0.00000000"],["78721.96000000","0.00000000"],["78721.99000000","0.00000000"],["78722.00000000","0.00136000"],["78722.01000000","0.00056000"],["78722.41000000","0.00000000"],["78722.44000000","0.00000000"],["78722.52000000","0.00000000"],["78722.64000000","0.00508000"],["78722.94000000","0.00000000"],["78723.48000000","0.00000000"],["78723.54000000","0.00007000"],["78723.94000000","0.00000000"],["78723.97000000","0.00000000"],["78723.99000000","0.00014000"],["78724.00000000","0.02407000"],["78724.23000000","0.00000000"],["78724.24000000","0.00007000"],["78724.44000000","0.05345000"],["78724.45000000","0.00000000"],["78724.60000000","0.00000000"],["78724.61000000","0.00007000"],["78724.62000000","0.00007000"],["78724.76000000","0.00000000"],["78724.80000000","0.00000000"],["78725.29000000","0.00000000"],["78725.46000000","0.00000000"],["78725.91000000","0.00000000"],["78725.99000000","0.00014000"],["78726.63000000","0.00000000"],["78727.02000000","0.00000000"],["78727.03000000","0.00007000"],["78727.39000000","0.00000000"],["78727.40000000","0.00000000"],["78727.41000000","0.00007000"],["78727.44000000","0.00000000"],["78727.61000000","0.00000000"],["78727.62000000","0.00000000"],["78727.72000000","0.00000000"],["78727.73000000","0.00000000"],["78727.85000000","0.00007000"],["78727.89000000","0.00007000"],["78727.99000000","0.00014000"],["78728.01000000","0.00000000"],["78728.31000000","0.00014000"],["78728.41000000","0.00000000"],["78728.60000000","0.00007000"],["78728.61000000","0.00000000"],["78729.54000000","0.00000000"],["78729.59000000","0.00000000"],["78729.60000000","0.00000000"],["78729.65000000","0.00000000"],["78729.68000000","0.00000000"],["78729.93000000","0.00000000"],["78729.99000000","0.00000000"],["78730.02000000","0.00000000"],["78730.16000000","0.00000000"],["78730.22000000","0.00000000"],["78730.23000000","0.00000000"],["78730.70000000","0.00000000"],["78731.28000000","0.00007000"],["78731.33000000","0.00000000"],["78731.37000000","0.00000000"],["78731.38000000","0.00000000"],["78731.47000000","0.00000000"],["78731.66000000","0.00000000"],["78731.67000000","0.00000000"],["78731.76000000","0.00000000"],["78732.10000000","0.00000000"],["78732.11000000","0.00000000"],["78732.34000000","0.00000000"],["78732.47000000","0.00000000"],["78732.53000000","0.02000000"],["78732.63000000","0.00000000"],["78732.73000000","0.08000000"],["78732.93000000","0.00007000"],["78733.11000000","0.00000000"],["78733.31000000","0.00000000"],["78733.32000000","0.00000000"],["78733.35000000","0.00000000"],["78733.39000000","0.00000000"],["78733.40000000","0.00000000"],["78733.44000000","0.07000000"],["78733.45000000","0.00048000"],["78733.53000000","0.00007000"],["78733.55000000","0.00000000"],["78733.71000000","0.00000000"],["78733.72000000","0.00000000"],["78733.82000000","0.00000000"],["78733.96000000","0.00000000"],["78734.19000000","0.00000000"],["78734.22000000","0.00000000"],["78734.38000000","0.00000000"],["78734.39000000","0.00000000"],["78734.80000000","0.00000000"],["78735.01000000","0.00000000"],["78735.03000000","0.00000000"],["78735.15000000","0.00007000"],["78735.35000000","0.00188000"],["78735.61000000","0.00329000"],["78735.99000000","0.00000000"],["78736.08000000","0.00007000"],["78736.83000000","0.00000000"],["78736.84000000","0.00007000"],["78736.85000000","0.00007000"],["78737.48000000","0.02161000"],["78737.49000000","0.00000000"],["78737.54000000","0.00000000"],["78737.55000000","0.00000000"],["78737.60000000","0.00000000"],["78737.65000000","0.00000000"],["78737.97000000","0.00000000"],["78737.98000000","0.00000000"],["78737.99000000","0.00000000"],["78738.07000000","0.16040000"],["78738.38000000","0.00254000"],["78738.39000000","0.00000000"],["78738.44000000","0.00254000"],["78738.69000000","0.00000000"],["78739.02000000","0.00007000"],["78739.37000000","0.00000000"],["78739.54000000","0.00000000"],["78739.55000000","0.00332000"],["78739.70000000","0.04857000"],["78740.22000000","0.00321000"],["78740.26000000","0.02285000"],["78740.44000000","0.00000000"],["78740.71000000","0.00137000"],["78740.92000000","0.00253000"],["78741.04000000","0.00000000"],["78741.27000000","0.31761000"],["78741.39000000","0.00000000"],["78741.63000000","0.00000000"],["78741.92000000","0.00000000"],["78741.99000000","0.02161000"],["78742.00000000","0.02400000"],["78742.40000000","0.00635000"],["78742.41000000","0.00000000"],["78742.47000000","0.00635000"],["78742.52000000","0.00000000"],["78742.63000000","0.00000000"],["78742.70000000","0.00000000"],["78742.83000000","0.00000000"],["78742.89000000","0.00007000"],["78743.00000000","0.00007000"],["78743.31000000","0.06522000"],["78743.49000000","0.00319000"],["78744.54000000","0.02000000"],["78744.80000000","0.00000000"],["78745.19000000","0.02788000"],["78745.20000000","0.00000000"],["78745.28000000","0.07526000"],["78746.00000000","0.02400000"],["78746.76000000","0.00007000"],["78746.90000000","1.21952000"],["78746.91000000","0.00000000"],["78747.10000000","0.00000000"],["78748.10000000","0.00333000"],["78748.16000000","0.00000000"],["78748.63000000","0.00000000"],["78749.00000000","0.00000000"],["78749.84000000","0.00000000"],["78750.00000000","0.02407000"],["78750.21000000","0.00000000"],["78750.57000000","0.00000000"],["78751.15000000","1.90515000"],["78751.16000000","1.21952000"],["78751.57000000","0.00000000"],["78751.98000000","0.00000000"],["78752.11000000","0.00000000"],["78752.15000000","0.00000000"],["78752.26000000","0.00000000"],["78752.68000000","0.00000000"],["78752.73000000","0.00000000"],["78752.94000000","0.00000000"],["78754.34000000","0.00000000"],["78755.71000000","0.34287000"],["78755.98000000","0.00322000"],["78756.00000000","0.02400000"],["78756.28000000","0.00400000"],["78756.99000000","0.00000000"],["78757.46000000","0.00000000"],["78757.97000000","0.00000000"],["78758.00000000","0.02400000"],["78758.37000000","0.00014000"],["78758.42000000","0.00400000"],["78758.61000000","0.00000000"],["78759.00000000","0.00000000"],["78759.04000000","0.43574000"],["78760.00000000","0.11923000"],["78760.22000000","0.00000000"],["78761.81000000","0.04633000"],["78762.00000000","0.03400000"],["78762.24000000","0.00007000"],["78762.70000000","0.00400000"],["78763.14000000","0.36224000"],["78763.15000000","0.00000000"],["78763.86000000","0.00331000"],["78765.05000000","0.02161000"],["78765.99000000","0.00000000"],["78766.11000000","0.00007000"],["78766.98000000","0.00400000"],["78769.98000000","0.00007000"],["78771.32000000","0.00315000"],["78771.33000000","0.00000000"],["78771.98000000","0.02161000"],["78773.60000000","0.00000000"],["78776.08000000","0.02161000"],["78777.99000000","0.00000000"],["78778.79000000","0.00000000"],["78779.23000000","0.00000000"],["78779.85000000","0.00000000"],["78786.89000000","0.00000000"],["78787.11000000","0.02161000"],["78789.86000000","0.00313000"],["78797.81000000","1.21952000"],["78797.83000000","0.00000000"],["78798.62000000","0.31836000"],["78807.75000000","1.90515000"],["78808.05000000","1.21952000"],["78808.94000000","0.00000000"],["78817.73000000","1.90515000"],["78818.29000000","1.21952000"],["78825.75000000","0.02789000"],["78831.40000000","0.21930000"],["78843.01000000","0.00000000"],["78849.73000000","0.00127000"],["78851.09000000","0.00000000"],["78856.56000000","0.00000000"],["78928.59000000","0.00000000"],["78975.75000000","0.00000000"],["79035.45000000","7.59240000"],["79273.61000000","0.00000000"],["86422.88000000","0.20801000"]]}}
{"rx_ns": 42758797500, "frame": {"e":"depthUpdate","E":1787603100214,"s":"BTCUSDT","U":99076641324,"u":99076642830,"b":[["78728.21000000","5.42711000"],["78728.00000000","0.39265000"],["78727.99000000","2.33486000"],["78727.98000000","0.00000000"],["78727.97000000","0.00000000"],["78727.88000000","0.00000000"],["78727.84000000","0.00007000"],["78727.75000000","0.00000000"],["78727.41000000","0.00014000"],["78727.40000000","0.00000000"],["78727.04000000","0.00000000"],["78727.03000000","0.00000000"],["78727.02000000","0.00000000"],["78726.97000000","0.00000000"],["78726.96000000","0.11457000"],["78726.95000000","0.70548000"],["78726.94000000","0.00000000"],["78726.93000000","0.00000000"],["78726.62000000","1.21952000"],["78726.61000000","0.00014000"],["78726.59000000","0.00000000"],["78726.40000000","0.11029000"],["78726.39000000","0.00021000"],["78726.32000000","0.00400000"],["78726.10000000","0.00000000"],["78726.00000000","0.07500000"],["78725.99000000","0.04924000"],["78725.98000000","0.00007000"],["78725.69000000","0.39377000"],["78725.49000000","0.00007000"],["78725.34000000","0.00007000"],["78725.20000000","0.04048000"],["78725.19000000","0.21944000"],["78725.18000000","0.00000000"],["78725.17000000","0.00000000"],["78725.10000000","0.04818000"],["78724.61000000","0.00000000"],["78724.60000000","0.00007000"],["78724.56000000","0.00000000"],["78724.51000000","0.00000000"],["78724.44000000","0.03491000"],["78724.43000000","0.13013000"],["78724.42000000","0.04097000"],["78724.41000000","0.00000000"],["78724.23000000","0.00000000"],["78724.18000000","0.00400000"],["78724.00000000","0.25520000"],["78723.99000000","0.55857000"],["78723.98000000","0.00000000"],["78723.97000000","0.00000000"],["78723.54000000","0.00014000"],["78723.53000000","0.00000000"],["78722.63000000","0.00000000"],["78722.58000000","0.03000000"],["78722.33000000","0.01669000"],["78722.30000000","0.00000000"],["78722.04000000","0.00400000"],["78722.00000000","1.90529000"],["78721.99000000","1.23963000"],["78721.98000000","0.00000000"],["78721.97000000","0.00000000"],["78721.93000000","0.00254000"],["78721.84000000","0.00000000"],["78721.83000000","0.21930000"],["78721.82000000","0.21060000"],["78721.54000000","0.00000000"],["78721.38000000","0.00014000"],["78721.31000000","0.04002000"],["78721.10000000","0.00000000"],["78721.07000000","0.02781000"],["78721.06000000","0.00000000"],["78720.75000000","0.30014000"],["78720.47000000","0.30000000"],["78720.31000000","0.00007000"],["78719.99000000","0.30007000"],["78719.90000000","0.30400000"],["78719.81000000","0.03338000"],["78719.30000000","0.02286000"],["78719.26000000","0.00000000"],["78719.25000000","0.30651000"],["78718.93000000","0.00000000"],["78718.57000000","0.00000000"],["78718.55000000","0.03338000"],["78718.51000000","0.00010000"],["78718.00000000","0.00000000"],["78717.99000000","1.61713000"],["78717.98000000","0.00000000"],["78717.88000000","0.00000000"],["78717.87000000","0.00014000"],["78717.81000000","0.12703000"],["78717.77000000","0.41797000"],["78717.76000000","0.34703000"],["78717.57000000","0.08576000"],["78717.41000000","0.00000000"],["78717.16000000","0.00007000"],["78716.51000000","0.39282000"],["78716.00000000","0.00000000"],["78715.99000000","0.22259000"],["78715.80000000","0.38130000"],["78715.26000000","0.00000000"],["78715.25000000","0.00332000"],["78714.61000000","0.00007000"],["78714.28000000","0.00000000"],["78713.99000000","0.00000000"],["78713.78000000","0.08000000"],["78713.15000000","0.00000000"],["78713.08000000","0.00000000"],["78712.67000000","0.00000000"],["78712.32000000","0.00400000"],["78711.88000000","0.00000000"],["78710.86000000","0.00000000"],["78710.37000000","0.00189000"],["78710.23000000","0.34306000"],["78710.01000000","0.63519000"],["78710.00000000","0.13929000"],["78709.88000000","0.00000000"],["78709.01000000","0.00000000"],["78708.24000000","0.00007000"],["78707.71000000","0.00000000"],["78707.10000000","0.00059000"],["78706.69000000","0.00012000"],["78706.28000000","0.00000000"],["78706.27000000","0.00000000"],["78706.26000000","0.00332000"],["78706.04000000","0.06525000"],["78704.37000000","0.00126000"],["78704.21000000","0.00000000"],["78704.07000000","0.07530000"],["78703.18000000","0.00000000"],["78702.86000000","0.02400000"],["78702.76000000","0.00000000"],["78702.75000000","0.00007000"],["78701.00000000","0.00000000"],["78700.79000000","0.00000000"],["78699.61000000","0.13707000"],["78698.05000000","0.00406000"],["78697.84000000","0.00400000"],["78697.42000000","0.00000000"],["78696.13000000","0.00000000"],["78695.85000000","0.00800000"],["78695.75000000","0.00000000"],["78695.65000000","0.00000000"],["78695.63000000","0.00000000"],["78695.26000000","0.00000000"],["78694.78000000","0.00000000"],["78694.75000000","0.00000000"],["78694.66000000","0.00000000"],["78694.50000000","0.00000000"],["78694.43000000","0.00000000"],["78693.26000000","0.00000000"],["78693.12000000","0.00000000"],["78692.88000000","0.00000000"],["78691.91000000","0.00000000"],["78691.74000000","0.00000000"],["78691.68000000","0.00000000"],["78691.00000000","0.00000000"],["78690.40000000","0.00000000"],["78690.19000000","0.00000000"],["78689.89000000","0.00000000"],["78688.71000000","0.00000000"],["78688.39000000","0.00000000"],["78687.92000000","0.00000000"],["78687.71000000","0.00000000"],["78686.08000000","0.02446000"],["78686.07000000","0.00000000"],["78684.84000000","0.00000000"],["78682.00000000","0.03400000"],["78680.00000000","0.02439000"],["78679.01000000","0.02784000"],["78678.00000000","0.02400000"],["78677.51000000","0.00631000"],["78677.00000000","0.00000000"],["78676.69000000","0.00000000"],["78676.15000000","0.00425000"],["78675.64000000","0.01137000"],["78673.58000000","0.00431000"],["78672.46000000","0.00436000"],["78664.03000000","0.00000000"],["78663.65000000","0.00000000"],["78661.15000000","0.00000000"],["78659.62000000","0.01699000"],["78658.70000000","0.00406000"],["78658.20000000","0.00000000"],["78656.98000000","0.00000000"],["78652.33000000","0.02200000"],["78650.69000000","0.00000000"],["78642.73000000","0.00000000"],["78641.67000000","0.00000000"],["78640.89000000","0.00000000"],["78640.67000000","0.00000000"],["78639.75000000","0.00007000"],["78627.22000000","0.00406000"],["78624.00000000","0.02414000"],["78621.30000000","0.00000000"],["78620.85000000","0.00000000"],["78608.25000000","0.00007000"],["78605.56000000","0.00000000"],["78592.50000000","0.00007000"],["78589.82000000","0.00000000"],["78589.61000000","0.00000000"],["78586.88000000","1.52223000"],["78580.00000000","0.00463000"],["78576.75000000","0.00007000"],["78574.08000000","0.00000000"],["78573.63000000","0.00000000"],["78570.23000000","0.00000000"],["78561.00000000","0.00007000"],["78558.34000000","0.00000000"],["78546.68000000","0.00000000"],["78545.25000000","0.00007000"],["78543.36000000","3.81998000"],["78542.60000000","0.00000000"],["78526.86000000","0.00000000"],["78511.12000000","0.00000000"],["78509.17000000","0.00406000"],["78507.68000000","0.00000000"],["78503.75000000","0.00016000"],["78502.81000000","0.00000000"],["78495.38000000","0.00000000"],["78479.64000000","0.00126000"],["78424.49000000","7.65217000"],["78407.47000000","0.00000000"],["78400.12000000","0.00028000"],["78389.86000000","0.00000000"],["77947.28000000","0.00000000"],["77947.27000000","0.00000000"],["77946.78000000","0.00000000"],["77946.46000000","0.00000000"],["77941.97000000","0.00000000"],["70851.99000000","0.00000000"],["70851.00000000","0.00000000"],["70849.00000000","0.00010000"],["70844.00000000","0.00000000"],["62972.80000000","0.00000000"]],"a":[["78722.00000000","0.00000000"],["78722.01000000","0.00000000"],["78722.64000000","0.00000000"],["78723.54000000","0.00000000"],["78723.99000000","0.00000000"],["78724.00000000","0.00000000"],["78724.01000000","0.00000000"],["78724.24000000","0.00000000"],["78724.43000000","0.00000000"],["78724.44000000","0.00000000"],["78724.45000000","0.00000000"],["78724.57000000","0.00000000"],["78724.61000000","0.00000000"],["78724.62000000","0.00000000"],["78725.20000000","0.00000000"],["78725.50000000","0.00000000"],["78725.70000000","0.00000000"],["78725.99000000","0.00000000"],["78726.00000000","0.00000000"],["78726.40000000","0.00000000"],["78726.60000000","0.00000000"],["78726.61000000","0.00000000"],["78726.62000000","0.00000000"],["78726.96000000","0.00000000"],["78726.97000000","0.00000000"],["78726.98000000","0.00000000"],["78727.03000000","0.00000000"],["78727.04000000","0.00000000"],["78727.05000000","0.00000000"],["78727.41000000","0.00000000"],["78727.76000000","0.00000000"],["78727.81000000","0.00000000"],["78727.85000000","0.00000000"],["78727.89000000","0.00000000"],["78727.99000000","0.00000000"],["78728.00000000","0.00000000"],["78728.01000000","0.00000000"],["78728.21000000","0.00000000"],["78728.22000000","0.04369000"],["78728.23000000","0.00035000"],["78728.31000000","0.00000000"],["78728.32000000","0.00014000"],["78728.60000000","0.00000000"],["78728.66000000","0.00000000"],["78729.00000000","0.00000000"],["78729.06000000","0.00000000"],["78729.30000000","0.00007000"],["78729.51000000","0.00000000"],["78729.78000000","0.00000000"],["78729.83000000","0.00000000"],["78729.84000000","0.00000000"],["78729.85000000","0.00000000"],["78729.99000000","0.00014000"],["78730.00000000","0.02407000"],["78730.19000000","0.00007000"],["78730.61000000","0.05345000"],["78730.71000000","0.00000000"],["78730.78000000","0.00014000"],["78730.79000000","0.00000000"],["78730.83000000","0.00000000"],["78731.48000000","0.00000000"],["78731.83000000","0.00000000"],["78731.99000000","0.00014000"],["78732.00000000","0.02407000"],["78732.50000000","0.00000000"],["78732.53000000","0.00007000"],["78732.55000000","0.00000000"],["78732.73000000","0.00007000"],["78732.93000000","0.00000000"],["78733.00000000","0.00048000"],["78733.25000000","0.20799000"],["78733.29000000","0.00204000"],["78733.33000000","0.00007000"],["78733.38000000","0.00000000"],["78733.44000000","0.00000000"],["78733.45000000","0.00000000"],["78733.83000000","0.00000000"],["78733.99000000","0.00014000"],["78734.04000000","0.00000000"],["78734.13000000","0.00000000"],["78734.44000000","0.00000000"],["78734.48000000","0.00000000"],["78735.15000000","0.00007000"],["78735.34000000","0.00000000"],["78735.35000000","0.00000000"],["78735.58000000","0.00000000"],["78735.61000000","0.00000000"],["78735.62000000","0.00000000"],["78735.99000000","0.00007000"],["78736.05000000","0.00000000"],["78736.06000000","0.00000000"],["78737.14000000","0.00000000"],["78737.48000000","0.00000000"],["78737.56000000","0.00000000"],["78738.08000000","0.00070000"],["78738.14000000","0.00000000"],["78738.38000000","0.00000000"],["78738.44000000","0.00000000"],["78738.64000000","0.00000000"],["78738.84000000","0.03000000"],["78739.02000000","0.00014000"],["78739.23000000","0.00007000"],["78739.34000000","0.00000000"],["78739.38000000","0.00000000"],["78739.54000000","0.00000000"],["78739.55000000","0.00000000"],["78739.69000000","0.00000000"],["78739.70000000","0.00000000"],["78739.94000000","0.04000000"],["78739.95000000","0.25410000"],["78739.97000000","0.00048000"],["78740.22000000","0.00000000"],["78740.64000000","0.00000000"],["78740.70000000","0.00000000"],["78740.73000000","0.00000000"],["78740.74000000","0.38115000"],["78741.08000000","0.00319000"],["78741.27000000","0.00000000"],["78741.28000000","0.00000000"],["78741.98000000","0.00000000"],["78741.99000000","0.00000000"],["78742.32000000","0.00000000"],["78742.38000000","0.00007000"],["78742.39000000","0.00254000"],["78742.40000000","0.00000000"],["78742.47000000","0.00000000"],["78742.89000000","0.00014000"],["78743.30000000","0.00254000"],["78743.31000000","0.00000000"],["78743.54000000","0.08000000"],["78743.56000000","0.00254000"],["78744.54000000","0.00000000"],["78744.60000000","0.04857000"],["78744.95000000","0.31757000"],["78745.19000000","0.00000000"],["78745.28000000","0.00000000"],["78746.39000000","0.00000000"],["78746.40000000","0.00000000"],["78746.57000000","0.00000000"],["78746.76000000","0.00014000"],["78746.89000000","0.02161000"],["78746.90000000","0.00406000"],["78747.21000000","0.00635000"],["78747.22000000","0.00000000"],["78747.76000000","0.00160000"],["78747.78000000","0.00000000"],["78748.98000000","0.00635000"],["78749.03000000","0.00000000"],["78749.15000000","0.00000000"],["78749.16000000","0.00000000"],["78749.46000000","0.40512000"],["78749.92000000","0.00400000"],["78750.54000000","0.00000000"],["78750.59000000","0.02161000"],["78750.62000000","0.00000000"],["78750.63000000","0.00014000"],["78750.95000000","0.00000000"],["78751.14000000","1.22579000"],["78751.15000000","0.00000000"],["78751.16000000","0.00000000"],["78751.37000000","0.00000000"],["78751.57000000","0.02000000"],["78751.75000000","0.00000000"],["78753.54000000","0.00000000"],["78754.27000000","0.00000000"],["78754.97000000","0.34287000"],["78755.98000000","0.00322000"],["78756.19000000","0.00000000"],["78756.37000000","0.09759000"],["78756.63000000","3.12467000"],["78756.64000000","0.00000000"],["78757.24000000","0.00000000"],["78759.04000000","0.00000000"],["78759.62000000","0.00000000"],["78760.05000000","0.00000000"],["78760.53000000","0.00000000"],["78760.56000000","0.00400000"],["78760.57000000","0.00000000"],["78760.60000000","0.00000000"],["78760.67000000","0.00000000"],["78760.75000000","0.00000000"],["78760.81000000","0.00012000"],["78761.81000000","0.00000000"],["78762.00000000","0.02400000"],["78762.24000000","0.00014000"],["78762.30000000","0.00000000"],["78762.89000000","0.00000000"],["78762.96000000","0.00000000"],["78763.14000000","0.00000000"],["78763.38000000","0.00000000"],["78763.71000000","0.00000000"],["78763.87000000","0.00000000"],["78764.00000000","0.02414000"],["78764.53000000","0.00000000"],["78764.91000000","0.43570000"],["78765.00000000","0.00000000"],["78765.34000000","0.04459000"],["78765.85000000","0.00000000"],["78766.11000000","0.00014000"],["78766.32000000","0.00202000"],["78767.00000000","0.01000000"],["78767.71000000","0.00000000"],["78768.60000000","0.66940000"],["78768.75000000","0.00000000"],["78769.53000000","0.02513000"],["78769.84000000","0.10000000"],["78770.00000000","0.11922000"],["78771.26000000","0.00400000"],["78772.83000000","1.21984000"],["78773.85000000","0.00007000"],["78775.00000000","0.00633000"],["78775.54000000","0.00400000"],["78775.59000000","0.00426000"],["78778.70000000","0.00008000"],["78779.11000000","0.00431000"],["78780.32000000","0.00431000"],["78780.66000000","0.02161000"],["78781.98000000","0.87007000"],["78783.99000000","0.00190000"],["78786.28000000","0.00406000"],["78786.41000000","0.00000000"],["78787.65000000","0.00000000"],["78789.86000000","0.00000000"],["78789.87000000","0.00000000"],["78790.55000000","0.00634000"],["78791.27000000","0.02000000"],["78793.94000000","0.00316000"],["78794.00000000","0.02400000"],["78794.44000000","0.00000000"],["78794.85000000","1.25657000"],["78795.36000000","0.90996000"],["78797.80000000","0.02171000"],["78801.03000000","0.00110000"],["78810.18000000","0.00000000"],["78812.15000000","0.00000000"],["78812.78000000","0.09313000"],["78817.78000000","0.00406000"],["78827.71000000","1.90515000"],["78828.53000000","1.21952000"],["78834.31000000","0.00000000"],["78839.28000000","0.21937000"],["78859.40000000","0.00000000"],["78862.65000000","0.00076000"],["78864.85000000","0.00000000"],["78865.03000000","0.00406000"],["78869.35000000","0.00000000"],["78872.58000000","0.00127000"],["78886.07000000","1.52223000"],["78888.88000000","0.00010000"],["78904.62000000","0.00000000"],["78920.36000000","0.00000000"],["78928.51000000","0.00007000"],["78930.26000000","0.00000000"],["78930.67000000","0.00007000"],["78932.00000000","0.00007000"],["78934.60000000","0.00007000"],["78935.90000000","0.00406000"],["78936.10000000","0.00000000"],["78939.15000000","0.00000000"],["78940.30000000","0.00007000"],["78951.32000000","0.01990000"],["78951.84000000","0.00000000"],["78986.09000000","0.00029000"],["80303.15000000","0.11769000"],["84202.54000000","0.00442000"]]}}
{"rx_ns": 42859470300, "frame": {"e":"depthUpdate","E":1787603100314,"s":"BTCUSDT","U":99076642831,"u":99076643152,"b":[["78728.21000000","4.49228000"],["78728.20000000","0.00020000"],["78728.19000000","0.00013000"],["78728.09000000","0.02132000"],["78728.01000000","0.00800000"],["78728.00000000","0.39272000"],["78727.99000000","2.33325000"],["78727.46000000","0.00000000"],["78726.96000000","0.11464000"],["78726.95000000","0.70886000"],["78726.62000000","1.21959000"],["78726.61000000","0.00007000"],["78726.40000000","0.11043000"],["78726.39000000","0.00014000"],["78726.00000000","0.00007000"],["78725.19000000","0.21937000"],["78724.80000000","0.00008000"],["78724.43000000","0.12661000"],["78723.99000000","0.55850000"],["78722.33000000","0.00000000"],["78721.99000000","1.21972000"],["78721.83000000","0.00000000"],["78721.38000000","0.00007000"],["78721.32000000","0.00000000"],["78721.07000000","0.00000000"],["78720.76000000","0.00000000"],["78720.00000000","0.00000000"],["78719.99000000","0.30000000"],["78719.81000000","0.00000000"],["78719.66000000","0.00000000"],["78719.25000000","0.30644000"],["78719.10000000","0.08576000"],["78719.09000000","0.00000000"],["78719.08000000","0.00000000"],["78718.55000000","0.00000000"],["78718.39000000","0.00007000"],["78717.99000000","1.21952000"],["78717.87000000","0.00000000"],["78717.82000000","0.36224000"],["78717.77000000","0.02516000"],["78717.57000000","0.00000000"],["78717.21000000","1.21984000"],["78716.51000000","0.00000000"],["78715.99000000","0.00329000"],["78712.91000000","0.00007000"],["78711.39000000","0.00000000"],["78703.47000000","0.13707000"],["78699.61000000","0.13453000"],["78698.05000000","0.00000000"],["78695.85000000","0.00000000"],["78695.20000000","0.00000000"],["78694.08000000","0.00000000"],["78691.89000000","0.00000000"],["78691.01000000","0.02497000"],["78690.74000000","0.00000000"],["78689.30000000","0.09615000"],["78686.08000000","0.00000000"],["78685.00000000","0.00000000"],["78682.43000000","0.00000000"],["78682.00000000","0.02400000"],["78658.07000000","0.00534000"],["78657.10000000","0.02510000"],["78656.47000000","0.00000000"],["78595.92000000","0.04092000"],["78515.45000000","0.00000000"],["78511.61000000","0.00072000"],["78509.17000000","0.00000000"],["78320.42000000","0.00000000"],["77928.81000000","0.00010000"],["77539.17000000","0.00000000"],["77151.47000000","0.00000000"],["76765.72000000","0.00000000"],["76381.89000000","0.00000000"],["75999.98000000","0.00012000"],["75619.98000000","0.00000000"],["75241.88000000","0.00000000"],["74865.67000000","0.00009000"],["74491.34000000","0.00000000"],["74118.88000000","0.00000000"],["73748.29000000","0.00000000"],["73379.55000000","0.00000000"],["73012.65000000","0.00000000"],["70855.39000000","0.00016000"],["70849.00000000","0.00000000"],["62982.00000000","0.00011000"],["62971.00000000","0.00000000"]],"a":[["78728.22000000","0.00093000"],["78728.23000000","0.00049000"],["78728.32000000","0.00000000"],["78728.81000000","0.00000000"],["78729.04000000","0.00014000"],["78729.05000000","0.01873000"],["78729.30000000","0.00000000"],["78730.00000000","0.02407000"],["78730.19000000","0.00000000"],["78730.30000000","0.00014000"],["78730.31000000","0.03123000"],["78730.60000000","0.00014000"],["78730.61000000","0.05359000"],["78730.78000000","0.00000000"],["78731.56000000","0.00007000"],["78731.57000000","0.03747000"],["78731.99000000","0.00007000"],["78732.00000000","0.02407000"],["78732.53000000","0.00000000"],["78732.73000000","0.00000000"],["78732.83000000","0.03747000"],["78733.00000000","0.00000000"],["78733.24000000","0.00000000"],["78733.25000000","0.20820000"],["78733.33000000","0.00000000"],["78733.99000000","0.00000000"],["78734.00000000","0.02407000"],["78735.99000000","0.00000000"],["78736.00000000","0.02414000"],["78736.10000000","0.21930000"],["78737.02000000","0.00000000"],["78738.00000000","0.02407000"],["78738.07000000","0.16047000"],["78738.45000000","0.00000000"],["78738.84000000","0.00007000"],["78739.24000000","0.01000000"],["78739.93000000","0.02161000"],["78739.94000000","0.02000000"],["78739.95000000","0.00000000"],["78740.71000000","0.00000000"],["78740.74000000","0.00000000"],["78741.08000000","0.00000000"],["78742.44000000","0.04000000"],["78743.06000000","0.00000000"],["78743.09000000","0.00000000"],["78743.10000000","0.00325000"],["78743.49000000","0.00000000"],["78743.54000000","0.00000000"],["78743.56000000","0.00000000"],["78743.92000000","0.00254000"],["78744.60000000","0.00000000"],["78744.66000000","0.00000000"],["78744.67000000","0.00324000"],["78744.95000000","0.00000000"],["78745.07000000","0.00047000"],["78745.54000000","0.08000000"],["78746.13000000","0.04857000"],["78746.57000000","0.31755000"],["78747.02000000","0.00191000"],["78747.48000000","0.02000000"],["78748.60000000","0.00327000"],["78751.09000000","0.02600000"],["78751.13000000","1.90515000"],["78751.84000000","0.00126000"],["78752.54000000","0.00318000"],["78753.53000000","0.00000000"],["78756.37000000","0.00000000"],["78756.48000000","0.00323000"],["78760.42000000","0.00327000"],["78763.46000000","0.00059000"],["78764.84000000","0.00400000"],["78764.92000000","0.00000000"],["78766.03000000","0.00000000"],["78766.08000000","0.00000000"],["78766.77000000","0.02725000"],["78767.00000000","0.00000000"],["78768.00000000","0.03400000"],["78769.12000000","0.00400000"],["78771.32000000","0.00000000"],["78775.54000000","0.00400000"],["78777.12000000","0.00317000"],["78788.06000000","0.01163000"],["78790.55000000","0.00000000"],["78803.15000000","0.00531000"],["78805.49000000","0.01729000"],["78806.60000000","0.02607000"],["78812.56000000","0.02000000"],["78815.73000000","0.00000000"],["78825.92000000","0.00000000"],["78827.71000000","0.00000000"],["78841.66000000","0.00000000"],["78843.26000000","0.04625000"],["78857.40000000","0.00000000"],["78865.03000000","0.00000000"],["78873.14000000","0.00000000"],["78936.62000000","0.00007000"],["78944.48000000","0.00000000"],["84202.54000000","0.00884000"]]}}
{"rx_ns": 42952998900, "frame": {"e":"depthUpdate","E":1787603100414,"s":"BTCUSDT","U":99076643153,"u":99076643436,"b":[["78729.04000000","3.93584000"],["78729.03000000","0.00020000"],["78729.02000000","0.00013000"],["78728.61000000","0.00014000"],["78728.60000000","0.01936000"],["78728.46000000","0.00400000"],["78728.23000000","0.00014000"],["78728.22000000","0.21944000"],["78728.21000000","2.58463000"],["78728.20000000","0.00000000"],["78728.19000000","0.00000000"],["78728.09000000","0.00007000"],["78728.01000000","0.00814000"],["78727.99000000","0.20880000"],["78727.34000000","0.03227000"],["78726.96000000","0.11471000"],["78726.95000000","0.49883000"],["78726.74000000","0.00254000"],["78726.40000000","0.11036000"],["78726.15000000","0.04818000"],["78726.08000000","0.03873000"],["78725.69000000","0.00000000"],["78725.19000000","0.00007000"],["78725.10000000","0.00000000"],["78725.00000000","0.00027000"],["78724.82000000","0.03873000"],["78724.00000000","0.03590000"],["78723.99000000","0.12605000"],["78722.00000000","1.90522000"],["78721.82000000","0.12053000"],["78721.38000000","0.00000000"],["78721.31000000","0.00000000"],["78720.75000000","0.30000000"],["78717.77000000","0.00000000"],["78717.44000000","0.00007000"],["78712.02000000","0.00000000"],["78711.58000000","0.00000000"],["78699.61000000","0.00000000"],["78698.05000000","0.00406000"],["78697.71000000","0.09639000"],["78695.36000000","0.00000000"],["78689.30000000","0.00000000"],["78689.00000000","0.01000000"],["78688.00000000","0.03001000"],["78664.92000000","0.86866000"],["78606.02000000","0.04091000"],["78595.92000000","0.00000000"],["70856.14000000","0.00032000"],["70855.39000000","0.00009000"]],"a":[["78728.22000000","0.00000000"],["78728.23000000","0.00000000"],["78729.03000000","0.00000000"],["78729.04000000","0.00000000"],["78729.05000000","0.01199000"],["78729.06000000","0.00077000"],["78729.31000000","0.00007000"],["78730.00000000","0.02407000"],["78730.31000000","0.03130000"],["78730.60000000","0.00000000"],["78730.61000000","0.00014000"],["78731.56000000","0.00014000"],["78731.57000000","0.03754000"],["78731.65000000","0.00014000"],["78731.66000000","0.05345000"],["78732.00000000","0.02407000"],["78732.46000000","0.00007000"],["78732.83000000","0.03754000"],["78733.25000000","0.20820000"],["78734.02000000","0.00000000"],["78734.27000000","0.00000000"],["78734.36000000","0.00000000"],["78734.38000000","0.00000000"],["78735.15000000","0.00014000"],["78736.00000000","0.02407000"],["78736.10000000","0.00000000"],["78736.93000000","0.21930000"],["78737.95000000","0.18515000"],["78738.00000000","0.02400000"],["78738.07000000","0.16047000"],["78738.84000000","0.00000000"],["78738.97000000","0.00000000"],["78739.24000000","0.00000000"],["78739.94000000","0.00000000"],["78740.75000000","0.00000000"],["78741.44000000","0.04000000"],["78742.34000000","0.03000000"],["78742.44000000","0.00000000"],["78742.48000000","0.00654000"],["78742.60000000","0.00048000"],["78743.10000000","0.00000000"],["78743.14000000","0.00000000"],["78743.19000000","0.00321000"],["78743.34000000","0.00000000"],["78743.92000000","0.00000000"],["78744.60000000","0.00007000"],["78744.67000000","0.00000000"],["78744.71000000","0.00000000"],["78744.77000000","0.00329000"],["78756.54000000","0.00000000"],["78757.52000000","0.00000000"],["78758.24000000","0.00000000"],["78765.61000000","0.00661000"],["78766.77000000","0.00000000"],["78767.52000000","0.00000000"],["78768.00000000","0.02400000"],["78768.48000000","0.00000000"],["78769.00000000","0.01000000"],["78770.22000000","0.00000000"],["78773.85000000","0.00000000"],["78784.74000000","0.86734000"],["78784.80000000","0.00400000"],["78806.60000000","0.00007000"],["78808.29000000","0.00000000"],["78812.56000000","0.00000000"],["78825.75000000","0.00000000"],["78828.40000000","3.80617000"],["78842.20000000","0.02789000"],["78847.62000000","0.00000000"],["78865.82000000","0.00000000"]]}}
{"rx_ns": 43054909100, "frame": {"e":"depthUpdate","E":1787603100514,"s":"BTCUSDT","U":99076643437,"u":99076643847,"b":[["78729.04000000","0.96837000"],["78728.60000000","0.01943000"],["78728.46000000","0.00000000"],["78728.24000000","0.00000000"],["78728.23000000","0.00000000"],["78728.22000000","0.00007000"],["78728.21000000","0.00021000"],["78728.09000000","0.00000000"],["78728.01000000","0.00007000"],["78728.00000000","0.00014000"],["78727.99000000","0.00007000"],["78727.41000000","0.00007000"],["78727.35000000","0.00014000"],["78727.34000000","0.03234000"],["78726.96000000","0.00021000"],["78726.95000000","0.07653000"],["78726.74000000","0.00000000"],["78726.62000000","0.00000000"],["78726.40000000","0.00000000"],["78726.16000000","0.00014000"],["78726.09000000","0.00007000"],["78726.00000000","0.00000000"],["78725.99000000","0.00007000"],["78725.72000000","0.00000000"],["78725.49000000","0.00000000"],["78725.34000000","0.00000000"],["78725.00000000","0.00000000"],["78724.78000000","0.00000000"],["78724.60000000","0.00000000"],["78724.44000000","0.00000000"],["78724.43000000","0.12654000"],["78724.42000000","0.00007000"],["78724.00000000","0.00000000"],["78723.99000000","0.12612000"],["78723.85000000","0.00000000"],["78723.83000000","0.00204000"],["78723.82000000","0.00000000"],["78723.54000000","0.00007000"],["78722.88000000","0.00000000"],["78722.58000000","0.00000000"],["78722.01000000","1.90515000"],["78722.00000000","0.00007000"],["78721.99000000","1.21965000"],["78721.82000000","0.05849000"],["78721.53000000","0.31761000"],["78721.46000000","0.00000000"],["78721.18000000","0.03000000"],["78721.16000000","0.21930000"],["78721.08000000","0.00000000"],["78720.56000000","0.00000000"],["78720.54000000","0.00000000"],["78719.95000000","0.00000000"],["78719.10000000","0.00000000"],["78719.01000000","0.00000000"],["78718.50000000","0.08576000"],["78718.00000000","0.36224000"],["78717.82000000","0.00000000"],["78717.76000000","0.00400000"],["78717.21000000","1.21984000"],["78717.18000000","0.00000000"],["78717.10000000","0.00008000"],["78717.08000000","0.02000000"],["78717.05000000","0.00000000"],["78717.04000000","0.00000000"],["78717.01000000","0.00000000"],["78716.94000000","0.00000000"],["78716.92000000","0.00000000"],["78716.87000000","0.00000000"],["78715.80000000","0.00014000"],["78715.57000000","0.00000000"],["78714.62000000","0.00400000"],["78714.01000000","0.00407000"],["78713.98000000","0.00000000"],["78713.78000000","0.00000000"],["78713.46000000","0.00000000"],["78712.91000000","0.00261000"],["78712.28000000","0.00000000"],["78711.41000000","0.00000000"],["78710.23000000","0.00000000"],["78710.01000000","0.00000000"],["78710.00000000","0.04400000"],["78709.88000000","0.12000000"],["78708.79000000","0.13242000"],["78707.88000000","0.00000000"],["78706.30000000","0.00000000"],["78705.38000000","0.00007000"],["78703.92000000","0.34309000"],["78703.58000000","0.00000000"],["78701.14000000","0.00000000"],["78700.98000000","0.63513000"],["78700.50000000","0.00000000"],["78699.54000000","0.34311000"],["78697.71000000","0.00000000"],["78695.92000000","0.09707000"],["78693.00000000","0.00000000"],["78690.33000000","0.00000000"],["78689.76000000","0.34315000"],["78688.71000000","0.00007000"],["78687.00000000","0.03231000"],["78684.84000000","0.00007000"],["78684.00000000","0.02800000"],["78680.97000000","0.00007000"],["78680.68000000","1.25839000"],["78663.67000000","1.25866000"],["78586.88000000","0.00000000"],["78570.43000000","1.52223000"],["78533.83000000","0.00778000"],["78520.83000000","0.00000000"],["70856.00000000","0.00066000"],["62983.24000000","0.00031000"]],"a":[["78729.05000000","1.56023000"],["78729.06000000","0.00028000"],["78729.47000000","0.00204000"],["78730.03000000","0.00000000"],["78730.31000000","0.03130000"],["78730.61000000","0.00007000"],["78731.28000000","0.00014000"],["78731.57000000","0.03754000"],["78731.66000000","0.05359000"],["78732.11000000","0.00000000"],["78732.75000000","0.00000000"],["78733.25000000","0.00021000"],["78733.29000000","0.00000000"],["78734.01000000","0.00000000"],["78734.15000000","0.02000000"],["78734.82000000","0.00000000"],["78734.84000000","0.00000000"],["78734.98000000","0.01199000"],["78735.35000000","0.00000000"],["78736.80000000","0.00400000"],["78736.92000000","0.31756000"],["78736.93000000","0.21930000"],["78737.19000000","0.00000000"],["78737.57000000","0.00000000"],["78737.95000000","0.00000000"],["78738.07000000","0.16040000"],["78738.08000000","0.00000000"],["78739.20000000","0.00400000"],["78739.47000000","0.00323000"],["78739.59000000","0.00000000"],["78742.39000000","0.00000000"],["78742.48000000","0.00400000"],["78742.60000000","0.00000000"],["78743.30000000","0.00000000"],["78743.41000000","0.00326000"],["78743.46000000","0.00000000"],["78744.92000000","0.25409000"],["78745.37000000","1.90515000"],["78745.53000000","0.04857000"],["78745.71000000","0.38114000"],["78746.13000000","0.00000000"],["78746.56000000","1.58176000"],["78746.57000000","0.00000000"],["78746.58000000","0.21930000"],["78746.99000000","0.00000000"],["78751.57000000","0.00000000"],["78752.63000000","0.00007000"],["78755.70000000","0.36224000"],["78758.27000000","0.09337000"],["78760.42000000","0.00000000"],["78761.48000000","0.34284000"],["78764.07000000","0.36224000"],["78766.00000000","0.36682000"],["78768.86000000","0.02768000"],["78769.98000000","0.00000000"],["78770.75000000","0.02347000"],["78771.57000000","0.02000000"],["78772.14000000","1.21952000"],["78775.20000000","0.00000000"],["78775.54000000","0.00000000"],["78777.46000000","1.25684000"],["78777.60000000","0.00000000"],["78780.00000000","0.02400000"],["78784.80000000","0.00000000"],["78817.72000000","1.21952000"],["78817.73000000","0.00000000"],["78818.29000000","0.00000000"],["78818.57000000","0.00000000"],["78824.71000000","0.00000000"],["78828.53000000","0.00000000"],["78830.81000000","0.00000000"],["78839.28000000","0.00007000"],["78869.56000000","1.52223000"],["78886.07000000","0.00000000"],["78923.73000000","0.00000000"],["78931.75000000","0.01989000"],["78943.23000000","0.00007000"],["78944.50000000","0.00000000"],["78947.16000000","0.00007000"]]}}
{"rx_ns": 43154591100, "frame": {"e":"depthUpdate","E":1787603100614,"s":"BTCUSDT","U":99076643848,"u":99076644114,"b":[["78729.04000000","0.01078000"],["78728.60000000","0.01943000"],["78728.22000000","0.00000000"],["78728.21000000","0.00000000"],["78728.01000000","0.00000000"],["78728.00000000","0.00000000"],["78727.99000000","0.00000000"],["78727.34000000","0.03234000"],["78726.96000000","0.00000000"],["78726.95000000","0.00014000"],["78726.39000000","0.00007000"],["78726.35000000","0.00014000"],["78726.34000000","0.02516000"],["78726.32000000","0.00000000"],["78726.15000000","0.04825000"],["78726.09000000","0.00014000"],["78726.08000000","0.03880000"],["78725.99000000","0.00000000"],["78725.98000000","0.00000000"],["78725.20000000","0.00007000"],["78724.83000000","0.00000000"],["78724.82000000","0.03880000"],["78724.80000000","0.00000000"],["78724.43000000","0.00014000"],["78724.18000000","0.00000000"],["78723.99000000","0.00021000"],["78723.83000000","0.00000000"],["78722.02000000","0.00000000"],["78722.01000000","0.00000000"],["78721.99000000","0.00013000"],["78721.82000000","0.05533000"],["78721.53000000","0.00007000"],["78721.18000000","0.00000000"],["78721.16000000","0.00000000"],["78720.75000000","0.00000000"],["78720.62000000","0.00154000"],["78720.47000000","0.00000000"],["78719.99000000","0.00000000"],["78719.90000000","0.00400000"],["78719.67000000","0.00007000"],["78719.28000000","0.00000000"],["78719.25000000","0.00644000"],["78718.50000000","0.00000000"],["78718.39000000","0.00055000"],["78718.01000000","1.21952000"],["78717.99000000","0.00000000"],["78717.83000000","0.00187000"],["78717.50000000","0.08576000"],["78717.16000000","0.00034000"],["78717.08000000","0.00000000"],["78716.96000000","0.00000000"],["78716.52000000","0.00000000"],["78716.49000000","0.00000000"],["78716.38000000","0.00000000"],["78715.80000000","0.00007000"],["78715.68000000","0.00000000"],["78714.88000000","0.00000000"],["78714.80000000","0.31763000"],["78714.62000000","0.00000000"],["78713.92000000","0.00000000"],["78713.88000000","0.02000000"],["78713.78000000","0.01000000"],["78713.65000000","0.00000000"],["78713.28000000","0.21930000"],["78712.91000000","0.00007000"],["78712.16000000","0.00000000"],["78712.07000000","0.02000000"],["78711.75000000","0.00000000"],["78711.71000000","0.00000000"],["78711.68000000","0.00000000"],["78711.62000000","0.00000000"],["78711.59000000","0.00000000"],["78711.42000000","0.00000000"],["78711.39000000","0.00000000"],["78711.13000000","1.90515000"],["78710.33000000","0.00000000"],["78710.32000000","0.00000000"],["78710.26000000","0.00000000"],["78709.09000000","0.00400000"],["78708.88000000","0.00254000"],["78706.30000000","0.00000000"],["78704.64000000","0.00000000"],["78703.92000000","0.00000000"],["78695.92000000","0.00000000"],["78695.22000000","0.00000000"],["78694.32000000","0.00000000"],["78692.98000000","0.00000000"],["78692.45000000","0.00000000"],["78691.78000000","0.51702000"],["78691.20000000","0.00400000"],["78691.01000000","0.00000000"],["78688.80000000","0.00400000"],["78680.97000000","0.00007000"],["78677.10000000","0.00007000"],["78675.00000000","0.00000000"],["78664.92000000","0.00000000"],["78647.45000000","0.02116000"],["78606.02000000","0.00000000"],["70856.14000000","0.00064000"],["70856.00000000","0.00056000"],["62983.24000000","0.00000000"]],"a":[["78729.05000000","2.21311000"],["78729.06000000","0.00007000"],["78729.47000000","0.00000000"],["78731.57000000","0.07756000"],["78731.66000000","0.05352000"],["78732.00000000","0.02807000"],["78732.29000000","0.12710000"],["78732.42000000","0.00000000"],["78732.83000000","0.03754000"],["78733.25000000","0.00014000"],["78733.34000000","0.03000000"],["78733.91000000","0.00000000"],["78734.00000000","0.02407000"],["78734.15000000","0.02007000"],["78734.20000000","0.00323000"],["78734.27000000","0.00000000"],["78734.40000000","0.00400000"],["78734.98000000","0.00000000"],["78735.78000000","0.00321000"],["78736.92000000","0.00000000"],["78736.93000000","0.21937000"],["78737.99000000","0.36224000"],["78738.27000000","0.00331000"],["78738.95000000","0.00160000"],["78740.01000000","0.34294000"],["78740.09000000","1.90515000"],["78740.44000000","1.21952000"],["78742.34000000","0.00000000"],["78744.53000000","0.04857000"],["78744.80000000","0.07444000"],["78745.53000000","0.00000000"],["78747.02000000","0.00000000"],["78747.21000000","0.00000000"],["78747.76000000","0.00000000"],["78747.98000000","0.34290000"],["78748.13000000","0.34290000"],["78750.00000000","0.11931000"],["78750.87000000","0.63498000"],["78752.54000000","0.00000000"],["78756.48000000","0.00000000"],["78760.60000000","0.63490000"],["78761.48000000","0.00000000"],["78761.94000000","0.00000000"],["78766.00000000","0.02400000"],["78766.97000000","0.00000000"],["78769.12000000","0.00000000"],["78771.26000000","0.00000000"],["78773.02000000","0.00000000"],["78784.74000000","0.00000000"],["78794.85000000","0.00000000"],["78807.74000000","0.00000000"],["78807.75000000","0.00000000"],["78817.72000000","0.00000000"],["78832.81000000","0.00012000"],["78842.20000000","0.00000000"],["78865.03000000","0.00406000"],["78947.16000000","0.00000000"],["80463.76000000","0.13477000"],["80624.69000000","0.15433000"]]}}
{"rx_ns": 43255917500, "frame": {"e":"depthUpdate","E":1787603100714,"s":"BTCUSDT","U":99076644115,"u":99076645211,"b":[["78729.04000000","0.00000000"],["78729.03000000","0.00000000"],["78729.02000000","0.00000000"],["78728.61000000","0.00000000"],["78728.60000000","0.00000000"],["78728.59000000","0.00000000"],["78727.84000000","0.00000000"],["78727.41000000","0.00000000"],["78727.35000000","0.00000000"],["78727.34000000","0.00000000"],["78726.95000000","0.00000000"],["78726.61000000","0.00000000"],["78726.39000000","0.00000000"],["78726.35000000","0.00000000"],["78726.34000000","0.00000000"],["78726.16000000","0.00000000"],["78726.15000000","0.00000000"],["78726.09000000","0.00000000"],["78726.08000000","0.00000000"],["78725.70000000","0.00000000"],["78725.20000000","0.00000000"],["78725.19000000","0.00000000"],["78724.83000000","0.00000000"],["78724.82000000","0.00000000"],["78724.81000000","0.00000000"],["78724.61000000","0.00000000"],["78724.60000000","0.00000000"],["78724.59000000","0.00000000"],["78724.56000000","0.00000000"],["78724.55000000","0.00000000"],["78724.43000000","0.00051000"],["78724.42000000","0.00021000"],["78722.04000000","0.00000000"],["78721.93000000","0.00000000"],["78721.83000000","0.00000000"],["78721.82000000","0.00014000"],["78721.53000000","0.00000000"],["78720.62000000","0.00000000"],["78720.31000000","0.00000000"],["78719.90000000","0.00000000"],["78719.31000000","0.00000000"],["78719.30000000","0.00007000"],["78719.25000000","0.00007000"],["78718.39000000","0.00007000"],["78718.14000000","0.00000000"],["78718.02000000","0.00000000"],["78718.01000000","0.00007000"],["78718.00000000","0.00014000"],["78717.98000000","0.00000000"],["78717.83000000","0.00000000"],["78717.82000000","0.00000000"],["78717.81000000","0.00014000"],["78717.76000000","0.00000000"],["78717.50000000","0.00007000"],["78717.48000000","0.00000000"],["78717.22000000","0.00027000"],["78717.21000000","0.00000000"],["78717.16000000","0.00007000"],["78717.10000000","0.00000000"],["78716.76000000","0.00047000"],["78716.57000000","0.00014000"],["78716.56000000","0.01512000"],["78716.48000000","0.00048000"],["78715.99000000","0.00000000"],["78715.91000000","0.00000000"],["78715.80000000","0.00007000"],["78715.62000000","0.00000000"],["78715.25000000","0.00000000"],["78715.07000000","0.00000000"],["78714.99000000","0.00000000"],["78714.95000000","0.00000000"],["78714.94000000","0.00000000"],["78714.80000000","0.00000000"],["78714.01000000","0.00007000"],["78714.00000000","0.00000000"],["78713.88000000","0.00000000"],["78713.83000000","0.00000000"],["78713.78000000","0.00000000"],["78713.48000000","0.00000000"],["78713.43000000","0.00000000"],["78713.42000000","0.00000000"],["78713.28000000","0.00000000"],["78712.37000000","0.00000000"],["78712.25000000","0.00000000"],["78712.07000000","0.00000000"],["78711.97000000","0.00325000"],["78711.93000000","0.00007000"],["78711.90000000","0.00000000"],["78711.54000000","0.00154000"],["78711.48000000","0.00000000"],["78711.14000000","1.90515000"],["78711.13000000","0.00000000"],["78710.86000000","0.00007000"],["78710.37000000","0.00000000"],["78710.13000000","0.00070000"],["78709.88000000","0.00000000"],["78709.28000000","0.00204000"],["78709.27000000","0.20799000"],["78709.18000000","0.00000000"],["78709.09000000","0.00000000"],["78709.07000000","0.02000000"],["78709.06000000","0.21930000"],["78708.88000000","0.00000000"],["78708.79000000","0.00000000"],["78708.78000000","1.21952000"],["78708.06000000","0.00014000"],["78708.03000000","0.00320000"],["78707.68000000","0.00000000"],["78707.61000000","0.00000000"],["78707.00000000","0.36224000"],["78706.97000000","0.00000000"],["78706.67000000","0.00000000"],["78706.30000000","0.00400000"],["78706.04000000","0.00000000"],["78705.77000000","0.00000000"],["78705.67000000","0.00190000"],["78705.66000000","0.00000000"],["78705.64000000","0.00000000"],["78705.37000000","0.07000000"],["78705.29000000","0.00254000"],["78704.27000000","0.00000000"],["78704.17000000","0.08007000"],["78704.13000000","0.00000000"],["78704.09000000","0.00320000"],["78704.07000000","0.00000000"],["78704.05000000","0.00000000"],["78703.72000000","0.00000000"],["78703.58000000","0.00000000"],["78702.75000000","0.00000000"],["78702.37000000","0.00000000"],["78701.72000000","0.00400000"],["78701.43000000","0.00254000"],["78701.00000000","0.00007000"],["78700.99000000","0.00000000"],["78700.98000000","0.00000000"],["78700.72000000","0.00000000"],["78700.71000000","0.00000000"],["78700.15000000","0.00332000"],["78700.12000000","0.02800000"],["78700.00000000","0.05207000"],["78699.54000000","0.00000000"],["78699.45000000","0.02287000"],["78695.38000000","0.13244000"],["78695.37000000","0.00000000"],["78693.22000000","0.00190000"],["78691.78000000","0.00000000"],["78691.58000000","0.00000000"],["78690.83000000","0.00000000"],["78690.64000000","0.63526000"],["78689.00000000","0.00000000"],["78688.71000000","0.00014000"],["78686.48000000","0.00635000"],["78686.06000000","0.00000000"],["78686.00000000","0.02400000"],["78685.00000000","0.01000000"],["78684.96000000","0.00000000"],["78684.30000000","0.00000000"],["78684.10000000","0.00000000"],["78683.79000000","0.00000000"],["78683.77000000","0.00000000"],["78681.60000000","0.00400000"],["78681.14000000","0.63554000"],["78680.68000000","0.00000000"],["78680.00000000","0.11972000"],["78679.01000000","0.00000000"],["78678.13000000","0.00000000"],["78677.51000000","0.00000000"],["78677.01000000","0.00000000"],["78676.83000000","0.00000000"],["78676.80000000","0.02800000"],["78676.53000000","0.00000000"],["78676.38000000","0.00000000"],["78676.24000000","0.00000000"],["78675.78000000","0.00000000"],["78675.53000000","0.00000000"],["78675.36000000","0.00000000"],["78675.12000000","0.00000000"],["78674.94000000","0.00000000"],["78674.64000000","0.00000000"],["78674.40000000","0.00400000"],["78673.89000000","0.00000000"],["78673.64000000","0.00000000"],["78673.58000000","0.00000000"],["78673.47000000","1.90515000"],["78673.23000000","0.00007000"],["78672.46000000","0.00000000"],["78672.00000000","0.02800000"],["78669.60000000","0.00400000"],["78669.36000000","0.00007000"],["78668.46000000","0.00635000"],["78666.12000000","0.00007000"],["78661.02000000","0.00615000"],["78659.62000000","0.00000000"],["78658.07000000","0.00000000"],["78657.10000000","0.02400000"],["78648.26000000","0.86836000"],["78640.63000000","0.00535000"],["78640.13000000","0.00111000"],["78608.25000000","0.00000000"],["78596.46000000","0.04092000"],["78592.50000000","0.00000000"],["78576.75000000","0.00000000"],["78561.00000000","0.00000000"],["78545.25000000","0.00000000"],["78407.77000000","7.65318000"],["78400.12000000","0.00000000"],["78389.06000000","0.00038000"],["78317.01000000","0.00007000"],["70856.14000000","0.00000000"],["70856.00000000","0.00066000"],["70855.39000000","0.00000000"],["70855.38000000","0.00009000"],["70852.14000000","0.00000000"]],"a":[["78724.44000000","2.47568000"],["78724.45000000","0.00013000"],["78724.46000000","0.00013000"],["78724.54000000","0.00014000"],["78724.55000000","0.37362000"],["78724.56000000","0.39583000"],["78724.57000000","0.00007000"],["78724.59000000","0.00014000"],["78724.60000000","0.37362000"],["78724.61000000","1.01126000"],["78724.62000000","0.00000000"],["78724.63000000","0.00000000"],["78724.80000000","0.00400000"],["78724.81000000","0.00000000"],["78724.82000000","0.07514000"],["78724.83000000","0.90778000"],["78724.84000000","0.00000000"],["78724.85000000","0.00000000"],["78725.20000000","0.00000000"],["78725.21000000","0.17820000"],["78725.69000000","0.00000000"],["78725.70000000","0.07500000"],["78725.71000000","0.02486000"],["78725.85000000","0.00000000"],["78725.87000000","0.00000000"],["78725.88000000","0.04045000"],["78725.89000000","0.00021000"],["78725.90000000","0.00000000"],["78725.91000000","0.00000000"],["78726.09000000","0.00000000"],["78726.10000000","0.00000000"],["78726.16000000","0.00000000"],["78726.17000000","0.00000000"],["78726.33000000","0.00000000"],["78726.35000000","0.00000000"],["78726.40000000","0.00000000"],["78726.62000000","0.00000000"],["78726.96000000","0.00000000"],["78727.20000000","0.00400000"],["78727.35000000","0.00000000"],["78727.36000000","0.00000000"],["78727.41000000","0.05407000"],["78727.42000000","0.00000000"],["78727.66000000","0.00000000"],["78727.85000000","0.19107000"],["78728.06000000","0.00027000"],["78728.29000000","0.00000000"],["78728.59000000","0.00000000"],["78728.60000000","3.12467000"],["78728.61000000","0.80580000"],["78728.62000000","0.00000000"],["78728.63000000","0.00000000"],["78729.00000000","0.00007000"],["78729.03000000","0.00000000"],["78729.04000000","0.38577000"],["78729.05000000","0.62916000"],["78729.06000000","0.00000000"],["78729.07000000","0.00000000"],["78729.60000000","0.00400000"],["78729.99000000","0.00000000"],["78730.30000000","0.00000000"],["78730.31000000","0.00000000"],["78730.35000000","0.02000000"],["78730.50000000","0.00160000"],["78730.61000000","0.00000000"],["78731.21000000","0.00000000"],["78731.56000000","0.00000000"],["78731.57000000","0.04002000"],["78731.65000000","0.00000000"],["78731.66000000","0.00007000"],["78731.99000000","0.00000000"],["78732.00000000","0.02800000"],["78732.14000000","0.00329000"],["78732.29000000","0.12710000"],["78732.50000000","0.00008000"],["78732.83000000","0.00000000"],["78732.93000000","0.00007000"],["78733.25000000","0.00000000"],["78733.34000000","0.00000000"],["78734.00000000","0.02400000"],["78734.15000000","0.00000000"],["78734.17000000","1.90515000"],["78734.65000000","0.00007000"],["78736.01000000","1.21952000"],["78736.93000000","0.21930000"],["78738.95000000","0.00000000"],["78739.97000000","0.00000000"],["78740.00000000","0.11926000"],["78740.19000000","0.10619000"],["78741.15000000","0.63506000"],["78741.44000000","0.00000000"],["78741.51000000","0.04647000"],["78741.64000000","0.00000000"],["78742.38000000","0.00000000"],["78743.44000000","0.06522000"],["78744.53000000","0.00000000"],["78744.77000000","0.00000000"],["78744.80000000","0.00000000"],["78745.07000000","0.00000000"],["78745.41000000","0.07526000"],["78745.54000000","0.00000000"],["78746.05000000","0.00060000"],["78748.60000000","0.00000000"],["78748.98000000","0.00000000"],["78750.15000000","0.00191000"],["78750.18000000","0.09565000"],["78751.48000000","0.02513000"],["78754.97000000","0.00000000"],["78755.20000000","0.02527000"],["78755.71000000","0.00000000"],["78755.98000000","0.00000000"],["78758.27000000","0.00000000"],["78759.39000000","0.00435000"],["78759.46000000","0.00615000"],["78762.70000000","0.00000000"],["78763.46000000","0.00000000"],["78763.86000000","0.00000000"],["78764.84000000","0.00000000"],["78765.17000000","0.00426000"],["78765.34000000","0.00000000"],["78766.11000000","0.00000000"],["78766.32000000","0.00010000"],["78766.98000000","0.00000000"],["78768.00000000","0.03400000"],["78768.18000000","0.86704000"],["78768.20000000","0.00662000"],["78769.00000000","0.00000000"],["78769.53000000","0.00000000"],["78775.00000000","0.00000000"],["78775.59000000","0.00000000"],["78776.54000000","0.00634000"],["78779.11000000","0.00000000"],["78779.85000000","0.31836000"],["78780.32000000","0.00000000"],["78784.09000000","0.00111000"],["78785.77000000","0.00000000"],["78786.07000000","0.00528000"],["78787.11000000","0.00000000"],["78788.28000000","0.01722000"],["78790.65000000","0.00000000"],["78797.79000000","0.00000000"],["78797.80000000","0.00010000"],["78797.81000000","0.00000000"],["78797.82000000","0.00000000"],["78798.62000000","0.00000000"],["78801.03000000","0.00000000"],["78803.15000000","0.00000000"],["78805.49000000","0.00000000"],["78807.76000000","0.00000000"],["78808.05000000","0.00000000"],["78815.64000000","0.00000000"],["78823.52000000","0.00202000"],["78828.40000000","0.00000000"],["78831.40000000","0.00000000"],["78832.62000000","0.02789000"],["78838.95000000","0.00019000"],["78845.04000000","0.00031000"],["78932.00000000","0.00000000"],["78937.19000000","0.00000000"],["78986.09000000","0.00000000"]]}}
{"rx_ns": 43356390400, "frame": {"e":"depthUpdate","E":1787603100814,"s":"BTCUSDT","U":99076645212,"u":99076645749,"b":[["78724.43000000","0.00000000"],["78724.42000000","0.00000000"],["78723.99000000","0.00000000"],["78723.54000000","0.00000000"],["78722.00000000","0.00000000"],["78721.99000000","0.00000000"],["78721.82000000","0.00000000"],["78719.67000000","0.00000000"],["78719.30000000","0.00000000"],["78719.25000000","0.00000000"],["78718.51000000","0.00000000"],["78718.39000000","0.00000000"],["78718.01000000","0.00000000"],["78718.00000000","0.00000000"],["78717.81000000","0.00000000"],["78717.50000000","0.00000000"],["78717.44000000","0.00000000"],["78717.22000000","1.09395000"],["78717.21000000","0.00049000"],["78717.16000000","0.00000000"],["78716.76000000","0.00000000"],["78716.57000000","0.00000000"],["78716.56000000","0.00007000"],["78716.48000000","0.00000000"],["78715.73000000","0.00014000"],["78715.72000000","0.01767000"],["78715.34000000","0.00000000"],["78714.61000000","0.00000000"],["78714.48000000","0.00014000"],["78714.47000000","0.02945000"],["78714.01000000","0.00000000"],["78713.22000000","0.00014000"],["78713.21000000","0.03534000"],["78712.91000000","0.00000000"],["78712.32000000","0.00000000"],["78712.00000000","0.00507000"],["78711.99000000","0.00539000"],["78711.96000000","0.00014000"],["78711.95000000","0.03534000"],["78711.15000000","0.00000000"],["78711.14000000","0.00007000"],["78710.93000000","0.00000000"],["78710.13000000","0.00000000"],["78710.01000000","0.00014000"],["78710.00000000","0.04407000"],["78709.99000000","0.04030000"],["78709.28000000","0.00204000"],["78709.27000000","0.20806000"],["78709.08000000","0.00027000"],["78709.07000000","0.02000000"],["78709.06000000","0.21937000"],["78708.79000000","1.90515000"],["78708.30000000","0.31773000"],["78707.71000000","0.00007000"],["78707.10000000","0.00000000"],["78707.01000000","0.00007000"],["78706.69000000","0.00000000"],["78706.29000000","0.00000000"],["78706.01000000","0.00047000"],["78705.85000000","0.00048000"],["78705.37000000","0.03000000"],["78704.56000000","0.00007000"],["78704.17000000","0.00007000"],["78703.58000000","1.90515000"],["78703.47000000","0.00000000"],["78701.72000000","0.00000000"],["78701.47000000","0.00254000"],["78701.43000000","0.00000000"],["78699.63000000","1.21984000"],["78698.05000000","0.00000000"],["78694.97000000","0.12000000"],["78693.77000000","0.06526000"],["78691.89000000","0.13690000"],["78691.80000000","0.07531000"],["78691.37000000","0.34315000"],["78691.21000000","0.00059000"],["78690.49000000","0.00000000"],["78685.00000000","0.00000000"],["78684.84000000","0.00014000"],["78682.74000000","0.00000000"],["78682.19000000","0.34319000"],["78682.15000000","0.00000000"],["78682.06000000","0.09759000"],["78680.97000000","0.00014000"],["78679.20000000","0.00400000"],["78677.00000000","0.01000000"],["78675.07000000","0.02523000"],["78673.98000000","0.00000000"],["78673.90000000","0.00000000"],["78672.09000000","0.02000000"],["78672.01000000","0.00000000"],["78671.65000000","0.04529000"],["78668.46000000","0.00000000"],["78658.70000000","0.00000000"],["78656.28000000","0.00426000"],["78647.45000000","0.00000000"],["78643.24000000","0.01706000"],["78638.01000000","0.00000000"],["78634.01000000","0.00317000"],["78627.22000000","0.00000000"],["78596.46000000","0.00000000"],["78596.34000000","0.80000000"],["78592.11000000","0.00000000"],["78583.92000000","0.04592000"],["78580.00000000","0.00057000"],["78514.83000000","0.00007000"],["78511.78000000","0.00007000"],["78509.17000000","0.00000000"],["78507.85000000","0.00007000"],["78503.04000000","0.00007000"],["78323.63000000","0.01000000"],["78232.00000000","0.00015000"],["77932.01000000","0.01000000"],["77542.35000000","0.01000000"],["77154.64000000","0.01000000"],["76768.87000000","0.01000000"],["76385.02000000","0.01000000"],["76003.10000000","0.01000000"],["75623.08000000","0.01000000"],["75244.97000000","0.01000000"],["74868.74000000","0.01000000"],["74494.40000000","0.01000000"],["74121.92000000","0.01000000"],["73751.32000000","0.01000000"],["73382.56000000","0.01000000"],["73015.65000000","0.01000000"],["70856.00000000","0.00056000"],["70851.00000000","0.00020000"],["70845.50000000","0.00016000"]],"a":[["78717.23000000","2.01737000"],["78717.24000000","0.00020000"],["78717.25000000","0.00013000"],["78717.50000000","0.00000000"],["78717.51000000","0.00021000"],["78717.82000000","0.00007000"],["78718.01000000","0.00007000"],["78718.48000000","0.00014000"],["78718.49000000","0.03406000"],["78719.14000000","0.00014000"],["78719.15000000","0.04045000"],["78719.67000000","0.00014000"],["78719.74000000","0.00014000"],["78719.75000000","0.04088000"],["78719.81000000","0.00014000"],["78719.82000000","0.05387000"],["78720.00000000","0.00400000"],["78721.00000000","0.00007000"],["78721.01000000","0.04088000"],["78721.81000000","0.00007000"],["78721.82000000","0.02161000"],["78721.83000000","0.00007000"],["78722.00000000","0.00007000"],["78722.01000000","0.00000000"],["78722.40000000","0.00400000"],["78723.54000000","0.00014000"],["78723.55000000","0.00000000"],["78724.00000000","0.00007000"],["78724.42000000","0.00000000"],["78724.43000000","0.30192000"],["78724.44000000","1.23544000"],["78724.45000000","0.00000000"],["78724.46000000","0.00000000"],["78724.54000000","0.00000000"],["78724.55000000","0.30007000"],["78724.56000000","0.69583000"],["78724.57000000","0.00000000"],["78724.59000000","0.00000000"],["78724.60000000","0.00007000"],["78724.61000000","0.84004000"],["78724.82000000","0.07507000"],["78724.83000000","0.63979000"],["78725.20000000","0.00007000"],["78725.21000000","0.17820000"],["78725.22000000","0.00330000"],["78725.70000000","0.07500000"],["78725.71000000","0.02268000"],["78725.88000000","0.00000000"],["78725.89000000","0.00014000"],["78726.63000000","0.00007000"],["78727.05000000","0.00007000"],["78727.41000000","0.00021000"],["78728.61000000","0.58636000"],["78729.04000000","0.02161000"],["78729.05000000","0.40958000"],["78729.78000000","0.00007000"],["78730.00000000","0.02400000"],["78730.98000000","0.00007000"],["78731.66000000","0.00000000"],["78732.98000000","0.10712000"],["78733.12000000","0.34297000"],["78734.84000000","0.00010000"],["78736.08000000","0.00000000"],["78738.69000000","0.06522000"],["78738.88000000","0.02000000"],["78739.23000000","0.00000000"],["78739.67000000","0.02000000"],["78739.68000000","0.02000000"],["78740.19000000","0.00000000"],["78740.66000000","0.07527000"],["78743.00000000","0.00000000"],["78743.44000000","0.00000000"],["78744.60000000","0.00000000"],["78745.41000000","0.00000000"],["78746.90000000","0.00000000"],["78748.13000000","0.00000000"],["78752.66000000","1.25724000"],["78756.00000000","0.02800000"],["78756.28000000","0.00000000"],["78758.03000000","0.66949000"],["78758.37000000","0.00000000"],["78758.40000000","0.00000000"],["78758.42000000","0.00000000"],["78760.56000000","0.00000000"],["78762.24000000","0.00000000"],["78763.03000000","0.00425000"],["78764.00000000","0.03414000"],["78764.67000000","0.01136000"],["78766.48000000","0.00317000"],["78768.00000000","0.02400000"],["78768.60000000","0.00000000"],["78769.84000000","0.00000000"],["78770.00000000","0.02400000"],["78771.41000000","0.87018000"],["78776.08000000","0.00000000"],["78777.12000000","0.00000000"],["78780.66000000","0.00000000"],["78781.98000000","0.00000000"],["78786.28000000","0.00000000"],["78787.99000000","0.00317000"],["78788.06000000","0.00000000"],["78788.39000000","0.02000000"],["78789.25000000","0.02000000"],["78789.33000000","0.02000000"],["78793.94000000","0.00000000"],["78799.77000000","0.21930000"],["78799.88000000","0.00000000"],["78817.78000000","0.00000000"],["78832.62000000","0.00000000"],["78865.03000000","0.00000000"],["78934.60000000","0.00000000"],["78935.90000000","0.00000000"],["78936.62000000","0.00000000"],["78940.30000000","0.00000000"],["78943.23000000","0.00000000"],["79110.82000000","0.01000000"],["79506.38000000","0.01000000"],["79903.91000000","0.01000000"],["80303.43000000","0.01000000"],["80704.94000000","0.01000000"],["81108.47000000","0.01000000"],["81514.01000000","0.01000000"],["81921.58000000","0.01000000"],["82331.19000000","0.01000000"],["82742.84000000","0.01131000"],["83156.56000000","0.01000000"],["83572.34000000","0.01000000"],["83990.20000000","0.01000000"],["84410.15000000","0.01000000"],["84832.20000000","0.01000000"]]}}
{"rx_ns": 43453132900, "frame": {"e":"depthUpdate","E":1787603100914,"s":"BTCUSDT","U":99076645750,"u":99076645869,"b":[["78717.22000000","1.12014000"],["78717.21000000","0.00070000"],["78716.56000000","0.00000000"],["78715.72000000","0.01774000"],["78715.00000000","0.00000000"],["78714.47000000","0.02952000"],["78713.21000000","0.03541000"],["78711.99000000","0.00539000"],["78711.95000000","0.03541000"],["78711.14000000","0.00000000"],["78709.28000000","0.00000000"],["78709.27000000","0.00007000"],["78708.06000000","0.00007000"],["78707.92000000","0.00070000"],["78707.37000000","0.00048000"],["78706.54000000","0.08576000"],["78704.65000000","0.02400000"],["78702.23000000","0.00000000"],["78701.52000000","0.00254000"],["78701.51000000","0.02400000"],["78701.47000000","0.00000000"],["78699.92000000","0.02000000"],["78699.86000000","0.02000000"],["78694.90000000","0.00010000"],["78692.65000000","0.00000000"],["78690.18000000","0.00000000"],["78687.96000000","0.00012000"],["78673.71000000","0.00000000"],["78672.90000000","0.02776000"],["78671.83000000","0.00000000"],["78671.01000000","0.02360000"],["78669.36000000","0.00007000"],["78666.12000000","0.00007000"],["78613.21000000","0.00000000"],["78503.04000000","0.00000000"],["70851.00000000","0.00000000"],["70845.50000000","0.00032000"],["62971.00000000","0.00300000"]],"a":[["78717.23000000","1.96169000"],["78717.51000000","0.00014000"],["78718.49000000","0.03413000"],["78719.15000000","0.04052000"],["78719.75000000","0.04095000"],["78719.82000000","0.05401000"],["78721.01000000","0.04095000"],["78721.81000000","0.31766000"],["78721.82000000","0.02168000"],["78724.43000000","0.30000000"],["78724.44000000","1.01614000"],["78724.55000000","0.30000000"],["78724.56000000","0.30007000"],["78724.60000000","0.00000000"],["78724.61000000","0.22121000"],["78724.82000000","0.07500000"],["78724.83000000","0.42049000"],["78725.11000000","0.21930000"],["78725.71000000","0.02168000"],["78728.61000000","0.18806000"],["78729.05000000","0.40944000"],["78733.57000000","0.04857000"],["78738.81000000","0.02000000"],["78741.95000000","0.02000000"],["78743.53000000","0.02000000"],["78743.60000000","0.02000000"],["78747.91000000","0.00000000"],["78748.99000000","0.00000000"],["78749.85000000","0.00000000"],["78749.93000000","0.00000000"],["78752.64000000","0.02600000"],["78757.00000000","0.01000000"],["78764.00000000","0.02414000"],["78792.09000000","0.02000000"],["78792.10000000","0.02000000"],["78795.25000000","0.02000000"],["78796.82000000","0.02000000"],["78807.65000000","0.21930000"],["78815.53000000","0.21930000"],["78820.04000000","0.02789000"]]}}
{"rx_ns": 43553547400, "frame": {"e":"depthUpdate","E":1787603101014,"s":"BTCUSDT","U":99076645870,"u":99076645958,"b":[["78717.22000000","0.74852000"],["78717.21000000","0.00077000"],["78716.44000000","0.00014000"],["78716.43000000","0.00000000"],["78715.16000000","0.00007000"],["78710.01000000","0.00000000"],["78709.99000000","0.04030000"],["78709.97000000","0.12704000"],["78709.07000000","0.00000000"],["78708.06000000","0.00014000"],["78707.72000000","0.00635000"],["78704.66000000","0.00635000"],["78702.77000000","0.02010000"],["78701.54000000","0.00254000"],["78701.52000000","0.00000000"],["78690.12000000","0.00000000"],["78658.36000000","0.00426000"],["78640.89000000","0.02000000"],["78640.87000000","0.00000000"],["78583.92000000","0.00000000"],["70845.50000000","0.00048000"],["62973.78000000","0.00031000"],["62971.00000000","0.00000000"]],"a":[["78717.23000000","2.22361000"],["78717.24000000","0.00034000"],["78718.01000000","0.00021000"],["78718.02000000","0.38114000"],["78718.47000000","0.00508000"],["78719.66000000","0.00137000"],["78719.88000000","0.00007000"],["78721.00000000","0.31765000"],["78721.01000000","0.04095000"],["78721.81000000","0.00007000"],["78722.39000000","0.00635000"],["78724.42000000","0.00635000"],["78724.44000000","1.01607000"],["78725.71000000","0.14870000"],["78728.59000000","0.00227000"],["78728.61000000","0.18799000"],["78729.31000000","0.00000000"],["78729.89000000","0.02000000"],["78732.46000000","0.00000000"],["78733.02000000","0.02000000"],["78733.58000000","0.12701000"],["78733.82000000","0.02600000"],["78733.89000000","0.02000000"],["78734.16000000","0.02161000"],["78744.92000000","0.00000000"],["78745.71000000","0.00000000"],["78745.82000000","0.43581000"],["78751.14000000","1.22352000"],["78752.70000000","0.00000000"],["78764.91000000","0.00000000"],["78771.98000000","0.00000000"],["78775.04000000","0.32016000"],["78779.34000000","0.00190000"],["78783.99000000","0.00000000"],["78789.28000000","0.00000000"],["78791.26000000","0.02000000"],["78792.09000000","0.00000000"],["78795.64000000","0.00406000"],["78796.82000000","0.04600000"],["78796.87000000","0.00000000"],["78810.37000000","2.13501000"],["78820.04000000","0.00000000"],["78832.81000000","0.00000000"],["78838.95000000","0.00000000"],["78845.04000000","0.00000000"],["78857.99000000","0.00076000"],["78862.65000000","0.00000000"],["80785.94000000","0.17672000"]]}}
{"rx_ns": 43652769600, "frame": {"e":"depthUpdate","E":1787603101114,"s":"BTCUSDT","U":99076645959,"u":99076646030,"b":[["78717.22000000","0.71384000"],["78717.21000000","0.00070000"],["78716.44000000","0.00000000"],["78710.01000000","0.00007000"],["78709.99000000","0.04030000"],["78702.05000000","0.12706000"],["78701.54000000","0.00000000"],["78701.52000000","0.00254000"],["78695.38000000","0.00000000"],["78692.01000000","0.13245000"],["78691.77000000","0.00000000"],["78691.09000000","0.50902000"],["78690.64000000","0.00000000"],["78689.77000000","0.63531000"],["78682.06000000","0.00000000"],["78672.90000000","0.00000000"],["78671.01000000","0.00000000"],["78667.48000000","1.02883000"],["78585.50000000","0.04092000"],["78008.76000000","0.00010000"],["70845.50000000","0.00064000"],["62973.78000000","0.00031000"]],"a":[["78717.23000000","2.23670000"],["78717.24000000","0.00020000"],["78717.50000000","0.00508000"],["78718.02000000","0.38121000"],["78718.47000000","0.00007000"],["78719.81000000","0.31779000"],["78719.82000000","0.05401000"],["78721.00000000","0.00007000"],["78721.01000000","0.04095000"],["78721.81000000","0.00000000"],["78721.82000000","0.02161000"],["78725.89000000","0.00007000"],["78726.62000000","0.00007000"],["78727.41000000","0.00014000"],["78728.66000000","0.00007000"],["78741.41000000","0.12699000"],["78751.08000000","0.00000000"],["78768.86000000","0.00000000"],["78811.60000000","0.00000000"],["78814.83000000","0.00025000"],["78821.62000000","0.02789000"],["78821.80000000","0.00012000"]]}}
{"rx_ns": 43753364000, "frame": {"e":"depthUpdate","E":1787603101214,"s":"BTCUSDT","U":99076646031,"u":99076646088,"b":[["78717.22000000","0.03909000"],["78707.72000000","0.00000000"],["78704.66000000","0.00000000"],["78704.38000000","0.00635000"],["78702.18000000","0.00635000"],["78701.52000000","0.00000000"],["78701.50000000","0.00254000"],["78689.77000000","0.00000000"],["78688.01000000","0.63532000"],["78681.66000000","0.45893000"],["78681.04000000","0.02400000"],["78672.56000000","0.02772000"],["78670.67000000","0.02440000"],["78668.05000000","0.00406000"],["78533.83000000","0.00000000"],["78518.23000000","0.00785000"],["70855.38000000","0.00000000"],["70845.50000000","0.00080000"],["62973.78000000","0.00000000"]],"a":[["78717.23000000","2.24325000"],["78717.50000000","0.00007000"],["78718.02000000","0.38128000"],["78718.47000000","0.00000000"],["78719.66000000","0.00000000"],["78719.75000000","0.04095000"],["78719.80000000","0.00007000"],["78719.81000000","0.31779000"],["78719.82000000","0.05387000"],["78720.08000000","0.00027000"],["78721.00000000","0.00000000"],["78722.79000000","0.02286000"],["78723.22000000","0.00254000"],["78725.71000000","0.14863000"],["78725.89000000","0.00000000"],["78728.59000000","0.36451000"],["78733.03000000","0.02000000"],["78740.26000000","0.00000000"],["78740.92000000","0.00000000"],["78752.73000000","0.02768000"],["78769.49000000","1.25697000"],["78791.26000000","0.00000000"],["78796.21000000","0.09218000"],["78796.82000000","0.02000000"],["78812.78000000","0.00000000"],["78827.94000000","0.00019000"],["78834.03000000","0.00031000"]]}}
{"rx_ns": 43852914300, "frame": {"e":"depthUpdate","E":1787603101314,"s":"BTCUSDT","U":99076646089,"u":99076646182,"b":[["78717.22000000","0.88394000"],["78717.21000000","0.00077000"],["78716.39000000","0.01378000"],["78715.23000000","0.00014000"],["78715.22000000","0.00000000"],["78710.01000000","0.00000000"],["78701.50000000","0.00000000"],["78701.48000000","0.00254000"],["78701.11000000","0.00007000"],["78639.27000000","0.00000000"],["78323.63000000","0.00000000"],["77932.01000000","0.00000000"],["77542.35000000","0.00000000"],["77154.64000000","0.00000000"],["76768.87000000","0.00000000"],["76385.02000000","0.00000000"],["76003.10000000","0.00000000"],["75623.08000000","0.00000000"],["75244.97000000","0.00000000"],["74868.74000000","0.00000000"],["74494.40000000","0.00000000"],["74121.92000000","0.00000000"],["73751.32000000","0.00000000"],["73382.56000000","0.00000000"],["73015.65000000","0.00000000"],["72419.85000000","0.00014000"],["70845.50000000","0.00112000"],["62974.00000000","0.00000000"]],"a":[["78717.23000000","1.97752000"],["78717.24000000","0.00062000"],["78717.50000000","0.00000000"],["78719.13000000","0.00508000"],["78719.80000000","0.00000000"],["78719.81000000","0.00014000"],["78719.82000000","0.05401000"],["78720.08000000","0.00000000"],["78721.00000000","0.31903000"],["78728.59000000","0.00227000"],["78729.88000000","0.02000000"],["78733.48000000","0.02600000"],["78779.34000000","0.00000000"],["78791.27000000","0.00000000"],["78857.99000000","0.00000000"],["78874.67000000","0.02000000"],["78890.25000000","0.02000000"],["79110.82000000","0.00000000"],["79506.38000000","0.00000000"],["79903.91000000","0.00000000"],["80303.43000000","0.00000000"],["80704.94000000","0.00000000"],["81108.47000000","0.00000000"],["81514.01000000","0.00000000"],["81921.58000000","0.00000000"],["82331.19000000","0.00000000"],["82742.84000000","0.00131000"],["83156.56000000","0.00000000"],["83572.34000000","0.00000000"],["83990.20000000","0.00000000"],["84410.15000000","0.00000000"],["84832.20000000","0.00000000"]]}}
{"rx_ns": 43960844800, "frame": {"e":"depthUpdate","E":1787603101414,"s":"BTCUSDT","U":99076646183,"u":99076646234,"b":[["78717.22000000","0.88437000"],["78717.21000000","0.01420000"],["78716.40000000","0.00000000"],["78716.39000000","0.00000000"],["78715.23000000","0.00000000"],["78709.99000000","0.04023000"],["78702.37000000","0.00254000"],["78701.48000000","0.00000000"],["78669.36000000","0.00000000"],["78666.12000000","0.00014000"],["78589.34000000","0.00406000"],["70845.50000000","0.00128000"]],"a":[["78717.23000000","2.19058000"],["78717.24000000","0.00069000"],["78718.49000000","0.03413000"],["78719.13000000","0.00515000"],["78719.75000000","0.04095000"],["78719.81000000","0.00007000"],["78719.82000000","0.05401000"],["78721.00000000","0.31910000"],["78728.59000000","0.00000000"],["78732.13000000","0.00227000"],["78736.17000000","0.00200000"],["78750.03000000","1.21983000"],["78772.83000000","0.00000000"],["78779.34000000","0.00190000"],["78786.90000000","0.00000000"],["78792.86000000","0.00000000"],["78857.99000000","0.00076000"],["78874.67000000","0.04000000"],["78890.25000000","0.00000000"],["80947.52000000","0.20244000"]]}}
{"rx_ns": 44067823300, "frame": {"e":"depthUpdate","E":1787603101515,"s":"BTCUSDT","U":99076646235,"u":99076646272,"b":[["78717.22000000","0.78720000"],["78717.21000000","0.01427000"],["78712.02000000","0.00007000"],["78712.01000000","0.20799000"],["78711.96000000","0.00007000"],["78705.38000000","0.00000000"],["78693.56000000","0.00007000"],["78683.02000000","0.34318000"],["78677.00000000","0.71000000"],["78674.70000000","0.34322000"],["78630.26000000","0.00000000"],["70845.50000000","0.00144000"],["62973.78000000","0.00031000"]],"a":[["78717.23000000","2.19008000"],["78717.24000000","0.00069000"],["78717.56000000","0.00254000"],["78718.30000000","0.00007000"],["78734.18000000","0.34296000"],["78740.80000000","0.00007000"],["78752.63000000","0.00000000"],["78760.81000000","0.00000000"]]}}
{"rx_ns": 44170028700, "frame": {"e":"depthUpdate","E":1787603101614,"s":"BTCUSDT","U":99076646273,"u":99076646306,"b":[["78717.22000000","0.78960000"],["78717.21000000","0.00097000"],["78717.20000000","0.00013000"],["78713.21000000","0.03541000"],["78712.02000000","0.00014000"],["78712.00000000","0.00711000"],["78710.00000000","0.04400000"],["78703.46000000","0.00254000"],["78702.37000000","0.00000000"],["78694.88000000","0.00400000"],["78669.60000000","0.00000000"],["78518.51000000","0.00435000"],["78317.01000000","0.00000000"],["70845.50000000","0.00144000"],["62973.78000000","0.00000000"]],"a":[["78717.23000000","2.19008000"],["78717.24000000","0.00069000"],["78717.56000000","0.00000000"],["78719.19000000","0.00254000"],["78731.57000000","0.00000000"],["78742.96000000","0.00012000"]]}}
{"rx_ns": 44255410200, "frame": {"e":"depthUpdate","E":1787603101714,"s":"BTCUSDT","U":99076646307,"u":99076646351,"b":[["78717.22000000","0.71787000"],["78717.21000000","0.00090000"],["78712.01000000","0.20806000"],["78680.75000000","0.28628000"],["78676.15000000","0.00000000"],["78630.26000000","0.02116000"],["78613.21000000","2.77181000"],["78518.23000000","0.00007000"],["78510.34000000","0.00778000"],["70845.50000000","0.00160000"]],"a":[["78717.23000000","2.45459000"],["78717.24000000","0.00020000"],["78719.13000000","0.00007000"],["78720.02000000","0.00027000"],["78724.54000000","1.21952000"],["78728.59000000","0.36224000"],["78729.05000000","0.40944000"],["78750.18000000","0.00000000"],["78790.64000000","0.00000000"]]}}
{"rx_ns": 44357763700, "frame": {"e":"depthUpdate","E":1787603101814,"s":"BTCUSDT","U":99076646352,"u":99076646405,"b":[["78717.22000000","0.04184000"],["78713.32000000","0.00014000"],["78713.31000000","0.01597000"],["78711.96000000","0.00000000"],["78694.19000000","0.12707000"],["78658.23000000","0.05191000"],["78630.26000000","0.00000000"],["78323.63000000","0.01000000"],["77932.01000000","0.01000000"],["77542.35000000","0.01000000"],["77154.64000000","0.01000000"],["76768.87000000","0.01000000"],["76385.02000000","0.01000000"],["76003.10000000","0.01000000"],["75623.08000000","0.01000000"],["75244.97000000","0.01000000"],["74868.74000000","0.01000000"],["74494.40000000","0.01000000"],["74121.92000000","0.01000000"],["73751.32000000","0.01000000"],["73382.56000000","0.01000000"],["73015.65000000","0.01000000"],["72419.85000000","0.00000000"]],"a":[["78717.23000000","2.45685000"],["78718.49000000","0.03413000"],["78719.13000000","0.00000000"],["78721.00000000","0.31773000"],["78721.82000000","0.02168000"],["78727.53000000","0.02000000"],["78728.26000000","0.02000000"],["78728.32000000","0.02000000"],["78740.00000000","0.81926000"],["78945.28000000","0.00406000"],["79110.82000000","0.01000000"],["79506.38000000","0.01000000"],["79903.91000000","0.01000000"],["80303.43000000","0.01000000"],["80704.94000000","0.01000000"],["81108.47000000","0.01000000"],["81514.01000000","0.01000000"],["81921.58000000","0.01000000"],["82331.19000000","0.01000000"],["82742.84000000","0.01131000"],["83156.56000000","0.01000000"],["83572.34000000","0.01000000"],["83990.20000000","0.01000000"],["84410.15000000","0.01000000"],["84832.20000000","0.01000000"]]}}
{"rx_ns": 44453610100, "frame": {"e":"depthUpdate","E":1787603101914,"s":"BTCUSDT","U":99076646406,"u":99076646432,"b":[["78717.22000000","0.04191000"],["78717.21000000","0.00097000"],["78714.47000000","0.02952000"],["78703.46000000","0.00000000"],["78701.62000000","0.00254000"],["78640.87000000","0.02000000"],["78317.01000000","0.00007000"],["70845.50000000","0.00176000"]],"a":[["78717.35000000","0.00254000"],["78719.19000000","0.00000000"],["78727.43000000","0.02000000"],["78730.58000000","0.02000000"],["78732.14000000","0.02329000"],["78732.22000000","0.02000000"],["78736.51000000","0.00007000"],["78738.81000000","0.00000000"],["78738.88000000","0.00000000"],["78739.67000000","0.00000000"],["78739.68000000","0.00000000"],["78741.95000000","0.00000000"],["78743.53000000","0.00000000"],["78755.88000000","0.00400000"],["78756.00000000","0.02400000"],["78792.09000000","0.02000000"]]}}
{"rx_ns": 44566304800, "frame": {"e":"depthUpdate","E":1787603102014,"s":"BTCUSDT","U":99076646433,"u":99076646448,"b":[["78717.22000000","0.01675000"],["78707.41000000","0.00406000"],["78686.48000000","0.00000000"],["78684.27000000","0.00635000"],["78682.00000000","0.72400000"],["78630.26000000","0.02116000"],["70845.50000000","0.00176000"],["62973.78000000","0.00031000"]],"a":[["78717.23000000","2.46955000"],["78717.27000000","0.06350000"],["78719.09000000","0.00007000"],["78719.14000000","0.31780000"],["78721.00000000","0.00007000"],["78722.78000000","0.00635000"],["78724.42000000","0.00227000"],["78732.13000000","0.00000000"],["78743.60000000","0.00000000"],["78792.09000000","0.00000000"]]}}
{"rx_ns": 44654152500, "frame": {"e":"depthUpdate","E":1787603102114,"s":"BTCUSDT","U":99076646449,"u":99076646490,"b":[["78717.22000000","0.03491000"],["78717.21000000","0.00104000"],["78716.01000000","0.00014000"],["78716.00000000","0.03500000"],["78714.00000000","0.00700000"],["78713.50000000","0.00020000"],["78712.02000000","0.00000000"],["78712.00000000","0.01411000"],["78708.30000000","0.31766000"],["70845.50000000","0.00192000"],["62973.78000000","0.00031000"]],"a":[["78717.23000000","2.46969000"],["78717.26000000","0.00014000"],["78717.27000000","0.06357000"],["78718.02000000","0.38128000"],["78718.49000000","0.03413000"],["78719.13000000","0.00014000"],["78719.14000000","0.31787000"],["78719.74000000","0.00000000"],["78719.81000000","0.00000000"],["78719.82000000","0.05387000"],["78719.88000000","0.00000000"],["78721.00000000","0.00000000"],["78721.82000000","0.02161000"],["78724.57000000","0.00007000"],["78725.21000000","0.17813000"],["78730.71000000","0.00007000"]]}}
{"rx_ns": 44758481600, "frame": {"e":"depthUpdate","E":1787603102214,"s":"BTCUSDT","U":99076646491,"u":99076646536,"b":[["78717.22000000","0.03075000"],["78716.00000000","0.03507000"],["78714.47000000","0.02952000"],["78713.32000000","0.00000000"],["78713.31000000","0.00000000"],["78712.01000000","0.00014000"],["78712.00000000","0.01207000"],["78711.99000000","0.00532000"],["78711.95000000","0.03534000"],["78708.06000000","0.00007000"],["78702.77000000","0.00010000"],["78701.62000000","0.00000000"],["78700.97000000","0.04600000"],["78691.37000000","0.00000000"],["78670.65000000","0.34324000"],["78669.36000000","0.00007000"],["78666.12000000","0.00007000"],["78597.62000000","0.00000000"],["78570.43000000","0.00000000"],["70845.50000000","0.00192000"],["62973.78000000","0.00000000"]],"a":[["78717.35000000","0.00000000"],["78719.82000000","0.05394000"],["78722.45000000","0.02000000"],["78724.80000000","0.00408000"],["78726.43000000","0.34299000"],["78730.00000000","0.11927000"],["78730.35000000","0.00000000"],["78740.99000000","0.34293000"],["78742.04000000","0.09313000"],["78747.98000000","0.00000000"],["78827.15000000","0.00406000"],["78869.56000000","0.00000000"]]}}
{"rx_ns": 44852486600, "frame": {"e":"depthUpdate","E":1787603102314,"s":"BTCUSDT","U":99076646537,"u":99076646775,"b":[["78717.22000000","0.00000000"],["78717.21000000","0.00000000"],["78717.20000000","0.00000000"],["78716.01000000","0.00000000"],["78716.00000000","0.07233000"],["78715.99000000","0.00042000"],["78714.00000000","0.01407000"],["78713.21000000","0.03541000"],["78712.01000000","0.00014000"],["78712.00000000","0.01907000"],["78711.99000000","0.00539000"],["78711.96000000","0.00007000"],["78711.95000000","0.03541000"],["78711.54000000","0.00000000"],["78710.00000000","0.04407000"],["78709.97000000","0.12711000"],["78709.95000000","0.00000000"],["78709.39000000","0.21003000"],["78706.54000000","0.00000000"],["78705.02000000","0.08576000"],["78702.62000000","0.00154000"],["78681.66000000","0.36224000"],["78677.10000000","0.00014000"],["78677.00000000","0.70000000"],["78676.00000000","0.03400000"],["78672.56000000","0.00000000"],["78671.83000000","0.02802000"],["78670.67000000","0.00000000"],["78669.94000000","0.02438000"],["78630.26000000","0.00000000"],["78613.21000000","0.00000000"],["78323.63000000","0.00000000"],["77932.01000000","0.00000000"],["77542.35000000","0.00000000"],["77154.64000000","0.00000000"],["76768.87000000","0.00000000"],["76385.02000000","0.00000000"],["76003.10000000","0.00000000"],["75623.08000000","0.00000000"],["75244.97000000","0.00000000"],["74868.74000000","0.00000000"],["74494.40000000","0.00000000"],["74121.92000000","0.00000000"],["73751.32000000","0.00000000"],["73382.56000000","0.00000000"],["73015.65000000","0.00000000"],["70845.50000000","0.00000000"],["62974.00000000","0.00000000"]],"a":[["78716.01000000","2.90123000"],["78716.02000000","0.00020000"],["78716.03000000","0.00013000"],["78717.21000000","0.00014000"],["78717.22000000","0.79348000"],["78717.23000000","0.77532000"],["78717.24000000","0.00000000"],["78717.25000000","0.00000000"],["78717.26000000","0.00000000"],["78718.02000000","0.38135000"],["78718.48000000","0.00000000"],["78718.59000000","0.05387000"],["78719.14000000","0.31773000"],["78719.82000000","0.00007000"],["78721.01000000","0.04088000"],["78727.05000000","0.00000000"],["78729.05000000","0.21836000"],["78731.76000000","0.09206000"],["78732.05000000","0.04857000"],["78732.98000000","0.00000000"],["78733.57000000","0.00000000"],["78740.03000000","0.02513000"],["78743.88000000","0.40575000"],["78751.48000000","0.00000000"],["78777.99000000","0.00190000"],["78779.34000000","0.00000000"],["79110.82000000","0.00000000"],["79506.38000000","0.00000000"],["79903.91000000","0.00000000"],["80303.43000000","0.00000000"],["80704.94000000","0.00000000"],["81108.47000000","0.00000000"],["81514.01000000","0.00000000"],["81921.58000000","0.00000000"],["82331.19000000","0.00000000"],["82742.84000000","0.00131000"],["83156.56000000","0.00000000"],["83572.34000000","0.00000000"],["83990.20000000","0.00000000"],["84410.15000000","0.00000000"],["84832.20000000","0.00000000"]]}}
{"rx_ns": 44971844400, "frame": {"e":"depthUpdate","E":1787603102414,"s":"BTCUSDT","U":99076646776,"u":99076646856,"b":[["78716.00000000","0.09746000"],["78715.99000000","0.00056000"],["78715.98000000","0.02516000"],["78715.73000000","0.00000000"],["78715.72000000","0.00007000"],["78714.48000000","0.00000000"],["78714.47000000","0.00007000"],["78714.01000000","0.00014000"],["78714.00000000","0.01907000"],["78713.22000000","0.00000000"],["78713.21000000","0.00007000"],["78712.00000000","0.02407000"],["78711.96000000","0.00000000"],["78711.95000000","0.00007000"],["78711.36000000","0.01507000"],["78710.39000000","0.00014000"],["78710.38000000","0.00000000"],["78710.01000000","0.00007000"],["78692.01000000","0.00000000"],["78688.81000000","0.13245000"]],"a":[["78716.01000000","3.10221000"],["78716.02000000","0.00020000"],["78717.22000000","0.29451000"],["78717.23000000","0.53925000"],["78717.26000000","0.00007000"],["78717.51000000","0.00007000"],["78718.49000000","0.00007000"],["78719.75000000","0.00000000"],["78719.82000000","0.00000000"],["78721.01000000","0.00000000"],["78723.89000000","0.00054000"],["78725.21000000","0.17806000"],["78740.19000000","0.43584000"],["78745.82000000","0.00000000"],["78749.46000000","0.00000000"],["78756.00000000","0.03400000"],["78757.00000000","0.00000000"],["78874.40000000","0.00406000"],["78934.12000000","0.00007000"],["78938.05000000","0.00000000"]]}}
{"rx_ns": 45053176800, "frame": {"e":"depthUpdate","E":1787603102514,"s":"BTCUSDT","U":99076646857,"u":99076646964,"b":[["78716.00000000","0.94151000"],["78715.99000000","0.00063000"],["78715.98000000","0.02523000"],["78715.72000000","0.00000000"],["78715.16000000","0.00000000"],["78714.51000000","0.00014000"],["78714.50000000","0.01767000"],["78714.47000000","0.00000000"],["78714.38000000","0.00007000"],["78714.00000000","0.01907000"],["78713.26000000","0.00007000"],["78713.25000000","0.02945000"],["78713.21000000","0.00000000"],["78712.63000000","0.01165000"],["78711.99000000","0.04073000"],["78711.95000000","0.00000000"],["78711.37000000","0.00000000"],["78711.36000000","0.00007000"],["78710.73000000","0.03534000"],["78710.39000000","0.00000000"],["78710.01000000","0.00000000"],["78709.99000000","0.04030000"],["78709.97000000","0.12718000"],["78709.39000000","0.20799000"],["78709.06000000","0.00007000"],["78708.12000000","0.21930000"],["78707.01000000","0.00000000"],["78695.20000000","0.00007000"],["78693.56000000","0.00000000"],["78677.00000000","0.00000000"],["70845.00000000","0.00080000"],["70844.40000000","0.00032000"],["62972.80000000","0.00031000"]],"a":[["78716.01000000","3.11740000"],["78716.02000000","0.00041000"],["78717.21000000","0.00000000"],["78717.22000000","0.00021000"],["78717.23000000","0.53621000"],["78717.26000000","0.00014000"],["78717.27000000","0.09763000"],["78718.00000000","0.00508000"],["78718.02000000","0.38135000"],["78718.49000000","0.00000000"],["78718.53000000","0.04088000"],["78718.58000000","0.00014000"],["78718.59000000","0.05394000"],["78719.13000000","0.00007000"],["78719.15000000","0.04052000"],["78719.79000000","0.04088000"],["78729.05000000","0.21436000"],["78731.76000000","0.09260000"],["78739.63000000","0.00054000"],["78740.80000000","0.00000000"],["78747.50000000","0.00054000"]]}}
{"rx_ns": 45157944600, "frame": {"e":"depthUpdate","E":1787603102614,"s":"BTCUSDT","U":99076646965,"u":99076647036,"b":[["78716.00000000","0.92086000"],["78715.99000000","0.00077000"],["78715.98000000","0.02523000"],["78714.66000000","0.00014000"],["78714.65000000","0.01577000"],["78714.50000000","0.01774000"],["78714.00000000","0.01907000"],["78713.26000000","0.00014000"],["78713.25000000","0.02952000"],["78712.64000000","0.00000000"],["78712.63000000","0.00007000"],["78712.01000000","0.00000000"],["78711.99000000","0.04066000"],["78711.36000000","0.00000000"],["78710.00000000","0.04400000"],["78709.99000000","0.04023000"],["78709.97000000","0.12711000"],["78708.30000000","0.31773000"],["78692.34000000","0.00007000"],["78660.47000000","0.00635000"],["78636.57000000","0.00406000"],["70844.40000000","0.00048000"],["62972.80000000","0.00000000"]],"a":[["78716.01000000","3.11854000"],["78716.02000000","0.00048000"],["78717.22000000","0.00014000"],["78717.27000000","0.09763000"],["78718.00000000","0.00515000"],["78718.02000000","0.38135000"],["78718.53000000","0.04095000"],["78718.59000000","0.05401000"],["78719.13000000","0.00000000"],["78719.14000000","0.00007000"],["78719.15000000","0.04052000"],["78721.81000000","0.31766000"],["78724.83000000","0.42042000"],["78739.58000000","0.00007000"]]}}
{"rx_ns": 45255925900, "frame": {"e":"depthUpdate","E":1787603102714,"s":"BTCUSDT","U":99076647037,"u":99076647065,"b":[["78716.00000000","0.92177000"],["78715.98000000","0.02523000"],["78714.65000000","0.01584000"],["78713.25000000","0.02952000"],["78712.63000000","0.00000000"],["78708.06000000","0.00014000"],["78707.92000000","0.00000000"],["78669.36000000","0.00000000"],["78666.12000000","0.00014000"],["70844.40000000","0.00064000"]],"a":[["78716.01000000","3.11854000"],["78716.02000000","0.00048000"],["78718.02000000","0.38128000"],["78718.59000000","0.05401000"],["78719.14000000","0.00000000"],["78719.79000000","0.04095000"]]}}
{"rx_ns": 45357267100, "frame": {"e":"depthUpdate","E":1787603102814,"s":"BTCUSDT","U":99076647066,"u":99076647095,"b":[["78716.00000000","0.95184000"],["78714.00000000","0.02407000"],["78707.41000000","0.00000000"],["78681.46000000","0.09475000"],["78668.05000000","0.00000000"],["78636.57000000","0.00000000"],["78589.34000000","0.00000000"],["78518.51000000","0.00029000"],["70844.40000000","0.00096000"]],"a":[["78716.01000000","3.11679000"],["78716.02000000","0.00048000"],["78747.28000000","0.02000000"],["78748.01000000","0.02000000"],["78748.07000000","0.02000000"],["78756.26000000","0.00000000"],["78795.64000000","0.00000000"],["78827.15000000","0.00000000"],["78874.40000000","0.00000000"],["78945.28000000","0.00000000"]]}}
{"rx_ns": 45457391000, "frame": {"e":"depthUpdate","E":1787603102914,"s":"BTCUSDT","U":99076647096,"u":99076647136,"b":[["78716.00000000","0.95195000"],["78715.61000000","0.01550000"],["78714.65000000","0.00007000"],["78510.34000000","0.00000000"],["78504.57000000","0.00779000"],["78322.42000000","0.01000000"],["77930.80000000","0.01000000"],["77541.15000000","0.01000000"],["77153.44000000","0.01000000"],["76767.68000000","0.01000000"],["76383.84000000","0.01000000"],["76001.92000000","0.01000000"],["75621.91000000","0.01000000"],["75243.80000000","0.01000000"],["74867.58000000","0.01000000"],["74493.24000000","0.01000000"],["74120.78000000","0.01000000"],["73750.17000000","0.01000000"],["73381.42000000","0.01000000"],["73014.51000000","0.01000000"],["70844.40000000","0.00112000"]],"a":[["78716.01000000","3.11868000"],["78747.18000000","0.02000000"],["78750.33000000","0.02000000"],["78751.89000000","0.02000000"],["78751.97000000","0.02000000"],["78792.09000000","0.02000000"],["79109.60000000","0.01000000"],["79505.14000000","0.01000000"],["79902.67000000","0.01000000"],["80302.18000000","0.01000000"],["80703.69000000","0.01000000"],["81107.21000000","0.01000000"],["81512.75000000","0.01000000"],["81920.31000000","0.01000000"],["82329.91000000","0.01000000"],["82741.56000000","0.01000000"],["83155.27000000","0.01000000"],["83571.05000000","0.01000000"],["83988.90000000","0.01000000"],["84408.85000000","0.01000000"],["84830.89000000","0.01000000"]]}}
{"rx_ns": 45554975500, "frame": {"e":"depthUpdate","E":1787603103014,"s":"BTCUSDT","U":99076647137,"u":99076647162,"b":[["78716.00000000","0.95195000"],["78715.99000000","0.00077000"],["78715.98000000","0.02523000"],["78715.62000000","0.00014000"],["78715.61000000","0.01557000"],["78714.66000000","0.00000000"],["78714.65000000","0.00000000"],["78707.01000000","0.00007000"],["78688.82000000","0.63532000"],["78688.01000000","0.00000000"],["70844.40000000","0.00144000"],["62972.80000000","0.00031000"]],"a":[["78717.50000000","0.00508000"],["78718.00000000","0.00007000"],["78719.78000000","0.31766000"],["78721.81000000","0.00000000"],["78722.78000000","0.00000000"],["78723.88000000","0.00635000"],["78789.33000000","0.00000000"],["78792.09000000","0.00000000"],["78857.79000000","0.00406000"]]}}
{"rx_ns": 45652868200, "frame": {"e":"depthUpdate","E":1787603103114,"s":"BTCUSDT","U":99076647163,"u":99076647198,"b":[["78716.00000000","0.95178000"],["78711.99000000","0.04073000"],["78008.76000000","0.00000000"],["70844.40000000","0.00153000"]],"a":[["78716.01000000","3.11882000"],["78716.02000000","0.00069000"],["78717.23000000","0.53611000"],["78717.27000000","0.09763000"],["78717.50000000","0.00515000"],["78718.00000000","0.00000000"],["78718.59000000","0.05401000"],["78719.15000000","0.04052000"],["78719.78000000","0.00007000"],["78719.79000000","0.04088000"],["78721.81000000","0.31766000"],["78722.52000000","0.00007000"],["78740.19000000","0.00000000"],["78742.70000000","0.43583000"],["78777.81000000","0.00007000"],["78788.39000000","0.00000000"],["78813.61000000","0.00025000"],["78814.83000000","0.00000000"]]}}
{"rx_ns": 45753319800, "frame": {"e":"depthUpdate","E":1787603103214,"s":"BTCUSDT","U":99076647199,"u":99076647264,"b":[["78716.00000000","1.37208000"],["78710.09000000","0.00000000"],["78709.39000000","0.00000000"],["78709.07000000","0.02000000"],["78707.37000000","0.00000000"],["78700.97000000","0.02600000"],["78689.97000000","0.00406000"],["78689.29000000","0.34316000"],["78670.65000000","0.00000000"],["70844.40000000","0.00169000"],["62972.80000000","0.00000000"]],"a":[["78716.01000000","2.42861000"],["78717.23000000","0.52204000"],["78717.27000000","0.03413000"],["78717.50000000","0.00007000"],["78718.29000000","0.00000000"],["78718.59000000","0.05401000"],["78719.08000000","0.00508000"],["78719.15000000","0.04052000"],["78719.78000000","0.00000000"],["78719.79000000","0.04095000"],["78719.98000000","0.00137000"],["78719.99000000","0.00000000"],["78721.81000000","0.31766000"],["78722.45000000","0.00000000"],["78723.88000000","0.00000000"],["78724.42000000","0.00000000"],["78724.54000000","0.00000000"],["78725.69000000","0.00635000"],["78726.22000000","0.00190000"],["78726.43000000","0.00000000"],["78728.59000000","0.00000000"],["78729.15000000","0.02000000"],["78731.75000000","0.00227000"],["78747.22000000","0.34290000"],["78789.25000000","0.00000000"],["78790.91000000","1.21952000"],["78823.41000000","0.21930000"]]}}
{"rx_ns": 45868545000, "frame": {"e":"depthUpdate","E":1787603103314,"s":"BTCUSDT","U":99076647265,"u":99076647284,"b":[["78716.00000000","1.15278000"],["78709.97000000","0.12704000"],["70844.40000000","0.00169000"],["62974.00000000","0.00000000"]],"a":[["78716.01000000","2.42854000"],["78716.02000000","0.00062000"],["78717.27000000","0.03413000"],["78717.50000000","0.00000000"],["78717.65000000","0.00020000"],["78718.59000000","0.05401000"],["78719.08000000","0.00515000"],["78792.10000000","0.00000000"],["78795.25000000","0.00000000"],["78796.82000000","0.00000000"]]}}
{"rx_ns": 45952233900, "frame": {"e":"depthUpdate","E":1787603103414,"s":"BTCUSDT","U":99076647285,"u":99076647318,"b":[["78706.46000000","0.00047000"],["78705.85000000","0.00000000"],["78650.62000000","0.00406000"],["78322.42000000","0.00000000"],["77930.80000000","0.00000000"],["77541.15000000","0.00000000"],["77153.44000000","0.00000000"],["76767.68000000","0.00000000"],["76383.84000000","0.00000000"],["76001.92000000","0.00000000"],["75621.91000000","0.00000000"],["75243.80000000","0.00000000"],["74867.58000000","0.00000000"],["74493.24000000","0.00000000"],["74120.78000000","0.00000000"],["73750.17000000","0.00000000"],["73381.42000000","0.00000000"],["73014.51000000","0.00000000"],["70844.40000000","0.00185000"]],"a":[["79109.60000000","0.00000000"],["79505.14000000","0.00000000"],["79902.67000000","0.00000000"],["80302.18000000","0.00000000"],["80703.69000000","0.00000000"],["81107.21000000","0.00000000"],["81512.75000000","0.00000000"],["81920.31000000","0.00000000"],["82329.91000000","0.00000000"],["82741.56000000","0.00000000"],["83155.27000000","0.00000000"],["83571.05000000","0.00000000"],["83988.90000000","0.00000000"],["84408.85000000","0.00000000"],["84830.89000000","0.00000000"]]}}
{"rx_ns": 46052851600, "frame": {"e":"depthUpdate","E":1787603103514,"s":"BTCUSDT","U":99076647319,"u":99076647337,"b":[["78716.00000000","0.61394000"],["78715.62000000","0.00000000"],["78715.61000000","0.00007000"],["78712.01000000","0.00007000"],["78709.07000000","0.00000000"],["78707.17000000","0.00000000"],["78705.27000000","0.02000000"],["78613.21000000","2.77185000"],["70844.40000000","0.00185000"],["62972.80000000","0.00031000"]],"a":[["78716.01000000","2.82849000"],["78718.52000000","0.00007000"]]}}
{"rx_ns": 46152860600, "frame": {"e":"depthUpdate","E":1787603103614,"s":"BTCUSDT","U":99076647338,"u":99076647376,"b":[["78716.00000000","0.84105000"],["78715.99000000","0.00083000"],["78715.98000000","0.02536000"],["78715.61000000","0.00000000"],["78710.73000000","0.03541000"],["78692.34000000","0.00007000"],["78681.46000000","0.00000000"],["78680.80000000","0.09561000"],["78671.83000000","0.00000000"],["78671.81000000","0.02832000"],["78669.94000000","0.00000000"],["78669.92000000","0.02365000"],["77862.68000000","0.00000000"],["76965.82000000","0.00000000"],["76079.29000000","0.00000000"],["75202.96000000","0.00000000"],["74336.74000000","0.00000000"],["73480.49000000","0.00000000"],["72634.10000000","0.00008000"],["71797.46000000","0.00000000"],["70844.40000000","0.00201000"],["70844.00000000","0.00000000"],["62972.80000000","0.00000000"]],"a":[["78716.01000000","2.82842000"],["78716.02000000","0.00055000"],["78739.58000000","0.00007000"],["78739.68000000","0.00406000"],["79687.88000000","0.00000000"],["80616.46000000","0.00000000"]]}}
{"rx_ns": 51554149700, "frame": {"e":"depthUpdate","E":1787603109014,"s":"BTCUSDT","U":99076649580,"u":99076649618,"b":[["78716.74000000","5.89142000"],["78716.73000000","2.26766000"],["78716.04000000","0.00014000"],["78716.03000000","0.45475000"],["78716.02000000","0.38794000"],["78716.00000000","0.70875000"],["78715.88000000","0.00000000"],["78715.47000000","0.01805000"],["78714.52000000","0.03224000"],["78714.50000000","0.00000000"],["78714.22000000","0.03009000"],["78714.00000000","0.02400000"],["78712.96000000","0.03610000"],["78711.70000000","0.03610000"],["78707.91000000","0.02200000"],["78700.13000000","0.63523000"],["78697.67000000","0.00000000"],["78640.95000000","0.00000000"],["78501.02000000","0.00000000"],["78488.31000000","0.01990000"],["70845.07000000","0.00048000"],["62973.40000000","0.00031000"]],"a":[["78718.53000000","0.04095000"],["78718.59000000","0.00007000"],["78719.34000000","0.05388000"],["78722.72000000","0.17823000"],["78727.19000000","0.00000000"],["78727.67000000","0.00000000"],["78728.05000000","0.00508000"],["78752.00000000","0.72400000"],["78754.99000000","0.02787000"],["78934.39000000","0.00000000"]]}}
{"rx_ns": 51652512800, "frame": {"e":"depthUpdate","E":1787603109114,"s":"BTCUSDT","U":99076649619,"u":99076649692,"b":[["78716.74000000","5.88500000"],["78716.73000000","2.26766000"],["78716.04000000","0.00007000"],["78716.03000000","0.07521000"],["78716.01000000","1.21973000"],["78716.00000000","0.70875000"],["78715.81000000","0.00000000"],["78715.47000000","0.01812000"],["78714.58000000","0.00635000"],["78714.52000000","0.03231000"],["78714.41000000","0.02516000"],["78700.04000000","0.00000000"],["78323.15000000","0.01000000"],["78008.29000000","0.00010000"],["77931.54000000","0.01000000"],["77541.88000000","0.01000000"],["77313.61000000","0.00013000"],["77154.17000000","0.01000000"],["76768.40000000","0.01000000"],["76384.56000000","0.01000000"],["76002.63000000","0.01010000"],["75622.62000000","0.01000000"],["75244.51000000","0.01000000"],["74868.28000000","0.01000000"],["74493.94000000","0.01000000"],["74121.47000000","0.01000000"],["73750.87000000","0.01000000"],["73382.11000000","0.01000000"],["73015.20000000","0.01008000"],["70844.40000000","0.00000000"]],"a":[["78716.75000000","0.10580000"],["78716.76000000","0.00063000"],["78719.34000000","0.05402000"],["78719.79000000","0.04095000"],["78720.98000000","0.22212000"],["78722.72000000","0.00007000"],["78723.91000000","0.00000000"],["78724.61000000","0.16129000"],["78731.78000000","0.00000000"],["78739.65000000","0.00000000"],["78747.52000000","0.00000000"],["78813.61000000","0.00000000"],["78816.77000000","0.93647000"],["78821.62000000","0.00000000"],["79110.34000000","0.01000000"],["79505.89000000","0.01000000"],["79903.42000000","0.01008000"],["80302.94000000","0.01000000"],["80704.45000000","0.01000000"],["81107.97000000","0.01000000"],["81513.51000000","0.01000000"],["81921.08000000","0.01000000"],["82330.69000000","0.01000000"],["82742.34000000","0.01000000"],["83156.05000000","0.01000000"],["83571.83000000","0.01000000"],["83989.69000000","0.01000000"],["84409.64000000","0.01000000"],["84831.69000000","0.01000000"]]}}
{"rx_ns": 51752764100, "frame": {"e":"depthUpdate","E":1787603109214,"s":"BTCUSDT","U":99076649693,"u":99076649727,"b":[["78716.74000000","5.88516000"],["78715.47000000","0.01812000"],["78713.80000000","0.05000000"],["78713.75000000","0.05000000"],["70845.07000000","0.00080000"],["70845.00000000","0.00080000"],["62973.40000000","0.00000000"]],"a":[["78716.75000000","0.09841000"],["78716.76000000","0.00063000"],["78717.29000000","0.00000000"],["78717.30000000","0.00014000"],["78719.34000000","0.05395000"],["78719.78000000","0.00014000"],["78719.79000000","0.04095000"],["78720.97000000","0.00007000"],["78720.98000000","0.22219000"],["78721.21000000","0.04038000"],["78722.72000000","0.00000000"],["78724.63000000","0.00034000"],["78732.50000000","0.00042000"],["78740.37000000","0.00034000"],["78748.24000000","0.00034000"],["78814.35000000","0.00355000"],["78828.62000000","0.02800000"]]}}
{"rx_ns": 51859280800, "frame": {"e":"depthUpdate","E":1787603109314,"s":"BTCUSDT","U":99076649728,"u":99076649747,"b":[["70845.07000000","0.00096000"],["62973.39000000","0.00000000"],["62973.00000000","0.01646000"]],"a":[["78716.75000000","0.09796000"],["78717.27000000","0.03413000"],["78717.30000000","0.00007000"],["78720.98000000","0.22219000"],["78721.21000000","0.04045000"],["78724.43000000","0.02161000"],["80253.27000000","0.00012000"]]}}
{"rx_ns": 51952679400, "frame": {"e":"depthUpdate","E":1787603109414,"s":"BTCUSDT","U":99076649748,"u":99076649768,"b":[["78716.74000000","5.88516000"],["78713.80000000","0.00000000"],["78711.37000000","0.00400000"],["78660.34000000","0.00314000"],["76798.93000000","0.00013000"],["70845.00000000","0.00090000"]],"a":[["78716.75000000","0.09412000"],["78722.79000000","0.02293000"],["78724.43000000","0.02168000"],["78724.44000000","0.07426000"],["78734.83000000","0.00400000"],["78743.26000000","0.00000000"],["78743.81000000","0.09408000"],["78790.14000000","0.00320000"]]}}
{"rx_ns": 52052568500, "frame": {"e":"depthUpdate","E":1787603109514,"s":"BTCUSDT","U":99076649769,"u":99076649780,"b":[["78713.80000000","0.05000000"],["78692.00000000","0.72400000"],["70845.07000000","0.00112000"],["70845.00000000","0.00080000"],["62973.40000000","0.00031000"]],"a":[["78716.75000000","0.09405000"],["78716.76000000","0.00056000"],["78720.97000000","0.00000000"],["78720.98000000","0.00007000"],["78721.20000000","0.00007000"]]}}
{"rx_ns": 52153229600, "frame": {"e":"depthUpdate","E":1787603109614,"s":"BTCUSDT","U":99076649781,"u":99076649825,"b":[["78716.74000000","5.88508000"],["78713.80000000","0.00000000"],["78641.35000000","0.02116000"],["78323.15000000","0.00000000"],["77931.54000000","0.00000000"],["77541.88000000","0.00000000"],["77154.17000000","0.00000000"],["76768.40000000","0.00000000"],["76384.56000000","0.00000000"],["76002.63000000","0.00010000"],["75622.62000000","0.00000000"],["75244.51000000","0.00000000"],["74868.28000000","0.00000000"],["74493.94000000","0.00000000"],["74121.47000000","0.00000000"],["73750.87000000","0.00000000"],["73382.11000000","0.00000000"],["73015.20000000","0.00008000"],["70845.07000000","0.00128000"],["62973.40000000","0.00000000"]],"a":[["78719.34000000","0.05388000"],["78719.79000000","0.04095000"],["78720.98000000","0.00000000"],["78724.44000000","0.07433000"],["79110.34000000","0.00000000"],["79505.89000000","0.00000000"],["79903.42000000","0.00008000"],["80302.94000000","0.00000000"],["80704.45000000","0.00000000"],["81107.97000000","0.00000000"],["81513.51000000","0.00000000"],["81837.80000000","0.00012000"],["81921.08000000","0.00000000"],["82330.69000000","0.00000000"],["82742.34000000","0.00000000"],["83156.05000000","0.00000000"],["83571.83000000","0.00000000"],["83989.69000000","0.00000000"],["84409.64000000","0.00000000"],["84831.69000000","0.00000000"]]}}
{"rx_ns": 52253920300, "frame": {"e":"depthUpdate","E":1787603109715,"s":"BTCUSDT","U":99076649826,"u":99076650082,"b":[["78717.26000000","5.52088000"],["78717.25000000","1.90535000"],["78717.24000000","0.00013000"],["78717.23000000","1.38158000"],["78717.22000000","1.32001000"],["78717.21000000","0.00000000"],["78717.20000000","0.00000000"],["78716.75000000","0.07500000"],["78716.74000000","0.60964000"],["78716.73000000","0.36231000"],["78716.72000000","0.00000000"],["78716.03000000","0.07507000"],["78716.02000000","0.07017000"],["78716.01000000","1.21959000"],["78714.52000000","0.03224000"],["78713.80000000","0.00000000"],["78713.75000000","0.00000000"],["78709.27000000","0.00000000"],["78709.06000000","0.00000000"],["78708.30000000","0.00000000"],["78707.54000000","0.08576000"],["78706.64000000","0.00000000"],["78703.18000000","0.00000000"],["78699.87000000","0.13243000"],["78691.89000000","0.00254000"],["78641.35000000","0.00000000"],["78634.01000000","0.00317000"],["78632.01000000","0.00000000"],["75840.85000000","0.00013000"],["75221.06000000","0.00056000"],["70845.54000000","0.00016000"],["70845.07000000","0.00009000"]],"a":[["78716.75000000","0.00000000"],["78716.76000000","0.00000000"],["78717.23000000","0.00000000"],["78717.24000000","0.00000000"],["78717.26000000","0.00000000"],["78717.27000000","0.09782000"],["78717.28000000","0.00056000"],["78719.01000000","0.00204000"],["78719.02000000","0.00014000"],["78719.03000000","0.20806000"],["78719.33000000","0.00000000"],["78719.34000000","0.00007000"],["78719.81000000","0.00014000"],["78719.82000000","0.05381000"],["78721.20000000","0.00014000"],["78722.78000000","0.00000000"],["78724.61000000","0.16136000"],["78726.70000000","0.00000000"],["78730.48000000","0.00000000"],["78730.71000000","0.31768000"],["78731.76000000","0.00000000"],["78732.98000000","0.02951000"],["78733.67000000","0.00000000"],["78734.56000000","0.04857000"],["78754.99000000","0.00000000"],["78755.05000000","0.02749000"],["78933.74000000","0.00007000"],["78937.67000000","0.00007000"]]}}
{"rx_ns": 52356165800, "frame": {"e":"depthUpdate","E":1787603109814,"s":"BTCUSDT","U":99076650083,"u":99076650158,"b":[["78717.26000000","5.47065000"],["78717.25000000","1.90542000"],["78717.24000000","0.00027000"],["78717.23000000","0.69711000"],["78717.22000000","0.63510000"],["78716.75000000","0.07521000"],["78716.74000000","0.60964000"],["78716.02000000","0.07024000"],["78716.01000000","1.21952000"],["78716.00000000","0.70868000"],["78715.47000000","0.01805000"],["78693.60000000","0.00007000"],["78692.36000000","0.00000000"],["78691.89000000","0.13602000"],["70845.54000000","0.00032000"]],"a":[["78717.27000000","0.06383000"],["78717.28000000","0.00070000"],["78717.30000000","0.00000000"],["78718.52000000","0.00000000"],["78718.53000000","0.00007000"],["78719.03000000","0.20813000"],["78719.34000000","0.00000000"],["78719.78000000","0.00000000"],["78719.79000000","0.00007000"],["78719.82000000","0.05388000"],["78722.78000000","0.00014000"],["78724.42000000","0.00007000"],["78724.61000000","0.16129000"],["78725.11000000","0.21944000"],["78725.52000000","0.01270000"],["78725.56000000","0.06350000"],["78727.69000000","0.00007000"],["78739.60000000","0.00000000"],["78740.84000000","0.00007000"],["78933.74000000","0.00000000"],["78937.67000000","0.00000000"]]}}
{"rx_ns": 52460436700, "kind": "rest", "req": {"method": "GET", "url": "https://data-api.binance.vision/api/v3/depth?symbol=BTCUSDT&limit=100", "limit": 100, "weight": 5, "sent_ns": 51384868100, "status": 200, "used_weight_1m": "5", "recv_ns": 52365540400}, "frame": {"lastUpdateId":99076650158,"bids":[["78717.26000000","5.47065000"],["78717.25000000","1.90542000"],["78717.24000000","0.00027000"],["78717.23000000","0.69711000"],["78717.22000000","0.63510000"],["78716.75000000","0.07521000"],["78716.74000000","0.60964000"],["78716.73000000","0.36231000"],["78716.04000000","0.00007000"],["78716.03000000","0.07507000"],["78716.02000000","0.07024000"],["78716.01000000","1.21952000"],["78716.00000000","0.70868000"],["78715.84000000","0.00400000"],["78715.80000000","0.00014000"],["78715.47000000","0.01805000"],["78714.58000000","0.00635000"],["78714.57000000","0.00325000"],["78714.52000000","0.03224000"],["78714.41000000","0.02516000"],["78714.38000000","0.00007000"],["78714.22000000","0.03009000"],["78714.00000000","0.02400000"],["78713.60000000","0.00400000"],["78713.50000000","0.00146000"],["78712.96000000","0.03610000"],["78712.30000000","0.00007000"],["78712.15000000","0.00325000"],["78712.00000000","0.02519000"],["78711.99000000","0.00532000"],["78711.93000000","0.00014000"],["78711.70000000","0.03610000"],["78711.37000000","0.00400000"],["78711.36000000","0.00400000"],["78710.86000000","0.00007000"],["78710.70000000","0.04000000"],["78710.64000000","0.00010000"],["78710.58000000","0.00319000"],["78710.25000000","0.00007000"],["78710.00000000","0.04400000"],["78709.97000000","0.12704000"],["78709.77000000","0.00400000"],["78709.68000000","0.00007000"],["78709.40000000","0.00008000"],["78709.08000000","0.00027000"],["78708.80000000","2.26739000"],["78708.78000000","1.21952000"],["78708.24000000","0.00007000"],["78708.21000000","0.00007000"],["78708.12000000","0.21930000"],["78708.06000000","0.00014000"],["78708.03000000","0.00320000"],["78708.00000000","0.02407000"],["78707.91000000","0.02200000"],["78707.71000000","0.00007000"],["78707.60000000","0.03224000"],["78707.54000000","0.08576000"],["78707.16000000","0.00400000"],["78707.01000000","0.00007000"],["78706.30000000","0.00400000"],["78706.26000000","0.00332000"],["78706.17000000","0.00007000"],["78706.16000000","0.00007000"],["78706.00000000","0.02400000"],["78705.80000000","0.00007000"],["78705.29000000","0.00254000"],["78705.01000000","0.00113000"],["78704.65000000","0.02400000"],["78704.56000000","0.00007000"],["78704.55000000","0.00400000"],["78704.37000000","0.00126000"],["78704.19000000","0.00014000"],["78704.17000000","0.00007000"],["78704.12000000","0.00007000"],["78704.09000000","0.00320000"],["78704.00000000","0.02400000"],["78703.88000000","0.12712000"],["78703.83000000","0.34309000"],["78703.71000000","0.00595000"],["78703.58000000","1.90515000"],["78703.57000000","1.21952000"],["78703.17000000","0.03000000"],["78702.86000000","0.02400000"],["78702.77000000","0.00010000"],["78702.17000000","0.00007000"],["78702.07000000","0.00007000"],["78702.05000000","0.12706000"],["78702.00000000","0.02400000"],["78701.92000000","0.00007000"],["78701.87000000","0.38122000"],["78701.71000000","0.02000000"],["78701.70000000","0.00408000"],["78701.51000000","0.02400000"],["78701.11000000","0.00007000"],["78701.08000000","0.00027000"],["78701.00000000","0.00007000"],["78700.97000000","0.02600000"],["78700.91000000","0.02000000"],["78700.84000000","0.02200000"],["78700.49000000","0.02200000"]],"asks":[["78717.27000000","0.06383000"],["78717.28000000","0.00070000"],["78717.51000000","0.00007000"],["78717.65000000","0.00020000"],["78718.02000000","0.00007000"],["78718.30000000","0.00007000"],["78718.53000000","0.00007000"],["78718.59000000","0.00007000"],["78719.01000000","0.00204000"],["78719.02000000","0.00014000"],["78719.03000000","0.20813000"],["78719.09000000","0.00007000"],["78719.67000000","0.00007000"],["78719.79000000","0.00007000"],["78719.81000000","0.00014000"],["78719.82000000","0.05388000"],["78720.48000000","0.00007000"],["78721.20000000","0.00014000"],["78721.21000000","0.04045000"],["78722.00000000","0.00007000"],["78722.52000000","0.00007000"],["78722.78000000","0.00014000"],["78722.79000000","0.02293000"],["78723.22000000","0.00254000"],["78723.35000000","0.00007000"],["78723.54000000","0.00014000"],["78724.42000000","0.00007000"],["78724.43000000","0.02168000"],["78724.44000000","0.07433000"],["78724.56000000","0.00007000"],["78724.57000000","0.00007000"],["78724.61000000","0.16129000"],["78724.63000000","0.00034000"],["78724.80000000","0.00008000"],["78724.83000000","0.41711000"],["78725.11000000","0.21944000"],["78725.20000000","0.00007000"],["78725.29000000","0.00048000"],["78725.52000000","0.01270000"],["78725.56000000","0.06350000"],["78725.71000000","0.12702000"],["78726.03000000","0.02000000"],["78726.23000000","0.01000000"],["78726.62000000","0.00007000"],["78726.63000000","0.00007000"],["78727.13000000","0.12000000"],["78727.20000000","0.00400000"],["78727.41000000","0.00014000"],["78727.43000000","0.02000000"],["78727.53000000","0.02000000"],["78727.68000000","0.00192000"],["78727.69000000","0.00007000"],["78728.00000000","0.00273000"],["78728.05000000","0.00508000"],["78728.06000000","0.00027000"],["78728.26000000","0.02000000"],["78728.32000000","0.02000000"],["78728.61000000","0.18799000"],["78728.66000000","0.00007000"],["78729.00000000","0.00007000"],["78729.05000000","0.21436000"],["78729.08000000","0.00007000"],["78729.60000000","0.00400000"],["78729.73000000","0.18486000"],["78729.78000000","0.00007000"],["78729.88000000","0.02000000"],["78729.89000000","0.02000000"],["78730.00000000","0.02400000"],["78730.01000000","0.00048000"],["78730.52000000","0.27729000"],["78730.57000000","0.00137000"],["78730.58000000","0.02000000"],["78730.71000000","0.31768000"],["78730.72000000","0.02161000"],["78730.98000000","0.00007000"],["78731.28000000","0.00014000"],["78731.56000000","0.00048000"],["78732.00000000","0.02800000"],["78732.14000000","0.02329000"],["78732.22000000","0.02000000"],["78732.24000000","0.00189000"],["78732.29000000","0.12710000"],["78732.50000000","0.00042000"],["78732.76000000","0.00007000"],["78732.93000000","0.00007000"],["78732.96000000","0.00007000"],["78732.98000000","0.02951000"],["78733.02000000","0.02000000"],["78733.03000000","0.02000000"],["78733.48000000","0.02600000"],["78733.53000000","0.00007000"],["78733.58000000","0.12701000"],["78733.82000000","0.02600000"],["78733.89000000","0.02000000"],["78733.99000000","0.00635000"],["78734.00000000","0.02400000"],["78734.15000000","0.02161000"],["78734.20000000","0.00323000"],["78734.39000000","0.00635000"],["78734.40000000","0.00400000"]]}}
{"rx_ns": 52460436700, "frame": {"e":"depthUpdate","E":1787603109914,"s":"BTCUSDT","U":99076650159,"u":99076650195,"b":[["78717.22000000","0.41580000"],["78717.10000000","0.00008000"],["78716.74000000","0.39041000"],["70845.54000000","0.00048000"]],"a":[["78717.27000000","0.06390000"],["78717.28000000","0.02068000"],["78717.50000000","0.00013000"],["78718.53000000","0.00014000"],["78718.54000000","0.03342000"],["78719.03000000","0.20813000"],["78719.79000000","0.00014000"],["78719.80000000","0.04011000"],["78721.06000000","0.04011000"],["78721.20000000","0.00000000"],["78722.78000000","0.00000000"],["78724.42000000","0.00000000"],["78724.61000000","0.16136000"],["78724.83000000","0.41718000"]]}}
{"rx_ns": 52556107400, "frame": {"e":"depthUpdate","E":1787603110014,"s":"BTCUSDT","U":99076650196,"u":99076650226,"b":[["78688.18000000","0.02200000"],["78640.94000000","0.00000000"],["70845.54000000","0.00080000"],["62973.81000000","0.00031000"]],"a":[["78717.27000000","0.06411000"],["78717.28000000","0.02096000"],["78718.54000000","0.03349000"],["78719.03000000","0.20813000"],["78719.80000000","0.04018000"],["78719.82000000","0.05388000"],["78721.06000000","0.04018000"],["78724.43000000","0.02161000"],["78724.44000000","0.07426000"],["78724.61000000","0.16129000"],["78724.83000000","0.41711000"],["78767.30000000","0.00400000"]]}}
{"rx_ns": 52652347000, "frame": {"e":"depthUpdate","E":1787603110114,"s":"BTCUSDT","U":99076650227,"u":99076650306,"b":[["78717.26000000","5.47057000"],["78717.23000000","0.31783000"],["78717.22000000","0.20352000"],["78712.71000000","0.00254000"],["78711.37000000","0.00800000"],["78705.15000000","0.00007000"],["78676.27000000","0.02541000"],["78621.30000000","0.00007000"],["78605.56000000","0.00007000"],["78589.82000000","0.00007000"],["78574.08000000","0.00007000"],["78571.02000000","1.52223000"],["78558.34000000","0.00007000"],["78542.60000000","0.00007000"],["78526.86000000","0.00007000"],["78511.12000000","0.00007000"],["78495.38000000","0.00007000"],["78479.64000000","0.00133000"],["78323.67000000","0.01000000"],["78008.29000000","0.00000000"],["77932.05000000","0.01000000"],["77542.39000000","0.01000000"],["77154.68000000","0.01000000"],["76768.90000000","0.01000000"],["76385.06000000","0.01000000"],["76003.13000000","0.01000000"],["75623.12000000","0.01000000"],["75245.00000000","0.01030000"],["74868.78000000","0.01000000"],["74494.43000000","0.01000000"],["74121.96000000","0.01000000"],["73751.35000000","0.01000000"],["73382.60000000","0.01000000"],["73015.68000000","0.01000000"],["70845.00000000","0.00090000"]],"a":[["78717.27000000","0.06455000"],["78724.63000000","0.00000000"],["78725.15000000","0.00043000"],["78728.18000000","0.00069000"],["78728.45000000","0.00254000"],["78728.78000000","0.00007000"],["78731.48000000","0.00007000"],["78732.50000000","0.00008000"],["78733.02000000","0.02043000"],["78740.37000000","0.00000000"],["78747.22000000","0.34297000"],["78748.24000000","0.00000000"],["78762.96000000","0.00007000"],["78778.70000000","0.00015000"],["78794.44000000","0.00007000"],["78810.18000000","0.00007000"],["78825.92000000","0.00007000"],["78841.66000000","0.00007000"],["78857.40000000","0.00007000"],["78870.15000000","1.52223000"],["78873.14000000","0.00007000"],["78888.88000000","0.00017000"],["78904.62000000","0.00007000"],["78920.36000000","0.00007000"],["78936.10000000","0.00007000"],["78951.84000000","0.00007000"],["79110.86000000","0.01000000"],["79506.42000000","0.01000000"],["79903.95000000","0.01000000"],["80303.47000000","0.01000000"],["80704.98000000","0.01000000"],["81108.51000000","0.01000000"],["81514.05000000","0.01000000"],["81921.62000000","0.01000000"],["82331.23000000","0.01021000"],["82742.89000000","0.01021000"],["83156.60000000","0.01010000"],["83572.38000000","0.01000000"],["83990.25000000","0.01000000"],["84410.20000000","0.01000000"],["84832.25000000","0.01000000"]]}}
{"rx_ns": 52767387900, "frame": {"e":"depthUpdate","E":1787603110214,"s":"BTCUSDT","U":99076650307,"u":99076650318,"b":[["78711.37000000","0.01200000"],["78532.88000000","0.00000000"],["70845.54000000","0.00112000"],["70845.00000000","0.00090000"],["62973.81000000","0.00000000"]],"a":[["78740.03000000","0.00000000"],["78740.89000000","0.00043000"],["78748.76000000","0.00043000"],["78751.74000000","0.02515000"]]}}
{"rx_ns": 52884328800, "frame": {"e":"depthUpdate","E":1787603110314,"s":"BTCUSDT","U":99076650319,"u":99076650343,"b":[["78717.26000000","5.25183000"],["78716.02000000","0.05498000"],["78711.37000000","0.01600000"],["70845.54000000","0.00144000"],["70845.00000000","0.00100000"],["62974.00000000","0.00000000"],["62973.81000000","0.00000000"]],"a":[["78717.27000000","0.06469000"],["78719.82000000","0.05395000"],["78721.78000000","0.19189000"],["78927.52000000","0.00000000"],["78943.16000000","0.01990000"],["78951.32000000","0.00000000"]]}}
{"rx_ns": 52953308300, "frame": {"e":"depthUpdate","E":1787603110414,"s":"BTCUSDT","U":99076650344,"u":99076650363,"b":[["78717.26000000","5.25583000"],["70845.00000000","0.00080000"]],"a":[["78717.27000000","0.05437000"],["78721.21000000","0.04045000"],["78721.78000000","0.19196000"],["78722.79000000","0.02286000"],["78748.58000000","0.01270000"],["78843.41000000","0.00000000"]]}}
{"rx_ns": 53054142700, "frame": {"e":"depthUpdate","E":1787603110514,"s":"BTCUSDT","U":99076650364,"u":99076650374,"b":[["78717.26000000","5.48609000"],["78683.18000000","0.02465000"],["78679.09000000","0.00000000"],["78540.77000000","4.45109000"],["70845.54000000","0.00160000"],["70845.00000000","0.00090000"],["62973.81000000","0.00031000"]],"a":[["78931.75000000","0.00000000"]]}}
{"rx_ns": 53157446800, "frame": {"e":"depthUpdate","E":1787603110614,"s":"BTCUSDT","U":99076650375,"u":99076650420,"b":[["78717.26000000","5.48616000"],["78715.82000000","0.00400000"],["78641.35000000","0.02116000"],["78323.67000000","0.00000000"],["77932.05000000","0.00000000"],["77542.39000000","0.00000000"],["77154.68000000","0.00000000"],["76768.90000000","0.00000000"],["76385.06000000","0.00000000"],["76003.13000000","0.00000000"],["75623.12000000","0.00000000"],["75245.00000000","0.00030000"],["74868.78000000","0.00000000"],["74494.43000000","0.00000000"],["74121.96000000","0.00000000"],["73751.35000000","0.00000000"],["73382.60000000","0.00000000"],["73015.68000000","0.00000000"],["70845.54000000","0.00160000"],["70845.00000000","0.00090000"],["62973.81000000","0.00000000"]],"a":[["78717.27000000","0.42073000"],["78717.28000000","0.02109000"],["78717.29000000","0.00013000"],["78730.00000000","0.02800000"],["78848.62000000","0.02037000"],["79110.86000000","0.00000000"],["79506.42000000","0.00000000"],["79903.95000000","0.00000000"],["80303.47000000","0.00000000"],["80704.98000000","0.00000000"],["81108.51000000","0.00000000"],["81514.05000000","0.00000000"],["81921.62000000","0.00000000"],["82331.23000000","0.00021000"],["82742.89000000","0.00021000"],["83156.60000000","0.00010000"],["83572.38000000","0.00000000"],["83990.25000000","0.00000000"],["84410.20000000","0.00000000"],["84832.25000000","0.00000000"]]}}
{"rx_ns": 53264222800, "frame": {"e":"depthUpdate","E":1787603110715,"s":"BTCUSDT","U":99076650421,"u":99076650430,"b":[["78687.41000000","0.02448000"],["78683.18000000","0.00000000"],["78641.35000000","0.00000000"],["70845.54000000","0.00160000"],["70845.00000000","0.00080000"]],"a":[["78717.27000000","0.05457000"],["78729.99000000","0.00000000"],["78730.51000000","0.31762000"],["78730.71000000","0.00007000"]]}}
{"rx_ns": 53362256400, "frame": {"e":"depthUpdate","E":1787603110816,"s":"BTCUSDT","U":99076650431,"u":99076650435,"b":[["78693.60000000","0.00007000"],["74371.84000000","0.00032000"],["70845.54000000","0.00176000"]],"a":[["78740.84000000","0.00007000"]]}}
{"rx_ns": 53470026500, "frame": {"e":"depthUpdate","E":1787603110916,"s":"BTCUSDT","U":99076650436,"u":99076650444,"b":[["78687.41000000","0.00000000"],["78682.09000000","0.02458000"],["78641.35000000","0.02116000"],["78539.06000000","0.00778000"],["78534.01000000","0.00000000"],["70845.54000000","0.00192000"]],"a":[["78785.14000000","0.00000000"],["78795.97000000","0.04764000"]]}}
{"rx_ns": 53555076400, "frame": {"e":"depthUpdate","E":1787603111014,"s":"BTCUSDT","U":99076650445,"u":99076650446,"b":[["70845.54000000","0.00176000"],["62973.81000000","0.00031000"]],"a":[]}}
{"rx_ns": 53652324900, "frame": {"e":"depthUpdate","E":1787603111114,"s":"BTCUSDT","U":99076650447,"u":99076650496,"b":[["78717.22000000","0.20372000"],["78712.71000000","0.00000000"],["78590.49000000","0.00000000"],["78323.67000000","0.01000000"],["78008.80000000","0.00010000"],["77932.05000000","0.01000000"],["77542.39000000","0.01000000"],["77159.26000000","0.00000000"],["77154.68000000","0.01000000"],["76768.90000000","0.01000000"],["76385.06000000","0.01000000"],["76003.13000000","0.01000000"],["75623.12000000","0.01000000"],["75245.00000000","0.01030000"],["74868.78000000","0.01000000"],["74494.43000000","0.01000000"],["74121.96000000","0.01000000"],["73751.35000000","0.01000000"],["73382.60000000","0.01000000"],["73015.68000000","0.01000000"],["70845.54000000","0.00208000"]],"a":[["78717.27000000","0.05467000"],["78719.01000000","0.00000000"],["78719.03000000","0.00014000"],["78726.61000000","0.00000000"],["78728.05000000","0.00000000"],["78728.45000000","0.00000000"],["78728.60000000","0.00508000"],["78730.51000000","0.00000000"],["78731.99000000","0.31761000"],["78755.05000000","0.00000000"],["78814.35000000","0.00330000"],["78814.87000000","0.00025000"],["79110.86000000","0.01000000"],["79506.42000000","0.01000000"],["79903.95000000","0.01000000"],["80303.47000000","0.01000000"],["80704.98000000","0.01000000"],["81108.51000000","0.01000000"],["81514.05000000","0.01000000"],["81921.62000000","0.01000000"],["82331.23000000","0.01021000"],["82742.89000000","0.01021000"],["83156.60000000","0.01010000"],["83572.38000000","0.01000000"],["83990.25000000","0.01000000"],["84410.20000000","0.01000000"],["84832.25000000","0.01000000"]]}}
{"rx_ns": 53752530900, "frame": {"e":"depthUpdate","E":1787603111214,"s":"BTCUSDT","U":99076650497,"u":99076650524,"b":[["78716.74000000","0.39358000"],["78714.79000000","0.00000000"],["78641.35000000","0.00000000"],["78598.97000000","0.04473000"],["77156.92000000","0.00191000"],["70845.54000000","0.00208000"],["62973.81000000","0.00000000"]],"a":[["78717.27000000","0.05460000"],["78717.28000000","0.02102000"],["78718.54000000","0.03349000"],["78719.02000000","0.00000000"],["78719.03000000","0.00007000"],["78719.64000000","0.00204000"],["78719.65000000","0.20799000"],["78721.05000000","0.00007000"],["78722.79000000","0.02293000"],["78730.52000000","0.27729000"],["78730.71000000","0.31768000"],["78731.99000000","0.00000000"]]}}
{"rx_ns": 53852901000, "frame": {"e":"depthUpdate","E":1787603111314,"s":"BTCUSDT","U":99076650525,"u":99076650547,"b":[["78713.22000000","0.00254000"],["77002.60000000","0.00058000"],["70845.54000000","0.00208000"],["62973.81000000","0.00000000"],["62973.00000000","0.01646000"]],"a":[["78717.27000000","0.05481000"],["78717.28000000","0.02116000"],["78718.54000000","0.03349000"],["78719.64000000","0.00218000"],["78719.65000000","0.20806000"],["78721.05000000","0.00000000"],["78722.79000000","0.02286000"],["78728.96000000","0.00254000"]]}}
{"rx_ns": 53953271600, "frame": {"e":"depthUpdate","E":1787603111414,"s":"BTCUSDT","U":99076650548,"u":99076650554,"b":[["78641.35000000","0.02116000"],["76848.59000000","0.00067000"],["76694.89000000","0.00077000"],["76541.50000000","0.00030000"],["70845.54000000","0.00224000"],["70845.00000000","0.00080000"]],"a":[]}}
{"rx_ns": 54053843800, "frame": {"e":"depthUpdate","E":1787603111514,"s":"BTCUSDT","U":99076650555,"u":99076650560,"b":[["78641.35000000","0.00000000"],["78540.78000000","0.00778000"],["78539.06000000","0.00000000"],["70845.54000000","0.00240000"],["62973.81000000","0.00031000"]],"a":[]}}
{"rx_ns": 54152610800, "frame": {"e":"depthUpdate","E":1787603111614,"s":"BTCUSDT","U":99076650561,"u":99076650597,"b":[["78717.26000000","5.48660000"],["78323.67000000","0.00000000"],["77932.05000000","0.00000000"],["77622.77000000","0.00032000"],["77542.39000000","0.00000000"],["77154.68000000","0.00000000"],["76768.90000000","0.00000000"],["76385.06000000","0.00000000"],["76003.13000000","0.00000000"],["75709.99000000","0.09990000"],["75623.12000000","0.00000000"],["75245.00000000","0.00030000"],["74868.78000000","0.00000000"],["74494.43000000","0.00000000"],["74121.96000000","0.00000000"],["73751.35000000","0.00000000"],["73382.60000000","0.00000000"],["73015.68000000","0.00000000"],["70845.54000000","0.00240000"],["62973.81000000","0.00000000"]],"a":[["78755.12000000","0.02786000"],["79110.86000000","0.00000000"],["79506.42000000","0.00000000"],["79903.95000000","0.00000000"],["80303.47000000","0.00000000"],["80704.98000000","0.00000000"],["81108.51000000","0.00000000"],["81514.05000000","0.00000000"],["81921.62000000","0.00000000"],["82331.23000000","0.00021000"],["82742.89000000","0.00021000"],["83156.60000000","0.00010000"],["83572.38000000","0.00000000"],["83990.25000000","0.00000000"],["84410.20000000","0.00000000"],["84832.25000000","0.00000000"]]}}
{"rx_ns": 54259302200, "frame": {"e":"depthUpdate","E":1787603111714,"s":"BTCUSDT","U":99076650598,"u":99076650643,"b":[["78717.26000000","5.21613000"],["78717.25000000","1.90556000"],["78715.82000000","0.00000000"],["78714.94000000","0.00400000"],["78714.59000000","0.00635000"],["78714.58000000","0.00000000"],["78713.64000000","0.00400000"],["78713.51000000","0.00635000"],["78713.22000000","0.00000000"],["78700.13000000","0.00000000"],["78698.29000000","0.63523000"],["78618.43000000","2.77181000"],["78607.99000000","0.00000000"],["70845.54000000","0.00256000"]],"a":[["78717.27000000","0.56243000"],["78717.28000000","0.02116000"],["78719.67000000","0.00014000"],["78719.82000000","0.05402000"],["78719.98000000","0.00027000"],["78720.32000000","0.19473000"],["78721.78000000","0.00007000"],["78725.11000000","0.21937000"],["78725.52000000","0.00000000"],["78725.56000000","0.00000000"],["78726.61000000","0.00508000"],["78728.60000000","0.00000000"],["78728.96000000","0.00000000"],["78729.04000000","0.31761000"],["78730.51000000","0.00635000"],["78730.71000000","0.00007000"],["78734.39000000","0.00000000"],["78761.29000000","1.25710000"],["78907.21000000","0.00000000"]]}}
{"rx_ns": 54355622500, "frame": {"e":"depthUpdate","E":1787603111814,"s":"BTCUSDT","U":99076650644,"u":99076650683,"b":[["78717.26000000","5.21627000"],["78717.25000000","1.90570000"],["78713.51000000","0.00000000"],["78712.31000000","0.00635000"],["78711.70000000","0.03864000"],["78710.00000000","0.02400000"],["78709.05000000","0.02600000"],["78708.27000000","0.02800000"],["78708.26000000","0.02800000"],["78693.60000000","0.00007000"],["73532.21000000","0.00033000"],["70845.54000000","0.00272000"]],"a":[["78717.27000000","0.56320000"],["78717.28000000","0.02116000"],["78719.43000000","0.00014000"],["78719.44000000","0.19049000"],["78719.81000000","0.00000000"],["78719.82000000","0.05395000"],["78720.32000000","0.00007000"],["78721.21000000","0.04045000"],["78721.78000000","0.00000000"],["78727.12000000","0.00137000"],["78727.43000000","0.02254000"],["78730.57000000","0.00000000"],["78740.84000000","0.00007000"]]}}
{"rx_ns": 54452221100, "frame": {"e":"depthUpdate","E":1787603111914,"s":"BTCUSDT","U":99076650684,"u":99076650741,"b":[["78711.70000000","0.03610000"],["78710.70000000","0.04254000"],["78700.97000000","0.00000000"],["78700.12000000","0.00000000"],["78700.00000000","0.11937000"],["78641.35000000","0.02116000"],["78598.97000000","0.00000000"],["70845.54000000","0.00272000"]],"a":[["78717.27000000","0.54379000"],["78717.28000000","0.02102000"],["78717.37000000","0.00014000"],["78717.38000000","0.18622000"],["78717.51000000","0.00000000"],["78718.54000000","0.03349000"],["78719.43000000","0.00000000"],["78719.44000000","0.00007000"],["78719.64000000","0.00000000"],["78719.65000000","0.00007000"],["78719.79000000","0.00014000"],["78719.81000000","0.00007000"],["78719.82000000","0.05388000"],["78720.32000000","0.00000000"],["78724.61000000","0.16136000"],["78724.74000000","0.01270000"],["78724.78000000","0.06350000"],["78725.29000000","0.00000000"],["78726.44000000","0.00254000"],["78727.43000000","0.02000000"],["78732.98000000","0.00000000"],["78733.02000000","0.02043000"],["78758.37000000","0.00000000"],["78764.95000000","0.00400000"],["78767.30000000","0.00000000"]]}}
{"rx_ns": 54559571100, "frame": {"e":"depthUpdate","E":1787603112014,"s":"BTCUSDT","U":99076650742,"u":99076650760,"b":[["78641.35000000","0.00000000"],["78590.22000000","0.04092000"],["70845.54000000","0.00288000"],["62973.81000000","0.00031000"]],"a":[["78717.27000000","0.54365000"],["78717.28000000","0.02102000"],["78717.38000000","0.18629000"],["78718.54000000","0.03349000"],["78719.44000000","0.00000000"],["78719.65000000","0.00000000"],["78722.79000000","0.02293000"],["78726.61000000","0.00000000"],["78727.11000000","0.00508000"],["78727.12000000","0.00000000"],["78728.31000000","0.00137000"]]}}
{"rx_ns": 54655588800, "frame": {"e":"depthUpdate","E":1787603112114,"s":"BTCUSDT","U":99076650761,"u":99076650771,"b":[["78717.26000000","5.21662000"],["78717.25000000","1.90577000"],["70845.54000000","0.00288000"]],"a":[["78729.04000000","0.00000000"],["78729.59000000","0.31762000"],["78733.02000000","0.02043000"]]}}
{"rx_ns": 54754280400, "frame": {"e":"depthUpdate","E":1787603112214,"s":"BTCUSDT","U":99076650772,"u":99076650831,"b":[["78717.26000000","4.81662000"],["78717.25000000","1.90577000"],["78716.75000000","0.00021000"],["78716.74000000","0.33358000"],["78716.03000000","0.00007000"],["78323.67000000","0.01000000"],["77932.05000000","0.01000000"],["77542.39000000","0.01000000"],["77154.68000000","0.01000000"],["76768.90000000","0.01000000"],["76385.06000000","0.01000000"],["76003.13000000","0.01000000"],["75623.12000000","0.01000000"],["75245.00000000","0.01030000"],["74868.78000000","0.01000000"],["74494.43000000","0.01000000"],["74121.96000000","0.01000000"],["73751.35000000","0.01000000"],["73382.60000000","0.01000000"],["73015.68000000","0.01000000"],["70845.54000000","0.00304000"],["62973.81000000","0.00000000"]],"a":[["78717.27000000","0.91199000"],["78726.22000000","0.00254000"],["78727.11000000","0.00254000"],["78728.60000000","0.31762000"],["78729.59000000","0.00000000"],["79110.86000000","0.01000000"],["79506.42000000","0.01000000"],["79903.95000000","0.01000000"],["80303.47000000","0.01000000"],["80704.98000000","0.01000000"],["81108.51000000","0.01000000"],["81514.05000000","0.01000000"],["81921.62000000","0.01000000"],["82331.23000000","0.01021000"],["82742.89000000","0.01021000"],["83156.60000000","0.01010000"],["83572.38000000","0.01000000"],["83990.25000000","0.01000000"],["84410.20000000","0.01000000"],["84832.25000000","0.01000000"]]}}
{"rx_ns": 54853727100, "frame": {"e":"depthUpdate","E":1787603112314,"s":"BTCUSDT","U":99076650832,"u":99076650863,"b":[["78717.26000000","4.81655000"],["78717.25000000","1.90584000"],["78717.22000000","0.20372000"],["78716.75000000","0.00014000"],["78716.74000000","0.33351000"],["78716.73000000","0.36231000"],["78716.04000000","0.00000000"],["78716.03000000","0.00000000"],["78716.01000000","1.21959000"],["62974.00000000","0.00000000"],["62973.81000000","0.00000000"]],"a":[["78717.27000000","0.54405000"],["78726.51000000","0.00069000"],["78728.18000000","0.00000000"]]}}
{"rx_ns": 54954221100, "frame": {"e":"depthUpdate","E":1787603112414,"s":"BTCUSDT","U":99076650864,"u":99076650892,"b":[["78717.26000000","4.81620000"],["78717.25000000","1.90570000"],["72419.85000000","0.00014000"],["70845.54000000","0.00320000"]],"a":[["78733.02000000","0.02043000"],["78764.46000000","0.00400000"],["78764.95000000","0.00000000"]]}}
{"rx_ns": 55059420600, "frame": {"e":"depthUpdate","E":1787603112514,"s":"BTCUSDT","U":99076650893,"u":99076650903,"b":[["78717.26000000","5.08428000"],["78641.35000000","0.00000000"],["70845.54000000","0.00320000"],["70845.00000000","0.00080000"],["62973.81000000","0.00031000"]],"a":[["78762.19000000","0.00400000"],["78764.46000000","0.00000000"]]}}
{"rx_ns": 55156371400, "frame": {"e":"depthUpdate","E":1787603112614,"s":"BTCUSDT","U":99076650904,"u":99076650911,"b":[["78540.78000000","0.00000000"],["78534.01000000","0.00778000"],["70845.54000000","0.00320000"],["62973.81000000","0.00000000"]],"a":[["78728.60000000","0.00000000"],["78729.59000000","0.31762000"],["78751.00000000","0.70000000"],["78752.00000000","0.02400000"],["78812.84000000","0.00529000"]]}}
{"rx_ns": 55252863200, "frame": {"e":"depthUpdate","E":1787603112714,"s":"BTCUSDT","U":99076650912,"u":99076650959,"b":[["78717.26000000","5.08407000"],["78717.25000000","1.90549000"],["78323.67000000","0.00000000"],["77932.05000000","0.00000000"],["77542.39000000","0.00000000"],["77410.94000000","0.00600000"],["77154.68000000","0.00000000"],["76768.90000000","0.00000000"],["76385.06000000","0.00000000"],["76003.13000000","0.00000000"],["75623.12000000","0.00000000"],["75245.00000000","0.00030000"],["74868.78000000","0.00000000"],["74494.43000000","0.00000000"],["74121.96000000","0.00000000"],["73751.35000000","0.00000000"],["73382.60000000","0.00000000"],["73015.68000000","0.00000000"],["70845.54000000","0.00336000"]],"a":[["78717.27000000","0.49901000"],["78717.37000000","0.00000000"],["78717.38000000","0.00007000"],["78719.81000000","0.00014000"],["78719.98000000","0.00000000"],["78721.05000000","0.00007000"],["78726.22000000","0.00000000"],["78727.10000000","0.00254000"],["79110.86000000","0.00000000"],["79506.42000000","0.00000000"],["79903.95000000","0.00000000"],["80303.47000000","0.00000000"],["80704.98000000","0.00000000"],["81108.51000000","0.00000000"],["81514.05000000","0.00000000"],["81921.62000000","0.00000000"],["82331.23000000","0.00021000"],["82742.89000000","0.00021000"],["83156.60000000","0.00010000"],["83572.38000000","0.00000000"],["83990.25000000","0.00000000"],["84410.20000000","0.00000000"],["84832.25000000","0.00000000"]]}}
{"rx_ns": 55352306800, "frame": {"e":"depthUpdate","E":1787603112814,"s":"BTCUSDT","U":99076650960,"u":99076650978,"b":[["78689.32000000","0.02600000"],["78688.54000000","0.02800000"],["78688.53000000","0.02800000"],["70845.54000000","0.00352000"]],"a":[["78717.27000000","0.49707000"],["78717.28000000","0.02095000"],["78717.38000000","0.00000000"],["78724.43000000","0.02168000"],["78755.12000000","0.00000000"]]}}
{"rx_ns": 55460788200, "frame": {"e":"depthUpdate","E":1787603112914,"s":"BTCUSDT","U":99076650979,"u":99076651149,"b":[["78717.27000000","5.04915000"],["78717.26000000","2.40110000"],["78717.25000000","0.00027000"],["78717.24000000","0.00014000"],["78717.23000000","0.31929000"],["78717.22000000","0.20365000"],["78716.75000000","0.00014000"],["78716.74000000","0.33351000"],["78716.02000000","0.05491000"],["78714.59000000","0.00000000"],["78710.70000000","0.04000000"],["78705.15000000","0.00000000"],["78693.60000000","0.00007000"],["78618.43000000","0.00000000"],["70845.54000000","0.00000000"]],"a":[["78717.27000000","0.00000000"],["78717.28000000","0.25733000"],["78717.29000000","0.00069000"],["78717.51000000","0.00007000"],["78719.63000000","0.00000000"],["78719.64000000","0.00000000"],["78719.67000000","0.00007000"],["78721.05000000","0.00014000"],["78721.20000000","0.00007000"],["78724.44000000","0.07433000"],["78726.44000000","0.00000000"],["78727.11000000","0.00000000"],["78727.52000000","0.00254000"],["78728.31000000","0.00000000"],["78729.59000000","0.00000000"],["78729.72000000","0.00137000"],["78730.50000000","0.31762000"],["78730.51000000","0.00000000"],["78731.99000000","0.00635000"],["78740.84000000","0.00007000"],["78755.13000000","0.02726000"],["78758.37000000","0.00007000"],["78811.55000000","0.93647000"],["78816.77000000","0.00000000"]]}}
{"rx_ns": 55552585000, "frame": {"e":"depthUpdate","E":1787603113014,"s":"BTCUSDT","U":99076651150,"u":99076651184,"b":[["78717.27000000","5.05327000"],["78717.26000000","2.17329000"],["78717.25000000","0.00020000"],["78711.95000000","0.00254000"],["78700.08000000","0.63523000"],["78698.29000000","0.00000000"],["78640.91000000","0.00000000"],["72419.85000000","0.00000000"],["70845.55000000","0.00032000"],["62973.82000000","0.00031000"]],"a":[["78717.28000000","0.25712000"],["78717.29000000","0.00069000"],["78727.10000000","0.00000000"],["78727.52000000","0.00000000"],["78727.67000000","0.00048000"],["78727.69000000","0.00261000"],["78727.99000000","0.00508000"],["78735.58000000","0.00000000"],["78737.82000000","0.02000000"]]}}
{"rx_ns": 55653090200, "frame": {"e":"depthUpdate","E":1787603113114,"s":"BTCUSDT","U":99076651185,"u":99076651195,"b":[["78717.26000000","1.95399000"],["78714.35000000","0.00000000"],["78714.30000000","0.00000000"],["78691.09000000","0.00000000"],["78667.48000000","0.00000000"],["78641.88000000","0.00000000"],["78008.80000000","0.00000000"],["70845.55000000","0.00048000"]],"a":[["78814.87000000","0.00000000"]]}}
{"rx_ns": 55752107300, "frame": {"e":"depthUpdate","E":1787603113214,"s":"BTCUSDT","U":99076651196,"u":99076651212,"b":[["78717.27000000","5.06686000"],["78716.02000000","0.06126000"],["78712.31000000","0.00000000"],["78641.03000000","0.00000000"],["70845.55000000","0.00080000"],["62973.82000000","0.00000000"]],"a":[["78717.28000000","0.25748000"],["78725.15000000","0.00000000"],["78725.16000000","0.00034000"],["78733.02000000","0.02000000"],["78733.03000000","0.02034000"],["78740.89000000","0.00000000"],["78740.90000000","0.00034000"],["78748.76000000","0.00000000"],["78748.77000000","0.00034000"],["78814.88000000","0.00025000"]]}}
{"rx_ns": 55854309300, "frame": {"e":"depthUpdate","E":1787603113315,"s":"BTCUSDT","U":99076651213,"u":99076651257,"b":[["78694.00000000","0.72415000"],["78682.00000000","0.02400000"],["78323.68000000","0.01000000"],["77932.06000000","0.01000000"],["77542.40000000","0.01000000"],["77154.69000000","0.01000000"],["76768.91000000","0.01000000"],["76385.07000000","0.01000000"],["76003.14000000","0.01000000"],["75623.13000000","0.01000000"],["75245.01000000","0.01000000"],["74868.79000000","0.01000000"],["74494.44000000","0.01000000"],["74121.97000000","0.01000000"],["73751.36000000","0.01000000"],["73382.61000000","0.01000000"],["73015.69000000","0.01000000"],["70845.55000000","0.00096000"],["62974.00000000","0.00000000"],["62973.82000000","0.00000000"]],"a":[["78717.28000000","0.25755000"],["78719.82000000","0.05395000"],["78723.41000000","0.17738000"],["78727.99000000","0.00000000"],["78728.31000000","0.00508000"],["78736.17000000","0.00000000"],["79110.87000000","0.01000000"],["79506.43000000","0.01000000"],["79903.96000000","0.01000000"],["80303.48000000","0.01000000"],["80704.99000000","0.01000000"],["81108.52000000","0.01000000"],["81514.06000000","0.01000000"],["81921.63000000","0.01000000"],["82331.24000000","0.01000000"],["82742.90000000","0.01053000"],["83156.61000000","0.01000000"],["83572.39000000","0.01000000"],["83990.26000000","0.01000000"],["84410.21000000","0.01000000"],["84832.26000000","0.01000000"]]}}
{"rx_ns": 55953025200, "frame": {"e":"depthUpdate","E":1787603113414,"s":"BTCUSDT","U":99076651258,"u":99076651263,"b":[["72702.06000000","0.00033000"],["70845.55000000","0.00112000"]],"a":[["78722.79000000","0.02293000"],["78723.41000000","0.17745000"],["78724.44000000","0.07426000"]]}}
{"rx_ns": 56055832700, "frame": {"e":"depthUpdate","E":1787603113514,"s":"BTCUSDT","U":99076651264,"u":99076651279,"b":[["78717.27000000","4.66686000"],["78695.71000000","0.49900000"],["78672.09000000","1.04020000"],["78641.35000000","0.02116000"],["70845.55000000","0.00144000"],["62973.82000000","0.00031000"]],"a":[["78717.28000000","0.25762000"],["78717.29000000","0.00076000"],["78719.82000000","0.05402000"],["78721.52000000","0.22873000"],["78723.41000000","0.00007000"]]}}
{"rx_ns": 56154705000, "frame": {"e":"depthUpdate","E":1787603113614,"s":"BTCUSDT","U":99076651280,"u":99076651288,"b":[["78641.35000000","0.00000000"],["62973.82000000","0.00000000"]],"a":[["78719.82000000","0.05395000"],["78721.21000000","0.04045000"],["78721.52000000","0.22880000"],["78722.79000000","0.02293000"],["78723.41000000","0.00000000"]]}}
{"rx_ns": 56255466800, "frame": {"e":"depthUpdate","E":1787603113714,"s":"BTCUSDT","U":99076651289,"u":99076651301,"b":[["70845.55000000","0.00160000"],["70845.00000000","0.00080000"]],"a":[["78717.28000000","0.25767000"],["78725.16000000","0.00039000"],["78733.03000000","0.02039000"],["78740.90000000","0.00000000"],["78748.77000000","0.00000000"]]}}
{"rx_ns": 56353347900, "frame": {"e":"depthUpdate","E":1787603113815,"s":"BTCUSDT","U":99076651302,"u":99076651336,"b":[["78323.68000000","0.00000000"],["77932.06000000","0.00000000"],["77542.40000000","0.00000000"],["77154.69000000","0.00000000"],["76768.91000000","0.00000000"],["76385.07000000","0.00000000"],["76003.14000000","0.00000000"],["75623.13000000","0.00000000"],["75245.01000000","0.00000000"],["74868.79000000","0.00000000"],["74494.44000000","0.00000000"],["74121.97000000","0.00000000"],["73751.36000000","0.00000000"],["73382.61000000","0.00000000"],["73015.69000000","0.00000000"],["70845.55000000","0.00160000"]],"a":[["78717.28000000","0.25759000"],["78740.90000000","0.00039000"],["78748.77000000","0.00039000"],["79110.87000000","0.00000000"],["79506.43000000","0.00000000"],["79903.96000000","0.00000000"],["80303.48000000","0.00000000"],["80704.99000000","0.00000000"],["81108.52000000","0.00000000"],["81514.06000000","0.00000000"],["81921.63000000","0.00000000"],["82331.24000000","0.00000000"],["82742.90000000","0.00053000"],["83156.61000000","0.00000000"],["83572.39000000","0.00000000"],["83990.26000000","0.00000000"],["84410.21000000","0.00000000"],["84832.26000000","0.00000000"]]}}
{"rx_ns": 56452840500, "frame": {"e":"depthUpdate","E":1787603113914,"s":"BTCUSDT","U":99076651337,"u":99076651340,"b":[["78693.61000000","0.00007000"],["78693.60000000","0.00000000"],["70845.55000000","0.00176000"]],"a":[["78740.84000000","0.00000000"],["78740.85000000","0.00007000"]]}}
{"rx_ns": 56552619200, "frame": {"e":"depthUpdate","E":1787603114014,"s":"BTCUSDT","U":99076651341,"u":99076651350,"b":[["78716.02000000","0.05491000"],["78714.58000000","0.00635000"],["78641.35000000","0.02116000"],["78618.43000000","2.77181000"],["70845.55000000","0.00176000"],["62973.82000000","0.00031000"]],"a":[["78727.52000000","0.00508000"],["78728.31000000","0.00000000"],["78729.88000000","0.33761000"],["78730.50000000","0.00000000"],["78811.55000000","0.00000000"]]}}
{"rx_ns": 56652736800, "frame": {"e":"depthUpdate","E":1787603114114,"s":"BTCUSDT","U":99076651351,"u":99076651371,"b":[["78717.27000000","4.66051000"],["78715.48000000","0.00635000"],["78700.08000000","0.00000000"],["78698.29000000","0.63524000"],["78641.35000000","0.00000000"],["78008.81000000","0.00010000"],["70845.55000000","0.00192000"]],"a":[["78717.28000000","0.28645000"],["78717.29000000","0.00076000"],["78717.51000000","0.00000000"],["78719.82000000","0.05402000"],["78720.71000000","0.00007000"],["78720.72000000","0.17291000"],["78721.20000000","0.00000000"],["78721.52000000","0.00007000"]]}}
{"rx_ns": 56752395800, "frame": {"e":"depthUpdate","E":1787603114214,"s":"BTCUSDT","U":99076651372,"u":99076651402,"b":[["78717.27000000","4.42918000"],["78717.26000000","1.95420000"],["78714.58000000","0.00000000"],["78712.97000000","0.00635000"],["70845.55000000","0.00176000"],["62973.82000000","0.00000000"]],"a":[["78717.28000000","0.74954000"],["78719.01000000","0.00007000"],["78719.02000000","0.20799000"],["78719.82000000","0.05395000"],["78720.71000000","0.00000000"],["78720.72000000","0.00007000"],["78721.21000000","0.04045000"],["78721.52000000","0.00000000"],["78726.22000000","0.00508000"],["78727.52000000","0.00000000"],["78728.25000000","0.31762000"],["78729.04000000","0.00000000"],["78729.88000000","0.02000000"]]}}
{"rx_ns": 56853022500, "frame": {"e":"depthUpdate","E":1787603114314,"s":"BTCUSDT","U":99076651403,"u":99076651456,"b":[["78717.27000000","4.35418000"],["78323.68000000","0.01000000"],["77932.06000000","0.01000000"],["77542.40000000","0.01000000"],["77154.69000000","0.01000000"],["76768.91000000","0.01000000"],["76385.07000000","0.01000000"],["76003.14000000","0.01000000"],["75623.13000000","0.01000000"],["75245.01000000","0.01000000"],["74868.79000000","0.01000000"],["74494.44000000","0.01000000"],["74121.97000000","0.01000000"],["73751.36000000","0.01000000"],["73382.61000000","0.01000000"],["73015.69000000","0.01000000"],["70845.55000000","0.00208000"],["62974.00000000","0.00000000"],["62973.82000000","0.00000000"]],"a":[["78717.28000000","0.74976000"],["78717.29000000","0.00076000"],["78718.54000000","0.03349000"],["78719.02000000","0.20806000"],["78719.82000000","0.05388000"],["78720.72000000","0.00000000"],["79110.87000000","0.01000000"],["79506.43000000","0.01000000"],["79903.96000000","0.01000000"],["80303.48000000","0.01000000"],["80704.99000000","0.01000000"],["81108.52000000","0.01000000"],["81514.06000000","0.01000000"],["81921.63000000","0.01000000"],["82331.24000000","0.01000000"],["82742.90000000","0.01053000"],["83156.61000000","0.01000000"],["83572.39000000","0.01000000"],["83990.26000000","0.01000000"],["84410.21000000","0.01000000"],["84832.26000000","0.01000000"]]}}
{"rx_ns": 56955482400, "frame": {"e":"depthUpdate","E":1787603114415,"s":"BTCUSDT","U":99076651457,"u":99076651460,"b":[["70845.55000000","0.00208000"],["70845.00000000","0.00090000"]],"a":[["78717.28000000","0.74987000"]]}}
{"rx_ns": 57052029600, "frame": {"e":"depthUpdate","E":1787603114514,"s":"BTCUSDT","U":99076651461,"u":99076651467,"b":[["70845.55000000","0.00208000"],["70845.00000000","0.00080000"],["65146.32000000","0.00000000"],["62973.82000000","0.00031000"]],"a":[]}}
{"rx_ns": 57152392900, "frame": {"e":"depthUpdate","E":1787603114614,"s":"BTCUSDT","U":99076651468,"u":99076651473,"b":[["78717.27000000","4.62623000"],["78641.35000000","0.02116000"],["71881.28000000","0.00033000"],["70845.55000000","0.00224000"],["62973.82000000","0.00000000"]],"a":[["78717.30000000","0.00013000"]]}}
{"rx_ns": 57252610800, "frame": {"e":"depthUpdate","E":1787603114714,"s":"BTCUSDT","U":99076651474,"u":99076651510,"b":[["78717.27000000","4.62595000"],["78717.26000000","1.95399000"],["78660.34000000","0.00000000"],["78655.23000000","0.00317000"],["78655.22000000","0.00316000"],["78654.02000000","0.00000000"],["78641.35000000","0.00000000"],["70845.55000000","0.00240000"]],"a":[["78717.28000000","0.19226000"],["78717.29000000","0.00069000"],["78719.01000000","0.00000000"],["78719.02000000","0.00007000"],["78719.09000000","0.00000000"],["78721.20000000","0.00007000"],["78726.22000000","0.00000000"],["78727.12000000","0.00508000"],["78728.25000000","0.00000000"],["78729.04000000","0.00000000"],["78729.87000000","0.31762000"],["78785.02000000","0.00320000"],["78790.14000000","0.00000000"]]}}
{"rx_ns": 57352415000, "frame": {"e":"depthUpdate","E":1787603114814,"s":"BTCUSDT","U":99076651511,"u":99076651555,"b":[["78323.68000000","0.00000000"],["77932.06000000","0.00000000"],["77542.40000000","0.00000000"],["77154.69000000","0.00000000"],["76768.91000000","0.00000000"],["76385.07000000","0.00000000"],["76003.14000000","0.00000000"],["75623.13000000","0.00000000"],["75245.01000000","0.00000000"],["74868.79000000","0.00000000"],["74494.44000000","0.00000000"],["74121.97000000","0.00000000"],["73751.36000000","0.00000000"],["73382.61000000","0.00000000"],["73015.69000000","0.00000000"],["70845.55000000","0.00256000"],["70845.00000000","0.00080000"],["65146.32000000","0.01188000"]],"a":[["78717.28000000","0.19219000"],["78718.54000000","0.03349000"],["78719.02000000","0.00000000"],["78719.88000000","0.00007000"],["78724.44000000","0.07433000"],["78814.16000000","0.93647000"],["79110.87000000","0.00000000"],["79506.43000000","0.00000000"],["79903.96000000","0.00000000"],["80303.48000000","0.00000000"],["80704.99000000","0.00000000"],["81108.52000000","0.00000000"],["81514.06000000","0.00000000"],["81921.63000000","0.00000000"],["82331.24000000","0.00000000"],["82742.90000000","0.00053000"],["83156.61000000","0.00000000"],["83572.39000000","0.00000000"],["83990.26000000","0.00000000"],["84410.21000000","0.00000000"],["84832.26000000","0.00000000"]]}}
{"rx_ns": 57455626000, "frame": {"e":"depthUpdate","E":1787603114914,"s":"BTCUSDT","U":99076651556,"u":99076651787,"b":[["78718.53000000","5.08438000"],["78718.52000000","0.00020000"],["78718.51000000","0.00013000"],["78718.01000000","0.00000000"],["78717.64000000","0.00000000"],["78717.49000000","0.00000000"],["78717.29000000","0.00014000"],["78717.28000000","1.24991000"],["78717.27000000","2.25671000"],["78717.26000000","0.03583000"],["78717.25000000","0.00007000"],["78717.24000000","0.00000000"],["78717.23000000","0.00153000"],["78716.75000000","0.00000000"],["78716.74000000","0.33344000"],["78716.02000000","0.05505000"],["78716.00000000","0.49865000"],["78715.48000000","0.00000000"],["78715.00000000","0.00007000"],["78714.35000000","0.00007000"],["78708.50000000","0.08576000"],["78707.54000000","0.00000000"],["78694.87000000","0.00007000"],["78693.61000000","0.00000000"],["78654.76000000","0.00000000"],["78232.00000000","0.00008000"],["70845.55000000","0.00000000"]],"a":[["78717.28000000","0.00000000"],["78717.29000000","0.00000000"],["78717.30000000","0.00000000"],["78717.50000000","0.00000000"],["78717.65000000","0.00000000"],["78718.02000000","0.00000000"],["78718.30000000","0.00000000"],["78718.53000000","0.00000000"],["78718.54000000","0.24504000"],["78718.55000000","0.00056000"],["78719.81000000","0.00000000"],["78719.82000000","0.00007000"],["78721.12000000","0.00014000"],["78721.13000000","0.05388000"],["78721.20000000","0.00014000"],["78722.00000000","0.00000000"],["78722.78000000","0.00007000"],["78723.95000000","0.00000000"],["78723.99000000","0.00000000"],["78724.28000000","0.16586000"],["78724.44000000","0.07419000"],["78724.61000000","0.16136000"],["78724.74000000","0.00000000"],["78724.78000000","0.00000000"],["78725.71000000","0.12709000"],["78727.12000000","0.00000000"],["78728.25000000","0.00254000"],["78728.60000000","0.00254000"],["78729.72000000","0.00000000"],["78729.87000000","0.00000000"],["78731.98000000","0.31898000"],["78733.99000000","0.00000000"],["78734.56000000","0.00000000"],["78735.14000000","0.00635000"],["78735.53000000","0.04857000"],["78740.85000000","0.00000000"],["78742.11000000","0.00007000"],["78743.00000000","0.00007000"],["78755.13000000","0.00000000"],["78757.00000000","0.00000000"],["78758.00000000","0.03400000"],["78765.99000000","0.00000000"],["78767.96000000","0.00316000"],["78769.84000000","0.00000000"]]}}
{"rx_ns": 57552683600, "frame": {"e":"depthUpdate","E":1787603115014,"s":"BTCUSDT","U":99076651788,"u":99076651867,"b":[["78718.53000000","5.08901000"],["78717.28000000","0.99118000"],["78717.27000000","2.23955000"],["78717.26000000","0.03576000"],["78717.23000000","0.00146000"],["78716.75000000","0.00014000"],["78716.74000000","0.33351000"],["78715.47000000","0.00000000"],["78714.22000000","0.00000000"],["78712.96000000","0.00000000"],["78711.70000000","0.00000000"],["78700.50000000","0.63523000"],["78698.29000000","0.00000000"],["78679.00000000","0.01000000"],["78677.00000000","0.00000000"],["70846.68000000","0.00032000"],["66000.00000000","20.03571000"],["62974.83000000","0.00031000"]],"a":[["78718.54000000","0.63627000"],["78718.55000000","0.00056000"],["78719.03000000","0.00000000"],["78719.79000000","0.00000000"],["78719.80000000","0.00007000"],["78719.82000000","0.00000000"],["78721.05000000","0.00000000"],["78721.06000000","0.00007000"],["78721.13000000","0.05395000"],["78722.78000000","0.00014000"],["78722.79000000","0.02293000"],["78724.27000000","0.00014000"],["78724.28000000","0.16593000"],["78724.42000000","0.00007000"],["78724.61000000","0.16129000"],["78725.16000000","0.00000000"],["78726.42000000","0.00039000"],["78726.51000000","0.00000000"],["78727.94000000","0.00070000"],["78730.51000000","0.31761000"],["78731.98000000","0.00137000"],["78733.03000000","0.02000000"],["78734.29000000","0.00039000"],["78740.90000000","0.00000000"],["78742.16000000","0.00039000"],["78748.77000000","0.00000000"],["78750.03000000","1.22022000"],["78932.72000000","0.00007000"],["78936.65000000","0.00000000"]]}}
{"rx_ns": 57653256000, "frame": {"e":"depthUpdate","E":1787603115114,"s":"BTCUSDT","U":99076651868,"u":99076651941,"b":[["78717.53000000","0.00014000"],["78717.52000000","0.01844000"],["78717.28000000","0.39290000"],["78717.27000000","2.02025000"],["78717.23000000","0.00153000"],["78716.74000000","0.33344000"],["78716.26000000","0.03074000"],["78716.02000000","0.05491000"],["78715.00000000","0.03696000"],["78713.74000000","0.03689000"],["78642.64000000","0.02541000"],["78008.81000000","0.00000000"],["70846.68000000","0.00048000"],["70846.00000000","0.00010000"],["70845.07000000","0.00000000"]],"a":[["78718.54000000","0.25095000"],["78718.55000000","0.00063000"],["78718.79000000","0.00014000"],["78718.80000000","0.01966000"],["78719.80000000","0.00000000"],["78720.05000000","0.00014000"],["78720.06000000","0.03276000"],["78721.06000000","0.00000000"],["78721.31000000","0.00007000"],["78721.32000000","0.03932000"],["78722.58000000","0.03932000"],["78722.78000000","0.00000000"],["78724.27000000","0.00000000"],["78724.42000000","0.00000000"],["78724.61000000","0.16136000"],["78724.83000000","0.41718000"],["78728.60000000","0.00000000"],["78728.99000000","0.00254000"],["78730.51000000","0.00000000"],["78731.98000000","0.31898000"],["78744.89000000","0.00000000"],["78746.74000000","0.00406000"],["78784.27000000","0.00000000"],["78786.12000000","0.00406000"],["78814.88000000","0.00000000"],["78815.77000000","0.00000000"],["78816.14000000","0.00025000"],["78817.62000000","0.00406000"],["78863.01000000","0.00000000"],["78864.87000000","0.00406000"],["78933.88000000","0.00000000"],["78935.74000000","0.00406000"]]}}
{"rx_ns": 57757588400, "frame": {"e":"depthUpdate","E":1787603115214,"s":"BTCUSDT","U":99076651942,"u":99076651980,"b":[["78718.53000000","5.11898000"],["78717.52000000","0.01858000"],["78717.26000000","0.03583000"],["78716.73000000","0.36224000"],["78716.02000000","0.05484000"],["78716.01000000","1.21952000"],["78714.38000000","0.00000000"],["70846.68000000","0.00064000"],["70846.00000000","0.00000000"],["62974.83000000","0.00000000"]],"a":[["78718.54000000","0.25102000"],["78718.80000000","0.01973000"],["78720.06000000","0.03283000"],["78721.21000000","0.04045000"],["78721.32000000","0.03939000"],["78722.58000000","0.03939000"],["78724.43000000","0.02161000"],["78724.44000000","0.07412000"],["78724.61000000","0.16129000"],["78724.83000000","0.41711000"],["78728.25000000","0.00000000"],["78728.59000000","0.00254000"],["78730.71000000","0.31768000"],["78731.98000000","0.00137000"],["78746.74000000","0.00000000"],["78746.83000000","0.00406000"],["78787.99000000","0.00000000"],["78789.93000000","0.00325000"],["78865.79000000","0.00000000"],["78867.99000000","0.00127000"],["78935.74000000","0.00000000"],["78935.83000000","0.00406000"]]}}
{"rx_ns": 57851786700, "frame": {"e":"depthUpdate","E":1787603115314,"s":"BTCUSDT","U":99076651981,"u":99076651994,"b":[["78539.06000000","0.00778000"],["78534.01000000","0.00000000"],["70846.68000000","0.00080000"],["62974.00000000","0.00000000"]],"a":[["78718.54000000","0.25123000"],["78718.55000000","0.00084000"],["78719.88000000","0.00000000"],["78721.45000000","0.00007000"],["78746.83000000","0.00000000"],["78746.84000000","0.00406000"]]}}
{"rx_ns": 57952423500, "frame": {"e":"depthUpdate","E":1787603115414,"s":"BTCUSDT","U":99076651995,"u":99076652066,"b":[["78718.53000000","4.82048000"],["78718.52000000","0.00048000"],["78716.27000000","0.00635000"],["78641.35000000","0.02116000"],["78324.93000000","0.01000000"],["77933.31000000","0.01000000"],["77543.64000000","0.01000000"],["77155.92000000","0.01000000"],["76770.14000000","0.01000000"],["76386.29000000","0.01000000"],["76004.36000000","0.01000000"],["75624.34000000","0.01000000"],["75246.22000000","0.01000000"],["74869.99000000","0.01000000"],["74495.64000000","0.01000000"],["74123.16000000","0.01000000"],["73752.54000000","0.01000000"],["73383.78000000","0.01000000"],["73016.86000000","0.01000000"],["70846.68000000","0.00112000"],["70846.00000000","0.00010000"],["62974.82000000","0.00000000"]],"a":[["78718.54000000","0.66486000"],["78718.55000000","0.00084000"],["78721.13000000","0.05402000"],["78722.33000000","0.21092000"],["78724.28000000","0.00007000"],["78726.42000000","0.00000000"],["78727.52000000","0.00254000"],["78727.93000000","0.00254000"],["78728.59000000","0.00000000"],["78728.99000000","0.00000000"],["78729.99000000","0.31761000"],["78730.71000000","0.00007000"],["78731.98000000","0.00137000"],["78734.29000000","0.00000000"],["78742.16000000","0.00000000"],["78755.31000000","0.02847000"],["79112.14000000","0.01000000"],["79507.70000000","0.01000000"],["79905.24000000","0.01000000"],["80304.76000000","0.01000000"],["80706.29000000","0.01000000"],["81109.82000000","0.01000000"],["81515.37000000","0.01000000"],["81922.94000000","0.01111000"],["82332.56000000","0.01000000"],["82744.22000000","0.01000000"],["83157.94000000","0.01000000"],["83573.73000000","0.01000000"],["83991.60000000","0.01000000"],["84411.56000000","0.01000000"],["84833.62000000","0.01000000"]]}}
{"rx_ns": 58055600000, "frame": {"e":"depthUpdate","E":1787603115516,"s":"BTCUSDT","U":99076652067,"u":99076652122,"b":[["78718.53000000","4.82055000"],["78718.52000000","0.00055000"],["78700.50000000","0.00000000"],["78698.29000000","0.63524000"],["70846.00000000","0.00010000"],["62974.83000000","0.00031000"]],"a":[["78718.54000000","0.72733000"],["78720.79000000","0.00007000"],["78720.80000000","0.20974000"],["78721.13000000","0.05395000"],["78721.31000000","0.00000000"],["78721.32000000","0.03939000"],["78722.33000000","0.00007000"],["78722.79000000","0.02293000"],["78724.28000000","0.00000000"],["78726.42000000","0.00031000"],["78727.94000000","0.00000000"],["78734.29000000","0.00031000"],["78742.16000000","0.00031000"],["78750.03000000","1.22014000"]]}}
{"rx_ns": 58154040900, "frame": {"e":"depthUpdate","E":1787603115614,"s":"BTCUSDT","U":99076652123,"u":99076652140,"b":[["78718.53000000","5.01133000"],["78641.35000000","0.00000000"],["70846.68000000","0.00144000"],["70846.00000000","0.00010000"],["62974.83000000","0.00000000"]],"a":[["78720.06000000","0.03283000"],["78720.80000000","0.20981000"],["78721.13000000","0.05388000"],["78721.32000000","0.03939000"],["78722.33000000","0.00000000"]]}}
{"rx_ns": 58252355900, "frame": {"e":"depthUpdate","E":1787603115714,"s":"BTCUSDT","U":99076652141,"u":99076652146,"b":[["78666.91000000","0.04764000"],["78658.23000000","0.00427000"],["70846.68000000","0.00144000"],["70846.00000000","0.00000000"]],"a":[["78718.54000000","0.72744000"]]}}
{"rx_ns": 58354676900, "frame": {"e":"depthUpdate","E":1787603115814,"s":"BTCUSDT","U":99076652147,"u":99076652150,"b":[["78641.35000000","0.02116000"],["70846.68000000","0.00160000"]],"a":[["78720.66000000","0.00007000"],["78721.45000000","0.00000000"]]}}
{"rx_ns": 58457670300, "frame": {"e":"depthUpdate","E":1787603115915,"s":"BTCUSDT","U":99076652151,"u":99076652186,"b":[["78718.53000000","4.75405000"],["78694.87000000","0.00000000"],["78324.93000000","0.00000000"],["77933.31000000","0.00000000"],["77543.64000000","0.00000000"],["77155.92000000","0.00000000"],["76770.14000000","0.00000000"],["76386.29000000","0.00000000"],["76004.36000000","0.00000000"],["75624.34000000","0.00000000"],["75246.22000000","0.00000000"],["74869.99000000","0.00000000"],["74495.64000000","0.00000000"],["74123.16000000","0.00000000"],["73752.54000000","0.00000000"],["73383.78000000","0.00000000"],["73016.86000000","0.00000000"],["70846.68000000","0.00160000"],["70846.00000000","0.00000000"]],"a":[["78742.11000000","0.00000000"],["79112.14000000","0.00000000"],["79507.70000000","0.00000000"],["79905.24000000","0.00000000"],["80304.76000000","0.00000000"],["80706.29000000","0.00000000"],["81109.82000000","0.00000000"],["81515.37000000","0.00000000"],["81922.94000000","0.00111000"],["82332.56000000","0.00000000"],["82744.22000000","0.00000000"],["83157.94000000","0.00000000"],["83573.73000000","0.00000000"],["83991.60000000","0.00000000"],["84411.56000000","0.00000000"],["84833.62000000","0.00000000"]]}}
{"rx_ns": 58555046200, "frame": {"e":"depthUpdate","E":1787603116014,"s":"BTCUSDT","U":99076652187,"u":99076652200,"b":[["78694.87000000","0.00007000"],["78641.35000000","0.00000000"],["78540.77000000","0.00000000"],["70846.68000000","0.00176000"],["62974.83000000","0.00031000"]],"a":[["78718.54000000","0.72744000"],["78718.55000000","0.00084000"],["78742.11000000","0.00007000"],["78811.55000000","0.93647000"],["78814.16000000","0.00000000"]]}}
{"rx_ns": 58655407100, "frame": {"e":"depthUpdate","E":1787603116114,"s":"BTCUSDT","U":99076652201,"u":99076652205,"b":[["78718.53000000","4.75416000"],["78010.06000000","0.00010000"],["70846.68000000","0.00160000"]],"a":[["78718.54000000","0.72765000"]]}}
