{"rx_ns": 13887800933900, "frame": {"stream":"btcusdt@depth20","data":{"lastUpdateId":99118608365,"bids":[["79913.99000000","6.74785000"],["79913.98000000","2.20392000"],["79913.97000000","0.00013000"],["79913.85000000","0.81939000"],["79913.84000000","2.31206000"],["79913.01000000","0.07500000"],["79913.00000000","1.57128000"],["79912.80000000","0.00021000"],["79912.75000000","0.00028000"],["79912.70000000","0.05000000"],["79912.65000000","0.05000000"],["79912.41000000","0.00400000"],["79912.05000000","0.01600000"],["79912.04000000","0.20652000"],["79911.63000000","0.00014000"],["79911.62000000","1.21963000"],["79911.43000000","0.00021000"],["79911.42000000","0.00007000"],["79911.41000000","0.20271000"],["79911.39000000","0.05337000"]],"asks":[["79914.00000000","0.02514000"],["79914.01000000","0.00042000"],["79914.03000000","0.00007000"],["79914.77000000","0.00021000"],["79915.50000000","0.00007000"],["79915.76000000","0.00007000"],["79915.98000000","0.00007000"],["79915.99000000","0.00021000"],["79916.00000000","0.02435000"],["79916.05000000","0.00021000"],["79916.20000000","0.00007000"],["79916.36000000","0.00007000"],["79916.98000000","0.04675000"],["79917.33000000","0.00028000"],["79917.39000000","0.00007000"],["79917.71000000","0.00010000"],["79917.96000000","0.00007000"],["79917.99000000","0.00007000"],["79918.00000000","0.02428000"],["79918.36000000","0.00007000"]]}}}
{"rx_ns": 13887801082500, "frame": {"stream":"btcusdt@depth@100ms","data":{"e":"depthUpdate","E":1787650883014,"s":"BTCUSDT","U":99118607625,"u":99118608365,"b":[["79913.99000000","6.74785000"],["79913.98000000","2.20392000"],["79913.97000000","0.00013000"],["79913.85000000","0.81939000"],["79913.84000000","2.31206000"],["79913.83000000","0.00000000"],["79913.82000000","0.00000000"],["79913.77000000","0.00000000"],["79913.76000000","0.00000000"],["79913.49000000","0.00000000"],["79913.22000000","0.00000000"],["79913.01000000","0.07500000"],["79913.00000000","1.57128000"],["79912.99000000","0.00000000"],["79912.98000000","0.00000000"],["79912.81000000","0.00000000"],["79912.80000000","0.00021000"],["79912.76000000","0.00000000"],["79912.75000000","0.00028000"],["79912.70000000","0.05000000"],["79912.66000000","0.00000000"],["79912.65000000","0.05000000"],["79912.41000000","0.00400000"],["79912.06000000","0.00000000"],["79912.05000000","0.01600000"],["79912.04000000","0.20652000"],["79911.63000000","0.00014000"],["79911.62000000","1.21963000"],["79911.44000000","0.00000000"],["79911.43000000","0.00021000"],["79911.42000000","0.00007000"],["79911.41000000","0.20271000"],["79911.39000000","0.05337000"],["79910.82000000","0.36586000"],["79910.81000000","0.07500000"],["79910.80000000","0.57326000"],["79910.75000000","0.00000000"],["79910.68000000","0.00000000"],["79910.66000000","0.00250000"],["79910.50000000","0.07909000"],["79910.41000000","0.03364000"],["79910.40000000","0.00000000"],["79910.35000000","0.02252000"],["79910.18000000","0.02486000"],["79909.52000000","0.00014000"],["79908.97000000","0.00007000"],["79908.94000000","0.00007000"],["79908.44000000","0.00007000"],["79908.34000000","0.00000000"],["79908.24000000","0.00000000"],["79906.96000000","0.00007000"],["79906.44000000","0.00711000"],["79905.89000000","0.00007000"],["79905.82000000","0.00708000"],["79905.70000000","1.10500000"],["79905.67000000","0.00000000"],["79905.29000000","0.08576000"],["79904.77000000","0.00000000"],["79904.31000000","0.00000000"],["79903.69000000","0.37554000"],["79902.75000000","0.26186000"],["79902.47000000","0.00007000"],["79901.48000000","0.00000000"],["79901.26000000","0.33799000"],["79900.02000000","0.62595000"],["79900.00000000","1.16733000"],["79899.41000000","0.02430000"],["79898.53000000","0.09462000"],["79896.53000000","0.10365000"],["79896.29000000","0.00000000"],["79895.10000000","0.00000000"],["79894.43000000","0.00800000"],["79894.20000000","0.00000000"],["79893.10000000","0.00000000"],["79892.67000000","0.00000000"],["79892.32000000","0.09419000"],["79888.02000000","0.00000000"],["79885.79000000","0.00000000"],["79883.67000000","0.00000000"],["79883.60000000","0.00000000"],["79880.00000000","0.11790000"],["79877.08000000","0.00000000"],["79873.00000000","0.01000000"],["79871.00000000","0.00000000"],["79870.00000000","0.11791000"],["79858.93000000","0.00012000"],["79856.72000000","0.00000000"],["79849.00000000","0.00000000"],["79848.03000000","0.00000000"],["79846.01000000","0.00312000"],["79837.71000000","0.00000000"],["79832.07000000","0.00000000"],["79830.53000000","0.00000000"],["79815.51000000","0.00000000"],["79789.43000000","0.00000000"],["79785.06000000","0.00000000"],["79773.41000000","0.04532000"],["79770.61000000","0.01960000"],["79765.84000000","0.00202000"],["79759.44000000","0.00000000"],["79755.98000000","0.00000000"],["79728.09000000","3.76371000"],["79681.01000000","0.00000000"],["79660.30000000","0.00000000"],["79591.12000000","0.00000000"],["79573.19000000","0.07607000"],["79502.21000000","0.00000000"],["79124.39000000","0.00000000"],["79124.09000000","0.00000000"],["73513.51000000","0.00014000"],["71921.70000000","0.00000000"],["67926.05000000","0.00051000"],["67826.87000000","0.00185000"],["67826.67000000","0.00034000"],["63930.40000000","0.00031000"]],"a":[["79913.01000000","0.00000000"],["79913.02000000","0.00000000"],["79913.23000000","0.00000000"],["79913.50000000","0.00000000"],["79913.77000000","0.00000000"],["79913.78000000","0.00000000"],["79913.85000000","0.00000000"],["79913.99000000","0.00000000"],["79914.00000000","0.02514000"],["79914.01000000","0.00042000"],["79914.48000000","0.00000000"],["79914.53000000","0.00000000"],["79914.77000000","0.00021000"],["79915.15000000","0.00000000"],["79915.77000000","0.00000000"],["79915.79000000","0.00000000"],["79915.98000000","0.00007000"],["79915.99000000","0.00021000"],["79916.00000000","0.02435000"],["79916.05000000","0.00021000"],["79916.72000000","0.00000000"],["79916.73000000","0.00000000"],["79916.98000000","0.04675000"],["79917.31000000","0.00000000"],["79917.32000000","0.00000000"],["79917.33000000","0.00028000"],["79917.38000000","0.00000000"],["79917.87000000","0.00000000"],["79917.96000000","0.00007000"],["79917.97000000","0.00000000"],["79918.00000000","0.02428000"],["79918.58000000","0.00007000"],["79918.59000000","0.00014000"],["79918.61000000","0.00021000"],["79918.65000000","0.00000000"],["79919.20000000","0.00007000"],["79919.21000000","0.00007000"],["79919.82000000","0.00007000"],["79919.83000000","0.00007000"],["79919.84000000","0.00007000"],["79919.85000000","0.00000000"],["79919.86000000","0.00000000"],["79919.87000000","0.00000000"],["79919.99000000","0.00007000"],["79922.02000000","0.00000000"],["79922.31000000","0.00000000"],["79922.46000000","0.00000000"],["79922.88000000","0.00000000"],["79922.93000000","0.00000000"],["79923.20000000","0.00000000"],["79923.24000000","0.00007000"],["79923.55000000","0.00000000"],["79923.81000000","0.00000000"],["79923.83000000","0.00026000"],["79923.94000000","0.00048000"],["79924.10000000","0.00000000"],["79924.37000000","0.00000000"],["79924.79000000","0.05708000"],["79924.96000000","0.06276000"],["79924.97000000","0.08564000"],["79925.68000000","0.00000000"],["79925.99000000","0.00008000"],["79926.65000000","0.06276000"],["79926.93000000","0.00008000"],["79926.94000000","0.00066000"],["79927.08000000","0.00000000"],["79927.09000000","0.00000000"],["79927.11000000","0.00014000"],["79927.27000000","0.06276000"],["79927.47000000","0.00007000"],["79927.89000000","0.06276000"],["79928.13000000","0.11023000"],["79928.39000000","0.00048000"],["79928.51000000","0.00000000"],["79929.08000000","0.00000000"],["79929.09000000","0.00000000"],["79929.27000000","0.00000000"],["79929.75000000","0.00000000"],["79930.15000000","0.00000000"],["79930.37000000","0.00000000"],["79930.94000000","0.06276000"],["79930.95000000","0.00000000"],["79930.98000000","0.00014000"],["79930.99000000","0.00000000"],["79931.61000000","0.00007000"],["79931.66000000","0.00000000"],["79931.95000000","0.06269000"],["79931.96000000","0.07143000"],["79932.02000000","0.02000000"],["79932.11000000","0.02187000"],["79932.85000000","0.00000000"],["79933.47000000","0.06276000"],["79933.92000000","0.00000000"],["79933.99000000","0.00400000"],["79934.09000000","0.06276000"],["79934.42000000","0.02000000"],["79934.71000000","0.06276000"],["79935.33000000","0.06276000"],["79935.36000000","0.00000000"],["79935.73000000","0.06276000"],["79935.74000000","0.00000000"],["79935.75000000","1.11368000"],["79935.77000000","0.00000000"],["79940.32000000","0.19019000"],["79940.33000000","0.00625000"],["79940.34000000","0.00000000"],["79940.54000000","0.31184000"],["79940.55000000","0.88152000"],["79943.79000000","0.62579000"],["79950.92000000","0.02479000"],["79952.66000000","0.42925000"],["79953.00000000","0.00000000"],["79954.00000000","0.03400000"],["79954.47000000","0.00000000"],["79954.57000000","1.20174000"],["79954.59000000","0.00191000"],["79955.24000000","0.00000000"],["79959.88000000","0.68161000"],["79960.66000000","0.00653000"],["79962.64000000","0.00400000"],["79967.84000000","0.00000000"],["79990.27000000","0.02000000"],["79990.32000000","0.02000000"],["80000.22000000","0.02000000"],["80009.89000000","0.00000000"],["80012.00000000","0.63103000"],["80013.10000000","0.02804000"],["80024.79000000","0.00000000"],["80032.86000000","0.04553000"],["80071.95000000","0.00000000"],["80079.02000000","0.00202000"],["80127.63000000","0.00000000"],["80138.70000000","0.01960000"],["80199.92000000","0.00028000"],["80402.58000000","0.00000000"]]}}}
{"rx_ns": 13887899950600, "frame": {"stream":"btcusdt@depth@100ms","data":{"e":"depthUpdate","E":1787650883114,"s":"BTCUSDT","U":99118608366,"u":99118609219,"b":[["79919.99000000","1.93139000"],["79919.98000000","0.00027000"],["79919.97000000","0.00013000"],["79919.84000000","0.00000000"],["79919.82000000","0.00000000"],["79919.37000000","0.00014000"],["79919.20000000","0.00000000"],["79918.87000000","0.03134000"],["79918.75000000","0.00000000"],["79918.72000000","0.00007000"],["79918.71000000","0.02003000"],["79918.60000000","0.00000000"],["79918.58000000","0.00000000"],["79918.35000000","0.00000000"],["79918.13000000","0.00000000"],["79917.99000000","0.00000000"],["79917.96000000","0.00000000"],["79917.44000000","0.00007000"],["79917.43000000","0.02396000"],["79917.42000000","0.00007000"],["79917.41000000","0.05383000"],["79917.38000000","0.00000000"],["79917.32000000","0.00000000"],["79916.98000000","0.00007000"],["79916.97000000","0.06252000"],["79916.55000000","0.00000000"],["79916.35000000","0.00000000"],["79916.28000000","0.00007000"],["79916.27000000","0.06273000"],["79916.19000000","0.00000000"],["79916.16000000","0.00007000"],["79916.15000000","0.02396000"],["79916.04000000","0.00000000"],["79916.00000000","0.00007000"],["79915.99000000","0.06198000"],["79915.98000000","0.00000000"],["79915.96000000","0.00000000"],["79915.75000000","0.00000000"],["79915.52000000","0.00400000"],["79915.50000000","0.00014000"],["79915.49000000","0.00000000"],["79915.04000000","0.00007000"],["79915.03000000","0.06266000"],["79914.76000000","0.00000000"],["79914.42000000","0.00000000"],["79914.41000000","0.06266000"],["79914.02000000","0.00000000"],["79914.01000000","0.00000000"],["79914.00000000","0.17972000"],["79913.99000000","3.74660000"],["79913.98000000","0.00014000"],["79913.97000000","0.00000000"],["79913.85000000","0.31312000"],["79913.84000000","2.20845000"],["79913.04000000","0.00400000"],["79913.01000000","0.07521000"],["79913.00000000","1.56832000"],["79912.80000000","0.00007000"],["79912.75000000","0.00014000"],["79912.70000000","0.00021000"],["79912.65000000","0.00014000"],["79912.41000000","0.00000000"],["79912.04000000","0.20645000"],["79912.00000000","0.00015000"],["79911.62000000","0.75458000"],["79911.43000000","0.00007000"],["79911.41000000","0.20250000"],["79911.39000000","0.00000000"],["79910.82000000","0.00000000"],["79910.81000000","0.07507000"],["79910.80000000","0.32928000"],["79910.78000000","0.00020000"],["79910.57000000","0.08576000"],["79910.50000000","0.07888000"],["79910.41000000","0.00000000"],["79910.19000000","0.00000000"],["79910.18000000","0.02479000"],["79909.99000000","0.00000000"],["79909.59000000","0.00000000"],["79909.52000000","0.00000000"],["79909.50000000","0.00010000"],["79909.15000000","0.00925000"],["79909.09000000","0.00007000"],["79908.97000000","0.00000000"],["79908.94000000","0.00000000"],["79908.60000000","0.00007000"],["79908.48000000","0.00007000"],["79908.46000000","0.00007000"],["79908.19000000","0.00000000"],["79907.01000000","0.00000000"],["79906.96000000","0.00000000"],["79906.01000000","0.00007000"],["79905.29000000","0.00000000"],["79905.01000000","0.00000000"],["79904.77000000","0.00007000"],["79904.01000000","0.00008000"],["79902.47000000","0.00000000"],["79902.08000000","0.09461000"],["79900.08000000","0.10365000"],["79900.01000000","1.87685000"],["79899.49000000","0.00000000"],["79899.35000000","0.33800000"],["79899.21000000","0.00000000"],["79898.53000000","0.00000000"],["79896.53000000","0.00000000"],["79896.01000000","0.00015000"],["79895.58000000","0.00000000"],["79894.21000000","0.00000000"],["79892.52000000","0.00125000"],["79892.02000000","0.00008000"],["79890.21000000","0.00000000"],["79888.02000000","0.00008000"],["79887.58000000","0.02541000"],["79887.51000000","0.38961000"],["79886.62000000","0.00000000"],["79886.22000000","0.00000000"],["79885.78000000","0.00000000"],["79885.01000000","0.00000000"],["79884.03000000","0.00008000"],["79882.22000000","0.00000000"],["79882.07000000","0.00000000"],["79882.04000000","0.00000000"],["79880.03000000","0.00008000"],["79878.23000000","0.00000000"],["79876.80000000","0.00000000"],["79876.16000000","0.00000000"],["79876.02000000","0.00000000"],["79874.23000000","0.00000000"],["79873.92000000","0.00000000"],["79871.51000000","0.45396000"],["79870.23000000","0.00000000"],["79870.00000000","0.02400000"],["79868.81000000","0.00625000"],["79866.44000000","0.82199000"],["79857.77000000","0.00000000"],["79854.26000000","0.00000000"],["79854.10000000","0.00000000"],["79850.11000000","0.00000000"],["79850.06000000","0.00310000"],["79847.10000000","0.65915000"],["79840.07000000","0.00008000"],["79839.64000000","0.01317000"],["79838.19000000","0.00007000"],["79836.26000000","0.00000000"],["79830.87000000","0.00000000"],["79830.34000000","0.00000000"],["79810.13000000","0.00000000"],["79770.62000000","0.00125000"],["79760.15000000","0.00008000"],["79750.96000000","0.00000000"],["79749.90000000","0.00000000"],["79740.16000000","0.00000000"],["79692.55000000","0.00000000"],["79689.83000000","0.00000000"],["79686.68000000","0.00000000"],["79680.23000000","0.00008000"],["79671.05000000","0.00000000"],["79636.78000000","0.00000000"],["79620.99000000","0.00000000"],["79615.73000000","0.00283000"],["79602.97000000","0.00026000"],["79600.31000000","0.00008000"],["79591.14000000","0.00000000"],["79520.39000000","0.00008000"],["79519.50000000","0.00000000"],["79511.23000000","0.00000000"],["79440.47000000","0.00008000"],["79431.32000000","0.00000000"],["79360.55000000","0.00008000"],["79351.40000000","0.00000000"],["71928.00000000","0.00439000"],["67932.00000000","0.00690000"]],"a":[["79914.00000000","0.00000000"],["79914.01000000","0.00000000"],["79914.03000000","0.00000000"],["79914.77000000","0.00000000"],["79915.50000000","0.00000000"],["79915.76000000","0.00000000"],["79915.98000000","0.00000000"],["79915.99000000","0.00000000"],["79916.00000000","0.00000000"],["79916.05000000","0.00000000"],["79916.20000000","0.00000000"],["79916.36000000","0.00000000"],["79916.97000000","0.00000000"],["79916.98000000","0.00000000"],["79917.33000000","0.00000000"],["79917.39000000","0.00000000"],["79917.71000000","0.00000000"],["79917.96000000","0.00000000"],["79917.99000000","0.00000000"],["79918.00000000","0.00000000"],["79918.36000000","0.00000000"],["79918.58000000","0.00000000"],["79918.59000000","0.00000000"],["79918.61000000","0.00000000"],["79918.64000000","0.00000000"],["79919.00000000","0.00000000"],["79919.20000000","0.00000000"],["79919.21000000","0.00000000"],["79919.37000000","0.00000000"],["79919.82000000","0.00000000"],["79919.83000000","0.00000000"],["79919.84000000","0.00000000"],["79919.99000000","0.00000000"],["79920.00000000","1.34780000"],["79920.01000000","0.00049000"],["79920.23000000","0.00000000"],["79920.37000000","0.00000000"],["79920.40000000","0.00000000"],["79920.72000000","0.00000000"],["79921.00000000","0.00000000"],["79921.06000000","0.00000000"],["79921.07000000","0.00000000"],["79921.98000000","0.00007000"],["79921.99000000","0.03065000"],["79922.00000000","0.02428000"],["79922.01000000","0.01904000"],["79922.21000000","0.11628000"],["79922.47000000","0.00000000"],["79923.09000000","0.00007000"],["79923.10000000","0.06098000"],["79923.24000000","0.00014000"],["79923.71000000","0.00007000"],["79923.72000000","0.06266000"],["79923.94000000","0.00000000"],["79923.95000000","0.00007000"],["79923.96000000","0.06259000"],["79923.97000000","0.01589000"],["79923.99000000","0.00007000"],["79924.00000000","0.02414000"],["79924.09000000","0.00007000"],["79924.10000000","0.12379000"],["79924.11000000","0.00007000"],["79924.27000000","0.00000000"],["79924.78000000","0.00000000"],["79924.79000000","0.00007000"],["79924.95000000","0.00007000"],["79924.96000000","0.06266000"],["79924.97000000","0.06266000"],["79924.98000000","0.20264000"],["79925.24000000","0.01131000"],["79925.34000000","0.00715000"],["79925.99000000","0.00000000"],["79926.00000000","0.02414000"],["79926.20000000","0.06259000"],["79926.29000000","0.02266000"],["79926.52000000","0.01357000"],["79926.64000000","0.00013000"],["79926.65000000","0.06283000"],["79926.93000000","0.00000000"],["79926.94000000","0.00000000"],["79926.99000000","0.02007000"],["79927.26000000","0.00000000"],["79927.27000000","0.06283000"],["79927.56000000","0.00000000"],["79927.79000000","0.02000000"],["79927.80000000","0.01357000"],["79927.87000000","0.00000000"],["79927.88000000","0.66812000"],["79927.89000000","0.00000000"],["79927.99000000","0.00008000"],["79928.13000000","0.00000000"],["79928.39000000","0.00000000"],["79928.68000000","0.05649000"],["79928.87000000","0.00000000"],["79928.88000000","0.00000000"],["79928.93000000","0.00073000"],["79929.50000000","0.06259000"],["79929.99000000","0.00000000"],["79930.03000000","0.00048000"],["79930.12000000","0.06259000"],["79930.67000000","0.00007000"],["79930.74000000","0.06259000"],["79930.93000000","1.87677000"],["79930.94000000","0.00000000"],["79931.07000000","0.00048000"],["79931.70000000","0.00000000"],["79931.95000000","0.00000000"],["79931.96000000","0.07143000"],["79931.99000000","0.00000000"],["79933.02000000","0.00000000"],["79933.22000000","0.00000000"],["79933.47000000","0.00000000"],["79933.78000000","0.01200000"],["79933.80000000","0.02000000"],["79933.87000000","0.00007000"],["79933.98000000","0.00007000"],["79934.09000000","0.00000000"],["79934.71000000","0.00000000"],["79934.81000000","0.00000000"],["79935.33000000","0.00000000"],["79935.73000000","0.00000000"],["79935.98000000","0.00008000"],["79936.13000000","0.00012000"],["79936.75000000","0.00007000"],["79937.80000000","0.09457000"],["79937.98000000","0.00000000"],["79939.80000000","0.10360000"],["79939.98000000","0.00008000"],["79940.54000000","0.00000000"],["79941.97000000","0.00000000"],["79943.79000000","0.34504000"],["79943.80000000","0.84316000"],["79943.98000000","0.00133000"],["79944.82000000","0.00000000"],["79945.97000000","0.00000000"],["79947.63000000","2.15703000"],["79947.65000000","0.00000000"],["79947.72000000","0.00400000"],["79947.97000000","0.00928000"],["79951.62000000","0.80830000"],["79951.97000000","0.00008000"],["79952.97000000","0.00000000"],["79954.00000000","0.02400000"],["79954.20000000","0.00014000"],["79955.96000000","0.00008000"],["79956.27000000","0.09565000"],["79956.44000000","0.99299000"],["79958.07000000","0.00014000"],["79958.24000000","0.00000000"],["79959.62000000","0.02454000"],["79959.96000000","0.00368000"],["79960.00000000","1.03515000"],["79963.75000000","1.24002000"],["79967.82000000","0.32319000"],["79968.22000000","0.00431000"],["79972.95000000","1.55411000"],["79975.99000000","0.54504000"],["79977.99000000","0.00000000"],["79981.50000000","0.00000000"],["79984.81000000","0.00000000"],["79987.27000000","0.00311000"],["79987.70000000","0.00400000"],["79987.92000000","0.00000000"],["79988.16000000","0.00312000"],["79990.27000000","0.00000000"],["79991.97000000","0.58121000"],["79991.99000000","0.00000000"],["79992.86000000","0.02000000"],["79997.51000000","0.00010000"],["79999.92000000","0.00318000"],["80001.03000000","0.00000000"],["80016.79000000","0.00000000"],["80019.68000000","0.00400000"],["80047.47000000","0.00000000"],["80051.50000000","0.15493000"],["80054.48000000","0.25000000"],["80064.75000000","0.00000000"],["80067.65000000","0.00400000"],["80067.83000000","0.00000000"],["80079.84000000","0.00268000"],["80136.70000000","0.00000000"],["80139.60000000","0.00400000"],["80147.73000000","0.00000000"],["80153.42000000","0.00007000"],["80157.41000000","0.00007000"],["80159.76000000","0.00008000"],["80188.58000000","0.00000000"],["80223.69000000","1.19998000"],["80307.55000000","0.00000000"],["80319.60000000","0.00008000"],["80467.37000000","0.00000000"],["80479.44000000","0.00008000"],["80547.27000000","0.00000000"],["80559.36000000","0.00008000"]]}}}
{"rx_ns": 13887999332700, "frame": {"stream":"btcusdt@depth@100ms","data":{"e":"depthUpdate","E":1787650883214,"s":"BTCUSDT","U":99118609220,"u":99118609529,"b":[["79919.99000000","1.93091000"],["79918.88000000","0.00007000"],["79918.87000000","0.03148000"],["79918.71000000","0.02024000"],["79918.07000000","0.00921000"],["79917.43000000","0.02410000"],["79917.41000000","0.05404000"],["79917.05000000","0.05000000"],["79917.00000000","0.05000000"],["79916.98000000","0.00000000"],["79916.97000000","0.00021000"],["79916.52000000","0.00718000"],["79916.43000000","0.00007000"],["79916.28000000","0.00000000"],["79916.27000000","0.00028000"],["79916.16000000","0.00007000"],["79916.00000000","0.00000000"],["79915.99000000","0.00007000"],["79915.04000000","0.00007000"],["79914.49000000","0.00007000"],["79914.42000000","0.00007000"],["79914.01000000","0.00007000"],["79914.00000000","0.17979000"],["79913.99000000","3.73896000"],["79913.98000000","0.00000000"],["79913.85000000","0.31298000"],["79913.84000000","2.00581000"],["79913.01000000","0.07500000"],["79913.00000000","1.54943000"],["79912.70000000","0.00000000"],["79912.65000000","0.00000000"],["79912.42000000","0.00007000"],["79912.04000000","0.20638000"],["79911.99000000","0.20250000"],["79911.62000000","0.51509000"],["79911.43000000","0.00000000"],["79911.41000000","0.00000000"],["79910.80000000","0.32911000"],["79910.78000000","0.00000000"],["79906.85000000","0.00000000"],["79903.92000000","0.00000000"],["79901.47000000","0.00000000"],["79889.99000000","0.33147000"],["79883.36000000","0.00400000"],["79880.00000000","0.12790000"],["79879.25000000","0.34118000"],["79878.09000000","0.00000000"],["79876.31000000","0.83176000"],["79873.00000000","0.00000000"],["79866.60000000","0.00000000"],["79865.91000000","0.00012000"],["79858.93000000","0.00000000"],["79845.62000000","0.02086000"],["79844.17000000","0.62553000"],["79843.41000000","0.00400000"],["79838.12000000","0.00000000"],["79813.31000000","0.00025000"],["79806.19000000","0.00000000"],["79791.16000000","0.00012000"],["79789.43000000","0.20250000"],["79780.36000000","0.00000000"],["79779.86000000","0.04532000"],["79773.41000000","0.00000000"],["79763.53000000","0.00400000"],["79758.27000000","0.00000000"],["79686.38000000","0.00000000"],["63930.40000000","0.00000000"]],"a":[["79920.00000000","1.53029000"],["79920.01000000","0.00042000"],["79921.98000000","0.00000000"],["79921.99000000","0.00021000"],["79922.01000000","0.01911000"],["79922.20000000","0.00007000"],["79922.21000000","0.11642000"],["79923.10000000","0.06112000"],["79923.72000000","0.06280000"],["79923.95000000","0.00007000"],["79923.96000000","0.06273000"],["79923.97000000","0.01603000"],["79923.99000000","0.00007000"],["79924.09000000","0.00007000"],["79924.95000000","0.00007000"],["79926.04000000","0.00000000"],["79927.27000000","0.06276000"],["79927.78000000","0.05992000"],["79928.51000000","0.36586000"],["79928.68000000","0.00000000"],["79929.50000000","0.00000000"],["79930.12000000","0.00000000"],["79936.13000000","0.00000000"],["79946.39000000","0.00250000"],["79947.72000000","0.00000000"],["79950.44000000","0.51379000"],["79964.82000000","0.62542000"],["79972.55000000","0.83076000"],["79974.49000000","0.99780000"],["79987.70000000","0.00000000"],["80009.90000000","0.00000000"],["80013.10000000","0.00000000"],["80019.57000000","0.02804000"],["80019.68000000","0.00000000"],["80029.74000000","0.00000000"],["80032.43000000","0.00000000"],["80036.59000000","0.00000000"],["80036.73000000","0.00012000"],["80067.65000000","0.00000000"],["80070.04000000","0.00399000"],["80139.60000000","0.00000000"],["80142.00000000","0.00399000"],["80161.40000000","0.00007000"],["80165.39000000","0.00000000"],["80630.00000000","0.00050000"]]}}}
{"rx_ns": 13888102064200, "frame": {"stream":"btcusdt@depth@100ms","data":{"e":"depthUpdate","E":1787650883314,"s":"BTCUSDT","U":99118609530,"u":99118609649,"b":[["79919.99000000","1.96517000"],["79918.88000000","0.00000000"],["79918.87000000","0.00014000"],["79918.71000000","0.02024000"],["79918.07000000","0.00935000"],["79918.03000000","0.00007000"],["79917.90000000","0.05000000"],["79917.41000000","0.05411000"],["79917.07000000","0.00007000"],["79917.06000000","1.04946000"],["79917.05000000","0.00021000"],["79917.01000000","0.00007000"],["79917.00000000","0.00000000"],["79916.97000000","0.00007000"],["79916.27000000","0.00014000"],["79916.16000000","0.00000000"],["79915.04000000","0.00000000"],["79915.03000000","0.00007000"],["79914.42000000","0.00000000"],["79914.41000000","0.00007000"],["79914.01000000","0.00007000"],["79914.00000000","0.17979000"],["79913.99000000","3.15728000"],["79913.85000000","0.31305000"],["79910.81000000","0.07500000"],["79910.80000000","0.32855000"],["79909.24000000","0.00000000"],["79908.47000000","0.00007000"],["79908.46000000","0.00000000"],["79908.44000000","0.00000000"],["79904.00000000","1.07353000"],["79902.80000000","0.00000000"],["79900.02000000","0.00014000"],["79899.36000000","0.51779000"],["79898.09000000","0.00000000"],["79896.13000000","0.62580000"],["79894.81000000","0.00000000"],["79886.82000000","0.00000000"],["79886.74000000","0.00000000"],["79878.83000000","0.00000000"],["79815.05000000","0.00000000"],["79700.91000000","0.00023000"],["79688.21000000","0.00770000"],["71928.00000000","0.00471000"],["63936.00000000","0.00363000"]],"a":[["79920.00000000","1.59369000"],["79921.99000000","0.03265000"],["79922.01000000","0.01918000"],["79922.19000000","0.00007000"],["79922.20000000","0.00000000"],["79922.21000000","0.00014000"],["79923.99000000","0.00007000"],["79924.00000000","0.02428000"],["79924.09000000","0.00007000"],["79924.10000000","0.19017000"],["79924.95000000","0.00072000"],["79926.01000000","0.00000000"],["79926.29000000","0.02266000"],["79926.43000000","0.00000000"],["79928.93000000","0.00000000"],["79930.74000000","0.00000000"],["79943.11000000","0.00012000"],["79944.19000000","0.04559000"],["79969.21000000","0.00000000"],["79990.32000000","0.00000000"],["79992.86000000","0.00000000"],["80013.10000000","0.00025000"],["80022.07000000","0.00399000"],["80047.45000000","0.00000000"]]}}}
{"rx_ns": 13888202328800, "frame": {"stream":"btcusdt@depth@100ms","data":{"e":"depthUpdate","E":1787650883414,"s":"BTCUSDT","U":99118609650,"u":99118609741,"b":[["79919.99000000","1.99003000"],["79919.43000000","0.00697000"],["79918.87000000","0.00000000"],["79918.64000000","0.04054000"],["79918.07000000","0.00949000"],["79917.91000000","0.00579000"],["79917.90000000","0.00014000"],["79917.41000000","0.05404000"],["79917.06000000","1.04939000"],["79917.05000000","0.00000000"],["79917.01000000","0.00000000"],["79914.01000000","0.00007000"],["79914.00000000","0.17979000"],["79913.85000000","0.31305000"],["79913.01000000","0.07507000"],["79911.99000000","0.20304000"],["79910.18000000","0.00000000"],["79910.00000000","0.00700000"],["79908.00000000","0.00700000"],["79906.00000000","0.00700000"],["79904.00000000","1.07407000"],["79903.63000000","0.00000000"],["79896.01000000","0.00069000"],["79888.02000000","0.00062000"],["79872.64000000","0.00562000"],["71928.00000000","0.00487000"]],"a":[["79920.00000000","1.59376000"],["79920.01000000","0.00049000"],["79921.98000000","0.00007000"],["79921.99000000","0.03279000"],["79922.01000000","0.01904000"],["79922.19000000","0.00000000"],["79922.21000000","0.00000000"],["79923.95000000","0.00007000"],["79923.99000000","0.00007000"],["79924.09000000","0.00007000"],["79924.95000000","0.00072000"],["79925.71000000","0.00000000"],["79926.29000000","0.02273000"],["79926.34000000","0.00000000"],["79927.39000000","0.00215000"],["79961.94000000","0.00000000"],["80000.22000000","0.00000000"],["80039.42000000","0.00018000"],["80043.58000000","0.00031000"],["80077.01000000","0.00000000"],["80116.60000000","0.01960000"]]}}}
{"rx_ns": 13888301223600, "frame": {"stream":"btcusdt@depth@100ms","data":{"e":"depthUpdate","E":1787650883514,"s":"BTCUSDT","U":99118609742,"u":99118609789,"b":[["79919.99000000","1.99024000"],["79919.43000000","0.00711000"],["79918.71000000","0.02031000"],["79918.65000000","0.00007000"],["79918.07000000","0.00928000"],["79917.91000000","0.00572000"],["79917.90000000","0.00000000"],["79914.00000000","0.17979000"],["79913.85000000","0.31305000"],["79913.01000000","0.07507000"],["79908.10000000","0.27712000"],["79845.62000000","0.00000000"],["79844.17000000","0.00000000"],["79691.63000000","0.00400000"],["79360.00000000","0.00583000"],["78721.19000000","0.00030000"],["71928.00000000","0.00503000"],["63936.00000000","0.00394000"]],"a":[["79920.00000000","1.64369000"],["79923.99000000","0.00007000"],["79924.09000000","0.00007000"],["79924.95000000","0.00072000"],["79924.97000000","0.00007000"],["79926.29000000","0.02266000"],["79926.65000000","0.00007000"],["79959.72000000","0.00653000"],["79960.78000000","0.33774000"]]}}}
{"rx_ns": 13888400057800, "frame": {"stream":"btcusdt@depth@100ms","data":{"e":"depthUpdate","E":1787650883614,"s":"BTCUSDT","U":99118609790,"u":99118609922,"b":[["79919.99000000","1.99031000"],["79918.19000000","0.00026000"],["79917.91000000","0.00579000"],["79917.48000000","0.00007000"],["79917.47000000","0.06360000"],["79917.41000000","0.05411000"],["79917.08000000","0.00007000"],["79917.07000000","0.06367000"],["79914.01000000","0.00007000"],["79914.00000000","0.17979000"],["79913.85000000","0.31298000"],["79913.01000000","0.07500000"],["79913.00000000","1.54936000"],["79911.42000000","0.00000000"],["79902.77000000","0.02200000"],["79901.97000000","0.02000000"],["79901.96000000","0.02000000"],["79900.87000000","0.49224000"],["79893.80000000","0.00000000"],["79829.25000000","0.00000000"],["73513.51000000","0.00000000"],["71928.00000000","0.00519000"],["63936.00000000","0.00363000"]],"a":[["79920.00000000","1.40659000"],["79920.01000000","0.00042000"],["79921.99000000","0.00021000"],["79923.09000000","0.00000000"],["79923.10000000","0.00014000"],["79923.71000000","0.00000000"],["79923.72000000","0.00021000"],["79923.83000000","0.00000000"],["79923.95000000","0.00000000"],["79923.96000000","0.00021000"],["79924.10000000","0.17349000"],["79924.95000000","0.00000000"],["79924.96000000","0.00014000"],["79924.97000000","0.06374000"],["79925.34000000","0.00722000"],["79925.66000000","0.00007000"],["79925.67000000","0.06360000"],["79925.99000000","0.00000000"],["79926.00000000","0.02414000"],["79926.20000000","0.00000000"],["79926.28000000","0.06360000"],["79926.52000000","0.01364000"],["79926.64000000","0.00000000"],["79926.93000000","0.06360000"],["79926.94000000","0.00065000"],["79927.26000000","0.00000000"],["79927.46000000","0.00013000"],["79927.88000000","0.69630000"],["79930.92000000","1.87677000"],["79930.93000000","0.00000000"],["79931.34000000","0.00000000"],["79931.95000000","0.00000000"],["79931.96000000","0.18566000"],["79931.99000000","0.00000000"],["79933.23000000","0.00000000"],["79933.77000000","0.00000000"],["79934.49000000","0.00000000"],["79935.12000000","0.00000000"],["79935.74000000","0.00000000"],["79936.91000000","0.02000000"],["79937.72000000","0.02000000"],["79944.19000000","0.00000000"],["79947.13000000","0.04400000"],["79953.00000000","0.70000000"],["79961.94000000","0.00007000"],["79993.73000000","0.02000000"],["79996.81000000","0.00000000"]]}}}
{"rx_ns": 13888500507600, "frame": {"stream":"btcusdt@depth@100ms","data":{"e":"depthUpdate","E":1787650883714,"s":"BTCUSDT","U":99118609923,"u":99118610084,"b":[["79919.99000000","2.00989000"],["79919.43000000","0.00725000"],["79919.35000000","0.00007000"],["79919.34000000","0.03224000"],["79918.74000000","0.00007000"],["79918.73000000","0.00000000"],["79918.64000000","0.04696000"],["79918.19000000","0.00000000"],["79918.11000000","0.00007000"],["79918.10000000","0.06360000"],["79918.07000000","0.00942000"],["79917.91000000","0.00021000"],["79917.47000000","0.06374000"],["79917.44000000","0.00007000"],["79917.42000000","0.00007000"],["79917.41000000","0.05397000"],["79917.08000000","0.00007000"],["79917.07000000","0.06360000"],["79914.01000000","0.00000000"],["79914.00000000","0.17972000"],["79913.99000000","3.11728000"],["79913.92000000","0.00153000"],["79912.04000000","0.20631000"],["79905.91000000","0.00000000"],["79886.00000000","0.82859000"],["79779.86000000","0.00000000"],["71928.00000000","0.00551000"],["71927.00000000","0.00000000"],["71919.71000000","0.00000000"]],"a":[["79920.00000000","1.07917000"],["79920.01000000","0.00035000"],["79921.98000000","0.00000000"],["79921.99000000","0.00007000"],["79922.01000000","0.01897000"],["79922.82000000","0.00007000"],["79923.10000000","0.00000000"],["79923.72000000","0.00007000"],["79923.78000000","0.06360000"],["79923.96000000","0.06367000"],["79924.10000000","0.17363000"],["79924.97000000","0.06388000"],["79924.98000000","0.20278000"],["79925.24000000","0.01145000"],["79925.66000000","0.00007000"],["79926.27000000","0.00007000"],["79926.94000000","0.00000000"],["79927.88000000","0.12529000"],["79928.50000000","0.00073000"],["79930.08000000","0.06360000"],["79930.71000000","0.06360000"],["79930.92000000","0.00000000"],["79931.34000000","0.06360000"],["79931.95000000","0.06360000"],["79931.96000000","0.16421000"],["79931.99000000","0.06272000"],["79933.23000000","0.06335000"],["79933.77000000","0.00000000"],["79933.78000000","0.06360000"],["79933.86000000","0.00000000"],["79933.99000000","0.00000000"],["79934.41000000","0.00800000"],["79934.49000000","0.06360000"],["79935.12000000","0.06360000"],["79935.74000000","0.06760000"],["79935.75000000","1.10568000"],["79961.43000000","0.00000000"],["79990.09000000","0.00399000"],["79995.18000000","0.04694000"]]}}}
{"rx_ns": 13888612633600, "frame": {"stream":"btcusdt@depth@100ms","data":{"e":"depthUpdate","E":1787650883814,"s":"BTCUSDT","U":99118610085,"u":99118610172,"b":[["79919.99000000","2.00989000"],["79919.43000000","0.00718000"],["79919.35000000","0.00000000"],["79919.34000000","0.00014000"],["79918.83000000","0.00007000"],["79918.74000000","0.00000000"],["79918.64000000","0.04696000"],["79918.11000000","0.00000000"],["79918.10000000","0.00014000"],["79918.07000000","0.00928000"],["79917.91000000","0.00007000"],["79917.48000000","0.00000000"],["79917.47000000","0.00014000"],["79917.42000000","0.00007000"],["79917.08000000","0.00000000"],["79917.07000000","0.00007000"],["79914.01000000","0.00007000"],["79914.00000000","0.17979000"],["79913.85000000","0.31305000"],["79913.01000000","0.07507000"],["79906.76000000","0.02800000"],["79906.70000000","0.02600000"],["79905.91000000","0.02000000"],["79902.76000000","0.02400000"],["79902.29000000","0.02200000"],["79901.89000000","0.04400000"],["79897.20000000","0.00000000"],["79892.35000000","0.00000000"],["79890.01000000","0.00007000"],["79889.21000000","0.00000000"],["79887.51000000","0.54857000"],["79865.91000000","0.00000000"],["79864.97000000","0.00012000"],["79863.66000000","0.00432000"],["79851.98000000","0.00000000"],["79849.12000000","0.02086000"],["79781.84000000","0.04531000"],["71928.00000000","0.00535000"],["63935.99000000","0.00000000"]],"a":[["79920.00000000","1.39904000"],["79922.01000000","0.01904000"],["79923.77000000","0.00007000"],["79923.78000000","0.06374000"],["79923.88000000","0.00026000"],["79923.95000000","0.00007000"],["79923.96000000","0.06381000"],["79924.96000000","0.00014000"],["79924.97000000","0.06388000"],["79924.98000000","0.20264000"],["79925.24000000","0.01131000"],["79925.66000000","0.00000000"],["79926.27000000","0.00000000"],["79927.88000000","0.17427000"],["79937.40000000","0.02000000"],["79943.11000000","0.00000000"],["79993.73000000","0.00000000"],["80001.51000000","0.02000000"]]}}}
{"rx_ns": 13888695684500, "frame": {"stream":"btcusdt@depth@100ms","data":{"e":"depthUpdate","E":1787650883914,"s":"BTCUSDT","U":99118610173,"u":99118610217,"b":[["79919.99000000","2.00991000"],["79919.43000000","0.00711000"],["79919.34000000","0.00000000"],["79918.64000000","0.04689000"],["79918.10000000","0.00000000"],["79918.07000000","0.00935000"],["79917.91000000","0.00000000"],["79917.47000000","0.00000000"],["79917.41000000","0.05411000"],["79917.06000000","1.04953000"],["79913.12000000","0.12513000"],["79897.14000000","0.12516000"],["79892.74000000","0.00000000"],["79892.34000000","0.00000000"],["79855.92000000","0.00000000"],["79855.09000000","0.00000000"],["79849.12000000","0.00000000"],["71928.00000000","0.00567000"],["63936.00000000","0.00563000"],["63935.99000000","0.00000000"]],"a":[["79937.10000000","0.12509000"],["79942.18000000","0.00012000"],["79945.09000000","0.12508000"],["79950.11000000","0.00399000"],["81118.80000000","0.00030000"]]}}}
{"rx_ns": 13888797162300, "frame": {"stream":"btcusdt@depth20","data":{"lastUpdateId":99118610308,"bids":[["79919.99000000","2.34784000"],["79919.98000000","0.00027000"],["79919.97000000","0.00013000"],["79919.96000000","0.00007000"],["79919.95000000","0.05007000"],["79919.91000000","0.00007000"],["79919.90000000","0.05000000"],["79919.43000000","0.00718000"],["79919.37000000","0.00654000"],["79918.83000000","0.00007000"],["79918.72000000","0.00007000"],["79918.71000000","0.02031000"],["79918.65000000","0.00007000"],["79918.64000000","0.04068000"],["79918.07000000","0.00935000"],["79918.03000000","0.00007000"],["79917.44000000","0.00007000"],["79917.43000000","0.02410000"],["79917.42000000","0.00007000"],["79917.41000000","0.05411000"]],"asks":[["79920.00000000","1.39641000"],["79920.01000000","0.00035000"],["79920.16000000","0.00075000"],["79920.24000000","0.00007000"],["79920.30000000","0.00007000"],["79920.31000000","0.33793000"],["79921.99000000","0.00007000"],["79922.00000000","0.02421000"],["79922.01000000","0.01904000"],["79922.42000000","0.00413000"],["79922.82000000","0.00007000"],["79923.24000000","0.00014000"],["79923.72000000","0.00007000"],["79923.77000000","0.00007000"],["79923.78000000","0.06374000"],["79923.88000000","0.00026000"],["79923.95000000","0.00007000"],["79923.96000000","0.00014000"],["79923.97000000","0.01603000"],["79923.99000000","0.00007000"]]}}}
{"rx_ns": 13888797306500, "frame": {"stream":"btcusdt@depth@100ms","data":{"e":"depthUpdate","E":1787650884014,"s":"BTCUSDT","U":99118610218,"u":99118610308,"b":[["79919.99000000","2.34784000"],["79919.96000000","0.00007000"],["79919.95000000","0.05007000"],["79919.91000000","0.00007000"],["79919.90000000","0.05000000"],["79919.43000000","0.00718000"],["79919.37000000","0.00654000"],["79918.64000000","0.04068000"],["79917.07000000","0.00007000"],["79915.53000000","0.00625000"],["79914.50000000","0.00625000"],["79914.11000000","0.00250000"],["79914.01000000","0.00007000"],["79914.00000000","0.17979000"],["79913.99000000","3.10478000"],["79913.85000000","0.31305000"],["79913.01000000","0.07500000"],["79905.96000000","0.02200000"],["79905.89000000","0.02407000"],["79903.57000000","0.02400000"],["79897.12000000","0.00000000"],["79896.33000000","0.02400000"],["79893.21000000","0.00000000"],["79852.01000000","0.00312000"],["79850.87000000","0.00312000"],["79850.06000000","0.00000000"],["79846.01000000","0.00000000"],["79781.84000000","0.00000000"],["79772.01000000","0.00125000"],["79770.25000000","1.49938000"],["79765.84000000","0.00000000"],["79762.24000000","0.00000000"],["79742.45000000","0.00000000"],["71928.00000000","0.00567000"],["63936.00000000","0.00394000"]],"a":[["79920.00000000","1.39641000"],["79920.30000000","0.00007000"],["79920.31000000","0.33793000"],["79922.00000000","0.02421000"],["79923.96000000","0.00014000"],["79924.00000000","0.02435000"],["79924.05000000","0.00007000"],["79924.06000000","0.14257000"],["79924.09000000","0.00007000"],["79924.96000000","0.00014000"],["79924.97000000","0.00028000"],["79925.34000000","0.00715000"],["79925.67000000","0.00000000"],["79926.28000000","0.00000000"],["79927.27000000","0.00000000"],["79927.76000000","0.00000000"],["79927.78000000","0.00000000"],["79929.99000000","0.00625000"],["79930.08000000","0.00000000"],["79930.09000000","0.00250000"],["79931.99000000","0.00000000"],["79933.23000000","0.00000000"],["80019.57000000","0.00000000"],["80056.73000000","0.00007000"],["80059.48000000","0.00000000"],["80065.90000000","0.00000000"],["80066.83000000","0.00125000"],["80067.99000000","0.00132000"],["80073.95000000","1.49938000"],["80079.02000000","0.00000000"]]}}}
{"rx_ns": 13888895717900, "frame": {"stream":"btcusdt@depth@100ms","data":{"e":"depthUpdate","E":1787650884114,"s":"BTCUSDT","U":99118610309,"u":99118610420,"b":[["79919.99000000","2.34791000"],["79919.95000000","0.05021000"],["79919.90000000","0.05014000"],["79919.43000000","0.00704000"],["79917.41000000","0.05397000"],["79917.08000000","0.00007000"],["79917.07000000","0.32275000"],["79917.06000000","1.04939000"],["79916.15000000","0.02403000"],["79915.53000000","0.00632000"],["79914.01000000","0.00007000"],["79914.00000000","2.44969000"],["79912.80000000","0.00000000"],["79912.75000000","0.00000000"],["79905.97000000","0.02000000"],["79904.77000000","0.00007000"],["79896.39000000","0.00000000"],["79896.33000000","0.00000000"],["79893.99000000","2.01508000"],["79847.10000000","0.12020000"],["79842.76000000","0.00000000"],["79835.11000000","0.00000000"],["79811.46000000","0.00400000"],["79790.59000000","0.04407000"],["71928.00000000","0.00583000"]],"a":[["79920.00000000","1.39662000"],["79920.01000000","0.00042000"],["79920.31000000","0.33807000"],["79922.01000000","0.01897000"],["79923.72000000","0.00000000"],["79923.78000000","0.06374000"],["79923.95000000","0.00000000"],["79923.96000000","0.00000000"],["79924.00000000","0.02435000"],["79924.06000000","0.14271000"],["79924.10000000","0.12393000"],["79924.96000000","0.00007000"],["79924.97000000","0.00014000"],["79925.99000000","0.00013000"],["79926.00000000","0.02407000"],["79926.27000000","0.00000000"],["79926.92000000","0.00007000"],["79926.99000000","0.02000000"],["79933.23000000","0.05707000"],["79936.75000000","0.00007000"],["79950.11000000","0.00000000"],["79990.09000000","0.00000000"],["80001.51000000","0.00000000"],["80022.07000000","0.00000000"],["80030.33000000","0.02804000"],["80070.04000000","0.00000000"],["80142.00000000","0.00000000"]]}}}
{"rx_ns": 13888996125200, "frame": {"stream":"btcusdt@depth@100ms","data":{"e":"depthUpdate","E":1787650884214,"s":"BTCUSDT","U":99118610421,"u":99118610440,"b":[["79919.99000000","2.34801000"],["79916.57000000","0.00007000"],["79915.01000000","0.00250000"],["79914.11000000","0.00000000"],["79913.00000000","1.54929000"],["79910.34000000","0.00007000"],["71928.00000000","0.00599000"],["63936.00000000","0.00363000"]],"a":[["79920.31000000","0.00014000"],["79921.78000000","0.00202000"],["79923.24000000","0.00007000"],["79923.77000000","0.00000000"],["79923.78000000","0.00014000"],["79930.09000000","0.00000000"],["79930.99000000","0.00250000"],["79950.92000000","0.00000000"],["79954.57000000","0.00000000"],["80046.92000000","0.01270000"],["80639.27000000","0.00010000"]]}}}
{"rx_ns": 13889096107800, "frame": {"stream":"btcusdt@depth@100ms","data":{"e":"depthUpdate","E":1787650884314,"s":"BTCUSDT","U":99118610441,"u":99118610522,"b":[["79919.99000000","2.34652000"],["79919.43000000","0.00718000"],["79917.08000000","0.00007000"],["79917.07000000","0.32275000"],["79914.01000000","0.00000000"],["79914.00000000","2.44962000"],["79890.00000000","2.05468000"],["79842.88000000","0.04655000"],["79817.97000000","0.00000000"],["71928.00000000","0.00599000"],["71927.99000000","0.00008000"],["63936.00000000","0.00363000"]],"a":[["79920.00000000","1.07765000"],["79920.01000000","0.00042000"],["79920.30000000","0.00000000"],["79920.31000000","0.00000000"],["79922.00000000","0.02428000"],["79922.01000000","0.01890000"],["79923.78000000","0.00000000"],["79923.96000000","0.00007000"],["79924.10000000","0.17318000"],["79924.97000000","0.00014000"],["79924.98000000","0.20278000"],["79925.24000000","0.01145000"],["79926.00000000","0.02414000"],["79926.27000000","0.00007000"],["79926.28000000","0.06361000"],["79926.92000000","0.00007000"],["79927.46000000","0.00000000"],["79927.55000000","0.00000000"],["79927.56000000","0.06361000"],["79927.61000000","0.12520000"],["79927.78000000","0.06361000"],["79928.49000000","0.00014000"],["79928.50000000","0.06434000"],["79929.98000000","0.06361000"],["79929.99000000","0.00000000"],["79931.33000000","0.00625000"],["79931.99000000","0.00000000"],["79948.97000000","0.12479000"],["79952.68000000","0.00399000"],["79956.62000000","1.20171000"],["79962.02000000","0.00000000"]]}}}
{"rx_ns": 13889195585600, "frame": {"stream":"btcusdt@depth@100ms","data":{"e":"depthUpdate","E":1787650884414,"s":"BTCUSDT","U":99118610523,"u":99118610572,"b":[["79917.08000000","0.00007000"],["79917.07000000","0.32275000"],["79914.01000000","0.00007000"],["79857.99000000","0.00200000"],["71928.00000000","0.00615000"]],"a":[["79920.00000000","1.07922000"],["79920.01000000","0.00049000"],["79922.01000000","0.01904000"],["79923.14000000","0.00007000"],["79923.15000000","0.05794000"],["79923.77000000","0.00007000"],["79923.78000000","0.06368000"],["79923.95000000","0.00007000"],["79923.96000000","0.06368000"],["79923.99000000","0.00007000"],["79924.05000000","0.00007000"],["79924.09000000","0.00007000"],["79924.96000000","0.00007000"],["79924.97000000","0.06245000"],["79926.27000000","0.00000000"],["79926.92000000","0.00000000"],["79927.78000000","0.00000000"],["79928.50000000","0.00073000"],["79929.98000000","0.00000000"],["79930.71000000","0.06271000"],["79950.44000000","0.00000000"],["79971.86000000","0.00425000"]]}}}
{"rx_ns": 13889297260900, "frame": {"stream":"btcusdt@depth@100ms","data":{"e":"depthUpdate","E":1787650884514,"s":"BTCUSDT","U":99118610573,"u":99118610616,"b":[["79917.08000000","0.00007000"],["79917.07000000","0.32275000"],["79914.01000000","0.00007000"],["79908.05000000","0.33797000"],["79885.80000000","0.00000000"],["79709.78000000","0.00770000"],["79688.21000000","0.00000000"],["78721.19000000","0.00030000"],["63936.00000000","0.00394000"]],"a":[["79920.00000000","1.39089000"],["79920.01000000","0.00056000"],["79922.01000000","0.01911000"],["79922.51000000","0.00007000"],["79922.52000000","0.06361000"],["79923.15000000","0.05808000"],["79923.78000000","0.06382000"],["79923.96000000","0.06375000"],["79923.99000000","0.00007000"],["79924.05000000","0.00007000"],["79924.09000000","0.00007000"],["79924.10000000","0.17304000"],["79924.98000000","0.20264000"],["79925.24000000","0.01131000"],["79927.60000000","0.06361000"],["79927.61000000","0.00000000"],["80072.61000000","0.00399000"]]}}}
{"rx_ns": 13889400535100, "frame": {"stream":"btcusdt@depth@100ms","data":{"e":"depthUpdate","E":1787650884614,"s":"BTCUSDT","U":99118610617,"u":99118610638,"b":[["79829.24000000","0.02000000"],["71928.00000000","0.00631000"],["63936.00000000","0.00363000"]],"a":[["79920.00000000","1.39102000"],["79920.01000000","0.00069000"],["79920.02000000","0.00013000"],["79922.01000000","0.01911000"],["79922.52000000","0.06375000"],["79923.24000000","0.00014000"],["79924.06000000","0.14257000"],["79924.97000000","0.00007000"],["79927.54000000","0.12520000"],["79927.60000000","0.00000000"],["79954.26000000","0.51226000"],["85500.00000000","26.61244000"]]}}}
{"rx_ns": 13889495415700, "frame": {"stream":"btcusdt@depth@100ms","data":{"e":"depthUpdate","E":1787650884714,"s":"BTCUSDT","U":99118610639,"u":99118610659,"b":[["79919.60000000","0.02204000"],["79917.08000000","0.00007000"],["79917.07000000","0.32275000"],["79914.01000000","0.00007000"],["71928.00000000","0.00631000"],["71927.99000000","0.00000000"],["71927.98000000","0.00008000"]],"a":[["79920.00000000","1.36001000"],["79922.51000000","0.00000000"],["79922.52000000","0.00014000"],["79923.96000000","0.06382000"],["79924.09000000","0.00007000"],["79927.54000000","0.00000000"],["80144.57000000","0.00399000"],["80299.71000000","0.00000000"],["80378.72000000","0.00000000"],["80380.53000000","0.01505000"],["80476.52000000","0.01503000"]]}}}
{"rx_ns": 13889595767800, "frame": {"stream":"btcusdt@depth@100ms","data":{"e":"depthUpdate","E":1787650884814,"s":"BTCUSDT","U":99118610660,"u":99118610699,"b":[["79919.99000000","2.34639000"],["79919.90000000","0.05021000"],["79919.61000000","0.00007000"],["79919.60000000","0.02218000"],["79919.37000000","0.00014000"],["79917.43000000","0.02396000"],["79917.42000000","0.00007000"],["79917.08000000","0.00007000"],["79917.07000000","0.32275000"],["79914.01000000","0.00000000"],["79860.69000000","0.02600000"],["79859.90000000","0.02000000"],["71928.00000000","0.00647000"],["71927.00000000","0.00020000"],["63935.99000000","0.00000000"]],"a":[["79922.01000000","0.01904000"],["79922.52000000","0.00000000"],["79923.99000000","0.00007000"],["79924.05000000","0.00007000"],["79924.06000000","0.14271000"],["79924.09000000","0.00007000"]]}}}
{"rx_ns": 13889696058800, "frame": {"stream":"btcusdt@depth@100ms","data":{"e":"depthUpdate","E":1787650884914,"s":"BTCUSDT","U":99118610700,"u":99118610731,"b":[["79919.43000000","0.00718000"],["79917.42000000","0.00007000"],["79917.08000000","0.00007000"],["79917.07000000","0.32275000"],["71928.00000000","0.00647000"],["71927.00000000","0.00000000"]],"a":[["79920.00000000","1.36060000"],["79920.01000000","0.00062000"],["79920.04000000","0.00330000"],["79923.95000000","0.00000000"],["79923.96000000","0.00021000"],["79924.05000000","0.00007000"],["79924.09000000","0.00007000"],["79924.97000000","0.00014000"],["79929.91000000","0.06259000"],["79930.54000000","0.06259000"],["79933.02000000","0.06259000"],["79992.66000000","0.00399000"],["81118.80000000","0.00030000"]]}}}
{"rx_ns": 13889801053400, "frame": {"stream":"btcusdt@depth20","data":{"lastUpdateId":99118610791,"bids":[["79919.99000000","2.34841000"],["79919.98000000","0.00027000"],["79919.97000000","0.00013000"],["79919.96000000","0.00007000"],["79919.95000000","0.05021000"],["79919.91000000","0.00007000"],["79919.90000000","0.05021000"],["79919.61000000","0.00007000"],["79919.60000000","0.02218000"],["79919.43000000","0.00718000"],["79919.37000000","0.00014000"],["79918.83000000","0.00007000"],["79918.72000000","0.00007000"],["79918.71000000","0.02031000"],["79918.65000000","0.00007000"],["79918.64000000","0.04068000"],["79918.07000000","0.00935000"],["79918.03000000","0.00007000"],["79917.44000000","0.00007000"],["79917.43000000","0.02396000"]],"asks":[["79920.00000000","1.36081000"],["79920.01000000","0.00076000"],["79920.02000000","0.00013000"],["79920.04000000","0.00330000"],["79920.16000000","0.00075000"],["79920.24000000","0.00007000"],["79921.02000000","0.00007000"],["79921.03000000","0.33793000"],["79921.78000000","0.00202000"],["79921.99000000","0.00007000"],["79922.00000000","0.02421000"],["79922.01000000","0.01904000"],["79922.42000000","0.00413000"],["79922.82000000","0.00007000"],["79923.15000000","0.00014000"],["79923.24000000","0.00014000"],["79923.78000000","0.00014000"],["79923.88000000","0.00026000"],["79923.97000000","0.01603000"],["79923.99000000","0.00007000"]]}}}
{"rx_ns": 13889801137500, "frame": {"stream":"btcusdt@depth@100ms","data":{"e":"depthUpdate","E":1787650885014,"s":"BTCUSDT","U":99118610732,"u":99118610791,"b":[["79919.99000000","2.34841000"],["79917.42000000","0.00000000"],["79917.08000000","0.00000000"],["79917.07000000","0.32268000"],["79915.04000000","0.00625000"],["79914.50000000","0.00000000"],["79841.53000000","0.62545000"],["79835.11000000","0.02200000"],["71928.00000000","0.00663000"],["63936.00000000","0.00394000"],["63935.99000000","0.00000000"]],"a":[["79920.00000000","1.36081000"],["79920.01000000","0.00076000"],["79921.02000000","0.00007000"],["79921.03000000","0.33793000"],["79922.00000000","0.02421000"],["79923.14000000","0.00000000"],["79923.15000000","0.00014000"],["79923.77000000","0.00000000"],["79923.78000000","0.00014000"],["79923.96000000","0.00000000"],["79924.09000000","0.00007000"],["79924.10000000","0.17318000"],["79924.97000000","0.00014000"],["79926.00000000","0.02414000"],["79926.19000000","0.00007000"],["79926.20000000","0.06259000"],["79926.28000000","0.00000000"],["79926.29000000","0.02259000"],["79926.65000000","0.00000000"],["79926.92000000","0.00007000"],["79928.50000000","0.06332000"],["79929.91000000","0.00000000"],["79930.53000000","0.00625000"],["79930.71000000","0.00000000"],["79931.33000000","0.00000000"],["79933.02000000","0.00000000"],["79933.23000000","0.00000000"]]}}}
{"rx_ns": 13889899490000, "frame": {"stream":"btcusdt@depth@100ms","data":{"e":"depthUpdate","E":1787650885114,"s":"BTCUSDT","U":99118610792,"u":99118612128,"b":[["79919.99000000","0.00000000"],["79919.98000000","0.00000000"],["79919.97000000","0.00000000"],["79919.96000000","0.00000000"],["79919.95000000","0.00000000"],["79919.91000000","0.00000000"],["79919.90000000","0.00000000"],["79919.61000000","0.00000000"],["79919.60000000","0.00000000"],["79919.43000000","0.00000000"],["79919.37000000","0.00000000"],["79918.83000000","0.00000000"],["79918.72000000","0.00000000"],["79918.71000000","0.00000000"],["79918.65000000","0.00000000"],["79918.64000000","0.00000000"],["79918.20000000","0.00000000"],["79918.19000000","0.00000000"],["79918.07000000","0.00000000"],["79918.03000000","0.00000000"],["79917.44000000","0.00000000"],["79917.43000000","0.00000000"],["79917.42000000","0.00000000"],["79917.41000000","0.00000000"],["79917.08000000","0.00000000"],["79917.07000000","0.00000000"],["79917.06000000","0.00000000"],["79916.97000000","0.00000000"],["79916.96000000","0.00000000"],["79916.57000000","0.00000000"],["79916.52000000","0.00000000"],["79916.43000000","0.00000000"],["79916.27000000","0.00000000"],["79916.20000000","0.00000000"],["79916.16000000","0.00000000"],["79916.15000000","0.01538000"],["79916.14000000","0.00042000"],["79915.53000000","0.00014000"],["79915.52000000","0.00000000"],["79915.50000000","0.00007000"],["79915.47000000","0.00000000"],["79915.04000000","0.00021000"],["79915.03000000","0.00007000"],["79915.01000000","0.00000000"],["79914.90000000","0.00000000"],["79914.49000000","0.00000000"],["79914.42000000","0.00007000"],["79914.41000000","0.00007000"],["79914.37000000","0.00000000"],["79914.01000000","0.00007000"],["79914.00000000","0.00028000"],["79913.99000000","0.00035000"],["79913.92000000","0.00000000"],["79913.86000000","0.00007000"],["79913.85000000","0.31312000"],["79913.84000000","0.00021000"],["79913.55000000","0.05359000"],["79913.52000000","0.00000000"],["79913.13000000","0.00007000"],["79913.12000000","0.00014000"],["79913.04000000","0.00000000"],["79913.01000000","0.00021000"],["79913.00000000","0.00007000"],["79912.36000000","0.00007000"],["79912.05000000","0.00000000"],["79912.04000000","0.00000000"],["79912.00000000","0.00014000"],["79911.99000000","0.00061000"],["79911.63000000","0.00007000"],["79911.62000000","0.00000000"],["79911.53000000","0.00000000"],["79910.82000000","0.00000000"],["79910.81000000","0.00115000"],["79910.80000000","0.12538000"],["79910.57000000","0.00000000"],["79910.56000000","0.00000000"],["79910.50000000","0.07895000"],["79910.49000000","0.00000000"],["79910.35000000","0.02259000"],["79910.00000000","0.00707000"],["79909.96000000","0.00000000"],["79909.90000000","0.00007000"],["79909.66000000","0.00000000"],["79909.63000000","0.00000000"],["79909.59000000","0.00000000"],["79909.51000000","0.00000000"],["79909.45000000","0.00008000"],["79909.16000000","0.00000000"],["79909.15000000","0.00932000"],["79909.07000000","0.08583000"],["79908.82000000","0.00000000"],["79908.43000000","0.00000000"],["79908.10000000","0.00000000"],["79908.08000000","0.00000000"],["79908.05000000","0.00000000"],["79907.86000000","0.02000000"],["79907.76000000","0.00007000"],["79906.77000000","0.00000000"],["79906.69000000","0.00189000"],["79906.40000000","0.07000000"],["79906.13000000","0.00047000"],["79905.80000000","0.00000000"],["79905.70000000","0.00000000"],["79905.69000000","0.00000000"],["79905.56000000","0.00000000"],["79905.50000000","0.08000000"],["79904.82000000","0.00153000"],["79904.77000000","0.00007000"],["79904.12000000","0.00625000"],["79903.92000000","0.00000000"],["79903.69000000","0.00000000"],["79902.78000000","0.00000000"],["79902.75000000","0.00000000"],["79902.74000000","0.00000000"],["79902.29000000","0.00000000"],["79902.03000000","0.00007000"],["79901.53000000","0.00625000"],["79901.26000000","0.00000000"],["79900.87000000","0.00000000"],["79900.56000000","0.00000000"],["79900.09000000","0.00000000"],["79900.02000000","0.00014000"],["79900.01000000","0.00008000"],["79900.00000000","1.07346000"],["79899.41000000","0.00000000"],["79899.36000000","0.32672000"],["79899.35000000","0.00000000"],["79898.00000000","0.02400000"],["79897.14000000","0.00000000"],["79896.97000000","0.00000000"],["79896.13000000","0.00000000"],["79895.00000000","0.00000000"],["79894.43000000","0.00000000"],["79894.01000000","0.00000000"],["79893.41000000","0.00000000"],["79893.03000000","0.00000000"],["79892.67000000","0.00000000"],["79892.32000000","0.00000000"],["79892.01000000","0.00000000"],["79891.67000000","0.00000000"],["79891.19000000","0.00000000"],["79890.44000000","0.00000000"],["79890.32000000","0.04425000"],["79890.07000000","0.00000000"],["79890.01000000","0.00007000"],["79890.00000000","2.05217000"],["79889.05000000","0.00000000"],["79888.02000000","0.39773000"],["79887.37000000","0.00625000"],["79887.29000000","0.33805000"],["79886.37000000","0.00000000"],["79886.01000000","0.62586000"],["79885.73000000","0.33806000"],["79882.14000000","0.36586000"],["79882.13000000","0.00000000"],["79880.00000000","0.12041000"],["79878.00000000","0.03400000"],["79876.80000000","0.00014000"],["79876.31000000","0.00000000"],["79874.63000000","0.00400000"],["79872.93000000","0.00007000"],["79872.10000000","0.00400000"],["79869.57000000","0.00400000"],["79869.06000000","0.00007000"],["79868.61000000","0.00007000"],["79864.51000000","0.00400000"],["79852.01000000","0.00000000"],["79850.87000000","1.24011000"],["79850.06000000","0.00311000"],["79847.11000000","0.00311000"],["79847.10000000","0.61356000"],["79846.22000000","0.00000000"],["79846.12000000","0.00000000"],["79844.01000000","0.00007000"],["79843.41000000","0.00400000"],["79842.76000000","1.06886000"],["79842.26000000","0.00000000"],["79841.53000000","0.00000000"],["79837.71000000","1.71464000"],["79813.31000000","0.00000000"],["79781.43000000","0.20250000"],["79773.43000000","0.20250000"],["79770.62000000","0.00000000"],["79766.67000000","0.00125000"],["79519.50000000","0.00014000"],["78721.19000000","0.00000000"],["71928.00000000","0.00407000"],["71927.98000000","0.00000000"]],"a":[["79916.16000000","6.34473000"],["79916.17000000","0.00027000"],["79916.18000000","0.00013000"],["79916.28000000","0.00000000"],["79916.44000000","0.00000000"],["79916.52000000","0.07500000"],["79916.53000000","0.00000000"],["79916.58000000","0.00000000"],["79916.78000000","0.00000000"],["79916.97000000","1.44864000"],["79916.98000000","3.71858000"],["79916.99000000","0.00000000"],["79917.00000000","0.00000000"],["79917.07000000","0.00000000"],["79917.20000000","0.00250000"],["79917.42000000","0.00000000"],["79917.43000000","0.07500000"],["79917.44000000","0.63648000"],["79917.45000000","0.00000000"],["79917.64000000","0.00400000"],["79917.80000000","0.00157000"],["79918.02000000","0.00000000"],["79918.04000000","0.00000000"],["79918.06000000","0.00000000"],["79918.07000000","0.00000000"],["79918.08000000","0.56857000"],["79918.09000000","0.00007000"],["79918.20000000","0.00000000"],["79918.21000000","0.00000000"],["79918.65000000","0.00000000"],["79918.72000000","0.00000000"],["79918.84000000","0.00000000"],["79919.14000000","0.04652000"],["79919.33000000","0.00000000"],["79919.37000000","0.00014000"],["79919.38000000","0.00000000"],["79919.44000000","0.00000000"],["79919.46000000","0.00000000"],["79919.61000000","0.19978000"],["79919.91000000","0.00000000"],["79919.92000000","0.00000000"],["79919.94000000","0.00000000"],["79919.96000000","0.00000000"],["79919.97000000","0.00000000"],["79919.98000000","0.00000000"],["79919.99000000","2.69258000"],["79920.00000000","1.74975000"],["79920.01000000","0.00000000"],["79920.02000000","0.00000000"],["79920.17000000","0.00400000"],["79920.62000000","0.00007000"],["79920.96000000","0.00689000"],["79921.01000000","0.00000000"],["79921.02000000","0.00000000"],["79921.03000000","0.00021000"],["79921.06000000","0.00000000"],["79921.17000000","0.04815000"],["79921.77000000","0.00000000"],["79921.78000000","0.00000000"],["79921.86000000","0.00000000"],["79921.99000000","0.00000000"],["79922.01000000","0.01904000"],["79922.48000000","0.00007000"],["79922.70000000","0.00400000"],["79922.99000000","0.00000000"],["79923.10000000","0.00000000"],["79923.15000000","0.00000000"],["79923.17000000","0.00695000"],["79923.23000000","0.00000000"],["79923.64000000","0.12511000"],["79923.72000000","0.00000000"],["79923.77000000","0.00000000"],["79923.78000000","0.00000000"],["79923.90000000","0.03224000"],["79923.96000000","0.00000000"],["79923.97000000","0.01589000"],["79923.99000000","0.00000000"],["79924.00000000","0.02421000"],["79924.05000000","0.00000000"],["79924.06000000","0.00000000"],["79924.09000000","0.00000000"],["79924.10000000","0.12379000"],["79924.27000000","0.00007000"],["79924.80000000","0.00000000"],["79924.90000000","0.00000000"],["79924.96000000","0.00007000"],["79924.97000000","0.00007000"],["79924.98000000","0.20264000"],["79925.28000000","0.00008000"],["79925.34000000","0.00722000"],["79925.43000000","0.00008000"],["79925.79000000","0.02000000"],["79925.98000000","0.00625000"],["79925.99000000","0.00000000"],["79926.00000000","0.02407000"],["79926.14000000","0.00000000"],["79926.19000000","0.00000000"],["79926.20000000","0.00000000"],["79926.46000000","0.00000000"],["79926.52000000","0.01357000"],["79926.82000000","0.00000000"],["79926.92000000","0.00000000"],["79926.93000000","0.00000000"],["79927.44000000","0.00000000"],["79927.50000000","0.00000000"],["79927.55000000","0.00000000"],["79927.56000000","0.00000000"],["79927.78000000","0.00000000"],["79927.87000000","0.00000000"],["79927.88000000","0.82080000"],["79927.99000000","0.00000000"],["79928.01000000","0.12511000"],["79928.48000000","0.00000000"],["79928.49000000","0.00000000"],["79928.50000000","0.00000000"],["79928.59000000","0.03000000"],["79929.30000000","0.00000000"],["79929.46000000","1.87677000"],["79929.62000000","1.04939000"],["79929.91000000","0.00000000"],["79930.03000000","0.00000000"],["79930.53000000","0.00000000"],["79930.54000000","0.00000000"],["79930.99000000","0.00000000"],["79931.07000000","0.00000000"],["79931.16000000","0.00000000"],["79931.34000000","0.00000000"],["79931.60000000","0.03224000"],["79931.75000000","0.26653000"],["79931.94000000","0.00000000"],["79931.95000000","0.00000000"],["79931.96000000","0.36988000"],["79932.10000000","0.00000000"],["79932.11000000","0.02000000"],["79932.35000000","0.33786000"],["79933.02000000","0.00000000"],["79933.61000000","0.62586000"],["79933.62000000","1.04939000"],["79933.64000000","0.00000000"],["79933.78000000","0.00000000"],["79933.79000000","0.00000000"],["79933.87000000","0.00000000"],["79934.41000000","0.00400000"],["79934.49000000","0.00000000"],["79935.12000000","0.00000000"],["79935.50000000","0.00000000"],["79935.73000000","0.00000000"],["79935.74000000","0.00400000"],["79936.60000000","0.04000000"],["79936.75000000","0.00007000"],["79939.80000000","0.44143000"],["79939.89000000","0.62562000"],["79940.32000000","0.00000000"],["79940.33000000","0.00000000"],["79943.79000000","0.00000000"],["79945.09000000","0.00000000"],["79946.71000000","0.33780000"],["79947.63000000","1.53124000"],["79947.81000000","0.00000000"],["79951.99000000","1.23854000"],["79952.67000000","0.00000000"],["79953.06000000","0.00400000"],["79956.12000000","0.00000000"],["79957.68000000","0.00000000"],["79958.07000000","0.00000000"],["79960.16000000","0.00000000"],["79960.78000000","0.00000000"],["79961.94000000","0.00000000"],["79962.13000000","0.00000000"],["79962.64000000","0.00000000"],["79964.82000000","0.00000000"],["79965.12000000","0.00000000"],["79972.55000000","0.00000000"],["79982.26000000","0.00000000"],["79984.94000000","0.00312000"],["79985.28000000","0.00312000"],["79987.27000000","0.00000000"],["79988.16000000","0.00000000"],["80013.10000000","0.00000000"],["80021.54000000","0.00556000"],["80024.64000000","0.00399000"],["80069.17000000","0.00000000"],["80078.76000000","0.00000000"],["80105.46000000","3.74598000"],["80123.70000000","0.00000000"],["81118.80000000","0.00000000"]]}}}
{"rx_ns": 13889997492900, "frame": {"stream":"btcusdt@depth@100ms","data":{"e":"depthUpdate","E":1787650885214,"s":"BTCUSDT","U":99118612129,"u":99118613239,"b":[["79916.15000000","0.00000000"],["79916.14000000","0.00000000"],["79915.99000000","0.00000000"],["79915.53000000","0.00000000"],["79915.50000000","0.00000000"],["79915.04000000","0.00000000"],["79915.03000000","0.00000000"],["79914.42000000","0.00000000"],["79914.41000000","0.00000000"],["79914.01000000","0.00000000"],["79914.00000000","0.00000000"],["79913.99000000","0.00000000"],["79913.98000000","0.00000000"],["79913.86000000","0.00000000"],["79913.85000000","0.00000000"],["79913.84000000","0.00000000"],["79913.56000000","0.00000000"],["79913.55000000","0.00000000"],["79913.13000000","0.00000000"],["79913.12000000","0.00000000"],["79913.01000000","0.00000000"],["79913.00000000","0.00000000"],["79912.42000000","0.00000000"],["79912.36000000","0.00000000"],["79912.00000000","0.00000000"],["79911.99000000","0.00000000"],["79911.63000000","0.00000000"],["79910.81000000","0.00000000"],["79910.80000000","0.02173000"],["79910.79000000","0.00077000"],["79910.51000000","0.00007000"],["79910.50000000","0.07909000"],["79910.36000000","0.00007000"],["79910.35000000","0.02273000"],["79910.34000000","0.00000000"],["79910.00000000","0.00735000"],["79909.53000000","0.00007000"],["79909.52000000","0.01754000"],["79909.45000000","0.00000000"],["79909.26000000","0.00000000"],["79909.25000000","0.00007000"],["79909.21000000","0.00000000"],["79909.20000000","0.00007000"],["79909.15000000","0.00021000"],["79909.09000000","0.00000000"],["79909.08000000","0.00000000"],["79909.07000000","0.00021000"],["79908.59000000","0.00202000"],["79908.51000000","0.00021000"],["79908.48000000","0.00000000"],["79908.47000000","0.00000000"],["79908.28000000","0.33793000"],["79908.26000000","0.00000000"],["79908.25000000","0.00007000"],["79908.24000000","0.02096000"],["79908.21000000","0.00007000"],["79908.20000000","0.05360000"],["79908.00000000","0.00742000"],["79907.87000000","0.00000000"],["79907.86000000","0.00021000"],["79907.70000000","0.06273000"],["79907.18000000","0.00000000"],["79907.09000000","0.00007000"],["79907.08000000","0.06260000"],["79906.97000000","0.00007000"],["79906.96000000","0.02103000"],["79906.77000000","0.00000000"],["79906.76000000","0.00007000"],["79906.70000000","0.00000000"],["79906.69000000","0.00000000"],["79906.47000000","0.00007000"],["79906.46000000","0.06260000"],["79906.44000000","0.00007000"],["79906.41000000","0.00000000"],["79906.40000000","0.00007000"],["79906.35000000","0.00675000"],["79906.13000000","0.00000000"],["79906.02000000","0.00007000"],["79906.01000000","0.06260000"],["79906.00000000","0.00714000"],["79905.99000000","0.68487000"],["79905.98000000","0.31294000"],["79905.97000000","0.00007000"],["79905.96000000","0.00007000"],["79905.91000000","0.00007000"],["79905.90000000","0.00000000"],["79905.89000000","0.00014000"],["79905.82000000","0.00715000"],["79905.51000000","0.00000000"],["79905.50000000","0.15007000"],["79905.35000000","0.02000000"],["79905.01000000","0.00000000"],["79904.82000000","0.00000000"],["79904.77000000","0.00000000"],["79904.76000000","0.00000000"],["79904.60000000","0.06260000"],["79904.41000000","0.00000000"],["79904.40000000","0.00694000"],["79904.38000000","0.00000000"],["79904.37000000","0.06152000"],["79904.31000000","0.00000000"],["79904.30000000","0.12514000"],["79904.12000000","0.00000000"],["79904.02000000","0.00000000"],["79904.01000000","0.06259000"],["79903.89000000","0.00014000"],["79903.57000000","0.00000000"],["79902.90000000","0.02479000"],["79902.81000000","0.00008000"],["79902.77000000","0.00000000"],["79902.76000000","0.00000000"],["79902.73000000","0.78636000"],["79902.08000000","0.00000000"],["79901.97000000","0.00000000"],["79901.96000000","0.00000000"],["79901.89000000","0.00000000"],["79901.53000000","0.00000000"],["79901.14000000","0.00048000"],["79901.01000000","0.00697000"],["79900.09000000","0.00008000"],["79900.08000000","0.00000000"],["79900.01000000","0.00000000"],["79899.49000000","0.00007000"],["79899.36000000","0.25609000"],["79898.75000000","0.00000000"],["79898.61000000","0.00250000"],["79898.43000000","0.00000000"],["79898.01000000","0.00008000"],["79897.79000000","0.49770000"],["79897.23000000","0.00000000"],["79897.01000000","0.00719000"],["79896.71000000","0.00153000"],["79896.31000000","0.12516000"],["79896.16000000","0.01250000"],["79896.12000000","0.00000000"],["79896.01000000","0.00061000"],["79895.62000000","0.00000000"],["79895.58000000","0.00007000"],["79895.00000000","0.00000000"],["79894.01000000","0.00808000"],["79893.01000000","0.00719000"],["79892.66000000","0.00000000"],["79892.02000000","0.00000000"],["79891.57000000","0.09462000"],["79890.32000000","0.00000000"],["79890.02000000","0.00008000"],["79890.00000000","1.35217000"],["79889.57000000","0.10373000"],["79889.01000000","0.00708000"],["79888.73000000","0.00000000"],["79888.02000000","0.00054000"],["79887.58000000","0.00000000"],["79887.51000000","0.38961000"],["79886.02000000","0.00015000"],["79886.01000000","0.00000000"],["79886.00000000","0.12859000"],["79884.03000000","0.00000000"],["79882.15000000","0.58846000"],["79882.02000000","0.00008000"],["79881.94000000","0.00000000"],["79881.43000000","0.62591000"],["79881.01000000","0.04559000"],["79880.03000000","0.00000000"],["79879.25000000","0.12501000"],["79878.03000000","0.02108000"],["79878.00000000","0.02400000"],["79876.00000000","0.02400000"],["79874.03000000","0.00008000"],["79874.00000000","0.02400000"],["79873.99000000","1.96154000"],["79873.98000000","0.36586000"],["79873.76000000","1.01110000"],["79872.93000000","0.00014000"],["79872.28000000","0.65015000"],["79870.00000000","0.03400000"],["79868.81000000","0.00000000"],["79866.44000000","0.00000000"],["79865.19000000","0.00000000"],["79864.97000000","0.00000000"],["79863.66000000","0.00000000"],["79861.13000000","0.00012000"],["79859.45000000","0.00400000"],["79856.67000000","0.00631000"],["79851.72000000","0.00428000"],["79850.06000000","0.00000000"],["79842.89000000","0.00312000"],["79842.09000000","0.00000000"],["79841.49000000","0.00000000"],["79841.10000000","0.00000000"],["79840.07000000","0.00000000"],["79839.96000000","0.00000000"],["79839.83000000","0.00000000"],["79839.69000000","0.00000000"],["79839.49000000","0.00000000"],["79839.38000000","0.00000000"],["79839.32000000","0.11936000"],["79833.58000000","0.79406000"],["79830.89000000","0.00008000"],["79826.42000000","1.87677000"],["79819.31000000","0.00025000"],["79791.16000000","0.00000000"],["79790.59000000","0.00000000"],["79783.50000000","0.00011000"],["79777.80000000","0.04532000"],["79770.25000000","0.00000000"],["79760.15000000","0.00000000"],["79753.11000000","1.49938000"],["79750.98000000","0.00008000"],["79692.41000000","0.00007000"],["79689.35000000","0.00007000"],["79685.36000000","0.00007000"],["79680.44000000","0.00007000"],["79680.23000000","0.00000000"],["79671.07000000","0.00008000"],["79602.97000000","0.00000000"],["79600.31000000","0.00000000"],["79591.16000000","0.00008000"],["79520.39000000","0.00000000"],["79511.25000000","0.00008000"],["79440.47000000","0.00000000"],["79431.34000000","0.00008000"],["79360.55000000","0.00000000"],["79351.42000000","0.00008000"],["71919.72000000","0.00032000"],["63936.00000000","0.00363000"]],"a":[["79910.81000000","2.83040000"],["79910.82000000","0.00062000"],["79910.83000000","0.00013000"],["79910.95000000","0.00690000"],["79911.43000000","0.00000000"],["79911.63000000","0.00014000"],["79912.00000000","0.00000000"],["79912.01000000","0.00000000"],["79912.05000000","0.00000000"],["79912.37000000","0.00000000"],["79912.40000000","0.00000000"],["79912.58000000","0.00400000"],["79912.61000000","0.00000000"],["79912.67000000","0.00000000"],["79913.01000000","0.00000000"],["79913.13000000","0.00000000"],["79913.14000000","0.00000000"],["79913.28000000","0.07145000"],["79913.29000000","0.06260000"],["79913.56000000","0.00021000"],["79913.77000000","0.00007000"],["79913.78000000","0.06267000"],["79913.79000000","0.04673000"],["79913.85000000","0.00000000"],["79913.86000000","0.00000000"],["79913.87000000","0.00000000"],["79913.97000000","0.00007000"],["79913.98000000","0.06267000"],["79913.99000000","0.07507000"],["79914.00000000","0.05656000"],["79914.01000000","0.00000000"],["79914.02000000","0.00000000"],["79914.42000000","0.00000000"],["79914.58000000","0.00250000"],["79914.62000000","0.00000000"],["79915.04000000","0.00000000"],["79915.05000000","0.00000000"],["79915.11000000","0.00400000"],["79915.24000000","0.00000000"],["79915.29000000","0.00000000"],["79915.50000000","0.00014000"],["79915.51000000","0.00000000"],["79915.54000000","0.00000000"],["79915.86000000","0.00000000"],["79915.99000000","1.09016000"],["79916.00000000","0.00000000"],["79916.15000000","1.12327000"],["79916.16000000","2.73942000"],["79916.17000000","0.00000000"],["79916.18000000","0.00000000"],["79916.51000000","0.00625000"],["79916.52000000","0.07528000"],["79916.97000000","0.00014000"],["79916.98000000","1.40909000"],["79917.03000000","0.00718000"],["79917.20000000","0.00000000"],["79917.43000000","0.07514000"],["79917.44000000","0.29639000"],["79917.80000000","0.00000000"],["79918.08000000","0.21194000"],["79918.09000000","0.00000000"],["79918.44000000","0.36586000"],["79918.64000000","0.00007000"],["79918.80000000","0.00008000"],["79919.14000000","0.00007000"],["79919.61000000","0.19985000"],["79919.98000000","0.57741000"],["79919.99000000","1.34417000"],["79920.00000000","1.74666000"],["79920.62000000","0.00000000"],["79920.72000000","0.00007000"],["79920.79000000","0.00007000"],["79921.03000000","0.00007000"],["79921.07000000","0.00007000"],["79921.10000000","0.00000000"],["79921.99000000","0.00000000"],["79922.00000000","0.02407000"],["79922.01000000","0.01876000"],["79922.48000000","0.00000000"],["79923.17000000","0.00695000"],["79923.27000000","0.00007000"],["79923.64000000","0.00000000"],["79923.97000000","0.00904000"],["79924.00000000","0.02400000"],["79924.10000000","0.08804000"],["79924.11000000","0.00000000"],["79924.45000000","0.08576000"],["79924.77000000","0.00191000"],["79924.79000000","0.00000000"],["79924.96000000","0.00000000"],["79924.97000000","0.00000000"],["79924.98000000","0.00000000"],["79925.24000000","0.00000000"],["79925.34000000","0.00708000"],["79925.43000000","0.00000000"],["79926.00000000","0.02400000"],["79926.29000000","0.02252000"],["79926.46000000","0.00000000"],["79926.52000000","0.00000000"],["79926.89000000","0.09458000"],["79927.56000000","0.00007000"],["79927.68000000","0.00330000"],["79927.80000000","0.00000000"],["79928.89000000","0.10361000"],["79929.34000000","0.00000000"],["79929.98000000","0.00008000"],["79930.00000000","0.11784000"],["79930.67000000","0.00000000"],["79931.62000000","0.00000000"],["79931.96000000","0.60602000"],["79932.36000000","0.00000000"],["79933.34000000","0.00000000"],["79933.62000000","1.04939000"],["79933.98000000","0.00015000"],["79934.81000000","0.00250000"],["79935.98000000","0.00000000"],["79936.75000000","0.00000000"],["79937.34000000","0.00007000"],["79937.80000000","0.00000000"],["79937.97000000","0.00008000"],["79939.80000000","0.33783000"],["79939.98000000","0.00000000"],["79940.00000000","0.33685000"],["79941.97000000","0.00008000"],["79942.18000000","0.00000000"],["79943.98000000","0.00125000"],["79945.97000000","0.00008000"],["79946.39000000","0.00000000"],["79947.97000000","0.00920000"],["79949.96000000","0.00008000"],["79950.00000000","0.12510000"],["79950.53000000","0.00400000"],["79951.03000000","0.00000000"],["79951.95000000","0.02422000"],["79951.97000000","0.00000000"],["79953.06000000","0.00000000"],["79953.96000000","0.00008000"],["79954.20000000","0.00000000"],["79955.20000000","0.00000000"],["79955.96000000","0.00000000"],["79955.98000000","0.00428000"],["79959.00000000","0.00000000"],["79959.50000000","0.00427000"],["79959.62000000","0.00000000"],["79959.96000000","0.00360000"],["79960.00000000","1.02515000"],["79968.22000000","0.00000000"],["79971.86000000","0.00000000"],["79990.72000000","0.00008000"],["79999.92000000","0.00310000"],["80017.50000000","0.02804000"],["80019.11000000","0.00025000"],["80024.64000000","0.00000000"],["80030.33000000","0.00000000"],["80044.53000000","0.15147000"],["80045.28000000","0.25000000"],["80051.50000000","0.09345000"],["80054.48000000","0.00000000"],["80056.74000000","1.50102000"],["80070.63000000","0.00008000"],["80073.95000000","0.00000000"],["80079.84000000","0.00260000"],["80150.54000000","0.00008000"],["80159.76000000","0.00000000"],["80161.40000000","0.00000000"],["80199.92000000","0.00000000"],["80310.36000000","0.00155000"],["80319.60000000","0.00000000"],["80470.19000000","0.00008000"],["80479.44000000","0.00000000"],["80550.10000000","0.00008000"],["80559.36000000","0.00000000"],["80639.27000000","0.00000000"]]}}}
{"rx_ns": 13890096385200, "kind": "control", "ctl": {"op": "ping", "recv_ns": 13890032425500, "pong_ns": 13890032629800, "payload_len": 13, "payload_b64": "MTc4NzY1MDg4NTIzOQ=="}, "frame": null}
{"rx_ns": 13890096385200, "frame": {"stream":"btcusdt@depth@100ms","data":{"e":"depthUpdate","E":1787650885314,"s":"BTCUSDT","U":99118613240,"u":99118613439,"b":[["79910.80000000","0.02265000"],["79910.79000000","0.00077000"],["79910.00000000","0.00735000"],["79909.52000000","0.01782000"],["79909.50000000","0.00000000"],["79909.15000000","0.00007000"],["79909.07000000","0.00007000"],["79908.81000000","0.00007000"],["79908.80000000","0.02173000"],["79908.65000000","0.00202000"],["79908.59000000","0.00000000"],["79908.51000000","0.00007000"],["79908.33000000","0.00007000"],["79908.32000000","0.06273000"],["79908.29000000","0.00000000"],["79908.28000000","0.00014000"],["79908.25000000","0.00007000"],["79908.24000000","0.02110000"],["79908.20000000","0.05374000"],["79908.00000000","0.00735000"],["79907.86000000","0.00007000"],["79907.71000000","0.00000000"],["79907.70000000","0.00000000"],["79907.09000000","0.00000000"],["79907.08000000","0.00000000"],["79906.97000000","0.00007000"],["79906.47000000","0.00007000"],["79906.02000000","0.00007000"],["79906.00000000","0.00714000"],["79905.99000000","0.68480000"],["79905.82000000","0.00708000"],["79905.50000000","0.15000000"],["79904.60000000","0.00000000"],["79904.37000000","0.00000000"],["79904.22000000","0.03618000"],["79904.01000000","0.00000000"],["79903.12000000","0.00000000"],["79899.75000000","0.00190000"],["79899.61000000","0.08576000"],["79898.61000000","0.00000000"],["79897.45000000","0.00000000"],["79883.36000000","0.00000000"],["79875.00000000","0.00000000"],["79867.04000000","0.00400000"],["79865.50000000","0.83188000"],["79843.41000000","0.00000000"],["79839.32000000","0.00000000"],["79839.30000000","0.00000000"],["79811.46000000","0.00000000"],["79777.80000000","0.00000000"],["79763.53000000","0.00000000"],["79753.11000000","0.00000000"],["79721.39000000","0.01414000"],["79702.97000000","0.00000000"],["79691.63000000","0.00000000"],["79680.44000000","0.00000000"],["79593.81000000","0.00035000"],["71919.72000000","0.00048000"],["63936.00000000","0.00363000"]],"a":[["79910.81000000","2.94403000"],["79910.82000000","0.00069000"],["79910.95000000","0.00711000"],["79912.86000000","0.00835000"],["79913.27000000","0.00007000"],["79913.28000000","0.05733000"],["79913.29000000","0.00014000"],["79913.42000000","0.00000000"],["79913.56000000","0.00007000"],["79913.78000000","0.06281000"],["79913.79000000","0.04687000"],["79913.97000000","0.00000000"],["79913.98000000","0.00021000"],["79913.99000000","0.07521000"],["79914.00000000","0.05649000"],["79914.14000000","0.01387000"],["79914.58000000","0.00000000"],["79915.15000000","0.06197000"],["79915.42000000","0.01657000"],["79915.77000000","0.06273000"],["79915.84000000","0.00026000"],["79915.98000000","0.06273000"],["79916.16000000","2.73928000"],["79916.52000000","0.07514000"],["79916.70000000","0.01657000"],["79916.97000000","0.00000000"],["79916.98000000","1.40895000"],["79917.43000000","0.07500000"],["79918.08000000","0.00944000"],["79920.00000000","1.54382000"],["79921.03000000","0.00000000"],["79921.17000000","0.00000000"],["79922.00000000","0.02400000"],["79938.34000000","0.00012000"],["79951.00000000","0.01000000"],["79952.68000000","0.00000000"],["79961.73000000","0.83088000"],["79992.66000000","0.00000000"],["80017.50000000","0.00000000"],["80024.51000000","0.00000000"],["80056.74000000","0.00164000"],["80072.61000000","0.00000000"],["80083.73000000","0.00000000"],["80144.57000000","0.00000000"],["80190.68000000","0.00032000"],["80219.69000000","0.02388000"]]}}}
{"rx_ns": 13890196253700, "frame": {"stream":"btcusdt@depth@100ms","data":{"e":"depthUpdate","E":1787650885414,"s":"BTCUSDT","U":99118613440,"u":99118613515,"b":[["79909.52000000","0.01775000"],["79909.24000000","0.00007000"],["79908.81000000","0.00000000"],["79908.80000000","0.00014000"],["79908.65000000","0.00000000"],["79908.32000000","0.06287000"],["79908.28000000","0.00000000"],["79908.00000000","0.00721000"],["79907.08000000","0.06017000"],["79906.85000000","0.00007000"],["79905.88000000","0.03013000"],["79904.40000000","0.00000000"],["79904.25000000","0.00714000"],["79904.22000000","0.00000000"],["79891.17000000","0.37560000"],["79871.50000000","0.00000000"],["79861.13000000","0.00000000"],["79843.32000000","1.24023000"],["79836.13000000","0.00000000"],["79770.96000000","0.04532000"],["71919.72000000","0.00064000"]],"a":[["79910.81000000","2.94361000"],["79910.82000000","0.00027000"],["79910.95000000","0.00711000"],["79912.86000000","0.00849000"],["79913.28000000","0.05733000"],["79913.29000000","0.00000000"],["79913.79000000","0.04687000"],["79913.98000000","0.00007000"],["79914.00000000","0.05663000"],["79915.42000000","0.01664000"],["79915.77000000","0.06280000"],["79920.00000000","1.54316000"],["79920.04000000","0.00000000"],["79922.82000000","0.00000000"],["79938.34000000","0.00000000"],["80010.65000000","0.02804000"]]}}}
{"rx_ns": 13890295429200, "frame": {"stream":"btcusdt@depth@100ms","data":{"e":"depthUpdate","E":1787650885514,"s":"BTCUSDT","U":99118613516,"u":99118613554,"b":[["79910.80000000","0.02726000"],["79910.79000000","0.00077000"],["79909.52000000","0.01775000"],["79908.80000000","0.00000000"],["79908.00000000","0.00728000"],["79907.09000000","0.00007000"],["79906.35000000","0.00007000"],["79905.89000000","0.00007000"],["79882.78000000","0.33807000"],["79871.57000000","0.33812000"],["79855.79000000","0.00012000"],["79839.83000000","0.00400000"],["79660.30000000","0.00007000"],["78712.13000000","0.00030000"],["71919.72000000","0.00080000"],["63928.64000000","0.00031000"],["55150.00000000","1.01200000"]],"a":[["79913.28000000","0.09387000"],["79914.14000000","0.01401000"],["79915.98000000","1.54868000"],["79916.15000000","0.19094000"],["79919.98000000","0.80893000"],["79920.00000000","1.54559000"],["79926.01000000","0.00007000"],["79932.99000000","0.00012000"],["79933.96000000","0.33786000"]]}}}
{"rx_ns": 13890407082300, "frame": {"stream":"btcusdt@depth@100ms","data":{"e":"depthUpdate","E":1787650885614,"s":"BTCUSDT","U":99118613555,"u":99118613574,"b":[["79910.80000000","0.02476000"],["79896.01000000","0.00007000"],["79890.56000000","0.02200000"],["79889.78000000","0.02000000"],["79889.77000000","0.02000000"],["79888.02000000","0.00000000"],["79873.79000000","0.00000000"],["79855.11000000","0.00000000"],["79835.11000000","0.00000000"],["79829.25000000","0.02000000"],["79809.24000000","0.00000000"],["79797.28000000","0.02200000"],["71919.72000000","0.00112000"],["63928.64000000","0.00000000"]],"a":[["79910.81000000","2.94369000"],["79925.53000000","0.02000000"],["79926.33000000","0.02000000"],["79932.02000000","0.00000000"],["79950.27000000","0.00000000"],["79970.27000000","0.00000000"],["79974.49000000","0.00000000"],["79976.81000000","0.00000000"]]}}}
{"rx_ns": 13890498737000, "frame": {"stream":"btcusdt@depth@100ms","data":{"e":"depthUpdate","E":1787650885714,"s":"BTCUSDT","U":99118613575,"u":99118613609,"b":[["79910.80000000","0.02510000"],["79910.79000000","0.00070000"],["79908.33000000","0.00000000"],["79908.32000000","0.00014000"],["79904.00000000","1.07353000"],["79902.80000000","0.00032000"],["79894.81000000","0.00032000"],["79886.95000000","0.09505000"],["79886.82000000","0.00032000"],["79878.83000000","0.00032000"],["79833.35000000","0.00000000"],["79793.41000000","0.00000000"],["79783.50000000","0.00000000"],["79778.54000000","0.00010000"],["79709.78000000","0.00000000"],["79683.67000000","0.00770000"],["79678.96000000","0.01960000"],["79669.76000000","0.00000000"],["79360.00000000","0.00590000"],["78983.31000000","0.00155000"]],"a":[["79910.81000000","2.94488000"],["79912.86000000","0.00856000"],["79913.27000000","0.06280000"],["79913.77000000","0.00000000"],["79913.78000000","0.06274000"],["79913.79000000","0.04680000"],["79913.98000000","0.00000000"],["79913.99000000","0.07514000"],["79914.53000000","0.06273000"],["79942.52000000","0.00400000"],["80036.73000000","0.00000000"],["80039.42000000","0.00000000"],["80043.58000000","0.00000000"]]}}}
{"rx_ns": 13890599814900, "frame": {"stream":"btcusdt@depth@100ms","data":{"e":"depthUpdate","E":1787650885814,"s":"BTCUSDT","U":99118613610,"u":99118613705,"b":[["79910.80000000","0.02234000"],["79910.00000000","0.01735000"],["79909.52000000","0.01768000"],["79908.55000000","0.00202000"],["79908.32000000","0.00000000"],["79908.00000000","0.01228000"],["79907.09000000","0.00000000"],["79907.08000000","0.00000000"],["79906.96000000","0.02096000"],["79906.47000000","0.00000000"],["79906.46000000","0.00000000"],["79906.35000000","0.00000000"],["79906.02000000","0.00000000"],["79906.01000000","0.00000000"],["79906.00000000","0.00728000"],["79905.99000000","0.68487000"],["79905.88000000","0.00000000"],["79905.51000000","0.00007000"],["79900.82000000","0.14134000"],["79894.58000000","0.02800000"],["79894.44000000","0.02600000"],["79893.64000000","0.02000000"],["79890.82000000","0.00007000"],["79890.59000000","0.02400000"],["79890.13000000","0.02200000"],["79889.74000000","0.02200000"],["79889.73000000","0.02200000"],["79886.95000000","0.00000000"],["79880.78000000","0.00000000"],["79875.94000000","0.00000000"],["79870.84000000","0.00019000"],["79840.69000000","0.02600000"],["79839.90000000","0.02000000"],["79839.22000000","0.00000000"],["79834.05000000","0.02800000"],["79830.05000000","0.02400000"],["79829.61000000","0.02200000"],["79829.21000000","0.04400000"],["79797.28000000","0.00000000"],["71919.72000000","0.00128000"]],"a":[["79910.81000000","4.88418000"],["79911.43000000","0.00000000"],["79912.05000000","0.00000000"],["79912.67000000","0.00000000"],["79912.86000000","0.00856000"],["79913.27000000","0.00014000"],["79913.28000000","0.06389000"],["79913.78000000","0.00014000"],["79914.14000000","0.01387000"],["79914.53000000","0.00000000"],["79915.15000000","0.00007000"],["79915.42000000","0.01671000"],["79915.77000000","0.00007000"],["79915.98000000","1.48595000"],["79916.52000000","0.07521000"],["79918.08000000","0.00951000"],["79924.77000000","0.00000000"],["79926.01000000","0.02007000"],["79936.91000000","0.00000000"],["79937.00000000","0.70000000"],["79937.72000000","0.00000000"],["79973.73000000","0.00000000"]]}}}
{"rx_ns": 13890697146200, "frame": {"stream":"btcusdt@depth@100ms","data":{"e":"depthUpdate","E":1787650885914,"s":"BTCUSDT","U":99118613706,"u":99118613794,"b":[["79910.80000000","0.02473000"],["79910.79000000","0.00063000"],["79910.66000000","0.00000000"],["79910.36000000","0.00000000"],["79910.35000000","0.00021000"],["79910.01000000","0.00007000"],["79908.44000000","0.00007000"],["79908.00000000","0.01228000"],["79906.01000000","0.06273000"],["79906.00000000","0.01228000"],["79905.82000000","0.00000000"],["79905.80000000","0.00000000"],["79905.77000000","0.00762000"],["79893.08000000","0.00257000"],["79892.30000000","0.02253000"],["79886.52000000","0.00000000"],["79886.24000000","0.00000000"],["79879.77000000","0.00400000"],["79879.25000000","0.08978000"],["79876.33000000","0.00000000"],["79876.04000000","0.09407000"],["79875.92000000","0.00000000"],["79840.69000000","0.00000000"],["79839.90000000","0.00000000"],["79838.84000000","0.00000000"],["79836.22000000","0.00000000"],["79835.98000000","0.12106000"],["79720.20000000","0.00000000"],["71919.72000000","0.00152000"],["71919.00000000","0.00000000"],["63928.64000000","0.00000000"]],"a":[["79910.81000000","4.81769000"],["79912.86000000","0.00849000"],["79913.23000000","0.00007000"],["79913.27000000","0.00000000"],["79913.28000000","0.06389000"],["79913.78000000","0.00000000"],["79914.14000000","0.01401000"],["79915.42000000","0.01685000"],["79920.69000000","0.00189000"],["79933.89000000","0.02478000"],["79937.40000000","0.00000000"],["79939.88000000","1.32361000"],["79940.33000000","0.50282000"],["79940.55000000","0.00000000"],["79948.06000000","0.09445000"],["79948.97000000","0.10000000"],["79956.27000000","0.00000000"],["80027.54000000","0.00012000"],["80030.23000000","0.00018000"],["81109.48000000","0.00030000"]]}}}
{"rx_ns": 13890799445200, "frame": {"stream":"btcusdt@depth20","data":{"lastUpdateId":99118613854,"bids":[["79910.80000000","0.02480000"],["79910.79000000","0.00063000"],["79910.51000000","0.00007000"],["79910.50000000","0.07909000"],["79910.35000000","0.00007000"],["79910.01000000","0.00007000"],["79910.00000000","0.04135000"],["79909.90000000","0.00007000"],["79909.53000000","0.00007000"],["79909.52000000","0.01768000"],["79909.25000000","0.00007000"],["79909.24000000","0.00007000"],["79909.20000000","0.00007000"],["79909.15000000","0.00007000"],["79909.14000000","0.00008000"],["79909.08000000","0.00007000"],["79909.07000000","0.33800000"],["79908.60000000","0.00007000"],["79908.55000000","0.00202000"],["79908.51000000","0.00007000"]],"asks":[["79910.81000000","4.81769000"],["79910.82000000","0.00027000"],["79910.83000000","0.00013000"],["79910.95000000","0.00021000"],["79911.63000000","0.00014000"],["79912.57000000","0.00625000"],["79912.58000000","0.00400000"],["79912.86000000","0.00849000"],["79913.23000000","0.00007000"],["79913.28000000","0.06389000"],["79913.56000000","0.00007000"],["79913.79000000","0.04680000"],["79913.99000000","0.07514000"],["79914.00000000","0.05663000"],["79914.14000000","0.01401000"],["79915.11000000","0.00400000"],["79915.15000000","0.00007000"],["79915.42000000","0.01685000"],["79915.50000000","0.00014000"],["79915.77000000","0.00007000"]]}}}
{"rx_ns": 13890799547500, "frame": {"stream":"btcusdt@depth@100ms","data":{"e":"depthUpdate","E":1787650886014,"s":"BTCUSDT","U":99118613795,"u":99118613854,"b":[["79910.80000000","0.02480000"],["79910.50000000","0.07909000"],["79910.35000000","0.00007000"],["79910.00000000","0.04135000"],["79909.08000000","0.00007000"],["79909.07000000","0.33800000"],["79908.25000000","0.00000000"],["79908.00000000","0.02428000"],["79906.97000000","0.00000000"],["79906.96000000","0.02117000"],["79906.47000000","0.00007000"],["79906.46000000","0.06280000"],["79906.02000000","0.00007000"],["79906.00000000","0.02428000"],["79905.64000000","0.04421000"],["79905.51000000","0.00000000"],["79904.81000000","0.00013000"],["79897.80000000","0.00625000"],["79896.16000000","0.00625000"],["79893.78000000","0.02200000"],["79893.71000000","0.02400000"],["79891.37000000","0.02400000"],["79890.14000000","0.36586000"],["79880.69000000","0.00000000"],["79879.90000000","0.00000000"],["79876.78000000","0.00000000"],["79871.00000000","0.70000000"],["79853.78000000","0.02200000"],["79830.86000000","0.02400000"],["79795.11000000","0.02400000"],["79760.16000000","0.00000000"],["71919.72000000","0.00152000"],["63928.64000000","0.00031000"]],"a":[["79910.95000000","0.00021000"],["79912.57000000","0.00625000"],["79916.51000000","0.00000000"],["79916.80000000","0.00013000"],["79920.00000000","1.54199000"],["79922.33000000","0.02000000"],["79922.41000000","0.02000000"],["79924.73000000","0.02000000"],["79942.33000000","0.02000000"],["79959.96000000","0.00000000"],["79962.33000000","0.02000000"],["79999.92000000","0.00000000"],["80034.39000000","0.00031000"],["80039.88000000","0.00000000"]]}}}
{"rx_ns": 13890895842200, "frame": {"stream":"btcusdt@depth@100ms","data":{"e":"depthUpdate","E":1787650886114,"s":"BTCUSDT","U":99118613855,"u":99118613883,"b":[["79910.80000000","0.02495000"],["79909.52000000","0.01768000"],["79906.96000000","0.02103000"],["79906.46000000","0.06273000"],["79906.02000000","0.00000000"],["79906.01000000","0.00000000"],["79905.51000000","0.00007000"],["79900.82000000","0.00000000"],["79893.03000000","0.02000000"],["79877.88000000","0.03872000"],["79831.24000000","0.02000000"],["79688.05000000","0.00400000"],["71919.72000000","0.00168000"]],"a":[["79910.81000000","4.81790000"],["79910.95000000","0.00007000"],["79912.57000000","0.00639000"],["79914.00000000","0.05656000"],["79921.39000000","0.02000000"],["79932.11000000","0.00000000"],["79934.42000000","0.00000000"]]}}}
{"rx_ns": 13891001083700, "frame": {"stream":"btcusdt@depth@100ms","data":{"e":"depthUpdate","E":1787650886214,"s":"BTCUSDT","U":99118613884,"u":99118613917,"b":[["79910.80000000","0.45179000"],["79910.79000000","0.00070000"],["79904.25000000","0.00000000"],["79895.58000000","0.00007000"],["79886.95000000","0.12517000"],["79835.98000000","0.00000000"],["71919.72000000","0.00168000"],["63928.64000000","0.00000000"]],"a":[["79913.27000000","0.00007000"],["79913.78000000","0.00007000"],["79913.98000000","0.00007000"],["79913.99000000","0.07521000"],["79915.97000000","0.00007000"],["79915.98000000","1.48602000"],["79915.99000000","1.04939000"],["79916.14000000","0.00007000"],["79916.15000000","0.19101000"],["79916.56000000","0.00007000"],["79918.44000000","0.36593000"],["79918.91000000","0.12512000"],["79920.00000000","1.53502000"],["79922.80000000","0.00007000"],["79927.56000000","0.00007000"],["79933.80000000","0.00000000"],["79948.06000000","0.00000000"],["80630.00000000","0.00060000"]]}}}
{"rx_ns": 13891096065100, "frame": {"stream":"btcusdt@depth@100ms","data":{"e":"depthUpdate","E":1787650886314,"s":"BTCUSDT","U":99118613918,"u":99118614021,"b":[["79910.80000000","0.45200000"],["79910.79000000","0.00084000"],["79910.20000000","0.00000000"],["79910.19000000","0.00000000"],["79910.00000000","0.04142000"],["79909.59000000","0.00007000"],["79909.58000000","0.06175000"],["79909.52000000","0.01775000"],["79909.09000000","0.00007000"],["79909.08000000","0.06182000"],["79908.37000000","0.00000000"],["79908.36000000","0.00000000"],["79908.21000000","0.00007000"],["79908.00000000","0.02435000"],["79907.76000000","0.00007000"],["79907.75000000","0.00000000"],["79907.14000000","0.00000000"],["79907.09000000","0.02459000"],["79906.96000000","0.02103000"],["79906.54000000","0.00007000"],["79906.53000000","0.06175000"],["79906.47000000","0.00000000"],["79906.46000000","0.00000000"],["79906.00000000","0.02421000"],["79905.99000000","0.68480000"],["79905.97000000","0.00000000"],["79905.96000000","0.00000000"],["79905.91000000","0.00000000"],["79905.64000000","0.00000000"],["79905.51000000","0.00000000"],["79902.73000000","1.10277000"],["79900.01000000","1.87677000"],["79899.76000000","0.00625000"],["79899.37000000","0.00625000"],["79897.80000000","0.00000000"],["79896.16000000","0.00000000"],["79893.86000000","0.33803000"],["79879.58000000","0.33809000"],["79871.57000000","0.00000000"],["79831.24000000","0.00000000"],["79807.87000000","0.00400000"],["79795.11000000","0.00000000"],["71919.72000000","0.00184000"],["63936.00000000","0.00363000"],["63929.00000000","0.00060000"]],"a":[["79910.81000000","2.94069000"],["79912.56000000","0.00040000"],["79912.57000000","0.00014000"],["79913.79000000","0.04687000"],["79913.97000000","0.00625000"],["79914.00000000","0.04942000"],["79914.14000000","0.01408000"],["79914.79000000","0.00694000"],["79916.14000000","0.00007000"],["79916.15000000","0.19101000"],["79916.97000000","0.00007000"],["79919.61000000","0.19978000"],["79920.00000000","1.53495000"],["79940.42000000","0.33783000"]]}}}
{"rx_ns": 13891198038300, "frame": {"stream":"btcusdt@depth@100ms","data":{"e":"depthUpdate","E":1787650886414,"s":"BTCUSDT","U":99118614022,"u":99118614101,"b":[["79910.80000000","0.97354000"],["79910.79000000","0.00084000"],["79910.00000000","0.04842000"],["79909.59000000","0.00000000"],["79909.58000000","0.00014000"],["79909.52000000","0.01761000"],["79909.07000000","0.33807000"],["79908.41000000","0.00007000"],["79908.40000000","0.03506000"],["79908.00000000","0.02414000"],["79907.76000000","0.00014000"],["79907.09000000","0.00000000"],["79906.85000000","0.00000000"],["79906.00000000","0.02421000"],["79903.10000000","0.00692000"],["79902.82000000","0.00013000"],["79900.09000000","0.00000000"],["79898.09000000","0.23125000"],["79847.11000000","0.00000000"],["79841.22000000","0.00311000"],["79830.86000000","0.00000000"],["79829.97000000","0.12218000"],["79772.01000000","0.00000000"],["79766.67000000","0.00000000"],["79762.28000000","0.00125000"],["79760.01000000","0.00125000"]],"a":[["79910.81000000","2.94076000"],["79912.57000000","0.00000000"],["79913.79000000","0.04680000"],["79913.97000000","0.00014000"],["79914.14000000","0.01415000"],["79914.79000000","0.00021000"],["79914.86000000","0.00695000"],["79915.41000000","0.00625000"],["79915.42000000","0.01671000"],["79915.98000000","1.48595000"],["79915.99000000","0.00000000"],["79916.14000000","0.00007000"],["79916.15000000","0.19101000"],["79916.97000000","0.00007000"],["79918.08000000","0.00944000"],["79919.14000000","0.00000000"],["79977.99000000","0.00311000"],["79979.10000000","0.00312000"],["79984.94000000","0.00000000"],["79985.28000000","0.00000000"],["80059.57000000","0.00125000"],["80067.99000000","0.00007000"],["80264.74000000","0.00000000"]]}}}
{"rx_ns": 13891298140600, "frame": {"stream":"btcusdt@depth@100ms","data":{"e":"depthUpdate","E":1787650886514,"s":"BTCUSDT","U":99118614102,"u":99118614163,"b":[["79910.80000000","0.97333000"],["79910.79000000","0.00063000"],["79910.00000000","0.04835000"],["79909.58000000","0.00000000"],["79909.52000000","0.01768000"],["79909.09000000","0.00000000"],["79909.08000000","0.00000000"],["79909.07000000","0.00014000"],["79908.55000000","0.00000000"],["79908.25000000","0.00007000"],["79908.01000000","0.00007000"],["79906.97000000","0.00007000"],["79906.00000000","0.02414000"],["79905.99000000","0.68480000"],["79905.98000000","0.31301000"],["79893.71000000","0.00000000"],["79855.07000000","0.00000000"],["79815.10000000","0.00000000"],["79789.44000000","0.00000000"],["79762.27000000","0.00000000"],["78712.13000000","0.00030000"],["71919.72000000","0.00200000"],["63928.64000000","0.00031000"]],"a":[["79913.79000000","0.04673000"],["79913.97000000","0.00000000"],["79914.14000000","0.01415000"],["79914.79000000","0.00007000"],["79914.86000000","0.00709000"],["79915.41000000","0.00639000"],["79916.15000000","0.19101000"],["79916.97000000","0.00000000"],["79919.99000000","1.15398000"],["79920.00000000","1.53414000"],["79922.41000000","0.00000000"],["79924.10000000","0.15688000"],["79925.99000000","0.19019000"],["79950.33000000","0.02014000"],["79970.32000000","0.00000000"],["80134.39000000","0.00400000"]]}}}
{"rx_ns": 13891400322100, "frame": {"stream":"btcusdt@depth@100ms","data":{"e":"depthUpdate","E":1787650886615,"s":"BTCUSDT","U":99118614164,"u":99118614194,"b":[["79910.80000000","0.97123000"],["79910.79000000","0.00076000"],["79910.78000000","0.00013000"],["79909.52000000","0.01768000"],["79908.00000000","0.02421000"],["79907.15000000","0.00007000"],["79907.14000000","0.06175000"],["79906.53000000","0.06182000"],["79906.01000000","0.06175000"],["71919.72000000","0.00200000"],["63928.64000000","0.00000000"]],"a":[["79910.81000000","2.94063000"],["79913.28000000","0.04348000"],["79913.98000000","0.00000000"],["79913.99000000","0.00021000"],["79914.13000000","0.00007000"],["79915.41000000","0.00646000"],["79916.15000000","0.19094000"],["79916.97000000","0.00000000"],["79920.00000000","1.53252000"],["79973.74000000","0.02000000"],["79976.81000000","0.02000000"]]}}}
{"rx_ns": 13891505778300, "frame": {"stream":"btcusdt@depth@100ms","data":{"e":"depthUpdate","E":1787650886714,"s":"BTCUSDT","U":99118614195,"u":99118614235,"b":[["79910.80000000","0.99364000"],["79908.00000000","0.02414000"],["79907.15000000","0.00000000"],["79907.14000000","0.00000000"],["79906.96000000","0.02096000"],["79906.54000000","0.00000000"],["79906.53000000","0.00000000"],["79906.01000000","0.00007000"],["79889.80000000","0.02415000"],["71919.72000000","0.00216000"]],"a":[["79913.28000000","0.07482000"],["79913.79000000","0.04673000"],["79913.99000000","0.00007000"],["79914.13000000","0.00000000"],["79914.86000000","0.00716000"],["79915.07000000","0.00007000"],["79915.08000000","0.06175000"],["79915.41000000","0.00639000"],["79915.42000000","0.01692000"],["79915.69000000","0.06182000"],["79915.97000000","0.06175000"],["79916.14000000","0.00000000"],["79916.15000000","0.19094000"],["79948.97000000","0.19259000"],["80062.44000000","0.00400000"]]}}}
{"rx_ns": 13891599650700, "frame": {"stream":"btcusdt@depth@100ms","data":{"e":"depthUpdate","E":1787650886815,"s":"BTCUSDT","U":99118614236,"u":99118614250,"b":[["79840.69000000","0.02600000"],["79839.90000000","0.02000000"],["79825.69000000","0.62553000"],["71919.72000000","0.00216000"]],"a":[["79914.86000000","0.00716000"],["79915.08000000","0.06189000"],["79915.42000000","0.01678000"],["79915.68000000","0.00007000"],["79920.56000000","0.02000000"]]}}}
{"rx_ns": 13891697280300, "frame": {"stream":"btcusdt@depth@100ms","data":{"e":"depthUpdate","E":1787650886914,"s":"BTCUSDT","U":99118614251,"u":99118614264,"b":[["79869.06000000","0.00000000"],["79868.61000000","0.00014000"],["79759.95000000","0.00400000"],["79688.21000000","0.00770000"],["79683.67000000","0.00000000"],["71919.72000000","0.00232000"],["63928.64000000","0.00000000"]],"a":[["79916.13000000","0.00000000"],["79928.94000000","0.00000000"],["81109.48000000","0.00030000"]]}}}
{"rx_ns": 13891799310300, "frame": {"stream":"btcusdt@depth20","data":{"lastUpdateId":99118614309,"bids":[["79910.80000000","0.99364000"],["79910.79000000","0.00076000"],["79910.78000000","0.00013000"],["79910.51000000","0.00007000"],["79910.50000000","0.07909000"],["79910.35000000","0.00007000"],["79910.01000000","0.00007000"],["79910.00000000","0.04835000"],["79909.90000000","0.00007000"],["79909.53000000","0.00007000"],["79909.52000000","0.01768000"],["79909.25000000","0.00007000"],["79909.24000000","0.00007000"],["79909.20000000","0.00007000"],["79909.15000000","0.00007000"],["79909.14000000","0.00008000"],["79909.07000000","0.00014000"],["79908.60000000","0.00007000"],["79908.51000000","0.00007000"],["79908.44000000","0.00007000"]],"asks":[["79910.81000000","2.94063000"],["79910.82000000","0.00027000"],["79910.83000000","0.00013000"],["79910.95000000","0.00007000"],["79911.63000000","0.00014000"],["79912.56000000","0.00040000"],["79912.58000000","0.00400000"],["79912.86000000","0.00849000"],["79913.23000000","0.00007000"],["79913.27000000","0.00007000"],["79913.28000000","0.07482000"],["79913.56000000","0.00007000"],["79913.78000000","0.00007000"],["79913.79000000","0.04673000"],["79913.99000000","0.00007000"],["79914.00000000","0.04942000"],["79914.14000000","0.01415000"],["79914.79000000","0.00007000"],["79914.86000000","0.00716000"],["79915.08000000","0.00014000"]]}}}
{"rx_ns": 13891799400600, "frame": {"stream":"btcusdt@depth@100ms","data":{"e":"depthUpdate","E":1787650887014,"s":"BTCUSDT","U":99118614265,"u":99118614309,"b":[["79908.01000000","0.00007000"],["79906.97000000","0.00007000"],["79906.96000000","0.02103000"],["79906.02000000","0.00007000"],["79906.01000000","0.06175000"],["79892.97000000","0.02400000"],["79852.98000000","0.02400000"],["79833.78000000","0.02200000"],["79795.08000000","0.00253000"],["79794.28000000","0.00000000"],["79696.56000000","0.00380000"],["79695.76000000","0.00000000"],["71919.72000000","0.00216000"],["71919.00000000","0.00000000"],["63928.64000000","0.00031000"]],"a":[["79915.07000000","0.00000000"],["79915.08000000","0.00014000"],["79915.41000000","0.00646000"],["79915.96000000","0.00007000"],["79915.97000000","0.06182000"],["79916.14000000","0.00007000"],["79916.15000000","0.19101000"],["79920.16000000","0.00000000"],["79920.96000000","0.00764000"],["79921.45000000","0.02000000"],["79941.45000000","0.02000000"],["79961.45000000","0.02000000"],["79964.53000000","0.00000000"],["79965.33000000","0.00380000"]]}}}
{"rx_ns": 13891901907100, "frame": {"stream":"btcusdt@depth@100ms","data":{"e":"depthUpdate","E":1787650887114,"s":"BTCUSDT","U":99118614310,"u":99118614379,"b":[["79910.80000000","0.97798000"],["79908.40000000","0.03520000"],["79908.00000000","0.02428000"],["79900.24000000","0.00048000"],["79876.00000000","0.72400000"],["79871.00000000","0.00000000"],["79845.64000000","0.02541000"],["79819.31000000","0.00000000"],["71919.72000000","0.00248000"],["63929.00000000","0.00060000"]],"a":[["79910.81000000","2.94035000"],["79914.86000000","0.00709000"],["79915.08000000","0.00000000"],["79915.42000000","0.01692000"],["79915.68000000","0.00007000"],["79915.96000000","0.00007000"],["79915.97000000","0.06182000"],["79916.14000000","0.00000000"],["79916.15000000","0.19094000"],["79963.48000000","0.01270000"],["80014.47000000","0.00400000"],["80019.11000000","0.00000000"],["80028.20000000","0.00000000"],["80046.92000000","0.00000000"]]}}}
{"rx_ns": 13891995455200, "frame": {"stream":"btcusdt@depth@100ms","data":{"e":"depthUpdate","E":1787650887214,"s":"BTCUSDT","U":99118614380,"u":99118614394,"b":[["79910.80000000","0.97811000"],["79895.58000000","0.00000000"],["79810.13000000","0.00025000"],["71919.72000000","0.00264000"],["63928.64000000","0.00000000"]],"a":[["79916.14000000","0.00007000"],["79916.15000000","0.19101000"],["79927.56000000","0.00000000"],["79969.37000000","0.00218000"],["80009.90000000","0.00025000"],["80011.41000000","0.25000000"],["80044.53000000","0.08419000"],["80045.28000000","0.00000000"],["80630.00000000","0.00050000"]]}}}
{"rx_ns": 13892095461300, "frame": {"stream":"btcusdt@depth@100ms","data":{"e":"depthUpdate","E":1787650887314,"s":"BTCUSDT","U":99118614395,"u":99118614438,"b":[["79910.80000000","0.97875000"],["79908.00000000","0.02428000"],["79907.56000000","0.00000000"],["79907.55000000","0.00000000"],["79906.02000000","0.00007000"],["79895.58000000","0.00007000"],["79879.77000000","0.00000000"],["79839.83000000","0.00000000"],["79807.87000000","0.00000000"],["79759.95000000","0.00000000"],["79688.05000000","0.00000000"],["71919.72000000","0.00248000"],["63929.00000000","0.00060000"]],"a":[["79910.81000000","2.94732000"],["79914.48000000","0.00007000"],["79915.96000000","0.00000000"],["79915.97000000","0.06175000"],["79916.14000000","0.00000000"],["79916.15000000","0.19094000"],["79927.56000000","0.00007000"],["79979.11000000","0.00055000"],["79982.50000000","0.00400000"],["80014.47000000","0.00000000"]]}}}
{"rx_ns": 13892201285700, "frame": {"stream":"btcusdt@depth@100ms","data":{"e":"depthUpdate","E":1787650887414,"s":"BTCUSDT","U":99118614439,"u":99118614454,"b":[["79910.80000000","0.97913000"],["79902.80000000","0.00025000"],["79894.81000000","0.00025000"],["79886.82000000","0.00025000"],["79878.83000000","0.00025000"],["71919.72000000","0.00280000"]],"a":[["79915.96000000","0.00007000"],["79915.97000000","0.06182000"],["79916.14000000","0.00007000"],["79916.15000000","0.19101000"]]}}}
{"rx_ns": 13892334938000, "frame": {"stream":"btcusdt@depth@100ms","data":{"e":"depthUpdate","E":1787650887514,"s":"BTCUSDT","U":99118614455,"u":99118614461,"b":[["79893.64000000","0.00000000"],["79873.72000000","0.00400000"],["79859.90000000","0.00000000"],["79839.90000000","0.00000000"],["78712.13000000","0.00030000"],["71919.72000000","0.00280000"],["63928.64000000","0.00031000"]],"a":[["79927.79000000","0.00000000"],["79950.33000000","0.00014000"],["79970.33000000","0.00000000"]]}}}
{"rx_ns": 13892402512500, "frame": {"stream":"btcusdt@depth@100ms","data":{"e":"depthUpdate","E":1787650887614,"s":"BTCUSDT","U":99118614462,"u":99118614472,"b":[["71919.72000000","0.00296000"],["63928.64000000","0.00000000"]],"a":[["79910.81000000","2.94975000"],["79915.96000000","0.00000000"],["79915.97000000","0.06175000"],["79916.14000000","0.00000000"],["79916.15000000","0.19094000"]]}}}
{"rx_ns": 13892495497500, "frame": {"stream":"btcusdt@depth@100ms","data":{"e":"depthUpdate","E":1787650887714,"s":"BTCUSDT","U":99118614473,"u":99118614474,"b":[["79903.10000000","0.00000000"],["79682.02000000","0.00400000"]],"a":[]}}}
{"rx_ns": 13892597190700, "frame": {"stream":"btcusdt@depth@100ms","data":{"e":"depthUpdate","E":1787650887814,"s":"BTCUSDT","U":99118614475,"u":99118614493,"b":[["79910.80000000","0.78122000"],["79893.01000000","0.02719000"],["79879.25000000","0.31970000"],["79853.02000000","0.02000000"],["79833.58000000","0.00000000"],["71919.72000000","0.00304000"],["71919.71000000","0.00008000"]],"a":[["79910.81000000","2.94947000"],["79914.86000000","0.00716000"],["79915.07000000","0.00007000"],["79915.08000000","0.06176000"],["79915.41000000","0.00639000"],["79915.68000000","0.00000000"],["79921.35000000","0.02000000"],["79941.35000000","0.02000000"],["79961.35000000","0.02000000"]]}}}
{"rx_ns": 13892700250400, "frame": {"stream":"btcusdt@depth@100ms","data":{"e":"depthUpdate","E":1787650887914,"s":"BTCUSDT","U":99118614494,"u":99118614521,"b":[["79910.80000000","0.78129000"],["79906.96000000","0.02110000"],["79906.54000000","0.00007000"],["79906.53000000","0.06176000"],["79753.90000000","0.00400000"],["71919.72000000","0.00304000"],["63928.64000000","0.00000000"]],"a":[["79914.86000000","0.00716000"],["79915.08000000","0.06190000"],["79915.42000000","0.01678000"],["79915.68000000","0.00007000"],["79915.96000000","0.00007000"],["79915.97000000","0.06175000"],["79916.14000000","0.00000000"],["79916.15000000","0.19094000"],["79918.44000000","0.36586000"],["81109.48000000","0.00030000"]]}}}
{"rx_ns": 13892798257100, "frame": {"stream":"btcusdt@depth20","data":{"lastUpdateId":99118614556,"bids":[["79910.80000000","1.12124000"],["79910.79000000","0.00076000"],["79910.78000000","0.00013000"],["79910.51000000","0.00007000"],["79910.50000000","0.07909000"],["79910.35000000","0.00007000"],["79910.01000000","0.00007000"],["79910.00000000","0.04835000"],["79909.90000000","0.00007000"],["79909.53000000","0.00007000"],["79909.52000000","0.01768000"],["79909.25000000","0.00007000"],["79909.24000000","0.00007000"],["79909.20000000","0.00007000"],["79909.15000000","0.00007000"],["79909.14000000","0.00008000"],["79909.07000000","0.00014000"],["79908.60000000","0.00007000"],["79908.51000000","0.00007000"],["79908.44000000","0.00007000"]],"asks":[["79910.81000000","2.94947000"],["79910.82000000","0.00027000"],["79910.83000000","0.00013000"],["79910.95000000","0.00007000"],["79911.63000000","0.00014000"],["79912.56000000","0.00040000"],["79912.58000000","0.00400000"],["79912.86000000","0.00849000"],["79913.23000000","0.00007000"],["79913.27000000","0.00007000"],["79913.28000000","0.04348000"],["79913.56000000","0.00007000"],["79913.78000000","0.00007000"],["79913.79000000","0.04673000"],["79913.99000000","0.00007000"],["79914.00000000","0.04942000"],["79914.13000000","0.00007000"],["79914.14000000","0.01415000"],["79914.48000000","0.00007000"],["79914.79000000","0.00007000"]]}}}
{"rx_ns": 13892798386400, "frame": {"stream":"btcusdt@depth@100ms","data":{"e":"depthUpdate","E":1787650888014,"s":"BTCUSDT","U":99118614522,"u":99118614556,"b":[["79910.80000000","1.12124000"],["79908.01000000","0.00007000"],["79906.97000000","0.00007000"],["79906.54000000","0.00007000"],["79906.02000000","0.00000000"],["79832.98000000","0.02400000"],["71919.72000000","0.00320000"],["63928.64000000","0.00031000"]],"a":[["79913.28000000","0.04348000"],["79914.13000000","0.00007000"],["79915.07000000","0.00000000"],["79915.08000000","0.00014000"],["79915.41000000","0.00646000"],["79915.68000000","0.00000000"],["79915.69000000","0.00007000"],["79915.96000000","0.00000000"],["79915.97000000","0.00007000"],["79916.14000000","0.00007000"],["79916.15000000","0.19101000"]]}}}
{"rx_ns": 13892896958800, "frame": {"stream":"btcusdt@depth@100ms","data":{"e":"depthUpdate","E":1787650888114,"s":"BTCUSDT","U":99118614557,"u":99118614621,"b":[["79910.80000000","1.12361000"],["79910.79000000","0.00083000"],["79910.00000000","0.04842000"],["79909.61000000","0.00007000"],["79909.60000000","0.03690000"],["79909.24000000","0.00000000"],["79908.41000000","0.00000000"],["79908.40000000","0.00014000"],["79908.00000000","0.02435000"],["79907.15000000","0.00007000"],["79907.14000000","0.06176000"],["79906.97000000","0.00007000"],["79906.54000000","0.00000000"],["79903.75000000","0.03224000"],["79901.53000000","0.00625000"],["79899.37000000","0.00000000"],["79801.83000000","0.00400000"],["71919.72000000","0.00320000"],["71919.00000000","0.00000000"]],"a":[["79910.81000000","2.40855000"],["79910.82000000","0.00055000"],["79914.00000000","0.04028000"],["79914.86000000","0.00014000"],["79915.08000000","0.00000000"],["79915.42000000","0.01692000"],["79915.97000000","0.06183000"],["79916.14000000","0.00007000"],["79916.15000000","0.19101000"],["79916.52000000","0.07514000"],["79916.97000000","0.00007000"],["79917.03000000","0.00000000"],["79917.44000000","0.24638000"]]}}}
{"rx_ns": 13893000640000, "frame": {"stream":"btcusdt@depth@100ms","data":{"e":"depthUpdate","E":1787650888214,"s":"BTCUSDT","U":99118614622,"u":99118614670,"b":[["79910.80000000","1.12371000"],["79910.00000000","0.04842000"],["79909.60000000","0.03704000"],["79909.52000000","0.01768000"],["79909.07000000","0.00007000"],["79908.40000000","0.00000000"],["79908.00000000","0.02435000"],["79906.85000000","0.00007000"],["79860.99000000","0.00400000"],["79859.60000000","0.02541000"],["79859.45000000","0.00000000"],["71919.72000000","0.00336000"],["63928.64000000","0.00000000"]],"a":[["79914.14000000","0.01408000"],["79914.86000000","0.00000000"],["79915.42000000","0.01692000"],["79915.69000000","0.06183000"],["79915.96000000","0.00007000"],["79915.97000000","0.06197000"],["79916.15000000","0.19101000"],["79916.97000000","0.00000000"],["79918.79000000","0.00000000"],["79918.89000000","0.00703000"],["80010.21000000","0.00000000"],["80630.00000000","0.00060000"]]}}}
{"rx_ns": 13893095488600, "frame": {"stream":"btcusdt@depth@100ms","data":{"e":"depthUpdate","E":1787650888314,"s":"BTCUSDT","U":99118614671,"u":99118614704,"b":[["79903.74000000","0.00697000"],["79895.58000000","0.00007000"],["79850.11000000","0.00007000"],["79848.03000000","0.00007000"],["79836.13000000","0.02086000"],["63929.00000000","0.00060000"]],"a":[["79910.81000000","2.40869000"],["79910.82000000","0.00062000"],["79913.28000000","0.07009000"],["79914.13000000","0.00000000"],["79914.14000000","0.01415000"],["79915.07000000","0.00007000"],["79915.08000000","0.06176000"],["79915.42000000","0.01692000"],["79915.68000000","0.00007000"],["79915.69000000","0.06197000"],["79915.97000000","0.06183000"],["79916.14000000","0.00007000"],["79916.15000000","0.19094000"],["79927.56000000","0.00007000"],["80012.41000000","0.00400000"]]}}}
{"rx_ns": 13893199529600, "frame": {"stream":"btcusdt@depth@100ms","data":{"e":"depthUpdate","E":1787650888414,"s":"BTCUSDT","U":99118614705,"u":99118614720,"b":[["79836.13000000","0.00000000"],["71919.72000000","0.00352000"]],"a":[["79914.14000000","0.01415000"],["79915.08000000","0.06190000"],["79915.69000000","0.06183000"],["79977.58000000","0.04694000"],["79995.18000000","0.00000000"],["80004.63000000","1.24837000"],["80005.19000000","1.95350000"]]}}}
{"rx_ns": 13893319458500, "frame": {"stream":"btcusdt@depth@100ms","data":{"e":"depthUpdate","E":1787650888514,"s":"BTCUSDT","U":99118614721,"u":99118614729,"b":[["79894.44000000","0.00000000"],["79860.69000000","0.00000000"],["79840.69000000","0.00000000"],["79833.78000000","0.02600000"],["78712.13000000","0.00030000"],["71919.72000000","0.00352000"],["63928.64000000","0.00031000"]],"a":[["79920.00000000","1.48252000"],["79926.99000000","0.00000000"],["79949.53000000","0.00000000"],["79969.52000000","0.00000000"],["80012.41000000","0.00000000"]]}}}
{"rx_ns": 13893400506300, "frame": {"stream":"btcusdt@depth@100ms","data":{"e":"depthUpdate","E":1787650888614,"s":"BTCUSDT","U":99118614730,"u":99118614734,"b":[["79910.80000000","1.12358000"],["71919.72000000","0.00352000"],["63928.64000000","0.00000000"]],"a":[["79952.67000000","0.00573000"]]}}}
{"rx_ns": 13893495849700, "frame": {"stream":"btcusdt@depth@100ms","data":{"e":"depthUpdate","E":1787650888714,"s":"BTCUSDT","U":99118614735,"u":99118614742,"b":[["79869.06000000","0.00007000"],["79868.61000000","0.00007000"],["73513.51000000","0.00014000"],["71919.72000000","0.00384000"]],"a":[["79915.35000000","0.00000000"],["80012.42000000","0.00400000"]]}}}
{"rx_ns": 13893598542000, "frame": {"stream":"btcusdt@depth@100ms","data":{"e":"depthUpdate","E":1787650888814,"s":"BTCUSDT","U":99118614743,"u":99118614788,"b":[["79910.80000000","1.12797000"],["79910.79000000","0.00076000"],["79908.00000000","0.02428000"],["79907.15000000","0.00000000"],["79907.14000000","0.00000000"],["79906.96000000","0.02103000"],["79906.54000000","0.00000000"],["79906.53000000","0.00000000"],["79906.02000000","0.00007000"],["79893.85000000","0.02600000"],["79853.85000000","0.02600000"],["79833.02000000","0.02000000"],["71919.72000000","0.00384000"]],"a":[["79910.81000000","2.40862000"],["79910.82000000","0.00069000"],["79913.28000000","0.10367000"],["79913.77000000","0.00007000"],["79913.78000000","0.06183000"],["79914.14000000","0.01422000"],["79914.46000000","0.00007000"],["79914.47000000","0.06176000"],["79915.41000000","0.00639000"],["79915.68000000","0.00000000"],["79915.72000000","0.00000000"],["79915.96000000","0.00000000"],["79915.97000000","0.06176000"],["79916.14000000","0.00000000"],["79920.51000000","0.02000000"],["79927.39000000","0.00000000"],["79940.51000000","0.02000000"],["79960.50000000","0.02000000"],["80012.42000000","0.00000000"]]}}}
{"rx_ns": 13893695850900, "frame": {"stream":"btcusdt@depth@100ms","data":{"e":"depthUpdate","E":1787650888914,"s":"BTCUSDT","U":99118614789,"u":99118614822,"b":[["79908.00000000","0.02428000"],["79770.96000000","0.00000000"],["71919.72000000","0.00384000"],["63928.64000000","0.00000000"]],"a":[["79910.81000000","2.40862000"],["79913.28000000","0.10367000"],["79913.78000000","0.06197000"],["79914.14000000","0.01422000"],["79914.47000000","0.06190000"],["79915.41000000","0.00625000"],["79915.42000000","0.01678000"],["79915.68000000","0.00007000"],["79915.96000000","0.00007000"],["79915.97000000","0.06183000"],["79916.66000000","0.00695000"],["80012.37000000","0.00400000"],["81109.48000000","0.00030000"]]}}}
{"rx_ns": 13893797617900, "frame": {"stream":"btcusdt@depth20","data":{"lastUpdateId":99118614830,"bids":[["79910.80000000","1.12797000"],["79910.79000000","0.00076000"],["79910.78000000","0.00013000"],["79910.51000000","0.00007000"],["79910.50000000","0.07909000"],["79910.35000000","0.00007000"],["79910.01000000","0.00007000"],["79910.00000000","0.04842000"],["79909.90000000","0.00007000"],["79909.61000000","0.00007000"],["79909.60000000","0.03704000"],["79909.53000000","0.00007000"],["79909.52000000","0.01768000"],["79909.25000000","0.00007000"],["79909.20000000","0.00007000"],["79909.15000000","0.00007000"],["79909.14000000","0.00008000"],["79909.07000000","0.00007000"],["79908.60000000","0.00007000"],["79908.51000000","0.00007000"]],"asks":[["79910.81000000","2.40862000"],["79910.82000000","0.00069000"],["79910.83000000","0.00013000"],["79910.95000000","0.00007000"],["79911.63000000","0.00014000"],["79912.56000000","0.00040000"],["79912.58000000","0.00400000"],["79912.86000000","0.00849000"],["79913.23000000","0.00007000"],["79913.27000000","0.00007000"],["79913.28000000","0.10367000"],["79913.56000000","0.00007000"],["79913.77000000","0.00007000"],["79913.78000000","0.06197000"],["79913.79000000","0.04673000"],["79913.99000000","0.00007000"],["79914.00000000","0.04028000"],["79914.14000000","0.01422000"],["79914.46000000","0.00007000"],["79914.47000000","0.06190000"]]}}}
{"rx_ns": 13893797733900, "frame": {"stream":"btcusdt@depth@100ms","data":{"e":"depthUpdate","E":1787650889014,"s":"BTCUSDT","U":99118614823,"u":99118614830,"b":[["79877.00000000","0.70000000"],["79876.00000000","0.02400000"],["79770.96000000","0.04532000"],["71919.72000000","0.00400000"],["63928.64000000","0.00031000"]],"a":[["79918.20000000","0.00215000"]]}}}
{"rx_ns": 13893896957300, "frame": {"stream":"btcusdt@depth@100ms","data":{"e":"depthUpdate","E":1787650889115,"s":"BTCUSDT","U":99118614831,"u":99118614866,"b":[["79910.80000000","1.12797000"],["79908.01000000","0.00007000"],["79908.00000000","0.02428000"],["79907.64000000","0.00000000"],["79907.63000000","0.00000000"],["79906.97000000","0.00007000"],["79906.02000000","0.00007000"],["79855.95000000","0.82210000"],["71919.72000000","0.00416000"],["71919.00000000","0.00020000"]],"a":[["79910.81000000","2.40869000"],["79910.82000000","0.00076000"],["79915.68000000","0.00007000"],["79915.96000000","0.00007000"],["79915.97000000","0.06183000"],["79950.74000000","0.01270000"]]}}}
{"rx_ns": 13894002964300, "frame": {"stream":"btcusdt@depth@100ms","data":{"e":"depthUpdate","E":1787650889215,"s":"BTCUSDT","U":99118614867,"u":99118614872,"b":[["79030.17000000","0.01300000"],["73513.51000000","0.00000000"],["71919.72000000","0.00416000"],["71919.00000000","0.00000000"],["63928.64000000","0.00000000"]],"a":[]}}}
{"rx_ns": 13894095446100, "frame": {"stream":"btcusdt@depth@100ms","data":{"e":"depthUpdate","E":1787650889314,"s":"BTCUSDT","U":99118614873,"u":99118614881,"b":[["79910.80000000","1.12317000"],["79895.58000000","0.00007000"],["79854.26000000","0.00007000"],["79847.26000000","0.00007000"],["71919.72000000","0.00432000"],["63929.00000000","0.00060000"]],"a":[["79927.56000000","0.00007000"]]}}}
{"rx_ns": 13894199912300, "frame": {"stream":"btcusdt@depth@100ms","data":{"e":"depthUpdate","E":1787650889414,"s":"BTCUSDT","U":99118614882,"u":99118614910,"b":[["79910.80000000","1.12324000"],["79910.79000000","0.00083000"],["79908.20000000","0.05381000"],["79908.17000000","0.00938000"],["79906.96000000","0.02110000"],["79906.56000000","0.00717000"],["79905.98000000","0.31294000"],["79905.78000000","0.00700000"],["79905.77000000","0.00000000"],["79885.01000000","0.09271000"],["79876.04000000","0.00000000"],["79836.13000000","0.02086000"],["71919.72000000","0.00416000"]],"a":[["79910.81000000","2.40883000"],["79910.82000000","0.00083000"],["79912.86000000","0.00856000"],["79912.96000000","0.00917000"],["79914.14000000","0.01429000"],["79914.31000000","0.00702000"],["79918.08000000","0.00937000"],["79948.97000000","0.10000000"],["79955.36000000","0.09513000"]]}}}
{"rx_ns": 13894295527800, "frame": {"stream":"btcusdt@depth@100ms","data":{"e":"depthUpdate","E":1787650889514,"s":"BTCUSDT","U":99118614911,"u":99118614938,"b":[["79908.20000000","0.05381000"],["79836.13000000","0.00000000"],["78712.13000000","0.00030000"],["71919.72000000","0.00432000"],["63928.64000000","0.00031000"]],"a":[["79910.81000000","2.40760000"],["79912.86000000","0.00856000"],["79912.96000000","0.00931000"],["79914.14000000","0.01429000"],["79914.31000000","0.00716000"],["79914.47000000","0.06176000"],["79915.08000000","0.06176000"]]}}}
{"rx_ns": 13894401874500, "frame": {"stream":"btcusdt@depth@100ms","data":{"e":"depthUpdate","E":1787650889614,"s":"BTCUSDT","U":99118614939,"u":99118615031,"b":[["79910.80000000","0.60154000"],["79910.79000000","0.00076000"],["79909.61000000","0.00000000"],["79909.60000000","0.00014000"],["79908.20000000","0.05374000"],["79908.17000000","0.00000000"],["79908.06000000","0.00000000"],["79906.96000000","0.02096000"],["79906.56000000","0.00000000"],["79906.02000000","0.00000000"],["79906.01000000","0.00007000"],["79906.00000000","0.02421000"],["79904.01000000","1.04939000"],["79904.00000000","0.02414000"],["79903.75000000","0.00000000"],["79902.82000000","0.00000000"],["79902.73000000","0.31641000"],["79901.53000000","0.00012000"],["79900.01000000","0.00000000"],["79900.00000000","0.02407000"],["79899.76000000","0.00000000"],["79899.50000000","0.00000000"],["79899.36000000","0.61425000"],["79898.43000000","0.00625000"],["79897.88000000","0.00625000"],["79896.15000000","1.04953000"],["79894.02000000","1.54044000"],["79894.01000000","1.88485000"],["79894.00000000","0.02400000"],["79893.99000000","0.13831000"],["79881.01000000","0.00000000"],["79878.92000000","0.04584000"],["79816.83000000","1.87677000"],["71919.72000000","0.00416000"],["63929.00000000","0.00060000"],["63928.64000000","0.00000000"]],"a":[["79910.81000000","4.34470000"],["79910.82000000","0.00069000"],["79911.42000000","0.00000000"],["79912.03000000","0.00000000"],["79912.56000000","0.00000000"],["79912.64000000","0.00000000"],["79913.25000000","0.00000000"],["79913.27000000","0.00000000"],["79913.28000000","0.04084000"],["79913.77000000","0.00000000"],["79913.78000000","0.00014000"],["79913.79000000","0.04666000"],["79913.99000000","0.00000000"],["79914.14000000","0.01415000"],["79914.46000000","0.00000000"],["79914.47000000","0.00000000"],["79915.07000000","0.00000000"],["79915.08000000","0.00000000"],["79915.42000000","0.01671000"],["79915.68000000","0.00000000"],["79915.69000000","0.00000000"],["79915.96000000","1.04939000"],["79915.97000000","0.00000000"],["79916.52000000","0.07521000"],["79923.56000000","0.08576000"],["79924.45000000","0.00000000"]]}}}
{"rx_ns": 13894495768000, "frame": {"stream":"btcusdt@depth@100ms","data":{"e":"depthUpdate","E":1787650889714,"s":"BTCUSDT","U":99118615032,"u":99118615162,"b":[["79910.80000000","0.03149000"],["79910.79000000","0.00083000"],["79910.00000000","0.04835000"],["79909.60000000","0.00000000"],["79908.20000000","0.05374000"],["79908.00000000","0.02435000"],["79907.81000000","0.00202000"],["79907.76000000","0.00007000"],["79907.12000000","0.00007000"],["79907.11000000","0.33793000"],["79906.97000000","0.00000000"],["79906.96000000","0.02110000"],["79906.47000000","0.00289000"],["79906.01000000","0.00000000"],["79906.00000000","0.02414000"],["79905.99000000","0.01259000"],["79905.98000000","0.31301000"],["79905.81000000","0.00000000"],["79905.51000000","0.00007000"],["79905.35000000","0.00000000"],["79904.01000000","0.00000000"],["79903.74000000","0.00000000"],["79903.53000000","0.02000000"],["79903.35000000","0.00707000"],["79901.53000000","0.00000000"],["79899.62000000","0.00016000"],["79899.61000000","0.00000000"],["79898.67000000","0.08576000"],["79898.43000000","0.00000000"],["79897.88000000","0.00000000"],["79897.02000000","0.00625000"],["79895.05000000","0.00625000"],["79894.03000000","0.00800000"],["79894.02000000","0.87693000"],["79894.01000000","0.00008000"],["79893.86000000","0.00000000"],["79890.14000000","0.00000000"],["79873.95000000","0.33811000"],["79865.19000000","0.00007000"],["79833.58000000","0.35579000"],["79825.69000000","0.00000000"],["71919.72000000","0.00432000"]],"a":[["79910.81000000","4.37969000"],["79910.82000000","0.00027000"],["79913.25000000","0.00000000"],["79913.28000000","0.04077000"],["79913.78000000","0.00000000"],["79914.31000000","0.00716000"],["79914.47000000","0.00000000"],["79915.08000000","0.00000000"],["79915.41000000","0.00014000"],["79915.42000000","0.01678000"],["79915.69000000","0.06183000"],["79915.90000000","0.02000000"],["79915.95000000","0.00000000"],["79917.21000000","0.00008000"],["79918.08000000","0.00944000"],["79920.69000000","0.00000000"],["79925.40000000","0.33790000"],["79925.79000000","0.00000000"],["79946.71000000","0.00000000"]]}}}
{"rx_ns": 13894597528700, "frame": {"stream":"btcusdt@depth@100ms","data":{"e":"depthUpdate","E":1787650889814,"s":"BTCUSDT","U":99118615163,"u":99118615194,"b":[["79910.80000000","0.01115000"],["79910.04000000","0.00007000"],["79908.00000000","0.02435000"],["79903.90000000","0.04205000"],["79879.59000000","0.20875000"],["79879.25000000","0.00000000"],["79877.00000000","0.00000000"],["79833.85000000","0.02600000"],["71919.72000000","0.00416000"],["63929.00000000","0.00060000"]],"a":[["79910.81000000","4.38158000"],["79914.14000000","0.01408000"],["79914.31000000","0.00716000"],["79914.79000000","0.00000000"],["79915.41000000","0.00000000"],["79915.42000000","0.01692000"],["79925.34000000","0.00000000"]]}}}
{"rx_ns": 13894695539700, "frame": {"stream":"btcusdt@depth@100ms","data":{"e":"depthUpdate","E":1787650889914,"s":"BTCUSDT","U":99118615195,"u":99118615207,"b":[["79906.00000000","0.02421000"],["79905.99000000","0.31852000"],["79894.03000000","0.01200000"],["79865.19000000","0.00000000"],["71919.72000000","0.00432000"],["63928.64000000","0.00000000"]],"a":[["79910.81000000","4.38165000"],["79911.91000000","0.00691000"],["79915.69000000","0.00007000"],["79915.83000000","0.00400000"],["81109.48000000","0.00030000"]]}}}
{"rx_ns": 13894804058100, "frame": {"stream":"btcusdt@depth20","data":{"lastUpdateId":99118615227,"bids":[["79910.80000000","0.01163000"],["79910.79000000","0.00083000"],["79910.78000000","0.00013000"],["79910.51000000","0.00007000"],["79910.50000000","0.07909000"],["79910.35000000","0.00007000"],["79910.04000000","0.00007000"],["79910.01000000","0.00007000"],["79910.00000000","0.04835000"],["79909.90000000","0.00007000"],["79909.53000000","0.00007000"],["79909.52000000","0.01768000"],["79909.25000000","0.00007000"],["79909.20000000","0.00007000"],["79909.15000000","0.00007000"],["79909.14000000","0.00008000"],["79909.07000000","0.00007000"],["79908.60000000","0.00007000"],["79908.51000000","0.00007000"],["79908.44000000","0.00007000"]],"asks":[["79910.81000000","4.37915000"],["79910.82000000","0.00027000"],["79910.83000000","0.00013000"],["79910.95000000","0.00007000"],["79911.63000000","0.00014000"],["79911.91000000","0.00705000"],["79912.58000000","0.00400000"],["79912.86000000","0.00856000"],["79912.96000000","0.00931000"],["79913.23000000","0.00007000"],["79913.28000000","0.04077000"],["79913.56000000","0.00007000"],["79913.79000000","0.04666000"],["79914.00000000","0.04028000"],["79914.14000000","0.01408000"],["79914.31000000","0.00716000"],["79914.48000000","0.00007000"],["79915.11000000","0.00400000"],["79915.15000000","0.00007000"],["79915.42000000","0.01678000"]]}}}
{"rx_ns": 13894804171900, "frame": {"stream":"btcusdt@depth@100ms","data":{"e":"depthUpdate","E":1787650890014,"s":"BTCUSDT","U":99118615208,"u":99118615227,"b":[["79910.80000000","0.01163000"],["79899.99000000","0.48560000"],["79894.05000000","1.44073000"],["79894.04000000","1.87677000"],["79894.02000000","0.00000000"],["79688.21000000","0.00000000"],["79683.67000000","0.00770000"],["71919.72000000","0.00432000"],["71919.71000000","0.00000000"],["63928.64000000","0.00031000"]],"a":[["79910.81000000","4.37915000"],["79911.91000000","0.00705000"],["79915.42000000","0.01678000"]]}}}
{"rx_ns": 13894896837500, "frame": {"stream":"btcusdt@depth@100ms","data":{"e":"depthUpdate","E":1787650890114,"s":"BTCUSDT","U":99118615228,"u":99118615261,"b":[["79910.80000000","0.01119000"],["79897.28000000","0.00250000"],["79833.53000000","0.02086000"],["79753.45000000","1.49938000"],["71919.72000000","0.00432000"]],"a":[["79910.81000000","4.37915000"],["79913.25000000","0.00250000"],["80057.08000000","1.49938000"],["86422.88000000","0.20801000"]]}}}
{"rx_ns": 13894997411700, "frame": {"stream":"btcusdt@depth@100ms","data":{"e":"depthUpdate","E":1787650890214,"s":"BTCUSDT","U":99118615262,"u":99118615269,"b":[["79910.80000000","0.01386000"],["79833.53000000","0.00000000"],["79820.41000000","0.62553000"],["79450.00000000","0.12895000"],["71919.72000000","0.00448000"],["71919.00000000","0.00020000"],["63928.64000000","0.00000000"]],"a":[]}}}
{"rx_ns": 13895100762400, "frame": {"stream":"btcusdt@depth@100ms","data":{"e":"depthUpdate","E":1787650890314,"s":"BTCUSDT","U":99118615270,"u":99118615285,"b":[["79895.58000000","0.00007000"],["79833.53000000","0.00000000"],["71919.72000000","0.00432000"],["71919.00000000","0.00000000"],["63929.00000000","0.00060000"]],"a":[["79910.81000000","4.37902000"],["79927.56000000","0.00007000"],["79935.00000000","0.70000000"],["79937.00000000","0.00000000"],["84202.54000000","0.00884000"]]}}}
{"rx_ns": 13895199395000, "frame": {"stream":"btcusdt@depth@100ms","data":{"e":"depthUpdate","E":1787650890414,"s":"BTCUSDT","U":99118615286,"u":99118615295,"b":[["79910.80000000","0.01126000"],["79909.24000000","0.00007000"],["71919.72000000","0.00448000"]],"a":[["79914.31000000","0.00723000"],["79914.85000000","0.01386000"],["79931.96000000","0.86785000"]]}}}
{"rx_ns": 13895297268600, "frame": {"stream":"btcusdt@depth@100ms","data":{"e":"depthUpdate","E":1787650890514,"s":"BTCUSDT","U":99118615296,"u":99118615307,"b":[["79872.00000000","1.02407000"],["78712.13000000","0.00030000"],["71919.72000000","0.00416000"],["63928.64000000","0.00031000"]],"a":[["79914.31000000","0.00716000"],["79914.85000000","0.00000000"]]}}}
{"rx_ns": 13895409670300, "frame": {"stream":"btcusdt@depth@100ms","data":{"e":"depthUpdate","E":1787650890614,"s":"BTCUSDT","U":99118615308,"u":99118615321,"b":[["79894.06000000","0.00800000"],["79823.05000000","0.62553000"],["79820.41000000","0.00000000"],["71919.72000000","0.00448000"],["63928.64000000","0.00000000"]],"a":[["79914.31000000","0.00716000"],["79915.42000000","0.01685000"],["79915.89000000","0.00800000"]]}}}
{"rx_ns": 13895496275500, "frame": {"stream":"btcusdt@depth@100ms","data":{"e":"depthUpdate","E":1787650890714,"s":"BTCUSDT","U":99118615322,"u":99118615330,"b":[["79904.95000000","0.02531000"],["79903.90000000","0.00000000"],["79894.06000000","0.01200000"],["71919.72000000","0.00432000"]],"a":[["79911.12000000","0.00400000"],["79915.95000000","0.00400000"],["79943.88000000","0.01270000"]]}}}
{"rx_ns": 13895601566200, "frame": {"stream":"btcusdt@depth@100ms","data":{"e":"depthUpdate","E":1787650890814,"s":"BTCUSDT","U":99118615331,"u":99118615334,"b":[["71919.72000000","0.00432000"]],"a":[["80013.89000000","0.00566000"],["80021.54000000","0.00000000"]]}}}
{"rx_ns": 13895696019600, "frame": {"stream":"btcusdt@depth@100ms","data":{"e":"depthUpdate","E":1787650890914,"s":"BTCUSDT","U":99118615335,"u":99118615345,"b":[["79910.80000000","0.00917000"],["79908.30000000","0.00008000"],["79868.29000000","0.00000000"],["71919.72000000","0.00432000"],["63928.64000000","0.00000000"]],"a":[["79910.81000000","4.31044000"],["79911.63000000","0.00021000"],["81109.48000000","0.00030000"]]}}}
{"rx_ns": 13895803995400, "frame": {"stream":"btcusdt@depth20","data":{"lastUpdateId":99118615351,"bids":[["79910.80000000","0.00917000"],["79910.79000000","0.00083000"],["79910.78000000","0.00013000"],["79910.51000000","0.00007000"],["79910.50000000","0.07909000"],["79910.35000000","0.00007000"],["79910.04000000","0.00007000"],["79910.01000000","0.00007000"],["79910.00000000","0.04835000"],["79909.90000000","0.00007000"],["79909.53000000","0.00007000"],["79909.52000000","0.01768000"],["79909.25000000","0.00007000"],["79909.24000000","0.00007000"],["79909.20000000","0.00007000"],["79909.15000000","0.00007000"],["79909.14000000","0.00008000"],["79909.07000000","0.00007000"],["79908.60000000","0.00007000"],["79908.51000000","0.00007000"]],"asks":[["79910.81000000","4.31444000"],["79910.82000000","0.00027000"],["79910.83000000","0.00013000"],["79910.95000000","0.00007000"],["79911.12000000","0.00400000"],["79911.63000000","0.00021000"],["79911.91000000","0.00705000"],["79912.58000000","0.00400000"],["79912.86000000","0.00856000"],["79912.96000000","0.00931000"],["79913.23000000","0.00007000"],["79913.25000000","0.00250000"],["79913.28000000","0.04077000"],["79913.56000000","0.00007000"],["79913.79000000","0.04666000"],["79914.00000000","0.04028000"],["79914.14000000","0.01408000"],["79914.31000000","0.00716000"],["79914.48000000","0.00007000"],["79915.11000000","0.00400000"]]}}}
{"rx_ns": 13895804101200, "frame": {"stream":"btcusdt@depth@100ms","data":{"e":"depthUpdate","E":1787650891014,"s":"BTCUSDT","U":99118615346,"u":99118615351,"b":[["79895.91000000","0.00400000"],["71919.72000000","0.00448000"],["63928.64000000","0.00031000"]],"a":[["79910.81000000","4.31444000"]]}}}
{"rx_ns": 13895895517000, "frame": {"stream":"btcusdt@depth@100ms","data":{"e":"depthUpdate","E":1787650891114,"s":"BTCUSDT","U":99118615352,"u":99118615359,"b":[["71919.72000000","0.00432000"],["63928.64000000","0.00031000"]],"a":[["80002.55000000","1.95350000"],["80004.63000000","0.78060000"],["80005.19000000","0.00000000"]]}}}
{"rx_ns": 13896006853900, "frame": {"stream":"btcusdt@depth@100ms","data":{"e":"depthUpdate","E":1787650891214,"s":"BTCUSDT","U":99118615360,"u":99118615363,"b":[["79875.00000000","0.70000000"],["79872.00000000","0.32407000"],["71919.72000000","0.00448000"],["63928.64000000","0.00000000"]],"a":[]}}}
{"rx_ns": 13896095789100, "frame": {"stream":"btcusdt@depth@100ms","data":{"e":"depthUpdate","E":1787650891314,"s":"BTCUSDT","U":99118615364,"u":99118615381,"b":[["79895.58000000","0.00000000"],["71919.72000000","0.00432000"],["63929.00000000","0.00060000"]],"a":[["79910.81000000","4.31444000"],["79911.12000000","0.00000000"],["79911.13000000","0.00400000"],["79915.42000000","0.01685000"],["79915.82000000","0.01200000"],["79915.83000000","0.00000000"],["79915.89000000","0.00000000"],["79927.56000000","0.00000000"]]}}}
{"rx_ns": 13896196161600, "frame": {"stream":"btcusdt@depth@100ms","data":{"e":"depthUpdate","E":1787650891414,"s":"BTCUSDT","U":99118615382,"u":99118615454,"b":[["79895.98000000","0.00400000"],["79895.91000000","0.00000000"],["79895.58000000","0.00007000"],["79894.07000000","0.02400000"],["79894.06000000","0.00000000"],["79894.03000000","0.00000000"],["71919.72000000","0.00432000"],["71919.00000000","0.00000000"]],"a":[["79910.81000000","4.31425000"],["79927.56000000","0.00007000"]]}}}
{"rx_ns": 13896296025300, "frame": {"stream":"btcusdt@depth@100ms","data":{"e":"depthUpdate","E":1787650891514,"s":"BTCUSDT","U":99118615455,"u":99118615457,"b":[["78712.13000000","0.00030000"],["63928.64000000","0.00031000"]],"a":[]}}}
{"rx_ns": 13896395382600, "frame": {"stream":"btcusdt@depth@100ms","data":{"e":"depthUpdate","E":1787650891614,"s":"BTCUSDT","U":99118615458,"u":99118615462,"b":[["71919.72000000","0.00432000"],["63928.64000000","0.00000000"]],"a":[]}}}
{"rx_ns": 13896504104700, "frame": {"stream":"btcusdt@depth@100ms","data":{"e":"depthUpdate","E":1787650891714,"s":"BTCUSDT","U":99118615463,"u":99118615469,"b":[["79910.80000000","0.00913000"],["79721.39000000","0.00000000"],["79704.57000000","0.01278000"],["71919.72000000","0.00448000"]],"a":[["80202.77000000","0.01154000"],["80219.69000000","0.00000000"]]}}}
{"rx_ns": 13896598288500, "frame": {"stream":"btcusdt@depth@100ms","data":{"e":"depthUpdate","E":1787650891814,"s":"BTCUSDT","U":99118615470,"u":99118615483,"b":[["79910.80000000","0.24083000"],["79907.14000000","0.06176000"],["79906.17000000","0.03254000"],["79904.95000000","0.00000000"],["79832.83000000","0.02086000"],["72000.00000000","74.61944000"],["71919.72000000","0.00432000"]],"a":[["79910.81000000","4.31625000"],["79913.27000000","0.00007000"],["79913.78000000","0.00007000"],["79913.99000000","0.00007000"]]}}}
{"rx_ns": 13896700716100, "frame": {"stream":"btcusdt@depth@100ms","data":{"e":"depthUpdate","E":1787650891914,"s":"BTCUSDT","U":99118615484,"u":99118615697,"b":[["79910.80000000","0.24154000"],["79910.79000000","0.00104000"],["79910.50000000","0.07909000"],["79910.20000000","0.00000000"],["79910.19000000","0.00000000"],["79910.00000000","0.04835000"],["79909.59000000","0.00000000"],["79909.58000000","0.00000000"],["79909.52000000","0.01775000"],["79908.98000000","0.00000000"],["79908.97000000","0.00007000"],["79908.37000000","0.00007000"],["79908.36000000","0.06176000"],["79908.25000000","0.00007000"],["79908.21000000","0.00007000"],["79908.01000000","0.00007000"],["79908.00000000","0.02442000"],["79907.76000000","0.00014000"],["79907.75000000","0.06176000"],["79907.15000000","0.00007000"],["79907.14000000","0.06197000"],["79907.12000000","0.05952000"],["79907.11000000","0.00000000"],["79906.96000000","0.02096000"],["79906.76000000","0.00000000"],["79906.44000000","0.00000000"],["79906.40000000","0.00000000"],["79906.18000000","0.00007000"],["79906.01000000","0.06176000"],["79906.00000000","0.02400000"],["79905.99000000","0.58000000"],["79905.98000000","0.31294000"],["79905.51000000","0.00000000"],["79904.31000000","1.04939000"],["79902.73000000","0.60014000"],["79900.24000000","1.04987000"],["79900.01000000","0.00000000"],["79899.28000000","0.00250000"],["79897.28000000","0.00000000"],["79890.14000000","0.36586000"],["79833.58000000","0.00000000"],["79832.83000000","0.00000000"],["79046.19000000","0.00012000"],["71919.72000000","0.00448000"]],"a":[["79910.81000000","2.36926000"],["79910.82000000","0.00027000"],["79911.13000000","0.00000000"],["79911.91000000","0.00712000"],["79911.97000000","0.00400000"],["79912.03000000","0.06176000"],["79912.37000000","0.00400000"],["79912.57000000","0.00625000"],["79912.64000000","0.06176000"],["79912.96000000","0.00938000"],["79913.24000000","0.00007000"],["79913.25000000","0.06176000"],["79913.28000000","0.10823000"],["79913.77000000","0.00007000"],["79913.78000000","0.06183000"],["79914.31000000","0.00723000"],["79914.46000000","0.00007000"],["79914.47000000","0.06183000"],["79915.07000000","0.00000000"],["79915.08000000","0.06176000"],["79915.25000000","0.00250000"],["79915.41000000","0.00000000"],["79915.68000000","0.00000000"],["79915.69000000","0.06183000"],["79915.82000000","0.01207000"],["79915.88000000","0.00000000"],["79915.89000000","0.06176000"],["79915.95000000","0.00400000"],["79915.97000000","0.00000000"],["79916.14000000","0.00000000"],["79916.15000000","0.19094000"],["79916.16000000","2.73921000"],["79916.52000000","0.07514000"],["79916.98000000","1.40888000"],["79917.44000000","0.24631000"],["79918.08000000","0.00937000"],["81109.48000000","0.00030000"]]}}}
{"rx_ns": 13896796341700, "frame": {"stream":"btcusdt@depth20","data":{"lastUpdateId":99118615761,"bids":[["79910.80000000","0.24140000"],["79910.79000000","0.00090000"],["79910.78000000","0.00013000"],["79910.51000000","0.00007000"],["79910.50000000","0.07909000"],["79910.35000000","0.00007000"],["79910.04000000","0.00007000"],["79910.01000000","0.00007000"],["79910.00000000","0.04835000"],["79909.90000000","0.00007000"],["79909.53000000","0.00007000"],["79909.52000000","0.01775000"],["79909.25000000","0.00007000"],["79909.24000000","0.00007000"],["79909.20000000","0.00007000"],["79909.15000000","0.00007000"],["79909.14000000","0.00008000"],["79909.07000000","0.00007000"],["79908.97000000","0.00007000"],["79908.60000000","0.00007000"]],"asks":[["79910.81000000","2.36918000"],["79910.82000000","0.00027000"],["79910.83000000","0.00013000"],["79910.95000000","0.00007000"],["79911.63000000","0.00021000"],["79911.91000000","0.00719000"],["79911.97000000","0.00400000"],["79912.02000000","0.00007000"],["79912.03000000","0.06190000"],["79912.37000000","0.00400000"],["79912.57000000","0.00646000"],["79912.58000000","0.00400000"],["79912.63000000","0.00007000"],["79912.64000000","0.06190000"],["79912.86000000","0.00856000"],["79912.96000000","0.00938000"],["79913.23000000","0.00007000"],["79913.24000000","0.00007000"],["79913.25000000","0.06190000"],["79913.27000000","0.00007000"]]}}}
{"rx_ns": 13896796455500, "frame": {"stream":"btcusdt@depth@100ms","data":{"e":"depthUpdate","E":1787650892014,"s":"BTCUSDT","U":99118615698,"u":99118615761,"b":[["79910.80000000","0.24140000"],["79910.79000000","0.00090000"],["79909.52000000","0.01775000"],["79908.36000000","0.06190000"],["79908.00000000","0.02435000"],["79907.86000000","0.00000000"],["79907.14000000","0.06183000"],["71919.72000000","0.00432000"],["63928.64000000","0.00031000"]],"a":[["79910.81000000","2.36918000"],["79911.91000000","0.00719000"],["79912.02000000","0.00007000"],["79912.03000000","0.06190000"],["79912.57000000","0.00646000"],["79912.63000000","0.00007000"],["79912.64000000","0.06190000"],["79912.96000000","0.00938000"],["79913.25000000","0.06190000"],["79913.28000000","0.10823000"],["79913.79000000","0.04652000"],["79914.00000000","0.04014000"],["79914.14000000","0.01394000"],["79914.31000000","0.00709000"],["79915.07000000","0.00007000"],["79916.52000000","0.07500000"]]}}}
{"rx_ns": 13896896958900, "frame": {"stream":"btcusdt@depth@100ms","data":{"e":"depthUpdate","E":1787650892114,"s":"BTCUSDT","U":99118615762,"u":99118615771,"b":[["79910.80000000","0.24127000"],["79910.04000000","0.00000000"],["71919.72000000","0.00432000"],["63928.64000000","0.00031000"]],"a":[["79911.63000000","0.00014000"],["79916.16000000","2.73914000"],["79916.38000000","0.00000000"]]}}}
{"rx_ns": 13896998620500, "frame": {"stream":"btcusdt@depth@100ms","data":{"e":"depthUpdate","E":1787650892214,"s":"BTCUSDT","U":99118615772,"u":99118615847,"b":[["79910.80000000","0.46649000"],["79910.79000000","0.00083000"],["79907.81000000","0.00000000"],["79907.12000000","0.05959000"],["79907.08000000","0.04503000"],["79906.96000000","0.02096000"],["79906.47000000","0.00000000"],["79906.17000000","0.00000000"],["79903.89000000","0.00014000"],["79899.38000000","1.23661000"],["79899.37000000","1.87677000"],["79899.36000000","0.00000000"],["79893.72000000","0.33810000"],["79873.95000000","0.00000000"],["79775.60000000","0.04908000"],["79770.96000000","0.00000000"],["71919.72000000","0.00432000"],["63928.64000000","0.00000000"]],"a":[["79910.81000000","2.33765000"],["79911.78000000","0.00000000"],["79911.97000000","0.00000000"],["79912.02000000","0.00000000"],["79912.03000000","0.00014000"],["79912.06000000","0.00000000"],["79912.08000000","0.00400000"],["79912.37000000","0.00000000"],["79912.76000000","0.00000000"],["79912.90000000","0.00400000"],["79912.91000000","0.00000000"],["79913.77000000","0.00000000"],["79913.78000000","0.00007000"],["79915.68000000","0.00007000"],["79915.82000000","0.00007000"],["79915.88000000","0.01207000"],["79915.96000000","0.00000000"],["79943.81000000","0.00653000"],["79952.81000000","0.00000000"],["80002.55000000","0.00000000"],["80004.63000000","1.24837000"],["80005.19000000","1.95350000"],["80010.65000000","0.00000000"],["80015.30000000","0.02804000"]]}}}
{"rx_ns": 13897095635200, "frame": {"stream":"btcusdt@depth@100ms","data":{"e":"depthUpdate","E":1787650892314,"s":"BTCUSDT","U":99118615848,"u":99118615900,"b":[["79910.80000000","0.46934000"],["79910.79000000","0.00090000"],["79908.36000000","0.06197000"],["79908.35000000","0.00007000"],["79908.34000000","0.03174000"],["79907.76000000","0.00014000"],["79907.15000000","0.00000000"],["79907.12000000","0.05952000"],["79907.08000000","0.00000000"],["79906.96000000","0.02110000"],["79906.02000000","0.01600000"],["79894.07000000","0.00800000"],["79688.21000000","0.00770000"],["79683.67000000","0.00000000"],["71919.72000000","0.00448000"],["63929.00000000","0.00060000"]],"a":[["79910.81000000","2.33576000"],["79911.91000000","0.00712000"],["79912.03000000","0.00000000"],["79913.28000000","0.10823000"],["79913.79000000","0.04666000"],["79915.07000000","0.00007000"],["79915.68000000","0.00007000"],["79915.88000000","0.01207000"],["79920.81000000","0.00187000"],["79957.46000000","0.02880000"]]}}}
{"rx_ns": 13897195556500, "frame": {"stream":"btcusdt@depth@100ms","data":{"e":"depthUpdate","E":1787650892414,"s":"BTCUSDT","U":99118615901,"u":99118615924,"b":[["79908.36000000","0.06197000"],["79908.12000000","0.00000000"],["79906.96000000","0.02103000"],["79906.02000000","0.00000000"],["79900.25000000","0.01600000"],["79895.58000000","0.00007000"],["71919.72000000","0.00416000"]],"a":[["79911.91000000","0.00021000"],["79915.97000000","1.04939000"],["79916.25000000","0.00000000"],["79927.56000000","0.00007000"]]}}}
{"rx_ns": 13897295229600, "frame": {"stream":"btcusdt@depth@100ms","data":{"e":"depthUpdate","E":1787650892514,"s":"BTCUSDT","U":99118615925,"u":99118615966,"b":[["79906.02000000","0.01600000"],["79906.01000000","0.06176000"],["79906.00000000","0.02400000"],["79900.25000000","0.00000000"],["78712.13000000","0.00030000"],["71919.72000000","0.00448000"],["71919.00000000","0.00000000"],["63928.64000000","0.00031000"]],"a":[["79910.81000000","2.33576000"],["79911.91000000","0.00007000"],["79914.00000000","0.04028000"],["79915.90000000","0.00000000"],["79918.72000000","0.02000000"],["80222.37000000","0.00000000"]]}}}
{"rx_ns": 13897399889200, "frame": {"stream":"btcusdt@depth@100ms","data":{"e":"depthUpdate","E":1787650892614,"s":"BTCUSDT","U":99118615967,"u":99118615978,"b":[["79906.96000000","0.02110000"],["79906.85000000","0.00000000"],["79861.98000000","0.00400000"],["79860.99000000","0.00000000"],["79832.83000000","0.02086000"],["71919.72000000","0.00432000"],["63928.64000000","0.00000000"]],"a":[["79912.43000000","0.00007000"],["79915.69000000","0.06176000"],["79955.36000000","0.00000000"]]}}}
{"rx_ns": 13897506871400, "frame": {"stream":"btcusdt@depth@100ms","data":{"e":"depthUpdate","E":1787650892714,"s":"BTCUSDT","U":99118615979,"u":99118616171,"b":[["79910.80000000","1.19338000"],["79910.79000000","0.00104000"],["79910.46000000","0.00202000"],["79909.52000000","0.01782000"],["79909.42000000","0.00007000"],["79909.41000000","0.03456000"],["79908.39000000","0.00007000"],["79908.38000000","0.38950000"],["79908.37000000","1.04939000"],["79908.36000000","0.00014000"],["79908.35000000","0.00000000"],["79908.34000000","0.00000000"],["79908.25000000","0.00000000"],["79908.21000000","0.00000000"],["79908.01000000","0.00000000"],["79908.00000000","0.02421000"],["79907.76000000","0.00014000"],["79907.75000000","0.00000000"],["79907.15000000","0.00000000"],["79907.14000000","0.00000000"],["79907.12000000","0.00000000"],["79906.96000000","0.02110000"],["79906.90000000","0.00007000"],["79906.89000000","0.12523000"],["79906.03000000","0.00400000"],["79906.02000000","0.01207000"],["79906.01000000","0.00000000"],["79906.00000000","0.02414000"],["79905.99000000","0.56762000"],["79905.51000000","0.00000000"],["79903.31000000","0.03224000"],["79902.91000000","0.00015000"],["79900.57000000","0.00400000"],["79900.56000000","0.00625000"],["79900.18000000","0.00250000"],["79900.01000000","0.00625000"],["79899.62000000","0.00000000"],["79899.28000000","0.00000000"],["79897.02000000","0.00000000"],["79895.98000000","0.00000000"],["79895.05000000","0.00000000"],["71919.72000000","0.00456000"]],"a":[["79910.81000000","2.33769000"],["79910.82000000","0.00055000"],["79912.08000000","0.00000000"],["79912.56000000","0.00051000"],["79912.57000000","0.00021000"],["79912.63000000","0.00000000"],["79912.64000000","0.00014000"],["79912.90000000","0.00000000"],["79913.24000000","0.00000000"],["79913.25000000","0.00014000"],["79913.28000000","0.07557000"],["79913.60000000","0.00000000"],["79913.77000000","0.00000000"],["79914.00000000","0.04021000"],["79914.31000000","0.00716000"],["79914.46000000","0.00000000"],["79914.47000000","0.00007000"],["79914.96000000","0.00000000"],["79915.06000000","0.00625000"],["79915.25000000","0.00000000"],["79915.35000000","0.00000000"],["79915.47000000","0.00400000"],["79915.63000000","0.00400000"],["79915.80000000","0.00000000"],["79915.87000000","0.01200000"],["79915.88000000","0.00007000"],["79915.97000000","0.00007000"],["79916.14000000","0.00007000"],["79916.15000000","0.19351000"],["79925.40000000","0.00000000"],["79945.33000000","0.33781000"],["79945.38000000","0.09574000"]]}}}
{"rx_ns": 13897605440000, "frame": {"stream":"btcusdt@depth@100ms","data":{"e":"depthUpdate","E":1787650892814,"s":"BTCUSDT","U":99118616172,"u":99118616237,"b":[["79909.52000000","0.01775000"],["79909.41000000","0.03470000"],["79908.97000000","0.00000000"],["79908.36000000","0.00000000"],["79908.00000000","0.02407000"],["79906.89000000","0.00000000"],["79906.03000000","0.00000000"],["79906.02000000","0.00007000"],["79905.82000000","0.00652000"],["79905.78000000","0.00000000"],["79900.25000000","0.01600000"],["79892.79000000","0.33803000"],["79882.78000000","0.00000000"],["79837.71000000","0.54024000"],["79832.83000000","0.00000000"],["71919.72000000","0.00440000"]],"a":[["79910.81000000","2.33776000"],["79911.91000000","0.00000000"],["79912.57000000","0.00000000"],["79912.64000000","0.00000000"],["79912.96000000","0.00014000"],["79913.16000000","0.00914000"],["79913.25000000","0.00000000"],["79914.14000000","0.01408000"],["79914.31000000","0.00028000"],["79914.56000000","0.00687000"],["79915.06000000","0.00639000"],["79915.41000000","0.00007000"],["79915.69000000","0.06183000"],["79916.14000000","0.00000000"],["79916.15000000","0.00257000"],["79916.97000000","0.00000000"]]}}}
{"rx_ns": 13897695520700, "frame": {"stream":"btcusdt@depth@100ms","data":{"e":"depthUpdate","E":1787650892914,"s":"BTCUSDT","U":99118616238,"u":99118616282,"b":[["79910.80000000","1.19331000"],["79906.96000000","0.02103000"],["79906.90000000","0.00000000"],["79905.98000000","0.31301000"],["79905.51000000","0.00007000"],["79902.91000000","0.00000000"],["71919.72000000","0.00440000"]],"a":[["79910.81000000","2.33776000"],["79910.82000000","0.00055000"],["79912.86000000","0.00856000"],["79912.96000000","0.00000000"],["79913.16000000","0.00928000"],["79914.14000000","0.01415000"],["79914.31000000","0.00014000"],["79914.56000000","0.00701000"],["79915.41000000","0.00000000"],["79915.97000000","0.00007000"],["79916.15000000","0.00257000"],["79916.97000000","0.00007000"],["79945.38000000","0.00000000"],["79946.88000000","0.09266000"],["81109.48000000","0.00030000"]]}}}
{"rx_ns": 13897795790900, "frame": {"stream":"btcusdt@depth20","data":{"lastUpdateId":99118616328,"bids":[["79910.80000000","1.19182000"],["79910.79000000","0.00104000"],["79910.78000000","0.00013000"],["79910.51000000","0.00007000"],["79910.50000000","0.07909000"],["79910.46000000","0.00202000"],["79910.35000000","0.00007000"],["79910.01000000","0.00007000"],["79910.00000000","0.04835000"],["79909.90000000","0.00007000"],["79909.53000000","0.00007000"],["79909.52000000","0.01775000"],["79909.42000000","0.00007000"],["79909.41000000","0.03470000"],["79909.25000000","0.00007000"],["79909.24000000","0.00007000"],["79909.20000000","0.00007000"],["79909.15000000","0.00007000"],["79909.14000000","0.00008000"],["79909.07000000","0.00007000"]],"asks":[["79910.81000000","2.33769000"],["79910.82000000","0.00055000"],["79910.83000000","0.00013000"],["79910.95000000","0.00007000"],["79911.63000000","0.00014000"],["79912.43000000","0.00007000"],["79912.56000000","0.00051000"],["79912.58000000","0.00400000"],["79912.86000000","0.00856000"],["79913.16000000","0.00928000"],["79913.23000000","0.00007000"],["79913.27000000","0.00007000"],["79913.28000000","0.07557000"],["79913.56000000","0.00007000"],["79913.78000000","0.00007000"],["79913.79000000","0.04666000"],["79913.99000000","0.00007000"],["79914.00000000","0.04021000"],["79914.14000000","0.01415000"],["79914.31000000","0.00014000"]]}}}
{"rx_ns": 13897795886500, "frame": {"stream":"btcusdt@depth@100ms","data":{"e":"depthUpdate","E":1787650893014,"s":"BTCUSDT","U":99118616283,"u":99118616328,"b":[["79910.80000000","1.19182000"],["79908.38000000","0.38964000"],["79908.00000000","0.02407000"],["79907.62000000","0.00000000"],["79907.61000000","0.00000000"],["79907.34000000","0.00000000"],["79906.00000000","0.02414000"],["79905.99000000","0.56762000"],["79905.51000000","0.00007000"],["79861.60000000","0.02541000"],["79811.62000000","0.00000000"],["79776.19000000","0.01960000"],["79770.61000000","0.00000000"],["71919.72000000","0.00432000"],["71919.71000000","0.00008000"],["63928.64000000","0.00031000"]],"a":[["79910.81000000","2.33769000"],["79915.82000000","0.00000000"],["79915.88000000","0.00000000"],["79915.89000000","0.00000000"],["79915.97000000","0.00007000"],["79916.15000000","0.00257000"],["79916.41000000","0.12523000"],["79916.97000000","0.00007000"],["80122.65000000","0.01960000"],["80138.70000000","0.00000000"]]}}}
{"rx_ns": 13897895763800, "frame": {"stream":"btcusdt@depth@100ms","data":{"e":"depthUpdate","E":1787650893114,"s":"BTCUSDT","U":99118616329,"u":99118616360,"b":[["79910.80000000","1.32725000"],["79909.24000000","0.00000000"],["79905.82000000","0.00659000"],["79905.52000000","0.00699000"],["79901.47000000","0.00250000"],["79900.18000000","0.00000000"],["79869.06000000","0.00000000"],["79868.61000000","0.00014000"],["71919.72000000","0.00432000"],["63928.64000000","0.00031000"]],"a":[["79910.81000000","2.33817000"],["79912.43000000","0.00000000"],["79914.46000000","0.00007000"],["79914.47000000","0.06183000"],["79915.42000000","0.01678000"],["79915.87000000","0.01207000"],["79915.96000000","0.00007000"],["79915.97000000","0.06183000"],["79916.15000000","0.00007000"],["79916.97000000","0.00000000"],["79917.45000000","0.00250000"]]}}}
{"rx_ns": 13897996128700, "frame": {"stream":"btcusdt@depth@100ms","data":{"e":"depthUpdate","E":1787650893214,"s":"BTCUSDT","U":99118616361,"u":99118616387,"b":[["79910.80000000","1.32732000"],["79908.00000000","0.02414000"],["79907.19000000","0.00007000"],["79907.18000000","0.00000000"],["79906.85000000","0.00007000"],["79905.51000000","0.00000000"],["71919.72000000","0.00448000"],["63928.64000000","0.00000000"]],"a":[["79914.14000000","0.01415000"],["79914.47000000","0.06197000"],["79915.06000000","0.00625000"],["79915.96000000","0.00007000"],["79915.97000000","0.06183000"],["79916.15000000","0.00007000"],["79944.12000000","1.20166000"],["79956.62000000","0.00000000"]]}}}
{"rx_ns": 13898096309300, "frame": {"stream":"btcusdt@depth@100ms","data":{"e":"depthUpdate","E":1787650893314,"s":"BTCUSDT","U":99118616388,"u":99118616428,"b":[["79910.80000000","1.32732000"],["79908.00000000","0.02414000"],["79907.62000000","0.00000000"],["79907.39000000","0.00007000"],["79907.38000000","0.00000000"],["79907.19000000","0.00000000"],["79906.83000000","0.12523000"],["79905.51000000","0.00000000"],["79832.83000000","0.02086000"],["71919.72000000","0.00432000"],["63929.00000000","0.00060000"]],"a":[["79915.96000000","0.00007000"],["79915.97000000","0.06183000"],["79916.15000000","0.00007000"],["79916.38000000","0.12523000"],["79916.41000000","0.00000000"]]}}}
{"rx_ns": 13898201904400, "frame": {"stream":"btcusdt@depth@100ms","data":{"e":"depthUpdate","E":1787650893414,"s":"BTCUSDT","U":99118616429,"u":99118616454,"b":[["79910.80000000","1.32690000"],["79908.00000000","0.02407000"],["79907.39000000","0.00000000"],["79906.96000000","0.02110000"],["79906.84000000","0.00007000"],["79895.58000000","0.00007000"],["71919.72000000","0.00448000"],["71919.71000000","0.00000000"]],"a":[["79910.81000000","2.33824000"],["79910.82000000","0.00062000"],["79912.40000000","0.00000000"],["79915.42000000","0.01671000"],["79915.96000000","0.00007000"],["79915.97000000","0.06183000"],["79916.15000000","0.00007000"],["79927.56000000","0.00007000"],["80264.74000000","0.00018000"]]}}}
{"rx_ns": 13898297254700, "frame": {"stream":"btcusdt@depth@100ms","data":{"e":"depthUpdate","E":1787650893514,"s":"BTCUSDT","U":99118616455,"u":99118616469,"b":[["79910.80000000","1.32554000"],["78712.13000000","0.00030000"],["71919.72000000","0.00432000"],["71919.00000000","0.00000000"],["63928.64000000","0.00031000"]],"a":[["79910.81000000","2.33817000"],["79910.82000000","0.00055000"],["79916.38000000","0.00000000"],["79916.46000000","0.12523000"],["80039.44000000","0.01960000"],["80116.60000000","0.00000000"]]}}}
{"rx_ns": 13898396675800, "frame": {"stream":"btcusdt@depth@100ms","data":{"e":"depthUpdate","E":1787650893614,"s":"BTCUSDT","U":99118616470,"u":99118616479,"b":[["79910.80000000","1.32568000"],["79908.20000000","0.05381000"],["79908.06000000","0.00925000"],["71919.72000000","0.00448000"],["63928.64000000","0.00000000"]],"a":[["79910.81000000","2.33875000"]]}}}
{"rx_ns": 13898504006400, "frame": {"stream":"btcusdt@depth@100ms","data":{"e":"depthUpdate","E":1787650893714,"s":"BTCUSDT","U":99118616480,"u":99118616712,"b":[["79910.80000000","1.45199000"],["79910.79000000","0.00111000"],["79910.00000000","0.04842000"],["79909.59000000","0.00007000"],["79909.58000000","0.00000000"],["79909.53000000","0.00033000"],["79909.52000000","0.01782000"],["79909.42000000","0.00000000"],["79909.41000000","0.00021000"],["79908.98000000","0.00007000"],["79908.97000000","0.00007000"],["79908.40000000","0.00007000"],["79908.39000000","0.06183000"],["79908.38000000","0.38964000"],["79908.37000000","1.04953000"],["79908.20000000","0.05381000"],["79906.84000000","0.00007000"],["79906.00000000","0.02407000"],["79905.99000000","1.11279000"],["79905.51000000","0.00000000"],["79904.82000000","0.00163000"],["79904.32000000","1.88302000"],["79904.18000000","0.00250000"],["79901.47000000","0.00000000"],["79900.57000000","0.00000000"],["79900.01000000","0.00000000"],["79898.36000000","0.37557000"],["79896.71000000","0.00000000"],["79873.34000000","1.23977000"],["79872.28000000","0.02400000"],["79843.32000000","0.00000000"],["71919.72000000","0.00424000"]],"a":[["79910.81000000","1.37734000"],["79911.63000000","0.00007000"],["79912.56000000","0.00000000"],["79913.16000000","0.00014000"],["79913.25000000","0.06176000"],["79913.78000000","0.06183000"],["79913.99000000","0.00000000"],["79914.00000000","0.00021000"],["79914.13000000","0.00007000"],["79914.30000000","0.00000000"],["79914.31000000","0.00007000"],["79914.56000000","0.00014000"],["79915.06000000","0.00000000"],["79915.47000000","0.00000000"],["79915.63000000","0.00000000"],["79915.84000000","0.00000000"],["79915.87000000","0.00007000"],["79915.95000000","0.00000000"],["79915.96000000","0.01207000"],["79915.97000000","0.06190000"],["79915.98000000","0.89200000"],["79916.15000000","0.00007000"],["79916.16000000","0.52087000"],["79916.45000000","0.00058000"],["79916.52000000","0.00000000"],["79916.66000000","0.00000000"],["79916.70000000","0.01657000"],["79916.76000000","0.00699000"],["79916.98000000","1.36888000"],["79917.43000000","0.00000000"],["79917.44000000","0.20631000"],["79917.45000000","0.00000000"],["79917.77000000","0.00000000"],["79918.07000000","0.00625000"],["79918.14000000","0.00000000"],["79918.42000000","0.00000000"],["79918.72000000","0.02000000"],["79918.81000000","0.20250000"],["79918.92000000","0.00000000"],["79919.05000000","0.00000000"],["79919.11000000","0.00000000"],["79919.15000000","0.00000000"],["79919.16000000","0.00000000"],["79919.47000000","0.00000000"],["79919.61000000","0.00000000"],["79919.63000000","0.00000000"],["79919.79000000","0.00000000"],["79919.83000000","0.00000000"],["79919.98000000","0.57741000"],["79919.99000000","0.10459000"],["79920.15000000","0.00250000"],["79923.90000000","0.00000000"],["79925.98000000","0.00000000"],["79926.95000000","0.00172000"],["79930.97000000","0.00625000"],["79931.96000000","0.63433000"],["79932.35000000","0.00000000"],["79934.41000000","0.00000000"],["79935.00000000","0.00000000"],["79935.74000000","0.00000000"],["79951.99000000","0.00000000"],["79952.03000000","0.33778000"],["79953.00000000","0.00000000"],["79984.36000000","1.23805000"],["80005.19000000","0.00000000"],["80007.83000000","1.95350000"]]}}}
{"rx_ns": 13898612320200, "frame": {"stream":"btcusdt@depth@100ms","data":{"e":"depthUpdate","E":1787650893814,"s":"BTCUSDT","U":99118616713,"u":99118616851,"b":[["79910.80000000","1.45387000"],["79910.79000000","0.00104000"],["79910.00000000","0.04835000"],["79909.59000000","0.00000000"],["79909.53000000","0.00007000"],["79909.52000000","0.01782000"],["79909.41000000","0.00007000"],["79908.98000000","0.00000000"],["79908.40000000","0.00407000"],["79908.39000000","0.06197000"],["79906.84000000","0.00007000"],["79906.00000000","0.02414000"],["79905.99000000","1.11286000"],["79904.18000000","0.00000000"],["79903.05000000","0.00250000"],["79900.25000000","0.00000000"],["79899.75000000","0.00000000"],["79832.83000000","0.00000000"],["79775.60000000","0.00000000"],["71919.72000000","0.00456000"]],"a":[["79910.81000000","1.38194000"],["79910.82000000","0.00055000"],["79911.63000000","0.00014000"],["79912.63000000","0.00007000"],["79912.64000000","0.06176000"],["79912.86000000","0.00870000"],["79912.94000000","0.00709000"],["79913.16000000","0.00000000"],["79913.23000000","0.00014000"],["79913.24000000","0.11720000"],["79913.25000000","0.06190000"],["79913.27000000","0.00000000"],["79913.28000000","0.00021000"],["79913.77000000","0.00007000"],["79913.78000000","0.06197000"],["79913.79000000","0.04666000"],["79914.00000000","0.00007000"],["79914.13000000","0.00000000"],["79914.14000000","0.01408000"],["79914.47000000","0.06197000"],["79914.56000000","0.00000000"],["79915.07000000","0.00007000"],["79915.08000000","0.06190000"],["79915.68000000","0.00033000"],["79915.69000000","0.06190000"],["79915.96000000","0.01207000"],["79915.97000000","0.06183000"],["79916.15000000","0.00000000"],["79916.16000000","0.52087000"],["79916.46000000","0.00000000"],["79916.70000000","0.01664000"],["79919.02000000","0.00250000"],["79919.96000000","0.87063000"],["79919.97000000","1.04939000"],["79919.98000000","0.00000000"],["79920.15000000","0.00000000"],["79924.10000000","0.97987000"],["79924.12000000","1.87684000"],["79925.59000000","1.04939000"],["80004.63000000","0.78060000"],["80039.44000000","0.00000000"],["80064.81000000","0.01960000"]]}}}
{"rx_ns": 13898695607400, "frame": {"stream":"btcusdt@depth@100ms","data":{"e":"depthUpdate","E":1787650893914,"s":"BTCUSDT","U":99118616852,"u":99118616976,"b":[["79910.80000000","1.16137000"],["79910.79000000","0.00097000"],["79908.40000000","0.00400000"],["79908.39000000","0.00021000"],["79908.20000000","0.05381000"],["79908.16000000","0.00000000"],["79907.98000000","0.00692000"],["79906.00000000","0.02414000"],["79905.99000000","0.56762000"],["79905.51000000","0.00007000"],["79904.32000000","0.00000000"],["79902.91000000","0.00625000"],["79900.98000000","0.00000000"],["79900.77000000","0.00189000"],["79898.36000000","0.00000000"],["79889.01000000","0.00000000"],["79879.59000000","0.36896000"],["79876.94000000","0.62612000"],["79875.00000000","0.00000000"],["79769.40000000","0.04532000"],["71919.72000000","0.00440000"]],"a":[["79910.81000000","1.38229000"],["79910.82000000","0.00076000"],["79911.29000000","0.22428000"],["79911.30000000","0.15323000"],["79911.34000000","0.00915000"],["79911.41000000","0.00007000"],["79911.42000000","0.06183000"],["79912.02000000","0.00007000"],["79912.03000000","0.06176000"],["79912.64000000","0.06190000"],["79912.86000000","0.00870000"],["79912.94000000","0.00723000"],["79913.24000000","0.00021000"],["79913.25000000","0.06190000"],["79913.28000000","0.00007000"],["79913.77000000","0.00007000"],["79913.78000000","0.06197000"],["79914.46000000","0.00007000"],["79914.47000000","0.06183000"],["79915.07000000","0.00000000"],["79915.08000000","0.06176000"],["79915.42000000","0.01664000"],["79915.68000000","0.00026000"],["79915.77000000","0.00000000"],["79915.94000000","1.49942000"],["79915.95000000","1.87677000"],["79915.96000000","0.01200000"],["79915.97000000","0.00007000"],["79915.98000000","0.00000000"],["79918.76000000","0.00165000"],["79926.95000000","0.00007000"],["79983.99000000","0.39907000"],["80007.82000000","0.99983000"],["80010.27000000","0.00000000"],["80064.81000000","0.00000000"],["81109.48000000","0.00030000"]]}}}
{"rx_ns": 13898807615100, "frame": {"stream":"btcusdt@depth20","data":{"lastUpdateId":99118617095,"bids":[["79910.80000000","1.16130000"],["79910.79000000","0.00083000"],["79910.78000000","0.00013000"],["79910.51000000","0.00007000"],["79910.50000000","0.07909000"],["79910.46000000","0.00202000"],["79910.35000000","0.00007000"],["79910.01000000","0.00007000"],["79910.00000000","0.04835000"],["79909.90000000","0.00007000"],["79909.53000000","0.00007000"],["79909.52000000","0.01782000"],["79909.41000000","0.00007000"],["79909.25000000","0.00007000"],["79909.20000000","0.00007000"],["79909.15000000","0.00007000"],["79909.14000000","0.00008000"],["79909.07000000","0.00007000"],["79908.97000000","0.00007000"],["79908.60000000","0.00007000"]],"asks":[["79910.81000000","1.44254000"],["79910.82000000","0.00097000"],["79910.83000000","0.00013000"],["79910.95000000","0.00007000"],["79911.28000000","0.00007000"],["79911.29000000","0.22442000"],["79911.30000000","0.15344000"],["79911.34000000","0.00929000"],["79911.41000000","0.00007000"],["79911.42000000","0.06197000"],["79911.63000000","0.00014000"],["79912.02000000","0.00007000"],["79912.03000000","0.06190000"],["79912.58000000","0.00400000"],["79912.63000000","0.00007000"],["79912.64000000","0.06190000"],["79912.86000000","0.00870000"],["79912.94000000","0.00723000"],["79913.23000000","0.00007000"],["79913.24000000","0.00007000"]]}}}
{"rx_ns": 13898807705700, "frame": {"stream":"btcusdt@depth@100ms","data":{"e":"depthUpdate","E":1787650894014,"s":"BTCUSDT","U":99118616977,"u":99118617095,"b":[["79910.80000000","1.16130000"],["79910.79000000","0.00083000"],["79909.52000000","0.01782000"],["79908.40000000","0.00000000"],["79908.39000000","0.00007000"],["79908.38000000","0.03308000"],["79908.37000000","0.00014000"],["79908.25000000","0.00007000"],["79908.21000000","0.00007000"],["79908.06000000","0.00939000"],["79908.01000000","0.00007000"],["79908.00000000","0.02414000"],["79907.98000000","0.00000000"],["79907.89000000","0.00700000"],["79906.97000000","0.00007000"],["79906.84000000","0.00007000"],["79906.00000000","0.02407000"],["79905.99000000","0.56755000"],["79905.51000000","0.00000000"],["79903.05000000","0.00000000"],["79902.10000000","0.00250000"],["79900.25000000","0.00400000"],["79850.00000000","0.02407000"],["71919.72000000","0.00440000"],["63928.64000000","0.00031000"]],"a":[["79910.81000000","1.44254000"],["79910.82000000","0.00097000"],["79911.28000000","0.00007000"],["79911.29000000","0.22442000"],["79911.30000000","0.15344000"],["79911.34000000","0.00929000"],["79911.42000000","0.06197000"],["79912.03000000","0.06190000"],["79912.94000000","0.00723000"],["79913.23000000","0.00007000"],["79913.24000000","0.00007000"],["79913.25000000","0.06176000"],["79913.77000000","0.00007000"],["79913.78000000","0.06183000"],["79913.79000000","0.04652000"],["79914.14000000","0.01394000"],["79914.46000000","0.00007000"],["79915.92000000","0.06176000"],["79915.93000000","1.04939000"],["79915.94000000","1.43766000"],["79916.70000000","0.01657000"],["79916.77000000","0.12522000"],["79918.07000000","0.00875000"],["79919.02000000","0.00000000"],["80039.44000000","0.01960000"],["80070.77000000","0.00000000"]]}}}
{"rx_ns": 13898900122300, "frame": {"stream":"btcusdt@depth@100ms","data":{"e":"depthUpdate","E":1787650894114,"s":"BTCUSDT","U":99118617096,"u":99118617144,"b":[["79910.80000000","1.16137000"],["79908.38000000","0.03308000"],["79908.37000000","0.00000000"],["79908.00000000","0.02428000"],["79907.89000000","0.00007000"],["79907.82000000","0.00707000"],["79907.75000000","0.06176000"],["79907.15000000","0.00007000"],["79907.14000000","0.06176000"],["79906.96000000","0.02117000"],["79906.84000000","0.06176000"],["79906.01000000","0.06176000"],["79700.91000000","0.00793000"],["79688.21000000","0.00000000"],["71919.72000000","0.00440000"],["63928.64000000","0.00031000"]],"a":[["79910.81000000","1.38236000"],["79910.82000000","0.00076000"],["79911.29000000","0.16693000"],["79911.34000000","0.00014000"],["79911.41000000","0.00000000"],["79911.42000000","0.00021000"],["79912.02000000","0.00000000"],["79912.03000000","0.00014000"],["79912.63000000","0.00000000"],["79912.64000000","0.00014000"],["79912.94000000","0.00014000"],["79913.91000000","0.00945000"],["79915.07000000","0.00007000"],["79915.68000000","0.00033000"],["79915.69000000","0.06197000"],["79915.91000000","0.00007000"],["79915.93000000","0.00000000"]]}}}
{"rx_ns": 13898995540100, "frame": {"stream":"btcusdt@depth@100ms","data":{"e":"depthUpdate","E":1787650894214,"s":"BTCUSDT","U":99118617145,"u":99118617208,"b":[["79910.80000000","1.16151000"],["79909.24000000","0.00007000"],["79908.38000000","0.04910000"],["79908.00000000","0.02435000"],["79907.82000000","0.00714000"],["79907.76000000","0.00021000"],["79906.97000000","0.00000000"],["79905.98000000","0.31294000"],["79905.82000000","0.00652000"],["71919.72000000","0.00424000"],["63928.64000000","0.00000000"]],"a":[["79910.81000000","1.38215000"],["79910.82000000","0.00062000"],["79911.30000000","0.15337000"],["79911.34000000","0.00000000"],["79911.42000000","0.00000000"],["79912.03000000","0.00000000"],["79912.64000000","0.00000000"],["79912.86000000","0.00863000"],["79912.94000000","0.00000000"],["79913.25000000","0.06190000"],["79913.78000000","0.06197000"],["79913.79000000","0.04673000"],["79913.91000000","0.00959000"],["79914.14000000","0.01408000"]]}}}
{"rx_ns": 13899096916200, "frame": {"stream":"btcusdt@depth@100ms","data":{"e":"depthUpdate","E":1787650894314,"s":"BTCUSDT","U":99118617209,"u":99118617244,"b":[["79910.80000000","1.36372000"],["79910.79000000","0.00090000"],["79909.58000000","0.06176000"],["79908.97000000","0.06183000"],["79908.40000000","0.00007000"],["79908.39000000","0.06183000"],["79908.21000000","0.00007000"],["79908.01000000","0.00007000"],["79907.76000000","0.00021000"],["79907.15000000","0.00000000"],["79906.83000000","0.00000000"],["73513.51000000","0.00014000"],["71919.72000000","0.00400000"],["71919.71000000","0.00008000"],["63929.00000000","0.00060000"]],"a":[["79910.81000000","1.37885000"],["79911.29000000","0.12390000"],["79911.30000000","0.00014000"],["79913.25000000","0.00014000"],["79913.78000000","0.00021000"],["79915.93000000","0.00007000"],["79918.72000000","0.00000000"],["79922.72000000","0.02000000"]]}}}
{"rx_ns": 13899196215400, "frame": {"stream":"btcusdt@depth@100ms","data":{"e":"depthUpdate","E":1787650894414,"s":"BTCUSDT","U":99118617245,"u":99118617423,"b":[["79910.80000000","1.45094000"],["79910.79000000","0.00097000"],["79910.50000000","0.07916000"],["79910.02000000","0.00007000"],["79910.01000000","0.42544000"],["79910.00000000","0.04842000"],["79909.59000000","0.00000000"],["79909.58000000","0.00014000"],["79909.53000000","0.00000000"],["79909.52000000","0.01782000"],["79908.98000000","0.00007000"],["79908.97000000","0.06197000"],["79908.41000000","0.00007000"],["79908.40000000","1.04939000"],["79908.39000000","0.00014000"],["79908.38000000","0.00014000"],["79908.25000000","0.00000000"],["79908.21000000","0.00000000"],["79908.20000000","0.05367000"],["79908.06000000","0.00925000"],["79908.01000000","0.00000000"],["79908.00000000","0.02414000"],["79907.89000000","0.00000000"],["79907.82000000","0.00707000"],["79907.76000000","0.00014000"],["79907.75000000","0.00000000"],["79907.14000000","0.00000000"],["79906.96000000","0.02103000"],["79906.84000000","0.00000000"],["79906.01000000","0.00000000"],["79906.00000000","0.02414000"],["79905.99000000","1.11093000"],["79904.33000000","0.00007000"],["79904.32000000","1.87677000"],["79904.03000000","0.00250000"],["79902.46000000","0.00400000"],["79902.10000000","0.00000000"],["79900.77000000","0.00000000"],["79900.24000000","1.04939000"],["79895.58000000","0.00000000"],["79861.98000000","0.00000000"],["71919.72000000","0.00416000"]],"a":[["79910.81000000","1.37441000"],["79910.82000000","0.00055000"],["79911.29000000","0.08703000"],["79911.30000000","0.00000000"],["79911.63000000","0.00007000"],["79912.86000000","0.00849000"],["79913.24000000","0.00000000"],["79913.25000000","0.00000000"],["79913.77000000","0.00000000"],["79913.78000000","0.00007000"],["79914.13000000","0.00007000"],["79914.47000000","0.06197000"],["79915.08000000","0.06190000"],["79915.42000000","0.01678000"],["79915.91000000","0.00007000"],["79915.92000000","0.06183000"],["79915.93000000","0.00007000"],["79915.94000000","0.89014000"],["79915.95000000","0.00000000"],["79916.15000000","0.00007000"],["79916.77000000","0.00000000"],["79918.07000000","0.00625000"],["79920.00000000","1.48502000"],["79922.72000000","0.00000000"],["79924.52000000","0.02000000"],["79927.56000000","0.00000000"],["79941.00000000","0.70000000"]]}}}
{"rx_ns": 13899297730500, "frame": {"stream":"btcusdt@depth@100ms","data":{"e":"depthUpdate","E":1787650894514,"s":"BTCUSDT","U":99118617424,"u":99118617491,"b":[["79910.80000000","1.45094000"],["79910.79000000","0.00090000"],["79910.50000000","0.07916000"],["79910.01000000","0.42558000"],["79910.00000000","0.04835000"],["79909.58000000","0.00000000"],["79909.52000000","0.01775000"],["79909.41000000","0.00000000"],["79908.98000000","0.00000000"],["79908.97000000","0.00014000"],["79908.40000000","1.04953000"],["79908.39000000","0.00000000"],["79908.38000000","0.00000000"],["79908.20000000","0.05381000"],["79906.01000000","0.00400000"],["79904.95000000","0.00250000"],["79904.32000000","1.87684000"],["79904.03000000","0.00000000"],["79900.25000000","0.00000000"],["79895.58000000","0.00007000"],["78712.13000000","0.00030000"],["71919.72000000","0.00416000"],["71919.00000000","0.00020000"],["63928.64000000","0.00031000"]],"a":[["79910.81000000","1.37427000"],["79911.29000000","0.12328000"],["79912.86000000","0.00856000"],["79913.24000000","0.00007000"],["79913.25000000","0.06176000"],["79913.77000000","0.00007000"],["79913.78000000","0.06183000"],["79913.79000000","0.04680000"],["79913.83000000","0.00007000"],["79913.84000000","0.15893000"],["79914.13000000","0.00000000"],["79915.68000000","0.00033000"],["79915.91000000","0.00007000"],["79915.93000000","0.00000000"],["79916.15000000","0.00000000"],["79920.00000000","1.48252000"],["79920.92000000","0.00250000"],["79927.56000000","0.00007000"]]}}}
{"rx_ns": 13899395614700, "frame": {"stream":"btcusdt@depth@100ms","data":{"e":"depthUpdate","E":1787650894614,"s":"BTCUSDT","U":99118617492,"u":99118617577,"b":[["79910.80000000","1.24796000"],["79909.52000000","0.01768000"],["79908.97000000","0.00000000"],["79908.11000000","0.00000000"],["79908.06000000","0.00939000"],["79907.86000000","0.12522000"],["79905.99000000","0.56762000"],["79905.98000000","0.31301000"],["79905.51000000","0.00007000"],["79904.95000000","0.00000000"],["79904.33000000","0.00000000"],["79904.32000000","0.00007000"],["79904.00000000","0.02421000"],["79903.91000000","0.00250000"],["79901.34000000","0.00048000"],["79877.73000000","0.00400000"],["79873.72000000","0.00000000"],["79837.79000000","0.00400000"],["79833.78000000","0.02200000"],["79805.84000000","0.00400000"],["79801.83000000","0.00000000"],["79757.91000000","0.00400000"],["79753.90000000","0.00000000"],["79686.02000000","0.00400000"],["79682.02000000","0.00000000"],["71919.72000000","0.00416000"],["71919.00000000","0.00000000"],["63928.64000000","0.00000000"]],"a":[["79910.81000000","1.37455000"],["79910.82000000","0.00076000"],["79911.29000000","0.17411000"],["79912.63000000","0.00007000"],["79912.64000000","0.06176000"],["79912.86000000","0.00856000"],["79913.25000000","0.06190000"],["79913.78000000","0.06197000"],["79913.79000000","0.04680000"],["79913.84000000","0.15907000"],["79914.46000000","0.00007000"],["79914.47000000","0.06183000"],["79915.07000000","0.00007000"],["79915.08000000","0.06176000"],["79915.42000000","0.01664000"],["79915.68000000","0.00033000"],["79915.91000000","0.00000000"],["79916.81000000","0.12522000"],["79919.89000000","0.00250000"],["79920.92000000","0.00000000"],["79932.85000000","0.04523000"],["79947.13000000","0.00000000"]]}}}
{"rx_ns": 13899498476100, "frame": {"stream":"btcusdt@depth@100ms","data":{"e":"depthUpdate","E":1787650894714,"s":"BTCUSDT","U":99118617578,"u":99118617689,"b":[["79910.80000000","1.45087000"],["79908.00000000","0.02414000"],["79907.87000000","0.00000000"],["79907.86000000","0.00000000"],["79906.01000000","0.00000000"],["79905.99000000","0.56762000"],["79905.82000000","0.00659000"],["79905.51000000","0.00007000"],["79904.32000000","0.00007000"],["79904.00000000","0.02421000"],["79901.34000000","0.00000000"],["79900.25000000","0.00400000"],["79825.69000000","0.62553000"],["79823.05000000","0.00000000"],["71919.72000000","0.00432000"],["71919.71000000","0.00000000"]],"a":[["79910.81000000","1.12321000"],["79910.82000000","0.00055000"],["79911.29000000","0.05938000"],["79911.63000000","0.00014000"],["79912.63000000","0.00000000"],["79912.64000000","0.00014000"],["79912.86000000","0.00863000"],["79912.87000000","0.00007000"],["79912.88000000","0.03065000"],["79913.24000000","0.00000000"],["79913.25000000","0.00014000"],["79913.77000000","0.00000000"],["79913.78000000","0.00021000"],["79913.83000000","0.00000000"],["79913.84000000","0.00014000"],["79914.14000000","0.01394000"],["79914.31000000","0.00000000"],["79914.46000000","0.00000000"],["79914.47000000","0.00000000"],["79915.07000000","0.00000000"],["79915.08000000","0.06176000"],["79915.41000000","0.00007000"],["79915.68000000","0.00033000"],["79915.91000000","0.00007000"],["79915.93000000","0.00007000"],["79916.15000000","0.00007000"],["79916.81000000","0.00000000"],["79916.97000000","0.00007000"],["79917.43000000","0.00007000"],["82000.00000000","122.77195000"]]}}}
{"rx_ns": 13899597193800, "frame": {"stream":"btcusdt@depth@100ms","data":{"e":"depthUpdate","E":1787650894814,"s":"BTCUSDT","U":99118617690,"u":99118617770,"b":[["79910.80000000","1.45075000"],["79905.51000000","0.00007000"],["79904.32000000","0.00007000"],["79904.00000000","0.02421000"],["73513.51000000","0.00000000"],["71919.72000000","0.00416000"]],"a":[["79910.81000000","1.32464000"],["79911.29000000","0.05931000"],["79912.64000000","0.00000000"],["79912.86000000","0.00856000"],["79912.88000000","0.03079000"],["79913.23000000","0.00000000"],["79913.25000000","0.00000000"],["79913.78000000","0.06183000"],["79913.79000000","0.04673000"],["79913.84000000","0.00000000"],["79914.14000000","0.01408000"],["79914.47000000","0.06176000"],["79915.07000000","0.00007000"],["79915.08000000","0.06190000"],["79915.42000000","0.01678000"],["79915.91000000","0.00007000"],["79915.93000000","0.00007000"],["79916.15000000","0.00007000"],["79916.97000000","0.00000000"],["79917.43000000","0.00000000"]]}}}
{"rx_ns": 13899697166400, "frame": {"stream":"btcusdt@depth@100ms","data":{"e":"depthUpdate","E":1787650894914,"s":"BTCUSDT","U":99118617771,"u":99118617853,"b":[["79910.80000000","1.44970000"],["79905.51000000","0.00007000"],["79904.32000000","0.00007000"],["79904.00000000","0.02421000"],["79769.40000000","0.00000000"],["71919.72000000","0.00432000"]],"a":[["79910.81000000","1.32485000"],["79910.82000000","0.00069000"],["79911.29000000","0.10695000"],["79912.88000000","0.03086000"],["79913.24000000","0.00007000"],["79913.25000000","0.06176000"],["79913.77000000","0.00007000"],["79913.78000000","0.06197000"],["79914.14000000","0.01415000"],["79914.45000000","0.00688000"],["79914.46000000","0.00007000"],["79914.47000000","0.06190000"],["79915.08000000","0.06176000"],["79915.41000000","0.00000000"],["79915.42000000","0.01664000"],["79915.68000000","0.00033000"],["79915.91000000","0.00007000"],["79915.93000000","0.00000000"],["79916.15000000","0.00000000"],["81109.48000000","0.00030000"]]}}}
