{"rx_ns": 45953346300, "frame": {"stream":"btcusdt@depth20","data":{"lastUpdateId":99076517651,"bids":[["78723.99000000","5.51384000"],["78723.98000000","1.90542000"],["78723.97000000","0.00013000"],["78723.55000000","0.00635000"],["78723.54000000","0.00014000"],["78723.17000000","0.00400000"],["78723.03000000","0.00007000"],["78722.47000000","0.01762000"],["78722.01000000","0.00635000"],["78722.00000000","0.07528000"],["78721.99000000","0.36014000"],["78721.96000000","0.07521000"],["78721.95000000","1.21959000"],["78721.21000000","0.02950000"],["78721.20000000","0.37409000"],["78721.18000000","0.04956000"],["78720.00000000","0.29283000"],["78719.95000000","0.03524000"],["78719.67000000","0.00014000"],["78719.66000000","0.21809000"]],"asks":[["78724.00000000","0.09098000"],["78724.01000000","0.00325000"],["78724.73000000","0.00014000"],["78725.25000000","0.00014000"],["78725.26000000","0.03421000"],["78725.66000000","0.00007000"],["78725.89000000","0.00007000"],["78725.99000000","0.00014000"],["78726.00000000","0.02407000"],["78726.02000000","0.00007000"],["78726.49000000","0.00204000"],["78726.51000000","0.00014000"],["78726.52000000","0.04104000"],["78726.58000000","0.00014000"],["78726.59000000","0.20844000"],["78726.62000000","0.00007000"],["78726.63000000","0.00014000"],["78726.64000000","0.31773000"],["78726.69000000","0.05235000"],["78727.41000000","0.00014000"]]}}}
{"rx_ns": 45955059700, "frame": {"stream":"btcusdt@depth","data":{"e":"depthUpdate","E":1787602913014,"s":"BTCUSDT","U":99076515436,"u":99076517651,"b":[["78723.99000000","5.51384000"],["78723.98000000","1.90542000"],["78723.97000000","0.00013000"],["78723.55000000","0.00635000"],["78723.54000000","0.00014000"],["78723.53000000","0.00000000"],["78723.17000000","0.00400000"],["78723.03000000","0.00007000"],["78722.51000000","0.00000000"],["78722.47000000","0.01762000"],["78722.09000000","0.00000000"],["78722.01000000","0.00635000"],["78722.00000000","0.07528000"],["78721.99000000","0.36014000"],["78721.98000000","0.00000000"],["78721.97000000","0.00000000"],["78721.96000000","0.07521000"],["78721.95000000","1.21959000"],["78721.94000000","0.00000000"],["78721.78000000","0.00000000"],["78721.21000000","0.02950000"],["78721.20000000","0.37409000"],["78721.19000000","0.00000000"],["78721.18000000","0.04956000"],["78720.68000000","0.00000000"],["78720.52000000","0.00000000"],["78720.47000000","0.00000000"],["78720.09000000","0.00000000"],["78720.06000000","0.00000000"],["78720.00000000","0.29283000"],["78719.95000000","0.03524000"],["78719.86000000","0.00000000"],["78719.67000000","0.00014000"],["78719.66000000","0.21809000"],["78719.58000000","0.07500000"],["78719.57000000","0.30014000"],["78719.56000000","0.00400000"],["78719.55000000","0.00000000"],["78719.34000000","0.03224000"],["78719.28000000","0.00000000"],["78719.27000000","0.00000000"],["78719.26000000","0.30007000"],["78719.25000000","0.00000000"],["78719.24000000","0.00000000"],["78719.23000000","0.00400000"],["78719.18000000","0.00000000"],["78718.69000000","0.03524000"],["78718.64000000","0.00000000"],["78718.62000000","0.00027000"],["78718.37000000","0.00000000"],["78718.05000000","0.00000000"],["78718.04000000","0.00000000"],["78718.02000000","0.00800000"],["78718.01000000","1.58176000"],["78718.00000000","0.06425000"],["78717.99000000","0.01627000"],["78717.98000000","0.00000000"],["78717.89000000","0.00000000"],["78717.88000000","0.00000000"],["78717.75000000","0.00000000"],["78717.58000000","0.00000000"],["78717.26000000","0.00400000"],["78717.10000000","0.00008000"],["78716.88000000","0.00000000"],["78716.85000000","0.00000000"],["78716.79000000","0.00000000"],["78716.74000000","0.00000000"],["78716.68000000","0.03000000"],["78716.50000000","0.00000000"],["78716.45000000","0.00000000"],["78716.39000000","0.00007000"],["78716.20000000","0.00000000"],["78716.07000000","0.00000000"],["78716.01000000","0.00011000"],["78716.00000000","0.02508000"],["78715.95000000","0.00000000"],["78715.90000000","0.00000000"],["78715.83000000","0.02000000"],["78715.82000000","0.00000000"],["78715.81000000","0.00000000"],["78715.80000000","0.00014000"],["78715.68000000","0.12000000"],["78715.65000000","0.00000000"],["78715.53000000","0.00000000"],["78715.47000000","0.00000000"],["78715.29000000","0.00400000"],["78715.20000000","0.00000000"],["78715.19000000","0.00000000"],["78715.18000000","0.00000000"],["78715.02000000","0.03224000"],["78715.00000000","0.00007000"],["78714.95000000","0.00000000"],["78714.78000000","0.08576000"],["78714.55000000","0.00000000"],["78714.51000000","0.00000000"],["78714.27000000","0.00000000"],["78714.17000000","0.00007000"],["78714.06000000","0.00322000"],["78714.00000000","0.02400000"],["78713.76000000","0.00000000"],["78713.32000000","0.00400000"],["78713.29000000","0.00000000"],["78712.75000000","0.00000000"],["78712.70000000","0.02000000"],["78712.50000000","0.00000000"],["78712.31000000","0.00000000"],["78712.20000000","0.04000000"],["78712.03000000","0.00000000"],["78711.93000000","0.00014000"],["78711.92000000","0.02000000"],["78711.83000000","0.02000000"],["78711.82000000","1.90515000"],["78711.34000000","0.00000000"],["78711.31000000","0.00331000"],["78711.14000000","0.00000000"],["78710.82000000","0.00000000"],["78710.16000000","0.00000000"],["78710.12000000","0.22264000"],["78710.00000000","0.11929000"],["78709.41000000","0.00000000"],["78709.40000000","0.00008000"],["78709.30000000","0.00000000"],["78709.29000000","0.12704000"],["78709.27000000","0.00406000"],["78709.08000000","0.34307000"],["78708.89000000","0.00000000"],["78708.87000000","0.00327000"],["78708.75000000","0.00000000"],["78708.74000000","0.00000000"],["78708.68000000","0.00000000"],["78708.46000000","0.00000000"],["78708.45000000","0.00000000"],["78707.92000000","0.00000000"],["78707.67000000","0.00000000"],["78707.42000000","0.00000000"],["78707.40000000","0.02000000"],["78707.18000000","0.00000000"],["78707.17000000","0.06332000"],["78706.90000000","0.00000000"],["78706.79000000","0.00000000"],["78706.49000000","0.00000000"],["78706.01000000","0.63446000"],["78705.99000000","0.00000000"],["78705.88000000","0.00000000"],["78705.87000000","0.03224000"],["78705.84000000","0.00000000"],["78705.20000000","0.07279000"],["78705.00000000","0.00000000"],["78704.93000000","0.00000000"],["78704.71000000","0.00000000"],["78704.62000000","0.00000000"],["78704.46000000","0.63536000"],["78704.20000000","0.00000000"],["78704.19000000","0.00014000"],["78703.91000000","0.00000000"],["78703.46000000","0.00000000"],["78703.01000000","0.00007000"],["78703.00000000","0.00000000"],["78702.99000000","0.00000000"],["78702.90000000","0.00000000"],["78702.71000000","0.00000000"],["78702.65000000","0.00000000"],["78702.55000000","0.34310000"],["78702.42000000","0.00000000"],["78702.01000000","0.00012000"],["78701.09000000","0.00000000"],["78700.45000000","0.00000000"],["78700.00000000","0.11963000"],["78699.97000000","0.00000000"],["78699.87000000","0.00000000"],["78699.61000000","0.13347000"],["78696.05000000","0.00000000"],["78696.04000000","0.00000000"],["78695.89000000","0.34313000"],["78695.75000000","0.00000000"],["78694.88000000","0.63543000"],["78694.34000000","0.00007000"],["78694.17000000","0.00000000"],["78694.07000000","0.00000000"],["78693.71000000","0.00000000"],["78691.65000000","0.00000000"],["78691.12000000","0.00000000"],["78689.68000000","0.00000000"],["78689.53000000","0.00000000"],["78689.10000000","0.00000000"],["78688.01000000","0.00000000"],["78687.71000000","0.00000000"],["78687.34000000","0.00000000"],["78687.08000000","0.00000000"],["78686.57000000","0.00000000"],["78686.55000000","0.00000000"],["78685.74000000","0.00000000"],["78685.15000000","0.04559000"],["78684.60000000","0.00000000"],["78684.34000000","1.25833000"],["78684.00000000","0.39624000"],["78683.52000000","0.00000000"],["78683.44000000","0.02506000"],["78683.04000000","0.00000000"],["78682.96000000","0.00000000"],["78682.83000000","0.09534000"],["78681.80000000","0.00200000"],["78680.97000000","0.00000000"],["78680.00000000","0.02439000"],["78679.00000000","0.00000000"],["78678.00000000","0.02400000"],["78677.10000000","0.00000000"],["78676.02000000","0.00000000"],["78675.49000000","0.00000000"],["78674.50000000","0.00000000"],["78673.23000000","0.00000000"],["78669.91000000","0.00406000"],["78669.42000000","0.00621000"],["78669.03000000","0.00431000"],["78668.08000000","0.00433000"],["78667.65000000","0.00426000"],["78666.47000000","0.00000000"],["78663.29000000","0.00000000"],["78662.13000000","0.86784000"],["78660.86000000","0.00000000"],["78660.08000000","0.00000000"],["78658.25000000","0.00000000"],["78658.07000000","0.00000000"],["78657.06000000","0.00000000"],["78656.90000000","0.00000000"],["78654.76000000","0.00000000"],["78654.11000000","0.00000000"],["78653.78000000","0.01691000"],["78653.58000000","0.00000000"],["78650.66000000","0.00000000"],["78650.10000000","0.00317000"],["78649.95000000","0.00000000"],["78644.98000000","0.00000000"],["78644.08000000","0.00000000"],["78639.86000000","0.00000000"],["78638.43000000","0.00406000"],["78636.75000000","0.00000000"],["78636.39000000","0.00317000"],["78634.60000000","0.00000000"],["78633.98000000","0.00000000"],["78631.81000000","0.00000000"],["78629.62000000","0.00000000"],["78627.36000000","0.00000000"],["78627.35000000","0.00243000"],["78626.01000000","0.00000000"],["78591.20000000","0.00406000"],["78584.59000000","0.00000000"],["78573.50000000","1.52237000"],["78559.65000000","0.00000000"],["78557.67000000","0.00127000"],["78556.04000000","0.00000000"],["78551.83000000","0.00663000"],["78547.40000000","0.00000000"],["78534.01000000","0.00778000"],["78513.76000000","0.00000000"],["78510.34000000","0.00000000"],["78503.67000000","0.00000000"],["78399.42000000","0.00028000"],["78391.45000000","0.00000000"],["78382.99000000","0.00000000"],["78324.41000000","0.00000000"],["78317.01000000","0.00000000"],["78232.00000000","0.00008000"],["77962.48000000","0.00000000"],["77944.21000000","0.00000000"],["77944.14000000","0.00000000"],["77932.78000000","0.00000000"],["77893.45000000","0.00300000"],["77543.12000000","0.00000000"],["77270.34000000","0.00577000"],["77155.40000000","0.00000000"],["76769.63000000","0.00000000"],["76385.78000000","0.00000000"],["76003.85000000","0.00000000"],["75623.83000000","0.00000000"],["75245.71000000","0.00000000"],["74869.48000000","0.00000000"],["74495.13000000","0.00000000"],["74122.66000000","0.00000000"],["73752.05000000","0.00000000"],["73383.29000000","0.00000000"],["73016.37000000","0.00000000"],["70851.60000000","0.00096000"],["70851.00000000","0.00000000"],["70847.62000000","0.00000000"],["70846.20000000","0.00000000"],["70846.19000000","0.00000000"],["66915.40000000","0.00034000"],["66872.90000000","0.00352000"],["62979.20000000","0.00031000"],["62979.19000000","0.00020000"],["62975.66000000","0.00000000"],["62974.40000000","0.00000000"],["62974.00000000","0.00000000"]],"a":[["78718.01000000","0.00000000"],["78718.02000000","0.00000000"],["78718.03000000","0.00000000"],["78718.04000000","0.00000000"],["78718.05000000","0.00000000"],["78718.28000000","0.00000000"],["78718.78000000","0.00000000"],["78718.80000000","0.00000000"],["78718.82000000","0.00000000"],["78718.84000000","0.00000000"],["78719.09000000","0.00000000"],["78719.25000000","0.00000000"],["78719.26000000","0.00000000"],["78719.27000000","0.00000000"],["78719.53000000","0.00000000"],["78719.54000000","0.00000000"],["78719.55000000","0.00000000"],["78719.57000000","0.00000000"],["78719.58000000","0.00000000"],["78719.59000000","0.00000000"],["78719.67000000","0.00000000"],["78719.87000000","0.00000000"],["78719.99000000","0.00000000"],["78720.00000000","0.00000000"],["78720.01000000","0.00000000"],["78720.06000000","0.00000000"],["78720.07000000","0.00000000"],["78720.16000000","0.00000000"],["78720.19000000","0.00000000"],["78720.20000000","0.00000000"],["78720.52000000","0.00000000"],["78720.53000000","0.00000000"],["78720.68000000","0.00000000"],["78720.69000000","0.00000000"],["78720.84000000","0.00000000"],["78721.04000000","0.00000000"],["78721.20000000","0.00000000"],["78721.21000000","0.00000000"],["78721.35000000","0.00000000"],["78721.77000000","0.00000000"],["78721.78000000","0.00000000"],["78721.79000000","0.00000000"],["78721.95000000","0.00000000"],["78721.96000000","0.00000000"],["78721.97000000","0.00000000"],["78721.99000000","0.00000000"],["78722.00000000","0.00000000"],["78722.01000000","0.00000000"],["78722.36000000","0.00000000"],["78722.52000000","0.00000000"],["78722.62000000","0.00000000"],["78723.52000000","0.00000000"],["78723.53000000","0.00000000"],["78723.54000000","0.00000000"],["78723.99000000","0.00000000"],["78724.00000000","0.09098000"],["78724.01000000","0.00325000"],["78724.37000000","0.00000000"],["78724.38000000","0.00000000"],["78724.55000000","0.00000000"],["78724.57000000","0.00000000"],["78724.69000000","0.00000000"],["78724.73000000","0.00014000"],["78724.80000000","0.00000000"],["78724.92000000","0.00000000"],["78725.25000000","0.00014000"],["78725.26000000","0.03421000"],["78725.37000000","0.00000000"],["78725.44000000","0.00000000"],["78725.45000000","0.00000000"],["78725.46000000","0.00000000"],["78725.65000000","0.00000000"],["78725.66000000","0.00007000"],["78725.73000000","0.00000000"],["78725.75000000","0.00000000"],["78725.83000000","0.00000000"],["78725.84000000","0.00000000"],["78725.87000000","0.00000000"],["78725.89000000","0.00007000"],["78725.99000000","0.00014000"],["78726.00000000","0.02407000"],["78726.02000000","0.00007000"],["78726.05000000","0.00000000"],["78726.15000000","0.00000000"],["78726.37000000","0.00000000"],["78726.38000000","0.00000000"],["78726.41000000","0.00000000"],["78726.49000000","0.00204000"],["78726.51000000","0.00014000"],["78726.52000000","0.04104000"],["78726.58000000","0.00014000"],["78726.59000000","0.20844000"],["78726.63000000","0.00014000"],["78726.64000000","0.31773000"],["78726.68000000","0.00000000"],["78726.69000000","0.05235000"],["78726.70000000","0.00000000"],["78726.98000000","0.00000000"],["78727.39000000","0.00000000"],["78727.40000000","0.00000000"],["78727.41000000","0.00014000"],["78727.47000000","0.00000000"],["78727.48000000","0.00000000"],["78727.50000000","0.00000000"],["78727.74000000","0.00007000"],["78727.78000000","0.04104000"],["78727.83000000","0.00000000"],["78727.85000000","0.00000000"],["78727.99000000","0.00000000"],["78728.00000000","0.02407000"],["78728.11000000","0.00000000"],["78728.12000000","0.00000000"],["78728.14000000","0.00027000"],["78728.48000000","0.00000000"],["78728.62000000","0.00000000"],["78728.63000000","0.00000000"],["78728.69000000","0.00000000"],["78728.70000000","0.00000000"],["78728.82000000","0.00069000"],["78728.90000000","0.00000000"],["78728.91000000","0.00000000"],["78728.97000000","0.00000000"],["78729.08000000","0.00007000"],["78729.31000000","0.00000000"],["78729.34000000","0.00000000"],["78729.50000000","0.00000000"],["78729.54000000","0.00000000"],["78729.60000000","0.00000000"],["78729.75000000","0.00000000"],["78729.76000000","0.00000000"],["78729.81000000","0.00000000"],["78729.82000000","0.00000000"],["78729.86000000","0.00000000"],["78729.90000000","0.00000000"],["78729.91000000","0.00000000"],["78729.99000000","0.00000000"],["78730.00000000","0.02407000"],["78730.11000000","0.00000000"],["78730.13000000","0.00000000"],["78730.25000000","0.00000000"],["78730.27000000","0.00000000"],["78730.40000000","0.00000000"],["78730.44000000","0.00000000"],["78730.50000000","0.00000000"],["78730.61000000","0.00007000"],["78730.68000000","0.00000000"],["78730.69000000","0.17911000"],["78730.83000000","0.00000000"],["78730.94000000","0.00000000"],["78731.04000000","0.00000000"],["78731.05000000","0.00000000"],["78731.18000000","0.00000000"],["78731.20000000","0.01000000"],["78731.28000000","0.00014000"],["78731.37000000","0.00000000"],["78731.39000000","0.00000000"],["78731.40000000","0.00000000"],["78731.53000000","0.00047000"],["78731.81000000","0.00000000"],["78731.85000000","0.00000000"],["78731.94000000","0.00000000"],["78731.95000000","0.00000000"],["78731.99000000","0.00000000"],["78732.00000000","0.02400000"],["78732.08000000","0.00000000"],["78732.10000000","0.00000000"],["78732.11000000","0.00000000"],["78732.18000000","0.00000000"],["78732.19000000","0.00000000"],["78732.30000000","0.02000000"],["78732.41000000","0.00000000"],["78732.52000000","0.00000000"],["78732.62000000","0.00000000"],["78732.63000000","0.00000000"],["78732.65000000","0.00000000"],["78732.85000000","0.00000000"],["78732.86000000","0.00000000"],["78732.90000000","0.00000000"],["78732.91000000","0.00000000"],["78732.93000000","0.00000000"],["78732.94000000","0.00000000"],["78733.00000000","0.00000000"],["78733.01000000","0.00000000"],["78733.02000000","0.00000000"],["78733.30000000","0.12007000"],["78733.42000000","0.00000000"],["78733.74000000","0.00000000"],["78733.75000000","0.00000000"],["78733.76000000","0.00000000"],["78733.94000000","0.00000000"],["78733.98000000","0.00000000"],["78734.06000000","0.02000000"],["78734.08000000","0.00000000"],["78734.37000000","0.00000000"],["78734.80000000","0.00000000"],["78734.90000000","0.00000000"],["78734.98000000","0.00000000"],["78734.99000000","0.00000000"],["78735.13000000","0.02161000"],["78735.14000000","0.00000000"],["78735.15000000","0.00014000"],["78735.26000000","0.00000000"],["78735.30000000","0.00000000"],["78735.33000000","0.00000000"],["78735.70000000","0.00254000"],["78735.71000000","0.00000000"],["78735.73000000","0.00000000"],["78735.97000000","0.00000000"],["78736.21000000","0.10327000"],["78736.22000000","0.00000000"],["78736.24000000","0.00000000"],["78736.31000000","0.00000000"],["78736.36000000","0.00000000"],["78736.83000000","0.00254000"],["78736.95000000","0.00000000"],["78736.96000000","0.00000000"],["78737.03000000","0.00000000"],["78737.07000000","0.00000000"],["78737.10000000","0.31759000"],["78737.11000000","0.00318000"],["78737.19000000","0.00000000"],["78737.30000000","0.00000000"],["78737.37000000","0.00000000"],["78737.57000000","0.00007000"],["78737.99000000","0.01270000"],["78738.06000000","0.00000000"],["78738.30000000","0.00000000"],["78738.31000000","0.00000000"],["78738.32000000","0.00000000"],["78738.48000000","0.00007000"],["78738.49000000","0.00000000"],["78738.88000000","0.00000000"],["78738.93000000","0.00000000"],["78738.95000000","0.15237000"],["78739.22000000","0.00000000"],["78739.26000000","0.00000000"],["78739.27000000","0.02161000"],["78739.70000000","0.00048000"],["78739.98000000","0.00000000"],["78739.99000000","0.00400000"],["78740.00000000","0.02400000"],["78740.25000000","0.00000000"],["78740.44000000","0.00000000"],["78740.55000000","0.00187000"],["78740.94000000","0.04110000"],["78741.05000000","0.00321000"],["78741.13000000","0.00000000"],["78741.58000000","0.00007000"],["78741.96000000","0.00000000"],["78741.99000000","0.00000000"],["78742.08000000","0.00000000"],["78742.09000000","0.00150000"],["78742.27000000","0.00000000"],["78742.48000000","0.02285000"],["78742.55000000","0.00635000"],["78742.56000000","0.02000000"],["78742.57000000","0.00253000"],["78742.60000000","0.02000000"],["78742.66000000","0.00000000"],["78742.84000000","0.00000000"],["78743.00000000","0.00007000"],["78743.01000000","0.00000000"],["78743.09000000","0.00000000"],["78743.24000000","0.00000000"],["78743.34000000","0.02161000"],["78743.35000000","0.02000000"],["78743.38000000","0.00000000"],["78743.39000000","0.02000000"],["78743.43000000","0.02000000"],["78744.33000000","0.00000000"],["78744.42000000","0.00000000"],["78744.71000000","0.00000000"],["78744.99000000","0.00328000"],["78745.83000000","0.38769000"],["78745.89000000","0.00000000"],["78746.09000000","0.00000000"],["78746.44000000","0.00455000"],["78746.71000000","0.00000000"],["78746.79000000","0.00000000"],["78746.88000000","0.34291000"],["78747.01000000","0.00000000"],["78747.22000000","0.00007000"],["78747.43000000","0.00000000"],["78747.66000000","0.00406000"],["78747.85000000","0.00000000"],["78748.01000000","0.00007000"],["78748.19000000","0.00000000"],["78748.70000000","0.00000000"],["78748.93000000","0.00321000"],["78749.08000000","0.00000000"],["78749.34000000","0.00000000"],["78749.78000000","0.00000000"],["78749.99000000","0.00000000"],["78750.00000000","0.02407000"],["78750.08000000","0.00000000"],["78750.20000000","0.00000000"],["78750.21000000","0.00000000"],["78750.33000000","0.00000000"],["78750.56000000","0.00000000"],["78750.75000000","0.00400000"],["78750.78000000","0.00000000"],["78750.94000000","0.38099000"],["78751.12000000","0.00000000"],["78751.13000000","0.02000000"],["78751.67000000","0.00000000"],["78751.84000000","0.00000000"],["78751.92000000","0.00000000"],["78751.93000000","0.00000000"],["78752.39000000","0.00000000"],["78752.45000000","0.00000000"],["78752.55000000","0.00000000"],["78752.57000000","0.34288000"],["78752.67000000","0.00000000"],["78752.72000000","0.00400000"],["78752.80000000","0.00000000"],["78752.87000000","0.00331000"],["78753.01000000","0.00000000"],["78753.14000000","0.00000000"],["78753.58000000","0.00000000"],["78753.73000000","0.00000000"],["78754.07000000","0.00000000"],["78754.21000000","0.00000000"],["78754.38000000","0.00000000"],["78754.39000000","0.00000000"],["78754.41000000","0.00000000"],["78754.49000000","0.00000000"],["78754.58000000","0.00000000"],["78754.69000000","0.00400000"],["78754.75000000","0.00000000"],["78755.38000000","0.00000000"],["78755.55000000","0.00000000"],["78756.07000000","0.00060000"],["78756.09000000","0.00000000"],["78756.23000000","0.00000000"],["78756.30000000","0.00000000"],["78756.36000000","0.00000000"],["78756.66000000","0.00400000"],["78756.84000000","0.02516000"],["78757.11000000","0.00000000"],["78757.31000000","0.00000000"],["78757.42000000","0.00000000"],["78757.55000000","0.00000000"],["78758.00000000","0.02400000"],["78758.12000000","0.00000000"],["78758.19000000","0.00000000"],["78758.27000000","0.00190000"],["78758.32000000","0.02723000"],["78758.37000000","0.36238000"],["78758.42000000","0.04459000"],["78758.63000000","0.00400000"],["78758.92000000","0.00000000"],["78759.00000000","0.00000000"],["78759.15000000","0.00000000"],["78759.20000000","0.00000000"],["78759.31000000","0.00000000"],["78759.42000000","0.00000000"],["78760.00000000","0.11923000"],["78760.01000000","0.00000000"],["78760.21000000","0.02438000"],["78760.60000000","0.00400000"],["78761.61000000","0.43572000"],["78762.24000000","0.00014000"],["78762.57000000","0.00400000"],["78762.75000000","0.00000000"],["78763.26000000","0.00000000"],["78764.00000000","0.03414000"],["78764.09000000","0.00000000"],["78764.54000000","0.00400000"],["78765.43000000","0.00426000"],["78765.82000000","0.00000000"],["78766.11000000","0.00007000"],["78766.39000000","0.00630000"],["78766.51000000","0.00400000"],["78766.99000000","1.21969000"],["78767.99000000","0.00000000"],["78769.40000000","0.00315000"],["78769.41000000","0.02161000"],["78769.66000000","0.00000000"],["78770.00000000","0.10901000"],["78770.45000000","0.00400000"],["78771.42000000","0.00000000"],["78772.42000000","0.00400000"],["78773.38000000","0.00433000"],["78773.99000000","0.00000000"],["78774.39000000","0.00000000"],["78774.41000000","0.00317000"],["78774.78000000","0.00000000"],["78775.07000000","0.00425000"],["78776.44000000","0.00000000"],["78778.25000000","0.00000000"],["78779.90000000","0.00317000"],["78780.29000000","0.00000000"],["78782.18000000","0.86652000"],["78783.23000000","1.25675000"],["78783.56000000","0.49727000"],["78784.63000000","0.00007000"],["78787.04000000","0.00406000"],["78791.63000000","1.90515000"],["78793.23000000","0.00000000"],["78794.12000000","0.02000000"],["78794.47000000","1.21952000"],["78795.59000000","0.02000000"],["78795.75000000","0.02000000"],["78796.37000000","0.03000000"],["78796.44000000","0.02000000"],["78796.75000000","0.01691000"],["78797.35000000","0.02000000"],["78797.39000000","0.02000000"],["78800.09000000","0.00000000"],["78801.10000000","1.90515000"],["78801.11000000","0.00000000"],["78803.72000000","0.00000000"],["78804.63000000","1.21952000"],["78805.58000000","0.02000000"],["78805.66000000","0.02000000"],["78805.68000000","0.02000000"],["78807.94000000","0.00000000"],["78809.75000000","0.00000000"],["78811.08000000","1.90515000"],["78811.33000000","3.80699000"],["78811.60000000","0.09344000"],["78818.01000000","0.00000000"],["78821.91000000","0.02000000"],["78823.99000000","0.00000000"],["78824.59000000","0.00000000"],["78827.83000000","0.21930000"],["78828.58000000","0.00012000"],["78830.73000000","0.00000000"],["78834.72000000","0.00019000"],["78836.82000000","0.00000000"],["78840.82000000","0.00031000"],["78845.90000000","0.00000000"],["78847.74000000","0.00127000"],["78851.99000000","0.00000000"],["78853.99000000","0.00127000"],["78855.18000000","0.00000000"],["78856.99000000","0.00000000"],["78858.73000000","0.00000000"],["78865.79000000","0.00406000"],["78872.64000000","1.52244000"],["78903.51000000","0.00000000"],["78925.24000000","0.00000000"],["78926.22000000","0.00000000"],["78927.86000000","0.00000000"],["78935.31000000","0.00007000"],["78935.61000000","0.00000000"],["78938.18000000","0.00007000"],["78939.24000000","0.00000000"],["78942.11000000","0.00000000"],["78942.20000000","0.01990000"],["78968.91000000","0.00000000"],["78980.75000000","0.00034000"],["79017.06000000","0.00000000"],["79031.67000000","7.59276000"],["79111.61000000","0.00008000"],["79507.16000000","0.00000000"],["79900.00000000","4.40282000"],["79904.70000000","0.00000000"],["80304.22000000","0.00000000"],["80705.74000000","0.00000000"],["81109.27000000","0.00000000"],["81514.82000000","0.00000000"],["81922.39000000","0.00000000"],["82332.00000000","0.00020000"],["82743.66000000","0.00000000"],["83157.38000000","0.00000000"],["83573.17000000","0.00000000"],["83991.04000000","0.00000000"],["84410.99000000","0.00000000"],["84833.05000000","0.00000000"]]}}}
{"rx_ns": 46952387400, "frame": {"stream":"btcusdt@depth20","data":{"lastUpdateId":99076517977,"bids":[["78723.99000000","5.52809000"],["78723.98000000","1.90542000"],["78723.97000000","0.00013000"],["78723.92000000","0.03231000"],["78723.54000000","0.00014000"],["78723.17000000","0.00400000"],["78723.03000000","0.00007000"],["78722.47000000","0.01769000"],["78722.24000000","0.00007000"],["78722.00000000","0.08028000"],["78721.99000000","0.36677000"],["78721.96000000","0.07521000"],["78721.95000000","1.21959000"],["78721.72000000","0.00400000"],["78721.21000000","0.02950000"],["78721.20000000","0.37402000"],["78721.18000000","0.04956000"],["78720.49000000","0.00007000"],["78720.01000000","0.00635000"],["78720.00000000","0.29783000"]],"asks":[["78724.00000000","0.16875000"],["78724.01000000","0.00338000"],["78724.02000000","0.00013000"],["78724.73000000","0.00014000"],["78725.25000000","0.00014000"],["78725.26000000","0.03421000"],["78725.66000000","0.00007000"],["78725.89000000","0.00007000"],["78725.99000000","0.00014000"],["78726.00000000","0.02407000"],["78726.02000000","0.00007000"],["78726.51000000","0.00014000"],["78726.52000000","0.04104000"],["78726.62000000","0.00007000"],["78726.63000000","0.00014000"],["78726.64000000","0.31773000"],["78726.68000000","0.00007000"],["78726.69000000","0.05235000"],["78727.41000000","0.00014000"],["78727.74000000","0.00007000"]]}}}
{"rx_ns": 46952581300, "frame": {"stream":"btcusdt@depth","data":{"e":"depthUpdate","E":1787602914014,"s":"BTCUSDT","U":99076517652,"u":99076517977,"b":[["78723.99000000","5.52809000"],["78723.98000000","1.90542000"],["78723.92000000","0.03231000"],["78723.55000000","0.00000000"],["78722.48000000","0.00000000"],["78722.47000000","0.01769000"],["78722.24000000","0.00007000"],["78722.01000000","0.00000000"],["78722.00000000","0.08028000"],["78721.99000000","0.36677000"],["78721.95000000","1.21959000"],["78721.72000000","0.00400000"],["78721.22000000","0.00000000"],["78721.20000000","0.37402000"],["78720.49000000","0.00007000"],["78720.01000000","0.00635000"],["78720.00000000","0.29783000"],["78719.57000000","0.30007000"],["78719.56000000","0.00000000"],["78718.71000000","0.00000000"],["78718.70000000","0.00254000"],["78718.44000000","0.00007000"],["78718.02000000","0.00800000"],["78718.00000000","0.06418000"],["78716.61000000","0.02200000"],["78716.56000000","0.02400000"],["78716.04000000","0.12703000"],["78715.83000000","0.04000000"],["78715.81000000","0.00400000"],["78715.77000000","0.02600000"],["78715.75000000","0.02600000"],["78715.02000000","0.00000000"],["78713.46000000","0.02200000"],["78712.68000000","0.02200000"],["78712.21000000","0.02000000"],["78712.20000000","0.00000000"],["78711.91000000","0.02000000"],["78707.95000000","0.34307000"],["78706.40000000","0.00000000"],["78706.22000000","0.00000000"],["78705.78000000","0.00000000"],["78705.74000000","0.00000000"],["78705.68000000","0.50837000"],["78704.95000000","0.00000000"],["78704.92000000","0.00000000"],["78702.66000000","0.00000000"],["78701.87000000","0.00000000"],["78701.08000000","0.00000000"],["78700.33000000","0.00007000"],["78694.34000000","0.00000000"],["78684.32000000","0.02541000"],["78660.87000000","0.02000000"],["78660.08000000","0.02000000"],["78658.28000000","0.00000000"],["78655.12000000","0.00000000"],["78654.68000000","0.00000000"],["78654.30000000","0.00000000"],["78649.95000000","0.00000000"],["78640.01000000","0.00315000"],["78636.39000000","0.00000000"],["78632.56000000","0.00243000"],["78627.35000000","0.00000000"],["78574.09000000","0.01989000"],["78554.57000000","0.00000000"],["78553.80000000","0.00097000"],["78547.76000000","0.00000000"],["78545.16000000","0.00778000"],["78534.01000000","0.00000000"],["78521.69000000","0.00000000"],["78521.53000000","0.00406000"],["78520.36000000","0.00000000"],["78330.37000000","0.00000000"],["78009.54000000","0.00000000"],["77938.71000000","0.00000000"],["77549.02000000","0.00000000"],["77161.27000000","0.00000000"],["76775.47000000","0.00000000"],["76391.59000000","0.00000000"],["76009.63000000","0.00000000"],["75629.58000000","0.00000000"],["75251.44000000","0.00000000"],["74875.18000000","0.00000000"],["74500.80000000","0.00202000"],["74128.30000000","0.00000000"],["73757.66000000","0.00000000"],["73388.87000000","0.00000000"],["73021.93000000","0.00000000"],["70851.60000000","0.00208000"],["70851.59000000","0.00009000"],["70851.00000000","0.00000000"],["62979.20000000","0.00031000"],["62979.19000000","0.00000000"],["62979.00000000","0.00000000"],["62974.00000000","0.00000000"]],"a":[["78724.00000000","0.16875000"],["78724.01000000","0.00338000"],["78724.02000000","0.00013000"],["78726.49000000","0.00000000"],["78726.52000000","0.04104000"],["78726.58000000","0.00000000"],["78726.59000000","0.00000000"],["78726.68000000","0.00007000"],["78726.69000000","0.05235000"],["78728.00000000","0.02407000"],["78728.18000000","0.00000000"],["78728.92000000","0.00607000"],["78728.93000000","0.00000000"],["78729.00000000","0.00007000"],["78730.00000000","0.02400000"],["78730.61000000","0.00000000"],["78730.69000000","0.00000000"],["78730.75000000","0.00000000"],["78732.01000000","0.00000000"],["78732.80000000","0.00000000"],["78733.29000000","0.00000000"],["78733.30000000","0.04007000"],["78733.69000000","0.00323000"],["78734.40000000","0.08000000"],["78734.41000000","0.00254000"],["78734.43000000","0.00254000"],["78734.80000000","0.00254000"],["78735.29000000","0.00000000"],["78735.68000000","0.00000000"],["78735.69000000","0.00000000"],["78735.70000000","0.00000000"],["78735.95000000","0.25412000"],["78736.74000000","0.38119000"],["78736.83000000","0.00000000"],["78737.10000000","0.31759000"],["78737.56000000","0.00635000"],["78737.99000000","0.00635000"],["78738.95000000","0.00048000"],["78741.58000000","0.00000000"],["78742.74000000","0.00000000"],["78747.53000000","0.12698000"],["78747.57000000","0.00007000"],["78747.98000000","0.09565000"],["78750.75000000","0.01670000"],["78752.87000000","0.00000000"],["78755.81000000","0.02516000"],["78756.84000000","0.00000000"],["78757.92000000","0.34286000"],["78766.11000000","0.00000000"],["78769.40000000","0.00000000"],["78773.37000000","0.00316000"],["78774.41000000","0.00000000"],["78779.34000000","0.00316000"],["78785.82000000","1.25671000"],["78789.35000000","0.02000000"],["78794.62000000","0.02000000"],["78805.58000000","0.00000000"],["78811.17000000","0.02600000"],["78818.54000000","0.00406000"],["78821.91000000","0.00000000"],["78821.99000000","0.93647000"],["78823.04000000","0.00529000"],["78843.95000000","0.00000000"],["78847.74000000","0.00000000"],["78851.99000000","0.00127000"],["78853.99000000","0.00000000"],["78857.99000000","0.00127000"],["78883.37000000","0.00000000"],["78936.66000000","0.00406000"],["79117.62000000","0.00000000"],["79513.21000000","0.00000000"],["79910.78000000","0.00000000"],["80310.33000000","0.00000000"],["80711.88000000","0.00000000"],["81115.44000000","0.00117000"],["81521.02000000","0.00000000"],["81928.63000000","0.00000000"],["82338.27000000","0.00000000"],["82749.96000000","0.00000000"],["83163.71000000","0.00000000"],["83579.53000000","0.00000000"],["83997.43000000","0.00000000"],["84417.41000000","0.00000000"],["84839.50000000","0.00000000"]]}}}
{"rx_ns": 47957525500, "frame": {"stream":"btcusdt@depth20","data":{"lastUpdateId":99076518192,"bids":[["78723.99000000","5.48910000"],["78723.98000000","1.90542000"],["78723.97000000","0.00013000"],["78723.92000000","0.03231000"],["78723.54000000","0.00014000"],["78723.17000000","0.00400000"],["78723.03000000","0.00007000"],["78722.47000000","0.01769000"],["78722.24000000","0.00007000"],["78722.00000000","0.08028000"],["78721.99000000","0.36677000"],["78721.96000000","0.07521000"],["78721.95000000","1.21966000"],["78721.72000000","0.00400000"],["78721.21000000","0.02950000"],["78721.20000000","0.37402000"],["78721.18000000","0.04956000"],["78720.49000000","0.00007000"],["78720.01000000","0.00635000"],["78720.00000000","0.30283000"]],"asks":[["78724.00000000","0.08943000"],["78724.01000000","0.00338000"],["78724.02000000","0.00013000"],["78724.59000000","0.00007000"],["78724.73000000","0.00014000"],["78725.25000000","0.00014000"],["78725.26000000","0.03421000"],["78725.38000000","0.00007000"],["78725.66000000","0.00007000"],["78725.89000000","0.00007000"],["78725.99000000","0.00014000"],["78726.00000000","0.02407000"],["78726.02000000","0.00007000"],["78726.51000000","0.00014000"],["78726.52000000","0.04104000"],["78726.62000000","0.00007000"],["78726.63000000","0.00014000"],["78726.64000000","0.31773000"],["78726.68000000","0.00007000"],["78726.69000000","0.05242000"]]}}}
{"rx_ns": 47957696300, "frame": {"stream":"btcusdt@depth","data":{"e":"depthUpdate","E":1787602915014,"s":"BTCUSDT","U":99076517978,"u":99076518192,"b":[["78723.99000000","5.48910000"],["78721.95000000","1.21966000"],["78720.00000000","0.30283000"],["78719.57000000","0.30007000"],["78719.27000000","0.00000000"],["78718.00000000","0.06636000"],["78701.61000000","0.34310000"],["78700.33000000","0.00007000"],["78650.10000000","0.00000000"],["78649.95000000","0.00000000"],["78545.16000000","0.00000000"],["78541.90000000","0.00000000"],["78534.01000000","0.00778000"],["78330.37000000","0.00000000"],["78015.47000000","0.00010000"],["77938.71000000","0.00000000"],["77549.02000000","0.00000000"],["77161.27000000","0.00000000"],["76775.47000000","0.00000000"],["76391.59000000","0.00000000"],["76009.63000000","0.00000000"],["75780.00000000","0.05289000"],["75629.58000000","0.00000000"],["75251.44000000","0.00000000"],["74875.18000000","0.00000000"],["74500.80000000","0.00202000"],["74128.30000000","0.00000000"],["73757.66000000","0.00000000"],["73388.87000000","0.00000000"],["73021.93000000","0.00000000"],["70851.60000000","0.00288000"],["70851.59000000","0.00000000"],["62979.20000000","0.00031000"],["62979.19000000","0.00000000"],["62979.00000000","0.00000000"]],"a":[["78724.00000000","0.08943000"],["78724.59000000","0.00007000"],["78725.38000000","0.00007000"],["78726.69000000","0.05242000"],["78728.46000000","0.00000000"],["78728.92000000","0.00607000"],["78729.11000000","0.00000000"],["78729.67000000","0.20812000"],["78730.84000000","0.00000000"],["78731.89000000","0.00324000"],["78732.11000000","0.01270000"],["78732.15000000","0.06350000"],["78733.30000000","0.04000000"],["78733.69000000","0.00000000"],["78733.85000000","0.00327000"],["78747.06000000","0.00169000"],["78747.57000000","0.00007000"],["78759.13000000","0.34285000"],["78779.90000000","0.00000000"],["78783.95000000","0.00007000"],["78794.48000000","1.25657000"],["78815.61000000","0.00000000"],["78821.61000000","0.00025000"],["78849.95000000","0.00160000"],["78854.63000000","0.01989000"],["78889.37000000","0.00160000"],["78898.17000000","0.00000000"],["79117.62000000","0.00000000"],["79513.21000000","0.00000000"],["79910.78000000","0.00000000"],["80310.33000000","0.00000000"],["80711.88000000","0.00000000"],["81115.44000000","0.00117000"],["81521.02000000","0.00000000"],["81928.63000000","0.00000000"],["82338.27000000","0.00000000"],["82749.96000000","0.00000000"],["83163.71000000","0.00000000"],["83579.53000000","0.00000000"],["83997.43000000","0.00000000"],["84417.41000000","0.00000000"],["84839.50000000","0.00000000"]]}}}
{"rx_ns": 48956459700, "frame": {"stream":"btcusdt@depth20","data":{"lastUpdateId":99076519091,"bids":[["78726.23000000","5.77721000"],["78726.22000000","0.00020000"],["78726.21000000","0.00013000"],["78726.01000000","0.00014000"],["78726.00000000","0.07521000"],["78725.99000000","1.98442000"],["78725.98000000","1.58183000"],["78725.26000000","0.07507000"],["78725.25000000","0.03007000"],["78725.10000000","0.01871000"],["78724.00000000","0.07507000"],["78723.99000000","0.12702000"],["78723.92000000","0.03224000"],["78723.84000000","0.03107000"],["78723.54000000","0.00014000"],["78723.18000000","0.05591000"],["78723.17000000","0.00400000"],["78722.58000000","0.03728000"],["78722.53000000","0.00007000"],["78722.00000000","0.00514000"]],"asks":[["78726.24000000","0.71748000"],["78726.25000000","0.00063000"],["78726.37000000","0.00014000"],["78726.38000000","0.01953000"],["78726.63000000","0.00014000"],["78726.64000000","0.31780000"],["78726.69000000","0.00007000"],["78727.09000000","0.00204000"],["78727.41000000","0.00007000"],["78727.63000000","0.00014000"],["78727.64000000","0.03904000"],["78727.74000000","0.00007000"],["78727.99000000","0.00014000"],["78728.00000000","0.02407000"],["78728.68000000","0.00007000"],["78728.69000000","0.05228000"],["78728.82000000","0.00069000"],["78728.90000000","0.03899000"],["78729.08000000","0.00007000"],["78729.31000000","0.00007000"]]}}}
{"rx_ns": 48956557400, "frame": {"stream":"btcusdt@depth","data":{"e":"depthUpdate","E":1787602916015,"s":"BTCUSDT","U":99076518193,"u":99076519091,"b":[["78726.23000000","5.77721000"],["78726.22000000","0.00020000"],["78726.21000000","0.00013000"],["78726.15000000","0.00000000"],["78726.10000000","0.00000000"],["78726.01000000","0.00014000"],["78726.00000000","0.07521000"],["78725.99000000","1.98442000"],["78725.98000000","1.58183000"],["78725.97000000","0.00000000"],["78725.88000000","0.00000000"],["78725.65000000","0.00000000"],["78725.37000000","0.00000000"],["78725.27000000","0.00000000"],["78725.26000000","0.07507000"],["78725.25000000","0.03007000"],["78725.24000000","0.00000000"],["78725.23000000","0.00000000"],["78725.10000000","0.01871000"],["78724.72000000","0.00000000"],["78724.00000000","0.07507000"],["78723.99000000","0.12702000"],["78723.98000000","0.00000000"],["78723.97000000","0.00000000"],["78723.92000000","0.03224000"],["78723.84000000","0.03107000"],["78723.18000000","0.05591000"],["78723.03000000","0.00000000"],["78722.58000000","0.03728000"],["78722.53000000","0.00007000"],["78722.47000000","0.00000000"],["78722.44000000","0.00000000"],["78722.24000000","0.00000000"],["78722.00000000","0.00514000"],["78721.99000000","0.36670000"],["78721.96000000","0.00014000"],["78721.95000000","1.51959000"],["78721.32000000","0.03728000"],["78721.21000000","0.00000000"],["78721.18000000","0.00000000"],["78720.96000000","0.00254000"],["78720.11000000","0.00000000"],["78720.01000000","0.00000000"],["78720.00000000","0.30983000"],["78719.95000000","0.00000000"],["78719.66000000","0.21802000"],["78719.58000000","0.00000000"],["78718.70000000","0.00000000"],["78718.69000000","0.00000000"],["78718.02000000","1.91315000"],["78718.00000000","0.03623000"],["78717.79000000","0.00000000"],["78717.00000000","1.21970000"],["78716.57000000","0.08576000"],["78716.17000000","0.00007000"],["78715.83000000","0.02000000"],["78715.80000000","0.02014000"],["78714.78000000","0.00000000"],["78712.91000000","0.00007000"],["78708.87000000","0.00000000"],["78708.08000000","0.62185000"],["78706.01000000","0.00000000"],["78701.00000000","0.00000000"],["78700.33000000","0.00007000"],["78700.00000000","0.11956000"],["78699.61000000","0.13347000"],["78697.16000000","0.00000000"],["78686.00000000","0.03400000"],["78685.00000000","0.00000000"],["78684.84000000","0.00000000"],["78684.00000000","0.38624000"],["78682.83000000","0.00000000"],["78681.14000000","0.00000000"],["78678.42000000","0.00000000"],["78676.93000000","0.09415000"],["78676.41000000","0.02000000"],["78674.33000000","0.02732000"],["78665.14000000","0.00007000"],["78662.10000000","0.00000000"],["78661.43000000","0.00000000"],["78661.15000000","0.00000000"],["78649.95000000","0.00000000"],["78626.26000000","2.77157000"],["78607.99000000","0.00000000"],["78589.82000000","0.00000000"],["78574.08000000","0.00000000"],["78563.35000000","0.00127000"],["78558.34000000","0.00000000"],["78557.67000000","0.00000000"],["78542.60000000","0.00000000"],["78526.86000000","0.00000000"],["78511.12000000","0.00000000"],["78506.05000000","0.00000000"],["78495.38000000","0.00000000"],["78479.64000000","0.00126000"],["78332.36000000","0.00000000"],["77940.69000000","0.00000000"],["77550.99000000","0.00000000"],["77163.23000000","0.00000000"],["76777.42000000","0.00000000"],["76393.53000000","0.00000000"],["76011.56000000","0.00000000"],["75631.51000000","0.00000000"],["75253.35000000","0.00000000"],["74877.08000000","0.00000000"],["74502.70000000","0.00000000"],["74130.18000000","0.00000000"],["73759.53000000","0.00000000"],["73390.73000000","0.00000000"],["73023.78000000","0.00000000"],["72426.09000000","0.00000000"],["70853.61000000","0.00073000"],["70853.40000000","0.00000000"],["70851.60000000","0.00000000"],["70851.00000000","0.00000000"],["62980.99000000","0.00031000"],["62980.80000000","0.00000000"],["62979.20000000","0.00000000"],["62979.19000000","0.00000000"],["62979.00000000","0.00000000"]],"a":[["78724.00000000","0.00000000"],["78724.01000000","0.00000000"],["78724.02000000","0.00000000"],["78724.59000000","0.00000000"],["78724.73000000","0.00000000"],["78725.25000000","0.00000000"],["78725.26000000","0.00000000"],["78725.27000000","0.00000000"],["78725.38000000","0.00000000"],["78725.66000000","0.00000000"],["78725.89000000","0.00000000"],["78725.99000000","0.00000000"],["78726.00000000","0.00000000"],["78726.01000000","0.00000000"],["78726.02000000","0.00000000"],["78726.11000000","0.00000000"],["78726.16000000","0.00000000"],["78726.23000000","0.00000000"],["78726.24000000","0.71748000"],["78726.25000000","0.00063000"],["78726.37000000","0.00014000"],["78726.38000000","0.01953000"],["78726.51000000","0.00000000"],["78726.52000000","0.00000000"],["78726.62000000","0.00000000"],["78726.64000000","0.31780000"],["78726.68000000","0.00000000"],["78726.69000000","0.00007000"],["78727.09000000","0.00204000"],["78727.41000000","0.00007000"],["78727.63000000","0.00014000"],["78727.64000000","0.03904000"],["78727.74000000","0.00007000"],["78727.77000000","0.00000000"],["78727.78000000","0.00000000"],["78727.95000000","0.00000000"],["78727.99000000","0.00014000"],["78728.00000000","0.02407000"],["78728.14000000","0.00000000"],["78728.66000000","0.00000000"],["78728.68000000","0.00007000"],["78728.69000000","0.05228000"],["78728.90000000","0.03899000"],["78728.92000000","0.00000000"],["78729.00000000","0.00000000"],["78729.30000000","0.00000000"],["78729.31000000","0.00007000"],["78729.67000000","0.00000000"],["78729.83000000","0.00000000"],["78730.00000000","0.02407000"],["78730.16000000","0.03899000"],["78731.20000000","0.01000000"],["78731.50000000","0.02161000"],["78731.51000000","0.19594000"],["78731.63000000","0.00000000"],["78731.77000000","0.00331000"],["78732.00000000","0.02400000"],["78732.11000000","0.00000000"],["78732.14000000","0.00000000"],["78732.15000000","0.00000000"],["78733.29000000","0.00000000"],["78733.43000000","0.12708000"],["78734.13000000","0.21951000"],["78734.41000000","0.00000000"],["78734.43000000","0.00000000"],["78734.80000000","0.00000000"],["78735.83000000","0.00254000"],["78735.84000000","0.00325000"],["78735.94000000","0.00254000"],["78736.69000000","0.00254000"],["78737.10000000","0.00000000"],["78737.98000000","0.00000000"],["78737.99000000","0.31759000"],["78739.25000000","0.00000000"],["78739.26000000","0.00000000"],["78739.98000000","0.00635000"],["78740.94000000","0.00007000"],["78742.73000000","0.04103000"],["78743.17000000","0.02000000"],["78743.35000000","0.00000000"],["78746.45000000","0.00000000"],["78747.57000000","0.00007000"],["78747.66000000","0.00000000"],["78747.98000000","0.00000000"],["78748.32000000","0.00000000"],["78748.66000000","0.00000000"],["78749.94000000","0.00000000"],["78749.99000000","0.09400000"],["78750.18000000","0.00406000"],["78758.32000000","0.00000000"],["78758.58000000","0.00000000"],["78758.72000000","0.00000000"],["78760.21000000","0.00000000"],["78760.47000000","0.00000000"],["78760.61000000","0.00000000"],["78762.87000000","0.02126000"],["78764.00000000","0.02414000"],["78765.00000000","0.00000000"],["78766.00000000","0.03400000"],["78766.11000000","0.00007000"],["78766.18000000","0.00000000"],["78779.34000000","0.00000000"],["78781.64000000","0.00316000"],["78782.56000000","0.38224000"],["78784.31000000","0.00000000"],["78785.89000000","0.00000000"],["78787.04000000","0.00000000"],["78789.32000000","0.00000000"],["78789.56000000","0.00406000"],["78798.41000000","0.00110000"],["78818.54000000","0.00000000"],["78819.94000000","1.90515000"],["78820.82000000","0.00000000"],["78821.06000000","0.00406000"],["78857.40000000","0.00000000"],["78865.79000000","0.00000000"],["78868.07000000","0.00000000"],["78868.31000000","0.00406000"],["78873.14000000","0.00000000"],["78888.88000000","0.00010000"],["78904.62000000","0.00000000"],["78920.36000000","0.00000000"],["78932.00000000","0.00007000"],["78936.10000000","0.00000000"],["78936.66000000","0.00000000"],["78938.94000000","0.00000000"],["78939.19000000","0.00406000"],["78940.28000000","0.00007000"],["78944.21000000","0.00000000"],["78951.84000000","0.00000000"],["79119.63000000","0.00000000"],["79515.23000000","0.00000000"],["79912.81000000","0.00000000"],["80312.37000000","0.00000000"],["80713.94000000","0.00000000"],["81117.50000000","0.00000000"],["81523.09000000","0.00000000"],["81930.71000000","0.00000000"],["82340.36000000","0.00000000"],["82752.06000000","0.00000000"],["83165.82000000","0.00000000"],["83581.65000000","0.00000000"],["83999.56000000","0.00000000"],["84419.56000000","0.00000000"],["84841.66000000","0.00000000"]]}}}
{"rx_ns": 49953085200, "frame": {"stream":"btcusdt@depth20","data":{"lastUpdateId":99076519574,"bids":[["78726.23000000","4.70655000"],["78726.22000000","0.00055000"],["78726.21000000","0.00013000"],["78726.01000000","0.00014000"],["78726.00000000","0.36238000"],["78725.99000000","0.04928000"],["78725.98000000","1.21959000"],["78725.25000000","0.00007000"],["78725.10000000","0.01871000"],["78724.60000000","0.00007000"],["78724.00000000","0.00500000"],["78723.99000000","0.06917000"],["78723.84000000","0.03114000"],["78723.54000000","0.00014000"],["78723.18000000","0.04963000"],["78723.17000000","0.00400000"],["78723.03000000","0.00007000"],["78722.58000000","0.03735000"],["78722.53000000","0.00007000"],["78722.00000000","0.01856000"]],"asks":[["78726.24000000","1.25675000"],["78726.25000000","0.00076000"],["78726.26000000","0.00013000"],["78726.37000000","0.00014000"],["78726.38000000","0.01953000"],["78726.63000000","0.00014000"],["78726.64000000","0.31780000"],["78726.69000000","0.00007000"],["78727.09000000","0.00204000"],["78727.41000000","0.00014000"],["78727.63000000","0.00014000"],["78727.64000000","0.03250000"],["78727.74000000","0.00007000"],["78727.99000000","0.00014000"],["78728.00000000","0.02407000"],["78728.03000000","0.00326000"],["78728.52000000","0.00007000"],["78728.68000000","0.00007000"],["78728.69000000","0.05235000"],["78728.90000000","0.03899000"]]}}}
{"rx_ns": 49953243900, "frame": {"stream":"btcusdt@depth","data":{"e":"depthUpdate","E":1787602917014,"s":"BTCUSDT","U":99076519092,"u":99076519574,"b":[["78726.23000000","4.70655000"],["78726.22000000","0.00055000"],["78726.01000000","0.00014000"],["78726.00000000","0.36238000"],["78725.99000000","0.04928000"],["78725.98000000","1.21959000"],["78725.26000000","0.00000000"],["78725.25000000","0.00007000"],["78725.10000000","0.01871000"],["78724.60000000","0.00007000"],["78724.00000000","0.00500000"],["78723.99000000","0.06917000"],["78723.92000000","0.00000000"],["78723.84000000","0.03114000"],["78723.54000000","0.00014000"],["78723.18000000","0.04963000"],["78723.03000000","0.00007000"],["78722.58000000","0.03735000"],["78722.01000000","0.00000000"],["78722.00000000","0.01856000"],["78721.96000000","0.00007000"],["78721.72000000","0.00000000"],["78721.33000000","0.00635000"],["78721.20000000","0.33407000"],["78720.96000000","0.00000000"],["78720.50000000","0.00000000"],["78720.00000000","0.02407000"],["78719.66000000","0.00007000"],["78719.35000000","0.00000000"],["78719.34000000","0.00000000"],["78719.26000000","0.30014000"],["78719.12000000","0.00000000"],["78718.85000000","0.00000000"],["78718.71000000","0.00027000"],["78718.70000000","0.00000000"],["78718.62000000","0.00000000"],["78718.60000000","0.02000000"],["78718.47000000","0.00000000"],["78718.35000000","0.21930000"],["78718.03000000","0.00000000"],["78718.02000000","1.90515000"],["78717.45000000","0.00000000"],["78717.11000000","0.00000000"],["78717.03000000","0.00000000"],["78716.00000000","0.02508000"],["78715.81000000","0.00000000"],["78715.75000000","0.00000000"],["78715.74000000","0.02600000"],["78715.34000000","0.00000000"],["78714.79000000","0.00000000"],["78714.58000000","0.00400000"],["78714.36000000","0.00000000"],["78714.01000000","0.00000000"],["78713.65000000","0.00150000"],["78713.33000000","0.00400000"],["78712.92000000","0.00400000"],["78712.88000000","0.00406000"],["78709.27000000","0.00000000"],["78709.08000000","0.00000000"],["78708.08000000","0.00000000"],["78707.95000000","0.00000000"],["78707.18000000","0.00000000"],["78705.88000000","0.63519000"],["78705.21000000","0.00000000"],["78704.46000000","0.00000000"],["78702.90000000","0.00000000"],["78702.57000000","0.00007000"],["78700.33000000","0.00000000"],["78694.30000000","0.34313000"],["78686.58000000","0.34317000"],["78684.84000000","0.00007000"],["78680.75000000","0.00000000"],["78676.35000000","0.02600000"],["78669.91000000","0.00000000"],["78661.05000000","0.00000000"],["78657.56000000","1.25876000"],["78656.71000000","0.02000000"],["78647.45000000","0.00000000"],["78643.65000000","0.00000000"],["78638.43000000","0.00000000"],["78626.26000000","0.00000000"],["78594.81000000","0.00406000"],["78591.20000000","0.00000000"],["78573.50000000","0.00000000"],["78544.84000000","0.00778000"],["78534.01000000","0.00000000"],["78332.59000000","0.00000000"],["78015.47000000","0.00000000"],["77940.93000000","0.00000000"],["77551.23000000","0.00000000"],["77410.94000000","0.00600000"],["77163.47000000","0.00000000"],["76777.65000000","0.00000000"],["76393.76000000","0.00000000"],["76011.80000000","0.00000000"],["75631.74000000","0.00000000"],["75253.58000000","0.00000000"],["74877.31000000","0.00000000"],["74502.92000000","0.00000000"],["74130.41000000","0.00000000"],["73759.76000000","0.00000000"],["73390.96000000","0.00000000"],["73024.00000000","0.00000000"],["70853.61000000","0.00176000"],["70853.60000000","0.00009000"],["70853.00000000","0.00000000"],["62980.99000000","0.00031000"],["62980.98000000","0.00000000"],["62979.00000000","0.00000000"]],"a":[["78726.24000000","1.25675000"],["78726.25000000","0.00076000"],["78726.26000000","0.00013000"],["78727.41000000","0.00014000"],["78727.64000000","0.03250000"],["78727.73000000","0.00000000"],["78727.75000000","0.00000000"],["78728.03000000","0.00326000"],["78728.52000000","0.00007000"],["78728.69000000","0.05235000"],["78728.82000000","0.00000000"],["78728.89000000","0.00000000"],["78728.90000000","0.03899000"],["78728.93000000","0.20619000"],["78729.30000000","0.00000000"],["78730.15000000","0.00000000"],["78730.16000000","0.03892000"],["78730.64000000","0.00000000"],["78730.65000000","0.00000000"],["78731.19000000","0.00000000"],["78731.49000000","0.00000000"],["78731.51000000","0.00000000"],["78731.53000000","0.00000000"],["78731.76000000","0.00000000"],["78732.10000000","0.00000000"],["78732.11000000","0.01270000"],["78732.15000000","0.06350000"],["78732.49000000","0.00000000"],["78732.77000000","0.00000000"],["78732.95000000","0.00000000"],["78733.29000000","0.00000000"],["78733.42000000","0.00254000"],["78733.83000000","0.00000000"],["78733.84000000","0.00000000"],["78734.12000000","0.00254000"],["78734.13000000","0.21944000"],["78734.39000000","0.00000000"],["78735.12000000","0.00000000"],["78735.15000000","0.00014000"],["78735.30000000","0.00400000"],["78735.81000000","0.00000000"],["78735.83000000","0.00000000"],["78735.94000000","0.00000000"],["78736.16000000","0.00048000"],["78736.20000000","0.31759000"],["78736.69000000","0.00000000"],["78736.73000000","0.01270000"],["78737.40000000","0.00400000"],["78737.56000000","0.00000000"],["78737.98000000","0.00000000"],["78737.99000000","0.00000000"],["78738.95000000","0.00000000"],["78739.98000000","0.00000000"],["78740.44000000","0.00000000"],["78741.99000000","0.06112000"],["78743.21000000","0.02000000"],["78743.43000000","0.00000000"],["78743.45000000","0.38102000"],["78745.60000000","0.00406000"],["78745.82000000","1.90515000"],["78747.57000000","0.00000000"],["78748.93000000","0.00000000"],["78749.81000000","0.00007000"],["78749.98000000","0.36224000"],["78750.00000000","0.09337000"],["78750.18000000","0.00000000"],["78756.37000000","0.00879000"],["78758.74000000","0.02813000"],["78760.63000000","0.02438000"],["78762.91000000","0.02000000"],["78764.13000000","0.02514000"],["78765.51000000","0.00000000"],["78766.11000000","0.00000000"],["78767.79000000","1.25700000"],["78768.90000000","0.00000000"],["78770.45000000","0.00000000"],["78772.42000000","0.00000000"],["78773.37000000","0.00000000"],["78775.88000000","0.00316000"],["78782.61000000","0.02000000"],["78784.98000000","0.00406000"],["78785.82000000","0.00000000"],["78785.96000000","0.00000000"],["78789.56000000","0.00000000"],["78789.83000000","0.00007000"],["78804.63000000","1.21952000"],["78805.66000000","0.00000000"],["78811.07000000","0.00000000"],["78811.08000000","1.90515000"],["78819.94000000","0.00000000"],["78821.06000000","0.00000000"],["78821.61000000","0.00000000"],["78823.85000000","0.00025000"],["78863.72000000","0.00406000"],["78868.31000000","0.00000000"],["78872.64000000","0.00007000"],["78939.19000000","0.00000000"],["79119.88000000","0.00000000"],["79515.48000000","0.00000000"],["79913.05000000","0.00000000"],["80312.62000000","0.00000000"],["80714.18000000","0.00000000"],["81117.75000000","0.00000000"],["81523.34000000","0.00000000"],["81930.96000000","0.00000000"],["82340.61000000","0.00000000"],["82752.32000000","0.00000000"],["83166.08000000","0.00000000"],["83581.91000000","0.00000000"],["83999.82000000","0.00000000"],["84419.82000000","0.00000000"],["84841.91000000","0.00000000"]]}}}
{"rx_ns": 50951449800, "frame": {"stream":"btcusdt@depth20","data":{"lastUpdateId":99076519967,"bids":[["78726.23000000","4.46835000"],["78726.22000000","0.00055000"],["78726.21000000","0.00013000"],["78726.01000000","0.00014000"],["78726.00000000","0.36245000"],["78725.99000000","0.04928000"],["78725.98000000","1.21959000"],["78725.25000000","0.00007000"],["78725.10000000","0.01871000"],["78724.80000000","0.00008000"],["78724.60000000","0.00007000"],["78724.00000000","0.00507000"],["78723.99000000","0.06917000"],["78723.84000000","0.03114000"],["78723.54000000","0.00014000"],["78723.18000000","0.04956000"],["78723.17000000","0.00400000"],["78723.03000000","0.00007000"],["78722.58000000","0.03728000"],["78722.53000000","0.00007000"]],"asks":[["78726.24000000","0.98797000"],["78726.25000000","0.00076000"],["78726.26000000","0.00013000"],["78726.37000000","0.00014000"],["78726.38000000","0.01953000"],["78726.49000000","0.00014000"],["78726.50000000","0.20447000"],["78726.63000000","0.00014000"],["78726.64000000","0.31780000"],["78726.69000000","0.00007000"],["78727.09000000","0.00204000"],["78727.41000000","0.00014000"],["78727.63000000","0.00014000"],["78727.64000000","0.03250000"],["78727.99000000","0.00007000"],["78728.00000000","0.02407000"],["78728.52000000","0.00007000"],["78728.69000000","0.05221000"],["78728.90000000","0.03899000"],["78729.08000000","0.00007000"]]}}}
{"rx_ns": 50951559200, "frame": {"stream":"btcusdt@depth","data":{"e":"depthUpdate","E":1787602918014,"s":"BTCUSDT","U":99076519575,"u":99076519967,"b":[["78726.23000000","4.46835000"],["78726.22000000","0.00055000"],["78726.00000000","0.36245000"],["78725.10000000","0.01871000"],["78724.80000000","0.00008000"],["78724.01000000","0.00000000"],["78724.00000000","0.00507000"],["78723.18000000","0.04956000"],["78722.58000000","0.03728000"],["78722.01000000","0.00635000"],["78722.00000000","0.01721000"],["78721.86000000","0.00150000"],["78721.20000000","0.33407000"],["78719.75000000","0.00000000"],["78719.72000000","0.00000000"],["78719.32000000","0.00000000"],["78719.26000000","0.30021000"],["78719.20000000","0.00000000"],["78718.71000000","0.12737000"],["78716.72000000","0.02600000"],["78716.43000000","0.03224000"],["78715.77000000","0.00000000"],["78713.65000000","0.00000000"],["78712.88000000","0.00000000"],["78709.98000000","0.34307000"],["78702.57000000","0.00007000"],["78686.58000000","0.00000000"],["78684.98000000","0.09410000"],["78684.84000000","0.00000000"],["78680.80000000","0.00000000"],["78677.32000000","0.02600000"],["78676.93000000","0.00000000"],["78673.52000000","0.00406000"],["78661.10000000","0.00000000"],["78656.65000000","0.02600000"],["78647.45000000","0.02116000"],["78642.03000000","0.00406000"],["78622.44000000","2.13830000"],["78621.04000000","2.77149000"],["78603.57000000","0.00000000"],["78544.84000000","0.00000000"],["78534.01000000","0.00778000"],["78332.59000000","0.00000000"],["78017.69000000","0.00010000"],["77940.93000000","0.00000000"],["77551.23000000","0.00000000"],["77163.47000000","0.00000000"],["76777.65000000","0.00000000"],["76393.76000000","0.00000000"],["76011.80000000","0.00000000"],["75631.74000000","0.00000000"],["75253.58000000","0.00000000"],["74877.31000000","0.00000000"],["74502.92000000","0.00000000"],["74130.41000000","0.00000000"],["73759.76000000","0.00000000"],["73390.96000000","0.00000000"],["73024.00000000","0.00000000"],["70853.61000000","0.00272000"],["70853.60000000","0.00000000"],["70853.00000000","0.00000000"],["62981.00000000","0.00031000"],["62980.99000000","0.00031000"],["62980.98000000","0.00000000"]],"a":[["78726.24000000","0.98797000"],["78726.25000000","0.00076000"],["78726.38000000","0.01953000"],["78726.49000000","0.00014000"],["78726.50000000","0.20447000"],["78726.64000000","0.31780000"],["78727.41000000","0.00014000"],["78727.44000000","0.00000000"],["78727.45000000","0.00000000"],["78727.74000000","0.00000000"],["78727.99000000","0.00007000"],["78728.00000000","0.02407000"],["78728.03000000","0.00000000"],["78728.44000000","0.00000000"],["78728.68000000","0.00000000"],["78728.69000000","0.05221000"],["78728.90000000","0.03899000"],["78728.93000000","0.00000000"],["78729.28000000","0.00000000"],["78729.31000000","0.00000000"],["78729.53000000","0.00000000"],["78729.56000000","0.00000000"],["78730.16000000","0.03892000"],["78730.30000000","0.00327000"],["78731.20000000","0.00000000"],["78731.50000000","0.00000000"],["78731.77000000","0.00000000"],["78732.11000000","0.00000000"],["78732.15000000","0.00000000"],["78732.60000000","0.01000000"],["78733.30000000","0.00000000"],["78733.42000000","0.00254000"],["78734.05000000","0.00254000"],["78734.10000000","0.04000000"],["78734.12000000","0.00000000"],["78734.13000000","0.21951000"],["78734.80000000","0.00000000"],["78735.38000000","0.00000000"],["78735.54000000","0.00000000"],["78735.95000000","0.00000000"],["78736.20000000","0.31759000"],["78736.72000000","0.00000000"],["78736.73000000","0.00000000"],["78737.10000000","0.00000000"],["78737.99000000","0.00000000"],["78738.47000000","0.00635000"],["78738.75000000","0.38110000"],["78738.89000000","0.00000000"],["78739.26000000","0.00000000"],["78740.89000000","0.00635000"],["78743.17000000","0.04000000"],["78743.33000000","1.21952000"],["78743.37000000","0.00000000"],["78743.39000000","0.00000000"],["78745.60000000","0.00000000"],["78745.82000000","0.00000000"],["78749.81000000","0.00007000"],["78749.92000000","0.00406000"],["78758.74000000","0.00000000"],["78758.90000000","0.02827000"],["78760.63000000","0.00000000"],["78760.79000000","0.02424000"],["78762.87000000","0.04126000"],["78766.11000000","0.00000000"],["78782.57000000","0.02000000"],["78784.98000000","0.00000000"],["78785.99000000","0.00000000"],["78804.64000000","0.00000000"],["78805.68000000","0.00000000"],["78811.07000000","0.00000000"],["78816.48000000","0.00000000"],["78819.93000000","1.90515000"],["78819.94000000","0.00000000"],["78823.55000000","2.13284000"],["78863.72000000","0.00000000"],["78934.59000000","0.00000000"],["79119.88000000","0.00000000"],["79515.48000000","0.00000000"],["79913.05000000","0.00000000"],["80312.62000000","0.00000000"],["80714.18000000","0.00000000"],["81117.75000000","0.00000000"],["81523.34000000","0.00000000"],["81930.96000000","0.00000000"],["82340.61000000","0.00000000"],["82752.32000000","0.00000000"],["83166.08000000","0.00000000"],["83581.91000000","0.00000000"],["83999.82000000","0.00000000"],["84419.82000000","0.00000000"],["84841.91000000","0.00000000"]]}}}
{"rx_ns": 51952295200, "frame": {"stream":"btcusdt@depth20","data":{"lastUpdateId":99076520178,"bids":[["78726.23000000","4.72968000"],["78726.22000000","0.00055000"],["78726.21000000","0.00013000"],["78726.01000000","0.00014000"],["78726.00000000","0.36245000"],["78725.99000000","0.04928000"],["78725.98000000","1.21959000"],["78725.25000000","0.00007000"],["78725.10000000","0.01871000"],["78724.80000000","0.00008000"],["78724.60000000","0.00007000"],["78724.00000000","0.00507000"],["78723.99000000","0.06917000"],["78723.84000000","0.03114000"],["78723.54000000","0.00014000"],["78723.18000000","0.04956000"],["78723.17000000","0.00400000"],["78723.03000000","0.00007000"],["78722.58000000","0.03728000"],["78722.53000000","0.00007000"]],"asks":[["78726.24000000","1.03004000"],["78726.25000000","0.00076000"],["78726.26000000","0.00013000"],["78726.37000000","0.00014000"],["78726.38000000","0.01953000"],["78726.49000000","0.00014000"],["78726.50000000","0.20447000"],["78726.63000000","0.00014000"],["78726.64000000","0.31780000"],["78726.69000000","0.00007000"],["78727.09000000","0.00204000"],["78727.41000000","0.00014000"],["78727.63000000","0.00014000"],["78727.64000000","0.03250000"],["78727.74000000","0.00007000"],["78727.99000000","0.00007000"],["78728.00000000","0.02407000"],["78728.52000000","0.00007000"],["78728.69000000","0.05235000"],["78728.90000000","0.03899000"]]}}}
{"rx_ns": 51952405500, "frame": {"stream":"btcusdt@depth","data":{"e":"depthUpdate","E":1787602919014,"s":"BTCUSDT","U":99076519968,"u":99076520178,"b":[["78726.23000000","4.72968000"],["78722.00000000","0.02421000"],["78717.55000000","0.02400000"],["78716.56000000","0.00000000"],["78711.43000000","0.00406000"],["78702.57000000","0.00007000"],["78685.88000000","0.00000000"],["78678.15000000","0.02400000"],["78666.17000000","0.00000000"],["78657.63000000","0.02600000"],["78647.45000000","0.02116000"],["78623.65000000","2.77149000"],["78621.04000000","0.00000000"],["78544.84000000","0.00778000"],["78534.01000000","0.00000000"],["78332.59000000","0.00000000"],["77940.93000000","0.00000000"],["77551.23000000","0.00000000"],["77163.47000000","0.00000000"],["76777.65000000","0.00000000"],["76393.76000000","0.00000000"],["76011.80000000","0.00000000"],["75631.74000000","0.00000000"],["75253.58000000","0.00000000"],["74877.31000000","0.00000000"],["74502.92000000","0.00000000"],["74130.41000000","0.00000000"],["73759.76000000","0.00000000"],["73390.96000000","0.00000000"],["73024.00000000","0.00000000"],["70853.61000000","0.00368000"],["70853.00000000","0.00000000"],["62981.00000000","0.00031000"],["62980.99000000","0.00031000"],["62980.98000000","0.00000000"]],"a":[["78726.24000000","1.03004000"],["78726.25000000","0.00076000"],["78727.74000000","0.00007000"],["78728.69000000","0.05235000"],["78728.90000000","0.03899000"],["78729.06000000","0.00000000"],["78729.08000000","0.00007000"],["78729.14000000","0.00000000"],["78729.15000000","0.00000000"],["78729.16000000","0.00000000"],["78729.22000000","0.00000000"],["78729.27000000","0.00000000"],["78729.33000000","0.00000000"],["78729.34000000","0.00000000"],["78729.50000000","0.00000000"],["78729.60000000","0.00000000"],["78730.00000000","0.02407000"],["78732.11000000","0.01270000"],["78732.15000000","0.06350000"],["78733.42000000","0.00000000"],["78734.39000000","0.00254000"],["78736.20000000","0.00000000"],["78736.73000000","0.31759000"],["78742.37000000","0.02000000"],["78742.60000000","0.00000000"],["78743.32000000","1.90515000"],["78749.81000000","0.00007000"],["78762.07000000","0.02000000"],["78774.42000000","0.00000000"],["78781.77000000","0.02000000"],["78789.30000000","0.00406000"],["78794.12000000","0.00000000"],["78819.93000000","0.00000000"],["78820.80000000","0.00406000"],["78868.05000000","0.00406000"],["78938.92000000","0.00000000"],["79119.88000000","0.00000000"],["79515.48000000","0.00000000"],["79913.05000000","0.00000000"],["80312.62000000","0.00000000"],["80714.18000000","0.00000000"],["81117.75000000","0.00000000"],["81523.34000000","0.00000000"],["81930.96000000","0.00000000"],["82340.61000000","0.00000000"],["82752.32000000","0.00000000"],["83166.08000000","0.00000000"],["83581.91000000","0.00000000"],["83999.82000000","0.00000000"],["84419.82000000","0.00000000"],["84841.91000000","0.00000000"]]}}}
{"rx_ns": 52951124100, "frame": {"stream":"btcusdt@depth20","data":{"lastUpdateId":99076520389,"bids":[["78726.23000000","4.24485000"],["78726.22000000","0.00055000"],["78726.21000000","0.00013000"],["78726.01000000","0.00014000"],["78726.00000000","0.36245000"],["78725.99000000","0.04928000"],["78725.98000000","1.21959000"],["78725.25000000","0.00007000"],["78725.10000000","0.01871000"],["78724.80000000","0.00008000"],["78724.60000000","0.00007000"],["78724.00000000","0.00507000"],["78723.99000000","0.06917000"],["78723.84000000","0.03114000"],["78723.54000000","0.00007000"],["78723.18000000","0.04956000"],["78723.17000000","0.00400000"],["78723.03000000","0.00007000"],["78722.58000000","0.03728000"],["78722.53000000","0.00007000"]],"asks":[["78726.24000000","1.24135000"],["78726.25000000","0.00076000"],["78726.26000000","0.00013000"],["78726.37000000","0.00014000"],["78726.38000000","0.01953000"],["78726.49000000","0.00014000"],["78726.50000000","0.20447000"],["78726.63000000","0.00014000"],["78726.64000000","0.31787000"],["78726.69000000","0.00007000"],["78727.09000000","0.00204000"],["78727.41000000","0.00014000"],["78727.63000000","0.00014000"],["78727.64000000","0.03250000"],["78727.74000000","0.00007000"],["78727.99000000","0.00007000"],["78728.00000000","0.02407000"],["78728.52000000","0.00007000"],["78728.54000000","0.00007000"],["78728.69000000","0.05228000"]]}}}
{"rx_ns": 52951616700, "frame": {"stream":"btcusdt@depth","data":{"e":"depthUpdate","E":1787602920014,"s":"BTCUSDT","U":99076520179,"u":99076520389,"b":[["78726.23000000","4.24485000"],["78723.54000000","0.00007000"],["78722.01000000","0.00000000"],["78721.33000000","0.00000000"],["78719.68000000","0.01270000"],["78718.71000000","0.00027000"],["78718.66000000","0.00000000"],["78718.53000000","0.00000000"],["78718.03000000","0.00400000"],["78717.45000000","0.00200000"],["78713.90000000","0.00007000"],["78706.17000000","0.13242000"],["78705.88000000","0.00000000"],["78704.01000000","0.63519000"],["78702.75000000","0.00007000"],["78702.57000000","0.00007000"],["78701.12000000","0.00635000"],["78689.13000000","0.00000000"],["78684.84000000","0.00007000"],["78682.46000000","0.00000000"],["78660.34000000","0.00316000"],["78658.45000000","0.02400000"],["78655.08000000","0.00316000"],["78647.45000000","0.00000000"],["78592.50000000","0.00007000"],["78576.93000000","0.00127000"],["78576.75000000","0.00007000"],["78561.00000000","0.00007000"],["78545.25000000","0.00007000"],["78544.84000000","0.00000000"],["78534.01000000","0.00778000"],["78529.50000000","0.00007000"],["78513.75000000","0.00007000"],["78510.51000000","0.01989000"],["78498.22000000","0.00000000"],["78498.00000000","0.00007000"],["78482.25000000","0.00007000"],["78332.59000000","0.01000000"],["77940.93000000","0.01000000"],["77551.23000000","0.01000000"],["77163.47000000","0.01000000"],["76777.65000000","0.01000000"],["76393.76000000","0.01000000"],["76011.80000000","0.01000000"],["75631.74000000","0.01000000"],["75253.58000000","0.01000000"],["74877.31000000","0.01000000"],["74502.92000000","0.01000000"],["74130.41000000","0.01000000"],["73759.76000000","0.01000000"],["73390.96000000","0.01000000"],["73024.00000000","0.01000000"],["70853.61000000","0.00432000"],["70853.60000000","0.00009000"],["70853.00000000","0.00000000"],["62981.00000000","0.00031000"],["62980.99000000","0.00031000"],["62980.98000000","0.00000000"]],"a":[["78726.24000000","1.24135000"],["78726.64000000","0.31787000"],["78728.00000000","0.02407000"],["78728.14000000","0.00000000"],["78728.54000000","0.00007000"],["78728.69000000","0.05228000"],["78728.90000000","0.03899000"],["78729.14000000","0.00000000"],["78729.45000000","0.00000000"],["78729.48000000","0.00000000"],["78729.51000000","0.00000000"],["78730.00000000","0.02400000"],["78732.49000000","0.00635000"],["78732.95000000","0.00254000"],["78733.42000000","0.00254000"],["78733.99000000","0.00635000"],["78734.05000000","0.00000000"],["78734.39000000","0.00000000"],["78735.12000000","0.00000000"],["78735.38000000","0.31760000"],["78735.83000000","0.00000000"],["78736.73000000","0.00000000"],["78737.99000000","0.00400000"],["78738.47000000","0.00000000"],["78739.26000000","0.00635000"],["78740.89000000","0.00000000"],["78742.55000000","0.00000000"],["78743.31000000","0.00455000"],["78744.52000000","0.06329000"],["78746.44000000","0.00000000"],["78746.49000000","0.07275000"],["78749.81000000","0.00007000"],["78750.00000000","0.09344000"],["78755.99000000","0.43575000"],["78761.61000000","0.00000000"],["78765.75000000","0.00007000"],["78787.99000000","0.00190000"],["78790.14000000","0.00317000"],["78820.49000000","0.00529000"],["78823.04000000","0.00000000"],["78860.25000000","0.00007000"],["78867.44000000","0.00076000"],["78876.00000000","0.02414000"],["78891.75000000","0.00007000"],["78907.50000000","0.00007000"],["78923.25000000","0.00007000"],["78938.95000000","0.00406000"],["78939.00000000","0.00007000"],["78954.75000000","0.00007000"],["79119.88000000","0.01000000"],["79515.48000000","0.01000000"],["79913.05000000","0.01000000"],["80312.62000000","0.01000000"],["80714.18000000","0.01000000"],["81117.75000000","0.01000000"],["81523.34000000","0.01000000"],["81930.96000000","0.01000000"],["82340.61000000","0.01000000"],["82752.32000000","0.01000000"],["83166.08000000","0.01000000"],["83581.91000000","0.01000000"],["83999.82000000","0.01000000"],["84419.82000000","0.01000000"],["84841.91000000","0.01000000"],["86422.88000000","0.18910000"]]}}}
{"rx_ns": 53952731100, "frame": {"stream":"btcusdt@depth20","data":{"lastUpdateId":99076520537,"bids":[["78726.23000000","4.24485000"],["78726.22000000","0.00055000"],["78726.21000000","0.00013000"],["78726.01000000","0.00014000"],["78726.00000000","0.36245000"],["78725.99000000","0.04602000"],["78725.98000000","1.21959000"],["78725.25000000","0.00007000"],["78725.10000000","0.01871000"],["78724.80000000","0.00008000"],["78724.60000000","0.00007000"],["78724.00000000","0.00507000"],["78723.99000000","0.06587000"],["78723.90000000","0.00020000"],["78723.84000000","0.03114000"],["78723.54000000","0.00007000"],["78723.18000000","0.04956000"],["78723.17000000","0.00400000"],["78723.03000000","0.00007000"],["78722.58000000","0.03728000"]],"asks":[["78726.24000000","1.23849000"],["78726.25000000","0.00083000"],["78726.26000000","0.00013000"],["78726.37000000","0.00014000"],["78726.38000000","0.01953000"],["78726.49000000","0.00014000"],["78726.50000000","0.20447000"],["78726.63000000","0.00014000"],["78726.64000000","0.31780000"],["78726.69000000","0.00007000"],["78727.09000000","0.00204000"],["78727.41000000","0.00014000"],["78727.63000000","0.00014000"],["78727.64000000","0.03250000"],["78727.74000000","0.00007000"],["78727.88000000","0.00324000"],["78727.99000000","0.00007000"],["78728.00000000","0.02407000"],["78728.52000000","0.00007000"],["78728.69000000","0.05228000"]]}}}
{"rx_ns": 53952833200, "frame": {"stream":"btcusdt@depth","data":{"e":"depthUpdate","E":1787602921014,"s":"BTCUSDT","U":99076520390,"u":99076520537,"b":[["78725.99000000","0.04602000"],["78723.99000000","0.06587000"],["78723.90000000","0.00020000"],["78720.46000000","0.00400000"],["78718.63000000","0.00000000"],["78718.61000000","0.00000000"],["78718.03000000","0.00800000"],["78715.45000000","0.00254000"],["78705.21000000","0.63519000"],["78704.01000000","0.00000000"],["78702.57000000","0.00007000"],["78701.51000000","0.00635000"],["78701.12000000","0.00000000"],["78623.65000000","0.00000000"],["78621.04000000","2.77149000"],["78596.26000000","0.04092000"],["78573.75000000","1.52237000"],["78332.59000000","0.01000000"],["77940.93000000","0.01000000"],["77606.60000000","0.01288000"],["77551.23000000","0.01000000"],["77163.47000000","0.01000000"],["76777.65000000","0.01000000"],["76393.76000000","0.01000000"],["76011.80000000","0.01000000"],["75631.74000000","0.01000000"],["75253.58000000","0.01000000"],["74877.31000000","0.01000000"],["74502.92000000","0.01000000"],["74130.41000000","0.01000000"],["73759.76000000","0.01000000"],["73390.96000000","0.01000000"],["73024.00000000","0.01000000"],["72426.09000000","0.00014000"],["70853.61000000","0.00432000"],["70853.00000000","0.00000000"],["62981.00000000","0.00031000"],["62980.99000000","0.00031000"],["62980.98000000","0.00000000"]],"a":[["78726.24000000","1.23849000"],["78726.25000000","0.00083000"],["78726.64000000","0.31780000"],["78727.88000000","0.00324000"],["78728.00000000","0.02407000"],["78728.54000000","0.00000000"],["78730.00000000","0.02407000"],["78731.18000000","0.00254000"],["78732.95000000","0.00000000"],["78733.42000000","0.00508000"],["78734.64000000","0.00400000"],["78735.38000000","0.00000000"],["78735.83000000","0.31759000"],["78739.26000000","0.00000000"],["78739.69000000","0.00635000"],["78749.81000000","0.00007000"],["78765.87000000","0.00400000"],["78766.51000000","0.00000000"],["78784.65000000","0.00000000"],["78802.67000000","0.04764000"],["78809.07000000","0.00000000"],["78832.41000000","0.02789000"],["78872.88000000","1.52237000"],["79119.88000000","0.01000000"],["79515.48000000","0.01000000"],["79913.05000000","0.01000000"],["80312.62000000","0.01000000"],["80714.18000000","0.01000000"],["81117.75000000","0.01000000"],["81523.34000000","0.01000000"],["81930.96000000","0.01000000"],["82340.61000000","0.01000000"],["82752.32000000","0.01000000"],["83166.08000000","0.01000000"],["83581.91000000","0.01000000"],["83999.82000000","0.01000000"],["84202.54000000","0.00884000"],["84419.82000000","0.01000000"],["84841.91000000","0.01000000"],["86422.88000000","0.20801000"]]}}}
{"rx_ns": 54952622400, "kind": "rest", "req": {"method": "GET", "url": "https://data-api.binance.vision/api/v3/depth?symbol=BTCUSDT&limit=100", "limit": 100, "weight": 5, "sent_ns": 52951480100, "status": 200, "used_weight_1m": "5", "recv_ns": 53997884200}, "frame": {"lastUpdateId":99076520537,"bids":[["78726.23000000","4.24485000"],["78726.22000000","0.00055000"],["78726.21000000","0.00013000"],["78726.01000000","0.00014000"],["78726.00000000","0.36245000"],["78725.99000000","0.04602000"],["78725.98000000","1.21959000"],["78725.25000000","0.00007000"],["78725.10000000","0.01871000"],["78724.80000000","0.00008000"],["78724.60000000","0.00007000"],["78724.00000000","0.00507000"],["78723.99000000","0.06587000"],["78723.90000000","0.00020000"],["78723.84000000","0.03114000"],["78723.54000000","0.00007000"],["78723.18000000","0.04956000"],["78723.17000000","0.00400000"],["78723.03000000","0.00007000"],["78722.58000000","0.03728000"],["78722.53000000","0.00007000"],["78722.00000000","0.02421000"],["78721.99000000","0.36670000"],["78721.96000000","0.00007000"],["78721.95000000","1.51959000"],["78721.86000000","0.00150000"],["78721.32000000","0.03728000"],["78721.20000000","0.33407000"],["78720.49000000","0.00007000"],["78720.46000000","0.00400000"],["78720.00000000","0.02407000"],["78719.68000000","0.01270000"],["78719.67000000","0.00014000"],["78719.66000000","0.00007000"],["78719.57000000","0.30007000"],["78719.26000000","0.30021000"],["78719.23000000","0.00400000"],["78718.71000000","0.00027000"],["78718.60000000","0.02000000"],["78718.44000000","0.00007000"],["78718.35000000","0.21930000"],["78718.03000000","0.00800000"],["78718.02000000","1.90515000"],["78718.01000000","1.58176000"],["78718.00000000","0.03623000"],["78717.99000000","0.01627000"],["78717.55000000","0.02400000"],["78717.45000000","0.00200000"],["78717.44000000","0.00007000"],["78717.26000000","0.00400000"],["78717.10000000","0.00008000"],["78717.00000000","1.21970000"],["78716.72000000","0.02600000"],["78716.68000000","0.03000000"],["78716.61000000","0.02200000"],["78716.57000000","0.08576000"],["78716.43000000","0.03224000"],["78716.39000000","0.00007000"],["78716.17000000","0.00007000"],["78716.04000000","0.12703000"],["78716.01000000","0.00011000"],["78716.00000000","0.02508000"],["78715.83000000","0.02000000"],["78715.80000000","0.02014000"],["78715.74000000","0.02600000"],["78715.68000000","0.12000000"],["78715.45000000","0.00254000"],["78715.29000000","0.00400000"],["78715.00000000","0.00007000"],["78714.58000000","0.00400000"],["78714.35000000","0.00007000"],["78714.17000000","0.00007000"],["78714.06000000","0.00322000"],["78714.00000000","0.02400000"],["78713.90000000","0.00007000"],["78713.56000000","0.00007000"],["78713.46000000","0.02200000"],["78713.33000000","0.00400000"],["78713.32000000","0.00400000"],["78712.92000000","0.00400000"],["78712.91000000","0.00007000"],["78712.70000000","0.02000000"],["78712.68000000","0.02200000"],["78712.30000000","0.00134000"],["78712.21000000","0.02000000"],["78712.00000000","0.02400000"],["78711.93000000","0.00014000"],["78711.92000000","0.02000000"],["78711.91000000","0.02000000"],["78711.83000000","0.02000000"],["78711.82000000","1.90515000"],["78711.43000000","0.00406000"],["78711.35000000","0.00400000"],["78711.31000000","0.00331000"],["78711.02000000","1.21952000"],["78710.64000000","0.00010000"],["78710.63000000","0.00007000"],["78710.62000000","0.00010000"],["78710.46000000","0.00027000"],["78710.25000000","0.00007000"]],"asks":[["78726.24000000","1.23849000"],["78726.25000000","0.00083000"],["78726.26000000","0.00013000"],["78726.37000000","0.00014000"],["78726.38000000","0.01953000"],["78726.49000000","0.00014000"],["78726.50000000","0.20447000"],["78726.63000000","0.00014000"],["78726.64000000","0.31780000"],["78726.69000000","0.00007000"],["78727.09000000","0.00204000"],["78727.41000000","0.00014000"],["78727.63000000","0.00014000"],["78727.64000000","0.03250000"],["78727.74000000","0.00007000"],["78727.88000000","0.00324000"],["78727.99000000","0.00007000"],["78728.00000000","0.02407000"],["78728.52000000","0.00007000"],["78728.69000000","0.05228000"],["78728.90000000","0.03899000"],["78729.08000000","0.00007000"],["78730.00000000","0.02407000"],["78730.16000000","0.03892000"],["78730.30000000","0.00327000"],["78730.71000000","0.00007000"],["78731.18000000","0.00254000"],["78731.27000000","0.00007000"],["78731.28000000","0.00014000"],["78731.48000000","0.00007000"],["78731.89000000","0.00324000"],["78732.00000000","0.02400000"],["78732.11000000","0.01270000"],["78732.15000000","0.06350000"],["78732.30000000","0.02000000"],["78732.49000000","0.00635000"],["78732.50000000","0.00008000"],["78732.60000000","0.01000000"],["78732.76000000","0.00007000"],["78732.96000000","0.00007000"],["78733.42000000","0.00508000"],["78733.43000000","0.12708000"],["78733.85000000","0.00327000"],["78733.99000000","0.00635000"],["78734.00000000","0.02400000"],["78734.06000000","0.02000000"],["78734.10000000","0.04000000"],["78734.13000000","0.21951000"],["78734.40000000","0.08000000"],["78734.42000000","0.00007000"],["78734.64000000","0.00400000"],["78734.81000000","0.00007000"],["78735.13000000","0.02161000"],["78735.15000000","0.00014000"],["78735.16000000","0.14289000"],["78735.30000000","0.00400000"],["78735.39000000","0.19391000"],["78735.83000000","0.31759000"],["78735.84000000","0.00325000"],["78736.00000000","0.02407000"],["78736.02000000","0.00027000"],["78736.16000000","0.00048000"],["78736.21000000","0.10327000"],["78736.74000000","0.38119000"],["78736.84000000","0.00007000"],["78736.85000000","0.00007000"],["78737.11000000","0.00318000"],["78737.40000000","0.00400000"],["78737.57000000","0.00007000"],["78737.99000000","0.00400000"],["78738.00000000","0.02400000"],["78738.48000000","0.00007000"],["78738.75000000","0.38110000"],["78738.90000000","0.00007000"],["78739.02000000","0.00014000"],["78739.27000000","0.02161000"],["78739.69000000","0.00635000"],["78739.70000000","0.00048000"],["78739.99000000","0.00400000"],["78740.00000000","0.02400000"],["78740.01000000","0.22743000"],["78740.10000000","0.00327000"],["78740.20000000","0.00008000"],["78740.26000000","0.26500000"],["78740.45000000","0.58742000"],["78740.55000000","0.00187000"],["78740.72000000","0.00007000"],["78740.90000000","0.00400000"],["78740.94000000","0.00007000"],["78740.95000000","0.00007000"],["78741.05000000","0.00321000"],["78741.28000000","0.58542000"],["78741.40000000","0.12699000"],["78741.99000000","0.06112000"],["78742.00000000","0.02400000"],["78742.01000000","0.21930000"],["78742.09000000","0.00150000"],["78742.14000000","0.00007000"],["78742.37000000","0.02000000"],["78742.48000000","0.02285000"]]}}
{"rx_ns": 54952622400, "frame": {"stream":"btcusdt@depth20","data":{"lastUpdateId":99076522608,"bids":[["78720.00000000","0.02542000"],["78719.99000000","0.00049000"],["78719.67000000","0.00007000"],["78719.66000000","0.00007000"],["78719.57000000","0.00007000"],["78719.26000000","0.00007000"],["78719.18000000","0.00007000"],["78718.44000000","0.00007000"],["78718.34000000","0.00014000"],["78718.33000000","0.01740000"],["78718.01000000","0.00014000"],["78718.00000000","0.02989000"],["78717.99000000","0.01634000"],["78717.45000000","0.00200000"],["78717.44000000","0.00007000"],["78717.19000000","0.00014000"],["78717.18000000","0.04956000"],["78717.08000000","0.02901000"],["78716.39000000","0.00007000"],["78716.17000000","0.00007000"]],"asks":[["78720.01000000","4.65791000"],["78720.02000000","0.00020000"],["78720.03000000","0.00013000"],["78721.26000000","0.00014000"],["78721.27000000","0.03450000"],["78721.65000000","0.00400000"],["78721.95000000","0.00014000"],["78721.96000000","0.20019000"],["78721.98000000","0.00014000"],["78721.99000000","0.31774000"],["78722.00000000","0.07683000"],["78722.01000000","0.60495000"],["78722.02000000","0.00014000"],["78722.53000000","0.04140000"],["78722.58000000","0.00007000"],["78722.59000000","0.40512000"],["78722.69000000","0.05207000"],["78723.17000000","0.00635000"],["78723.18000000","0.02168000"],["78723.19000000","0.00007000"]]}}}
{"rx_ns": 54954203400, "frame": {"stream":"btcusdt@depth","data":{"e":"depthUpdate","E":1787602922014,"s":"BTCUSDT","U":99076520538,"u":99076522608,"b":[["78726.23000000","0.00000000"],["78726.22000000","0.00000000"],["78726.21000000","0.00000000"],["78726.17000000","0.00000000"],["78726.01000000","0.00000000"],["78726.00000000","0.00000000"],["78725.99000000","0.00000000"],["78725.98000000","0.00000000"],["78725.25000000","0.00000000"],["78725.11000000","0.00000000"],["78725.10000000","0.00000000"],["78724.80000000","0.00000000"],["78724.60000000","0.00000000"],["78724.00000000","0.00000000"],["78723.99000000","0.00000000"],["78723.90000000","0.00000000"],["78723.85000000","0.00000000"],["78723.84000000","0.00000000"],["78723.54000000","0.00000000"],["78723.19000000","0.00000000"],["78723.18000000","0.00000000"],["78723.17000000","0.00000000"],["78723.03000000","0.00000000"],["78722.59000000","0.00000000"],["78722.58000000","0.00000000"],["78722.57000000","0.00000000"],["78722.53000000","0.00000000"],["78722.43000000","0.00000000"],["78722.01000000","0.00000000"],["78722.00000000","0.00000000"],["78721.99000000","0.00000000"],["78721.96000000","0.00000000"],["78721.95000000","0.00000000"],["78721.86000000","0.00000000"],["78721.54000000","0.00000000"],["78721.33000000","0.00000000"],["78721.32000000","0.00000000"],["78721.21000000","0.00000000"],["78721.20000000","0.00000000"],["78720.75000000","0.00000000"],["78720.49000000","0.00000000"],["78720.46000000","0.00000000"],["78720.01000000","0.00000000"],["78720.00000000","0.02542000"],["78719.99000000","0.00049000"],["78719.77000000","0.00000000"],["78719.76000000","0.00000000"],["78719.68000000","0.00000000"],["78719.67000000","0.00007000"],["78719.58000000","0.00000000"],["78719.57000000","0.00007000"],["78719.26000000","0.00007000"],["78719.23000000","0.00000000"],["78719.19000000","0.00000000"],["78719.18000000","0.00007000"],["78719.14000000","0.00000000"],["78718.95000000","0.00000000"],["78718.71000000","0.00000000"],["78718.70000000","0.00000000"],["78718.69000000","0.00000000"],["78718.60000000","0.00000000"],["78718.35000000","0.00000000"],["78718.34000000","0.00014000"],["78718.33000000","0.01740000"],["78718.03000000","0.00000000"],["78718.02000000","0.00000000"],["78718.01000000","0.00014000"],["78718.00000000","0.02989000"],["78717.99000000","0.01634000"],["78717.97000000","0.00000000"],["78717.90000000","0.00000000"],["78717.63000000","0.00000000"],["78717.56000000","0.00000000"],["78717.55000000","0.00000000"],["78717.50000000","0.00000000"],["78717.49000000","0.00000000"],["78717.48000000","0.00000000"],["78717.46000000","0.00000000"],["78717.26000000","0.00000000"],["78717.19000000","0.00014000"],["78717.18000000","0.04956000"],["78717.10000000","0.00000000"],["78717.08000000","0.02901000"],["78717.00000000","0.00000000"],["78716.94000000","0.00000000"],["78716.91000000","0.00000000"],["78716.77000000","0.00000000"],["78716.73000000","0.00000000"],["78716.72000000","0.00000000"],["78716.68000000","0.00000000"],["78716.61000000","0.00000000"],["78716.57000000","0.00000000"],["78716.51000000","0.00000000"],["78716.43000000","0.00000000"],["78716.29000000","0.00000000"],["78716.05000000","0.00000000"],["78716.04000000","0.00000000"],["78716.01000000","0.00018000"],["78716.00000000","0.02515000"],["78715.83000000","0.00000000"],["78715.82000000","0.03481000"],["78715.80000000","0.00007000"],["78715.74000000","0.00000000"],["78715.71000000","0.00069000"],["78715.68000000","0.00000000"],["78715.46000000","0.00000000"],["78715.45000000","0.00000000"],["78715.34000000","0.00000000"],["78715.30000000","0.00048000"],["78715.29000000","0.00000000"],["78715.08000000","0.00000000"],["78714.89000000","0.00000000"],["78714.84000000","0.00000000"],["78714.81000000","0.00000000"],["78714.79000000","0.00000000"],["78714.78000000","0.00000000"],["78714.77000000","0.00000000"],["78714.67000000","0.00000000"],["78714.64000000","0.00000000"],["78714.61000000","0.00000000"],["78714.58000000","0.00000000"],["78714.56000000","0.03481000"],["78714.50000000","0.00000000"],["78714.38000000","0.00000000"],["78714.37000000","0.02523000"],["78714.36000000","0.00000000"],["78714.27000000","0.00000000"],["78714.24000000","0.00000000"],["78714.22000000","0.00000000"],["78714.17000000","0.00000000"],["78714.15000000","0.00000000"],["78714.08000000","0.00000000"],["78714.06000000","0.00000000"],["78714.00000000","0.02407000"],["78713.91000000","0.00000000"],["78713.57000000","0.00000000"],["78713.48000000","0.00000000"],["78713.47000000","0.04725000"],["78713.46000000","0.00000000"],["78713.33000000","0.00000000"],["78713.32000000","0.00000000"],["78712.98000000","0.00000000"],["78712.92000000","0.00000000"],["78712.74000000","0.00000000"],["78712.70000000","0.00000000"],["78712.68000000","0.00000000"],["78712.58000000","0.00000000"],["78712.52000000","0.00000000"],["78712.50000000","0.00000000"],["78712.49000000","0.00000000"],["78712.22000000","0.12711000"],["78712.21000000","0.00000000"],["78712.14000000","0.00000000"],["78711.93000000","0.00007000"],["78711.92000000","0.00000000"],["78711.91000000","0.00000000"],["78711.84000000","0.00000000"],["78711.83000000","0.00000000"],["78711.82000000","0.00000000"],["78711.43000000","0.00000000"],["78711.35000000","0.00000000"],["78711.31000000","0.00000000"],["78711.02000000","1.21952000"],["78710.98000000","0.00000000"],["78710.66000000","0.00000000"],["78710.57000000","0.20840000"],["78710.50000000","0.00000000"],["78710.47000000","0.00000000"],["78710.25000000","0.00007000"],["78710.14000000","0.00000000"],["78710.12000000","0.00000000"],["78710.00000000","0.02400000"],["78709.98000000","0.00000000"],["78709.58000000","0.00000000"],["78709.41000000","0.00000000"],["78709.37000000","0.00000000"],["78709.36000000","0.00204000"],["78709.29000000","0.00000000"],["78709.14000000","0.00000000"],["78708.37000000","0.08576000"],["78708.08000000","0.00000000"],["78708.07000000","0.00000000"],["78708.06000000","0.00014000"],["78707.77000000","0.00007000"],["78707.72000000","0.00000000"],["78707.58000000","0.00000000"],["78707.17000000","0.00000000"],["78707.05000000","0.00400000"],["78706.72000000","0.00325000"],["78706.26000000","0.00048000"],["78706.17000000","0.00000000"],["78705.97000000","0.00000000"],["78705.87000000","0.00000000"],["78705.68000000","0.00000000"],["78705.21000000","0.00000000"],["78705.20000000","0.00000000"],["78705.09000000","0.00328000"],["78704.84000000","0.00047000"],["78704.77000000","0.00190000"],["78704.57000000","0.00000000"],["78704.55000000","0.00150000"],["78704.35000000","0.12705000"],["78704.27000000","0.00000000"],["78704.19000000","0.00014000"],["78704.07000000","0.01000000"],["78703.48000000","0.00000000"],["78703.37000000","0.00000000"],["78703.07000000","0.00000000"],["78703.02000000","0.00635000"],["78702.90000000","0.00000000"],["78702.78000000","0.00329000"],["78702.57000000","0.00007000"],["78702.55000000","0.00000000"],["78702.37000000","0.00000000"],["78702.10000000","0.00635000"],["78702.01000000","0.00000000"],["78701.86000000","0.00000000"],["78701.69000000","0.00000000"],["78701.67000000","0.00000000"],["78701.61000000","0.00000000"],["78701.57000000","0.06000000"],["78701.51000000","0.00000000"],["78701.42000000","0.00000000"],["78701.00000000","0.00007000"],["78700.97000000","0.02000000"],["78700.73000000","0.02000000"],["78700.60000000","0.00000000"],["78700.17000000","0.00000000"],["78700.06000000","0.36224000"],["78700.01000000","0.00000000"],["78700.00000000","0.11963000"],["78699.93000000","0.02000000"],["78699.92000000","0.00000000"],["78699.62000000","0.00400000"],["78699.54000000","0.00000000"],["78698.84000000","0.00330000"],["78698.17000000","0.08000000"],["78697.99000000","0.00092000"],["78697.69000000","0.00000000"],["78697.57000000","0.00000000"],["78697.04000000","0.00000000"],["78696.18000000","0.00000000"],["78695.90000000","0.00000000"],["78695.89000000","0.00000000"],["78694.90000000","0.00328000"],["78694.88000000","0.00000000"],["78694.73000000","1.21966000"],["78694.30000000","0.00000000"],["78692.03000000","0.36224000"],["78692.02000000","1.90515000"],["78691.11000000","0.00000000"],["78690.46000000","0.34315000"],["78689.49000000","0.00400000"],["78688.72000000","0.13245000"],["78688.67000000","0.63526000"],["78688.66000000","0.34316000"],["78688.57000000","0.00012000"],["78687.75000000","0.00007000"],["78686.00000000","0.02400000"],["78685.47000000","0.00400000"],["78685.33000000","0.00000000"],["78685.15000000","0.00000000"],["78685.00000000","0.00000000"],["78684.98000000","0.00000000"],["78684.87000000","0.00635000"],["78684.84000000","0.00014000"],["78684.34000000","0.00000000"],["78683.46000000","0.00400000"],["78683.44000000","0.00000000"],["78683.00000000","0.00000000"],["78682.32000000","0.34319000"],["78682.14000000","1.31212000"],["78682.13000000","0.00000000"],["78682.00000000","0.02400000"],["78681.45000000","0.00400000"],["78681.21000000","0.00000000"],["78680.97000000","0.00014000"],["78680.30000000","0.00000000"],["78680.00000000","0.03439000"],["78679.04000000","0.04636000"],["78677.43000000","0.00400000"],["78677.10000000","0.00007000"],["78675.42000000","0.00400000"],["78674.33000000","0.00000000"],["78673.52000000","0.00000000"],["78673.41000000","0.00400000"],["78673.23000000","0.00007000"],["78672.46000000","0.00000000"],["78669.89000000","0.00000000"],["78669.42000000","0.00000000"],["78669.36000000","0.00000000"],["78669.03000000","0.00000000"],["78668.76000000","0.00000000"],["78668.66000000","0.00406000"],["78668.48000000","0.00000000"],["78668.19000000","0.00000000"],["78668.08000000","0.00000000"],["78667.92000000","0.00000000"],["78667.80000000","0.00000000"],["78667.65000000","0.00000000"],["78667.55000000","0.00000000"],["78666.12000000","0.00014000"],["78663.20000000","0.00008000"],["78662.13000000","0.00000000"],["78661.47000000","0.00635000"],["78660.34000000","0.00000000"],["78657.86000000","0.00626000"],["78657.39000000","0.00425000"],["78655.08000000","0.00000000"],["78654.69000000","0.00427000"],["78654.29000000","0.02000000"],["78654.06000000","0.00434000"],["78653.78000000","0.00000000"],["78652.61000000","1.25884000"],["78652.01000000","0.00000000"],["78649.00000000","0.00316000"],["78647.05000000","0.00000000"],["78642.03000000","0.00000000"],["78641.17000000","0.00000000"],["78640.39000000","0.00000000"],["78640.01000000","0.00000000"],["78638.12000000","0.01739000"],["78638.01000000","0.00314000"],["78632.56000000","0.00000000"],["78630.01000000","0.00000000"],["78628.01000000","0.00243000"],["78621.04000000","0.00000000"],["78596.26000000","0.00000000"],["78594.81000000","0.00000000"],["78589.95000000","0.00406000"],["78589.82000000","0.00007000"],["78585.60000000","0.04092000"],["78576.93000000","0.00000000"],["78576.75000000","0.00000000"],["78574.08000000","0.00007000"],["78573.75000000","0.00000000"],["78571.48000000","0.00000000"],["78570.41000000","0.00127000"],["78563.35000000","0.00000000"],["78561.00000000","0.00000000"],["78560.01000000","0.00127000"],["78558.14000000","1.52206000"],["78553.80000000","0.00000000"],["78551.83000000","0.00000000"],["78549.81000000","0.00097000"],["78545.25000000","0.00000000"],["78545.01000000","0.00663000"],["78529.50000000","0.00000000"],["78521.53000000","0.00000000"],["78518.01000000","0.00382000"],["78513.75000000","0.00000000"],["78498.00000000","0.00000000"],["78482.25000000","0.00000000"],["78399.42000000","0.00000000"],["78390.06000000","0.00037000"],["78332.59000000","0.00000000"],["78317.01000000","0.00007000"],["78052.93000000","0.00032000"],["77940.93000000","0.00000000"],["77832.00000000","0.00000000"],["77551.23000000","0.00000000"],["77163.47000000","0.00000000"],["76934.14000000","0.00900000"],["76777.65000000","0.00000000"],["76393.76000000","0.00000000"],["76011.80000000","0.00000000"],["75631.74000000","0.00000000"],["75253.58000000","0.00000000"],["74877.31000000","0.00000000"],["74502.92000000","0.00000000"],["74130.41000000","0.00000000"],["73759.76000000","0.00000000"],["73390.96000000","0.00000000"],["73024.00000000","0.00000000"],["72426.09000000","0.00000000"],["70853.61000000","0.00027000"],["70853.60000000","0.00000000"],["70853.59000000","0.00009000"],["70850.33000000","0.00000000"],["70850.00000000","0.06318000"],["70848.00000000","0.00032000"],["62981.00000000","0.00031000"],["62980.99000000","0.00000000"],["62980.98000000","0.00000000"],["62976.00000000","0.00031000"]],"a":[["78720.01000000","4.65791000"],["78720.02000000","0.00020000"],["78720.03000000","0.00013000"],["78721.21000000","0.00000000"],["78721.26000000","0.00014000"],["78721.27000000","0.03450000"],["78721.33000000","0.00000000"],["78721.65000000","0.00400000"],["78721.95000000","0.00014000"],["78721.96000000","0.20019000"],["78721.98000000","0.00014000"],["78721.99000000","0.31774000"],["78722.00000000","0.07683000"],["78722.01000000","0.60495000"],["78722.02000000","0.00014000"],["78722.03000000","0.00000000"],["78722.53000000","0.04140000"],["78722.57000000","0.00000000"],["78722.58000000","0.00007000"],["78722.59000000","0.40512000"],["78722.60000000","0.00000000"],["78722.61000000","0.00000000"],["78722.69000000","0.05207000"],["78723.04000000","0.00000000"],["78723.17000000","0.00635000"],["78723.18000000","0.02168000"],["78723.19000000","0.00007000"],["78723.54000000","0.00014000"],["78723.55000000","0.00000000"],["78723.66000000","0.00400000"],["78723.79000000","0.04140000"],["78723.83000000","0.00000000"],["78723.84000000","0.00000000"],["78723.85000000","0.00014000"],["78723.91000000","0.00000000"],["78723.95000000","0.00000000"],["78724.00000000","0.00000000"],["78724.01000000","0.00000000"],["78724.68000000","0.00000000"],["78724.69000000","0.00007000"],["78724.80000000","0.00008000"],["78724.81000000","0.00007000"],["78725.08000000","0.00455000"],["78725.09000000","3.12467000"],["78725.10000000","0.07507000"],["78725.11000000","0.04517000"],["78725.12000000","0.10792000"],["78725.25000000","0.00000000"],["78725.26000000","0.19424000"],["78725.27000000","0.00007000"],["78725.52000000","0.00000000"],["78725.53000000","0.36224000"],["78725.54000000","0.00007000"],["78725.55000000","0.00007000"],["78725.63000000","0.00000000"],["78725.67000000","0.00400000"],["78725.91000000","0.02286000"],["78725.99000000","0.00000000"],["78726.00000000","0.00000000"],["78726.01000000","0.00000000"],["78726.17000000","0.00000000"],["78726.22000000","0.00000000"],["78726.23000000","0.07500000"],["78726.24000000","0.22713000"],["78726.25000000","0.00000000"],["78726.26000000","0.00000000"],["78726.37000000","0.00000000"],["78726.38000000","0.00000000"],["78726.48000000","0.00000000"],["78726.49000000","0.02161000"],["78726.50000000","0.00007000"],["78726.61000000","0.00254000"],["78726.62000000","0.00007000"],["78726.63000000","0.00000000"],["78726.64000000","0.00000000"],["78726.69000000","0.00000000"],["78726.73000000","0.04032000"],["78727.09000000","0.00000000"],["78727.24000000","0.38117000"],["78727.29000000","0.00321000"],["78727.39000000","0.38110000"],["78727.54000000","0.00000000"],["78727.62000000","0.00000000"],["78727.63000000","0.00000000"],["78727.64000000","0.00000000"],["78727.68000000","0.00400000"],["78727.81000000","0.00000000"],["78727.87000000","0.00000000"],["78727.91000000","0.00027000"],["78727.94000000","0.00000000"],["78727.99000000","0.00000000"],["78728.00000000","0.02400000"],["78728.12000000","0.00007000"],["78728.53000000","0.12701000"],["78728.66000000","0.00007000"],["78728.68000000","0.00000000"],["78728.69000000","0.00000000"],["78728.89000000","0.00000000"],["78728.90000000","0.00000000"],["78729.00000000","0.00007000"],["78729.69000000","0.00400000"],["78729.83000000","0.00007000"],["78729.96000000","0.00000000"],["78730.00000000","0.10213000"],["78730.13000000","0.00000000"],["78730.14000000","1.24113000"],["78730.15000000","0.00000000"],["78730.16000000","0.00000000"],["78730.58000000","0.01270000"],["78730.62000000","0.06350000"],["78731.17000000","0.00000000"],["78731.18000000","0.00000000"],["78731.26000000","0.00000000"],["78731.30000000","0.00007000"],["78731.70000000","0.00400000"],["78731.83000000","0.00007000"],["78732.11000000","0.00000000"],["78732.15000000","0.00000000"],["78732.30000000","0.00000000"],["78732.35000000","0.34297000"],["78732.49000000","0.00000000"],["78732.60000000","0.00000000"],["78732.67000000","0.00000000"],["78732.95000000","0.00000000"],["78733.31000000","0.00000000"],["78733.42000000","0.00000000"],["78733.43000000","0.12701000"],["78733.71000000","0.00400000"],["78733.84000000","0.00000000"],["78733.99000000","0.36224000"],["78734.05000000","0.00000000"],["78734.06000000","0.00000000"],["78734.09000000","0.34296000"],["78734.10000000","0.00000000"],["78734.13000000","0.21937000"],["78734.40000000","0.00000000"],["78734.53000000","0.04103000"],["78735.00000000","0.38106000"],["78735.12000000","3.12467000"],["78735.45000000","0.01500000"],["78735.76000000","0.10279000"],["78735.83000000","0.00000000"],["78736.16000000","0.00000000"],["78736.34000000","0.00000000"],["78736.66000000","0.00000000"],["78736.74000000","0.00000000"],["78736.83000000","0.06329000"],["78737.57000000","0.00000000"],["78737.99000000","0.00000000"],["78738.34000000","0.00000000"],["78738.75000000","0.00000000"],["78738.79000000","0.07275000"],["78739.53000000","0.02516000"],["78739.56000000","0.34294000"],["78739.69000000","0.00000000"],["78739.70000000","0.00000000"],["78739.73000000","0.43584000"],["78739.74000000","0.00400000"],["78740.00000000","0.10054000"],["78740.01000000","0.14632000"],["78740.55000000","0.34293000"],["78741.05000000","0.00000000"],["78741.24000000","0.00000000"],["78741.28000000","0.00000000"],["78741.32000000","0.34293000"],["78741.42000000","0.09485000"],["78741.98000000","0.36224000"],["78741.99000000","0.00000000"],["78742.09000000","0.00000000"],["78742.48000000","0.00000000"],["78742.52000000","0.00060000"],["78742.57000000","0.00406000"],["78742.73000000","0.00000000"],["78743.31000000","0.00000000"],["78743.41000000","0.00000000"],["78743.43000000","0.00190000"],["78744.52000000","0.00000000"],["78744.99000000","0.00000000"],["78745.98000000","0.00000000"],["78746.10000000","0.00000000"],["78746.49000000","0.00000000"],["78746.87000000","0.00000000"],["78746.88000000","0.00000000"],["78747.06000000","0.00000000"],["78747.11000000","0.00000000"],["78747.53000000","0.00000000"],["78749.81000000","0.00007000"],["78749.92000000","0.00000000"],["78749.99000000","0.00000000"],["78752.57000000","0.00000000"],["78752.72000000","0.00000000"],["78754.69000000","0.00000000"],["78755.81000000","0.00000000"],["78755.93000000","0.00435000"],["78755.99000000","0.00000000"],["78756.07000000","0.00000000"],["78756.24000000","0.00625000"],["78756.29000000","0.02500000"],["78756.66000000","0.00000000"],["78757.83000000","0.00000000"],["78757.92000000","0.00000000"],["78758.27000000","0.00000000"],["78758.38000000","0.38095000"],["78758.63000000","0.00000000"],["78759.13000000","0.00000000"],["78759.84000000","0.00000000"],["78760.60000000","0.00000000"],["78761.83000000","0.00433000"],["78761.85000000","0.00000000"],["78762.00000000","0.03407000"],["78762.24000000","0.00000000"],["78762.40000000","0.00432000"],["78762.57000000","0.00000000"],["78763.86000000","0.00000000"],["78764.13000000","0.00000000"],["78764.54000000","0.00000000"],["78765.00000000","0.00000000"],["78765.43000000","0.00000000"],["78765.87000000","0.00000000"],["78766.00000000","0.02400000"],["78766.39000000","0.00000000"],["78766.86000000","0.49720000"],["78769.41000000","0.00000000"],["78769.53000000","0.00634000"],["78770.00000000","0.02400000"],["78771.66000000","0.00324000"],["78773.38000000","0.00000000"],["78775.07000000","0.00000000"],["78775.88000000","0.00000000"],["78777.64000000","0.00317000"],["78780.54000000","0.00000000"],["78781.52000000","0.01739000"],["78781.64000000","0.00000000"],["78781.76000000","0.00190000"],["78782.12000000","0.00112000"],["78782.18000000","0.00000000"],["78783.23000000","0.00000000"],["78783.25000000","0.00000000"],["78783.56000000","0.00000000"],["78784.63000000","0.00000000"],["78785.27000000","0.00000000"],["78785.28000000","0.32014000"],["78785.48000000","0.00000000"],["78787.99000000","0.00000000"],["78789.30000000","0.00000000"],["78789.83000000","0.00000000"],["78790.14000000","0.00000000"],["78791.62000000","1.90515000"],["78791.63000000","0.00000000"],["78794.47000000","0.00000000"],["78794.48000000","0.00000000"],["78796.75000000","0.00000000"],["78798.41000000","0.00000000"],["78801.09000000","0.00000000"],["78801.10000000","0.00000000"],["78804.63000000","0.00000000"],["78811.08000000","0.00000000"],["78811.60000000","0.00000000"],["78816.77000000","0.93647000"],["78816.98000000","0.00000000"],["78819.95000000","0.00000000"],["78820.80000000","0.00000000"],["78821.72000000","0.02789000"],["78821.99000000","0.00000000"],["78827.83000000","0.00000000"],["78832.41000000","0.00000000"],["78857.22000000","1.52206000"],["78857.40000000","0.00007000"],["78860.68000000","0.00076000"],["78860.69000000","0.00406000"],["78863.62000000","0.00000000"],["78864.22000000","0.00000000"],["78867.44000000","0.00000000"],["78868.05000000","0.00000000"],["78872.88000000","0.00000000"],["78873.14000000","0.00007000"],["78876.00000000","0.02407000"],["78888.88000000","0.00017000"],["78891.75000000","0.00000000"],["78904.62000000","0.00007000"],["78907.50000000","0.00000000"],["78920.36000000","0.00007000"],["78923.25000000","0.00000000"],["78931.56000000","0.00406000"],["78932.00000000","0.00000000"],["78935.10000000","0.00000000"],["78936.10000000","0.00007000"],["78938.18000000","0.00000000"],["78938.95000000","0.00000000"],["78939.00000000","0.00000000"],["78940.28000000","0.00000000"],["78951.84000000","0.00007000"],["78954.75000000","0.00000000"],["78967.58000000","0.00000000"],["79119.88000000","0.01000000"],["79515.48000000","0.01000000"],["79913.05000000","0.01000000"],["80312.62000000","0.01000000"],["80714.18000000","0.01000000"],["81000.00000000","78.26479000"],["81117.75000000","0.01000000"],["81523.34000000","0.01000000"],["81666.66000000","2.54462000"],["81930.96000000","0.01000000"],["82333.33000000","0.02022000"],["82340.61000000","0.01000000"],["82752.32000000","0.01000000"],["83000.00000000","103.36960000"],["83166.08000000","0.01000000"],["83581.91000000","0.01000000"],["83666.66000000","0.01511000"],["83999.82000000","0.01000000"],["84333.33000000","0.00982000"],["84419.82000000","0.01000000"],["84841.91000000","0.01000000"],["85000.00000000","114.74833000"]]}}}
{"rx_ns": 55954535100, "frame": {"stream":"btcusdt@depth20","data":{"lastUpdateId":99076523011,"bids":[["78720.00000000","0.02775000"],["78719.99000000","0.00049000"],["78719.88000000","0.00007000"],["78719.67000000","0.00007000"],["78719.66000000","0.00007000"],["78719.57000000","0.00007000"],["78719.26000000","0.00007000"],["78719.10000000","0.00007000"],["78718.44000000","0.00007000"],["78718.34000000","0.00014000"],["78718.33000000","0.01747000"],["78718.01000000","0.00014000"],["78718.00000000","0.02989000"],["78717.99000000","0.01634000"],["78717.45000000","0.00200000"],["78717.44000000","0.00007000"],["78717.19000000","0.00014000"],["78717.18000000","0.04963000"],["78717.08000000","0.02908000"],["78716.74000000","0.00007000"]],"asks":[["78720.01000000","4.41314000"],["78720.02000000","0.00020000"],["78720.03000000","0.00013000"],["78721.26000000","0.00014000"],["78721.27000000","0.03457000"],["78721.65000000","0.00400000"],["78721.95000000","0.00014000"],["78721.96000000","0.20026000"],["78721.98000000","0.00014000"],["78721.99000000","0.31781000"],["78722.00000000","0.07521000"],["78722.01000000","0.05313000"],["78722.52000000","0.25413000"],["78722.53000000","0.04147000"],["78722.59000000","0.17756000"],["78722.69000000","0.05214000"],["78723.17000000","0.00635000"],["78723.18000000","0.02161000"],["78723.19000000","0.00007000"],["78723.54000000","0.00014000"]]}}}
{"rx_ns": 55954754200, "frame": {"stream":"btcusdt@depth","data":{"e":"depthUpdate","E":1787602923014,"s":"BTCUSDT","U":99076522609,"u":99076523011,"b":[["78720.00000000","0.02775000"],["78719.99000000","0.00049000"],["78719.88000000","0.00007000"],["78719.18000000","0.00000000"],["78719.10000000","0.00007000"],["78718.33000000","0.01747000"],["78717.99000000","0.01634000"],["78717.18000000","0.04963000"],["78717.08000000","0.02908000"],["78716.74000000","0.00007000"],["78716.00000000","0.02515000"],["78715.82000000","0.03488000"],["78715.71000000","0.00000000"],["78715.70000000","0.00000000"],["78715.30000000","0.00000000"],["78715.06000000","0.00000000"],["78714.56000000","0.03481000"],["78714.37000000","0.00000000"],["78714.00000000","0.02400000"],["78713.47000000","0.00000000"],["78712.91000000","0.00000000"],["78712.22000000","0.12704000"],["78712.12000000","0.00000000"],["78712.02000000","0.02516000"],["78711.85000000","0.00000000"],["78711.78000000","0.00204000"],["78711.25000000","0.04822000"],["78710.57000000","0.00000000"],["78710.25000000","0.00007000"],["78710.16000000","0.00000000"],["78710.05000000","0.00000000"],["78709.74000000","0.00000000"],["78709.58000000","0.00000000"],["78709.38000000","0.00000000"],["78709.36000000","0.00000000"],["78708.06000000","0.00007000"],["78708.02000000","0.00000000"],["78707.41000000","0.00000000"],["78707.40000000","0.00000000"],["78707.05000000","0.00000000"],["78707.04000000","0.00000000"],["78707.01000000","0.00000000"],["78706.72000000","0.00000000"],["78706.44000000","0.00048000"],["78706.32000000","0.00069000"],["78706.25000000","0.00000000"],["78703.86000000","0.00000000"],["78703.30000000","0.02200000"],["78703.25000000","0.02400000"],["78703.08000000","0.00000000"],["78703.07000000","0.00000000"],["78703.03000000","0.00000000"],["78702.96000000","0.00000000"],["78702.90000000","0.00400000"],["78702.57000000","0.00000000"],["78702.52000000","0.02000000"],["78702.46000000","0.02600000"],["78702.45000000","0.02600000"],["78701.68000000","0.00000000"],["78701.65000000","0.00000000"],["78701.60000000","0.00000000"],["78701.55000000","0.00000000"],["78701.52000000","0.00000000"],["78701.48000000","0.00000000"],["78701.42000000","0.00254000"],["78700.17000000","0.02200000"],["78700.00000000","0.02433000"],["78698.85000000","0.00000000"],["78698.60000000","0.02000000"],["78698.52000000","0.02000000"],["78698.17000000","0.00000000"],["78697.27000000","0.08000000"],["78696.78000000","1.21966000"],["78696.34000000","0.00007000"],["78695.18000000","0.12707000"],["78694.73000000","0.00000000"],["78689.30000000","0.00000000"],["78689.29000000","0.00000000"],["78688.73000000","0.63533000"],["78688.67000000","0.00000000"],["78688.01000000","0.00000000"],["78686.12000000","0.50392000"],["78682.12000000","0.34319000"],["78680.00000000","0.08496000"],["78679.93000000","0.00000000"],["78674.35000000","0.34322000"],["78672.72000000","0.63561000"],["78671.40000000","0.00400000"],["78669.39000000","0.00400000"],["78669.36000000","0.00007000"],["78668.66000000","0.00000000"],["78667.05000000","0.00000000"],["78666.86000000","0.00000000"],["78666.75000000","0.00000000"],["78666.62000000","0.00000000"],["78666.45000000","0.00000000"],["78666.40000000","0.00000000"],["78666.35000000","0.00000000"],["78666.12000000","0.00007000"],["78665.68000000","1.00307000"],["78661.04000000","0.00335000"],["78658.28000000","0.02000000"],["78655.12000000","0.02200000"],["78654.76000000","0.00007000"],["78654.68000000","0.02000000"],["78651.53000000","0.86811000"],["78650.10000000","0.00314000"],["78645.08000000","0.02200000"],["78641.93000000","0.02200000"],["78640.34000000","0.00000000"],["78638.76000000","0.00000000"],["78637.93000000","0.00000000"],["78637.18000000","0.00000000"],["78637.01000000","0.02000000"],["78636.95000000","0.00000000"],["78634.61000000","0.02000000"],["78622.46000000","0.00000000"],["78605.38000000","2.77171000"],["78589.95000000","0.00000000"],["78585.60000000","0.00000000"],["78584.12000000","0.04474000"],["78534.01000000","0.00000000"],["78533.83000000","0.00778000"],["78519.12000000","0.00000000"],["78504.12000000","0.00007000"],["78500.19000000","0.00008000"],["78333.33000000","0.55748000"],["78326.40000000","0.01000000"],["78017.69000000","0.00000000"],["77934.76000000","0.01000000"],["77666.66000000","0.02496000"],["77545.09000000","0.01000000"],["77157.36000000","0.01000000"],["76771.58000000","0.01000000"],["76387.72000000","0.01000000"],["76005.78000000","0.05000000"],["75625.75000000","0.01000000"],["75247.62000000","0.01000000"],["74871.38000000","0.01000000"],["74497.03000000","0.01000000"],["74124.54000000","0.01000000"],["73753.92000000","0.01000000"],["73385.15000000","0.01000000"],["73018.22000000","0.01000000"],["70853.61000000","0.00000000"],["70850.00000000","0.06298000"],["70848.00000000","0.00176000"],["62976.00000000","0.00031000"]],"a":[["78720.01000000","4.41314000"],["78721.27000000","0.03457000"],["78721.96000000","0.20026000"],["78721.99000000","0.31781000"],["78722.00000000","0.07521000"],["78722.01000000","0.05313000"],["78722.02000000","0.00000000"],["78722.52000000","0.25413000"],["78722.53000000","0.04147000"],["78722.58000000","0.00000000"],["78722.59000000","0.17756000"],["78722.69000000","0.05214000"],["78723.18000000","0.02161000"],["78724.00000000","0.00500000"],["78724.57000000","0.00007000"],["78724.69000000","0.00000000"],["78725.07000000","0.00455000"],["78725.08000000","0.36224000"],["78725.10000000","0.07500000"],["78725.26000000","0.19417000"],["78725.27000000","0.00000000"],["78725.53000000","0.00000000"],["78726.00000000","0.01200000"],["78726.24000000","0.22703000"],["78727.74000000","0.00000000"],["78728.52000000","0.00000000"],["78729.43000000","0.02000000"],["78729.52000000","0.02000000"],["78729.68000000","0.00000000"],["78730.15000000","0.02000000"],["78730.22000000","0.02000000"],["78730.26000000","0.02000000"],["78730.31000000","0.02000000"],["78730.58000000","0.00000000"],["78730.62000000","0.00000000"],["78732.57000000","0.02000000"],["78733.38000000","0.02000000"],["78733.76000000","0.02600000"],["78734.16000000","0.05000000"],["78734.21000000","0.02000000"],["78734.22000000","0.02000000"],["78734.73000000","0.04443000"],["78737.11000000","0.00000000"],["78742.13000000","0.02000000"],["78742.37000000","0.00000000"],["78742.56000000","0.00000000"],["78742.57000000","0.00000000"],["78743.17000000","0.00000000"],["78743.21000000","0.00000000"],["78743.58000000","0.00007000"],["78749.81000000","0.00000000"],["78751.61000000","0.00000000"],["78758.42000000","0.00000000"],["78760.00000000","0.12923000"],["78762.00000000","0.02407000"],["78771.52000000","0.86679000"],["78779.90000000","0.00320000"],["78781.95000000","0.00000000"],["78789.35000000","0.00000000"],["78794.89000000","0.09197000"],["78795.59000000","0.00000000"],["78796.37000000","0.00000000"],["78797.35000000","0.00000000"],["78811.17000000","0.00000000"],["78813.44000000","0.00000000"],["78817.61000000","0.00025000"],["78819.95000000","0.21930000"],["78823.85000000","0.00000000"],["78824.58000000","0.00012000"],["78828.58000000","0.00000000"],["78830.72000000","0.00019000"],["78834.72000000","0.00000000"],["78836.82000000","0.00031000"],["78840.82000000","0.00000000"],["78854.63000000","0.00000000"],["78860.69000000","0.00000000"],["78885.45000000","0.01990000"],["78896.58000000","3.80288000"],["78928.12000000","0.01990000"],["78931.56000000","0.00000000"],["78942.20000000","0.00000000"],["79031.67000000","0.00000000"],["79113.62000000","0.01000000"],["79119.88000000","0.00000000"],["79509.18000000","0.01000000"],["79515.48000000","0.00000000"],["79666.66000000","0.52818000"],["79906.73000000","0.01000000"],["79913.05000000","0.00000000"],["80306.26000000","0.01000000"],["80312.62000000","0.00000000"],["80333.33000000","0.52389000"],["80707.79000000","0.01000000"],["80714.18000000","0.00000000"],["81111.33000000","0.01000000"],["81117.75000000","0.00000000"],["81516.89000000","0.01000000"],["81523.34000000","0.00000000"],["81924.47000000","0.01000000"],["81930.96000000","0.00000000"],["82334.10000000","0.01000000"],["82340.61000000","0.00000000"],["82745.77000000","0.01000000"],["82752.32000000","0.00000000"],["83159.50000000","0.01000000"],["83166.08000000","0.00000000"],["83575.29000000","0.01000000"],["83581.91000000","0.00000000"],["83993.17000000","0.01000000"],["83999.82000000","0.00000000"],["84413.14000000","0.01000000"],["84419.82000000","0.00000000"],["84835.20000000","0.01000000"],["84841.91000000","0.00000000"]]}}}
{"rx_ns": 56956095200, "frame": {"stream":"btcusdt@depth20","data":{"lastUpdateId":99076523708,"bids":[["78718.00000000","0.03102000"],["78717.99000000","0.01669000"],["78717.52000000","0.00007000"],["78717.45000000","0.00200000"],["78717.44000000","0.00007000"],["78716.74000000","0.00007000"],["78716.39000000","0.00007000"],["78716.34000000","0.00007000"],["78716.33000000","0.01747000"],["78716.17000000","0.00007000"],["78716.01000000","0.00025000"],["78716.00000000","0.02515000"],["78715.80000000","0.00007000"],["78715.52000000","0.00014000"],["78715.51000000","0.04963000"],["78715.17000000","0.00007000"],["78715.08000000","0.02908000"],["78714.35000000","0.00007000"],["78714.01000000","0.00007000"],["78714.00000000","0.02407000"]],"asks":[["78718.01000000","3.57180000"],["78718.02000000","0.00020000"],["78718.03000000","0.00013000"],["78718.32000000","0.31781000"],["78718.33000000","0.31783000"],["78718.34000000","0.28284000"],["78719.26000000","0.00014000"],["78719.27000000","0.03457000"],["78719.67000000","0.00014000"],["78719.99000000","0.00014000"],["78720.00000000","0.09682000"],["78720.01000000","0.19314000"],["78720.53000000","0.04147000"],["78721.02000000","0.05215000"],["78721.65000000","0.00400000"],["78721.79000000","0.04147000"],["78721.96000000","0.00007000"],["78721.99000000","0.00007000"],["78722.00000000","0.07507000"],["78722.01000000","0.05306000"]]}}}
{"rx_ns": 56956206800, "frame": {"stream":"btcusdt@depth","data":{"e":"depthUpdate","E":1787602924015,"s":"BTCUSDT","U":99076523012,"u":99076523708,"b":[["78720.00000000","0.00000000"],["78719.99000000","0.00000000"],["78719.88000000","0.00000000"],["78719.67000000","0.00000000"],["78719.66000000","0.00000000"],["78719.57000000","0.00000000"],["78719.26000000","0.00000000"],["78719.10000000","0.00000000"],["78718.44000000","0.00000000"],["78718.34000000","0.00000000"],["78718.33000000","0.00000000"],["78718.32000000","0.00000000"],["78718.31000000","0.00000000"],["78718.01000000","0.00000000"],["78718.00000000","0.03102000"],["78717.99000000","0.01669000"],["78717.52000000","0.00007000"],["78717.19000000","0.00000000"],["78717.18000000","0.00000000"],["78717.09000000","0.00000000"],["78717.08000000","0.00000000"],["78716.74000000","0.00007000"],["78716.34000000","0.00007000"],["78716.33000000","0.01747000"],["78716.01000000","0.00025000"],["78716.00000000","0.02515000"],["78715.83000000","0.00000000"],["78715.82000000","0.00000000"],["78715.52000000","0.00014000"],["78715.51000000","0.04963000"],["78715.17000000","0.00007000"],["78715.08000000","0.02908000"],["78715.00000000","0.00000000"],["78714.56000000","0.00000000"],["78714.01000000","0.00007000"],["78714.00000000","0.02407000"],["78713.90000000","0.00000000"],["78713.82000000","0.03488000"],["78713.77000000","0.00000000"],["78713.62000000","0.02516000"],["78712.93000000","0.04294000"],["78712.56000000","0.03481000"],["78712.22000000","0.12718000"],["78712.05000000","0.00000000"],["78712.02000000","0.00000000"],["78712.00000000","0.02400000"],["78711.78000000","0.00000000"],["78711.25000000","0.00000000"],["78710.45000000","0.21930000"],["78710.12000000","0.21044000"],["78709.51000000","0.00000000"],["78709.25000000","0.00000000"],["78709.18000000","0.00000000"],["78709.10000000","0.00000000"],["78708.98000000","0.00000000"],["78708.37000000","0.00000000"],["78706.82000000","0.08576000"],["78706.24000000","0.00000000"],["78706.23000000","0.00332000"],["78702.90000000","0.00000000"],["78702.75000000","0.00000000"],["78701.47000000","0.00027000"],["78701.44000000","0.00000000"],["78701.42000000","0.00000000"],["78701.40000000","0.00000000"],["78701.39000000","0.00000000"],["78701.38000000","0.00000000"],["78701.37000000","0.00000000"],["78701.36000000","0.00000000"],["78701.33000000","0.00000000"],["78698.01000000","0.00400000"],["78696.34000000","0.00000000"],["78694.34000000","0.00007000"],["78688.73000000","0.00000000"],["78688.01000000","0.63534000"],["78680.00000000","0.07496000"],["78679.60000000","0.00000000"],["78679.27000000","0.09369000"],["78678.00000000","0.03400000"],["78666.06000000","0.00000000"],["78665.78000000","0.02841000"],["78657.06000000","0.00007000"],["78649.00000000","0.00000000"],["78646.01000000","0.00313000"],["78645.08000000","0.00000000"],["78641.93000000","0.00000000"],["78638.01000000","0.00000000"],["78637.01000000","0.00000000"],["78634.61000000","0.00000000"],["78634.60000000","0.00316000"],["78632.25000000","0.00406000"],["78628.01000000","0.00000000"],["78626.01000000","0.00243000"],["78622.46000000","0.00000000"],["78592.50000000","0.00000000"],["78584.12000000","0.09531000"],["78570.41000000","0.00000000"],["78568.76000000","0.00127000"],["78560.01000000","0.00000000"],["78556.15000000","0.00127000"],["78533.83000000","0.00000000"],["78510.52000000","0.00778000"],["78326.40000000","0.00000000"],["78324.41000000","0.01000000"],["78232.00000000","0.00015000"],["78011.52000000","0.00010000"],["77934.76000000","0.00000000"],["77932.78000000","0.01000000"],["77545.09000000","0.00000000"],["77543.12000000","0.01000000"],["77157.36000000","0.00000000"],["77155.40000000","0.01000000"],["77000.00000000","69.22872000"],["76771.58000000","0.00000000"],["76769.63000000","0.01000000"],["76387.72000000","0.00000000"],["76385.78000000","0.01000000"],["76333.33000000","0.03138000"],["76005.78000000","0.04000000"],["76003.85000000","0.01000000"],["75666.66000000","0.03291000"],["75625.75000000","0.00000000"],["75623.83000000","0.01000000"],["75247.62000000","0.00000000"],["75245.71000000","0.01000000"],["75000.00000000","111.15012000"],["74871.38000000","0.00000000"],["74869.48000000","0.01000000"],["74497.03000000","0.00000000"],["74495.13000000","0.01000000"],["74124.54000000","0.00000000"],["74122.66000000","0.01000000"],["73753.92000000","0.00000000"],["73752.05000000","0.01000000"],["73385.15000000","0.00000000"],["73383.29000000","0.01000000"],["73018.22000000","0.00000000"],["73016.37000000","0.01000000"],["70853.59000000","0.00000000"],["70848.00000000","0.00000000"],["70846.50000000","0.00000000"],["70846.20000000","0.00096000"],["65000.00000000","77.51112000"],["62981.00000000","0.00031000"],["62976.00000000","0.00000000"],["62974.40000000","0.00031000"]],"a":[["78718.01000000","3.57180000"],["78718.02000000","0.00020000"],["78718.03000000","0.00013000"],["78718.32000000","0.31781000"],["78718.33000000","0.31783000"],["78718.34000000","0.28284000"],["78718.35000000","0.00000000"],["78718.36000000","0.00000000"],["78719.26000000","0.00014000"],["78719.27000000","0.03457000"],["78719.58000000","0.00000000"],["78719.67000000","0.00014000"],["78719.68000000","0.00000000"],["78719.89000000","0.00000000"],["78719.99000000","0.00014000"],["78720.00000000","0.09682000"],["78720.01000000","0.19314000"],["78720.02000000","0.00000000"],["78720.03000000","0.00000000"],["78720.53000000","0.04147000"],["78721.01000000","0.00000000"],["78721.02000000","0.05215000"],["78721.26000000","0.00000000"],["78721.27000000","0.00000000"],["78721.79000000","0.04147000"],["78721.95000000","0.00000000"],["78721.96000000","0.00007000"],["78721.98000000","0.00000000"],["78721.99000000","0.00007000"],["78722.00000000","0.07507000"],["78722.01000000","0.05306000"],["78722.15000000","0.01100000"],["78722.16000000","0.04032000"],["78722.51000000","0.00000000"],["78722.52000000","0.25413000"],["78722.53000000","0.00000000"],["78722.59000000","0.17749000"],["78722.69000000","0.00014000"],["78723.79000000","0.00000000"],["78723.85000000","0.00007000"],["78724.00000000","0.26000000"],["78724.81000000","0.00000000"],["78725.07000000","0.00455000"],["78725.10000000","0.00000000"],["78725.26000000","0.19410000"],["78725.54000000","0.00000000"],["78726.00000000","0.01700000"],["78726.22000000","0.21930000"],["78726.23000000","0.00000000"],["78726.24000000","0.22682000"],["78726.50000000","0.00000000"],["78726.73000000","0.00000000"],["78727.24000000","0.38110000"],["78727.83000000","0.00007000"],["78729.82000000","0.00000000"],["78731.30000000","0.00000000"],["78732.97000000","0.04103000"],["78733.40000000","0.02000000"],["78734.09000000","0.45624000"],["78734.53000000","0.00000000"],["78735.39000000","0.13862000"],["78735.45000000","0.00000000"],["78735.76000000","0.00000000"],["78737.63000000","0.00406000"],["78741.58000000","0.00007000"],["78742.13000000","0.00000000"],["78743.00000000","0.00000000"],["78743.58000000","0.00000000"],["78749.20000000","0.02000000"],["78749.43000000","0.00663000"],["78753.32000000","0.00663000"],["78755.38000000","0.10000000"],["78757.33000000","0.00007000"],["78758.00000000","0.03400000"],["78758.37000000","0.36224000"],["78760.00000000","0.11923000"],["78763.76000000","0.00000000"],["78777.00000000","0.00406000"],["78779.89000000","0.00190000"],["78781.76000000","0.00000000"],["78783.95000000","0.00000000"],["78795.75000000","0.00000000"],["78796.44000000","0.00000000"],["78797.39000000","0.00000000"],["78819.95000000","0.00000000"],["78849.95000000","0.00000000"],["78855.74000000","0.00406000"],["78860.25000000","0.00000000"],["78885.45000000","0.00000000"],["78889.37000000","0.00000000"],["78898.57000000","0.01990000"],["78926.61000000","0.00406000"],["78935.31000000","0.00000000"],["79111.61000000","0.01008000"],["79113.62000000","0.00000000"],["79507.16000000","0.01000000"],["79509.18000000","0.00000000"],["79904.70000000","0.01000000"],["79906.73000000","0.00000000"],["80304.22000000","0.01000000"],["80306.26000000","0.00000000"],["80705.74000000","0.01000000"],["80707.79000000","0.00000000"],["81109.27000000","0.01000000"],["81111.33000000","0.00000000"],["81514.82000000","0.01000000"],["81516.89000000","0.00000000"],["81922.39000000","0.01000000"],["81924.47000000","0.00000000"],["82332.00000000","0.01020000"],["82334.10000000","0.00000000"],["82743.66000000","0.01000000"],["82745.77000000","0.00000000"],["83157.38000000","0.01000000"],["83159.50000000","0.00000000"],["83573.17000000","0.01000000"],["83575.29000000","0.00000000"],["83991.04000000","0.01000000"],["83993.17000000","0.00000000"],["84410.99000000","0.01000000"],["84413.14000000","0.00000000"],["84833.05000000","0.01000000"],["84835.20000000","0.00000000"]]}}}
{"rx_ns": 57962189000, "frame": {"stream":"btcusdt@depth20","data":{"lastUpdateId":99076523970,"bids":[["78718.00000000","0.03129000"],["78717.99000000","0.01682000"],["78717.98000000","0.00013000"],["78717.45000000","0.00200000"],["78717.44000000","0.00007000"],["78716.74000000","0.00007000"],["78716.39000000","0.00007000"],["78716.34000000","0.00007000"],["78716.33000000","0.01747000"],["78716.17000000","0.00007000"],["78716.01000000","0.00025000"],["78716.00000000","0.02515000"],["78715.80000000","0.00007000"],["78715.52000000","0.00014000"],["78715.51000000","0.04963000"],["78715.17000000","0.00007000"],["78715.08000000","0.02908000"],["78714.35000000","0.00007000"],["78714.01000000","0.00007000"],["78714.00000000","0.02407000"]],"asks":[["78718.01000000","3.26765000"],["78718.02000000","0.00020000"],["78718.03000000","0.00013000"],["78718.24000000","0.00014000"],["78718.25000000","0.25413000"],["78718.31000000","0.00014000"],["78718.32000000","0.31788000"],["78718.33000000","0.31783000"],["78718.34000000","0.28291000"],["78718.56000000","0.01277000"],["78718.59000000","0.00014000"],["78718.60000000","0.06364000"],["78719.05000000","0.38110000"],["78719.27000000","0.03457000"],["78719.67000000","0.00014000"],["78719.87000000","0.00007000"],["78720.00000000","0.02161000"],["78720.01000000","0.19307000"],["78720.53000000","0.04140000"],["78721.02000000","0.05208000"]]}}}
{"rx_ns": 57962307500, "frame": {"stream":"btcusdt@depth","data":{"e":"depthUpdate","E":1787602925014,"s":"BTCUSDT","U":99076523709,"u":99076523970,"b":[["78718.00000000","0.03129000"],["78717.99000000","0.01682000"],["78717.98000000","0.00013000"],["78717.52000000","0.00000000"],["78713.82000000","0.03481000"],["78713.79000000","0.00000000"],["78713.62000000","0.00000000"],["78713.23000000","0.02516000"],["78712.93000000","0.00000000"],["78712.22000000","0.12711000"],["78710.59000000","0.20847000"],["78710.53000000","0.00204000"],["78710.45000000","0.00000000"],["78710.12000000","0.21930000"],["78708.64000000","0.00000000"],["78708.47000000","0.00000000"],["78708.06000000","0.00007000"],["78707.05000000","0.00000000"],["78707.04000000","1.90515000"],["78707.01000000","0.00007000"],["78706.23000000","0.00000000"],["78706.18000000","0.00320000"],["78703.09000000","0.00000000"],["78702.85000000","0.00000000"],["78701.97000000","0.00000000"],["78701.57000000","0.02000000"],["78701.30000000","0.00000000"],["78701.26000000","0.00000000"],["78700.07000000","0.04000000"],["78698.01000000","0.00000000"],["78694.34000000","0.00007000"],["78691.20000000","0.00400000"],["78669.39000000","0.00000000"],["78669.36000000","0.00007000"],["78666.12000000","0.00007000"],["78663.73000000","0.00406000"],["78661.15000000","0.00007000"],["78650.10000000","0.00000000"],["78622.46000000","0.00000000"],["78585.03000000","0.00000000"],["78577.42000000","0.01990000"],["78574.09000000","0.00000000"],["78558.14000000","0.00000000"],["78514.20000000","0.00406000"],["78324.41000000","0.01000000"],["77932.78000000","0.01000000"],["77543.12000000","0.01000000"],["77155.40000000","0.01000000"],["76769.63000000","0.01000000"],["76385.78000000","0.01000000"],["76003.85000000","0.01000000"],["75623.83000000","0.01000000"],["75245.71000000","0.01000000"],["74869.48000000","0.01000000"],["74495.13000000","0.01000000"],["74333.33000000","0.04622000"],["74122.66000000","0.01000000"],["73752.05000000","0.01000000"],["73666.66000000","0.06123000"],["73383.29000000","0.01000000"],["73016.37000000","0.01000000"],["73000.00000000","62.00065000"],["72333.33000000","0.01211000"],["70846.20000000","0.00208000"],["70846.00000000","0.00000000"],["62976.00000000","0.00000000"],["62974.40000000","0.00031000"]],"a":[["78718.01000000","3.26765000"],["78718.24000000","0.00014000"],["78718.25000000","0.25413000"],["78718.31000000","0.00014000"],["78718.32000000","0.31788000"],["78718.34000000","0.28291000"],["78718.56000000","0.01277000"],["78718.59000000","0.00014000"],["78718.60000000","0.06364000"],["78719.05000000","0.38110000"],["78719.26000000","0.00000000"],["78719.87000000","0.00007000"],["78719.99000000","0.00000000"],["78720.00000000","0.02161000"],["78720.01000000","0.19307000"],["78720.53000000","0.04140000"],["78721.02000000","0.05208000"],["78721.79000000","0.04140000"],["78722.52000000","0.00007000"],["78724.00000000","0.26700000"],["78725.07000000","0.00455000"],["78725.26000000","0.19403000"],["78725.55000000","0.00000000"],["78726.00000000","0.02400000"],["78727.39000000","0.00000000"],["78729.51000000","0.00000000"],["78734.64000000","0.00000000"],["78741.58000000","0.00007000"],["78745.34000000","0.00000000"],["78753.16000000","0.02000000"],["78772.89000000","0.00317000"],["78777.64000000","0.00000000"],["78779.90000000","0.00000000"],["78794.62000000","0.00000000"],["78798.50000000","0.93647000"],["78802.21000000","0.00000000"],["78808.50000000","0.00406000"],["78810.29000000","0.00529000"],["78815.61000000","0.00025000"],["78816.77000000","0.00000000"],["78817.61000000","0.00000000"],["78820.49000000","0.00000000"],["78843.95000000","0.00160000"],["78857.22000000","0.00000000"],["78883.37000000","0.00160000"],["79111.61000000","0.01008000"],["79507.16000000","0.01000000"],["79904.70000000","0.01000000"],["80304.22000000","0.01000000"],["80705.74000000","0.01000000"],["81109.27000000","0.01000000"],["81514.82000000","0.01000000"],["81922.39000000","0.01000000"],["82332.00000000","0.01020000"],["82743.66000000","0.01000000"],["83157.38000000","0.01000000"],["83573.17000000","0.01000000"],["83991.04000000","0.01000000"],["84410.99000000","0.01000000"],["84833.05000000","0.01000000"]]}}}
{"rx_ns": 58955988300, "frame": {"stream":"btcusdt@depth20","data":{"lastUpdateId":99076524316,"bids":[["78718.00000000","0.80365000"],["78717.99000000","0.01696000"],["78717.98000000","0.00013000"],["78717.45000000","0.00200000"],["78717.44000000","0.00007000"],["78716.74000000","0.00007000"],["78716.39000000","0.00007000"],["78716.34000000","0.00014000"],["78716.33000000","0.01747000"],["78716.01000000","0.00025000"],["78716.00000000","0.02515000"],["78715.95000000","0.00007000"],["78715.80000000","0.00007000"],["78715.52000000","0.00014000"],["78715.51000000","0.04963000"],["78715.26000000","0.00007000"],["78715.08000000","0.02908000"],["78714.35000000","0.00007000"],["78714.00000000","0.02407000"],["78713.82000000","0.03481000"]],"asks":[["78718.01000000","2.91334000"],["78718.02000000","0.00062000"],["78718.03000000","0.00013000"],["78718.23000000","0.00508000"],["78718.24000000","0.00014000"],["78718.25000000","0.25413000"],["78718.32000000","0.00014000"],["78718.33000000","0.31783000"],["78718.34000000","0.25530000"],["78718.60000000","0.00007000"],["78719.04000000","0.00021000"],["78719.05000000","0.38117000"],["78719.27000000","0.03457000"],["78719.67000000","0.00014000"],["78719.87000000","0.00007000"],["78720.00000000","0.00007000"],["78720.01000000","0.19311000"],["78720.51000000","0.31766000"],["78720.52000000","0.00642000"],["78720.53000000","0.04140000"]]}}}
{"rx_ns": 58956096600, "frame": {"stream":"btcusdt@depth","data":{"e":"depthUpdate","E":1787602926014,"s":"BTCUSDT","U":99076523971,"u":99076524316,"b":[["78718.00000000","0.80365000"],["78717.99000000","0.01696000"],["78716.34000000","0.00014000"],["78716.17000000","0.00000000"],["78715.95000000","0.00007000"],["78715.51000000","0.04963000"],["78715.28000000","0.00000000"],["78715.26000000","0.00007000"],["78715.17000000","0.00000000"],["78715.09000000","0.00000000"],["78715.08000000","0.02908000"],["78714.32000000","0.00000000"],["78714.01000000","0.00000000"],["78713.82000000","0.03481000"],["78713.46000000","0.00000000"],["78712.59000000","0.00000000"],["78711.93000000","0.00007000"],["78711.13000000","0.00323000"],["78710.59000000","0.00007000"],["78710.53000000","0.00000000"],["78709.56000000","0.00324000"],["78708.94000000","0.00070000"],["78708.12000000","0.36224000"],["78708.06000000","0.00014000"],["78706.32000000","0.00000000"],["78701.85000000","0.00406000"],["78701.82000000","0.00000000"],["78694.34000000","0.00007000"],["78690.55000000","0.63532000"],["78688.01000000","0.00000000"],["78680.16000000","0.00400000"],["78679.17000000","0.02480000"],["78673.68000000","0.00400000"],["78673.41000000","0.00000000"],["78673.23000000","0.00007000"],["78671.52000000","0.00000000"],["78671.40000000","0.00000000"],["78669.36000000","0.00000000"],["78666.12000000","0.00014000"],["78622.46000000","0.00000000"],["78583.79000000","0.00406000"],["78583.76000000","0.00000000"],["78499.89000000","0.00007000"],["78495.96000000","0.00000000"],["78324.41000000","0.01000000"],["78317.01000000","0.00000000"],["78011.52000000","0.00000000"],["77932.78000000","0.01000000"],["77543.12000000","0.01000000"],["77155.40000000","0.01000000"],["76769.63000000","0.01000000"],["76385.78000000","0.01000000"],["76003.85000000","0.01000000"],["75623.83000000","0.01000000"],["75245.71000000","0.01000000"],["74869.48000000","0.01000000"],["74495.13000000","0.01000000"],["74122.66000000","0.01000000"],["73752.05000000","0.01000000"],["73383.29000000","0.01000000"],["73016.37000000","0.01000000"],["71666.66000000","0.16741000"],["71000.00000000","36.60925000"],["70846.20000000","0.00288000"],["70846.00000000","0.00000000"],["70333.33000000","0.01539000"],["69666.66000000","0.11616000"],["62974.40000000","0.00031000"],["62974.00000000","0.00000000"]],"a":[["78718.01000000","2.91334000"],["78718.02000000","0.00062000"],["78718.23000000","0.00508000"],["78718.25000000","0.25413000"],["78718.31000000","0.00000000"],["78718.32000000","0.00014000"],["78718.34000000","0.25530000"],["78718.56000000","0.00000000"],["78718.59000000","0.00000000"],["78718.60000000","0.00007000"],["78719.03000000","0.00000000"],["78719.04000000","0.00021000"],["78719.05000000","0.38117000"],["78719.27000000","0.03457000"],["78720.00000000","0.00007000"],["78720.01000000","0.19311000"],["78720.51000000","0.31766000"],["78720.52000000","0.00642000"],["78721.01000000","0.00000000"],["78722.00000000","0.00516000"],["78722.01000000","0.02306000"],["78722.59000000","0.14749000"],["78722.69000000","0.00007000"],["78723.17000000","0.00000000"],["78724.00000000","0.27400000"],["78724.56000000","0.00635000"],["78725.06000000","0.00635000"],["78725.07000000","0.00000000"],["78725.08000000","0.00000000"],["78725.09000000","0.00000000"],["78725.10000000","1.21952000"],["78726.50000000","0.00020000"],["78729.66000000","1.90515000"],["78729.68000000","0.00455000"],["78733.85000000","0.00000000"],["78734.73000000","0.00000000"],["78737.78000000","0.04468000"],["78739.73000000","0.00000000"],["78741.58000000","0.00007000"],["78742.51000000","0.43583000"],["78781.64000000","0.00000000"],["78798.50000000","0.00000000"],["78801.10000000","0.00000000"],["78801.11000000","0.93647000"],["79111.61000000","0.01008000"],["79507.16000000","0.01000000"],["79904.70000000","0.01000000"],["80304.22000000","0.01000000"],["80705.74000000","0.01000000"],["81109.27000000","0.01000000"],["81514.82000000","0.01000000"],["81922.39000000","0.01000000"],["82332.00000000","0.01020000"],["82743.66000000","0.01000000"],["83157.38000000","0.01000000"],["83573.17000000","0.01000000"],["83991.04000000","0.01000000"],["84410.99000000","0.01000000"],["84833.05000000","0.01000000"]]}}}
{"rx_ns": 59952678900, "frame": {"stream":"btcusdt@depth20","data":{"lastUpdateId":99076524570,"bids":[["78718.00000000","0.29302000"],["78717.99000000","0.01682000"],["78717.98000000","0.00013000"],["78717.45000000","0.00200000"],["78717.44000000","0.00007000"],["78716.74000000","0.00007000"],["78716.39000000","0.00007000"],["78716.34000000","0.00014000"],["78716.33000000","0.01747000"],["78716.01000000","0.00025000"],["78716.00000000","0.02515000"],["78715.95000000","0.00007000"],["78715.80000000","0.00007000"],["78715.52000000","0.00014000"],["78715.51000000","0.04963000"],["78715.08000000","0.02908000"],["78714.35000000","0.00007000"],["78714.02000000","0.04424000"],["78714.00000000","0.02407000"],["78713.82000000","0.03488000"]],"asks":[["78718.01000000","3.01625000"],["78718.02000000","0.00020000"],["78718.03000000","0.00013000"],["78718.04000000","0.00014000"],["78718.05000000","0.06357000"],["78718.24000000","0.00014000"],["78718.25000000","0.25413000"],["78718.32000000","0.00014000"],["78718.33000000","0.31783000"],["78718.34000000","0.25523000"],["78718.60000000","0.00007000"],["78719.04000000","0.31780000"],["78719.05000000","0.38117000"],["78719.27000000","0.03457000"],["78719.67000000","0.00014000"],["78719.87000000","0.00007000"],["78720.01000000","0.19311000"],["78720.51000000","0.00007000"],["78720.53000000","0.04140000"],["78721.02000000","0.05208000"]]}}}
{"rx_ns": 59952783300, "frame": {"stream":"btcusdt@depth","data":{"e":"depthUpdate","E":1787602927014,"s":"BTCUSDT","U":99076524317,"u":99076524570,"b":[["78718.00000000","0.29302000"],["78717.99000000","0.01682000"],["78716.00000000","0.02515000"],["78715.85000000","0.00000000"],["78715.51000000","0.04963000"],["78715.26000000","0.00000000"],["78714.02000000","0.04424000"],["78713.82000000","0.03488000"],["78712.40000000","0.00000000"],["78712.22000000","0.12718000"],["78711.60000000","0.20840000"],["78711.13000000","0.00000000"],["78709.56000000","0.00000000"],["78708.12000000","0.00000000"],["78708.06000000","0.00007000"],["78707.12000000","0.00000000"],["78707.08000000","0.00000000"],["78706.89000000","0.00000000"],["78701.57000000","0.00000000"],["78700.17000000","0.04200000"],["78694.34000000","0.00007000"],["78690.55000000","0.00000000"],["78690.01000000","0.00000000"],["78688.73000000","0.63532000"],["78679.27000000","0.00000000"],["78677.63000000","0.09667000"],["78669.36000000","0.00007000"],["78666.12000000","0.00007000"],["78665.78000000","0.00000000"],["78665.70000000","0.02915000"],["78622.46000000","0.00000000"],["78607.99000000","2.77178000"],["78605.38000000","0.00000000"],["78584.12000000","0.00000000"],["78583.79000000","0.00000000"],["78583.66000000","0.00406000"],["78583.27000000","0.09912000"],["78526.12000000","0.00778000"],["78510.52000000","0.00000000"],["78324.41000000","0.01000000"],["78317.01000000","0.00007000"],["78009.54000000","0.00010000"],["77932.78000000","0.01000000"],["77543.12000000","0.01000000"],["77155.40000000","0.01000000"],["76769.63000000","0.01000000"],["76385.78000000","0.01000000"],["76003.85000000","0.01000000"],["75623.83000000","0.01000000"],["75245.71000000","0.01000000"],["74869.48000000","0.01000000"],["74495.13000000","0.01000000"],["74122.66000000","0.01000000"],["73752.05000000","0.01000000"],["73383.29000000","0.01000000"],["73016.37000000","0.01000000"],["72426.09000000","0.00000000"],["70846.20000000","0.00368000"],["70846.00000000","0.00000000"],["69000.00000000","44.67842000"],["68333.33000000","0.02275000"],["67666.66000000","0.02575000"],["67000.00000000","41.86886000"],["62974.40000000","0.00031000"],["62974.00000000","0.00000000"]],"a":[["78718.01000000","3.01625000"],["78718.02000000","0.00020000"],["78718.04000000","0.00014000"],["78718.05000000","0.06357000"],["78718.23000000","0.00000000"],["78718.34000000","0.25523000"],["78719.04000000","0.31780000"],["78720.00000000","0.00000000"],["78720.01000000","0.19311000"],["78720.51000000","0.00007000"],["78720.52000000","0.00000000"],["78722.68000000","0.00635000"],["78723.99000000","1.90515000"],["78724.56000000","0.00000000"],["78725.06000000","0.00000000"],["78725.09000000","0.36224000"],["78741.42000000","0.00000000"],["78741.58000000","0.00007000"],["78750.69000000","0.09344000"],["78791.62000000","0.00000000"],["79089.35000000","0.00000000"],["79111.61000000","0.01008000"],["79507.16000000","0.01000000"],["79904.70000000","0.01000000"],["80304.22000000","0.01000000"],["80705.74000000","0.01000000"],["81109.27000000","0.01000000"],["81514.82000000","0.01000000"],["81922.39000000","0.01000000"],["82332.00000000","0.01020000"],["82743.66000000","0.01000000"],["83157.38000000","0.01000000"],["83573.17000000","0.01000000"],["83991.04000000","0.01000000"],["84410.99000000","0.01000000"],["84833.05000000","0.01000000"]]}}}
{"rx_ns": 60950741900, "kind": "control", "ctl": {"op": "ping", "recv_ns": 60396799600, "pong_ns": 60396914100, "payload_len": 13, "payload_b64": "MTc4NzYwMjkyNzQ2MQ=="}, "frame": null}
{"rx_ns": 60950741900, "frame": {"stream":"btcusdt@depth20","data":{"lastUpdateId":99076524797,"bids":[["78718.00000000","0.80108000"],["78717.99000000","0.01689000"],["78717.98000000","0.00013000"],["78717.44000000","0.00007000"],["78716.86000000","0.03852000"],["78716.39000000","0.00007000"],["78716.34000000","0.00014000"],["78716.33000000","0.01747000"],["78716.01000000","0.00025000"],["78716.00000000","0.02515000"],["78715.95000000","0.00007000"],["78715.80000000","0.00007000"],["78715.52000000","0.00014000"],["78715.51000000","0.04963000"],["78715.08000000","0.02901000"],["78714.35000000","0.00007000"],["78714.00000000","0.02407000"],["78713.82000000","0.03488000"],["78713.56000000","0.00007000"],["78713.23000000","0.02516000"]],"asks":[["78718.01000000","3.00390000"],["78718.02000000","0.00048000"],["78718.03000000","0.00013000"],["78718.04000000","0.00014000"],["78718.05000000","0.06357000"],["78718.24000000","0.00014000"],["78718.25000000","0.25413000"],["78718.32000000","0.00014000"],["78718.33000000","0.31783000"],["78718.34000000","0.25523000"],["78718.60000000","0.00007000"],["78719.04000000","0.00007000"],["78719.05000000","0.38124000"],["78719.27000000","0.03457000"],["78719.52000000","0.00400000"],["78719.67000000","0.00014000"],["78719.87000000","0.00007000"],["78720.00000000","0.00007000"],["78720.01000000","0.19304000"],["78720.51000000","0.31766000"]]}}}
{"rx_ns": 60951093200, "frame": {"stream":"btcusdt@depth","data":{"e":"depthUpdate","E":1787602928014,"s":"BTCUSDT","U":99076524571,"u":99076524797,"b":[["78718.00000000","0.80108000"],["78717.99000000","0.01689000"],["78717.45000000","0.00000000"],["78716.86000000","0.03852000"],["78716.74000000","0.00000000"],["78716.00000000","0.02515000"],["78715.90000000","0.00000000"],["78715.08000000","0.02901000"],["78714.85000000","0.00000000"],["78714.02000000","0.00000000"],["78711.12000000","0.00324000"],["78709.55000000","0.00318000"],["78708.06000000","0.00014000"],["78707.43000000","0.00000000"],["78707.40000000","0.00000000"],["78707.29000000","0.00000000"],["78707.28000000","0.00400000"],["78707.27000000","0.00000000"],["78707.20000000","0.00000000"],["78707.09000000","0.00000000"],["78707.04000000","1.90515000"],["78697.08000000","0.02000000"],["78694.34000000","0.00007000"],["78694.08000000","0.00000000"],["78693.70000000","0.00000000"],["78690.47000000","0.63532000"],["78688.73000000","0.00000000"],["78686.88000000","0.00400000"],["78675.42000000","0.00000000"],["78673.68000000","0.00000000"],["78669.36000000","0.00000000"],["78666.12000000","0.00014000"],["78634.60000000","0.02316000"],["78622.46000000","0.00000000"],["78607.99000000","0.00000000"],["78605.38000000","2.77178000"],["78526.12000000","0.00000000"],["78510.52000000","0.00778000"],["78324.41000000","0.01000000"],["77932.78000000","0.01000000"],["77543.12000000","0.01000000"],["77155.40000000","0.01000000"],["76769.63000000","0.01000000"],["76385.78000000","0.01000000"],["76003.85000000","0.01000000"],["75623.83000000","0.01000000"],["75245.71000000","0.01000000"],["74869.48000000","0.01000000"],["74495.13000000","0.01000000"],["74122.66000000","0.01000000"],["73752.05000000","0.01000000"],["73383.29000000","0.01000000"],["73016.37000000","0.01000000"],["70846.20000000","0.00432000"],["70846.00000000","0.00000000"],["66333.33000000","0.02998000"],["65666.66000000","0.02181000"],["65000.00000000","77.51218000"],["62974.40000000","0.00031000"],["62974.00000000","0.00000000"]],"a":[["78718.01000000","3.00390000"],["78718.02000000","0.00048000"],["78718.23000000","0.00000000"],["78718.34000000","0.25523000"],["78719.03000000","0.00000000"],["78719.04000000","0.00007000"],["78719.05000000","0.38124000"],["78719.27000000","0.03457000"],["78719.52000000","0.00400000"],["78720.00000000","0.00007000"],["78720.01000000","0.19304000"],["78720.51000000","0.31766000"],["78720.52000000","0.00635000"],["78721.64000000","0.00635000"],["78722.68000000","0.00000000"],["78723.53000000","0.00000000"],["78724.56000000","0.00635000"],["78741.58000000","0.00007000"],["78749.55000000","1.21972000"],["78750.75000000","0.01270000"],["78766.99000000","0.00000000"],["79111.61000000","0.01008000"],["79507.16000000","0.01000000"],["79904.70000000","0.01000000"],["80304.22000000","0.01000000"],["80705.74000000","0.01000000"],["81109.27000000","0.01000000"],["81514.82000000","0.01000000"],["81922.39000000","0.01000000"],["82332.00000000","0.01020000"],["82743.66000000","0.01000000"],["83157.38000000","0.01000000"],["83573.17000000","0.01000000"],["83991.04000000","0.01000000"],["84410.99000000","0.01000000"],["84833.05000000","0.01000000"]]}}}
{"rx_ns": 61950759200, "frame": {"stream":"btcusdt@depth20","data":{"lastUpdateId":99076525002,"bids":[["78718.00000000","0.80412000"],["78717.99000000","0.01689000"],["78717.98000000","0.00013000"],["78717.44000000","0.00007000"],["78716.39000000","0.00007000"],["78716.34000000","0.00014000"],["78716.33000000","0.01747000"],["78716.01000000","0.00025000"],["78716.00000000","0.02515000"],["78715.95000000","0.00007000"],["78715.80000000","0.00007000"],["78715.52000000","0.00014000"],["78715.51000000","0.04963000"],["78715.08000000","0.02908000"],["78714.35000000","0.00007000"],["78714.00000000","0.02407000"],["78713.82000000","0.03488000"],["78713.56000000","0.00007000"],["78713.23000000","0.02516000"],["78712.56000000","0.03481000"]],"asks":[["78718.01000000","3.00490000"],["78718.02000000","0.00048000"],["78718.03000000","0.00013000"],["78718.04000000","0.00014000"],["78718.05000000","0.06357000"],["78718.24000000","0.00014000"],["78718.25000000","0.25413000"],["78718.32000000","0.00014000"],["78718.33000000","0.31783000"],["78718.34000000","0.25523000"],["78718.60000000","0.00007000"],["78719.04000000","0.00007000"],["78719.05000000","0.38117000"],["78719.27000000","0.03457000"],["78719.52000000","0.00400000"],["78719.67000000","0.00014000"],["78719.87000000","0.00007000"],["78720.00000000","0.31766000"],["78720.01000000","0.19311000"],["78720.51000000","0.00007000"]]}}}
{"rx_ns": 61950856900, "frame": {"stream":"btcusdt@depth","data":{"e":"depthUpdate","E":1787602929014,"s":"BTCUSDT","U":99076524798,"u":99076525002,"b":[["78718.00000000","0.80412000"],["78717.99000000","0.01689000"],["78717.93000000","0.00000000"],["78716.86000000","0.00000000"],["78715.08000000","0.02908000"],["78711.19000000","0.00204000"],["78711.12000000","0.00000000"],["78711.10000000","0.00325000"],["78709.55000000","0.00000000"],["78709.53000000","0.00330000"],["78707.47000000","0.00000000"],["78707.35000000","0.00000000"],["78707.29000000","0.12713000"],["78707.24000000","0.00000000"],["78707.22000000","0.00000000"],["78707.04000000","1.90515000"],["78707.02000000","0.00000000"],["78706.97000000","0.00000000"],["78697.68000000","0.00000000"],["78697.50000000","0.02000000"],["78694.34000000","0.00007000"],["78690.47000000","0.00000000"],["78688.73000000","0.63532000"],["78669.36000000","0.00000000"],["78666.12000000","0.00014000"],["78634.99000000","0.00000000"],["78634.60000000","0.00316000"],["78622.46000000","0.00000000"],["78324.41000000","0.01000000"],["77932.78000000","0.01000000"],["77543.12000000","0.01000000"],["77155.40000000","0.01000000"],["76769.63000000","0.01000000"],["76385.78000000","0.01000000"],["76003.85000000","0.01000000"],["75623.83000000","0.01000000"],["75245.71000000","0.01000000"],["74869.48000000","0.01000000"],["74495.13000000","0.01000000"],["74122.66000000","0.01000000"],["73752.05000000","0.01000000"],["73383.29000000","0.01000000"],["73016.37000000","0.01000000"],["70846.20000000","0.00432000"],["70846.00000000","0.00000000"],["62974.40000000","0.00031000"],["62974.00000000","0.00000000"]],"a":[["78718.01000000","3.00490000"],["78718.02000000","0.00048000"],["78718.34000000","0.25523000"],["78718.59000000","0.00000000"],["78719.05000000","0.38117000"],["78719.27000000","0.03457000"],["78720.00000000","0.31766000"],["78720.01000000","0.19311000"],["78720.51000000","0.00007000"],["78732.31000000","0.02516000"],["78739.53000000","0.00000000"],["78741.58000000","0.00007000"],["78750.69000000","0.00000000"],["79111.61000000","0.01008000"],["79507.16000000","0.01000000"],["79904.70000000","0.01000000"],["80304.22000000","0.01000000"],["80705.74000000","0.01000000"],["81109.27000000","0.01000000"],["81514.82000000","0.01000000"],["81922.39000000","0.01000000"],["82332.00000000","0.01020000"],["82743.66000000","0.01000000"],["83157.38000000","0.01000000"],["83573.17000000","0.01000000"],["83991.04000000","0.01000000"],["84410.99000000","0.01000000"],["84833.05000000","0.01000000"]]}}}
