{"rx_ns": 173328841483900, "frame": {"stream":"btcusdt@depth20@100ms","data":{"lastUpdateId":99076740358,"bids":[["78649.99000000","3.89783000"],["78649.98000000","0.00020000"],["78649.97000000","0.00013000"],["78649.90000000","0.05000000"],["78649.65000000","0.00400000"],["78648.88000000","0.07500000"],["78648.87000000","2.66327000"],["78648.86000000","0.00007000"],["78648.61000000","0.07507000"],["78648.60000000","0.00007000"],["78648.00000000","0.39291000"],["78647.99000000","0.77743000"],["78647.98000000","1.21952000"],["78647.90000000","0.05000000"],["78647.80000000","0.00008000"],["78647.10000000","0.04821000"],["78646.14000000","0.00014000"],["78646.13000000","0.00007000"],["78646.01000000","0.31384000"],["78646.00000000","0.00007000"]],"asks":[["78650.00000000","0.02804000"],["78650.01000000","0.00063000"],["78650.14000000","0.00007000"],["78650.31000000","0.00007000"],["78650.61000000","0.00007000"],["78650.92000000","0.00007000"],["78651.40000000","0.00007000"],["78651.48000000","0.00007000"],["78651.49000000","0.00007000"],["78651.83000000","0.00007000"],["78651.99000000","0.00014000"],["78652.00000000","0.02407000"],["78652.60000000","0.00014000"],["78652.61000000","0.05352000"],["78652.66000000","0.00007000"],["78652.96000000","0.00007000"],["78652.97000000","0.00027000"],["78653.35000000","0.00007000"],["78653.59000000","0.00010000"],["78653.88000000","0.00007000"]]}}}
{"rx_ns": 173328841610300, "frame": {"stream":"btcusdt@depth@100ms","data":{"e":"depthUpdate","E":1787603268014,"s":"BTCUSDT","U":99076739593,"u":99076740358,"b":[["78649.99000000","3.89783000"],["78649.98000000","0.00020000"],["78649.97000000","0.00013000"],["78649.94000000","0.00000000"],["78649.90000000","0.05000000"],["78649.65000000","0.00400000"],["78649.36000000","0.00000000"],["78649.08000000","0.00000000"],["78648.88000000","0.07500000"],["78648.87000000","2.66327000"],["78648.86000000","0.00007000"],["78648.85000000","0.00000000"],["78648.61000000","0.07507000"],["78648.60000000","0.00007000"],["78648.59000000","0.00000000"],["78648.30000000","0.00000000"],["78648.00000000","0.39291000"],["78647.99000000","0.77743000"],["78647.98000000","1.21952000"],["78647.97000000","0.00000000"],["78647.90000000","0.05000000"],["78647.80000000","0.00008000"],["78647.59000000","0.00000000"],["78647.18000000","0.00000000"],["78647.10000000","0.04821000"],["78646.82000000","0.00000000"],["78646.14000000","0.00014000"],["78646.13000000","0.00007000"],["78646.02000000","0.00000000"],["78646.01000000","0.31384000"],["78646.00000000","0.00007000"],["78645.99000000","0.03346000"],["78645.98000000","0.00000000"],["78645.95000000","0.00021000"],["78645.90000000","0.00000000"],["78645.10000000","0.00400000"],["78645.00000000","0.00007000"],["78644.73000000","0.00007000"],["78643.99000000","0.00329000"],["78643.72000000","0.00000000"],["78643.71000000","1.77573000"],["78643.51000000","0.02288000"],["78643.47000000","0.00000000"],["78643.11000000","0.00000000"],["78643.10000000","0.00000000"],["78642.89000000","0.00000000"],["78642.21000000","0.00000000"],["78641.99000000","0.30021000"],["78641.63000000","0.30000000"],["78641.62000000","0.32861000"],["78641.56000000","0.00007000"],["78640.85000000","0.15000000"],["78640.17000000","0.00007000"],["78640.00000000","0.09538000"],["78639.84000000","0.00007000"],["78639.81000000","0.00010000"],["78639.74000000","0.00000000"],["78639.62000000","0.08576000"],["78639.47000000","0.00000000"],["78639.10000000","0.00327000"],["78638.60000000","0.00000000"],["78638.41000000","0.00007000"],["78638.39000000","0.00000000"],["78638.17000000","0.00007000"],["78638.09000000","0.00000000"],["78637.13000000","0.00329000"],["78635.73000000","0.00000000"],["78634.65000000","0.00000000"],["78632.20000000","0.63577000"],["78632.19000000","0.06596000"],["78632.11000000","0.00000000"],["78630.22000000","0.07621000"],["78628.96000000","0.00000000"],["78627.21000000","0.00000000"],["78627.20000000","0.00000000"],["78626.28000000","0.00000000"],["78626.27000000","0.00254000"],["78624.31000000","0.00000000"],["78623.61000000","0.00000000"],["78622.29000000","0.41193000"],["78622.20000000","0.00000000"],["78620.44000000","0.00000000"],["78612.18000000","0.68363000"],["78611.38000000","0.00000000"],["78609.92000000","0.09603000"],["78609.85000000","0.00000000"],["78609.54000000","0.00000000"],["78608.45000000","0.00000000"],["78607.44000000","0.00000000"],["78607.15000000","0.02762000"],["78606.00000000","0.02400000"],["78602.64000000","0.01134000"],["78601.77000000","0.00000000"],["78598.81000000","0.91286000"],["78596.81000000","0.00436000"],["78596.27000000","0.00436000"],["78589.97000000","0.00000000"],["78588.40000000","0.00000000"],["78582.42000000","0.00000000"],["78582.39000000","0.00406000"],["78582.06000000","0.00000000"],["78582.00000000","0.02400000"],["78580.58000000","0.00000000"],["78567.77000000","0.00000000"],["78550.39000000","0.04652000"],["78538.72000000","2.14339000"],["78526.76000000","0.00000000"],["78515.68000000","0.00000000"],["78500.25000000","0.00000000"],["78452.92000000","0.00000000"],["78420.61000000","0.00000000"],["70785.00000000","0.01546000"],["62920.00000000","0.00472000"]],"a":[["78646.02000000","0.00000000"],["78646.03000000","0.00000000"],["78646.14000000","0.00000000"],["78646.83000000","0.00000000"],["78647.19000000","0.00000000"],["78647.60000000","0.00000000"],["78647.99000000","0.00000000"],["78648.00000000","0.00000000"],["78648.01000000","0.00000000"],["78648.31000000","0.00000000"],["78648.60000000","0.00000000"],["78648.61000000","0.00000000"],["78648.87000000","0.00000000"],["78648.88000000","0.00000000"],["78648.89000000","0.00000000"],["78649.09000000","0.00000000"],["78649.37000000","0.00000000"],["78649.95000000","0.00000000"],["78649.99000000","0.00000000"],["78650.00000000","0.02804000"],["78650.01000000","0.00063000"],["78650.13000000","0.00000000"],["78650.14000000","0.00007000"],["78650.20000000","0.00000000"],["78650.60000000","0.00000000"],["78650.61000000","0.00007000"],["78651.03000000","0.00000000"],["78651.39000000","0.00000000"],["78651.40000000","0.00007000"],["78651.48000000","0.00007000"],["78651.49000000","0.00007000"],["78651.99000000","0.00014000"],["78652.00000000","0.02407000"],["78652.60000000","0.00014000"],["78652.61000000","0.05352000"],["78652.65000000","0.00000000"],["78652.66000000","0.00007000"],["78652.97000000","0.00027000"],["78653.05000000","0.00000000"],["78653.35000000","0.00007000"],["78653.99000000","0.00014000"],["78654.00000000","0.02407000"],["78654.18000000","0.00000000"],["78654.38000000","0.00007000"],["78654.67000000","0.00000000"],["78654.73000000","0.00000000"],["78654.84000000","0.00000000"],["78655.50000000","0.00000000"],["78655.60000000","0.00000000"],["78655.83000000","0.00000000"],["78655.99000000","0.00014000"],["78656.00000000","0.02407000"],["78656.60000000","0.00007000"],["78656.61000000","0.20818000"],["78658.15000000","0.00000000"],["78658.16000000","0.00000000"],["78658.20000000","0.00000000"],["78658.21000000","0.00000000"],["78658.22000000","0.12713000"],["78659.77000000","0.00508000"],["78659.99000000","0.00000000"],["78660.12000000","0.00000000"],["78660.48000000","0.00007000"],["78660.91000000","0.00000000"],["78661.44000000","0.00000000"],["78661.55000000","0.00000000"],["78661.88000000","0.00000000"],["78661.99000000","0.00000000"],["78662.29000000","0.00000000"],["78662.60000000","0.00137000"],["78662.67000000","0.00000000"],["78663.63000000","0.00007000"],["78663.69000000","0.31788000"],["78663.70000000","0.03000000"],["78664.04000000","0.00000000"],["78664.25000000","0.00000000"],["78664.57000000","0.00000000"],["78664.70000000","0.00000000"],["78664.76000000","0.00048000"],["78664.79000000","0.00635000"],["78665.42000000","0.00317000"],["78665.60000000","0.04000000"],["78665.77000000","0.04857000"],["78666.15000000","0.00000000"],["78666.40000000","0.08000000"],["78666.95000000","0.00000000"],["78667.00000000","0.00007000"],["78668.31000000","0.00400000"],["78668.34000000","0.00000000"],["78669.74000000","0.06593000"],["78669.97000000","0.00163000"],["78671.59000000","0.00126000"],["78671.74000000","0.00227000"],["78673.00000000","0.00007000"],["78675.05000000","0.12710000"],["78675.09000000","1.90515000"],["78675.10000000","0.00000000"],["78676.61000000","0.00000000"],["78676.94000000","0.09696000"],["78681.70000000","0.00000000"],["78683.98000000","0.00196000"],["78685.27000000","0.00000000"],["78685.41000000","0.00000000"],["78686.00000000","0.72400000"],["78686.03000000","0.00000000"],["78687.46000000","0.00000000"],["78687.64000000","0.00000000"],["78687.75000000","0.02764000"],["78688.00000000","0.02400000"],["78688.71000000","0.00014000"],["78689.00000000","0.00000000"],["78689.06000000","0.68296000"],["78689.18000000","0.00000000"],["78689.48000000","0.00000000"],["78690.00000000","0.12932000"],["78690.17000000","0.00000000"],["78690.48000000","0.00000000"],["78693.05000000","0.00000000"],["78693.71000000","0.00000000"],["78693.91000000","0.00663000"],["78694.53000000","0.00000000"],["78696.45000000","0.00000000"],["78699.99000000","0.00315000"],["78700.65000000","0.00400000"],["78703.20000000","0.00400000"],["78703.49000000","0.00038000"],["78704.30000000","0.00430000"],["78704.90000000","0.00431000"],["78708.17000000","0.01149000"],["78720.62000000","0.00000000"],["78723.92000000","0.00000000"],["78732.19000000","0.00010000"],["78739.37000000","5.60409000"],["78740.36000000","0.09153000"],["78743.69000000","0.00000000"],["78747.23000000","0.00000000"],["78756.83000000","2.15346000"],["78759.30000000","0.00000000"],["78792.93000000","0.00400000"],["78799.11000000","0.00000000"],["78853.99000000","0.00007000"],["78857.92000000","0.00007000"],["78866.18000000","0.00000000"],["78875.98000000","0.01991000"],["78901.19000000","0.00000000"]]}}}
{"rx_ns": 173328947572000, "frame": {"stream":"btcusdt@depth20@100ms","data":{"lastUpdateId":99076740507,"bids":[["78649.99000000","3.94963000"],["78649.98000000","0.00020000"],["78649.97000000","0.00013000"],["78649.96000000","0.00014000"],["78649.95000000","0.05000000"],["78649.91000000","0.00014000"],["78649.90000000","0.05007000"],["78649.65000000","0.00400000"],["78648.89000000","0.00014000"],["78648.88000000","0.07521000"],["78648.87000000","2.65637000"],["78648.73000000","0.03784000"],["78648.61000000","0.07514000"],["78648.60000000","0.00007000"],["78648.01000000","0.00007000"],["78648.00000000","0.39298000"],["78647.99000000","0.77743000"],["78647.98000000","1.21952000"],["78647.80000000","0.00008000"],["78647.47000000","0.04541000"]],"asks":[["78650.00000000","0.02818000"],["78650.01000000","0.00063000"],["78650.61000000","0.00007000"],["78650.92000000","0.00007000"],["78651.48000000","0.00007000"],["78651.49000000","0.00007000"],["78651.83000000","0.00007000"],["78651.99000000","0.00014000"],["78652.00000000","0.02407000"],["78652.60000000","0.00014000"],["78652.61000000","0.05359000"],["78652.87000000","0.00014000"],["78652.88000000","0.01543000"],["78652.96000000","0.00007000"],["78653.88000000","0.00007000"],["78653.99000000","0.00014000"],["78654.00000000","0.02407000"],["78654.13000000","0.00007000"],["78654.14000000","0.02572000"],["78654.67000000","0.00027000"]]}}}
{"rx_ns": 173328947681000, "frame": {"stream":"btcusdt@depth@100ms","data":{"e":"depthUpdate","E":1787603268114,"s":"BTCUSDT","U":99076740359,"u":99076740507,"b":[["78649.99000000","3.94963000"],["78649.96000000","0.00014000"],["78649.95000000","0.05000000"],["78649.91000000","0.00014000"],["78649.90000000","0.05007000"],["78648.89000000","0.00014000"],["78648.88000000","0.07521000"],["78648.87000000","2.65637000"],["78648.86000000","0.00000000"],["78648.73000000","0.03784000"],["78648.61000000","0.07514000"],["78648.01000000","0.00007000"],["78648.00000000","0.39298000"],["78647.99000000","0.77743000"],["78647.90000000","0.00000000"],["78647.47000000","0.04541000"],["78646.21000000","0.04541000"],["78646.01000000","0.30007000"],["78646.00000000","0.00000000"],["78645.99000000","0.03339000"],["78645.95000000","0.00014000"],["78644.73000000","0.00000000"],["78641.62000000","0.32841000"],["78640.36000000","0.00000000"],["78639.99000000","0.00335000"],["78626.27000000","0.14041000"],["78622.41000000","0.00000000"],["78619.93000000","0.00000000"],["78618.08000000","0.00000000"],["78613.57000000","0.31894000"],["78610.00000000","0.13016000"],["78608.00000000","0.02400000"],["78582.52000000","0.00000000"],["78422.80000000","0.00000000"],["77933.85000000","0.00000000"],["70785.00000000","0.01562000"]],"a":[["78650.00000000","0.02818000"],["78650.01000000","0.00063000"],["78650.14000000","0.00000000"],["78650.31000000","0.00000000"],["78651.40000000","0.00000000"],["78652.00000000","0.02407000"],["78652.61000000","0.05359000"],["78652.66000000","0.00000000"],["78652.87000000","0.00014000"],["78652.88000000","0.01543000"],["78652.97000000","0.00000000"],["78653.35000000","0.00000000"],["78653.59000000","0.00000000"],["78654.00000000","0.02407000"],["78654.13000000","0.00007000"],["78654.14000000","0.02572000"],["78654.38000000","0.00000000"],["78654.67000000","0.00027000"],["78655.40000000","0.03087000"],["78655.99000000","0.00000000"],["78656.00000000","0.02407000"],["78656.60000000","0.00000000"],["78656.61000000","0.20825000"],["78656.66000000","0.03087000"],["78657.55000000","0.02168000"],["78657.87000000","0.00000000"],["78658.00000000","0.02407000"],["78658.22000000","0.12727000"],["78658.34000000","0.16542000"],["78659.77000000","0.00000000"],["78662.59000000","0.00508000"],["78662.60000000","0.00000000"],["78663.18000000","0.00000000"],["78663.19000000","0.00340000"],["78663.69000000","0.00000000"],["78664.56000000","0.00000000"],["78665.23000000","0.00137000"],["78665.59000000","0.31788000"],["78668.55000000","0.00635000"],["78669.61000000","0.00000000"],["78672.90000000","0.02000000"],["78674.82000000","0.00000000"],["78676.94000000","0.00000000"],["78680.34000000","0.00000000"],["78682.47000000","0.00000000"],["78684.16000000","0.04654000"],["78686.00000000","0.02400000"],["78687.39000000","0.43611000"],["78687.75000000","0.00000000"],["78688.37000000","0.00059000"],["78690.32000000","0.02390000"],["78703.49000000","0.00635000"],["78748.95000000","0.02000000"],["78750.48000000","0.00000000"],["78756.62000000","0.00000000"],["78762.71000000","0.00000000"],["78857.92000000","0.00000000"]]}}}
{"rx_ns": 173329054410100, "frame": {"stream":"btcusdt@depth20@100ms","data":{"lastUpdateId":99076740566,"bids":[["78649.99000000","3.95289000"],["78649.98000000","0.00020000"],["78649.97000000","0.00013000"],["78649.96000000","0.00014000"],["78649.95000000","0.05007000"],["78649.91000000","0.00014000"],["78649.90000000","0.05007000"],["78649.65000000","0.00400000"],["78649.11000000","0.00007000"],["78648.89000000","0.00014000"],["78648.88000000","0.07521000"],["78648.87000000","2.30340000"],["78648.73000000","0.03784000"],["78648.61000000","0.07514000"],["78648.60000000","0.00007000"],["78648.01000000","0.00007000"],["78648.00000000","0.39298000"],["78647.99000000","0.20646000"],["78647.98000000","1.21952000"],["78647.80000000","0.00008000"]],"asks":[["78650.00000000","0.02818000"],["78650.01000000","0.00063000"],["78650.61000000","0.00007000"],["78650.92000000","0.00007000"],["78651.48000000","0.00007000"],["78651.49000000","0.00007000"],["78651.83000000","0.00007000"],["78651.99000000","0.00014000"],["78652.00000000","0.02407000"],["78652.60000000","0.00014000"],["78652.61000000","0.05359000"],["78652.87000000","0.00014000"],["78652.88000000","0.01550000"],["78652.96000000","0.00007000"],["78653.81000000","0.00007000"],["78653.88000000","0.00007000"],["78653.99000000","0.00014000"],["78654.00000000","0.02407000"],["78654.13000000","0.00007000"],["78654.14000000","0.02579000"]]}}}
{"rx_ns": 173329054501400, "frame": {"stream":"btcusdt@depth@100ms","data":{"e":"depthUpdate","E":1787603268214,"s":"BTCUSDT","U":99076740508,"u":99076740566,"b":[["78649.99000000","3.95289000"],["78649.95000000","0.05007000"],["78649.11000000","0.00007000"],["78648.87000000","2.30340000"],["78647.99000000","0.20646000"],["78645.17000000","0.00000000"],["78644.39000000","0.00000000"],["78642.00000000","0.00700000"],["78640.71000000","0.00007000"],["78640.00000000","0.10238000"],["78638.00000000","0.00707000"],["78636.63000000","0.00193000"],["78636.18000000","0.00007000"],["78636.00000000","0.01200000"],["78634.05000000","0.00059000"],["78634.00000000","0.01700000"],["78632.65000000","0.00012000"],["78622.45000000","0.00000000"],["78618.66000000","0.00000000"],["78618.47000000","0.00000000"],["78550.95000000","0.00406000"],["70785.00000000","0.01578000"],["62920.00000000","0.00441000"]],"a":[["78652.61000000","0.05359000"],["78652.88000000","0.01550000"],["78653.81000000","0.00007000"],["78654.00000000","0.02407000"],["78654.14000000","0.02579000"],["78655.40000000","0.03094000"],["78656.61000000","0.20825000"],["78657.55000000","0.02161000"],["78658.00000000","0.02400000"],["78658.22000000","0.12720000"],["78659.78000000","0.00000000"],["78673.44000000","0.00000000"],["78678.37000000","0.00000000"],["78687.70000000","0.00012000"],["78689.07000000","0.02760000"],["78690.32000000","0.00000000"],["78692.00000000","0.02588000"],["78712.28000000","0.00000000"],["78713.41000000","0.00000000"],["78715.63000000","0.00000000"],["78726.55000000","0.00112000"],["78727.89000000","0.00537000"],["78730.10000000","0.01739000"],["78754.49000000","0.00012000"],["78760.63000000","0.00019000"]]}}}
{"rx_ns": 173329156858600, "frame": {"stream":"btcusdt@depth20@100ms","data":{"lastUpdateId":99076740618,"bids":[["78649.99000000","4.03296000"],["78649.98000000","0.00020000"],["78649.97000000","0.00013000"],["78649.96000000","0.00014000"],["78649.95000000","0.05007000"],["78649.91000000","0.00014000"],["78649.90000000","0.05007000"],["78649.65000000","0.00400000"],["78649.11000000","0.00007000"],["78648.89000000","0.00014000"],["78648.88000000","0.07521000"],["78648.87000000","2.14340000"],["78648.73000000","0.03784000"],["78648.61000000","0.07514000"],["78648.60000000","0.00007000"],["78648.01000000","0.00007000"],["78648.00000000","0.39298000"],["78647.99000000","0.20646000"],["78647.98000000","1.21952000"],["78647.80000000","0.00008000"]],"asks":[["78650.00000000","0.02818000"],["78650.01000000","0.00063000"],["78650.61000000","0.00007000"],["78650.92000000","0.00007000"],["78651.48000000","0.00007000"],["78651.49000000","0.00007000"],["78651.83000000","0.00007000"],["78651.99000000","0.00014000"],["78652.00000000","0.02407000"],["78652.60000000","0.00014000"],["78652.61000000","0.05359000"],["78652.87000000","0.00014000"],["78652.88000000","0.01550000"],["78652.96000000","0.00007000"],["78653.81000000","0.00007000"],["78653.88000000","0.00007000"],["78653.99000000","0.00014000"],["78654.00000000","0.02407000"],["78654.13000000","0.00007000"],["78654.14000000","0.02579000"]]}}}
{"rx_ns": 173329156947900, "frame": {"stream":"btcusdt@depth@100ms","data":{"e":"depthUpdate","E":1787603268314,"s":"BTCUSDT","U":99076740567,"u":99076740618,"b":[["78649.99000000","4.03296000"],["78648.87000000","2.14340000"],["78633.85000000","0.04509000"],["78632.00000000","0.02400000"],["78630.00000000","0.11939000"],["78628.00000000","0.02400000"],["78626.36000000","0.00007000"],["78622.36000000","0.00000000"],["78609.88000000","0.00000000"],["78474.90000000","4.39154000"],["78256.74000000","0.01000000"],["77865.45000000","0.01000000"],["77476.12000000","0.01000000"],["77088.74000000","0.01000000"],["76703.30000000","0.01070000"],["76319.78000000","0.01000000"],["75938.18000000","0.01000000"],["75558.49000000","0.01000000"],["75180.70000000","0.01000000"],["74804.80000000","0.01000000"],["74430.77000000","0.01000000"],["74058.62000000","0.01000000"],["73688.33000000","0.01000000"],["73319.88000000","0.01000000"],["72953.29000000","0.01000000"],["70785.00000000","0.01610000"],["62920.00000000","0.00441000"],["62915.00000000","0.00000000"]],"a":[["78669.55000000","0.00000000"],["78673.56000000","0.00007000"],["79043.25000000","0.01000000"],["79438.47000000","0.01000000"],["79835.66000000","0.01000000"],["80234.84000000","0.01000000"],["80636.02000000","0.01000000"],["81039.20000000","0.01000000"],["81444.39000000","0.01000000"],["81851.61000000","0.01000000"],["82260.87000000","0.01000000"],["82672.18000000","0.01000000"],["83085.54000000","0.01000000"],["83500.96000000","0.01000000"],["83918.47000000","0.01000000"],["84338.06000000","0.01000000"],["84759.75000000","0.01000000"]]}}}
{"rx_ns": 173329254207900, "frame": {"stream":"btcusdt@depth20@100ms","data":{"lastUpdateId":99076740634,"bids":[["78649.99000000","4.03296000"],["78649.98000000","0.00020000"],["78649.97000000","0.00013000"],["78649.96000000","0.00014000"],["78649.95000000","0.05007000"],["78649.91000000","0.00014000"],["78649.90000000","0.05007000"],["78649.65000000","0.00400000"],["78649.11000000","0.00007000"],["78648.89000000","0.00014000"],["78648.88000000","0.07521000"],["78648.87000000","2.14340000"],["78648.73000000","0.03784000"],["78648.61000000","0.07514000"],["78648.60000000","0.00007000"],["78648.01000000","0.00007000"],["78648.00000000","0.39298000"],["78647.99000000","0.20646000"],["78647.98000000","1.21952000"],["78647.80000000","0.00008000"]],"asks":[["78650.00000000","0.02488000"],["78650.01000000","0.00063000"],["78650.61000000","0.00007000"],["78650.92000000","0.00007000"],["78651.48000000","0.00007000"],["78651.49000000","0.00007000"],["78651.83000000","0.00007000"],["78651.99000000","0.00014000"],["78652.00000000","0.02407000"],["78652.60000000","0.00014000"],["78652.61000000","0.05359000"],["78652.87000000","0.00014000"],["78652.88000000","0.01550000"],["78652.96000000","0.00007000"],["78653.81000000","0.00007000"],["78653.88000000","0.00007000"],["78653.99000000","0.00014000"],["78654.00000000","0.02407000"],["78654.13000000","0.00007000"],["78654.14000000","0.02579000"]]}}}
{"rx_ns": 173329254323700, "frame": {"stream":"btcusdt@depth@100ms","data":{"e":"depthUpdate","E":1787603268414,"s":"BTCUSDT","U":99076740619,"u":99076740634,"b":[["78621.71000000","0.00000000"],["78582.39000000","0.00000000"],["78572.17000000","0.02118000"],["78550.95000000","0.00000000"],["78503.77000000","0.00000000"],["78433.01000000","0.00000000"],["70784.00000000","0.00119000"]],"a":[["78650.00000000","0.02488000"],["78671.41000000","0.00000000"],["78710.75000000","0.00000000"],["78742.22000000","0.00000000"],["78766.72000000","0.00031000"],["78789.42000000","0.00000000"],["78860.23000000","0.00000000"]]}}}
{"rx_ns": 173329341603200, "frame": {"stream":"btcusdt@depth20@100ms","data":{"lastUpdateId":99076740693,"bids":[["78649.99000000","3.69354000"],["78649.98000000","0.00020000"],["78649.97000000","0.00013000"],["78649.96000000","0.00014000"],["78649.95000000","0.05007000"],["78649.91000000","0.00014000"],["78649.90000000","0.05007000"],["78649.65000000","0.00400000"],["78649.11000000","0.00007000"],["78648.88000000","0.00021000"],["78648.87000000","2.14340000"],["78648.73000000","0.03784000"],["78648.61000000","0.07514000"],["78648.60000000","0.00007000"],["78648.01000000","0.00014000"],["78648.00000000","0.39298000"],["78647.99000000","0.07756000"],["78647.98000000","1.21952000"],["78647.80000000","0.00008000"],["78647.47000000","0.04541000"]],"asks":[["78650.00000000","0.80118000"],["78650.01000000","0.00063000"],["78650.61000000","0.00007000"],["78650.92000000","0.00007000"],["78651.48000000","0.00007000"],["78651.49000000","0.00007000"],["78651.99000000","0.00014000"],["78652.00000000","0.02407000"],["78652.60000000","0.00014000"],["78652.61000000","0.05366000"],["78652.87000000","0.00014000"],["78652.88000000","0.01550000"],["78652.96000000","0.00007000"],["78653.81000000","0.00007000"],["78653.88000000","0.00014000"],["78653.99000000","0.00014000"],["78654.00000000","0.02407000"],["78654.13000000","0.00007000"],["78654.14000000","0.02579000"],["78654.67000000","0.00027000"]]}}}
{"rx_ns": 173329341686900, "frame": {"stream":"btcusdt@depth@100ms","data":{"e":"depthUpdate","E":1787603268514,"s":"BTCUSDT","U":99076740635,"u":99076740693,"b":[["78649.99000000","3.69354000"],["78648.89000000","0.00000000"],["78648.88000000","0.00021000"],["78648.01000000","0.00014000"],["78647.99000000","0.07756000"],["78646.22000000","0.00635000"],["78645.11000000","0.00635000"],["78637.69000000","0.34338000"],["78635.09000000","0.00000000"],["78572.17000000","0.00000000"],["78466.05000000","3.82378000"],["70785.00000000","0.01642000"],["62920.00000000","0.00472000"]],"a":[["78650.00000000","0.80118000"],["78650.01000000","0.00063000"],["78651.83000000","0.00000000"],["78652.61000000","0.05366000"],["78653.88000000","0.00014000"],["78655.99000000","0.19885000"],["78656.61000000","0.00014000"],["78657.59000000","0.00196000"],["78657.87000000","0.21930000"],["78658.22000000","0.12713000"],["78658.34000000","0.00000000"],["78658.99000000","0.00508000"],["78661.99000000","0.31787000"],["78662.59000000","0.00000000"],["78665.59000000","0.00000000"],["78666.59000000","0.12711000"],["78670.53000000","0.00000000"],["78673.86000000","0.36224000"],["78683.98000000","0.00000000"],["78692.23000000","0.02514000"],["78692.58000000","0.00000000"],["78748.95000000","0.00000000"],["78856.31000000","0.00007000"],["78860.24000000","0.00007000"]]}}}
{"rx_ns": 173329443946000, "frame": {"stream":"btcusdt@depth20@100ms","data":{"lastUpdateId":99076740740,"bids":[["78649.99000000","3.69354000"],["78649.98000000","0.00020000"],["78649.97000000","0.00013000"],["78649.96000000","0.00014000"],["78649.95000000","0.05007000"],["78649.91000000","0.00014000"],["78649.90000000","0.05007000"],["78649.65000000","0.00400000"],["78649.11000000","0.00007000"],["78648.88000000","0.00014000"],["78648.87000000","2.14347000"],["78648.73000000","0.03784000"],["78648.61000000","0.03238000"],["78648.60000000","0.00007000"],["78648.01000000","0.00014000"],["78648.00000000","0.31798000"],["78647.99000000","0.07756000"],["78647.98000000","1.21952000"],["78647.80000000","0.00008000"],["78647.47000000","0.04541000"]],"asks":[["78650.00000000","0.80185000"],["78650.01000000","0.19265000"],["78650.61000000","0.00007000"],["78650.92000000","0.00007000"],["78651.37000000","0.00007000"],["78651.48000000","0.00007000"],["78651.49000000","0.00007000"],["78651.99000000","0.00014000"],["78652.00000000","0.02407000"],["78652.60000000","0.00014000"],["78652.61000000","0.05366000"],["78652.87000000","0.00014000"],["78652.88000000","0.01550000"],["78652.96000000","0.00007000"],["78653.81000000","0.00007000"],["78653.88000000","0.00014000"],["78653.99000000","0.00014000"],["78654.00000000","0.02407000"],["78654.14000000","0.02579000"],["78654.67000000","0.00027000"]]}}}
{"rx_ns": 173329444126200, "frame": {"stream":"btcusdt@depth@100ms","data":{"e":"depthUpdate","E":1787603268614,"s":"BTCUSDT","U":99076740694,"u":99076740740,"b":[["78649.90000000","0.05007000"],["78648.88000000","0.00014000"],["78648.87000000","2.14347000"],["78648.61000000","0.03238000"],["78648.00000000","0.31798000"],["78642.75000000","0.00407000"],["78637.69000000","0.00000000"],["78628.84000000","0.00406000"],["78624.00000000","0.72407000"],["78621.07000000","0.34346000"],["78604.00000000","0.02427000"],["78572.17000000","0.02118000"],["70785.00000000","0.01658000"],["62920.00000000","0.00441000"]],"a":[["78650.00000000","0.80185000"],["78650.01000000","0.19265000"],["78651.37000000","0.00007000"],["78651.38000000","0.00000000"],["78654.13000000","0.00000000"],["78655.40000000","0.03094000"],["78655.99000000","0.00007000"],["78656.00000000","0.02407000"],["78656.61000000","0.00007000"],["78665.76000000","1.21952000"],["78669.73000000","1.90515000"],["78671.08000000","1.21952000"],["78677.74000000","0.09426000"],["78739.35000000","0.00000000"],["78749.29000000","0.00000000"],["78749.33000000","0.00000000"],["78860.24000000","0.00000000"]]}}}
{"rx_ns": 173329539683500, "frame": {"stream":"btcusdt@depth20@100ms","data":{"lastUpdateId":99076740802,"bids":[["78649.99000000","1.75832000"],["78649.98000000","0.00020000"],["78649.97000000","0.00013000"],["78649.96000000","0.00014000"],["78649.95000000","0.05007000"],["78649.91000000","0.00014000"],["78649.90000000","0.05007000"],["78649.65000000","0.00400000"],["78649.11000000","0.00007000"],["78648.88000000","0.00014000"],["78648.87000000","0.20832000"],["78648.74000000","0.00007000"],["78648.73000000","0.03784000"],["78648.61000000","0.00014000"],["78648.60000000","0.00007000"],["78648.01000000","1.21966000"],["78648.00000000","0.31798000"],["78647.99000000","0.07742000"],["78647.80000000","0.00008000"],["78647.47000000","0.04541000"]],"asks":[["78650.00000000","0.99775000"],["78650.01000000","0.00063000"],["78650.61000000","0.00014000"],["78650.62000000","0.20818000"],["78650.92000000","0.00007000"],["78651.48000000","0.00007000"],["78651.49000000","0.00007000"],["78651.99000000","0.00014000"],["78652.00000000","0.02407000"],["78652.60000000","0.00014000"],["78652.61000000","0.05359000"],["78652.87000000","0.00014000"],["78652.88000000","0.01550000"],["78652.96000000","0.00007000"],["78653.81000000","0.00007000"],["78653.88000000","0.00014000"],["78653.99000000","0.00014000"],["78654.00000000","0.02407000"],["78654.14000000","0.02579000"],["78654.67000000","0.00027000"]]}}}
{"rx_ns": 173329539764800, "frame": {"stream":"btcusdt@depth@100ms","data":{"e":"depthUpdate","E":1787603268714,"s":"BTCUSDT","U":99076740741,"u":99076740802,"b":[["78649.99000000","1.75832000"],["78648.87000000","0.20832000"],["78648.74000000","0.00007000"],["78648.61000000","0.00014000"],["78648.01000000","1.21966000"],["78647.99000000","0.07742000"],["78647.98000000","0.00000000"],["78646.22000000","0.00000000"],["78645.95000000","0.00007000"],["78643.72000000","1.21952000"],["78643.71000000","0.55621000"],["78642.89000000","0.00635000"],["78642.31000000","0.00000000"],["78639.12000000","1.21952000"],["78639.09000000","0.00000000"],["78632.20000000","0.00000000"],["78628.75000000","0.63578000"],["78584.97000000","1.25994000"],["78572.17000000","0.00000000"],["70785.00000000","0.01658000"]],"a":[["78650.00000000","0.99775000"],["78650.01000000","0.00063000"],["78650.61000000","0.00014000"],["78650.62000000","0.20818000"],["78651.37000000","0.00000000"],["78652.61000000","0.05359000"],["78653.99000000","0.00014000"],["78654.13000000","0.00000000"],["78655.40000000","0.03087000"],["78655.99000000","0.00000000"],["78656.49000000","0.00000000"],["78658.02000000","0.00291000"],["78658.06000000","0.01455000"],["78690.95000000","0.02418000"]]}}}
{"rx_ns": 173329639239500, "frame": {"stream":"btcusdt@depth20@100ms","data":{"lastUpdateId":99076740864,"bids":[["78649.99000000","3.92651000"],["78649.98000000","0.00020000"],["78649.97000000","0.00013000"],["78649.96000000","0.00014000"],["78649.95000000","0.05007000"],["78649.91000000","0.00014000"],["78649.90000000","0.05007000"],["78649.65000000","0.00400000"],["78649.11000000","0.00007000"],["78648.88000000","0.00014000"],["78648.87000000","0.20832000"],["78648.74000000","0.00007000"],["78648.73000000","0.03784000"],["78648.61000000","0.00007000"],["78648.60000000","0.00007000"],["78648.32000000","0.00007000"],["78648.01000000","1.21959000"],["78648.00000000","0.31798000"],["78647.99000000","0.07735000"],["78647.80000000","0.00008000"]],"asks":[["78650.00000000","0.98941000"],["78650.01000000","0.00056000"],["78650.61000000","0.00021000"],["78650.62000000","0.20825000"],["78650.92000000","0.00007000"],["78651.48000000","0.00007000"],["78651.49000000","0.00007000"],["78651.99000000","0.00014000"],["78652.00000000","0.02407000"],["78652.60000000","0.00014000"],["78652.61000000","0.05359000"],["78652.87000000","0.00014000"],["78652.88000000","0.01550000"],["78652.96000000","0.00007000"],["78653.81000000","0.00007000"],["78653.88000000","0.00014000"],["78653.99000000","0.00014000"],["78654.00000000","0.02407000"],["78654.14000000","0.02579000"],["78654.67000000","0.00027000"]]}}}
{"rx_ns": 173329639327600, "frame": {"stream":"btcusdt@depth@100ms","data":{"e":"depthUpdate","E":1787603268814,"s":"BTCUSDT","U":99076740803,"u":99076740864,"b":[["78649.99000000","3.92651000"],["78648.61000000","0.00007000"],["78648.32000000","0.00007000"],["78648.01000000","1.21959000"],["78647.99000000","0.07735000"],["78644.00000000","1.90515000"],["78635.29000000","0.38155000"],["78619.00000000","0.00000000"],["78595.51000000","0.00636000"],["78509.13000000","0.00127000"],["78495.77000000","0.00000000"],["78488.08000000","0.00127000"],["78473.45000000","0.00000000"],["78466.05000000","0.00000000"],["78256.74000000","0.00000000"],["77865.45000000","0.00000000"],["77476.12000000","0.00000000"],["77088.74000000","0.00000000"],["76703.30000000","0.00070000"],["76319.78000000","0.00000000"],["75938.18000000","0.00000000"],["75558.49000000","0.00000000"],["75180.70000000","0.00000000"],["74804.80000000","0.00000000"],["74430.77000000","0.00000000"],["74058.62000000","0.00000000"],["73688.33000000","0.00000000"],["73319.88000000","0.00000000"],["72953.29000000","0.00000000"],["70785.00000000","0.01674000"]],"a":[["78650.00000000","0.98941000"],["78650.01000000","0.00056000"],["78650.61000000","0.00021000"],["78650.62000000","0.20825000"],["78655.40000000","0.03094000"],["78657.59000000","0.00000000"],["78659.78000000","0.00007000"],["78717.99000000","0.00000000"],["78721.99000000","0.00315000"],["78769.99000000","0.00000000"],["78777.99000000","0.00127000"],["78796.56000000","0.00406000"],["79043.25000000","0.00000000"],["79438.47000000","0.00000000"],["79835.66000000","0.00000000"],["80234.84000000","0.00000000"],["80636.02000000","0.00000000"],["81039.20000000","0.00000000"],["81444.39000000","0.00000000"],["81851.61000000","0.00000000"],["82260.87000000","0.00000000"],["82672.18000000","0.00000000"],["83085.54000000","0.00000000"],["83500.96000000","0.00000000"],["83918.47000000","0.00000000"],["84338.06000000","0.00000000"],["84759.75000000","0.00000000"]]}}}
{"rx_ns": 173329745638300, "frame": {"stream":"btcusdt@depth20@100ms","data":{"lastUpdateId":99076740880,"bids":[["78649.99000000","3.92651000"],["78649.98000000","0.00020000"],["78649.97000000","0.00013000"],["78649.96000000","0.00014000"],["78649.95000000","0.05007000"],["78649.91000000","0.00014000"],["78649.90000000","0.05007000"],["78649.65000000","0.00400000"],["78649.11000000","0.00007000"],["78648.88000000","0.00014000"],["78648.87000000","0.20832000"],["78648.74000000","0.00007000"],["78648.73000000","0.03784000"],["78648.61000000","0.00007000"],["78648.60000000","0.00007000"],["78648.32000000","0.00007000"],["78648.01000000","1.21959000"],["78648.00000000","0.31798000"],["78647.99000000","0.07735000"],["78647.80000000","0.00008000"]],"asks":[["78650.00000000","0.98948000"],["78650.01000000","0.00063000"],["78650.61000000","0.00021000"],["78650.62000000","0.20825000"],["78650.92000000","0.00007000"],["78651.48000000","0.00007000"],["78651.49000000","0.00007000"],["78651.99000000","0.00014000"],["78652.00000000","0.02407000"],["78652.60000000","0.00014000"],["78652.61000000","0.05359000"],["78652.87000000","0.00014000"],["78652.88000000","0.01550000"],["78652.96000000","0.00007000"],["78653.81000000","0.00007000"],["78653.88000000","0.00014000"],["78653.99000000","0.00014000"],["78654.00000000","0.02407000"],["78654.14000000","0.02579000"],["78654.67000000","0.00027000"]]}}}
{"rx_ns": 173329745737400, "frame": {"stream":"btcusdt@depth@100ms","data":{"e":"depthUpdate","E":1787603268914,"s":"BTCUSDT","U":99076740865,"u":99076740880,"b":[["78643.59000000","0.02600000"],["78642.80000000","0.02800000"],["78642.79000000","0.02800000"],["78633.85000000","0.00000000"],["78629.86000000","0.04558000"],["70785.00000000","0.01690000"],["62919.99000000","0.00000000"]],"a":[["78650.00000000","0.98948000"],["78650.01000000","0.00063000"],["78670.03000000","0.02000000"],["78717.31000000","0.02000000"]]}}}
{"rx_ns": 173329858352100, "frame": {"stream":"btcusdt@depth20@100ms","data":{"lastUpdateId":99076740897,"bids":[["78649.99000000","3.92658000"],["78649.98000000","0.00020000"],["78649.97000000","0.00013000"],["78649.96000000","0.00014000"],["78649.95000000","0.05007000"],["78649.91000000","0.00014000"],["78649.90000000","0.05007000"],["78649.65000000","0.00400000"],["78649.11000000","0.00007000"],["78648.88000000","0.00014000"],["78648.87000000","0.20832000"],["78648.74000000","0.00007000"],["78648.73000000","0.03784000"],["78648.61000000","0.00007000"],["78648.60000000","0.00007000"],["78648.32000000","0.00007000"],["78648.01000000","1.21959000"],["78648.00000000","0.31798000"],["78647.99000000","0.07735000"],["78647.80000000","0.00008000"]],"asks":[["78650.00000000","0.99548000"],["78650.01000000","0.00063000"],["78650.61000000","0.00021000"],["78650.62000000","0.20825000"],["78650.92000000","0.00007000"],["78651.48000000","0.00007000"],["78651.49000000","0.00007000"],["78651.99000000","0.00014000"],["78652.00000000","0.02407000"],["78652.11000000","0.20297000"],["78652.60000000","0.00014000"],["78652.61000000","0.05359000"],["78652.87000000","0.00014000"],["78652.88000000","0.01550000"],["78652.96000000","0.00007000"],["78653.81000000","0.00007000"],["78653.88000000","0.00014000"],["78653.99000000","0.00014000"],["78654.00000000","0.02407000"],["78654.14000000","0.02579000"]]}}}
{"rx_ns": 173329858453200, "frame": {"stream":"btcusdt@depth@100ms","data":{"e":"depthUpdate","E":1787603269014,"s":"BTCUSDT","U":99076740881,"u":99076740897,"b":[["78649.99000000","3.92658000"],["78643.68000000","0.02400000"],["78642.96000000","0.12715000"],["78641.99000000","0.30014000"],["78641.62000000","0.32834000"],["78638.96000000","0.02000000"],["78631.02000000","0.00000000"],["78631.00000000","0.00007000"],["70785.00000000","0.01674000"],["62920.00000000","0.00472000"]],"a":[["78650.00000000","0.99548000"],["78652.11000000","0.20297000"],["78669.92000000","0.02000000"],["78674.64000000","0.02000000"],["78678.54000000","0.00406000"],["78730.25000000","0.02000000"],["78734.63000000","0.02000000"]]}}}
{"rx_ns": 173329938656400, "frame": {"stream":"btcusdt@depth20@100ms","data":{"lastUpdateId":99076740938,"bids":[["78649.99000000","3.66354000"],["78649.98000000","0.00020000"],["78649.97000000","0.00013000"],["78649.96000000","0.00014000"],["78649.95000000","0.05007000"],["78649.91000000","0.00014000"],["78649.90000000","0.05007000"],["78649.65000000","0.00400000"],["78649.11000000","0.00007000"],["78648.88000000","0.00014000"],["78648.87000000","0.20832000"],["78648.74000000","0.00007000"],["78648.73000000","0.03784000"],["78648.61000000","0.00007000"],["78648.60000000","0.00007000"],["78648.32000000","0.00007000"],["78648.01000000","1.21959000"],["78648.00000000","0.32298000"],["78647.99000000","0.07735000"],["78647.80000000","0.00008000"]],"asks":[["78650.00000000","0.98965000"],["78650.01000000","0.00070000"],["78650.61000000","0.00021000"],["78650.62000000","0.20832000"],["78650.92000000","0.00007000"],["78651.22000000","0.17784000"],["78651.48000000","0.00007000"],["78651.49000000","0.00007000"],["78651.99000000","0.00014000"],["78652.00000000","0.02407000"],["78652.10000000","0.00014000"],["78652.11000000","0.00007000"],["78652.60000000","0.00014000"],["78652.61000000","0.05359000"],["78652.88000000","0.01550000"],["78652.96000000","0.00007000"],["78653.81000000","0.00007000"],["78653.88000000","0.00014000"],["78653.99000000","0.00014000"],["78654.00000000","0.02407000"]]}}}
{"rx_ns": 173329938736500, "frame": {"stream":"btcusdt@depth@100ms","data":{"e":"depthUpdate","E":1787603269114,"s":"BTCUSDT","U":99076740898,"u":99076740938,"b":[["78649.99000000","3.66354000"],["78648.00000000","0.32298000"],["78646.00000000","0.00500000"],["78644.00000000","1.91015000"],["78643.71000000","0.55628000"],["78642.88000000","0.02207000"],["78642.00000000","0.01200000"],["78641.99000000","0.30000000"],["78640.53000000","0.02400000"],["78640.00000000","0.10738000"],["78638.85000000","0.02000000"],["78638.00000000","0.01207000"],["78636.00000000","0.01700000"],["78631.80000000","0.00000000"],["78627.18000000","0.00000000"],["78627.06000000","0.00000000"],["78582.09000000","0.00000000"],["78482.12000000","0.00779000"],["78480.71000000","0.00000000"],["77942.14000000","0.00010000"],["70785.00000000","0.01706000"]],"a":[["78650.00000000","0.98965000"],["78650.01000000","0.00070000"],["78650.62000000","0.20832000"],["78651.22000000","0.17784000"],["78652.00000000","0.02407000"],["78652.10000000","0.00014000"],["78652.11000000","0.00007000"],["78652.87000000","0.00000000"],["78656.00000000","0.02400000"],["78677.93000000","0.00000000"],["78730.25000000","0.00000000"],["78743.51000000","0.00000000"],["78747.52000000","0.00025000"]]}}}
{"rx_ns": 173330039925000, "frame": {"stream":"btcusdt@depth20@100ms","data":{"lastUpdateId":99076740994,"bids":[["78649.99000000","3.66424000"],["78649.98000000","0.00062000"],["78649.97000000","0.00013000"],["78649.96000000","0.00014000"],["78649.95000000","0.05007000"],["78649.91000000","0.00014000"],["78649.90000000","0.05007000"],["78649.65000000","0.00400000"],["78649.11000000","0.00007000"],["78648.88000000","0.00014000"],["78648.87000000","0.20832000"],["78648.74000000","0.00007000"],["78648.73000000","0.03784000"],["78648.61000000","0.00007000"],["78648.60000000","0.00007000"],["78648.32000000","0.00007000"],["78648.01000000","1.21959000"],["78648.00000000","0.32298000"],["78647.99000000","0.07735000"],["78647.80000000","0.00008000"]],"asks":[["78650.00000000","0.98338000"],["78650.01000000","0.00070000"],["78650.61000000","0.00021000"],["78650.62000000","0.20832000"],["78650.92000000","0.00007000"],["78651.21000000","0.00014000"],["78651.22000000","0.17791000"],["78651.48000000","0.00007000"],["78651.49000000","0.00007000"],["78651.99000000","0.00014000"],["78652.00000000","0.02407000"],["78652.60000000","0.00014000"],["78652.61000000","0.05359000"],["78652.88000000","0.01550000"],["78652.96000000","0.00007000"],["78653.81000000","0.00007000"],["78653.88000000","0.00014000"],["78653.99000000","0.00014000"],["78654.00000000","0.02407000"],["78654.14000000","0.02579000"]]}}}
{"rx_ns": 173330040028300, "frame": {"stream":"btcusdt@depth@100ms","data":{"e":"depthUpdate","E":1787603269214,"s":"BTCUSDT","U":99076740939,"u":99076740994,"b":[["78649.99000000","3.66424000"],["78649.98000000","0.00062000"],["78646.00000000","0.00640000"],["78644.00000000","1.91715000"],["78642.00000000","0.01900000"],["78640.00000000","0.11438000"],["78639.74000000","0.02000000"],["78638.95000000","0.02000000"],["78638.85000000","0.04200000"],["78638.66000000","0.00007000"],["78638.00000000","0.01907000"],["78631.89000000","0.00000000"],["78628.74000000","0.00000000"],["78627.07000000","0.00000000"],["78599.56000000","0.02000000"],["78581.49000000","0.00000000"],["78558.07000000","0.00406000"],["78495.86000000","0.01991000"],["78473.44000000","0.00000000"],["70785.00000000","0.01722000"],["62920.00000000","0.00441000"]],"a":[["78650.00000000","0.98338000"],["78650.01000000","0.00070000"],["78650.62000000","0.20832000"],["78651.21000000","0.00014000"],["78651.22000000","0.17791000"],["78652.00000000","0.02407000"],["78652.10000000","0.00000000"],["78652.11000000","0.00000000"]]}}}
{"rx_ns": 173330138116200, "frame": {"stream":"btcusdt@depth20@100ms","data":{"lastUpdateId":99076741076,"bids":[["78649.99000000","3.92143000"],["78649.98000000","0.00062000"],["78649.97000000","0.00013000"],["78649.96000000","0.00014000"],["78649.95000000","0.05007000"],["78649.91000000","0.00014000"],["78649.90000000","0.05007000"],["78649.65000000","0.00400000"],["78649.11000000","0.00007000"],["78648.88000000","0.00014000"],["78648.87000000","0.20832000"],["78648.74000000","0.00007000"],["78648.73000000","0.03784000"],["78648.61000000","0.00007000"],["78648.60000000","0.00007000"],["78648.32000000","0.00007000"],["78648.01000000","1.21959000"],["78648.00000000","0.32298000"],["78647.99000000","0.07735000"],["78647.80000000","0.00008000"]],"asks":[["78650.00000000","0.98345000"],["78650.01000000","0.00070000"],["78650.40000000","0.00014000"],["78650.41000000","0.21886000"],["78650.61000000","0.00021000"],["78650.62000000","0.20832000"],["78650.92000000","0.00007000"],["78651.22000000","0.00007000"],["78651.48000000","0.00007000"],["78651.49000000","0.00007000"],["78651.99000000","0.00014000"],["78652.00000000","0.02407000"],["78652.60000000","0.00014000"],["78652.61000000","0.05359000"],["78652.88000000","0.01550000"],["78652.96000000","0.00007000"],["78653.81000000","0.00007000"],["78653.88000000","0.00014000"],["78653.99000000","0.00014000"],["78654.00000000","0.02407000"]]}}}
{"rx_ns": 173330138201800, "frame": {"stream":"btcusdt@depth@100ms","data":{"e":"depthUpdate","E":1787603269314,"s":"BTCUSDT","U":99076740995,"u":99076741076,"b":[["78649.99000000","3.92143000"],["78649.98000000","0.00062000"],["78636.00000000","0.02400000"],["78634.00000000","0.02400000"],["78631.09000000","0.00000000"],["78627.57000000","0.00400000"],["78626.36000000","0.00007000"],["78256.74000000","0.01000000"],["77865.45000000","0.01000000"],["77476.12000000","0.01000000"],["77088.74000000","0.01000000"],["76703.30000000","0.01070000"],["76319.78000000","0.01000000"],["75938.18000000","0.01000000"],["75558.49000000","0.01000000"],["75180.70000000","0.01000000"],["74804.80000000","0.01000000"],["74430.77000000","0.01000000"],["74058.62000000","0.01000000"],["73688.33000000","0.01000000"],["73319.88000000","0.01000000"],["72953.29000000","0.01000000"],["70785.00000000","0.01722000"],["62920.00000000","0.00441000"]],"a":[["78650.00000000","0.98345000"],["78650.40000000","0.00014000"],["78650.41000000","0.21886000"],["78651.21000000","0.00000000"],["78651.22000000","0.00007000"],["78671.58000000","0.00007000"],["78673.56000000","0.00007000"],["79043.25000000","0.01000000"],["79438.47000000","0.01000000"],["79835.66000000","0.01000000"],["80234.84000000","0.01000000"],["80636.02000000","0.01000000"],["81039.20000000","0.01000000"],["81444.39000000","0.01000000"],["81851.61000000","0.01000000"],["82260.87000000","0.01000000"],["82672.18000000","0.01000000"],["83085.54000000","0.01000000"],["83500.96000000","0.01000000"],["83918.47000000","0.01000000"],["84338.06000000","0.01000000"],["84759.75000000","0.01000000"]]}}}
{"rx_ns": 173330243491100, "frame": {"stream":"btcusdt@depth20@100ms","data":{"lastUpdateId":99076741112,"bids":[["78649.99000000","3.92157000"],["78649.98000000","0.00062000"],["78649.97000000","0.00013000"],["78649.96000000","0.00014000"],["78649.95000000","0.05007000"],["78649.91000000","0.00014000"],["78649.90000000","0.05007000"],["78649.65000000","0.00400000"],["78649.11000000","0.00007000"],["78648.88000000","0.00014000"],["78648.87000000","0.20832000"],["78648.74000000","0.00007000"],["78648.73000000","0.03784000"],["78648.61000000","0.00007000"],["78648.60000000","0.00007000"],["78648.32000000","0.00007000"],["78648.01000000","1.21959000"],["78648.00000000","0.32298000"],["78647.99000000","0.07735000"],["78647.80000000","0.00008000"]],"asks":[["78650.00000000","0.99132000"],["78650.01000000","0.00070000"],["78650.40000000","0.00014000"],["78650.41000000","0.21893000"],["78650.61000000","0.00021000"],["78650.62000000","0.20818000"],["78650.92000000","0.00007000"],["78651.48000000","0.00007000"],["78651.49000000","0.00007000"],["78651.99000000","0.00014000"],["78652.00000000","0.02407000"],["78652.24000000","0.00007000"],["78652.60000000","0.00014000"],["78652.61000000","0.05359000"],["78652.88000000","0.01550000"],["78652.96000000","0.00007000"],["78653.81000000","0.00007000"],["78653.88000000","0.00014000"],["78653.99000000","0.00014000"],["78654.00000000","0.02407000"]]}}}
{"rx_ns": 173330243631600, "frame": {"stream":"btcusdt@depth@100ms","data":{"e":"depthUpdate","E":1787603269414,"s":"BTCUSDT","U":99076741077,"u":99076741112,"b":[["78649.99000000","3.92157000"],["78646.00000000","0.00707000"],["78644.01000000","0.00400000"],["78644.00000000","1.92215000"],["78642.88000000","0.02200000"],["78642.00000000","0.02400000"],["78640.00000000","0.11938000"],["78638.00000000","0.02407000"],["78628.36000000","0.00000000"],["78558.16000000","0.00000000"],["78537.46000000","0.00317000"],["78510.89000000","0.00406000"],["70785.00000000","0.01738000"]],"a":[["78650.00000000","0.99132000"],["78650.01000000","0.00070000"],["78650.41000000","0.21893000"],["78650.62000000","0.20818000"],["78651.22000000","0.00000000"],["78652.24000000","0.00007000"],["78664.05000000","0.00400000"],["78667.26000000","0.00650000"],["78684.00000000","0.94330000"],["78734.63000000","0.00000000"]]}}}
{"rx_ns": 173330337860300, "frame": {"stream":"btcusdt@depth20@100ms","data":{"lastUpdateId":99076741124,"bids":[["78649.99000000","3.94673000"],["78649.98000000","0.00062000"],["78649.97000000","0.00013000"],["78649.96000000","0.00014000"],["78649.95000000","0.05007000"],["78649.91000000","0.00014000"],["78649.90000000","0.05007000"],["78649.65000000","0.00400000"],["78649.11000000","0.00007000"],["78648.88000000","0.00014000"],["78648.87000000","0.20832000"],["78648.74000000","0.00007000"],["78648.73000000","0.03784000"],["78648.61000000","0.00007000"],["78648.60000000","0.00007000"],["78648.32000000","0.00007000"],["78648.01000000","1.21959000"],["78648.00000000","0.32298000"],["78647.99000000","0.07735000"],["78647.80000000","0.00008000"]],"asks":[["78650.00000000","0.98352000"],["78650.01000000","0.00070000"],["78650.40000000","0.00014000"],["78650.41000000","0.21893000"],["78650.61000000","0.00021000"],["78650.62000000","0.20818000"],["78650.92000000","0.00007000"],["78651.48000000","0.00007000"],["78651.49000000","0.00007000"],["78651.99000000","0.00014000"],["78652.00000000","0.02407000"],["78652.24000000","0.00007000"],["78652.60000000","0.00014000"],["78652.61000000","0.05359000"],["78652.88000000","0.01550000"],["78652.96000000","0.00007000"],["78653.81000000","0.00007000"],["78653.88000000","0.00014000"],["78653.99000000","0.00014000"],["78654.00000000","0.02407000"]]}}}
{"rx_ns": 173330337950800, "frame": {"stream":"btcusdt@depth@100ms","data":{"e":"depthUpdate","E":1787603269514,"s":"BTCUSDT","U":99076741113,"u":99076741124,"b":[["78649.99000000","3.94673000"],["78641.62000000","0.30317000"],["78629.74000000","0.34342000"],["78618.87000000","0.34347000"],["78572.17000000","0.02118000"],["70785.00000000","0.01738000"],["70784.00000000","0.00119000"],["62920.00000000","0.00472000"]],"a":[["78650.00000000","0.98352000"]]}}}
{"rx_ns": 173330440075900, "frame": {"stream":"btcusdt@depth20@100ms","data":{"lastUpdateId":99076741134,"bids":[["78649.99000000","3.95386000"],["78649.98000000","0.00062000"],["78649.97000000","0.00013000"],["78649.96000000","0.00014000"],["78649.95000000","0.05007000"],["78649.91000000","0.00014000"],["78649.90000000","0.05007000"],["78649.65000000","0.00400000"],["78649.11000000","0.00007000"],["78648.88000000","0.00014000"],["78648.87000000","0.20832000"],["78648.74000000","0.00007000"],["78648.73000000","0.03784000"],["78648.61000000","0.00007000"],["78648.60000000","0.00007000"],["78648.32000000","0.00007000"],["78648.01000000","1.21959000"],["78648.00000000","0.32298000"],["78647.99000000","0.07735000"],["78647.80000000","0.00008000"]],"asks":[["78650.00000000","0.98545000"],["78650.01000000","0.00083000"],["78650.02000000","0.00013000"],["78650.40000000","0.00014000"],["78650.41000000","0.21893000"],["78650.61000000","0.00021000"],["78650.62000000","0.20818000"],["78650.92000000","0.00007000"],["78651.48000000","0.00007000"],["78651.49000000","0.00007000"],["78651.99000000","0.00014000"],["78652.00000000","0.02407000"],["78652.24000000","0.00007000"],["78652.60000000","0.00014000"],["78652.61000000","0.05359000"],["78652.88000000","0.01550000"],["78652.96000000","0.00007000"],["78653.81000000","0.00007000"],["78653.88000000","0.00014000"],["78653.99000000","0.00014000"]]}}}
{"rx_ns": 173330440157400, "frame": {"stream":"btcusdt@depth@100ms","data":{"e":"depthUpdate","E":1787603269614,"s":"BTCUSDT","U":99076741125,"u":99076741134,"b":[["78649.99000000","3.95386000"],["78644.80000000","0.00007000"],["70785.00000000","0.01738000"],["62920.00000000","0.00441000"]],"a":[["78650.00000000","0.98545000"],["78650.01000000","0.00083000"],["78650.02000000","0.00013000"],["78749.36000000","0.00406000"]]}}}
{"rx_ns": 173330541332800, "frame": {"stream":"btcusdt@depth20@100ms","data":{"lastUpdateId":99076741147,"bids":[["78649.99000000","3.95386000"],["78649.98000000","0.00062000"],["78649.97000000","0.00013000"],["78649.96000000","0.00014000"],["78649.95000000","0.05007000"],["78649.91000000","0.00014000"],["78649.90000000","0.05007000"],["78649.65000000","0.00400000"],["78649.11000000","0.00007000"],["78648.88000000","0.00014000"],["78648.87000000","0.20832000"],["78648.74000000","0.00007000"],["78648.73000000","0.03784000"],["78648.61000000","0.00007000"],["78648.60000000","0.00007000"],["78648.32000000","0.00007000"],["78648.01000000","1.21959000"],["78648.00000000","0.32298000"],["78647.99000000","0.07735000"],["78647.80000000","0.00008000"]],"asks":[["78650.00000000","0.99152000"],["78650.01000000","0.00097000"],["78650.02000000","0.00013000"],["78650.40000000","0.00014000"],["78650.41000000","0.21893000"],["78650.61000000","0.00021000"],["78650.62000000","0.20818000"],["78650.92000000","0.00007000"],["78651.48000000","0.00007000"],["78651.49000000","0.00007000"],["78651.99000000","0.00014000"],["78652.00000000","0.02407000"],["78652.24000000","0.00007000"],["78652.60000000","0.00014000"],["78652.61000000","0.05359000"],["78652.88000000","0.01550000"],["78652.96000000","0.00007000"],["78653.81000000","0.00007000"],["78653.88000000","0.00014000"],["78654.00000000","0.02407000"]]}}}
{"rx_ns": 173330541416000, "frame": {"stream":"btcusdt@depth@100ms","data":{"e":"depthUpdate","E":1787603269714,"s":"BTCUSDT","U":99076741135,"u":99076741147,"b":[["78572.17000000","0.00000000"],["64107.56000000","0.00000000"]],"a":[["78650.00000000","0.99152000"],["78650.01000000","0.00097000"],["78650.02000000","0.00013000"],["78653.99000000","0.00000000"],["78660.38000000","0.00317000"],["78664.32000000","0.00325000"],["78671.74000000","0.07844000"]]}}}
{"rx_ns": 173330638084400, "frame": {"stream":"btcusdt@depth20@100ms","data":{"lastUpdateId":99076741186,"bids":[["78649.99000000","3.95386000"],["78649.98000000","0.00062000"],["78649.97000000","0.00013000"],["78649.96000000","0.00014000"],["78649.95000000","0.05007000"],["78649.91000000","0.00014000"],["78649.90000000","0.05007000"],["78649.65000000","0.00400000"],["78649.11000000","0.00007000"],["78648.88000000","0.00014000"],["78648.87000000","0.20832000"],["78648.74000000","0.00014000"],["78648.73000000","0.03784000"],["78648.61000000","0.00007000"],["78648.60000000","0.00007000"],["78648.32000000","0.00007000"],["78648.01000000","1.21959000"],["78648.00000000","0.32298000"],["78647.99000000","0.07735000"],["78647.80000000","0.00008000"]],"asks":[["78650.00000000","0.99152000"],["78650.01000000","0.00083000"],["78650.02000000","0.00013000"],["78650.40000000","0.00014000"],["78650.41000000","0.21893000"],["78650.61000000","0.00021000"],["78650.62000000","0.20818000"],["78650.92000000","0.00007000"],["78651.48000000","0.00007000"],["78651.49000000","0.00007000"],["78651.99000000","0.00014000"],["78652.00000000","0.02407000"],["78652.24000000","0.00007000"],["78652.60000000","0.00014000"],["78652.61000000","0.05359000"],["78652.88000000","0.01550000"],["78652.96000000","0.00007000"],["78653.81000000","0.00007000"],["78653.88000000","0.00014000"],["78653.99000000","0.00007000"]]}}}
{"rx_ns": 173330638225100, "frame": {"stream":"btcusdt@depth@100ms","data":{"e":"depthUpdate","E":1787603269814,"s":"BTCUSDT","U":99076741148,"u":99076741186,"b":[["78648.74000000","0.00014000"],["78256.74000000","0.00000000"],["77865.45000000","0.00000000"],["77476.12000000","0.00000000"],["77088.74000000","0.00000000"],["76703.30000000","0.00070000"],["76319.78000000","0.00000000"],["75938.18000000","0.00000000"],["75558.49000000","0.00000000"],["75180.70000000","0.00000000"],["74804.80000000","0.00000000"],["74430.77000000","0.00000000"],["74058.62000000","0.00000000"],["73688.33000000","0.00000000"],["73319.88000000","0.00000000"],["72953.29000000","0.00000000"],["70785.00000000","0.01754000"]],"a":[["78650.01000000","0.00083000"],["78653.99000000","0.00007000"],["78743.69000000","0.93649000"],["78867.37000000","0.00406000"],["79043.25000000","0.00000000"],["79438.47000000","0.00000000"],["79835.66000000","0.00000000"],["80234.84000000","0.00000000"],["80636.02000000","0.00000000"],["81039.20000000","0.00000000"],["81444.39000000","0.00000000"],["81851.61000000","0.00000000"],["82260.87000000","0.00000000"],["82672.18000000","0.00000000"],["83085.54000000","0.00000000"],["83500.96000000","0.00000000"],["83918.47000000","0.00000000"],["84338.06000000","0.00000000"],["84759.75000000","0.00000000"]]}}}
{"rx_ns": 173330741327700, "frame": {"stream":"btcusdt@depth20@100ms","data":{"lastUpdateId":99076741195,"bids":[["78649.99000000","3.95386000"],["78649.98000000","0.00062000"],["78649.97000000","0.00013000"],["78649.96000000","0.00014000"],["78649.95000000","0.05007000"],["78649.91000000","0.00014000"],["78649.90000000","0.05007000"],["78649.65000000","0.00400000"],["78649.11000000","0.00007000"],["78648.88000000","0.00014000"],["78648.87000000","0.20832000"],["78648.74000000","0.00014000"],["78648.73000000","0.03784000"],["78648.61000000","0.00007000"],["78648.60000000","0.00007000"],["78648.32000000","0.00007000"],["78648.01000000","1.21959000"],["78648.00000000","0.32298000"],["78647.99000000","0.07735000"],["78647.80000000","0.00008000"]],"asks":[["78650.00000000","0.98972000"],["78650.01000000","0.00083000"],["78650.02000000","0.00013000"],["78650.40000000","0.00014000"],["78650.41000000","0.21893000"],["78650.61000000","0.00021000"],["78650.62000000","0.20818000"],["78650.92000000","0.00007000"],["78651.48000000","0.00007000"],["78651.49000000","0.00007000"],["78651.99000000","0.00014000"],["78652.00000000","0.02407000"],["78652.24000000","0.00007000"],["78652.60000000","0.00014000"],["78652.61000000","0.05359000"],["78652.88000000","0.01550000"],["78652.96000000","0.00007000"],["78653.81000000","0.00007000"],["78653.88000000","0.00014000"],["78653.99000000","0.00007000"]]}}}
{"rx_ns": 173330741411600, "frame": {"stream":"btcusdt@depth@100ms","data":{"e":"depthUpdate","E":1787603269914,"s":"BTCUSDT","U":99076741187,"u":99076741195,"b":[["78623.84000000","0.02600000"],["78623.06000000","0.02800000"],["78623.04000000","0.02800000"],["70785.00000000","0.01754000"],["62919.99000000","0.00020000"]],"a":[["78650.00000000","0.98972000"]]}}}
{"rx_ns": 173330843437700, "frame": {"stream":"btcusdt@depth20@100ms","data":{"lastUpdateId":99076741208,"bids":[["78649.99000000","3.95386000"],["78649.98000000","0.00062000"],["78649.97000000","0.00013000"],["78649.96000000","0.00014000"],["78649.95000000","0.05007000"],["78649.91000000","0.00014000"],["78649.90000000","0.05007000"],["78649.65000000","0.00400000"],["78649.11000000","0.00007000"],["78648.88000000","0.00014000"],["78648.87000000","0.20832000"],["78648.74000000","0.00014000"],["78648.73000000","0.03784000"],["78648.61000000","0.00007000"],["78648.60000000","0.00007000"],["78648.32000000","0.00007000"],["78648.01000000","1.21959000"],["78648.00000000","0.32298000"],["78647.99000000","0.07735000"],["78647.80000000","0.00008000"]],"asks":[["78650.00000000","0.98972000"],["78650.01000000","0.00083000"],["78650.02000000","0.00013000"],["78650.40000000","0.00014000"],["78650.41000000","0.21893000"],["78650.61000000","0.00021000"],["78650.62000000","0.20818000"],["78650.92000000","0.00007000"],["78651.48000000","0.00007000"],["78651.49000000","0.00007000"],["78651.99000000","0.00014000"],["78652.00000000","0.02407000"],["78652.24000000","0.00007000"],["78652.60000000","0.00014000"],["78652.61000000","0.05359000"],["78652.88000000","0.01550000"],["78652.96000000","0.00007000"],["78653.81000000","0.00007000"],["78653.88000000","0.00014000"],["78653.99000000","0.00007000"]]}}}
{"rx_ns": 173330843518900, "frame": {"stream":"btcusdt@depth@100ms","data":{"e":"depthUpdate","E":1787603270014,"s":"BTCUSDT","U":99076741196,"u":99076741208,"b":[["78643.88000000","0.00254000"],["78623.93000000","0.02400000"],["78619.22000000","0.02000000"],["78589.52000000","0.00406000"],["78582.09000000","0.02400000"],["78502.31000000","1.52351000"],["70785.00000000","0.01770000"],["62920.00000000","0.00472000"],["62919.99000000","0.00000000"]],"a":[["78659.60000000","0.00254000"],["78670.05000000","0.00400000"],["78703.20000000","0.00000000"],["78801.17000000","1.52351000"]]}}}
{"rx_ns": 173330938621000, "frame": {"stream":"btcusdt@depth20@100ms","data":{"lastUpdateId":99076741244,"bids":[["78649.99000000","3.96107000"],["78649.98000000","0.00062000"],["78649.97000000","0.00013000"],["78649.96000000","0.00014000"],["78649.95000000","0.05007000"],["78649.91000000","0.00014000"],["78649.90000000","0.05007000"],["78649.65000000","0.00400000"],["78649.11000000","0.00007000"],["78648.88000000","0.00014000"],["78648.87000000","0.20832000"],["78648.74000000","0.00014000"],["78648.73000000","0.03784000"],["78648.61000000","0.00007000"],["78648.60000000","0.00007000"],["78648.32000000","0.00007000"],["78648.01000000","1.21959000"],["78648.00000000","0.32298000"],["78647.99000000","0.07735000"],["78647.80000000","0.00008000"]],"asks":[["78650.00000000","0.99090000"],["78650.01000000","0.00083000"],["78650.02000000","0.00013000"],["78650.40000000","0.00014000"],["78650.41000000","0.21893000"],["78650.61000000","0.00021000"],["78650.62000000","0.20818000"],["78650.92000000","0.00007000"],["78651.48000000","0.00007000"],["78651.49000000","0.00007000"],["78651.99000000","0.00014000"],["78652.00000000","0.02407000"],["78652.24000000","0.00007000"],["78652.60000000","0.00014000"],["78652.61000000","0.05359000"],["78652.88000000","0.01550000"],["78652.96000000","0.00007000"],["78653.81000000","0.00007000"],["78653.88000000","0.00014000"],["78653.99000000","0.00007000"]]}}}
{"rx_ns": 173330938699500, "frame": {"stream":"btcusdt@depth@100ms","data":{"e":"depthUpdate","E":1787603270114,"s":"BTCUSDT","U":99076741209,"u":99076741244,"b":[["78649.99000000","3.96107000"],["78644.01000000","0.00800000"],["78637.62000000","0.00007000"],["78634.27000000","0.00007000"],["78623.13000000","0.02200000"],["78620.78000000","0.02400000"],["78619.10000000","0.02000000"],["78598.14000000","0.00627000"],["78596.86000000","0.00434000"],["78582.09000000","0.00000000"],["78581.49000000","0.02200000"],["78461.24000000","0.00007000"],["78445.51000000","0.00007000"],["78429.78000000","0.00007000"],["78414.05000000","0.00007000"],["70785.00000000","0.01770000"]],"a":[["78650.00000000","0.99090000"],["78661.23000000","0.00007000"],["78695.18000000","0.00434000"],["78696.56000000","0.00627000"],["78744.38000000","0.00007000"],["78760.11000000","0.00007000"],["78775.84000000","0.00007000"],["78791.57000000","0.00007000"],["78807.30000000","0.00007000"],["78823.03000000","0.00007000"],["78838.76000000","0.00007000"],["78854.49000000","0.00007000"],["78870.22000000","0.00007000"],["78885.95000000","0.00007000"]]}}}
{"rx_ns": 173331038155300, "frame": {"stream":"btcusdt@depth20@100ms","data":{"lastUpdateId":99076741260,"bids":[["78649.99000000","3.96107000"],["78649.98000000","0.00062000"],["78649.97000000","0.00013000"],["78649.96000000","0.00014000"],["78649.95000000","0.05007000"],["78649.91000000","0.00014000"],["78649.90000000","0.05007000"],["78649.65000000","0.00400000"],["78649.11000000","0.00007000"],["78648.88000000","0.00014000"],["78648.87000000","0.20832000"],["78648.74000000","0.00014000"],["78648.73000000","0.03784000"],["78648.61000000","0.00007000"],["78648.60000000","0.00007000"],["78648.32000000","0.00007000"],["78648.01000000","1.21959000"],["78648.00000000","0.32298000"],["78647.99000000","0.07735000"],["78647.80000000","0.00008000"]],"asks":[["78650.00000000","0.98990000"],["78650.01000000","0.00083000"],["78650.02000000","0.00013000"],["78650.40000000","0.00014000"],["78650.41000000","0.21893000"],["78650.61000000","0.00021000"],["78650.62000000","0.20818000"],["78650.92000000","0.00007000"],["78651.48000000","0.00007000"],["78651.49000000","0.00007000"],["78651.99000000","0.00014000"],["78652.00000000","0.02407000"],["78652.24000000","0.00007000"],["78652.60000000","0.00014000"],["78652.61000000","0.05359000"],["78652.88000000","0.01550000"],["78652.96000000","0.00007000"],["78653.81000000","0.00007000"],["78653.88000000","0.00014000"],["78653.99000000","0.00007000"]]}}}
{"rx_ns": 173331038238800, "frame": {"stream":"btcusdt@depth@100ms","data":{"e":"depthUpdate","E":1787603270214,"s":"BTCUSDT","U":99076741245,"u":99076741260,"b":[["78644.01000000","0.01200000"],["78620.00000000","0.16096000"],["78619.11000000","0.02200000"],["78581.49000000","0.00000000"],["78578.32000000","0.00000000"],["78577.76000000","0.00007000"],["78573.57000000","0.00000000"],["70785.00000000","0.01786000"],["70781.40000000","0.00000000"],["70781.39000000","0.00009000"],["62920.00000000","0.00441000"]],"a":[["78650.00000000","0.98990000"],["78706.15000000","0.00007000"],["78717.88000000","0.00406000"],["78751.64000000","0.00529000"]]}}}
{"rx_ns": 173331140293200, "frame": {"stream":"btcusdt@depth20@100ms","data":{"lastUpdateId":99076741297,"bids":[["78649.99000000","3.96107000"],["78649.98000000","0.00062000"],["78649.97000000","0.00013000"],["78649.96000000","0.00014000"],["78649.95000000","0.05007000"],["78649.91000000","0.00014000"],["78649.90000000","0.05007000"],["78649.65000000","0.00400000"],["78649.11000000","0.00007000"],["78648.88000000","0.00014000"],["78648.87000000","0.20832000"],["78648.74000000","0.00014000"],["78648.73000000","0.03784000"],["78648.61000000","0.00007000"],["78648.60000000","0.00007000"],["78648.32000000","0.00007000"],["78648.01000000","1.21959000"],["78648.00000000","0.32298000"],["78647.99000000","0.07735000"],["78647.80000000","0.00008000"]],"asks":[["78650.00000000","0.98990000"],["78650.01000000","0.00083000"],["78650.02000000","0.00013000"],["78650.40000000","0.00014000"],["78650.41000000","0.21893000"],["78650.61000000","0.00021000"],["78650.62000000","0.20818000"],["78650.92000000","0.00007000"],["78651.48000000","0.00007000"],["78651.49000000","0.00007000"],["78651.99000000","0.00014000"],["78652.00000000","0.02407000"],["78652.24000000","0.00007000"],["78652.60000000","0.00014000"],["78652.61000000","0.05359000"],["78652.88000000","0.01550000"],["78652.96000000","0.00007000"],["78653.81000000","0.00007000"],["78653.88000000","0.00014000"],["78653.99000000","0.00007000"]]}}}
{"rx_ns": 173331140376600, "frame": {"stream":"btcusdt@depth@100ms","data":{"e":"depthUpdate","E":1787603270314,"s":"BTCUSDT","U":99076741261,"u":99076741297,"b":[["78644.02000000","0.00400000"],["78626.36000000","0.00000000"],["78569.67000000","0.00000000"],["78482.12000000","0.00000000"],["78475.47000000","0.00779000"],["78256.74000000","0.01000000"],["77865.45000000","0.01000000"],["77476.12000000","0.01000000"],["77088.74000000","0.01000000"],["76703.30000000","0.01070000"],["76319.78000000","0.01000000"],["75938.18000000","0.01000000"],["75558.49000000","0.01000000"],["75180.70000000","0.01000000"],["74804.80000000","0.01000000"],["74430.77000000","0.01000000"],["74058.62000000","0.01000000"],["73688.33000000","0.01000000"],["73319.88000000","0.01000000"],["72953.29000000","0.01000000"],["70785.00000000","0.01770000"],["62920.00000000","0.00441000"]],"a":[["78673.56000000","0.00000000"],["79043.25000000","0.01000000"],["79438.47000000","0.01000000"],["79835.66000000","0.01000000"],["80234.84000000","0.01000000"],["80636.02000000","0.01000000"],["81039.20000000","0.01000000"],["81444.39000000","0.01000000"],["81851.61000000","0.01000000"],["82260.87000000","0.01000000"],["82672.18000000","0.01000000"],["83085.54000000","0.01000000"],["83500.96000000","0.01000000"],["83918.47000000","0.01000000"],["84338.06000000","0.01000000"],["84759.75000000","0.01000000"]]}}}
{"rx_ns": 173331240216300, "frame": {"stream":"btcusdt@depth20@100ms","data":{"lastUpdateId":99076741313,"bids":[["78649.99000000","3.96107000"],["78649.98000000","0.00062000"],["78649.97000000","0.00013000"],["78649.96000000","0.00014000"],["78649.95000000","0.05007000"],["78649.91000000","0.00014000"],["78649.90000000","0.05007000"],["78649.65000000","0.00400000"],["78649.11000000","0.00007000"],["78648.88000000","0.00014000"],["78648.87000000","0.20832000"],["78648.74000000","0.00014000"],["78648.73000000","0.03784000"],["78648.61000000","0.00007000"],["78648.60000000","0.00007000"],["78648.32000000","0.00007000"],["78648.01000000","1.21959000"],["78648.00000000","0.32298000"],["78647.99000000","0.07735000"],["78647.80000000","0.00008000"]],"asks":[["78650.00000000","0.98990000"],["78650.01000000","0.00083000"],["78650.02000000","0.00013000"],["78650.40000000","0.00014000"],["78650.41000000","0.21893000"],["78650.61000000","0.00021000"],["78650.62000000","0.20818000"],["78650.92000000","0.00007000"],["78651.48000000","0.00007000"],["78651.49000000","0.00007000"],["78651.99000000","0.00014000"],["78652.00000000","0.02407000"],["78652.24000000","0.00007000"],["78652.60000000","0.00014000"],["78652.61000000","0.05359000"],["78652.88000000","0.01550000"],["78652.96000000","0.00007000"],["78653.81000000","0.00007000"],["78653.88000000","0.00014000"],["78653.99000000","0.00007000"]]}}}
{"rx_ns": 173331240324600, "frame": {"stream":"btcusdt@depth@100ms","data":{"e":"depthUpdate","E":1787603270414,"s":"BTCUSDT","U":99076741298,"u":99076741313,"b":[["78626.36000000","0.00007000"],["78578.25000000","0.00000000"],["78574.43000000","0.00000000"],["78440.13000000","0.00000000"],["70785.00000000","0.01802000"]],"a":[["78650.00000000","0.98990000"],["78673.56000000","0.00007000"],["78678.54000000","0.00000000"],["78717.88000000","0.00000000"],["78749.36000000","0.00000000"],["78796.56000000","0.00000000"],["78867.37000000","0.00000000"],["79019.86000000","0.01518000"],["79056.48000000","0.00000000"]]}}}
{"rx_ns": 173331338518400, "frame": {"stream":"btcusdt@depth20@100ms","data":{"lastUpdateId":99076741367,"bids":[["78649.99000000","3.96556000"],["78649.98000000","0.00020000"],["78649.97000000","0.00013000"],["78649.96000000","0.00014000"],["78649.95000000","0.05007000"],["78649.91000000","0.00014000"],["78649.90000000","0.05007000"],["78649.65000000","0.00400000"],["78649.11000000","0.00007000"],["78648.88000000","0.00014000"],["78648.87000000","0.20832000"],["78648.78000000","0.00007000"],["78648.77000000","0.03224000"],["78648.74000000","0.00014000"],["78648.73000000","0.03784000"],["78648.61000000","0.00007000"],["78648.60000000","0.00007000"],["78648.32000000","0.00007000"],["78648.01000000","1.21952000"],["78648.00000000","0.32298000"]],"asks":[["78650.00000000","0.53585000"],["78650.01000000","0.00076000"],["78650.02000000","0.00013000"],["78650.41000000","0.00007000"],["78650.61000000","0.00021000"],["78650.62000000","0.20818000"],["78650.92000000","0.00007000"],["78651.48000000","0.00007000"],["78651.49000000","0.00007000"],["78651.99000000","0.00014000"],["78652.00000000","0.02407000"],["78652.24000000","0.00007000"],["78652.60000000","0.00014000"],["78652.61000000","0.05359000"],["78652.87000000","0.00014000"],["78652.88000000","0.01550000"],["78652.96000000","0.00007000"],["78653.81000000","0.00007000"],["78653.88000000","0.00014000"],["78653.99000000","0.00007000"]]}}}
{"rx_ns": 173331338743900, "frame": {"stream":"btcusdt@depth@100ms","data":{"e":"depthUpdate","E":1787603270514,"s":"BTCUSDT","U":99076741314,"u":99076741367,"b":[["78649.99000000","3.96556000"],["78649.98000000","0.00020000"],["78648.78000000","0.00007000"],["78648.77000000","0.03224000"],["78648.01000000","1.21952000"],["78632.20000000","0.63578000"],["78628.75000000","0.00000000"],["78609.65000000","0.00000000"],["78575.21000000","0.00000000"],["78573.63000000","0.00000000"],["77500.00000000","13.63402000"],["72358.00000000","0.01396000"],["70785.00000000","0.01802000"],["62920.00000000","0.00472000"]],"a":[["78650.00000000","0.53585000"],["78650.01000000","0.00076000"],["78650.40000000","0.00000000"],["78650.41000000","0.00007000"],["78652.87000000","0.00014000"],["78658.02000000","0.00000000"],["78658.06000000","0.00000000"],["78661.99000000","0.00000000"],["78662.60000000","0.31789000"],["78700.00000000","0.03607000"],["78700.65000000","0.00000000"]]}}}
{"rx_ns": 173331444440300, "frame": {"stream":"btcusdt@depth20@100ms","data":{"lastUpdateId":99076741390,"bids":[["78649.99000000","3.96556000"],["78649.98000000","0.00020000"],["78649.97000000","0.00013000"],["78649.96000000","0.00014000"],["78649.95000000","0.05007000"],["78649.91000000","0.00014000"],["78649.90000000","0.05007000"],["78649.65000000","0.00400000"],["78649.11000000","0.00007000"],["78648.88000000","0.00014000"],["78648.87000000","0.20825000"],["78648.78000000","0.00007000"],["78648.77000000","0.03224000"],["78648.74000000","0.00014000"],["78648.73000000","0.03784000"],["78648.61000000","0.00007000"],["78648.60000000","0.00007000"],["78648.32000000","0.00007000"],["78648.01000000","1.21952000"],["78648.00000000","0.32298000"]],"asks":[["78650.00000000","0.20217000"],["78650.01000000","0.00076000"],["78650.02000000","0.00013000"],["78650.61000000","0.00021000"],["78650.62000000","0.20825000"],["78650.92000000","0.00007000"],["78651.48000000","0.00007000"],["78651.49000000","0.00007000"],["78651.99000000","0.00014000"],["78652.00000000","0.02407000"],["78652.24000000","0.00007000"],["78652.60000000","0.00014000"],["78652.61000000","0.05359000"],["78652.87000000","0.00014000"],["78652.88000000","0.01550000"],["78652.96000000","0.00007000"],["78653.81000000","0.00007000"],["78653.88000000","0.00014000"],["78653.99000000","0.00007000"],["78654.00000000","0.02407000"]]}}}
{"rx_ns": 173331444522700, "frame": {"stream":"btcusdt@depth@100ms","data":{"e":"depthUpdate","E":1787603270614,"s":"BTCUSDT","U":99076741368,"u":99076741390,"b":[["78648.87000000","0.20825000"],["78647.55000000","0.00400000"],["78609.92000000","0.00000000"],["70785.00000000","0.01802000"],["70784.00000000","0.00119000"],["62920.00000000","0.00441000"]],"a":[["78650.00000000","0.20217000"],["78650.41000000","0.00000000"],["78650.62000000","0.20825000"],["78656.00000000","0.02407000"],["78658.99000000","0.00000000"],["78660.37000000","0.00508000"],["78661.72000000","0.00400000"],["78704.11000000","0.00007000"],["78745.33000000","0.00406000"],["86514.99000000","0.00000000"]]}}}
{"rx_ns": 173331543914600, "frame": {"stream":"btcusdt@depth20@100ms","data":{"lastUpdateId":99076741404,"bids":[["78649.99000000","3.96556000"],["78649.98000000","0.00020000"],["78649.97000000","0.00013000"],["78649.96000000","0.00014000"],["78649.95000000","0.05007000"],["78649.91000000","0.00014000"],["78649.90000000","0.05007000"],["78649.65000000","0.00400000"],["78649.11000000","0.00007000"],["78648.88000000","0.00014000"],["78648.87000000","0.20825000"],["78648.78000000","0.00007000"],["78648.77000000","0.03224000"],["78648.74000000","0.00014000"],["78648.73000000","0.03784000"],["78648.61000000","0.00007000"],["78648.60000000","0.00007000"],["78648.32000000","0.00007000"],["78648.01000000","1.21952000"],["78648.00000000","0.32298000"]],"asks":[["78650.00000000","0.20810000"],["78650.01000000","0.00076000"],["78650.02000000","0.00013000"],["78650.61000000","0.00021000"],["78650.62000000","0.20825000"],["78650.92000000","0.00007000"],["78651.48000000","0.00007000"],["78651.49000000","0.00007000"],["78651.99000000","0.00014000"],["78652.00000000","0.02407000"],["78652.24000000","0.00007000"],["78652.60000000","0.00014000"],["78652.61000000","0.05366000"],["78652.87000000","0.00014000"],["78652.88000000","0.01550000"],["78652.96000000","0.00007000"],["78653.78000000","0.16420000"],["78653.81000000","0.00007000"],["78653.88000000","0.00014000"],["78653.99000000","0.00007000"]]}}}
{"rx_ns": 173331543994600, "frame": {"stream":"btcusdt@depth@100ms","data":{"e":"depthUpdate","E":1787603270714,"s":"BTCUSDT","U":99076741391,"u":99076741404,"b":[["78644.77000000","0.00254000"],["78643.88000000","0.00000000"],["78640.83000000","0.00000000"],["78480.71000000","0.00779000"],["78475.47000000","0.00000000"],["70785.00000000","0.01834000"]],"a":[["78650.00000000","0.20810000"],["78652.61000000","0.05366000"],["78653.78000000","0.16420000"],["78659.39000000","0.00070000"],["78659.60000000","0.00000000"],["78660.49000000","0.00254000"]]}}}
{"rx_ns": 173331638146500, "frame": {"stream":"btcusdt@depth20@100ms","data":{"lastUpdateId":99076741442,"bids":[["78649.99000000","3.96556000"],["78649.98000000","0.00020000"],["78649.97000000","0.00013000"],["78649.96000000","0.00014000"],["78649.95000000","0.05007000"],["78649.91000000","0.00014000"],["78649.90000000","0.05007000"],["78649.65000000","0.00400000"],["78649.11000000","0.00007000"],["78648.88000000","0.00014000"],["78648.87000000","0.20825000"],["78648.78000000","0.00007000"],["78648.77000000","0.03224000"],["78648.74000000","0.00014000"],["78648.73000000","0.03784000"],["78648.61000000","0.00007000"],["78648.60000000","0.00007000"],["78648.32000000","0.00007000"],["78648.01000000","1.21952000"],["78648.00000000","0.32298000"]],"asks":[["78650.00000000","0.20810000"],["78650.01000000","0.00076000"],["78650.02000000","0.00013000"],["78650.61000000","0.00021000"],["78650.62000000","0.20825000"],["78650.92000000","0.00007000"],["78651.48000000","0.00007000"],["78651.49000000","0.00007000"],["78651.99000000","0.00014000"],["78652.00000000","0.02407000"],["78652.24000000","0.00007000"],["78652.60000000","0.00014000"],["78652.61000000","0.05366000"],["78652.87000000","0.00014000"],["78652.88000000","0.01550000"],["78652.96000000","0.00007000"],["78653.78000000","0.16427000"],["78653.81000000","0.00007000"],["78653.88000000","0.00014000"],["78653.99000000","0.00007000"]]}}}
{"rx_ns": 173331638237100, "frame": {"stream":"btcusdt@depth@100ms","data":{"e":"depthUpdate","E":1787603270814,"s":"BTCUSDT","U":99076741405,"u":99076741442,"b":[["78641.51000000","0.12721000"],["78256.74000000","0.00000000"],["77865.45000000","0.00000000"],["77476.12000000","0.00000000"],["77088.74000000","0.00000000"],["76703.30000000","0.00070000"],["76319.78000000","0.00000000"],["75938.18000000","0.00000000"],["75558.49000000","0.00000000"],["75180.70000000","0.00000000"],["74804.80000000","0.00000000"],["74430.77000000","0.00000000"],["74058.62000000","0.00000000"],["73688.33000000","0.00000000"],["73319.88000000","0.00000000"],["72953.29000000","0.00000000"],["70785.00000000","0.01834000"]],"a":[["78652.88000000","0.01550000"],["78653.78000000","0.16427000"],["78656.00000000","0.02400000"],["78863.34000000","0.00406000"],["79043.25000000","0.00000000"],["79438.47000000","0.00000000"],["79835.66000000","0.00000000"],["80234.84000000","0.00000000"],["80636.02000000","0.00000000"],["81039.20000000","0.00000000"],["81444.39000000","0.00000000"],["81851.61000000","0.00000000"],["82260.87000000","0.00000000"],["82672.18000000","0.00000000"],["83085.54000000","0.00000000"],["83500.96000000","0.00000000"],["83918.47000000","0.00000000"],["84338.06000000","0.00000000"],["84759.75000000","0.00000000"]]}}}
{"rx_ns": 173331739331100, "frame": {"stream":"btcusdt@depth20@100ms","data":{"lastUpdateId":99076741480,"bids":[["78649.99000000","3.96556000"],["78649.98000000","0.00020000"],["78649.97000000","0.00013000"],["78649.96000000","0.00014000"],["78649.95000000","0.05007000"],["78649.91000000","0.00014000"],["78649.90000000","0.05007000"],["78649.65000000","0.00400000"],["78649.11000000","0.00007000"],["78648.88000000","0.00014000"],["78648.87000000","0.20825000"],["78648.78000000","0.00007000"],["78648.77000000","0.03224000"],["78648.74000000","0.00014000"],["78648.73000000","0.03784000"],["78648.61000000","0.00007000"],["78648.60000000","0.00007000"],["78648.32000000","0.00007000"],["78648.01000000","1.21952000"],["78648.00000000","0.32298000"]],"asks":[["78650.00000000","0.20231000"],["78650.01000000","0.00090000"],["78650.02000000","0.00013000"],["78650.61000000","0.00021000"],["78650.62000000","0.20832000"],["78650.92000000","0.00007000"],["78651.48000000","0.00007000"],["78651.49000000","0.00007000"],["78651.99000000","0.00014000"],["78652.00000000","0.02407000"],["78652.24000000","0.00007000"],["78652.60000000","0.00014000"],["78652.61000000","0.05366000"],["78652.88000000","0.01550000"],["78652.96000000","0.00007000"],["78653.77000000","0.00007000"],["78653.78000000","0.16427000"],["78653.81000000","0.00007000"],["78653.88000000","0.00014000"],["78654.00000000","0.02407000"]]}}}
{"rx_ns": 173331739423600, "frame": {"stream":"btcusdt@depth@100ms","data":{"e":"depthUpdate","E":1787603270914,"s":"BTCUSDT","U":99076741443,"u":99076741480,"b":[["78641.69000000","0.00000000"],["78641.58000000","0.00000000"],["78641.51000000","0.00000000"],["78618.39000000","0.09463000"],["78572.17000000","0.02118000"],["70785.00000000","0.01834000"]],"a":[["78650.00000000","0.20231000"],["78650.01000000","0.00090000"],["78650.62000000","0.20832000"],["78650.76000000","0.00000000"],["78650.82000000","0.00000000"],["78650.92000000","0.00007000"],["78650.93000000","0.00000000"],["78652.87000000","0.00000000"],["78653.77000000","0.00007000"],["78653.99000000","0.00000000"],["78660.38000000","0.00000000"],["78677.74000000","0.00000000"]]}}}
{"rx_ns": 173331838758100, "frame": {"stream":"btcusdt@depth20@100ms","data":{"lastUpdateId":99076741523,"bids":[["78649.99000000","3.96556000"],["78649.98000000","0.00020000"],["78649.97000000","0.00013000"],["78649.96000000","0.00014000"],["78649.95000000","0.05007000"],["78649.91000000","0.00014000"],["78649.90000000","0.05007000"],["78649.65000000","0.00400000"],["78649.11000000","0.00007000"],["78648.88000000","0.00014000"],["78648.87000000","0.20825000"],["78648.78000000","0.00007000"],["78648.77000000","0.03224000"],["78648.74000000","0.00014000"],["78648.73000000","0.03784000"],["78648.61000000","0.00007000"],["78648.60000000","0.00007000"],["78648.32000000","0.00007000"],["78648.01000000","1.21952000"],["78648.00000000","0.32298000"]],"asks":[["78650.00000000","0.28058000"],["78650.01000000","0.00083000"],["78650.02000000","0.00013000"],["78650.61000000","0.00021000"],["78650.62000000","0.20825000"],["78650.92000000","0.00007000"],["78651.48000000","0.00007000"],["78651.49000000","0.00007000"],["78651.99000000","0.00014000"],["78652.00000000","0.02407000"],["78652.24000000","0.00007000"],["78652.60000000","0.00014000"],["78652.61000000","0.05366000"],["78652.87000000","0.00014000"],["78652.88000000","0.01550000"],["78652.94000000","0.20777000"],["78652.96000000","0.00007000"],["78653.77000000","0.00007000"],["78653.78000000","0.00007000"],["78653.88000000","0.00014000"]]}}}
{"rx_ns": 173331838869600, "frame": {"stream":"btcusdt@depth@100ms","data":{"e":"depthUpdate","E":1787603271014,"s":"BTCUSDT","U":99076741481,"u":99076741523,"b":[["78641.38000000","0.00000000"],["78641.29000000","0.00000000"],["78572.17000000","0.00000000"],["78482.12000000","0.00779000"],["78480.71000000","0.00000000"],["72358.00000000","0.01405000"],["70785.00000000","0.01850000"],["62920.00000000","0.00472000"],["62919.99000000","0.00000000"]],"a":[["78650.00000000","0.28058000"],["78650.01000000","0.00083000"],["78650.54000000","0.00000000"],["78650.55000000","0.00000000"],["78650.62000000","0.20825000"],["78650.68000000","0.00000000"],["78652.87000000","0.00014000"],["78652.94000000","0.20777000"],["78653.78000000","0.00007000"],["78653.81000000","0.00000000"],["78656.80000000","0.00275000"],["78656.84000000","0.01375000"],["78665.73000000","0.10858000"],["78792.54000000","0.00406000"]]}}}
{"rx_ns": 173331938227700, "frame": {"stream":"btcusdt@depth20@100ms","data":{"lastUpdateId":99076741562,"bids":[["78649.99000000","3.70802000"],["78649.98000000","0.00020000"],["78649.97000000","0.00013000"],["78649.96000000","0.00014000"],["78649.95000000","0.05007000"],["78649.91000000","0.00014000"],["78649.90000000","0.05007000"],["78649.65000000","0.00400000"],["78649.11000000","0.00007000"],["78648.88000000","0.00014000"],["78648.87000000","0.20832000"],["78648.78000000","0.00007000"],["78648.77000000","0.03231000"],["78648.74000000","0.00014000"],["78648.73000000","0.03791000"],["78648.61000000","0.00007000"],["78648.60000000","0.00007000"],["78648.32000000","0.00007000"],["78648.01000000","1.21959000"],["78648.00000000","0.32298000"]],"asks":[["78650.00000000","0.72855000"],["78650.01000000","0.00083000"],["78650.02000000","0.00013000"],["78650.61000000","0.00021000"],["78650.62000000","0.20825000"],["78650.92000000","0.00007000"],["78651.48000000","0.00007000"],["78651.49000000","0.00007000"],["78651.99000000","0.00014000"],["78652.00000000","0.02407000"],["78652.24000000","0.00007000"],["78652.60000000","0.00014000"],["78652.61000000","0.05366000"],["78652.87000000","0.00014000"],["78652.88000000","0.01550000"],["78652.93000000","0.00007000"],["78652.94000000","0.20784000"],["78652.96000000","0.00007000"],["78653.88000000","0.00014000"],["78654.00000000","0.02407000"]]}}}
{"rx_ns": 173331938316000, "frame": {"stream":"btcusdt@depth@100ms","data":{"e":"depthUpdate","E":1787603271114,"s":"BTCUSDT","U":99076741524,"u":99076741562,"b":[["78649.99000000","3.70802000"],["78648.87000000","0.20832000"],["78648.77000000","0.03231000"],["78648.73000000","0.03791000"],["78648.01000000","1.21959000"],["78641.16000000","0.00000000"],["78637.13000000","0.00000000"],["78632.20000000","0.00000000"],["78631.12000000","0.63577000"],["72358.00000000","0.01391000"],["70785.00000000","0.01866000"],["70781.39000000","0.00000000"]],"a":[["78650.00000000","0.72855000"],["78650.01000000","0.00083000"],["78652.61000000","0.05366000"],["78652.88000000","0.01550000"],["78652.93000000","0.00007000"],["78652.94000000","0.20784000"],["78653.77000000","0.00000000"],["78653.78000000","0.00000000"],["78659.39000000","0.00000000"]]}}}
{"rx_ns": 173332038277500, "frame": {"stream":"btcusdt@depth20@100ms","data":{"lastUpdateId":99076741575,"bids":[["78649.99000000","3.71129000"],["78649.98000000","0.00020000"],["78649.97000000","0.00013000"],["78649.96000000","0.00014000"],["78649.95000000","0.05007000"],["78649.91000000","0.00014000"],["78649.90000000","0.05007000"],["78649.65000000","0.00400000"],["78649.11000000","0.00007000"],["78648.88000000","0.00014000"],["78648.87000000","0.20832000"],["78648.78000000","0.00007000"],["78648.77000000","0.03231000"],["78648.74000000","0.00014000"],["78648.73000000","0.03791000"],["78648.61000000","0.00007000"],["78648.60000000","0.00007000"],["78648.32000000","0.00007000"],["78648.01000000","1.21959000"],["78648.00000000","0.32298000"]],"asks":[["78650.00000000","0.72867000"],["78650.01000000","0.00083000"],["78650.02000000","0.00013000"],["78650.61000000","0.00021000"],["78650.62000000","0.20825000"],["78650.69000000","0.12721000"],["78650.92000000","0.00007000"],["78651.48000000","0.00007000"],["78651.49000000","0.00007000"],["78651.99000000","0.00014000"],["78652.00000000","0.02407000"],["78652.24000000","0.00007000"],["78652.60000000","0.00014000"],["78652.61000000","0.05366000"],["78652.87000000","0.00014000"],["78652.88000000","0.01550000"],["78652.93000000","0.00007000"],["78652.94000000","0.20784000"],["78652.96000000","0.00007000"],["78653.88000000","0.00014000"]]}}}
{"rx_ns": 173332038397700, "frame": {"stream":"btcusdt@depth@100ms","data":{"e":"depthUpdate","E":1787603271214,"s":"BTCUSDT","U":99076741563,"u":99076741575,"b":[["78649.99000000","3.71129000"],["78644.00000000","1.92915000"],["78641.39000000","0.12721000"],["78440.05000000","0.00406000"],["70785.00000000","0.01866000"],["62920.00000000","0.00441000"]],"a":[["78650.00000000","0.72867000"],["78650.41000000","0.00000000"],["78650.69000000","0.12721000"],["78708.20000000","0.00007000"],["78913.43000000","0.00030000"]]}}}
{"rx_ns": 173332150921400, "frame": {"stream":"btcusdt@depth20@100ms","data":{"lastUpdateId":99076741639,"bids":[["78649.99000000","3.71129000"],["78649.98000000","0.00020000"],["78649.97000000","0.00013000"],["78649.96000000","0.00014000"],["78649.95000000","0.05007000"],["78649.91000000","0.00014000"],["78649.90000000","0.05007000"],["78649.65000000","0.00400000"],["78649.11000000","0.00007000"],["78648.88000000","0.00014000"],["78648.87000000","0.20832000"],["78648.78000000","0.00007000"],["78648.77000000","0.03231000"],["78648.74000000","0.00014000"],["78648.73000000","0.03791000"],["78648.61000000","0.00007000"],["78648.60000000","0.00007000"],["78648.32000000","0.00007000"],["78648.01000000","1.21959000"],["78648.00000000","0.32298000"]],"asks":[["78650.00000000","0.72867000"],["78650.01000000","0.00083000"],["78650.02000000","0.00013000"],["78650.61000000","0.00021000"],["78650.62000000","0.20832000"],["78650.69000000","0.00007000"],["78650.92000000","0.00007000"],["78651.48000000","0.00007000"],["78651.49000000","0.00007000"],["78651.99000000","0.00014000"],["78652.00000000","0.02407000"],["78652.24000000","0.00007000"],["78652.60000000","0.00014000"],["78652.61000000","0.05366000"],["78652.87000000","0.00014000"],["78652.88000000","0.01550000"],["78652.93000000","0.00007000"],["78652.94000000","0.20784000"],["78652.96000000","0.00007000"],["78653.88000000","0.00014000"]]}}}
{"rx_ns": 173332151003500, "frame": {"stream":"btcusdt@depth@100ms","data":{"e":"depthUpdate","E":1787603271314,"s":"BTCUSDT","U":99076741576,"u":99076741639,"b":[["78641.39000000","0.00000000"],["78641.26000000","0.00000000"],["78256.74000000","0.01000000"],["77865.45000000","0.01000000"],["77476.12000000","0.01000000"],["77088.74000000","0.01000000"],["76703.30000000","0.01070000"],["76319.78000000","0.01000000"],["75938.18000000","0.01000000"],["75558.49000000","0.01000000"],["75180.70000000","0.01000000"],["74804.80000000","0.01000000"],["74430.77000000","0.01000000"],["74058.62000000","0.01000000"],["73688.33000000","0.01000000"],["73319.88000000","0.01000000"],["72953.29000000","0.01000000"],["70785.00000000","0.01882000"],["62920.00000000","0.00441000"]],"a":[["78650.00000000","0.72867000"],["78650.62000000","0.20832000"],["78650.68000000","0.00000000"],["78650.69000000","0.00007000"],["78650.72000000","0.00000000"],["78650.73000000","0.00000000"],["78652.87000000","0.00014000"],["78655.40000000","0.03087000"],["79043.25000000","0.01000000"],["79438.47000000","0.01000000"],["79835.66000000","0.01000000"],["80234.84000000","0.01000000"],["80636.02000000","0.01000000"],["81039.20000000","0.01000000"],["81444.39000000","0.01000000"],["81851.61000000","0.01000000"],["82260.87000000","0.01000000"],["82672.18000000","0.01000000"],["83085.54000000","0.01000000"],["83500.96000000","0.01000000"],["83918.47000000","0.01000000"],["84338.06000000","0.01000000"],["84759.75000000","0.01000000"]]}}}
{"rx_ns": 173332243230800, "frame": {"stream":"btcusdt@depth20@100ms","data":{"lastUpdateId":99076741658,"bids":[["78649.99000000","3.71129000"],["78649.98000000","0.00020000"],["78649.97000000","0.00013000"],["78649.96000000","0.00014000"],["78649.95000000","0.05007000"],["78649.91000000","0.00014000"],["78649.90000000","0.05007000"],["78649.65000000","0.00400000"],["78649.11000000","0.00007000"],["78648.88000000","0.00014000"],["78648.87000000","0.20832000"],["78648.78000000","0.00007000"],["78648.77000000","0.03231000"],["78648.74000000","0.00014000"],["78648.73000000","0.03791000"],["78648.61000000","0.00007000"],["78648.60000000","0.00007000"],["78648.32000000","0.00007000"],["78648.01000000","1.21959000"],["78648.00000000","0.32298000"]],"asks":[["78650.00000000","0.72879000"],["78650.01000000","0.00083000"],["78650.02000000","0.00013000"],["78650.61000000","0.00021000"],["78650.62000000","0.20825000"],["78650.92000000","0.00007000"],["78651.48000000","0.00007000"],["78651.49000000","0.00007000"],["78651.99000000","0.00014000"],["78652.00000000","0.02407000"],["78652.24000000","0.00007000"],["78652.60000000","0.00014000"],["78652.61000000","0.05366000"],["78652.87000000","0.00014000"],["78652.88000000","0.01550000"],["78652.93000000","0.00007000"],["78652.94000000","0.20784000"],["78652.96000000","0.00007000"],["78653.88000000","0.00014000"],["78654.00000000","0.02407000"]]}}}
{"rx_ns": 173332243328400, "frame": {"stream":"btcusdt@depth@100ms","data":{"e":"depthUpdate","E":1787603271414,"s":"BTCUSDT","U":99076741640,"u":99076741658,"b":[["78626.36000000","0.00007000"],["78600.35000000","0.04769000"],["78572.17000000","0.02118000"],["78563.80000000","0.00000000"],["78271.38000000","0.00000000"],["78246.77000000","0.01526000"],["70785.00000000","0.01882000"]],"a":[["78650.00000000","0.72879000"],["78650.62000000","0.20825000"],["78650.69000000","0.00000000"],["78655.40000000","0.03094000"],["78673.56000000","0.00007000"],["78677.90000000","0.09551000"],["78713.86000000","0.00406000"]]}}}
{"rx_ns": 173332338735700, "frame": {"stream":"btcusdt@depth20@100ms","data":{"lastUpdateId":99076741670,"bids":[["78649.99000000","3.71129000"],["78649.98000000","0.00020000"],["78649.97000000","0.00013000"],["78649.96000000","0.00014000"],["78649.95000000","0.05007000"],["78649.91000000","0.00014000"],["78649.90000000","0.05007000"],["78649.65000000","0.00400000"],["78649.11000000","0.00007000"],["78648.88000000","0.00014000"],["78648.87000000","0.20832000"],["78648.78000000","0.00007000"],["78648.77000000","0.03231000"],["78648.74000000","0.00014000"],["78648.73000000","0.03791000"],["78648.61000000","0.00007000"],["78648.60000000","0.00007000"],["78648.32000000","0.00007000"],["78648.01000000","1.21959000"],["78648.00000000","0.32298000"]],"asks":[["78650.00000000","0.27444000"],["78650.01000000","0.00083000"],["78650.02000000","0.00013000"],["78650.61000000","0.00021000"],["78650.62000000","0.20825000"],["78650.92000000","0.00007000"],["78651.48000000","0.00007000"],["78651.49000000","0.00007000"],["78651.99000000","0.00014000"],["78652.00000000","0.02407000"],["78652.24000000","0.00007000"],["78652.60000000","0.00014000"],["78652.61000000","0.05366000"],["78652.87000000","0.00014000"],["78652.88000000","0.01550000"],["78652.93000000","0.00007000"],["78652.94000000","0.20784000"],["78652.96000000","0.00007000"],["78653.88000000","0.00014000"],["78654.00000000","0.02407000"]]}}}
{"rx_ns": 173332338882400, "frame": {"stream":"btcusdt@depth@100ms","data":{"e":"depthUpdate","E":1787603271514,"s":"BTCUSDT","U":99076741659,"u":99076741670,"b":[["78572.17000000","0.00000000"],["70785.00000000","0.01898000"],["62920.00000000","0.00472000"]],"a":[["78650.00000000","0.27444000"],["78659.61000000","0.00069000"]]}}}
{"rx_ns": 173332438095000, "frame": {"stream":"btcusdt@depth20@100ms","data":{"lastUpdateId":99076741679,"bids":[["78649.99000000","3.71129000"],["78649.98000000","0.00020000"],["78649.97000000","0.00013000"],["78649.96000000","0.00014000"],["78649.95000000","0.05007000"],["78649.91000000","0.00014000"],["78649.90000000","0.05007000"],["78649.65000000","0.00400000"],["78649.11000000","0.00007000"],["78648.88000000","0.00014000"],["78648.87000000","0.20832000"],["78648.78000000","0.00007000"],["78648.77000000","0.03231000"],["78648.74000000","0.00014000"],["78648.73000000","0.03791000"],["78648.61000000","0.00007000"],["78648.60000000","0.00007000"],["78648.32000000","0.00007000"],["78648.01000000","1.21959000"],["78648.00000000","0.32298000"]],"asks":[["78650.00000000","0.27444000"],["78650.01000000","0.00083000"],["78650.02000000","0.00013000"],["78650.61000000","0.00021000"],["78650.62000000","0.20825000"],["78650.92000000","0.00007000"],["78651.48000000","0.00007000"],["78651.49000000","0.00007000"],["78651.99000000","0.00014000"],["78652.00000000","0.02407000"],["78652.24000000","0.00007000"],["78652.60000000","0.00014000"],["78652.61000000","0.05366000"],["78652.87000000","0.00014000"],["78652.88000000","0.01550000"],["78652.93000000","0.00007000"],["78652.94000000","0.20784000"],["78652.96000000","0.00007000"],["78653.88000000","0.00014000"],["78654.00000000","0.02407000"]]}}}
{"rx_ns": 173332438170200, "frame": {"stream":"btcusdt@depth@100ms","data":{"e":"depthUpdate","E":1787603271614,"s":"BTCUSDT","U":99076741671,"u":99076741679,"b":[["78440.05000000","0.00000000"],["62920.00000000","0.00441000"]],"a":[["78674.52000000","0.00000000"],["78700.01000000","0.00007000"],["78713.86000000","0.00000000"],["78745.33000000","0.00000000"],["78792.54000000","0.00000000"],["78863.34000000","0.00000000"]]}}}
{"rx_ns": 173332538205400, "frame": {"stream":"btcusdt@depth20@100ms","data":{"lastUpdateId":99076741699,"bids":[["78649.99000000","3.95530000"],["78649.98000000","0.00020000"],["78649.97000000","0.00013000"],["78649.96000000","0.00014000"],["78649.95000000","0.05007000"],["78649.91000000","0.00014000"],["78649.90000000","0.05007000"],["78649.65000000","0.00400000"],["78649.11000000","0.00007000"],["78648.88000000","0.00014000"],["78648.87000000","0.20832000"],["78648.78000000","0.00007000"],["78648.77000000","0.03231000"],["78648.74000000","0.00014000"],["78648.73000000","0.03791000"],["78648.61000000","0.00007000"],["78648.60000000","0.00007000"],["78648.32000000","0.00007000"],["78648.01000000","1.21959000"],["78648.00000000","0.32298000"]],"asks":[["78650.00000000","0.27451000"],["78650.01000000","0.00083000"],["78650.02000000","0.00013000"],["78650.37000000","0.00014000"],["78650.61000000","0.00021000"],["78650.62000000","0.20825000"],["78650.92000000","0.00007000"],["78651.48000000","0.00007000"],["78651.49000000","0.00007000"],["78651.99000000","0.00014000"],["78652.00000000","0.02407000"],["78652.24000000","0.00007000"],["78652.60000000","0.00014000"],["78652.61000000","0.05366000"],["78652.88000000","0.01550000"],["78652.93000000","0.00007000"],["78652.94000000","0.20784000"],["78652.96000000","0.00007000"],["78653.88000000","0.00014000"],["78654.00000000","0.02407000"]]}}}
{"rx_ns": 173332538295200, "frame": {"stream":"btcusdt@depth@100ms","data":{"e":"depthUpdate","E":1787603271714,"s":"BTCUSDT","U":99076741680,"u":99076741699,"b":[["78649.99000000","3.95530000"],["78641.20000000","0.00000000"],["78550.57000000","2.77418000"],["78521.86000000","0.00000000"],["70785.00000000","0.01914000"],["70784.00000000","0.00119000"],["68000.00000000","44.99541000"]],"a":[["78650.00000000","0.27451000"],["78650.37000000","0.00014000"],["78650.38000000","0.00000000"],["78652.87000000","0.00000000"],["78743.69000000","0.00000000"]]}}}
{"rx_ns": 173332638406300, "frame": {"stream":"btcusdt@depth20@100ms","data":{"lastUpdateId":99076741739,"bids":[["78649.99000000","3.95530000"],["78649.98000000","0.00020000"],["78649.97000000","0.00013000"],["78649.96000000","0.00014000"],["78649.95000000","0.05007000"],["78649.91000000","0.00014000"],["78649.90000000","0.05007000"],["78649.65000000","0.00400000"],["78649.11000000","0.00007000"],["78648.88000000","0.00014000"],["78648.87000000","0.20832000"],["78648.78000000","0.00007000"],["78648.77000000","0.03231000"],["78648.74000000","0.00014000"],["78648.73000000","0.03791000"],["78648.61000000","0.00007000"],["78648.60000000","0.00007000"],["78648.32000000","0.00007000"],["78648.01000000","1.21959000"],["78648.00000000","0.32298000"]],"asks":[["78650.00000000","0.27444000"],["78650.01000000","0.00083000"],["78650.02000000","0.00013000"],["78650.61000000","0.00021000"],["78650.62000000","0.20825000"],["78650.92000000","0.00007000"],["78651.48000000","0.00007000"],["78651.49000000","0.00007000"],["78651.99000000","0.00014000"],["78652.00000000","0.02407000"],["78652.24000000","0.00007000"],["78652.60000000","0.00014000"],["78652.61000000","0.05366000"],["78652.87000000","0.00014000"],["78652.88000000","0.01550000"],["78652.93000000","0.00007000"],["78652.94000000","0.20784000"],["78652.96000000","0.00007000"],["78653.88000000","0.00014000"],["78654.00000000","0.02407000"]]}}}
{"rx_ns": 173332638485400, "frame": {"stream":"btcusdt@depth@100ms","data":{"e":"depthUpdate","E":1787603271814,"s":"BTCUSDT","U":99076741700,"u":99076741739,"b":[["78641.17000000","0.00000000"],["78256.74000000","0.00000000"],["77865.45000000","0.00000000"],["77476.12000000","0.00000000"],["77088.74000000","0.00000000"],["76703.30000000","0.00070000"],["76319.78000000","0.00000000"],["75938.18000000","0.00000000"],["75558.49000000","0.00000000"],["75180.70000000","0.00000000"],["74804.80000000","0.00000000"],["74430.77000000","0.00000000"],["74058.62000000","0.00000000"],["73688.33000000","0.00000000"],["73319.88000000","0.00000000"],["72953.29000000","0.00000000"],["70785.00000000","0.01914000"]],"a":[["78650.00000000","0.27444000"],["78650.37000000","0.00000000"],["78652.87000000","0.00014000"],["78796.49000000","0.00406000"],["79043.25000000","0.00000000"],["79438.47000000","0.00000000"],["79835.66000000","0.00000000"],["80234.84000000","0.00000000"],["80636.02000000","0.00000000"],["81039.20000000","0.00000000"],["81444.39000000","0.00000000"],["81851.61000000","0.00000000"],["82260.87000000","0.00000000"],["82672.18000000","0.00000000"],["83085.54000000","0.00000000"],["83500.96000000","0.00000000"],["83918.47000000","0.00000000"],["84338.06000000","0.00000000"],["84759.75000000","0.00000000"]]}}}
{"rx_ns": 173332738996900, "frame": {"stream":"btcusdt@depth20@100ms","data":{"lastUpdateId":99076741754,"bids":[["78649.99000000","3.95530000"],["78649.98000000","0.00020000"],["78649.97000000","0.00013000"],["78649.96000000","0.00014000"],["78649.95000000","0.05007000"],["78649.91000000","0.00014000"],["78649.90000000","0.05007000"],["78649.65000000","0.00400000"],["78649.11000000","0.00007000"],["78648.88000000","0.00014000"],["78648.87000000","0.20832000"],["78648.78000000","0.00007000"],["78648.77000000","0.03231000"],["78648.74000000","0.00014000"],["78648.73000000","0.03791000"],["78648.61000000","0.00007000"],["78648.60000000","0.00007000"],["78648.32000000","0.00007000"],["78648.01000000","1.21959000"],["78648.00000000","0.32298000"]],"asks":[["78650.00000000","0.27437000"],["78650.01000000","0.00076000"],["78650.02000000","0.00013000"],["78650.61000000","0.00007000"],["78650.62000000","0.00007000"],["78650.92000000","0.00007000"],["78651.48000000","0.00007000"],["78651.49000000","0.00007000"],["78651.99000000","0.00014000"],["78652.00000000","0.02407000"],["78652.24000000","0.00007000"],["78652.60000000","0.00014000"],["78652.61000000","0.05366000"],["78652.87000000","0.00014000"],["78652.88000000","0.01550000"],["78652.93000000","0.00014000"],["78652.94000000","0.20784000"],["78652.96000000","0.00007000"],["78653.88000000","0.00014000"],["78653.99000000","0.00007000"]]}}}
{"rx_ns": 173332739094100, "frame": {"stream":"btcusdt@depth@100ms","data":{"e":"depthUpdate","E":1787603271914,"s":"BTCUSDT","U":99076741740,"u":99076741754,"b":[["78646.03000000","0.00254000"],["78644.77000000","0.00000000"],["70785.00000000","0.01930000"]],"a":[["78650.00000000","0.27437000"],["78650.01000000","0.00076000"],["78650.38000000","0.00000000"],["78650.61000000","0.00007000"],["78650.62000000","0.00007000"],["78652.93000000","0.00014000"],["78653.99000000","0.00007000"],["78660.49000000","0.00000000"],["78661.51000000","0.00325000"],["78661.75000000","0.00254000"]]}}}
{"rx_ns": 173332839744700, "frame": {"stream":"btcusdt@depth20@100ms","data":{"lastUpdateId":99076741769,"bids":[["78649.99000000","3.95530000"],["78649.98000000","0.00020000"],["78649.97000000","0.00013000"],["78649.96000000","0.00014000"],["78649.95000000","0.05007000"],["78649.91000000","0.00014000"],["78649.90000000","0.05007000"],["78649.65000000","0.00400000"],["78649.11000000","0.00007000"],["78648.88000000","0.00014000"],["78648.87000000","0.20832000"],["78648.78000000","0.00007000"],["78648.77000000","0.03231000"],["78648.74000000","0.00014000"],["78648.73000000","0.03791000"],["78648.61000000","0.00007000"],["78648.60000000","0.00007000"],["78648.32000000","0.00007000"],["78648.01000000","1.21959000"],["78648.00000000","0.32298000"]],"asks":[["78650.00000000","0.27430000"],["78650.01000000","0.00076000"],["78650.02000000","0.00013000"],["78650.61000000","0.00007000"],["78650.92000000","0.00007000"],["78651.48000000","0.00007000"],["78651.49000000","0.00007000"],["78651.99000000","0.00014000"],["78652.00000000","0.02407000"],["78652.24000000","0.00007000"],["78652.60000000","0.00014000"],["78652.61000000","0.05366000"],["78652.87000000","0.00014000"],["78652.88000000","0.01550000"],["78652.93000000","0.00014000"],["78652.94000000","0.20784000"],["78652.96000000","0.00007000"],["78653.88000000","0.00014000"],["78653.99000000","0.00007000"],["78654.00000000","0.02407000"]]}}}
{"rx_ns": 173332839859100, "frame": {"stream":"btcusdt@depth@100ms","data":{"e":"depthUpdate","E":1787603272014,"s":"BTCUSDT","U":99076741755,"u":99076741769,"b":[["70785.00000000","0.01930000"],["62920.00000000","0.00472000"],["62919.99000000","0.00000000"]],"a":[["78650.00000000","0.27430000"],["78650.62000000","0.00000000"],["78656.00000000","0.02407000"],["78717.81000000","0.00406000"]]}}}
{"rx_ns": 173332939073300, "frame": {"stream":"btcusdt@depth20@100ms","data":{"lastUpdateId":99076741775,"bids":[["78649.99000000","3.95203000"],["78649.98000000","0.00020000"],["78649.97000000","0.00013000"],["78649.96000000","0.00014000"],["78649.95000000","0.05007000"],["78649.91000000","0.00014000"],["78649.90000000","0.05007000"],["78649.65000000","0.00400000"],["78649.11000000","0.00007000"],["78648.88000000","0.00014000"],["78648.87000000","0.20832000"],["78648.78000000","0.00007000"],["78648.77000000","0.03231000"],["78648.74000000","0.00014000"],["78648.73000000","0.03791000"],["78648.61000000","0.00007000"],["78648.60000000","0.00007000"],["78648.32000000","0.00007000"],["78648.01000000","1.21959000"],["78648.00000000","0.32298000"]],"asks":[["78650.00000000","0.27430000"],["78650.01000000","0.00076000"],["78650.02000000","0.00013000"],["78650.61000000","0.00007000"],["78650.92000000","0.00007000"],["78651.48000000","0.00007000"],["78651.49000000","0.00007000"],["78651.99000000","0.00014000"],["78652.00000000","0.02407000"],["78652.24000000","0.00007000"],["78652.60000000","0.00014000"],["78652.61000000","0.05366000"],["78652.87000000","0.00014000"],["78652.88000000","0.01550000"],["78652.93000000","0.00014000"],["78652.94000000","0.20784000"],["78652.96000000","0.00007000"],["78653.88000000","0.00014000"],["78653.99000000","0.00007000"],["78654.00000000","0.02407000"]]}}}
{"rx_ns": 173332939163900, "frame": {"stream":"btcusdt@depth@100ms","data":{"e":"depthUpdate","E":1787603272115,"s":"BTCUSDT","U":99076741770,"u":99076741775,"b":[["78649.99000000","3.95203000"],["78640.37000000","0.00000000"],["78572.17000000","0.02118000"],["70785.00000000","0.01946000"]],"a":[]}}}
{"rx_ns": 173333042600200, "frame": {"stream":"btcusdt@depth20@100ms","data":{"lastUpdateId":99076741925,"bids":[["78649.99000000","3.68298000"],["78649.98000000","0.00062000"],["78649.97000000","0.00013000"],["78649.96000000","0.00014000"],["78649.95000000","0.05007000"],["78649.91000000","0.00014000"],["78649.90000000","0.05007000"],["78649.65000000","0.00400000"],["78649.11000000","0.00612000"],["78648.88000000","0.00014000"],["78648.87000000","0.20832000"],["78648.77000000","0.00007000"],["78648.74000000","0.00014000"],["78648.73000000","0.03791000"],["78648.61000000","0.00007000"],["78648.60000000","0.00007000"],["78648.32000000","0.00007000"],["78648.02000000","0.00007000"],["78648.01000000","1.21959000"],["78648.00000000","0.32298000"]],"asks":[["78650.00000000","1.12392000"],["78650.01000000","0.00076000"],["78650.02000000","0.00013000"],["78650.61000000","0.00007000"],["78650.92000000","0.00007000"],["78651.38000000","0.20817000"],["78651.48000000","0.00007000"],["78651.49000000","0.00007000"],["78651.60000000","0.00014000"],["78651.61000000","0.19203000"],["78651.99000000","0.00014000"],["78652.00000000","0.02407000"],["78652.24000000","0.00007000"],["78652.60000000","0.00014000"],["78652.61000000","0.05366000"],["78652.87000000","0.00014000"],["78652.88000000","0.01550000"],["78652.94000000","0.00007000"],["78652.96000000","0.00007000"],["78653.88000000","0.00014000"]]}}}
{"rx_ns": 173333042729100, "frame": {"stream":"btcusdt@depth@100ms","data":{"e":"depthUpdate","E":1787603272214,"s":"BTCUSDT","U":99076741776,"u":99076741925,"b":[["78649.99000000","3.68298000"],["78649.98000000","0.00062000"],["78649.11000000","0.00612000"],["78648.78000000","0.00000000"],["78648.77000000","0.00007000"],["78648.02000000","0.00007000"],["78647.72000000","0.02000000"],["78647.55000000","0.00000000"],["78646.03000000","0.00000000"],["78646.01000000","0.30014000"],["78645.15000000","0.08000000"],["78645.13000000","0.00254000"],["78645.11000000","0.00000000"],["78644.02000000","0.00000000"],["78644.01000000","0.00000000"],["78642.60000000","0.00000000"],["78642.54000000","0.00000000"],["78642.51000000","0.00400000"],["78641.99000000","0.30000000"],["78641.98000000","0.00000000"],["78641.93000000","0.00000000"],["78641.85000000","0.00400000"],["78641.75000000","0.30000000"],["78641.33000000","0.00000000"],["78641.10000000","0.00000000"],["78640.86000000","0.00635000"],["78640.85000000","0.07000000"],["78639.13000000","0.01600000"],["78631.12000000","0.00000000"],["78628.01000000","0.63577000"],["78550.57000000","0.00000000"],["70785.00000000","0.01946000"],["62920.00000000","0.00441000"]],"a":[["78650.00000000","1.12392000"],["78650.01000000","0.00076000"],["78651.38000000","0.20817000"],["78651.60000000","0.00014000"],["78651.61000000","0.19203000"],["78652.93000000","0.00000000"],["78652.94000000","0.00007000"],["78655.99000000","0.00000000"],["78656.60000000","0.00254000"],["78657.74000000","0.00254000"],["78659.61000000","0.00000000"],["78659.99000000","0.31788000"],["78660.00000000","0.02954000"],["78660.37000000","0.00000000"],["78660.86000000","0.00000000"],["78661.75000000","0.00000000"],["78662.60000000","0.00000000"],["78700.00000000","0.03207000"],["78711.87000000","0.00007000"],["78749.29000000","0.00406000"]]}}}
{"rx_ns": 173333141787400, "frame": {"stream":"btcusdt@depth20@100ms","data":{"lastUpdateId":99076741995,"bids":[["78649.99000000","3.68298000"],["78649.98000000","0.00062000"],["78649.97000000","0.00013000"],["78649.96000000","0.00014000"],["78649.95000000","0.05007000"],["78649.91000000","0.00014000"],["78649.90000000","0.05007000"],["78649.65000000","0.00400000"],["78649.11000000","0.00619000"],["78648.88000000","0.00014000"],["78648.87000000","0.20832000"],["78648.74000000","0.00014000"],["78648.73000000","0.03791000"],["78648.61000000","0.00007000"],["78648.60000000","0.00007000"],["78648.32000000","0.00007000"],["78648.02000000","0.00007000"],["78648.01000000","1.21959000"],["78648.00000000","0.32298000"],["78647.99000000","0.07735000"]],"asks":[["78650.00000000","1.12399000"],["78650.01000000","0.00083000"],["78650.02000000","0.00013000"],["78650.61000000","0.00007000"],["78650.92000000","0.00007000"],["78651.37000000","0.00014000"],["78651.38000000","0.20824000"],["78651.48000000","0.00007000"],["78651.49000000","0.00007000"],["78651.60000000","0.00014000"],["78651.61000000","0.19210000"],["78651.99000000","0.00014000"],["78652.00000000","0.02407000"],["78652.24000000","0.00007000"],["78652.60000000","0.00014000"],["78652.61000000","0.05359000"],["78652.88000000","0.01550000"],["78652.96000000","0.00007000"],["78653.88000000","0.00014000"],["78653.99000000","0.00007000"]]}}}
{"rx_ns": 173333141873500, "frame": {"stream":"btcusdt@depth@100ms","data":{"e":"depthUpdate","E":1787603272315,"s":"BTCUSDT","U":99076741926,"u":99076741995,"b":[["78649.90000000","0.05007000"],["78649.11000000","0.00619000"],["78648.87000000","0.20832000"],["78648.77000000","0.00000000"],["78646.00000000","0.01267000"],["78624.00000000","0.02407000"],["78572.17000000","0.00000000"],["78256.74000000","0.01000000"],["77889.50000000","0.00000000"],["77865.45000000","0.01000000"],["77476.12000000","0.01000000"],["77088.74000000","0.01000000"],["76703.30000000","0.01070000"],["76319.78000000","0.01000000"],["75938.18000000","0.01000000"],["75558.49000000","0.01000000"],["75180.70000000","0.01000000"],["74804.80000000","0.01000000"],["74430.77000000","0.01000000"],["74058.62000000","0.01000000"],["73688.33000000","0.01000000"],["73319.88000000","0.01000000"],["72953.29000000","0.01000000"],["70785.00000000","0.01946000"],["62920.00000000","0.00441000"]],"a":[["78650.00000000","1.12399000"],["78650.01000000","0.00083000"],["78651.37000000","0.00014000"],["78651.38000000","0.20824000"],["78651.61000000","0.19210000"],["78652.61000000","0.05359000"],["78652.87000000","0.00000000"],["78652.88000000","0.01550000"],["78652.94000000","0.00000000"],["78656.00000000","0.02400000"],["78659.28000000","0.00000000"],["78659.29000000","0.00254000"],["79043.25000000","0.01000000"],["79289.06000000","0.00499000"],["79438.47000000","0.01000000"],["79835.66000000","0.01000000"],["80234.84000000","0.01000000"],["80636.02000000","0.01000000"],["81039.20000000","0.01000000"],["81444.39000000","0.01000000"],["81851.61000000","0.01000000"],["82260.87000000","0.01000000"],["82672.18000000","0.01000000"],["83085.54000000","0.01000000"],["83500.96000000","0.01000000"],["83918.47000000","0.01000000"],["84338.06000000","0.01000000"],["84759.75000000","0.01000000"]]}}}
{"rx_ns": 173333244684400, "frame": {"stream":"btcusdt@depth20@100ms","data":{"lastUpdateId":99076743029,"bids":[["78655.00000000","3.83195000"],["78654.99000000","0.00020000"],["78654.98000000","0.00013000"],["78654.67000000","0.61608000"],["78654.66000000","0.82346000"],["78654.50000000","0.00400000"],["78654.14000000","0.39218000"],["78654.13000000","0.87495000"],["78653.88000000","0.00014000"],["78653.87000000","3.80301000"],["78652.52000000","0.04917000"],["78652.23000000","0.00015000"],["78652.15000000","0.00400000"],["78652.00000000","0.07500000"],["78651.99000000","0.00382000"],["78651.93000000","0.00027000"],["78651.47000000","0.42032000"],["78651.38000000","0.07500000"],["78651.37000000","0.96086000"],["78651.30000000","0.05000000"]],"asks":[["78655.01000000","0.11672000"],["78655.02000000","0.00056000"],["78655.36000000","0.00028000"],["78655.37000000","0.00007000"],["78655.39000000","0.00014000"],["78655.40000000","0.03094000"],["78655.99000000","0.00014000"],["78656.00000000","0.02407000"],["78656.65000000","0.00014000"],["78656.66000000","0.03094000"],["78656.83000000","0.00014000"],["78656.84000000","0.00007000"],["78657.55000000","0.00007000"],["78657.67000000","0.05255000"],["78657.75000000","0.00007000"],["78657.83000000","0.00007000"],["78657.87000000","0.00007000"],["78657.99000000","0.00007000"],["78658.00000000","0.02407000"],["78658.22000000","0.00014000"]]}}}
{"rx_ns": 173333244768800, "frame": {"stream":"btcusdt@depth@100ms","data":{"e":"depthUpdate","E":1787603272414,"s":"BTCUSDT","U":99076741996,"u":99076743029,"b":[["78655.00000000","3.83195000"],["78654.99000000","0.00020000"],["78654.98000000","0.00013000"],["78654.67000000","0.61608000"],["78654.66000000","0.82346000"],["78654.50000000","0.00400000"],["78654.14000000","0.39218000"],["78654.13000000","0.87495000"],["78653.99000000","0.00000000"],["78653.98000000","0.00000000"],["78653.88000000","0.00014000"],["78653.87000000","3.80301000"],["78653.86000000","0.00000000"],["78653.85000000","0.00000000"],["78653.79000000","0.00000000"],["78653.57000000","0.00000000"],["78652.95000000","0.00000000"],["78652.87000000","0.00000000"],["78652.81000000","0.00000000"],["78652.60000000","0.00000000"],["78652.59000000","0.00000000"],["78652.52000000","0.04917000"],["78652.23000000","0.00015000"],["78652.15000000","0.00400000"],["78652.00000000","0.07500000"],["78651.99000000","0.00382000"],["78651.98000000","0.00000000"],["78651.93000000","0.00027000"],["78651.60000000","0.00000000"],["78651.59000000","0.00000000"],["78651.48000000","0.00000000"],["78651.47000000","0.42032000"],["78651.38000000","0.07500000"],["78651.37000000","0.96086000"],["78651.36000000","0.00000000"],["78651.35000000","0.00000000"],["78651.30000000","0.05000000"],["78650.91000000","0.00000000"],["78650.90000000","0.00015000"],["78650.04000000","0.00000000"],["78650.01000000","0.00014000"],["78650.00000000","0.79569000"],["78649.99000000","0.30233000"],["78649.98000000","0.00000000"],["78649.97000000","0.00000000"],["78649.96000000","0.00000000"],["78649.95000000","0.00000000"],["78649.91000000","0.00000000"],["78649.90000000","0.00000000"],["78649.57000000","0.03224000"],["78649.11000000","0.00612000"],["78648.88000000","0.00000000"],["78648.87000000","0.00007000"],["78648.74000000","0.00000000"],["78648.73000000","0.03784000"],["78648.49000000","0.00000000"],["78648.34000000","0.00000000"],["78648.02000000","0.00000000"],["78648.01000000","1.21952000"],["78648.00000000","0.00500000"],["78647.93000000","0.12714000"],["78647.72000000","0.00000000"],["78647.45000000","0.00400000"],["78647.10000000","0.00000000"],["78646.00000000","0.31367000"],["78645.99000000","0.30339000"],["78645.15000000","0.38000000"],["78645.13000000","0.00000000"],["78644.71000000","0.00007000"],["78644.05000000","0.00007000"],["78643.72000000","1.21959000"],["78643.71000000","0.49440000"],["78642.63000000","0.00007000"],["78642.38000000","0.38152000"],["78641.99000000","0.00000000"],["78641.75000000","0.00000000"],["78641.63000000","0.00000000"],["78641.62000000","0.00317000"],["78641.50000000","0.00000000"],["78641.04000000","0.08576000"],["78640.86000000","0.00000000"],["78639.62000000","0.00000000"],["78639.41000000","0.34338000"],["78639.29000000","0.34338000"],["78639.13000000","0.00000000"],["78639.00000000","0.00000000"],["78637.66000000","0.34338000"],["78637.63000000","0.00000000"],["78637.62000000","0.00000000"],["78635.26000000","0.00000000"],["78631.33000000","0.29364000"],["78626.86000000","0.00000000"],["78626.36000000","0.00007000"],["78626.27000000","0.13787000"],["78625.11000000","0.00800000"],["78624.78000000","0.00000000"],["78621.07000000","0.00000000"],["78619.25000000","0.00400000"],["78618.87000000","0.00000000"],["78618.81000000","0.00000000"],["78616.90000000","0.00000000"],["78616.62000000","0.00000000"],["78615.18000000","0.00000000"],["78614.55000000","0.00000000"],["78614.43000000","0.00000000"],["78613.57000000","0.02522000"],["78612.85000000","0.00000000"],["78611.31000000","0.00000000"],["78611.22000000","0.19020000"],["78596.92000000","0.00000000"],["78594.32000000","3.41000000"],["78592.43000000","0.00315000"],["78589.61000000","0.00000000"],["78587.56000000","0.00000000"],["78587.30000000","0.00000000"],["78584.97000000","0.00000000"],["78584.09000000","0.00000000"],["78577.00000000","0.00000000"],["78571.48000000","0.00317000"],["78562.01000000","0.00000000"],["78560.64000000","0.00000000"],["78544.90000000","0.00509000"],["78526.12000000","0.00000000"],["78519.95000000","0.00000000"],["78505.68000000","0.00000000"],["78455.34000000","0.00250000"],["78440.47000000","2.88671000"],["78440.06000000","0.00406000"],["78405.35000000","0.00000000"],["77877.80000000","0.00400000"],["74718.80000000","0.00010000"],["74717.50000000","0.00000000"],["70786.24000000","0.00009000"],["70785.00000000","0.01530000"],["66969.80000000","0.00034000"]],"a":[["78650.00000000","0.00000000"],["78650.01000000","0.00000000"],["78650.02000000","0.00000000"],["78650.61000000","0.00000000"],["78650.91000000","0.00000000"],["78650.92000000","0.00000000"],["78651.37000000","0.00000000"],["78651.38000000","0.00000000"],["78651.39000000","0.00000000"],["78651.48000000","0.00000000"],["78651.49000000","0.00000000"],["78651.60000000","0.00000000"],["78651.61000000","0.00000000"],["78651.99000000","0.00000000"],["78652.00000000","0.00000000"],["78652.24000000","0.00000000"],["78652.60000000","0.00000000"],["78652.61000000","0.00000000"],["78652.87000000","0.00000000"],["78652.88000000","0.00000000"],["78652.96000000","0.00000000"],["78653.58000000","0.00000000"],["78653.88000000","0.00000000"],["78653.99000000","0.00000000"],["78654.00000000","0.00000000"],["78654.13000000","0.00000000"],["78654.14000000","0.00000000"],["78654.64000000","0.00000000"],["78654.67000000","0.00000000"],["78655.01000000","0.11672000"],["78655.02000000","0.00056000"],["78655.36000000","0.00028000"],["78655.37000000","0.00007000"],["78655.39000000","0.00014000"],["78655.99000000","0.00014000"],["78656.00000000","0.02407000"],["78656.52000000","0.00000000"],["78656.60000000","0.00000000"],["78656.61000000","0.00000000"],["78656.65000000","0.00014000"],["78656.66000000","0.03094000"],["78656.80000000","0.00000000"],["78656.83000000","0.00014000"],["78656.84000000","0.00007000"],["78657.05000000","0.00000000"],["78657.33000000","0.00000000"],["78657.36000000","0.00000000"],["78657.55000000","0.00007000"],["78657.67000000","0.05255000"],["78657.68000000","0.00000000"],["78657.74000000","0.00000000"],["78657.75000000","0.00007000"],["78657.87000000","0.00007000"],["78657.99000000","0.00007000"],["78658.00000000","0.02407000"],["78658.22000000","0.00014000"],["78658.40000000","0.00000000"],["78658.41000000","0.00000000"],["78659.29000000","0.00000000"],["78659.99000000","0.00000000"],["78660.00000000","0.02554000"],["78661.50000000","0.00000000"],["78661.51000000","0.00000000"],["78661.62000000","0.00007000"],["78661.71000000","0.00000000"],["78661.72000000","0.00000000"],["78662.25000000","0.00000000"],["78662.60000000","0.00000000"],["78662.61000000","0.00000000"],["78662.92000000","0.00000000"],["78662.93000000","0.00000000"],["78663.19000000","0.00007000"],["78663.69000000","0.00000000"],["78663.70000000","0.00000000"],["78663.83000000","0.00007000"],["78663.84000000","0.00000000"],["78663.87000000","0.00000000"],["78663.98000000","0.00000000"],["78664.03000000","0.00000000"],["78664.05000000","0.00000000"],["78664.07000000","0.00000000"],["78664.31000000","0.00000000"],["78664.32000000","0.00000000"],["78664.35000000","0.00000000"],["78664.79000000","0.00000000"],["78665.23000000","0.00000000"],["78665.32000000","0.00000000"],["78665.42000000","0.00000000"],["78665.49000000","0.00007000"],["78665.59000000","0.00000000"],["78665.60000000","0.00000000"],["78665.72000000","0.00000000"],["78665.73000000","0.00007000"],["78665.76000000","0.00000000"],["78665.77000000","0.00000000"],["78665.88000000","0.00000000"],["78666.40000000","0.00000000"],["78666.78000000","0.00007000"],["78667.19000000","0.04857000"],["78667.25000000","0.31789000"],["78667.26000000","0.00332000"],["78667.30000000","0.15000000"],["78667.97000000","0.00254000"],["78668.31000000","0.00000000"],["78668.32000000","0.00000000"],["78668.54000000","0.00635000"],["78668.55000000","0.00635000"],["78668.56000000","0.00000000"],["78668.74000000","0.00000000"],["78669.06000000","0.00137000"],["78669.51000000","0.00000000"],["78669.72000000","0.00007000"],["78669.73000000","0.00254000"],["78670.16000000","0.00000000"],["78670.24000000","0.00000000"],["78670.75000000","0.05307000"],["78671.08000000","0.00000000"],["78671.74000000","0.07617000"],["78672.38000000","0.00319000"],["78673.56000000","0.00007000"],["78673.86000000","0.00000000"],["78673.87000000","0.00000000"],["78674.25000000","0.02287000"],["78675.09000000","0.00000000"],["78675.22000000","0.00000000"],["78676.15000000","0.02000000"],["78677.16000000","0.00227000"],["78677.90000000","0.00000000"],["78678.63000000","0.00000000"],["78679.37000000","0.00000000"],["78679.39000000","0.12709000"],["78679.96000000","0.00000000"],["78679.99000000","0.00000000"],["78680.00000000","0.02407000"],["78680.26000000","0.00000000"],["78680.93000000","0.09704000"],["78681.11000000","0.00000000"],["78681.31000000","0.00000000"],["78683.95000000","0.02161000"],["78684.16000000","0.00000000"],["78684.32000000","0.00000000"],["78687.14000000","0.00000000"],["78687.16000000","0.00000000"],["78689.07000000","0.00000000"],["78690.00000000","0.11932000"],["78690.17000000","0.04669000"],["78690.18000000","0.00000000"],["78690.91000000","0.00000000"],["78690.95000000","0.00000000"],["78691.00000000","0.00000000"],["78691.90000000","0.00000000"],["78692.15000000","0.00000000"],["78692.21000000","0.02720000"],["78692.58000000","0.00014000"],["78692.96000000","0.00000000"],["78695.28000000","0.34313000"],["78696.45000000","0.00007000"],["78696.76000000","0.00000000"],["78699.36000000","0.02516000"],["78699.99000000","0.00000000"],["78700.32000000","0.00007000"],["78700.94000000","0.63539000"],["78701.22000000","0.02161000"],["78701.50000000","0.00400000"],["78702.52000000","0.00000000"],["78703.85000000","0.00400000"],["78703.87000000","0.00317000"],["78704.37000000","0.00000000"],["78705.28000000","0.00000000"],["78706.01000000","0.34309000"],["78710.78000000","0.02161000"],["78720.51000000","0.02161000"],["78721.99000000","0.00000000"],["78723.18000000","0.52014000"],["78724.09000000","0.32318000"],["78726.54000000","0.00316000"],["78734.15000000","1.25755000"],["78739.35000000","1.21952000"],["78749.33000000","1.90515000"],["78749.58000000","1.21952000"],["78751.64000000","0.00000000"],["78753.79000000","0.00000000"],["78756.82000000","1.90515000"],["78759.11000000","0.21930000"],["78759.81000000","1.21952000"],["78766.79000000","1.90515000"],["78795.99000000","0.00000000"],["78809.43000000","0.00127000"],["78839.39000000","0.00000000"],["78880.96000000","2.25863000"],["79043.25000000","0.00000000"],["79054.02000000","0.00007000"],["79282.35000000","0.00250000"],["79438.47000000","0.00000000"],["79835.66000000","0.00000000"],["80234.84000000","0.00000000"],["80636.02000000","0.00000000"],["81039.20000000","0.00000000"],["81444.39000000","0.00000000"],["81851.61000000","0.00000000"],["82260.87000000","0.00000000"],["82672.18000000","0.00000000"],["83085.54000000","0.00000000"],["83500.96000000","0.00000000"],["83918.47000000","0.00000000"],["84338.06000000","0.00000000"],["84759.75000000","0.00000000"]]}}}
{"rx_ns": 173333339991400, "frame": {"stream":"btcusdt@depth20@100ms","data":{"lastUpdateId":99076744290,"bids":[["78657.99000000","5.31440000"],["78657.98000000","1.90535000"],["78657.97000000","0.00013000"],["78657.95000000","0.05000000"],["78657.90000000","0.05000000"],["78657.75000000","0.00014000"],["78657.74000000","0.00007000"],["78657.66000000","0.38414000"],["78657.65000000","0.00007000"],["78656.85000000","0.00400000"],["78656.66000000","0.07507000"],["78656.65000000","0.59479000"],["78656.00000000","0.07500000"],["78655.99000000","0.38270000"],["78655.50000000","0.00008000"],["78655.40000000","0.07500000"],["78655.39000000","0.21951000"],["78655.01000000","0.00007000"],["78655.00000000","0.08372000"],["78654.83000000","0.04917000"]],"asks":[["78658.00000000","0.02500000"],["78658.01000000","0.00049000"],["78659.10000000","0.00007000"],["78659.24000000","0.00007000"],["78659.32000000","0.00007000"],["78659.99000000","0.00014000"],["78660.00000000","0.02561000"],["78660.32000000","0.00014000"],["78660.33000000","0.05254000"],["78661.14000000","0.00007000"],["78661.45000000","0.00010000"],["78661.62000000","0.00007000"],["78661.83000000","0.00007000"],["78661.99000000","0.00014000"],["78662.00000000","0.02407000"],["78663.12000000","0.00007000"],["78663.19000000","0.00007000"],["78663.63000000","0.00007000"],["78663.99000000","0.00014000"],["78664.00000000","0.02407000"]]}}}
{"rx_ns": 173333340093200, "frame": {"stream":"btcusdt@depth@100ms","data":{"e":"depthUpdate","E":1787603272514,"s":"BTCUSDT","U":99076743030,"u":99076744290,"b":[["78657.99000000","5.31440000"],["78657.98000000","1.90535000"],["78657.97000000","0.00013000"],["78657.95000000","0.05000000"],["78657.90000000","0.05000000"],["78657.86000000","0.00000000"],["78657.82000000","0.00000000"],["78657.75000000","0.00014000"],["78657.74000000","0.00007000"],["78657.67000000","0.00000000"],["78657.66000000","0.38414000"],["78657.65000000","0.00007000"],["78657.64000000","0.00000000"],["78657.54000000","0.00000000"],["78656.85000000","0.00400000"],["78656.83000000","0.00000000"],["78656.82000000","0.00000000"],["78656.66000000","0.07507000"],["78656.65000000","0.59479000"],["78656.64000000","0.00000000"],["78656.63000000","0.00000000"],["78656.32000000","0.00000000"],["78656.00000000","0.07500000"],["78655.99000000","0.38270000"],["78655.98000000","0.00000000"],["78655.97000000","0.00000000"],["78655.50000000","0.00008000"],["78655.40000000","0.07500000"],["78655.39000000","0.21951000"],["78655.38000000","0.00000000"],["78655.37000000","0.00000000"],["78655.36000000","0.00000000"],["78655.35000000","0.00000000"],["78655.20000000","0.00000000"],["78655.01000000","0.00007000"],["78655.00000000","0.08372000"],["78654.99000000","0.00000000"],["78654.98000000","0.00000000"],["78654.83000000","0.04917000"],["78654.68000000","0.00000000"],["78654.67000000","0.00014000"],["78654.66000000","0.07016000"],["78654.27000000","0.04055000"],["78654.14000000","0.00000000"],["78654.13000000","0.00672000"],["78653.99000000","0.00000000"],["78653.98000000","0.00324000"],["78653.87000000","1.90106000"],["78653.82000000","0.00000000"],["78653.16000000","0.00000000"],["78652.52000000","0.30007000"],["78652.23000000","0.00000000"],["78652.15000000","0.30400000"],["78652.00000000","0.30014000"],["78651.99000000","0.00367000"],["78651.47000000","0.00007000"],["78651.38000000","0.00000000"],["78651.37000000","0.52635000"],["78651.30000000","0.00000000"],["78650.90000000","0.00000000"],["78650.00000000","0.22037000"],["78649.99000000","0.24994000"],["78649.57000000","0.00000000"],["78649.11000000","0.00007000"],["78648.95000000","0.03000000"],["78648.73000000","0.00000000"],["78648.17000000","0.00007000"],["78647.99000000","0.00663000"],["78647.93000000","0.00000000"],["78647.86000000","0.00007000"],["78647.70000000","0.08576000"],["78647.68000000","0.00010000"],["78647.65000000","0.12720000"],["78647.47000000","0.00000000"],["78646.87000000","0.34334000"],["78646.21000000","0.00000000"],["78646.13000000","0.00000000"],["78646.01000000","0.30000000"],["78646.00000000","0.01367000"],["78645.99000000","0.00325000"],["78645.95000000","0.00000000"],["78645.72000000","0.00000000"],["78645.62000000","0.00007000"],["78645.29000000","0.00000000"],["78645.15000000","0.08000000"],["78644.28000000","0.00000000"],["78643.99000000","0.00322000"],["78643.62000000","0.00000000"],["78643.02000000","0.00000000"],["78642.89000000","0.00000000"],["78642.63000000","0.00000000"],["78642.08000000","0.00007000"],["78641.76000000","0.63575000"],["78641.62000000","0.00000000"],["78641.04000000","0.00000000"],["78640.85000000","0.04000000"],["78639.10000000","0.00000000"],["78638.41000000","0.00000000"],["78637.66000000","0.00000000"],["78636.45000000","0.06596000"],["78634.49000000","0.07621000"],["78634.06000000","0.00126000"],["78633.01000000","0.51126000"],["78632.19000000","0.00000000"],["78631.97000000","0.00000000"],["78631.00000000","0.00000000"],["78630.57000000","0.41188000"],["78630.39000000","0.00000000"],["78630.22000000","0.00000000"],["78630.13000000","0.14035000"],["78629.74000000","0.00000000"],["78628.82000000","0.19020000"],["78628.10000000","0.00800000"],["78628.01000000","0.00000000"],["78627.64000000","0.00000000"],["78627.63000000","0.00000000"],["78627.57000000","0.00400000"],["78626.39000000","0.00007000"],["78625.11000000","0.00000000"],["78624.37000000","0.00000000"],["78622.29000000","0.00000000"],["78621.60000000","0.00400000"],["78621.00000000","0.00000000"],["78619.25000000","0.00000000"],["78618.03000000","0.00000000"],["78617.13000000","0.00000000"],["78613.57000000","0.00000000"],["78611.22000000","0.00000000"],["78610.98000000","0.02391000"],["78610.33000000","0.00625000"],["78610.00000000","0.02475000"],["78609.07000000","0.00430000"],["78598.36000000","0.01134000"],["78598.14000000","0.00000000"],["78596.86000000","0.00000000"],["78591.65000000","0.01740000"],["78589.59000000","0.00534000"],["78588.54000000","0.00125000"],["78582.99000000","0.00000000"],["78572.35000000","0.00000000"],["78570.29000000","0.00911000"],["78569.57000000","0.00000000"],["78569.24000000","0.00000000"],["78550.15000000","0.00000000"],["78546.68000000","0.04538000"],["78542.58000000","0.00000000"],["78537.46000000","0.00000000"],["78517.95000000","1.52347000"],["78517.62000000","0.00000000"],["78513.62000000","0.09318000"],["78502.31000000","0.00000000"],["78481.66000000","0.00000000"],["78464.79000000","0.00007000"],["78428.03000000","0.00000000"],["78425.79000000","0.00000000"],["78335.06000000","0.00026000"],["78322.51000000","0.00000000"],["77880.76000000","0.00400000"],["77880.29000000","0.00000000"],["77880.24000000","0.00000000"],["77877.93000000","0.00000000"],["77877.80000000","0.00000000"],["66969.80000000","0.00017000"],["66857.09000000","0.00034000"],["62926.40000000","0.00031000"]],"a":[["78655.01000000","0.00000000"],["78655.02000000","0.00000000"],["78655.36000000","0.00000000"],["78655.37000000","0.00000000"],["78655.39000000","0.00000000"],["78655.40000000","0.00000000"],["78655.41000000","0.00000000"],["78655.99000000","0.00000000"],["78656.00000000","0.00000000"],["78656.01000000","0.00000000"],["78656.65000000","0.00000000"],["78656.66000000","0.00000000"],["78656.67000000","0.00000000"],["78656.83000000","0.00000000"],["78656.84000000","0.00000000"],["78657.55000000","0.00000000"],["78657.66000000","0.00000000"],["78657.67000000","0.00000000"],["78657.68000000","0.00000000"],["78657.75000000","0.00000000"],["78657.83000000","0.00000000"],["78657.87000000","0.00000000"],["78657.99000000","0.00000000"],["78658.00000000","0.02500000"],["78658.01000000","0.00049000"],["78658.22000000","0.00000000"],["78658.65000000","0.00000000"],["78658.66000000","0.00000000"],["78659.00000000","0.00000000"],["78659.31000000","0.00000000"],["78659.32000000","0.00007000"],["78659.78000000","0.00000000"],["78659.83000000","0.00000000"],["78659.84000000","0.00000000"],["78659.99000000","0.00014000"],["78660.00000000","0.02561000"],["78660.32000000","0.00014000"],["78660.33000000","0.05254000"],["78660.48000000","0.00000000"],["78660.67000000","0.00000000"],["78661.23000000","0.00000000"],["78661.99000000","0.00014000"],["78662.00000000","0.02407000"],["78663.20000000","0.00000000"],["78663.83000000","0.00000000"],["78663.91000000","0.00000000"],["78663.99000000","0.00014000"],["78664.00000000","0.02407000"],["78664.76000000","0.00000000"],["78664.80000000","0.00000000"],["78665.31000000","0.00000000"],["78665.49000000","0.00007000"],["78665.99000000","0.00007000"],["78666.99000000","0.00000000"],["78667.19000000","0.00000000"],["78667.25000000","0.00000000"],["78667.26000000","0.00000000"],["78667.30000000","0.00000000"],["78667.97000000","0.00000000"],["78667.98000000","0.00000000"],["78668.00000000","0.02400000"],["78668.09000000","0.00000000"],["78668.30000000","0.00000000"],["78668.37000000","0.00000000"],["78668.54000000","0.00000000"],["78668.55000000","0.00000000"],["78668.75000000","0.00000000"],["78669.06000000","0.00000000"],["78669.18000000","0.00048000"],["78669.36000000","0.00007000"],["78669.67000000","0.00000000"],["78669.74000000","0.00000000"],["78669.80000000","0.00000000"],["78669.93000000","0.00007000"],["78669.97000000","0.00000000"],["78670.16000000","0.00070000"],["78670.30000000","0.00000000"],["78670.75000000","0.00000000"],["78671.19000000","0.00254000"],["78671.20000000","0.01000000"],["78671.74000000","0.00000000"],["78671.88000000","0.00000000"],["78671.90000000","0.00000000"],["78671.91000000","0.00000000"],["78671.92000000","0.00000000"],["78672.38000000","0.00000000"],["78672.70000000","0.02000000"],["78672.88000000","0.00000000"],["78672.89000000","0.00000000"],["78673.52000000","0.00000000"],["78673.86000000","0.04857000"],["78673.87000000","0.31784000"],["78673.91000000","0.00048000"],["78674.30000000","0.04000000"],["78674.49000000","0.00000000"],["78674.78000000","0.00000000"],["78674.96000000","0.00000000"],["78674.98000000","0.00000000"],["78675.05000000","0.00000000"],["78675.30000000","0.00000000"],["78675.49000000","0.00321000"],["78675.60000000","0.08000000"],["78675.73000000","0.00189000"],["78675.74000000","0.00635000"],["78676.15000000","0.00000000"],["78676.90000000","0.00254000"],["78677.16000000","0.00000000"],["78677.50000000","0.00719000"],["78677.83000000","0.00000000"],["78678.69000000","0.00163000"],["78678.72000000","0.00318000"],["78680.05000000","0.02000000"],["78680.93000000","0.00000000"],["78681.10000000","0.00000000"],["78682.27000000","0.00000000"],["78682.47000000","0.00000000"],["78682.66000000","0.00324000"],["78682.92000000","0.00000000"],["78682.99000000","0.00227000"],["78683.43000000","0.12709000"],["78683.72000000","0.00000000"],["78683.90000000","0.00000000"],["78683.94000000","0.00000000"],["78684.17000000","0.00000000"],["78684.58000000","0.00000000"],["78684.70000000","0.00000000"],["78685.30000000","0.00000000"],["78686.03000000","0.00000000"],["78686.60000000","0.00319000"],["78686.70000000","0.09730000"],["78687.39000000","0.00000000"],["78689.05000000","0.00000000"],["78689.06000000","0.00000000"],["78690.54000000","0.00320000"],["78691.61000000","0.00000000"],["78692.21000000","0.00000000"],["78692.23000000","0.00000000"],["78692.44000000","0.00000000"],["78692.97000000","0.00000000"],["78693.31000000","0.00000000"],["78693.42000000","0.00000000"],["78693.91000000","0.00000000"],["78694.00000000","0.02415000"],["78694.14000000","0.00000000"],["78694.15000000","0.43608000"],["78694.24000000","0.00000000"],["78694.49000000","0.00000000"],["78694.51000000","0.00000000"],["78694.64000000","0.00000000"],["78694.86000000","0.00000000"],["78694.87000000","0.00000000"],["78694.98000000","0.00000000"],["78695.00000000","0.00000000"],["78695.18000000","0.00000000"],["78695.20000000","0.00000000"],["78695.50000000","0.00000000"],["78695.89000000","0.00000000"],["78696.00000000","0.02400000"],["78696.03000000","0.00000000"],["78696.13000000","0.00000000"],["78696.37000000","0.00000000"],["78696.45000000","0.00014000"],["78696.53000000","0.00000000"],["78696.56000000","0.00000000"],["78696.76000000","0.00000000"],["78696.87000000","0.00000000"],["78697.00000000","0.00000000"],["78697.39000000","0.00000000"],["78698.00000000","0.03400000"],["78698.02000000","0.00000000"],["78699.06000000","0.00000000"],["78700.00000000","0.12737000"],["78703.12000000","0.10000000"],["78704.19000000","0.00007000"],["78704.91000000","0.00007000"],["78706.02000000","0.00662000"],["78706.20000000","0.00400000"],["78707.38000000","0.02430000"],["78707.55000000","0.00000000"],["78708.55000000","0.00400000"],["78708.74000000","0.00625000"],["78722.00000000","0.02407000"],["78723.03000000","0.01134000"],["78740.05000000","0.00010000"],["78764.00000000","0.02414000"],["78766.78000000","1.90515000"],["78766.79000000","0.00000000"],["78801.17000000","0.00000000"],["78816.88000000","1.52347000"],["78859.40000000","0.00007000"],["78863.33000000","0.00007000"],["78867.11000000","0.00007000"],["78871.04000000","0.00007000"],["78898.41000000","0.00000000"],["78913.43000000","0.00000000"],["78978.34000000","0.00000000"],["79019.20000000","0.00000000"],["79042.93000000","0.01905000"]]}}}
{"rx_ns": 173333440017400, "frame": {"stream":"btcusdt@depth20@100ms","data":{"lastUpdateId":99076745248,"bids":[["78661.99000000","5.15171000"],["78661.98000000","0.00020000"],["78661.97000000","0.00013000"],["78661.62000000","0.00014000"],["78661.45000000","1.00549000"],["78661.44000000","2.36672000"],["78661.40000000","0.05000000"],["78661.35000000","0.05000000"],["78661.14000000","0.00007000"],["78661.13000000","0.21944000"],["78660.34000000","0.00007000"],["78660.33000000","0.00007000"],["78660.32000000","0.00014000"],["78660.18000000","0.04015000"],["78660.00000000","0.07500000"],["78659.99000000","0.60906000"],["78659.41000000","0.00400000"],["78659.20000000","0.00400000"],["78659.16000000","0.04917000"],["78658.92000000","0.04819000"]],"asks":[["78662.00000000","0.01996000"],["78662.01000000","0.00056000"],["78663.12000000","0.00007000"],["78663.19000000","0.00007000"],["78663.99000000","0.00014000"],["78664.00000000","0.02407000"],["78664.06000000","0.00200000"],["78664.10000000","0.00014000"],["78664.11000000","0.00007000"],["78664.66000000","0.05254000"],["78665.18000000","0.00014000"],["78665.19000000","0.01404000"],["78665.24000000","0.00007000"],["78665.49000000","0.00007000"],["78665.68000000","0.00007000"],["78665.73000000","0.00007000"],["78665.99000000","0.00014000"],["78666.00000000","0.02421000"],["78666.44000000","0.00007000"],["78666.45000000","0.02340000"]]}}}
{"rx_ns": 173333440119100, "frame": {"stream":"btcusdt@depth@100ms","data":{"e":"depthUpdate","E":1787603272614,"s":"BTCUSDT","U":99076744291,"u":99076745248,"b":[["78661.99000000","5.15171000"],["78661.98000000","0.00020000"],["78661.97000000","0.00013000"],["78661.82000000","0.00000000"],["78661.72000000","0.00000000"],["78661.62000000","0.00014000"],["78661.61000000","0.00000000"],["78661.45000000","1.00549000"],["78661.44000000","2.36672000"],["78661.43000000","0.00000000"],["78661.42000000","0.00000000"],["78661.40000000","0.05000000"],["78661.35000000","0.05000000"],["78661.14000000","0.00007000"],["78661.13000000","0.21944000"],["78660.34000000","0.00007000"],["78660.33000000","0.00007000"],["78660.32000000","0.00014000"],["78660.31000000","0.00000000"],["78660.30000000","0.00000000"],["78660.18000000","0.04015000"],["78660.00000000","0.07500000"],["78659.99000000","0.60906000"],["78659.98000000","0.00000000"],["78659.97000000","0.00000000"],["78659.41000000","0.00400000"],["78659.31000000","0.00000000"],["78659.23000000","0.00000000"],["78659.20000000","0.00400000"],["78659.16000000","0.04917000"],["78659.09000000","0.00000000"],["78658.92000000","0.04819000"],["78658.68000000","0.00325000"],["78658.65000000","0.00000000"],["78658.61000000","0.00000000"],["78658.54000000","0.00007000"],["78658.00000000","0.07507000"],["78657.99000000","1.93748000"],["78657.98000000","0.00007000"],["78657.97000000","0.00000000"],["78657.95000000","0.00014000"],["78657.91000000","0.00000000"],["78657.90000000","0.00000000"],["78657.86000000","0.00254000"],["78657.67000000","0.00000000"],["78657.66000000","0.43233000"],["78657.16000000","0.00000000"],["78656.86000000","0.07000000"],["78656.67000000","0.00000000"],["78656.66000000","0.00000000"],["78656.65000000","0.38613000"],["78656.00000000","0.00000000"],["78655.99000000","0.38263000"],["78655.57000000","0.12713000"],["78655.40000000","0.00000000"],["78655.39000000","0.21937000"],["78655.01000000","0.00000000"],["78655.00000000","0.07002000"],["78654.83000000","0.00000000"],["78654.67000000","0.00007000"],["78654.66000000","0.00014000"],["78653.88000000","1.90529000"],["78653.87000000","1.52279000"],["78652.00000000","0.30007000"],["78651.99000000","0.00193000"],["78651.62000000","0.00007000"],["78651.47000000","0.00000000"],["78651.37000000","0.00318000"],["78651.01000000","0.00007000"],["78650.95000000","0.08576000"],["78650.93000000","0.00007000"],["78650.00000000","0.09536000"],["78649.99000000","0.03044000"],["78648.95000000","0.00000000"],["78648.87000000","0.00000000"],["78648.61000000","0.00000000"],["78648.60000000","0.00000000"],["78647.99000000","0.00656000"],["78647.95000000","0.00000000"],["78647.70000000","0.00000000"],["78647.62000000","0.00000000"],["78645.62000000","0.00000000"],["78644.00000000","1.93550000"],["78643.71000000","0.49121000"],["78642.51000000","0.00000000"],["78642.09000000","0.00000000"],["78641.99000000","0.06595000"],["78641.85000000","0.00000000"],["78641.56000000","0.00000000"],["78640.85000000","0.00000000"],["78640.02000000","0.07620000"],["78637.85000000","0.14055000"],["78636.45000000","0.00000000"],["78635.50000000","0.00000000"],["78634.53000000","0.41202000"],["78634.49000000","0.00000000"],["78633.99000000","0.13781000"],["78633.09000000","0.00400000"],["78632.54000000","0.00000000"],["78630.73000000","0.00000000"],["78630.67000000","0.00000000"],["78630.13000000","0.00000000"],["78628.82000000","0.00000000"],["78628.10000000","0.00000000"],["78626.41000000","0.09751000"],["78626.27000000","0.00000000"],["78623.95000000","0.00400000"],["78623.19000000","0.00000000"],["78621.94000000","0.68354000"],["78621.60000000","0.00000000"],["78620.00000000","0.06600000"],["78619.05000000","0.00000000"],["78618.39000000","0.00000000"],["78618.00000000","0.03400000"],["78616.00000000","0.02426000"],["78614.46000000","0.00000000"],["78612.18000000","0.00000000"],["78611.80000000","0.00429000"],["78610.91000000","0.00433000"],["78604.01000000","1.95847000"],["78596.81000000","0.00000000"],["78596.27000000","0.00000000"],["78595.19000000","0.90692000"],["78593.69000000","0.00000000"],["78591.51000000","0.86919000"],["78579.53000000","0.00000000"],["78574.72000000","0.00000000"],["78560.38000000","0.00000000"],["78547.70000000","0.00320000"],["78486.94000000","1.20000000"],["78482.12000000","0.00000000"],["78475.47000000","0.00779000"],["78468.61000000","0.00000000"],["78435.02000000","0.00000000"],["78431.09000000","0.00000000"],["78360.60000000","0.00000000"],["78352.73000000","0.00000000"],["78344.86000000","0.00000000"],["77883.31000000","0.00000000"],["77880.76000000","0.00000000"],["77435.17000000","0.00000000"],["70795.30000000","0.00000000"],["70792.20000000","0.00000000"],["66862.23000000","0.00017000"],["62926.40000000","0.00000000"]],"a":[["78658.00000000","0.00000000"],["78658.01000000","0.00000000"],["78659.10000000","0.00000000"],["78659.24000000","0.00000000"],["78659.32000000","0.00000000"],["78659.99000000","0.00000000"],["78660.00000000","0.00000000"],["78660.01000000","0.00000000"],["78660.32000000","0.00000000"],["78660.33000000","0.00000000"],["78660.34000000","0.00000000"],["78661.14000000","0.00000000"],["78661.45000000","0.00000000"],["78661.46000000","0.00000000"],["78661.62000000","0.00000000"],["78661.83000000","0.00000000"],["78661.99000000","0.00000000"],["78662.00000000","0.01996000"],["78662.01000000","0.00056000"],["78662.66000000","0.00000000"],["78663.63000000","0.00000000"],["78664.10000000","0.00014000"],["78664.11000000","0.00007000"],["78664.66000000","0.05254000"],["78665.18000000","0.00014000"],["78665.19000000","0.01404000"],["78665.83000000","0.00000000"],["78665.99000000","0.00014000"],["78666.00000000","0.02421000"],["78666.44000000","0.00007000"],["78666.45000000","0.02340000"],["78666.58000000","0.00000000"],["78666.59000000","0.00007000"],["78667.71000000","0.02808000"],["78667.99000000","0.00000000"],["78668.00000000","0.02407000"],["78668.97000000","0.02808000"],["78669.18000000","0.00000000"],["78669.41000000","0.17788000"],["78669.44000000","0.20859000"],["78669.73000000","0.00000000"],["78669.92000000","0.00007000"],["78669.99000000","0.00000000"],["78670.00000000","0.02407000"],["78670.03000000","0.00000000"],["78670.05000000","0.00000000"],["78671.19000000","0.00000000"],["78671.20000000","0.00000000"],["78671.30000000","0.12738000"],["78671.37000000","0.00007000"],["78672.69000000","0.00254000"],["78672.70000000","0.00000000"],["78672.80000000","0.00000000"],["78672.90000000","0.00000000"],["78673.06000000","0.00000000"],["78673.08000000","0.00007000"],["78673.23000000","0.00014000"],["78673.80000000","0.01000000"],["78673.86000000","0.00000000"],["78673.87000000","0.00000000"],["78673.88000000","0.00000000"],["78674.30000000","0.00000000"],["78674.64000000","0.00000000"],["78675.49000000","0.00000000"],["78675.59000000","0.00000000"],["78675.60000000","0.06000000"],["78675.70000000","0.00000000"],["78675.72000000","0.00326000"],["78675.74000000","0.00000000"],["78676.21000000","0.00000000"],["78676.25000000","0.00000000"],["78676.68000000","0.00000000"],["78676.90000000","0.00000000"],["78677.02000000","0.31784000"],["78677.03000000","0.00000000"],["78677.10000000","0.00014000"],["78677.11000000","0.04857000"],["78677.12000000","0.00000000"],["78677.13000000","0.00000000"],["78677.34000000","0.00000000"],["78677.50000000","0.00400000"],["78677.90000000","0.08000000"],["78677.94000000","0.00654000"],["78679.20000000","0.00000000"],["78679.38000000","0.00635000"],["78680.05000000","0.00000000"],["78682.95000000","0.02000000"],["78683.43000000","0.00000000"],["78683.96000000","0.00000000"],["78684.00000000","0.24330000"],["78684.54000000","0.06592000"],["78686.51000000","0.07616000"],["78686.70000000","0.00000000"],["78686.90000000","0.00000000"],["78687.30000000","0.00000000"],["78687.56000000","0.00000000"],["78687.74000000","0.00000000"],["78688.21000000","0.00000000"],["78688.39000000","0.00000000"],["78689.13000000","0.00000000"],["78689.89000000","0.00000000"],["78690.00000000","0.02400000"],["78690.45000000","0.09430000"],["78696.70000000","0.00000000"],["78696.87000000","0.00000000"],["78697.49000000","0.00000000"],["78697.85000000","0.00000000"],["78698.00000000","0.02400000"],["78698.32000000","0.00000000"],["78698.59000000","0.00000000"],["78698.76000000","0.00000000"],["78698.92000000","0.00000000"],["78699.30000000","0.00000000"],["78699.38000000","0.00000000"],["78699.74000000","0.00000000"],["78699.82000000","0.00000000"],["78700.00000000","0.12737000"],["78700.32000000","0.00014000"],["78700.37000000","0.00000000"],["78700.45000000","0.00000000"],["78700.59000000","0.00000000"],["78700.61000000","0.00000000"],["78700.82000000","0.00000000"],["78701.00000000","0.00000000"],["78701.18000000","0.00000000"],["78701.71000000","0.00000000"],["78702.00000000","0.03400000"],["78702.26000000","0.00000000"],["78702.34000000","0.00000000"],["78702.48000000","0.00007000"],["78703.82000000","0.68283000"],["78703.87000000","0.00000000"],["78704.30000000","0.00000000"],["78704.90000000","0.00000000"],["78708.06000000","0.00007000"],["78709.56000000","0.00316000"],["78710.00000000","0.11929000"],["78710.90000000","0.00400000"],["78711.30000000","0.86787000"],["78713.25000000","0.00400000"],["78717.19000000","0.88753000"],["78717.50000000","0.00433000"],["78718.44000000","0.00435000"],["78726.54000000","0.00000000"],["78730.57000000","0.90536000"],["78733.37000000","0.00315000"],["78739.37000000","2.13793000"],["78754.49000000","0.00000000"],["78760.63000000","0.00000000"],["78766.72000000","0.00000000"],["78766.98000000","0.21930000"],["78770.04000000","1.21952000"],["78770.36000000","3.46588000"],["78777.99000000","0.00000000"],["78785.47000000","0.00180000"],["78787.99000000","0.00127000"],["78793.16000000","0.00000000"],["78867.30000000","0.00406000"],["78874.15000000","0.00007000"],["78878.08000000","0.00007000"],["78924.37000000","0.00032000"],["79054.02000000","0.00014000"],["79447.64000000","0.00102000"]]}}}
{"rx_ns": 173333541701500, "frame": {"stream":"btcusdt@depth20@100ms","data":{"lastUpdateId":99076745934,"bids":[["78665.18000000","5.77454000"],["78665.17000000","2.39345000"],["78665.16000000","0.00013000"],["78665.10000000","0.05000000"],["78664.66000000","0.04073000"],["78664.65000000","0.00014000"],["78664.00000000","0.07500000"],["78663.99000000","0.42899000"],["78663.90000000","0.00400000"],["78663.20000000","0.00008000"],["78663.11000000","0.00114000"],["78662.34000000","0.04917000"],["78662.00000000","1.29452000"],["78661.99000000","0.73502000"],["78661.62000000","0.00014000"],["78661.55000000","0.00400000"],["78661.45000000","0.00014000"],["78661.44000000","0.44690000"],["78661.40000000","0.00007000"],["78661.13000000","0.00007000"]],"asks":[["78665.19000000","0.01581000"],["78665.20000000","0.00056000"],["78665.49000000","0.00007000"],["78665.68000000","0.00007000"],["78665.99000000","0.00014000"],["78666.00000000","0.02407000"],["78666.44000000","0.00014000"],["78666.45000000","0.02347000"],["78667.00000000","0.00007000"],["78667.28000000","0.00007000"],["78667.70000000","0.00014000"],["78667.71000000","0.02815000"],["78667.83000000","0.00014000"],["78667.84000000","0.05261000"],["78667.99000000","0.00007000"],["78668.00000000","0.02407000"],["78668.05000000","0.00007000"],["78668.97000000","0.02815000"],["78669.31000000","0.00010000"],["78669.33000000","0.00007000"]]}}}
{"rx_ns": 173333541805700, "frame": {"stream":"btcusdt@depth@100ms","data":{"e":"depthUpdate","E":1787603272714,"s":"BTCUSDT","U":99076745249,"u":99076745934,"b":[["78665.18000000","5.77454000"],["78665.17000000","2.39345000"],["78665.16000000","0.00013000"],["78665.15000000","0.00000000"],["78665.10000000","0.05000000"],["78664.66000000","0.04073000"],["78664.65000000","0.00014000"],["78664.64000000","0.00000000"],["78664.63000000","0.00000000"],["78664.10000000","0.00000000"],["78664.09000000","0.00000000"],["78664.05000000","0.00000000"],["78664.00000000","0.07500000"],["78663.99000000","0.42899000"],["78663.98000000","0.00000000"],["78663.97000000","0.00000000"],["78663.90000000","0.00400000"],["78663.20000000","0.00008000"],["78663.18000000","0.00000000"],["78663.12000000","0.00000000"],["78663.11000000","0.00114000"],["78662.34000000","0.04917000"],["78662.00000000","1.29452000"],["78661.99000000","0.73502000"],["78661.98000000","0.00000000"],["78661.97000000","0.00000000"],["78661.55000000","0.00400000"],["78661.46000000","0.00000000"],["78661.45000000","0.00014000"],["78661.44000000","0.44690000"],["78661.40000000","0.00007000"],["78661.35000000","0.00000000"],["78661.15000000","0.00000000"],["78661.14000000","0.00000000"],["78661.13000000","0.00007000"],["78660.79000000","0.00027000"],["78660.34000000","0.00000000"],["78660.33000000","0.00000000"],["78660.32000000","0.00007000"],["78660.18000000","0.04015000"],["78660.12000000","0.00007000"],["78660.00000000","0.00000000"],["78659.99000000","0.34896000"],["78659.87000000","0.02288000"],["78659.16000000","0.00000000"],["78659.00000000","0.00007000"],["78658.00000000","0.00000000"],["78657.99000000","1.36509000"],["78657.98000000","0.00000000"],["78657.95000000","0.00000000"],["78657.66000000","0.04833000"],["78657.65000000","0.00000000"],["78657.31000000","0.00007000"],["78656.94000000","0.38145000"],["78656.65000000","0.00333000"],["78655.99000000","0.00014000"],["78655.55000000","0.00010000"],["78655.39000000","0.00007000"],["78655.00000000","0.00007000"],["78654.71000000","0.08576000"],["78654.67000000","0.00000000"],["78654.66000000","0.00000000"],["78654.26000000","0.34331000"],["78654.16000000","0.00007000"],["78654.13000000","0.00658000"],["78653.87000000","1.52272000"],["78652.52000000","0.30000000"],["78651.53000000","1.22101000"],["78650.96000000","0.13251000"],["78650.95000000","0.00000000"],["78649.99000000","0.00528000"],["78649.11000000","0.00000000"],["78648.32000000","0.00000000"],["78647.86000000","0.00000000"],["78645.99000000","0.00000000"],["78645.44000000","0.34335000"],["78644.71000000","0.00000000"],["78643.51000000","0.00000000"],["78640.93000000","0.00007000"],["78637.85000000","0.00254000"],["78636.63000000","0.00000000"],["78635.72000000","0.00400000"],["78635.19000000","0.00000000"],["78634.05000000","0.00000000"],["78633.99000000","0.00000000"],["78633.09000000","0.00000000"],["78632.65000000","0.00000000"],["78631.11000000","0.00000000"],["78631.00000000","0.00400000"],["78630.57000000","0.00000000"],["78627.98000000","0.00000000"],["78627.60000000","0.00000000"],["78627.57000000","0.00000000"],["78626.30000000","0.00000000"],["78625.38000000","0.00000000"],["78624.36000000","0.02513000"],["78623.95000000","0.00000000"],["78622.93000000","0.02760000"],["78622.92000000","0.00000000"],["78622.21000000","0.00000000"],["78622.00000000","0.03400000"],["78618.00000000","0.02400000"],["78607.15000000","0.00000000"],["78604.17000000","0.00000000"],["78601.05000000","0.00350000"],["78599.82000000","0.00000000"],["78597.78000000","0.00000000"],["78176.00000000","0.06581000"],["70795.80000000","0.00000000"],["70786.24000000","0.00000000"],["70786.23000000","0.00009000"],["66969.80000000","0.00000000"]],"a":[["78662.00000000","0.00000000"],["78662.01000000","0.00000000"],["78663.12000000","0.00000000"],["78663.19000000","0.00000000"],["78663.99000000","0.00000000"],["78664.00000000","0.00000000"],["78664.01000000","0.00000000"],["78664.06000000","0.00000000"],["78664.10000000","0.00000000"],["78664.11000000","0.00000000"],["78664.65000000","0.00000000"],["78664.66000000","0.00000000"],["78665.18000000","0.00000000"],["78665.19000000","0.01581000"],["78665.20000000","0.00056000"],["78665.24000000","0.00000000"],["78665.73000000","0.00000000"],["78666.00000000","0.02407000"],["78666.44000000","0.00014000"],["78666.45000000","0.02347000"],["78666.59000000","0.00000000"],["78666.66000000","0.00000000"],["78666.78000000","0.00000000"],["78667.70000000","0.00014000"],["78667.71000000","0.02815000"],["78667.83000000","0.00014000"],["78667.84000000","0.05261000"],["78667.99000000","0.00007000"],["78668.00000000","0.02407000"],["78668.97000000","0.02815000"],["78669.07000000","0.00000000"],["78669.41000000","0.00014000"],["78669.44000000","0.00014000"],["78669.92000000","0.00000000"],["78670.00000000","0.02407000"],["78670.90000000","0.00000000"],["78671.18000000","0.20859000"],["78671.59000000","0.00000000"],["78672.69000000","0.00000000"],["78673.80000000","0.00000000"],["78675.13000000","0.00000000"],["78675.72000000","0.00000000"],["78676.23000000","0.00007000"],["78676.30000000","0.01000000"],["78677.01000000","0.00254000"],["78677.02000000","0.00000000"],["78677.11000000","0.00000000"],["78677.33000000","0.00000000"],["78677.50000000","0.00000000"],["78677.94000000","0.00400000"],["78678.60000000","0.00008000"],["78678.69000000","0.00000000"],["78678.72000000","0.00000000"],["78678.77000000","0.00000000"],["78678.91000000","0.00331000"],["78679.38000000","0.00000000"],["78679.62000000","0.00048000"],["78680.77000000","0.00254000"],["78680.87000000","0.04857000"],["78681.99000000","0.31782000"],["78682.95000000","0.00000000"],["78682.99000000","0.00000000"],["78685.28000000","0.00254000"],["78685.66000000","0.00000000"],["78685.68000000","0.00635000"],["78686.50000000","0.00400000"],["78687.00000000","0.00007000"],["78687.66000000","0.02000000"],["78687.70000000","0.00000000"],["78688.37000000","0.00000000"],["78688.78000000","0.00126000"],["78690.17000000","0.00000000"],["78690.19000000","0.00227000"],["78690.45000000","0.00000000"],["78691.08000000","0.00163000"],["78691.27000000","0.00000000"],["78691.68000000","0.00000000"],["78691.94000000","0.09333000"],["78693.21000000","0.00000000"],["78694.15000000","0.00000000"],["78694.65000000","0.00000000"],["78700.72000000","0.00000000"],["78700.74000000","0.43604000"],["78701.75000000","0.00000000"],["78701.82000000","0.00060000"],["78702.00000000","0.02400000"],["78702.58000000","0.00000000"],["78702.61000000","0.00000000"],["78702.77000000","0.02803000"],["78703.00000000","0.00000000"],["78703.64000000","0.00000000"],["78704.19000000","0.00014000"],["78704.47000000","0.00000000"],["78704.66000000","0.02369000"],["78704.68000000","0.34309000"],["78704.89000000","0.63536000"],["78704.91000000","0.00000000"],["78705.00000000","0.01000000"],["78707.74000000","0.04584000"],["78710.79000000","0.00000000"],["78742.70000000","1.25741000"],["78747.91000000","0.00010000"],["78757.56000000","0.00000000"],["78762.50000000","0.00012000"],["78768.64000000","0.00019000"],["78776.75000000","1.90515000"],["78781.74000000","0.05719000"],["78875.98000000","0.00000000"],["78878.08000000","0.00000000"],["78902.48000000","0.01991000"],["79003.19000000","0.00018000"],["79041.58000000","0.54998000"]]}}}
{"rx_ns": 173333639930600, "frame": {"stream":"btcusdt@depth20@100ms","data":{"lastUpdateId":99076746444,"bids":[["78665.99000000","4.64645000"],["78665.98000000","0.00020000"],["78665.97000000","0.00013000"],["78665.49000000","0.00014000"],["78665.48000000","0.00007000"],["78665.21000000","0.00014000"],["78665.20000000","0.39298000"],["78665.19000000","2.27673000"],["78665.18000000","0.63504000"],["78665.17000000","0.48817000"],["78665.10000000","0.00007000"],["78664.66000000","0.04080000"],["78664.65000000","0.00007000"],["78664.00000000","0.00014000"],["78663.99000000","0.42899000"],["78663.90000000","0.01035000"],["78663.20000000","0.00008000"],["78663.16000000","0.04917000"],["78663.11000000","0.00107000"],["78662.34000000","0.00007000"]],"asks":[["78666.00000000","0.02570000"],["78666.01000000","0.00056000"],["78666.45000000","0.00007000"],["78667.00000000","0.00007000"],["78667.28000000","0.00007000"],["78667.71000000","0.00007000"],["78667.84000000","0.00014000"],["78667.99000000","0.00014000"],["78668.00000000","0.02407000"],["78668.05000000","0.00007000"],["78668.65000000","0.00014000"],["78668.66000000","0.05254000"],["78668.97000000","0.00007000"],["78669.33000000","0.00007000"],["78669.36000000","0.00007000"],["78669.41000000","0.00007000"],["78669.44000000","0.00007000"],["78669.99000000","0.00014000"],["78670.00000000","0.02407000"],["78670.88000000","0.00007000"]]}}}
{"rx_ns": 173333640073400, "frame": {"stream":"btcusdt@depth@100ms","data":{"e":"depthUpdate","E":1787603272814,"s":"BTCUSDT","U":99076745935,"u":99076746444,"b":[["78665.99000000","4.64645000"],["78665.98000000","0.00020000"],["78665.97000000","0.00013000"],["78665.67000000","0.00000000"],["78665.49000000","0.00014000"],["78665.48000000","0.00007000"],["78665.21000000","0.00014000"],["78665.20000000","0.39298000"],["78665.19000000","2.27673000"],["78665.18000000","0.63504000"],["78665.17000000","0.48817000"],["78665.16000000","0.00000000"],["78665.10000000","0.00007000"],["78664.66000000","0.04080000"],["78664.65000000","0.00007000"],["78664.00000000","0.00014000"],["78663.99000000","0.42899000"],["78663.90000000","0.01035000"],["78663.16000000","0.04917000"],["78663.11000000","0.00107000"],["78662.34000000","0.00007000"],["78662.01000000","0.00000000"],["78662.00000000","1.21952000"],["78661.99000000","0.39197000"],["78661.45000000","0.00000000"],["78661.44000000","0.20337000"],["78661.40000000","0.00000000"],["78660.18000000","0.00000000"],["78659.99000000","0.00188000"],["78658.92000000","0.00000000"],["78657.99000000","1.22292000"],["78657.66000000","0.00014000"],["78655.99000000","0.00007000"],["78655.51000000","0.08576000"],["78655.39000000","0.00000000"],["78655.36000000","0.00007000"],["78655.00000000","0.00000000"],["78654.71000000","0.00000000"],["78654.13000000","0.00000000"],["78651.23000000","0.00190000"],["78649.65000000","0.38548000"],["78648.81000000","0.00059000"],["78647.60000000","0.00007000"],["78647.49000000","0.06595000"],["78647.45000000","0.00412000"],["78645.52000000","0.07620000"],["78642.35000000","0.00007000"],["78641.99000000","0.00000000"],["78641.71000000","0.13801000"],["78640.02000000","0.00000000"],["78639.29000000","0.00000000"],["78638.64000000","0.41188000"],["78637.85000000","0.00000000"],["78635.72000000","0.00000000"],["78635.47000000","0.00000000"],["78628.84000000","0.00000000"],["78628.20000000","0.00000000"],["78626.36000000","0.00000000"],["78625.00000000","0.01000000"],["78623.00000000","0.00000000"],["78622.00000000","0.02400000"],["78614.06000000","0.88869000"],["78598.81000000","0.02400000"],["78591.51000000","0.00000000"],["78589.52000000","0.00000000"],["78568.84000000","2.77418000"],["78564.52000000","0.00000000"],["78558.07000000","0.00000000"],["78547.70000000","0.00000000"],["78538.72000000","0.00000000"],["78510.89000000","0.00000000"],["78440.06000000","0.00000000"],["78438.69000000","0.00000000"],["78256.74000000","0.00000000"],["77865.45000000","0.00000000"],["77476.12000000","0.00000000"],["77088.74000000","0.00000000"],["76703.30000000","0.00070000"],["76319.78000000","0.00000000"],["75938.18000000","0.00000000"],["75558.49000000","0.00000000"],["75180.70000000","0.00000000"],["74804.80000000","0.00000000"],["74430.77000000","0.00000000"],["74058.62000000","0.00000000"],["73688.33000000","0.00000000"],["73319.88000000","0.00000000"],["72953.29000000","0.00000000"],["70799.40000000","0.00016000"],["70798.68000000","0.00000000"],["66865.42000000","0.00017000"]],"a":[["78665.19000000","0.00000000"],["78665.20000000","0.00000000"],["78665.21000000","0.00000000"],["78665.49000000","0.00000000"],["78665.68000000","0.00000000"],["78665.99000000","0.00000000"],["78666.00000000","0.02570000"],["78666.01000000","0.00056000"],["78666.44000000","0.00000000"],["78666.45000000","0.00007000"],["78667.70000000","0.00000000"],["78667.71000000","0.00007000"],["78667.83000000","0.00000000"],["78667.84000000","0.00014000"],["78667.99000000","0.00014000"],["78668.65000000","0.00014000"],["78668.66000000","0.05254000"],["78668.96000000","0.00000000"],["78668.97000000","0.00007000"],["78669.31000000","0.00000000"],["78669.41000000","0.00007000"],["78669.44000000","0.00007000"],["78669.72000000","0.00000000"],["78669.93000000","0.00000000"],["78669.99000000","0.00014000"],["78670.00000000","0.02407000"],["78670.16000000","0.00000000"],["78670.87000000","0.00000000"],["78671.18000000","0.00007000"],["78671.29000000","0.00014000"],["78671.30000000","0.12752000"],["78671.37000000","0.00007000"],["78671.99000000","0.00007000"],["78672.01000000","0.01581000"],["78673.23000000","0.00007000"],["78673.50000000","0.20859000"],["78673.56000000","0.00000000"],["78673.91000000","0.00000000"],["78674.76000000","0.00007000"],["78675.73000000","0.00000000"],["78675.75000000","0.00000000"],["78677.34000000","0.00325000"],["78678.47000000","0.00000000"],["78679.38000000","0.00007000"],["78680.77000000","0.00070000"],["78680.87000000","0.00000000"],["78681.67000000","0.04857000"],["78681.74000000","0.00007000"],["78681.93000000","0.00254000"],["78683.86000000","0.00048000"],["78684.54000000","0.00000000"],["78686.45000000","0.00188000"],["78686.51000000","0.00000000"],["78689.56000000","0.00007000"],["78691.94000000","0.00000000"],["78692.00000000","0.02400000"],["78693.28000000","0.00000000"],["78694.18000000","1.90515000"],["78697.63000000","0.00000000"],["78702.45000000","0.00012000"],["78702.77000000","0.00000000"],["78703.49000000","0.00000000"],["78704.03000000","0.00027000"],["78704.66000000","0.00000000"],["78705.00000000","0.00000000"],["78705.92000000","0.00000000"],["78706.00000000","0.03400000"],["78707.38000000","0.02000000"],["78707.41000000","0.00189000"],["78708.74000000","0.00000000"],["78711.30000000","0.00000000"],["78711.93000000","0.00007000"],["78712.12000000","0.00000000"],["78717.31000000","0.02425000"],["78717.81000000","0.00000000"],["78717.95000000","0.00400000"],["78718.49000000","0.00615000"],["78718.69000000","1.25780000"],["78721.50000000","0.00015000"],["78726.55000000","0.00000000"],["78727.89000000","0.00000000"],["78730.10000000","0.00000000"],["78739.37000000","0.00000000"],["78740.36000000","0.00000000"],["78742.36000000","0.00113000"],["78743.62000000","0.00541000"],["78744.65000000","0.01725000"],["78749.29000000","0.00000000"],["78749.30000000","0.00000000"],["78758.79000000","0.09376000"],["78772.82000000","0.04633000"],["78776.75000000","0.00000000"],["78796.49000000","0.00000000"],["78845.61000000","0.00007000"],["78867.30000000","0.00000000"],["78874.15000000","0.00000000"]]}}}
{"rx_ns": 173333738010000, "frame": {"stream":"btcusdt@depth20@100ms","data":{"lastUpdateId":99076746573,"bids":[["78665.99000000","4.93466000"],["78665.98000000","0.00020000"],["78665.97000000","0.00013000"],["78665.49000000","0.00014000"],["78665.48000000","0.00007000"],["78665.21000000","0.00014000"],["78665.20000000","0.39305000"],["78665.19000000","2.27673000"],["78665.18000000","0.07528000"],["78665.17000000","0.26880000"],["78664.73000000","0.04059000"],["78664.66000000","0.04080000"],["78664.65000000","0.00007000"],["78664.20000000","0.00322000"],["78663.99000000","0.08861000"],["78663.90000000","0.01042000"],["78663.47000000","0.04871000"],["78663.20000000","0.00008000"],["78663.16000000","0.04917000"],["78663.11000000","0.00007000"]],"asks":[["78666.00000000","0.02507000"],["78666.01000000","0.00049000"],["78667.00000000","0.00007000"],["78667.28000000","0.00007000"],["78667.99000000","0.00014000"],["78668.00000000","0.02407000"],["78668.05000000","0.00007000"],["78668.65000000","0.00014000"],["78668.66000000","0.05261000"],["78669.33000000","0.00007000"],["78669.36000000","0.00007000"],["78669.41000000","0.00007000"],["78669.44000000","0.00007000"],["78669.90000000","0.00014000"],["78669.91000000","0.01377000"],["78669.99000000","0.00014000"],["78670.00000000","0.02407000"],["78670.88000000","0.00007000"],["78671.16000000","0.00007000"],["78671.17000000","0.02296000"]]}}}
{"rx_ns": 173333738143800, "frame": {"stream":"btcusdt@depth@100ms","data":{"e":"depthUpdate","E":1787603272914,"s":"BTCUSDT","U":99076746445,"u":99076746573,"b":[["78665.99000000","4.93466000"],["78665.20000000","0.39305000"],["78665.18000000","0.07528000"],["78665.17000000","0.26880000"],["78665.10000000","0.00000000"],["78664.73000000","0.04059000"],["78664.66000000","0.04080000"],["78664.20000000","0.00322000"],["78664.00000000","0.00000000"],["78663.99000000","0.08861000"],["78663.90000000","0.01042000"],["78663.47000000","0.04871000"],["78663.11000000","0.00007000"],["78662.34000000","0.00000000"],["78662.21000000","0.04871000"],["78661.99000000","0.15904000"],["78661.44000000","0.20344000"],["78657.99000000","1.22278000"],["78657.31000000","0.21937000"],["78652.23000000","0.02600000"],["78651.45000000","0.02800000"],["78651.43000000","0.02800000"],["78649.44000000","0.21930000"],["78647.99000000","0.00330000"],["78641.71000000","0.14055000"],["78634.53000000","0.00014000"],["78626.00000000","0.03400000"],["78625.00000000","0.00000000"],["78597.60000000","0.86912000"],["78557.17000000","2.14289000"],["70799.00000000","0.00000000"]],"a":[["78666.00000000","0.02507000"],["78666.01000000","0.00049000"],["78666.45000000","0.00000000"],["78667.71000000","0.00000000"],["78667.84000000","0.00000000"],["78668.00000000","0.02407000"],["78668.66000000","0.05261000"],["78668.97000000","0.00000000"],["78669.90000000","0.00014000"],["78669.91000000","0.01377000"],["78670.00000000","0.02407000"],["78671.16000000","0.00007000"],["78671.17000000","0.02296000"],["78671.18000000","0.00000000"],["78671.29000000","0.00007000"],["78671.75000000","0.00000000"],["78671.99000000","0.00000000"],["78672.00000000","0.02407000"],["78672.01000000","0.00007000"],["78672.43000000","0.02755000"],["78673.50000000","0.20873000"],["78673.69000000","0.02755000"],["78674.00000000","0.02407000"],["78674.19000000","0.00000000"],["78677.34000000","0.00000000"],["78678.91000000","0.00000000"],["78681.93000000","0.00000000"],["78682.98000000","0.00000000"],["78682.99000000","0.00254000"],["78688.55000000","0.02000000"],["78717.40000000","0.86780000"],["78728.74000000","0.04000000"],["78737.01000000","0.02000000"],["78757.87000000","2.13743000"],["78774.73000000","0.00031000"],["78874.35000000","0.00007000"],["78878.28000000","0.00014000"]]}}}
{"rx_ns": 173333838183500, "frame": {"stream":"btcusdt@depth20@100ms","data":{"lastUpdateId":99076746626,"bids":[["78665.99000000","4.93780000"],["78665.98000000","0.00020000"],["78665.97000000","0.00013000"],["78665.49000000","0.00014000"],["78665.48000000","0.00007000"],["78665.21000000","0.00014000"],["78665.20000000","0.39305000"],["78665.19000000","2.05729000"],["78665.18000000","0.07528000"],["78665.17000000","0.26873000"],["78664.73000000","0.04066000"],["78664.66000000","0.04080000"],["78664.65000000","0.00007000"],["78664.20000000","0.00322000"],["78663.99000000","0.08861000"],["78663.90000000","0.01035000"],["78663.47000000","0.04871000"],["78663.20000000","0.00008000"],["78663.16000000","0.04917000"],["78663.11000000","0.00007000"]],"asks":[["78666.00000000","0.02521000"],["78666.01000000","0.00063000"],["78667.00000000","0.00007000"],["78667.28000000","0.00007000"],["78667.99000000","0.00014000"],["78668.00000000","0.02407000"],["78668.05000000","0.00007000"],["78668.65000000","0.00014000"],["78668.66000000","0.05261000"],["78669.33000000","0.00007000"],["78669.36000000","0.00007000"],["78669.41000000","0.00007000"],["78669.44000000","0.00007000"],["78669.90000000","0.00014000"],["78669.91000000","0.01384000"],["78669.99000000","0.00014000"],["78670.00000000","0.02407000"],["78670.88000000","0.00007000"],["78671.16000000","0.00007000"],["78671.17000000","0.02303000"]]}}}
{"rx_ns": 173333838270900, "frame": {"stream":"btcusdt@depth@100ms","data":{"e":"depthUpdate","E":1787603273014,"s":"BTCUSDT","U":99076746574,"u":99076746626,"b":[["78665.99000000","4.93780000"],["78665.19000000","2.05729000"],["78665.17000000","0.26873000"],["78664.73000000","0.04066000"],["78663.90000000","0.01035000"],["78658.52000000","0.02400000"],["78652.23000000","0.32600000"],["78650.01000000","0.63576000"],["78646.01000000","0.00000000"],["78642.80000000","0.00000000"],["78641.76000000","0.00000000"],["78641.45000000","0.00406000"],["78630.25000000","0.21930000"],["78603.38000000","0.00000000"],["72358.00000000","0.01382000"],["70799.40000000","0.00048000"],["62932.80000000","0.00031000"],["62932.79000000","0.00000000"]],"a":[["78666.00000000","0.02521000"],["78666.01000000","0.00063000"],["78668.66000000","0.05261000"],["78669.91000000","0.01384000"],["78670.00000000","0.02407000"],["78671.17000000","0.02303000"],["78672.00000000","0.02407000"],["78672.01000000","0.00000000"],["78672.43000000","0.02762000"],["78673.50000000","0.20866000"],["78674.00000000","0.02400000"],["78677.01000000","0.00000000"],["78678.59000000","0.00508000"],["78682.96000000","0.00000000"],["78682.99000000","0.00000000"],["78694.17000000","0.02161000"],["78694.71000000","0.00000000"],["78730.26000000","0.02000000"],["78761.51000000","0.00180000"],["78785.47000000","0.00000000"],["78878.28000000","0.00007000"]]}}}
{"rx_ns": 173333940197400, "frame": {"stream":"btcusdt@depth20@100ms","data":{"lastUpdateId":99076746659,"bids":[["78665.99000000","4.93780000"],["78665.98000000","0.00020000"],["78665.97000000","0.00013000"],["78665.49000000","0.00014000"],["78665.48000000","0.00007000"],["78665.21000000","0.00014000"],["78665.20000000","0.39305000"],["78665.19000000","2.05729000"],["78665.18000000","0.07528000"],["78665.17000000","0.26873000"],["78664.73000000","0.04066000"],["78664.66000000","0.04080000"],["78664.65000000","0.00007000"],["78664.20000000","0.00322000"],["78663.99000000","0.08861000"],["78663.90000000","0.01035000"],["78663.47000000","0.04871000"],["78663.20000000","0.00008000"],["78663.16000000","0.04917000"],["78663.11000000","0.00007000"]],"asks":[["78666.00000000","0.02521000"],["78666.01000000","0.00063000"],["78667.00000000","0.00007000"],["78667.28000000","0.00007000"],["78667.99000000","0.00014000"],["78668.00000000","0.02407000"],["78668.05000000","0.00007000"],["78668.65000000","0.00014000"],["78668.66000000","0.05261000"],["78669.33000000","0.00007000"],["78669.36000000","0.00007000"],["78669.41000000","0.00007000"],["78669.44000000","0.00007000"],["78669.90000000","0.00014000"],["78669.91000000","0.01384000"],["78669.99000000","0.00014000"],["78670.00000000","0.02407000"],["78670.88000000","0.00007000"],["78671.16000000","0.00007000"],["78671.17000000","0.02303000"]]}}}
{"rx_ns": 173333940283300, "frame": {"stream":"btcusdt@depth@100ms","data":{"e":"depthUpdate","E":1787603273115,"s":"BTCUSDT","U":99076746627,"u":99076746659,"b":[["78662.01000000","0.00014000"],["78657.72000000","0.02200000"],["78655.99000000","0.00000000"],["78655.37000000","0.02400000"],["78655.36000000","0.00014000"],["78653.80000000","0.02000000"],["78653.69000000","0.02000000"],["78647.98000000","0.00007000"],["78643.59000000","0.00000000"],["78642.79000000","0.00000000"],["78638.96000000","0.00000000"],["78638.85000000","0.02200000"],["78636.18000000","0.00000000"],["78630.27000000","0.00000000"],["78601.79000000","0.00000000"],["78595.51000000","0.00000000"],["77942.14000000","0.00000000"],["70799.40000000","0.00064000"]],"a":[["78674.28000000","0.20694000"],["78681.91000000","0.00254000"],["78681.95000000","0.00000000"],["78691.58000000","0.02000000"],["78697.62000000","0.00000000"],["78728.63000000","0.02000000"],["78734.63000000","0.02000000"],["78736.21000000","0.02000000"],["78748.96000000","0.02000000"],["78762.50000000","0.00000000"],["78768.64000000","0.00000000"],["78771.76000000","0.00007000"],["78774.73000000","0.00000000"]]}}}
{"rx_ns": 173334037847500, "frame": {"stream":"btcusdt@depth20@100ms","data":{"lastUpdateId":99076746802,"bids":[["78666.00000000","6.32800000"],["78665.99000000","2.20051000"],["78665.98000000","0.00013000"],["78665.49000000","0.00014000"],["78665.48000000","0.00007000"],["78665.20000000","0.07521000"],["78665.19000000","0.15214000"],["78665.18000000","0.00627000"],["78665.17000000","0.26873000"],["78664.73000000","0.04066000"],["78664.66000000","0.04080000"],["78664.65000000","0.00007000"],["78664.20000000","0.00322000"],["78663.99000000","0.08861000"],["78663.90000000","0.00400000"],["78663.47000000","0.04871000"],["78663.20000000","0.00008000"],["78663.16000000","0.04917000"],["78663.11000000","0.00007000"],["78662.21000000","0.04871000"]],"asks":[["78666.01000000","0.00202000"],["78666.02000000","0.00069000"],["78666.03000000","0.00013000"],["78667.00000000","0.00007000"],["78667.28000000","0.00007000"],["78667.99000000","0.00014000"],["78668.00000000","0.02407000"],["78668.05000000","0.00007000"],["78668.65000000","0.00014000"],["78668.66000000","0.05261000"],["78669.33000000","0.00007000"],["78669.36000000","0.00007000"],["78669.41000000","0.00007000"],["78669.44000000","0.00007000"],["78669.54000000","0.00007000"],["78669.90000000","0.00014000"],["78669.91000000","0.01384000"],["78669.99000000","0.00014000"],["78670.00000000","0.02407000"],["78670.88000000","0.00007000"]]}}}
{"rx_ns": 173334037936200, "frame": {"stream":"btcusdt@depth@100ms","data":{"e":"depthUpdate","E":1787603273214,"s":"BTCUSDT","U":99076746660,"u":99076746802,"b":[["78666.00000000","6.32800000"],["78665.99000000","2.20051000"],["78665.98000000","0.00013000"],["78665.97000000","0.00000000"],["78665.21000000","0.00000000"],["78665.20000000","0.07521000"],["78665.19000000","0.15214000"],["78665.18000000","0.00627000"],["78663.90000000","0.00400000"],["78662.01000000","0.00000000"],["78658.54000000","0.00000000"],["78656.65000000","0.00326000"],["78654.59000000","0.02000000"],["78653.80000000","0.32000000"],["78653.79000000","0.02000000"],["78653.70000000","0.02200000"],["78653.69000000","0.32000000"],["78653.19000000","0.34332000"],["78652.97000000","0.00007000"],["78652.15000000","0.00400000"],["78652.00000000","0.00007000"],["78643.68000000","0.00000000"],["78612.50000000","0.00636000"],["78601.19000000","0.00000000"],["78100.67000000","0.00065000"],["70799.40000000","0.00080000"],["62932.80000000","0.00000000"]],"a":[["78666.00000000","0.00000000"],["78666.01000000","0.00202000"],["78666.02000000","0.00069000"],["78666.03000000","0.00013000"],["78669.54000000","0.00007000"],["78671.30000000","0.12759000"],["78672.61000000","0.02521000"],["78673.47000000","0.16367000"],["78673.50000000","0.20873000"],["78674.28000000","0.00000000"],["78679.29000000","0.00349000"],["78679.33000000","0.01745000"],["78681.86000000","0.00254000"],["78681.91000000","0.00000000"],["78706.15000000","0.02382000"],["78707.47000000","0.36308000"],["78735.61000000","0.02000000"],["78736.20000000","0.02000000"],["78736.38000000","0.02600000"],["78747.52000000","0.00000000"],["78763.54000000","0.00025000"],["78770.51000000","0.00012000"],["78776.64000000","0.00019000"],["78809.19000000","0.00406000"]]}}}
{"rx_ns": 173334143996900, "frame": {"stream":"btcusdt@depth20@100ms","data":{"lastUpdateId":99076746869,"bids":[["78666.00000000","6.34569000"],["78665.99000000","2.18688000"],["78665.98000000","0.00013000"],["78665.49000000","0.00014000"],["78665.48000000","0.00007000"],["78665.20000000","0.07521000"],["78665.19000000","0.15214000"],["78665.18000000","0.00627000"],["78665.17000000","0.26873000"],["78664.73000000","0.04066000"],["78664.66000000","0.04080000"],["78664.65000000","0.00007000"],["78664.20000000","0.00322000"],["78664.05000000","0.00007000"],["78663.99000000","0.08854000"],["78663.90000000","0.00400000"],["78663.47000000","0.04871000"],["78663.20000000","0.00008000"],["78663.16000000","0.04917000"],["78663.11000000","0.00007000"]],"asks":[["78666.01000000","0.00195000"],["78666.02000000","0.00069000"],["78666.03000000","0.00013000"],["78667.00000000","0.00007000"],["78667.28000000","0.00007000"],["78667.99000000","0.00014000"],["78668.00000000","0.02407000"],["78668.05000000","0.00007000"],["78668.65000000","0.00014000"],["78668.66000000","0.05261000"],["78669.33000000","0.00007000"],["78669.36000000","0.00007000"],["78669.41000000","0.00007000"],["78669.44000000","0.00007000"],["78669.54000000","0.00007000"],["78669.90000000","0.00014000"],["78669.91000000","0.01384000"],["78669.99000000","0.00014000"],["78670.00000000","0.02407000"],["78670.88000000","0.00007000"]]}}}
{"rx_ns": 173334144138600, "frame": {"stream":"btcusdt@depth@100ms","data":{"e":"depthUpdate","E":1787603273314,"s":"BTCUSDT","U":99076746803,"u":99076746869,"b":[["78666.00000000","6.34569000"],["78665.99000000","2.18688000"],["78664.05000000","0.00007000"],["78663.99000000","0.08854000"],["78660.12000000","0.00000000"],["78654.58000000","0.02400000"],["78653.79000000","0.32000000"],["78653.70000000","0.32200000"],["78652.52000000","0.00000000"],["78652.23000000","0.02600000"],["78646.22000000","0.50339000"],["78642.88000000","0.00000000"],["78640.53000000","0.00000000"],["78638.95000000","0.00000000"],["78638.85000000","0.00000000"],["78272.67000000","0.01000000"],["77881.30000000","0.01000000"],["77491.90000000","0.01000000"],["77104.44000000","0.01000000"],["76718.91000000","0.01000000"],["76335.32000000","0.01000000"],["75953.64000000","0.01000000"],["75573.87000000","0.01000000"],["75196.00000000","0.01000000"],["74820.02000000","0.01000000"],["74445.92000000","0.01000000"],["74073.69000000","0.01000000"],["73703.33000000","0.01000000"],["73334.81000000","0.01000000"],["72968.14000000","0.01000000"],["70799.40000000","0.00096000"],["62933.00000000","0.00000000"]],"a":[["78666.01000000","0.00195000"],["78672.43000000","0.02762000"],["78672.61000000","0.00007000"],["78672.65000000","0.00508000"],["78673.50000000","0.20866000"],["78681.84000000","0.00254000"],["78681.86000000","0.00000000"],["78693.41000000","0.09311000"],["78704.26000000","0.02722000"],["78706.00000000","0.73400000"],["78732.74000000","0.02000000"],["79059.35000000","0.01000000"],["79454.64000000","0.01000000"],["79851.91000000","0.01000000"],["80251.17000000","0.01000000"],["80652.43000000","0.01000000"],["81055.69000000","0.01000000"],["81460.97000000","0.01000000"],["81868.28000000","0.01000000"],["82277.62000000","0.01000000"],["82689.01000000","0.01000000"],["83102.45000000","0.01000000"],["83517.96000000","0.01000000"],["83935.55000000","0.01000000"],["84355.23000000","0.01000000"],["84777.01000000","0.01000000"]]}}}
{"rx_ns": 173334237990500, "frame": {"stream":"btcusdt@depth20@100ms","data":{"lastUpdateId":99076746902,"bids":[["78666.00000000","6.39590000"],["78665.99000000","1.96758000"],["78665.98000000","0.00013000"],["78665.95000000","0.05000000"],["78665.49000000","0.00014000"],["78665.48000000","0.00007000"],["78665.20000000","0.07521000"],["78665.19000000","0.15214000"],["78665.18000000","0.00641000"],["78665.17000000","0.26873000"],["78664.73000000","0.04066000"],["78664.66000000","0.04080000"],["78664.65000000","0.00007000"],["78664.20000000","0.00322000"],["78664.05000000","0.00007000"],["78663.99000000","0.08861000"],["78663.90000000","0.00400000"],["78663.47000000","0.04871000"],["78663.20000000","0.00008000"],["78663.16000000","0.04917000"]],"asks":[["78666.01000000","0.00177000"],["78666.02000000","0.00069000"],["78666.03000000","0.00013000"],["78667.00000000","0.00007000"],["78667.28000000","0.00007000"],["78667.99000000","0.00014000"],["78668.00000000","0.02407000"],["78668.05000000","0.00007000"],["78668.65000000","0.00014000"],["78668.66000000","0.05261000"],["78669.33000000","0.00007000"],["78669.36000000","0.00007000"],["78669.41000000","0.00007000"],["78669.44000000","0.00007000"],["78669.54000000","0.00007000"],["78669.90000000","0.00014000"],["78669.91000000","0.01384000"],["78669.99000000","0.00014000"],["78670.00000000","0.02407000"],["78670.88000000","0.00007000"]]}}}
{"rx_ns": 173334238134400, "frame": {"stream":"btcusdt@depth@100ms","data":{"e":"depthUpdate","E":1787603273414,"s":"BTCUSDT","U":99076746870,"u":99076746902,"b":[["78666.00000000","6.39590000"],["78665.99000000","1.96758000"],["78665.95000000","0.05000000"],["78665.18000000","0.00641000"],["78663.99000000","0.08861000"],["78657.70000000","0.02200000"],["78651.48000000","0.00007000"],["78650.95000000","0.12714000"],["78639.74000000","0.00000000"],["78531.20000000","0.00000000"],["70799.40000000","0.00112000"],["70786.23000000","0.00000000"]],"a":[["78666.01000000","0.00177000"],["78672.43000000","0.02762000"],["78672.61000000","0.00000000"],["78672.65000000","0.00007000"],["78673.15000000","0.00508000"],["78681.82000000","0.00254000"],["78681.84000000","0.00000000"],["78729.60000000","0.02000000"],["78782.74000000","0.00031000"],["78880.01000000","0.00406000"]]}}}
{"rx_ns": 173334348496600, "frame": {"stream":"btcusdt@depth20@100ms","data":{"lastUpdateId":99076747168,"bids":[["78667.99000000","5.05479000"],["78667.98000000","0.00020000"],["78667.97000000","0.00013000"],["78666.99000000","0.00007000"],["78666.02000000","0.00014000"],["78666.01000000","0.72121000"],["78666.00000000","4.42931000"],["78665.99000000","0.03781000"],["78665.95000000","0.00007000"],["78665.49000000","0.00014000"],["78665.48000000","0.00007000"],["78665.20000000","0.07507000"],["78665.19000000","0.07714000"],["78665.18000000","0.00014000"],["78665.17000000","0.06014000"],["78665.16000000","0.04917000"],["78664.73000000","0.00007000"],["78664.66000000","0.04073000"],["78664.65000000","0.00007000"],["78664.20000000","0.00322000"]],"asks":[["78668.00000000","0.02728000"],["78668.01000000","0.00056000"],["78668.05000000","0.00007000"],["78668.66000000","0.00007000"],["78669.33000000","0.00007000"],["78669.36000000","0.00007000"],["78669.41000000","0.00007000"],["78669.44000000","0.00007000"],["78669.54000000","0.00007000"],["78669.91000000","0.00007000"],["78669.99000000","0.00014000"],["78670.00000000","0.02407000"],["78670.65000000","0.00014000"],["78670.66000000","0.05254000"],["78670.88000000","0.00007000"],["78671.17000000","0.00007000"],["78671.30000000","0.00048000"],["78671.37000000","0.00007000"],["78671.58000000","0.00007000"],["78671.99000000","0.00014000"]]}}}
{"rx_ns": 173334348583100, "frame": {"stream":"btcusdt@depth@100ms","data":{"e":"depthUpdate","E":1787603273514,"s":"BTCUSDT","U":99076746903,"u":99076747168,"b":[["78667.99000000","5.05479000"],["78667.98000000","0.00020000"],["78667.97000000","0.00013000"],["78667.27000000","0.00000000"],["78666.99000000","0.00007000"],["78666.02000000","0.00014000"],["78666.01000000","0.72121000"],["78666.00000000","4.42931000"],["78665.99000000","0.03781000"],["78665.98000000","0.00000000"],["78665.95000000","0.00007000"],["78665.20000000","0.07507000"],["78665.19000000","0.07714000"],["78665.18000000","0.00014000"],["78665.17000000","0.06014000"],["78665.16000000","0.04917000"],["78664.73000000","0.00007000"],["78664.66000000","0.04073000"],["78663.99000000","0.08854000"],["78663.47000000","0.00000000"],["78663.16000000","0.00000000"],["78662.21000000","0.00000000"],["78661.44000000","0.00332000"],["78659.99000000","0.00007000"],["78658.17000000","0.00007000"],["78657.74000000","0.00000000"],["78657.66000000","0.00000000"],["78657.37000000","0.08576000"],["78655.51000000","0.00000000"],["78654.27000000","0.00000000"],["78654.07000000","0.02000000"],["78650.95000000","0.00000000"],["78626.79000000","0.00000000"],["78577.12000000","0.00000000"],["70799.40000000","0.00000000"],["62934.40000000","0.00031000"]],"a":[["78666.01000000","0.00000000"],["78666.02000000","0.00000000"],["78666.03000000","0.00000000"],["78667.00000000","0.00000000"],["78667.28000000","0.00000000"],["78667.99000000","0.00000000"],["78668.00000000","0.02728000"],["78668.01000000","0.00056000"],["78668.65000000","0.00000000"],["78668.66000000","0.00007000"],["78669.90000000","0.00000000"],["78669.91000000","0.00007000"],["78670.65000000","0.00014000"],["78670.66000000","0.05254000"],["78671.16000000","0.00000000"],["78671.17000000","0.00007000"],["78671.29000000","0.00000000"],["78671.30000000","0.00048000"],["78671.99000000","0.00014000"],["78672.42000000","0.00000000"],["78672.43000000","0.00007000"],["78672.65000000","0.00000000"],["78673.15000000","0.00007000"],["78673.46000000","0.00014000"],["78673.49000000","0.00007000"],["78673.69000000","0.00000000"],["78681.67000000","0.00000000"],["78681.82000000","0.00000000"],["78682.18000000","0.00000000"],["78682.52000000","0.00007000"],["78682.58000000","0.00254000"],["78683.53000000","0.04857000"],["78693.41000000","0.00000000"],["78704.26000000","0.00000000"],["78704.54000000","0.02831000"],["78706.00000000","0.72400000"],["78706.15000000","0.00007000"],["78706.43000000","0.02412000"],["78708.00000000","0.03407000"],["78709.56000000","0.00000000"],["78717.18000000","0.00317000"],["78733.21000000","0.02600000"],["78737.69000000","0.00180000"],["78761.51000000","0.00000000"],["78936.83000000","0.00000000"],["78966.93000000","1.19998000"],["79059.35000000","0.00000000"],["79454.64000000","0.00000000"],["79851.91000000","0.00000000"],["80251.17000000","0.00000000"],["80652.43000000","0.00000000"],["81055.69000000","0.00000000"],["81460.97000000","0.00000000"],["81868.28000000","0.00000000"],["82277.62000000","0.00000000"],["82689.01000000","0.00000000"],["83102.45000000","0.00000000"],["83517.96000000","0.00000000"],["83935.55000000","0.00000000"],["84355.23000000","0.00000000"],["84777.01000000","0.00000000"]]}}}
{"rx_ns": 173334444539600, "frame": {"stream":"btcusdt@depth20@100ms","data":{"lastUpdateId":99076747271,"bids":[["78667.99000000","5.09354000"],["78667.98000000","0.00020000"],["78667.97000000","0.00013000"],["78667.96000000","0.00014000"],["78667.95000000","0.05000000"],["78667.91000000","0.00014000"],["78667.90000000","0.05000000"],["78667.65000000","0.00254000"],["78666.99000000","0.00676000"],["78666.73000000","0.04059000"],["78666.02000000","0.00014000"],["78666.01000000","0.46239000"],["78666.00000000","3.93742000"],["78665.99000000","0.03781000"],["78665.49000000","0.00014000"],["78665.48000000","0.00007000"],["78665.47000000","0.04871000"],["78665.20000000","0.07507000"],["78665.19000000","0.07714000"],["78665.18000000","0.00007000"]],"asks":[["78668.00000000","0.02721000"],["78668.01000000","0.00063000"],["78668.05000000","0.00007000"],["78669.33000000","0.00007000"],["78669.36000000","0.00007000"],["78669.41000000","0.00007000"],["78669.44000000","0.00007000"],["78669.54000000","0.00007000"],["78669.99000000","0.00014000"],["78670.00000000","0.02407000"],["78670.65000000","0.00014000"],["78670.66000000","0.05261000"],["78670.88000000","0.00007000"],["78671.30000000","0.00041000"],["78671.37000000","0.00007000"],["78671.90000000","0.00014000"],["78671.91000000","0.01377000"],["78671.99000000","0.00014000"],["78672.00000000","0.02407000"],["78673.00000000","0.00007000"]]}}}
{"rx_ns": 173334444664300, "frame": {"stream":"btcusdt@depth@100ms","data":{"e":"depthUpdate","E":1787603273614,"s":"BTCUSDT","U":99076747169,"u":99076747271,"b":[["78667.99000000","5.09354000"],["78667.96000000","0.00014000"],["78667.95000000","0.05000000"],["78667.91000000","0.00014000"],["78667.90000000","0.05000000"],["78667.65000000","0.00254000"],["78666.99000000","0.00676000"],["78666.73000000","0.04059000"],["78666.01000000","0.46239000"],["78666.00000000","3.93742000"],["78665.99000000","0.03781000"],["78665.95000000","0.00000000"],["78665.47000000","0.04871000"],["78665.19000000","0.07714000"],["78665.18000000","0.00007000"],["78665.17000000","0.06014000"],["78665.16000000","0.04924000"],["78664.73000000","0.00000000"],["78664.21000000","0.04871000"],["78661.44000000","0.00325000"],["78653.89000000","0.00007000"],["78628.00000000","0.03400000"],["78626.00000000","0.02400000"],["78622.93000000","0.00000000"],["78610.98000000","0.00000000"],["78606.12000000","0.00316000"],["78592.43000000","0.00000000"],["78586.18000000","0.00000000"],["78585.68000000","0.00000000"],["78584.09000000","0.00315000"],["78571.48000000","0.00000000"],["78527.78000000","0.00127000"],["78523.48000000","0.00406000"],["78509.13000000","0.00000000"],["78506.11000000","0.00127000"],["78494.87000000","0.00960000"],["78488.08000000","0.00000000"],["78475.47000000","0.00000000"],["78440.80000000","0.00000000"],["70801.20000000","0.00032000"],["62934.40000000","0.00000000"]],"a":[["78668.00000000","0.02721000"],["78668.01000000","0.00063000"],["78668.66000000","0.00000000"],["78669.91000000","0.00000000"],["78670.00000000","0.02407000"],["78670.66000000","0.05261000"],["78671.17000000","0.00000000"],["78671.30000000","0.00041000"],["78671.58000000","0.00000000"],["78671.90000000","0.00014000"],["78671.91000000","0.01377000"],["78672.00000000","0.02407000"],["78672.43000000","0.00000000"],["78673.15000000","0.00000000"],["78673.16000000","0.00007000"],["78673.17000000","0.02296000"],["78673.46000000","0.00007000"],["78673.47000000","0.16374000"],["78673.49000000","0.00000000"],["78673.50000000","0.20873000"],["78673.83000000","0.00000000"],["78674.00000000","0.02407000"],["78674.25000000","0.02294000"],["78674.43000000","0.02755000"],["78675.60000000","0.06007000"],["78675.69000000","0.02755000"],["78684.08000000","0.12709000"],["78691.92000000","0.12707000"],["78697.28000000","0.09439000"],["78704.54000000","0.00000000"],["78706.43000000","0.00000000"],["78733.37000000","0.00000000"],["78739.34000000","0.00317000"],["78748.96000000","0.00000000"],["78787.99000000","0.00000000"],["78795.99000000","0.00127000"],["78809.43000000","0.00000000"],["78819.87000000","0.00127000"]]}}}
{"rx_ns": 173334541391200, "frame": {"stream":"btcusdt@depth20@100ms","data":{"lastUpdateId":99076747401,"bids":[["78667.99000000","5.42807000"],["78667.98000000","0.00020000"],["78667.97000000","0.00013000"],["78667.96000000","0.00014000"],["78667.95000000","0.05014000"],["78667.91000000","0.00014000"],["78667.90000000","0.05007000"],["78666.99000000","0.00683000"],["78666.74000000","0.00014000"],["78666.73000000","0.04066000"],["78666.01000000","0.00021000"],["78666.00000000","3.47414000"],["78665.99000000","0.03781000"],["78665.61000000","0.00400000"],["78665.49000000","0.00014000"],["78665.48000000","0.00007000"],["78665.47000000","0.04871000"],["78665.20000000","0.07500000"],["78665.19000000","0.00007000"],["78665.18000000","0.00007000"]],"asks":[["78668.00000000","0.02726000"],["78668.01000000","0.00070000"],["78669.33000000","0.00007000"],["78669.36000000","0.00007000"],["78669.41000000","0.00007000"],["78669.44000000","0.00007000"],["78669.54000000","0.00007000"],["78669.99000000","0.00014000"],["78670.00000000","0.02407000"],["78670.65000000","0.00014000"],["78670.66000000","0.05261000"],["78670.88000000","0.00007000"],["78671.30000000","0.00041000"],["78671.37000000","0.00007000"],["78671.90000000","0.00014000"],["78671.91000000","0.01384000"],["78671.99000000","0.00014000"],["78672.00000000","0.02407000"],["78673.00000000","0.00007000"],["78673.08000000","0.00007000"]]}}}
{"rx_ns": 173334541481900, "frame": {"stream":"btcusdt@depth@100ms","data":{"e":"depthUpdate","E":1787603273714,"s":"BTCUSDT","U":99076747272,"u":99076747401,"b":[["78667.99000000","5.42807000"],["78667.95000000","0.05014000"],["78667.90000000","0.05007000"],["78667.65000000","0.00000000"],["78667.54000000","0.00000000"],["78667.53000000","0.00000000"],["78667.30000000","0.00000000"],["78666.99000000","0.00683000"],["78666.74000000","0.00014000"],["78666.73000000","0.04066000"],["78666.14000000","0.00000000"],["78666.02000000","0.00000000"],["78666.01000000","0.00021000"],["78666.00000000","3.47414000"],["78665.99000000","0.03781000"],["78665.61000000","0.00400000"],["78665.20000000","0.07500000"],["78665.19000000","0.00007000"],["78665.17000000","0.06007000"],["78665.16000000","0.04917000"],["78664.73000000","0.00254000"],["78664.20000000","0.00000000"],["78663.91000000","0.00332000"],["78659.41000000","0.00000000"],["78657.06000000","0.00007000"],["78650.01000000","0.00014000"],["78648.02000000","0.63561000"],["78644.00000000","2.63550000"],["77551.49000000","0.00007000"],["70801.20000000","0.00073000"]],"a":[["78668.00000000","0.02726000"],["78668.01000000","0.00070000"],["78668.05000000","0.00000000"],["78670.66000000","0.05261000"],["78670.88000000","0.00007000"],["78671.91000000","0.01384000"],["78672.00000000","0.02407000"],["78672.25000000","0.00000000"],["78672.26000000","0.00000000"],["78673.17000000","0.02303000"],["78673.23000000","0.00014000"],["78673.46000000","0.02161000"],["78673.47000000","0.00007000"],["78673.50000000","0.00014000"],["78674.25000000","0.02287000"],["78675.60000000","0.06000000"],["78675.87000000","0.00000000"],["78679.28000000","0.00000000"],["78679.29000000","0.00000000"],["78679.33000000","0.00000000"],["78680.46000000","0.00254000"],["78681.99000000","0.31781000"],["78682.58000000","0.00000000"],["78682.66000000","0.00000000"],["78683.74000000","0.00320000"],["78694.16000000","0.36231000"],["78711.93000000","0.00000000"],["78783.84000000","0.00160000"],["78876.36000000","0.00007000"],["78880.29000000","0.00007000"]]}}}
