{"captured_at": "2026-08-24T20:27:43.120160+00:00", "url": "wss://data-stream.binance.vision/stream?streams=btcusdt@depth@100ms/btcusdt@depth20@100ms", "venue": "binance", "symbol": "BTCUSDT", "streams": ["depth@100ms", "depth20@100ms"], "combined": true, "rest_url": "https://data-api.binance.vision/api/v3/depth?symbol=BTCUSDT&limit=1000", "rest_limit": 1000, "rest_weight_per_fetch": 50, "snapshot_every_s": 20.0, "tool_version": "0.1.0", "clock": "perf_counter_ns", "capture_mode": "baseline", "cycles": 1, "origin_sent": null, "handshake_status": "HTTP/1.1 101 Switching Protocols"}
{"rx_ns": 173325040360500, "frame": {"stream":"btcusdt@depth20@100ms","data":{"lastUpdateId":99076734269,"bids":[["78629.99000000","5.58166000"],["78629.98000000","1.90542000"],["78629.97000000","0.00013000"],["78629.76000000","0.00400000"],["78629.47000000","0.01932000"],["78629.40000000","0.00014000"],["78629.39000000","0.20019000"],["78629.38000000","0.03042000"],["78629.37000000","1.21959000"],["78629.28000000","0.01985000"],["78629.07000000","0.00327000"],["78628.21000000","0.03216000"],["78628.00000000","0.07500000"],["78627.99000000","0.00541000"],["78627.87000000","0.00007000"],["78627.85000000","0.03007000"],["78627.79000000","0.07500000"],["78627.57000000","0.00400000"],["78627.10000000","0.04810000"],["78626.99000000","0.00254000"]],"asks":[["78630.00000000","0.02655000"],["78630.01000000","0.00070000"],["78630.66000000","0.00007000"],["78630.73000000","0.00014000"],["78630.74000000","0.01896000"],["78631.01000000","0.00007000"],["78631.24000000","0.00007000"],["78631.66000000","0.00007000"],["78631.99000000","0.00014000"],["78632.00000000","0.05556000"],["78632.08000000","0.00007000"],["78632.52000000","0.00007000"],["78632.59000000","0.00014000"],["78632.60000000","0.05372000"],["78632.92000000","0.00007000"],["78633.25000000","0.00014000"],["78633.26000000","0.03786000"],["78633.41000000","0.00007000"],["78633.99000000","0.00007000"],["78634.00000000","0.02407000"]]}}}
{"rx_ns": 173325040457300, "frame": {"stream":"btcusdt@depth@100ms","data":{"e":"depthUpdate","E":1787603264214,"s":"BTCUSDT","U":99076734247,"u":99076734269,"b":[["78629.99000000","5.58166000"],["78606.36000000","0.00007000"],["78605.14000000","0.00000000"],["78565.83000000","0.00000000"],["78534.39000000","0.00000000"],["78487.23000000","0.00000000"],["78416.48000000","0.00000000"],["70767.00000000","0.00176000"],["62904.00000000","0.00000000"]],"a":[["78630.00000000","0.02655000"],["78639.17000000","0.00000000"],["78653.55000000","0.00007000"],["78657.43000000","0.00000000"],["78667.46000000","0.02826000"],["78696.76000000","0.00406000"],["78702.52000000","1.25805000"]]}}}
{"rx_ns": 173325140318800, "frame": {"stream":"btcusdt@depth20@100ms","data":{"lastUpdateId":99076734287,"bids":[["78629.99000000","5.58610000"],["78629.98000000","1.90542000"],["78629.97000000","0.00013000"],["78629.76000000","0.00400000"],["78629.47000000","0.01932000"],["78629.40000000","0.00014000"],["78629.39000000","0.20019000"],["78629.38000000","0.03042000"],["78629.37000000","1.21959000"],["78629.28000000","0.01985000"],["78629.07000000","0.00327000"],["78628.21000000","0.03216000"],["78628.00000000","0.07500000"],["78627.99000000","0.00541000"],["78627.87000000","0.00007000"],["78627.85000000","0.03007000"],["78627.79000000","0.07500000"],["78627.57000000","0.00400000"],["78627.10000000","0.04810000"],["78626.99000000","0.00254000"]],"asks":[["78630.00000000","0.02594000"],["78630.01000000","0.00070000"],["78630.66000000","0.00007000"],["78630.73000000","0.00014000"],["78630.74000000","0.01896000"],["78631.01000000","0.00007000"],["78631.24000000","0.00007000"],["78631.66000000","0.00007000"],["78631.99000000","0.00014000"],["78632.00000000","0.05556000"],["78632.08000000","0.00007000"],["78632.52000000","0.00007000"],["78632.59000000","0.00014000"],["78632.60000000","0.05372000"],["78632.92000000","0.00007000"],["78633.25000000","0.00014000"],["78633.26000000","0.03786000"],["78633.36000000","0.00007000"],["78633.41000000","0.00007000"],["78633.99000000","0.00007000"]]}}}
{"rx_ns": 173325140406100, "frame": {"stream":"btcusdt@depth@100ms","data":{"e":"depthUpdate","E":1787603264314,"s":"BTCUSDT","U":99076734270,"u":99076734287,"b":[["78629.99000000","5.58610000"],["78573.77000000","0.00200000"],["78557.44000000","0.02400000"],["62899.00000000","0.01012000"]],"a":[["78630.00000000","0.02594000"],["78633.36000000","0.00007000"],["78636.18000000","0.17026000"],["78637.88000000","0.00000000"],["78639.06000000","0.00000000"],["78639.17000000","0.00048000"],["78640.63000000","0.00000000"],["78643.12000000","0.00000000"]]}}}
{"rx_ns": 173325238501100, "frame": {"stream":"btcusdt@depth20@100ms","data":{"lastUpdateId":99076734310,"bids":[["78629.99000000","5.58610000"],["78629.98000000","1.90542000"],["78629.97000000","0.00013000"],["78629.76000000","0.00400000"],["78629.47000000","0.01932000"],["78629.40000000","0.00014000"],["78629.39000000","0.20019000"],["78629.38000000","0.03042000"],["78629.37000000","1.21959000"],["78629.28000000","0.01985000"],["78629.07000000","0.00327000"],["78628.21000000","0.03216000"],["78628.00000000","0.07500000"],["78627.99000000","0.00541000"],["78627.87000000","0.00007000"],["78627.85000000","0.03007000"],["78627.79000000","0.07500000"],["78627.57000000","0.00400000"],["78627.10000000","0.04810000"],["78626.99000000","0.00254000"]],"asks":[["78630.00000000","0.02601000"],["78630.01000000","0.00070000"],["78630.22000000","0.00007000"],["78630.66000000","0.00007000"],["78630.73000000","0.00014000"],["78630.74000000","0.01896000"],["78631.01000000","0.00007000"],["78631.24000000","0.00007000"],["78631.66000000","0.00007000"],["78631.99000000","0.00014000"],["78632.00000000","0.05556000"],["78632.08000000","0.00007000"],["78632.52000000","0.00007000"],["78632.59000000","0.00014000"],["78632.60000000","0.05379000"],["78632.92000000","0.00007000"],["78633.25000000","0.00014000"],["78633.26000000","0.03786000"],["78633.36000000","0.00007000"],["78633.41000000","0.00007000"]]}}}
{"rx_ns": 173325238590300, "frame": {"stream":"btcusdt@depth@100ms","data":{"e":"depthUpdate","E":1787603264414,"s":"BTCUSDT","U":99076734288,"u":99076734310,"b":[["78629.99000000","5.58610000"],["78566.49000000","0.02200000"],["78462.64000000","0.00127000"],["78459.70000000","0.00779000"],["78416.84000000","0.01992000"],["78397.30000000","0.00000000"],["70767.00000000","0.00192000"]],"a":[["78630.00000000","0.02601000"],["78630.22000000","0.00007000"],["78632.60000000","0.05379000"],["78637.14000000","0.58713000"],["78639.17000000","0.00000000"],["78639.23000000","0.00048000"],["78642.07000000","0.00000000"],["78658.63000000","0.00406000"]]}}}
{"rx_ns": 173325339126300, "frame": {"stream":"btcusdt@depth20@100ms","data":{"lastUpdateId":99076734338,"bids":[["78629.99000000","5.58610000"],["78629.98000000","1.90542000"],["78629.97000000","0.00013000"],["78629.76000000","0.00400000"],["78629.47000000","0.01932000"],["78629.40000000","0.00014000"],["78629.39000000","0.20019000"],["78629.38000000","0.03042000"],["78629.37000000","1.21959000"],["78629.28000000","0.01985000"],["78629.07000000","0.00327000"],["78628.40000000","0.00254000"],["78628.21000000","0.03216000"],["78628.00000000","0.07500000"],["78627.99000000","0.00541000"],["78627.87000000","0.00007000"],["78627.85000000","0.03007000"],["78627.79000000","0.07500000"],["78627.57000000","0.00400000"],["78627.10000000","0.04810000"]],"asks":[["78630.00000000","0.02601000"],["78630.01000000","0.00077000"],["78630.22000000","0.00007000"],["78630.66000000","0.00007000"],["78630.73000000","0.00014000"],["78630.74000000","0.01896000"],["78631.01000000","0.00007000"],["78631.24000000","0.00007000"],["78631.66000000","0.00007000"],["78631.99000000","0.00014000"],["78632.00000000","0.05556000"],["78632.08000000","0.00007000"],["78632.52000000","0.00007000"],["78632.59000000","0.00014000"],["78632.60000000","0.05379000"],["78632.92000000","0.00007000"],["78633.25000000","0.00014000"],["78633.26000000","0.03786000"],["78633.36000000","0.00007000"],["78633.41000000","0.00007000"]]}}}
{"rx_ns": 173325339205100, "frame": {"stream":"btcusdt@depth@100ms","data":{"e":"depthUpdate","E":1787603264514,"s":"BTCUSDT","U":99076734311,"u":99076734338,"b":[["78629.99000000","5.58610000"],["78628.40000000","0.00254000"],["78626.99000000","0.00000000"],["70767.00000000","0.00192000"],["62904.00000000","0.00031000"]],"a":[["78630.00000000","0.02601000"],["78630.01000000","0.00077000"],["78632.60000000","0.05379000"],["78634.44000000","0.20818000"],["78634.53000000","0.00007000"],["78636.18000000","0.00000000"],["78639.23000000","0.00000000"],["78642.71000000","0.00000000"],["78643.99000000","0.00000000"],["78644.12000000","0.00254000"],["78645.07000000","0.31796000"],["78656.75000000","0.00000000"],["78668.19000000","0.02517000"],["78689.78000000","0.00007000"]]}}}
{"rx_ns": 173325444172000, "frame": {"stream":"btcusdt@depth20@100ms","data":{"lastUpdateId":99076734599,"bids":[["78630.73000000","5.11320000"],["78630.72000000","2.10547000"],["78630.71000000","0.00013000"],["78630.01000000","0.00014000"],["78630.00000000","0.47532000"],["78629.99000000","0.51406000"],["78629.98000000","0.00007000"],["78629.76000000","0.00400000"],["78629.47000000","0.01932000"],["78629.39000000","0.00007000"],["78629.38000000","0.03042000"],["78629.37000000","1.21959000"],["78629.28000000","0.00007000"],["78629.07000000","0.00327000"],["78628.40000000","0.00254000"],["78628.21000000","0.03216000"],["78628.00000000","0.07500000"],["78627.99000000","0.00541000"],["78627.87000000","0.00007000"],["78627.85000000","0.03007000"]],"asks":[["78630.74000000","0.02100000"],["78630.75000000","0.00069000"],["78630.76000000","0.00013000"],["78631.01000000","0.00007000"],["78631.24000000","0.00007000"],["78631.66000000","0.00007000"],["78631.99000000","0.00014000"],["78632.00000000","0.05570000"],["78632.08000000","0.00007000"],["78632.52000000","0.00007000"],["78632.60000000","0.00014000"],["78632.92000000","0.00007000"],["78633.25000000","0.00014000"],["78633.26000000","0.03786000"],["78633.33000000","0.00014000"],["78633.34000000","0.05365000"],["78633.36000000","0.00007000"],["78633.41000000","0.00007000"],["78633.99000000","0.00014000"],["78634.00000000","0.02414000"]]}}}
{"rx_ns": 173325444255300, "frame": {"stream":"btcusdt@depth@100ms","data":{"e":"depthUpdate","E":1787603264614,"s":"BTCUSDT","U":99076734339,"u":99076734599,"b":[["78630.73000000","5.11320000"],["78630.72000000","2.10547000"],["78630.71000000","0.00013000"],["78630.65000000","0.00000000"],["78630.21000000","0.00000000"],["78630.01000000","0.00014000"],["78630.00000000","0.47532000"],["78629.99000000","0.51406000"],["78629.98000000","0.00007000"],["78629.97000000","0.00000000"],["78629.40000000","0.00000000"],["78629.39000000","0.00007000"],["78629.28000000","0.00007000"],["78627.84000000","0.04810000"],["78627.10000000","0.00000000"],["78625.53000000","0.04104000"],["78622.66000000","0.00007000"],["78620.11000000","0.08576000"],["78618.93000000","0.00000000"],["78613.21000000","0.00000000"],["78606.97000000","0.14011000"],["78603.11000000","0.13690000"],["78591.00000000","0.01000000"],["78590.00000000","0.11994000"],["78552.17000000","0.02118000"],["78491.02000000","0.00406000"],["78236.84000000","0.00000000"],["77845.65000000","0.00000000"],["77456.42000000","0.00000000"],["77069.14000000","0.00000000"],["76683.79000000","0.00000000"],["76300.38000000","0.00000000"],["75918.87000000","0.00000000"],["75539.28000000","0.00000000"],["75161.58000000","0.00000000"],["74785.78000000","0.00000000"],["74411.85000000","0.00000000"],["74039.79000000","0.00000000"],["73669.59000000","0.00000000"],["73301.24000000","0.00000000"],["72934.73000000","0.00000000"],["70767.00000000","0.00000000"],["62904.00000000","0.00000000"]],"a":[["78630.00000000","0.00000000"],["78630.01000000","0.00000000"],["78630.22000000","0.00000000"],["78630.66000000","0.00000000"],["78630.73000000","0.00000000"],["78630.74000000","0.02100000"],["78630.75000000","0.00069000"],["78630.76000000","0.00013000"],["78632.00000000","0.05570000"],["78632.59000000","0.00000000"],["78632.60000000","0.00014000"],["78633.33000000","0.00014000"],["78633.34000000","0.05365000"],["78633.99000000","0.00014000"],["78634.00000000","0.02414000"],["78634.01000000","0.02014000"],["78634.44000000","0.20825000"],["78635.28000000","0.00000000"],["78636.00000000","0.02407000"],["78637.14000000","0.58720000"],["78637.74000000","0.00283000"],["78637.78000000","0.01415000"],["78644.73000000","0.00007000"],["78645.08000000","0.00000000"],["78646.25000000","0.04857000"],["78655.89000000","0.00000000"],["78667.46000000","0.00000000"],["78667.57000000","0.02735000"],["78669.36000000","0.00014000"],["78670.00000000","0.11934000"],["78671.00000000","0.01000000"],["79023.15000000","0.00000000"],["79418.27000000","0.00000000"],["79815.36000000","0.00000000"],["80214.44000000","0.00000000"],["80615.51000000","0.00000000"],["81018.59000000","0.00000000"],["81423.68000000","0.00000000"],["81830.80000000","0.00000000"],["82239.95000000","0.00000000"],["82651.15000000","0.00000000"],["83064.41000000","0.00000000"],["83479.73000000","0.00000000"],["83897.13000000","0.00000000"],["84316.62000000","0.00000000"],["84738.20000000","0.00000000"]]}}}
{"rx_ns": 173325538851100, "frame": {"stream":"btcusdt@depth20@100ms","data":{"lastUpdateId":99076734642,"bids":[["78630.73000000","5.12690000"],["78630.72000000","2.10554000"],["78630.71000000","0.00013000"],["78630.01000000","0.00014000"],["78630.00000000","0.47539000"],["78629.99000000","0.28058000"],["78629.76000000","0.00400000"],["78629.47000000","0.01932000"],["78629.38000000","0.03042000"],["78629.37000000","1.21959000"],["78629.07000000","0.00327000"],["78628.40000000","0.00254000"],["78628.21000000","0.03216000"],["78628.00000000","0.07500000"],["78627.99000000","0.00541000"],["78627.87000000","0.00007000"],["78627.85000000","0.03007000"],["78627.84000000","0.04810000"],["78627.79000000","0.07500000"],["78627.57000000","0.00400000"]],"asks":[["78630.74000000","0.02086000"],["78630.75000000","0.00069000"],["78630.76000000","0.00013000"],["78631.01000000","0.00007000"],["78631.24000000","0.00007000"],["78631.66000000","0.00007000"],["78631.99000000","0.00014000"],["78632.00000000","0.05570000"],["78632.08000000","0.00007000"],["78632.52000000","0.00007000"],["78632.60000000","0.00007000"],["78632.92000000","0.00007000"],["78633.25000000","0.00014000"],["78633.26000000","0.03786000"],["78633.33000000","0.00014000"],["78633.34000000","0.05372000"],["78633.36000000","0.00007000"],["78633.41000000","0.00007000"],["78633.99000000","0.00014000"],["78634.00000000","0.02414000"]]}}}
{"rx_ns": 173325538937200, "frame": {"stream":"btcusdt@depth@100ms","data":{"e":"depthUpdate","E":1787603264714,"s":"BTCUSDT","U":99076734600,"u":99076734642,"b":[["78630.73000000","5.12690000"],["78630.72000000","2.10554000"],["78630.00000000","0.47539000"],["78629.99000000","0.28058000"],["78629.98000000","0.00000000"],["78629.47000000","0.01932000"],["78629.39000000","0.00000000"],["78629.37000000","1.21959000"],["78629.28000000","0.00000000"],["78603.11000000","0.00000000"],["78591.38000000","0.00000000"],["78590.18000000","0.09582000"],["78552.17000000","0.02118000"],["70767.66000000","0.00032000"]],"a":[["78630.74000000","0.02086000"],["78632.00000000","0.05570000"],["78632.60000000","0.00007000"],["78633.26000000","0.03786000"],["78633.34000000","0.05372000"],["78637.74000000","0.00000000"],["78637.78000000","0.00000000"],["78639.75000000","0.22653000"],["78656.96000000","0.09409000"]]}}}
{"rx_ns": 173325644137400, "frame": {"stream":"btcusdt@depth20@100ms","data":{"lastUpdateId":99076734646,"bids":[["78630.73000000","5.12690000"],["78630.72000000","2.10554000"],["78630.71000000","0.00013000"],["78630.01000000","0.00014000"],["78630.00000000","0.47539000"],["78629.99000000","0.28058000"],["78629.76000000","0.00400000"],["78629.47000000","0.01932000"],["78629.38000000","0.03042000"],["78629.37000000","1.21959000"],["78629.07000000","0.00327000"],["78628.40000000","0.00254000"],["78628.21000000","0.03216000"],["78628.00000000","0.07500000"],["78627.99000000","0.00541000"],["78627.87000000","0.00007000"],["78627.85000000","0.03007000"],["78627.84000000","0.04810000"],["78627.79000000","0.07500000"],["78627.57000000","0.00400000"]],"asks":[["78630.74000000","0.02086000"],["78630.75000000","0.00069000"],["78630.76000000","0.00013000"],["78631.01000000","0.00007000"],["78631.24000000","0.00007000"],["78631.66000000","0.00007000"],["78631.99000000","0.00014000"],["78632.00000000","0.05570000"],["78632.08000000","0.00007000"],["78632.52000000","0.00007000"],["78632.60000000","0.00007000"],["78632.92000000","0.00007000"],["78633.25000000","0.00014000"],["78633.26000000","0.03786000"],["78633.33000000","0.00014000"],["78633.34000000","0.05372000"],["78633.36000000","0.00007000"],["78633.41000000","0.00007000"],["78633.99000000","0.00014000"],["78634.00000000","0.02414000"]]}}}
{"rx_ns": 173325644390400, "frame": {"stream":"btcusdt@depth@100ms","data":{"e":"depthUpdate","E":1787603264814,"s":"BTCUSDT","U":99076734643,"u":99076734646,"b":[["78569.63000000","0.00406000"],["70767.66000000","0.00048000"]],"a":[["78638.95000000","0.17886000"],["78639.75000000","0.00000000"]]}}}
{"rx_ns": 173325740954600, "frame": {"stream":"btcusdt@depth20@100ms","data":{"lastUpdateId":99076734656,"bids":[["78630.73000000","5.12690000"],["78630.72000000","2.10554000"],["78630.71000000","0.00013000"],["78630.01000000","0.00014000"],["78630.00000000","0.47539000"],["78629.99000000","0.28058000"],["78629.76000000","0.00400000"],["78629.47000000","0.01932000"],["78629.38000000","0.03042000"],["78629.37000000","1.21959000"],["78629.07000000","0.00327000"],["78628.40000000","0.00254000"],["78628.21000000","0.03216000"],["78628.00000000","0.07500000"],["78627.99000000","0.00541000"],["78627.87000000","0.00007000"],["78627.85000000","0.03007000"],["78627.84000000","0.04810000"],["78627.79000000","0.07500000"],["78627.57000000","0.00400000"]],"asks":[["78630.74000000","0.02086000"],["78630.75000000","0.00069000"],["78630.76000000","0.00013000"],["78631.01000000","0.00007000"],["78631.24000000","0.00007000"],["78631.66000000","0.00007000"],["78631.99000000","0.00014000"],["78632.00000000","0.05570000"],["78632.08000000","0.00007000"],["78632.52000000","0.00007000"],["78632.58000000","0.00007000"],["78632.60000000","0.00007000"],["78632.92000000","0.00007000"],["78633.25000000","0.00014000"],["78633.26000000","0.03786000"],["78633.33000000","0.00014000"],["78633.34000000","0.05372000"],["78633.36000000","0.00007000"],["78633.41000000","0.00007000"],["78633.99000000","0.00014000"]]}}}
{"rx_ns": 173325741026000, "frame": {"stream":"btcusdt@depth@100ms","data":{"e":"depthUpdate","E":1787603264914,"s":"BTCUSDT","U":99076734647,"u":99076734656,"b":[["78630.73000000","5.12690000"],["78552.17000000","0.00000000"],["78459.70000000","0.00000000"],["78455.86000000","0.00786000"],["72360.01000000","0.00014000"],["62904.58000000","0.00000000"]],"a":[["78632.58000000","0.00007000"]]}}}
{"rx_ns": 173325841960400, "frame": {"stream":"btcusdt@depth20@100ms","data":{"lastUpdateId":99076734666,"bids":[["78630.73000000","5.12682000"],["78630.72000000","2.10554000"],["78630.71000000","0.00013000"],["78630.01000000","0.00014000"],["78630.00000000","0.47539000"],["78629.99000000","0.28058000"],["78629.76000000","0.00400000"],["78629.47000000","0.01932000"],["78629.38000000","0.03042000"],["78629.37000000","1.21959000"],["78629.07000000","0.00327000"],["78628.40000000","0.00254000"],["78628.21000000","0.03216000"],["78628.00000000","0.07500000"],["78627.99000000","0.00541000"],["78627.87000000","0.00007000"],["78627.85000000","0.03007000"],["78627.84000000","0.04810000"],["78627.79000000","0.07500000"],["78627.57000000","0.00400000"]],"asks":[["78630.74000000","0.02086000"],["78630.75000000","0.00069000"],["78630.76000000","0.00013000"],["78631.01000000","0.00007000"],["78631.24000000","0.00007000"],["78631.66000000","0.00007000"],["78631.99000000","0.00014000"],["78632.00000000","0.05570000"],["78632.08000000","0.00007000"],["78632.52000000","0.00007000"],["78632.58000000","0.00007000"],["78632.60000000","0.00007000"],["78632.92000000","0.00007000"],["78633.25000000","0.00014000"],["78633.26000000","0.03786000"],["78633.33000000","0.00014000"],["78633.34000000","0.05372000"],["78633.36000000","0.00007000"],["78633.41000000","0.00007000"],["78633.99000000","0.00014000"]]}}}
{"rx_ns": 173325842034600, "frame": {"stream":"btcusdt@depth@100ms","data":{"e":"depthUpdate","E":1787603265014,"s":"BTCUSDT","U":99076734657,"u":99076734666,"b":[["78630.73000000","5.12682000"],["78420.27000000","0.00406000"],["70767.66000000","0.00064000"],["70767.00000000","0.00000000"],["62904.59000000","0.00031000"]],"a":[["78657.38000000","0.00000000"],["78672.89000000","0.34323000"]]}}}
{"rx_ns": 173325944131100, "frame": {"stream":"btcusdt@depth20@100ms","data":{"lastUpdateId":99076734902,"bids":[["78631.99000000","5.40299000"],["78631.98000000","1.90535000"],["78631.97000000","0.00013000"],["78630.74000000","1.65524000"],["78630.73000000","0.26690000"],["78630.72000000","0.00007000"],["78630.66000000","0.00014000"],["78630.00000000","0.07507000"],["78629.99000000","0.07240000"],["78629.76000000","0.00400000"],["78629.47000000","0.01932000"],["78629.38000000","0.03042000"],["78629.37000000","1.21959000"],["78629.10000000","0.04810000"],["78629.07000000","0.00327000"],["78628.44000000","0.00007000"],["78628.40000000","0.00254000"],["78628.21000000","0.03216000"],["78628.00000000","0.07500000"],["78627.99000000","0.00541000"]],"asks":[["78632.00000000","0.05798000"],["78632.01000000","0.00056000"],["78632.08000000","0.00007000"],["78632.58000000","0.00007000"],["78632.60000000","0.00007000"],["78632.92000000","0.00007000"],["78633.25000000","0.00014000"],["78633.26000000","0.03786000"],["78633.33000000","0.00014000"],["78633.34000000","0.00007000"],["78633.36000000","0.00007000"],["78633.41000000","0.00007000"],["78633.99000000","0.00014000"],["78634.00000000","0.02421000"],["78634.01000000","0.02014000"],["78634.43000000","0.00007000"],["78634.44000000","0.20825000"],["78634.52000000","0.03786000"],["78634.53000000","0.00007000"],["78634.60000000","0.05365000"]]}}}
{"rx_ns": 173325944215300, "frame": {"stream":"btcusdt@depth@100ms","data":{"e":"depthUpdate","E":1787603265114,"s":"BTCUSDT","U":99076734667,"u":99076734902,"b":[["78631.99000000","5.40299000"],["78631.98000000","1.90535000"],["78631.97000000","0.00013000"],["78631.65000000","0.00000000"],["78631.23000000","0.00000000"],["78631.00000000","0.00000000"],["78630.75000000","0.00000000"],["78630.74000000","1.65524000"],["78630.73000000","0.26690000"],["78630.72000000","0.00007000"],["78630.71000000","0.00000000"],["78630.66000000","0.00014000"],["78630.01000000","0.00000000"],["78630.00000000","0.07507000"],["78629.99000000","0.07240000"],["78629.10000000","0.04810000"],["78628.44000000","0.00007000"],["78627.93000000","0.00027000"],["78627.84000000","0.00000000"],["78627.79000000","0.00000000"],["78627.20000000","0.02289000"],["78624.07000000","0.00010000"],["78624.05000000","1.90515000"],["78624.00000000","0.01021000"],["78621.23000000","0.08576000"],["78620.11000000","0.00000000"],["78611.09000000","0.00762000"],["78608.97000000","0.00000000"],["78595.53000000","0.00000000"],["78591.96000000","0.00000000"],["78588.54000000","0.00014000"],["78567.13000000","0.00000000"],["78489.96000000","0.00000000"],["78237.57000000","0.01000000"],["77922.32000000","0.00000000"],["77846.38000000","0.01000000"],["77457.15000000","0.01000000"],["77069.87000000","0.01000000"],["76684.52000000","0.01000000"],["76301.09000000","0.01000000"],["75919.59000000","0.01000000"],["75539.99000000","0.01000000"],["75162.29000000","0.01019000"],["74786.48000000","0.01000000"],["74412.55000000","0.01000000"],["74040.48000000","0.01000000"],["73670.28000000","0.01000000"],["73301.93000000","0.01000000"],["72935.42000000","0.01000000"],["70767.66000000","0.00000000"]],"a":[["78630.74000000","0.00000000"],["78630.75000000","0.00000000"],["78630.76000000","0.00000000"],["78631.01000000","0.00000000"],["78631.24000000","0.00000000"],["78631.66000000","0.00000000"],["78631.99000000","0.00000000"],["78632.00000000","0.05798000"],["78632.01000000","0.00056000"],["78632.52000000","0.00000000"],["78633.34000000","0.00007000"],["78634.00000000","0.02421000"],["78634.43000000","0.00007000"],["78634.56000000","0.00000000"],["78634.60000000","0.05365000"],["78635.24000000","0.00000000"],["78636.01000000","0.00653000"],["78638.78000000","0.12723000"],["78641.57000000","0.00000000"],["78642.73000000","0.00508000"],["78646.25000000","0.00000000"],["78647.16000000","0.00000000"],["78647.38000000","0.04857000"],["78667.57000000","0.00000000"],["78671.00000000","0.00000000"],["78672.00000000","0.03400000"],["78725.49000000","0.00000000"],["78728.23000000","0.00431000"],["78757.20000000","0.00000000"],["79023.91000000","0.00000000"],["79419.03000000","0.00000000"],["79816.12000000","0.00000000"],["80215.20000000","0.00000000"],["80616.28000000","0.00038000"],["81019.36000000","0.00000000"],["81424.46000000","0.00000000"],["81831.58000000","0.00000000"],["82240.74000000","0.00000000"],["82651.94000000","0.00000000"],["83065.20000000","0.00000000"],["83480.53000000","0.00000000"],["83897.93000000","0.00000000"],["84317.42000000","0.00127000"],["84739.01000000","0.00000000"]]}}}
{"rx_ns": 173326049760100, "frame": {"stream":"btcusdt@depth20@100ms","data":{"lastUpdateId":99076734994,"bids":[["78631.99000000","5.46046000"],["78631.98000000","1.90542000"],["78631.97000000","0.00013000"],["78630.75000000","0.00014000"],["78630.74000000","0.29451000"],["78630.73000000","0.24951000"],["78630.66000000","0.00014000"],["78630.00000000","0.07507000"],["78629.99000000","0.07240000"],["78629.76000000","0.00400000"],["78629.47000000","0.00007000"],["78629.38000000","0.03042000"],["78629.37000000","1.21952000"],["78629.10000000","0.04810000"],["78629.07000000","0.00327000"],["78628.44000000","0.00007000"],["78628.40000000","0.00254000"],["78628.00000000","0.07500000"],["78627.99000000","0.00534000"],["78627.93000000","0.00027000"]],"asks":[["78632.00000000","0.50418000"],["78632.01000000","0.00056000"],["78632.07000000","0.00013000"],["78632.08000000","0.00007000"],["78632.58000000","0.00007000"],["78632.60000000","0.00007000"],["78632.92000000","0.00007000"],["78633.26000000","0.00007000"],["78633.36000000","0.00007000"],["78633.41000000","0.00007000"],["78633.99000000","0.00014000"],["78634.00000000","0.02421000"],["78634.01000000","0.02014000"],["78634.43000000","0.00014000"],["78634.44000000","0.20832000"],["78634.52000000","0.00007000"],["78634.53000000","0.00007000"],["78634.59000000","0.00014000"],["78634.60000000","0.05372000"],["78635.96000000","0.00007000"]]}}}
{"rx_ns": 173326049845400, "frame": {"stream":"btcusdt@depth@100ms","data":{"e":"depthUpdate","E":1787603265216,"s":"BTCUSDT","U":99076734903,"u":99076734994,"b":[["78631.99000000","5.46046000"],["78631.98000000","1.90542000"],["78630.75000000","0.00014000"],["78630.74000000","0.29451000"],["78630.73000000","0.24951000"],["78630.72000000","0.00000000"],["78629.47000000","0.00007000"],["78629.37000000","1.21952000"],["78628.21000000","0.00000000"],["78627.99000000","0.00534000"],["78626.95000000","0.00000000"],["78626.00000000","0.00700000"],["78625.69000000","0.00000000"],["78625.53000000","0.00007000"],["78624.00000000","0.01707000"],["78622.17000000","0.00007000"],["78608.36000000","0.00007000"],["78606.36000000","0.00000000"],["78592.00000000","0.03400000"],["78591.00000000","0.00000000"],["78538.19000000","0.00406000"],["78398.19000000","0.00000000"],["76666.00000000","4.66834000"],["62904.59000000","0.00000000"]],"a":[["78632.00000000","0.50418000"],["78632.01000000","0.00056000"],["78632.07000000","0.00013000"],["78633.25000000","0.00000000"],["78633.26000000","0.00007000"],["78633.33000000","0.00000000"],["78633.34000000","0.00000000"],["78634.43000000","0.00014000"],["78634.44000000","0.20832000"],["78634.51000000","0.00000000"],["78634.52000000","0.00007000"],["78634.59000000","0.00014000"],["78634.60000000","0.05372000"],["78635.99000000","0.00007000"],["78653.55000000","0.00000000"],["78655.55000000","0.00007000"]]}}}
{"rx_ns": 173326144227600, "frame": {"stream":"btcusdt@depth20@100ms","data":{"lastUpdateId":99076735048,"bids":[["78631.99000000","5.46259000"],["78631.98000000","1.90542000"],["78631.97000000","0.00013000"],["78631.69000000","0.01960000"],["78630.75000000","0.00014000"],["78630.74000000","0.29437000"],["78630.73000000","0.03021000"],["78630.66000000","0.00014000"],["78630.43000000","0.03268000"],["78630.00000000","0.07507000"],["78629.99000000","0.07240000"],["78629.76000000","0.00400000"],["78629.38000000","0.03042000"],["78629.37000000","1.21959000"],["78629.17000000","0.03921000"],["78629.10000000","0.04810000"],["78629.07000000","0.00327000"],["78628.44000000","0.00007000"],["78628.40000000","0.00254000"],["78628.00000000","0.07500000"]],"asks":[["78632.00000000","0.08461000"],["78632.01000000","0.00063000"],["78632.07000000","0.00013000"],["78632.08000000","0.00007000"],["78632.58000000","0.00007000"],["78632.60000000","0.00007000"],["78632.92000000","0.00007000"],["78632.96000000","0.00014000"],["78632.97000000","0.01854000"],["78633.36000000","0.00007000"],["78633.41000000","0.00007000"],["78633.99000000","0.00014000"],["78634.00000000","0.02421000"],["78634.01000000","0.02014000"],["78634.21000000","0.00014000"],["78634.22000000","0.03090000"],["78634.43000000","0.00014000"],["78634.44000000","0.20832000"],["78634.53000000","0.00007000"],["78634.60000000","0.05372000"]]}}}
{"rx_ns": 173326144309200, "frame": {"stream":"btcusdt@depth@100ms","data":{"e":"depthUpdate","E":1787603265314,"s":"BTCUSDT","U":99076734995,"u":99076735048,"b":[["78631.99000000","5.46259000"],["78631.69000000","0.01960000"],["78630.74000000","0.29437000"],["78630.73000000","0.03021000"],["78630.43000000","0.03268000"],["78629.99000000","0.07240000"],["78629.47000000","0.00000000"],["78629.37000000","1.21959000"],["78629.17000000","0.03921000"],["78627.91000000","0.03922000"],["78552.17000000","0.02118000"],["70768.80000000","0.00032000"],["62906.00000000","0.00000000"]],"a":[["78632.00000000","0.08461000"],["78632.01000000","0.00063000"],["78632.96000000","0.00014000"],["78632.97000000","0.01854000"],["78633.26000000","0.00000000"],["78634.21000000","0.00014000"],["78634.22000000","0.03090000"],["78634.44000000","0.20832000"],["78634.52000000","0.00000000"],["78634.59000000","0.00000000"],["78635.48000000","0.03708000"],["78635.99000000","0.00000000"],["78636.74000000","0.03708000"],["78637.13000000","0.02168000"],["78637.14000000","0.58727000"],["78674.81000000","0.00000000"]]}}}
{"rx_ns": 173326258664200, "frame": {"stream":"btcusdt@depth20@100ms","data":{"lastUpdateId":99076735089,"bids":[["78631.99000000","5.20029000"],["78631.98000000","1.90542000"],["78631.97000000","0.00013000"],["78631.69000000","0.01967000"],["78630.75000000","0.00014000"],["78630.74000000","0.29437000"],["78630.73000000","0.03021000"],["78630.66000000","0.00014000"],["78630.43000000","0.03268000"],["78630.00000000","0.07507000"],["78629.99000000","0.06795000"],["78629.76000000","0.00400000"],["78629.38000000","0.03042000"],["78629.37000000","1.21952000"],["78629.17000000","0.03921000"],["78629.10000000","0.04810000"],["78629.07000000","0.00327000"],["78628.44000000","0.00007000"],["78628.40000000","0.00254000"],["78628.00000000","0.07500000"]],"asks":[["78632.00000000","0.56086000"],["78632.01000000","0.00063000"],["78632.07000000","0.00013000"],["78632.08000000","0.00007000"],["78632.58000000","0.00007000"],["78632.60000000","0.00007000"],["78632.92000000","0.00007000"],["78632.96000000","0.00014000"],["78632.97000000","0.01861000"],["78633.41000000","0.00007000"],["78633.99000000","0.00014000"],["78634.00000000","0.02421000"],["78634.01000000","0.02014000"],["78634.21000000","0.00014000"],["78634.22000000","0.03097000"],["78634.43000000","0.00014000"],["78634.44000000","0.20832000"],["78634.53000000","0.00007000"],["78634.60000000","0.05372000"],["78634.94000000","0.00007000"]]}}}
{"rx_ns": 173326258745700, "frame": {"stream":"btcusdt@depth@100ms","data":{"e":"depthUpdate","E":1787603265414,"s":"BTCUSDT","U":99076735049,"u":99076735089,"b":[["78631.99000000","5.20029000"],["78631.98000000","1.90542000"],["78631.69000000","0.01967000"],["78630.73000000","0.03021000"],["78629.99000000","0.06795000"],["78629.37000000","1.21952000"],["78625.54000000","0.00642000"],["78618.47000000","0.00007000"],["78609.00000000","0.70000000"],["78608.94000000","0.00406000"],["78552.17000000","0.00000000"],["78538.19000000","0.00000000"],["72360.01000000","0.00000000"],["70768.80000000","0.00057000"]],"a":[["78632.00000000","0.56086000"],["78632.97000000","0.01861000"],["78633.36000000","0.00000000"],["78634.01000000","0.02014000"],["78634.22000000","0.03097000"],["78634.60000000","0.05372000"],["78634.94000000","0.00007000"],["78635.48000000","0.03715000"],["78636.01000000","0.00646000"],["78637.13000000","0.02161000"],["78637.14000000","0.58720000"],["78696.76000000","0.00000000"],["78728.23000000","0.00025000"],["78775.42000000","0.00000000"],["78846.21000000","0.00000000"]]}}}
{"rx_ns": 173326342831900, "frame": {"stream":"btcusdt@depth20@100ms","data":{"lastUpdateId":99076735121,"bids":[["78631.99000000","5.46189000"],["78631.98000000","1.90542000"],["78631.97000000","0.00013000"],["78631.69000000","0.01967000"],["78631.02000000","0.00007000"],["78630.75000000","0.00014000"],["78630.74000000","0.29437000"],["78630.73000000","0.03021000"],["78630.66000000","0.00014000"],["78630.43000000","0.03268000"],["78630.00000000","0.07507000"],["78629.99000000","0.06795000"],["78629.76000000","0.00400000"],["78629.38000000","0.03042000"],["78629.37000000","1.21952000"],["78629.17000000","0.03921000"],["78629.10000000","0.04810000"],["78629.07000000","0.00327000"],["78628.44000000","0.00007000"],["78628.40000000","0.00254000"]],"asks":[["78632.00000000","0.08355000"],["78632.01000000","0.00084000"],["78632.07000000","0.00013000"],["78632.08000000","0.00007000"],["78632.60000000","0.00007000"],["78632.92000000","0.00007000"],["78632.96000000","0.00014000"],["78632.97000000","0.01861000"],["78633.41000000","0.00007000"],["78633.99000000","0.00014000"],["78634.00000000","0.02421000"],["78634.01000000","0.02014000"],["78634.21000000","0.00014000"],["78634.22000000","0.03097000"],["78634.43000000","0.00014000"],["78634.44000000","0.20832000"],["78634.53000000","0.00007000"],["78634.60000000","0.05372000"],["78634.94000000","0.00007000"],["78635.48000000","0.03715000"]]}}}
{"rx_ns": 173326342908100, "frame": {"stream":"btcusdt@depth@100ms","data":{"e":"depthUpdate","E":1787603265514,"s":"BTCUSDT","U":99076735090,"u":99076735121,"b":[["78631.99000000","5.46189000"],["78631.02000000","0.00007000"],["78630.01000000","0.00000000"],["78627.87000000","0.00000000"],["78625.53000000","0.00007000"],["78625.25000000","0.12897000"],["78609.66000000","0.49663000"],["78586.08000000","0.97566000"],["70768.80000000","0.00073000"],["62905.60000000","0.00031000"]],"a":[["78632.00000000","0.08355000"],["78632.01000000","0.00084000"],["78632.58000000","0.00000000"],["78637.14000000","0.58727000"],["78637.52000000","0.17607000"],["78638.78000000","0.12716000"],["78638.95000000","0.00000000"],["78693.87000000","0.00007000"]]}}}
{"rx_ns": 173326456321000, "frame": {"stream":"btcusdt@depth20@100ms","data":{"lastUpdateId":99076736258,"bids":[["78635.99000000","4.25059000"],["78635.98000000","0.00020000"],["78635.97000000","0.00013000"],["78635.95000000","0.00007000"],["78635.70000000","0.00400000"],["78635.49000000","0.00014000"],["78635.48000000","0.07521000"],["78635.47000000","2.75984000"],["78634.65000000","0.00317000"],["78634.59000000","0.00007000"],["78634.53000000","0.00014000"],["78634.22000000","0.07521000"],["78634.21000000","0.21925000"],["78634.20000000","1.58176000"],["78634.00000000","0.00014000"],["78633.99000000","0.00014000"],["78633.40000000","0.00014000"],["78633.35000000","0.00400000"],["78633.10000000","0.04821000"],["78632.96000000","0.35558000"]],"asks":[["78636.00000000","0.02271000"],["78636.01000000","0.00702000"],["78636.74000000","0.00007000"],["78637.13000000","0.00021000"],["78637.14000000","0.58741000"],["78637.52000000","0.00007000"],["78638.00000000","0.02407000"],["78638.08000000","0.00007000"],["78638.40000000","0.00007000"],["78638.48000000","0.00007000"],["78638.60000000","0.00014000"],["78638.61000000","0.05353000"],["78639.83000000","0.00007000"],["78639.84000000","0.00007000"],["78640.00000000","0.02400000"],["78640.70000000","0.00007000"],["78641.58000000","0.00007000"],["78641.83000000","0.00007000"],["78642.00000000","0.02400000"],["78642.27000000","0.00007000"]]}}}
{"rx_ns": 173326456403800, "frame": {"stream":"btcusdt@depth@100ms","data":{"e":"depthUpdate","E":1787603265614,"s":"BTCUSDT","U":99076735122,"u":99076736258,"b":[["78635.99000000","4.25059000"],["78635.98000000","0.00020000"],["78635.97000000","0.00013000"],["78635.95000000","0.00007000"],["78635.70000000","0.00400000"],["78635.49000000","0.00014000"],["78635.48000000","0.07521000"],["78635.47000000","2.75984000"],["78635.46000000","0.00000000"],["78635.45000000","0.00000000"],["78634.93000000","0.00000000"],["78634.65000000","0.00317000"],["78634.60000000","0.00000000"],["78634.59000000","0.00007000"],["78634.56000000","0.00000000"],["78634.53000000","0.00014000"],["78634.52000000","0.00000000"],["78634.43000000","0.00000000"],["78634.42000000","0.00000000"],["78634.22000000","0.07521000"],["78634.21000000","0.21925000"],["78634.20000000","1.58176000"],["78634.19000000","0.00000000"],["78634.00000000","0.00014000"],["78633.99000000","0.00014000"],["78633.98000000","0.00000000"],["78633.40000000","0.00014000"],["78633.35000000","0.00400000"],["78633.10000000","0.04821000"],["78632.96000000","0.35558000"],["78632.95000000","0.03000000"],["78632.91000000","0.00000000"],["78632.72000000","0.00000000"],["78632.60000000","0.00000000"],["78632.59000000","0.00007000"],["78632.58000000","0.00000000"],["78632.40000000","0.00008000"],["78632.07000000","0.00000000"],["78632.06000000","0.00000000"],["78632.00000000","0.07500000"],["78631.99000000","0.09159000"],["78631.98000000","0.00007000"],["78631.97000000","0.00000000"],["78631.69000000","0.00000000"],["78631.32000000","0.00000000"],["78631.03000000","0.00000000"],["78631.00000000","0.00007000"],["78630.75000000","0.00000000"],["78630.74000000","0.00000000"],["78630.73000000","0.03338000"],["78630.43000000","0.00000000"],["78630.33000000","0.00000000"],["78630.00000000","0.00000000"],["78629.99000000","0.06645000"],["78629.70000000","0.00000000"],["78629.38000000","0.03014000"],["78629.17000000","0.00000000"],["78629.10000000","0.00000000"],["78628.40000000","0.00000000"],["78628.00000000","0.00000000"],["78627.99000000","0.00527000"],["78627.91000000","0.00000000"],["78627.85000000","0.00000000"],["78627.33000000","0.38166000"],["78626.86000000","0.12718000"],["78626.78000000","0.00000000"],["78626.45000000","0.08576000"],["78625.81000000","0.00007000"],["78625.65000000","0.00007000"],["78625.55000000","0.00000000"],["78625.54000000","0.00635000"],["78625.53000000","0.00000000"],["78625.49000000","0.00000000"],["78625.27000000","0.00000000"],["78625.26000000","0.00000000"],["78625.25000000","0.00000000"],["78625.19000000","0.00000000"],["78624.65000000","0.12000000"],["78624.32000000","0.00007000"],["78622.90000000","0.00000000"],["78622.45000000","0.00188000"],["78622.22000000","0.63586000"],["78622.21000000","0.13256000"],["78621.24000000","0.00000000"],["78621.23000000","0.00000000"],["78621.01000000","0.00400000"],["78620.01000000","0.00000000"],["78619.93000000","0.00059000"],["78618.96000000","0.00000000"],["78617.90000000","0.06597000"],["78617.12000000","0.00000000"],["78616.75000000","0.00000000"],["78616.74000000","0.00000000"],["78616.36000000","0.00000000"],["78615.93000000","0.07623000"],["78614.46000000","0.00635000"],["78614.35000000","0.02000000"],["78613.57000000","0.29372000"],["78611.35000000","0.00000000"],["78611.10000000","0.00000000"],["78610.83000000","0.14022000"],["78609.50000000","0.00000000"],["78609.38000000","0.00000000"],["78608.64000000","0.00000000"],["78607.20000000","0.41062000"],["78606.97000000","0.13757000"],["78606.72000000","0.00000000"],["78606.64000000","0.00800000"],["78605.18000000","0.00000000"],["78605.14000000","0.00000000"],["78605.13000000","0.00000000"],["78604.92000000","0.00000000"],["78604.70000000","0.00000000"],["78603.04000000","0.00000000"],["78602.79000000","0.00000000"],["78601.29000000","0.00000000"],["78600.96000000","0.00000000"],["78600.57000000","0.00000000"],["78599.97000000","0.00000000"],["78599.46000000","0.09564000"],["78599.25000000","0.00000000"],["78598.97000000","0.00000000"],["78597.75000000","0.00000000"],["78597.00000000","0.00000000"],["78596.51000000","0.00000000"],["78595.83000000","0.00000000"],["78593.00000000","0.01000000"],["78592.00000000","0.02400000"],["78591.97000000","0.00200000"],["78591.11000000","0.00000000"],["78590.18000000","0.00000000"],["78590.00000000","0.02450000"],["78589.97000000","0.02742000"],["78586.80000000","0.00626000"],["78582.42000000","0.00428000"],["78582.06000000","0.00432000"],["78574.44000000","0.00317000"],["78574.12000000","0.00000000"],["78572.35000000","0.01701000"],["78571.74000000","0.00000000"],["78571.73000000","0.00000000"],["78570.30000000","0.00000000"],["78570.29000000","0.01450000"],["78568.01000000","0.00000000"],["78566.72000000","0.00000000"],["78566.21000000","0.00000000"],["78555.57000000","0.00000000"],["78554.29000000","0.00000000"],["78553.43000000","0.00000000"],["78552.70000000","0.00000000"],["78552.55000000","0.00316000"],["78546.31000000","0.00000000"],["78495.77000000","0.00127000"],["78484.85000000","0.00000000"],["78473.45000000","0.00127000"],["78462.64000000","0.00000000"],["78428.00000000","0.00671000"],["78402.09000000","0.00000000"],["78311.25000000","0.00028000"],["78299.89000000","0.00000000"],["78239.43000000","0.00000000"],["78237.57000000","0.00000000"],["77858.01000000","0.00000000"],["77846.38000000","0.00000000"],["77457.15000000","0.00000000"],["77069.87000000","0.00000000"],["76684.52000000","0.00000000"],["76301.09000000","0.00000000"],["75919.59000000","0.00000000"],["75539.99000000","0.00000000"],["75162.29000000","0.00019000"],["74834.68000000","0.00020000"],["74786.48000000","0.00000000"],["74702.50000000","0.00010000"],["74700.96000000","0.00020000"],["74412.55000000","0.00000000"],["74040.48000000","0.00000000"],["73670.28000000","0.00000000"],["73301.93000000","0.00000000"],["72935.42000000","0.00000000"],["70769.34000000","0.00000000"],["70768.80000000","0.00009000"],["62905.60000000","0.00000000"]],"a":[["78632.00000000","0.00000000"],["78632.01000000","0.00000000"],["78632.07000000","0.00000000"],["78632.08000000","0.00000000"],["78632.60000000","0.00000000"],["78632.92000000","0.00000000"],["78632.96000000","0.00000000"],["78632.97000000","0.00000000"],["78633.41000000","0.00000000"],["78633.99000000","0.00000000"],["78634.00000000","0.00000000"],["78634.01000000","0.00000000"],["78634.21000000","0.00000000"],["78634.22000000","0.00000000"],["78634.23000000","0.00000000"],["78634.43000000","0.00000000"],["78634.44000000","0.00000000"],["78634.53000000","0.00000000"],["78634.59000000","0.00000000"],["78634.60000000","0.00000000"],["78634.94000000","0.00000000"],["78635.21000000","0.00000000"],["78635.47000000","0.00000000"],["78635.48000000","0.00000000"],["78635.49000000","0.00000000"],["78635.96000000","0.00000000"],["78635.99000000","0.00000000"],["78636.00000000","0.02271000"],["78636.01000000","0.00702000"],["78636.61000000","0.00000000"],["78636.73000000","0.00000000"],["78636.74000000","0.00007000"],["78636.83000000","0.00000000"],["78637.12000000","0.00000000"],["78637.13000000","0.00021000"],["78637.14000000","0.58741000"],["78637.51000000","0.00000000"],["78637.52000000","0.00007000"],["78637.56000000","0.00000000"],["78638.00000000","0.02407000"],["78638.08000000","0.00007000"],["78638.09000000","0.00000000"],["78638.32000000","0.00000000"],["78638.40000000","0.00007000"],["78638.43000000","0.00000000"],["78638.48000000","0.00007000"],["78638.60000000","0.00014000"],["78638.61000000","0.05353000"],["78638.65000000","0.00000000"],["78638.68000000","0.00000000"],["78638.78000000","0.00000000"],["78638.94000000","0.00000000"],["78639.41000000","0.00000000"],["78639.46000000","0.00000000"],["78640.10000000","0.00000000"],["78641.77000000","0.00000000"],["78641.78000000","0.00000000"],["78641.85000000","0.00000000"],["78641.86000000","0.00000000"],["78641.87000000","0.00000000"],["78641.88000000","0.00000000"],["78642.27000000","0.00007000"],["78642.29000000","0.00000000"],["78642.73000000","0.00000000"],["78643.08000000","0.00000000"],["78643.09000000","0.00000000"],["78643.18000000","0.00000000"],["78643.27000000","0.00000000"],["78643.28000000","0.00000000"],["78643.70000000","0.00000000"],["78643.71000000","0.00000000"],["78643.99000000","0.00000000"],["78644.07000000","0.00000000"],["78644.12000000","0.00000000"],["78645.07000000","0.00000000"],["78645.13000000","0.00000000"],["78645.72000000","0.00000000"],["78645.75000000","0.00000000"],["78645.99000000","0.00000000"],["78646.05000000","0.00000000"],["78646.14000000","0.00007000"],["78646.34000000","0.00000000"],["78646.36000000","0.00000000"],["78646.47000000","0.00000000"],["78646.66000000","0.00000000"],["78646.82000000","0.00000000"],["78646.90000000","0.00069000"],["78647.13000000","0.00000000"],["78647.14000000","0.00000000"],["78647.24000000","0.00000000"],["78647.26000000","0.00000000"],["78647.38000000","0.00000000"],["78647.79000000","0.00000000"],["78647.88000000","0.00007000"],["78647.94000000","0.00000000"],["78647.95000000","0.00000000"],["78648.01000000","0.00000000"],["78648.30000000","0.00000000"],["78648.31000000","0.00000000"],["78648.38000000","0.00000000"],["78648.39000000","0.01000000"],["78648.44000000","0.00000000"],["78648.81000000","0.00000000"],["78648.86000000","0.00000000"],["78649.18000000","0.00000000"],["78649.19000000","0.00000000"],["78649.21000000","0.00000000"],["78649.50000000","0.00000000"],["78649.84000000","0.00000000"],["78650.01000000","0.30299000"],["78650.27000000","0.00000000"],["78650.28000000","0.00400000"],["78650.41000000","0.00000000"],["78650.58000000","0.00000000"],["78650.59000000","0.00000000"],["78650.69000000","0.06000000"],["78650.81000000","0.00048000"],["78650.91000000","0.00508000"],["78651.08000000","0.00000000"],["78651.17000000","0.00000000"],["78651.29000000","0.08000000"],["78651.34000000","0.00000000"],["78651.48000000","0.00007000"],["78651.52000000","0.00000000"],["78651.56000000","0.00322000"],["78651.82000000","0.00635000"],["78651.88000000","0.00000000"],["78651.89000000","0.00000000"],["78652.00000000","0.02407000"],["78652.29000000","0.00000000"],["78652.33000000","0.00000000"],["78652.60000000","0.04857000"],["78652.85000000","0.00000000"],["78652.95000000","0.00000000"],["78653.05000000","0.00047000"],["78653.09000000","0.00000000"],["78653.13000000","0.00331000"],["78653.35000000","0.00191000"],["78653.58000000","0.00137000"],["78653.91000000","0.00000000"],["78653.99000000","0.31793000"],["78654.01000000","0.00000000"],["78654.35000000","0.00000000"],["78654.45000000","0.00000000"],["78655.35000000","0.00000000"],["78655.52000000","0.00000000"],["78655.79000000","0.00000000"],["78656.39000000","0.00000000"],["78656.74000000","0.00000000"],["78656.96000000","0.00000000"],["78657.04000000","0.00635000"],["78657.07000000","0.07619000"],["78657.39000000","0.00879000"],["78657.87000000","0.00000000"],["78658.29000000","0.00196000"],["78658.31000000","0.12713000"],["78658.41000000","0.02288000"],["78658.59000000","0.02000000"],["78658.94000000","0.00000000"],["78659.00000000","0.00007000"],["78659.39000000","0.00321000"],["78660.00000000","0.02554000"],["78660.11000000","0.00227000"],["78661.39000000","0.00163000"],["78661.43000000","0.00000000"],["78663.98000000","1.92676000"],["78663.99000000","0.00000000"],["78664.47000000","0.00000000"],["78665.01000000","0.00000000"],["78665.93000000","0.00000000"],["78666.45000000","0.00000000"],["78667.26000000","0.00332000"],["78667.27000000","0.00000000"],["78667.80000000","0.00000000"],["78668.19000000","0.00000000"],["78668.34000000","0.00000000"],["78668.64000000","0.00000000"],["78669.25000000","0.00000000"],["78669.61000000","0.00000000"],["78669.62000000","1.90515000"],["78671.00000000","0.00000000"],["78671.49000000","0.00000000"],["78672.00000000","0.02400000"],["78672.61000000","0.00000000"],["78672.82000000","0.00000000"],["78672.94000000","0.04593000"],["78673.23000000","0.00014000"],["78673.82000000","0.43618000"],["78674.00000000","0.02400000"],["78674.02000000","0.00000000"],["78674.41000000","0.68309000"],["78674.82000000","0.00059000"],["78675.00000000","0.00000000"],["78675.05000000","0.00000000"],["78675.13000000","0.00325000"],["78675.75000000","0.03186000"],["78676.00000000","0.03400000"],["78677.10000000","0.00007000"],["78678.91000000","0.00000000"],["78679.56000000","0.00000000"],["78679.96000000","0.34320000"],["78680.00000000","0.11940000"],["78680.97000000","0.00007000"],["78681.11000000","0.34320000"],["78683.00000000","0.00330000"],["78683.35000000","0.00000000"],["78684.20000000","0.00000000"],["78684.27000000","0.00000000"],["78684.84000000","0.00000000"],["78685.05000000","0.00400000"],["78685.26000000","0.00317000"],["78686.40000000","0.00007000"],["78687.40000000","0.00400000"],["78689.75000000","0.00400000"],["78693.03000000","0.00000000"],["78694.21000000","0.00000000"],["78696.39000000","0.00000000"],["78697.97000000","0.00000000"],["78701.22000000","0.00000000"],["78704.37000000","0.52030000"],["78705.28000000","0.32328000"],["78705.94000000","0.00000000"],["78707.69000000","0.00316000"],["78710.79000000","1.25792000"],["78713.41000000","0.00534000"],["78715.63000000","0.01696000"],["78720.52000000","1.21952000"],["78730.47000000","3.12467000"],["78730.64000000","0.00000000"],["78730.69000000","0.00406000"],["78735.50000000","0.21930000"],["78739.36000000","0.00000000"],["78757.99000000","0.00000000"],["78763.99000000","0.00127000"],["78779.99000000","0.00000000"],["78785.99000000","0.00127000"],["78883.32000000","0.00000000"],["78896.37000000","0.00000000"]]}}}
{"rx_ns": 173326538536900, "kind": "rest", "req": {"method": "GET", "url": "https://data-api.binance.vision/api/v3/depth?symbol=BTCUSDT&limit=1000", "limit": 1000, "weight": 50, "sent_ns": 173324932762200, "status": 200, "used_weight_1m": "50", "recv_ns": 173326472614400}, "frame": {"lastUpdateId":99076734902,"bids":[["78631.99000000","5.40299000"],["78631.98000000","1.90535000"],["78631.97000000","0.00013000"],["78630.74000000","1.65524000"],["78630.73000000","0.26690000"],["78630.72000000","0.00007000"],["78630.66000000","0.00014000"],["78630.00000000","0.07507000"],["78629.99000000","0.07240000"],["78629.76000000","0.00400000"],["78629.47000000","0.01932000"],["78629.38000000","0.03042000"],["78629.37000000","1.21959000"],["78629.10000000","0.04810000"],["78629.07000000","0.00327000"],["78628.44000000","0.00007000"],["78628.40000000","0.00254000"],["78628.21000000","0.03216000"],["78628.00000000","0.07500000"],["78627.99000000","0.00541000"],["78627.93000000","0.00027000"],["78627.87000000","0.00007000"],["78627.85000000","0.03007000"],["78627.57000000","0.00400000"],["78627.20000000","0.02289000"],["78626.95000000","0.03851000"],["78626.79000000","0.00014000"],["78626.78000000","0.03007000"],["78626.39000000","0.00329000"],["78626.34000000","0.00254000"],["78626.27000000","0.02517000"],["78625.89000000","0.00329000"],["78625.69000000","0.03851000"],["78625.55000000","0.00635000"],["78625.54000000","0.00007000"],["78625.53000000","0.04104000"],["78625.52000000","0.36224000"],["78625.49000000","0.00007000"],["78625.38000000","0.00400000"],["78625.27000000","0.00007000"],["78625.26000000","0.03007000"],["78625.25000000","0.12904000"],["78625.22000000","0.00400000"],["78624.70000000","0.00008000"],["78624.35000000","0.00007000"],["78624.07000000","0.00010000"],["78624.05000000","1.90515000"],["78624.04000000","1.21952000"],["78624.00000000","0.01021000"],["78623.52000000","0.00076000"],["78623.31000000","0.00321000"],["78623.19000000","0.00400000"],["78622.92000000","0.00014000"],["78622.90000000","0.12718000"],["78622.66000000","0.00007000"],["78622.31000000","0.00007000"],["78622.20000000","0.00333000"],["78622.00000000","0.02400000"],["78621.26000000","0.00126000"],["78621.23000000","0.08576000"],["78621.06000000","0.00322000"],["78621.01000000","0.01600000"],["78621.00000000","0.00400000"],["78620.44000000","0.00007000"],["78620.26000000","0.00007000"],["78620.00000000","0.14096000"],["78619.94000000","0.38163000"],["78619.89000000","0.00027000"],["78619.56000000","0.00007000"],["78619.51000000","0.00007000"],["78619.05000000","0.00014000"],["78618.95000000","0.02400000"],["78618.85000000","0.02600000"],["78618.81000000","0.00400000"],["78618.54000000","0.00007000"],["78618.37000000","0.01271000"],["78618.22000000","0.00007000"],["78618.16000000","0.02200000"],["78618.07000000","0.02800000"],["78618.06000000","0.02800000"],["78618.00000000","0.02400000"],["78617.74000000","0.00321000"],["78617.63000000","0.36224000"],["78617.40000000","1.92515000"],["78617.12000000","0.00319000"],["78617.00000000","0.00036000"],["78616.74000000","0.03000000"],["78616.66000000","0.00013000"],["78616.62000000","0.00400000"],["78616.56000000","0.00007000"],["78616.36000000","0.00007000"],["78616.21000000","0.00007000"],["78616.20000000","0.00010000"],["78616.17000000","0.00007000"],["78616.14000000","1.21952000"],["78616.13000000","0.21930000"],["78616.00000000","0.02426000"],["78615.79000000","0.02400000"],["78615.66000000","0.12720000"],["78615.65000000","0.00508000"],["78615.50000000","0.00007000"],["78615.18000000","0.00014000"],["78615.14000000","0.04400000"],["78614.45000000","0.00013000"],["78614.43000000","0.00400000"],["78614.35000000","0.02329000"],["78614.25000000","0.02200000"],["78614.22000000","0.02000000"],["78614.17000000","0.00007000"],["78614.13000000","0.00007000"],["78614.12000000","0.02000000"],["78614.09000000","0.00013000"],["78614.00000000","0.02400000"],["78612.85000000","0.00400000"],["78612.74000000","0.00320000"],["78612.68000000","0.00007000"],["78612.57000000","0.00007000"],["78612.37000000","1.90515000"],["78612.36000000","0.01400000"],["78612.35000000","0.38166000"],["78612.17000000","0.00007000"],["78612.09000000","0.00007000"],["78612.00000000","0.02400000"],["78611.94000000","0.00027000"],["78611.86000000","1.21952000"],["78611.35000000","0.06598000"],["78611.31000000","0.00014000"],["78611.10000000","0.63594000"],["78611.09000000","0.00762000"],["78610.97000000","0.03224000"],["78610.85000000","0.00273000"],["78610.10000000","0.34351000"],["78610.04000000","0.00007000"],["78610.00000000","0.12016000"],["78609.88000000","0.04496000"],["78609.65000000","0.00200000"],["78609.38000000","0.07623000"],["78609.30000000","0.00008000"],["78608.91000000","0.00400000"],["78608.80000000","0.00007000"],["78608.64000000","0.12000000"],["78608.33000000","0.00010000"],["78608.32000000","0.36224000"],["78608.05000000","0.00007000"],["78608.00000000","0.02400000"],["78607.79000000","1.21952000"],["78607.65000000","0.00400000"],["78607.64000000","1.90515000"],["78607.44000000","0.00014000"],["78606.97000000","0.14011000"],["78606.72000000","0.01232000"],["78606.36000000","0.00007000"],["78606.11000000","0.21930000"],["78606.07000000","0.00007000"],["78606.00000000","0.02400000"],["78605.95000000","0.00007000"],["78605.56000000","0.00007000"],["78605.18000000","0.12721000"],["78604.97000000","0.00400000"],["78604.94000000","1.22117000"],["78604.92000000","0.00007000"],["78604.87000000","0.00334000"],["78604.17000000","0.38170000"],["78604.00000000","0.72427000"],["78603.91000000","0.00007000"],["78603.57000000","0.00014000"],["78603.09000000","0.00007000"],["78603.04000000","0.00190000"],["78603.00000000","0.00400000"],["78602.81000000","0.00007000"],["78602.79000000","0.34354000"],["78602.67000000","0.40976000"],["78602.19000000","0.00126000"],["78602.00000000","0.02400000"],["78601.96000000","0.51143000"],["78601.87000000","0.00007000"],["78601.79000000","0.02400000"],["78601.75000000","0.00018000"],["78601.60000000","0.00008000"],["78601.33000000","0.00011000"],["78601.19000000","0.02200000"],["78601.12000000","0.00007000"],["78601.04000000","0.00007000"],["78601.03000000","0.00400000"],["78601.00000000","0.02000000"],["78600.57000000","0.00059000"],["78600.46000000","0.00010000"],["78600.00000000","0.13148000"],["78599.97000000","0.00012000"],["78599.84000000","1.90515000"],["78599.82000000","0.00007000"],["78599.74000000","1.21952000"],["78599.70000000","0.00014000"],["78599.25000000","0.00400000"],["78599.01000000","0.00007000"],["78598.97000000","0.29377000"],["78598.81000000","0.02400000"],["78598.23000000","0.21930000"],["78598.07000000","0.00011000"],["78598.00000000","0.02400000"],["78597.78000000","0.00007000"],["78597.75000000","0.00400000"],["78597.20000000","0.36224000"],["78597.16000000","0.02000000"],["78597.08000000","0.02000000"],["78597.00000000","0.00334000"],["78596.92000000","0.63623000"],["78596.51000000","0.13261000"],["78596.50000000","0.03395000"],["78596.24000000","0.00007000"],["78596.00000000","0.02434000"],["78595.83000000","0.00014000"],["78595.74000000","0.00007000"],["78595.66000000","0.00019000"],["78595.04000000","1.21952000"],["78595.03000000","1.90515000"],["78594.00000000","0.02400000"],["78593.90000000","0.00008000"],["78593.73000000","0.00150000"],["78593.69000000","0.00007000"],["78593.28000000","0.00007000"],["78592.59000000","0.00010000"],["78592.56000000","0.00007000"],["78592.51000000","0.00010000"],["78592.00000000","0.02400000"],["78591.97000000","0.02722000"],["78591.65000000","0.00007000"],["78591.35000000","0.68381000"],["78591.11000000","0.00636000"],["78591.00000000","0.01000000"],["78590.30000000","1.90515000"],["78590.29000000","1.21952000"],["78590.18000000","0.09582000"],["78590.13000000","0.21930000"],["78590.00000000","0.11994000"],["78589.82000000","0.00007000"],["78589.61000000","0.00007000"],["78589.40000000","0.00026000"],["78588.77000000","0.00007000"],["78588.54000000","0.00014000"],["78588.23000000","0.00349000"],["78588.19000000","0.36224000"],["78588.10000000","0.00419000"],["78588.01000000","0.00027000"],["78588.00000000","0.02400000"],["78587.87000000","0.00018000"],["78587.84000000","0.00008000"],["78587.56000000","0.00007000"],["78587.32000000","0.63631000"],["78587.30000000","0.00007000"],["78587.08000000","0.00007000"],["78586.74000000","0.00108000"],["78586.69000000","0.00013000"],["78586.20000000","0.00008000"],["78586.18000000","0.02200000"],["78586.00000000","0.02400000"],["78585.91000000","0.00007000"],["78585.75000000","0.00009000"],["78585.68000000","0.02000000"],["78585.52000000","0.00007000"],["78585.23000000","1.21952000"],["78585.00000000","0.70000000"],["78584.72000000","0.00010000"],["78584.51000000","0.00009000"],["78584.28000000","0.00007000"],["78584.08000000","0.00109000"],["78584.00000000","0.02400000"],["78583.70000000","0.00007000"],["78583.48000000","0.00007000"],["78582.99000000","0.02354000"],["78582.52000000","0.00079000"],["78582.25000000","0.21930000"],["78582.00000000","0.02407000"],["78581.43000000","0.00007000"],["78581.31000000","0.02200000"],["78580.84000000","1.21952000"],["78580.83000000","1.90515000"],["78580.80000000","0.00007000"],["78580.58000000","0.01141000"],["78580.52000000","0.00433000"],["78580.00000000","0.02457000"],["78579.39000000","0.00007000"],["78579.35000000","0.00027000"],["78578.50000000","0.00008000"],["78578.34000000","0.02400000"],["78578.32000000","0.02800000"],["78578.25000000","0.02800000"],["78578.00000000","0.02400000"],["78577.98000000","0.88910000"],["78577.95000000","0.00007000"],["78577.84000000","0.02000000"],["78577.77000000","0.00007000"],["78577.76000000","0.02007000"],["78577.63000000","1.26005000"],["78577.35000000","0.00007000"],["78577.12000000","0.02400000"],["78576.93000000","0.00007000"],["78576.92000000","0.00036000"],["78576.85000000","0.00010000"],["78576.00000000","0.02400000"],["78575.68000000","0.00007000"],["78575.59000000","0.03224000"],["78575.28000000","1.21952000"],["78575.27000000","0.36224000"],["78575.21000000","0.02400000"],["78574.72000000","1.95901000"],["78574.43000000","0.02000000"],["78574.12000000","0.02805000"],["78574.00000000","0.02400000"],["78573.77000000","0.00200000"],["78573.76000000","0.00007000"],["78573.63000000","0.02000000"],["78573.57000000","0.02200000"],["78573.48000000","0.21930000"],["78573.26000000","0.00007000"],["78573.21000000","0.02541000"],["78572.59000000","0.00007000"],["78572.00000000","0.02400000"],["78571.74000000","0.00007000"],["78571.73000000","0.00618000"],["78571.67000000","0.00007000"],["78571.47000000","0.00050000"],["78571.42000000","0.00025000"],["78571.38000000","1.90515000"],["78571.37000000","0.00027000"],["78571.35000000","0.00023000"],["78570.80000000","0.00008000"],["78570.61000000","1.21952000"],["78570.40000000","0.00109000"],["78570.32000000","0.00176000"],["78570.30000000","1.26017000"],["78570.29000000","0.00911000"],["78570.00000000","0.02662000"],["78569.67000000","0.02600000"],["78569.63000000","0.00406000"],["78569.57000000","0.01137000"],["78569.18000000","0.00007000"],["78568.98000000","0.00010000"],["78568.66000000","0.00007000"],["78568.56000000","0.00007000"],["78568.01000000","0.00316000"],["78568.00000000","0.02494000"],["78566.72000000","0.00428000"],["78566.66000000","0.00007000"],["78566.49000000","0.02200000"],["78566.46000000","0.00007000"],["78566.42000000","0.00010000"],["78566.21000000","0.00426000"],["78566.00000000","0.02400000"],["78565.99000000","0.02000000"],["78565.61000000","0.21930000"],["78565.50000000","0.00330000"],["78565.09000000","0.00007000"],["78564.52000000","1.21952000"],["78564.31000000","0.90883000"],["78564.10000000","0.00007000"],["78564.03000000","0.03224000"],["78564.00000000","0.02400000"],["78563.98000000","0.00026000"],["78563.96000000","0.00632000"],["78563.86000000","0.00007000"],["78563.82000000","0.00274000"],["78563.80000000","0.04768000"],["78563.34000000","0.00290000"],["78563.10000000","0.00008000"],["78563.03000000","0.00027000"],["78562.24000000","0.00008000"],["78562.00000000","0.02400000"],["78561.94000000","0.36224000"],["78561.93000000","1.90515000"],["78561.11000000","0.00010000"],["78561.01000000","0.00007000"],["78560.77000000","0.00038000"],["78560.64000000","3.41027000"],["78560.38000000","1.21952000"],["78560.00000000","0.04698000"],["78559.93000000","0.00129000"],["78559.84000000","0.00245000"],["78559.75000000","0.00009000"],["78559.53000000","0.00010000"],["78559.24000000","0.00059000"],["78559.15000000","0.00007000"],["78558.82000000","0.00100000"],["78558.70000000","0.00030000"],["78558.65000000","0.00010000"],["78558.63000000","0.02800000"],["78558.57000000","0.00013000"],["78558.56000000","0.02800000"],["78558.55000000","0.00221000"],["78558.40000000","0.00010000"],["78558.36000000","0.00035000"],["78558.16000000","0.02000000"],["78558.00000000","0.02400000"],["78557.66000000","0.00237000"],["78557.44000000","0.02400000"],["78557.42000000","0.00007000"],["78557.14000000","0.00030000"],["78557.01000000","0.00010000"],["78557.00000000","0.00255000"],["78556.86000000","0.00053000"],["78556.59000000","0.02541000"],["78556.14000000","0.21930000"],["78556.03000000","0.00229000"],["78556.02000000","0.06561000"],["78556.00000000","0.02400000"],["78555.88000000","0.00200000"],["78555.87000000","0.00007000"],["78555.62000000","0.00007000"],["78555.57000000","0.01738000"],["78555.55000000","0.00022000"],["78555.54000000","0.00021000"],["78555.50000000","0.00012000"],["78555.45000000","0.00126000"],["78555.40000000","0.00008000"],["78555.24000000","0.00007000"],["78555.00000000","0.00141000"],["78554.93000000","0.00027000"],["78554.88000000","0.00007000"],["78554.74000000","0.02000000"],["78554.60000000","0.00385000"],["78554.52000000","0.00025000"],["78554.48000000","0.00008000"],["78554.29000000","0.86960000"],["78554.25000000","0.00016000"],["78554.21000000","0.00019000"],["78554.00000000","0.02400000"],["78553.88000000","0.02200000"],["78553.79000000","0.00020000"],["78553.62000000","0.00007000"],["78553.59000000","0.00060000"],["78553.57000000","0.00028000"],["78553.54000000","0.00010000"],["78553.48000000","0.00063000"],["78553.43000000","0.00539000"],["78553.24000000","0.00010000"],["78553.14000000","0.00048000"],["78552.84000000","0.00007000"],["78552.78000000","0.00016000"],["78552.70000000","0.00111000"],["78552.58000000","0.00022000"],["78552.54000000","0.00050000"],["78552.48000000","1.90515000"],["78552.45000000","0.00017000"],["78552.28000000","0.00007000"],["78552.11000000","0.00010000"],["78552.00000000","0.02400000"],["78551.72000000","0.00450000"],["78551.68000000","0.00007000"],["78551.22000000","0.00038000"],["78550.87000000","0.00022000"],["78550.70000000","0.00024000"],["78550.41000000","0.00010000"],["78550.15000000","1.21952000"],["78550.00000000","0.04888000"],["78549.98000000","0.02600000"],["78549.80000000","0.00021000"],["78549.75000000","0.00014000"],["78549.64000000","0.00007000"],["78549.47000000","0.00103000"],["78549.37000000","0.00472000"],["78549.01000000","0.00007000"],["78549.00000000","0.00127000"],["78548.79000000","0.00010000"],["78548.75000000","0.00007000"],["78548.47000000","0.02541000"],["78548.46000000","0.00381000"],["78548.38000000","0.00105000"],["78548.37000000","0.00011000"],["78548.20000000","0.00055000"],["78548.05000000","0.00010000"],["78548.00000000","0.02830000"],["78547.94000000","0.00008000"],["78547.82000000","0.00011000"],["78547.78000000","0.36224000"],["78547.75000000","0.00025000"],["78547.44000000","0.00007000"],["78547.04000000","0.00027000"],["78546.72000000","0.00008000"],["78546.66000000","0.00009000"],["78546.61000000","0.00009000"],["78546.31000000","0.00316000"],["78546.30000000","0.00777000"],["78546.00000000","0.02400000"],["78545.53000000","0.00011000"],["78545.51000000","0.00007000"],["78545.45000000","0.00146000"],["78545.37000000","0.00010000"],["78545.30000000","0.00035000"],["78545.29000000","0.00007000"],["78545.15000000","0.03224000"],["78545.00000000","0.00012000"],["78544.90000000","1.22461000"],["78544.89000000","1.90515000"],["78544.76000000","0.00007000"],["78544.67000000","0.00007000"],["78544.60000000","0.00088000"],["78544.39000000","0.00011000"],["78544.12000000","0.00160000"],["78544.01000000","0.00055000"],["78544.00000000","0.02400000"],["78543.75000000","0.00012000"],["78543.70000000","0.00007000"],["78543.64000000","0.00030000"],["78543.36000000","3.81998000"],["78542.93000000","0.00023000"],["78542.73000000","0.00239000"],["78542.61000000","0.00038000"],["78542.37000000","0.00177000"],["78542.03000000","0.00116000"],["78542.00000000","0.02400000"],["78541.90000000","0.07040000"],["78541.89000000","0.21930000"],["78541.68000000","0.00007000"],["78541.64000000","0.00007000"],["78541.48000000","0.00007000"],["78541.36000000","0.00007000"],["78541.20000000","0.00013000"],["78541.17000000","0.00011000"],["78541.15000000","0.00024000"],["78541.10000000","0.00153000"],["78541.08000000","0.00011000"],["78540.74000000","0.00015000"],["78540.58000000","0.00007000"],["78540.54000000","0.00158000"],["78540.51000000","0.00072000"],["78540.43000000","0.00012000"],["78540.33000000","0.00007000"],["78540.27000000","0.00021000"],["78540.05000000","0.00036000"],["78540.00000000","0.02965000"],["78539.95000000","0.03276000"],["78539.92000000","0.00008000"],["78539.90000000","0.00042000"],["78539.89000000","0.00007000"],["78539.71000000","0.00028000"],["78539.68000000","0.00007000"],["78539.37000000","0.00013000"],["78538.96000000","0.00008000"],["78538.95000000","0.00008000"],["78538.88000000","0.00025000"],["78538.46000000","0.00031000"],["78538.29000000","0.00007000"],["78538.06000000","0.00033000"],["78538.00000000","0.02400000"],["78537.68000000","0.00200000"],["78537.67000000","0.00162000"],["78537.59000000","0.00049000"],["78537.55000000","0.00211000"],["78537.50000000","0.00010000"],["78537.19000000","0.00029000"],["78537.12000000","0.00007000"],["78537.03000000","0.00008000"],["78536.99000000","0.00011000"],["78536.87000000","0.00027000"],["78536.26000000","0.00007000"],["78536.01000000","0.00010000"],["78536.00000000","0.02400000"],["78535.99000000","0.00271000"],["78535.93000000","0.00063000"],["78535.82000000","0.00017000"],["78535.65000000","0.00007000"],["78535.45000000","1.90515000"],["78535.40000000","0.00044000"],["78535.35000000","0.00025000"],["78535.09000000","0.00007000"],["78534.73000000","0.00009000"],["78534.62000000","0.00008000"],["78534.46000000","0.00007000"],["78534.01000000","0.36224000"],["78534.00000000","0.24330000"],["78533.82000000","3.56216000"],["78533.69000000","0.00023000"],["78533.43000000","0.00008000"],["78533.33000000","0.00407000"],["78533.25000000","0.00018000"],["78533.24000000","0.00019000"],["78533.15000000","0.00007000"],["78532.10000000","0.00007000"],["78532.00000000","0.02400000"],["78531.74000000","0.00022000"],["78531.66000000","0.00026000"],["78531.20000000","0.00008000"],["78530.79000000","0.00009000"],["78530.71000000","0.00007000"],["78530.16000000","0.00010000"],["78530.00000000","0.03311000"],["78529.63000000","0.00010000"],["78529.41000000","0.03018000"],["78529.38000000","0.00033000"],["78529.35000000","0.00033000"],["78529.05000000","0.00023000"],["78528.99000000","0.00009000"],["78528.94000000","0.00027000"],["78528.93000000","0.00029000"],["78528.91000000","0.00039000"],["78528.60000000","0.00011000"],["78528.53000000","0.00043000"],["78528.43000000","0.00013000"],["78528.20000000","0.00010000"],["78528.15000000","0.00009000"],["78528.12000000","0.11607000"],["78528.00000000","0.02400000"],["78527.77000000","0.00148000"],["78527.49000000","0.00014000"],["78527.28000000","0.00007000"],["78527.20000000","0.00242000"],["78526.95000000","0.00080000"],["78526.76000000","0.04605000"],["78526.43000000","0.00017000"],["78526.29000000","0.00007000"],["78526.14000000","0.00226000"],["78526.12000000","1.90515000"],["78526.11000000","0.21960000"],["78526.00000000","0.02400000"],["78525.84000000","0.00203000"],["78525.74000000","0.00024000"],["78525.72000000","0.00028000"],["78525.57000000","0.00012000"],["78525.23000000","0.00420000"],["78525.08000000","0.00018000"],["78525.00000000","0.00031000"],["78524.75000000","0.00290000"],["78524.62000000","0.00762000"],["78524.60000000","0.00008000"],["78524.45000000","0.00274000"],["78524.32000000","0.00010000"],["78524.19000000","0.00139000"],["78524.16000000","0.00007000"],["78524.00000000","0.02400000"],["78523.80000000","0.00023000"],["78523.44000000","0.00008000"],["78523.35000000","0.00053000"],["78523.30000000","0.00232000"],["78523.21000000","0.00011000"],["78522.77000000","0.00013000"],["78522.72000000","0.00075000"],["78522.56000000","0.03499000"],["78522.38000000","0.00011000"],["78522.23000000","0.00087000"],["78522.21000000","0.00007000"],["78522.19000000","0.00057000"],["78522.00000000","0.02413000"],["78521.86000000","2.77509000"],["78521.76000000","0.00010000"],["78521.40000000","0.00007000"],["78521.25000000","0.00013000"],["78521.16000000","0.00017000"],["78521.07000000","0.00027000"],["78520.79000000","0.00009000"],["78520.66000000","0.00017000"],["78520.11000000","0.00008000"],["78520.00000000","0.03068000"],["78519.95000000","1.90515000"],["78519.94000000","2.14390000"],["78519.85000000","0.36231000"],["78519.77000000","0.00007000"],["78519.69000000","0.00016000"],["78519.41000000","0.00013000"],["78518.97000000","0.00260000"],["78518.52000000","0.00010000"],["78518.51000000","0.00029000"],["78518.34000000","0.00019000"],["78518.26000000","0.02823000"],["78518.23000000","0.00007000"],["78518.22000000","0.21930000"],["78518.18000000","0.00039000"],["78518.17000000","0.00007000"],["78518.01000000","0.00382000"],["78518.00000000","0.02400000"],["78517.84000000","0.00008000"],["78517.64000000","0.00030000"],["78517.62000000","0.04555000"],["78517.61000000","0.00007000"],["78517.53000000","0.00031000"],["78517.47000000","0.00368000"],["78517.27000000","0.00124000"],["78517.05000000","0.00021000"],["78516.55000000","0.00010000"],["78516.48000000","0.00011000"],["78516.44000000","0.00022000"],["78516.34000000","0.11607000"],["78516.12000000","0.00025000"],["78516.00000000","0.02400000"],["78515.68000000","0.00008000"],["78515.38000000","0.00093000"],["78515.15000000","0.00010000"],["78514.83000000","0.00007000"],["78514.82000000","0.00015000"],["78514.72000000","0.00007000"],["78514.47000000","0.00035000"],["78514.36000000","0.05082000"],["78514.35000000","0.00010000"],["78514.32000000","0.00025000"],["78514.30000000","0.00010000"],["78514.11000000","0.00024000"],["78514.08000000","0.05883000"],["78514.01000000","0.00023000"],["78514.00000000","0.02400000"],["78513.96000000","0.00167000"],["78513.77000000","0.00010000"],["78513.47000000","0.00008000"],["78513.43000000","0.00042000"],["78513.20000000","0.00027000"],["78512.81000000","0.00007000"],["78512.52000000","0.00023000"],["78512.50000000","0.00025000"],["78512.45000000","0.00429000"],["78512.35000000","0.00254000"],["78512.12000000","0.00007000"],["78512.05000000","0.00029000"],["78512.00000000","0.02407000"],["78511.78000000","0.00007000"],["78511.76000000","0.00016000"],["78511.72000000","0.00273000"],["78511.61000000","0.00072000"],["78511.58000000","0.00010000"],["78511.49000000","0.00010000"],["78511.44000000","0.00008000"],["78511.20000000","0.00017000"],["78510.96000000","0.00014000"],["78510.68000000","0.00007000"],["78510.47000000","0.80000000"],["78510.33000000","0.21930000"],["78510.28000000","0.00417000"],["78510.15000000","0.00007000"],["78510.00000000","0.02519000"],["78509.90000000","0.00042000"],["78509.82000000","0.00007000"],["78509.54000000","0.00007000"],["78509.25000000","0.00063000"],["78509.20000000","0.00129000"],["78509.19000000","0.00011000"],["78509.12000000","0.00014000"],["78509.09000000","0.00035000"],["78509.01000000","0.00008000"],["78508.99000000","0.00400000"],["78508.43000000","0.00020000"],["78508.17000000","0.00012000"],["78508.07000000","0.00047000"],["78508.00000000","0.02400000"],["78507.95000000","0.00008000"],["78507.82000000","0.00007000"],["78507.10000000","0.00054000"],["78506.66000000","0.00017000"],["78506.43000000","0.00012000"],["78506.40000000","0.00027000"],["78506.20000000","0.00011000"],["78506.10000000","0.00020000"],["78506.00000000","0.03071000"],["78505.73000000","0.00007000"],["78505.69000000","0.36224000"],["78505.68000000","0.00007000"],["78505.67000000","0.00017000"],["78505.55000000","0.00023000"],["78505.43000000","0.00136000"],["78505.40000000","0.00007000"],["78505.39000000","0.00049000"],["78505.24000000","0.00027000"],["78505.00000000","0.03915000"],["78504.98000000","0.00027000"],["78504.96000000","0.00016000"],["78504.93000000","0.00008000"],["78504.56000000","0.11607000"],["78504.51000000","0.00008000"],["78504.36000000","0.00007000"],["78504.28000000","0.00011000"],["78504.27000000","0.00109000"],["78504.26000000","0.00103000"],["78504.15000000","0.00030000"],["78504.13000000","0.00022000"],["78504.00000000","0.02400000"],["78503.75000000","0.00016000"],["78503.66000000","3.82191000"],["78503.30000000","0.00008000"],["78503.18000000","0.00635000"],["78502.64000000","0.00880000"],["78502.61000000","0.00077000"],["78502.44000000","0.21930000"],["78502.00000000","0.02400000"],["78501.82000000","0.00048000"],["78501.80000000","0.00007000"],["78501.21000000","0.00009000"],["78501.03000000","0.00049000"],["78501.00000000","0.05000000"],["78500.88000000","0.01286000"],["78500.78000000","0.00008000"],["78500.41000000","0.00028000"],["78500.33000000","0.00058000"],["78500.19000000","0.00008000"],["78500.16000000","0.00008000"],["78500.00000000","3.52770000"],["78499.95000000","0.00011000"],["78499.92000000","0.00023000"],["78499.82000000","0.00007000"],["78499.72000000","0.00050000"],["78499.66000000","0.00139000"],["78499.18000000","0.00007000"],["78499.16000000","0.00024000"],["78499.01000000","0.00015000"],["78498.93000000","0.00015000"],["78498.68000000","0.06000000"],["78498.29000000","0.00010000"],["78497.93000000","0.00013000"],["78497.66000000","0.00028000"],["78497.35000000","0.00027000"],["78497.14000000","0.00183000"],["78497.10000000","0.00011000"],["78496.67000000","0.00007000"],["78496.24000000","0.00011000"],["78496.08000000","0.00015000"],["78495.89000000","0.00007000"],["78495.78000000","0.00007000"],["78495.76000000","0.00013000"],["78495.49000000","0.00012000"],["78495.26000000","0.00042000"],["78494.87000000","0.00181000"],["78494.86000000","0.36224000"],["78494.73000000","0.00007000"],["78494.69000000","0.00122000"],["78494.55000000","0.21930000"],["78494.34000000","0.00327000"],["78494.00000000","0.00007000"],["78493.83000000","0.00007000"],["78493.80000000","0.00008000"],["78493.25000000","0.00009000"],["78492.95000000","0.00010000"],["78492.71000000","0.00033000"],["78492.70000000","0.00007000"],["78492.54000000","0.00007000"],["78492.41000000","0.00904000"],["78492.30000000","0.00046000"],["78492.10000000","0.00009000"],["78492.04000000","0.00035000"],["78491.22000000","0.00007000"],["78491.02000000","0.00406000"],["78490.83000000","0.00080000"],["78490.78000000","0.00010000"],["78490.70000000","0.00071000"],["78490.61000000","0.03725000"],["78490.54000000","0.00044000"],["78490.45000000","0.00007000"],["78490.23000000","0.00007000"],["78490.06000000","0.00009000"],["78490.00000000","0.00078000"],["78489.52000000","0.00009000"],["78489.46000000","0.00027000"],["78489.12000000","0.00023000"],["78489.00000000","0.01309000"],["78488.82000000","0.00007000"],["78488.57000000","0.00045000"],["78488.07000000","0.00243000"],["78488.00000000","0.00108000"],["78487.98000000","0.00012000"],["78487.53000000","0.00016000"],["78487.50000000","0.00007000"],["78487.29000000","0.00007000"],["78486.81000000","0.01114000"],["78486.66000000","0.21930000"],["78486.60000000","0.00018000"],["78486.39000000","0.00013000"],["78486.13000000","0.00198000"],["78486.12000000","3.82280000"],["78485.87000000","0.00038000"],["78485.71000000","0.00008000"],["78485.66000000","0.00084000"],["78485.56000000","0.00042000"],["78485.33000000","0.00007000"],["78485.25000000","0.00048000"],["78484.85000000","0.00127000"],["78484.84000000","0.00026000"],["78484.73000000","0.00014000"],["78484.57000000","0.00046000"],["78484.42000000","0.01610000"],["78484.10000000","1.52355000"],["78484.00000000","0.00060000"],["78483.64000000","0.00007000"],["78483.61000000","0.00019000"],["78483.45000000","0.00043000"],["78483.33000000","0.00009000"],["78482.91000000","0.00144000"],["78482.75000000","0.00120000"],["78482.58000000","0.00007000"],["78482.11000000","0.11607000"],["78481.66000000","0.09365000"],["78481.57000000","0.00027000"],["78481.47000000","0.00144000"],["78480.79000000","0.00008000"],["78480.70000000","0.36292000"],["78480.45000000","0.01068000"],["78480.43000000","0.00010000"],["78480.39000000","0.00019000"],["78480.37000000","0.00109000"],["78480.31000000","0.00009000"],["78480.15000000","0.00011000"],["78480.00000000","0.05548000"],["78479.93000000","0.00015000"],["78479.81000000","0.00010000"],["78479.64000000","0.00126000"],["78479.19000000","0.00008000"],["78479.17000000","0.00085000"],["78479.16000000","0.00023000"],["78478.77000000","0.21930000"],["78478.74000000","0.00764000"],["78478.65000000","0.00007000"],["78478.58000000","0.00061000"],["78478.46000000","0.00007000"],["78478.40000000","0.00516000"],["78478.26000000","0.00007000"],["78478.23000000","0.00016000"],["78477.93000000","0.00009000"],["78477.85000000","0.00066000"],["78477.71000000","0.00026000"],["78477.32000000","0.00008000"],["78477.27000000","0.00029000"],["78476.97000000","0.00007000"],["78476.88000000","0.00008000"],["78476.87000000","0.00013000"],["78476.69000000","0.00007000"],["78476.26000000","0.00059000"],["78476.00000000","0.00053000"],["78475.93000000","0.00040000"],["78475.90000000","0.00029000"],["78475.77000000","0.00544000"],["78475.46000000","0.01443000"],["78475.45000000","0.00126000"],["78475.40000000","0.00008000"],["78475.37000000","0.00015000"],["78475.32000000","0.00127000"],["78475.00000000","0.00008000"],["78474.99000000","0.00008000"],["78474.85000000","0.00009000"],["78474.83000000","0.00009000"],["78474.75000000","1.96083000"],["78474.68000000","0.00007000"],["78474.63000000","0.00109000"],["78474.60000000","0.00059000"],["78474.40000000","0.00010000"],["78474.39000000","0.00023000"],["78474.28000000","0.00009000"],["78474.26000000","0.00007000"],["78474.25000000","0.00031000"],["78474.22000000","0.00010000"],["78474.21000000","0.00509000"],["78474.16000000","0.00012000"],["78473.68000000","0.00027000"],["78473.67000000","0.00010000"],["78473.44000000","0.01992000"],["78473.33000000","0.00043000"],["78473.28000000","0.00007000"],["78473.14000000","0.00072000"],["78473.02000000","0.00014000"],["78472.90000000","0.00051000"],["78472.39000000","0.00007000"],["78472.33000000","0.00012000"],["78472.29000000","0.00010000"],["78472.22000000","0.00031000"],["78472.19000000","0.00019000"],["78472.17000000","0.00014000"],["78471.43000000","0.03032000"],["78470.95000000","0.01273000"],["78470.88000000","0.21930000"],["78470.76000000","0.00010000"],["78470.75000000","0.00007000"],["78470.74000000","0.00011000"],["78470.58000000","0.01365000"],["78470.33000000","0.11607000"],["78470.29000000","0.00009000"],["78470.00000000","0.01839000"],["78469.87000000","0.00177000"],["78469.81000000","0.00012000"],["78469.49000000","0.00129000"],["78469.27000000","0.00009000"],["78469.23000000","0.00010000"],["78468.79000000","0.00007000"],["78468.72000000","0.00013000"],["78468.64000000","0.00007000"],["78468.47000000","0.00012000"],["78468.46000000","0.00111000"],["78468.23000000","0.00060000"],["78468.22000000","0.00168000"],["78468.10000000","0.00007000"],["78468.02000000","0.00351000"],["78468.00000000","0.00074000"],["78467.98000000","0.00048000"],["78467.74000000","0.00013000"],["78467.45000000","0.00162000"],["78467.38000000","0.00007000"],["78467.13000000","0.00009000"],["78467.05000000","0.00020000"],["78466.75000000","0.00007000"],["78466.66000000","0.00258000"],["78466.55000000","0.00082000"],["78466.54000000","0.36224000"],["78466.53000000","0.00494000"],["78466.35000000","0.00011000"],["78466.12000000","0.00007000"],["78466.09000000","0.00012000"],["78466.04000000","0.00134000"],["78465.97000000","0.00234000"],["78465.93000000","0.00491000"]],"asks":[["78632.00000000","0.05798000"],["78632.01000000","0.00056000"],["78632.08000000","0.00007000"],["78632.58000000","0.00007000"],["78632.60000000","0.00007000"],["78632.92000000","0.00007000"],["78633.25000000","0.00014000"],["78633.26000000","0.03786000"],["78633.33000000","0.00014000"],["78633.34000000","0.00007000"],["78633.36000000","0.00007000"],["78633.41000000","0.00007000"],["78633.99000000","0.00014000"],["78634.00000000","0.02421000"],["78634.01000000","0.02014000"],["78634.43000000","0.00007000"],["78634.44000000","0.20825000"],["78634.52000000","0.03786000"],["78634.53000000","0.00007000"],["78634.60000000","0.05365000"],["78635.96000000","0.00007000"],["78636.00000000","0.02407000"],["78636.01000000","0.00653000"],["78636.61000000","0.00007000"],["78637.13000000","0.02161000"],["78637.14000000","0.58720000"],["78637.56000000","0.00047000"],["78638.00000000","0.02407000"],["78638.08000000","0.04000000"],["78638.32000000","0.00048000"],["78638.40000000","0.00014000"],["78638.43000000","0.00007000"],["78638.48000000","0.03000000"],["78638.65000000","0.00007000"],["78638.68000000","0.00027000"],["78638.78000000","0.12723000"],["78638.95000000","0.17886000"],["78639.41000000","0.00070000"],["78639.46000000","0.00191000"],["78639.83000000","0.00007000"],["78639.84000000","0.00007000"],["78640.00000000","0.02400000"],["78640.10000000","0.00008000"],["78640.70000000","0.00007000"],["78641.58000000","0.00007000"],["78641.77000000","0.00196000"],["78641.78000000","0.08000000"],["78641.83000000","0.00007000"],["78641.85000000","0.02288000"],["78641.87000000","0.02161000"],["78641.88000000","0.21930000"],["78642.00000000","0.02400000"],["78642.27000000","0.00014000"],["78642.73000000","0.00508000"],["78642.74000000","0.00007000"],["78643.18000000","0.00400000"],["78643.71000000","0.00137000"],["78643.72000000","0.00014000"],["78643.83000000","0.00007000"],["78644.00000000","0.02400000"],["78644.07000000","0.00328000"],["78644.12000000","0.00254000"],["78644.73000000","0.00007000"],["78644.79000000","0.00007000"],["78645.00000000","0.00007000"],["78645.07000000","0.31796000"],["78645.13000000","0.02161000"],["78645.72000000","0.00635000"],["78645.73000000","0.00010000"],["78645.75000000","0.00317000"],["78646.00000000","0.02600000"],["78646.01000000","0.00007000"],["78646.14000000","0.00014000"],["78646.34000000","0.00400000"],["78646.36000000","0.02000000"],["78646.47000000","0.02000000"],["78646.66000000","0.00027000"],["78646.83000000","0.00007000"],["78647.14000000","0.02000000"],["78647.24000000","0.02000000"],["78647.26000000","0.02000000"],["78647.38000000","0.04857000"],["78647.59000000","0.00400000"],["78647.60000000","0.00007000"],["78647.80000000","0.00008000"],["78647.95000000","0.00316000"],["78647.97000000","0.00007000"],["78648.00000000","0.02400000"],["78648.01000000","0.00332000"],["78648.30000000","0.00635000"],["78648.31000000","0.00400000"],["78648.87000000","0.00007000"],["78649.19000000","0.02000000"],["78649.21000000","0.06595000"],["78649.37000000","0.12714000"],["78649.50000000","0.02000000"],["78649.83000000","0.00007000"],["78649.84000000","0.02161000"],["78649.88000000","0.21930000"],["78650.00000000","0.02407000"],["78650.01000000","0.30299000"],["78650.28000000","0.00400000"],["78650.59000000","0.02000000"],["78650.92000000","0.00007000"],["78651.08000000","0.02000000"],["78651.17000000","0.02000000"],["78651.83000000","0.00007000"],["78651.89000000","0.00332000"],["78652.00000000","0.02570000"],["78652.25000000","0.00400000"],["78652.33000000","1.21952000"],["78652.96000000","0.00007000"],["78653.19000000","0.00254000"],["78653.55000000","0.00007000"],["78653.59000000","0.00010000"],["78653.88000000","0.00014000"],["78654.00000000","0.02400000"],["78654.01000000","0.00012000"],["78654.22000000","0.00400000"],["78654.28000000","0.02161000"],["78654.35000000","0.12713000"],["78654.84000000","0.00027000"],["78655.01000000","0.00007000"],["78655.35000000","0.00227000"],["78655.36000000","0.00007000"],["78655.47000000","0.02000000"],["78655.49000000","0.02000000"],["78655.50000000","0.00008000"],["78655.52000000","0.00059000"],["78655.60000000","0.00126000"],["78655.83000000","0.00329000"],["78655.96000000","0.02600000"],["78656.00000000","0.02400000"],["78656.19000000","0.00400000"],["78656.26000000","0.02600000"],["78656.39000000","0.02000000"],["78656.74000000","1.21952000"],["78656.96000000","0.09409000"],["78657.05000000","0.00007000"],["78657.39000000","0.00879000"],["78657.55000000","0.02161000"],["78657.75000000","0.00014000"],["78657.83000000","0.00007000"],["78657.87000000","1.90515000"],["78657.88000000","0.21930000"],["78658.00000000","0.02400000"],["78658.16000000","0.00400000"],["78658.63000000","0.00406000"],["78658.94000000","0.34329000"],["78659.10000000","0.00007000"],["78659.83000000","0.00007000"],["78660.00000000","0.12089000"],["78660.12000000","0.00400000"],["78660.92000000","1.21952000"],["78661.14000000","0.00007000"],["78661.43000000","0.36224000"],["78661.45000000","0.00010000"],["78661.62000000","0.00014000"],["78661.83000000","0.00007000"],["78662.00000000","0.02400000"],["78662.61000000","0.00400000"],["78662.88000000","0.00007000"],["78662.92000000","0.00027000"],["78663.06000000","0.10000000"],["78663.12000000","0.00007000"],["78663.19000000","0.00007000"],["78663.20000000","0.00008000"],["78663.83000000","0.00007000"],["78663.99000000","1.90515000"],["78664.00000000","0.02400000"],["78664.06000000","0.00200000"],["78664.47000000","0.00188000"],["78664.80000000","0.00400000"],["78665.01000000","0.34327000"],["78665.24000000","0.00007000"],["78665.49000000","0.00014000"],["78665.73000000","0.00007000"],["78665.83000000","0.00007000"],["78665.88000000","0.21930000"],["78665.93000000","0.34326000"],["78666.00000000","0.02414000"],["78666.45000000","0.04482000"],["78666.96000000","1.22117000"],["78666.99000000","0.00400000"],["78667.27000000","0.43622000"],["78667.28000000","0.00007000"],["78667.34000000","1.21952000"],["78667.80000000","0.63566000"],["78668.00000000","0.04400000"],["78668.05000000","0.00007000"],["78668.09000000","0.02000000"],["78668.19000000","0.02517000"],["78668.56000000","0.02161000"],["78668.75000000","0.02000000"],["78669.00000000","0.70000000"],["78669.31000000","0.00010000"],["78669.33000000","0.00007000"],["78669.36000000","0.00014000"],["78669.62000000","2.26739000"],["78670.00000000","0.11934000"],["78670.16000000","0.01270000"],["78670.84000000","0.02000000"],["78670.88000000","0.00007000"],["78670.90000000","0.00668000"],["78671.30000000","0.00027000"],["78671.37000000","0.00407000"],["78671.41000000","0.34324000"],["78671.75000000","0.00007000"],["78672.00000000","0.03400000"],["78672.89000000","0.34323000"],["78673.06000000","0.02000000"],["78673.23000000","0.00007000"],["78673.42000000","0.00007000"],["78673.83000000","0.00007000"],["78673.87000000","0.02161000"],["78673.88000000","0.21930000"],["78674.00000000","0.02400000"],["78674.02000000","0.86828000"],["78674.15000000","0.00008000"],["78674.81000000","0.12718000"],["78674.89000000","1.90515000"],["78675.22000000","1.21952000"],["78675.31000000","0.00010000"],["78675.46000000","0.00007000"],["78675.47000000","0.02000000"],["78675.55000000","0.02000000"],["78675.75000000","0.00400000"],["78675.83000000","0.00007000"],["78676.00000000","0.02400000"],["78676.21000000","0.02000000"],["78676.25000000","0.02000000"],["78676.68000000","0.02600000"],["78677.03000000","0.02600000"],["78677.12000000","0.02000000"],["78677.13000000","0.02000000"],["78677.17000000","0.00010000"],["78677.51000000","0.00007000"],["78677.66000000","0.63558000"],["78677.84000000","0.00007000"],["78677.93000000","0.02000000"],["78677.94000000","0.00400000"],["78678.00000000","0.02400000"],["78678.55000000","0.00426000"],["78678.60000000","0.00015000"],["78678.64000000","0.00007000"],["78678.77000000","0.36224000"],["78678.91000000","1.25843000"],["78679.43000000","0.00027000"],["78679.55000000","0.00007000"],["78679.56000000","0.00316000"],["78679.57000000","0.02161000"],["78679.83000000","0.00007000"],["78679.92000000","0.00625000"],["78679.99000000","1.21952000"],["78680.00000000","0.02407000"],["78680.35000000","0.00400000"],["78681.05000000","0.79579000"],["78681.31000000","1.90515000"],["78681.42000000","0.02346000"],["78681.46000000","0.00007000"],["78681.60000000","0.00007000"],["78681.79000000","0.00007000"],["78682.00000000","0.02400000"],["78682.18000000","0.01270000"],["78683.36000000","0.00427000"],["78683.64000000","0.00007000"],["78683.95000000","0.00423000"],["78683.96000000","1.21952000"],["78683.97000000","0.00007000"],["78684.00000000","0.24330000"],["78684.20000000","0.52017000"],["78684.27000000","0.32330000"],["78685.03000000","0.00010000"],["78685.27000000","0.01160000"],["78685.69000000","0.00007000"],["78685.90000000","0.00007000"],["78686.00000000","0.02400000"],["78686.30000000","0.00008000"],["78686.40000000","0.90594000"],["78687.14000000","0.36224000"],["78687.16000000","0.63550000"],["78687.47000000","0.00027000"],["78687.69000000","0.02000000"],["78687.78000000","0.02000000"],["78687.83000000","0.00007000"],["78688.00000000","0.02400000"],["78688.43000000","0.02000000"],["78689.78000000","0.00007000"],["78689.83000000","0.00007000"],["78690.00000000","0.02400000"],["78690.21000000","0.02000000"],["78690.48000000","0.00635000"],["78690.86000000","0.02000000"],["78691.27000000","1.90515000"],["78691.83000000","0.00014000"],["78691.88000000","0.21930000"],["78692.00000000","0.02400000"],["78692.89000000","0.00010000"],["78693.03000000","0.00111000"],["78693.06000000","0.01270000"],["78693.35000000","0.02000000"],["78693.42000000","0.01164000"],["78693.82000000","0.02600000"],["78693.83000000","0.00007000"],["78694.00000000","0.02415000"],["78694.16000000","0.00007000"],["78694.19000000","1.21952000"],["78694.21000000","0.00536000"],["78694.30000000","1.25818000"],["78694.32000000","0.00007000"],["78695.24000000","0.02000000"],["78695.30000000","0.04769000"],["78695.93000000","0.00027000"],["78696.00000000","0.02400000"],["78696.22000000","0.02000000"],["78696.29000000","0.00007000"],["78696.39000000","0.01702000"],["78696.76000000","0.00406000"],["78696.81000000","0.02000000"],["78696.82000000","0.02000000"],["78696.99000000","0.02600000"],["78697.19000000","0.00007000"],["78697.62000000","0.02000000"],["78697.63000000","0.36224000"],["78697.76000000","0.00007000"],["78697.97000000","0.00007000"],["78698.00000000","0.02400000"],["78700.00000000","0.03207000"],["78700.11000000","0.00007000"],["78700.75000000","0.00010000"],["78701.22000000","0.00315000"],["78701.23000000","1.90515000"],["78701.70000000","0.00008000"],["78701.92000000","0.00007000"],["78702.00000000","0.02400000"],["78702.06000000","0.00007000"],["78702.48000000","0.00007000"],["78702.52000000","1.25805000"],["78703.88000000","0.21930000"],["78704.00000000","0.02400000"],["78704.03000000","0.00027000"],["78704.42000000","1.21952000"],["78704.43000000","0.00100000"],["78704.91000000","0.00014000"],["78705.83000000","0.00007000"],["78705.95000000","0.36224000"],["78706.00000000","0.02400000"],["78707.70000000","0.00360000"],["78707.94000000","0.00007000"],["78708.00000000","0.02407000"],["78708.25000000","0.32030000"],["78708.61000000","0.00010000"],["78709.40000000","0.00008000"],["78709.57000000","0.02000000"],["78709.68000000","0.00007000"],["78709.92000000","0.00109000"],["78710.00000000","0.02400000"],["78710.04000000","0.00007000"],["78710.24000000","0.00007000"],["78710.33000000","0.00007000"],["78711.19000000","1.90515000"],["78711.89000000","0.21930000"],["78712.00000000","0.02400000"],["78712.01000000","0.00027000"],["78712.92000000","0.00007000"],["78713.83000000","0.00007000"],["78713.88000000","0.36224000"],["78714.00000000","0.02400000"],["78714.14000000","0.00057000"],["78714.34000000","0.00007000"],["78714.65000000","1.21952000"],["78714.68000000","0.00010000"],["78715.74000000","0.00007000"],["78715.83000000","0.00007000"],["78716.00000000","0.02400000"],["78716.33000000","0.00419000"],["78716.47000000","0.00010000"],["78717.10000000","0.00008000"],["78717.44000000","0.00007000"],["78717.83000000","0.00007000"],["78718.00000000","0.02400000"],["78718.43000000","0.00007000"],["78719.76000000","0.21930000"],["78719.82000000","0.00007000"],["78720.00000000","0.02400000"],["78720.35000000","0.00027000"],["78720.53000000","1.90515000"],["78720.54000000","2.13844000"],["78720.62000000","0.09314000"],["78720.74000000","0.00274000"],["78720.75000000","0.00285000"],["78720.89000000","3.81140000"],["78721.83000000","0.00007000"],["78722.00000000","0.02400000"],["78722.52000000","0.00007000"],["78722.57000000","0.36224000"],["78722.79000000","0.00007000"],["78723.92000000","2.15426000"],["78723.97000000","0.00007000"],["78724.00000000","0.02400000"],["78724.44000000","0.04544000"],["78724.80000000","0.00008000"],["78725.20000000","0.00007000"],["78725.76000000","0.00007000"],["78726.00000000","0.02400000"],["78727.63000000","0.21930000"],["78727.69000000","0.00007000"],["78728.00000000","0.02400000"],["78728.23000000","0.00431000"],["78728.29000000","0.00027000"],["78728.33000000","0.04630000"],["78728.65000000","0.00007000"],["78728.66000000","0.00007000"],["78730.00000000","0.02400000"],["78730.48000000","0.36224000"],["78730.64000000","0.93649000"],["78730.98000000","0.00007000"],["78732.00000000","0.02400000"],["78732.50000000","0.00008000"],["78732.76000000","0.00007000"],["78732.96000000","0.00007000"],["78733.38000000","0.80000000"],["78734.00000000","0.02400000"],["78734.47000000","0.00012000"],["78734.65000000","0.00007000"],["78736.00000000","0.02407000"],["78736.17000000","0.00200000"],["78736.19000000","0.00027000"],["78737.46000000","0.00007000"],["78738.00000000","0.02400000"],["78738.43000000","0.36224000"],["78738.90000000","0.00007000"],["78739.37000000","3.46616000"],["78739.50000000","0.00007000"],["78740.00000000","0.02400000"],["78740.20000000","0.00008000"],["78740.60000000","0.00019000"],["78740.72000000","0.00007000"],["78741.48000000","0.00007000"],["78741.69000000","0.00007000"],["78742.00000000","0.02400000"],["78743.25000000","0.00310000"],["78743.70000000","0.00014000"],["78743.83000000","0.00007000"],["78743.93000000","0.00508000"],["78744.00000000","0.02400000"],["78744.62000000","0.00027000"],["78745.04000000","0.00007000"],["78745.83000000","0.00007000"],["78746.00000000","0.02400000"],["78746.54000000","0.36224000"],["78746.69000000","0.00031000"],["78747.23000000","0.00400000"],["78747.89000000","0.00007000"],["78747.96000000","0.00076000"],["78748.00000000","0.02400000"],["78748.48000000","0.00007000"],["78749.14000000","0.00007000"],["78750.00000000","0.02400000"],["78750.81000000","0.00922000"],["78751.17000000","0.00007000"],["78752.00000000","0.02400000"],["78752.60000000","0.00027000"],["78753.69000000","0.00007000"],["78753.79000000","0.00160000"],["78754.00000000","0.02400000"],["78754.05000000","0.00010000"],["78755.28000000","0.00007000"],["78755.60000000","0.00008000"],["78755.69000000","0.36224000"],["78755.83000000","0.00007000"],["78756.00000000","0.02400000"],["78756.24000000","0.00007000"],["78757.56000000","0.05837000"],["78757.99000000","0.00127000"],["78758.00000000","0.02400000"],["78758.90000000","0.00007000"],["78759.37000000","0.00007000"],["78760.00000000","0.02400000"],["78760.02000000","0.00274000"],["78760.71000000","0.00027000"],["78760.99000000","0.00007000"],["78761.99000000","3.80941000"],["78762.00000000","0.02400000"],["78762.39000000","0.00007000"],["78763.00000000","0.00381000"],["78763.83000000","0.00007000"],["78764.00000000","0.02407000"],["78764.07000000","0.36224000"],["78765.52000000","0.00007000"],["78766.00000000","0.02400000"],["78766.23000000","0.00022000"],["78767.24000000","0.00007000"],["78768.00000000","0.02400000"],["78768.62000000","0.00027000"],["78769.58000000","0.00007000"],["78769.61000000","0.00007000"],["78770.00000000","0.02400000"],["78770.88000000","0.00381000"],["78771.00000000","0.00008000"],["78771.83000000","0.00007000"],["78771.99000000","0.36224000"],["78772.00000000","0.02400000"],["78773.83000000","0.00007000"],["78774.00000000","0.02400000"],["78774.01000000","0.00012000"],["78775.42000000","0.00406000"],["78775.83000000","0.00007000"],["78776.00000000","0.02400000"],["78776.50000000","0.00027000"],["78777.81000000","0.00007000"],["78778.00000000","0.02400000"],["78778.01000000","0.00007000"],["78778.80000000","0.00350000"],["78779.01000000","0.00381000"],["78779.35000000","0.00419000"],["78779.52000000","0.00007000"],["78779.99000000","0.00127000"],["78780.00000000","0.02400000"],["78780.69000000","0.36224000"],["78781.69000000","0.00007000"],["78781.90000000","0.00007000"],["78782.00000000","0.02400000"],["78782.49000000","0.00014000"],["78782.90000000","1.52355000"],["78783.83000000","0.00007000"],["78784.00000000","0.02400000"],["78784.48000000","0.00027000"],["78785.67000000","0.00695000"],["78786.00000000","0.02407000"],["78786.40000000","0.00008000"],["78787.76000000","0.00007000"],["78788.00000000","0.02400000"],["78788.57000000","0.00136000"],["78789.83000000","0.00007000"],["78789.94000000","0.36224000"],["78790.00000000","0.02444000"],["78790.10000000","0.00007000"],["78791.83000000","0.00007000"],["78792.00000000","0.02407000"],["78792.97000000","0.00027000"],["78793.16000000","0.00160000"],["78793.42000000","0.00010000"],["78793.44000000","1.25659000"],["78793.83000000","0.00007000"],["78793.95000000","0.01400000"],["78794.00000000","0.02400000"],["78794.51000000","0.00010000"],["78796.00000000","0.02400000"],["78796.24000000","0.00007000"],["78797.53000000","0.00007000"],["78797.94000000","0.36224000"],["78798.00000000","0.02400000"],["78798.99000000","0.00274000"],["78799.00000000","0.01636000"],["78799.84000000","0.00007000"],["78800.00000000","0.11296000"],["78800.25000000","0.00134000"],["78800.34000000","0.00007000"],["78801.34000000","0.10163000"],["78801.37000000","0.00027000"],["78801.80000000","0.00008000"],["78801.85000000","0.00007000"],["78801.99000000","0.00007000"],["78802.32000000","0.00094000"],["78802.78000000","0.00220000"],["78802.80000000","0.00007000"],["78803.30000000","0.00065000"],["78804.02000000","0.00007000"],["78804.30000000","0.00122000"],["78806.49000000","0.00007000"],["78806.60000000","0.00007000"],["78808.56000000","0.00007000"],["78809.44000000","0.00027000"],["78810.00000000","0.00050000"],["78810.16000000","0.01992000"],["78810.54000000","0.00007000"],["78811.76000000","0.00010000"],["78811.96000000","0.01270000"],["78812.34000000","0.03176000"],["78812.63000000","0.00007000"],["78813.67000000","0.00007000"],["78814.28000000","0.00020000"],["78814.35000000","0.00330000"],["78814.86000000","0.00507000"],["78815.85000000","0.00007000"],["78816.73000000","0.00007000"],["78816.89000000","0.00007000"],["78817.08000000","0.00008000"],["78817.20000000","0.00008000"],["78817.32000000","0.00014000"],["78817.54000000","0.00027000"],["78817.85000000","0.00007000"],["78819.88000000","0.03317000"],["78820.00000000","0.00057000"],["78820.28000000","0.00023000"],["78820.36000000","0.00007000"],["78820.45000000","0.00385000"],["78821.14000000","3.80656000"],["78821.28000000","0.00014000"],["78821.77000000","0.00008000"],["78822.10000000","0.00007000"],["78822.70000000","0.00010000"],["78822.80000000","0.00007000"],["78822.88000000","0.00007000"],["78823.15000000","0.00023000"],["78823.52000000","0.00202000"],["78824.45000000","0.00007000"],["78824.78000000","3.80638000"],["78824.82000000","0.00007000"],["78825.46000000","0.00027000"],["78826.08000000","0.00007000"],["78826.59000000","0.00021000"],["78826.98000000","0.00007000"],["78827.18000000","0.00021000"],["78828.45000000","0.00007000"],["78828.57000000","0.00008000"],["78828.62000000","0.00011000"],["78828.82000000","0.00111000"],["78828.92000000","0.00031000"],["78829.11000000","0.00013000"],["78829.24000000","0.00010000"],["78829.55000000","0.00008000"],["78830.00000000","0.00050000"],["78830.63000000","0.00058000"],["78832.15000000","0.03783000"],["78832.38000000","0.00007000"],["78832.60000000","0.00008000"],["78832.79000000","0.00010000"],["78832.98000000","0.00138000"],["78833.13000000","0.00007000"],["78833.33000000","0.50461000"],["78833.63000000","0.00027000"],["78833.67000000","0.00009000"],["78835.89000000","0.00032000"],["78837.83000000","0.00012000"],["78837.99000000","0.00274000"],["78839.28000000","0.00007000"],["78839.39000000","2.43413000"],["78839.65000000","0.00008000"],["78840.00000000","0.02618000"],["78840.68000000","0.00007000"],["78841.17000000","0.00031000"],["78841.58000000","0.00007000"],["78841.61000000","0.00151000"],["78841.69000000","0.00021000"],["78842.10000000","0.00007000"],["78842.42000000","0.00418000"],["78842.53000000","0.00012000"],["78842.62000000","0.00027000"],["78842.85000000","0.00013000"],["78843.02000000","0.00016000"],["78843.21000000","0.00007000"],["78843.52000000","0.00007000"],["78843.61000000","0.00008000"],["78843.74000000","0.00027000"],["78844.16000000","0.00025000"],["78844.32000000","0.00010000"],["78844.89000000","0.00011000"],["78845.20000000","0.00007000"],["78845.43000000","0.00007000"],["78845.91000000","0.00125000"],["78846.02000000","0.00008000"],["78846.15000000","0.00109000"],["78846.21000000","0.00406000"],["78847.48000000","0.00007000"],["78847.81000000","0.00010000"],["78848.00000000","0.00015000"],["78848.32000000","0.00035000"],["78848.37000000","0.00011000"],["78848.62000000","0.00047000"],["78849.36000000","0.00007000"],["78849.74000000","0.00380000"],["78849.90000000","0.00350000"],["78850.00000000","0.10484000"],["78850.17000000","0.00023000"],["78850.47000000","0.00020000"],["78850.90000000","0.00027000"],["78852.55000000","0.00018000"],["78852.61000000","0.00014000"],["78852.85000000","0.00009000"],["78852.88000000","0.00268000"],["78853.68000000","0.00011000"],["78855.03000000","0.00008000"],["78855.29000000","0.00025000"],["78855.67000000","0.00048000"],["78855.68000000","0.00007000"],["78856.57000000","0.00085000"],["78856.58000000","0.00023000"],["78856.80000000","0.00166000"],["78857.01000000","0.00010000"],["78857.03000000","0.00044000"],["78857.14000000","0.00099000"],["78857.29000000","0.00007000"],["78857.50000000","0.00023000"],["78857.62000000","0.00380000"],["78858.05000000","0.01992000"],["78858.48000000","0.00029000"],["78858.77000000","0.00099000"],["78858.90000000","0.00099000"],["78859.16000000","0.00007000"],["78859.20000000","0.00027000"],["78859.24000000","0.00197000"],["78860.00000000","0.00278000"],["78860.07000000","0.00014000"],["78860.14000000","0.00265000"],["78861.80000000","0.00009000"],["78862.30000000","0.00007000"],["78862.66000000","0.00007000"],["78863.40000000","0.00008000"],["78863.59000000","0.00010000"],["78863.63000000","0.00102000"],["78864.48000000","3.80462000"],["78864.86000000","0.00158000"],["78865.11000000","0.00010000"],["78865.32000000","0.00682000"],["78865.80000000","0.00019000"],["78865.92000000","0.00007000"],["78866.60000000","0.00012000"],["78866.66000000","0.00078000"],["78866.97000000","0.00008000"],["78867.22000000","0.00136000"],["78867.25000000","0.00903000"],["78867.45000000","0.00027000"],["78867.87000000","0.00007000"],["78867.91000000","0.00007000"],["78868.00000000","0.00007000"],["78868.06000000","0.00007000"],["78868.51000000","0.00025000"],["78869.11000000","0.00010000"],["78870.00000000","0.00057000"],["78870.08000000","0.00010000"],["78870.40000000","0.00260000"],["78870.96000000","0.00105000"],["78871.48000000","0.00008000"],["78872.01000000","0.00095000"],["78872.16000000","0.00010000"],["78872.18000000","0.00013000"],["78872.59000000","0.00285000"],["78872.64000000","0.00007000"],["78872.81000000","0.00008000"],["78872.94000000","0.00093000"],["78872.97000000","0.00025000"],["78873.07000000","0.00007000"],["78873.08000000","0.00008000"],["78873.64000000","0.00011000"],["78873.97000000","3.45968000"],["78874.00000000","0.00103000"],["78874.47000000","0.00012000"],["78874.67000000","0.04000000"],["78874.82000000","0.00010000"],["78875.00000000","0.00257000"],["78875.39000000","0.00027000"],["78876.47000000","0.00016000"],["78876.70000000","0.00102000"],["78876.71000000","0.00008000"],["78877.99000000","0.00274000"],["78878.28000000","0.00007000"],["78878.80000000","0.00008000"],["78878.83000000","0.00041000"],["78880.00000000","0.02631000"],["78881.18000000","0.00007000"],["78882.30000000","0.00008000"],["78882.35000000","0.00651000"],["78882.36000000","0.00104000"],["78882.51000000","0.00010000"],["78883.01000000","0.00007000"],["78883.10000000","0.00007000"],["78883.32000000","0.00030000"],["78883.48000000","0.00007000"],["78883.76000000","0.00027000"],["78884.01000000","0.00021000"],["78884.48000000","0.00016000"],["78884.62000000","0.00028000"],["78884.84000000","0.00131000"],["78885.87000000","0.00507000"],["78886.18000000","0.00007000"],["78886.38000000","0.00052000"],["78887.30000000","0.00040000"],["78888.00000000","0.00150000"],["78888.45000000","0.00053000"],["78888.69000000","0.00007000"],["78888.88000000","0.00010000"],["78889.71000000","0.00007000"],["78889.98000000","0.00026000"],["78890.00000000","0.00050000"],["78890.05000000","0.00062000"],["78890.12000000","0.00021000"],["78890.90000000","0.00010000"],["78891.43000000","0.00041000"],["78891.79000000","0.00027000"],["78891.84000000","0.00011000"],["78892.10000000","0.00250000"],["78892.45000000","0.00010000"],["78892.58000000","0.00491000"],["78893.00000000","0.00013000"],["78893.09000000","2.14968000"],["78893.90000000","0.00007000"],["78894.11000000","0.00030000"],["78894.13000000","0.00012000"],["78894.20000000","0.00008000"],["78894.75000000","0.00010000"],["78895.32000000","0.00015000"],["78895.60000000","0.00256000"],["78895.92000000","0.00007000"],["78896.19000000","0.00017000"],["78896.23000000","0.00011000"],["78897.28000000","0.00021000"],["78897.36000000","0.00380000"],["78897.38000000","0.00378000"],["78897.68000000","0.00011000"],["78898.19000000","0.00011000"],["78898.41000000","0.07296000"],["78898.66000000","0.00076000"],["78898.80000000","0.00020000"],["78898.86000000","0.00014000"],["78899.00000000","0.00670000"],["78899.10000000","0.00007000"],["78899.22000000","0.00035000"],["78899.71000000","0.11505000"],["78900.00000000","2.46224000"],["78900.05000000","0.00035000"],["78900.14000000","0.00007000"],["78900.67000000","0.00027000"],["78901.00000000","0.00012000"],["78901.05000000","0.00057000"],["78902.75000000","0.00011000"],["78903.52000000","0.00019000"],["78903.76000000","0.00012000"],["78904.00000000","0.00007000"],["78904.31000000","0.00007000"],["78904.33000000","0.00008000"],["78904.36000000","0.00078000"],["78904.49000000","0.00126000"],["78904.60000000","0.01377000"],["78904.72000000","0.01621000"],["78904.84000000","0.00012000"],["78905.45000000","0.00010000"],["78905.54000000","0.00418000"],["78905.73000000","0.11306000"],["78905.88000000","0.00007000"],["78906.70000000","0.00958000"],["78907.31000000","0.00047000"],["78907.40000000","0.00014000"],["78907.85000000","0.02759000"],["78908.53000000","0.00009000"],["78908.56000000","0.00027000"],["78908.66000000","0.00007000"],["78908.67000000","0.01889000"],["78909.41000000","0.00011000"],["78909.52000000","0.00007000"],["78909.60000000","0.00008000"],["78910.00000000","0.00050000"],["78910.47000000","0.00007000"],["78911.53000000","0.00010000"],["78911.63000000","0.01883000"],["78911.76000000","0.00008000"],["78912.10000000","0.01888000"],["78912.13000000","0.00273000"],["78912.16000000","0.00007000"],["78912.93000000","0.00254000"],["78913.04000000","0.00007000"],["78913.40000000","0.00021000"],["78914.28000000","0.00026000"],["78914.54000000","3.80201000"],["78914.73000000","0.00007000"],["78915.36000000","0.00022000"],["78915.52000000","0.00011000"],["78916.38000000","0.00007000"],["78916.56000000","0.00042000"],["78916.66000000","0.09978000"],["78916.86000000","0.00273000"],["78917.20000000","0.00009000"],["78917.23000000","0.00009000"],["78917.64000000","0.00007000"],["78918.49000000","0.00253000"],["78918.69000000","0.00064000"],["78919.20000000","0.00007000"],["78919.52000000","0.00017000"],["78919.53000000","0.00038000"],["78920.00000000","0.00137000"],["78920.04000000","0.00039000"],["78920.41000000","0.00027000"],["78920.46000000","0.00035000"],["78920.80000000","0.00010000"],["78922.80000000","0.00046000"],["78923.07000000","0.00007000"],["78923.88000000","0.00010000"],["78924.39000000","0.00008000"],["78924.57000000","0.00007000"],["78925.00000000","0.00350000"],["78925.17000000","0.00020000"],["78925.60000000","0.00017000"],["78925.81000000","0.00007000"],["78925.96000000","0.00050000"],["78926.06000000","0.00012000"],["78926.83000000","0.00038000"],["78928.01000000","0.00380000"],["78928.57000000","0.00146000"],["78929.06000000","2.50000000"],["78929.89000000","0.00017000"],["78929.96000000","0.00007000"],["78930.00000000","0.00145000"],["78931.32000000","0.00377000"],["78932.80000000","0.00008000"],["78932.86000000","0.00008000"],["78932.90000000","0.00027000"],["78933.06000000","0.00022000"],["78933.08000000","0.00010000"],["78933.18000000","0.00008000"],["78933.33000000","0.00041000"],["78933.69000000","0.02854000"],["78934.53000000","0.00009000"],["78935.15000000","0.00026000"],["78935.22000000","0.00034000"],["78935.39000000","0.00009000"],["78935.62000000","0.00055000"],["78935.66000000","0.00127000"],["78935.91000000","0.00011000"],["78936.19000000","0.00390000"],["78936.44000000","0.00017000"],["78936.50000000","0.00022000"],["78936.57000000","0.00380000"],["78936.77000000","0.00022000"],["78936.80000000","0.00007000"],["78936.83000000","1.19998000"],["78937.50000000","0.00007000"],["78937.59000000","0.00035000"],["78937.65000000","0.00014000"],["78937.84000000","0.00039000"],["78938.23000000","0.00244000"],["78938.58000000","0.07741000"],["78938.84000000","0.00236000"],["78939.38000000","0.00290000"],["78939.39000000","0.00037000"],["78939.80000000","0.00078000"],["78940.00000000","0.00065000"],["78940.29000000","0.00016000"],["78940.40000000","0.00008000"],["78940.45000000","0.00177000"],["78940.49000000","0.00008000"],["78940.99000000","0.00027000"],["78941.17000000","0.00727000"],["78941.62000000","0.00028000"],["78942.31000000","0.00017000"],["78942.48000000","0.00007000"],["78943.01000000","0.00160000"],["78943.37000000","0.00188000"],["78944.35000000","0.00009000"],["78944.44000000","0.00037000"],["78944.45000000","0.00050000"],["78944.46000000","0.00380000"],["78944.57000000","0.00010000"],["78944.66000000","0.00044000"],["78945.55000000","0.00011000"],["78945.86000000","0.00136000"],["78946.13000000","0.00032000"],["78946.42000000","0.00013000"],["78947.57000000","0.00033000"],["78947.77000000","0.00023000"],["78947.87000000","0.00022000"],["78948.22000000","0.01772000"],["78948.38000000","0.00197000"],["78948.44000000","0.00010000"],["78948.47000000","0.02135000"],["78948.63000000","0.00065000"],["78949.00000000","0.00018000"],["78949.27000000","0.00027000"],["78949.33000000","0.00016000"],["78949.51000000","0.00015000"],["78949.62000000","0.00011000"],["78949.77000000","0.00017000"],["78950.00000000","0.00236000"],["78950.01000000","0.00066000"],["78950.14000000","0.00009000"],["78950.90000000","0.00010000"],["78950.94000000","0.00013000"],["78952.06000000","0.00020000"],["78952.78000000","0.00013000"],["78953.01000000","0.00014000"],["78953.49000000","0.00046000"],["78953.95000000","0.00013000"],["78954.01000000","0.00044000"],["78954.57000000","0.00063000"],["78955.55000000","0.00202000"],["78955.65000000","0.00014000"],["78955.81000000","0.00013000"],["78956.11000000","0.00010000"],["78956.20000000","0.00026000"],["78956.22000000","0.00019000"],["78956.93000000","0.00506000"],["78957.23000000","0.00019000"],["78957.26000000","0.00273000"],["78957.34000000","0.00038000"],["78957.74000000","0.00009000"],["78958.01000000","0.00027000"],["78958.48000000","0.00048000"],["78958.65000000","0.00187000"],["78959.59000000","0.02408000"],["78960.00000000","0.00438000"]]}}
{"rx_ns": 173326538536900, "frame": {"stream":"btcusdt@depth20@100ms","data":{"lastUpdateId":99076736639,"bids":[["78637.13000000","5.34192000"],["78637.12000000","1.90535000"],["78637.11000000","0.00013000"],["78636.01000000","0.07500000"],["78636.00000000","0.44906000"],["78635.99000000","0.39948000"],["78635.95000000","0.00007000"],["78635.87000000","0.03538000"],["78635.70000000","0.00400000"],["78635.49000000","0.00800000"],["78635.48000000","0.07514000"],["78635.47000000","0.64979000"],["78634.65000000","0.00317000"],["78634.61000000","0.04246000"],["78634.59000000","0.00007000"],["78634.53000000","0.00014000"],["78634.24000000","0.04821000"],["78634.22000000","0.00014000"],["78634.21000000","0.21911000"],["78634.20000000","1.58183000"]],"asks":[["78637.14000000","0.58841000"],["78637.15000000","0.00049000"],["78637.99000000","0.00014000"],["78638.00000000","0.02407000"],["78638.40000000","0.00007000"],["78638.61000000","0.00014000"],["78639.10000000","0.00014000"],["78639.11000000","0.01691000"],["78639.74000000","0.00014000"],["78639.75000000","0.05353000"],["78639.84000000","0.00007000"],["78639.99000000","0.00014000"],["78640.00000000","0.02407000"],["78640.36000000","0.00007000"],["78640.37000000","0.02819000"],["78640.70000000","0.00007000"],["78641.63000000","0.03383000"],["78641.83000000","0.00007000"],["78641.99000000","0.00007000"],["78642.00000000","0.02407000"]]}}}
{"rx_ns": 173326538900000, "frame": {"stream":"btcusdt@depth@100ms","data":{"e":"depthUpdate","E":1787603265714,"s":"BTCUSDT","U":99076736259,"u":99076736639,"b":[["78637.13000000","5.34192000"],["78637.12000000","1.90535000"],["78637.11000000","0.00013000"],["78636.73000000","0.00000000"],["78636.01000000","0.07500000"],["78636.00000000","0.44906000"],["78635.99000000","0.39948000"],["78635.98000000","0.00000000"],["78635.97000000","0.00000000"],["78635.87000000","0.03538000"],["78635.49000000","0.00800000"],["78635.48000000","0.07514000"],["78635.47000000","0.64979000"],["78634.61000000","0.04246000"],["78634.24000000","0.04821000"],["78634.22000000","0.00014000"],["78634.21000000","0.21911000"],["78634.20000000","1.58183000"],["78634.00000000","0.00007000"],["78633.99000000","0.00007000"],["78633.40000000","0.00007000"],["78633.35000000","0.04646000"],["78633.10000000","0.00007000"],["78632.96000000","0.35551000"],["78632.00000000","0.00000000"],["78631.99000000","0.07748000"],["78631.98000000","0.00000000"],["78630.00000000","0.09539000"],["78629.99000000","0.03645000"],["78629.38000000","0.00014000"],["78628.96000000","0.00007000"],["78627.37000000","0.08576000"],["78626.45000000","0.00000000"],["78619.51000000","0.00000000"],["78618.66000000","0.00012000"],["78610.83000000","0.14022000"],["78609.77000000","0.41062000"],["78607.20000000","0.00000000"],["78606.97000000","0.00000000"],["78606.64000000","0.00000000"],["78604.87000000","0.00000000"],["78602.67000000","0.00000000"],["78602.14000000","0.02525000"],["78596.00000000","0.03434000"],["78593.00000000","0.00000000"],["78569.24000000","0.00110000"],["70773.42000000","0.00032000"]],"a":[["78636.00000000","0.00000000"],["78636.01000000","0.00000000"],["78636.02000000","0.00000000"],["78636.74000000","0.00000000"],["78637.13000000","0.00000000"],["78637.14000000","0.58841000"],["78637.15000000","0.00049000"],["78637.52000000","0.00000000"],["78637.99000000","0.00014000"],["78638.00000000","0.02407000"],["78638.08000000","0.00000000"],["78638.48000000","0.00000000"],["78638.60000000","0.00000000"],["78638.61000000","0.00014000"],["78639.10000000","0.00014000"],["78639.11000000","0.01691000"],["78639.74000000","0.00014000"],["78639.75000000","0.05353000"],["78639.83000000","0.00000000"],["78639.99000000","0.00014000"],["78640.00000000","0.02407000"],["78640.36000000","0.00007000"],["78640.37000000","0.02819000"],["78641.58000000","0.00000000"],["78641.63000000","0.03383000"],["78641.99000000","0.00007000"],["78642.00000000","0.02407000"],["78642.89000000","0.03383000"],["78643.99000000","0.00000000"],["78644.00000000","0.02407000"],["78645.99000000","0.00000000"],["78646.00000000","0.02607000"],["78646.86000000","0.00027000"],["78648.00000000","0.02407000"],["78648.39000000","0.01007000"],["78649.36000000","0.00000000"],["78649.37000000","0.12721000"],["78650.69000000","0.02000000"],["78651.03000000","0.00007000"],["78651.29000000","0.00000000"],["78651.49000000","0.00000000"],["78651.56000000","0.00000000"],["78652.39000000","0.04000000"],["78652.60000000","0.00000000"],["78652.64000000","0.00000000"],["78652.69000000","0.00000000"],["78652.76000000","0.00319000"],["78653.13000000","0.00000000"],["78653.18000000","0.00000000"],["78653.19000000","0.00254000"],["78653.52000000","0.04857000"],["78655.09000000","0.08000000"],["78655.47000000","0.00000000"],["78655.49000000","0.00000000"],["78655.96000000","0.00000000"],["78656.26000000","0.00000000"],["78658.29000000","0.00000000"],["78669.00000000","0.00000000"],["78669.61000000","0.36224000"],["78673.44000000","0.00012000"],["78675.75000000","0.00400000"],["78676.00000000","0.02400000"],["78676.27000000","0.02742000"],["78677.00000000","0.01000000"],["78677.75000000","0.02517000"],["78678.37000000","0.00193000"],["78678.55000000","0.00000000"],["78679.92000000","0.00000000"],["78681.82000000","0.00196000"],["78683.36000000","0.00000000"],["78683.95000000","0.00000000"],["78684.84000000","0.00007000"],["78712.28000000","0.00110000"],["78835.59000000","0.00007000"],["78839.52000000","0.00007000"],["78901.19000000","0.00030000"]]}}}
{"rx_ns": 173326638270900, "frame": {"stream":"btcusdt@depth20@100ms","data":{"lastUpdateId":99076736736,"bids":[["78637.13000000","5.35920000"],["78637.12000000","1.90542000"],["78637.11000000","0.00013000"],["78636.01000000","0.07521000"],["78636.00000000","0.44913000"],["78635.99000000","0.03014000"],["78635.95000000","0.00007000"],["78635.87000000","0.03545000"],["78635.70000000","0.00400000"],["78635.49000000","0.00800000"],["78635.48000000","0.07514000"],["78635.47000000","0.07497000"],["78634.65000000","0.00317000"],["78634.61000000","0.04246000"],["78634.59000000","0.00007000"],["78634.53000000","0.00014000"],["78634.24000000","0.04821000"],["78634.21000000","0.21911000"],["78634.20000000","1.58176000"],["78634.00000000","0.00007000"]],"asks":[["78637.14000000","0.58862000"],["78637.15000000","0.00070000"],["78637.99000000","0.00014000"],["78638.00000000","0.02407000"],["78638.40000000","0.00007000"],["78638.61000000","0.00007000"],["78639.10000000","0.00014000"],["78639.11000000","0.01698000"],["78639.74000000","0.00014000"],["78639.75000000","0.05367000"],["78639.84000000","0.00007000"],["78639.99000000","0.00014000"],["78640.00000000","0.02407000"],["78640.36000000","0.00007000"],["78640.37000000","0.02826000"],["78640.70000000","0.00007000"],["78641.63000000","0.03390000"],["78641.83000000","0.00007000"],["78642.00000000","0.02407000"],["78642.27000000","0.00007000"]]}}}
{"rx_ns": 173326638365900, "frame": {"stream":"btcusdt@depth@100ms","data":{"e":"depthUpdate","E":1787603265814,"s":"BTCUSDT","U":99076736640,"u":99076736736,"b":[["78637.13000000","5.35920000"],["78637.12000000","1.90542000"],["78636.01000000","0.07521000"],["78636.00000000","0.44913000"],["78635.99000000","0.03014000"],["78635.87000000","0.03545000"],["78635.48000000","0.07514000"],["78635.47000000","0.07497000"],["78634.22000000","0.00000000"],["78634.21000000","0.21911000"],["78634.20000000","1.58176000"],["78633.10000000","0.00000000"],["78632.96000000","0.00000000"],["78631.99000000","0.07430000"],["78627.60000000","1.22117000"],["78622.22000000","0.00000000"],["78620.01000000","0.63585000"],["78604.94000000","0.00000000"],["78597.00000000","0.01000000"],["78596.00000000","0.02434000"],["78570.50000000","0.86942000"],["70773.42000000","0.00048000"]],"a":[["78637.14000000","0.58862000"],["78637.15000000","0.00070000"],["78638.00000000","0.02407000"],["78638.61000000","0.00007000"],["78639.11000000","0.01698000"],["78639.75000000","0.05367000"],["78640.00000000","0.02407000"],["78640.37000000","0.02826000"],["78641.63000000","0.03390000"],["78641.99000000","0.00000000"],["78642.00000000","0.02407000"],["78642.89000000","0.03390000"],["78644.00000000","0.02400000"],["78645.21000000","0.21668000"],["78646.00000000","0.02600000"],["78648.00000000","0.02400000"],["78648.39000000","0.01000000"],["78650.28000000","0.00000000"],["78652.38000000","0.31792000"],["78653.99000000","0.00000000"],["78654.25000000","0.00000000"],["78654.34000000","0.00254000"],["78655.09000000","0.00000000"],["78656.21000000","0.02000000"],["78656.49000000","0.08000000"],["78658.59000000","0.00000000"],["78664.10000000","0.00000000"],["78676.27000000","0.00000000"],["78676.84000000","0.00000000"],["78690.17000000","0.00628000"],["78690.25000000","0.86810000"],["78692.10000000","0.00400000"],["78693.71000000","0.00433000"],["78694.53000000","0.00429000"],["78699.22000000","0.00406000"],["78741.08000000","0.93649000"],["78839.52000000","0.00000000"],["78858.05000000","0.00000000"],["78866.18000000","0.01992000"]]}}}
{"rx_ns": 173326738251500, "frame": {"stream":"btcusdt@depth20@100ms","data":{"lastUpdateId":99076736766,"bids":[["78637.13000000","5.61632000"],["78637.12000000","1.90542000"],["78637.11000000","0.00013000"],["78637.10000000","0.05000000"],["78637.05000000","0.05000000"],["78636.01000000","0.07507000"],["78636.00000000","0.09514000"],["78635.99000000","0.03014000"],["78635.95000000","0.00007000"],["78635.87000000","0.03545000"],["78635.70000000","0.00400000"],["78635.49000000","0.00800000"],["78635.48000000","0.07514000"],["78635.47000000","0.07497000"],["78634.65000000","0.00317000"],["78634.61000000","0.04246000"],["78634.59000000","0.00007000"],["78634.53000000","0.00014000"],["78634.24000000","0.04821000"],["78634.21000000","0.21911000"]],"asks":[["78637.14000000","0.58869000"],["78637.15000000","0.00070000"],["78637.99000000","0.00014000"],["78638.00000000","0.02407000"],["78638.40000000","0.00007000"],["78638.61000000","0.00007000"],["78639.10000000","0.00014000"],["78639.11000000","0.01698000"],["78639.74000000","0.00014000"],["78639.75000000","0.05367000"],["78639.84000000","0.00007000"],["78639.99000000","0.00014000"],["78640.00000000","0.02407000"],["78640.36000000","0.00007000"],["78640.37000000","0.02826000"],["78640.70000000","0.00007000"],["78641.63000000","0.03390000"],["78641.83000000","0.00007000"],["78642.00000000","0.02407000"],["78642.27000000","0.00007000"]]}}}
{"rx_ns": 173326738333900, "frame": {"stream":"btcusdt@depth@100ms","data":{"e":"depthUpdate","E":1787603265914,"s":"BTCUSDT","U":99076736737,"u":99076736766,"b":[["78637.13000000","5.61632000"],["78637.10000000","0.05000000"],["78637.05000000","0.05000000"],["78636.01000000","0.07507000"],["78636.00000000","0.09514000"],["78631.80000000","0.02600000"],["78631.02000000","0.02807000"],["78631.00000000","0.02807000"],["78628.20000000","0.00007000"],["78618.07000000","0.00000000"],["78592.42000000","0.02600000"],["70773.42000000","0.00064000"],["62909.70000000","0.00000000"]],"a":[["78637.14000000","0.58869000"],["78639.75000000","0.05367000"],["78643.97000000","0.17780000"],["78645.21000000","0.00000000"],["78654.33000000","0.00254000"],["78654.34000000","0.00000000"],["78661.55000000","0.02000000"],["78707.38000000","0.02000000"],["78707.47000000","0.02000000"],["78717.31000000","0.02000000"]]}}}
{"rx_ns": 173326849505500, "frame": {"stream":"btcusdt@depth20@100ms","data":{"lastUpdateId":99076737508,"bids":[["78641.62000000","3.88927000"],["78641.61000000","1.90515000"],["78640.80000000","0.00932000"],["78640.37000000","1.34530000"],["78640.36000000","4.08483000"],["78640.35000000","0.43643000"],["78640.00000000","1.16166000"],["78639.99000000","0.58561000"],["78639.74000000","0.04009000"],["78639.73000000","0.00007000"],["78639.11000000","0.07500000"],["78639.10000000","0.81196000"],["78639.09000000","1.21952000"],["78639.05000000","0.05000000"],["78638.60000000","0.00007000"],["78638.40000000","0.00014000"],["78638.39000000","0.00007000"],["78638.05000000","0.00400000"],["78638.00000000","0.07507000"],["78637.99000000","0.00114000"]],"asks":[["78641.63000000","0.02856000"],["78641.64000000","0.00014000"],["78641.71000000","0.00014000"],["78641.72000000","0.00007000"],["78641.83000000","0.00007000"],["78641.99000000","0.00014000"],["78642.00000000","0.02407000"],["78642.27000000","0.00007000"],["78642.88000000","0.00014000"],["78642.89000000","0.03390000"],["78643.72000000","0.00007000"],["78643.97000000","0.00007000"],["78643.99000000","0.00014000"],["78644.00000000","0.02407000"],["78644.79000000","0.00007000"],["78645.73000000","0.00010000"],["78645.99000000","0.00007000"],["78646.00000000","0.02607000"],["78646.01000000","0.00007000"],["78646.14000000","0.00007000"]]}}}
{"rx_ns": 173326849606200, "frame": {"stream":"btcusdt@depth@100ms","data":{"e":"depthUpdate","E":1787603266014,"s":"BTCUSDT","U":99076736767,"u":99076737508,"b":[["78641.62000000","3.88927000"],["78641.61000000","1.90515000"],["78640.80000000","0.00932000"],["78640.69000000","0.00000000"],["78640.37000000","1.34530000"],["78640.36000000","4.08483000"],["78640.35000000","0.43643000"],["78640.00000000","1.16166000"],["78639.99000000","0.58561000"],["78639.98000000","0.00000000"],["78639.97000000","0.00000000"],["78639.83000000","0.00000000"],["78639.74000000","0.04009000"],["78639.73000000","0.00007000"],["78639.72000000","0.00000000"],["78639.65000000","0.00000000"],["78639.11000000","0.07500000"],["78639.10000000","0.81196000"],["78639.09000000","1.21952000"],["78639.08000000","0.00000000"],["78639.05000000","0.05000000"],["78638.60000000","0.00007000"],["78638.40000000","0.00014000"],["78638.39000000","0.00007000"],["78638.05000000","0.00400000"],["78638.00000000","0.07507000"],["78637.99000000","0.00114000"],["78637.98000000","0.00000000"],["78637.29000000","0.00000000"],["78637.21000000","0.00000000"],["78637.15000000","0.00000000"],["78637.14000000","0.21944000"],["78637.13000000","0.63531000"],["78637.12000000","0.00000000"],["78637.11000000","0.00000000"],["78637.10000000","0.00000000"],["78637.05000000","0.00000000"],["78636.21000000","0.00000000"],["78636.01000000","0.00000000"],["78636.00000000","0.00007000"],["78635.99000000","0.03007000"],["78635.93000000","0.00027000"],["78635.87000000","0.03538000"],["78635.49000000","0.00000000"],["78635.48000000","0.00007000"],["78635.47000000","0.07504000"],["78635.09000000","0.38155000"],["78634.24000000","0.00000000"],["78634.21000000","0.12904000"],["78632.41000000","0.00400000"],["78632.11000000","0.00007000"],["78631.99000000","0.04423000"],["78631.94000000","0.00010000"],["78631.89000000","0.02400000"],["78631.02000000","0.02800000"],["78630.73000000","0.00331000"],["78630.17000000","0.00007000"],["78630.00000000","0.18115000"],["78629.99000000","0.00007000"],["78629.38000000","1.90515000"],["78627.37000000","0.00000000"],["78627.33000000","0.38159000"],["78627.18000000","0.02000000"],["78626.27000000","0.00000000"],["78624.37000000","0.00007000"],["78624.06000000","0.63585000"],["78622.66000000","0.00000000"],["78621.77000000","0.06597000"],["78621.06000000","0.00000000"],["78620.01000000","0.00000000"],["78619.81000000","0.07622000"],["78618.06000000","0.00000000"],["78618.03000000","0.00126000"],["78617.90000000","0.00000000"],["78615.93000000","0.00000000"],["78614.69000000","0.00254000"],["78614.22000000","0.00000000"],["78610.83000000","0.13768000"],["78610.10000000","0.00000000"],["78603.72000000","0.00000000"],["78602.19000000","0.00000000"],["78601.77000000","0.68372000"],["78601.03000000","0.00000000"],["78600.00000000","0.03606000"],["78599.70000000","0.00000000"],["78599.46000000","0.00000000"],["78591.35000000","0.00000000"],["78588.40000000","0.88898000"],["78577.98000000","0.00000000"],["78576.93000000","0.00000000"],["78500.25000000","1.52355000"],["78484.10000000","0.00000000"],["78459.69000000","0.00000000"],["74834.68000000","0.00000000"],["74705.27000000","0.00020000"],["70773.42000000","0.00000000"],["70768.80000000","0.00000000"],["70768.79000000","0.00009000"],["66961.30000000","0.00000000"],["66843.24000000","0.00017000"],["62912.00000000","0.00031000"]],"a":[["78637.14000000","0.00000000"],["78637.15000000","0.00000000"],["78637.30000000","0.00000000"],["78637.99000000","0.00000000"],["78638.00000000","0.00000000"],["78638.40000000","0.00000000"],["78638.61000000","0.00000000"],["78639.10000000","0.00000000"],["78639.11000000","0.00000000"],["78639.12000000","0.00000000"],["78639.66000000","0.00000000"],["78639.74000000","0.00000000"],["78639.75000000","0.00000000"],["78639.76000000","0.00000000"],["78639.84000000","0.00000000"],["78639.99000000","0.00000000"],["78640.00000000","0.00000000"],["78640.01000000","0.00000000"],["78640.36000000","0.00000000"],["78640.37000000","0.00000000"],["78640.70000000","0.00000000"],["78641.62000000","0.00000000"],["78641.63000000","0.02856000"],["78641.64000000","0.00014000"],["78641.71000000","0.00014000"],["78641.72000000","0.00007000"],["78641.99000000","0.00014000"],["78642.61000000","0.00000000"],["78642.74000000","0.00000000"],["78642.88000000","0.00014000"],["78642.89000000","0.03390000"],["78643.72000000","0.00007000"],["78643.83000000","0.00000000"],["78643.97000000","0.00007000"],["78643.99000000","0.00014000"],["78644.00000000","0.02407000"],["78644.73000000","0.00000000"],["78645.00000000","0.00000000"],["78645.99000000","0.00007000"],["78646.00000000","0.02607000"],["78647.97000000","0.00000000"],["78648.00000000","0.02407000"],["78648.39000000","0.00000000"],["78649.37000000","0.12721000"],["78649.88000000","0.00000000"],["78650.01000000","0.30292000"],["78650.69000000","0.00000000"],["78650.91000000","0.00000000"],["78651.19000000","0.00000000"],["78651.49000000","0.00000000"],["78651.82000000","0.00000000"],["78652.24000000","0.00508000"],["78652.38000000","0.00000000"],["78652.39000000","0.00000000"],["78652.76000000","0.00000000"],["78652.99000000","0.03000000"],["78653.37000000","0.00000000"],["78653.51000000","0.00000000"],["78653.52000000","0.00000000"],["78654.18000000","0.00007000"],["78654.32000000","0.00000000"],["78654.33000000","0.00000000"],["78654.58000000","0.00000000"],["78654.59000000","0.00000000"],["78654.69000000","0.04000000"],["78654.76000000","0.00000000"],["78655.83000000","0.00007000"],["78655.99000000","0.31792000"],["78656.13000000","0.00000000"],["78656.15000000","0.04857000"],["78656.16000000","0.00000000"],["78656.21000000","0.00000000"],["78656.33000000","0.00000000"],["78657.07000000","0.00000000"],["78657.36000000","0.00007000"],["78657.39000000","0.00000000"],["78657.74000000","0.00635000"],["78659.24000000","0.00007000"],["78659.31000000","0.02000000"],["78660.10000000","0.00323000"],["78661.44000000","0.02000000"],["78661.50000000","0.06594000"],["78663.06000000","0.00000000"],["78663.98000000","0.02161000"],["78664.04000000","0.00322000"],["78666.15000000","0.02000000"],["78667.98000000","0.00325000"],["78669.61000000","0.00000000"],["78670.00000000","0.02400000"],["78670.90000000","0.00008000"],["78671.92000000","0.00321000"],["78675.55000000","0.00000000"],["78676.91000000","0.00000000"],["78677.00000000","0.00000000"],["78677.10000000","0.00014000"],["78677.46000000","0.00000000"],["78678.00000000","0.02400000"],["78678.60000000","0.00015000"],["78678.98000000","0.00000000"],["78680.00000000","0.12940000"],["78681.05000000","0.00000000"],["78681.10000000","0.10000000"],["78685.26000000","0.00000000"],["78688.21000000","0.34316000"],["78688.42000000","0.00317000"],["78690.24000000","1.21952000"],["78707.55000000","0.90563000"],["78707.69000000","0.00000000"],["78710.56000000","0.02000000"],["78710.78000000","0.00316000"],["78712.12000000","1.25790000"],["78714.93000000","0.02000000"],["78720.89000000","0.00000000"],["78724.33000000","0.00010000"],["78739.36000000","1.90515000"],["78743.37000000","0.21930000"],["78782.90000000","0.00000000"],["78785.99000000","0.00000000"],["78789.93000000","0.00127000"],["78799.11000000","1.52355000"],["78810.16000000","0.00000000"],["78844.24000000","0.01992000"],["78848.68000000","0.00406000"],["78963.32000000","7.59941000"],["79128.00000000","0.00007000"]]}}}
{"rx_ns": 173326940175500, "frame": {"stream":"btcusdt@depth20@100ms","data":{"lastUpdateId":99076738017,"bids":[["78641.99000000","5.18935000"],["78641.98000000","1.90535000"],["78641.97000000","0.00013000"],["78641.95000000","0.05000000"],["78641.90000000","0.05000000"],["78641.63000000","0.07500000"],["78641.62000000","0.74321000"],["78641.61000000","0.00007000"],["78640.80000000","0.00007000"],["78640.40000000","0.00400000"],["78640.37000000","0.04086000"],["78640.36000000","0.21944000"],["78640.35000000","0.00007000"],["78640.10000000","0.00008000"],["78640.00000000","0.07507000"],["78639.99000000","0.57476000"],["78639.74000000","0.04002000"],["78639.11000000","0.07500000"],["78639.10000000","0.76516000"],["78639.09000000","1.21952000"]],"asks":[["78642.00000000","0.02349000"],["78642.01000000","0.00056000"],["78642.27000000","0.00007000"],["78642.89000000","0.00007000"],["78643.72000000","0.00007000"],["78643.99000000","0.00014000"],["78644.00000000","0.02407000"],["78644.23000000","0.00014000"],["78644.24000000","0.05360000"],["78644.79000000","0.00007000"],["78645.99000000","0.00014000"],["78646.00000000","0.02607000"],["78646.14000000","0.00007000"],["78646.83000000","0.00007000"],["78646.86000000","0.00027000"],["78647.59000000","0.00400000"],["78647.60000000","0.00007000"],["78647.88000000","0.00007000"],["78647.99000000","0.00014000"],["78648.00000000","0.02407000"]]}}}
{"rx_ns": 173326940324700, "frame": {"stream":"btcusdt@depth@100ms","data":{"e":"depthUpdate","E":1787603266114,"s":"BTCUSDT","U":99076737509,"u":99076738017,"b":[["78641.99000000","5.18935000"],["78641.98000000","1.90535000"],["78641.97000000","0.00013000"],["78641.95000000","0.05000000"],["78641.90000000","0.05000000"],["78641.82000000","0.00000000"],["78641.71000000","0.00000000"],["78641.70000000","0.00000000"],["78641.63000000","0.07500000"],["78641.62000000","0.74321000"],["78641.61000000","0.00007000"],["78641.60000000","0.00000000"],["78640.80000000","0.00007000"],["78640.40000000","0.00400000"],["78640.38000000","0.00000000"],["78640.37000000","0.04086000"],["78640.36000000","0.21944000"],["78640.35000000","0.00007000"],["78640.10000000","0.00008000"],["78640.00000000","0.07507000"],["78639.99000000","0.57476000"],["78639.74000000","0.04002000"],["78639.73000000","0.00000000"],["78639.10000000","0.76516000"],["78639.05000000","0.00000000"],["78638.73000000","0.04821000"],["78638.00000000","0.00007000"],["78637.99000000","0.00107000"],["78637.14000000","0.21937000"],["78637.13000000","0.55273000"],["78637.12000000","0.30007000"],["78637.10000000","0.30007000"],["78635.87000000","0.00000000"],["78635.50000000","0.12716000"],["78634.61000000","0.00000000"],["78634.57000000","0.00007000"],["78634.00000000","0.00500000"],["78633.99000000","0.00000000"],["78633.40000000","0.00000000"],["78633.35000000","0.00400000"],["78632.59000000","0.00000000"],["78632.41000000","0.00000000"],["78632.17000000","0.00007000"],["78632.00000000","0.00500000"],["78631.99000000","0.04403000"],["78631.96000000","0.08576000"],["78631.09000000","0.02200000"],["78630.00000000","0.10039000"],["78628.74000000","0.02400000"],["78628.00000000","0.00500000"],["78627.87000000","0.00007000"],["78627.21000000","0.63583000"],["78627.06000000","0.02000000"],["78626.00000000","0.01200000"],["78625.89000000","0.00000000"],["78624.06000000","0.00000000"],["78623.31000000","0.00000000"],["78618.85000000","0.00000000"],["78618.55000000","0.14022000"],["78617.13000000","0.51141000"],["78617.00000000","0.00029000"],["78615.66000000","0.00000000"],["78614.69000000","0.14022000"],["78614.13000000","0.41078000"],["78614.12000000","0.00000000"],["78612.74000000","0.00000000"],["78608.45000000","0.02446000"],["78607.94000000","0.09717000"],["78605.15000000","0.00400000"],["78604.97000000","0.00000000"],["78603.00000000","0.00000000"],["78602.74000000","0.00000000"],["78602.14000000","0.00000000"],["78602.00000000","0.03400000"],["78601.96000000","0.00000000"],["78598.00000000","0.02400000"],["78597.00000000","0.00000000"],["78580.52000000","0.00000000"],["78578.34000000","0.00000000"],["78577.35000000","0.00000000"],["78577.00000000","0.86935000"],["78570.50000000","0.00000000"],["78533.82000000","4.09058000"],["78468.61000000","1.20000000"],["78451.03000000","0.00000000"],["78407.36000000","0.00000000"],["78404.10000000","0.00010000"],["78329.12000000","0.00000000"],["78321.25000000","0.00000000"],["78311.25000000","0.00000000"],["78248.78000000","0.01000000"],["77933.85000000","0.00010000"],["77857.53000000","0.01000000"],["77468.24000000","0.01000000"],["77080.90000000","0.01000000"],["76695.50000000","0.01000000"],["76312.02000000","0.01000000"],["75930.46000000","0.01000000"],["75550.81000000","0.01000000"],["75173.05000000","0.01000000"],["74797.19000000","0.01000000"],["74423.20000000","0.01000000"],["74051.09000000","0.01000000"],["73680.83000000","0.01000000"],["73312.43000000","0.01000000"],["72945.86000000","0.01000000"],["70777.80000000","0.00016000"],["70777.46000000","0.00000000"],["70777.00000000","4.78696000"]],"a":[["78641.63000000","0.00000000"],["78641.64000000","0.00000000"],["78641.71000000","0.00000000"],["78641.72000000","0.00000000"],["78641.83000000","0.00000000"],["78641.99000000","0.00000000"],["78642.00000000","0.02349000"],["78642.01000000","0.00056000"],["78642.88000000","0.00000000"],["78642.89000000","0.00007000"],["78643.97000000","0.00000000"],["78644.23000000","0.00014000"],["78644.24000000","0.05360000"],["78645.73000000","0.00000000"],["78645.99000000","0.00014000"],["78646.01000000","0.00000000"],["78646.90000000","0.00000000"],["78647.80000000","0.00000000"],["78647.99000000","0.00014000"],["78648.00000000","0.02407000"],["78648.39000000","0.00000000"],["78649.36000000","0.00007000"],["78649.37000000","0.12728000"],["78650.00000000","0.02414000"],["78650.01000000","0.30306000"],["78650.31000000","0.20818000"],["78650.81000000","0.00000000"],["78652.00000000","0.02414000"],["78652.24000000","0.00000000"],["78652.25000000","0.00000000"],["78652.99000000","0.00000000"],["78653.19000000","0.00000000"],["78653.58000000","0.00000000"],["78653.88000000","0.00014000"],["78653.99000000","0.00000000"],["78654.22000000","0.00000000"],["78654.69000000","0.00000000"],["78654.77000000","0.00000000"],["78655.00000000","0.00000000"],["78655.39000000","0.00000000"],["78655.99000000","0.00000000"],["78656.09000000","0.01000000"],["78656.15000000","0.00000000"],["78656.19000000","0.00400000"],["78656.34000000","0.00000000"],["78656.48000000","0.00000000"],["78656.49000000","0.00069000"],["78656.98000000","0.00508000"],["78656.99000000","0.02000000"],["78657.03000000","0.00000000"],["78657.04000000","0.00000000"],["78657.54000000","0.00000000"],["78657.74000000","0.00000000"],["78657.83000000","0.00007000"],["78658.10000000","0.31790000"],["78658.11000000","0.04857000"],["78658.39000000","0.00000000"],["78658.70000000","0.00000000"],["78659.29000000","0.04000000"],["78659.30000000","0.00000000"],["78659.46000000","0.00254000"],["78659.99000000","0.00137000"],["78660.11000000","0.00000000"],["78660.67000000","0.00047000"],["78660.91000000","0.01270000"],["78660.92000000","0.00000000"],["78661.70000000","0.08000000"],["78664.57000000","0.02000000"],["78666.95000000","0.00227000"],["78666.96000000","0.00000000"],["78669.07000000","0.00254000"],["78672.94000000","0.00000000"],["78673.82000000","0.00000000"],["78677.75000000","0.00000000"],["78678.77000000","0.00000000"],["78679.33000000","0.00000000"],["78680.00000000","0.11940000"],["78680.34000000","0.43615000"],["78680.97000000","0.00014000"],["78681.00000000","0.00000000"],["78681.42000000","0.00000000"],["78681.62000000","0.00000000"],["78681.70000000","0.00663000"],["78681.73000000","0.00000000"],["78681.81000000","0.00000000"],["78682.00000000","0.03400000"],["78682.44000000","0.00000000"],["78682.47000000","0.04575000"],["78683.50000000","0.00000000"],["78683.66000000","0.00000000"],["78684.31000000","0.00000000"],["78684.73000000","0.02341000"],["78688.71000000","0.00007000"],["78690.00000000","0.11932000"],["78690.25000000","0.00000000"],["78694.45000000","0.00400000"],["78695.30000000","0.00000000"],["78696.76000000","0.86803000"],["78696.80000000","0.00400000"],["78708.12000000","0.02000000"],["78710.56000000","0.00000000"],["78716.51000000","0.02000000"],["78724.44000000","0.00000000"],["78728.33000000","0.00000000"],["78728.83000000","0.04770000"],["78729.26000000","0.02000000"],["78734.47000000","0.00000000"],["78740.60000000","0.00000000"],["78741.08000000","0.00000000"],["78746.69000000","0.00000000"],["78749.30000000","0.04546000"],["78756.19000000","0.04571000"],["78763.99000000","0.00000000"],["78769.99000000","0.00127000"],["78839.40000000","0.00007000"],["78843.33000000","0.00007000"],["78847.68000000","0.00007000"],["78851.61000000","0.00007000"],["79035.21000000","0.01000000"],["79430.39000000","0.01000000"],["79827.54000000","0.01000000"],["80226.68000000","0.01000000"],["80627.81000000","0.01000000"],["81030.95000000","0.01000000"],["81436.11000000","0.01000000"],["81843.29000000","0.01000000"],["82252.50000000","0.01000000"],["82663.77000000","0.01000000"],["83077.09000000","0.01000000"],["83492.47000000","0.01000000"],["83909.93000000","0.01000000"],["84329.48000000","0.01000000"],["84751.13000000","0.01000000"]]}}}
{"rx_ns": 173327044007000, "frame": {"stream":"btcusdt@depth20@100ms","data":{"lastUpdateId":99076738507,"bids":[["78643.99000000","3.95252000"],["78643.98000000","0.00020000"],["78643.97000000","0.00013000"],["78643.72000000","0.07514000"],["78643.71000000","4.15172000"],["78643.70000000","0.05000000"],["78642.89000000","0.04079000"],["78642.88000000","0.00021000"],["78642.75000000","0.00400000"],["78642.45000000","0.03784000"],["78642.27000000","0.00014000"],["78642.00000000","0.20033000"],["78641.99000000","1.16855000"],["78641.98000000","0.00007000"],["78641.95000000","0.00014000"],["78641.90000000","0.00007000"],["78641.75000000","0.00400000"],["78641.63000000","0.07507000"],["78641.62000000","0.16865000"],["78641.19000000","0.04541000"]],"asks":[["78644.00000000","0.02527000"],["78644.01000000","0.00069000"],["78644.02000000","0.00013000"],["78644.24000000","0.00014000"],["78644.79000000","0.00007000"],["78645.99000000","0.00014000"],["78646.00000000","0.02607000"],["78646.14000000","0.00007000"],["78646.32000000","0.00014000"],["78646.33000000","0.05353000"],["78646.59000000","0.00014000"],["78646.60000000","0.01543000"],["78646.83000000","0.00034000"],["78647.59000000","0.00400000"],["78647.60000000","0.00007000"],["78647.85000000","0.00014000"],["78647.86000000","0.02572000"],["78647.99000000","0.00007000"],["78648.00000000","0.02407000"],["78648.87000000","0.00007000"]]}}}
{"rx_ns": 173327044151600, "frame": {"stream":"btcusdt@depth@100ms","data":{"e":"depthUpdate","E":1787603266214,"s":"BTCUSDT","U":99076738018,"u":99076738507,"b":[["78643.99000000","3.95252000"],["78643.98000000","0.00020000"],["78643.97000000","0.00013000"],["78643.72000000","0.07514000"],["78643.71000000","4.15172000"],["78643.70000000","0.05000000"],["78643.69000000","0.00000000"],["78643.30000000","0.00000000"],["78642.90000000","0.00000000"],["78642.89000000","0.04079000"],["78642.88000000","0.00021000"],["78642.75000000","0.00400000"],["78642.46000000","0.00000000"],["78642.45000000","0.03784000"],["78642.27000000","0.00014000"],["78642.26000000","0.00000000"],["78642.01000000","0.00000000"],["78642.00000000","0.20033000"],["78641.99000000","1.16855000"],["78641.98000000","0.00007000"],["78641.97000000","0.00000000"],["78641.95000000","0.00014000"],["78641.90000000","0.00007000"],["78641.75000000","0.00400000"],["78641.63000000","0.07507000"],["78641.62000000","0.16865000"],["78641.61000000","0.00000000"],["78641.19000000","0.04541000"],["78640.85000000","0.15000000"],["78640.82000000","0.04821000"],["78640.80000000","0.00000000"],["78640.37000000","0.04079000"],["78640.36000000","0.00007000"],["78640.35000000","0.00000000"],["78640.00000000","0.07500000"],["78639.99000000","0.00342000"],["78639.93000000","0.04541000"],["78639.75000000","0.00000000"],["78639.11000000","0.00000000"],["78639.10000000","0.19245000"],["78638.73000000","0.00000000"],["78637.99000000","0.00007000"],["78637.14000000","0.00007000"],["78637.13000000","0.33343000"],["78635.99000000","0.30007000"],["78635.95000000","0.00000000"],["78635.48000000","0.00000000"],["78635.47000000","0.00328000"],["78635.26000000","0.00007000"],["78634.59000000","0.00000000"],["78634.22000000","1.90515000"],["78634.21000000","0.12897000"],["78634.17000000","0.00007000"],["78634.06000000","0.08576000"],["78632.95000000","0.00000000"],["78632.08000000","0.00007000"],["78632.00000000","0.01200000"],["78631.99000000","0.00324000"],["78631.96000000","0.00000000"],["78630.00000000","0.10739000"],["78628.36000000","0.02000000"],["78627.57000000","0.02400000"],["78627.07000000","0.02200000"],["78626.28000000","0.06597000"],["78625.81000000","0.00000000"],["78625.22000000","0.00000000"],["78624.65000000","0.00000000"],["78624.31000000","0.07622000"],["78621.77000000","0.00000000"],["78620.08000000","0.00007000"],["78619.81000000","0.00000000"],["78618.95000000","0.00000000"],["78618.55000000","0.14022000"],["78618.16000000","0.00000000"],["78615.79000000","0.00000000"],["78614.69000000","0.00000000"],["78614.25000000","0.00000000"],["78612.68000000","0.00000000"],["78610.83000000","0.00000000"],["78609.77000000","0.00000000"],["78609.66000000","0.00000000"],["78608.36000000","0.00000000"],["78605.15000000","0.00000000"],["78603.57000000","0.00000000"],["78586.80000000","0.00000000"],["78586.08000000","0.00000000"],["78581.31000000","0.00000000"],["78579.53000000","0.90710000"],["78564.31000000","0.00000000"],["78539.45000000","0.00406000"],["78462.64000000","0.00779000"],["78455.86000000","0.00007000"],["78410.11000000","0.00000000"],["78336.99000000","0.00000000"],["78322.51000000","0.00026000"],["70779.60000000","0.96157000"],["70777.80000000","0.00000000"],["62912.00000000","0.00000000"]],"a":[["78642.00000000","0.00000000"],["78642.01000000","0.00000000"],["78642.27000000","0.00000000"],["78642.89000000","0.00000000"],["78643.72000000","0.00000000"],["78643.73000000","0.00000000"],["78643.99000000","0.00000000"],["78644.00000000","0.02527000"],["78644.01000000","0.00069000"],["78644.02000000","0.00013000"],["78644.23000000","0.00000000"],["78644.24000000","0.00014000"],["78646.32000000","0.00014000"],["78646.33000000","0.05353000"],["78646.59000000","0.00014000"],["78646.60000000","0.01543000"],["78646.83000000","0.00034000"],["78646.86000000","0.00000000"],["78647.85000000","0.00014000"],["78647.86000000","0.02572000"],["78647.88000000","0.00000000"],["78647.99000000","0.00007000"],["78649.12000000","0.03087000"],["78649.36000000","0.00000000"],["78649.37000000","0.00014000"],["78649.99000000","0.00000000"],["78650.01000000","0.30306000"],["78650.31000000","0.20832000"],["78650.38000000","0.03087000"],["78651.01000000","0.00000000"],["78652.00000000","0.02414000"],["78653.35000000","0.12714000"],["78655.55000000","0.00000000"],["78656.09000000","0.00000000"],["78656.19000000","0.00000000"],["78656.99000000","0.03000000"],["78657.33000000","0.00007000"],["78658.10000000","0.00000000"],["78658.11000000","0.00000000"],["78659.28000000","0.31790000"],["78659.46000000","0.00000000"],["78659.63000000","0.00254000"],["78659.64000000","0.00000000"],["78660.10000000","0.00000000"],["78660.22000000","0.04857000"],["78660.42000000","0.00323000"],["78661.50000000","0.00000000"],["78663.91000000","0.00187000"],["78667.27000000","0.00007000"],["78668.34000000","0.07618000"],["78670.84000000","0.00000000"],["78671.41000000","0.00000000"],["78674.41000000","0.00000000"],["78675.47000000","0.00000000"],["78682.00000000","0.02400000"],["78683.03000000","0.00000000"],["78683.93000000","0.02831000"],["78684.00000000","0.25330000"],["78684.32000000","0.02517000"],["78684.73000000","0.00000000"],["78685.72000000","0.00000000"],["78685.81000000","0.02386000"],["78688.42000000","0.00000000"],["78691.36000000","1.22116000"],["78693.05000000","0.00317000"],["78699.06000000","0.88773000"],["78699.15000000","0.00400000"],["78710.78000000","0.00000000"],["78714.92000000","0.00317000"],["78715.91000000","0.02000000"],["78716.50000000","0.02000000"],["78716.68000000","0.02600000"],["78746.11000000","0.00012000"],["78752.25000000","0.00019000"],["78851.61000000","0.00000000"],["79035.21000000","0.00000000"],["79430.39000000","0.00000000"],["79827.54000000","0.00000000"],["80226.68000000","0.00000000"],["80627.81000000","0.00000000"],["81030.95000000","0.00000000"],["81436.11000000","0.00000000"],["81843.29000000","0.00000000"],["82252.50000000","0.00000000"],["82663.77000000","0.00000000"],["83077.09000000","0.00000000"],["83492.47000000","0.00000000"],["83909.93000000","0.00000000"],["84329.48000000","0.00000000"],["84751.13000000","0.00000000"]]}}}
{"rx_ns": 173327143690600, "frame": {"stream":"btcusdt@depth20@100ms","data":{"lastUpdateId":99076738758,"bids":[["78645.99000000","4.74621000"],["78645.98000000","0.00020000"],["78645.97000000","0.00013000"],["78645.10000000","0.00400000"],["78644.23000000","0.00007000"],["78644.01000000","0.00014000"],["78644.00000000","0.72926000"],["78643.99000000","2.24770000"],["78643.72000000","0.07521000"],["78643.71000000","2.03871000"],["78643.70000000","0.00007000"],["78643.10000000","0.04820000"],["78642.89000000","0.04086000"],["78642.88000000","0.00014000"],["78642.75000000","0.00400000"],["78642.45000000","0.03791000"],["78642.27000000","0.00014000"],["78642.09000000","0.00254000"],["78642.00000000","0.20033000"],["78641.99000000","0.80253000"]],"asks":[["78646.00000000","0.01698000"],["78646.01000000","0.00063000"],["78646.14000000","0.00007000"],["78646.33000000","0.00007000"],["78646.59000000","0.00014000"],["78646.60000000","0.01550000"],["78646.83000000","0.00007000"],["78647.59000000","0.00400000"],["78647.60000000","0.00007000"],["78647.85000000","0.00014000"],["78647.86000000","0.02579000"],["78647.99000000","0.00014000"],["78648.00000000","0.02407000"],["78648.60000000","0.00014000"],["78648.61000000","0.05353000"],["78648.87000000","0.00007000"],["78649.11000000","0.00007000"],["78649.12000000","0.03094000"],["78649.37000000","0.00007000"],["78649.83000000","0.00007000"]]}}}
{"rx_ns": 173327143841300, "frame": {"stream":"btcusdt@depth@100ms","data":{"e":"depthUpdate","E":1787603266314,"s":"BTCUSDT","U":99076738508,"u":99076738758,"b":[["78645.99000000","4.74621000"],["78645.98000000","0.00020000"],["78645.97000000","0.00013000"],["78645.10000000","0.00400000"],["78644.99000000","0.00000000"],["78644.78000000","0.00000000"],["78644.24000000","0.00000000"],["78644.23000000","0.00007000"],["78644.01000000","0.00014000"],["78644.00000000","0.72926000"],["78643.99000000","2.24770000"],["78643.98000000","0.00000000"],["78643.97000000","0.00000000"],["78643.73000000","0.00000000"],["78643.72000000","0.07521000"],["78643.71000000","2.03871000"],["78643.70000000","0.00007000"],["78643.10000000","0.04820000"],["78642.89000000","0.04086000"],["78642.88000000","0.00014000"],["78642.45000000","0.03791000"],["78642.09000000","0.00254000"],["78642.00000000","0.20033000"],["78641.99000000","0.80253000"],["78641.98000000","0.00000000"],["78641.95000000","0.00000000"],["78641.90000000","0.00000000"],["78641.63000000","0.07500000"],["78641.62000000","0.16851000"],["78640.82000000","0.00000000"],["78640.00000000","0.00000000"],["78637.13000000","0.30343000"],["78635.99000000","0.30000000"],["78635.73000000","0.08576000"],["78635.05000000","0.02400000"],["78634.06000000","0.00000000"],["78629.07000000","0.00000000"],["78628.00000000","0.01200000"],["78626.34000000","0.00000000"],["78626.00000000","0.01900000"],["78624.00000000","0.02407000"],["78618.08000000","0.41071000"],["78617.74000000","0.00000000"],["78614.35000000","0.00000000"],["78609.85000000","0.00400000"],["78608.91000000","0.00000000"],["78607.65000000","0.00000000"],["78604.00000000","0.73427000"],["78602.00000000","0.02400000"],["78579.39000000","0.00000000"],["78549.98000000","0.00000000"],["78412.72000000","0.00000000"],["70779.60000000","0.96141000"],["62915.00000000","0.00000000"]],"a":[["78644.00000000","0.00000000"],["78644.01000000","0.00000000"],["78644.02000000","0.00000000"],["78644.24000000","0.00000000"],["78644.79000000","0.00000000"],["78645.99000000","0.00000000"],["78646.00000000","0.01698000"],["78646.01000000","0.00063000"],["78646.32000000","0.00000000"],["78646.33000000","0.00007000"],["78646.60000000","0.01550000"],["78646.83000000","0.00007000"],["78647.86000000","0.02579000"],["78647.99000000","0.00014000"],["78648.00000000","0.02407000"],["78648.60000000","0.00014000"],["78648.61000000","0.05353000"],["78649.11000000","0.00007000"],["78649.12000000","0.03094000"],["78649.37000000","0.00007000"],["78650.31000000","0.20832000"],["78652.00000000","0.02407000"],["78658.31000000","0.00000000"],["78659.05000000","0.00000000"],["78659.63000000","0.00000000"],["78660.22000000","0.00000000"],["78661.88000000","0.04857000"],["78683.93000000","0.00000000"],["78684.00000000","0.24330000"],["78684.84000000","0.00014000"],["78685.81000000","0.00000000"],["78686.00000000","0.03400000"],["78713.04000000","0.02000000"],["78717.31000000","0.00000000"]]}}}
{"rx_ns": 173327238755200, "frame": {"stream":"btcusdt@depth20@100ms","data":{"lastUpdateId":99076738846,"bids":[["78645.99000000","4.76272000"],["78645.98000000","0.00020000"],["78645.97000000","0.00013000"],["78645.10000000","0.00400000"],["78644.96000000","0.00254000"],["78644.23000000","0.00007000"],["78644.01000000","0.00014000"],["78644.00000000","0.72933000"],["78643.99000000","2.23407000"],["78643.72000000","0.07521000"],["78643.71000000","2.01587000"],["78643.10000000","0.04820000"],["78642.89000000","0.04086000"],["78642.88000000","0.00014000"],["78642.75000000","0.00400000"],["78642.45000000","0.00007000"],["78642.27000000","0.00014000"],["78642.09000000","0.00254000"],["78642.00000000","0.20033000"],["78641.99000000","0.79944000"]],"asks":[["78646.00000000","0.01684000"],["78646.01000000","0.00056000"],["78646.14000000","0.00007000"],["78646.60000000","0.00007000"],["78646.83000000","0.00007000"],["78647.59000000","0.00400000"],["78647.60000000","0.00007000"],["78647.86000000","0.00007000"],["78647.99000000","0.00014000"],["78648.00000000","0.02407000"],["78648.60000000","0.00014000"],["78648.61000000","0.05360000"],["78648.87000000","0.00007000"],["78649.12000000","0.00007000"],["78649.37000000","0.00007000"],["78649.83000000","0.00007000"],["78649.99000000","0.00014000"],["78650.00000000","0.02428000"],["78650.01000000","0.30306000"],["78650.30000000","0.00007000"]]}}}
{"rx_ns": 173327238854400, "frame": {"stream":"btcusdt@depth@100ms","data":{"e":"depthUpdate","E":1787603266414,"s":"BTCUSDT","U":99076738759,"u":99076738846,"b":[["78645.99000000","4.76272000"],["78644.96000000","0.00254000"],["78644.00000000","0.72933000"],["78643.99000000","2.23407000"],["78643.71000000","2.01587000"],["78643.70000000","0.00000000"],["78642.45000000","0.00007000"],["78641.99000000","0.79944000"],["78641.19000000","0.00000000"],["78639.93000000","0.00000000"],["78638.18000000","0.02200000"],["78637.10000000","0.30000000"],["78636.17000000","0.00007000"],["78636.00000000","0.00507000"],["78634.00000000","0.01000000"],["78632.00000000","0.01700000"],["78630.00000000","0.11239000"],["78628.00000000","0.01700000"],["78627.98000000","0.00007000"],["78626.00000000","0.02400000"],["78622.41000000","0.14022000"],["78618.55000000","0.13768000"],["78615.50000000","0.00000000"],["78615.14000000","0.02400000"],["78614.13000000","0.00007000"],["78608.94000000","0.00000000"],["78606.00000000","0.03400000"],["78604.00000000","0.72427000"],["78569.63000000","0.00000000"],["78539.45000000","0.00000000"],["78491.02000000","0.00000000"],["78420.27000000","0.00000000"],["78416.68000000","0.00000000"],["70781.40000000","0.00032000"]],"a":[["78646.00000000","0.01684000"],["78646.01000000","0.00056000"],["78646.33000000","0.00000000"],["78646.59000000","0.00000000"],["78646.60000000","0.00007000"],["78647.85000000","0.00000000"],["78647.86000000","0.00007000"],["78648.00000000","0.02407000"],["78648.61000000","0.05360000"],["78649.11000000","0.00000000"],["78649.12000000","0.00007000"],["78649.99000000","0.00014000"],["78650.00000000","0.02428000"],["78650.30000000","0.00007000"],["78650.31000000","0.20839000"],["78650.38000000","0.00000000"],["78653.01000000","0.19676000"],["78658.63000000","0.00000000"],["78660.68000000","0.00254000"],["78684.56000000","0.00000000"],["78686.44000000","0.00000000"],["78699.22000000","0.00000000"],["78709.91000000","0.02000000"],["78730.69000000","0.00000000"],["78758.34000000","0.00031000"],["78777.88000000","0.00000000"],["78848.68000000","0.00000000"]]}}}
{"rx_ns": 173327348958300, "frame": {"stream":"btcusdt@depth20@100ms","data":{"lastUpdateId":99076738903,"bids":[["78645.99000000","4.78542000"],["78645.98000000","0.00020000"],["78645.97000000","0.00013000"],["78645.10000000","0.00400000"],["78644.96000000","0.00254000"],["78644.73000000","0.03784000"],["78644.39000000","0.00007000"],["78644.23000000","0.00007000"],["78644.01000000","0.00014000"],["78644.00000000","0.47049000"],["78643.99000000","1.91643000"],["78643.72000000","0.07521000"],["78643.71000000","2.01594000"],["78643.47000000","0.04541000"],["78643.10000000","0.04820000"],["78642.89000000","0.04079000"],["78642.88000000","0.00014000"],["78642.75000000","0.00400000"],["78642.27000000","0.00014000"],["78642.21000000","0.04541000"]],"asks":[["78646.00000000","0.01698000"],["78646.01000000","0.00056000"],["78646.14000000","0.00007000"],["78646.83000000","0.00007000"],["78647.59000000","0.00400000"],["78647.60000000","0.00007000"],["78647.99000000","0.00014000"],["78648.00000000","0.02407000"],["78648.60000000","0.00014000"],["78648.61000000","0.05360000"],["78648.87000000","0.00021000"],["78648.88000000","0.01543000"],["78649.37000000","0.00007000"],["78649.83000000","0.00007000"],["78649.99000000","0.00014000"],["78650.00000000","0.02428000"],["78650.01000000","0.30306000"],["78650.14000000","0.02572000"],["78650.31000000","0.20839000"],["78650.92000000","0.00007000"]]}}}
{"rx_ns": 173327349091800, "frame": {"stream":"btcusdt@depth@100ms","data":{"e":"depthUpdate","E":1787603266514,"s":"BTCUSDT","U":99076738847,"u":99076738903,"b":[["78645.99000000","4.78542000"],["78644.73000000","0.03784000"],["78644.39000000","0.00007000"],["78644.00000000","0.47049000"],["78643.99000000","1.91643000"],["78643.71000000","2.01594000"],["78643.47000000","0.04541000"],["78642.89000000","0.04079000"],["78642.45000000","0.00000000"],["78642.21000000","0.04541000"],["78641.99000000","0.58014000"],["78639.10000000","0.19252000"],["78638.12000000","0.21930000"],["78634.54000000","0.02000000"],["78630.27000000","0.00007000"],["78618.55000000","0.00000000"],["78612.57000000","0.00000000"],["78557.44000000","0.00000000"],["78486.13000000","0.00977000"],["78462.64000000","0.00000000"],["62917.00000000","0.00000000"],["62916.80000000","0.00031000"]],"a":[["78646.00000000","0.01698000"],["78646.01000000","0.00056000"],["78646.60000000","0.00000000"],["78647.86000000","0.00000000"],["78648.61000000","0.05360000"],["78648.87000000","0.00021000"],["78648.88000000","0.01543000"],["78649.12000000","0.00000000"],["78650.14000000","0.02572000"],["78650.30000000","0.00000000"],["78650.31000000","0.20839000"],["78651.40000000","0.03087000"],["78652.00000000","0.02414000"],["78652.12000000","0.18753000"],["78652.66000000","0.03087000"],["78653.01000000","0.00007000"],["78653.35000000","0.12721000"],["78693.21000000","0.34314000"],["78713.51000000","0.02600000"]]}}}
{"rx_ns": 173327444685700, "frame": {"stream":"btcusdt@depth20@100ms","data":{"lastUpdateId":99076738965,"bids":[["78645.99000000","4.78692000"],["78645.98000000","0.00020000"],["78645.97000000","0.00013000"],["78645.10000000","0.00400000"],["78644.73000000","0.03791000"],["78644.39000000","0.00007000"],["78644.23000000","0.00007000"],["78644.01000000","0.00014000"],["78644.00000000","0.47049000"],["78643.99000000","1.91493000"],["78643.72000000","0.07521000"],["78643.71000000","2.01594000"],["78643.47000000","0.04541000"],["78643.42000000","0.00254000"],["78643.10000000","0.04820000"],["78642.89000000","0.04079000"],["78642.88000000","0.00014000"],["78642.75000000","0.00400000"],["78642.27000000","0.00014000"],["78642.21000000","0.04541000"]],"asks":[["78646.00000000","0.01698000"],["78646.01000000","0.00056000"],["78646.14000000","0.00007000"],["78646.83000000","0.00007000"],["78647.59000000","0.00400000"],["78647.60000000","0.00007000"],["78647.99000000","0.00014000"],["78648.00000000","0.02407000"],["78648.60000000","0.00014000"],["78648.61000000","0.05360000"],["78648.87000000","0.00021000"],["78648.88000000","0.01550000"],["78649.09000000","0.00007000"],["78649.37000000","0.00007000"],["78649.83000000","0.00007000"],["78649.99000000","0.00014000"],["78650.00000000","0.02428000"],["78650.01000000","0.30306000"],["78650.14000000","0.02579000"],["78650.31000000","0.20839000"]]}}}
{"rx_ns": 173327444794000, "frame": {"stream":"btcusdt@depth@100ms","data":{"e":"depthUpdate","E":1787603266614,"s":"BTCUSDT","U":99076738904,"u":99076738965,"b":[["78645.99000000","4.78692000"],["78644.96000000","0.00000000"],["78644.73000000","0.03791000"],["78643.99000000","1.91493000"],["78643.71000000","2.01594000"],["78643.42000000","0.00254000"],["78642.00000000","0.20026000"],["78635.96000000","0.00007000"],["78632.53000000","0.00007000"],["78631.23000000","0.12717000"],["78626.97000000","0.50632000"],["78603.38000000","1.03095000"],["78566.49000000","0.00000000"],["78565.99000000","0.00000000"],["78248.78000000","0.00000000"],["77857.53000000","0.00000000"],["77468.24000000","0.00000000"],["77080.90000000","0.00000000"],["76695.50000000","0.00000000"],["76312.02000000","0.00000000"],["75930.46000000","0.00000000"],["75550.81000000","0.00000000"],["75173.05000000","0.00000000"],["74797.19000000","0.00000000"],["74423.20000000","0.00000000"],["74051.09000000","0.00000000"],["73680.83000000","0.00000000"],["73312.43000000","0.00000000"],["72945.86000000","0.00000000"],["70781.40000000","0.00064000"],["62916.80000000","0.00000000"]],"a":[["78646.00000000","0.01698000"],["78648.61000000","0.05360000"],["78648.88000000","0.01550000"],["78649.09000000","0.00007000"],["78650.01000000","0.30306000"],["78650.14000000","0.02579000"],["78650.31000000","0.20839000"],["78651.40000000","0.03094000"],["78652.00000000","0.02407000"],["78653.01000000","0.00000000"],["78653.35000000","0.12714000"],["78658.21000000","0.00196000"],["78659.14000000","0.00254000"],["78660.68000000","0.00000000"],["78662.67000000","0.12712000"],["78670.53000000","0.12711000"],["78681.82000000","0.00000000"],["78746.11000000","0.00000000"],["78752.25000000","0.00000000"],["78758.34000000","0.00000000"],["78789.42000000","0.00406000"]]}}}
{"rx_ns": 173327555516800, "frame": {"stream":"btcusdt@depth20@100ms","data":{"lastUpdateId":99076739007,"bids":[["78645.99000000","4.79501000"],["78645.98000000","0.00020000"],["78645.97000000","0.00013000"],["78645.10000000","0.00400000"],["78644.73000000","0.03791000"],["78644.39000000","0.00007000"],["78644.23000000","0.00007000"],["78644.01000000","0.00014000"],["78644.00000000","0.07521000"],["78643.99000000","1.91493000"],["78643.72000000","0.07521000"],["78643.71000000","1.81582000"],["78643.47000000","0.04548000"],["78643.10000000","0.04827000"],["78642.89000000","0.04079000"],["78642.88000000","0.00014000"],["78642.75000000","0.00400000"],["78642.27000000","0.00014000"],["78642.21000000","0.04541000"],["78642.09000000","0.00254000"]],"asks":[["78646.00000000","0.01691000"],["78646.01000000","0.00056000"],["78646.14000000","0.00007000"],["78646.83000000","0.00007000"],["78647.59000000","0.00400000"],["78647.60000000","0.00007000"],["78647.99000000","0.00014000"],["78648.00000000","0.02407000"],["78648.60000000","0.00014000"],["78648.61000000","0.05360000"],["78648.87000000","0.00021000"],["78648.88000000","0.01550000"],["78649.09000000","0.00007000"],["78649.37000000","0.00007000"],["78649.99000000","0.00014000"],["78650.00000000","0.02428000"],["78650.01000000","0.30313000"],["78650.14000000","0.02579000"],["78650.31000000","0.00021000"],["78650.92000000","0.00007000"]]}}}
{"rx_ns": 173327555600900, "frame": {"stream":"btcusdt@depth@100ms","data":{"e":"depthUpdate","E":1787603266714,"s":"BTCUSDT","U":99076738966,"u":99076739007,"b":[["78645.99000000","4.79501000"],["78644.00000000","0.07521000"],["78643.71000000","1.81582000"],["78643.47000000","0.04548000"],["78643.42000000","0.00000000"],["78643.10000000","0.04827000"],["78642.06000000","0.00254000"],["78642.00000000","0.00014000"],["78619.00000000","0.70000000"],["78585.00000000","0.00000000"],["78567.77000000","0.02118000"],["70781.40000000","0.00080000"],["70768.79000000","0.00000000"]],"a":[["78646.00000000","0.01691000"],["78646.01000000","0.00056000"],["78649.83000000","0.00000000"],["78650.01000000","0.30313000"],["78650.31000000","0.00021000"],["78651.26000000","0.18203000"],["78652.12000000","0.00000000"],["78657.78000000","0.00254000"],["78657.82000000","0.00291000"],["78657.86000000","0.01455000"],["78659.14000000","0.00000000"],["78674.88000000","0.36224000"],["78688.71000000","0.00000000"],["78750.48000000","0.00012000"],["78756.62000000","0.00019000"]]}}}
{"rx_ns": 173327651877100, "frame": {"stream":"btcusdt@depth20@100ms","data":{"lastUpdateId":99076739018,"bids":[["78645.99000000","4.79501000"],["78645.98000000","0.00020000"],["78645.97000000","0.00013000"],["78645.10000000","0.00400000"],["78644.73000000","0.03791000"],["78644.39000000","0.00007000"],["78644.23000000","0.00007000"],["78644.01000000","0.00014000"],["78644.00000000","0.07521000"],["78643.99000000","1.91493000"],["78643.72000000","0.07521000"],["78643.71000000","1.81582000"],["78643.47000000","0.04548000"],["78643.10000000","0.04827000"],["78642.89000000","0.04079000"],["78642.88000000","0.00014000"],["78642.75000000","0.00400000"],["78642.27000000","0.00014000"],["78642.21000000","0.04541000"],["78642.09000000","0.00254000"]],"asks":[["78646.00000000","0.01691000"],["78646.01000000","0.00056000"],["78646.14000000","0.00007000"],["78646.83000000","0.00007000"],["78647.59000000","0.00400000"],["78647.60000000","0.00007000"],["78647.99000000","0.00014000"],["78648.00000000","0.02407000"],["78648.60000000","0.00014000"],["78648.61000000","0.05360000"],["78648.87000000","0.00021000"],["78648.88000000","0.01550000"],["78649.09000000","0.00007000"],["78649.37000000","0.00007000"],["78649.99000000","0.00014000"],["78650.00000000","0.02428000"],["78650.01000000","0.30313000"],["78650.14000000","0.02579000"],["78650.31000000","0.00014000"],["78650.92000000","0.00007000"]]}}}
{"rx_ns": 173327651976600, "frame": {"stream":"btcusdt@depth@100ms","data":{"e":"depthUpdate","E":1787603266814,"s":"BTCUSDT","U":99076739008,"u":99076739018,"b":[["78567.77000000","0.00000000"],["78503.77000000","0.00406000"],["70781.40000000","0.00096000"]],"a":[["78650.14000000","0.02579000"],["78650.31000000","0.00014000"],["78651.26000000","0.18210000"],["78673.40000000","0.09425000"],["78850.13000000","0.00007000"],["78854.06000000","0.00000000"]]}}}
{"rx_ns": 173327743744600, "frame": {"stream":"btcusdt@depth20@100ms","data":{"lastUpdateId":99076739054,"bids":[["78645.99000000","4.79501000"],["78645.98000000","0.00020000"],["78645.97000000","0.00013000"],["78645.96000000","0.00014000"],["78645.95000000","0.05000000"],["78645.91000000","0.00014000"],["78645.90000000","0.05000000"],["78645.10000000","0.00400000"],["78644.73000000","0.03791000"],["78644.39000000","0.00007000"],["78644.23000000","0.00007000"],["78644.01000000","0.00014000"],["78644.00000000","0.07521000"],["78643.99000000","1.91493000"],["78643.86000000","0.00254000"],["78643.72000000","0.07507000"],["78643.71000000","1.81582000"],["78643.47000000","0.04548000"],["78643.10000000","0.04827000"],["78642.89000000","0.04079000"]],"asks":[["78646.00000000","0.01698000"],["78646.01000000","0.00056000"],["78646.14000000","0.00007000"],["78646.83000000","0.00007000"],["78647.59000000","0.00400000"],["78647.60000000","0.00007000"],["78647.99000000","0.00014000"],["78648.00000000","0.02407000"],["78648.60000000","0.00014000"],["78648.61000000","0.05360000"],["78648.87000000","0.00021000"],["78648.88000000","0.01550000"],["78649.09000000","0.00007000"],["78649.37000000","0.00007000"],["78649.99000000","0.00014000"],["78650.00000000","0.02428000"],["78650.01000000","0.30313000"],["78650.14000000","0.02579000"],["78650.20000000","0.20818000"],["78650.31000000","0.00014000"]]}}}
{"rx_ns": 173327743829800, "frame": {"stream":"btcusdt@depth@100ms","data":{"e":"depthUpdate","E":1787603266914,"s":"BTCUSDT","U":99076739019,"u":99076739054,"b":[["78645.96000000","0.00014000"],["78645.95000000","0.05000000"],["78645.91000000","0.00014000"],["78645.90000000","0.05000000"],["78643.86000000","0.00254000"],["78643.72000000","0.07507000"],["78642.88000000","0.00007000"],["78642.06000000","0.00000000"],["78642.00000000","0.00000000"],["78637.13000000","0.30336000"],["78636.00000000","0.00500000"],["78598.69000000","0.02800000"],["78598.68000000","0.02800000"],["70781.40000000","0.00112000"],["62916.79000000","0.00000000"]],"a":[["78646.00000000","0.01698000"],["78650.01000000","0.30313000"],["78650.20000000","0.20818000"],["78657.78000000","0.00000000"],["78659.58000000","0.00254000"],["78673.40000000","0.00000000"],["78684.76000000","0.00000000"],["78686.00000000","0.73400000"],["78686.64000000","0.00000000"],["78688.71000000","0.00007000"],["78762.71000000","0.00031000"]]}}}
{"rx_ns": 173327838785500, "frame": {"stream":"btcusdt@depth20@100ms","data":{"lastUpdateId":99076739081,"bids":[["78645.99000000","4.79531000"],["78645.98000000","0.00020000"],["78645.97000000","0.00013000"],["78645.96000000","0.00014000"],["78645.95000000","0.05000000"],["78645.91000000","0.00014000"],["78645.90000000","0.05000000"],["78645.10000000","0.00400000"],["78644.73000000","0.03791000"],["78644.39000000","0.00007000"],["78644.23000000","0.00007000"],["78644.01000000","0.00014000"],["78644.00000000","0.07521000"],["78643.99000000","0.00978000"],["78643.86000000","0.00254000"],["78643.72000000","0.07507000"],["78643.71000000","1.81582000"],["78643.47000000","0.04548000"],["78643.10000000","0.04820000"],["78642.89000000","0.04079000"]],"asks":[["78646.00000000","0.01711000"],["78646.01000000","0.00056000"],["78646.14000000","0.00007000"],["78646.83000000","0.00007000"],["78647.59000000","0.00400000"],["78647.60000000","0.00007000"],["78647.99000000","0.00014000"],["78648.00000000","0.02407000"],["78648.60000000","0.00014000"],["78648.61000000","0.05360000"],["78648.87000000","0.00021000"],["78648.88000000","0.01550000"],["78649.09000000","0.00007000"],["78649.37000000","0.00007000"],["78649.99000000","0.00014000"],["78650.00000000","0.02428000"],["78650.01000000","0.30313000"],["78650.14000000","0.02579000"],["78650.20000000","0.20825000"],["78650.31000000","0.00014000"]]}}}
{"rx_ns": 173327838910200, "frame": {"stream":"btcusdt@depth@100ms","data":{"e":"depthUpdate","E":1787603267014,"s":"BTCUSDT","U":99076739055,"u":99076739081,"b":[["78645.99000000","4.79531000"],["78643.99000000","0.00978000"],["78643.10000000","0.04820000"],["78639.11000000","1.90515000"],["78621.71000000","0.00406000"],["78607.94000000","0.00000000"],["78601.60000000","0.09584000"],["78582.09000000","0.02400000"],["70781.40000000","0.00144000"],["62916.80000000","0.00031000"]],"a":[["78646.00000000","0.01711000"],["78650.14000000","0.02579000"],["78650.20000000","0.20825000"],["78651.40000000","0.03087000"],["78659.28000000","0.00000000"],["78659.78000000","0.00007000"],["78659.99000000","0.31926000"],["78673.73000000","0.00000000"],["78675.10000000","0.09672000"],["78684.80000000","0.02733000"],["78686.68000000","0.02432000"],["78710.56000000","0.02000000"]]}}}
{"rx_ns": 173327938504600, "frame": {"stream":"btcusdt@depth20@100ms","data":{"lastUpdateId":99076739094,"bids":[["78645.99000000","4.52413000"],["78645.98000000","0.00020000"],["78645.97000000","0.00013000"],["78645.96000000","0.00014000"],["78645.95000000","0.05000000"],["78645.91000000","0.00014000"],["78645.90000000","0.05000000"],["78645.17000000","0.00007000"],["78645.10000000","0.00400000"],["78644.74000000","0.00014000"],["78644.73000000","0.03791000"],["78644.39000000","0.00007000"],["78644.23000000","0.00007000"],["78644.01000000","0.00014000"],["78644.00000000","0.07507000"],["78643.99000000","0.00978000"],["78643.86000000","0.00254000"],["78643.72000000","0.07507000"],["78643.71000000","1.81582000"],["78643.47000000","0.04548000"]],"asks":[["78646.00000000","0.01711000"],["78646.01000000","0.00056000"],["78646.14000000","0.00007000"],["78646.83000000","0.00007000"],["78647.59000000","0.00400000"],["78647.60000000","0.00007000"],["78647.99000000","0.00014000"],["78648.00000000","0.02407000"],["78648.60000000","0.00014000"],["78648.61000000","0.05360000"],["78648.87000000","0.00021000"],["78648.88000000","0.01550000"],["78649.09000000","0.00007000"],["78649.37000000","0.00007000"],["78649.99000000","0.00014000"],["78650.00000000","0.02428000"],["78650.01000000","0.30313000"],["78650.14000000","0.02579000"],["78650.20000000","0.20825000"],["78650.31000000","0.00014000"]]}}}
{"rx_ns": 173327938699100, "frame": {"stream":"btcusdt@depth@100ms","data":{"e":"depthUpdate","E":1787603267114,"s":"BTCUSDT","U":99076739082,"u":99076739094,"b":[["78645.99000000","4.52413000"],["78645.17000000","0.00007000"],["78644.74000000","0.00014000"],["78644.00000000","0.07507000"],["78637.14000000","0.00000000"],["78637.13000000","0.30329000"],["78637.12000000","0.30000000"],["78581.49000000","0.02200000"],["70781.40000000","0.00128000"]],"a":[["78728.23000000","0.00000000"],["78743.51000000","0.00025000"]]}}}
{"rx_ns": 173328049282700, "frame": {"stream":"btcusdt@depth20@100ms","data":{"lastUpdateId":99076739109,"bids":[["78645.99000000","4.52413000"],["78645.98000000","0.00020000"],["78645.97000000","0.00013000"],["78645.96000000","0.00014000"],["78645.95000000","0.05000000"],["78645.91000000","0.00014000"],["78645.90000000","0.05000000"],["78645.17000000","0.00007000"],["78645.10000000","0.00400000"],["78644.74000000","0.00014000"],["78644.73000000","0.03791000"],["78644.39000000","0.00007000"],["78644.23000000","0.00007000"],["78644.01000000","0.00014000"],["78644.00000000","0.07507000"],["78643.99000000","0.00978000"],["78643.86000000","0.00254000"],["78643.72000000","0.07507000"],["78643.71000000","1.81582000"],["78643.47000000","0.04548000"]],"asks":[["78646.00000000","0.01711000"],["78646.01000000","0.00056000"],["78646.14000000","0.00007000"],["78646.83000000","0.00007000"],["78647.59000000","0.00400000"],["78647.60000000","0.00007000"],["78647.99000000","0.00014000"],["78648.00000000","0.02407000"],["78648.60000000","0.00014000"],["78648.61000000","0.05360000"],["78648.87000000","0.00021000"],["78648.88000000","0.01550000"],["78649.09000000","0.00007000"],["78649.37000000","0.00007000"],["78649.99000000","0.00014000"],["78650.00000000","0.02428000"],["78650.01000000","0.30313000"],["78650.14000000","0.02579000"],["78650.20000000","0.20825000"],["78650.31000000","0.00014000"]]}}}
{"rx_ns": 173328049368900, "frame": {"stream":"btcusdt@depth@100ms","data":{"e":"depthUpdate","E":1787603267214,"s":"BTCUSDT","U":99076739095,"u":99076739109,"b":[["78636.62000000","0.00007000"],["78620.08000000","0.00000000"],["78595.64000000","0.02000000"],["78594.74000000","0.02200000"],["78584.09000000","0.00316000"],["78574.44000000","0.00000000"],["78567.77000000","0.02118000"],["78562.01000000","0.00315000"],["78558.63000000","0.00000000"],["78553.88000000","0.00000000"],["78552.55000000","0.00000000"],["78433.01000000","0.00406000"],["70781.40000000","0.00160000"],["62916.80000000","0.00000000"]],"a":[["78667.27000000","0.00000000"],["78714.92000000","0.00000000"],["78717.99000000","0.00315000"],["78789.93000000","0.00000000"],["78795.99000000","0.00127000"]]}}}
{"rx_ns": 173328142902500, "frame": {"stream":"btcusdt@depth20@100ms","data":{"lastUpdateId":99076739151,"bids":[["78645.99000000","4.52495000"],["78645.98000000","0.00020000"],["78645.97000000","0.00013000"],["78645.96000000","0.00014000"],["78645.95000000","0.05000000"],["78645.91000000","0.00014000"],["78645.90000000","0.05000000"],["78645.17000000","0.00007000"],["78645.10000000","0.00400000"],["78644.74000000","0.00014000"],["78644.73000000","0.03791000"],["78644.39000000","0.00007000"],["78644.23000000","0.00007000"],["78644.01000000","0.00014000"],["78644.00000000","0.07507000"],["78643.99000000","0.00978000"],["78643.86000000","0.00254000"],["78643.72000000","0.07507000"],["78643.71000000","1.81582000"],["78643.47000000","0.04548000"]],"asks":[["78646.00000000","0.01711000"],["78646.01000000","0.00056000"],["78646.14000000","0.00007000"],["78646.83000000","0.00007000"],["78647.59000000","0.00400000"],["78647.60000000","0.00007000"],["78647.99000000","0.00014000"],["78648.00000000","0.02407000"],["78648.60000000","0.00014000"],["78648.61000000","0.05360000"],["78648.87000000","0.00021000"],["78648.88000000","0.01550000"],["78649.09000000","0.00007000"],["78649.37000000","0.00007000"],["78649.99000000","0.00014000"],["78650.00000000","0.02428000"],["78650.01000000","0.30313000"],["78650.14000000","0.02579000"],["78650.20000000","0.20825000"],["78650.31000000","0.00014000"]]}}}
{"rx_ns": 173328142990500, "frame": {"stream":"btcusdt@depth@100ms","data":{"e":"depthUpdate","E":1787603267314,"s":"BTCUSDT","U":99076739110,"u":99076739151,"b":[["78645.99000000","4.52495000"],["78637.99000000","0.00000000"],["78622.36000000","0.00007000"],["78567.77000000","0.00000000"],["78252.76000000","0.01000000"],["77947.32000000","0.00000000"],["77861.49000000","0.01000000"],["77472.18000000","0.01000000"],["77158.88000000","0.01544000"],["77084.82000000","0.01000000"],["76699.40000000","0.01000000"],["76315.90000000","0.01000000"],["75934.32000000","0.01000000"],["75554.65000000","0.01463000"],["75176.88000000","0.01000000"],["74800.99000000","0.01019000"],["74426.99000000","0.01000000"],["74054.85000000","0.01000000"],["73684.58000000","0.01000000"],["73316.16000000","0.01000000"],["72949.57000000","0.01000000"],["70781.40000000","0.00160000"],["70781.00000000","0.00000000"],["62906.00000000","0.00000000"]],"a":[["78669.55000000","0.00007000"],["79039.23000000","0.01000000"],["79434.43000000","0.01000000"],["79831.60000000","0.01011000"],["80230.76000000","0.01015000"],["80631.92000000","0.01000000"],["81035.07000000","0.01000000"],["81440.25000000","0.01000000"],["81847.45000000","0.01000000"],["82256.69000000","0.01000000"],["82667.97000000","0.01000000"],["83081.31000000","0.01000000"],["83496.72000000","0.01000000"],["83914.20000000","0.01008000"],["84333.77000000","0.01000000"],["84755.44000000","0.01000000"]]}}}
{"rx_ns": 173328238420500, "frame": {"stream":"btcusdt@depth20@100ms","data":{"lastUpdateId":99076739157,"bids":[["78645.99000000","4.52495000"],["78645.98000000","0.00020000"],["78645.97000000","0.00013000"],["78645.96000000","0.00014000"],["78645.95000000","0.05000000"],["78645.91000000","0.00014000"],["78645.90000000","0.05000000"],["78645.17000000","0.00007000"],["78645.10000000","0.00400000"],["78644.74000000","0.00014000"],["78644.73000000","0.03791000"],["78644.39000000","0.00007000"],["78644.23000000","0.00007000"],["78644.01000000","0.00014000"],["78644.00000000","0.07507000"],["78643.99000000","0.00978000"],["78643.86000000","0.00254000"],["78643.72000000","0.07507000"],["78643.71000000","1.81582000"],["78643.47000000","0.04548000"]],"asks":[["78646.00000000","0.01711000"],["78646.01000000","0.00056000"],["78646.14000000","0.00007000"],["78646.83000000","0.00007000"],["78647.59000000","0.00400000"],["78647.60000000","0.00007000"],["78647.99000000","0.00014000"],["78648.00000000","0.02407000"],["78648.60000000","0.00014000"],["78648.61000000","0.05360000"],["78648.87000000","0.00021000"],["78648.88000000","0.01550000"],["78649.09000000","0.00007000"],["78649.37000000","0.00007000"],["78649.99000000","0.00014000"],["78650.00000000","0.02428000"],["78650.01000000","0.30313000"],["78650.14000000","0.02579000"],["78650.20000000","0.20825000"],["78650.31000000","0.00014000"]]}}}
{"rx_ns": 173328238549800, "frame": {"stream":"btcusdt@depth@100ms","data":{"e":"depthUpdate","E":1787603267414,"s":"BTCUSDT","U":99076739152,"u":99076739157,"b":[["78558.56000000","0.00000000"],["78556.59000000","0.00000000"],["78554.74000000","0.00000000"],["70781.40000000","0.00160000"]],"a":[["78742.22000000","0.00406000"]]}}}
{"rx_ns": 173328339423700, "frame": {"stream":"btcusdt@depth20@100ms","data":{"lastUpdateId":99076739186,"bids":[["78645.99000000","4.52495000"],["78645.98000000","0.00020000"],["78645.97000000","0.00013000"],["78645.96000000","0.00014000"],["78645.95000000","0.05000000"],["78645.91000000","0.00014000"],["78645.90000000","0.05000000"],["78645.17000000","0.00007000"],["78645.10000000","0.00400000"],["78644.74000000","0.00014000"],["78644.73000000","0.03791000"],["78644.39000000","0.00007000"],["78644.23000000","0.00007000"],["78644.01000000","0.00014000"],["78644.00000000","0.00007000"],["78643.99000000","0.00343000"],["78643.72000000","0.07507000"],["78643.71000000","1.77587000"],["78643.47000000","0.04548000"],["78643.10000000","0.04820000"]],"asks":[["78646.00000000","0.79448000"],["78646.01000000","0.00056000"],["78646.14000000","0.00007000"],["78646.83000000","0.00007000"],["78647.59000000","0.00400000"],["78647.60000000","0.00007000"],["78647.99000000","0.00014000"],["78648.00000000","0.02407000"],["78648.60000000","0.00014000"],["78648.61000000","0.05367000"],["78648.87000000","0.00021000"],["78648.88000000","0.01550000"],["78649.09000000","0.00007000"],["78649.37000000","0.00007000"],["78649.95000000","0.00014000"],["78649.96000000","0.17690000"],["78649.99000000","0.00014000"],["78650.00000000","0.02414000"],["78650.01000000","0.30320000"],["78650.14000000","0.02579000"]]}}}
{"rx_ns": 173328339512500, "frame": {"stream":"btcusdt@depth@100ms","data":{"e":"depthUpdate","E":1787603267514,"s":"BTCUSDT","U":99076739158,"u":99076739186,"b":[["78645.99000000","4.52495000"],["78644.00000000","0.00007000"],["78643.99000000","0.00343000"],["78643.86000000","0.00000000"],["78643.71000000","1.77587000"],["78640.86000000","0.00635000"],["78639.10000000","0.19245000"],["70781.40000000","0.00176000"],["62916.80000000","0.00031000"]],"a":[["78646.00000000","0.79448000"],["78648.61000000","0.05367000"],["78649.95000000","0.00014000"],["78649.96000000","0.17690000"],["78650.00000000","0.02414000"],["78650.01000000","0.30320000"],["78651.26000000","0.00007000"],["78659.58000000","0.00000000"]]}}}
{"rx_ns": 173328440446100, "frame": {"stream":"btcusdt@depth20@100ms","data":{"lastUpdateId":99076739251,"bids":[["78645.99000000","4.51860000"],["78645.98000000","0.00020000"],["78645.97000000","0.00013000"],["78645.96000000","0.00014000"],["78645.95000000","0.05014000"],["78645.91000000","0.00014000"],["78645.90000000","0.05007000"],["78645.17000000","0.00007000"],["78645.10000000","0.00400000"],["78644.74000000","0.00014000"],["78644.73000000","0.03791000"],["78644.39000000","0.00007000"],["78643.99000000","0.00336000"],["78643.72000000","0.00021000"],["78643.71000000","1.77587000"],["78643.47000000","0.04548000"],["78643.11000000","0.00635000"],["78643.10000000","0.04820000"],["78642.91000000","0.00254000"],["78642.89000000","0.04079000"]],"asks":[["78646.00000000","0.79547000"],["78646.01000000","0.00076000"],["78646.02000000","0.00013000"],["78646.14000000","0.00007000"],["78646.83000000","0.00007000"],["78647.18000000","0.00014000"],["78647.19000000","0.22358000"],["78647.59000000","0.00400000"],["78647.60000000","0.00007000"],["78647.99000000","0.00014000"],["78648.00000000","0.02407000"],["78648.60000000","0.00014000"],["78648.61000000","0.05367000"],["78648.87000000","0.00021000"],["78648.88000000","0.01550000"],["78649.09000000","0.00007000"],["78649.37000000","0.00007000"],["78649.94000000","0.00007000"],["78649.95000000","0.02161000"],["78649.96000000","0.00007000"]]}}}
{"rx_ns": 173328440539600, "frame": {"stream":"btcusdt@depth@100ms","data":{"e":"depthUpdate","E":1787603267614,"s":"BTCUSDT","U":99076739187,"u":99076739251,"b":[["78645.99000000","4.51860000"],["78645.95000000","0.05014000"],["78645.90000000","0.05007000"],["78644.73000000","0.03791000"],["78644.23000000","0.00000000"],["78644.01000000","0.00000000"],["78644.00000000","0.00000000"],["78643.99000000","0.00336000"],["78643.73000000","0.00000000"],["78643.72000000","0.00021000"],["78643.11000000","0.00635000"],["78642.91000000","0.00254000"],["78641.62000000","0.08861000"],["78630.48000000","0.00007000"],["78000.00000000","21.10188000"],["70781.40000000","0.00192000"],["62916.80000000","0.00000000"],["62000.00000000","98.92249000"]],"a":[["78646.00000000","0.79547000"],["78646.01000000","0.00076000"],["78646.02000000","0.00013000"],["78647.18000000","0.00014000"],["78647.19000000","0.22358000"],["78648.88000000","0.01550000"],["78649.94000000","0.00007000"],["78649.95000000","0.02161000"],["78649.96000000","0.00007000"],["78649.99000000","0.00007000"],["78650.20000000","0.20825000"],["78650.31000000","0.00007000"],["78651.26000000","0.00000000"],["78658.63000000","0.00254000"],["78665.68000000","0.00007000"],["78671.41000000","0.00406000"]]}}}
{"rx_ns": 173328550342700, "frame": {"stream":"btcusdt@depth20@100ms","data":{"lastUpdateId":99076739274,"bids":[["78645.99000000","4.51860000"],["78645.98000000","0.00020000"],["78645.97000000","0.00013000"],["78645.96000000","0.00014000"],["78645.95000000","0.05014000"],["78645.91000000","0.00014000"],["78645.90000000","0.05007000"],["78645.17000000","0.00007000"],["78645.10000000","0.00400000"],["78644.74000000","0.00014000"],["78644.73000000","0.03791000"],["78644.39000000","0.00007000"],["78643.99000000","0.00336000"],["78643.72000000","0.00014000"],["78643.71000000","1.77587000"],["78643.47000000","0.04548000"],["78643.11000000","0.00642000"],["78643.10000000","0.04820000"],["78642.91000000","0.00254000"],["78642.89000000","0.04079000"]],"asks":[["78646.00000000","0.79367000"],["78646.01000000","0.00076000"],["78646.02000000","0.00013000"],["78646.14000000","0.00007000"],["78646.83000000","0.00007000"],["78647.18000000","0.00014000"],["78647.19000000","0.22365000"],["78647.59000000","0.00400000"],["78647.60000000","0.00007000"],["78647.99000000","0.00014000"],["78648.00000000","0.02407000"],["78648.31000000","0.00007000"],["78648.60000000","0.00014000"],["78648.61000000","0.05360000"],["78648.87000000","0.00021000"],["78648.88000000","0.01550000"],["78649.09000000","0.00007000"],["78649.37000000","0.00007000"],["78649.94000000","0.00007000"],["78649.95000000","0.02168000"]]}}}
{"rx_ns": 173328550426100, "frame": {"stream":"btcusdt@depth@100ms","data":{"e":"depthUpdate","E":1787603267714,"s":"BTCUSDT","U":99076739252,"u":99076739274,"b":[["78644.73000000","0.03791000"],["78643.72000000","0.00014000"],["78643.47000000","0.04548000"],["78643.11000000","0.00642000"],["70781.40000000","0.00208000"]],"a":[["78646.00000000","0.79367000"],["78647.19000000","0.22365000"],["78648.31000000","0.00007000"],["78648.61000000","0.05360000"],["78648.88000000","0.01550000"],["78649.95000000","0.02168000"],["78649.96000000","0.00000000"],["78650.20000000","0.20818000"],["78743.69000000","0.93649000"]]}}}
{"rx_ns": 173328638831000, "frame": {"stream":"btcusdt@depth20@100ms","data":{"lastUpdateId":99076739309,"bids":[["78645.99000000","4.51847000"],["78645.98000000","0.00020000"],["78645.97000000","0.00013000"],["78645.96000000","0.00014000"],["78645.95000000","0.05014000"],["78645.91000000","0.00014000"],["78645.90000000","0.05007000"],["78645.17000000","0.00007000"],["78645.10000000","0.00400000"],["78644.74000000","0.00014000"],["78644.73000000","0.03791000"],["78644.39000000","0.00007000"],["78643.99000000","0.00336000"],["78643.72000000","0.00014000"],["78643.71000000","1.77587000"],["78643.47000000","0.04548000"],["78643.11000000","0.00642000"],["78643.10000000","0.04820000"],["78642.91000000","0.00254000"],["78642.89000000","0.04079000"]],"asks":[["78646.00000000","0.79367000"],["78646.01000000","0.00076000"],["78646.02000000","0.00013000"],["78646.14000000","0.00007000"],["78646.83000000","0.00007000"],["78647.18000000","0.00014000"],["78647.19000000","0.22365000"],["78647.59000000","0.00400000"],["78647.60000000","0.00007000"],["78647.99000000","0.00014000"],["78648.00000000","0.02407000"],["78648.31000000","0.00007000"],["78648.60000000","0.00014000"],["78648.61000000","0.05360000"],["78648.87000000","0.00021000"],["78648.88000000","0.01550000"],["78649.09000000","0.00007000"],["78649.37000000","0.00007000"],["78649.94000000","0.00007000"],["78649.95000000","0.02168000"]]}}}
{"rx_ns": 173328638913700, "frame": {"stream":"btcusdt@depth@100ms","data":{"e":"depthUpdate","E":1787603267814,"s":"BTCUSDT","U":99076739275,"u":99076739309,"b":[["78645.99000000","4.51847000"],["78486.13000000","0.00198000"],["78480.71000000","0.00779000"],["78252.76000000","0.00000000"],["77861.49000000","0.00000000"],["77472.18000000","0.00000000"],["77084.82000000","0.00000000"],["76699.40000000","0.00000000"],["76315.90000000","0.00000000"],["75934.32000000","0.00000000"],["75554.65000000","0.00463000"],["75176.88000000","0.00000000"],["74800.99000000","0.00019000"],["74426.99000000","0.00000000"],["74054.85000000","0.00000000"],["73684.58000000","0.00000000"],["73316.16000000","0.00000000"],["72949.57000000","0.00000000"]],"a":[["78682.80000000","0.00400000"],["78699.15000000","0.00000000"],["78860.23000000","0.00406000"],["79039.23000000","0.00000000"],["79434.43000000","0.00000000"],["79831.60000000","0.00011000"],["80230.76000000","0.00015000"],["80631.92000000","0.00000000"],["81035.07000000","0.00000000"],["81440.25000000","0.00000000"],["81847.45000000","0.00000000"],["82256.69000000","0.00000000"],["82667.97000000","0.00000000"],["83081.31000000","0.00000000"],["83496.72000000","0.00000000"],["83914.20000000","0.00008000"],["84333.77000000","0.00000000"],["84755.44000000","0.00000000"]]}}}
{"rx_ns": 173328748615900, "frame": {"stream":"btcusdt@depth20@100ms","data":{"lastUpdateId":99076739592,"bids":[["78646.01000000","4.47528000"],["78646.00000000","2.03035000"],["78645.99000000","0.31694000"],["78645.95000000","0.05014000"],["78645.90000000","0.00007000"],["78645.17000000","0.00007000"],["78645.10000000","0.00400000"],["78644.73000000","0.03791000"],["78644.39000000","0.00007000"],["78643.99000000","0.00336000"],["78643.85000000","0.00027000"],["78643.72000000","0.00014000"],["78643.71000000","1.77587000"],["78643.47000000","0.04548000"],["78643.11000000","0.00007000"],["78643.10000000","0.04827000"],["78642.89000000","0.04079000"],["78642.88000000","0.00007000"],["78642.75000000","0.00400000"],["78642.31000000","0.38152000"]],"asks":[["78646.02000000","0.00197000"],["78646.03000000","0.00056000"],["78646.14000000","0.00007000"],["78646.83000000","0.00007000"],["78647.19000000","0.00007000"],["78647.60000000","0.00007000"],["78647.99000000","0.00014000"],["78648.00000000","0.02407000"],["78648.31000000","0.00007000"],["78648.60000000","0.00014000"],["78648.61000000","0.05360000"],["78648.87000000","0.00021000"],["78648.88000000","0.01550000"],["78649.09000000","0.00007000"],["78649.37000000","0.00007000"],["78649.95000000","0.00007000"],["78649.99000000","0.00014000"],["78650.00000000","0.02414000"],["78650.01000000","0.00028000"],["78650.14000000","0.02579000"]]}}}
{"rx_ns": 173328748696900, "frame": {"stream":"btcusdt@depth@100ms","data":{"e":"depthUpdate","E":1787603267914,"s":"BTCUSDT","U":99076739310,"u":99076739592,"b":[["78646.01000000","4.47528000"],["78646.00000000","2.03035000"],["78645.99000000","0.31694000"],["78645.98000000","0.00000000"],["78645.97000000","0.00000000"],["78645.96000000","0.00000000"],["78645.91000000","0.00000000"],["78645.90000000","0.00007000"],["78645.13000000","0.00000000"],["78644.74000000","0.00000000"],["78643.99000000","0.00336000"],["78643.85000000","0.00027000"],["78643.11000000","0.00007000"],["78643.10000000","0.04827000"],["78642.91000000","0.00000000"],["78642.31000000","0.38152000"],["78642.00000000","0.00000000"],["78641.99000000","0.30014000"],["78641.75000000","0.30400000"],["78641.63000000","0.37500000"],["78641.62000000","0.38861000"],["78640.86000000","0.00000000"],["78639.47000000","0.12716000"],["78637.12000000","0.00000000"],["78637.10000000","0.00000000"],["78635.99000000","0.00000000"],["78631.99000000","0.00000000"],["78631.23000000","0.00000000"],["78631.11000000","0.34341000"],["78624.78000000","0.34344000"],["78623.61000000","0.34345000"],["78622.41000000","0.14022000"],["78601.60000000","0.00008000"],["78587.32000000","0.00000000"],["78567.77000000","0.02118000"],["78519.94000000","0.00000000"],["70781.40000000","0.00009000"],["62916.79000000","0.00000000"]],"a":[["78646.00000000","0.00000000"],["78646.01000000","0.00000000"],["78646.02000000","0.00197000"],["78646.03000000","0.00056000"],["78647.18000000","0.00000000"],["78647.19000000","0.00007000"],["78647.59000000","0.00000000"],["78649.94000000","0.00000000"],["78649.95000000","0.00007000"],["78649.99000000","0.00014000"],["78650.00000000","0.02414000"],["78650.01000000","0.00028000"],["78650.20000000","0.00007000"],["78653.88000000","0.00007000"],["78654.28000000","0.00000000"],["78654.38000000","0.20818000"],["78656.79000000","0.00000000"],["78656.98000000","0.00000000"],["78656.99000000","0.00000000"],["78657.82000000","0.00000000"],["78657.86000000","0.00000000"],["78657.88000000","0.00000000"],["78658.15000000","0.00254000"],["78658.20000000","0.00254000"],["78658.63000000","0.00000000"],["78659.29000000","0.00000000"],["78659.31000000","0.00000000"],["78659.39000000","0.00000000"],["78660.42000000","0.00000000"],["78660.85000000","0.00000000"],["78660.91000000","0.00635000"],["78660.93000000","0.00000000"],["78661.39000000","0.00000000"],["78661.70000000","0.00000000"],["78661.98000000","0.00000000"],["78662.88000000","0.00000000"],["78663.70000000","0.15000000"],["78664.56000000","0.00635000"],["78667.34000000","0.00000000"],["78668.32000000","0.02000000"],["78669.61000000","1.21952000"],["78669.62000000","0.00000000"],["78672.89000000","0.00000000"],["78674.88000000","0.00000000"],["78674.89000000","0.00000000"],["78677.66000000","0.00000000"],["78684.80000000","0.00000000"],["78685.41000000","0.02831000"],["78686.68000000","0.00000000"],["78687.07000000","0.00000000"],["78690.20000000","0.02161000"],["78691.90000000","0.63546000"],["78692.58000000","0.00007000"],["78694.30000000","0.00000000"],["78694.71000000","0.34314000"],["78720.54000000","0.00000000"],["78727.13000000","1.25766000"],["78739.35000000","1.21952000"],["78749.33000000","1.90515000"],["78751.24000000","0.21930000"],["78759.30000000","1.90515000"]]}}}
