{"rx_ns": 10697753358800, "frame": {"stream":"btcusdt@depth20@100ms","data":{"lastUpdateId":99116120543,"bids":[["79983.99000000","5.86964000"],["79983.98000000","0.80083000"],["79983.97000000","0.00013000"],["79983.51000000","0.00014000"],["79983.50000000","1.47185000"],["79983.49000000","0.19365000"],["79983.10000000","0.00400000"],["79982.81000000","0.00007000"],["79982.71000000","0.01688000"],["79982.29000000","0.00014000"],["79982.28000000","0.20648000"],["79982.00000000","0.00007000"],["79981.99000000","0.39428000"],["79981.94000000","0.00007000"],["79981.77000000","0.00008000"],["79981.54000000","0.00007000"],["79981.51000000","0.21906000"],["79981.43000000","0.02023000"],["79981.29000000","0.00014000"],["79981.06000000","0.00014000"]],"asks":[["79984.00000000","1.08390000"],["79984.01000000","0.00097000"],["79984.02000000","0.00013000"],["79984.27000000","0.00007000"],["79984.61000000","0.00007000"],["79985.16000000","0.00014000"],["79985.50000000","0.00884000"],["79985.94000000","0.00007000"],["79985.99000000","0.00014000"],["79986.00000000","0.02421000"],["79986.20000000","0.00007000"],["79986.28000000","0.00014000"],["79986.29000000","0.03050000"],["79986.63000000","0.00014000"],["79986.64000000","0.05309000"],["79986.77000000","0.00014000"],["79986.78000000","0.01465000"],["79986.95000000","0.00007000"],["79987.24000000","0.00007000"],["79987.99000000","0.00007000"]]}}}
{"rx_ns": 10697753503400, "frame": {"stream":"btcusdt@depth@100ms","data":{"e":"depthUpdate","E":1787647692914,"s":"BTCUSDT","U":99116120531,"u":99116120543,"b":[["79983.99000000","5.86964000"],["79956.00000000","0.72400000"],["79909.94000000","0.00000000"],["79909.14000000","0.00008000"],["79848.30000000","0.00018000"],["79844.38000000","0.00399000"],["71985.60000000","0.00240000"],["71985.00000000","0.00000000"]],"a":[["79991.59000000","0.05482000"],["79995.46000000","0.00000000"],["79996.52000000","0.00400000"]]}}}
{"rx_ns": 10697852711900, "frame": {"stream":"btcusdt@depth20@100ms","data":{"lastUpdateId":99116120569,"bids":[["79983.99000000","5.86964000"],["79983.98000000","0.80083000"],["79983.97000000","0.00013000"],["79983.51000000","0.00014000"],["79983.50000000","1.47185000"],["79983.49000000","0.19365000"],["79983.10000000","0.00400000"],["79982.81000000","0.00007000"],["79982.71000000","0.01688000"],["79982.29000000","0.00014000"],["79982.28000000","0.20648000"],["79982.00000000","0.00007000"],["79981.99000000","0.39428000"],["79981.94000000","0.00007000"],["79981.77000000","0.00008000"],["79981.54000000","0.00007000"],["79981.51000000","0.21906000"],["79981.43000000","0.02023000"],["79981.29000000","0.00014000"],["79981.06000000","0.00014000"]],"asks":[["79984.00000000","1.29332000"],["79984.01000000","0.00090000"],["79984.02000000","0.00013000"],["79984.27000000","0.00007000"],["79984.61000000","0.00007000"],["79985.16000000","0.00014000"],["79985.50000000","0.00884000"],["79985.94000000","0.00007000"],["79985.99000000","0.00014000"],["79986.00000000","0.02421000"],["79986.20000000","0.00007000"],["79986.28000000","0.00014000"],["79986.29000000","0.03050000"],["79986.63000000","0.00014000"],["79986.64000000","0.05309000"],["79986.77000000","0.00014000"],["79986.78000000","0.01465000"],["79986.95000000","0.00007000"],["79987.24000000","0.00007000"],["79987.99000000","0.00007000"]]}}}
{"rx_ns": 10697852806500, "frame": {"stream":"btcusdt@depth@100ms","data":{"e":"depthUpdate","E":1787647693014,"s":"BTCUSDT","U":99116120544,"u":99116120569,"b":[["79982.28000000","0.20648000"],["79982.05000000","0.00000000"],["79912.13000000","0.00000000"],["79906.55000000","0.00000000"],["79821.19000000","0.00000000"],["78784.23000000","0.00030000"],["71985.60000000","0.00256000"],["63987.20000000","0.00031000"]],"a":[["79984.00000000","1.29332000"],["79984.01000000","0.00090000"],["79988.06000000","0.01769000"],["79989.01000000","0.04557000"],["79990.00000000","0.02421000"],["79991.59000000","0.00000000"],["79992.65000000","0.00578000"]]}}}
{"rx_ns": 10697959140300, "frame": {"stream":"btcusdt@depth20@100ms","data":{"lastUpdateId":99116120595,"bids":[["79983.99000000","5.86964000"],["79983.98000000","0.80083000"],["79983.97000000","0.00013000"],["79983.51000000","0.00014000"],["79983.50000000","1.47185000"],["79983.49000000","0.19365000"],["79983.10000000","0.00400000"],["79982.81000000","0.00007000"],["79982.71000000","0.01688000"],["79982.29000000","0.00014000"],["79982.28000000","0.20648000"],["79982.00000000","0.00007000"],["79981.99000000","0.39428000"],["79981.94000000","0.00007000"],["79981.77000000","0.00008000"],["79981.54000000","0.00007000"],["79981.51000000","0.21906000"],["79981.43000000","0.02023000"],["79981.29000000","0.00014000"],["79981.06000000","0.00014000"]],"asks":[["79984.00000000","1.08445000"],["79984.01000000","0.00090000"],["79984.02000000","0.00013000"],["79984.27000000","0.00007000"],["79984.61000000","0.00007000"],["79985.16000000","0.00014000"],["79985.50000000","0.00884000"],["79985.94000000","0.00007000"],["79985.99000000","0.00014000"],["79986.00000000","0.02421000"],["79986.20000000","0.00007000"],["79986.28000000","0.00014000"],["79986.29000000","0.03050000"],["79986.63000000","0.00014000"],["79986.64000000","0.05309000"],["79986.77000000","0.00014000"],["79986.78000000","0.01465000"],["79986.95000000","0.00007000"],["79987.24000000","0.00007000"],["79987.99000000","0.00007000"]]}}}
{"rx_ns": 10697959243300, "frame": {"stream":"btcusdt@depth@100ms","data":{"e":"depthUpdate","E":1787647693114,"s":"BTCUSDT","U":99116120570,"u":99116120595,"b":[["79968.75000000","0.00007000"],["79912.13000000","0.00312000"],["79911.66000000","0.90939000"],["79910.49000000","0.00000000"],["79901.63000000","0.00000000"],["79899.61000000","0.62495000"],["79896.97000000","0.00000000"],["79883.22000000","0.00025000"],["79882.73000000","0.00000000"],["79830.33000000","0.00125000"]],"a":[["79984.00000000","1.08445000"],["79988.06000000","0.01769000"],["79989.01000000","0.04571000"],["79989.34000000","0.01762000"],["80000.75000000","0.00007000"],["80082.68000000","0.00000000"],["80083.18000000","0.12248000"],["80206.59000000","0.00399000"]]}}}
{"rx_ns": 10698053751600, "frame": {"stream":"btcusdt@depth20@100ms","data":{"lastUpdateId":99116120609,"bids":[["79983.99000000","5.86971000"],["79983.98000000","0.80083000"],["79983.97000000","0.00013000"],["79983.51000000","0.00014000"],["79983.50000000","1.47185000"],["79983.49000000","0.19365000"],["79983.10000000","0.00400000"],["79982.81000000","0.00007000"],["79982.71000000","0.01688000"],["79982.29000000","0.00014000"],["79982.28000000","0.20648000"],["79982.00000000","0.00007000"],["79981.99000000","0.39428000"],["79981.94000000","0.00007000"],["79981.77000000","0.00008000"],["79981.54000000","0.00007000"],["79981.51000000","0.21906000"],["79981.43000000","0.02023000"],["79981.29000000","0.00014000"],["79981.06000000","0.00014000"]],"asks":[["79984.00000000","1.08295000"],["79984.01000000","0.00090000"],["79984.02000000","0.00013000"],["79984.27000000","0.00007000"],["79984.61000000","0.00007000"],["79985.16000000","0.00014000"],["79985.50000000","0.00884000"],["79985.94000000","0.00007000"],["79985.99000000","0.00014000"],["79986.00000000","0.02421000"],["79986.20000000","0.00007000"],["79986.28000000","0.00014000"],["79986.29000000","0.03050000"],["79986.63000000","0.00014000"],["79986.64000000","0.05309000"],["79986.77000000","0.00014000"],["79986.78000000","0.01465000"],["79986.95000000","0.00007000"],["79987.24000000","0.00007000"],["79987.99000000","0.00007000"]]}}}
{"rx_ns": 10698053879500, "frame": {"stream":"btcusdt@depth@100ms","data":{"e":"depthUpdate","E":1787647693214,"s":"BTCUSDT","U":99116120596,"u":99116120609,"b":[["79983.99000000","5.86971000"],["79902.53000000","0.00000000"],["71985.60000000","0.00272000"],["63987.20000000","0.00000000"],["63987.19000000","0.00020000"]],"a":[["79984.00000000","1.08295000"],["81183.76000000","0.00030000"]]}}}
{"rx_ns": 10698158465500, "frame": {"stream":"btcusdt@depth20@100ms","data":{"lastUpdateId":99116120625,"bids":[["79983.99000000","5.86971000"],["79983.98000000","0.80083000"],["79983.97000000","0.00013000"],["79983.51000000","0.00014000"],["79983.50000000","1.47185000"],["79983.49000000","0.19365000"],["79983.10000000","0.00400000"],["79982.81000000","0.00007000"],["79982.71000000","0.01688000"],["79982.29000000","0.00014000"],["79982.28000000","0.20648000"],["79982.00000000","0.00007000"],["79981.99000000","0.39428000"],["79981.94000000","0.00007000"],["79981.77000000","0.00008000"],["79981.54000000","0.00007000"],["79981.51000000","0.21906000"],["79981.43000000","0.02023000"],["79981.29000000","0.00014000"],["79981.06000000","0.00014000"]],"asks":[["79984.00000000","1.08288000"],["79984.01000000","0.00090000"],["79984.02000000","0.00013000"],["79984.27000000","0.00007000"],["79984.61000000","0.00007000"],["79985.16000000","0.00014000"],["79985.50000000","0.00884000"],["79985.94000000","0.00007000"],["79985.99000000","0.00014000"],["79986.00000000","0.02421000"],["79986.20000000","0.00007000"],["79986.28000000","0.00014000"],["79986.29000000","0.03050000"],["79986.63000000","0.00014000"],["79986.64000000","0.05309000"],["79986.77000000","0.00014000"],["79986.78000000","0.01465000"],["79986.95000000","0.00007000"],["79987.24000000","0.00007000"],["79987.99000000","0.00007000"]]}}}
{"rx_ns": 10698158712500, "frame": {"stream":"btcusdt@depth@100ms","data":{"e":"depthUpdate","E":1787647693314,"s":"BTCUSDT","U":99116120610,"u":99116120625,"b":[["79964.33000000","0.00399000"],["79910.11000000","0.02084000"],["79862.96000000","0.18261000"],["71985.60000000","0.00288000"],["63987.19000000","0.00000000"],["63987.00000000","0.00000000"]],"a":[["79984.00000000","1.08288000"],["79989.01000000","0.00014000"],["80013.26000000","1.00757000"],["80068.60000000","2.13553000"],["80093.94000000","0.05287000"],["80134.24000000","1.57435000"],["81180.00000000","0.03047000"]]}}}
{"rx_ns": 10698252497600, "frame": {"stream":"btcusdt@depth20@100ms","data":{"lastUpdateId":99116120646,"bids":[["79983.99000000","5.86971000"],["79983.98000000","0.80083000"],["79983.97000000","0.00013000"],["79983.51000000","0.00014000"],["79983.50000000","1.47185000"],["79983.49000000","0.19365000"],["79983.10000000","0.00400000"],["79982.81000000","0.00007000"],["79982.71000000","0.01688000"],["79982.29000000","0.00014000"],["79982.28000000","0.20648000"],["79982.00000000","0.00007000"],["79981.99000000","0.39428000"],["79981.94000000","0.00007000"],["79981.77000000","0.00008000"],["79981.54000000","0.00007000"],["79981.51000000","0.21906000"],["79981.43000000","0.02023000"],["79981.29000000","0.00014000"],["79981.06000000","0.00014000"]],"asks":[["79984.00000000","1.07500000"],["79984.01000000","0.00090000"],["79984.02000000","0.00013000"],["79984.27000000","0.00007000"],["79984.61000000","0.00007000"],["79985.16000000","0.00014000"],["79985.50000000","0.00884000"],["79985.94000000","0.00007000"],["79985.99000000","0.00014000"],["79986.00000000","0.02421000"],["79986.20000000","0.00007000"],["79986.28000000","0.00014000"],["79986.29000000","0.03050000"],["79986.63000000","0.00014000"],["79986.64000000","0.05309000"],["79986.77000000","0.00014000"],["79986.78000000","0.01465000"],["79986.95000000","0.00007000"],["79987.24000000","0.00007000"],["79987.99000000","0.00007000"]]}}}
{"rx_ns": 10698252598200, "frame": {"stream":"btcusdt@depth@100ms","data":{"e":"depthUpdate","E":1787647693414,"s":"BTCUSDT","U":99116120626,"u":99116120646,"b":[["79974.00000000","0.01700000"],["79972.00000000","0.01700000"],["79970.00000000","0.11079000"],["79910.11000000","0.00000000"],["79792.15000000","0.00000000"],["79327.62000000","0.01513000"],["78990.79000000","0.00000000"],["71985.60000000","0.00272000"],["42091.80000000","0.00000000"]],"a":[["79984.00000000","1.07500000"],["79988.06000000","0.01762000"],["79989.01000000","0.00000000"],["79989.34000000","0.01776000"],["80120.00000000","0.02462000"],["80161.36000000","0.00000000"]]}}}
{"rx_ns": 10698355818200, "frame": {"stream":"btcusdt@depth20@100ms","data":{"lastUpdateId":99116120653,"bids":[["79983.99000000","5.86971000"],["79983.98000000","0.80083000"],["79983.97000000","0.00013000"],["79983.51000000","0.00014000"],["79983.50000000","1.47185000"],["79983.49000000","0.19365000"],["79983.10000000","0.00400000"],["79982.81000000","0.00007000"],["79982.71000000","0.01688000"],["79982.29000000","0.00014000"],["79982.28000000","0.20648000"],["79982.05000000","0.00591000"],["79982.00000000","0.00007000"],["79981.99000000","0.39428000"],["79981.94000000","0.00007000"],["79981.77000000","0.00008000"],["79981.54000000","0.00007000"],["79981.51000000","0.21906000"],["79981.43000000","0.02023000"],["79981.29000000","0.00014000"]],"asks":[["79984.00000000","1.07500000"],["79984.01000000","0.00090000"],["79984.02000000","0.00013000"],["79984.27000000","0.00007000"],["79984.61000000","0.00007000"],["79985.16000000","0.00014000"],["79985.50000000","0.00884000"],["79985.94000000","0.00007000"],["79985.99000000","0.00014000"],["79986.00000000","0.02421000"],["79986.20000000","0.00007000"],["79986.28000000","0.00014000"],["79986.29000000","0.03050000"],["79986.63000000","0.00014000"],["79986.64000000","0.05309000"],["79986.77000000","0.00014000"],["79986.78000000","0.01465000"],["79986.95000000","0.00007000"],["79987.24000000","0.00007000"],["79987.99000000","0.00007000"]]}}}
{"rx_ns": 10698355902300, "frame": {"stream":"btcusdt@depth@100ms","data":{"e":"depthUpdate","E":1787647693514,"s":"BTCUSDT","U":99116120647,"u":99116120653,"b":[["79982.05000000","0.00591000"],["71985.60000000","0.00304000"],["63987.20000000","0.00031000"]],"a":[["79990.97000000","0.05792000"],["80014.55000000","0.00399000"],["80100.00000000","0.02452000"]]}}}
{"rx_ns": 10698452010300, "frame": {"stream":"btcusdt@depth20@100ms","data":{"lastUpdateId":99116120671,"bids":[["79983.99000000","5.86971000"],["79983.98000000","0.80083000"],["79983.97000000","0.00013000"],["79983.51000000","0.00014000"],["79983.50000000","1.47185000"],["79983.49000000","0.19365000"],["79983.10000000","0.00400000"],["79982.81000000","0.00007000"],["79982.71000000","0.01688000"],["79982.29000000","0.00014000"],["79982.28000000","0.20655000"],["79982.05000000","0.00605000"],["79982.00000000","0.00007000"],["79981.99000000","0.39428000"],["79981.94000000","0.00007000"],["79981.77000000","0.00008000"],["79981.54000000","0.00007000"],["79981.51000000","0.21906000"],["79981.43000000","0.02009000"],["79981.29000000","0.00014000"]],"asks":[["79984.00000000","1.07474000"],["79984.01000000","0.00090000"],["79984.02000000","0.00013000"],["79984.27000000","0.00007000"],["79984.61000000","0.00007000"],["79985.16000000","0.00014000"],["79985.50000000","0.00884000"],["79985.94000000","0.00007000"],["79985.99000000","0.00014000"],["79986.00000000","0.02421000"],["79986.20000000","0.00007000"],["79986.28000000","0.00014000"],["79986.29000000","0.03050000"],["79986.63000000","0.00014000"],["79986.64000000","0.05309000"],["79986.77000000","0.00014000"],["79986.78000000","0.01465000"],["79986.95000000","0.00007000"],["79987.24000000","0.00007000"],["79987.99000000","0.00007000"]]}}}
{"rx_ns": 10698452121700, "frame": {"stream":"btcusdt@depth@100ms","data":{"e":"depthUpdate","E":1787647693614,"s":"BTCUSDT","U":99116120654,"u":99116120671,"b":[["79982.28000000","0.20655000"],["79982.05000000","0.00605000"],["79981.43000000","0.02009000"],["79910.11000000","0.02084000"],["79803.55000000","4.55944000"],["71985.60000000","0.00304000"],["63987.20000000","0.00000000"]],"a":[["79984.00000000","1.07474000"],["79990.00000000","0.02428000"],["80005.00000000","0.70000000"],["80172.40000000","4.45080000"]]}}}
{"rx_ns": 10698552509700, "frame": {"stream":"btcusdt@depth20@100ms","data":{"lastUpdateId":99116120695,"bids":[["79983.99000000","5.87055000"],["79983.98000000","0.80125000"],["79983.97000000","0.00013000"],["79983.51000000","0.00014000"],["79983.50000000","1.47185000"],["79983.49000000","0.19365000"],["79983.10000000","0.00400000"],["79982.81000000","0.00007000"],["79982.71000000","0.01688000"],["79982.29000000","0.00014000"],["79982.28000000","0.20655000"],["79982.05000000","0.00605000"],["79982.00000000","0.00007000"],["79981.99000000","0.39428000"],["79981.94000000","0.00007000"],["79981.77000000","0.00008000"],["79981.54000000","0.00007000"],["79981.51000000","0.21906000"],["79981.43000000","0.02009000"],["79981.29000000","0.00014000"]],"asks":[["79984.00000000","1.07474000"],["79984.01000000","0.00090000"],["79984.02000000","0.00013000"],["79984.27000000","0.00007000"],["79984.61000000","0.00007000"],["79985.16000000","0.00014000"],["79985.50000000","0.00884000"],["79985.94000000","0.00007000"],["79985.99000000","0.00014000"],["79986.00000000","0.02421000"],["79986.20000000","0.00007000"],["79986.28000000","0.00014000"],["79986.29000000","0.03050000"],["79986.63000000","0.00014000"],["79986.64000000","0.05309000"],["79986.77000000","0.00014000"],["79986.78000000","0.01465000"],["79986.95000000","0.00007000"],["79987.24000000","0.00007000"],["79987.99000000","0.00007000"]]}}}
{"rx_ns": 10698552688600, "frame": {"stream":"btcusdt@depth@100ms","data":{"e":"depthUpdate","E":1787647693714,"s":"BTCUSDT","U":99116120672,"u":99116120695,"b":[["79983.99000000","5.87055000"],["79983.98000000","0.80125000"],["79910.11000000","0.00000000"],["79792.16000000","0.00000000"],["79790.57000000","0.00769000"],["71985.60000000","0.00304000"]],"a":[["80041.33000000","0.00007000"],["80086.57000000","0.00399000"]]}}}
{"rx_ns": 10698656856900, "frame": {"stream":"btcusdt@depth20@100ms","data":{"lastUpdateId":99116120703,"bids":[["79983.99000000","5.87055000"],["79983.98000000","0.80125000"],["79983.97000000","0.00013000"],["79983.51000000","0.00014000"],["79983.50000000","1.47185000"],["79983.49000000","0.19365000"],["79983.10000000","0.00400000"],["79982.81000000","0.00007000"],["79982.71000000","0.01688000"],["79982.29000000","0.00014000"],["79982.28000000","0.20655000"],["79982.05000000","0.00605000"],["79982.00000000","0.00007000"],["79981.99000000","0.39428000"],["79981.94000000","0.00007000"],["79981.77000000","0.00008000"],["79981.54000000","0.00007000"],["79981.51000000","0.21906000"],["79981.43000000","0.02009000"],["79981.29000000","0.00014000"]],"asks":[["79984.00000000","1.07462000"],["79984.01000000","0.00090000"],["79984.02000000","0.00013000"],["79984.27000000","0.00007000"],["79984.61000000","0.00007000"],["79985.16000000","0.00014000"],["79985.50000000","0.00884000"],["79985.94000000","0.00007000"],["79985.99000000","0.00014000"],["79986.00000000","0.02421000"],["79986.20000000","0.00007000"],["79986.28000000","0.00014000"],["79986.29000000","0.03050000"],["79986.63000000","0.00014000"],["79986.64000000","0.05309000"],["79986.77000000","0.00014000"],["79986.78000000","0.01465000"],["79986.95000000","0.00007000"],["79987.24000000","0.00007000"],["79987.99000000","0.00007000"]]}}}
{"rx_ns": 10698656934100, "frame": {"stream":"btcusdt@depth@100ms","data":{"e":"depthUpdate","E":1787647693814,"s":"BTCUSDT","U":99116120696,"u":99116120703,"b":[["79902.25000000","2.49555000"],["79899.61000000","0.00000000"],["71985.60000000","0.00320000"]],"a":[["79984.00000000","1.07462000"],["79990.00000000","0.02428000"],["79990.17000000","0.03368000"],["79990.97000000","0.00000000"]]}}}
{"rx_ns": 10698757471100, "frame": {"stream":"btcusdt@depth20@100ms","data":{"lastUpdateId":99116120712,"bids":[["79983.99000000","5.87055000"],["79983.98000000","0.80125000"],["79983.97000000","0.00013000"],["79983.51000000","0.00014000"],["79983.50000000","1.47185000"],["79983.49000000","0.19365000"],["79983.10000000","0.00400000"],["79982.81000000","0.00007000"],["79982.71000000","0.01688000"],["79982.29000000","0.00014000"],["79982.28000000","0.20655000"],["79982.05000000","0.00605000"],["79982.00000000","0.00007000"],["79981.99000000","0.39428000"],["79981.94000000","0.00007000"],["79981.77000000","0.00008000"],["79981.54000000","0.00007000"],["79981.51000000","0.21906000"],["79981.43000000","0.02009000"],["79981.29000000","0.00014000"]],"asks":[["79984.00000000","1.07462000"],["79984.01000000","0.00090000"],["79984.02000000","0.00013000"],["79984.27000000","0.00007000"],["79984.61000000","0.00007000"],["79985.16000000","0.00014000"],["79985.50000000","0.00884000"],["79985.94000000","0.00007000"],["79985.99000000","0.00014000"],["79986.00000000","0.02421000"],["79986.20000000","0.00007000"],["79986.28000000","0.00014000"],["79986.29000000","0.03050000"],["79986.63000000","0.00014000"],["79986.64000000","0.05309000"],["79986.77000000","0.00014000"],["79986.78000000","0.01465000"],["79986.95000000","0.00007000"],["79987.24000000","0.00007000"],["79987.99000000","0.00007000"]]}}}
{"rx_ns": 10698757549700, "frame": {"stream":"btcusdt@depth@100ms","data":{"e":"depthUpdate","E":1787647693914,"s":"BTCUSDT","U":99116120704,"u":99116120712,"b":[["79974.00000000","0.02400000"],["79972.00000000","0.02400000"],["79970.00000000","0.11779000"],["79772.41000000","0.00399000"],["71985.60000000","0.00336000"],["71985.00000000","0.00000000"]],"a":[]}}}
{"rx_ns": 10698860549100, "frame": {"stream":"btcusdt@depth20@100ms","data":{"lastUpdateId":99116120720,"bids":[["79983.99000000","5.87017000"],["79983.98000000","0.80125000"],["79983.97000000","0.00013000"],["79983.51000000","0.00014000"],["79983.50000000","1.47185000"],["79983.49000000","0.19365000"],["79983.10000000","0.00400000"],["79982.81000000","0.00007000"],["79982.71000000","0.01688000"],["79982.29000000","0.00014000"],["79982.28000000","0.20655000"],["79982.05000000","0.00605000"],["79982.00000000","0.00007000"],["79981.99000000","0.39428000"],["79981.94000000","0.00007000"],["79981.77000000","0.00008000"],["79981.54000000","0.00007000"],["79981.51000000","0.21906000"],["79981.43000000","0.02009000"],["79981.29000000","0.00014000"]],"asks":[["79984.00000000","1.07462000"],["79984.01000000","0.00090000"],["79984.02000000","0.00013000"],["79984.27000000","0.00007000"],["79984.61000000","0.00007000"],["79985.16000000","0.00014000"],["79985.50000000","0.00884000"],["79985.94000000","0.00007000"],["79985.99000000","0.00014000"],["79986.00000000","0.02421000"],["79986.20000000","0.00007000"],["79986.28000000","0.00014000"],["79986.29000000","0.03050000"],["79986.63000000","0.00014000"],["79986.64000000","0.05309000"],["79986.77000000","0.00014000"],["79986.78000000","0.01465000"],["79986.95000000","0.00007000"],["79987.24000000","0.00007000"],["79987.99000000","0.00007000"]]}}}
{"rx_ns": 10698860651400, "frame": {"stream":"btcusdt@depth@100ms","data":{"e":"depthUpdate","E":1787647694014,"s":"BTCUSDT","U":99116120713,"u":99116120720,"b":[["79983.99000000","5.87017000"],["78784.23000000","0.00030000"],["71985.60000000","0.00336000"],["71985.59000000","0.00000000"],["71985.58000000","0.00008000"],["63987.20000000","0.00031000"],["42091.80000000","0.00036000"]],"a":[]}}}
{"rx_ns": 10698952255500, "frame": {"stream":"btcusdt@depth20@100ms","data":{"lastUpdateId":99116120726,"bids":[["79983.99000000","5.87017000"],["79983.98000000","0.80125000"],["79983.97000000","0.00013000"],["79983.51000000","0.00014000"],["79983.50000000","1.47185000"],["79983.49000000","0.19365000"],["79983.10000000","0.00400000"],["79982.81000000","0.00007000"],["79982.71000000","0.01688000"],["79982.29000000","0.00014000"],["79982.28000000","0.20655000"],["79982.05000000","0.00605000"],["79982.00000000","0.00007000"],["79981.99000000","0.39428000"],["79981.94000000","0.00007000"],["79981.77000000","0.00008000"],["79981.54000000","0.00007000"],["79981.51000000","0.21906000"],["79981.43000000","0.02009000"],["79981.29000000","0.00014000"]],"asks":[["79984.00000000","1.07462000"],["79984.01000000","0.00090000"],["79984.02000000","0.00013000"],["79984.27000000","0.00007000"],["79984.61000000","0.00007000"],["79985.16000000","0.00014000"],["79985.50000000","0.00884000"],["79985.94000000","0.00007000"],["79985.99000000","0.00014000"],["79986.00000000","0.02421000"],["79986.20000000","0.00007000"],["79986.28000000","0.00014000"],["79986.29000000","0.03050000"],["79986.63000000","0.00014000"],["79986.64000000","0.05309000"],["79986.77000000","0.00014000"],["79986.78000000","0.01465000"],["79986.95000000","0.00007000"],["79987.24000000","0.00007000"],["79987.99000000","0.00007000"]]}}}
{"rx_ns": 10698952386400, "frame": {"stream":"btcusdt@depth@100ms","data":{"e":"depthUpdate","E":1787647694114,"s":"BTCUSDT","U":99116120721,"u":99116120726,"b":[["79971.44000000","0.14827000"],["79968.75000000","0.00007000"],["79924.34000000","0.00399000"],["71985.60000000","0.00352000"]],"a":[["80000.75000000","0.00007000"]]}}}
{"rx_ns": 10699052997900, "frame": {"stream":"btcusdt@depth20@100ms","data":{"lastUpdateId":99116120747,"bids":[["79983.99000000","5.87017000"],["79983.98000000","0.80125000"],["79983.97000000","0.00013000"],["79983.51000000","0.00014000"],["79983.50000000","1.47185000"],["79983.49000000","0.19365000"],["79983.10000000","0.00400000"],["79982.81000000","0.00007000"],["79982.71000000","0.01688000"],["79982.29000000","0.00014000"],["79982.28000000","0.20655000"],["79982.05000000","0.00014000"],["79982.00000000","0.00007000"],["79981.99000000","0.39428000"],["79981.94000000","0.00007000"],["79981.77000000","0.00008000"],["79981.54000000","0.00007000"],["79981.51000000","0.21906000"],["79981.43000000","0.02009000"],["79981.29000000","0.00014000"]],"asks":[["79984.00000000","1.28735000"],["79984.01000000","0.00090000"],["79984.02000000","0.00013000"],["79984.27000000","0.00007000"],["79984.61000000","0.00007000"],["79985.16000000","0.00021000"],["79985.50000000","0.00884000"],["79985.94000000","0.00007000"],["79985.99000000","0.00014000"],["79986.00000000","0.02421000"],["79986.20000000","0.00007000"],["79986.28000000","0.00014000"],["79986.29000000","0.03050000"],["79986.63000000","0.00014000"],["79986.64000000","0.05309000"],["79986.77000000","0.00014000"],["79986.78000000","0.01465000"],["79986.95000000","0.00007000"],["79987.24000000","0.00007000"],["79987.99000000","0.00007000"]]}}}
{"rx_ns": 10699053097000, "frame": {"stream":"btcusdt@depth@100ms","data":{"e":"depthUpdate","E":1787647694214,"s":"BTCUSDT","U":99116120727,"u":99116120747,"b":[["79982.05000000","0.00014000"],["79979.60000000","0.00000000"],["79978.48000000","0.00400000"],["79970.00000000","0.02400000"],["79910.11000000","0.02084000"],["71985.60000000","0.00352000"],["63987.20000000","0.00000000"]],"a":[["79984.00000000","1.28735000"],["79985.16000000","0.00021000"],["79988.46000000","0.05072000"],["79990.17000000","0.00000000"],["79992.85000000","0.00400000"],["79996.15000000","0.00000000"],["79996.52000000","0.00000000"],["80007.27000000","0.36586000"],["80087.84000000","0.00555000"],["81183.76000000","0.00030000"]]}}}
{"rx_ns": 10699152689200, "frame": {"stream":"btcusdt@depth20@100ms","data":{"lastUpdateId":99116120801,"bids":[["79983.99000000","5.87017000"],["79983.98000000","0.80125000"],["79983.97000000","0.00013000"],["79983.51000000","0.00014000"],["79983.50000000","1.47185000"],["79983.49000000","0.19365000"],["79983.10000000","0.00400000"],["79982.81000000","0.00007000"],["79982.71000000","0.01688000"],["79982.29000000","0.00014000"],["79982.28000000","0.20648000"],["79982.00000000","0.00007000"],["79981.99000000","0.39428000"],["79981.94000000","0.00007000"],["79981.77000000","0.00008000"],["79981.54000000","0.00007000"],["79981.51000000","0.21906000"],["79981.43000000","0.02023000"],["79981.29000000","0.00014000"],["79981.06000000","0.00014000"]],"asks":[["79984.00000000","1.28742000"],["79984.01000000","0.00090000"],["79984.02000000","0.00013000"],["79984.27000000","0.00007000"],["79984.61000000","0.00007000"],["79985.16000000","0.00021000"],["79985.50000000","0.00884000"],["79985.94000000","0.00007000"],["79985.99000000","0.00014000"],["79986.00000000","0.02421000"],["79986.20000000","0.00007000"],["79986.28000000","0.00014000"],["79986.29000000","0.03050000"],["79986.63000000","0.00014000"],["79986.64000000","0.05309000"],["79986.77000000","0.00014000"],["79986.78000000","0.01465000"],["79986.95000000","0.00007000"],["79987.24000000","0.00007000"],["79987.57000000","0.03988000"]]}}}
{"rx_ns": 10699152830400, "frame": {"stream":"btcusdt@depth@100ms","data":{"e":"depthUpdate","E":1787647694314,"s":"BTCUSDT","U":99116120748,"u":99116120801,"b":[["79983.99000000","5.87017000"],["79983.98000000","0.80125000"],["79982.28000000","0.20648000"],["79982.05000000","0.00000000"],["79981.43000000","0.02023000"],["79978.73000000","0.00007000"],["79978.42000000","0.26463000"],["79976.01000000","0.00000000"],["79974.49000000","0.00162000"],["79943.86000000","0.00000000"],["79924.34000000","0.00000000"],["79910.11000000","0.00000000"],["79902.25000000","1.87060000"],["79892.36000000","0.00399000"],["71985.60000000","0.00368000"],["63987.19000000","0.00000000"],["63987.00000000","0.00000000"]],"a":[["79984.00000000","1.28742000"],["79987.57000000","0.03988000"],["79988.06000000","0.01769000"],["79988.46000000","0.00014000"],["79989.34000000","0.01762000"],["79990.00000000","0.02421000"],["80006.93000000","0.02000000"],["80010.00000000","0.12174000"],["80014.95000000","0.00000000"],["80020.01000000","1.64699000"],["80021.14000000","0.00000000"],["80064.03000000","1.54665000"],["80088.62000000","0.25256000"],["80128.79000000","0.02428000"]]}}}
{"rx_ns": 10699252251400, "frame": {"stream":"btcusdt@depth20@100ms","data":{"lastUpdateId":99116120830,"bids":[["79983.99000000","6.11010000"],["79983.98000000","0.80125000"],["79983.97000000","0.00013000"],["79983.51000000","0.00014000"],["79983.50000000","1.47185000"],["79983.49000000","0.19365000"],["79983.10000000","0.00400000"],["79982.81000000","0.00007000"],["79982.71000000","0.01688000"],["79982.29000000","0.00014000"],["79982.28000000","0.20648000"],["79982.00000000","0.00007000"],["79981.99000000","0.39428000"],["79981.94000000","0.00007000"],["79981.77000000","0.00008000"],["79981.54000000","0.00007000"],["79981.51000000","0.21906000"],["79981.43000000","0.02023000"],["79981.29000000","0.00014000"],["79981.06000000","0.00014000"]],"asks":[["79984.00000000","1.28755000"],["79984.01000000","0.00097000"],["79984.02000000","0.00013000"],["79984.27000000","0.00007000"],["79984.61000000","0.00007000"],["79985.16000000","0.00021000"],["79985.50000000","0.00884000"],["79985.94000000","0.00007000"],["79985.99000000","0.00014000"],["79986.00000000","0.02421000"],["79986.20000000","0.00007000"],["79986.28000000","0.00014000"],["79986.29000000","0.03050000"],["79986.63000000","0.00014000"],["79986.64000000","0.05309000"],["79986.77000000","0.00014000"],["79986.78000000","0.01472000"],["79986.95000000","0.00007000"],["79987.24000000","0.00007000"],["79987.57000000","0.04002000"]]}}}
{"rx_ns": 10699252356300, "frame": {"stream":"btcusdt@depth@100ms","data":{"e":"depthUpdate","E":1787647694414,"s":"BTCUSDT","U":99116120802,"u":99116120830,"b":[["79983.99000000","6.11010000"],["79954.08000000","0.00000000"],["79943.46000000","0.09286000"]],"a":[["79984.00000000","1.28755000"],["79984.01000000","0.00097000"],["79986.78000000","0.01472000"],["79987.57000000","0.04002000"],["79988.06000000","0.01762000"],["79988.46000000","0.00000000"],["79992.85000000","0.00000000"],["79993.89000000","0.00650000"],["80021.92000000","0.00000000"],["80022.20000000","0.00000000"],["80023.41000000","0.09209000"],["80030.00000000","0.11772000"]]}}}
{"rx_ns": 10699357394800, "frame": {"stream":"btcusdt@depth20@100ms","data":{"lastUpdateId":99116120840,"bids":[["79983.99000000","5.87017000"],["79983.98000000","0.80125000"],["79983.97000000","0.00013000"],["79983.51000000","0.00014000"],["79983.50000000","1.47185000"],["79983.49000000","0.19365000"],["79983.10000000","0.00400000"],["79982.81000000","0.00007000"],["79982.71000000","0.01688000"],["79982.29000000","0.00014000"],["79982.28000000","0.20648000"],["79982.00000000","0.00007000"],["79981.99000000","0.39428000"],["79981.94000000","0.00007000"],["79981.77000000","0.00008000"],["79981.54000000","0.00007000"],["79981.51000000","0.21906000"],["79981.43000000","0.02023000"],["79981.29000000","0.00014000"],["79981.06000000","0.00014000"]],"asks":[["79984.00000000","1.07458000"],["79984.01000000","0.00097000"],["79984.02000000","0.00013000"],["79984.27000000","0.00007000"],["79984.61000000","0.00007000"],["79985.16000000","0.00021000"],["79985.50000000","0.00884000"],["79985.94000000","0.00007000"],["79985.99000000","0.00014000"],["79986.00000000","0.02421000"],["79986.20000000","0.00007000"],["79986.28000000","0.00014000"],["79986.29000000","0.03050000"],["79986.63000000","0.00014000"],["79986.64000000","0.05309000"],["79986.77000000","0.00014000"],["79986.78000000","0.01472000"],["79986.95000000","0.00007000"],["79987.24000000","0.00007000"],["79987.57000000","0.04002000"]]}}}
{"rx_ns": 10699357477200, "frame": {"stream":"btcusdt@depth@100ms","data":{"e":"depthUpdate","E":1787647694514,"s":"BTCUSDT","U":99116120831,"u":99116120840,"b":[["79983.99000000","5.87017000"],["79924.35000000","0.00000000"],["79896.97000000","0.62495000"],["71985.60000000","0.00384000"],["63987.20000000","0.00031000"]],"a":[["79984.00000000","1.07458000"]]}}}
{"rx_ns": 10699452425600, "frame": {"stream":"btcusdt@depth20@100ms","data":{"lastUpdateId":99116120846,"bids":[["79983.99000000","5.87017000"],["79983.98000000","0.80125000"],["79983.97000000","0.00013000"],["79983.51000000","0.00014000"],["79983.50000000","1.47185000"],["79983.49000000","0.19365000"],["79983.10000000","0.00400000"],["79982.81000000","0.00007000"],["79982.71000000","0.01688000"],["79982.29000000","0.00014000"],["79982.28000000","0.20648000"],["79982.00000000","0.00007000"],["79981.99000000","0.39428000"],["79981.94000000","0.00007000"],["79981.77000000","0.00008000"],["79981.54000000","0.00007000"],["79981.51000000","0.21906000"],["79981.43000000","0.02023000"],["79981.29000000","0.00014000"],["79981.06000000","0.00014000"]],"asks":[["79984.00000000","1.07458000"],["79984.01000000","0.00097000"],["79984.02000000","0.00013000"],["79984.27000000","0.00007000"],["79984.61000000","0.00007000"],["79985.16000000","0.00014000"],["79985.50000000","0.00884000"],["79985.94000000","0.00007000"],["79985.99000000","0.00014000"],["79986.00000000","0.02421000"],["79986.20000000","0.00007000"],["79986.28000000","0.00014000"],["79986.29000000","0.03050000"],["79986.63000000","0.00014000"],["79986.64000000","0.05309000"],["79986.77000000","0.00014000"],["79986.78000000","0.01472000"],["79986.95000000","0.00007000"],["79987.24000000","0.00007000"],["79987.57000000","0.04002000"]]}}}
{"rx_ns": 10699452503400, "frame": {"stream":"btcusdt@depth@100ms","data":{"e":"depthUpdate","E":1787647694614,"s":"BTCUSDT","U":99116120841,"u":99116120846,"b":[["71985.60000000","0.00384000"],["63987.20000000","0.00000000"]],"a":[["79985.16000000","0.00014000"],["79993.89000000","0.00250000"],["79994.97000000","0.00400000"]]}}}
{"rx_ns": 10699554908800, "frame": {"stream":"btcusdt@depth20@100ms","data":{"lastUpdateId":99116120925,"bids":[["79983.99000000","5.87024000"],["79983.98000000","0.80125000"],["79983.97000000","0.00013000"],["79983.51000000","0.00014000"],["79983.50000000","1.47185000"],["79983.49000000","0.19365000"],["79983.10000000","0.00400000"],["79982.81000000","0.00007000"],["79982.71000000","0.01688000"],["79982.29000000","0.00014000"],["79982.28000000","0.20655000"],["79982.00000000","0.00007000"],["79981.99000000","0.39428000"],["79981.94000000","0.00007000"],["79981.77000000","0.00008000"],["79981.54000000","0.00007000"],["79981.51000000","0.21906000"],["79981.43000000","0.02023000"],["79981.29000000","0.00014000"],["79981.06000000","0.00014000"]],"asks":[["79984.00000000","1.02357000"],["79984.01000000","0.00090000"],["79984.02000000","0.00013000"],["79984.27000000","0.00007000"],["79984.61000000","0.00007000"],["79985.16000000","0.00014000"],["79985.50000000","0.00884000"],["79985.94000000","0.00007000"],["79985.99000000","0.00014000"],["79986.00000000","0.02421000"],["79986.20000000","0.00007000"],["79986.28000000","0.00014000"],["79986.29000000","0.03050000"],["79986.63000000","0.00014000"],["79986.64000000","0.05309000"],["79986.77000000","0.00014000"],["79986.78000000","0.01472000"],["79986.95000000","0.00007000"],["79987.24000000","0.00007000"],["79987.57000000","0.00014000"]]}}}
{"rx_ns": 10699555007100, "frame": {"stream":"btcusdt@depth@100ms","data":{"e":"depthUpdate","E":1787647694715,"s":"BTCUSDT","U":99116120847,"u":99116120925,"b":[["79983.99000000","5.87024000"],["79983.98000000","0.80125000"],["79982.28000000","0.20655000"],["79982.05000000","0.00000000"],["79980.81000000","0.00400000"],["79978.76000000","0.00400000"],["79978.48000000","0.00000000"],["79924.34000000","0.00000000"],["71985.60000000","0.00400000"]],"a":[["79984.00000000","1.02357000"],["79984.01000000","0.00090000"],["79987.57000000","0.00014000"],["79992.41000000","0.00000000"],["79993.47000000","0.00046000"],["79994.97000000","0.00000000"],["79996.09000000","0.00400000"],["80007.52000000","0.02000000"],["80008.15000000","0.00000000"],["80018.88000000","0.00000000"]]}}}
{"rx_ns": 10699661060000, "frame": {"stream":"btcusdt@depth20@100ms","data":{"lastUpdateId":99116121321,"bids":[["79983.99000000","0.71719000"],["79983.98000000","0.00090000"],["79983.97000000","0.00013000"],["79983.50000000","0.00035000"],["79983.49000000","0.08146000"],["79982.81000000","0.00007000"],["79982.72000000","0.00014000"],["79982.71000000","0.01688000"],["79982.28000000","0.00021000"],["79981.99000000","0.00848000"],["79981.94000000","0.00007000"],["79981.54000000","0.00007000"],["79981.51000000","0.00028000"],["79981.44000000","0.00014000"],["79981.43000000","0.02023000"],["79981.29000000","0.00007000"],["79981.06000000","0.00014000"],["79981.05000000","0.00014000"],["79981.04000000","0.04715000"],["79980.24000000","0.00007000"]],"asks":[["79984.00000000","2.30992000"],["79984.01000000","0.00027000"],["79984.02000000","0.00013000"],["79984.27000000","0.00007000"],["79984.61000000","0.00007000"],["79985.16000000","0.00021000"],["79985.50000000","0.00891000"],["79985.94000000","0.00007000"],["79985.98000000","0.00014000"],["79985.99000000","0.04415000"],["79986.00000000","0.02428000"],["79986.18000000","0.00014000"],["79986.19000000","0.03224000"],["79986.20000000","0.00007000"],["79986.28000000","0.00014000"],["79986.29000000","0.03050000"],["79986.63000000","0.00014000"],["79986.64000000","0.05309000"],["79986.78000000","0.01465000"],["79986.95000000","0.00007000"]]}}}
{"rx_ns": 10699661161900, "frame": {"stream":"btcusdt@depth@100ms","data":{"e":"depthUpdate","E":1787647694814,"s":"BTCUSDT","U":99116120926,"u":99116121321,"b":[["79983.99000000","0.71719000"],["79983.98000000","0.00090000"],["79983.51000000","0.00000000"],["79983.50000000","0.00035000"],["79983.49000000","0.08146000"],["79983.10000000","0.00000000"],["79982.72000000","0.00014000"],["79982.29000000","0.00000000"],["79982.28000000","0.00021000"],["79982.00000000","0.00000000"],["79981.99000000","0.00848000"],["79981.77000000","0.00000000"],["79981.51000000","0.00028000"],["79981.44000000","0.00014000"],["79981.29000000","0.00007000"],["79981.05000000","0.00014000"],["79981.00000000","0.00000000"],["79980.95000000","0.00000000"],["79980.81000000","0.00000000"],["79980.69000000","0.00000000"],["79980.40000000","0.00000000"],["79980.24000000","0.00007000"],["79980.14000000","0.00000000"],["79980.00000000","0.00000000"],["79979.99000000","0.14011000"],["79979.47000000","0.00000000"],["79979.29000000","0.00000000"],["79979.15000000","0.00000000"],["79979.14000000","0.00000000"],["79979.09000000","0.00000000"],["79978.94000000","0.00000000"],["79978.76000000","0.00000000"],["79978.75000000","0.00000000"],["79978.74000000","0.00000000"],["79978.52000000","0.00000000"],["79978.42000000","0.00904000"],["79978.29000000","0.40239000"],["79978.01000000","0.00000000"],["79977.99000000","0.21351000"],["79977.97000000","0.00000000"],["79977.42000000","0.00007000"],["79977.17000000","0.00000000"],["79977.16000000","0.00000000"],["79976.90000000","0.30407000"],["79976.67000000","0.30007000"],["79976.11000000","0.00000000"],["79976.01000000","1.04939000"],["79976.00000000","0.23568000"],["79974.49000000","0.00000000"],["79974.48000000","0.00000000"],["79974.47000000","0.00000000"],["79973.73000000","0.00000000"],["79973.58000000","0.12504000"],["79973.55000000","0.00007000"],["79972.80000000","0.00000000"],["79972.78000000","0.08576000"],["79971.86000000","1.04939000"],["79971.44000000","0.00000000"],["79971.38000000","0.00151000"],["79970.82000000","0.00000000"],["79970.81000000","0.00000000"],["79970.51000000","0.00177000"],["79970.33000000","1.87060000"],["79970.21000000","0.00000000"],["79970.17000000","0.00026000"],["79969.91000000","0.00000000"],["79969.88000000","0.00000000"],["79969.68000000","0.31278000"],["79969.15000000","0.00000000"],["79969.14000000","0.00000000"],["79968.99000000","0.02474000"],["79968.28000000","0.00000000"],["79968.26000000","0.00000000"],["79968.11000000","0.02200000"],["79967.60000000","1.04939000"],["79967.25000000","0.00000000"],["79967.20000000","0.00000000"],["79967.04000000","0.00625000"],["79966.87000000","0.00000000"],["79966.47000000","0.00625000"],["79965.87000000","0.02000000"],["79965.85000000","0.00000000"],["79965.58000000","0.12505000"],["79965.45000000","1.87060000"],["79965.24000000","0.15381000"],["79965.15000000","0.36586000"],["79964.81000000","0.15000000"],["79964.35000000","0.00400000"],["79964.34000000","0.00012000"],["79963.38000000","0.49455000"],["79963.37000000","1.05339000"],["79963.36000000","0.00000000"],["79963.29000000","0.00000000"],["79963.06000000","0.00000000"],["79963.05000000","0.00000000"],["79962.99000000","0.00000000"],["79962.78000000","0.00000000"],["79962.64000000","0.00000000"],["79962.40000000","0.00000000"],["79960.60000000","0.00000000"],["79960.25000000","0.00625000"],["79960.00000000","0.11787000"],["79959.88000000","0.00000000"],["79959.76000000","1.87060000"],["79959.50000000","0.00000000"],["79959.48000000","0.00000000"],["79958.76000000","1.04939000"],["79958.75000000","0.00000000"],["79958.57000000","0.00000000"],["79957.58000000","0.12506000"],["79956.97000000","0.36586000"],["79954.82000000","0.00000000"],["79953.53000000","0.42901000"],["79950.00000000","0.12039000"],["79947.46000000","0.00000000"],["79944.51000000","0.26126000"],["79943.55000000","0.47998000"],["79942.82000000","0.33784000"],["79942.59000000","0.00007000"],["79942.27000000","0.33784000"],["79941.15000000","0.00000000"],["79940.22000000","0.00000000"],["79939.37000000","0.00000000"],["79938.84000000","0.33785000"],["79938.72000000","0.00007000"],["79930.24000000","1.23894000"],["79929.88000000","0.00400000"],["79926.87000000","0.00000000"],["79921.71000000","0.04533000"],["79919.95000000","0.00400000"],["79912.13000000","0.00000000"],["79906.26000000","1.23931000"],["79902.18000000","0.00000000"],["79896.97000000","0.00000000"],["79836.30000000","0.00000000"],["79830.33000000","0.00000000"],["77000.00000000","80.73857000"],["71985.60000000","0.00416000"]],"a":[["79984.00000000","2.30992000"],["79984.01000000","0.00027000"],["79985.12000000","0.00000000"],["79985.16000000","0.00021000"],["79985.50000000","0.00891000"],["79985.98000000","0.00014000"],["79985.99000000","0.04415000"],["79986.00000000","0.02428000"],["79986.18000000","0.00014000"],["79986.19000000","0.03224000"],["79986.24000000","0.00000000"],["79986.28000000","0.00014000"],["79986.63000000","0.00014000"],["79986.77000000","0.00000000"],["79986.78000000","0.01465000"],["79987.57000000","0.00000000"],["79987.99000000","0.00000000"],["79988.06000000","0.01769000"],["79988.28000000","0.12501000"],["79988.30000000","0.00441000"],["79989.34000000","0.01776000"],["79989.46000000","0.00400000"],["79989.60000000","0.08574000"],["79989.63000000","0.37922000"],["79989.64000000","0.00000000"],["79990.00000000","0.02428000"],["79990.14000000","0.00586000"],["79990.96000000","0.00153000"],["79991.99000000","1.04947000"],["79992.00000000","0.22671000"],["79992.45000000","0.04173000"],["79992.46000000","0.00000000"],["79992.77000000","0.00400000"],["79992.86000000","0.00000000"],["79993.47000000","0.00000000"],["79993.93000000","0.00000000"],["79994.36000000","0.03224000"],["79995.30000000","0.02000000"],["79995.81000000","0.00000000"],["79996.09000000","0.00000000"],["79996.16000000","0.36111000"],["79996.50000000","0.00000000"],["79997.48000000","0.08566000"],["79997.73000000","1.04939000"],["79998.42000000","0.00000000"],["79998.82000000","0.00625000"],["79999.11000000","0.00000000"],["79999.54000000","0.00000000"],["80000.16000000","1.05716000"],["80000.17000000","1.87060000"],["80000.18000000","0.00000000"],["80002.71000000","0.02000000"],["80002.77000000","0.33758000"],["80004.23000000","0.42901000"],["80004.48000000","0.12499000"],["80004.93000000","0.33757000"],["80005.68000000","0.00000000"],["80006.70000000","0.02000000"],["80008.24000000","0.00000000"],["80008.59000000","0.00000000"],["80009.80000000","0.00000000"],["80011.13000000","0.62509000"],["80013.81000000","0.00000000"],["80016.00000000","0.02414000"],["80019.99000000","0.00014000"],["80021.70000000","0.00000000"],["80024.08000000","0.00000000"],["80028.46000000","0.00000000"],["80042.42000000","0.00000000"],["80044.02000000","0.00000000"],["80045.10000000","0.00000000"],["80048.93000000","0.00000000"],["80050.82000000","0.00000000"],["80056.77000000","0.00000000"],["80148.73000000","0.00000000"]]}}}
{"rx_ns": 10699752889900, "frame": {"stream":"btcusdt@depth20@100ms","data":{"lastUpdateId":99116121578,"bids":[["79983.99000000","3.01325000"],["79983.98000000","0.00076000"],["79983.97000000","0.00013000"],["79983.50000000","0.00021000"],["79983.49000000","0.08146000"],["79982.81000000","0.00007000"],["79982.72000000","0.00014000"],["79982.71000000","0.01688000"],["79982.28000000","0.00007000"],["79981.99000000","0.00855000"],["79981.94000000","0.00007000"],["79981.77000000","0.00014000"],["79981.76000000","0.08638000"],["79981.54000000","0.00007000"],["79981.51000000","0.00014000"],["79981.44000000","0.00014000"],["79981.43000000","0.02023000"],["79981.29000000","0.00014000"],["79981.06000000","0.00007000"],["79981.05000000","0.00014000"]],"asks":[["79984.00000000","2.11903000"],["79984.01000000","0.00027000"],["79984.02000000","0.00013000"],["79984.27000000","0.00007000"],["79984.61000000","0.00007000"],["79985.16000000","0.00021000"],["79985.50000000","0.00891000"],["79985.94000000","0.00007000"],["79985.98000000","0.00014000"],["79985.99000000","0.04429000"],["79986.00000000","0.02428000"],["79986.15000000","0.00400000"],["79986.19000000","0.00014000"],["79986.20000000","0.00007000"],["79986.28000000","0.00014000"],["79986.29000000","0.03050000"],["79986.63000000","0.00014000"],["79986.64000000","0.05309000"],["79986.77000000","0.00007000"],["79986.78000000","0.01465000"]]}}}
{"rx_ns": 10699753068900, "frame": {"stream":"btcusdt@depth@100ms","data":{"e":"depthUpdate","E":1787647694914,"s":"BTCUSDT","U":99116121322,"u":99116121578,"b":[["79983.99000000","3.01325000"],["79983.98000000","0.00076000"],["79983.50000000","0.00021000"],["79982.71000000","0.01688000"],["79982.28000000","0.00007000"],["79981.99000000","0.00855000"],["79981.77000000","0.00014000"],["79981.76000000","0.08638000"],["79981.75000000","0.00000000"],["79981.51000000","0.00014000"],["79981.29000000","0.00014000"],["79981.06000000","0.00007000"],["79981.04000000","0.04736000"],["79980.64000000","0.04032000"],["79980.63000000","0.00000000"],["79980.24000000","0.00000000"],["79980.23000000","0.16039000"],["79980.15000000","0.02023000"],["79979.99000000","0.14025000"],["79979.72000000","0.00000000"],["79979.05000000","0.00007000"],["79978.94000000","0.00625000"],["79978.61000000","0.00026000"],["79978.42000000","0.00904000"],["79978.39000000","0.00000000"],["79978.30000000","0.00000000"],["79978.29000000","1.18855000"],["79977.99000000","0.21344000"],["79977.42000000","0.00014000"],["79976.90000000","0.30007000"],["79976.29000000","0.30598000"],["79976.02000000","1.87060000"],["79975.60000000","0.00625000"],["79973.55000000","0.00014000"],["79973.26000000","0.36586000"],["79972.01000000","0.00169000"],["79971.14000000","0.00000000"],["79970.68000000","0.00007000"],["79970.51000000","0.00000000"],["79970.45000000","0.00702000"],["79969.68000000","0.31285000"],["79969.23000000","0.03224000"],["79967.04000000","0.00000000"],["79966.47000000","0.00000000"],["79963.38000000","0.36895000"],["79956.00000000","0.02400000"],["79943.99000000","0.02400000"],["79943.58000000","0.02200000"],["79942.59000000","0.00000000"],["79940.99000000","0.00000000"],["79939.18000000","0.83458000"],["79938.72000000","0.00000000"],["79936.30000000","0.02474000"],["79933.19000000","0.00400000"],["79924.33000000","0.00399000"],["79923.26000000","0.00400000"],["79919.95000000","0.00000000"],["79912.13000000","0.00312000"],["79830.33000000","0.00125000"],["71985.60000000","0.00416000"],["42091.80000000","0.00000000"]],"a":[["79984.00000000","2.11903000"],["79984.98000000","0.00000000"],["79985.15000000","0.00000000"],["79985.49000000","0.00000000"],["79985.50000000","0.00891000"],["79985.99000000","0.04429000"],["79986.00000000","0.02428000"],["79986.15000000","0.00400000"],["79986.18000000","0.00000000"],["79986.19000000","0.00014000"],["79986.29000000","0.03050000"],["79986.62000000","0.00000000"],["79986.77000000","0.00007000"],["79988.06000000","0.01762000"],["79988.27000000","0.14359000"],["79988.28000000","0.12508000"],["79988.98000000","0.00598000"],["79989.34000000","0.01755000"],["79989.37000000","0.04000000"],["79989.60000000","0.00000000"],["79989.63000000","0.00000000"],["79990.00000000","0.02407000"],["79990.95000000","0.00000000"],["79991.15000000","0.00000000"],["79991.84000000","0.00000000"],["79991.99000000","0.00008000"],["79992.30000000","0.00000000"],["79992.45000000","0.07060000"],["79993.88000000","0.00625000"],["79994.08000000","0.08574000"],["79994.36000000","0.00000000"],["79995.20000000","0.07733000"],["79995.30000000","0.00000000"],["79996.15000000","0.08574000"],["79997.47000000","0.00000000"],["79997.72000000","1.04939000"],["79997.73000000","0.00000000"],["79997.80000000","0.00000000"],["79997.90000000","0.02000000"],["79998.82000000","0.00000000"],["80000.16000000","0.60562000"],["80000.17000000","0.00000000"],["80000.24000000","0.00000000"],["80001.51000000","0.00625000"],["80004.23000000","0.00000000"],["80004.24000000","0.00000000"],["80005.14000000","1.87060000"],["80005.15000000","0.00000000"],["80005.43000000","0.02441000"],["80009.78000000","0.44647000"],["80018.06000000","0.00000000"],["80025.55000000","0.03024000"],["80038.90000000","0.00000000"],["80042.53000000","0.83350000"],["80251.81000000","0.00000000"]]}}}
{"rx_ns": 10699853842500, "frame": {"stream":"btcusdt@depth20@100ms","data":{"lastUpdateId":99116121627,"bids":[["79983.99000000","3.01284000"],["79983.98000000","0.00076000"],["79983.97000000","0.00013000"],["79983.50000000","0.00021000"],["79983.49000000","0.08146000"],["79982.81000000","0.00007000"],["79982.75000000","0.00007000"],["79982.72000000","0.00014000"],["79982.71000000","0.01688000"],["79982.28000000","0.00007000"],["79981.99000000","0.00855000"],["79981.94000000","0.00007000"],["79981.77000000","0.00014000"],["79981.76000000","0.08652000"],["79981.54000000","0.00007000"],["79981.51000000","0.00014000"],["79981.44000000","0.00014000"],["79981.43000000","0.02023000"],["79981.29000000","0.00014000"],["79981.06000000","0.00007000"]],"asks":[["79984.00000000","1.91714000"],["79984.01000000","0.00027000"],["79984.02000000","0.00013000"],["79984.27000000","0.00007000"],["79984.61000000","0.00007000"],["79985.16000000","0.00021000"],["79985.50000000","0.00891000"],["79985.94000000","0.00007000"],["79985.98000000","0.00014000"],["79985.99000000","0.04429000"],["79986.00000000","0.02421000"],["79986.15000000","0.00400000"],["79986.20000000","0.00007000"],["79986.28000000","0.00014000"],["79986.29000000","0.03050000"],["79986.63000000","0.00014000"],["79986.64000000","0.05309000"],["79986.77000000","0.00007000"],["79986.78000000","0.01465000"],["79986.95000000","0.00007000"]]}}}
{"rx_ns": 10699853931300, "frame": {"stream":"btcusdt@depth@100ms","data":{"e":"depthUpdate","E":1787647695014,"s":"BTCUSDT","U":99116121579,"u":99116121627,"b":[["79983.99000000","3.01284000"],["79982.75000000","0.00007000"],["79981.99000000","0.00855000"],["79981.76000000","0.08652000"],["79981.04000000","0.04736000"],["79980.64000000","0.04046000"],["79980.29000000","0.00441000"],["79980.15000000","0.02009000"],["79979.99000000","0.14011000"],["79978.41000000","0.00590000"],["79973.04000000","0.00048000"],["79959.77000000","1.14728000"],["79959.49000000","0.00000000"],["79953.50000000","0.04579000"],["79921.71000000","0.00000000"],["79790.57000000","0.00000000"],["79781.65000000","0.00769000"],["78784.23000000","0.00030000"],["71985.60000000","0.00432000"],["71985.00000000","0.00000000"],["63987.20000000","0.00031000"]],"a":[["79984.00000000","1.91714000"],["79986.00000000","0.02421000"],["79986.19000000","0.00000000"],["79988.06000000","0.01776000"],["79994.99000000","0.00000000"],["80014.07000000","0.00000000"],["80243.78000000","0.00030000"]]}}}
{"rx_ns": 10699957555200, "frame": {"stream":"btcusdt@depth20@100ms","data":{"lastUpdateId":99116121650,"bids":[["79983.99000000","3.01403000"],["79983.98000000","0.00076000"],["79983.97000000","0.00013000"],["79983.50000000","0.00021000"],["79983.49000000","0.08146000"],["79982.81000000","0.00007000"],["79982.75000000","0.00007000"],["79982.72000000","0.00014000"],["79982.71000000","0.01688000"],["79982.28000000","0.00007000"],["79981.99000000","0.00855000"],["79981.94000000","0.00007000"],["79981.77000000","0.00014000"],["79981.76000000","0.08652000"],["79981.54000000","0.00007000"],["79981.51000000","0.00014000"],["79981.44000000","0.00014000"],["79981.43000000","0.02023000"],["79981.29000000","0.00014000"],["79981.06000000","0.00007000"]],"asks":[["79984.00000000","1.99183000"],["79984.01000000","0.00027000"],["79984.02000000","0.00013000"],["79984.27000000","0.00007000"],["79984.61000000","0.00007000"],["79985.16000000","0.00021000"],["79985.50000000","0.00891000"],["79985.94000000","0.00007000"],["79985.98000000","0.00014000"],["79985.99000000","0.04429000"],["79986.00000000","0.02421000"],["79986.15000000","0.00400000"],["79986.20000000","0.00007000"],["79986.28000000","0.00014000"],["79986.29000000","0.03050000"],["79986.63000000","0.00014000"],["79986.64000000","0.05309000"],["79986.77000000","0.00007000"],["79986.78000000","0.01465000"],["79986.95000000","0.00007000"]]}}}
{"rx_ns": 10699957696000, "frame": {"stream":"btcusdt@depth@100ms","data":{"e":"depthUpdate","E":1787647695114,"s":"BTCUSDT","U":99116121628,"u":99116121650,"b":[["79983.99000000","3.01403000"],["79978.42000000","0.00911000"],["79978.28000000","0.19392000"],["79978.10000000","0.02474000"],["79968.99000000","0.00000000"],["79968.75000000","0.00000000"],["79957.82000000","0.49229000"],["79933.83000000","0.97253000"],["79918.96000000","0.00335000"],["79899.42000000","0.00000000"],["71985.60000000","0.00432000"],["71985.58000000","0.00000000"]],"a":[["79984.00000000","1.99183000"],["79988.98000000","0.00000000"],["80000.75000000","0.00000000"],["80038.50000000","0.37481000"]]}}}
{"rx_ns": 10700053620200, "frame": {"stream":"btcusdt@depth20@100ms","data":{"lastUpdateId":99116121679,"bids":[["79983.99000000","3.54251000"],["79983.98000000","0.00076000"],["79983.97000000","0.00013000"],["79983.50000000","0.00021000"],["79983.49000000","0.08146000"],["79982.81000000","0.00007000"],["79982.75000000","0.00007000"],["79982.72000000","0.00014000"],["79982.71000000","0.01688000"],["79982.28000000","0.00007000"],["79981.99000000","0.00855000"],["79981.94000000","0.00007000"],["79981.77000000","0.00014000"],["79981.76000000","0.08652000"],["79981.54000000","0.00007000"],["79981.51000000","0.00014000"],["79981.44000000","0.00014000"],["79981.43000000","0.02023000"],["79981.29000000","0.00014000"],["79981.06000000","0.00007000"]],"asks":[["79984.00000000","1.99183000"],["79984.01000000","0.00027000"],["79984.02000000","0.00013000"],["79984.27000000","0.00007000"],["79984.61000000","0.00007000"],["79985.16000000","0.00021000"],["79985.50000000","0.00891000"],["79985.94000000","0.00007000"],["79985.98000000","0.00014000"],["79985.99000000","0.04429000"],["79986.00000000","0.02421000"],["79986.15000000","0.00400000"],["79986.20000000","0.00007000"],["79986.28000000","0.00014000"],["79986.29000000","0.03050000"],["79986.63000000","0.00014000"],["79986.64000000","0.05309000"],["79986.77000000","0.00007000"],["79986.78000000","0.01465000"],["79986.95000000","0.00007000"]]}}}
{"rx_ns": 10700053720600, "frame": {"stream":"btcusdt@depth@100ms","data":{"e":"depthUpdate","E":1787647695214,"s":"BTCUSDT","U":99116121651,"u":99116121679,"b":[["79983.99000000","3.54251000"],["79968.75000000","0.00007000"],["79894.34000000","0.56786000"],["79894.33000000","0.62495000"],["79893.40000000","0.00312000"],["79829.28000000","0.00202000"],["79808.85000000","0.01958000"],["79781.10000000","0.00000000"],["71985.60000000","0.00448000"],["63987.20000000","0.00000000"]],"a":[["79984.00000000","1.99183000"],["79988.27000000","0.14282000"],["79988.28000000","0.12501000"],["79989.31000000","0.00090000"],["79990.91000000","0.05507000"],["80000.75000000","0.00007000"],["80141.39000000","0.00202000"],["81183.76000000","0.00030000"]]}}}
{"rx_ns": 10700156343500, "frame": {"stream":"btcusdt@depth20@100ms","data":{"lastUpdateId":99116121728,"bids":[["79983.99000000","3.54230000"],["79983.98000000","0.00076000"],["79983.97000000","0.00013000"],["79983.50000000","0.00021000"],["79983.49000000","0.08146000"],["79982.81000000","0.00007000"],["79982.75000000","0.00007000"],["79982.72000000","0.00014000"],["79982.71000000","0.01688000"],["79982.28000000","0.00007000"],["79981.99000000","0.00855000"],["79981.94000000","0.00007000"],["79981.77000000","0.00014000"],["79981.76000000","0.08652000"],["79981.54000000","0.00007000"],["79981.51000000","0.00014000"],["79981.44000000","0.00014000"],["79981.43000000","0.02023000"],["79981.29000000","0.00014000"],["79981.06000000","0.00007000"]],"asks":[["79984.00000000","1.91126000"],["79984.01000000","0.00027000"],["79984.02000000","0.00013000"],["79984.27000000","0.00007000"],["79984.61000000","0.00007000"],["79985.16000000","0.00021000"],["79985.50000000","0.00891000"],["79985.94000000","0.00007000"],["79985.98000000","0.00014000"],["79985.99000000","0.04429000"],["79986.00000000","0.02421000"],["79986.15000000","0.00400000"],["79986.20000000","0.00007000"],["79986.28000000","0.00014000"],["79986.29000000","0.03050000"],["79986.63000000","0.00014000"],["79986.64000000","0.05309000"],["79986.77000000","0.00007000"],["79986.78000000","0.01472000"],["79986.95000000","0.00007000"]]}}}
{"rx_ns": 10700156467800, "frame": {"stream":"btcusdt@depth@100ms","data":{"e":"depthUpdate","E":1787647695314,"s":"BTCUSDT","U":99116121680,"u":99116121728,"b":[["79983.99000000","3.54230000"],["79976.00000000","0.24640000"],["79900.71000000","0.11978000"],["71985.60000000","0.00416000"],["64000.00000000","66.11297000"],["63987.19000000","0.00000000"],["63987.00000000","0.00000000"]],"a":[["79984.00000000","1.91126000"],["79986.78000000","0.01472000"],["79987.51000000","0.00000000"],["79990.52000000","0.08000000"],["79992.00000000","0.22664000"],["79994.14000000","0.00048000"],["79994.27000000","0.00000000"],["79996.15000000","0.00000000"],["80001.26000000","0.02000000"],["80001.51000000","0.00000000"],["80004.39000000","0.00625000"],["80004.99000000","1.35199000"],["80010.35000000","0.00000000"],["80036.01000000","0.22709000"],["80060.01000000","0.00000000"],["80077.02000000","1.18192000"],["80101.99000000","0.01445000"],["80125.99000000","0.01569000"]]}}}
{"rx_ns": 10700252911500, "frame": {"stream":"btcusdt@depth20@100ms","data":{"lastUpdateId":99116121802,"bids":[["79983.99000000","3.54306000"],["79983.98000000","0.00076000"],["79983.97000000","0.00013000"],["79983.50000000","0.00021000"],["79983.49000000","0.08146000"],["79982.81000000","0.00007000"],["79982.75000000","0.00007000"],["79982.72000000","0.00014000"],["79982.71000000","0.01688000"],["79982.28000000","0.00007000"],["79981.99000000","0.00855000"],["79981.94000000","0.00007000"],["79981.77000000","0.00014000"],["79981.76000000","0.08652000"],["79981.54000000","0.00007000"],["79981.51000000","0.00014000"],["79981.44000000","0.00014000"],["79981.43000000","0.02023000"],["79981.29000000","0.00014000"],["79981.06000000","0.00007000"]],"asks":[["79984.00000000","1.80026000"],["79984.01000000","0.00027000"],["79984.02000000","0.00013000"],["79984.27000000","0.00007000"],["79984.61000000","0.00007000"],["79985.16000000","0.00021000"],["79985.50000000","0.00891000"],["79985.94000000","0.00007000"],["79985.98000000","0.00014000"],["79985.99000000","0.04429000"],["79986.00000000","0.02421000"],["79986.20000000","0.00007000"],["79986.28000000","0.00014000"],["79986.29000000","0.03050000"],["79986.63000000","0.00014000"],["79986.64000000","0.05309000"],["79986.77000000","0.00007000"],["79986.78000000","0.01465000"],["79986.95000000","0.00007000"],["79987.24000000","0.00007000"]]}}}
{"rx_ns": 10700253029600, "frame": {"stream":"btcusdt@depth@100ms","data":{"e":"depthUpdate","E":1787647695414,"s":"BTCUSDT","U":99116121729,"u":99116121802,"b":[["79983.99000000","3.54306000"],["79980.23000000","0.16320000"],["79979.99000000","0.14281000"],["79979.98000000","0.31267000"],["79973.04000000","0.00000000"],["79970.61000000","0.00007000"],["79970.45000000","0.00400000"],["79969.68000000","0.00014000"],["79962.60000000","0.37528000"],["79959.93000000","0.33776000"],["79938.84000000","0.00000000"],["79927.68000000","0.00400000"],["79926.57000000","0.02800000"],["79923.26000000","0.00000000"],["79906.26000000","0.00000000"],["79902.04000000","0.00000000"],["79808.85000000","0.00000000"],["71985.60000000","0.00448000"]],"a":[["79984.00000000","1.80026000"],["79986.15000000","0.00000000"],["79986.78000000","0.01465000"],["79989.31000000","0.00000000"],["79989.61000000","0.01756000"],["79989.84000000","0.03609000"],["79990.14000000","0.00586000"],["79990.52000000","0.00000000"],["79990.84000000","0.00092000"],["79990.91000000","0.00000000"],["79992.45000000","0.05123000"],["79994.08000000","0.08574000"],["79996.14000000","0.08491000"],["79996.15000000","0.00000000"],["79997.71000000","1.04939000"],["79997.72000000","0.00000000"],["79998.37000000","0.03134000"],["80009.78000000","0.01749000"],["80010.52000000","0.00000000"],["80014.54000000","0.42896000"],["80040.36000000","0.00400000"],["80045.73000000","0.00000000"],["80051.08000000","1.23707000"]]}}}
{"rx_ns": 10700361634200, "frame": {"stream":"btcusdt@depth20@100ms","data":{"lastUpdateId":99116121924,"bids":[["79983.99000000","0.63697000"],["79983.98000000","0.00076000"],["79983.97000000","0.00013000"],["79983.50000000","0.00021000"],["79983.49000000","0.08146000"],["79982.81000000","0.00007000"],["79982.75000000","0.00007000"],["79982.72000000","0.00014000"],["79982.71000000","0.01688000"],["79982.28000000","0.00007000"],["79981.99000000","0.00855000"],["79981.94000000","0.00007000"],["79981.76000000","0.00014000"],["79981.54000000","0.00007000"],["79981.51000000","0.00014000"],["79981.50000000","0.42211000"],["79981.44000000","0.00014000"],["79981.43000000","0.02023000"],["79981.29000000","0.00014000"],["79981.06000000","0.00007000"]],"asks":[["79984.00000000","2.21295000"],["79984.01000000","0.00027000"],["79984.02000000","0.00013000"],["79984.27000000","0.00007000"],["79984.61000000","0.00007000"],["79985.15000000","0.00079000"],["79985.16000000","0.00021000"],["79985.50000000","0.00891000"],["79985.94000000","0.00007000"],["79985.98000000","0.00014000"],["79985.99000000","0.04429000"],["79986.00000000","0.02421000"],["79986.20000000","0.00007000"],["79986.28000000","0.00014000"],["79986.29000000","0.03050000"],["79986.63000000","0.00014000"],["79986.64000000","0.05309000"],["79986.77000000","0.00007000"],["79986.78000000","0.01472000"],["79986.95000000","0.00007000"]]}}}
{"rx_ns": 10700361716500, "frame": {"stream":"btcusdt@depth@100ms","data":{"e":"depthUpdate","E":1787647695514,"s":"BTCUSDT","U":99116121803,"u":99116121924,"b":[["79983.99000000","0.63697000"],["79981.77000000","0.00000000"],["79981.76000000","0.00014000"],["79981.50000000","0.42211000"],["79981.29000000","0.00014000"],["79980.29000000","0.00000000"],["79979.99000000","0.14274000"],["79979.05000000","0.00000000"],["79978.94000000","0.00000000"],["79978.42000000","0.00904000"],["79978.41000000","0.00000000"],["79976.03000000","0.00000000"],["79975.60000000","0.00000000"],["79972.80000000","0.00625000"],["79972.79000000","0.00625000"],["79972.65000000","0.00048000"],["79972.01000000","0.00007000"],["79967.61000000","0.00400000"],["79966.01000000","0.00407000"],["79965.24000000","0.00000000"],["79964.35000000","0.00000000"],["79963.37000000","1.04939000"],["79961.95000000","0.15382000"],["79942.59000000","0.00007000"],["79797.96000000","0.00000000"],["79653.45000000","0.20250000"],["71985.60000000","0.00432000"],["71985.59000000","0.00008000"],["63987.20000000","0.00031000"]],"a":[["79984.00000000","2.21295000"],["79985.15000000","0.00079000"],["79986.78000000","0.01472000"],["79987.36000000","0.08574000"],["79987.63000000","0.05264000"],["79987.99000000","0.00000000"],["79988.26000000","0.08574000"],["79988.27000000","0.19713000"],["79989.37000000","0.04007000"],["79989.60000000","0.07884000"],["79989.61000000","0.01749000"],["79989.84000000","0.00000000"],["79990.72000000","0.08574000"],["79990.84000000","0.00000000"],["79991.60000000","0.00000000"],["79991.84000000","0.00000000"],["79991.99000000","0.00008000"],["79992.45000000","0.02815000"],["79993.44000000","0.03224000"],["79994.08000000","0.00000000"],["79994.14000000","0.00000000"],["79995.20000000","0.00000000"],["79996.14000000","0.00000000"],["80000.16000000","1.09067000"],["80000.22000000","1.87060000"],["80012.01000000","0.00250000"]]}}}
{"rx_ns": 10700452260100, "frame": {"stream":"btcusdt@depth20@100ms","data":{"lastUpdateId":99116121984,"bids":[["79983.99000000","0.84111000"],["79983.98000000","0.00090000"],["79983.97000000","0.00013000"],["79983.50000000","0.00021000"],["79983.49000000","0.08146000"],["79982.81000000","0.00007000"],["79982.75000000","0.00007000"],["79982.72000000","0.00014000"],["79982.71000000","0.01688000"],["79982.28000000","0.00007000"],["79981.99000000","0.00855000"],["79981.94000000","0.00007000"],["79981.54000000","0.00007000"],["79981.52000000","0.00014000"],["79981.51000000","0.21341000"],["79981.50000000","0.42225000"],["79981.43000000","0.02023000"],["79981.29000000","0.00014000"],["79981.06000000","0.00007000"],["79981.05000000","0.00014000"]],"asks":[["79984.00000000","2.21308000"],["79984.01000000","0.00027000"],["79984.02000000","0.00013000"],["79984.27000000","0.00007000"],["79984.61000000","0.00007000"],["79985.15000000","0.00079000"],["79985.16000000","0.00021000"],["79985.50000000","0.00891000"],["79985.94000000","0.00007000"],["79985.98000000","0.00014000"],["79985.99000000","0.07995000"],["79986.00000000","0.02421000"],["79986.20000000","0.00007000"],["79986.28000000","0.00014000"],["79986.29000000","0.03050000"],["79986.63000000","0.00014000"],["79986.64000000","0.05309000"],["79986.77000000","0.00007000"],["79986.78000000","0.01479000"],["79986.95000000","0.00007000"]]}}}
{"rx_ns": 10700452343100, "frame": {"stream":"btcusdt@depth@100ms","data":{"e":"depthUpdate","E":1787647695614,"s":"BTCUSDT","U":99116121925,"u":99116121984,"b":[["79983.99000000","0.84111000"],["79983.98000000","0.00090000"],["79981.99000000","0.00855000"],["79981.76000000","0.00000000"],["79981.52000000","0.00014000"],["79981.51000000","0.21341000"],["79981.50000000","0.42225000"],["79981.44000000","0.00000000"],["79972.79000000","0.00000000"],["79971.00000000","0.00625000"],["71985.60000000","0.00432000"],["63987.20000000","0.00000000"],["42091.80000000","0.00036000"]],"a":[["79984.00000000","2.21308000"],["79985.99000000","0.07995000"],["79986.78000000","0.01479000"],["79987.36000000","0.00014000"],["79987.63000000","0.05278000"],["79988.00000000","0.02414000"],["79988.06000000","0.01769000"],["79988.27000000","0.17566000"],["79989.37000000","0.04000000"],["79989.60000000","0.00000000"],["79991.60000000","0.01307000"],["79999.17000000","0.00047000"],["79999.45000000","0.00069000"],["80009.54000000","0.00000000"],["80009.56000000","0.00000000"],["80034.10000000","0.00400000"],["80040.36000000","0.00000000"]]}}}
{"rx_ns": 10700557775400, "frame": {"stream":"btcusdt@depth20@100ms","data":{"lastUpdateId":99116122020,"bids":[["79983.99000000","0.84111000"],["79983.98000000","0.00090000"],["79983.97000000","0.00013000"],["79983.50000000","0.00021000"],["79983.49000000","0.08146000"],["79983.24000000","0.00037000"],["79982.81000000","0.00007000"],["79982.75000000","0.00007000"],["79982.72000000","0.00014000"],["79982.71000000","0.01688000"],["79982.28000000","0.00007000"],["79981.99000000","0.00855000"],["79981.94000000","0.00007000"],["79981.54000000","0.00007000"],["79981.52000000","0.00014000"],["79981.51000000","0.21355000"],["79981.50000000","0.42225000"],["79981.43000000","0.02023000"],["79981.29000000","0.00014000"],["79981.06000000","0.00007000"]],"asks":[["79984.00000000","2.22470000"],["79984.01000000","0.00027000"],["79984.02000000","0.00013000"],["79984.27000000","0.00007000"],["79984.61000000","0.00007000"],["79985.15000000","0.00079000"],["79985.16000000","0.00021000"],["79985.50000000","0.00891000"],["79985.94000000","0.00007000"],["79985.98000000","0.00014000"],["79985.99000000","0.07995000"],["79986.00000000","0.02421000"],["79986.20000000","0.00007000"],["79986.28000000","0.00014000"],["79986.29000000","0.03057000"],["79986.30000000","0.00581000"],["79986.63000000","0.00014000"],["79986.64000000","0.05309000"],["79986.77000000","0.00007000"],["79986.78000000","0.01472000"]]}}}
{"rx_ns": 10700557909000, "frame": {"stream":"btcusdt@depth@100ms","data":{"e":"depthUpdate","E":1787647695714,"s":"BTCUSDT","U":99116121985,"u":99116122020,"b":[["79983.24000000","0.00037000"],["79981.99000000","0.00855000"],["79981.51000000","0.21355000"],["79980.40000000","0.10992000"],["79980.23000000","0.16306000"],["79904.41000000","0.00000000"],["79813.37000000","0.01958000"],["79803.55000000","0.00000000"],["71985.60000000","0.00432000"]],"a":[["79984.00000000","2.22470000"],["79986.29000000","0.03057000"],["79986.30000000","0.00581000"],["79986.78000000","0.01472000"],["79987.36000000","0.00000000"],["79987.63000000","0.00014000"],["79988.00000000","0.02428000"],["80002.00000000","0.12845000"],["80026.03000000","0.00000000"],["80134.24000000","0.00000000"],["80172.40000000","0.00000000"]]}}}
{"rx_ns": 10700652742900, "frame": {"stream":"btcusdt@depth20@100ms","data":{"lastUpdateId":99116122111,"bids":[["79983.99000000","0.63674000"],["79983.98000000","0.00083000"],["79983.97000000","0.00013000"],["79983.50000000","0.00021000"],["79983.49000000","0.08146000"],["79983.24000000","0.00037000"],["79982.81000000","0.00007000"],["79982.75000000","0.00007000"],["79982.72000000","0.00014000"],["79982.71000000","0.01688000"],["79982.28000000","0.00007000"],["79981.99000000","0.00855000"],["79981.94000000","0.00007000"],["79981.54000000","0.00007000"],["79981.51000000","0.00028000"],["79981.50000000","0.00014000"],["79981.44000000","0.00014000"],["79981.43000000","0.02023000"],["79981.29000000","0.00007000"],["79981.06000000","0.00007000"]],"asks":[["79984.00000000","2.22396000"],["79984.01000000","0.00027000"],["79984.02000000","0.00013000"],["79984.27000000","0.00007000"],["79984.61000000","0.00007000"],["79985.15000000","0.00079000"],["79985.16000000","0.00021000"],["79985.50000000","0.00898000"],["79985.94000000","0.00007000"],["79985.97000000","0.00014000"],["79985.98000000","0.01763000"],["79985.99000000","0.06601000"],["79986.00000000","0.02421000"],["79986.20000000","0.00007000"],["79986.28000000","0.00014000"],["79986.29000000","0.03057000"],["79986.30000000","0.00595000"],["79986.63000000","0.00014000"],["79986.64000000","0.05309000"],["79986.78000000","0.01472000"]]}}}
{"rx_ns": 10700652864900, "frame": {"stream":"btcusdt@depth@100ms","data":{"e":"depthUpdate","E":1787647695814,"s":"BTCUSDT","U":99116122021,"u":99116122111,"b":[["79983.99000000","0.63674000"],["79983.98000000","0.00083000"],["79981.52000000","0.00000000"],["79981.51000000","0.00028000"],["79981.50000000","0.00014000"],["79981.44000000","0.00014000"],["79981.29000000","0.00007000"],["79980.64000000","0.00021000"],["79980.41000000","0.00007000"],["79976.02000000","0.00000000"],["79973.26000000","0.00000000"],["79969.04000000","0.00162000"],["79900.71000000","0.00000000"],["79899.24000000","0.12299000"],["79894.33000000","0.00000000"],["71985.60000000","0.00448000"]],"a":[["79984.00000000","2.22396000"],["79985.50000000","0.00898000"],["79985.97000000","0.00014000"],["79985.98000000","0.01763000"],["79985.99000000","0.06601000"],["79986.29000000","0.03057000"],["79986.30000000","0.00595000"],["79986.77000000","0.00000000"],["79986.78000000","0.01472000"],["79987.36000000","0.08575000"],["79987.63000000","0.00000000"],["79989.37000000","0.04007000"],["79989.60000000","0.07802000"],["79990.71000000","0.00772000"],["79990.72000000","0.00000000"],["79992.00000000","0.22671000"],["79992.45000000","0.45648000"],["79993.70000000","1.04939000"],["79995.99000000","0.36586000"],["80004.48000000","0.14973000"],["80010.55000000","0.02399000"],["80014.55000000","0.00000000"],["80020.02000000","0.20250000"],["80050.56000000","0.00399000"],["80054.56000000","0.00000000"],["80085.41000000","0.00000000"],["80086.57000000","0.00000000"],["80098.89000000","0.00393000"],["80130.57000000","0.00399000"],["80134.58000000","0.00000000"],["80202.58000000","0.00399000"],["80206.59000000","0.00000000"]]}}}
{"rx_ns": 10700754134400, "frame": {"stream":"btcusdt@depth20@100ms","data":{"lastUpdateId":99116122244,"bids":[["79983.99000000","0.63450000"],["79983.98000000","0.00076000"],["79983.97000000","0.00013000"],["79983.50000000","0.00021000"],["79983.49000000","0.08146000"],["79983.24000000","0.00037000"],["79982.81000000","0.00007000"],["79982.75000000","0.00007000"],["79982.72000000","0.00014000"],["79982.71000000","0.01688000"],["79982.28000000","0.00007000"],["79981.99000000","0.00028000"],["79981.94000000","0.00007000"],["79981.54000000","0.00007000"],["79981.51000000","0.00014000"],["79981.44000000","0.00014000"],["79981.43000000","0.02023000"],["79981.29000000","0.00007000"],["79981.06000000","0.00303000"],["79981.05000000","0.00014000"]],"asks":[["79984.00000000","2.25002000"],["79984.01000000","0.00027000"],["79984.02000000","0.00013000"],["79984.27000000","0.00007000"],["79984.61000000","0.00007000"],["79985.16000000","0.00021000"],["79985.50000000","0.00905000"],["79985.94000000","0.00007000"],["79985.96000000","0.10184000"],["79985.97000000","0.07766000"],["79985.98000000","0.01777000"],["79985.99000000","0.00028000"],["79986.00000000","0.02421000"],["79986.20000000","0.00007000"],["79986.29000000","0.00035000"],["79986.30000000","0.00595000"],["79986.63000000","0.00014000"],["79986.64000000","0.05316000"],["79986.66000000","0.03224000"],["79986.78000000","0.01472000"]]}}}
{"rx_ns": 10700754218900, "frame": {"stream":"btcusdt@depth@100ms","data":{"e":"depthUpdate","E":1787647695914,"s":"BTCUSDT","U":99116122112,"u":99116122244,"b":[["79983.99000000","0.63450000"],["79983.98000000","0.00076000"],["79981.99000000","0.00028000"],["79981.51000000","0.00014000"],["79981.50000000","0.00000000"],["79981.06000000","0.00303000"],["79981.04000000","0.04736000"],["79980.64000000","0.00007000"],["79980.40000000","0.11006000"],["79980.23000000","0.16320000"],["79980.15000000","0.02023000"],["79979.99000000","0.14011000"],["79978.29000000","0.72511000"],["79976.00000000","0.18684000"],["79975.89000000","0.00000000"],["79975.83000000","0.00000000"],["79975.73000000","0.00858000"],["79975.11000000","0.00000000"],["79975.10000000","0.00000000"],["79975.03000000","0.00000000"],["79975.00000000","0.00000000"],["79972.72000000","0.00000000"],["79971.89000000","0.00000000"],["79971.87000000","0.00000000"],["79971.11000000","0.00000000"],["79971.04000000","0.00000000"],["79971.00000000","0.00000000"],["79970.99000000","0.00000000"],["79969.23000000","0.00000000"],["79969.05000000","0.00625000"],["79965.87000000","0.00000000"],["79960.65000000","0.02000000"],["79959.93000000","0.00000000"],["79953.50000000","0.00000000"],["79938.72000000","0.00007000"],["79938.67000000","0.04539000"],["79938.07000000","0.33786000"],["79899.24000000","0.00000000"],["79894.34000000","0.00065000"],["79889.05000000","0.62495000"],["79797.87000000","4.37398000"],["71985.60000000","0.00432000"]],"a":[["79984.00000000","2.25002000"],["79985.15000000","0.00000000"],["79985.50000000","0.00905000"],["79985.96000000","0.10184000"],["79985.97000000","0.07766000"],["79985.98000000","0.01777000"],["79985.99000000","0.00028000"],["79986.28000000","0.00000000"],["79986.29000000","0.00035000"],["79986.64000000","0.05316000"],["79986.66000000","0.03224000"],["79986.78000000","0.01472000"],["79987.15000000","0.00400000"],["79988.00000000","0.02414000"],["79988.06000000","0.01769000"],["79988.23000000","0.08575000"],["79988.24000000","0.44654000"],["79988.25000000","1.04939000"],["79988.26000000","0.00000000"],["79988.27000000","0.00000000"],["79989.37000000","0.04000000"],["79989.60000000","0.00000000"],["79990.71000000","0.00000000"],["79992.45000000","0.96187000"],["79993.68000000","0.13341000"],["79993.69000000","1.87060000"],["80005.16000000","0.00000000"],["80010.00000000","0.12424000"],["80010.55000000","0.02000000"],["80035.80000000","0.00000000"],["80050.56000000","0.00000000"],["80082.56000000","0.00399000"],["80167.88000000","4.62654000"],["80202.58000000","0.00000000"],["80500.00000000","2.87147000"]]}}}
{"rx_ns": 10700854202700, "frame": {"stream":"btcusdt@depth20@100ms","data":{"lastUpdateId":99116122380,"bids":[["79983.99000000","0.24512000"],["79983.98000000","0.00083000"],["79983.97000000","0.00013000"],["79983.50000000","0.00021000"],["79983.49000000","0.08146000"],["79983.24000000","0.00037000"],["79982.81000000","0.00007000"],["79982.75000000","0.00007000"],["79982.72000000","0.00014000"],["79982.71000000","0.01688000"],["79982.28000000","0.00007000"],["79981.99000000","0.00014000"],["79981.94000000","0.00007000"],["79981.54000000","0.00007000"],["79981.51000000","0.00014000"],["79981.44000000","0.00014000"],["79981.43000000","0.02023000"],["79981.29000000","0.00007000"],["79981.06000000","0.00303000"],["79981.05000000","0.00014000"]],"asks":[["79984.00000000","2.42715000"],["79984.01000000","0.00027000"],["79984.02000000","0.00013000"],["79984.27000000","0.00007000"],["79984.61000000","0.00007000"],["79985.12000000","0.08575000"],["79985.14000000","0.00007000"],["79985.16000000","0.00021000"],["79985.50000000","0.00912000"],["79985.94000000","0.00007000"],["79985.96000000","0.10184000"],["79985.97000000","0.07766000"],["79985.98000000","0.01763000"],["79986.00000000","0.02421000"],["79986.20000000","0.00007000"],["79986.29000000","0.00021000"],["79986.30000000","0.00595000"],["79986.64000000","0.05316000"],["79986.66000000","0.03238000"],["79986.78000000","0.01458000"]]}}}
{"rx_ns": 10700854321000, "frame": {"stream":"btcusdt@depth@100ms","data":{"e":"depthUpdate","E":1787647696014,"s":"BTCUSDT","U":99116122245,"u":99116122380,"b":[["79983.99000000","0.24512000"],["79983.98000000","0.00083000"],["79982.71000000","0.01688000"],["79981.99000000","0.00014000"],["79980.41000000","0.00000000"],["79980.40000000","0.00014000"],["79980.23000000","0.00302000"],["79979.99000000","0.00041000"],["79979.98000000","0.00000000"],["79978.61000000","0.00000000"],["79978.29000000","0.00870000"],["79978.28000000","0.00860000"],["79977.99000000","0.00007000"],["79977.42000000","0.00007000"],["79976.90000000","0.00007000"],["79976.67000000","0.00007000"],["79976.29000000","0.00598000"],["79976.01000000","0.00000000"],["79976.00000000","0.14028000"],["79975.83000000","0.42211000"],["79972.90000000","0.31269000"],["79972.80000000","0.00000000"],["79972.78000000","0.00000000"],["79971.89000000","0.08576000"],["79969.04000000","0.00000000"],["79968.54000000","0.00625000"],["79966.64000000","0.02400000"],["79964.23000000","0.02000000"],["79962.60000000","0.00000000"],["79960.25000000","0.00000000"],["79960.00000000","0.02407000"],["79957.98000000","0.00000000"],["79956.02000000","0.00625000"],["79955.87000000","0.36273000"],["79954.63000000","0.62538000"],["79952.69000000","0.00000000"],["79934.85000000","0.00007000"],["79911.66000000","0.93339000"],["79909.60000000","1.23926000"],["79909.40000000","0.02000000"],["79898.40000000","0.12388000"],["79895.61000000","0.02084000"],["78784.23000000","0.00030000"],["71985.60000000","0.00432000"],["71985.00000000","0.00000000"],["63987.20000000","0.00031000"]],"a":[["79984.00000000","2.42715000"],["79985.12000000","0.08575000"],["79985.14000000","0.00007000"],["79985.50000000","0.00912000"],["79985.95000000","0.00000000"],["79985.96000000","0.10184000"],["79985.97000000","0.07766000"],["79985.98000000","0.01763000"],["79985.99000000","0.00000000"],["79986.00000000","0.02421000"],["79986.29000000","0.00021000"],["79986.63000000","0.00000000"],["79986.64000000","0.05316000"],["79986.66000000","0.03238000"],["79986.78000000","0.01458000"],["79987.36000000","0.00773000"],["79988.23000000","0.00000000"],["79988.69000000","0.02000000"],["79993.88000000","0.00000000"],["79995.16000000","0.33761000"],["79995.55000000","0.00625000"],["79995.98000000","0.36586000"],["79995.99000000","0.00000000"],["79996.59000000","0.08566000"],["79997.47000000","0.37775000"],["79997.48000000","0.00000000"],["79997.90000000","0.00000000"],["80000.00000000","0.12130000"],["80000.04000000","0.62518000"],["80000.15000000","0.62538000"],["80004.39000000","0.00000000"],["80009.97000000","0.62510000"],["80015.36000000","0.00000000"],["80020.00000000","0.11773000"],["80023.27000000","0.00000000"],["80051.08000000","0.00000000"]]}}}
{"rx_ns": 10700957924300, "frame": {"stream":"btcusdt@depth20@100ms","data":{"lastUpdateId":99116122453,"bids":[["79983.99000000","0.24431000"],["79983.98000000","0.00083000"],["79983.97000000","0.00013000"],["79983.50000000","0.00021000"],["79983.49000000","0.08146000"],["79983.24000000","0.00037000"],["79982.81000000","0.00007000"],["79982.75000000","0.00007000"],["79982.72000000","0.00014000"],["79982.71000000","0.01688000"],["79982.28000000","0.00007000"],["79981.99000000","0.00014000"],["79981.94000000","0.00007000"],["79981.54000000","0.00007000"],["79981.51000000","0.00014000"],["79981.44000000","0.00014000"],["79981.43000000","0.02023000"],["79981.29000000","0.00007000"],["79981.06000000","0.00303000"],["79981.05000000","0.00014000"]],"asks":[["79984.00000000","2.43302000"],["79984.01000000","0.00027000"],["79984.02000000","0.00413000"],["79984.27000000","0.00007000"],["79984.61000000","0.00007000"],["79985.12000000","0.08589000"],["79985.14000000","0.00007000"],["79985.16000000","0.00021000"],["79985.50000000","0.00905000"],["79985.94000000","0.00007000"],["79985.96000000","0.10184000"],["79985.97000000","0.07766000"],["79985.98000000","0.01763000"],["79986.00000000","0.02421000"],["79986.20000000","0.00007000"],["79986.29000000","0.00021000"],["79986.30000000","0.00595000"],["79986.64000000","0.05316000"],["79986.66000000","0.03224000"],["79986.78000000","0.01458000"]]}}}
{"rx_ns": 10700958066600, "frame": {"stream":"btcusdt@depth@100ms","data":{"e":"depthUpdate","E":1787647696114,"s":"BTCUSDT","U":99116122381,"u":99116122453,"b":[["79983.99000000","0.24431000"],["79981.04000000","0.04729000"],["79980.64000000","0.00000000"],["79980.40000000","0.00000000"],["79980.23000000","0.00288000"],["79980.15000000","0.02023000"],["79979.99000000","0.00020000"],["79978.42000000","0.00918000"],["79978.31000000","0.00026000"],["79978.29000000","0.00884000"],["79978.28000000","0.00874000"],["79976.30000000","0.00000000"],["79976.29000000","0.00605000"],["79976.15000000","0.08575000"],["79976.01000000","0.08575000"],["79976.00000000","0.31576000"],["79966.68000000","0.02000000"],["79913.11000000","0.00000000"],["79889.05000000","0.00000000"],["79850.24000000","0.00000000"],["79845.39000000","0.04528000"],["79781.65000000","0.00000000"],["79778.60000000","0.00770000"],["71985.60000000","0.00432000"]],"a":[["79984.00000000","2.43302000"],["79984.02000000","0.00413000"],["79985.12000000","0.08589000"],["79985.50000000","0.00905000"],["79986.66000000","0.03224000"],["79986.78000000","0.01458000"],["79987.35000000","0.07758000"],["79987.36000000","0.00000000"],["79988.06000000","0.01762000"],["79988.28000000","0.12508000"],["79996.44000000","0.02000000"],["80006.24000000","0.49370000"],["80024.87000000","0.00434000"],["80030.26000000","0.00632000"],["80030.95000000","0.00430000"],["80030.97000000","0.00400000"],["80032.00000000","0.02414000"],["80034.10000000","0.00000000"],["80035.73000000","0.00000000"],["80040.89000000","0.00000000"],["80042.74000000","0.00000000"],["80050.56000000","0.00399000"],["80064.44000000","0.00000000"],["80090.16000000","0.00000000"]]}}}
{"rx_ns": 10701052491400, "frame": {"stream":"btcusdt@depth20@100ms","data":{"lastUpdateId":99116122497,"bids":[["79983.99000000","0.24422000"],["79983.98000000","0.00083000"],["79983.97000000","0.00013000"],["79983.50000000","0.00021000"],["79983.49000000","0.08146000"],["79983.24000000","0.00037000"],["79982.81000000","0.00007000"],["79982.75000000","0.00007000"],["79982.72000000","0.00014000"],["79982.71000000","0.01688000"],["79982.28000000","0.00007000"],["79981.99000000","0.00014000"],["79981.94000000","0.00007000"],["79981.54000000","0.00007000"],["79981.51000000","0.00014000"],["79981.44000000","0.00014000"],["79981.43000000","0.02023000"],["79981.29000000","0.00007000"],["79981.06000000","0.00303000"],["79981.05000000","0.00014000"]],"asks":[["79984.00000000","2.47302000"],["79984.01000000","0.00027000"],["79984.02000000","0.00413000"],["79984.27000000","0.00007000"],["79984.61000000","0.00007000"],["79985.12000000","0.08589000"],["79985.14000000","0.00007000"],["79985.16000000","0.00021000"],["79985.50000000","0.00905000"],["79985.94000000","0.00007000"],["79985.96000000","0.10184000"],["79985.97000000","0.07766000"],["79985.98000000","0.01763000"],["79986.00000000","0.02421000"],["79986.20000000","0.00007000"],["79986.29000000","0.00021000"],["79986.30000000","0.00595000"],["79986.64000000","0.05316000"],["79986.66000000","0.03224000"],["79986.78000000","0.01458000"]]}}}
{"rx_ns": 10701052571400, "frame": {"stream":"btcusdt@depth@100ms","data":{"e":"depthUpdate","E":1787647696214,"s":"BTCUSDT","U":99116122454,"u":99116122497,"b":[["79983.99000000","0.24422000"],["79983.98000000","0.00083000"],["79981.04000000","0.05026000"],["79980.23000000","0.00007000"],["79978.39000000","0.08176000"],["79978.10000000","0.02481000"],["79977.27000000","0.08575000"],["79976.29000000","0.00014000"],["79975.59000000","0.00000000"],["79972.09000000","0.00000000"],["79971.58000000","0.00000000"],["79970.95000000","0.00435000"],["79969.98000000","0.00000000"],["79968.75000000","0.00007000"],["79966.53000000","0.02000000"],["79955.06000000","0.00000000"],["79934.85000000","0.00000000"],["79911.53000000","0.38586000"],["79895.61000000","0.00000000"],["79845.39000000","0.00000000"],["71985.60000000","0.00432000"],["71985.59000000","0.00000000"],["71985.58000000","0.00008000"],["63987.20000000","0.00000000"]],"a":[["79984.00000000","2.47302000"],["79989.34000000","0.01748000"],["79989.37000000","0.00000000"],["79996.51000000","0.02000000"],["80000.75000000","0.00007000"],["80080.63000000","0.02804000"],["80703.85000000","0.00000000"],["80726.38000000","0.00122000"],["81183.76000000","0.00030000"]]}}}
{"rx_ns": 10701153369600, "frame": {"stream":"btcusdt@depth20@100ms","data":{"lastUpdateId":99116122545,"bids":[["79983.99000000","0.24477000"],["79983.98000000","0.00083000"],["79983.97000000","0.00013000"],["79983.50000000","0.00021000"],["79983.49000000","0.08146000"],["79983.24000000","0.00037000"],["79982.81000000","0.00007000"],["79982.75000000","0.00007000"],["79982.72000000","0.00014000"],["79982.71000000","0.01688000"],["79982.28000000","0.00007000"],["79981.99000000","0.00014000"],["79981.94000000","0.00007000"],["79981.54000000","0.00007000"],["79981.51000000","0.00014000"],["79981.44000000","0.00014000"],["79981.43000000","0.02023000"],["79981.29000000","0.00007000"],["79981.06000000","0.00303000"],["79981.05000000","0.00014000"]],"asks":[["79984.00000000","2.37685000"],["79984.01000000","0.00027000"],["79984.02000000","0.00413000"],["79984.27000000","0.00007000"],["79984.61000000","0.00007000"],["79985.12000000","0.08589000"],["79985.14000000","0.00007000"],["79985.16000000","0.00021000"],["79985.50000000","0.00905000"],["79985.94000000","0.00007000"],["79985.96000000","0.10184000"],["79985.97000000","0.07766000"],["79985.98000000","0.01763000"],["79986.00000000","0.02421000"],["79986.20000000","0.00007000"],["79986.29000000","0.00021000"],["79986.30000000","0.00595000"],["79986.64000000","0.05316000"],["79986.66000000","0.03224000"],["79986.78000000","0.01458000"]]}}}
{"rx_ns": 10701153462100, "frame": {"stream":"btcusdt@depth@100ms","data":{"e":"depthUpdate","E":1787647696314,"s":"BTCUSDT","U":99116122498,"u":99116122545,"b":[["79983.99000000","0.24477000"],["79980.16000000","0.00007000"],["79978.42000000","0.00925000"],["79978.39000000","0.08190000"],["79978.28000000","0.00860000"],["79976.00000000","0.01207000"],["79975.55000000","0.12791000"],["79974.00000000","0.02400000"],["79966.48000000","0.02400000"],["79955.04000000","0.00000000"],["79955.00000000","0.00000000"],["79954.97000000","0.00007000"],["79901.45000000","0.02400000"],["79899.74000000","0.02200000"],["79893.40000000","0.31762000"],["79842.66000000","0.04528000"],["71985.60000000","0.00448000"],["63987.19000000","0.00000000"],["63987.00000000","0.00000000"]],"a":[["79984.00000000","2.37685000"],["79996.45000000","0.02000000"],["80006.82000000","0.00000000"],["80006.93000000","0.00000000"],["80006.97000000","0.00000000"],["80010.55000000","0.02399000"],["80024.58000000","0.64027000"],["80048.39000000","0.85180000"],["80077.02000000","0.00000000"],["80096.22000000","0.00000000"]]}}}
{"rx_ns": 10701261754100, "frame": {"stream":"btcusdt@depth20@100ms","data":{"lastUpdateId":99116122572,"bids":[["79983.99000000","0.48470000"],["79983.98000000","0.00083000"],["79983.97000000","0.00013000"],["79983.50000000","0.00021000"],["79983.49000000","0.08146000"],["79983.24000000","0.00037000"],["79982.81000000","0.00007000"],["79982.75000000","0.00007000"],["79982.72000000","0.00014000"],["79982.71000000","0.01688000"],["79982.28000000","0.00007000"],["79981.99000000","0.00014000"],["79981.94000000","0.00007000"],["79981.54000000","0.00007000"],["79981.51000000","0.00014000"],["79981.44000000","0.00014000"],["79981.43000000","0.02023000"],["79981.29000000","0.00007000"],["79981.06000000","0.00303000"],["79981.05000000","0.00014000"]],"asks":[["79984.00000000","2.29565000"],["79984.01000000","0.00027000"],["79984.02000000","0.00413000"],["79984.27000000","0.00007000"],["79984.61000000","0.00007000"],["79985.11000000","0.00014000"],["79985.12000000","0.00014000"],["79985.14000000","0.00007000"],["79985.16000000","0.00021000"],["79985.50000000","0.00905000"],["79985.94000000","0.00007000"],["79985.95000000","0.00014000"],["79985.96000000","0.10198000"],["79985.97000000","0.00028000"],["79985.98000000","0.01763000"],["79985.99000000","0.00007000"],["79986.00000000","0.02421000"],["79986.20000000","0.00007000"],["79986.29000000","0.00021000"],["79986.30000000","0.00595000"]]}}}
{"rx_ns": 10701261876300, "frame": {"stream":"btcusdt@depth@100ms","data":{"e":"depthUpdate","E":1787647696414,"s":"BTCUSDT","U":99116122546,"u":99116122572,"b":[["79983.99000000","0.48470000"],["79979.51000000","0.08575000"],["79976.50000000","0.03820000"],["79976.00000000","0.01707000"],["79975.55000000","0.00000000"],["79974.29000000","0.08575000"],["79972.91000000","0.08575000"],["79970.95000000","0.00000000"],["79970.90000000","0.00449000"],["71985.60000000","0.00432000"]],"a":[["79984.00000000","2.29565000"],["79985.11000000","0.00014000"],["79985.12000000","0.00014000"],["79985.95000000","0.00014000"],["79985.96000000","0.10198000"],["79985.97000000","0.00028000"],["79985.99000000","0.00007000"],["79998.37000000","0.00000000"]]}}}
{"rx_ns": 10701358129700, "frame": {"stream":"btcusdt@depth20@100ms","data":{"lastUpdateId":99116122635,"bids":[["79983.99000000","0.24480000"],["79983.98000000","0.00083000"],["79983.97000000","0.00013000"],["79983.50000000","0.00021000"],["79983.49000000","0.08146000"],["79983.24000000","0.00037000"],["79982.81000000","0.00007000"],["79982.75000000","0.00007000"],["79982.72000000","0.00014000"],["79982.71000000","0.01688000"],["79982.28000000","0.00007000"],["79981.99000000","0.00014000"],["79981.94000000","0.00007000"],["79981.54000000","0.00007000"],["79981.51000000","0.00014000"],["79981.44000000","0.00014000"],["79981.43000000","0.02023000"],["79981.29000000","0.00007000"],["79981.06000000","0.00303000"],["79981.05000000","0.00014000"]],"asks":[["79984.00000000","2.29678000"],["79984.01000000","0.00027000"],["79984.02000000","0.00413000"],["79984.27000000","0.00007000"],["79984.61000000","0.00007000"],["79985.14000000","0.00007000"],["79985.16000000","0.00021000"],["79985.50000000","0.00905000"],["79985.94000000","0.00007000"],["79985.95000000","0.00014000"],["79985.96000000","0.07604000"],["79985.97000000","0.00014000"],["79985.98000000","0.01763000"],["79985.99000000","0.00014000"],["79986.00000000","0.02421000"],["79986.20000000","0.00007000"],["79986.29000000","0.00021000"],["79986.30000000","0.00595000"],["79986.63000000","0.00014000"],["79986.64000000","0.05316000"]]}}}
{"rx_ns": 10701358230600, "frame": {"stream":"btcusdt@depth@100ms","data":{"e":"depthUpdate","E":1787647696514,"s":"BTCUSDT","U":99116122573,"u":99116122635,"b":[["79983.99000000","0.24480000"],["79980.15000000","0.02030000"],["79979.51000000","0.08589000"],["79978.29000000","0.00870000"],["79975.84000000","0.36818000"],["79962.59000000","0.02000000"],["79909.13000000","0.02000000"],["71985.60000000","0.00448000"],["63987.20000000","0.00031000"],["42091.80000000","0.00000000"]],"a":[["79984.00000000","2.29678000"],["79985.11000000","0.00000000"],["79985.12000000","0.00000000"],["79985.96000000","0.07604000"],["79985.97000000","0.00014000"],["79985.99000000","0.00014000"],["79986.63000000","0.00014000"],["79986.65000000","0.00007000"],["79986.66000000","0.03238000"],["79986.78000000","0.01472000"],["79988.06000000","0.01769000"],["79988.23000000","0.08575000"],["80000.32000000","0.02000000"],["80050.56000000","0.00000000"],["80187.14000000","0.01958000"],["80195.26000000","0.00000000"],["80202.58000000","0.00399000"]]}}}
{"rx_ns": 10701451631600, "frame": {"stream":"btcusdt@depth20@100ms","data":{"lastUpdateId":99116122646,"bids":[["79983.99000000","0.24487000"],["79983.98000000","0.00083000"],["79983.97000000","0.00013000"],["79983.50000000","0.00021000"],["79983.49000000","0.08146000"],["79983.24000000","0.00037000"],["79982.81000000","0.00007000"],["79982.75000000","0.00007000"],["79982.72000000","0.00014000"],["79982.71000000","0.01688000"],["79982.28000000","0.00007000"],["79981.99000000","0.00014000"],["79981.94000000","0.00007000"],["79981.54000000","0.00007000"],["79981.51000000","0.00014000"],["79981.44000000","0.00014000"],["79981.43000000","0.02023000"],["79981.29000000","0.00007000"],["79981.06000000","0.00303000"],["79981.05000000","0.00014000"]],"asks":[["79984.00000000","2.29678000"],["79984.01000000","0.00027000"],["79984.02000000","0.00413000"],["79984.27000000","0.00007000"],["79984.61000000","0.00007000"],["79985.16000000","0.00021000"],["79985.50000000","0.00905000"],["79985.94000000","0.00007000"],["79985.95000000","0.00014000"],["79985.96000000","0.07604000"],["79985.97000000","0.00014000"],["79985.98000000","0.01763000"],["79985.99000000","0.00014000"],["79986.00000000","0.02421000"],["79986.20000000","0.00007000"],["79986.29000000","0.00021000"],["79986.30000000","0.00595000"],["79986.63000000","0.00014000"],["79986.64000000","0.05316000"],["79986.65000000","0.00007000"]]}}}
{"rx_ns": 10701451737500, "frame": {"stream":"btcusdt@depth@100ms","data":{"e":"depthUpdate","E":1787647696614,"s":"BTCUSDT","U":99116122636,"u":99116122646,"b":[["79983.99000000","0.24487000"],["79978.10000000","0.02488000"],["79977.79000000","0.11536000"],["79976.50000000","0.00000000"],["79963.38000000","0.39095000"],["79909.94000000","0.02200000"],["79886.41000000","0.62495000"],["71985.60000000","0.00432000"],["63987.20000000","0.00000000"]],"a":[["79985.14000000","0.00000000"],["79999.54000000","0.02000000"]]}}}
{"rx_ns": 10701562690600, "frame": {"stream":"btcusdt@depth20@100ms","data":{"lastUpdateId":99116122673,"bids":[["79983.99000000","0.23243000"],["79983.98000000","0.00083000"],["79983.97000000","0.00013000"],["79983.50000000","0.00021000"],["79983.49000000","0.08146000"],["79983.24000000","0.00037000"],["79982.81000000","0.00007000"],["79982.75000000","0.00007000"],["79982.72000000","0.00014000"],["79982.71000000","0.01688000"],["79982.28000000","0.00007000"],["79981.99000000","0.00014000"],["79981.94000000","0.00007000"],["79981.54000000","0.00007000"],["79981.51000000","0.00014000"],["79981.44000000","0.00014000"],["79981.43000000","0.02023000"],["79981.29000000","0.00007000"],["79981.06000000","0.00303000"],["79981.05000000","0.00014000"]],"asks":[["79984.00000000","2.29678000"],["79984.01000000","0.00027000"],["79984.02000000","0.00413000"],["79984.27000000","0.00007000"],["79984.61000000","0.00007000"],["79985.16000000","0.00021000"],["79985.50000000","0.00905000"],["79985.94000000","0.00007000"],["79985.95000000","0.00014000"],["79985.96000000","0.07604000"],["79985.97000000","0.00014000"],["79985.98000000","0.01763000"],["79985.99000000","0.00014000"],["79986.00000000","0.02421000"],["79986.20000000","0.00007000"],["79986.29000000","0.00021000"],["79986.30000000","0.00595000"],["79986.63000000","0.00014000"],["79986.64000000","0.05316000"],["79986.65000000","0.00007000"]]}}}
{"rx_ns": 10701562840500, "frame": {"stream":"btcusdt@depth@100ms","data":{"e":"depthUpdate","E":1787647696714,"s":"BTCUSDT","U":99116122647,"u":99116122673,"b":[["79983.99000000","0.23243000"],["79981.04000000","0.05033000"],["79980.64000000","0.00007000"],["79980.63000000","0.08575000"],["79979.51000000","0.08596000"],["79978.69000000","0.04084000"],["79978.10000000","0.02481000"],["79977.79000000","0.00000000"],["79962.58000000","0.02000000"],["79951.84000000","0.00000000"],["79951.08000000","0.00000000"],["79951.01000000","0.00000000"],["79910.48000000","0.02000000"],["71985.60000000","0.00448000"]],"a":[["79994.12000000","0.06578000"],["79995.00000000","0.70000000"],["80010.14000000","0.00000000"],["80010.91000000","0.00000000"],["80050.21000000","0.00399000"],["80202.58000000","0.00000000"]]}}}
{"rx_ns": 10701652582700, "frame": {"stream":"btcusdt@depth20@100ms","data":{"lastUpdateId":99116122705,"bids":[["79983.99000000","0.23243000"],["79983.98000000","0.00083000"],["79983.97000000","0.00013000"],["79983.50000000","0.00021000"],["79983.49000000","0.08146000"],["79983.24000000","0.00037000"],["79982.81000000","0.00007000"],["79982.75000000","0.00007000"],["79982.72000000","0.00014000"],["79982.71000000","0.01688000"],["79982.28000000","0.00007000"],["79981.99000000","0.00014000"],["79981.94000000","0.00007000"],["79981.54000000","0.00007000"],["79981.51000000","0.00014000"],["79981.44000000","0.00014000"],["79981.43000000","0.02023000"],["79981.29000000","0.00007000"],["79981.06000000","0.00303000"],["79981.05000000","0.00014000"]],"asks":[["79984.00000000","2.27088000"],["79984.01000000","0.00027000"],["79984.02000000","0.00413000"],["79984.27000000","0.00007000"],["79984.61000000","0.00007000"],["79985.16000000","0.00021000"],["79985.50000000","0.00905000"],["79985.94000000","0.00007000"],["79985.95000000","0.00014000"],["79985.96000000","0.07604000"],["79985.97000000","0.00014000"],["79985.98000000","0.01763000"],["79985.99000000","0.00014000"],["79986.00000000","0.02421000"],["79986.20000000","0.00007000"],["79986.29000000","0.00021000"],["79986.30000000","0.00595000"],["79986.63000000","0.00014000"],["79986.64000000","0.05316000"],["79986.65000000","0.00007000"]]}}}
{"rx_ns": 10701652662800, "frame": {"stream":"btcusdt@depth@100ms","data":{"e":"depthUpdate","E":1787647696814,"s":"BTCUSDT","U":99116122674,"u":99116122705,"b":[["79983.99000000","0.23243000"],["79981.04000000","0.05033000"],["79980.63000000","0.08589000"],["79979.51000000","0.08596000"],["79978.69000000","0.04098000"],["79978.42000000","0.00911000"],["79978.39000000","0.08176000"],["79967.37000000","0.02600000"],["79963.37000000","1.06939000"],["79962.50000000","0.02200000"],["79955.86000000","0.00000000"],["79950.96000000","0.00000000"],["79906.54000000","0.02600000"],["79902.53000000","0.02000000"],["79901.63000000","0.02200000"],["71985.60000000","0.00432000"]],"a":[["79984.00000000","2.27088000"],["80000.49000000","0.02000000"]]}}}
{"rx_ns": 10701753544100, "frame": {"stream":"btcusdt@depth20@100ms","data":{"lastUpdateId":99116122730,"bids":[["79983.99000000","0.23118000"],["79983.98000000","0.00090000"],["79983.97000000","0.00013000"],["79983.50000000","0.00021000"],["79983.49000000","0.08146000"],["79983.24000000","0.00037000"],["79982.81000000","0.00007000"],["79982.75000000","0.00007000"],["79982.72000000","0.00014000"],["79982.71000000","0.01688000"],["79982.28000000","0.00007000"],["79981.99000000","0.00014000"],["79981.94000000","0.00007000"],["79981.54000000","0.00007000"],["79981.51000000","0.00014000"],["79981.44000000","0.00014000"],["79981.43000000","0.02023000"],["79981.29000000","0.00007000"],["79981.06000000","0.00303000"],["79981.05000000","0.00014000"]],"asks":[["79984.00000000","2.27146000"],["79984.01000000","0.00027000"],["79984.02000000","0.00413000"],["79984.27000000","0.00007000"],["79984.61000000","0.00007000"],["79985.12000000","0.07194000"],["79985.16000000","0.00021000"],["79985.50000000","0.00912000"],["79985.94000000","0.00007000"],["79985.95000000","0.08589000"],["79985.96000000","0.07604000"],["79985.97000000","0.00014000"],["79985.98000000","0.01763000"],["79985.99000000","0.00014000"],["79986.00000000","0.02421000"],["79986.20000000","0.00007000"],["79986.29000000","0.00021000"],["79986.30000000","0.00595000"],["79986.64000000","0.05316000"],["79986.66000000","0.03238000"]]}}}
{"rx_ns": 10701753628600, "frame": {"stream":"btcusdt@depth@100ms","data":{"e":"depthUpdate","E":1787647696914,"s":"BTCUSDT","U":99116122706,"u":99116122730,"b":[["79983.99000000","0.23118000"],["79983.98000000","0.00090000"],["79980.64000000","0.00000000"],["79980.63000000","0.00014000"],["79979.51000000","0.00021000"],["79976.00000000","0.02407000"],["79974.29000000","0.00000000"],["79972.91000000","0.00000000"],["79951.86000000","0.00000000"],["71985.60000000","0.00432000"]],"a":[["79984.00000000","2.27146000"],["79985.12000000","0.07194000"],["79985.50000000","0.00912000"],["79985.95000000","0.08589000"],["79986.63000000","0.00000000"],["79986.65000000","0.00000000"],["80000.09000000","0.02000000"],["80000.48000000","0.02000000"],["80010.55000000","0.00399000"],["80010.94000000","0.00000000"],["80202.12000000","0.00399000"]]}}}
{"rx_ns": 10701852938400, "frame": {"stream":"btcusdt@depth20@100ms","data":{"lastUpdateId":99116122783,"bids":[["79983.99000000","0.23093000"],["79983.98000000","0.00083000"],["79983.97000000","0.00013000"],["79983.50000000","0.00021000"],["79983.49000000","0.08146000"],["79983.24000000","0.00037000"],["79982.81000000","0.00007000"],["79982.75000000","0.00007000"],["79982.72000000","0.00014000"],["79982.71000000","0.01688000"],["79982.28000000","0.00007000"],["79981.99000000","0.00014000"],["79981.94000000","0.00007000"],["79981.54000000","0.00007000"],["79981.51000000","0.00014000"],["79981.44000000","0.00014000"],["79981.43000000","0.02023000"],["79981.29000000","0.00007000"],["79981.06000000","0.00303000"],["79981.05000000","0.00014000"]],"asks":[["79984.00000000","2.27619000"],["79984.01000000","0.00027000"],["79984.02000000","0.00413000"],["79984.27000000","0.00007000"],["79984.61000000","0.00007000"],["79985.12000000","0.07208000"],["79985.16000000","0.00021000"],["79985.50000000","0.00912000"],["79985.94000000","0.00007000"],["79985.95000000","0.08603000"],["79985.96000000","0.07604000"],["79985.97000000","0.00014000"],["79985.98000000","0.01763000"],["79985.99000000","0.00014000"],["79986.00000000","0.02421000"],["79986.20000000","0.00007000"],["79986.29000000","0.00021000"],["79986.30000000","0.00595000"],["79986.64000000","0.05316000"],["79986.66000000","0.03224000"]]}}}
{"rx_ns": 10701853017800, "frame": {"stream":"btcusdt@depth@100ms","data":{"e":"depthUpdate","E":1787647697014,"s":"BTCUSDT","U":99116122731,"u":99116122783,"b":[["79983.99000000","0.23093000"],["79983.98000000","0.00083000"],["79981.04000000","0.05026000"],["79980.63000000","0.00000000"],["79980.15000000","0.02030000"],["79979.51000000","0.00007000"],["79978.69000000","0.00014000"],["79978.42000000","0.00925000"],["79978.39000000","0.08190000"],["79978.10000000","0.00007000"],["79966.56000000","0.02474000"],["79945.00000000","1.74939000"],["78784.23000000","0.00030000"],["71985.60000000","0.00432000"],["71985.58000000","0.00000000"],["63987.20000000","0.00031000"]],"a":[["79984.00000000","2.27619000"],["79985.12000000","0.07208000"],["79985.50000000","0.00912000"],["79985.95000000","0.08603000"],["79986.66000000","0.03224000"],["79986.78000000","0.01458000"],["79996.37000000","0.02000000"],["79998.77000000","0.02000000"],["80009.32000000","0.00000000"],["80020.46000000","0.00000000"]]}}}
{"rx_ns": 10701953214900, "frame": {"stream":"btcusdt@depth20@100ms","data":{"lastUpdateId":99116122806,"bids":[["79983.99000000","0.23093000"],["79983.98000000","0.00083000"],["79983.97000000","0.00013000"],["79983.50000000","0.00021000"],["79983.49000000","0.08146000"],["79983.24000000","0.00037000"],["79982.81000000","0.00007000"],["79982.75000000","0.00007000"],["79982.72000000","0.00014000"],["79982.71000000","0.01688000"],["79982.28000000","0.00007000"],["79981.99000000","0.00014000"],["79981.94000000","0.00007000"],["79981.54000000","0.00007000"],["79981.51000000","0.00014000"],["79981.44000000","0.00014000"],["79981.43000000","0.02023000"],["79981.29000000","0.00007000"],["79981.06000000","0.00303000"],["79981.05000000","0.00014000"]],"asks":[["79984.00000000","2.27608000"],["79984.01000000","0.00027000"],["79984.02000000","0.00413000"],["79984.27000000","0.00007000"],["79984.61000000","0.00007000"],["79985.12000000","0.07208000"],["79985.14000000","0.00007000"],["79985.16000000","0.00021000"],["79985.50000000","0.00912000"],["79985.94000000","0.00007000"],["79985.95000000","0.08603000"],["79985.96000000","0.07604000"],["79985.97000000","0.00014000"],["79985.98000000","0.01763000"],["79985.99000000","0.00014000"],["79986.00000000","0.02421000"],["79986.20000000","0.00007000"],["79986.29000000","0.00021000"],["79986.30000000","0.00595000"],["79986.64000000","0.05316000"]]}}}
{"rx_ns": 10701953305700, "frame": {"stream":"btcusdt@depth@100ms","data":{"e":"depthUpdate","E":1787647697114,"s":"BTCUSDT","U":99116122784,"u":99116122806,"b":[["79980.15000000","0.02023000"],["79979.51000000","0.00000000"],["79978.69000000","0.00000000"],["79978.29000000","0.00884000"],["79913.11000000","0.02000000"],["71985.60000000","0.00448000"],["71985.00000000","0.00000000"]],"a":[["79984.00000000","2.27608000"],["79985.14000000","0.00007000"],["79996.16000000","0.49868000"],["80064.44000000","0.02000000"]]}}}
{"rx_ns": 10702059992100, "frame": {"stream":"btcusdt@depth20@100ms","data":{"lastUpdateId":99116122992,"bids":[["79983.99000000","1.14105000"],["79983.98000000","0.00097000"],["79983.97000000","0.00013000"],["79983.50000000","0.00021000"],["79983.49000000","0.08153000"],["79983.24000000","0.00037000"],["79982.88000000","0.00014000"],["79982.81000000","0.00007000"],["79982.75000000","0.00007000"],["79982.72000000","0.00014000"],["79982.71000000","0.01695000"],["79982.28000000","0.00007000"],["79981.99000000","0.00014000"],["79981.94000000","0.00007000"],["79981.76000000","0.00014000"],["79981.75000000","0.08575000"],["79981.54000000","0.00007000"],["79981.51000000","0.00014000"],["79981.44000000","0.00014000"],["79981.43000000","0.02023000"]],"asks":[["79984.00000000","1.63429000"],["79984.01000000","0.00027000"],["79984.02000000","0.00413000"],["79984.27000000","0.00007000"],["79984.61000000","0.00007000"],["79985.10000000","0.00014000"],["79985.11000000","0.04457000"],["79985.12000000","0.00014000"],["79985.14000000","0.00007000"],["79985.16000000","0.00021000"],["79985.50000000","0.00912000"],["79985.93000000","0.00014000"],["79985.94000000","0.01756000"],["79985.95000000","0.00014000"],["79985.96000000","0.00014000"],["79985.98000000","0.00014000"],["79985.99000000","0.00014000"],["79986.00000000","0.02421000"],["79986.20000000","0.00007000"],["79986.28000000","0.00034000"]]}}}
{"rx_ns": 10702060133900, "frame": {"stream":"btcusdt@depth@100ms","data":{"e":"depthUpdate","E":1787647697214,"s":"BTCUSDT","U":99116122807,"u":99116122992,"b":[["79983.99000000","1.14105000"],["79983.98000000","0.00097000"],["79983.49000000","0.08153000"],["79982.88000000","0.00014000"],["79982.87000000","0.00000000"],["79982.71000000","0.01695000"],["79981.76000000","0.00014000"],["79981.75000000","0.08575000"],["79981.05000000","0.00000000"],["79981.04000000","0.05033000"],["79980.63000000","0.08575000"],["79980.29000000","0.02855000"],["79980.16000000","0.00000000"],["79980.15000000","0.02030000"],["79979.51000000","0.08575000"],["79978.42000000","0.00932000"],["79978.40000000","0.11512000"],["79978.39000000","0.08589000"],["79977.42000000","0.00014000"],["79975.83000000","0.00000000"],["79975.19000000","0.00000000"],["79974.29000000","0.08575000"],["79972.91000000","0.08575000"],["79972.01000000","0.15387000"],["79969.31000000","0.00584000"],["79969.06000000","0.00162000"],["79968.75000000","0.00007000"],["79961.96000000","0.00000000"],["79961.95000000","0.00000000"],["79959.78000000","0.61892000"],["79958.77000000","0.62539000"],["79955.87000000","0.00000000"],["79954.63000000","0.00000000"],["79952.38000000","0.00000000"],["79947.69000000","0.42475000"],["79938.72000000","0.00000000"],["79938.67000000","0.00000000"],["79933.67000000","0.04443000"],["79898.40000000","0.00000000"],["79897.61000000","0.12228000"],["79829.28000000","0.00000000"],["71985.60000000","0.00416000"],["63987.20000000","0.00000000"],["42091.80000000","0.00036000"]],"a":[["79984.00000000","1.63429000"],["79985.10000000","0.00014000"],["79985.11000000","0.04457000"],["79985.12000000","0.00014000"],["79985.50000000","0.00912000"],["79985.93000000","0.00014000"],["79985.94000000","0.01756000"],["79985.95000000","0.00014000"],["79985.96000000","0.00014000"],["79985.97000000","0.00000000"],["79985.98000000","0.00014000"],["79985.99000000","0.00014000"],["79986.28000000","0.00034000"],["79986.30000000","0.00014000"],["79986.63000000","0.00051000"],["79986.64000000","0.05309000"],["79986.65000000","0.00000000"],["79986.66000000","0.00000000"],["79986.77000000","0.00007000"],["79986.78000000","0.01451000"],["79987.03000000","0.00596000"],["79987.35000000","0.00000000"],["79987.99000000","0.00007000"],["79988.06000000","0.01762000"],["79988.23000000","0.00000000"],["79988.25000000","0.00000000"],["79988.28000000","0.12501000"],["79988.69000000","0.00000000"],["79990.29000000","0.00000000"],["79991.84000000","0.08575000"],["79991.98000000","0.07862000"],["79991.99000000","1.04947000"],["79992.45000000","0.38072000"],["79992.79000000","0.02000000"],["79993.67000000","0.00400000"],["79993.68000000","0.00000000"],["79993.69000000","0.00000000"],["79993.70000000","0.00000000"],["79995.15000000","0.00000000"],["79995.16000000","0.00000000"],["79995.55000000","0.00000000"],["79996.16000000","0.44610000"],["79997.47000000","0.00000000"],["79999.12000000","0.00000000"],["79999.99000000","0.00000000"],["80000.04000000","0.00000000"],["80000.15000000","0.13341000"],["80000.63000000","0.00625000"],["80000.75000000","0.00007000"],["80001.99000000","0.30814000"],["80004.47000000","0.62539000"],["80006.86000000","0.00000000"],["80009.97000000","0.00000000"],["80017.13000000","0.33752000"],["80022.53000000","1.23751000"],["80024.58000000","0.61349000"],["80043.15000000","1.23719000"],["80044.02000000","0.20250000"],["80076.47000000","3.13843000"],["80081.75000000","0.00000000"],["80141.39000000","0.00000000"],["80703.85000000","0.00010000"],["81183.76000000","0.00030000"]]}}}
{"rx_ns": 10702152974500, "frame": {"stream":"btcusdt@depth20@100ms","data":{"lastUpdateId":99116123124,"bids":[["79983.99000000","1.14098000"],["79983.98000000","0.00090000"],["79983.97000000","0.00013000"],["79983.50000000","0.00021000"],["79983.49000000","0.08146000"],["79983.24000000","0.00037000"],["79982.81000000","0.00007000"],["79982.75000000","0.00007000"],["79982.72000000","0.00014000"],["79982.71000000","0.01695000"],["79982.28000000","0.00007000"],["79981.99000000","0.00014000"],["79981.94000000","0.00007000"],["79981.75000000","0.00014000"],["79981.54000000","0.00007000"],["79981.51000000","0.00014000"],["79981.44000000","0.21167000"],["79981.43000000","0.12641000"],["79981.29000000","0.00007000"],["79981.06000000","0.00303000"]],"asks":[["79984.00000000","1.63422000"],["79984.01000000","0.00027000"],["79984.02000000","0.00013000"],["79984.27000000","0.00007000"],["79984.61000000","0.00007000"],["79985.10000000","0.00014000"],["79985.11000000","0.04471000"],["79985.14000000","0.00007000"],["79985.16000000","0.00021000"],["79985.50000000","0.00891000"],["79985.93000000","0.00014000"],["79985.94000000","0.01770000"],["79985.99000000","0.00014000"],["79986.00000000","0.02421000"],["79986.20000000","0.00007000"],["79986.28000000","0.00034000"],["79986.29000000","0.00014000"],["79986.63000000","0.00051000"],["79986.64000000","0.05309000"],["79986.77000000","0.00007000"]]}}}
{"rx_ns": 10702153135800, "frame": {"stream":"btcusdt@depth@100ms","data":{"e":"depthUpdate","E":1787647697314,"s":"BTCUSDT","U":99116122993,"u":99116123124,"b":[["79983.99000000","1.14098000"],["79983.98000000","0.00090000"],["79983.49000000","0.08146000"],["79982.88000000","0.00000000"],["79982.71000000","0.01695000"],["79981.76000000","0.00000000"],["79981.75000000","0.00014000"],["79981.44000000","0.21167000"],["79981.43000000","0.12641000"],["79981.05000000","0.00014000"],["79981.04000000","0.05040000"],["79980.96000000","0.42211000"],["79980.63000000","0.08596000"],["79980.29000000","0.00014000"],["79980.15000000","0.02030000"],["79978.42000000","0.00918000"],["79978.39000000","0.08575000"],["79978.29000000","0.00870000"],["79975.84000000","0.79939000"],["79975.23000000","1.87060000"],["79974.29000000","0.00000000"],["79972.91000000","0.00000000"],["79972.01000000","0.00007000"],["79971.69000000","0.00596000"],["79965.46000000","0.15381000"],["79960.86000000","0.37529000"],["79945.00000000","1.04939000"],["79944.66000000","0.02400000"],["79921.80000000","0.00000000"],["79799.10000000","0.00000000"],["79781.48000000","0.01888000"],["79778.60000000","0.00000000"],["79773.62000000","0.00770000"],["71985.60000000","0.00448000"],["63987.19000000","0.00000000"],["63987.00000000","0.00000000"]],"a":[["79984.00000000","1.63422000"],["79984.02000000","0.00013000"],["79985.11000000","0.04471000"],["79985.12000000","0.00000000"],["79985.50000000","0.00891000"],["79985.94000000","0.01770000"],["79985.95000000","0.00000000"],["79985.96000000","0.00000000"],["79985.98000000","0.00000000"],["79986.00000000","0.02421000"],["79986.29000000","0.00014000"],["79986.30000000","0.00000000"],["79986.64000000","0.05309000"],["79986.78000000","0.01472000"],["79987.03000000","0.00014000"],["79988.00000000","0.03610000"],["79988.06000000","0.01769000"],["79988.23000000","0.08575000"],["79990.72000000","0.07916000"],["79992.45000000","0.16104000"],["79995.00000000","0.00000000"],["80005.00000000","0.00000000"],["80037.23000000","0.00400000"],["80040.36000000","0.00000000"],["80040.68000000","1.51650000"],["80076.47000000","0.00000000"],["80144.08000000","0.00680000"],["80161.77000000","0.00000000"]]}}}
{"rx_ns": 10702252764900, "frame": {"stream":"btcusdt@depth20@100ms","data":{"lastUpdateId":99116123209,"bids":[["79983.99000000","0.88296000"],["79983.98000000","0.00090000"],["79983.97000000","0.00013000"],["79983.50000000","0.00021000"],["79983.49000000","0.08146000"],["79983.24000000","0.00037000"],["79982.81000000","0.00007000"],["79982.75000000","0.00007000"],["79982.72000000","0.00014000"],["79982.71000000","0.01695000"],["79982.28000000","0.00007000"],["79981.99000000","0.00014000"],["79981.94000000","0.00007000"],["79981.54000000","0.00007000"],["79981.51000000","0.00014000"],["79981.44000000","0.00028000"],["79981.43000000","0.02023000"],["79981.29000000","0.00007000"],["79981.06000000","0.00303000"],["79981.05000000","0.00014000"]],"asks":[["79984.00000000","1.83662000"],["79984.01000000","0.00027000"],["79984.02000000","0.00013000"],["79984.27000000","0.00007000"],["79984.61000000","0.00007000"],["79985.10000000","0.00014000"],["79985.11000000","0.09714000"],["79985.14000000","0.00007000"],["79985.16000000","0.00021000"],["79985.50000000","0.00891000"],["79985.93000000","0.00014000"],["79985.94000000","0.01770000"],["79985.99000000","0.00014000"],["79986.00000000","0.02428000"],["79986.20000000","0.00007000"],["79986.23000000","0.00014000"],["79986.24000000","0.08575000"],["79986.28000000","0.00034000"],["79986.29000000","0.00014000"],["79986.63000000","0.00051000"]]}}}
{"rx_ns": 10702252862500, "frame": {"stream":"btcusdt@depth@100ms","data":{"e":"depthUpdate","E":1787647697414,"s":"BTCUSDT","U":99116123125,"u":99116123209,"b":[["79983.99000000","0.88296000"],["79982.71000000","0.01695000"],["79981.75000000","0.00000000"],["79981.44000000","0.00028000"],["79981.43000000","0.02023000"],["79981.04000000","0.05040000"],["79980.96000000","0.42225000"],["79980.63000000","0.00014000"],["79980.29000000","0.00000000"],["79980.15000000","0.02023000"],["79979.51000000","0.00000000"],["79978.42000000","0.00911000"],["79978.40000000","0.03825000"],["79978.39000000","0.00000000"],["79978.28000000","0.00853000"],["79978.10000000","0.00000000"],["79977.27000000","0.00000000"],["79976.01000000","0.00000000"],["79975.85000000","0.08575000"],["79974.46000000","0.01250000"],["79971.69000000","0.00000000"],["79968.52000000","0.00000000"],["79968.11000000","0.00000000"],["79947.86000000","0.00012000"],["79901.45000000","0.00000000"],["73585.27000000","0.00014000"],["73000.00000000","64.08719000"],["71985.60000000","0.00440000"],["71500.00000000","15.11638000"]],"a":[["79984.00000000","1.83662000"],["79985.11000000","0.09714000"],["79985.50000000","0.00891000"],["79985.56000000","0.00000000"],["79986.00000000","0.02428000"],["79986.23000000","0.00014000"],["79986.24000000","0.08575000"],["79986.77000000","0.00000000"],["79986.78000000","0.01479000"],["79987.03000000","0.00000000"],["79987.36000000","0.08575000"],["79987.87000000","0.00599000"],["79987.99000000","0.00000000"],["79988.06000000","0.01783000"],["79991.98000000","0.00000000"],["80035.20000000","0.00400000"],["80037.23000000","0.00000000"]]}}}
{"rx_ns": 10702354209100, "frame": {"stream":"btcusdt@depth20@100ms","data":{"lastUpdateId":99116123268,"bids":[["79983.99000000","0.88303000"],["79983.98000000","0.00090000"],["79983.97000000","0.00013000"],["79983.50000000","0.00021000"],["79983.49000000","0.08146000"],["79983.24000000","0.00037000"],["79982.81000000","0.00007000"],["79982.75000000","0.00007000"],["79982.72000000","0.00014000"],["79982.71000000","0.01695000"],["79982.28000000","0.00007000"],["79981.99000000","0.00014000"],["79981.94000000","0.00007000"],["79981.54000000","0.00007000"],["79981.51000000","0.00014000"],["79981.44000000","0.00014000"],["79981.43000000","0.02023000"],["79981.29000000","0.00007000"],["79981.06000000","0.00303000"],["79981.05000000","0.00014000"]],"asks":[["79984.00000000","1.83680000"],["79984.01000000","0.00027000"],["79984.02000000","0.00013000"],["79984.27000000","0.00007000"],["79984.61000000","0.00007000"],["79985.10000000","0.00014000"],["79985.11000000","0.09714000"],["79985.14000000","0.00007000"],["79985.16000000","0.00021000"],["79985.50000000","0.00891000"],["79985.93000000","0.00014000"],["79985.94000000","0.01770000"],["79985.99000000","0.00014000"],["79986.00000000","0.02428000"],["79986.20000000","0.00007000"],["79986.23000000","0.00014000"],["79986.24000000","0.08589000"],["79986.28000000","0.00034000"],["79986.29000000","0.00014000"],["79986.63000000","0.00051000"]]}}}
{"rx_ns": 10702354311700, "frame": {"stream":"btcusdt@depth@100ms","data":{"e":"depthUpdate","E":1787647697514,"s":"BTCUSDT","U":99116123210,"u":99116123268,"b":[["79983.99000000","0.88303000"],["79982.71000000","0.01695000"],["79981.44000000","0.00014000"],["79981.04000000","0.05033000"],["79980.96000000","0.42225000"],["79980.63000000","0.00000000"],["79980.15000000","0.02023000"],["79978.42000000","0.00925000"],["79978.40000000","0.05908000"],["79978.28000000","0.00860000"],["79977.27000000","0.08575000"],["79975.87000000","0.08575000"],["79975.86000000","1.04939000"],["79975.85000000","0.00000000"],["79974.46000000","0.01372000"],["79899.41000000","0.02084000"],["71985.60000000","0.00440000"],["63987.20000000","0.00031000"],["58500.00000000","33.09356000"]],"a":[["79984.00000000","1.83680000"],["79986.00000000","0.02428000"],["79986.24000000","0.08589000"],["79986.78000000","0.01479000"],["79987.36000000","0.08589000"],["79988.00000000","0.03596000"],["79988.06000000","0.01769000"],["79992.45000000","0.16191000"],["80025.15000000","0.00012000"]]}}}
{"rx_ns": 10702454234500, "frame": {"stream":"btcusdt@depth20@100ms","data":{"lastUpdateId":99116123275,"bids":[["79983.99000000","0.88310000"],["79983.98000000","0.00097000"],["79983.97000000","0.00013000"],["79983.50000000","0.00021000"],["79983.49000000","0.08146000"],["79983.24000000","0.00037000"],["79982.81000000","0.00007000"],["79982.75000000","0.00007000"],["79982.72000000","0.00014000"],["79982.71000000","0.01695000"],["79982.28000000","0.00007000"],["79981.99000000","0.00014000"],["79981.94000000","0.00007000"],["79981.54000000","0.00007000"],["79981.51000000","0.00014000"],["79981.44000000","0.00014000"],["79981.43000000","0.02023000"],["79981.29000000","0.00007000"],["79981.06000000","0.00303000"],["79981.05000000","0.18375000"]],"asks":[["79984.00000000","1.83680000"],["79984.01000000","0.00027000"],["79984.02000000","0.00013000"],["79984.27000000","0.00007000"],["79984.61000000","0.00007000"],["79985.10000000","0.00014000"],["79985.11000000","0.09714000"],["79985.14000000","0.00007000"],["79985.16000000","0.00021000"],["79985.50000000","0.00891000"],["79985.93000000","0.00014000"],["79985.94000000","0.01770000"],["79985.99000000","0.00014000"],["79986.00000000","0.02428000"],["79986.20000000","0.00007000"],["79986.23000000","0.00014000"],["79986.24000000","0.08589000"],["79986.28000000","0.00034000"],["79986.29000000","0.00014000"],["79986.63000000","0.00051000"]]}}}
{"rx_ns": 10702454321100, "frame": {"stream":"btcusdt@depth@100ms","data":{"e":"depthUpdate","E":1787647697614,"s":"BTCUSDT","U":99116123269,"u":99116123275,"b":[["79983.99000000","0.88310000"],["79983.98000000","0.00097000"],["79981.05000000","0.18375000"],["79980.96000000","0.42232000"],["79980.70000000","0.12216000"],["79899.41000000","0.00000000"],["63987.20000000","0.00000000"]],"a":[]}}}
{"rx_ns": 10702558024800, "frame": {"stream":"btcusdt@depth20@100ms","data":{"lastUpdateId":99116123333,"bids":[["79983.99000000","0.85939000"],["79983.98000000","0.00097000"],["79983.97000000","0.00013000"],["79983.50000000","0.00021000"],["79983.49000000","0.08146000"],["79983.24000000","0.00037000"],["79982.81000000","0.00007000"],["79982.75000000","0.00007000"],["79982.72000000","0.00014000"],["79982.71000000","0.01695000"],["79982.28000000","0.00007000"],["79981.99000000","0.00014000"],["79981.94000000","0.00007000"],["79981.54000000","0.00007000"],["79981.51000000","0.00014000"],["79981.44000000","0.00014000"],["79981.43000000","0.02030000"],["79981.29000000","0.00007000"],["79981.06000000","0.00303000"],["79981.05000000","0.00329000"]],"asks":[["79984.00000000","1.83680000"],["79984.01000000","0.00027000"],["79984.02000000","0.00013000"],["79984.27000000","0.00007000"],["79984.61000000","0.00007000"],["79985.10000000","0.00014000"],["79985.11000000","0.09721000"],["79985.12000000","0.00587000"],["79985.14000000","0.00007000"],["79985.16000000","0.00021000"],["79985.50000000","0.00891000"],["79985.93000000","0.00014000"],["79985.94000000","0.01770000"],["79985.99000000","0.00014000"],["79986.00000000","0.02428000"],["79986.20000000","0.00007000"],["79986.23000000","0.00014000"],["79986.24000000","0.08589000"],["79986.28000000","0.00034000"],["79986.29000000","0.00014000"]]}}}
{"rx_ns": 10702558116300, "frame": {"stream":"btcusdt@depth@100ms","data":{"e":"depthUpdate","E":1787647697714,"s":"BTCUSDT","U":99116123276,"u":99116123333,"b":[["79983.99000000","0.85939000"],["79983.98000000","0.00097000"],["79981.43000000","0.02030000"],["79981.05000000","0.00329000"],["79981.04000000","0.04736000"],["79980.96000000","0.42232000"],["79980.70000000","0.00014000"],["79978.42000000","0.00904000"],["79978.40000000","0.00000000"],["79978.28000000","0.00860000"],["79977.27000000","0.00000000"],["79976.68000000","0.03284000"],["79965.46000000","0.00000000"],["79960.01000000","0.15389000"],["79958.77000000","0.00000000"],["79956.98000000","0.62536000"],["79912.13000000","0.00000000"],["79899.41000000","0.02084000"],["79830.33000000","0.00000000"],["71985.60000000","0.00440000"]],"a":[["79985.11000000","0.09721000"],["79985.12000000","0.00587000"],["79991.84000000","0.00000000"],["79994.12000000","0.00000000"],["79998.70000000","0.02000000"],["80007.52000000","0.00000000"],["80010.96000000","0.62509000"],["80048.39000000","0.00000000"],["80048.40000000","0.00000000"],["84902.00000000","0.02244000"]]}}}
{"rx_ns": 10702652318600, "frame": {"stream":"btcusdt@depth20@100ms","data":{"lastUpdateId":99116123402,"bids":[["79983.99000000","0.86110000"],["79983.98000000","0.00097000"],["79983.97000000","0.00013000"],["79983.50000000","0.00021000"],["79983.49000000","0.08146000"],["79983.24000000","0.00037000"],["79982.81000000","0.00007000"],["79982.75000000","0.00007000"],["79982.72000000","0.00014000"],["79982.71000000","0.01695000"],["79982.28000000","0.00007000"],["79981.99000000","0.00014000"],["79981.94000000","0.00007000"],["79981.54000000","0.00007000"],["79981.51000000","0.00014000"],["79981.44000000","0.00014000"],["79981.43000000","0.02030000"],["79981.29000000","0.00007000"],["79981.06000000","0.00303000"],["79981.05000000","0.00014000"]],"asks":[["79984.00000000","1.83348000"],["79984.01000000","0.00027000"],["79984.02000000","0.00013000"],["79984.27000000","0.00007000"],["79984.61000000","0.00007000"],["79985.10000000","0.00014000"],["79985.11000000","0.40382000"],["79985.12000000","0.00601000"],["79985.14000000","0.00007000"],["79985.16000000","0.00021000"],["79985.50000000","0.00891000"],["79985.94000000","0.01770000"],["79985.99000000","0.00014000"],["79986.00000000","0.02428000"],["79986.20000000","0.00007000"],["79986.24000000","0.00014000"],["79986.28000000","0.00034000"],["79986.29000000","0.00014000"],["79986.63000000","0.00051000"],["79986.64000000","0.05309000"]]}}}
{"rx_ns": 10702652416600, "frame": {"stream":"btcusdt@depth@100ms","data":{"e":"depthUpdate","E":1787647697814,"s":"BTCUSDT","U":99116123334,"u":99116123402,"b":[["79983.99000000","0.86110000"],["79981.43000000","0.02030000"],["79981.05000000","0.00014000"],["79981.04000000","0.04968000"],["79980.97000000","0.00007000"],["79980.96000000","0.42225000"],["79980.70000000","0.00000000"],["79978.42000000","0.00918000"],["79978.29000000","0.00884000"],["79978.28000000","0.00867000"],["79977.28000000","0.05848000"],["79977.27000000","0.08575000"],["79976.68000000","0.00000000"],["79912.13000000","0.00312000"],["79899.41000000","0.00000000"],["79830.33000000","0.00125000"],["79002.50000000","0.00300000"],["71985.60000000","0.00448000"],["71985.59000000","0.00008000"]],"a":[["79984.00000000","1.83348000"],["79985.11000000","0.40382000"],["79985.12000000","0.00601000"],["79985.93000000","0.00000000"],["79986.23000000","0.00000000"],["79986.24000000","0.00014000"],["79987.35000000","0.00014000"],["79987.36000000","0.08575000"],["79987.98000000","0.00007000"],["79987.99000000","1.04939000"],["79988.06000000","0.01762000"],["79988.23000000","0.00000000"],["79990.72000000","0.00000000"],["79992.45000000","0.13043000"],["79993.90000000","0.02000000"],["79997.89000000","0.02000000"],["80002.71000000","0.00000000"]]}}}
{"rx_ns": 10702761213400, "frame": {"stream":"btcusdt@depth20@100ms","data":{"lastUpdateId":99116123437,"bids":[["79983.99000000","0.86120000"],["79983.98000000","0.00097000"],["79983.97000000","0.00013000"],["79983.50000000","0.00021000"],["79983.49000000","0.08146000"],["79983.24000000","0.00037000"],["79982.81000000","0.00007000"],["79982.75000000","0.00007000"],["79982.72000000","0.00014000"],["79982.71000000","0.01695000"],["79982.28000000","0.00007000"],["79981.99000000","0.00014000"],["79981.94000000","0.00007000"],["79981.54000000","0.00007000"],["79981.51000000","0.00014000"],["79981.44000000","0.00014000"],["79981.43000000","0.02030000"],["79981.29000000","0.00007000"],["79981.06000000","0.00303000"],["79981.05000000","0.00014000"]],"asks":[["79984.00000000","1.83242000"],["79984.01000000","0.00027000"],["79984.02000000","0.00013000"],["79984.27000000","0.00007000"],["79984.61000000","0.00007000"],["79985.10000000","0.00014000"],["79985.11000000","0.40382000"],["79985.12000000","0.00601000"],["79985.14000000","0.00007000"],["79985.16000000","0.00021000"],["79985.50000000","0.00891000"],["79985.94000000","0.01770000"],["79985.99000000","0.00014000"],["79986.00000000","0.02421000"],["79986.20000000","0.00007000"],["79986.28000000","0.00034000"],["79986.29000000","0.00014000"],["79986.63000000","0.00051000"],["79986.64000000","0.05309000"],["79986.78000000","0.01479000"]]}}}
{"rx_ns": 10702761386500, "frame": {"stream":"btcusdt@depth@100ms","data":{"e":"depthUpdate","E":1787647697914,"s":"BTCUSDT","U":99116123403,"u":99116123437,"b":[["79983.99000000","0.86120000"],["79983.98000000","0.00097000"],["79980.96000000","0.42232000"],["79980.17000000","0.11724000"],["79961.11000000","0.02400000"],["79960.70000000","0.02200000"],["79902.04000000","0.02400000"],["79899.42000000","0.02200000"],["73585.27000000","0.00000000"],["71985.60000000","0.00432000"]],"a":[["79984.00000000","1.83242000"],["79986.00000000","0.02421000"],["79986.24000000","0.00000000"],["79987.35000000","0.00000000"],["79987.36000000","0.00014000"],["79987.98000000","0.00014000"],["79988.23000000","0.00007000"],["79992.00000000","0.25167000"],["80006.70000000","0.00000000"],["80015.20000000","0.00000000"],["80023.41000000","0.00000000"],["80024.04000000","0.09280000"],["80071.19000000","3.13843000"]]}}}
{"rx_ns": 10702852290900, "frame": {"stream":"btcusdt@depth20@100ms","data":{"lastUpdateId":99116123465,"bids":[["79983.99000000","0.86120000"],["79983.98000000","0.00097000"],["79983.97000000","0.00013000"],["79983.50000000","0.00021000"],["79983.49000000","0.08146000"],["79983.24000000","0.00037000"],["79982.81000000","0.00007000"],["79982.75000000","0.00007000"],["79982.72000000","0.00014000"],["79982.71000000","0.01695000"],["79982.28000000","0.00007000"],["79981.99000000","0.00014000"],["79981.94000000","0.00007000"],["79981.54000000","0.00007000"],["79981.51000000","0.00014000"],["79981.44000000","0.00014000"],["79981.43000000","0.02030000"],["79981.29000000","0.00007000"],["79981.06000000","0.00303000"],["79981.05000000","0.00014000"]],"asks":[["79984.00000000","1.83242000"],["79984.01000000","0.00027000"],["79984.02000000","0.00013000"],["79984.27000000","0.00007000"],["79984.61000000","0.00007000"],["79985.10000000","0.00014000"],["79985.11000000","0.40382000"],["79985.12000000","0.00601000"],["79985.14000000","0.00007000"],["79985.16000000","0.00021000"],["79985.50000000","0.00891000"],["79985.94000000","0.01770000"],["79985.99000000","0.00014000"],["79986.00000000","0.02421000"],["79986.20000000","0.00007000"],["79986.28000000","0.00034000"],["79986.29000000","0.00014000"],["79986.63000000","0.00051000"],["79986.64000000","0.05309000"],["79986.78000000","0.01472000"]]}}}
{"rx_ns": 10702852387300, "frame": {"stream":"btcusdt@depth@100ms","data":{"e":"depthUpdate","E":1787647698014,"s":"BTCUSDT","U":99116123438,"u":99116123465,"b":[["79980.96000000","0.42232000"],["79980.17000000","0.11738000"],["79978.29000000","0.00870000"],["79948.00000000","0.72400000"],["79797.87000000","0.00000000"],["78784.23000000","0.00030000"],["71985.60000000","0.00448000"],["63987.20000000","0.00031000"]],"a":[["79986.78000000","0.01472000"],["79987.36000000","0.00000000"],["79987.87000000","0.00613000"],["80000.00000000","0.82130000"],["80073.99000000","0.07794000"],["80167.88000000","0.00025000"]]}}}
{"rx_ns": 10702952316000, "frame": {"stream":"btcusdt@depth20@100ms","data":{"lastUpdateId":99116123478,"bids":[["79983.99000000","0.86120000"],["79983.98000000","0.00097000"],["79983.97000000","0.00013000"],["79983.50000000","0.00021000"],["79983.49000000","0.08146000"],["79983.24000000","0.00037000"],["79982.81000000","0.00007000"],["79982.75000000","0.00007000"],["79982.72000000","0.00014000"],["79982.71000000","0.01695000"],["79982.28000000","0.00007000"],["79981.99000000","0.00014000"],["79981.94000000","0.00007000"],["79981.54000000","0.00007000"],["79981.51000000","0.00014000"],["79981.44000000","0.00014000"],["79981.43000000","0.02030000"],["79981.29000000","0.00007000"],["79981.06000000","0.00303000"],["79981.05000000","0.00014000"]],"asks":[["79984.00000000","1.80102000"],["79984.01000000","0.00027000"],["79984.02000000","0.00013000"],["79984.27000000","0.00007000"],["79984.61000000","0.00007000"],["79985.10000000","0.00014000"],["79985.11000000","0.40382000"],["79985.12000000","0.00601000"],["79985.14000000","0.00007000"],["79985.16000000","0.00021000"],["79985.50000000","0.00891000"],["79985.94000000","0.01770000"],["79985.99000000","0.00014000"],["79986.00000000","0.02421000"],["79986.20000000","0.00007000"],["79986.28000000","0.00034000"],["79986.29000000","0.00014000"],["79986.63000000","0.00051000"],["79986.64000000","0.05309000"],["79986.78000000","0.01472000"]]}}}
{"rx_ns": 10702952426300, "frame": {"stream":"btcusdt@depth@100ms","data":{"e":"depthUpdate","E":1787647698114,"s":"BTCUSDT","U":99116123466,"u":99116123478,"b":[["79899.42000000","0.00000000"],["79838.38000000","0.00000000"],["71985.60000000","0.00432000"],["71985.00000000","0.00020000"],["42091.80000000","0.00000000"]],"a":[["79984.00000000","1.80102000"],["79989.61000000","0.01756000"],["79989.76000000","0.04000000"],["80118.29000000","0.00000000"]]}}}
{"rx_ns": 10703059284900, "frame": {"stream":"btcusdt@depth20@100ms","data":{"lastUpdateId":99116123498,"bids":[["79983.99000000","0.86120000"],["79983.98000000","0.00097000"],["79983.97000000","0.00013000"],["79983.50000000","0.00021000"],["79983.49000000","0.08146000"],["79983.24000000","0.00037000"],["79982.81000000","0.00007000"],["79982.75000000","0.00007000"],["79982.72000000","0.00014000"],["79982.71000000","0.01695000"],["79982.28000000","0.00007000"],["79981.99000000","0.00014000"],["79981.94000000","0.00007000"],["79981.54000000","0.00007000"],["79981.51000000","0.00014000"],["79981.44000000","0.00014000"],["79981.43000000","0.02030000"],["79981.29000000","0.00007000"],["79981.06000000","0.00303000"],["79981.05000000","0.00014000"]],"asks":[["79984.00000000","2.22174000"],["79984.01000000","0.00027000"],["79984.02000000","0.00013000"],["79984.27000000","0.00007000"],["79984.61000000","0.00007000"],["79985.10000000","0.00014000"],["79985.11000000","0.40382000"],["79985.12000000","0.00601000"],["79985.14000000","0.00007000"],["79985.16000000","0.00021000"],["79985.50000000","0.00891000"],["79985.94000000","0.01770000"],["79985.99000000","0.00014000"],["79986.00000000","0.02421000"],["79986.20000000","0.00007000"],["79986.28000000","0.00034000"],["79986.29000000","0.00014000"],["79986.63000000","0.00051000"],["79986.64000000","0.05309000"],["79986.78000000","0.01472000"]]}}}
{"rx_ns": 10703059377600, "frame": {"stream":"btcusdt@depth@100ms","data":{"e":"depthUpdate","E":1787647698214,"s":"BTCUSDT","U":99116123479,"u":99116123498,"b":[["79968.75000000","0.00000000"],["79948.00000000","0.02400000"],["79928.00000000","0.02407000"],["79824.43000000","0.00202000"],["79794.41000000","4.49535000"],["71985.60000000","0.00448000"],["71985.59000000","0.00000000"],["71985.00000000","0.00000000"],["63987.20000000","0.00000000"]],"a":[["79984.00000000","2.22174000"],["80000.75000000","0.00000000"],["80136.84000000","0.00202000"],["80164.41000000","4.42389000"],["81183.76000000","0.00030000"]]}}}
{"rx_ns": 10703152522800, "frame": {"stream":"btcusdt@depth20@100ms","data":{"lastUpdateId":99116123513,"bids":[["79983.99000000","0.86120000"],["79983.98000000","0.00097000"],["79983.97000000","0.00013000"],["79983.50000000","0.00021000"],["79983.49000000","0.08146000"],["79983.24000000","0.00037000"],["79982.81000000","0.00007000"],["79982.75000000","0.00007000"],["79982.72000000","0.00014000"],["79982.71000000","0.01695000"],["79982.28000000","0.00007000"],["79981.99000000","0.00014000"],["79981.94000000","0.00007000"],["79981.54000000","0.00007000"],["79981.51000000","0.00014000"],["79981.44000000","0.00014000"],["79981.43000000","0.02030000"],["79981.29000000","0.00007000"],["79981.06000000","0.00303000"],["79981.05000000","0.00014000"]],"asks":[["79984.00000000","2.22213000"],["79984.01000000","0.00027000"],["79984.02000000","0.00013000"],["79984.27000000","0.00007000"],["79984.61000000","0.00007000"],["79985.10000000","0.00014000"],["79985.11000000","0.40382000"],["79985.12000000","0.00601000"],["79985.14000000","0.00007000"],["79985.16000000","0.00021000"],["79985.50000000","0.00891000"],["79985.94000000","0.01770000"],["79985.99000000","0.00014000"],["79986.00000000","0.02421000"],["79986.20000000","0.00007000"],["79986.28000000","0.00034000"],["79986.29000000","0.00014000"],["79986.63000000","0.00051000"],["79986.64000000","0.05309000"],["79986.78000000","0.01472000"]]}}}
{"rx_ns": 10703152603000, "frame": {"stream":"btcusdt@depth@100ms","data":{"e":"depthUpdate","E":1787647698314,"s":"BTCUSDT","U":99116123499,"u":99116123513,"b":[["79968.75000000","0.00007000"],["71985.60000000","0.00432000"],["63987.19000000","0.00000000"],["63987.00000000","0.00000000"]],"a":[["79984.00000000","2.22213000"],["80000.75000000","0.00007000"],["80050.98000000","0.42964000"],["80525.42000000","0.00000000"]]}}}
{"rx_ns": 10703253981800, "frame": {"stream":"btcusdt@depth20@100ms","data":{"lastUpdateId":99116123518,"bids":[["79983.99000000","1.10113000"],["79983.98000000","0.00097000"],["79983.97000000","0.00013000"],["79983.50000000","0.00021000"],["79983.49000000","0.08146000"],["79983.24000000","0.00037000"],["79982.81000000","0.00007000"],["79982.75000000","0.00007000"],["79982.72000000","0.00014000"],["79982.71000000","0.01695000"],["79982.28000000","0.00007000"],["79981.99000000","0.00014000"],["79981.94000000","0.00007000"],["79981.54000000","0.00007000"],["79981.51000000","0.00014000"],["79981.44000000","0.00014000"],["79981.43000000","0.02030000"],["79981.29000000","0.00007000"],["79981.06000000","0.00303000"],["79981.05000000","0.00014000"]],"asks":[["79984.00000000","2.22213000"],["79984.01000000","0.00027000"],["79984.02000000","0.00013000"],["79984.27000000","0.00007000"],["79984.61000000","0.00007000"],["79985.10000000","0.00014000"],["79985.11000000","0.40382000"],["79985.12000000","0.00601000"],["79985.14000000","0.00007000"],["79985.16000000","0.00021000"],["79985.50000000","0.00891000"],["79985.94000000","0.01770000"],["79985.99000000","0.00014000"],["79986.00000000","0.02421000"],["79986.20000000","0.00007000"],["79986.28000000","0.00034000"],["79986.29000000","0.00014000"],["79986.63000000","0.00051000"],["79986.64000000","0.05309000"],["79986.78000000","0.01472000"]]}}}
{"rx_ns": 10703254078300, "frame": {"stream":"btcusdt@depth@100ms","data":{"e":"depthUpdate","E":1787647698414,"s":"BTCUSDT","U":99116123514,"u":99116123518,"b":[["79983.99000000","1.10113000"],["79902.04000000","0.00000000"],["71985.60000000","0.00432000"]],"a":[]}}}
{"rx_ns": 10703354299100, "frame": {"stream":"btcusdt@depth20@100ms","data":{"lastUpdateId":99116123533,"bids":[["79983.99000000","0.86120000"],["79983.98000000","0.00097000"],["79983.97000000","0.00013000"],["79983.50000000","0.00021000"],["79983.49000000","0.08146000"],["79983.24000000","0.00037000"],["79982.81000000","0.00007000"],["79982.75000000","0.00007000"],["79982.72000000","0.00014000"],["79982.71000000","0.01695000"],["79982.28000000","0.00007000"],["79981.99000000","0.00014000"],["79981.94000000","0.00007000"],["79981.54000000","0.00007000"],["79981.51000000","0.00014000"],["79981.44000000","0.00014000"],["79981.43000000","0.02030000"],["79981.29000000","0.00007000"],["79981.06000000","0.00303000"],["79981.05000000","0.00014000"]],"asks":[["79984.00000000","2.22213000"],["79984.01000000","0.00027000"],["79984.02000000","0.00013000"],["79984.27000000","0.00007000"],["79984.61000000","0.00007000"],["79985.10000000","0.00014000"],["79985.11000000","0.40382000"],["79985.12000000","0.00601000"],["79985.14000000","0.00007000"],["79985.16000000","0.00021000"],["79985.50000000","0.00891000"],["79985.94000000","0.01770000"],["79985.99000000","0.00014000"],["79986.00000000","0.02421000"],["79986.20000000","0.00007000"],["79986.28000000","0.00034000"],["79986.29000000","0.00014000"],["79986.63000000","0.00051000"],["79986.64000000","0.05309000"],["79986.78000000","0.01472000"]]}}}
{"rx_ns": 10703354376100, "frame": {"stream":"btcusdt@depth@100ms","data":{"e":"depthUpdate","E":1787647698514,"s":"BTCUSDT","U":99116123519,"u":99116123533,"b":[["79983.99000000","0.86120000"],["79968.00000000","0.36728000"],["79889.05000000","0.62495000"],["79886.41000000","0.00000000"],["79778.60000000","0.00770000"],["79773.62000000","0.00000000"],["79200.00000000","14.39801000"],["71985.60000000","0.00400000"],["63987.20000000","0.00031000"],["42091.80000000","0.00036000"]],"a":[["80000.00000000","0.12130000"],["80241.97000000","0.00000000"],["80319.20000000","0.00000000"],["80396.43000000","0.00000000"]]}}}
{"rx_ns": 10703454224500, "frame": {"stream":"btcusdt@depth20@100ms","data":{"lastUpdateId":99116123540,"bids":[["79983.99000000","0.86120000"],["79983.98000000","0.00097000"],["79983.97000000","0.00013000"],["79983.50000000","0.00021000"],["79983.49000000","0.08146000"],["79983.24000000","0.00037000"],["79982.81000000","0.00007000"],["79982.75000000","0.00007000"],["79982.72000000","0.00014000"],["79982.71000000","0.01695000"],["79982.28000000","0.00007000"],["79981.99000000","0.00014000"],["79981.94000000","0.00007000"],["79981.54000000","0.00007000"],["79981.51000000","0.00014000"],["79981.44000000","0.00014000"],["79981.43000000","0.02030000"],["79981.29000000","0.00007000"],["79981.06000000","0.00303000"],["79981.05000000","0.00014000"]],"asks":[["79984.00000000","2.22213000"],["79984.01000000","0.00027000"],["79984.02000000","0.00013000"],["79984.27000000","0.00007000"],["79984.61000000","0.00007000"],["79985.10000000","0.00014000"],["79985.11000000","0.40382000"],["79985.12000000","0.00601000"],["79985.14000000","0.00007000"],["79985.16000000","0.00021000"],["79985.50000000","0.00891000"],["79985.94000000","0.01770000"],["79985.99000000","0.00014000"],["79986.00000000","0.02421000"],["79986.20000000","0.00007000"],["79986.28000000","0.00034000"],["79986.29000000","0.00014000"],["79986.63000000","0.00051000"],["79986.64000000","0.05309000"],["79986.78000000","0.01472000"]]}}}
{"rx_ns": 10703454325500, "frame": {"stream":"btcusdt@depth@100ms","data":{"e":"depthUpdate","E":1787647698614,"s":"BTCUSDT","U":99116123534,"u":99116123540,"b":[["79899.41000000","0.00000000"],["79744.97000000","0.01958000"],["79739.23000000","0.00000000"],["71985.60000000","0.00432000"],["63987.20000000","0.00000000"]],"a":[]}}}
{"rx_ns": 10703552785300, "frame": {"stream":"btcusdt@depth20@100ms","data":{"lastUpdateId":99116123545,"bids":[["79983.99000000","0.86120000"],["79983.98000000","0.00097000"],["79983.97000000","0.00013000"],["79983.50000000","0.00021000"],["79983.49000000","0.08146000"],["79983.24000000","0.00037000"],["79982.81000000","0.00007000"],["79982.75000000","0.00007000"],["79982.72000000","0.00014000"],["79982.71000000","0.01695000"],["79982.28000000","0.00007000"],["79981.99000000","0.00014000"],["79981.94000000","0.00007000"],["79981.54000000","0.00007000"],["79981.51000000","0.00014000"],["79981.44000000","0.00014000"],["79981.43000000","0.02030000"],["79981.29000000","0.00007000"],["79981.06000000","0.00303000"],["79981.05000000","0.00014000"]],"asks":[["79984.00000000","2.22203000"],["79984.01000000","0.00027000"],["79984.02000000","0.00013000"],["79984.27000000","0.00007000"],["79984.61000000","0.00007000"],["79985.10000000","0.00014000"],["79985.11000000","0.40382000"],["79985.12000000","0.00601000"],["79985.14000000","0.00007000"],["79985.16000000","0.00021000"],["79985.50000000","0.00891000"],["79985.94000000","0.01770000"],["79985.99000000","0.00014000"],["79986.00000000","0.02421000"],["79986.20000000","0.00007000"],["79986.28000000","0.00034000"],["79986.29000000","0.00014000"],["79986.63000000","0.00051000"],["79986.64000000","0.05309000"],["79986.78000000","0.01472000"]]}}}
{"rx_ns": 10703552955300, "frame": {"stream":"btcusdt@depth@100ms","data":{"e":"depthUpdate","E":1787647698714,"s":"BTCUSDT","U":99116123541,"u":99116123545,"b":[["71985.60000000","0.00424000"]],"a":[["79984.00000000","2.22203000"]]}}}
{"rx_ns": 10703653658000, "frame": {"stream":"btcusdt@depth20@100ms","data":{"lastUpdateId":99116123556,"bids":[["79983.99000000","0.86120000"],["79983.98000000","0.00097000"],["79983.97000000","0.00013000"],["79983.50000000","0.00021000"],["79983.49000000","0.08146000"],["79983.24000000","0.00037000"],["79982.81000000","0.00007000"],["79982.75000000","0.00007000"],["79982.72000000","0.00014000"],["79982.71000000","0.01695000"],["79982.28000000","0.00007000"],["79981.99000000","0.00014000"],["79981.94000000","0.00007000"],["79981.54000000","0.00007000"],["79981.51000000","0.00014000"],["79981.44000000","0.00014000"],["79981.43000000","0.02030000"],["79981.29000000","0.00007000"],["79981.06000000","0.00303000"],["79981.05000000","0.00014000"]],"asks":[["79984.00000000","2.22213000"],["79984.01000000","0.00027000"],["79984.02000000","0.00013000"],["79984.27000000","0.00007000"],["79984.61000000","0.00007000"],["79985.10000000","0.00014000"],["79985.11000000","0.40382000"],["79985.12000000","0.00601000"],["79985.14000000","0.00007000"],["79985.16000000","0.00021000"],["79985.50000000","0.00891000"],["79985.94000000","0.01770000"],["79985.99000000","0.00014000"],["79986.00000000","0.02421000"],["79986.20000000","0.00007000"],["79986.28000000","0.00034000"],["79986.29000000","0.00014000"],["79986.63000000","0.00051000"],["79986.64000000","0.05309000"],["79986.78000000","0.01472000"]]}}}
{"rx_ns": 10703653733300, "frame": {"stream":"btcusdt@depth@100ms","data":{"e":"depthUpdate","E":1787647698814,"s":"BTCUSDT","U":99116123546,"u":99116123556,"b":[["79981.00000000","0.04791000"],["79980.17000000","0.00014000"],["79899.41000000","0.00000000"],["71985.60000000","0.00424000"],["63987.00000000","0.00000000"]],"a":[["79984.00000000","2.22213000"]]}}}
{"rx_ns": 10703753028900, "frame": {"stream":"btcusdt@depth20@100ms","data":{"lastUpdateId":99116123589,"bids":[["79983.99000000","0.86127000"],["79983.98000000","0.00097000"],["79983.97000000","0.00013000"],["79983.50000000","0.00021000"],["79983.49000000","0.08146000"],["79983.24000000","0.00037000"],["79982.81000000","0.00007000"],["79982.75000000","0.00007000"],["79982.72000000","0.00014000"],["79982.71000000","0.01695000"],["79982.28000000","0.00007000"],["79981.99000000","0.00014000"],["79981.94000000","0.00007000"],["79981.54000000","0.00007000"],["79981.51000000","0.00014000"],["79981.44000000","0.00014000"],["79981.43000000","0.02030000"],["79981.29000000","0.00007000"],["79981.06000000","0.00303000"],["79981.05000000","0.00014000"]],"asks":[["79984.00000000","2.22213000"],["79984.01000000","0.00027000"],["79984.02000000","0.00013000"],["79984.27000000","0.00007000"],["79984.61000000","0.00007000"],["79985.10000000","0.00014000"],["79985.11000000","0.40382000"],["79985.12000000","0.00601000"],["79985.14000000","0.00007000"],["79985.16000000","0.00021000"],["79985.50000000","0.00891000"],["79985.94000000","0.01770000"],["79985.99000000","0.00014000"],["79986.00000000","0.02421000"],["79986.20000000","0.00007000"],["79986.28000000","0.00034000"],["79986.29000000","0.00014000"],["79986.63000000","0.00051000"],["79986.64000000","0.05309000"],["79986.78000000","0.01472000"]]}}}
{"rx_ns": 10703753109700, "frame": {"stream":"btcusdt@depth@100ms","data":{"e":"depthUpdate","E":1787647698914,"s":"BTCUSDT","U":99116123557,"u":99116123589,"b":[["79983.99000000","0.86127000"],["79983.98000000","0.00097000"],["79981.04000000","0.04975000"],["79981.01000000","0.00007000"],["79981.00000000","0.04805000"],["79980.96000000","0.42225000"],["79980.17000000","0.00000000"],["79978.42000000","0.00932000"],["79978.40000000","0.08944000"],["79978.39000000","0.08575000"],["79978.28000000","0.00860000"],["79977.28000000","0.00000000"],["79899.41000000","0.02084000"],["79035.87000000","0.00000000"],["78000.00000000","31.63645000"],["71985.60000000","0.00424000"]],"a":[]}}}
{"rx_ns": 10703856348300, "frame": {"stream":"btcusdt@depth20@100ms","data":{"lastUpdateId":99116124622,"bids":[["79980.15000000","1.49045000"],["79980.14000000","0.00063000"],["79980.10000000","0.00007000"],["79979.99000000","0.00020000"],["79978.93000000","0.00007000"],["79978.73000000","0.00007000"],["79978.42000000","0.00035000"],["79978.40000000","0.00014000"],["79978.39000000","0.00014000"],["79978.29000000","0.00021000"],["79978.28000000","0.00028000"],["79977.99000000","0.00007000"],["79977.42000000","0.00007000"],["79977.27000000","0.00014000"],["79977.20000000","0.00014000"],["79977.19000000","0.04711000"],["79976.90000000","0.00007000"],["79976.85000000","0.00007000"],["79976.67000000","0.00007000"],["79976.29000000","0.00014000"]],"asks":[["79980.16000000","3.84876000"],["79980.17000000","0.00027000"],["79980.18000000","0.00013000"],["79980.97000000","0.00007000"],["79981.01000000","0.00007000"],["79981.04000000","0.00014000"],["79981.05000000","1.00475000"],["79981.06000000","0.01756000"],["79981.29000000","0.00014000"],["79981.65000000","0.00400000"],["79982.78000000","0.00014000"],["79982.79000000","0.05300000"],["79983.49000000","0.00014000"],["79983.50000000","1.05297000"],["79983.51000000","0.08775000"],["79983.88000000","0.00021000"],["79983.99000000","0.00187000"],["79984.00000000","1.38453000"],["79984.21000000","0.00007000"],["79984.27000000","0.00007000"]]}}}
{"rx_ns": 10703856429800, "frame": {"stream":"btcusdt@depth@100ms","data":{"e":"depthUpdate","E":1787647699014,"s":"BTCUSDT","U":99116123590,"u":99116124622,"b":[["79983.99000000","0.00000000"],["79983.98000000","0.00000000"],["79983.97000000","0.00000000"],["79983.50000000","0.00000000"],["79983.49000000","0.00000000"],["79983.24000000","0.00000000"],["79982.81000000","0.00000000"],["79982.75000000","0.00000000"],["79982.72000000","0.00000000"],["79982.71000000","0.00000000"],["79982.28000000","0.00000000"],["79981.99000000","0.00000000"],["79981.94000000","0.00000000"],["79981.54000000","0.00000000"],["79981.51000000","0.00000000"],["79981.44000000","0.00000000"],["79981.43000000","0.00000000"],["79981.29000000","0.00000000"],["79981.06000000","0.00000000"],["79981.05000000","0.00000000"],["79981.04000000","0.00000000"],["79981.01000000","0.00000000"],["79981.00000000","0.00000000"],["79980.97000000","0.00000000"],["79980.96000000","0.00000000"],["79980.23000000","0.00000000"],["79980.15000000","1.49045000"],["79980.14000000","0.00063000"],["79978.42000000","0.00035000"],["79978.41000000","0.00000000"],["79978.40000000","0.00014000"],["79978.39000000","0.00014000"],["79978.31000000","0.00000000"],["79978.29000000","0.00021000"],["79978.28000000","0.00028000"],["79978.08000000","0.00000000"],["79978.00000000","0.00000000"],["79977.42000000","0.00007000"],["79977.28000000","0.00000000"],["79977.27000000","0.00014000"],["79977.20000000","0.00014000"],["79977.19000000","0.04711000"],["79976.16000000","0.00000000"],["79976.15000000","0.00014000"],["79976.01000000","0.00014000"],["79976.00000000","0.02414000"],["79975.99000000","0.00000000"],["79975.87000000","0.00007000"],["79975.86000000","0.00000000"],["79975.84000000","0.00007000"],["79975.73000000","0.00872000"],["79975.23000000","0.00000000"],["79975.05000000","0.00013000"],["79974.56000000","0.00014000"],["79974.55000000","0.08528000"],["79974.47000000","0.00014000"],["79974.46000000","0.01379000"],["79974.29000000","0.00014000"],["79974.28000000","0.12777000"],["79974.01000000","0.00014000"],["79974.00000000","0.02414000"],["79973.80000000","0.00000000"],["79973.70000000","0.00000000"],["79973.58000000","0.00000000"],["79973.55000000","0.00007000"],["79973.43000000","0.08254000"],["79973.04000000","0.20258000"],["79972.90000000","0.00000000"],["79972.65000000","0.00000000"],["79972.31000000","0.08576000"],["79971.99000000","0.00000000"],["79971.89000000","0.00000000"],["79971.86000000","0.00000000"],["79971.85000000","0.00000000"],["79971.38000000","0.00000000"],["79971.19000000","0.08576000"],["79970.90000000","0.00000000"],["79970.45000000","0.00000000"],["79970.35000000","0.08576000"],["79970.34000000","1.99564000"],["79970.33000000","0.00000000"],["79970.17000000","0.00000000"],["79970.07000000","0.00000000"],["79970.01000000","0.00454000"],["79970.00000000","0.02426000"],["79969.68000000","0.00014000"],["79969.31000000","0.00000000"],["79969.06000000","0.00000000"],["79969.05000000","0.00000000"],["79969.04000000","0.00000000"],["79969.03000000","0.00000000"],["79968.54000000","0.00000000"],["79968.41000000","0.08118000"],["79968.02000000","0.00000000"],["79967.61000000","0.00000000"],["79967.60000000","0.00000000"],["79967.47000000","0.00000000"],["79967.35000000","0.00000000"],["79967.03000000","0.00000000"],["79966.96000000","0.94716000"],["79966.95000000","1.04939000"],["79966.71000000","0.00000000"],["79966.56000000","0.00000000"],["79966.55000000","0.00000000"],["79966.17000000","0.00000000"],["79966.02000000","0.00625000"],["79966.01000000","0.00007000"],["79965.81000000","0.00014000"],["79965.59000000","0.00000000"],["79965.58000000","0.00000000"],["79965.46000000","1.87060000"],["79965.45000000","0.00000000"],["79965.30000000","0.00000000"],["79965.15000000","0.00000000"],["79964.81000000","0.00000000"],["79964.47000000","0.00000000"],["79964.34000000","0.00000000"],["79964.14000000","0.00000000"],["79963.39000000","0.36586000"],["79963.38000000","0.02200000"],["79963.37000000","0.02000000"],["79962.95000000","0.57759000"],["79962.94000000","1.04939000"],["79962.51000000","0.00250000"],["79962.35000000","0.12505000"],["79962.23000000","0.00000000"],["79962.01000000","0.00407000"],["79961.94000000","0.00014000"],["79961.87000000","0.00000000"],["79961.44000000","0.06296000"],["79961.29000000","0.00000000"],["79961.28000000","0.31274000"],["79960.86000000","0.00000000"],["79960.65000000","0.00000000"],["79960.01000000","0.00007000"],["79959.82000000","0.00000000"],["79959.80000000","1.07828000"],["79959.79000000","1.87460000"],["79959.78000000","0.00000000"],["79959.77000000","0.00000000"],["79959.76000000","0.00000000"],["79959.44000000","0.07247000"],["79959.41000000","0.03000000"],["79958.83000000","0.00000000"],["79958.76000000","0.00000000"],["79958.66000000","0.00000000"],["79958.65000000","1.04939000"],["79957.82000000","0.00000000"],["79957.58000000","0.00000000"],["79956.98000000","0.00000000"],["79956.97000000","0.00000000"],["79956.81000000","0.12000000"],["79956.45000000","0.25048000"],["79956.44000000","0.15383000"],["79956.43000000","0.02000000"],["79956.02000000","0.00000000"],["79955.62000000","0.00151000"],["79955.33000000","0.36586000"],["79954.82000000","0.00000000"],["79954.81000000","1.01582000"],["79954.75000000","0.00000000"],["79954.35000000","0.12507000"],["79954.34000000","0.00000000"],["79952.68000000","0.00000000"],["79952.37000000","0.00000000"],["79951.64000000","0.00625000"],["79951.25000000","0.00000000"],["79950.82000000","0.00000000"],["79950.01000000","0.62536000"],["79950.00000000","0.02407000"],["79947.69000000","0.00000000"],["79946.70000000","0.00000000"],["79946.26000000","0.36586000"],["79945.83000000","0.00000000"],["79944.51000000","0.00000000"],["79943.55000000","0.00000000"],["79943.00000000","0.00000000"],["79942.82000000","0.00000000"],["79942.59000000","0.00014000"],["79942.27000000","0.00000000"],["79941.00000000","0.00000000"],["79940.00000000","0.03585000"],["79939.61000000","0.00000000"],["79938.72000000","0.00007000"],["79938.44000000","0.63423000"],["79934.85000000","0.00007000"],["79933.87000000","0.33787000"],["79933.83000000","0.00000000"],["79933.67000000","0.00000000"],["79933.14000000","0.02000000"],["79932.31000000","0.00000000"],["79931.29000000","0.62572000"],["79930.98000000","0.00007000"],["79930.44000000","0.33789000"],["79930.24000000","0.00000000"],["79930.00000000","0.12085000"],["79928.45000000","0.26124000"],["79927.70000000","0.00000000"],["79927.11000000","0.00000000"],["79926.54000000","0.00619000"],["79926.42000000","0.00000000"],["79923.89000000","1.50272000"],["79923.30000000","0.04595000"],["79921.80000000","0.00400000"],["79918.63000000","0.00428000"],["79915.80000000","0.00007000"],["79915.55000000","0.00000000"],["79915.50000000","0.00400000"],["79915.00000000","0.00000000"],["79913.75000000","0.00433000"],["79912.13000000","0.00000000"],["79908.12000000","0.00311000"],["79907.47000000","1.23929000"],["79900.38000000","0.01731000"],["79899.41000000","0.00000000"],["79897.61000000","0.00000000"],["79893.77000000","0.83943000"],["79893.76000000","1.74240000"],["79893.66000000","0.00000000"],["79893.51000000","0.00000000"],["79893.44000000","0.00000000"],["79893.40000000","0.00312000"],["79889.05000000","0.00000000"],["79887.89000000","0.00000000"],["79886.82000000","0.00000000"],["79830.33000000","0.00000000"],["79830.32000000","0.00000000"],["79827.18000000","0.00125000"],["79824.43000000","0.00000000"],["79821.12000000","0.00202000"],["79813.65000000","1.50117000"],["79768.23000000","3.76200000"],["79652.09000000","0.00000000"],["79645.45000000","0.20250000"],["79641.13000000","0.00035000"],["78784.23000000","0.00000000"],["78780.44000000","0.00030000"],["71985.60000000","0.00000000"],["71985.59000000","0.00008000"],["71982.14000000","0.00016000"],["63987.00000000","0.00000000"],["63984.12000000","0.00031000"]],"a":[["79980.16000000","3.84876000"],["79980.17000000","0.00027000"],["79980.18000000","0.00013000"],["79980.97000000","0.00007000"],["79981.00000000","0.00000000"],["79981.01000000","0.00007000"],["79981.04000000","0.00014000"],["79981.05000000","1.00475000"],["79981.06000000","0.01756000"],["79981.07000000","0.00000000"],["79981.29000000","0.00014000"],["79981.44000000","0.00000000"],["79981.55000000","0.00000000"],["79981.65000000","0.00400000"],["79981.95000000","0.00000000"],["79982.00000000","0.00000000"],["79982.29000000","0.00000000"],["79982.52000000","0.00000000"],["79982.72000000","0.00000000"],["79982.73000000","0.00000000"],["79982.76000000","0.00000000"],["79982.78000000","0.00014000"],["79982.79000000","0.05300000"],["79982.82000000","0.00000000"],["79983.25000000","0.00000000"],["79983.48000000","0.00000000"],["79983.49000000","0.00014000"],["79983.50000000","1.05297000"],["79983.51000000","0.08775000"],["79983.52000000","0.00000000"],["79983.68000000","0.00000000"],["79983.87000000","0.00000000"],["79983.88000000","0.00021000"],["79983.93000000","0.00000000"],["79983.98000000","0.00000000"],["79983.99000000","0.00187000"],["79984.00000000","1.38453000"],["79984.01000000","0.00000000"],["79984.02000000","0.00000000"],["79984.21000000","0.00007000"],["79984.56000000","0.03224000"],["79984.75000000","0.00000000"],["79984.80000000","0.00400000"],["79985.10000000","0.00000000"],["79985.11000000","0.00021000"],["79985.50000000","0.00021000"],["79985.94000000","0.01756000"],["79985.99000000","0.00000000"],["79986.00000000","0.02407000"],["79986.21000000","0.00000000"],["79986.28000000","0.00000000"],["79986.63000000","0.00000000"],["79986.64000000","0.00007000"],["79986.78000000","0.00007000"],["79987.04000000","0.00013000"],["79987.36000000","0.00000000"],["79987.87000000","0.00613000"],["79987.97000000","0.47301000"],["79987.98000000","0.36586000"],["79988.00000000","0.03589000"],["79988.06000000","0.00007000"],["79988.18000000","0.00000000"],["79988.23000000","0.00000000"],["79988.24000000","1.01133000"],["79988.28000000","0.00000000"],["79988.72000000","0.00007000"],["79989.05000000","0.00008000"],["79989.34000000","0.00000000"],["79989.61000000","0.01749000"],["79989.75000000","0.00000000"],["79989.84000000","0.00008000"],["79989.99000000","0.00000000"],["79990.00000000","0.02400000"],["79990.17000000","0.08576000"],["79990.64000000","0.00000000"],["79991.34000000","0.00048000"],["79991.97000000","0.13341000"],["79991.98000000","1.87060000"],["79991.99000000","1.04939000"],["79992.21000000","0.02000000"],["79992.28000000","0.12501000"],["79992.45000000","0.23622000"],["79992.79000000","0.00000000"],["79993.43000000","0.00000000"],["79993.99000000","0.00625000"],["79994.51000000","0.00000000"],["79994.90000000","0.00000000"],["79995.00000000","0.00000000"],["79995.97000000","0.38348000"],["79996.13000000","0.33761000"],["79996.59000000","0.06294000"],["79997.30000000","0.00000000"],["79998.32000000","0.00000000"],["79998.58000000","0.62540000"],["79998.59000000","0.07243000"],["79998.89000000","0.00000000"],["79999.17000000","0.00000000"],["79999.45000000","0.00000000"],["80000.00000000","0.82130000"],["80000.15000000","0.00000000"],["80000.23000000","0.83149000"],["80000.46000000","0.00000000"],["80000.63000000","0.00000000"],["80001.99000000","0.00000000"],["80004.47000000","0.00000000"],["80005.43000000","0.00000000"],["80007.79000000","0.00000000"],["80008.15000000","0.00250000"],["80009.79000000","0.00000000"],["80010.85000000","0.00000000"],["80011.13000000","0.00000000"],["80011.63000000","0.33755000"],["80012.01000000","0.00000000"],["80013.15000000","0.00000000"],["80013.35000000","0.63364000"],["80014.76000000","0.09274000"],["80017.13000000","0.00000000"],["80021.18000000","0.00000000"],["80021.39000000","0.00000000"],["80022.43000000","0.00000000"],["80022.53000000","0.00000000"],["80023.86000000","0.00000000"],["80024.04000000","0.00000000"],["80024.59000000","0.00000000"],["80026.65000000","0.47211000"],["80030.97000000","0.00000000"],["80031.59000000","0.00000000"],["80035.20000000","0.00000000"],["80036.02000000","0.00000000"],["80040.36000000","1.23724000"],["80044.02000000","0.00000000"],["80046.69000000","0.00000000"],["80047.75000000","0.00000000"],["80059.30000000","0.00000000"],["80059.48000000","0.00000000"],["80060.32000000","0.00000000"],["80068.60000000","0.38716000"],["80086.63000000","0.00000000"],["80096.23000000","0.00000000"],["80113.99000000","0.00007000"],["80117.51000000","1.50117000"],["80120.16000000","0.00000000"],["80125.99000000","0.00125000"],["80128.79000000","0.00000000"],["80134.01000000","0.00202000"],["80134.25000000","0.00007000"],["80136.84000000","0.00000000"],["80241.97000000","2.50000000"],["80282.07000000","7.47585000"],["80282.67000000","0.00000000"],["80538.59000000","0.00000000"],["81183.76000000","0.00000000"]]}}}
{"rx_ns": 10703955450200, "frame": {"stream":"btcusdt@depth20@100ms","data":{"lastUpdateId":99116124872,"bids":[["79980.15000000","1.30120000"],["79980.14000000","0.00084000"],["79980.10000000","0.00015000"],["79979.99000000","0.00020000"],["79979.03000000","0.00907000"],["79978.93000000","0.00007000"],["79978.73000000","0.00007000"],["79978.42000000","0.00007000"],["79978.29000000","0.00007000"],["79978.28000000","0.00007000"],["79977.99000000","0.00007000"],["79977.76000000","0.00014000"],["79977.75000000","0.01507000"],["79977.42000000","0.00007000"],["79977.20000000","0.00014000"],["79977.19000000","0.04725000"],["79976.90000000","0.00007000"],["79976.85000000","0.00007000"],["79976.67000000","0.00007000"],["79976.48000000","0.00014000"]],"asks":[["79980.16000000","3.38551000"],["79980.17000000","0.00027000"],["79980.18000000","0.00013000"],["79980.32000000","0.00014000"],["79980.33000000","0.00974000"],["79980.97000000","0.00007000"],["79981.01000000","0.00007000"],["79981.04000000","0.00014000"],["79981.05000000","1.00475000"],["79981.06000000","0.01784000"],["79981.15000000","0.00594000"],["79981.29000000","0.00014000"],["79981.61000000","0.01625000"],["79981.65000000","0.00400000"],["79982.77000000","0.00040000"],["79982.78000000","0.00014000"],["79982.79000000","0.05314000"],["79982.89000000","0.01949000"],["79983.49000000","0.00014000"],["79983.50000000","0.85047000"]]}}}
{"rx_ns": 10703955593400, "frame": {"stream":"btcusdt@depth@100ms","data":{"e":"depthUpdate","E":1787647699114,"s":"BTCUSDT","U":99116124623,"u":99116124872,"b":[["79980.15000000","1.30120000"],["79980.14000000","0.00084000"],["79980.10000000","0.00015000"],["79979.03000000","0.00907000"],["79978.42000000","0.00007000"],["79978.40000000","0.00000000"],["79978.39000000","0.00000000"],["79978.29000000","0.00007000"],["79978.28000000","0.00007000"],["79977.76000000","0.00014000"],["79977.75000000","0.01507000"],["79977.27000000","0.00000000"],["79977.21000000","0.00000000"],["79977.20000000","0.00014000"],["79977.19000000","0.04725000"],["79976.48000000","0.00014000"],["79976.47000000","0.01800000"],["79976.29000000","0.00007000"],["79976.15000000","0.00000000"],["79976.00000000","0.02421000"],["79975.73000000","0.00886000"],["79975.64000000","0.00000000"],["79975.63000000","0.00000000"],["79975.20000000","0.00007000"],["79975.19000000","0.01800000"],["79974.56000000","0.00007000"],["79974.55000000","0.00007000"],["79974.47000000","0.00000000"],["79974.46000000","0.01386000"],["79974.30000000","0.00000000"],["79974.29000000","0.00000000"],["79974.28000000","0.12784000"],["79974.01000000","0.00007000"],["79974.00000000","0.02407000"],["79973.43000000","0.00000000"],["79973.34000000","0.00000000"],["79973.04000000","0.20258000"],["79972.31000000","0.00000000"],["79972.24000000","0.08445000"],["79971.19000000","0.00000000"],["79971.11000000","0.08662000"],["79970.37000000","0.92009000"],["79970.36000000","1.87060000"],["79970.35000000","0.00000000"],["79970.34000000","0.12504000"],["79969.99000000","0.00000000"],["79969.68000000","0.00007000"],["79969.66000000","0.31271000"],["79969.28000000","0.08118000"],["79968.41000000","0.00000000"],["79967.14000000","0.00151000"],["79966.96000000","0.92309000"],["79965.75000000","0.08576000"],["79965.02000000","0.00048000"],["79962.95000000","0.51959000"],["79962.07000000","0.02474000"],["79961.28000000","0.00000000"],["79959.82000000","0.15382000"],["79959.41000000","0.15000000"],["79956.81000000","0.00000000"],["79956.44000000","0.00000000"],["79955.62000000","0.00000000"],["79953.29000000","0.50760000"],["79952.60000000","0.00192000"],["79951.67000000","0.00012000"],["79951.45000000","0.00060000"],["79950.00000000","0.11788000"],["79946.56000000","1.53839000"],["79943.46000000","0.00000000"],["79942.24000000","0.09328000"],["79940.00000000","0.13219000"],["79930.98000000","0.00000000"],["79930.00000000","0.11834000"],["79929.30000000","1.01878000"],["79924.95000000","0.00400000"],["79918.65000000","0.66155000"],["79915.50000000","0.00000000"],["79908.12000000","0.00000000"],["79899.61000000","0.00110000"],["79893.24000000","0.12212000"],["79842.66000000","0.00000000"],["79827.18000000","0.00000000"],["79821.12000000","0.00000000"],["71982.14000000","0.00032000"]],"a":[["79980.16000000","3.38551000"],["79980.32000000","0.00014000"],["79980.33000000","0.00974000"],["79981.05000000","1.00475000"],["79981.06000000","0.01784000"],["79981.15000000","0.00594000"],["79981.61000000","0.01625000"],["79982.77000000","0.00040000"],["79982.79000000","0.05314000"],["79982.89000000","0.01949000"],["79983.50000000","0.85047000"],["79983.51000000","0.08782000"],["79983.88000000","0.00007000"],["79983.99000000","0.00021000"],["79984.00000000","1.09342000"],["79984.17000000","0.01949000"],["79984.56000000","0.03231000"],["79985.11000000","0.00007000"],["79985.12000000","0.00601000"],["79985.50000000","0.00007000"],["79987.96000000","0.00000000"],["79988.00000000","0.03582000"],["79988.06000000","0.00000000"],["79988.24000000","0.97806000"],["79989.76000000","0.00000000"],["79991.69000000","0.00069000"],["79991.96000000","1.87060000"],["79991.98000000","0.00000000"],["79996.16000000","0.66565000"],["80001.02000000","0.00166000"],["80001.61000000","0.02448000"],["80006.24000000","0.00000000"],["80008.44000000","0.00060000"],["80008.67000000","0.00012000"],["80009.69000000","0.00192000"],["80019.20000000","0.00000000"],["80021.00000000","0.01000000"],["80024.00000000","0.02400000"],["80036.02000000","0.20250000"],["80046.56000000","0.00536000"],["80046.75000000","0.00110000"],["80047.58000000","0.01731000"],["80134.01000000","0.00000000"]]}}}
{"rx_ns": 10704054965200, "frame": {"stream":"btcusdt@depth20@100ms","data":{"lastUpdateId":99116124989,"bids":[["79980.15000000","1.11438000"],["79980.14000000","0.00084000"],["79980.10000000","0.00015000"],["79979.99000000","0.00020000"],["79979.03000000","0.00921000"],["79978.93000000","0.00007000"],["79978.73000000","0.00007000"],["79978.42000000","0.00007000"],["79978.29000000","0.00007000"],["79978.28000000","0.00007000"],["79978.05000000","0.00014000"],["79978.04000000","0.09946000"],["79977.99000000","0.00007000"],["79977.76000000","0.00014000"],["79977.75000000","0.01514000"],["79977.42000000","0.00007000"],["79977.20000000","0.00014000"],["79977.19000000","0.04725000"],["79976.90000000","0.00007000"],["79976.85000000","0.00007000"]],"asks":[["79980.16000000","0.00067000"],["79980.17000000","0.00027000"],["79980.18000000","0.00013000"],["79980.32000000","0.00014000"],["79980.33000000","0.00981000"],["79980.97000000","0.00007000"],["79981.01000000","0.00007000"],["79981.04000000","0.00014000"],["79981.05000000","1.00475000"],["79981.06000000","0.01777000"],["79981.15000000","0.00007000"],["79981.23000000","0.00014000"],["79981.24000000","0.04786000"],["79981.29000000","0.00014000"],["79981.61000000","0.01632000"],["79981.64000000","0.00597000"],["79981.65000000","0.00400000"],["79982.78000000","0.00014000"],["79982.79000000","0.05314000"],["79982.89000000","0.01956000"]]}}}
{"rx_ns": 10704055055000, "frame": {"stream":"btcusdt@depth@100ms","data":{"e":"depthUpdate","E":1787647699214,"s":"BTCUSDT","U":99116124873,"u":99116124989,"b":[["79980.15000000","1.11438000"],["79980.14000000","0.00084000"],["79979.03000000","0.00921000"],["79978.05000000","0.00014000"],["79978.04000000","0.09946000"],["79977.75000000","0.01514000"],["79977.19000000","0.04725000"],["79976.48000000","0.00007000"],["79976.47000000","0.01807000"],["79976.01000000","0.00007000"],["79975.73000000","0.00879000"],["79975.20000000","0.00000000"],["79975.19000000","0.01807000"],["79974.55000000","0.00000000"],["79974.50000000","0.08662000"],["79974.29000000","0.29017000"],["79974.28000000","0.12777000"],["79974.00000000","0.02407000"],["79973.55000000","0.00014000"],["79973.37000000","0.00000000"],["79973.20000000","0.42211000"],["79972.24000000","0.00000000"],["79971.11000000","0.00000000"],["79970.37000000","0.83347000"],["79969.68000000","0.00014000"],["79964.33000000","0.00000000"],["79960.82000000","0.00399000"],["79947.86000000","0.00000000"],["79924.33000000","0.00000000"],["79920.83000000","0.00399000"],["79908.12000000","0.00311000"],["79895.96000000","1.23947000"],["79892.36000000","0.00000000"],["79888.85000000","0.00409000"],["79883.77000000","0.62495000"],["79883.22000000","0.00000000"],["79879.39000000","0.00025000"],["79844.38000000","0.00000000"],["79840.87000000","0.00399000"],["79838.13000000","0.04528000"],["79827.18000000","0.00125000"],["79772.41000000","0.00000000"],["79768.91000000","0.00399000"],["71982.14000000","0.00048000"],["63984.12000000","0.00000000"]],"a":[["79980.16000000","0.00067000"],["79980.33000000","0.00981000"],["79981.06000000","0.01777000"],["79981.15000000","0.00007000"],["79981.23000000","0.00014000"],["79981.24000000","0.04786000"],["79981.61000000","0.01632000"],["79981.64000000","0.00597000"],["79982.77000000","0.00000000"],["79982.79000000","0.05314000"],["79982.89000000","0.01956000"],["79983.50000000","0.20652000"],["79983.51000000","0.08768000"],["79983.99000000","0.00007000"],["79984.00000000","1.05639000"],["79984.56000000","0.03224000"],["79985.12000000","0.00587000"],["79986.95000000","0.00000000"],["79987.98000000","0.00000000"],["79991.34000000","0.00000000"],["80007.09000000","0.00399000"],["80010.55000000","0.00000000"],["80025.15000000","0.00000000"],["80079.10000000","0.00399000"],["80079.34000000","0.00025000"],["80082.56000000","0.00000000"],["80083.18000000","0.12223000"],["80127.11000000","0.00399000"],["80130.57000000","0.00000000"],["80703.85000000","0.00000000"]]}}}
{"rx_ns": 10704152943900, "frame": {"stream":"btcusdt@depth20@100ms","data":{"lastUpdateId":99116125275,"bids":[["79980.15000000","2.09413000"],["79980.14000000","0.00063000"],["79980.10000000","0.00015000"],["79979.99000000","0.00020000"],["79979.03000000","0.00928000"],["79978.93000000","0.00007000"],["79978.73000000","0.00007000"],["79978.42000000","0.00007000"],["79978.29000000","0.00007000"],["79978.28000000","0.00007000"],["79978.17000000","0.00026000"],["79978.06000000","0.00014000"],["79978.05000000","0.06132000"],["79978.04000000","0.09953000"],["79977.99000000","0.00007000"],["79977.76000000","0.00014000"],["79977.75000000","0.01514000"],["79977.42000000","0.00007000"],["79977.20000000","0.00014000"],["79977.19000000","0.04725000"]],"asks":[["79980.16000000","2.06439000"],["79980.17000000","0.00027000"],["79980.18000000","0.00013000"],["79980.32000000","0.00014000"],["79980.33000000","0.00981000"],["79980.97000000","0.00007000"],["79981.01000000","0.00007000"],["79981.04000000","0.00014000"],["79981.05000000","0.67260000"],["79981.06000000","0.00021000"],["79981.24000000","0.00007000"],["79981.29000000","0.00014000"],["79981.61000000","0.01632000"],["79981.64000000","0.00007000"],["79981.65000000","0.00400000"],["79982.78000000","0.00014000"],["79982.79000000","0.05314000"],["79982.89000000","0.01956000"],["79983.50000000","0.00021000"],["79983.51000000","0.08768000"]]}}}
{"rx_ns": 10704153032600, "frame": {"stream":"btcusdt@depth@100ms","data":{"e":"depthUpdate","E":1787647699314,"s":"BTCUSDT","U":99116124990,"u":99116125275,"b":[["79980.15000000","2.09413000"],["79980.14000000","0.00063000"],["79979.05000000","0.00000000"],["79979.04000000","0.00000000"],["79979.03000000","0.00928000"],["79978.32000000","0.00000000"],["79978.17000000","0.00026000"],["79978.06000000","0.00014000"],["79978.05000000","0.06132000"],["79978.04000000","0.09953000"],["79977.76000000","0.00014000"],["79977.20000000","0.00014000"],["79976.77000000","0.00000000"],["79976.76000000","0.00000000"],["79976.48000000","0.00007000"],["79976.01000000","0.00000000"],["79975.73000000","0.00886000"],["79975.63000000","0.00000000"],["79975.44000000","0.21414000"],["79975.43000000","0.42215000"],["79975.19000000","0.01807000"],["79974.50000000","0.00000000"],["79974.46000000","0.01386000"],["79974.30000000","0.00000000"],["79974.29000000","0.00000000"],["79974.00000000","0.02407000"],["79973.21000000","0.00000000"],["79973.20000000","0.00000000"],["79973.04000000","0.00008000"],["79972.24000000","0.08662000"],["79972.20000000","0.00400000"],["79971.22000000","0.15380000"],["79971.21000000","0.08662000"],["79971.20000000","0.00000000"],["79971.19000000","1.04939000"],["79971.11000000","0.00000000"],["79970.38000000","0.00625000"],["79969.28000000","0.00000000"],["79968.75000000","0.00000000"],["79966.02000000","0.00000000"],["79964.91000000","0.00007000"],["79960.44000000","0.00000000"],["79960.43000000","0.03224000"],["79959.82000000","0.00000000"],["79955.09000000","0.37532000"],["79948.62000000","0.42472000"],["79945.60000000","0.33782000"],["79934.85000000","0.00000000"],["79921.80000000","0.00000000"],["79920.83000000","0.00000000"],["79888.85000000","0.00010000"],["79768.91000000","0.00000000"],["79768.23000000","0.00000000"],["71985.59000000","0.00000000"],["71982.14000000","0.00080000"],["71982.00000000","0.00000000"],["63984.00000000","0.00014000"]],"a":[["79980.16000000","2.06439000"],["79981.05000000","0.67260000"],["79981.06000000","0.00021000"],["79981.15000000","0.00000000"],["79981.23000000","0.00000000"],["79981.24000000","0.00007000"],["79981.61000000","0.01632000"],["79981.64000000","0.00007000"],["79982.58000000","0.00000000"],["79983.49000000","0.00000000"],["79983.50000000","0.00021000"],["79983.51000000","0.08768000"],["79983.87000000","0.00000000"],["79983.98000000","0.00000000"],["79983.99000000","0.01756000"],["79984.00000000","1.04297000"],["79984.21000000","0.00000000"],["79984.56000000","0.00000000"],["79985.11000000","0.00000000"],["79985.12000000","0.00000000"],["79985.15000000","0.00000000"],["79985.49000000","0.00038000"],["79985.94000000","0.00007000"],["79986.29000000","0.00007000"],["79987.87000000","0.00599000"],["79987.95000000","0.32916000"],["79987.96000000","1.06688000"],["79987.97000000","0.00000000"],["79987.99000000","0.00000000"],["79988.24000000","0.93884000"],["79989.61000000","0.00000000"],["79990.81000000","0.02000000"],["79990.96000000","0.00000000"],["79991.95000000","1.87060000"],["79991.96000000","0.00000000"],["79991.97000000","0.00000000"],["79991.98000000","1.04939000"],["79991.99000000","0.00000000"],["79992.12000000","0.00048000"],["79992.21000000","0.00000000"],["79992.45000000","0.13043000"],["79992.46000000","0.00153000"],["79993.91000000","0.02000000"],["79993.99000000","0.00000000"],["79995.97000000","0.00000000"],["79996.13000000","0.00000000"],["79996.91000000","0.00007000"],["79997.88000000","0.00625000"],["79998.58000000","0.30915000"],["79999.71000000","0.13341000"],["80000.23000000","0.20631000"],["80000.75000000","0.00000000"],["80001.26000000","0.00000000"],["80001.99000000","0.62540000"],["80007.09000000","0.00000000"],["80009.98000000","1.13351000"],["80010.20000000","0.62510000"],["80016.30000000","0.33753000"],["80022.31000000","1.23751000"],["80040.36000000","0.00000000"],["80041.99000000","0.00190000"],["80045.69000000","0.00399000"],["80050.21000000","0.00000000"],["80079.10000000","0.00000000"],["80096.86000000","0.01326000"],["80121.99000000","0.00076000"],["80127.11000000","0.00000000"],["80197.70000000","0.00399000"],["80202.12000000","0.00000000"],["81179.87000000","0.00030000"]]}}}
{"rx_ns": 10704257515400, "frame": {"stream":"btcusdt@depth20@100ms","data":{"lastUpdateId":99116125339,"bids":[["79980.15000000","2.09413000"],["79980.14000000","0.00063000"],["79980.10000000","0.00015000"],["79979.99000000","0.00020000"],["79979.03000000","0.00928000"],["79978.93000000","0.00007000"],["79978.73000000","0.00007000"],["79978.42000000","0.00007000"],["79978.29000000","0.00007000"],["79978.28000000","0.00007000"],["79978.17000000","0.00026000"],["79978.06000000","0.00014000"],["79978.05000000","0.06139000"],["79978.04000000","0.09953000"],["79977.99000000","0.00007000"],["79977.76000000","0.00014000"],["79977.75000000","0.01514000"],["79977.42000000","0.00007000"],["79977.20000000","0.00014000"],["79977.19000000","0.04725000"]],"asks":[["79980.16000000","2.07341000"],["79980.17000000","0.00027000"],["79980.18000000","0.00013000"],["79980.32000000","0.00014000"],["79980.33000000","0.00981000"],["79980.97000000","0.00007000"],["79981.01000000","0.00007000"],["79981.04000000","0.00014000"],["79981.05000000","0.67253000"],["79981.06000000","0.00014000"],["79981.29000000","0.00014000"],["79981.61000000","0.01639000"],["79981.65000000","0.00400000"],["79981.95000000","0.00007000"],["79982.62000000","0.00014000"],["79982.63000000","0.04018000"],["79982.78000000","0.00014000"],["79982.79000000","0.05314000"],["79982.89000000","0.01956000"],["79983.50000000","0.00021000"]]}}}
{"rx_ns": 10704257610200, "frame": {"stream":"btcusdt@depth@100ms","data":{"e":"depthUpdate","E":1787647699414,"s":"BTCUSDT","U":99116125276,"u":99116125339,"b":[["79980.15000000","2.09413000"],["79979.03000000","0.00928000"],["79978.05000000","0.06139000"],["79975.73000000","0.00893000"],["79975.19000000","0.01800000"],["79974.46000000","0.01379000"],["79972.24000000","0.00000000"],["79971.22000000","0.00000000"],["79971.21000000","0.00000000"],["79960.71000000","0.15382000"],["79934.85000000","0.00007000"],["79767.52000000","0.00399000"],["71982.14000000","0.00096000"],["63984.12000000","0.00000000"],["42091.80000000","0.00000000"]],"a":[["79980.16000000","2.07341000"],["79981.05000000","0.67253000"],["79981.06000000","0.00014000"],["79981.24000000","0.00000000"],["79981.61000000","0.01639000"],["79981.64000000","0.00000000"],["79981.95000000","0.00007000"],["79982.62000000","0.00014000"],["79982.63000000","0.04018000"],["79982.89000000","0.01956000"],["79983.51000000","0.08775000"],["79983.54000000","0.00007000"],["79983.99000000","0.01756000"],["79984.00000000","1.04297000"],["79985.14000000","0.00000000"],["79985.50000000","0.00000000"],["79985.94000000","0.00000000"],["79987.87000000","0.00606000"],["79988.16000000","0.00007000"],["79992.00000000","0.25160000"],["79996.16000000","0.66572000"],["80000.00000000","0.12123000"],["80003.97000000","0.49046000"],["80004.16000000","0.00007000"],["80008.00000000","0.02407000"],["80027.98000000","0.98684000"]]}}}
{"rx_ns": 10704355546800, "frame": {"stream":"btcusdt@depth20@100ms","data":{"lastUpdateId":99116125352,"bids":[["79980.15000000","2.09413000"],["79980.14000000","0.00063000"],["79980.10000000","0.00015000"],["79979.99000000","0.00020000"],["79979.03000000","0.00928000"],["79978.93000000","0.00007000"],["79978.73000000","0.00007000"],["79978.42000000","0.00007000"],["79978.29000000","0.00007000"],["79978.28000000","0.00007000"],["79978.17000000","0.00026000"],["79978.06000000","0.00014000"],["79978.05000000","0.06139000"],["79978.04000000","0.09953000"],["79977.99000000","0.00007000"],["79977.76000000","0.00014000"],["79977.75000000","0.01514000"],["79977.42000000","0.00007000"],["79977.20000000","0.00014000"],["79977.19000000","0.04725000"]],"asks":[["79980.16000000","2.07341000"],["79980.17000000","0.00027000"],["79980.18000000","0.00013000"],["79980.32000000","0.00014000"],["79980.33000000","0.00981000"],["79980.97000000","0.00007000"],["79981.01000000","0.00007000"],["79981.04000000","0.00014000"],["79981.05000000","0.67253000"],["79981.06000000","0.00014000"],["79981.29000000","0.00014000"],["79981.61000000","0.01639000"],["79981.65000000","0.00400000"],["79981.95000000","0.00007000"],["79982.30000000","0.00441000"],["79982.62000000","0.00014000"],["79982.63000000","0.04025000"],["79982.78000000","0.00014000"],["79982.79000000","0.05314000"],["79982.89000000","0.01956000"]]}}}
{"rx_ns": 10704355674800, "frame": {"stream":"btcusdt@depth@100ms","data":{"e":"depthUpdate","E":1787647699514,"s":"BTCUSDT","U":99116125340,"u":99116125352,"b":[["71982.14000000","0.00112000"],["63984.12000000","0.00031000"]],"a":[["79980.16000000","2.07341000"],["79981.61000000","0.01639000"],["79982.30000000","0.00441000"],["79982.63000000","0.04025000"],["79984.00000000","1.04283000"],["79984.17000000","0.01956000"],["79984.67000000","0.00578000"],["80319.20000000","2.50000000"]]}}}
{"rx_ns": 10704452740300, "frame": {"stream":"btcusdt@depth20@100ms","data":{"lastUpdateId":99116125385,"bids":[["79980.15000000","2.09413000"],["79980.14000000","0.00056000"],["79980.10000000","0.00015000"],["79979.99000000","0.00020000"],["79979.77000000","0.00014000"],["79979.76000000","0.06664000"],["79979.03000000","0.00928000"],["79978.93000000","0.00007000"],["79978.73000000","0.00007000"],["79978.42000000","0.00007000"],["79978.29000000","0.00007000"],["79978.28000000","0.00007000"],["79978.17000000","0.00026000"],["79978.05000000","0.00007000"],["79978.04000000","0.00007000"],["79977.99000000","0.00007000"],["79977.76000000","0.00014000"],["79977.75000000","0.01514000"],["79977.42000000","0.00007000"],["79977.20000000","0.00014000"]],"asks":[["79980.16000000","2.07333000"],["79980.17000000","0.00027000"],["79980.18000000","0.00013000"],["79980.32000000","0.00014000"],["79980.33000000","0.00981000"],["79980.97000000","0.00007000"],["79981.01000000","0.00007000"],["79981.04000000","0.00014000"],["79981.05000000","0.67253000"],["79981.06000000","0.00014000"],["79981.29000000","0.00014000"],["79981.61000000","0.01639000"],["79981.65000000","0.00400000"],["79981.95000000","0.00007000"],["79982.30000000","0.00441000"],["79982.62000000","0.00014000"],["79982.63000000","0.04025000"],["79982.78000000","0.00014000"],["79982.79000000","0.05314000"],["79982.89000000","0.01963000"]]}}}
{"rx_ns": 10704452818900, "frame": {"stream":"btcusdt@depth@100ms","data":{"e":"depthUpdate","E":1787647699614,"s":"BTCUSDT","U":99116125353,"u":99116125385,"b":[["79980.15000000","2.09413000"],["79980.14000000","0.00056000"],["79979.77000000","0.00014000"],["79979.76000000","0.06664000"],["79978.06000000","0.00000000"],["79978.05000000","0.00007000"],["79978.04000000","0.00007000"],["79976.48000000","0.00014000"],["79976.01000000","0.00007000"],["79971.21000000","0.08662000"],["79971.20000000","0.15380000"],["79960.71000000","0.00000000"],["79887.46000000","0.00399000"],["71982.14000000","0.00128000"],["63984.12000000","0.00000000"]],"a":[["79980.16000000","2.07333000"],["79982.89000000","0.01963000"],["79982.95000000","0.00007000"],["79982.96000000","0.04983000"],["79983.50000000","0.00014000"],["79993.14000000","0.03142000"]]}}}
{"rx_ns": 10704559138000, "frame": {"stream":"btcusdt@depth20@100ms","data":{"lastUpdateId":99116125418,"bids":[["79980.15000000","2.09409000"],["79980.14000000","0.00056000"],["79980.10000000","0.00015000"],["79979.99000000","0.00020000"],["79979.77000000","0.00014000"],["79979.76000000","0.06671000"],["79979.03000000","0.00914000"],["79978.93000000","0.00007000"],["79978.73000000","0.00007000"],["79978.42000000","0.00007000"],["79978.29000000","0.00007000"],["79978.28000000","0.00007000"],["79978.17000000","0.00026000"],["79977.99000000","0.00007000"],["79977.76000000","0.00014000"],["79977.75000000","0.01514000"],["79977.42000000","0.00007000"],["79977.20000000","0.00014000"],["79977.19000000","0.04725000"],["79976.90000000","0.00007000"]],"asks":[["79980.16000000","2.02383000"],["79980.17000000","0.00027000"],["79980.18000000","0.00013000"],["79980.32000000","0.00014000"],["79980.33000000","0.00981000"],["79980.97000000","0.00007000"],["79981.01000000","0.00007000"],["79981.04000000","0.00014000"],["79981.05000000","0.67253000"],["79981.06000000","0.00014000"],["79981.29000000","0.00014000"],["79981.61000000","0.01639000"],["79981.65000000","0.00400000"],["79981.95000000","0.00007000"],["79982.30000000","0.00441000"],["79982.62000000","0.00014000"],["79982.63000000","0.04025000"],["79982.78000000","0.00014000"],["79982.79000000","0.05314000"],["79982.89000000","0.01963000"]]}}}
{"rx_ns": 10704559236400, "frame": {"stream":"btcusdt@depth@100ms","data":{"e":"depthUpdate","E":1787647699714,"s":"BTCUSDT","U":99116125386,"u":99116125418,"b":[["79980.15000000","2.09409000"],["79979.76000000","0.06671000"],["79979.03000000","0.00914000"],["79978.05000000","0.00000000"],["79978.04000000","0.00000000"],["79975.44000000","0.21421000"],["71982.14000000","0.00144000"]],"a":[["79980.16000000","2.02383000"],["79982.89000000","0.01963000"],["79982.96000000","0.04990000"],["79983.99000000","0.01749000"]]}}}
{"rx_ns": 10704652912600, "frame": {"stream":"btcusdt@depth20@100ms","data":{"lastUpdateId":99116125434,"bids":[["79980.15000000","2.09409000"],["79980.14000000","0.00056000"],["79980.10000000","0.00015000"],["79979.99000000","0.00020000"],["79979.77000000","0.00014000"],["79979.76000000","0.06671000"],["79979.03000000","0.00914000"],["79978.93000000","0.00007000"],["79978.73000000","0.00007000"],["79978.42000000","0.00007000"],["79978.29000000","0.00007000"],["79978.28000000","0.00007000"],["79977.99000000","0.00007000"],["79977.76000000","0.00014000"],["79977.75000000","0.01514000"],["79977.42000000","0.00007000"],["79977.20000000","0.00014000"],["79977.19000000","0.04725000"],["79976.90000000","0.00007000"],["79976.85000000","0.00007000"]],"asks":[["79980.16000000","2.02357000"],["79980.17000000","0.00027000"],["79980.18000000","0.00013000"],["79980.32000000","0.00014000"],["79980.33000000","0.00981000"],["79980.97000000","0.00007000"],["79981.01000000","0.00007000"],["79981.04000000","0.00014000"],["79981.05000000","0.67253000"],["79981.06000000","0.00014000"],["79981.29000000","0.00014000"],["79981.61000000","0.01646000"],["79981.65000000","0.00400000"],["79981.70000000","0.00014000"],["79981.71000000","0.04352000"],["79981.95000000","0.00007000"],["79982.30000000","0.00441000"],["79982.62000000","0.00014000"],["79982.63000000","0.04025000"],["79982.78000000","0.00014000"]]}}}
{"rx_ns": 10704652992000, "frame": {"stream":"btcusdt@depth@100ms","data":{"e":"depthUpdate","E":1787647699814,"s":"BTCUSDT","U":99116125419,"u":99116125434,"b":[["79978.17000000","0.00000000"],["79971.22000000","0.15380000"],["79971.20000000","0.00000000"],["79960.44000000","0.00000000"],["79919.45000000","0.02599000"],["79895.01000000","0.02084000"],["79886.41000000","0.62498000"],["79883.77000000","0.00000000"],["79778.60000000","0.00000000"],["79770.98000000","0.00770000"]],"a":[["79980.16000000","2.02357000"],["79981.61000000","0.01646000"],["79981.70000000","0.00014000"],["79981.71000000","0.04352000"],["79982.95000000","0.00000000"],["79982.96000000","0.00007000"],["79983.50000000","0.00007000"]]}}}
{"rx_ns": 10704752906100, "frame": {"stream":"btcusdt@depth20@100ms","data":{"lastUpdateId":99116125453,"bids":[["79980.15000000","2.09409000"],["79980.14000000","0.00056000"],["79980.10000000","0.00015000"],["79979.99000000","0.00020000"],["79979.77000000","0.00014000"],["79979.76000000","0.06671000"],["79979.03000000","0.00914000"],["79978.93000000","0.00007000"],["79978.73000000","0.00007000"],["79978.42000000","0.00007000"],["79978.29000000","0.00007000"],["79978.28000000","0.00007000"],["79977.99000000","0.00007000"],["79977.76000000","0.00014000"],["79977.75000000","0.01514000"],["79977.42000000","0.00007000"],["79977.20000000","0.00014000"],["79977.19000000","0.04725000"],["79976.90000000","0.00007000"],["79976.85000000","0.00007000"]],"asks":[["79980.16000000","2.02357000"],["79980.17000000","0.00027000"],["79980.18000000","0.00013000"],["79980.32000000","0.00014000"],["79980.33000000","0.00981000"],["79980.97000000","0.00007000"],["79981.01000000","0.00007000"],["79981.04000000","0.00014000"],["79981.05000000","0.67253000"],["79981.06000000","0.00014000"],["79981.29000000","0.00014000"],["79981.61000000","0.01646000"],["79981.65000000","0.00400000"],["79981.70000000","0.00014000"],["79981.71000000","0.04359000"],["79982.30000000","0.00441000"],["79982.62000000","0.00014000"],["79982.63000000","0.04025000"],["79982.78000000","0.00014000"],["79982.79000000","0.05314000"]]}}}
{"rx_ns": 10704753032700, "frame": {"stream":"btcusdt@depth@100ms","data":{"e":"depthUpdate","E":1787647699914,"s":"BTCUSDT","U":99116125435,"u":99116125453,"b":[["79971.23000000","0.00400000"],["79971.22000000","0.00000000"],["79971.21000000","0.00000000"],["79960.97000000","0.15382000"],["79895.01000000","0.00000000"],["75000.00000000","112.52179000"],["71982.14000000","0.00160000"]],"a":[["79980.16000000","2.02357000"],["79981.61000000","0.01646000"],["79981.71000000","0.04359000"],["79981.95000000","0.00000000"],["79982.89000000","0.01956000"],["79982.96000000","0.00000000"],["79987.94000000","0.00400000"]]}}}
{"rx_ns": 10704853978400, "frame": {"stream":"btcusdt@depth20@100ms","data":{"lastUpdateId":99116125467,"bids":[["79980.15000000","2.09409000"],["79980.14000000","0.00056000"],["79980.10000000","0.00015000"],["79979.99000000","0.00020000"],["79979.77000000","0.00014000"],["79979.76000000","0.06671000"],["79979.03000000","0.00914000"],["79978.93000000","0.00007000"],["79978.73000000","0.00007000"],["79978.42000000","0.00007000"],["79978.29000000","0.00007000"],["79978.28000000","0.00007000"],["79977.99000000","0.00007000"],["79977.76000000","0.00014000"],["79977.75000000","0.01514000"],["79977.42000000","0.00007000"],["79977.20000000","0.00014000"],["79977.19000000","0.04725000"],["79976.90000000","0.00007000"],["79976.85000000","0.00007000"]],"asks":[["79980.16000000","2.02357000"],["79980.17000000","0.00027000"],["79980.18000000","0.00013000"],["79980.32000000","0.00014000"],["79980.33000000","0.00981000"],["79980.97000000","0.00007000"],["79981.01000000","0.00007000"],["79981.04000000","0.00014000"],["79981.05000000","0.67253000"],["79981.06000000","0.00014000"],["79981.29000000","0.00014000"],["79981.61000000","0.01646000"],["79981.65000000","0.00400000"],["79981.70000000","0.00014000"],["79981.71000000","0.04359000"],["79982.30000000","0.00441000"],["79982.62000000","0.00014000"],["79982.63000000","0.04025000"],["79982.78000000","0.00014000"],["79982.79000000","0.05314000"]]}}}
{"rx_ns": 10704854061700, "frame": {"stream":"btcusdt@depth@100ms","data":{"e":"depthUpdate","E":1787647700014,"s":"BTCUSDT","U":99116125454,"u":99116125467,"b":[["79971.20000000","0.08663000"],["79934.85000000","0.00000000"],["78780.44000000","0.00030000"],["71982.14000000","0.00160000"],["63984.12000000","0.00031000"]],"a":[["79987.94000000","0.00000000"],["79990.84000000","0.00400000"],["80000.00000000","0.82123000"],["80005.68000000","0.00399000"],["80396.43000000","2.50000000"]]}}}
{"rx_ns": 10704952467200, "frame": {"stream":"btcusdt@depth20@100ms","data":{"lastUpdateId":99116125499,"bids":[["79980.15000000","2.09418000"],["79980.14000000","0.00056000"],["79980.10000000","0.00015000"],["79979.99000000","0.00020000"],["79979.78000000","0.00014000"],["79979.77000000","0.05453000"],["79979.76000000","0.06678000"],["79979.03000000","0.00921000"],["79978.93000000","0.00007000"],["79978.73000000","0.00007000"],["79978.42000000","0.00007000"],["79978.29000000","0.00007000"],["79978.28000000","0.00007000"],["79977.99000000","0.00007000"],["79977.76000000","0.00014000"],["79977.75000000","0.01521000"],["79977.42000000","0.00007000"],["79977.20000000","0.00014000"],["79977.19000000","0.04732000"],["79976.90000000","0.00007000"]],"asks":[["79980.16000000","2.02364000"],["79980.17000000","0.00027000"],["79980.18000000","0.00013000"],["79980.32000000","0.00014000"],["79980.33000000","0.00988000"],["79980.97000000","0.00007000"],["79981.01000000","0.00007000"],["79981.04000000","0.00014000"],["79981.05000000","0.67260000"],["79981.06000000","0.00014000"],["79981.29000000","0.00014000"],["79981.61000000","0.01653000"],["79981.65000000","0.00400000"],["79981.70000000","0.00014000"],["79981.71000000","0.04366000"],["79982.30000000","0.00441000"],["79982.62000000","0.00014000"],["79982.63000000","0.04032000"],["79982.78000000","0.00014000"],["79982.79000000","0.05321000"]]}}}
{"rx_ns": 10704952562300, "frame": {"stream":"btcusdt@depth@100ms","data":{"e":"depthUpdate","E":1787647700114,"s":"BTCUSDT","U":99116125468,"u":99116125499,"b":[["79980.15000000","2.09418000"],["79979.78000000","0.00014000"],["79979.77000000","0.05453000"],["79979.76000000","0.06678000"],["79979.03000000","0.00921000"],["79977.75000000","0.01521000"],["79977.19000000","0.04732000"],["79976.47000000","0.01814000"],["79976.01000000","0.00000000"],["79976.00000000","0.02428000"],["79975.73000000","0.00900000"],["79975.44000000","0.21428000"],["79972.24000000","0.08663000"],["79968.65000000","0.00007000"],["71982.14000000","0.00176000"],["71982.13000000","0.00008000"]],"a":[["79980.16000000","2.02364000"],["79980.33000000","0.00988000"],["79981.05000000","0.67260000"],["79981.61000000","0.01653000"],["79981.71000000","0.04366000"],["79982.63000000","0.04032000"],["79982.79000000","0.05321000"],["79982.89000000","0.01963000"],["79983.51000000","0.08782000"],["79988.09000000","0.12501000"],["79992.66000000","0.00007000"],["80224.00000000","0.00007000"]]}}}
