{"rx_ns": 10714056171600, "frame": {"stream":"btcusdt@depth20@100ms","data":{"lastUpdateId":99116129044,"bids":[["79980.15000000","0.87065000"],["79980.14000000","0.00083000"],["79980.13000000","0.00013000"],["79980.10000000","0.00007000"],["79979.99000000","0.00020000"],["79979.06000000","0.00014000"],["79979.05000000","0.12543000"],["79979.04000000","0.08677000"],["79979.03000000","0.00928000"],["79978.93000000","0.00007000"],["79978.73000000","0.00007000"],["79978.42000000","0.00007000"],["79978.29000000","0.00007000"],["79978.28000000","0.00007000"],["79977.99000000","0.00007000"],["79977.90000000","0.00014000"],["79977.89000000","0.08233000"],["79977.75000000","0.01521000"],["79977.42000000","0.00007000"],["79977.20000000","0.00014000"]],"asks":[["79980.16000000","2.04951000"],["79980.17000000","0.00076000"],["79980.18000000","0.00013000"],["79980.32000000","0.00014000"],["79980.33000000","0.01002000"],["79980.52000000","0.00014000"],["79980.53000000","0.01770000"],["79980.61000000","0.00014000"],["79980.62000000","0.11021000"],["79980.72000000","0.00014000"],["79980.73000000","0.03817000"],["79980.97000000","0.00007000"],["79980.99000000","0.00007000"],["79981.00000000","0.46606000"],["79981.01000000","0.00007000"],["79981.05000000","0.32793000"],["79981.06000000","0.00014000"],["79981.29000000","0.00014000"],["79981.56000000","0.00597000"],["79981.61000000","0.01653000"]]}}}
{"rx_ns": 10714056248800, "frame": {"stream":"btcusdt@depth@100ms","data":{"e":"depthUpdate","E":1787647709214,"s":"BTCUSDT","U":99116129029,"u":99116129044,"b":[["79980.15000000","0.87065000"],["79979.03000000","0.00928000"],["79978.71000000","0.00000000"],["79976.77000000","0.00007000"],["79973.71000000","0.00625000"],["79972.70000000","0.00000000"],["71982.14000000","0.00416000"],["63984.12000000","0.00000000"]],"a":[["79987.62000000","0.00000000"],["79988.23000000","0.00625000"]]}}}
{"rx_ns": 10714157475200, "frame": {"stream":"btcusdt@depth20@100ms","data":{"lastUpdateId":99116129368,"bids":[["79980.14000000","0.47519000"],["79980.13000000","0.00069000"],["79980.12000000","0.00013000"],["79980.10000000","0.00007000"],["79979.99000000","0.00020000"],["79979.05000000","0.00021000"],["79979.04000000","0.00021000"],["79979.03000000","0.00928000"],["79978.93000000","0.00007000"],["79978.73000000","0.00007000"],["79978.42000000","0.00007000"],["79978.29000000","0.00007000"],["79978.28000000","0.00007000"],["79977.99000000","0.00007000"],["79977.89000000","0.00014000"],["79977.88000000","0.07774000"],["79977.76000000","0.00014000"],["79977.75000000","0.01528000"],["79977.42000000","0.00007000"],["79977.23000000","0.00014000"]],"asks":[["79980.15000000","2.76866000"],["79980.16000000","1.30605000"],["79980.17000000","0.00013000"],["79980.33000000","0.01002000"],["79980.53000000","0.01770000"],["79980.61000000","0.00014000"],["79980.62000000","0.11021000"],["79980.64000000","0.03224000"],["79980.73000000","0.03817000"],["79980.97000000","0.00007000"],["79980.99000000","0.00014000"],["79981.00000000","0.46606000"],["79981.01000000","0.00007000"],["79981.04000000","0.00014000"],["79981.05000000","0.32793000"],["79981.06000000","0.00014000"],["79981.29000000","0.00014000"],["79981.56000000","0.00014000"],["79981.61000000","0.01639000"],["79981.77000000","0.00008000"]]}}}
{"rx_ns": 10714157554200, "frame": {"stream":"btcusdt@depth@100ms","data":{"e":"depthUpdate","E":1787647709314,"s":"BTCUSDT","U":99116129045,"u":99116129368,"b":[["79980.15000000","0.00000000"],["79980.14000000","0.47519000"],["79980.13000000","0.00069000"],["79980.12000000","0.00013000"],["79979.06000000","0.00000000"],["79979.05000000","0.00021000"],["79979.04000000","0.00021000"],["79979.03000000","0.00928000"],["79977.90000000","0.00000000"],["79977.89000000","0.00014000"],["79977.88000000","0.07774000"],["79977.76000000","0.00014000"],["79977.75000000","0.01528000"],["79977.23000000","0.00014000"],["79977.22000000","0.07043000"],["79977.21000000","0.08663000"],["79977.20000000","0.00014000"],["79977.19000000","0.04746000"],["79977.06000000","0.00014000"],["79977.05000000","0.05828000"],["79976.77000000","0.00000000"],["79976.76000000","0.00014000"],["79976.48000000","0.00000000"],["79976.47000000","0.01814000"],["79976.01000000","0.00000000"],["79976.00000000","0.02414000"],["79975.73000000","0.00886000"],["79975.64000000","0.00000000"],["79975.62000000","0.08663000"],["79975.49000000","0.08663000"],["79975.48000000","0.24324000"],["79975.47000000","0.00000000"],["79973.71000000","0.00000000"],["79973.55000000","0.00007000"],["79972.16000000","0.08174000"],["79970.35000000","0.08663000"],["79970.01000000","0.00625000"],["79968.84000000","0.08663000"],["79968.02000000","0.08663000"],["79967.68000000","0.00575000"],["79967.38000000","0.00000000"],["79966.97000000","0.00000000"],["79966.02000000","0.00625000"],["79965.75000000","0.00162000"],["79964.37000000","0.02200000"],["79924.33000000","0.02200000"],["79903.48000000","0.02400000"],["79893.42000000","0.02084000"],["79820.62000000","0.00000000"],["79610.80000000","0.00000000"],["71982.14000000","0.00000000"],["71982.13000000","0.00016000"],["71982.12000000","0.00000000"],["63984.00000000","0.00014000"]],"a":[["79980.15000000","2.76866000"],["79980.16000000","1.30605000"],["79980.17000000","0.00013000"],["79980.18000000","0.00000000"],["79980.32000000","0.00000000"],["79980.52000000","0.00000000"],["79980.64000000","0.03224000"],["79980.72000000","0.00000000"],["79980.99000000","0.00014000"],["79981.04000000","0.00014000"],["79981.56000000","0.00014000"],["79981.61000000","0.01639000"],["79981.67000000","0.00000000"],["79981.81000000","0.00000000"],["79983.51000000","0.00021000"],["79983.99000000","0.01756000"],["79984.60000000","0.00625000"],["79984.66000000","0.97946000"],["79987.42000000","0.00000000"],["79987.93000000","1.87460000"],["79988.23000000","0.00000000"],["79992.48000000","0.02000000"],["79992.65000000","0.00585000"],["79992.66000000","0.00000000"],["79996.48000000","0.00000000"],["80012.50000000","0.02000000"],["80033.37000000","0.04000000"],["80132.46000000","0.00000000"],["81179.86000000","0.00030000"],["81179.87000000","0.00000000"]]}}}
{"rx_ns": 10714253517100, "frame": {"stream":"btcusdt@depth20@100ms","data":{"lastUpdateId":99116129445,"bids":[["79980.14000000","0.47526000"],["79980.13000000","0.00076000"],["79980.12000000","0.00013000"],["79980.10000000","0.00007000"],["79979.99000000","0.00020000"],["79979.05000000","0.00007000"],["79979.04000000","0.00007000"],["79979.03000000","0.00935000"],["79978.93000000","0.00007000"],["79978.73000000","0.00007000"],["79978.42000000","0.00007000"],["79978.29000000","0.00007000"],["79978.28000000","0.00007000"],["79977.99000000","0.00007000"],["79977.89000000","0.00014000"],["79977.88000000","0.07788000"],["79977.76000000","0.00014000"],["79977.75000000","0.01535000"],["79977.42000000","0.00007000"],["79977.23000000","0.00014000"]],"asks":[["79980.15000000","2.76859000"],["79980.16000000","1.30605000"],["79980.17000000","0.00013000"],["79980.33000000","0.01002000"],["79980.53000000","0.01770000"],["79980.61000000","0.00014000"],["79980.62000000","0.11021000"],["79980.64000000","0.03238000"],["79980.73000000","0.03817000"],["79980.97000000","0.00007000"],["79980.99000000","0.00014000"],["79981.00000000","0.46606000"],["79981.01000000","0.00007000"],["79981.04000000","0.00014000"],["79981.05000000","0.32793000"],["79981.06000000","0.00014000"],["79981.29000000","0.00014000"],["79981.61000000","0.01639000"],["79981.77000000","0.00008000"],["79981.82000000","0.04000000"]]}}}
{"rx_ns": 10714253617600, "frame": {"stream":"btcusdt@depth@100ms","data":{"e":"depthUpdate","E":1787647709414,"s":"BTCUSDT","U":99116129369,"u":99116129445,"b":[["79980.14000000","0.47526000"],["79980.13000000","0.00076000"],["79979.05000000","0.00007000"],["79979.04000000","0.00007000"],["79979.03000000","0.00935000"],["79977.89000000","0.00014000"],["79977.88000000","0.07788000"],["79977.75000000","0.01535000"],["79977.22000000","0.07057000"],["79977.21000000","0.08677000"],["79977.19000000","0.04739000"],["79977.06000000","0.00000000"],["79977.05000000","0.05842000"],["79976.76000000","0.00000000"],["79973.55000000","0.00007000"],["79972.23000000","0.08663000"],["79970.35000000","0.00000000"],["79967.68000000","0.00000000"],["79967.35000000","0.00574000"],["79893.42000000","0.00000000"],["71982.13000000","0.00032000"]],"a":[["79980.15000000","2.76859000"],["79980.62000000","0.11021000"],["79980.64000000","0.03238000"],["79981.05000000","0.32793000"],["79981.56000000","0.00000000"],["79982.13000000","0.00000000"],["79982.21000000","0.00440000"],["79983.51000000","0.00014000"],["79983.73000000","0.00000000"],["79983.81000000","0.00588000"]]}}}
{"rx_ns": 10714353763300, "frame": {"stream":"btcusdt@depth20@100ms","data":{"lastUpdateId":99116129487,"bids":[["79980.14000000","0.27114000"],["79980.13000000","0.00076000"],["79980.12000000","0.00013000"],["79980.10000000","0.00007000"],["79979.99000000","0.00020000"],["79979.05000000","0.00007000"],["79979.04000000","0.00007000"],["79979.03000000","0.00935000"],["79978.93000000","0.00007000"],["79978.73000000","0.00007000"],["79978.42000000","0.00007000"],["79978.29000000","0.00007000"],["79978.28000000","0.00007000"],["79977.99000000","0.00007000"],["79977.89000000","0.00014000"],["79977.88000000","0.07788000"],["79977.76000000","0.00014000"],["79977.75000000","0.01535000"],["79977.42000000","0.00007000"],["79977.23000000","0.00014000"]],"asks":[["79980.15000000","2.76754000"],["79980.16000000","1.30549000"],["79980.17000000","0.00013000"],["79980.33000000","0.01002000"],["79980.53000000","0.01770000"],["79980.61000000","0.00014000"],["79980.62000000","0.11021000"],["79980.64000000","0.03238000"],["79980.73000000","0.03817000"],["79980.97000000","0.00007000"],["79980.99000000","0.00014000"],["79981.00000000","0.46606000"],["79981.01000000","0.00007000"],["79981.04000000","0.00014000"],["79981.05000000","0.32793000"],["79981.06000000","0.00014000"],["79981.29000000","0.00014000"],["79981.61000000","0.01639000"],["79981.77000000","0.00008000"],["79981.82000000","0.04000000"]]}}}
{"rx_ns": 10714353960400, "frame": {"stream":"btcusdt@depth@100ms","data":{"e":"depthUpdate","E":1787647709514,"s":"BTCUSDT","U":99116129446,"u":99116129487,"b":[["79980.14000000","0.27114000"],["79972.23000000","0.00000000"],["79972.16000000","0.00000000"],["79964.91000000","0.00000000"],["79942.93000000","0.28888000"],["79889.05000000","0.00000000"],["79886.41000000","0.62498000"],["71982.13000000","0.00064000"],["63984.12000000","0.00031000"],["63984.11000000","0.00000000"]],"a":[["79980.15000000","2.76754000"],["79980.16000000","1.30549000"],["79996.91000000","0.00000000"]]}}}
{"rx_ns": 10714455801700, "frame": {"stream":"btcusdt@depth20@100ms","data":{"lastUpdateId":99116129500,"bids":[["79980.14000000","0.47558000"],["79980.13000000","0.00076000"],["79980.12000000","0.00013000"],["79980.10000000","0.00007000"],["79979.99000000","0.00020000"],["79979.05000000","0.00007000"],["79979.04000000","0.08009000"],["79979.03000000","0.00935000"],["79978.93000000","0.00007000"],["79978.73000000","0.00007000"],["79978.42000000","0.00007000"],["79978.29000000","0.00007000"],["79978.28000000","0.00007000"],["79977.99000000","0.00007000"],["79977.89000000","0.00014000"],["79977.88000000","0.07788000"],["79977.76000000","0.00014000"],["79977.75000000","0.01535000"],["79977.42000000","0.00007000"],["79977.23000000","0.00014000"]],"asks":[["79980.15000000","2.76754000"],["79980.16000000","1.30549000"],["79980.17000000","0.00013000"],["79980.33000000","0.01002000"],["79980.53000000","0.01770000"],["79980.61000000","0.00014000"],["79980.62000000","0.11021000"],["79980.64000000","0.03238000"],["79980.73000000","0.03817000"],["79980.97000000","0.00007000"],["79980.99000000","0.00014000"],["79981.00000000","0.46606000"],["79981.01000000","0.00007000"],["79981.04000000","0.00014000"],["79981.05000000","0.32793000"],["79981.06000000","0.00014000"],["79981.29000000","0.00014000"],["79981.61000000","0.01639000"],["79981.77000000","0.00008000"],["79981.82000000","0.04000000"]]}}}
{"rx_ns": 10714455902500, "frame": {"stream":"btcusdt@depth@100ms","data":{"e":"depthUpdate","E":1787647709614,"s":"BTCUSDT","U":99116129488,"u":99116129500,"b":[["79980.14000000","0.47558000"],["79979.04000000","0.08009000"],["79972.23000000","0.08663000"],["79972.16000000","0.08663000"],["79970.35000000","0.08663000"],["79967.35000000","0.00000000"],["79966.97000000","0.08663000"],["79964.90000000","0.00007000"],["71982.13000000","0.00080000"],["63984.12000000","0.00000000"]],"a":[["79996.90000000","0.00007000"]]}}}
{"rx_ns": 10714552070000, "frame": {"stream":"btcusdt@depth20@100ms","data":{"lastUpdateId":99116129534,"bids":[["79980.14000000","0.47675000"],["79980.13000000","0.00083000"],["79980.12000000","0.00013000"],["79980.10000000","0.00007000"],["79979.99000000","0.00020000"],["79979.05000000","0.00021000"],["79979.04000000","0.08023000"],["79979.03000000","0.00935000"],["79978.93000000","0.00007000"],["79978.73000000","0.00007000"],["79978.42000000","0.00007000"],["79978.29000000","0.00007000"],["79978.28000000","0.00007000"],["79977.99000000","0.00007000"],["79977.89000000","0.00014000"],["79977.88000000","0.07788000"],["79977.76000000","0.00014000"],["79977.75000000","0.01528000"],["79977.42000000","0.00007000"],["79977.23000000","0.00014000"]],"asks":[["79980.15000000","2.76761000"],["79980.16000000","1.30542000"],["79980.17000000","0.00013000"],["79980.33000000","0.01002000"],["79980.53000000","0.01770000"],["79980.61000000","0.00014000"],["79980.62000000","0.11021000"],["79980.64000000","0.03238000"],["79980.73000000","0.03817000"],["79980.97000000","0.00007000"],["79980.99000000","0.00014000"],["79981.00000000","0.46606000"],["79981.01000000","0.00007000"],["79981.04000000","0.00014000"],["79981.05000000","0.32793000"],["79981.06000000","0.00014000"],["79981.29000000","0.00014000"],["79981.61000000","0.01639000"],["79981.77000000","0.00008000"],["79981.82000000","0.04000000"]]}}}
{"rx_ns": 10714552176300, "frame": {"stream":"btcusdt@depth@100ms","data":{"e":"depthUpdate","E":1787647709714,"s":"BTCUSDT","U":99116129501,"u":99116129534,"b":[["79980.14000000","0.47675000"],["79980.13000000","0.00083000"],["79979.05000000","0.00021000"],["79979.04000000","0.08023000"],["79977.75000000","0.01528000"],["79977.22000000","0.07064000"],["79977.20000000","0.00000000"],["79976.47000000","0.01800000"],["79970.35000000","0.00000000"],["79966.97000000","0.00000000"],["79941.54000000","0.04577000"],["79923.30000000","0.00000000"],["71982.13000000","0.00096000"]],"a":[["79980.15000000","2.76761000"],["79980.16000000","1.30542000"],["79988.15000000","0.00007000"],["79988.16000000","0.00000000"],["79996.15000000","0.00007000"],["79996.16000000","0.95239000"],["80004.15000000","0.00007000"],["80004.16000000","0.00000000"]]}}}
{"rx_ns": 10714655571000, "frame": {"stream":"btcusdt@depth20@100ms","data":{"lastUpdateId":99116129538,"bids":[["79980.14000000","0.47675000"],["79980.13000000","0.00083000"],["79980.12000000","0.00013000"],["79980.10000000","0.00007000"],["79979.99000000","0.00020000"],["79979.05000000","0.00021000"],["79979.04000000","0.08023000"],["79979.03000000","0.00935000"],["79978.93000000","0.00007000"],["79978.73000000","0.00007000"],["79978.42000000","0.00007000"],["79978.29000000","0.00007000"],["79978.28000000","0.00007000"],["79977.99000000","0.00007000"],["79977.89000000","0.00014000"],["79977.88000000","0.07788000"],["79977.76000000","0.00014000"],["79977.75000000","0.01528000"],["79977.42000000","0.00007000"],["79977.23000000","0.00014000"]],"asks":[["79980.15000000","2.76761000"],["79980.16000000","1.30542000"],["79980.17000000","0.00013000"],["79980.33000000","0.01002000"],["79980.53000000","0.01770000"],["79980.61000000","0.00014000"],["79980.62000000","0.11021000"],["79980.64000000","0.03238000"],["79980.73000000","0.03817000"],["79980.97000000","0.00007000"],["79980.99000000","0.00014000"],["79981.00000000","0.46606000"],["79981.01000000","0.00007000"],["79981.04000000","0.00014000"],["79981.05000000","0.32793000"],["79981.06000000","0.00014000"],["79981.29000000","0.00014000"],["79981.61000000","0.01639000"],["79981.77000000","0.00008000"],["79981.82000000","0.04000000"]]}}}
{"rx_ns": 10714655650900, "frame": {"stream":"btcusdt@depth@100ms","data":{"e":"depthUpdate","E":1787647709814,"s":"BTCUSDT","U":99116129535,"u":99116129538,"b":[["79973.55000000","0.00014000"],["79941.00000000","0.70000000"],["71982.13000000","0.00128000"]],"a":[]}}}
{"rx_ns": 10714753236000, "frame": {"stream":"btcusdt@depth20@100ms","data":{"lastUpdateId":99116129544,"bids":[["79980.14000000","0.47668000"],["79980.13000000","0.00083000"],["79980.12000000","0.00013000"],["79980.10000000","0.00007000"],["79979.99000000","0.00020000"],["79979.05000000","0.00021000"],["79979.04000000","0.08023000"],["79979.03000000","0.00935000"],["79978.93000000","0.00007000"],["79978.73000000","0.00007000"],["79978.42000000","0.00007000"],["79978.29000000","0.00007000"],["79978.28000000","0.00007000"],["79977.99000000","0.00007000"],["79977.89000000","0.00014000"],["79977.88000000","0.07788000"],["79977.76000000","0.00014000"],["79977.75000000","0.01528000"],["79977.42000000","0.00007000"],["79977.23000000","0.00014000"]],"asks":[["79980.15000000","2.76761000"],["79980.16000000","1.30542000"],["79980.17000000","0.00013000"],["79980.33000000","0.01002000"],["79980.53000000","0.01770000"],["79980.61000000","0.00014000"],["79980.62000000","0.11021000"],["79980.64000000","0.03238000"],["79980.73000000","0.03817000"],["79980.97000000","0.00007000"],["79980.99000000","0.00014000"],["79981.00000000","0.46606000"],["79981.01000000","0.00007000"],["79981.04000000","0.00014000"],["79981.05000000","0.32793000"],["79981.06000000","0.00014000"],["79981.29000000","0.00014000"],["79981.61000000","0.01639000"],["79981.77000000","0.00008000"],["79981.82000000","0.04000000"]]}}}
{"rx_ns": 10714753367800, "frame": {"stream":"btcusdt@depth@100ms","data":{"e":"depthUpdate","E":1787647709914,"s":"BTCUSDT","U":99116129539,"u":99116129544,"b":[["79980.14000000","0.47668000"],["79966.97000000","0.00400000"],["71982.13000000","0.00144000"]],"a":[["79986.19000000","0.00400000"]]}}}
{"rx_ns": 10714856246000, "frame": {"stream":"btcusdt@depth20@100ms","data":{"lastUpdateId":99116129549,"bids":[["79980.14000000","0.47668000"],["79980.13000000","0.00083000"],["79980.12000000","0.00013000"],["79980.10000000","0.00007000"],["79979.99000000","0.00020000"],["79979.05000000","0.00021000"],["79979.04000000","0.08023000"],["79979.03000000","0.00935000"],["79978.93000000","0.00007000"],["79978.73000000","0.00007000"],["79978.42000000","0.00007000"],["79978.29000000","0.00007000"],["79978.28000000","0.00007000"],["79977.99000000","0.00007000"],["79977.89000000","0.00014000"],["79977.88000000","0.07788000"],["79977.76000000","0.00014000"],["79977.75000000","0.01528000"],["79977.42000000","0.00007000"],["79977.23000000","0.00014000"]],"asks":[["79980.15000000","2.76761000"],["79980.16000000","1.30542000"],["79980.17000000","0.00013000"],["79980.33000000","0.01002000"],["79980.53000000","0.01770000"],["79980.61000000","0.00014000"],["79980.62000000","0.11021000"],["79980.64000000","0.03238000"],["79980.73000000","0.03817000"],["79980.97000000","0.00007000"],["79980.99000000","0.00014000"],["79981.00000000","0.46606000"],["79981.01000000","0.00007000"],["79981.04000000","0.00014000"],["79981.05000000","0.32793000"],["79981.06000000","0.00014000"],["79981.29000000","0.00014000"],["79981.61000000","0.01639000"],["79981.77000000","0.00008000"],["79981.82000000","0.04000000"]]}}}
{"rx_ns": 10714856320800, "frame": {"stream":"btcusdt@depth@100ms","data":{"e":"depthUpdate","E":1787647710014,"s":"BTCUSDT","U":99116129545,"u":99116129549,"b":[["79967.15000000","0.00625000"],["79966.02000000","0.00000000"],["71982.13000000","0.00160000"],["71982.00000000","0.00000000"],["63984.12000000","0.00031000"]],"a":[]}}}
{"rx_ns": 10714962116100, "frame": {"stream":"btcusdt@depth20@100ms","data":{"lastUpdateId":99116129557,"bids":[["79980.14000000","0.47668000"],["79980.13000000","0.00083000"],["79980.12000000","0.00013000"],["79980.10000000","0.00007000"],["79979.99000000","0.00020000"],["79979.05000000","0.00021000"],["79979.04000000","0.08023000"],["79979.03000000","0.00935000"],["79978.93000000","0.00007000"],["79978.73000000","0.00007000"],["79978.42000000","0.00007000"],["79978.29000000","0.00007000"],["79978.28000000","0.00007000"],["79977.99000000","0.00007000"],["79977.89000000","0.00014000"],["79977.88000000","0.07788000"],["79977.76000000","0.00014000"],["79977.75000000","0.01528000"],["79977.42000000","0.00007000"],["79977.23000000","0.00014000"]],"asks":[["79980.15000000","2.76761000"],["79980.16000000","1.30542000"],["79980.17000000","0.00013000"],["79980.33000000","0.01002000"],["79980.53000000","0.01770000"],["79980.61000000","0.00014000"],["79980.62000000","0.11021000"],["79980.64000000","0.03238000"],["79980.73000000","0.03817000"],["79980.97000000","0.00007000"],["79980.99000000","0.00014000"],["79981.00000000","0.46606000"],["79981.01000000","0.00007000"],["79981.04000000","0.00014000"],["79981.05000000","0.32793000"],["79981.06000000","0.00014000"],["79981.29000000","0.00014000"],["79981.61000000","0.01639000"],["79981.77000000","0.00008000"],["79981.82000000","0.04000000"]]}}}
{"rx_ns": 10714962212500, "frame": {"stream":"btcusdt@depth@100ms","data":{"e":"depthUpdate","E":1787647710114,"s":"BTCUSDT","U":99116129550,"u":99116129557,"b":[["79967.53000000","0.00574000"],["79893.42000000","0.02084000"],["78780.44000000","0.00000000"],["78780.43000000","0.00030000"],["71982.13000000","0.00160000"]],"a":[["86422.88000000","0.20801000"]]}}}
{"rx_ns": 10715059131100, "frame": {"stream":"btcusdt@depth20@100ms","data":{"lastUpdateId":99116129565,"bids":[["79980.14000000","0.47668000"],["79980.13000000","0.00083000"],["79980.12000000","0.00013000"],["79980.10000000","0.00007000"],["79979.99000000","0.00020000"],["79979.05000000","0.00021000"],["79979.04000000","0.08023000"],["79979.03000000","0.00935000"],["79978.93000000","0.00007000"],["79978.73000000","0.00007000"],["79978.42000000","0.00007000"],["79978.29000000","0.00007000"],["79978.28000000","0.00007000"],["79977.99000000","0.00007000"],["79977.89000000","0.00014000"],["79977.88000000","0.07788000"],["79977.76000000","0.00014000"],["79977.75000000","0.01528000"],["79977.42000000","0.00007000"],["79977.23000000","0.00014000"]],"asks":[["79980.15000000","2.76761000"],["79980.16000000","1.30542000"],["79980.17000000","0.00013000"],["79980.33000000","0.01002000"],["79980.53000000","0.01770000"],["79980.61000000","0.00014000"],["79980.62000000","0.11021000"],["79980.64000000","0.03238000"],["79980.73000000","0.03817000"],["79980.97000000","0.00007000"],["79980.99000000","0.00014000"],["79981.00000000","0.46606000"],["79981.01000000","0.00007000"],["79981.04000000","0.00014000"],["79981.05000000","0.32793000"],["79981.06000000","0.00014000"],["79981.29000000","0.00014000"],["79981.61000000","0.01639000"],["79981.77000000","0.00008000"],["79981.82000000","0.04000000"]]}}}
{"rx_ns": 10715059223600, "frame": {"stream":"btcusdt@depth@100ms","data":{"e":"depthUpdate","E":1787647710214,"s":"BTCUSDT","U":99116129558,"u":99116129565,"b":[["79969.41000000","0.00443000"],["79893.42000000","0.00000000"],["71982.13000000","0.00176000"],["63984.12000000","0.00000000"]],"a":[["80699.97000000","0.00000000"],["84202.54000000","0.00442000"]]}}}
{"rx_ns": 10715152095800, "frame": {"stream":"btcusdt@depth20@100ms","data":{"lastUpdateId":99116129810,"bids":[["79980.14000000","1.33793000"],["79980.13000000","0.00069000"],["79980.12000000","0.00013000"],["79980.10000000","0.00007000"],["79979.99000000","0.00020000"],["79979.05000000","0.00007000"],["79979.04000000","0.00021000"],["79979.03000000","0.00942000"],["79978.93000000","0.00007000"],["79978.73000000","0.00007000"],["79978.42000000","0.00007000"],["79978.29000000","0.00007000"],["79978.28000000","0.00007000"],["79978.23000000","0.00014000"],["79978.22000000","0.03631000"],["79978.01000000","0.00026000"],["79977.99000000","0.00007000"],["79977.89000000","0.00014000"],["79977.88000000","0.07788000"],["79977.76000000","0.00014000"]],"asks":[["79980.15000000","2.38541000"],["79980.16000000","0.88376000"],["79980.17000000","0.00013000"],["79980.33000000","0.01002000"],["79980.53000000","0.01770000"],["79980.61000000","0.00014000"],["79980.62000000","0.11021000"],["79980.64000000","0.00014000"],["79980.73000000","0.00014000"],["79980.97000000","0.00007000"],["79981.00000000","0.00014000"],["79981.01000000","0.00007000"],["79981.04000000","0.00014000"],["79981.05000000","0.32793000"],["79981.06000000","0.00014000"],["79981.29000000","0.00014000"],["79981.61000000","0.01639000"],["79981.77000000","0.00008000"],["79981.82000000","0.04000000"],["79981.95000000","0.00007000"]]}}}
{"rx_ns": 10715152272400, "frame": {"stream":"btcusdt@depth@100ms","data":{"e":"depthUpdate","E":1787647710314,"s":"BTCUSDT","U":99116129566,"u":99116129810,"b":[["79980.14000000","1.33793000"],["79980.13000000","0.00069000"],["79979.05000000","0.00007000"],["79979.04000000","0.00021000"],["79979.03000000","0.00942000"],["79978.23000000","0.00014000"],["79978.22000000","0.03631000"],["79978.01000000","0.00026000"],["79977.22000000","0.07057000"],["79977.21000000","0.00014000"],["79977.05000000","0.00014000"],["79976.90000000","0.08125000"],["79975.62000000","0.08670000"],["79975.49000000","0.00000000"],["79975.48000000","0.77240000"],["79975.19000000","0.01807000"],["79974.90000000","0.00000000"],["79974.89000000","0.00000000"],["79973.80000000","0.00000000"],["79973.71000000","0.00625000"],["79973.36000000","0.00000000"],["79972.24000000","1.87060000"],["79972.23000000","0.00000000"],["79972.16000000","0.00000000"],["79970.35000000","0.00625000"],["79970.01000000","0.00000000"],["79969.41000000","0.00000000"],["79969.37000000","0.00451000"],["79968.84000000","0.00000000"],["79968.03000000","0.00162000"],["79968.02000000","0.00000000"],["79967.15000000","0.00000000"],["79966.98000000","0.00000000"],["79965.75000000","0.00000000"],["79954.69000000","0.33779000"],["79953.02000000","0.33779000"],["79952.76000000","0.62555000"],["79936.07000000","0.00400000"],["79934.85000000","0.00000000"],["79933.87000000","0.00000000"],["79933.16000000","0.00000000"],["79930.45000000","0.00400000"],["79929.88000000","0.00000000"],["79927.64000000","0.00000000"],["79904.30000000","0.02200000"],["79895.97000000","0.94504000"],["79895.96000000","0.00000000"],["63984.00000000","0.00014000"]],"a":[["79980.15000000","2.38541000"],["79980.16000000","0.88376000"],["79980.64000000","0.00014000"],["79980.73000000","0.00014000"],["79980.99000000","0.00000000"],["79981.00000000","0.00014000"],["79982.21000000","0.00000000"],["79982.78000000","0.00454000"],["79983.49000000","0.00009000"],["79983.81000000","0.00000000"],["79983.99000000","0.01763000"],["79984.44000000","0.00000000"],["79984.47000000","0.00595000"],["79984.60000000","0.00000000"],["79984.65000000","0.00007000"],["79984.66000000","0.35613000"],["79985.62000000","0.00000000"],["79986.18000000","0.00000000"],["79986.19000000","0.00000000"],["79987.92000000","1.05339000"],["79987.93000000","0.00400000"],["79987.94000000","0.00000000"],["79987.95000000","0.00000000"],["79989.45000000","0.00625000"],["79992.27000000","0.96067000"],["79994.96000000","1.87060000"],["79994.97000000","0.00000000"],["79996.63000000","0.12500000"],["80032.53000000","0.02200000"],["80041.99000000","0.00000000"],["80044.02000000","0.20250000"],["80065.91000000","0.00000000"],["80068.60000000","0.00000000"],["80121.99000000","0.00000000"],["81179.86000000","0.00030000"],["84202.54000000","0.00884000"]]}}}
{"rx_ns": 10715253685400, "frame": {"stream":"btcusdt@depth20@100ms","data":{"lastUpdateId":99116129919,"bids":[["79980.14000000","1.59588000"],["79980.13000000","0.00069000"],["79980.12000000","0.00013000"],["79980.10000000","0.00007000"],["79979.99000000","0.00020000"],["79979.05000000","0.00007000"],["79979.04000000","0.00007000"],["79979.03000000","0.00942000"],["79978.93000000","0.00007000"],["79978.73000000","0.00007000"],["79978.42000000","0.00007000"],["79978.29000000","0.00007000"],["79978.28000000","0.00007000"],["79978.23000000","0.00014000"],["79978.22000000","0.03645000"],["79978.01000000","0.00026000"],["79977.99000000","0.00007000"],["79977.90000000","0.00014000"],["79977.89000000","0.07926000"],["79977.88000000","0.07788000"]],"asks":[["79980.15000000","2.36651000"],["79980.16000000","0.88376000"],["79980.17000000","0.00013000"],["79980.33000000","0.01002000"],["79980.53000000","0.01770000"],["79980.61000000","0.00014000"],["79980.62000000","0.11014000"],["79980.97000000","0.00007000"],["79981.01000000","0.00007000"],["79981.04000000","0.00014000"],["79981.05000000","0.32793000"],["79981.06000000","0.00014000"],["79981.29000000","0.00014000"],["79981.61000000","0.01653000"],["79981.77000000","0.00008000"],["79981.82000000","0.04014000"],["79981.95000000","0.00007000"],["79982.63000000","0.04032000"],["79982.71000000","0.00400000"],["79982.79000000","0.05307000"]]}}}
{"rx_ns": 10715253787000, "frame": {"stream":"btcusdt@depth@100ms","data":{"e":"depthUpdate","E":1787647710414,"s":"BTCUSDT","U":99116129811,"u":99116129919,"b":[["79980.14000000","1.59588000"],["79980.13000000","0.00069000"],["79979.04000000","0.00007000"],["79979.03000000","0.00942000"],["79978.22000000","0.03645000"],["79977.90000000","0.00014000"],["79977.89000000","0.07926000"],["79977.23000000","0.00000000"],["79977.22000000","0.00014000"],["79977.21000000","0.00000000"],["79977.20000000","0.00007000"],["79977.19000000","0.04732000"],["79977.05000000","0.00000000"],["79976.90000000","0.08139000"],["79976.47000000","0.01814000"],["79975.62000000","0.08663000"],["79974.28000000","0.12777000"],["79974.01000000","0.00007000"],["79973.81000000","0.00448000"],["79972.69000000","0.00149000"],["79972.25000000","1.04939000"],["79972.24000000","1.87210000"],["79972.06000000","0.00584000"],["79949.99000000","0.00000000"],["79931.28000000","0.00400000"],["79930.45000000","0.00000000"],["71982.13000000","0.00192000"],["71982.12000000","0.00008000"]],"a":[["79980.15000000","2.36651000"],["79980.62000000","0.11014000"],["79980.64000000","0.00000000"],["79980.73000000","0.00000000"],["79981.00000000","0.00000000"],["79981.61000000","0.01653000"],["79981.82000000","0.04014000"],["79982.63000000","0.04032000"],["79982.78000000","0.00000000"],["79983.44000000","0.00000000"],["79983.45000000","0.00000000"],["79984.17000000","0.01956000"],["79984.47000000","0.00000000"],["79985.59000000","0.00000000"],["79985.60000000","0.00000000"],["79987.92000000","1.04939000"],["79990.13000000","0.00400000"],["79992.27000000","0.83219000"],["79994.00000000","0.02400000"],["79994.78000000","0.00000000"],["80000.00000000","0.12135000"],["80018.05000000","0.33752000"],["80039.99000000","0.00190000"],["80065.91000000","3.13843000"],["80119.99000000","0.00076000"]]}}}
{"rx_ns": 10715352843400, "frame": {"stream":"btcusdt@depth20@100ms","data":{"lastUpdateId":99116130003,"bids":[["79980.14000000","0.65543000"],["79980.13000000","0.00062000"],["79980.12000000","0.00013000"],["79980.10000000","0.00007000"],["79979.99000000","0.00020000"],["79979.05000000","0.00007000"],["79979.04000000","0.00007000"],["79979.03000000","0.00942000"],["79978.93000000","0.00007000"],["79978.73000000","0.00007000"],["79978.42000000","0.00007000"],["79978.29000000","0.00007000"],["79978.28000000","0.00007000"],["79978.23000000","0.00014000"],["79978.22000000","0.03645000"],["79977.99000000","0.00007000"],["79977.90000000","0.00014000"],["79977.89000000","0.05593000"],["79977.88000000","0.00014000"],["79977.76000000","0.00014000"]],"asks":[["79980.15000000","2.78876000"],["79980.16000000","0.88397000"],["79980.17000000","0.00013000"],["79980.29000000","0.00014000"],["79980.30000000","0.09772000"],["79980.33000000","0.01002000"],["79980.53000000","0.01770000"],["79980.61000000","0.00014000"],["79980.62000000","0.11021000"],["79980.97000000","0.00007000"],["79981.01000000","0.00007000"],["79981.03000000","0.00014000"],["79981.04000000","0.46655000"],["79981.05000000","0.32793000"],["79981.06000000","0.00014000"],["79981.29000000","0.00014000"],["79981.61000000","0.01653000"],["79981.77000000","0.00008000"],["79981.82000000","0.04014000"],["79981.95000000","0.00007000"]]}}}
{"rx_ns": 10715352982700, "frame": {"stream":"btcusdt@depth@100ms","data":{"e":"depthUpdate","E":1787647710514,"s":"BTCUSDT","U":99116129920,"u":99116130003,"b":[["79980.14000000","0.65543000"],["79980.13000000","0.00062000"],["79978.22000000","0.03645000"],["79978.01000000","0.00000000"],["79977.89000000","0.05593000"],["79977.88000000","0.00014000"],["79977.75000000","0.01521000"],["79977.22000000","0.00000000"],["79977.20000000","0.00014000"],["79976.91000000","0.00007000"],["79976.59000000","0.42215000"],["79973.81000000","0.00000000"],["79973.71000000","0.00000000"],["79972.26000000","0.00000000"],["79972.25000000","1.05072000"],["79972.24000000","1.87060000"],["79972.06000000","0.00000000"],["79971.59000000","0.00000000"],["79970.35000000","0.00000000"],["79970.01000000","0.00625000"],["79969.69000000","0.00000000"],["79968.77000000","0.00625000"],["79968.03000000","0.00000000"],["79966.98000000","0.00162000"],["79954.81000000","1.46547000"],["79821.38000000","0.00202000"],["71982.13000000","0.00192000"],["63984.12000000","0.00031000"],["63984.11000000","0.00020000"]],"a":[["79980.15000000","2.78876000"],["79980.16000000","0.88397000"],["79980.29000000","0.00014000"],["79980.30000000","0.09772000"],["79980.62000000","0.11021000"],["79981.03000000","0.00014000"],["79981.04000000","0.46655000"],["79983.99000000","0.01749000"],["79984.30000000","0.00438000"],["79984.65000000","0.00000000"],["79984.66000000","0.35620000"],["79985.52000000","0.03224000"],["80133.10000000","0.00202000"]]}}}
{"rx_ns": 10715452667000, "frame": {"stream":"btcusdt@depth20@100ms","data":{"lastUpdateId":99116130056,"bids":[["79980.14000000","0.85742000"],["79980.13000000","0.00069000"],["79980.12000000","0.00013000"],["79980.10000000","0.00007000"],["79979.99000000","0.00020000"],["79979.05000000","0.00007000"],["79979.04000000","0.00007000"],["79979.03000000","0.00935000"],["79978.93000000","0.00007000"],["79978.73000000","0.00007000"],["79978.42000000","0.00007000"],["79978.29000000","0.00007000"],["79978.28000000","0.00007000"],["79978.23000000","0.00014000"],["79978.22000000","0.03645000"],["79977.99000000","0.00007000"],["79977.90000000","0.00014000"],["79977.89000000","0.17483000"],["79977.76000000","0.00014000"],["79977.75000000","0.01521000"]],"asks":[["79980.15000000","2.78876000"],["79980.16000000","0.88397000"],["79980.17000000","0.00013000"],["79980.29000000","0.00014000"],["79980.30000000","0.09786000"],["79980.33000000","0.01002000"],["79980.53000000","0.01770000"],["79980.61000000","0.00014000"],["79980.62000000","0.11021000"],["79980.97000000","0.00007000"],["79981.01000000","0.00007000"],["79981.03000000","0.00014000"],["79981.04000000","0.46669000"],["79981.05000000","0.32793000"],["79981.06000000","0.00014000"],["79981.29000000","0.00014000"],["79981.61000000","0.01653000"],["79981.77000000","0.00008000"],["79981.82000000","0.04000000"],["79981.95000000","0.00007000"]]}}}
{"rx_ns": 10715452769200, "frame": {"stream":"btcusdt@depth@100ms","data":{"e":"depthUpdate","E":1787647710614,"s":"BTCUSDT","U":99116130004,"u":99116130056,"b":[["79980.14000000","0.85742000"],["79980.13000000","0.00069000"],["79979.03000000","0.00935000"],["79977.89000000","0.17483000"],["79977.88000000","0.00000000"],["79976.90000000","0.08146000"],["79976.59000000","0.42229000"],["79975.73000000","0.00879000"],["79975.62000000","0.00000000"],["79968.66000000","0.00400000"],["79966.97000000","0.00800000"],["79964.90000000","0.00007000"],["79934.85000000","0.00007000"],["71982.13000000","0.00192000"],["63984.12000000","0.00000000"],["63984.11000000","0.00000000"]],"a":[["79980.15000000","2.78876000"],["79980.16000000","0.88397000"],["79980.30000000","0.09786000"],["79980.62000000","0.11021000"],["79981.04000000","0.46669000"],["79981.82000000","0.04000000"],["79982.63000000","0.04018000"],["79983.51000000","0.00612000"],["79987.91000000","0.00400000"],["79996.90000000","0.00007000"]]}}}
{"rx_ns": 10715551983700, "frame": {"stream":"btcusdt@depth20@100ms","data":{"lastUpdateId":99116130068,"bids":[["79980.14000000","0.65331000"],["79980.13000000","0.00069000"],["79980.12000000","0.00013000"],["79980.10000000","0.00007000"],["79979.99000000","0.00020000"],["79979.05000000","0.00007000"],["79979.04000000","0.00007000"],["79979.03000000","0.00935000"],["79978.93000000","0.00007000"],["79978.73000000","0.00007000"],["79978.42000000","0.00007000"],["79978.29000000","0.00007000"],["79978.28000000","0.00007000"],["79978.23000000","0.00014000"],["79978.22000000","0.03645000"],["79977.99000000","0.00007000"],["79977.90000000","0.00014000"],["79977.89000000","0.17483000"],["79977.76000000","0.00014000"],["79977.75000000","0.01521000"]],"asks":[["79980.15000000","2.80773000"],["79980.16000000","0.88397000"],["79980.17000000","0.00013000"],["79980.29000000","0.00014000"],["79980.30000000","0.09786000"],["79980.33000000","0.01002000"],["79980.53000000","0.01770000"],["79980.61000000","0.00014000"],["79980.62000000","0.11021000"],["79980.97000000","0.00007000"],["79981.01000000","0.00007000"],["79981.03000000","0.00014000"],["79981.04000000","0.46669000"],["79981.05000000","0.32793000"],["79981.06000000","0.00014000"],["79981.29000000","0.00014000"],["79981.61000000","0.01653000"],["79981.77000000","0.00008000"],["79981.82000000","0.04000000"],["79981.95000000","0.00007000"]]}}}
{"rx_ns": 10715552088600, "frame": {"stream":"btcusdt@depth@100ms","data":{"e":"depthUpdate","E":1787647710714,"s":"BTCUSDT","U":99116130057,"u":99116130068,"b":[["79980.14000000","0.65331000"],["79966.97000000","0.01200000"],["79766.63000000","0.00770000"],["79762.12000000","0.00000000"],["71982.13000000","0.00208000"],["71982.12000000","0.00000000"],["71982.11000000","0.00008000"]],"a":[["79980.15000000","2.80773000"],["79983.06000000","0.00400000"],["79987.23000000","0.00400000"]]}}}
{"rx_ns": 10715651971500, "frame": {"stream":"btcusdt@depth20@100ms","data":{"lastUpdateId":99116130084,"bids":[["79980.14000000","0.85731000"],["79980.13000000","0.00069000"],["79980.12000000","0.00013000"],["79980.10000000","0.00007000"],["79979.99000000","0.00020000"],["79979.05000000","0.00007000"],["79979.04000000","0.00007000"],["79979.03000000","0.00935000"],["79978.93000000","0.00007000"],["79978.73000000","0.00007000"],["79978.42000000","0.00007000"],["79978.29000000","0.00007000"],["79978.28000000","0.00007000"],["79978.23000000","0.00014000"],["79978.22000000","0.03645000"],["79977.99000000","0.00007000"],["79977.90000000","0.00014000"],["79977.89000000","0.17483000"],["79977.76000000","0.00014000"],["79977.75000000","0.01521000"]],"asks":[["79980.15000000","2.80773000"],["79980.16000000","0.88397000"],["79980.17000000","0.00013000"],["79980.29000000","0.00014000"],["79980.30000000","0.09786000"],["79980.33000000","0.01002000"],["79980.53000000","0.01770000"],["79980.61000000","0.00014000"],["79980.62000000","0.11021000"],["79980.97000000","0.00007000"],["79981.01000000","0.00007000"],["79981.03000000","0.00014000"],["79981.04000000","0.46669000"],["79981.05000000","0.32793000"],["79981.06000000","0.00014000"],["79981.29000000","0.00014000"],["79981.61000000","0.01653000"],["79981.77000000","0.00008000"],["79981.82000000","0.04000000"],["79981.95000000","0.00007000"]]}}}
{"rx_ns": 10715652152600, "frame": {"stream":"btcusdt@depth@100ms","data":{"e":"depthUpdate","E":1787647710814,"s":"BTCUSDT","U":99116130069,"u":99116130084,"b":[["79980.14000000","0.85731000"],["79976.88000000","0.00007000"],["79966.98000000","0.00562000"],["71982.13000000","0.00224000"],["63984.00000000","0.00014000"]],"a":[["79987.72000000","0.00400000"]]}}}
{"rx_ns": 10715754122500, "frame": {"stream":"btcusdt@depth20@100ms","data":{"lastUpdateId":99116130101,"bids":[["79980.14000000","0.65481000"],["79980.13000000","0.00069000"],["79980.12000000","0.00013000"],["79980.10000000","0.00007000"],["79979.99000000","0.00020000"],["79979.05000000","0.00007000"],["79979.04000000","0.00007000"],["79979.03000000","0.00935000"],["79978.93000000","0.00007000"],["79978.73000000","0.00007000"],["79978.42000000","0.00007000"],["79978.29000000","0.00007000"],["79978.28000000","0.00007000"],["79978.23000000","0.00014000"],["79978.22000000","0.03645000"],["79977.99000000","0.00007000"],["79977.90000000","0.00014000"],["79977.89000000","0.17483000"],["79977.76000000","0.00014000"],["79977.75000000","0.01521000"]],"asks":[["79980.15000000","2.80765000"],["79980.16000000","0.88397000"],["79980.17000000","0.00013000"],["79980.29000000","0.00014000"],["79980.30000000","0.09786000"],["79980.33000000","0.01002000"],["79980.53000000","0.01770000"],["79980.61000000","0.00014000"],["79980.62000000","0.11021000"],["79980.97000000","0.00007000"],["79981.01000000","0.00007000"],["79981.03000000","0.00014000"],["79981.04000000","0.46669000"],["79981.05000000","0.32793000"],["79981.06000000","0.00014000"],["79981.29000000","0.00014000"],["79981.61000000","0.01653000"],["79981.77000000","0.00008000"],["79981.82000000","0.04000000"],["79981.95000000","0.00007000"]]}}}
{"rx_ns": 10715754204300, "frame": {"stream":"btcusdt@depth@100ms","data":{"e":"depthUpdate","E":1787647710914,"s":"BTCUSDT","U":99116130085,"u":99116130101,"b":[["79980.14000000","0.65481000"],["79969.50000000","0.00400000"],["79968.66000000","0.00000000"],["79967.59000000","0.00400000"],["79966.98000000","0.00162000"],["79966.97000000","0.00000000"],["79963.40000000","0.01600000"],["79889.05000000","0.62498000"],["79886.41000000","0.00000000"],["71982.13000000","0.00208000"]],"a":[["79980.15000000","2.80765000"],["79983.90000000","0.00400000"]]}}}
{"rx_ns": 10715852689900, "frame": {"stream":"btcusdt@depth20@100ms","data":{"lastUpdateId":99116130114,"bids":[["79980.14000000","0.65528000"],["79980.13000000","0.00069000"],["79980.12000000","0.00013000"],["79980.10000000","0.00007000"],["79979.99000000","0.00020000"],["79979.05000000","0.00007000"],["79979.04000000","0.00007000"],["79979.03000000","0.00935000"],["79978.93000000","0.00007000"],["79978.73000000","0.00007000"],["79978.42000000","0.00007000"],["79978.29000000","0.00007000"],["79978.28000000","0.00007000"],["79978.23000000","0.00014000"],["79978.22000000","0.03645000"],["79977.99000000","0.00007000"],["79977.90000000","0.00014000"],["79977.89000000","0.17483000"],["79977.76000000","0.00014000"],["79977.75000000","0.01521000"]],"asks":[["79980.15000000","2.80777000"],["79980.16000000","0.88397000"],["79980.17000000","0.00013000"],["79980.29000000","0.00014000"],["79980.30000000","0.09786000"],["79980.33000000","0.01002000"],["79980.53000000","0.01770000"],["79980.61000000","0.00014000"],["79980.62000000","0.11021000"],["79980.97000000","0.00007000"],["79981.01000000","0.00007000"],["79981.03000000","0.00014000"],["79981.04000000","0.46669000"],["79981.05000000","0.32793000"],["79981.06000000","0.00014000"],["79981.29000000","0.00014000"],["79981.61000000","0.01653000"],["79981.77000000","0.00008000"],["79981.82000000","0.04000000"],["79981.95000000","0.00007000"]]}}}
{"rx_ns": 10715852767700, "frame": {"stream":"btcusdt@depth@100ms","data":{"e":"depthUpdate","E":1787647711014,"s":"BTCUSDT","U":99116130102,"u":99116130114,"b":[["79980.14000000","0.65528000"],["79968.77000000","0.00000000"],["79967.60000000","0.00625000"],["79943.00000000","0.70000000"],["79941.00000000","0.00000000"],["71982.13000000","0.00240000"],["63984.12000000","0.00031000"],["63984.00000000","0.00014000"]],"a":[["79980.15000000","2.80777000"],["79983.98000000","0.00625000"],["79989.45000000","0.00000000"],["79995.27000000","0.33761000"],["80018.05000000","0.00000000"]]}}}
{"rx_ns": 10715952058800, "frame": {"stream":"btcusdt@depth20@100ms","data":{"lastUpdateId":99116130125,"bids":[["79980.14000000","0.65528000"],["79980.13000000","0.00069000"],["79980.12000000","0.00013000"],["79980.10000000","0.00007000"],["79979.99000000","0.00020000"],["79979.05000000","0.00007000"],["79979.04000000","0.00007000"],["79979.03000000","0.00935000"],["79978.93000000","0.00007000"],["79978.73000000","0.00007000"],["79978.42000000","0.00007000"],["79978.29000000","0.00007000"],["79978.28000000","0.00007000"],["79978.23000000","0.00014000"],["79978.22000000","0.03645000"],["79977.99000000","0.00007000"],["79977.90000000","0.00014000"],["79977.89000000","0.17483000"],["79977.76000000","0.00014000"],["79977.75000000","0.01521000"]],"asks":[["79980.15000000","2.80777000"],["79980.16000000","0.88397000"],["79980.17000000","0.00013000"],["79980.29000000","0.00014000"],["79980.30000000","0.09786000"],["79980.33000000","0.01002000"],["79980.53000000","0.01770000"],["79980.61000000","0.00014000"],["79980.62000000","0.11021000"],["79980.97000000","0.00007000"],["79981.01000000","0.00007000"],["79981.03000000","0.00014000"],["79981.04000000","0.46669000"],["79981.05000000","0.32793000"],["79981.06000000","0.00014000"],["79981.29000000","0.00014000"],["79981.61000000","0.01653000"],["79981.77000000","0.00008000"],["79981.82000000","0.04000000"],["79981.95000000","0.00007000"]]}}}
{"rx_ns": 10715952136900, "frame": {"stream":"btcusdt@depth@100ms","data":{"e":"depthUpdate","E":1787647711114,"s":"BTCUSDT","U":99116130115,"u":99116130125,"b":[["79879.39000000","0.00000000"],["79879.38000000","0.00025000"],["78780.43000000","0.00030000"],["71982.13000000","0.00240000"],["71982.00000000","0.00000000"]],"a":[["79994.00000000","0.72400000"],["80079.33000000","0.00025000"],["80079.34000000","0.00000000"]]}}}
{"rx_ns": 10716052331600, "frame": {"stream":"btcusdt@depth20@100ms","data":{"lastUpdateId":99116130166,"bids":[["79980.14000000","1.13274000"],["79980.13000000","0.00069000"],["79980.12000000","0.00013000"],["79980.10000000","0.00007000"],["79979.99000000","0.00020000"],["79979.59000000","0.06440000"],["79979.05000000","0.00007000"],["79979.04000000","0.00007000"],["79979.03000000","0.00935000"],["79978.93000000","0.00007000"],["79978.73000000","0.00007000"],["79978.42000000","0.00007000"],["79978.29000000","0.00007000"],["79978.28000000","0.00007000"],["79978.23000000","0.00014000"],["79978.22000000","0.00014000"],["79977.99000000","0.00007000"],["79977.90000000","0.00014000"],["79977.89000000","0.17483000"],["79977.76000000","0.00014000"]],"asks":[["79980.15000000","2.80777000"],["79980.16000000","0.88397000"],["79980.17000000","0.00013000"],["79980.29000000","0.00014000"],["79980.30000000","0.09786000"],["79980.33000000","0.01002000"],["79980.53000000","0.01770000"],["79980.61000000","0.00014000"],["79980.62000000","0.11021000"],["79980.97000000","0.00007000"],["79981.01000000","0.00007000"],["79981.03000000","0.00014000"],["79981.04000000","0.00028000"],["79981.05000000","0.32793000"],["79981.06000000","0.00014000"],["79981.29000000","0.00014000"],["79981.61000000","0.01653000"],["79981.77000000","0.00008000"],["79981.82000000","0.04000000"],["79981.95000000","0.00007000"]]}}}
{"rx_ns": 10716052502200, "frame": {"stream":"btcusdt@depth@100ms","data":{"e":"depthUpdate","E":1787647711214,"s":"BTCUSDT","U":99116130126,"u":99116130166,"b":[["79980.14000000","1.13274000"],["79979.59000000","0.06440000"],["79978.22000000","0.00014000"],["79976.91000000","0.08746000"],["79970.02000000","0.00625000"],["79967.60000000","0.00000000"],["71982.13000000","0.00256000"],["71982.11000000","0.00000000"],["63984.12000000","0.00000000"]],"a":[["79981.04000000","0.00028000"],["79982.68000000","0.00000000"],["79983.06000000","0.00000000"],["79983.46000000","0.00000000"],["79983.51000000","0.00619000"],["79983.90000000","0.00000000"],["79983.98000000","0.00000000"],["79984.60000000","0.00400000"],["79985.51000000","0.00625000"],["79985.83000000","0.00400000"],["79987.72000000","0.00000000"],["79987.91000000","0.01200000"],["79990.13000000","0.00000000"],["79994.00000000","0.02400000"],["80699.96000000","0.00010000"]]}}}
{"rx_ns": 10716154252600, "frame": {"stream":"btcusdt@depth20@100ms","data":{"lastUpdateId":99116130552,"bids":[["79980.14000000","3.35356000"],["79980.13000000","0.00027000"],["79980.12000000","0.00013000"],["79980.10000000","0.00007000"],["79979.99000000","0.00020000"],["79979.60000000","0.00014000"],["79979.59000000","0.06454000"],["79979.05000000","0.00007000"],["79979.04000000","0.00007000"],["79979.03000000","0.00935000"],["79978.93000000","0.00007000"],["79978.73000000","0.00007000"],["79978.42000000","0.00007000"],["79978.29000000","0.00007000"],["79978.28000000","0.00007000"],["79978.23000000","0.00026000"],["79977.99000000","0.00007000"],["79977.90000000","0.00014000"],["79977.89000000","0.05593000"],["79977.76000000","0.00014000"]],"asks":[["79980.15000000","2.12142000"],["79980.16000000","0.51079000"],["79980.17000000","0.00013000"],["79980.30000000","0.00014000"],["79980.33000000","0.01002000"],["79980.53000000","0.01763000"],["79980.62000000","0.00014000"],["79980.97000000","0.00007000"],["79981.01000000","0.00007000"],["79981.05000000","0.00028000"],["79981.06000000","0.00014000"],["79981.29000000","0.00014000"],["79981.52000000","0.01000000"],["79981.61000000","0.01660000"],["79981.62000000","0.02000000"],["79981.77000000","0.00008000"],["79981.81000000","0.00014000"],["79981.82000000","0.04014000"],["79981.95000000","0.00007000"],["79982.62000000","0.00014000"]]}}}
{"rx_ns": 10716154396500, "frame": {"stream":"btcusdt@depth@100ms","data":{"e":"depthUpdate","E":1787647711314,"s":"BTCUSDT","U":99116130167,"u":99116130552,"b":[["79980.14000000","3.35356000"],["79980.13000000","0.00027000"],["79979.60000000","0.00014000"],["79979.59000000","0.06454000"],["79979.03000000","0.00935000"],["79979.01000000","0.00000000"],["79979.00000000","0.00000000"],["79978.23000000","0.00026000"],["79978.22000000","0.00000000"],["79977.91000000","0.00000000"],["79977.90000000","0.00014000"],["79977.89000000","0.05593000"],["79977.76000000","0.00014000"],["79977.42000000","0.00014000"],["79977.32000000","0.00400000"],["79977.19000000","0.04739000"],["79976.92000000","0.00000000"],["79976.91000000","0.00014000"],["79976.90000000","0.08153000"],["79976.61000000","0.00625000"],["79976.60000000","0.00000000"],["79976.59000000","0.00014000"],["79976.47000000","0.01800000"],["79976.01000000","0.00000000"],["79975.48000000","1.10988000"],["79975.12000000","0.00400000"],["79974.52000000","0.00400000"],["79974.35000000","0.00000000"],["79974.28000000","0.12770000"],["79974.02000000","0.00625000"],["79973.48000000","0.00000000"],["79972.26000000","0.38186000"],["79971.06000000","0.00000000"],["79970.97000000","0.00000000"],["79970.02000000","0.00000000"],["79970.01000000","0.00000000"],["79969.84000000","0.00590000"],["79969.54000000","0.00000000"],["79969.50000000","0.00000000"],["79968.02000000","0.00162000"],["79967.59000000","0.00000000"],["79966.98000000","0.00000000"],["79965.33000000","0.02000000"],["79963.40000000","0.00000000"],["79962.55000000","0.37528000"],["79956.43000000","0.00000000"],["79952.76000000","0.00000000"],["79950.00000000","0.24546000"],["79938.72000000","0.00000000"],["79934.85000000","0.00000000"],["79934.02000000","0.00400000"],["79933.19000000","0.00000000"],["79931.28000000","0.00000000"],["79813.65000000","0.00000000"],["71982.13000000","0.00272000"],["63984.00000000","0.00014000"]],"a":[["79980.15000000","2.12142000"],["79980.16000000","0.51079000"],["79980.29000000","0.00000000"],["79980.30000000","0.00014000"],["79980.53000000","0.01763000"],["79980.61000000","0.00000000"],["79980.62000000","0.00014000"],["79981.03000000","0.00000000"],["79981.04000000","0.00000000"],["79981.05000000","0.00028000"],["79981.52000000","0.01000000"],["79981.61000000","0.01660000"],["79981.62000000","0.02000000"],["79981.81000000","0.00014000"],["79981.82000000","0.04014000"],["79982.62000000","0.00014000"],["79982.71000000","0.00000000"],["79982.78000000","0.00014000"],["79983.49000000","0.00000000"],["79983.51000000","0.00014000"],["79983.99000000","0.01763000"],["79984.09000000","0.00000000"],["79984.17000000","0.01956000"],["79984.60000000","0.00000000"],["79984.65000000","0.00000000"],["79984.66000000","0.00000000"],["79984.80000000","0.00000000"],["79985.03000000","0.00000000"],["79985.31000000","0.00000000"],["79985.38000000","0.00000000"],["79985.41000000","0.05113000"],["79985.42000000","0.08000000"],["79985.51000000","0.00000000"],["79985.52000000","0.00000000"],["79985.83000000","0.00000000"],["79985.98000000","0.00007000"],["79985.99000000","0.00018000"],["79987.03000000","0.00000000"],["79987.23000000","0.00000000"],["79987.63000000","0.00000000"],["79987.89000000","0.00000000"],["79987.91000000","0.00000000"],["79987.92000000","0.00000000"],["79988.56000000","0.00000000"],["79988.58000000","0.00000000"],["79988.66000000","0.00000000"],["79988.67000000","0.00000000"],["79988.70000000","0.00000000"],["79988.71000000","0.00000000"],["79988.76000000","0.00000000"],["79988.86000000","0.00000000"],["79989.15000000","0.00000000"],["79989.16000000","0.00000000"],["79989.45000000","0.00000000"],["79989.56000000","0.00400000"],["79989.61000000","0.00000000"],["79989.81000000","0.00000000"],["79990.07000000","0.00000000"],["79990.09000000","0.00000000"],["79990.13000000","0.00000000"],["79990.59000000","0.00000000"],["79990.94000000","0.00047000"],["79991.11000000","0.00000000"],["79991.14000000","0.00625000"],["79991.16000000","0.00000000"],["79991.24000000","0.00000000"],["79991.97000000","0.00400000"],["79992.17000000","0.00000000"],["79992.27000000","0.15792000"],["79993.67000000","0.02000000"],["79994.77000000","0.00000000"],["79994.95000000","0.00400000"],["79994.96000000","0.00000000"],["79995.27000000","0.00000000"],["79996.16000000","0.59785000"],["79997.69000000","0.00000000"],["79999.80000000","0.00000000"],["79999.99000000","0.00000000"],["80000.15000000","0.13341000"],["80000.58000000","0.00000000"],["80000.92000000","0.32388000"],["80003.96000000","0.62538000"],["80015.58000000","0.00000000"],["80017.95000000","0.33752000"],["80018.07000000","0.00166000"],["80020.01000000","1.33477000"],["80023.63000000","1.23749000"],["80029.92000000","0.00400000"],["80032.66000000","0.00400000"],["80045.94000000","1.23722000"],["80065.91000000","0.00000000"],["80071.19000000","3.13843000"],["80077.64000000","0.00000000"],["80080.19000000","0.00555000"],["80117.51000000","0.00000000"],["81179.86000000","0.00030000"]]}}}
{"rx_ns": 10716253293100, "frame": {"stream":"btcusdt@depth20@100ms","data":{"lastUpdateId":99116130629,"bids":[["79980.14000000","3.35356000"],["79980.13000000","0.00027000"],["79980.12000000","0.00013000"],["79980.10000000","0.00007000"],["79979.99000000","0.00020000"],["79979.60000000","0.00014000"],["79979.59000000","0.06454000"],["79979.05000000","0.00007000"],["79979.04000000","0.00007000"],["79979.03000000","0.00935000"],["79978.93000000","0.00007000"],["79978.73000000","0.00007000"],["79978.42000000","0.00007000"],["79978.29000000","0.00007000"],["79978.28000000","0.00007000"],["79978.23000000","0.00026000"],["79977.99000000","0.00007000"],["79977.90000000","0.00014000"],["79977.89000000","0.05593000"],["79977.86000000","0.00400000"]],"asks":[["79980.15000000","2.11383000"],["79980.16000000","0.51065000"],["79980.17000000","0.00013000"],["79980.33000000","0.00995000"],["79980.53000000","0.01763000"],["79980.97000000","0.00007000"],["79981.01000000","0.00007000"],["79981.05000000","0.00014000"],["79981.06000000","0.00014000"],["79981.29000000","0.00014000"],["79981.52000000","0.01014000"],["79981.61000000","0.01660000"],["79981.62000000","0.02014000"],["79981.77000000","0.00008000"],["79981.81000000","0.00014000"],["79981.82000000","0.04014000"],["79981.95000000","0.00007000"],["79982.62000000","0.00014000"],["79982.63000000","0.04032000"],["79982.78000000","0.00014000"]]}}}
{"rx_ns": 10716253391000, "frame": {"stream":"btcusdt@depth@100ms","data":{"e":"depthUpdate","E":1787647711414,"s":"BTCUSDT","U":99116130553,"u":99116130629,"b":[["79977.86000000","0.00400000"],["79977.19000000","0.04739000"],["79976.90000000","0.08146000"],["79976.61000000","0.00639000"],["79976.59000000","0.00000000"],["79976.33000000","0.00164000"],["79972.26000000","0.38353000"],["79972.25000000","1.04939000"],["79967.14000000","0.00000000"],["79965.46000000","1.87310000"],["79965.11000000","0.02250000"],["79962.51000000","0.00000000"],["79962.11000000","0.00000000"],["79961.42000000","0.00407000"],["79960.00000000","0.11787000"],["79940.00000000","0.12968000"],["79936.07000000","0.00000000"],["79934.02000000","0.00000000"],["79828.90000000","1.50117000"],["71982.13000000","0.00272000"]],"a":[["79980.15000000","2.11383000"],["79980.16000000","0.51065000"],["79980.30000000","0.00000000"],["79980.33000000","0.00995000"],["79980.53000000","0.01763000"],["79980.62000000","0.00000000"],["79981.05000000","0.00014000"],["79981.52000000","0.01014000"],["79981.61000000","0.01660000"],["79981.62000000","0.02014000"],["79982.63000000","0.04032000"],["79985.41000000","0.05120000"],["79985.98000000","0.00000000"],["79990.55000000","0.00250000"],["79992.16000000","0.00400000"],["79993.89000000","0.00000000"],["79994.97000000","0.01200000"],["79998.75000000","0.00000000"],["80002.12000000","0.04475000"],["80096.86000000","0.20310000"],["80108.12000000","0.00000000"],["80120.16000000","0.12403000"],["80132.81000000","1.50117000"]]}}}
{"rx_ns": 10716352152200, "frame": {"stream":"btcusdt@depth20@100ms","data":{"lastUpdateId":99116130664,"bids":[["79980.14000000","3.35370000"],["79980.13000000","0.00034000"],["79980.12000000","0.00013000"],["79980.10000000","0.00007000"],["79980.03000000","0.00014000"],["79980.02000000","0.20921000"],["79980.01000000","0.42215000"],["79979.99000000","0.00020000"],["79979.60000000","0.00014000"],["79979.59000000","0.06454000"],["79979.05000000","0.00007000"],["79979.04000000","0.00007000"],["79979.03000000","0.00935000"],["79978.93000000","0.00007000"],["79978.73000000","0.00007000"],["79978.42000000","0.00007000"],["79978.29000000","0.00007000"],["79978.28000000","0.00007000"],["79978.23000000","0.00026000"],["79977.99000000","0.00007000"]],"asks":[["79980.15000000","2.11409000"],["79980.16000000","0.50165000"],["79980.17000000","0.00013000"],["79980.33000000","0.00995000"],["79980.53000000","0.01763000"],["79980.97000000","0.00007000"],["79981.01000000","0.00007000"],["79981.05000000","0.00014000"],["79981.06000000","0.00014000"],["79981.29000000","0.00014000"],["79981.52000000","0.01014000"],["79981.61000000","0.01660000"],["79981.62000000","0.02014000"],["79981.77000000","0.00008000"],["79981.81000000","0.00014000"],["79981.82000000","0.04014000"],["79981.95000000","0.00007000"],["79982.62000000","0.00014000"],["79982.63000000","0.04032000"],["79982.78000000","0.00014000"]]}}}
{"rx_ns": 10716352286700, "frame": {"stream":"btcusdt@depth@100ms","data":{"e":"depthUpdate","E":1787647711514,"s":"BTCUSDT","U":99116130630,"u":99116130664,"b":[["79980.14000000","3.35370000"],["79980.13000000","0.00034000"],["79980.03000000","0.00014000"],["79980.02000000","0.20921000"],["79980.01000000","0.42215000"],["79977.90000000","0.00000000"],["79977.89000000","0.00014000"],["79977.76000000","0.00000000"],["79976.47000000","0.01814000"],["79974.46000000","0.01622000"],["79943.01000000","0.51075000"],["79942.93000000","0.00000000"],["79781.48000000","0.01615000"],["71982.13000000","0.00288000"],["63984.12000000","0.00031000"]],"a":[["79980.15000000","2.11409000"],["79980.16000000","0.50165000"],["79985.42000000","0.08007000"],["79985.80000000","0.13223000"],["80068.60000000","0.54728000"],["80144.08000000","0.02156000"]]}}}
{"rx_ns": 10716452390400, "frame": {"stream":"btcusdt@depth20@100ms","data":{"lastUpdateId":99116130731,"bids":[["79980.14000000","3.35397000"],["79980.13000000","0.00069000"],["79980.12000000","0.00013000"],["79980.10000000","0.00007000"],["79980.03000000","0.00014000"],["79980.02000000","0.20935000"],["79980.01000000","0.42229000"],["79979.99000000","0.00020000"],["79979.60000000","0.00014000"],["79979.59000000","0.06454000"],["79979.05000000","0.00007000"],["79979.04000000","0.00007000"],["79979.03000000","0.00921000"],["79978.93000000","0.00007000"],["79978.73000000","0.00007000"],["79978.42000000","0.00007000"],["79978.29000000","0.00007000"],["79978.28000000","0.00007000"],["79977.99000000","0.00007000"],["79977.86000000","0.00400000"]],"asks":[["79980.15000000","2.11409000"],["79980.16000000","0.50165000"],["79980.17000000","0.00013000"],["79980.33000000","0.00995000"],["79980.53000000","0.01763000"],["79980.97000000","0.00007000"],["79981.01000000","0.00007000"],["79981.05000000","0.00014000"],["79981.06000000","0.00014000"],["79981.29000000","0.00014000"],["79981.52000000","0.01014000"],["79981.61000000","0.01660000"],["79981.62000000","0.02014000"],["79981.77000000","0.00008000"],["79981.81000000","0.00014000"],["79981.82000000","0.04014000"],["79981.95000000","0.00007000"],["79982.62000000","0.00014000"],["79982.63000000","0.04032000"],["79982.78000000","0.00014000"]]}}}
{"rx_ns": 10716452493300, "frame": {"stream":"btcusdt@depth@100ms","data":{"e":"depthUpdate","E":1787647711614,"s":"BTCUSDT","U":99116130665,"u":99116130731,"b":[["79980.14000000","3.35397000"],["79980.13000000","0.00069000"],["79980.02000000","0.20935000"],["79980.01000000","0.42229000"],["79979.03000000","0.00921000"],["79978.23000000","0.00000000"],["79977.89000000","0.00000000"],["79977.32000000","0.00000000"],["79976.47000000","0.01800000"],["79976.45000000","0.00400000"],["79975.73000000","0.00872000"],["79964.90000000","0.00007000"],["79953.29000000","0.00000000"],["79930.63000000","0.00000000"],["79929.30000000","0.00000000"],["63984.12000000","0.00000000"],["63984.11000000","0.00000000"]],"a":[["79984.17000000","0.01963000"],["79984.35000000","0.02894000"],["79985.26000000","0.00598000"],["79985.42000000","0.08000000"],["79985.80000000","0.00000000"],["79996.90000000","0.00007000"],["80003.97000000","0.00000000"],["80024.58000000","0.00000000"],["80027.98000000","0.00000000"],["80148.17000000","0.00000000"]]}}}
{"rx_ns": 10716552605400, "frame": {"stream":"btcusdt@depth20@100ms","data":{"lastUpdateId":99116130767,"bids":[["79980.14000000","3.35432000"],["79980.13000000","0.00083000"],["79980.12000000","0.00013000"],["79980.10000000","0.00007000"],["79980.03000000","0.00014000"],["79980.02000000","0.20935000"],["79980.01000000","0.42229000"],["79979.99000000","0.00020000"],["79979.60000000","0.00014000"],["79979.59000000","0.06454000"],["79979.05000000","0.00007000"],["79979.04000000","0.00007000"],["79979.03000000","0.00921000"],["79978.93000000","0.00007000"],["79978.73000000","0.00007000"],["79978.42000000","0.00007000"],["79978.29000000","0.00007000"],["79978.28000000","0.00007000"],["79977.99000000","0.00007000"],["79977.86000000","0.00400000"]],"asks":[["79980.15000000","2.11409000"],["79980.16000000","0.50165000"],["79980.17000000","0.00013000"],["79980.33000000","0.00995000"],["79980.53000000","0.01763000"],["79980.97000000","0.00007000"],["79981.01000000","0.00007000"],["79981.05000000","0.00014000"],["79981.06000000","0.00014000"],["79981.15000000","0.00007000"],["79981.29000000","0.00014000"],["79981.52000000","0.01014000"],["79981.61000000","0.01660000"],["79981.62000000","0.02014000"],["79981.77000000","0.00008000"],["79981.81000000","0.00014000"],["79981.82000000","0.04014000"],["79981.95000000","0.00007000"],["79982.63000000","0.00014000"],["79982.78000000","0.00014000"]]}}}
{"rx_ns": 10716552695100, "frame": {"stream":"btcusdt@depth@100ms","data":{"e":"depthUpdate","E":1787647711714,"s":"BTCUSDT","U":99116130732,"u":99116130767,"b":[["79980.14000000","3.35432000"],["79980.13000000","0.00083000"],["79977.75000000","0.01528000"],["79977.39000000","0.00014000"],["79977.38000000","0.04033000"],["79977.19000000","0.04732000"],["79976.91000000","0.00000000"],["79974.52000000","0.00000000"],["79972.26000000","0.36753000"],["79968.54000000","0.01200000"],["77000.00000000","80.73913000"],["71982.13000000","0.00304000"]],"a":[["79980.15000000","2.11409000"],["79981.15000000","0.00007000"],["79982.62000000","0.00000000"],["79982.63000000","0.00014000"],["79984.35000000","0.02901000"],["79988.23000000","0.00007000"],["79999.00000000","0.70000000"],["80018.74000000","0.02000000"]]}}}
{"rx_ns": 10716652239500, "frame": {"stream":"btcusdt@depth20@100ms","data":{"lastUpdateId":99116130791,"bids":[["79980.14000000","3.35432000"],["79980.13000000","0.00083000"],["79980.12000000","0.00013000"],["79980.10000000","0.00007000"],["79980.03000000","0.00014000"],["79980.02000000","0.20935000"],["79980.01000000","0.42229000"],["79979.99000000","0.00020000"],["79979.60000000","0.00014000"],["79979.59000000","0.06454000"],["79979.05000000","0.00007000"],["79979.04000000","0.00007000"],["79979.03000000","0.00921000"],["79978.93000000","0.00007000"],["79978.73000000","0.00007000"],["79978.42000000","0.00007000"],["79978.29000000","0.00007000"],["79978.28000000","0.00007000"],["79977.99000000","0.00007000"],["79977.86000000","0.00400000"]],"asks":[["79980.15000000","2.11409000"],["79980.16000000","0.50165000"],["79980.17000000","0.00013000"],["79980.33000000","0.00995000"],["79980.53000000","0.01763000"],["79980.97000000","0.00007000"],["79981.01000000","0.00007000"],["79981.05000000","0.00014000"],["79981.06000000","0.00014000"],["79981.15000000","0.00007000"],["79981.29000000","0.00014000"],["79981.52000000","0.01014000"],["79981.61000000","0.01653000"],["79981.62000000","0.02014000"],["79981.77000000","0.00008000"],["79981.81000000","0.00014000"],["79981.82000000","0.04014000"],["79981.95000000","0.00007000"],["79982.78000000","0.00014000"],["79982.79000000","0.05321000"]]}}}
{"rx_ns": 10716652398400, "frame": {"stream":"btcusdt@depth@100ms","data":{"e":"depthUpdate","E":1787647711814,"s":"BTCUSDT","U":99116130768,"u":99116130791,"b":[["79977.75000000","0.01528000"],["79977.38000000","0.04047000"],["79976.61000000","0.00625000"],["79744.97000000","0.00000000"],["79400.00000000","1.68461000"],["71982.13000000","0.00304000"]],"a":[["79981.61000000","0.01653000"],["79981.82000000","0.04014000"],["79982.63000000","0.00000000"],["79982.79000000","0.05321000"],["79990.60000000","0.00000000"],["80013.93000000","0.02000000"],["80017.92000000","0.02000000"]]}}}
{"rx_ns": 10716752063900, "frame": {"stream":"btcusdt@depth20@100ms","data":{"lastUpdateId":99116130813,"bids":[["79980.14000000","3.35432000"],["79980.13000000","0.00083000"],["79980.12000000","0.00013000"],["79980.10000000","0.00007000"],["79980.03000000","0.00014000"],["79980.02000000","0.20935000"],["79980.01000000","0.42229000"],["79979.99000000","0.00020000"],["79979.60000000","0.00014000"],["79979.59000000","0.06454000"],["79979.05000000","0.00007000"],["79979.04000000","0.00007000"],["79979.03000000","0.00921000"],["79978.93000000","0.00007000"],["79978.73000000","0.00007000"],["79978.42000000","0.00007000"],["79978.29000000","0.00007000"],["79978.28000000","0.00007000"],["79977.99000000","0.00007000"],["79977.86000000","0.00400000"]],"asks":[["79980.15000000","2.11409000"],["79980.16000000","0.50165000"],["79980.17000000","0.00013000"],["79980.33000000","0.00995000"],["79980.53000000","0.01763000"],["79980.97000000","0.00007000"],["79981.01000000","0.00007000"],["79981.05000000","0.00014000"],["79981.06000000","0.00014000"],["79981.15000000","0.00007000"],["79981.29000000","0.00014000"],["79981.52000000","0.01014000"],["79981.61000000","0.01653000"],["79981.62000000","0.02014000"],["79981.77000000","0.00008000"],["79981.81000000","0.00014000"],["79981.82000000","0.04014000"],["79981.95000000","0.00007000"],["79982.78000000","0.00014000"],["79982.79000000","0.05321000"]]}}}
{"rx_ns": 10716752177600, "frame": {"stream":"btcusdt@depth@100ms","data":{"e":"depthUpdate","E":1787647711914,"s":"BTCUSDT","U":99116130792,"u":99116130813,"b":[["79954.45000000","0.51871000"],["79938.72000000","0.00007000"],["79930.46000000","1.01889000"],["79899.41000000","0.03126000"],["79894.33000000","0.62498000"],["79889.05000000","0.00000000"],["79778.60000000","0.00770000"],["79766.63000000","0.00000000"],["79748.81000000","0.01958000"],["71982.13000000","0.00320000"]],"a":[["79987.03000000","0.00010000"],["80005.68000000","0.00000000"],["80007.73000000","0.50823000"],["80008.75000000","0.00399000"],["80031.73000000","1.03251000"],["80045.69000000","0.00000000"],["80048.76000000","0.00399000"],["80077.69000000","0.00000000"],["80080.76000000","0.00399000"],["80125.55000000","0.00000000"],["80128.77000000","0.00399000"],["80197.70000000","0.00000000"],["80200.78000000","0.00399000"]]}}}
{"rx_ns": 10716852654200, "frame": {"stream":"btcusdt@depth20@100ms","data":{"lastUpdateId":99116130829,"bids":[["79980.14000000","3.35424000"],["79980.13000000","0.00083000"],["79980.12000000","0.00013000"],["79980.10000000","0.00007000"],["79980.03000000","0.00014000"],["79980.02000000","0.20935000"],["79980.01000000","0.42229000"],["79979.99000000","0.00020000"],["79979.60000000","0.00014000"],["79979.59000000","0.06454000"],["79979.05000000","0.00007000"],["79979.04000000","0.00007000"],["79979.03000000","0.00921000"],["79978.93000000","0.00007000"],["79978.73000000","0.00007000"],["79978.42000000","0.00007000"],["79978.29000000","0.00007000"],["79978.28000000","0.00007000"],["79977.99000000","0.00007000"],["79977.86000000","0.00400000"]],"asks":[["79980.15000000","2.11409000"],["79980.16000000","0.50165000"],["79980.17000000","0.00013000"],["79980.33000000","0.00995000"],["79980.53000000","0.01763000"],["79980.97000000","0.00007000"],["79981.01000000","0.00007000"],["79981.05000000","0.00014000"],["79981.06000000","0.00014000"],["79981.15000000","0.00007000"],["79981.29000000","0.00014000"],["79981.52000000","0.01014000"],["79981.61000000","0.01653000"],["79981.62000000","0.02014000"],["79981.77000000","0.00008000"],["79981.81000000","0.00014000"],["79981.82000000","0.04014000"],["79981.95000000","0.00007000"],["79982.78000000","0.00014000"],["79982.79000000","0.05321000"]]}}}
{"rx_ns": 10716852785200, "frame": {"stream":"btcusdt@depth@100ms","data":{"e":"depthUpdate","E":1787647712014,"s":"BTCUSDT","U":99116130814,"u":99116130829,"b":[["79980.14000000","3.35424000"],["79899.41000000","0.00000000"],["71982.13000000","0.00320000"],["63984.12000000","0.00031000"]],"a":[["79989.56000000","0.00000000"],["79990.69000000","0.00400000"],["79991.97000000","0.01200000"],["79992.16000000","0.00000000"],["79994.97000000","0.00000000"],["80058.94000000","0.00000000"],["80110.55000000","0.01958000"],["80178.95000000","0.00000000"]]}}}
{"rx_ns": 10716959992100, "frame": {"stream":"btcusdt@depth20@100ms","data":{"lastUpdateId":99116130843,"bids":[["79980.14000000","3.35424000"],["79980.13000000","0.00083000"],["79980.12000000","0.00013000"],["79980.10000000","0.00007000"],["79980.03000000","0.00014000"],["79980.02000000","0.20935000"],["79980.01000000","0.42229000"],["79979.99000000","0.00020000"],["79979.60000000","0.00014000"],["79979.59000000","0.06454000"],["79979.05000000","0.00007000"],["79979.04000000","0.00007000"],["79979.03000000","0.00921000"],["79978.93000000","0.00007000"],["79978.73000000","0.00007000"],["79978.42000000","0.00007000"],["79978.29000000","0.00007000"],["79978.28000000","0.00007000"],["79977.99000000","0.00007000"],["79977.86000000","0.00400000"]],"asks":[["79980.15000000","2.11439000"],["79980.16000000","0.50135000"],["79980.17000000","0.00013000"],["79980.33000000","0.00995000"],["79980.53000000","0.01763000"],["79980.97000000","0.00007000"],["79981.01000000","0.00007000"],["79981.05000000","0.00014000"],["79981.06000000","0.00014000"],["79981.15000000","0.00007000"],["79981.29000000","0.00014000"],["79981.52000000","0.01014000"],["79981.61000000","0.01653000"],["79981.62000000","0.02014000"],["79981.77000000","0.00008000"],["79981.81000000","0.00014000"],["79981.82000000","0.04014000"],["79981.95000000","0.00007000"],["79982.78000000","0.00014000"],["79982.79000000","0.05321000"]]}}}
{"rx_ns": 10716960093800, "frame": {"stream":"btcusdt@depth@100ms","data":{"e":"depthUpdate","E":1787647712115,"s":"BTCUSDT","U":99116130830,"u":99116130843,"b":[["79949.00000000","0.70400000"],["79943.01000000","0.00000000"],["79943.00000000","0.00000000"],["78780.43000000","0.00030000"],["71982.13000000","0.00336000"]],"a":[["79980.15000000","2.11439000"],["79980.16000000","0.50135000"],["79984.35000000","0.02894000"],["79985.26000000","0.00000000"],["79993.57000000","0.02714000"],["80063.76000000","0.00000000"]]}}}
{"rx_ns": 10717052132600, "frame": {"stream":"btcusdt@depth20@100ms","data":{"lastUpdateId":99116130857,"bids":[["79980.14000000","3.35424000"],["79980.13000000","0.00083000"],["79980.12000000","0.00013000"],["79980.10000000","0.00007000"],["79980.03000000","0.00014000"],["79980.02000000","0.20935000"],["79980.01000000","0.42229000"],["79979.99000000","0.00020000"],["79979.60000000","0.00014000"],["79979.59000000","0.06454000"],["79979.05000000","0.00007000"],["79979.04000000","0.00007000"],["79979.03000000","0.00921000"],["79978.93000000","0.00007000"],["79978.73000000","0.00007000"],["79978.42000000","0.00007000"],["79978.29000000","0.00007000"],["79978.28000000","0.00007000"],["79977.99000000","0.00007000"],["79977.86000000","0.00400000"]],"asks":[["79980.15000000","2.11439000"],["79980.16000000","0.50135000"],["79980.17000000","0.00013000"],["79980.33000000","0.00995000"],["79980.53000000","0.01763000"],["79980.97000000","0.00007000"],["79981.01000000","0.00007000"],["79981.05000000","0.00014000"],["79981.06000000","0.00014000"],["79981.15000000","0.00007000"],["79981.29000000","0.00014000"],["79981.52000000","0.01014000"],["79981.61000000","0.01653000"],["79981.62000000","0.02014000"],["79981.77000000","0.00008000"],["79981.81000000","0.00014000"],["79981.82000000","0.04014000"],["79981.95000000","0.00007000"],["79982.78000000","0.00014000"],["79982.79000000","0.05321000"]]}}}
{"rx_ns": 10717052215600, "frame": {"stream":"btcusdt@depth@100ms","data":{"e":"depthUpdate","E":1787647712214,"s":"BTCUSDT","U":99116130844,"u":99116130857,"b":[["79953.99000000","0.00000000"],["71982.13000000","0.00320000"],["71982.00000000","0.00020000"],["63984.12000000","0.00000000"]],"a":[["79983.99000000","0.32883000"],["79985.41000000","0.05128000"],["79992.27000000","0.11634000"],["80062.94000000","0.00000000"],["80110.55000000","0.00000000"],["80153.77000000","0.01958000"]]}}}
{"rx_ns": 10717152861300, "frame": {"stream":"btcusdt@depth20@100ms","data":{"lastUpdateId":99116130875,"bids":[["79980.14000000","3.35424000"],["79980.13000000","0.00083000"],["79980.12000000","0.00013000"],["79980.10000000","0.00007000"],["79980.03000000","0.00014000"],["79980.02000000","0.20935000"],["79980.01000000","0.42229000"],["79979.99000000","0.00020000"],["79979.60000000","0.00014000"],["79979.59000000","0.06454000"],["79979.05000000","0.00007000"],["79979.04000000","0.00007000"],["79979.03000000","0.00921000"],["79978.93000000","0.00007000"],["79978.73000000","0.00007000"],["79978.42000000","0.00007000"],["79978.29000000","0.00007000"],["79978.28000000","0.00007000"],["79977.99000000","0.00007000"],["79977.86000000","0.00400000"]],"asks":[["79980.15000000","2.11404000"],["79980.16000000","0.50135000"],["79980.17000000","0.00013000"],["79980.33000000","0.00995000"],["79980.53000000","0.01763000"],["79980.97000000","0.00007000"],["79981.01000000","0.00007000"],["79981.05000000","0.00014000"],["79981.06000000","0.00014000"],["79981.15000000","0.00007000"],["79981.29000000","0.00014000"],["79981.52000000","0.01014000"],["79981.61000000","0.01653000"],["79981.62000000","0.02014000"],["79981.77000000","0.00008000"],["79981.81000000","0.00014000"],["79981.82000000","0.04014000"],["79981.95000000","0.00007000"],["79982.78000000","0.00014000"],["79982.79000000","0.05321000"]]}}}
{"rx_ns": 10717152944600, "frame": {"stream":"btcusdt@depth@100ms","data":{"e":"depthUpdate","E":1787647712314,"s":"BTCUSDT","U":99116130858,"u":99116130875,"b":[["79973.84000000","0.00450000"],["79972.06000000","0.00598000"],["79840.72000000","0.00000000"],["79840.65000000","0.04528000"],["71982.13000000","0.00352000"],["71982.00000000","0.00000000"],["63984.00000000","0.00014000"]],"a":[["79980.15000000","2.11404000"],["79983.98000000","0.00014000"],["79988.23000000","0.00000000"],["80153.77000000","0.00000000"],["80174.54000000","0.01958000"],["80525.54000000","0.00000000"],["81179.86000000","0.00030000"]]}}}
{"rx_ns": 10717259018500, "frame": {"stream":"btcusdt@depth20@100ms","data":{"lastUpdateId":99116130883,"bids":[["79980.14000000","3.59454000"],["79980.13000000","0.00083000"],["79980.12000000","0.00013000"],["79980.10000000","0.00007000"],["79980.03000000","0.00014000"],["79980.02000000","0.20935000"],["79980.01000000","0.42229000"],["79979.99000000","0.00020000"],["79979.60000000","0.00014000"],["79979.59000000","0.06454000"],["79979.05000000","0.00007000"],["79979.04000000","0.00007000"],["79979.03000000","0.00921000"],["79978.93000000","0.00007000"],["79978.73000000","0.00007000"],["79978.42000000","0.00007000"],["79978.29000000","0.00007000"],["79978.28000000","0.00007000"],["79977.99000000","0.00007000"],["79977.86000000","0.00400000"]],"asks":[["79980.15000000","2.11404000"],["79980.16000000","0.50135000"],["79980.17000000","0.00013000"],["79980.33000000","0.00995000"],["79980.53000000","0.01763000"],["79980.97000000","0.00007000"],["79981.01000000","0.00007000"],["79981.05000000","0.00014000"],["79981.06000000","0.00014000"],["79981.15000000","0.00007000"],["79981.29000000","0.00014000"],["79981.52000000","0.01014000"],["79981.61000000","0.01653000"],["79981.62000000","0.02014000"],["79981.77000000","0.00008000"],["79981.81000000","0.00014000"],["79981.82000000","0.04014000"],["79981.95000000","0.00007000"],["79982.78000000","0.00014000"],["79982.79000000","0.05321000"]]}}}
{"rx_ns": 10717259106300, "frame": {"stream":"btcusdt@depth@100ms","data":{"e":"depthUpdate","E":1787647712414,"s":"BTCUSDT","U":99116130876,"u":99116130883,"b":[["79980.14000000","3.59454000"],["79899.41000000","0.03126000"],["71982.13000000","0.00352000"]],"a":[["80108.11000000","0.00160000"]]}}}
{"rx_ns": 10717352489300, "frame": {"stream":"btcusdt@depth20@100ms","data":{"lastUpdateId":99116130904,"bids":[["79980.14000000","3.35461000"],["79980.13000000","0.00076000"],["79980.12000000","0.00013000"],["79980.10000000","0.00007000"],["79980.03000000","0.00014000"],["79980.02000000","0.20935000"],["79980.01000000","0.42229000"],["79979.99000000","0.00020000"],["79979.60000000","0.00014000"],["79979.59000000","0.06454000"],["79979.05000000","0.00007000"],["79979.04000000","0.00007000"],["79979.03000000","0.00921000"],["79978.93000000","0.00007000"],["79978.73000000","0.00007000"],["79978.42000000","0.00007000"],["79978.29000000","0.00007000"],["79978.28000000","0.00007000"],["79977.99000000","0.00007000"],["79977.86000000","0.00400000"]],"asks":[["79980.15000000","2.11404000"],["79980.16000000","0.50135000"],["79980.17000000","0.00013000"],["79980.33000000","0.00995000"],["79980.53000000","0.01763000"],["79980.97000000","0.00007000"],["79981.01000000","0.00007000"],["79981.05000000","0.00014000"],["79981.06000000","0.00014000"],["79981.15000000","0.00007000"],["79981.29000000","0.00014000"],["79981.52000000","0.01014000"],["79981.61000000","0.01653000"],["79981.62000000","0.02014000"],["79981.77000000","0.00008000"],["79981.81000000","0.00014000"],["79981.82000000","0.04014000"],["79981.95000000","0.00007000"],["79982.78000000","0.00014000"],["79982.79000000","0.05321000"]]}}}
{"rx_ns": 10717352593800, "frame": {"stream":"btcusdt@depth@100ms","data":{"e":"depthUpdate","E":1787647712514,"s":"BTCUSDT","U":99116130884,"u":99116130904,"b":[["79980.14000000","3.35461000"],["79980.13000000","0.00076000"],["79942.93000000","0.30180000"],["79909.20000000","0.04689000"],["79902.83000000","0.00000000"],["79899.41000000","0.00000000"],["79840.65000000","0.00000000"],["71982.13000000","0.00352000"],["63984.12000000","0.00031000"]],"a":[["80025.69000000","0.43766000"],["80081.27000000","0.00000000"]]}}}
{"rx_ns": 10717452306500, "frame": {"stream":"btcusdt@depth20@100ms","data":{"lastUpdateId":99116130931,"bids":[["79980.14000000","1.38255000"],["79980.13000000","0.00076000"],["79980.12000000","0.00013000"],["79980.10000000","0.00007000"],["79980.03000000","0.00014000"],["79980.02000000","0.20935000"],["79980.01000000","0.42229000"],["79979.99000000","0.00020000"],["79979.60000000","0.00014000"],["79979.59000000","0.06454000"],["79979.05000000","0.00007000"],["79979.04000000","0.00007000"],["79979.03000000","0.00921000"],["79978.93000000","0.00007000"],["79978.73000000","0.00007000"],["79978.42000000","0.00007000"],["79978.29000000","0.00007000"],["79978.28000000","0.00007000"],["79977.99000000","0.00007000"],["79977.86000000","0.00400000"]],"asks":[["79980.15000000","2.31654000"],["79980.16000000","0.50135000"],["79980.17000000","0.00013000"],["79980.33000000","0.00995000"],["79980.53000000","0.01763000"],["79980.97000000","0.00007000"],["79981.01000000","0.00007000"],["79981.05000000","0.00014000"],["79981.06000000","0.00014000"],["79981.15000000","0.00007000"],["79981.29000000","0.00014000"],["79981.52000000","0.01014000"],["79981.61000000","0.01653000"],["79981.62000000","0.02014000"],["79981.77000000","0.00008000"],["79981.81000000","0.00014000"],["79981.82000000","0.04014000"],["79981.95000000","0.00007000"],["79982.78000000","0.00014000"],["79982.79000000","0.05321000"]]}}}
{"rx_ns": 10717452553400, "frame": {"stream":"btcusdt@depth@100ms","data":{"e":"depthUpdate","E":1787647712614,"s":"BTCUSDT","U":99116130905,"u":99116130931,"b":[["79980.14000000","1.38255000"],["79976.90000000","0.08139000"],["79976.61000000","0.00000000"],["79976.45000000","0.00000000"],["79975.06000000","0.00000000"],["79974.02000000","0.00000000"],["79972.21000000","0.00625000"],["79971.57000000","0.00625000"],["79968.54000000","0.00000000"],["79966.97000000","0.00400000"],["79964.90000000","0.00000000"],["79849.69000000","0.04903000"],["71982.13000000","0.00384000"],["63984.12000000","0.00000000"],["63984.11000000","0.00000000"]],"a":[["79980.15000000","2.31654000"],["79987.95000000","1.04939000"],["79990.69000000","0.00000000"],["79996.90000000","0.00000000"],["80089.60000000","0.02804000"],["80148.16000000","0.00160000"]]}}}
{"rx_ns": 10717552242700, "frame": {"stream":"btcusdt@depth20@100ms","data":{"lastUpdateId":99116130965,"bids":[["79980.14000000","1.38255000"],["79980.13000000","0.00076000"],["79980.12000000","0.00013000"],["79980.10000000","0.00007000"],["79980.03000000","0.00014000"],["79980.02000000","0.20935000"],["79980.01000000","0.42229000"],["79979.99000000","0.00020000"],["79979.60000000","0.00014000"],["79979.59000000","0.06454000"],["79979.05000000","0.00007000"],["79979.04000000","0.00007000"],["79979.03000000","0.00921000"],["79978.93000000","0.00007000"],["79978.73000000","0.00007000"],["79978.42000000","0.00007000"],["79978.29000000","0.00007000"],["79978.28000000","0.00007000"],["79977.99000000","0.00007000"],["79977.86000000","0.00400000"]],"asks":[["79980.15000000","2.32561000"],["79980.16000000","0.50135000"],["79980.17000000","0.00013000"],["79980.33000000","0.00995000"],["79980.53000000","0.01763000"],["79980.97000000","0.00007000"],["79981.01000000","0.00007000"],["79981.05000000","0.00014000"],["79981.06000000","0.00014000"],["79981.15000000","0.00007000"],["79981.29000000","0.00014000"],["79981.52000000","0.01014000"],["79981.61000000","0.01653000"],["79981.62000000","0.02014000"],["79981.77000000","0.00008000"],["79981.81000000","0.00014000"],["79981.82000000","0.04014000"],["79981.95000000","0.00007000"],["79982.78000000","0.00014000"],["79982.79000000","0.05321000"]]}}}
{"rx_ns": 10717552332800, "frame": {"stream":"btcusdt@depth@100ms","data":{"e":"depthUpdate","E":1787647712714,"s":"BTCUSDT","U":99116130932,"u":99116130965,"b":[["79976.90000000","0.08139000"],["79973.84000000","0.00000000"],["79973.59000000","0.00442000"],["79972.06000000","0.00000000"],["79971.87000000","0.00594000"],["79971.57000000","0.00000000"],["79970.01000000","0.00625000"],["79966.97000000","0.01200000"],["79964.90000000","0.00007000"],["79849.69000000","0.00000000"],["71982.13000000","0.00384000"]],"a":[["79980.15000000","2.32561000"],["79982.89000000","0.01956000"],["79983.08000000","0.00014000"],["79983.09000000","0.13289000"],["79983.99000000","0.32869000"],["79984.17000000","0.01956000"],["79984.35000000","0.00000000"],["79985.41000000","0.35798000"],["79987.03000000","0.00000000"],["79987.94000000","0.00400000"],["79994.95000000","0.00000000"],["79996.90000000","0.00007000"],["80027.18000000","0.00400000"],["80027.64000000","0.00000000"],["80032.66000000","0.00000000"],["80089.60000000","0.00000000"]]}}}
{"rx_ns": 10717652424400, "frame": {"stream":"btcusdt@depth20@100ms","data":{"lastUpdateId":99116130977,"bids":[["79980.14000000","1.38255000"],["79980.13000000","0.00076000"],["79980.12000000","0.00013000"],["79980.10000000","0.00007000"],["79980.03000000","0.00014000"],["79980.02000000","0.20935000"],["79980.01000000","0.42229000"],["79979.99000000","0.00020000"],["79979.60000000","0.00014000"],["79979.59000000","0.06454000"],["79979.05000000","0.00007000"],["79979.04000000","0.00007000"],["79979.03000000","0.00921000"],["79978.93000000","0.00007000"],["79978.73000000","0.00007000"],["79978.42000000","0.00007000"],["79978.29000000","0.00007000"],["79978.28000000","0.00007000"],["79977.99000000","0.00007000"],["79977.86000000","0.00400000"]],"asks":[["79980.15000000","2.34327000"],["79980.16000000","0.50135000"],["79980.17000000","0.00013000"],["79980.33000000","0.00995000"],["79980.53000000","0.01763000"],["79980.97000000","0.00007000"],["79981.01000000","0.00007000"],["79981.05000000","0.00014000"],["79981.06000000","0.00014000"],["79981.15000000","0.00007000"],["79981.29000000","0.00014000"],["79981.52000000","0.01014000"],["79981.61000000","0.01653000"],["79981.62000000","0.02014000"],["79981.77000000","0.00008000"],["79981.81000000","0.00014000"],["79981.82000000","0.04014000"],["79981.95000000","0.00007000"],["79982.78000000","0.00014000"],["79982.79000000","0.05321000"]]}}}
{"rx_ns": 10717652530900, "frame": {"stream":"btcusdt@depth@100ms","data":{"e":"depthUpdate","E":1787647712814,"s":"BTCUSDT","U":99116130966,"u":99116130977,"b":[["79840.65000000","0.04528000"],["71982.13000000","0.00384000"]],"a":[["79980.15000000","2.34327000"],["79984.30000000","0.00000000"],["79987.94000000","0.00000000"],["79990.54000000","0.00400000"],["80068.55000000","3.13843000"],["80071.19000000","0.00000000"],["80080.54000000","0.02804000"]]}}}
{"rx_ns": 10717769528400, "frame": {"stream":"btcusdt@depth20@100ms","data":{"lastUpdateId":99116130983,"bids":[["79980.14000000","1.38255000"],["79980.13000000","0.00076000"],["79980.12000000","0.00013000"],["79980.10000000","0.00007000"],["79980.03000000","0.00014000"],["79980.02000000","0.20935000"],["79980.01000000","0.42229000"],["79979.99000000","0.00020000"],["79979.60000000","0.00014000"],["79979.59000000","0.06454000"],["79979.05000000","0.00007000"],["79979.04000000","0.00007000"],["79979.03000000","0.00921000"],["79978.93000000","0.00007000"],["79978.73000000","0.00007000"],["79978.42000000","0.00007000"],["79978.29000000","0.00007000"],["79978.28000000","0.00007000"],["79977.99000000","0.00007000"],["79977.86000000","0.00400000"]],"asks":[["79980.15000000","2.34327000"],["79980.16000000","0.50135000"],["79980.17000000","0.00013000"],["79980.33000000","0.00995000"],["79980.53000000","0.01763000"],["79980.97000000","0.00007000"],["79981.01000000","0.00007000"],["79981.05000000","0.00014000"],["79981.06000000","0.00014000"],["79981.15000000","0.00007000"],["79981.29000000","0.00014000"],["79981.52000000","0.01014000"],["79981.61000000","0.01653000"],["79981.62000000","0.02014000"],["79981.77000000","0.00008000"],["79981.81000000","0.00014000"],["79981.82000000","0.04014000"],["79981.95000000","0.00007000"],["79982.78000000","0.00014000"],["79982.79000000","0.05321000"]]}}}
{"rx_ns": 10717769662500, "frame": {"stream":"btcusdt@depth@100ms","data":{"e":"depthUpdate","E":1787647712914,"s":"BTCUSDT","U":99116130978,"u":99116130983,"b":[["79954.00000000","0.03426000"],["79938.72000000","0.00007000"],["79899.41000000","0.03126000"],["75493.45000000","0.00000000"],["71982.13000000","0.00400000"]],"a":[]}}}
{"rx_ns": 10717853637500, "frame": {"stream":"btcusdt@depth20@100ms","data":{"lastUpdateId":99116130991,"bids":[["79980.14000000","1.38150000"],["79980.13000000","0.00076000"],["79980.12000000","0.00013000"],["79980.10000000","0.00007000"],["79980.03000000","0.00014000"],["79980.02000000","0.20935000"],["79980.01000000","0.42229000"],["79979.99000000","0.00020000"],["79979.60000000","0.00014000"],["79979.59000000","0.06454000"],["79979.05000000","0.00007000"],["79979.04000000","0.00007000"],["79979.03000000","0.00921000"],["79978.93000000","0.00007000"],["79978.73000000","0.00007000"],["79978.42000000","0.00007000"],["79978.29000000","0.00007000"],["79978.28000000","0.00007000"],["79977.99000000","0.00007000"],["79977.86000000","0.00400000"]],"asks":[["79980.15000000","2.34327000"],["79980.16000000","0.50135000"],["79980.17000000","0.00013000"],["79980.33000000","0.00995000"],["79980.53000000","0.01763000"],["79980.97000000","0.00007000"],["79981.01000000","0.00007000"],["79981.05000000","0.00014000"],["79981.06000000","0.00014000"],["79981.15000000","0.00007000"],["79981.29000000","0.00014000"],["79981.52000000","0.01014000"],["79981.61000000","0.01653000"],["79981.62000000","0.02014000"],["79981.77000000","0.00008000"],["79981.81000000","0.00014000"],["79981.82000000","0.04014000"],["79981.95000000","0.00007000"],["79982.78000000","0.00014000"],["79982.79000000","0.05321000"]]}}}
{"rx_ns": 10717853755400, "frame": {"stream":"btcusdt@depth@100ms","data":{"e":"depthUpdate","E":1787647713014,"s":"BTCUSDT","U":99116130984,"u":99116130991,"b":[["79980.14000000","1.38150000"],["79899.41000000","0.00000000"],["79778.60000000","0.00000000"],["79773.62000000","0.00770000"],["71982.13000000","0.00416000"],["71982.12000000","0.00008000"],["63984.12000000","0.00031000"]],"a":[]}}}
{"rx_ns": 10717951901600, "frame": {"stream":"btcusdt@depth20@100ms","data":{"lastUpdateId":99116131013,"bids":[["79980.14000000","1.38132000"],["79980.13000000","0.00076000"],["79980.12000000","0.00013000"],["79980.10000000","0.00007000"],["79980.03000000","0.00014000"],["79980.02000000","0.20935000"],["79980.01000000","0.42229000"],["79979.99000000","0.00020000"],["79979.60000000","0.00014000"],["79979.59000000","0.06454000"],["79979.05000000","0.00007000"],["79979.04000000","0.00007000"],["79979.03000000","0.00921000"],["79978.93000000","0.00007000"],["79978.73000000","0.00007000"],["79978.42000000","0.00007000"],["79978.29000000","0.00007000"],["79978.28000000","0.00007000"],["79977.99000000","0.00007000"],["79977.86000000","0.00400000"]],"asks":[["79980.15000000","2.34334000"],["79980.16000000","0.50142000"],["79980.17000000","0.00013000"],["79980.33000000","0.00995000"],["79980.53000000","0.01763000"],["79980.97000000","0.00007000"],["79981.01000000","0.00007000"],["79981.05000000","0.00014000"],["79981.06000000","0.00014000"],["79981.15000000","0.00007000"],["79981.29000000","0.00014000"],["79981.52000000","0.01014000"],["79981.61000000","0.01653000"],["79981.62000000","0.02021000"],["79981.72000000","0.00014000"],["79981.73000000","0.02562000"],["79981.77000000","0.00008000"],["79981.81000000","0.00014000"],["79981.82000000","0.04014000"],["79981.95000000","0.00007000"]]}}}
{"rx_ns": 10717952009800, "frame": {"stream":"btcusdt@depth@100ms","data":{"e":"depthUpdate","E":1787647713114,"s":"BTCUSDT","U":99116130992,"u":99116131013,"b":[["79980.14000000","1.38132000"],["78780.43000000","0.00030000"],["71982.13000000","0.00416000"]],"a":[["79980.15000000","2.34334000"],["79980.16000000","0.50142000"],["79981.62000000","0.02021000"],["79981.72000000","0.00014000"],["79981.73000000","0.02562000"],["79982.89000000","0.01949000"],["79983.08000000","0.00000000"],["79983.09000000","0.00000000"],["79983.54000000","0.00000000"],["80013.54000000","0.00606000"]]}}}
{"rx_ns": 10718053835800, "frame": {"stream":"btcusdt@depth20@100ms","data":{"lastUpdateId":99116131023,"bids":[["79980.14000000","1.38132000"],["79980.13000000","0.00076000"],["79980.12000000","0.00013000"],["79980.10000000","0.00007000"],["79980.03000000","0.00014000"],["79980.02000000","0.20935000"],["79980.01000000","0.42229000"],["79979.99000000","0.00020000"],["79979.60000000","0.00014000"],["79979.59000000","0.06454000"],["79979.05000000","0.00007000"],["79979.04000000","0.00007000"],["79979.03000000","0.00921000"],["79978.93000000","0.00007000"],["79978.73000000","0.00007000"],["79978.42000000","0.00007000"],["79978.29000000","0.00007000"],["79978.28000000","0.00007000"],["79977.99000000","0.00007000"],["79977.86000000","0.00400000"]],"asks":[["79980.15000000","2.34334000"],["79980.16000000","0.50142000"],["79980.17000000","0.00013000"],["79980.33000000","0.00995000"],["79980.53000000","0.01763000"],["79980.97000000","0.00007000"],["79981.01000000","0.00007000"],["79981.05000000","0.00014000"],["79981.06000000","0.00014000"],["79981.15000000","0.00007000"],["79981.29000000","0.00014000"],["79981.52000000","0.01014000"],["79981.61000000","0.01653000"],["79981.62000000","0.02021000"],["79981.72000000","0.00014000"],["79981.73000000","0.02576000"],["79981.77000000","0.00008000"],["79981.81000000","0.00014000"],["79981.82000000","0.04014000"],["79981.95000000","0.00007000"]]}}}
{"rx_ns": 10718053937800, "frame": {"stream":"btcusdt@depth@100ms","data":{"e":"depthUpdate","E":1787647713214,"s":"BTCUSDT","U":99116131014,"u":99116131023,"b":[["71982.13000000","0.00432000"],["63984.12000000","0.00000000"]],"a":[["79981.62000000","0.02021000"],["79981.73000000","0.02576000"],["79982.79000000","0.05307000"]]}}}
{"rx_ns": 10718157233700, "frame": {"stream":"btcusdt@depth20@100ms","data":{"lastUpdateId":99116131039,"bids":[["79980.14000000","1.38132000"],["79980.13000000","0.00076000"],["79980.12000000","0.00013000"],["79980.10000000","0.00007000"],["79980.03000000","0.00014000"],["79980.02000000","0.20935000"],["79980.01000000","0.42229000"],["79979.99000000","0.00020000"],["79979.60000000","0.00014000"],["79979.59000000","0.06454000"],["79979.05000000","0.00007000"],["79979.04000000","0.00007000"],["79979.03000000","0.00921000"],["79978.93000000","0.00007000"],["79978.73000000","0.00007000"],["79978.42000000","0.00007000"],["79978.29000000","0.00007000"],["79978.28000000","0.00007000"],["79977.99000000","0.00007000"],["79977.86000000","0.00400000"]],"asks":[["79980.15000000","2.34334000"],["79980.16000000","0.50142000"],["79980.17000000","0.00013000"],["79980.33000000","0.00995000"],["79980.53000000","0.01763000"],["79980.97000000","0.00007000"],["79981.01000000","0.00007000"],["79981.05000000","0.00014000"],["79981.06000000","0.00014000"],["79981.15000000","0.00007000"],["79981.29000000","0.00014000"],["79981.52000000","0.01014000"],["79981.61000000","0.01653000"],["79981.62000000","0.02021000"],["79981.72000000","0.00014000"],["79981.73000000","0.02576000"],["79981.77000000","0.00008000"],["79981.81000000","0.00014000"],["79981.82000000","0.04014000"],["79981.95000000","0.00007000"]]}}}
{"rx_ns": 10718157375700, "frame": {"stream":"btcusdt@depth@100ms","data":{"e":"depthUpdate","E":1787647713314,"s":"BTCUSDT","U":99116131024,"u":99116131039,"b":[["79899.41000000","0.03126000"],["71982.13000000","0.00432000"],["71982.00000000","0.00020000"],["63984.00000000","0.00014000"]],"a":[["81179.86000000","0.00030000"]]}}}
{"rx_ns": 10718254933800, "frame": {"stream":"btcusdt@depth20@100ms","data":{"lastUpdateId":99116131047,"bids":[["79980.14000000","1.38132000"],["79980.13000000","0.00076000"],["79980.12000000","0.00013000"],["79980.10000000","0.00007000"],["79980.03000000","0.00014000"],["79980.02000000","0.20935000"],["79980.01000000","0.42229000"],["79979.99000000","0.00020000"],["79979.60000000","0.00014000"],["79979.59000000","0.06454000"],["79979.05000000","0.00007000"],["79979.04000000","0.00007000"],["79979.03000000","0.00921000"],["79978.93000000","0.00007000"],["79978.73000000","0.00007000"],["79978.42000000","0.00007000"],["79978.29000000","0.00007000"],["79978.28000000","0.00007000"],["79977.99000000","0.00007000"],["79977.86000000","0.00400000"]],"asks":[["79980.15000000","2.34013000"],["79980.16000000","0.50142000"],["79980.17000000","0.00013000"],["79980.33000000","0.00995000"],["79980.53000000","0.01763000"],["79980.97000000","0.00007000"],["79981.01000000","0.00007000"],["79981.05000000","0.00014000"],["79981.06000000","0.00014000"],["79981.15000000","0.00007000"],["79981.29000000","0.00014000"],["79981.52000000","0.01014000"],["79981.61000000","0.01653000"],["79981.62000000","0.02021000"],["79981.72000000","0.00014000"],["79981.73000000","0.02576000"],["79981.77000000","0.00008000"],["79981.81000000","0.00014000"],["79981.82000000","0.04014000"],["79982.78000000","0.00014000"]]}}}
{"rx_ns": 10718255079800, "frame": {"stream":"btcusdt@depth@100ms","data":{"e":"depthUpdate","E":1787647713414,"s":"BTCUSDT","U":99116131040,"u":99116131047,"b":[["79899.41000000","0.00000000"],["71982.13000000","0.00448000"],["71982.00000000","0.00000000"]],"a":[["79980.15000000","2.34013000"],["79981.95000000","0.00000000"],["80130.00000000","0.02487000"]]}}}
{"rx_ns": 10718359620500, "frame": {"stream":"btcusdt@depth20@100ms","data":{"lastUpdateId":99116131145,"bids":[["79980.14000000","0.90288000"],["79980.13000000","0.00076000"],["79980.12000000","0.00013000"],["79980.10000000","0.00007000"],["79980.02000000","0.00014000"],["79980.01000000","0.00014000"],["79979.99000000","0.00020000"],["79979.60000000","0.00014000"],["79979.59000000","0.06454000"],["79979.05000000","0.00007000"],["79979.04000000","0.00007000"],["79979.03000000","0.00921000"],["79978.93000000","0.00007000"],["79978.73000000","0.00007000"],["79978.42000000","0.00007000"],["79978.29000000","0.00007000"],["79978.28000000","0.00007000"],["79977.99000000","0.00007000"],["79977.76000000","0.00014000"],["79977.75000000","0.01528000"]],"asks":[["79980.15000000","2.34020000"],["79980.16000000","0.50149000"],["79980.17000000","0.00027000"],["79980.18000000","0.11037000"],["79980.33000000","0.00995000"],["79980.53000000","0.01763000"],["79980.97000000","0.00007000"],["79981.01000000","0.00007000"],["79981.05000000","0.00014000"],["79981.06000000","0.00014000"],["79981.15000000","0.00007000"],["79981.29000000","0.00014000"],["79981.52000000","0.01014000"],["79981.61000000","0.01653000"],["79981.62000000","0.02021000"],["79981.73000000","0.00014000"],["79981.77000000","0.00008000"],["79981.81000000","0.00014000"],["79981.82000000","0.04014000"],["79982.78000000","0.00014000"]]}}}
{"rx_ns": 10718359724200, "frame": {"stream":"btcusdt@depth@100ms","data":{"e":"depthUpdate","E":1787647713514,"s":"BTCUSDT","U":99116131048,"u":99116131145,"b":[["79980.14000000","0.90288000"],["79980.03000000","0.00000000"],["79980.02000000","0.00014000"],["79980.01000000","0.00014000"],["79977.86000000","0.00000000"],["79977.76000000","0.00014000"],["79977.42000000","0.00007000"],["79976.91000000","0.00007000"],["79976.33000000","0.00000000"],["79975.48000000","0.64131000"],["79975.12000000","0.00000000"],["79973.59000000","0.00000000"],["79972.24000000","0.00000000"],["79972.21000000","0.00000000"],["79971.87000000","0.00000000"],["79970.02000000","0.00625000"],["79970.01000000","0.00000000"],["79968.77000000","0.00625000"],["79968.02000000","0.00000000"],["79966.98000000","0.01200000"],["79966.97000000","0.00000000"],["79966.05000000","0.00326000"],["79965.33000000","0.00000000"],["79962.93000000","0.02000000"],["79962.55000000","0.00000000"],["79934.02000000","0.00400000"],["79930.63000000","0.79489000"],["79928.54000000","0.00400000"],["79911.66000000","1.57237000"],["79909.24000000","1.23926000"],["79894.33000000","0.00000000"],["79889.05000000","0.62498000"],["71982.13000000","0.00432000"],["63984.12000000","0.00031000"]],"a":[["79980.15000000","2.34020000"],["79980.16000000","0.50149000"],["79980.17000000","0.00027000"],["79980.18000000","0.11037000"],["79981.72000000","0.00000000"],["79981.73000000","0.00014000"],["79983.34000000","0.00400000"],["79983.92000000","0.00450000"],["79984.17000000","0.01963000"],["79985.15000000","0.00625000"],["79985.42000000","0.08007000"],["79985.67000000","0.03231000"],["79985.72000000","0.00594000"],["79988.24000000","0.94223000"],["79990.94000000","0.00000000"],["79991.14000000","0.00000000"],["79991.96000000","1.87060000"],["79995.60000000","0.33761000"],["80000.16000000","1.51486000"],["80001.01000000","0.62517000"],["80002.52000000","0.00400000"],["80004.98000000","0.00399000"],["80008.75000000","0.00000000"],["80011.19000000","0.62509000"],["80017.95000000","0.00000000"],["80020.01000000","0.84105000"],["80023.63000000","0.00000000"],["80024.44000000","0.00400000"],["80024.80000000","0.00000000"],["80027.18000000","0.00000000"],["80029.92000000","0.00000000"],["80044.99000000","0.00399000"],["80045.94000000","0.00007000"],["80048.76000000","0.00000000"],["80076.99000000","0.00399000"],["80080.76000000","0.00000000"],["80124.99000000","0.00399000"],["80128.77000000","0.00000000"],["80197.00000000","0.00399000"],["80200.78000000","0.00000000"]]}}}
{"rx_ns": 10718452054000, "frame": {"stream":"btcusdt@depth20@100ms","data":{"lastUpdateId":99116131227,"bids":[["79980.14000000","0.71418000"],["79980.13000000","0.00083000"],["79980.12000000","0.00013000"],["79980.10000000","0.00007000"],["79979.99000000","0.00020000"],["79979.60000000","0.00014000"],["79979.59000000","0.06454000"],["79979.05000000","0.00007000"],["79979.04000000","0.00007000"],["79979.03000000","0.00921000"],["79978.93000000","0.00007000"],["79978.73000000","0.00007000"],["79978.42000000","0.00007000"],["79978.29000000","0.00007000"],["79978.28000000","0.00007000"],["79977.99000000","0.00007000"],["79977.76000000","0.00014000"],["79977.75000000","0.01528000"],["79977.42000000","0.00007000"],["79977.39000000","0.00014000"]],"asks":[["79980.15000000","2.34070000"],["79980.16000000","0.50149000"],["79980.17000000","0.00027000"],["79980.18000000","0.11051000"],["79980.33000000","0.00995000"],["79980.53000000","0.01763000"],["79980.97000000","0.00007000"],["79981.01000000","0.00007000"],["79981.05000000","0.00014000"],["79981.06000000","0.00014000"],["79981.15000000","0.00007000"],["79981.29000000","0.00014000"],["79981.52000000","0.01014000"],["79981.61000000","0.01653000"],["79981.62000000","0.02014000"],["79981.77000000","0.00008000"],["79981.81000000","0.00014000"],["79981.82000000","0.04014000"],["79982.78000000","0.00014000"],["79982.79000000","0.05307000"]]}}}
{"rx_ns": 10718452184400, "frame": {"stream":"btcusdt@depth@100ms","data":{"e":"depthUpdate","E":1787647713614,"s":"BTCUSDT","U":99116131146,"u":99116131227,"b":[["79980.14000000","0.71418000"],["79980.13000000","0.00083000"],["79980.02000000","0.00000000"],["79980.01000000","0.00000000"],["79977.38000000","0.04054000"],["79977.21000000","0.00014000"],["79977.20000000","0.17734000"],["79976.91000000","0.00000000"],["79976.90000000","0.08146000"],["79976.70000000","0.42215000"],["79976.47000000","0.01814000"],["79976.00000000","0.02428000"],["79970.07000000","0.00048000"],["79949.00000000","0.00400000"],["71982.13000000","0.00448000"],["63984.12000000","0.00000000"],["63984.11000000","0.00000000"]],"a":[["79980.15000000","2.34070000"],["79980.16000000","0.50149000"],["79980.18000000","0.11051000"],["79981.62000000","0.02014000"],["79981.73000000","0.00000000"],["79982.89000000","0.01956000"],["79983.03000000","0.00571000"],["79983.53000000","0.00165000"],["79983.54000000","0.00007000"],["79991.60000000","0.00000000"],["79992.27000000","0.21135000"],["79992.46000000","0.00000000"]]}}}
{"rx_ns": 10718552894900, "frame": {"stream":"btcusdt@depth20@100ms","data":{"lastUpdateId":99116131250,"bids":[["79980.14000000","0.71418000"],["79980.13000000","0.00083000"],["79980.12000000","0.00013000"],["79980.10000000","0.00007000"],["79979.99000000","0.00020000"],["79979.60000000","0.00014000"],["79979.59000000","0.06454000"],["79979.05000000","0.00007000"],["79979.04000000","0.00007000"],["79979.03000000","0.00921000"],["79978.93000000","0.00007000"],["79978.73000000","0.00007000"],["79978.42000000","0.00007000"],["79978.29000000","0.00007000"],["79978.28000000","0.00007000"],["79977.99000000","0.00007000"],["79977.76000000","0.00014000"],["79977.75000000","0.01528000"],["79977.42000000","0.00007000"],["79977.39000000","0.00014000"]],"asks":[["79980.15000000","2.34070000"],["79980.16000000","0.50149000"],["79980.17000000","0.00027000"],["79980.18000000","0.11051000"],["79980.33000000","0.00995000"],["79980.53000000","0.01763000"],["79980.97000000","0.00007000"],["79981.01000000","0.00007000"],["79981.05000000","0.00014000"],["79981.06000000","0.00014000"],["79981.15000000","0.00007000"],["79981.29000000","0.00014000"],["79981.52000000","0.01014000"],["79981.61000000","0.01653000"],["79981.62000000","0.02014000"],["79981.77000000","0.00008000"],["79981.81000000","0.00014000"],["79981.82000000","0.04014000"],["79982.78000000","0.00014000"],["79982.79000000","0.05307000"]]}}}
{"rx_ns": 10718553033300, "frame": {"stream":"btcusdt@depth@100ms","data":{"e":"depthUpdate","E":1787647713714,"s":"BTCUSDT","U":99116131228,"u":99116131250,"b":[["79977.38000000","0.04054000"],["79977.20000000","0.17748000"],["79976.90000000","0.08146000"],["79976.70000000","0.42229000"],["79976.47000000","0.01800000"],["79976.00000000","0.02414000"],["79964.90000000","0.00007000"],["79894.12000000","0.03126000"],["71982.13000000","0.00432000"]],"a":[["79996.90000000","0.00007000"]]}}}
{"rx_ns": 10718662496300, "frame": {"stream":"btcusdt@depth20@100ms","data":{"lastUpdateId":99116131258,"bids":[["79980.14000000","0.71410000"],["79980.13000000","0.00083000"],["79980.12000000","0.00013000"],["79980.10000000","0.00007000"],["79979.99000000","0.00020000"],["79979.60000000","0.00014000"],["79979.59000000","0.00014000"],["79979.05000000","0.00007000"],["79979.04000000","0.00007000"],["79979.03000000","0.00921000"],["79978.93000000","0.00007000"],["79978.73000000","0.00007000"],["79978.42000000","0.00007000"],["79978.29000000","0.00007000"],["79978.28000000","0.00007000"],["79977.99000000","0.00007000"],["79977.76000000","0.00014000"],["79977.75000000","0.01528000"],["79977.42000000","0.00007000"],["79977.39000000","0.00014000"]],"asks":[["79980.15000000","2.34070000"],["79980.16000000","0.50149000"],["79980.17000000","0.00027000"],["79980.18000000","0.11051000"],["79980.33000000","0.00995000"],["79980.53000000","0.01763000"],["79980.97000000","0.00007000"],["79981.01000000","0.00007000"],["79981.05000000","0.00014000"],["79981.06000000","0.00014000"],["79981.15000000","0.00007000"],["79981.29000000","0.00014000"],["79981.52000000","0.01014000"],["79981.61000000","0.01653000"],["79981.62000000","0.02014000"],["79981.77000000","0.00008000"],["79981.81000000","0.00014000"],["79981.82000000","0.04014000"],["79982.78000000","0.00014000"],["79982.79000000","0.05307000"]]}}}
{"rx_ns": 10718662626300, "frame": {"stream":"btcusdt@depth@100ms","data":{"e":"depthUpdate","E":1787647713814,"s":"BTCUSDT","U":99116131251,"u":99116131258,"b":[["79980.14000000","0.71410000"],["79979.59000000","0.00014000"],["71982.13000000","0.00432000"],["71982.12000000","0.00000000"],["71982.11000000","0.00008000"]],"a":[["79985.16000000","0.04021000"],["80065.91000000","3.13843000"],["80068.55000000","0.00000000"]]}}}
