{"rx_ns": 58760776000, "frame": {"e":"depthUpdate","E":1787603116214,"s":"BTCUSDT","U":99076652206,"u":99076653097,"b":[["78720.05000000","3.75133000"],["78720.04000000","3.12487000"],["78720.03000000","0.00013000"],["78719.68000000","0.00014000"],["78719.67000000","0.21958000"],["78719.66000000","2.02006000"],["78719.65000000","1.90515000"],["78719.64000000","0.00000000"],["78719.04000000","0.00400000"],["78718.81000000","0.00000000"],["78718.80000000","0.28414000"],["78718.79000000","0.06136000"],["78718.78000000","0.00000000"],["78718.77000000","0.00000000"],["78718.58000000","0.00000000"],["78718.54000000","0.00000000"],["78718.53000000","0.21155000"],["78718.52000000","0.00000000"],["78718.51000000","0.00000000"],["78717.89000000","0.00027000"],["78717.53000000","0.00000000"],["78717.52000000","0.00014000"],["78717.40000000","0.00254000"],["78717.29000000","0.00000000"],["78717.28000000","0.00014000"],["78717.27000000","0.11510000"],["78717.23000000","0.00146000"],["78717.22000000","0.20358000"],["78716.75000000","0.00000000"],["78716.74000000","0.33171000"],["78716.73000000","0.36231000"],["78716.39000000","0.00007000"],["78716.28000000","0.15000000"],["78716.27000000","0.00000000"],["78716.26000000","0.00000000"],["78716.02000000","0.03484000"],["78716.00000000","0.49865000"],["78715.39000000","0.00000000"],["78715.00000000","0.00007000"],["78714.46000000","0.12704000"],["78713.74000000","0.00000000"],["78712.97000000","0.00000000"],["78711.95000000","0.00000000"],["78710.70000000","0.00000000"],["78710.63000000","0.08576000"],["78710.26000000","0.34306000"],["78710.23000000","0.00007000"],["78709.26000000","0.38119000"],["78709.09000000","0.13242000"],["78708.50000000","0.00000000"],["78704.24000000","0.06460000"],["78703.18000000","0.63524000"],["78703.17000000","0.00000000"],["78703.07000000","0.34310000"],["78702.27000000","0.07447000"],["78701.87000000","0.00000000"],["78701.05000000","0.63538000"],["78700.15000000","0.00000000"],["78700.08000000","0.00000000"],["78699.87000000","0.00000000"],["78698.29000000","0.00000000"],["78695.75000000","0.13729000"],["78694.97000000","0.00000000"],["78694.19000000","0.00000000"],["78693.77000000","0.00000000"],["78691.89000000","0.13348000"],["78691.80000000","0.00000000"],["78689.76000000","0.00000000"],["78689.29000000","0.00000000"],["78684.48000000","0.00000000"],["78684.21000000","0.65723000"],["78684.00000000","0.02400000"],["78673.62000000","0.00000000"],["78670.80000000","0.00424000"],["78661.02000000","0.00000000"],["78660.34000000","0.00314000"],["78658.23000000","0.00000000"],["78658.21000000","0.00007000"],["78658.01000000","0.00317000"],["78655.23000000","0.00000000"],["78655.22000000","0.00000000"],["78655.02000000","0.00000000"],["78648.26000000","0.00000000"],["78636.61000000","0.00316000"],["78634.01000000","0.00000000"],["78507.85000000","0.00000000"],["78389.06000000","0.00000000"],["70848.05000000","0.00016000"],["70846.68000000","0.00000000"],["66960.06000000","0.00000000"],["66912.05000000","0.00017000"],["62974.83000000","0.00000000"]],"a":[["78718.54000000","0.00000000"],["78718.55000000","0.00000000"],["78718.59000000","0.00000000"],["78718.79000000","0.00000000"],["78718.80000000","0.00000000"],["78718.81000000","0.00000000"],["78719.65000000","0.00000000"],["78719.66000000","0.00000000"],["78719.67000000","0.00000000"],["78719.68000000","0.00000000"],["78720.05000000","0.00000000"],["78720.06000000","0.42258000"],["78720.07000000","0.00042000"],["78720.48000000","0.00000000"],["78720.79000000","0.00000000"],["78720.80000000","0.00014000"],["78721.12000000","0.00000000"],["78721.13000000","0.00007000"],["78721.20000000","0.00000000"],["78721.21000000","0.00007000"],["78721.31000000","0.00000000"],["78721.32000000","0.00007000"],["78721.40000000","0.00000000"],["78722.52000000","0.00000000"],["78722.57000000","0.00000000"],["78722.58000000","0.00007000"],["78722.65000000","0.00014000"],["78722.66000000","0.05383000"],["78722.79000000","0.00007000"],["78722.96000000","0.00102000"],["78723.22000000","0.00000000"],["78723.54000000","0.00007000"],["78724.43000000","0.00007000"],["78724.44000000","0.00014000"],["78724.61000000","0.00000000"],["78724.80000000","0.00000000"],["78724.83000000","0.00000000"],["78725.11000000","0.00000000"],["78725.71000000","0.00000000"],["78726.03000000","0.00000000"],["78726.23000000","0.00000000"],["78727.13000000","0.00000000"],["78727.41000000","0.00014000"],["78727.43000000","0.00000000"],["78727.52000000","0.00000000"],["78727.53000000","0.00000000"],["78727.54000000","0.00014000"],["78727.55000000","0.21937000"],["78727.68000000","0.00000000"],["78727.69000000","0.00007000"],["78727.93000000","0.00000000"],["78728.06000000","0.00000000"],["78728.26000000","0.00000000"],["78728.29000000","0.00027000"],["78728.32000000","0.00000000"],["78728.61000000","0.00000000"],["78729.04000000","0.00014000"],["78729.05000000","0.20785000"],["78729.73000000","0.00000000"],["78729.87000000","0.00000000"],["78729.88000000","0.00000000"],["78729.89000000","0.00000000"],["78729.99000000","0.00014000"],["78730.00000000","0.02400000"],["78730.51000000","0.00000000"],["78730.52000000","0.00000000"],["78730.58000000","0.00007000"],["78730.59000000","0.12701000"],["78730.62000000","0.00070000"],["78730.72000000","0.00000000"],["78731.13000000","0.00000000"],["78731.27000000","0.00254000"],["78731.45000000","0.15000000"],["78731.98000000","0.00000000"],["78731.99000000","0.00254000"],["78732.14000000","0.00000000"],["78732.22000000","0.00000000"],["78732.24000000","0.00189000"],["78732.32000000","0.00000000"],["78732.52000000","0.00000000"],["78732.69000000","0.00000000"],["78733.02000000","0.00000000"],["78733.03000000","0.00000000"],["78733.13000000","0.00254000"],["78733.29000000","0.00000000"],["78733.47000000","0.00000000"],["78733.48000000","0.00000000"],["78733.57000000","0.00000000"],["78733.58000000","0.00000000"],["78733.63000000","0.00000000"],["78733.82000000","0.00000000"],["78733.89000000","0.00000000"],["78733.99000000","0.31762000"],["78734.15000000","0.00000000"],["78734.43000000","0.00000000"],["78734.46000000","0.00000000"],["78734.63000000","0.00000000"],["78734.83000000","0.00000000"],["78734.96000000","0.27579000"],["78735.02000000","0.00000000"],["78735.07000000","0.00000000"],["78735.12000000","0.00000000"],["78735.14000000","0.00000000"],["78735.45000000","0.00000000"],["78735.49000000","0.00000000"],["78735.52000000","0.00137000"],["78735.53000000","0.00000000"],["78735.54000000","0.00000000"],["78735.55000000","0.00000000"],["78735.59000000","0.02161000"],["78735.77000000","0.00635000"],["78736.18000000","0.00000000"],["78736.50000000","0.00000000"],["78736.65000000","0.27579000"],["78737.66000000","0.04857000"],["78737.81000000","0.00635000"],["78738.46000000","0.12700000"],["78738.68000000","0.00000000"],["78738.79000000","0.02286000"],["78739.11000000","0.00254000"],["78739.19000000","0.00400000"],["78739.49000000","0.00400000"],["78739.93000000","0.00000000"],["78739.97000000","0.02161000"],["78739.98000000","0.00000000"],["78739.99000000","0.00000000"],["78740.01000000","0.00000000"],["78740.44000000","1.21952000"],["78740.99000000","0.00000000"],["78741.41000000","0.00000000"],["78741.77000000","0.02000000"],["78743.81000000","0.00000000"],["78745.24000000","0.00192000"],["78745.35000000","0.00227000"],["78745.36000000","3.14628000"],["78745.37000000","0.00000000"],["78745.95000000","0.00000000"],["78746.54000000","0.36224000"],["78746.55000000","0.00000000"],["78746.56000000","0.00000000"],["78746.89000000","0.00000000"],["78747.81000000","0.00000000"],["78749.99000000","1.21952000"],["78750.03000000","0.00031000"],["78750.59000000","0.00000000"],["78750.86000000","1.92676000"],["78751.13000000","0.00000000"],["78751.14000000","0.00000000"],["78751.74000000","0.00000000"],["78753.74000000","0.00000000"],["78754.02000000","0.00000000"],["78755.31000000","0.00000000"],["78755.40000000","0.34287000"],["78755.69000000","1.58176000"],["78755.70000000","0.00000000"],["78756.62000000","1.92676000"],["78756.63000000","0.00000000"],["78758.00000000","0.02400000"],["78758.37000000","0.00014000"],["78758.78000000","0.00000000"],["78758.96000000","0.02732000"],["78759.39000000","0.00000000"],["78759.46000000","0.00000000"],["78760.00000000","0.12923000"],["78761.15000000","0.34284000"],["78761.29000000","0.00000000"],["78761.89000000","0.02161000"],["78762.24000000","0.00007000"],["78763.03000000","0.00000000"],["78764.32000000","1.21952000"],["78765.05000000","0.00000000"],["78765.62000000","1.90515000"],["78766.48000000","0.02161000"],["78766.49000000","0.00000000"],["78766.94000000","0.00000000"],["78767.31000000","0.04640000"],["78767.96000000","0.00000000"],["78768.18000000","0.00000000"],["78768.99000000","0.00424000"],["78769.48000000","0.00316000"],["78770.07000000","0.00622000"],["78771.40000000","1.24113000"],["78772.13000000","0.00000000"],["78772.14000000","0.00000000"],["78773.17000000","1.90515000"],["78773.58000000","0.00436000"],["78776.08000000","0.02161000"],["78777.99000000","0.00000000"],["78780.66000000","1.90515000"],["78780.68000000","0.00000000"],["78781.88000000","0.00190000"],["78781.90000000","0.00007000"],["78785.02000000","0.00000000"],["78787.11000000","0.02161000"],["78790.14000000","0.00316000"],["78791.27000000","0.02000000"],["78793.22000000","0.00000000"],["78793.44000000","1.25659000"],["78798.14000000","0.00000000"],["78810.35000000","1.90515000"],["78811.55000000","0.00000000"],["78812.84000000","0.00000000"],["78820.33000000","0.00000000"],["78820.60000000","0.00000000"],["78830.31000000","0.00000000"],["78830.59000000","0.00000000"],["78840.29000000","0.00000000"],["78840.83000000","0.00000000"],["78845.90000000","0.00000000"],["78847.99000000","0.00127000"],["78850.27000000","0.00000000"],["78851.07000000","0.00000000"],["78856.56000000","0.00000000"],["78861.99000000","0.00076000"],["78914.54000000","3.80201000"],["78974.95000000","0.00000000"]]}}
{"rx_ns": 58854327900, "frame": {"e":"depthUpdate","E":1787603116314,"s":"BTCUSDT","U":99076653098,"u":99076653372,"b":[["78720.74000000","4.33520000"],["78720.73000000","0.00020000"],["78720.72000000","0.00013000"],["78720.07000000","0.00014000"],["78720.06000000","1.24973000"],["78720.05000000","2.30731000"],["78720.04000000","1.21959000"],["78720.03000000","0.00000000"],["78719.68000000","0.00000000"],["78719.67000000","0.21951000"],["78719.66000000","0.11477000"],["78719.65000000","0.00007000"],["78719.47000000","0.01914000"],["78718.80000000","0.07514000"],["78718.53000000","0.18738000"],["78718.21000000","0.03190000"],["78717.89000000","0.00000000"],["78717.52000000","0.00007000"],["78717.28000000","0.00007000"],["78717.27000000","0.11503000"],["78717.26000000","0.03576000"],["78716.95000000","0.03829000"],["78716.00000000","0.46260000"],["78715.69000000","0.03829000"],["78715.51000000","0.02286000"],["78709.09000000","0.00000000"],["78705.81000000","0.13242000"],["78699.45000000","0.00000000"],["78698.99000000","0.00406000"],["78695.18000000","0.00000000"],["78691.89000000","0.00000000"],["78680.97000000","0.00000000"],["78680.00000000","0.12972000"],["78679.00000000","0.00000000"],["78672.25000000","0.00624000"],["78659.64000000","0.00406000"],["78657.81000000","0.86826000"],["78655.83000000","0.00000000"],["78628.16000000","0.00406000"],["78624.35000000","0.00000000"],["78583.66000000","0.01990000"],["78580.94000000","0.00406000"],["78577.13000000","0.00000000"],["78573.84000000","0.00000000"],["78540.43000000","4.41481000"],["78506.31000000","0.00000000"],["78399.03000000","0.00026000"],["70848.67000000","0.00016000"],["70848.05000000","0.00000000"],["62976.00000000","0.00000000"],["62974.00000000","0.00000000"]],"a":[["78720.06000000","0.00000000"],["78720.07000000","0.00000000"],["78720.66000000","0.00000000"],["78720.74000000","0.00000000"],["78720.75000000","0.02017000"],["78720.76000000","0.00035000"],["78720.80000000","0.00000000"],["78721.13000000","0.00000000"],["78721.21000000","0.00000000"],["78721.32000000","0.00000000"],["78722.00000000","0.00014000"],["78722.01000000","0.03160000"],["78722.45000000","0.00102000"],["78722.58000000","0.00000000"],["78722.65000000","0.00000000"],["78722.66000000","0.00014000"],["78722.79000000","0.00000000"],["78723.02000000","0.00007000"],["78723.26000000","0.00014000"],["78723.27000000","0.03792000"],["78723.34000000","0.00014000"],["78723.35000000","0.05383000"],["78723.39000000","0.00014000"],["78723.40000000","0.20798000"],["78724.43000000","0.00000000"],["78724.44000000","0.00000000"],["78724.52000000","0.00007000"],["78724.53000000","0.03792000"],["78724.56000000","0.00000000"],["78726.42000000","0.00000000"],["78727.54000000","0.00007000"],["78727.55000000","0.21944000"],["78729.04000000","0.02161000"],["78729.05000000","0.20799000"],["78729.99000000","0.00000000"],["78730.00000000","0.02407000"],["78730.58000000","0.00000000"],["78730.59000000","0.12715000"],["78732.28000000","0.02161000"],["78734.29000000","0.00000000"],["78738.61000000","0.02000000"],["78742.16000000","0.00000000"],["78742.23000000","0.02600000"],["78746.84000000","0.00000000"],["78747.48000000","0.00000000"],["78748.06000000","0.09489000"],["78748.70000000","0.00406000"],["78750.03000000","0.00000000"],["78751.00000000","0.00000000"],["78751.88000000","0.00000000"],["78752.76000000","0.02515000"],["78758.96000000","0.00000000"],["78760.00000000","0.11923000"],["78761.00000000","0.01000000"],["78763.04000000","1.21979000"],["78765.17000000","0.00000000"],["78776.08000000","0.00000000"],["78777.75000000","0.86694000"],["78786.12000000","0.00000000"],["78786.90000000","0.02600000"],["78787.11000000","0.00000000"],["78792.86000000","0.02000000"],["78817.62000000","0.00000000"],["78819.58000000","0.00406000"],["78864.87000000","0.00000000"],["78866.83000000","0.00406000"],["78935.83000000","0.00000000"],["78937.70000000","0.00406000"],["78984.99000000","0.00029000"]]}}
{"rx_ns": 58952521600, "frame": {"e":"depthUpdate","E":1787603116414,"s":"BTCUSDT","U":99076653373,"u":99076653474,"b":[["78720.74000000","4.59353000"],["78720.06000000","0.99100000"],["78720.05000000","2.03851000"],["78719.66000000","0.11463000"],["78719.65000000","0.00000000"],["78718.53000000","0.17197000"],["78717.40000000","0.00000000"],["78681.00000000","0.01000000"],["78680.00000000","0.11972000"],["78327.13000000","0.01000000"],["77935.50000000","0.01000000"],["77545.82000000","0.01000000"],["77158.09000000","0.01000000"],["76772.30000000","0.01000000"],["76388.44000000","0.01000000"],["76006.49000000","0.01000000"],["75626.46000000","0.01000000"],["75248.33000000","0.01000000"],["74872.09000000","0.01000000"],["74497.73000000","0.01000000"],["74125.24000000","0.01000000"],["73754.61000000","0.01000000"],["73385.84000000","0.01000000"],["73018.91000000","0.01000000"],["62976.59000000","0.00000000"]],"a":[["78720.75000000","0.02045000"],["78720.76000000","0.00070000"],["78722.01000000","0.03167000"],["78722.66000000","0.00007000"],["78723.27000000","0.03799000"],["78723.35000000","0.05390000"],["78723.40000000","0.20812000"],["78724.53000000","0.03799000"],["78725.69000000","0.20720000"],["78727.55000000","0.21944000"],["78727.94000000","0.00024000"],["78729.04000000","0.02168000"],["78730.00000000","0.02400000"],["78730.59000000","0.12708000"],["78733.13000000","0.00000000"],["78735.81000000","0.00024000"],["78738.68000000","0.00400000"],["78739.49000000","0.00000000"],["78743.68000000","0.00024000"],["78751.55000000","0.00024000"],["78775.02000000","0.00436000"],["78786.90000000","0.00000000"],["79114.36000000","0.01000000"],["79509.93000000","0.01000000"],["79907.48000000","0.01000000"],["80307.02000000","0.01000000"],["80708.55000000","0.01000000"],["81112.10000000","0.01000000"],["81517.66000000","0.01000000"],["81925.24000000","0.01000000"],["82334.87000000","0.01000000"],["82746.54000000","0.01000000"],["83160.28000000","0.01000000"],["83576.08000000","0.01000000"],["83993.96000000","0.01000000"],["84413.93000000","0.01000000"],["84836.00000000","0.01000000"]]}}
{"rx_ns": 59052403200, "frame": {"e":"depthUpdate","E":1787603116514,"s":"BTCUSDT","U":99076653475,"u":99076653504,"b":[["78720.74000000","4.59519000"],["78720.06000000","0.39282000"],["78720.05000000","2.03585000"],["78719.67000000","0.00021000"],["78716.96000000","0.00254000"],["78716.03000000","0.00000000"],["78539.06000000","0.00000000"],["78534.01000000","0.00778000"],["70848.67000000","0.00048000"],["62976.60000000","0.00031000"]],"a":[["78720.75000000","0.02031000"],["78720.76000000","0.00063000"],["78724.53000000","0.03799000"],["78725.69000000","0.20727000"],["78727.20000000","0.00000000"],["78729.05000000","0.20792000"],["78731.76000000","0.00000000"],["78732.70000000","0.00254000"],["78751.09000000","0.00000000"],["78759.07000000","0.00000000"],["78759.22000000","0.02757000"],["78766.56000000","0.00400000"],["78788.08000000","0.00406000"]]}}
{"rx_ns": 59152364200, "frame": {"e":"depthUpdate","E":1787603116614,"s":"BTCUSDT","U":99076653505,"u":99076653517,"b":[["78720.04000000","1.21959000"],["78719.67000000","0.00014000"],["78719.66000000","0.11470000"],["70848.67000000","0.00064000"],["62976.60000000","0.00000000"]],"a":[["78720.75000000","0.02031000"],["78720.76000000","0.00063000"],["78723.40000000","0.20819000"],["78724.87000000","0.22271000"],["78725.69000000","0.00007000"]]}}
{"rx_ns": 59252751900, "frame": {"e":"depthUpdate","E":1787603116714,"s":"BTCUSDT","U":99076653518,"u":99076653543,"b":[["78720.74000000","4.80324000"],["78716.96000000","0.00000000"],["78715.30000000","0.00254000"],["78698.99000000","0.00000000"],["78628.16000000","0.00000000"],["78580.94000000","0.00000000"],["78510.11000000","0.00406000"],["76934.14000000","0.00900000"],["70848.67000000","0.00096000"]],"a":[["78720.75000000","0.02024000"],["78720.76000000","0.00056000"],["78723.39000000","0.00000000"],["78723.40000000","0.00014000"],["78724.52000000","0.00014000"],["78724.53000000","0.03799000"],["78724.86000000","0.00007000"],["78724.87000000","0.22278000"],["78725.69000000","0.00000000"],["78731.03000000","0.00254000"],["78731.27000000","0.00000000"],["78732.23000000","0.00254000"],["78732.70000000","0.00000000"]]}}
{"rx_ns": 59357056400, "frame": {"e":"depthUpdate","E":1787603116815,"s":"BTCUSDT","U":99076653544,"u":99076653580,"b":[["78720.06000000","0.07521000"],["78717.52000000","0.00000000"],["78716.00000000","0.46260000"],["78709.26000000","0.00000000"],["78678.97000000","0.00000000"]],"a":[["78720.75000000","0.02052000"],["78721.45000000","0.00007000"],["78723.02000000","0.00000000"],["78723.35000000","0.05390000"],["78723.40000000","0.00007000"],["78724.59000000","0.00007000"],["78724.87000000","0.54037000"],["78727.94000000","0.00000000"],["78728.63000000","0.00024000"],["78729.05000000","0.20799000"],["78733.99000000","0.00000000"],["78734.95000000","0.31760000"],["78735.81000000","0.00000000"],["78736.50000000","0.00024000"],["78737.81000000","0.02635000"],["78738.59000000","0.02000000"],["78738.62000000","0.02000000"],["78742.54000000","0.38103000"],["78743.68000000","0.00000000"],["78744.37000000","0.00024000"],["78751.55000000","0.00000000"],["78752.24000000","0.00024000"],["78788.39000000","0.02000000"],["78789.25000000","0.02000000"],["78789.33000000","0.02000000"],["78789.93000000","0.00010000"],["78791.88000000","0.00316000"],["78848.62000000","0.00047000"],["78860.64000000","0.01989000"],["78867.99000000","0.00000000"],["78870.14000000","0.00127000"]]}}
{"rx_ns": 59454479300, "frame": {"e":"depthUpdate","E":1787603116915,"s":"BTCUSDT","U":99076653581,"u":99076653627,"b":[["78720.74000000","4.80375000"],["78716.00000000","0.46260000"],["78629.54000000","0.00406000"],["78327.13000000","0.00000000"],["77935.50000000","0.00000000"],["77545.82000000","0.00000000"],["77158.09000000","0.00000000"],["76772.30000000","0.00000000"],["76388.44000000","0.00000000"],["76006.49000000","0.00000000"],["75626.46000000","0.00000000"],["75248.33000000","0.00000000"],["74872.09000000","0.00000000"],["74497.73000000","0.00000000"],["74125.24000000","0.00000000"],["73754.61000000","0.00000000"],["73385.84000000","0.00000000"],["73018.91000000","0.00000000"],["70848.67000000","0.00128000"]],"a":[["78737.76000000","0.02000000"],["78740.89000000","0.02000000"],["78742.46000000","0.02000000"],["78747.18000000","0.00000000"],["78747.28000000","0.00000000"],["78748.01000000","0.00000000"],["78748.07000000","0.00000000"],["78792.10000000","0.02000000"],["78795.26000000","0.02000000"],["78796.83000000","0.02000000"],["79114.36000000","0.00000000"],["79509.93000000","0.00000000"],["79907.48000000","0.00000000"],["80307.02000000","0.00000000"],["80708.55000000","0.00000000"],["81112.10000000","0.00000000"],["81517.66000000","0.00000000"],["81925.24000000","0.00000000"],["82334.87000000","0.00000000"],["82746.54000000","0.00000000"],["83160.28000000","0.00000000"],["83576.08000000","0.00000000"],["83993.96000000","0.00000000"],["84413.93000000","0.00000000"],["84836.00000000","0.00000000"]]}}
{"rx_ns": 59552948100, "frame": {"e":"depthUpdate","E":1787603117014,"s":"BTCUSDT","U":99076653628,"u":99076653654,"b":[["78704.25000000","0.63520000"],["78703.18000000","0.00000000"],["78700.33000000","0.00635000"],["78697.08000000","0.00007000"],["78694.87000000","0.00000000"],["78693.78000000","0.00000000"],["70848.67000000","0.00144000"],["70848.00000000","0.00000000"],["62976.60000000","0.00031000"]],"a":[["78720.75000000","0.02066000"],["78727.55000000","0.21951000"],["78728.08000000","0.01270000"],["78728.12000000","0.06350000"],["78734.39000000","0.31760000"],["78734.95000000","0.00000000"],["78738.53000000","0.02000000"],["78742.11000000","0.00000000"],["78742.54000000","0.40103000"],["78742.55000000","0.02000000"],["78744.32000000","0.00007000"],["78750.33000000","0.00000000"],["78751.89000000","0.00000000"],["78751.97000000","0.00000000"],["78789.28000000","0.00000000"],["78792.09000000","0.00000000"],["78796.87000000","0.00000000"]]}}
{"rx_ns": 59657897400, "frame": {"e":"depthUpdate","E":1787603117115,"s":"BTCUSDT","U":99076653655,"u":99076653673,"b":[["78720.74000000","4.82891000"],["78714.41000000","0.00000000"],["78700.38000000","0.00406000"],["78010.06000000","0.00000000"],["70848.67000000","0.00160000"]],"a":[["78727.55000000","0.21951000"],["78728.08000000","0.01277000"],["78728.12000000","0.06357000"],["78729.04000000","0.02161000"],["78729.05000000","0.20792000"],["78741.65000000","0.02000000"],["78742.44000000","0.02600000"],["78751.87000000","0.00000000"],["78752.69000000","0.00000000"],["78791.26000000","0.02000000"],["78796.83000000","0.04600000"],["78816.14000000","0.00000000"],["78818.35000000","0.00025000"]]}}
{"rx_ns": 59753085300, "frame": {"e":"depthUpdate","E":1787603117214,"s":"BTCUSDT","U":99076653674,"u":99076653697,"b":[["78720.74000000","4.82993000"],["78718.00000000","0.02500000"],["78716.09000000","0.00254000"],["78716.00000000","0.43760000"],["78715.30000000","0.00000000"],["70848.67000000","0.00160000"],["62976.60000000","0.00000000"]],"a":[["78720.75000000","0.02080000"],["78720.76000000","0.00063000"],["78721.42000000","0.00014000"],["78721.43000000","0.20798000"],["78722.96000000","0.00000000"],["78724.86000000","0.00000000"],["78727.54000000","0.00000000"],["78731.03000000","0.00000000"],["78731.83000000","0.00254000"],["78745.83000000","0.12706000"],["78749.89000000","0.00000000"],["78752.64000000","0.00000000"],["78796.83000000","0.02000000"]]}}
{"rx_ns": 59852605700, "frame": {"e":"depthUpdate","E":1787603117314,"s":"BTCUSDT","U":99076653698,"u":99076653740,"b":[["78720.74000000","4.59330000"],["78720.05000000","2.03271000"],["78718.22000000","0.00635000"],["78716.48000000","0.02000000"],["78716.02000000","0.03498000"],["78704.25000000","0.00000000"],["78703.59000000","0.63520000"],["78700.38000000","0.00000000"],["78689.43000000","0.09320000"],["78601.21000000","0.04473000"],["78590.22000000","0.00000000"],["78582.32000000","0.00406000"],["70848.67000000","0.00176000"],["62977.00000000","0.00030000"]],"a":[["78720.75000000","0.05860000"],["78721.43000000","0.20812000"],["78722.55000000","0.00102000"],["78722.79000000","0.00014000"],["78722.80000000","0.20226000"],["78724.52000000","0.00000000"],["78724.86000000","0.02161000"],["78724.87000000","0.31766000"],["78728.12000000","0.06350000"],["78731.27000000","0.00254000"],["78732.23000000","0.00000000"],["78740.92000000","0.34293000"],["78761.15000000","0.00000000"],["78771.40000000","1.21952000"],["78786.90000000","0.02600000"],["78828.62000000","0.00011000"],["78837.38000000","0.02789000"]]}}
{"rx_ns": 59952192400, "frame": {"e":"depthUpdate","E":1787603117414,"s":"BTCUSDT","U":99076653741,"u":99076653827,"b":[["78720.74000000","4.61330000"],["78720.07000000","0.00000000"],["78720.06000000","0.00021000"],["78719.66000000","0.03970000"],["78718.80000000","0.00014000"],["78716.75000000","0.00014000"],["78716.48000000","0.00000000"],["78716.09000000","0.00000000"],["78715.05000000","0.00254000"],["78710.26000000","0.00000000"],["78705.81000000","0.00000000"],["78703.59000000","0.00000000"],["78702.28000000","0.76764000"],["78690.74000000","0.34315000"],["78327.13000000","0.01000000"],["77935.50000000","0.01000000"],["77545.82000000","0.01000000"],["77158.09000000","0.01000000"],["76772.30000000","0.01000000"],["76388.44000000","0.01000000"],["76006.49000000","0.01000000"],["75626.46000000","0.01000000"],["75248.33000000","0.01000000"],["74872.09000000","0.01000000"],["74497.73000000","0.01000000"],["74125.24000000","0.01000000"],["73754.61000000","0.01000000"],["73385.84000000","0.01000000"],["73018.91000000","0.01000000"],["62976.59000000","0.00000000"]],"a":[["78720.75000000","0.65847000"],["78720.76000000","0.00077000"],["78720.82000000","0.00014000"],["78720.83000000","0.21890000"],["78721.45000000","0.00000000"],["78722.01000000","0.03167000"],["78722.23000000","0.00007000"],["78722.79000000","0.00000000"],["78722.80000000","0.00007000"],["78724.53000000","0.03799000"],["78724.86000000","0.02168000"],["78727.55000000","0.21944000"],["78728.08000000","0.01270000"],["78730.59000000","0.12701000"],["78730.78000000","0.00254000"],["78730.97000000","0.00254000"],["78731.83000000","0.00000000"],["78731.99000000","0.00000000"],["78740.43000000","0.00227000"],["78745.35000000","0.00000000"],["78757.00000000","0.70000000"],["78765.25000000","0.00400000"],["78766.56000000","0.00000000"],["78841.95000000","0.00000000"],["79114.36000000","0.01000000"],["79509.93000000","0.01000000"],["79907.48000000","0.01000000"],["80307.02000000","0.01000000"],["80708.55000000","0.01000000"],["81112.10000000","0.01000000"],["81517.66000000","0.01000000"],["81925.24000000","0.01000000"],["82334.87000000","0.01000000"],["82746.54000000","0.01000000"],["83160.28000000","0.01000000"],["83576.08000000","0.01000000"],["83993.96000000","0.01000000"],["84413.93000000","0.01000000"],["84836.00000000","0.01000000"]]}}
{"rx_ns": 60053798200, "frame": {"e":"depthUpdate","E":1787603117514,"s":"BTCUSDT","U":99076653828,"u":99076653854,"b":[["78720.74000000","4.61330000"],["78720.06000000","0.00014000"],["78719.47000000","0.01921000"],["78718.80000000","0.00007000"],["78718.53000000","0.17204000"],["78700.39000000","0.00406000"],["78601.21000000","0.00000000"],["70848.67000000","0.00192000"],["62976.60000000","0.00031000"]],"a":[["78720.75000000","0.65847000"],["78720.83000000","0.21897000"],["78721.43000000","0.20805000"],["78722.01000000","0.03167000"],["78722.45000000","0.00000000"],["78722.55000000","0.00000000"],["78722.80000000","0.00000000"],["78723.54000000","0.00014000"],["78730.00000000","0.02654000"],["78731.27000000","0.00000000"],["78762.24000000","0.00000000"],["78837.38000000","0.00000000"]]}}
{"rx_ns": 60153500800, "frame": {"e":"depthUpdate","E":1787603117614,"s":"BTCUSDT","U":99076653855,"u":99076653870,"b":[["78720.74000000","4.61323000"],["78718.22000000","0.00642000"],["78700.39000000","0.00000000"],["78591.57000000","0.04092000"],["78540.44000000","0.00778000"],["78534.01000000","0.00000000"],["70848.67000000","0.00192000"],["62976.60000000","0.00000000"]],"a":[["78720.75000000","0.65861000"],["78720.76000000","0.00090000"],["78720.77000000","0.00013000"],["78732.28000000","0.33922000"],["78734.39000000","0.00000000"],["78827.71000000","0.02789000"],["78881.37000000","0.00000000"]]}}
{"rx_ns": 60252359300, "frame": {"e":"depthUpdate","E":1787603117714,"s":"BTCUSDT","U":99076653871,"u":99076653878,"b":[["78715.05000000","0.00000000"],["78713.43000000","0.00254000"],["78700.13000000","0.00406000"],["70848.67000000","0.00192000"]],"a":[["78729.16000000","0.00254000"],["78730.78000000","0.00000000"],["78820.49000000","0.00529000"]]}}
{"rx_ns": 60351995600, "frame": {"e":"depthUpdate","E":1787603117814,"s":"BTCUSDT","U":99076653879,"u":99076653879,"b":[["70848.67000000","0.00208000"]],"a":[]}}
{"rx_ns": 60453828500, "frame": {"e":"depthUpdate","E":1787603117914,"s":"BTCUSDT","U":99076653880,"u":99076653911,"b":[["78327.13000000","0.00000000"],["77935.50000000","0.00000000"],["77545.82000000","0.00000000"],["77158.09000000","0.00000000"],["76772.30000000","0.00000000"],["76388.44000000","0.00000000"],["76006.49000000","0.00000000"],["75626.46000000","0.00000000"],["75248.33000000","0.00000000"],["74872.09000000","0.00000000"],["74497.73000000","0.00000000"],["74125.24000000","0.00000000"],["73754.61000000","0.00000000"],["73385.84000000","0.00000000"],["73018.91000000","0.00000000"],["70848.67000000","0.00208000"]],"a":[["79114.36000000","0.00000000"],["79509.93000000","0.00000000"],["79907.48000000","0.00000000"],["80307.02000000","0.00000000"],["80708.55000000","0.00000000"],["81112.10000000","0.00000000"],["81517.66000000","0.00000000"],["81925.24000000","0.00000000"],["82334.87000000","0.00000000"],["82746.54000000","0.00000000"],["83160.28000000","0.00000000"],["83576.08000000","0.00000000"],["83993.96000000","0.00000000"],["84413.93000000","0.00000000"],["84836.00000000","0.00000000"]]}}
{"rx_ns": 60552141100, "frame": {"e":"depthUpdate","E":1787603118014,"s":"BTCUSDT","U":99076653912,"u":99076653928,"b":[["78697.08000000","0.00007000"],["72419.85000000","0.00014000"],["70848.67000000","0.00208000"],["62976.60000000","0.00031000"]],"a":[["78720.75000000","0.62601000"],["78729.99000000","0.00254000"],["78730.97000000","0.00000000"],["78732.27000000","0.31761000"],["78732.28000000","0.02161000"],["78733.99000000","0.00000000"],["78744.32000000","0.00007000"],["78755.00000000","0.70000000"],["78789.28000000","0.02000000"],["78792.09000000","0.02000000"],["78796.87000000","0.02000000"],["78816.77000000","0.93647000"]]}}
{"rx_ns": 60660689000, "frame": {"e":"depthUpdate","E":1787603118114,"s":"BTCUSDT","U":99076653929,"u":99076654160,"b":[["78720.74000000","1.00501000"],["78720.73000000","0.00048000"],["78720.05000000","0.12346000"],["78720.04000000","0.00007000"],["78719.67000000","0.00007000"],["78719.04000000","0.00000000"],["78718.53000000","0.08470000"],["78718.22000000","0.00007000"],["78718.21000000","0.03197000"],["78717.26000000","0.05576000"],["78716.73000000","0.00007000"],["78716.28000000","0.00000000"],["78716.01000000","0.00000000"],["78715.80000000","0.00007000"],["78714.94000000","0.00000000"],["78714.52000000","0.00000000"],["78713.64000000","0.00000000"],["78713.43000000","0.00000000"],["78711.93000000","0.00007000"],["78711.37000000","0.00000000"],["78710.38000000","0.15000000"],["78710.31000000","0.00166000"],["78709.97000000","0.00000000"],["78709.85000000","1.21952000"],["78709.43000000","0.00000000"],["78709.08000000","0.00000000"],["78708.80000000","0.36224000"],["78708.78000000","0.00000000"],["78706.30000000","0.00000000"],["78705.79000000","1.21952000"],["78705.30000000","0.00000000"],["78704.55000000","1.90915000"],["78704.18000000","0.00254000"],["78703.83000000","0.00000000"],["78703.58000000","0.00000000"],["78703.57000000","0.00000000"],["78703.07000000","0.00000000"],["78702.28000000","0.00000000"],["78701.54000000","1.21952000"],["78701.05000000","0.00000000"],["78700.33000000","0.00000000"],["78699.64000000","1.90515000"],["78699.63000000","0.00000000"],["78699.37000000","0.04443000"],["78698.28000000","0.00000000"],["78698.10000000","0.00000000"],["78697.30000000","1.21952000"],["78695.76000000","0.00000000"],["78695.73000000","0.00000000"],["78695.35000000","0.00000000"],["78695.34000000","0.00000000"],["78694.54000000","1.90515000"],["78694.17000000","0.13244000"],["78694.01000000","0.63522000"],["78692.01000000","1.21952000"],["78691.56000000","0.00635000"],["78691.55000000","0.00000000"],["78690.04000000","0.00000000"],["78689.43000000","0.00000000"],["78688.25000000","0.00000000"],["78688.10000000","0.34316000"],["78687.06000000","1.21952000"],["78686.51000000","0.09505000"],["78685.11000000","1.90515000"],["78685.10000000","0.00000000"],["78685.09000000","0.00000000"],["78682.37000000","0.34319000"],["78680.97000000","0.00007000"],["78679.69000000","0.00000000"],["78679.25000000","0.00400000"],["78677.10000000","0.00007000"],["78675.66000000","1.90515000"],["78673.47000000","0.00000000"],["78673.23000000","0.00007000"],["78660.34000000","0.00000000"],["78655.22000000","0.00320000"],["78639.89000000","1.21952000"],["78629.65000000","1.21952000"],["78619.41000000","1.25176000"],["78618.43000000","0.00000000"],["78609.18000000","1.90715000"],["78599.73000000","1.90515000"],["78590.28000000","1.90515000"],["78411.12000000","7.65293000"],["78012.25000000","0.00010000"],["70848.67000000","0.00233000"],["70848.00000000","0.00000000"]],"a":[["78720.75000000","1.78745000"],["78720.76000000","0.00069000"],["78720.82000000","0.02161000"],["78720.83000000","0.00007000"],["78721.03000000","0.00000000"],["78723.25000000","0.00254000"],["78724.52000000","0.00007000"],["78724.85000000","0.31761000"],["78725.16000000","0.00000000"],["78725.19000000","0.00254000"],["78726.55000000","0.00400000"],["78726.61000000","0.00137000"],["78727.54000000","0.00000000"],["78727.55000000","0.00014000"],["78728.08000000","0.00000000"],["78728.12000000","0.00000000"],["78728.62000000","0.00635000"],["78728.63000000","0.21954000"],["78729.16000000","0.00000000"],["78729.52000000","0.02000000"],["78729.99000000","0.00000000"],["78730.00000000","0.02400000"],["78730.23000000","0.18496000"],["78730.58000000","0.00000000"],["78730.85000000","0.00400000"],["78731.88000000","0.00150000"],["78732.27000000","0.00000000"],["78733.52000000","0.00635000"],["78733.99000000","0.00000000"],["78734.55000000","0.34296000"],["78734.83000000","0.00227000"],["78734.95000000","1.90515000"],["78735.35000000","0.38107000"],["78735.52000000","0.00000000"],["78735.77000000","0.00000000"],["78736.18000000","0.00200000"],["78736.65000000","0.00000000"],["78737.81000000","0.02000000"],["78737.82000000","0.00000000"],["78737.99000000","0.36224000"],["78740.43000000","0.00000000"],["78740.55000000","0.00000000"],["78741.82000000","0.34293000"],["78743.75000000","0.00400000"],["78744.61000000","0.43582000"],["78745.24000000","0.00000000"],["78748.05000000","0.00000000"],["78754.54000000","0.00000000"],["78755.40000000","0.00000000"],["78755.99000000","0.00000000"],["78759.42000000","0.02509000"],["78760.64000000","0.00000000"],["78762.19000000","0.00000000"],["78765.25000000","0.00000000"],["78766.48000000","0.00000000"],["78796.83000000","0.04600000"],["78800.63000000","1.90515000"],["78800.64000000","0.00000000"],["78810.34000000","1.21952000"],["78810.35000000","0.00000000"],["78810.36000000","0.00000000"],["79035.45000000","0.00000000"]]}}
{"rx_ns": 60758367800, "frame": {"e":"depthUpdate","E":1787603118214,"s":"BTCUSDT","U":99076654161,"u":99076654387,"b":[["78720.74000000","3.29322000"],["78720.73000000","0.00041000"],["78720.05000000","0.08290000"],["78720.04000000","0.00000000"],["78719.68000000","0.02516000"],["78719.67000000","0.00021000"],["78719.48000000","0.00014000"],["78718.80000000","0.00021000"],["78718.54000000","0.00007000"],["78718.53000000","0.08470000"],["78718.25000000","0.00204000"],["78718.22000000","0.00000000"],["78718.00000000","0.02507000"],["78717.28000000","0.36231000"],["78717.27000000","0.11510000"],["78717.26000000","0.03576000"],["78717.22000000","0.20365000"],["78716.84000000","0.31763000"],["78716.75000000","0.00000000"],["78716.74000000","0.33164000"],["78716.73000000","0.00000000"],["78716.02000000","0.03477000"],["78716.00000000","0.43760000"],["78715.88000000","0.00000000"],["78715.80000000","0.00014000"],["78714.90000000","0.00000000"],["78714.67000000","1.90515000"],["78714.46000000","0.14704000"],["78713.85000000","1.21952000"],["78711.93000000","0.00014000"],["78710.65000000","0.00635000"],["78710.63000000","0.00000000"],["78710.50000000","0.00000000"],["78709.86000000","1.90515000"],["78709.73000000","0.08576000"],["78709.41000000","0.00635000"],["78709.31000000","0.00400000"],["78709.22000000","0.00000000"],["78709.16000000","0.00000000"],["78709.15000000","0.00000000"],["78709.05000000","0.02627000"],["78708.98000000","0.00000000"],["78708.74000000","0.00254000"],["78707.26000000","0.00000000"],["78705.80000000","0.01207000"],["78704.95000000","0.00000000"],["78704.56000000","0.00407000"],["78704.18000000","0.00400000"],["78701.40000000","1.21978000"],["78698.83000000","0.38124000"],["78682.09000000","0.00000000"],["78677.73000000","0.02450000"],["78677.10000000","0.00000000"],["78673.23000000","0.00000000"],["78670.62000000","1.90515000"],["70848.67000000","0.00249000"],["62976.60000000","0.00000000"]],"a":[["78720.75000000","1.38492000"],["78720.76000000","0.00076000"],["78720.81000000","0.00007000"],["78720.82000000","0.02168000"],["78720.83000000","0.00000000"],["78721.99000000","0.00000000"],["78722.99000000","0.00000000"],["78723.24000000","0.00000000"],["78723.25000000","0.00000000"],["78723.35000000","0.05404000"],["78724.08000000","0.04019000"],["78724.47000000","0.00254000"],["78724.52000000","0.00000000"],["78724.53000000","0.03799000"],["78724.85000000","0.00007000"],["78724.87000000","0.00007000"],["78725.19000000","0.00000000"],["78726.53000000","0.00508000"],["78726.54000000","0.00000000"],["78727.55000000","0.00007000"],["78727.67000000","0.00000000"],["78728.61000000","0.31764000"],["78728.62000000","0.00000000"],["78729.05000000","0.20785000"],["78729.52000000","0.00000000"],["78730.01000000","0.00000000"],["78730.62000000","0.00000000"],["78731.27000000","0.00635000"],["78734.33000000","0.02000000"],["78734.54000000","1.21952000"],["78734.55000000","0.00000000"],["78734.83000000","0.00000000"],["78734.95000000","0.00000000"],["78735.35000000","0.00000000"],["78736.50000000","0.00662000"],["78736.75000000","0.04857000"],["78737.66000000","0.00000000"],["78737.99000000","0.00000000"],["78738.44000000","0.00227000"],["78738.45000000","0.36224000"],["78744.61000000","0.00000000"],["78748.31000000","0.34290000"],["78748.47000000","0.43579000"],["78757.00000000","0.00000000"],["78810.33000000","1.90515000"],["78810.34000000","0.00000000"]]}}
{"rx_ns": 60852862400, "frame": {"e":"depthUpdate","E":1787603118314,"s":"BTCUSDT","U":99076654388,"u":99076654447,"b":[["78720.74000000","3.30797000"],["78720.73000000","0.00055000"],["78720.05000000","0.08290000"],["78719.69000000","0.00007000"],["78719.68000000","0.02523000"],["78718.54000000","0.00000000"],["78718.00000000","0.02507000"],["78717.27000000","0.11503000"],["78710.71000000","0.00188000"],["78708.74000000","0.00000000"],["78707.85000000","0.00254000"],["78699.37000000","0.00000000"],["78696.53000000","0.04684000"],["78694.00000000","0.02415000"],["78692.00000000","0.02400000"],["78689.00000000","0.00000000"],["78677.10000000","0.00007000"],["70848.67000000","0.00249000"],["62977.00000000","0.00030000"]],"a":[["78720.75000000","1.34751000"],["78720.76000000","0.00076000"],["78723.35000000","0.05397000"],["78723.59000000","0.00254000"],["78724.08000000","0.04026000"],["78724.47000000","0.00000000"],["78724.53000000","0.03799000"],["78724.83000000","0.00156000"],["78724.85000000","0.00000000"],["78724.86000000","0.02168000"],["78726.61000000","0.00000000"],["78728.60000000","0.00137000"],["78728.61000000","0.00000000"],["78729.59000000","0.31762000"],["78731.55000000","0.00048000"],["78736.50000000","0.10614000"]]}}
{"rx_ns": 60952448500, "frame": {"e":"depthUpdate","E":1787603118414,"s":"BTCUSDT","U":99076654448,"u":99076654458,"b":[["78677.10000000","0.00000000"],["70848.67000000","0.00265000"],["62976.59000000","0.00000000"]],"a":[["78720.75000000","1.57695000"],["78720.76000000","0.00083000"],["78723.35000000","0.05390000"],["78846.69000000","0.00160000"]]}}
{"rx_ns": 61054217900, "frame": {"e":"depthUpdate","E":1787603118514,"s":"BTCUSDT","U":99076654459,"u":99076654532,"b":[["78720.74000000","0.98530000"],["78718.25000000","0.00000000"],["78715.80000000","0.00007000"],["78714.68000000","1.90515000"],["78714.67000000","0.00000000"],["78710.71000000","0.00000000"],["78709.42000000","0.00254000"],["78709.31000000","0.00000000"],["78707.85000000","0.00000000"],["78705.80000000","0.00007000"],["78679.86000000","0.00400000"],["78679.25000000","0.00000000"],["78327.13000000","0.01000000"],["77935.50000000","0.01000000"],["77545.82000000","0.01000000"],["77158.09000000","0.01000000"],["76772.30000000","0.01000000"],["76388.44000000","0.01000000"],["76006.49000000","0.01000000"],["75626.46000000","0.01000000"],["75248.33000000","0.01000000"],["74872.09000000","0.01000000"],["74497.73000000","0.01000000"],["74125.24000000","0.01000000"],["73754.61000000","0.01000000"],["73385.84000000","0.01000000"],["73018.91000000","0.01000000"],["72419.85000000","0.00000000"],["70848.67000000","0.00265000"],["62976.60000000","0.00031000"]],"a":[["78720.75000000","1.79386000"],["78720.76000000","0.00055000"],["78723.59000000","0.00000000"],["78725.16000000","0.00254000"],["78734.53000000","1.90515000"],["78735.44000000","0.34296000"],["78757.98000000","0.00400000"],["78758.40000000","0.00000000"],["78810.33000000","0.00000000"],["79114.36000000","0.01000000"],["79509.93000000","0.01000000"],["79907.48000000","0.01000000"],["80307.02000000","0.01000000"],["80708.55000000","0.01000000"],["81112.10000000","0.01000000"],["81517.66000000","0.01000000"],["81925.24000000","0.01000000"],["82334.87000000","0.01000000"],["82746.54000000","0.01000000"],["83160.28000000","0.01000000"],["83576.08000000","0.01000000"],["83993.96000000","0.01000000"],["84413.93000000","0.01000000"],["84836.00000000","0.01000000"]]}}
{"rx_ns": 61154514400, "frame": {"e":"depthUpdate","E":1787603118614,"s":"BTCUSDT","U":99076654533,"u":99076654585,"b":[["78720.74000000","3.10778000"],["78720.73000000","0.00048000"],["78717.38000000","0.00027000"],["78715.84000000","0.00000000"],["78715.80000000","0.00014000"],["78710.80000000","0.00400000"],["78710.21000000","0.00191000"],["78709.42000000","0.00000000"],["78708.07000000","0.00000000"],["78705.80000000","0.01207000"],["78684.20000000","0.00400000"],["78675.52000000","0.00000000"],["70848.67000000","0.00281000"],["62976.60000000","0.00000000"]],"a":[["78720.75000000","1.79428000"],["78720.76000000","0.00076000"],["78720.81000000","0.00000000"],["78720.82000000","0.00007000"],["78723.25000000","0.00000000"],["78723.26000000","0.00414000"],["78723.80000000","0.00000000"],["78724.07000000","0.00007000"],["78725.16000000","0.00000000"],["78726.52000000","0.00254000"],["78726.53000000","0.00254000"],["78731.55000000","0.00000000"],["78734.53000000","0.00000000"],["78740.00000000","0.11926000"],["78757.98000000","0.00000000"],["78810.36000000","1.90515000"],["78886.11000000","0.00160000"]]}}
{"rx_ns": 61252353000, "frame": {"e":"depthUpdate","E":1787603118714,"s":"BTCUSDT","U":99076654586,"u":99076654625,"b":[["78720.74000000","3.10965000"],["78719.22000000","0.00204000"],["78710.21000000","0.00000000"],["78709.19000000","0.00254000"],["78000.00000000","21.12751000"]],"a":[["78720.75000000","1.79421000"],["78720.76000000","0.00069000"],["78720.82000000","0.00000000"],["78724.86000000","0.02168000"],["78724.92000000","0.00254000"],["78728.63000000","0.21961000"],["78731.19000000","0.00048000"],["78739.96000000","1.90515000"],["78745.05000000","0.00406000"],["78748.70000000","0.00000000"],["78784.43000000","0.00406000"],["78788.08000000","0.00000000"],["78810.36000000","0.00000000"],["78815.93000000","0.00406000"],["78819.58000000","0.00000000"],["78863.17000000","0.00406000"],["78866.83000000","0.00000000"],["78882.28000000","0.00283000"],["78934.04000000","0.00406000"],["78937.70000000","0.00000000"],["79198.14000000","0.01460000"]]}}
