{"rx_ns": 9255071200, "frame": {"e":"depthUpdate","E":1787603066714,"s":"BTCUSDT","U":99076624054,"u":99076624936,"b":[["78717.85000000","3.47790000"],["78717.84000000","0.00020000"],["78717.83000000","0.00013000"],["78717.79000000","0.00007000"],["78717.78000000","2.49051000"],["78717.77000000","0.00000000"],["78717.76000000","0.00000000"],["78717.75000000","0.05000000"],["78717.70000000","0.05000000"],["78717.10000000","0.00008000"],["78716.57000000","0.07500000"],["78716.56000000","0.87310000"],["78716.55000000","0.00000000"],["78716.52000000","0.70597000"],["78716.51000000","0.00000000"],["78716.50000000","0.00000000"],["78716.30000000","0.00400000"],["78715.99000000","0.00007000"],["78715.93000000","0.00007000"],["78715.80000000","0.00014000"],["78715.79000000","0.00014000"],["78715.27000000","0.07500000"],["78715.26000000","1.20192000"],["78715.25000000","0.20216000"],["78715.24000000","0.00000000"],["78714.87000000","0.04773000"],["78714.79000000","0.00000000"],["78714.36000000","0.00000000"],["78714.02000000","0.00000000"],["78714.01000000","1.63143000"],["78714.00000000","0.45775000"],["78713.99000000","0.00419000"],["78713.98000000","0.08000000"],["78713.95000000","0.00007000"],["78713.61000000","0.00000000"],["78713.28000000","0.00400000"],["78713.27000000","0.00007000"],["78712.79000000","0.03224000"],["78712.35000000","0.00000000"],["78712.00000000","0.02400000"],["78711.07000000","0.00000000"],["78711.05000000","0.00000000"],["78710.66000000","0.00000000"],["78710.04000000","0.36224000"],["78710.03000000","1.21952000"],["78710.00000000","0.02400000"],["78709.98000000","0.03000000"],["78709.97000000","0.02000000"],["78709.81000000","0.00000000"],["78709.27000000","0.04000000"],["78708.74000000","0.08576000"],["78708.55000000","0.00000000"],["78708.23000000","0.00000000"],["78708.09000000","0.00000000"],["78707.29000000","0.00000000"],["78706.03000000","0.00000000"],["78705.44000000","0.00000000"],["78701.87000000","0.00321000"],["78700.00000000","0.08908000"],["78698.36000000","0.06590000"],["78697.91000000","0.00000000"],["78697.27000000","0.00000000"],["78696.40000000","0.07615000"],["78693.97000000","0.00000000"],["78691.89000000","0.13479000"],["78688.03000000","0.13238000"],["78682.89000000","1.25835000"],["78680.32000000","0.09451000"],["78679.43000000","0.00000000"],["78677.10000000","0.00000000"],["78671.62000000","0.00000000"],["78671.00000000","0.00400000"],["78670.60000000","0.00000000"],["78670.58000000","0.00000000"],["78667.98000000","0.00000000"],["78654.56000000","0.00317000"],["78652.01000000","0.00000000"],["78649.69000000","0.00000000"],["78584.87000000","0.00000000"],["78567.05000000","0.00102000"],["78557.09000000","0.00000000"],["78556.75000000","0.00000000"],["78462.41000000","0.00000000"],["70842.60000000","0.00000000"],["62985.60000000","0.00000000"],["62974.28000000","0.00018000"]],"a":[["78714.01000000","0.00000000"],["78714.02000000","0.00000000"],["78714.03000000","0.00000000"],["78714.37000000","0.00000000"],["78714.80000000","0.00000000"],["78715.26000000","0.00000000"],["78715.27000000","0.00000000"],["78715.28000000","0.00000000"],["78715.80000000","0.00000000"],["78715.94000000","0.00000000"],["78716.00000000","0.00000000"],["78716.52000000","0.00000000"],["78716.53000000","0.00000000"],["78716.56000000","0.00000000"],["78716.57000000","0.00000000"],["78717.78000000","0.00000000"],["78717.79000000","0.00000000"],["78717.85000000","0.00000000"],["78717.86000000","0.00328000"],["78717.87000000","0.00056000"],["78717.94000000","0.00000000"],["78717.95000000","0.00000000"],["78717.99000000","0.00021000"],["78718.00000000","0.01207000"],["78719.12000000","0.00000000"],["78719.69000000","0.00000000"],["78719.73000000","0.00000000"],["78719.99000000","0.00014000"],["78720.00000000","0.01207000"],["78720.01000000","0.00027000"],["78720.37000000","0.00014000"],["78720.38000000","0.05391000"],["78721.99000000","0.00014000"],["78722.00000000","0.01214000"],["78722.01000000","0.00014000"],["78723.36000000","0.00000000"],["78723.54000000","0.00007000"],["78723.83000000","0.00000000"],["78723.99000000","0.00014000"],["78724.00000000","0.01707000"],["78724.60000000","0.00000000"],["78724.61000000","0.02071000"],["78724.62000000","0.02789000"],["78724.80000000","0.00000000"],["78725.29000000","0.00325000"],["78726.00000000","0.05214000"],["78726.15000000","0.02293000"],["78726.45000000","0.00318000"],["78727.13000000","0.00007000"],["78727.40000000","0.00000000"],["78727.41000000","0.00014000"],["78727.84000000","0.02161000"],["78727.85000000","0.12708000"],["78727.89000000","0.21937000"],["78728.13000000","0.00000000"],["78728.14000000","0.00048000"],["78729.21000000","0.00070000"],["78729.73000000","0.00000000"],["78729.76000000","0.00000000"],["78730.33000000","0.01000000"],["78730.62000000","0.00137000"],["78730.63000000","0.02000000"],["78731.02000000","0.00000000"],["78731.33000000","0.08000000"],["78732.01000000","0.00000000"],["78732.47000000","0.00000000"],["78732.84000000","0.00000000"],["78733.37000000","0.00000000"],["78735.34000000","0.00000000"],["78735.77000000","0.04857000"],["78736.50000000","0.00635000"],["78736.69000000","0.00000000"],["78737.46000000","0.00007000"],["78737.55000000","1.90515000"],["78737.99000000","1.21952000"],["78739.74000000","0.00000000"],["78740.49000000","0.02000000"],["78742.52000000","1.21952000"],["78746.33000000","0.00000000"],["78746.60000000","0.00000000"],["78747.00000000","0.70000000"],["78747.40000000","0.00000000"],["78748.00000000","0.02400000"],["78749.41000000","0.00000000"],["78749.47000000","0.00192000"],["78749.63000000","0.00000000"],["78749.84000000","0.36224000"],["78749.85000000","0.00000000"],["78749.86000000","0.43621000"],["78753.30000000","0.02515000"],["78754.00000000","0.02400000"],["78754.50000000","0.00014000"],["78755.00000000","0.00000000"],["78755.27000000","0.43576000"],["78756.00000000","0.02400000"],["78758.00000000","0.03400000"],["78758.17000000","0.04613000"],["78759.70000000","1.21933000"],["78760.46000000","0.00000000"],["78763.38000000","0.00000000"],["78764.62000000","0.00316000"],["78769.75000000","0.00000000"],["78785.33000000","0.00000000"],["78787.47000000","0.00316000"],["78800.17000000","0.00000000"],["78807.74000000","0.00000000"],["78808.27000000","0.00000000"],["78808.28000000","0.00000000"],["78820.13000000","0.00000000"],["78863.62000000","0.00000000"],["78865.43000000","0.00000000"],["78865.72000000","0.00000000"],["78865.99000000","0.00127000"],["78876.14000000","0.00102000"],["78938.05000000","0.00000000"],["79273.61000000","0.00000000"]]}}
{"rx_ns": 9357529800, "frame": {"e":"depthUpdate","E":1787603066814,"s":"BTCUSDT","U":99076624937,"u":99076625192,"b":[["78717.99000000","4.99437000"],["78717.98000000","3.48711000"],["78717.97000000","0.00013000"],["78717.95000000","0.05000000"],["78717.90000000","0.05000000"],["78717.87000000","0.00000000"],["78717.86000000","0.00014000"],["78717.85000000","0.61976000"],["78717.84000000","0.00000000"],["78717.83000000","0.00000000"],["78717.79000000","0.00021000"],["78717.78000000","0.58543000"],["78717.75000000","0.00014000"],["78717.70000000","0.00007000"],["78717.14000000","0.00000000"],["78716.57000000","0.00021000"],["78716.53000000","0.00007000"],["78716.52000000","0.70597000"],["78715.27000000","0.00007000"],["78715.26000000","1.19855000"],["78715.25000000","0.03007000"],["78714.16000000","0.01390000"],["78714.01000000","1.21959000"],["78714.00000000","0.45586000"],["78713.95000000","0.00000000"],["78712.90000000","0.02317000"],["78712.10000000","0.00000000"],["78711.64000000","0.02780000"],["78710.61000000","0.00000000"],["78710.60000000","0.00000000"],["78710.38000000","0.02780000"],["78710.21000000","0.00000000"],["78710.05000000","0.00000000"],["78701.79000000","0.02800000"],["78688.82000000","0.02449000"],["78688.03000000","0.00000000"],["78678.00000000","0.03400000"],["78674.00000000","0.02400000"],["78662.40000000","0.02800000"],["78594.32000000","0.04092000"],["78399.96000000","0.00000000"],["70846.07000000","0.00000000"],["70846.00000000","0.00020000"]],"a":[["78717.86000000","0.00000000"],["78717.87000000","0.00000000"],["78717.99000000","0.00000000"],["78718.00000000","0.80926000"],["78718.01000000","0.00056000"],["78719.14000000","0.00014000"],["78719.15000000","0.21132000"],["78719.25000000","0.00014000"],["78719.26000000","0.04034000"],["78720.00000000","0.01707000"],["78720.01000000","0.00020000"],["78720.06000000","0.00027000"],["78720.38000000","0.05398000"],["78720.51000000","0.00007000"],["78720.52000000","0.04841000"],["78721.45000000","0.00007000"],["78721.78000000","0.04841000"],["78721.99000000","0.00000000"],["78722.00000000","0.01714000"],["78723.54000000","0.00014000"],["78723.99000000","0.00000000"],["78724.60000000","0.00000000"],["78726.15000000","0.02293000"],["78727.13000000","0.00000000"],["78732.24000000","0.25410000"],["78733.03000000","0.38116000"],["78733.75000000","0.04067000"],["78736.28000000","0.02000000"],["78747.00000000","0.00000000"],["78749.86000000","0.34289000"],["78755.98000000","0.02000000"],["78762.24000000","0.00000000"],["78775.68000000","0.02000000"],["78830.47000000","0.02789000"],["78936.11000000","0.00007000"],["78940.04000000","0.00000000"],["78947.17000000","0.01990000"]]}}
{"rx_ns": 9455044600, "frame": {"e":"depthUpdate","E":1787603066914,"s":"BTCUSDT","U":99076625193,"u":99076625445,"b":[["78717.99000000","2.52662000"],["78717.98000000","0.36251000"],["78717.96000000","0.00014000"],["78717.95000000","0.05014000"],["78717.91000000","0.00007000"],["78717.90000000","0.05007000"],["78717.85000000","0.02361000"],["78717.78000000","0.04527000"],["78717.75000000","0.00000000"],["78717.70000000","0.00000000"],["78717.10000000","0.00008000"],["78716.57000000","0.00000000"],["78716.56000000","0.02416000"],["78716.53000000","0.00000000"],["78716.52000000","0.08816000"],["78715.81000000","0.00000000"],["78715.80000000","0.00007000"],["78715.79000000","0.00007000"],["78715.27000000","0.00000000"],["78715.26000000","0.57310000"],["78715.25000000","0.00007000"],["78715.11000000","0.00000000"],["78715.05000000","0.00331000"],["78714.00000000","0.45586000"],["78713.98000000","0.00000000"],["78713.39000000","0.00000000"],["78712.95000000","0.00000000"],["78712.80000000","0.00000000"],["78711.70000000","0.02200000"],["78710.24000000","0.26049000"],["78710.11000000","0.21930000"],["78710.05000000","0.00635000"],["78709.98000000","0.00000000"],["78708.88000000","0.03000000"],["78708.75000000","0.00635000"],["78707.71000000","0.02007000"],["78704.01000000","0.00000000"],["78703.58000000","0.00000000"],["78703.25000000","0.00000000"],["78702.78000000","0.00000000"],["78702.46000000","0.00400000"],["78701.34000000","0.00000000"],["78700.47000000","0.08000000"],["78682.89000000","0.00000000"],["78677.10000000","0.00007000"],["78673.23000000","0.00007000"],["78660.57000000","0.00000000"],["78657.74000000","1.25876000"],["78655.94000000","0.86876000"],["78642.67000000","0.02200000"],["78594.32000000","0.00000000"],["78408.64000000","7.65309000"],["78324.40000000","0.01008000"],["77932.77000000","0.01000000"],["77543.11000000","0.01000000"],["77155.39000000","0.01000000"],["76769.62000000","0.01000000"],["76385.77000000","0.01000000"],["76003.84000000","0.01000000"],["75623.82000000","0.01000000"],["75245.70000000","0.01000000"],["74869.47000000","0.01000000"],["74495.13000000","0.01000000"],["74122.65000000","0.01000000"],["73752.04000000","0.01000000"],["73383.28000000","0.01000000"],["73016.36000000","0.01000000"],["70846.20000000","0.00032000"],["70846.00000000","0.00000000"]],"a":[["78718.00000000","1.23202000"],["78718.01000000","0.00070000"],["78718.35000000","0.00014000"],["78718.36000000","0.17962000"],["78719.14000000","0.00000000"],["78719.15000000","0.00014000"],["78719.26000000","0.04041000"],["78719.42000000","0.00014000"],["78719.43000000","0.26049000"],["78719.67000000","0.00014000"],["78719.99000000","0.00000000"],["78720.38000000","0.05398000"],["78720.51000000","0.00007000"],["78720.52000000","0.04848000"],["78721.78000000","0.04848000"],["78723.47000000","0.00254000"],["78723.72000000","0.00321000"],["78723.99000000","0.00254000"],["78724.61000000","0.02064000"],["78724.62000000","0.02782000"],["78725.28000000","0.00192000"],["78726.00000000","0.05214000"],["78726.14000000","0.31762000"],["78726.15000000","0.02286000"],["78727.89000000","0.21930000"],["78728.14000000","0.00000000"],["78729.21000000","0.00000000"],["78729.58000000","0.00000000"],["78729.59000000","0.00000000"],["78730.98000000","0.02000000"],["78731.98000000","1.90515000"],["78731.99000000","0.00000000"],["78732.84000000","1.21952000"],["78737.54000000","0.36224000"],["78739.93000000","0.00000000"],["78740.49000000","0.00000000"],["78749.47000000","0.00000000"],["78749.87000000","0.09707000"],["78758.37000000","0.00000000"],["78767.56000000","0.02487000"],["78770.66000000","0.00400000"],["78777.27000000","0.86742000"],["78779.30000000","0.00000000"],["78779.72000000","0.00000000"],["78785.67000000","0.00406000"],["78789.93000000","0.00010000"],["78800.64000000","0.00000000"],["78810.80000000","0.00000000"],["78817.17000000","0.00406000"],["78818.57000000","0.00000000"],["78822.58000000","0.00012000"],["78824.71000000","0.00000000"],["78828.72000000","0.00019000"],["78830.47000000","0.00000000"],["78830.81000000","0.00000000"],["78858.04000000","0.00000000"],["78864.41000000","0.00406000"],["78928.91000000","0.00000000"],["78935.29000000","0.00406000"],["79111.59000000","0.01000000"],["79507.15000000","0.01000000"],["79904.69000000","0.01000000"],["80304.21000000","0.01000000"],["80705.73000000","0.01000000"],["81109.26000000","0.01000000"],["81514.81000000","0.01000000"],["81922.38000000","0.01000000"],["82331.99000000","0.01000000"],["82743.65000000","0.01000000"],["83157.37000000","0.01000000"],["83573.16000000","0.01000000"],["83991.02000000","0.01000000"],["84410.98000000","0.01000000"],["84833.03000000","0.01000000"]]}}
{"rx_ns": 9553717300, "frame": {"e":"depthUpdate","E":1787603067014,"s":"BTCUSDT","U":99076625446,"u":99076625530,"b":[["78717.99000000","4.41689000"],["78717.98000000","0.00027000"],["78717.92000000","0.00007000"],["78717.91000000","0.04046000"],["78717.79000000","0.00014000"],["78716.57000000","0.00000000"],["78714.00000000","0.45586000"],["78713.27000000","0.00000000"],["78712.79000000","0.00000000"],["78711.50000000","1.90515000"],["78710.04000000","0.00000000"],["78709.39000000","0.00152000"],["78709.14000000","0.36224000"],["78708.88000000","0.01000000"],["78707.01000000","0.00007000"],["78706.27000000","0.02000000"],["78706.26000000","0.00000000"],["78701.77000000","0.00000000"],["78700.07000000","0.38123000"],["78700.00000000","0.02407000"],["78688.82000000","0.00000000"],["78684.29000000","0.02443000"],["78684.00000000","0.02400000"],["78675.07000000","1.25848000"],["78674.98000000","0.00000000"],["78673.23000000","0.00000000"],["78642.67000000","0.00000000"],["78592.60000000","0.04092000"],["78408.64000000","0.00000000"],["70846.20000000","0.00048000"],["62974.40000000","0.00031000"]],"a":[["78718.00000000","1.03300000"],["78718.01000000","0.00063000"],["78718.36000000","0.17969000"],["78719.15000000","0.00007000"],["78719.26000000","0.04041000"],["78719.43000000","0.26056000"],["78720.06000000","0.00000000"],["78721.31000000","0.00324000"],["78721.37000000","0.00000000"],["78723.47000000","0.00000000"],["78723.99000000","0.00000000"],["78724.00000000","0.01700000"],["78725.19000000","0.00508000"],["78726.14000000","0.00000000"],["78727.81000000","0.31763000"],["78727.82000000","0.25410000"],["78731.98000000","0.00000000"],["78732.24000000","0.00000000"],["78737.53000000","0.36224000"],["78737.54000000","0.00000000"],["78746.29000000","0.00406000"],["78767.56000000","0.00000000"],["78800.64000000","1.90515000"],["78828.74000000","0.02789000"],["78834.81000000","0.00031000"]]}}
{"rx_ns": 9654488800, "frame": {"e":"depthUpdate","E":1787603067115,"s":"BTCUSDT","U":99076625531,"u":99076625562,"b":[["78717.99000000","4.61708000"],["78717.98000000","0.00020000"],["78717.95000000","0.05014000"],["78717.92000000","0.00000000"],["78717.91000000","0.00014000"],["78716.57000000","0.00007000"],["78713.06000000","0.12711000"],["78706.74000000","0.00188000"],["78697.43000000","0.00000000"],["78529.42000000","0.00778000"],["78520.83000000","0.00000000"],["78005.57000000","0.00000000"],["70846.20000000","0.00064000"]],"a":[["78718.00000000","1.03300000"],["78718.01000000","0.00063000"],["78725.19000000","0.00000000"],["78725.99000000","0.00508000"],["78726.00000000","0.05207000"],["78746.29000000","0.00000000"],["78811.61000000","0.00000000"],["78815.60000000","0.00025000"]]}}
{"rx_ns": 9753176500, "frame": {"e":"depthUpdate","E":1787603067214,"s":"BTCUSDT","U":99076625563,"u":99076625581,"b":[["78717.99000000","4.61708000"],["78717.95000000","0.05014000"],["78717.85000000","0.02658000"],["78715.05000000","0.00000000"],["78714.73000000","0.00331000"],["78714.00000000","0.45586000"],["78713.06000000","0.00000000"],["78634.39000000","0.00316000"],["78630.01000000","0.00000000"],["77436.17000000","0.00000000"],["70846.20000000","0.00080000"],["62974.40000000","0.00000000"]],"a":[["78721.31000000","0.00000000"],["78746.44000000","0.00406000"],["78764.62000000","0.00000000"],["78767.19000000","0.00317000"],["78787.47000000","0.00000000"],["78789.86000000","0.00314000"],["78841.99000000","0.00000000"],["78845.90000000","0.00127000"]]}}
{"rx_ns": 9853747900, "frame": {"e":"depthUpdate","E":1787603067314,"s":"BTCUSDT","U":99076625582,"u":99076625606,"b":[["78717.99000000","4.61708000"],["78715.26000000","0.57317000"],["78585.34000000","0.02541000"],["70846.20000000","0.00096000"],["62971.00000000","0.00000000"]],"a":[["78718.00000000","0.98760000"],["78718.01000000","0.00063000"],["78719.87000000","0.00007000"],["78727.81000000","0.00000000"],["78728.23000000","0.31763000"],["78746.44000000","0.00000000"],["78753.23000000","0.00007000"],["78849.33000000","0.00000000"],["78864.65000000","0.01990000"]]}}
{"rx_ns": 9953499700, "frame": {"e":"depthUpdate","E":1787603067414,"s":"BTCUSDT","U":99076625607,"u":99076625643,"b":[["78710.24000000","0.00000000"],["78674.46000000","0.00000000"],["78665.47000000","0.00014000"],["78324.40000000","0.00008000"],["77932.77000000","0.00000000"],["77543.11000000","0.00000000"],["77155.39000000","0.00000000"],["76769.62000000","0.00000000"],["76385.77000000","0.00000000"],["76003.84000000","0.00000000"],["75623.82000000","0.00000000"],["75245.70000000","0.00000000"],["74869.47000000","0.00000000"],["74495.13000000","0.00000000"],["74122.65000000","0.00000000"],["73752.04000000","0.00000000"],["73383.28000000","0.00000000"],["73016.36000000","0.00000000"],["70846.20000000","0.00112000"]],"a":[["78746.45000000","0.00406000"],["78782.54000000","0.00000000"],["78839.94000000","0.00160000"],["79111.59000000","0.00000000"],["79507.15000000","0.00000000"],["79904.69000000","0.00000000"],["80304.21000000","0.00000000"],["80705.73000000","0.00000000"],["81109.26000000","0.00000000"],["81514.81000000","0.00000000"],["81922.38000000","0.00000000"],["82331.99000000","0.00000000"],["82743.65000000","0.00000000"],["83157.37000000","0.00000000"],["83573.16000000","0.00000000"],["83991.02000000","0.00000000"],["84410.98000000","0.00000000"],["84833.03000000","0.00000000"]]}}
{"rx_ns": 10052924900, "frame": {"e":"depthUpdate","E":1787603067514,"s":"BTCUSDT","U":99076625644,"u":99076625653,"b":[["78717.85000000","0.34420000"],["78716.00000000","0.00237000"],["78714.00000000","0.45579000"],["78701.43000000","0.00000000"],["78690.34000000","0.00000000"],["78683.69000000","0.00000000"],["78663.98000000","0.00000000"],["70846.20000000","0.00128000"],["62974.40000000","0.00031000"]],"a":[["78718.00000000","0.99023000"],["78728.23000000","0.00000000"],["78729.01000000","0.31763000"],["78729.02000000","0.00000000"],["78737.58000000","0.00000000"],["78745.57000000","0.00000000"],["78767.75000000","0.00000000"],["78773.53000000","0.00634000"]]}}
{"rx_ns": 10153278300, "frame": {"e":"depthUpdate","E":1787603067614,"s":"BTCUSDT","U":99076625654,"u":99076625683,"b":[["78717.99000000","4.61898000"],["78714.00000000","0.46086000"],["78711.19000000","0.12704000"],["78706.74000000","0.00000000"],["78701.11000000","0.00007000"],["78694.33000000","0.00007000"],["70846.20000000","0.00144000"],["62974.40000000","0.00000000"],["62974.39000000","0.00000000"]],"a":[["78718.00000000","0.68660000"],["78718.01000000","0.00076000"],["78718.02000000","0.00013000"],["78718.35000000","0.00000000"],["78718.36000000","0.00007000"],["78719.99000000","0.00014000"],["78741.57000000","0.00007000"],["78742.68000000","0.12699000"],["78756.00000000","0.72400000"]]}}
{"rx_ns": 10254900000, "frame": {"e":"depthUpdate","E":1787603067714,"s":"BTCUSDT","U":99076625684,"u":99076625699,"b":[["78717.99000000","4.42543000"],["78715.80000000","0.00014000"],["78592.60000000","0.00000000"],["70842.59000000","0.00000000"]],"a":[["78718.00000000","0.68833000"],["78718.36000000","0.00000000"],["78724.00000000","0.01707000"],["78757.33000000","0.00007000"],["78828.74000000","0.00000000"],["78843.77000000","0.00000000"],["78879.35000000","0.00160000"]]}}
{"rx_ns": 10353342500, "frame": {"e":"depthUpdate","E":1787603067814,"s":"BTCUSDT","U":99076625700,"u":99076625714,"b":[["78714.73000000","0.00000000"],["78707.20000000","0.02800000"],["78667.80000000","0.02800000"],["78642.70000000","0.02800000"],["78631.52000000","0.01302000"],["78592.02000000","0.04092000"],["72420.55000000","0.00014000"],["70846.20000000","0.00160000"]],"a":[["78736.35000000","0.02000000"],["78740.45000000","0.57122000"],["78756.05000000","0.02000000"],["78775.75000000","0.02000000"],["78828.16000000","0.02789000"]]}}
{"rx_ns": 10455081500, "frame": {"e":"depthUpdate","E":1787603067914,"s":"BTCUSDT","U":99076625715,"u":99076625763,"b":[["78716.44000000","0.04032000"],["78709.27000000","0.00000000"],["78687.53000000","0.02200000"],["78677.10000000","0.00000000"],["78660.57000000","0.02000000"],["78642.67000000","0.02200000"],["78324.40000000","0.01008000"],["77932.77000000","0.01000000"],["77543.11000000","0.01000000"],["77155.39000000","0.01000000"],["76769.62000000","0.01000000"],["76385.77000000","0.01000000"],["76003.84000000","0.01000000"],["75623.82000000","0.01000000"],["75245.70000000","0.01000000"],["74869.47000000","0.01000000"],["74495.13000000","0.01000000"],["74122.65000000","0.01000000"],["73752.04000000","0.01000000"],["73383.28000000","0.01000000"],["73016.36000000","0.01000000"],["70846.20000000","0.00160000"],["70846.00000000","0.00000000"]],"a":[["78718.00000000","0.90214000"],["78718.01000000","0.00069000"],["78720.21000000","0.00324000"],["78721.67000000","0.00327000"],["78742.43000000","0.63505000"],["79018.18000000","0.00000000"],["79111.59000000","0.01000000"],["79507.15000000","0.01000000"],["79904.69000000","0.01000000"],["80304.21000000","0.01000000"],["80705.73000000","0.01000000"],["81109.26000000","0.01000000"],["81514.81000000","0.01000000"],["81922.38000000","0.01000000"],["82331.99000000","0.01000000"],["82743.65000000","0.01000000"],["83157.37000000","0.01000000"],["83573.16000000","0.01000000"],["83991.02000000","0.01000000"],["84410.98000000","0.01000000"],["84833.03000000","0.01000000"]]}}
{"rx_ns": 10553274000, "frame": {"e":"depthUpdate","E":1787603068014,"s":"BTCUSDT","U":99076625764,"u":99076625775,"b":[["78716.52000000","0.08816000"],["78692.00000000","0.72400000"],["78642.67000000","0.00000000"],["70846.20000000","0.00160000"],["62974.40000000","0.00031000"]],"a":[["78718.00000000","0.90241000"],["78718.01000000","0.00083000"]]}}
{"rx_ns": 10658554600, "frame": {"e":"depthUpdate","E":1787603068114,"s":"BTCUSDT","U":99076625776,"u":99076625785,"b":[["78714.73000000","0.00327000"],["78636.95000000","0.02116000"],["78009.53000000","0.00050000"],["70846.20000000","0.00176000"]],"a":[["78718.00000000","0.90251000"],["78722.64000000","0.01270000"],["78722.68000000","0.06350000"],["78741.04000000","0.34293000"],["78765.83000000","0.00000000"],["78811.55000000","0.93647000"]]}}
{"rx_ns": 10753258700, "frame": {"e":"depthUpdate","E":1787603068214,"s":"BTCUSDT","U":99076625786,"u":99076625801,"b":[["78714.00000000","0.46093000"],["78712.59000000","0.00000000"],["78636.95000000","0.00000000"],["70846.20000000","0.00192000"],["62974.40000000","0.00000000"]],"a":[["78718.00000000","0.90265000"],["78720.38000000","0.05405000"],["78722.00000000","0.01714000"],["78722.64000000","0.01277000"],["78724.00000000","0.01700000"],["78727.85000000","0.12701000"]]}}
{"rx_ns": 10853885100, "frame": {"e":"depthUpdate","E":1787603068314,"s":"BTCUSDT","U":99076625802,"u":99076625810,"b":[["78717.99000000","4.42430000"],["78714.73000000","0.00000000"],["78714.00000000","0.46086000"],["78636.95000000","0.02116000"],["72420.55000000","0.00000000"],["70846.20000000","0.00176000"],["62971.00000000","0.00000000"]],"a":[["78745.04000000","0.00007000"]]}}
{"rx_ns": 10953183600, "frame": {"e":"depthUpdate","E":1787603068414,"s":"BTCUSDT","U":99076625811,"u":99076625843,"b":[["78636.95000000","0.00000000"],["78324.40000000","0.00008000"],["77932.77000000","0.00000000"],["77543.11000000","0.00000000"],["77155.39000000","0.00000000"],["76769.62000000","0.00000000"],["76385.77000000","0.00000000"],["76003.84000000","0.00000000"],["75623.82000000","0.00000000"],["75245.70000000","0.00000000"],["74869.47000000","0.00000000"],["74495.13000000","0.00000000"],["74122.65000000","0.00000000"],["73752.04000000","0.00000000"],["73383.28000000","0.00000000"],["73016.36000000","0.00000000"],["70846.20000000","0.00208000"]],"a":[["79111.59000000","0.00000000"],["79507.15000000","0.00000000"],["79904.69000000","0.00000000"],["80304.21000000","0.00000000"],["80705.73000000","0.00000000"],["81109.26000000","0.00000000"],["81514.81000000","0.00000000"],["81922.38000000","0.00000000"],["82331.99000000","0.00000000"],["82743.65000000","0.00000000"],["83157.37000000","0.00000000"],["83573.16000000","0.00000000"],["83991.02000000","0.00000000"],["84410.98000000","0.00000000"],["84833.03000000","0.00000000"]]}}
{"rx_ns": 11053220900, "frame": {"e":"depthUpdate","E":1787603068514,"s":"BTCUSDT","U":99076625844,"u":99076625853,"b":[["78717.85000000","0.34123000"],["78715.45000000","0.26049000"],["78713.05000000","0.00000000"],["78702.23000000","0.00000000"],["78684.41000000","0.00000000"],["78664.70000000","0.00000000"],["70846.20000000","0.00208000"],["62974.40000000","0.00031000"]],"a":[["78728.24000000","0.00000000"],["78742.61000000","0.02515000"],["78744.78000000","0.00000000"],["78753.30000000","0.00000000"],["78766.96000000","0.00000000"]]}}
{"rx_ns": 11152948200, "frame": {"e":"depthUpdate","E":1787603068614,"s":"BTCUSDT","U":99076625854,"u":99076625868,"b":[["78716.52000000","0.08823000"],["78716.44000000","0.04039000"],["78715.26000000","0.57310000"],["78694.33000000","0.00007000"],["70846.20000000","0.00224000"],["62974.40000000","0.00000000"],["62974.39000000","0.00000000"]],"a":[["78733.74000000","0.00007000"],["78741.57000000","0.00007000"],["78773.76000000","0.00000000"]]}}
{"rx_ns": 11253210300, "frame": {"e":"depthUpdate","E":1787603068714,"s":"BTCUSDT","U":99076625869,"u":99076625873,"b":[["78636.95000000","0.02116000"],["70846.20000000","0.00240000"]],"a":[["78718.00000000","0.90258000"],["78722.64000000","0.00007000"],["78759.37000000","0.00007000"]]}}
{"rx_ns": 11353663500, "frame": {"e":"depthUpdate","E":1787603068814,"s":"BTCUSDT","U":99076625874,"u":99076625893,"b":[["78714.00000000","0.46093000"],["78712.85000000","0.12711000"],["78708.00000000","0.05007000"],["78668.60000000","0.02600000"],["78648.11000000","0.02800000"],["78636.95000000","0.00000000"],["70846.20000000","0.00240000"]],"a":[["78720.00000000","0.03107000"],["78722.00000000","0.02414000"],["78722.64000000","0.00000000"],["78722.68000000","0.06357000"],["78724.00000000","0.02400000"],["78726.00000000","0.02407000"],["78735.56000000","0.02000000"],["78755.26000000","0.02000000"],["78774.96000000","0.02000000"]]}}
{"rx_ns": 11456912600, "frame": {"e":"depthUpdate","E":1787603068914,"s":"BTCUSDT","U":99076625894,"u":99076626032,"b":[["78717.99000000","0.92966000"],["78717.85000000","0.31783000"],["78717.79000000","0.00000000"],["78717.78000000","0.00014000"],["78716.57000000","0.00000000"],["78716.56000000","0.00014000"],["78716.53000000","0.00014000"],["78716.52000000","0.08816000"],["78716.45000000","0.00007000"],["78716.30000000","0.00000000"],["78715.80000000","0.00007000"],["78715.45000000","0.00000000"],["78715.26000000","0.49017000"],["78714.02000000","1.21952000"],["78714.01000000","0.00007000"],["78714.00000000","0.45754000"],["78713.17000000","0.00000000"],["78712.85000000","0.00000000"],["78712.54000000","0.00000000"],["78711.75000000","0.00317000"],["78711.50000000","0.00000000"],["78710.05000000","0.00000000"],["78709.97000000","0.00000000"],["78709.48000000","0.04000000"],["78708.75000000","0.00000000"],["78708.74000000","0.00000000"],["78708.17000000","0.02007000"],["78707.24000000","0.08576000"],["78706.67000000","0.00635000"],["78706.28000000","0.00635000"],["78705.87000000","0.00191000"],["78703.58000000","0.00000000"],["78702.46000000","0.00400000"],["78700.47000000","0.00000000"],["78700.07000000","0.00000000"],["78699.87000000","0.00000000"],["78697.37000000","0.08000000"],["78694.83000000","0.00000000"],["78680.60000000","0.63555000"],["78677.92000000","0.34321000"],["78677.10000000","0.00007000"],["78673.23000000","0.00007000"],["78661.83000000","0.00400000"],["78324.40000000","0.01008000"],["77932.77000000","0.01000000"],["77543.11000000","0.01000000"],["77155.39000000","0.01000000"],["76769.62000000","0.01000000"],["76385.77000000","0.01000000"],["76003.84000000","0.01000000"],["75623.82000000","0.01000000"],["75245.70000000","0.01000000"],["74869.47000000","0.01000000"],["74495.13000000","0.01000000"],["74122.65000000","0.01000000"],["73752.04000000","0.01000000"],["73383.28000000","0.01000000"],["73016.36000000","0.01000000"],["70846.20000000","0.00256000"]],"a":[["78718.00000000","0.99895000"],["78718.01000000","0.00062000"],["78720.04000000","0.00027000"],["78722.68000000","0.06364000"],["78723.47000000","0.00254000"],["78723.71000000","0.00635000"],["78723.99000000","0.00254000"],["78724.60000000","0.00137000"],["78725.12000000","0.38115000"],["78725.28000000","0.00000000"],["78725.46000000","0.00400000"],["78725.99000000","0.00000000"],["78726.00000000","0.02400000"],["78726.14000000","0.31763000"],["78727.80000000","0.00227000"],["78727.81000000","3.12467000"],["78729.01000000","0.00000000"],["78730.62000000","0.00000000"],["78733.03000000","0.00000000"],["78733.99000000","0.00000000"],["78734.27000000","0.04857000"],["78735.77000000","0.00000000"],["78739.98000000","0.00000000"],["78740.00000000","0.09541000"],["78741.63000000","0.34293000"],["78759.06000000","0.00000000"],["78763.02000000","0.02483000"],["78773.68000000","0.00000000"],["78780.70000000","0.00000000"],["78800.64000000","0.00000000"],["79111.59000000","0.01000000"],["79507.15000000","0.01000000"],["79904.69000000","0.01000000"],["80304.21000000","0.01000000"],["80705.73000000","0.01000000"],["81109.26000000","0.01000000"],["81514.81000000","0.01000000"],["81922.38000000","0.01000000"],["82331.99000000","0.01000000"],["82743.65000000","0.01000000"],["83157.37000000","0.01000000"],["83573.16000000","0.01000000"],["83991.02000000","0.01000000"],["84410.98000000","0.01000000"],["84833.03000000","0.01000000"]]}}
{"rx_ns": 11554191000, "frame": {"e":"depthUpdate","E":1787603069014,"s":"BTCUSDT","U":99076626033,"u":99076626089,"b":[["78717.99000000","1.14889000"],["78717.85000000","0.31776000"],["78717.78000000","0.00007000"],["78716.56000000","0.00007000"],["78716.44000000","0.04039000"],["78715.26000000","0.49024000"],["78714.87000000","0.04780000"],["78712.90000000","0.02317000"],["78708.17000000","0.00007000"],["78704.97000000","0.02000000"],["78692.00000000","0.02400000"],["78682.00000000","0.02400000"],["78673.23000000","0.00000000"],["78592.02000000","0.00000000"],["78586.14000000","0.04092000"],["62974.40000000","0.00031000"]],"a":[["78718.00000000","0.91422000"],["78718.01000000","0.00069000"],["78720.04000000","0.00000000"],["78721.77000000","0.00254000"],["78722.68000000","0.06364000"],["78723.71000000","0.00000000"],["78723.99000000","0.00000000"],["78724.60000000","0.31901000"],["78726.13000000","0.00635000"],["78726.14000000","0.00000000"],["78726.51000000","0.00000000"],["78727.80000000","0.00000000"],["78727.81000000","1.21952000"],["78734.79000000","0.00227000"],["78800.64000000","1.90515000"]]}}
{"rx_ns": 11655600700, "frame": {"e":"depthUpdate","E":1787603069114,"s":"BTCUSDT","U":99076626090,"u":99076626134,"b":[["78717.99000000","0.92966000"],["70846.20000000","0.00272000"],["70846.00000000","0.00000000"]],"a":[["78718.00000000","0.97386000"],["78719.70000000","0.00332000"],["78722.68000000","0.00021000"],["78723.71000000","0.31764000"],["78724.59000000","0.02161000"],["78724.60000000","0.00137000"],["78728.78000000","0.00048000"],["78742.17000000","0.00406000"],["78746.45000000","0.00000000"],["78781.55000000","0.00406000"],["78785.67000000","0.00000000"],["78813.04000000","0.00406000"],["78817.17000000","0.00000000"],["78847.43000000","0.00400000"],["78860.29000000","0.00406000"],["78864.41000000","0.00000000"],["78901.61000000","0.00000000"],["78931.16000000","0.00406000"],["78935.29000000","0.00000000"]]}}
{"rx_ns": 11764317300, "frame": {"e":"depthUpdate","E":1787603069214,"s":"BTCUSDT","U":99076626135,"u":99076626159,"b":[["78714.00000000","0.45761000"],["78713.18000000","0.00000000"],["78712.91000000","0.00000000"],["77410.94000000","0.00600000"],["70846.20000000","0.00272000"],["62974.40000000","0.00000000"]],"a":[["78718.00000000","0.97454000"],["78718.01000000","0.00076000"],["78720.38000000","0.05412000"],["78722.00000000","0.02414000"],["78722.68000000","0.00014000"],["78723.71000000","0.31771000"],["78728.78000000","0.00000000"],["78742.10000000","0.00406000"],["78742.17000000","0.00000000"],["78781.48000000","0.00406000"],["78781.55000000","0.00000000"],["78931.09000000","0.00406000"],["78931.16000000","0.00000000"]]}}
{"rx_ns": 11853733700, "frame": {"e":"depthUpdate","E":1787603069314,"s":"BTCUSDT","U":99076626160,"u":99076626170,"b":[["78714.00000000","0.46454000"],["78713.34000000","0.00000000"],["78529.42000000","0.00000000"],["78520.83000000","0.00778000"],["70846.20000000","0.00288000"],["62974.00000000","0.00000000"]],"a":[["78724.57000000","0.00007000"],["78781.46000000","0.00406000"],["78781.48000000","0.00000000"]]}}
{"rx_ns": 11954147700, "frame": {"e":"depthUpdate","E":1787603069414,"s":"BTCUSDT","U":99076626171,"u":99076626208,"b":[["78717.99000000","0.92957000"],["78703.72000000","0.00400000"],["78685.94000000","0.00320000"],["78324.40000000","0.00008000"],["77932.77000000","0.00000000"],["77543.11000000","0.00000000"],["77155.39000000","0.00000000"],["76769.62000000","0.00000000"],["76385.77000000","0.00000000"],["76003.84000000","0.00000000"],["75623.82000000","0.00000000"],["75245.70000000","0.00000000"],["74869.47000000","0.00000000"],["74495.13000000","0.00000000"],["74122.65000000","0.00000000"],["73752.04000000","0.00000000"],["73383.28000000","0.00000000"],["73016.36000000","0.00000000"],["70846.20000000","0.00288000"],["70846.00000000","0.00010000"]],"a":[["78726.62000000","0.00407000"],["78815.74000000","0.00314000"],["79111.59000000","0.00000000"],["79507.15000000","0.00000000"],["79904.69000000","0.00000000"],["80304.21000000","0.00000000"],["80705.73000000","0.00000000"],["81109.26000000","0.00000000"],["81514.81000000","0.00000000"],["81922.38000000","0.00000000"],["82331.99000000","0.00000000"],["82743.65000000","0.00000000"],["83157.37000000","0.00000000"],["83573.16000000","0.00000000"],["83991.02000000","0.00000000"],["84410.98000000","0.00000000"],["84833.03000000","0.00000000"]]}}
{"rx_ns": 12052972000, "frame": {"e":"depthUpdate","E":1787603069514,"s":"BTCUSDT","U":99076626209,"u":99076626220,"b":[["78713.50000000","0.00000000"],["78713.17000000","0.12712000"],["78713.08000000","0.00000000"],["70846.20000000","0.00304000"],["70846.00000000","0.00000000"],["62974.40000000","0.00031000"]],"a":[]}}
{"rx_ns": 12156201500, "frame": {"e":"depthUpdate","E":1787603069614,"s":"BTCUSDT","U":99076626221,"u":99076626252,"b":[["78717.99000000","0.93027000"],["78717.98000000","0.00048000"],["78714.00000000","0.46461000"],["78713.37000000","0.00000000"],["78713.17000000","0.00000000"],["78694.33000000","0.00007000"],["78664.86000000","0.00400000"],["78661.83000000","0.00000000"],["70846.20000000","0.00288000"],["62974.40000000","0.00000000"],["62974.39000000","0.00000000"]],"a":[["78739.69000000","0.06587000"],["78741.57000000","0.00007000"],["78741.65000000","0.07610000"],["78749.00000000","0.70000000"]]}}
{"rx_ns": 12253140400, "kind": "rest", "req": {"method": "GET", "url": "https://data-api.binance.vision/api/v3/depth?symbol=BTCUSDT&limit=100", "limit": 100, "weight": 5, "sent_ns": 11153240300, "status": 200, "used_weight_1m": "10", "recv_ns": 12186910000}, "frame": {"lastUpdateId":99076626252,"bids":[["78717.99000000","0.93027000"],["78717.98000000","0.00048000"],["78717.97000000","0.00013000"],["78717.96000000","0.00014000"],["78717.95000000","0.05014000"],["78717.91000000","0.00014000"],["78717.90000000","0.05007000"],["78717.86000000","0.00014000"],["78717.85000000","0.31776000"],["78717.78000000","0.00007000"],["78717.10000000","0.00008000"],["78716.56000000","0.00007000"],["78716.53000000","0.00014000"],["78716.52000000","0.08816000"],["78716.45000000","0.00007000"],["78716.44000000","0.04039000"],["78716.00000000","0.00237000"],["78715.99000000","0.00007000"],["78715.93000000","0.00007000"],["78715.80000000","0.00007000"],["78715.79000000","0.00007000"],["78715.26000000","0.49024000"],["78715.25000000","0.00007000"],["78714.87000000","0.04780000"],["78714.16000000","0.01390000"],["78714.02000000","1.21952000"],["78714.01000000","0.00007000"],["78714.00000000","0.46461000"],["78713.99000000","0.00419000"],["78713.56000000","0.00007000"],["78713.28000000","0.00400000"],["78712.90000000","0.02317000"],["78712.30000000","0.00007000"],["78712.00000000","0.02400000"],["78711.93000000","0.00014000"],["78711.75000000","0.00317000"],["78711.70000000","0.02200000"],["78711.64000000","0.02780000"],["78711.19000000","0.12704000"],["78710.64000000","0.00010000"],["78710.62000000","0.00010000"],["78710.38000000","0.02780000"],["78710.26000000","0.00400000"],["78710.25000000","0.00007000"],["78710.11000000","0.21930000"],["78710.03000000","1.21952000"],["78710.00000000","0.02400000"],["78709.68000000","0.00007000"],["78709.67000000","0.00319000"],["78709.48000000","0.04000000"],["78709.40000000","0.00008000"],["78709.39000000","0.00152000"],["78709.31000000","0.00027000"],["78709.14000000","0.36224000"],["78708.88000000","0.01000000"],["78708.21000000","0.00007000"],["78708.17000000","0.00007000"],["78708.11000000","0.00324000"],["78708.06000000","0.00014000"],["78708.00000000","0.05007000"],["78707.76000000","0.00400000"],["78707.71000000","0.02007000"],["78707.36000000","0.03224000"],["78707.24000000","0.08576000"],["78707.20000000","0.02800000"],["78707.01000000","0.00007000"],["78706.67000000","0.00635000"],["78706.66000000","1.90515000"],["78706.28000000","0.00635000"],["78706.27000000","0.02000000"],["78706.17000000","0.00007000"],["78706.16000000","0.00007000"],["78706.05000000","0.00126000"],["78706.00000000","0.15105000"],["78705.87000000","0.00191000"],["78705.80000000","0.00007000"],["78705.79000000","0.00332000"],["78705.28000000","0.00400000"],["78704.97000000","0.02000000"],["78704.56000000","0.00007000"],["78704.34000000","0.02200000"],["78704.19000000","0.00014000"],["78704.12000000","0.00007000"],["78704.00000000","0.02400000"],["78703.72000000","0.00400000"],["78703.71000000","0.00595000"],["78703.57000000","1.21952000"],["78703.54000000","0.00254000"],["78702.80000000","0.00400000"],["78702.77000000","0.00010000"],["78702.46000000","0.00400000"],["78702.45000000","0.02400000"],["78702.24000000","0.00007000"],["78702.07000000","0.00007000"],["78702.00000000","0.02400000"],["78701.92000000","0.00007000"],["78701.87000000","0.00321000"],["78701.85000000","0.00321000"],["78701.79000000","0.02800000"],["78701.70000000","0.00008000"]],"asks":[["78718.00000000","0.97454000"],["78718.01000000","0.00076000"],["78718.02000000","0.00013000"],["78719.15000000","0.00007000"],["78719.25000000","0.00014000"],["78719.26000000","0.04041000"],["78719.42000000","0.00014000"],["78719.43000000","0.26056000"],["78719.67000000","0.00014000"],["78719.70000000","0.00332000"],["78719.87000000","0.00007000"],["78719.99000000","0.00014000"],["78720.00000000","0.03107000"],["78720.01000000","0.00020000"],["78720.21000000","0.00324000"],["78720.37000000","0.00014000"],["78720.38000000","0.05412000"],["78720.51000000","0.00007000"],["78720.52000000","0.04848000"],["78721.45000000","0.00007000"],["78721.67000000","0.00327000"],["78721.77000000","0.00254000"],["78721.78000000","0.04848000"],["78722.00000000","0.02414000"],["78722.01000000","0.00014000"],["78722.68000000","0.00014000"],["78723.47000000","0.00254000"],["78723.48000000","0.00007000"],["78723.54000000","0.00014000"],["78723.55000000","0.00007000"],["78723.71000000","0.31771000"],["78723.72000000","0.00321000"],["78724.00000000","0.02400000"],["78724.01000000","0.00007000"],["78724.57000000","0.00007000"],["78724.59000000","0.02161000"],["78724.60000000","0.00137000"],["78724.61000000","0.02064000"],["78724.62000000","0.02782000"],["78725.12000000","0.38115000"],["78725.20000000","0.00007000"],["78725.23000000","0.00007000"],["78725.29000000","0.00325000"],["78725.46000000","0.00400000"],["78726.00000000","0.02400000"],["78726.13000000","0.00635000"],["78726.15000000","0.02286000"],["78726.33000000","0.00254000"],["78726.45000000","0.00318000"],["78726.62000000","0.00407000"],["78726.63000000","0.00007000"],["78727.41000000","0.00014000"],["78727.76000000","0.00007000"],["78727.81000000","1.21952000"],["78727.82000000","0.25410000"],["78727.84000000","0.02161000"],["78727.85000000","0.12701000"],["78727.89000000","0.21930000"],["78728.00000000","0.02400000"],["78728.01000000","0.04782000"],["78728.11000000","0.02000000"],["78728.32000000","0.09414000"],["78728.56000000","0.00327000"],["78728.66000000","0.00007000"],["78729.00000000","0.00007000"],["78729.07000000","0.02000000"],["78729.08000000","0.00007000"],["78729.60000000","0.00400000"],["78729.68000000","0.11793000"],["78729.78000000","0.00007000"],["78729.83000000","0.00007000"],["78730.00000000","0.02400000"],["78730.33000000","0.01000000"],["78730.63000000","0.02000000"],["78730.70000000","0.00191000"],["78730.71000000","0.00007000"],["78730.83000000","0.04000000"],["78730.98000000","0.02000000"],["78731.28000000","0.02014000"],["78731.33000000","0.08000000"],["78731.83000000","0.00007000"],["78732.00000000","0.02400000"],["78732.08000000","0.02000000"],["78732.10000000","0.02000000"],["78732.50000000","0.00008000"],["78732.55000000","0.00400000"],["78732.76000000","0.00007000"],["78732.84000000","1.21952000"],["78732.85000000","0.02000000"],["78732.86000000","0.02600000"],["78732.90000000","0.04000000"],["78732.96000000","0.00007000"],["78733.74000000","0.00007000"],["78733.75000000","0.04067000"],["78734.00000000","0.02400000"],["78734.01000000","0.00007000"],["78734.19000000","0.02161000"],["78734.20000000","0.00327000"],["78734.27000000","0.04857000"],["78734.79000000","0.00227000"]]}}
{"rx_ns": 12253140400, "frame": {"e":"depthUpdate","E":1787603069714,"s":"BTCUSDT","U":99076626253,"u":99076626284,"b":[["78717.99000000","0.67253000"],["78714.00000000","0.46454000"],["78713.25000000","0.00000000"],["78712.98000000","0.00000000"],["78709.48000000","0.00000000"],["78696.87000000","0.04000000"],["78681.00000000","0.70000000"],["70846.20000000","0.00320000"]],"a":[["78718.00000000","0.97426000"],["78718.01000000","0.00069000"],["78720.37000000","0.00268000"],["78723.47000000","0.00000000"],["78727.80000000","1.90515000"],["78784.63000000","0.00007000"],["78800.64000000","0.00000000"]]}}
{"rx_ns": 12353844500, "frame": {"e":"depthUpdate","E":1787603069814,"s":"BTCUSDT","U":99076626285,"u":99076626298,"b":[["78717.99000000","0.67254000"],["78714.00000000","0.46461000"],["78712.11000000","0.12712000"],["78648.90000000","0.02600000"],["78633.65000000","0.02116000"],["70846.20000000","0.00320000"]],"a":[["78718.00000000","0.97461000"],["78720.37000000","0.00014000"],["78721.44000000","0.00254000"]]}}
{"rx_ns": 12462757400, "frame": {"e":"depthUpdate","E":1787603069914,"s":"BTCUSDT","U":99076626299,"u":99076626337,"b":[["78717.99000000","0.71763000"],["78714.00000000","0.46454000"],["78712.11000000","0.00000000"],["78633.65000000","0.00000000"],["78324.40000000","0.01008000"],["77932.77000000","0.01000000"],["77543.11000000","0.01000000"],["77155.39000000","0.01000000"],["76769.62000000","0.01000000"],["76385.77000000","0.01000000"],["76003.84000000","0.01000000"],["75623.82000000","0.01000000"],["75245.70000000","0.01000000"],["74869.47000000","0.01000000"],["74495.13000000","0.01000000"],["74122.65000000","0.01000000"],["73752.04000000","0.01000000"],["73383.28000000","0.01000000"],["73016.36000000","0.01000000"],["70846.20000000","0.00320000"]],"a":[["78718.00000000","0.97461000"],["79111.59000000","0.01000000"],["79507.15000000","0.01000000"],["79904.69000000","0.01000000"],["80304.21000000","0.01000000"],["80705.73000000","0.01000000"],["81109.26000000","0.01000000"],["81514.81000000","0.01000000"],["81922.38000000","0.01000000"],["82331.99000000","0.01000000"],["82743.65000000","0.01000000"],["83157.37000000","0.01000000"],["83573.16000000","0.01000000"],["83991.02000000","0.01000000"],["84410.98000000","0.01000000"],["84833.03000000","0.01000000"]]}}
{"rx_ns": 12553275800, "frame": {"e":"depthUpdate","E":1787603070014,"s":"BTCUSDT","U":99076626338,"u":99076626339,"b":[["70846.20000000","0.00336000"],["62974.40000000","0.00031000"]],"a":[]}}
{"rx_ns": 12657709100, "frame": {"e":"depthUpdate","E":1787603070114,"s":"BTCUSDT","U":99076626340,"u":99076626393,"b":[["78711.95000000","0.00000000"],["78711.71000000","0.00000000"],["78711.70000000","0.14912000"],["78706.11000000","0.00007000"],["78703.72000000","0.00800000"],["78680.32000000","0.00000000"],["78676.91000000","0.09655000"],["78668.52000000","0.00007000"],["78664.19000000","0.02541000"],["78652.78000000","0.00007000"],["78637.50000000","0.02541000"],["78637.04000000","0.00007000"],["78625.56000000","0.02541000"],["78621.30000000","0.00007000"],["78605.56000000","0.00007000"],["78589.82000000","0.00007000"],["78585.34000000","0.00000000"],["78574.08000000","0.00007000"],["78562.32000000","1.52477000"],["78558.34000000","0.00007000"],["78542.60000000","0.00007000"],["78526.86000000","0.00007000"],["78511.12000000","0.00007000"],["78495.38000000","0.00007000"],["78479.64000000","0.00133000"],["70846.20000000","0.00352000"],["70846.00000000","0.00040000"]],"a":[["78729.74000000","0.00007000"],["78731.48000000","0.00007000"],["78747.22000000","0.00007000"],["78762.96000000","0.00007000"],["78778.70000000","0.00015000"],["78794.44000000","0.00007000"],["78810.18000000","0.00007000"],["78825.92000000","0.00007000"],["78841.66000000","0.00007000"],["78857.40000000","0.00007000"],["78861.42000000","1.52477000"],["78873.14000000","0.00007000"],["78888.88000000","0.00017000"],["78904.62000000","0.00007000"],["78920.36000000","0.00007000"],["78936.10000000","0.00007000"],["78951.84000000","0.00007000"],["86422.88000000","0.20801000"]]}}
{"rx_ns": 12752842100, "frame": {"e":"depthUpdate","E":1787603070214,"s":"BTCUSDT","U":99076626394,"u":99076626409,"b":[["78717.99000000","0.93699000"],["78714.00000000","0.46461000"],["78711.75000000","0.00000000"],["78703.72000000","0.01200000"],["70846.20000000","0.00368000"],["70846.00000000","0.00010000"],["62974.40000000","0.00000000"]],"a":[["78720.38000000","0.05419000"],["78722.69000000","0.01270000"],["78722.73000000","0.06350000"],["84202.54000000","0.00442000"]]}}
{"rx_ns": 12854023100, "frame": {"e":"depthUpdate","E":1787603070314,"s":"BTCUSDT","U":99076626410,"u":99076626427,"b":[["78717.99000000","0.71770000"],["78711.70000000","0.02200000"],["78703.58000000","0.00400000"],["70846.00000000","0.00000000"],["62974.00000000","0.00000000"]],"a":[["78722.00000000","0.02414000"],["78722.52000000","0.00007000"],["78722.69000000","0.01277000"],["78723.71000000","0.31764000"],["84202.54000000","0.00884000"]]}}
{"rx_ns": 12953493500, "frame": {"e":"depthUpdate","E":1787603070414,"s":"BTCUSDT","U":99076626428,"u":99076626470,"b":[["78717.99000000","0.71840000"],["78712.19000000","0.00000000"],["78711.39000000","0.12712000"],["78709.74000000","0.00400000"],["78666.70000000","0.00400000"],["78664.86000000","0.00000000"],["78520.83000000","0.00000000"],["78518.23000000","0.00785000"],["78324.40000000","0.00008000"],["77932.77000000","0.00000000"],["77543.11000000","0.00000000"],["77155.39000000","0.00000000"],["76769.62000000","0.00000000"],["76385.77000000","0.00000000"],["76003.84000000","0.00000000"],["75623.82000000","0.00000000"],["75245.70000000","0.00000000"],["74869.47000000","0.00000000"],["74495.13000000","0.00000000"],["74122.65000000","0.00000000"],["73752.04000000","0.00000000"],["73383.28000000","0.00000000"],["73016.36000000","0.00000000"],["70846.20000000","0.00384000"]],"a":[["78735.58000000","0.00400000"],["78770.66000000","0.00000000"],["79111.59000000","0.00000000"],["79507.15000000","0.00000000"],["79904.69000000","0.00000000"],["80304.21000000","0.00000000"],["80705.73000000","0.00000000"],["81109.26000000","0.00000000"],["81514.81000000","0.00000000"],["81922.38000000","0.00000000"],["82331.99000000","0.00000000"],["82743.65000000","0.00000000"],["83157.37000000","0.00000000"],["83573.16000000","0.00000000"],["83991.02000000","0.00000000"],["84410.98000000","0.00000000"],["84833.03000000","0.00000000"]]}}
{"rx_ns": 13052995600, "frame": {"e":"depthUpdate","E":1787603070514,"s":"BTCUSDT","U":99076626471,"u":99076626480,"b":[["78717.99000000","0.82340000"],["78714.00000000","0.46468000"],["78636.75000000","0.02116000"],["70846.20000000","0.00384000"],["70846.00000000","0.00010000"],["62974.40000000","0.00031000"]],"a":[]}}
{"rx_ns": 13158961200, "frame": {"e":"depthUpdate","E":1787603070614,"s":"BTCUSDT","U":99076626481,"u":99076626493,"b":[["78708.67000000","0.00400000"],["78706.83000000","0.00048000"],["78694.33000000","0.00000000"],["78664.19000000","0.00000000"],["78636.75000000","0.00000000"],["70846.20000000","0.00409000"],["70846.00000000","0.00010000"],["62974.40000000","0.00000000"],["62974.39000000","0.00020000"]],"a":[["78718.00000000","0.94014000"],["78722.85000000","0.00400000"],["78741.57000000","0.00000000"]]}}
{"rx_ns": 13252627900, "frame": {"e":"depthUpdate","E":1787603070714,"s":"BTCUSDT","U":99076626494,"u":99076626569,"b":[["78717.99000000","0.82347000"],["78694.33000000","0.00007000"],["78671.38000000","0.00007000"],["78615.82000000","2.77178000"],["78610.60000000","0.00000000"],["78583.34000000","0.01990000"],["78577.31000000","0.00000000"],["70846.20000000","0.00409000"],["70846.00000000","0.00000000"],["62974.39000000","0.00000000"]],"a":[["78718.00000000","0.94014000"],["78741.57000000","0.00007000"]]}}
{"rx_ns": 13361098800, "frame": {"e":"depthUpdate","E":1787603070822,"s":"BTCUSDT","U":99076626570,"u":99076626579,"b":[["78717.99000000","0.82374000"],["78520.83000000","0.00778000"],["78518.23000000","0.00007000"],["70846.20000000","0.00425000"],["62974.00000000","0.00000000"]],"a":[["78937.55000000","0.00000000"]]}}
{"rx_ns": 13452892100, "frame": {"e":"depthUpdate","E":1787603070914,"s":"BTCUSDT","U":99076626580,"u":99076626580,"b":[],"a":[["78729.13000000","0.00048000"]]}}
{"rx_ns": 13553600100, "frame": {"e":"depthUpdate","E":1787603071014,"s":"BTCUSDT","U":99076626581,"u":99076626634,"b":[["78717.99000000","0.82326000"],["78707.92000000","0.00048000"],["78684.00000000","0.72400000"],["78681.00000000","0.00000000"],["78324.40000000","0.01008000"],["77932.77000000","0.01000000"],["77543.11000000","0.01000000"],["77155.39000000","0.01000000"],["76769.62000000","0.01000000"],["76385.77000000","0.01000000"],["76003.84000000","0.01000000"],["75623.82000000","0.01000000"],["75245.70000000","0.01000000"],["74869.47000000","0.01000000"],["74495.13000000","0.01000000"],["74122.65000000","0.01000000"],["73752.04000000","0.01000000"],["73383.28000000","0.01000000"],["73016.36000000","0.01000000"],["70846.20000000","0.00441000"],["62974.40000000","0.00031000"],["62974.00000000","0.00000000"]],"a":[["78718.00000000","0.94014000"],["79111.59000000","0.01000000"],["79507.15000000","0.01000000"],["79904.69000000","0.01000000"],["80304.21000000","0.01000000"],["80705.73000000","0.01000000"],["81109.26000000","0.01000000"],["81514.81000000","0.01000000"],["81922.38000000","0.01000000"],["82331.99000000","0.01000000"],["82743.65000000","0.01000000"],["83157.37000000","0.01000000"],["83573.16000000","0.01000000"],["83991.02000000","0.01000000"],["84410.98000000","0.01000000"],["84833.03000000","0.01000000"]]}}
{"rx_ns": 13653606500, "kind": "control", "ctl": {"op": "ping", "recv_ns": 13559412000, "pong_ns": 13559502500, "payload_len": 13, "payload_b64": "MTc4NzYwMzA3MTAxNw=="}, "frame": null}
{"rx_ns": 13653606500, "frame": {"e":"depthUpdate","E":1787603071114,"s":"BTCUSDT","U":99076626635,"u":99076626679,"b":[["78717.99000000","1.28943000"],["78714.00000000","0.46461000"],["78711.69000000","1.90515000"],["78711.39000000","0.00000000"],["78710.17000000","0.00328000"],["78707.92000000","0.00000000"],["78698.99000000","0.00000000"],["78695.87000000","0.00406000"],["78659.64000000","0.00000000"],["78656.52000000","0.00406000"],["78628.16000000","0.00000000"],["78625.04000000","0.00406000"],["78580.94000000","0.00000000"],["78577.82000000","0.00406000"],["78510.11000000","0.00000000"],["78506.99000000","0.00406000"],["70846.20000000","0.00425000"]],"a":[["78718.00000000","0.87943000"],["78720.38000000","0.05412000"],["78721.44000000","0.00000000"],["78721.77000000","0.00000000"],["78722.51000000","0.00508000"],["78723.71000000","0.00000000"],["78725.11000000","0.31765000"],["78727.80000000","0.00000000"],["78727.81000000","0.00000000"],["78728.43000000","0.00048000"],["78786.43000000","1.21952000"],["78800.64000000","1.90515000"]]}}
{"rx_ns": 13753262600, "frame": {"e":"depthUpdate","E":1787603071214,"s":"BTCUSDT","U":99076626680,"u":99076626717,"b":[["78717.99000000","3.39531000"],["78714.88000000","0.00635000"],["78712.31000000","0.00635000"],["78706.83000000","0.00000000"],["78706.67000000","0.00000000"],["78706.28000000","0.00000000"],["70846.20000000","0.00432000"],["70846.19000000","0.00009000"],["70846.00000000","0.00000000"],["62974.40000000","0.00000000"]],"a":[["78718.00000000","0.87712000"],["78719.70000000","0.00000000"],["78722.00000000","0.02414000"],["78722.51000000","0.00007000"],["78722.68000000","0.00007000"],["78722.69000000","0.01270000"],["78722.85000000","0.00000000"],["78723.99000000","0.00000000"],["78724.60000000","0.00000000"],["78725.11000000","0.00508000"],["78726.12000000","0.00000000"],["78726.13000000","0.00000000"],["78726.45000000","0.00718000"],["78726.61000000","0.00137000"],["78726.62000000","0.00007000"],["78727.81000000","0.31764000"],["78728.99000000","0.00635000"],["78730.97000000","0.00400000"],["78733.08000000","0.00192000"]]}}
{"rx_ns": 13853128700, "frame": {"e":"depthUpdate","E":1787603071314,"s":"BTCUSDT","U":99076626718,"u":99076626751,"b":[["78715.26000000","0.49024000"],["78699.64000000","0.00406000"],["78695.87000000","0.00000000"],["78660.29000000","0.00406000"],["78656.52000000","0.00000000"],["78628.81000000","0.00406000"],["78625.04000000","0.00000000"],["78581.59000000","0.00406000"],["78577.82000000","0.00000000"],["78510.76000000","0.00406000"],["78506.99000000","0.00000000"],["70846.20000000","0.00416000"],["62974.00000000","0.00000000"]],"a":[["78718.00000000","0.87712000"],["78718.01000000","0.00069000"],["78720.38000000","0.05405000"],["78722.00000000","0.02414000"],["78722.51000000","0.00000000"],["78722.69000000","0.00007000"],["78722.73000000","0.00000000"]]}}
{"rx_ns": 13954459600, "frame": {"e":"depthUpdate","E":1787603071414,"s":"BTCUSDT","U":99076626752,"u":99076626763,"b":[["78677.52000000","0.00007000"],["78660.29000000","0.00000000"],["78581.59000000","0.00000000"],["78510.76000000","0.00406000"],["70846.20000000","0.00432000"]],"a":[["78722.00000000","0.02414000"],["78722.69000000","0.00000000"],["78724.00000000","0.02407000"]]}}
{"rx_ns": 14053501500, "frame": {"e":"depthUpdate","E":1787603071514,"s":"BTCUSDT","U":99076626764,"u":99076626796,"b":[["78714.00000000","0.46565000"],["78324.40000000","0.00008000"],["77932.77000000","0.00000000"],["77543.11000000","0.00000000"],["77155.39000000","0.00000000"],["76769.62000000","0.00000000"],["76385.77000000","0.00000000"],["76003.84000000","0.00000000"],["75623.82000000","0.00000000"],["75245.70000000","0.00000000"],["74869.47000000","0.00000000"],["74495.13000000","0.00000000"],["74122.65000000","0.00000000"],["73752.04000000","0.00000000"],["73383.28000000","0.00000000"],["73016.36000000","0.00000000"],["70846.20000000","0.00416000"],["62974.40000000","0.00031000"]],"a":[["79111.59000000","0.00000000"],["79507.15000000","0.00000000"],["79904.69000000","0.00000000"],["80304.21000000","0.00000000"],["80705.73000000","0.00000000"],["81109.26000000","0.00000000"],["81514.81000000","0.00000000"],["81922.38000000","0.00000000"],["82331.99000000","0.00000000"],["82743.65000000","0.00000000"],["83157.37000000","0.00000000"],["83573.16000000","0.00000000"],["83991.02000000","0.00000000"],["84410.98000000","0.00000000"],["84833.03000000","0.00000000"]]}}
{"rx_ns": 14153117700, "frame": {"e":"depthUpdate","E":1787603071614,"s":"BTCUSDT","U":99076626797,"u":99076626805,"b":[["78713.40000000","0.26049000"],["78660.29000000","0.00406000"],["78636.75000000","0.02116000"],["77153.78000000","0.00567000"],["76999.47000000","0.00328000"],["70846.20000000","0.00432000"],["62974.40000000","0.00000000"]],"a":[]}}
{"rx_ns": 14253123400, "frame": {"e":"depthUpdate","E":1787603071714,"s":"BTCUSDT","U":99076626806,"u":99076626824,"b":[["78717.99000000","3.20183000"],["78714.00000000","0.46572000"],["78694.33000000","0.00007000"],["78667.29000000","0.00007000"],["78636.75000000","0.00000000"],["76845.47000000","0.00375000"],["76691.77000000","0.00430000"],["70846.20000000","0.00448000"],["62974.39000000","0.00000000"]],"a":[["78718.00000000","0.87698000"],["78741.57000000","0.00007000"]]}}
{"rx_ns": 14354512600, "frame": {"e":"depthUpdate","E":1787603071814,"s":"BTCUSDT","U":99076626825,"u":99076626841,"b":[["78717.99000000","2.98253000"],["78713.70000000","0.00322000"],["78711.59000000","0.12712000"],["78660.29000000","0.00000000"],["78636.75000000","0.02116000"],["78581.59000000","0.00000000"],["78510.76000000","0.00000000"],["76538.38000000","0.00518000"],["70846.20000000","0.00416000"]],"a":[["78718.00000000","1.27615000"],["78738.07000000","0.18401000"],["78761.84000000","0.00662000"],["78800.59000000","0.00000000"]]}}
{"rx_ns": 14455625100, "frame": {"e":"depthUpdate","E":1787603071914,"s":"BTCUSDT","U":99076626842,"u":99076626858,"b":[["78715.80000000","0.00014000"],["78711.59000000","0.00000000"],["78711.32000000","0.00000000"],["78711.18000000","0.00000000"],["78711.11000000","0.00000000"],["78678.18000000","0.00400000"],["78677.10000000","0.00000000"],["78666.70000000","0.00000000"],["78529.42000000","0.00778000"],["78520.83000000","0.00000000"],["70846.20000000","0.00448000"]],"a":[["78718.00000000","1.27807000"],["78733.08000000","0.00000000"],["79103.65000000","0.00635000"]]}}
{"rx_ns": 14553601600, "frame": {"e":"depthUpdate","E":1787603072014,"s":"BTCUSDT","U":99076626859,"u":99076626896,"b":[["78636.75000000","0.00000000"],["78581.59000000","0.00406000"],["78324.40000000","0.01008000"],["77932.77000000","0.01000000"],["77543.11000000","0.01000000"],["77155.39000000","0.01000000"],["76769.62000000","0.01000000"],["76385.77000000","0.01000000"],["76003.84000000","0.01000000"],["75623.82000000","0.01000000"],["75245.70000000","0.01000000"],["74869.47000000","0.01000000"],["74495.13000000","0.01000000"],["74122.65000000","0.01000000"],["73752.04000000","0.01000000"],["73383.28000000","0.01000000"],["73016.36000000","0.01000000"],["70846.20000000","0.00432000"],["62974.40000000","0.00031000"]],"a":[["78718.00000000","0.87890000"],["78754.01000000","0.00200000"],["79111.59000000","0.01000000"],["79507.15000000","0.01000000"],["79904.69000000","0.01000000"],["80304.21000000","0.01000000"],["80705.73000000","0.01000000"],["81109.26000000","0.01000000"],["81514.81000000","0.01000000"],["81922.38000000","0.01000000"],["82331.99000000","0.01000000"],["82743.65000000","0.01000000"],["83157.37000000","0.01000000"],["83573.16000000","0.01000000"],["83991.02000000","0.01000000"],["84410.98000000","0.01000000"],["84833.03000000","0.01000000"]]}}
{"rx_ns": 14658954000, "frame": {"e":"depthUpdate","E":1787603072114,"s":"BTCUSDT","U":99076626897,"u":99076626912,"b":[["78711.49000000","0.00000000"],["78684.29000000","0.00000000"],["78678.61000000","0.02497000"],["78533.91000000","0.00000000"],["70846.20000000","0.00448000"]],"a":[["78718.00000000","0.87890000"],["78720.21000000","0.00000000"],["78720.73000000","0.00329000"],["78721.67000000","0.00000000"],["78763.02000000","0.00000000"]]}}
{"rx_ns": 14755161800, "frame": {"e":"depthUpdate","E":1787603072214,"s":"BTCUSDT","U":99076626913,"u":99076626918,"b":[["78711.18000000","0.12712000"],["78660.29000000","0.00406000"],["70846.20000000","0.00432000"],["62974.40000000","0.00000000"]],"a":[["78808.94000000","0.93647000"],["78811.55000000","0.00000000"]]}}
{"rx_ns": 14855618900, "frame": {"e":"depthUpdate","E":1787603072314,"s":"BTCUSDT","U":99076626919,"u":99076626944,"b":[["78636.75000000","0.02116000"],["70846.20000000","0.00448000"],["70846.00000000","0.00000000"],["62974.00000000","0.00000000"]],"a":[["78718.00000000","1.36005000"],["78718.01000000","0.00076000"],["78720.38000000","0.05412000"],["78720.77000000","0.01270000"],["78720.81000000","0.06350000"],["78726.44000000","0.31763000"],["78727.81000000","0.00000000"],["78757.33000000","0.02543000"]]}}
{"rx_ns": 14957237600, "frame": {"e":"depthUpdate","E":1787603072414,"s":"BTCUSDT","U":99076626945,"u":99076626978,"b":[["78715.80000000","0.00007000"],["78712.35000000","0.00327000"],["78711.18000000","0.00000000"],["78700.91000000","0.38123000"],["78692.56000000","0.34314000"],["78681.61000000","0.00007000"],["78680.60000000","0.00000000"],["78677.92000000","0.00000000"],["78677.10000000","0.00007000"],["78660.29000000","0.00000000"],["78645.90000000","0.00200000"],["78636.75000000","0.00000000"],["78581.59000000","0.00000000"],["78534.05000000","4.66419000"],["78510.76000000","0.00406000"],["70846.20000000","0.00432000"],["62974.00000000","0.00300000"]],"a":[["78718.00000000","0.87904000"],["78718.01000000","0.00076000"],["78720.52000000","0.04848000"],["78720.73000000","0.00000000"],["78720.77000000","0.01277000"],["78720.81000000","0.06357000"],["78720.95000000","0.00324000"],["78722.00000000","0.02407000"],["78724.00000000","0.02400000"],["78726.44000000","0.00000000"],["78727.81000000","0.31763000"]]}}
{"rx_ns": 15053048100, "frame": {"e":"depthUpdate","E":1787603072514,"s":"BTCUSDT","U":99076626979,"u":99076627019,"b":[["78711.74000000","0.00000000"],["78711.70000000","0.02200000"],["78324.40000000","0.00008000"],["77932.77000000","0.00000000"],["77543.11000000","0.00000000"],["77155.39000000","0.00000000"],["76769.62000000","0.00000000"],["76385.77000000","0.00000000"],["76003.84000000","0.00000000"],["75623.82000000","0.00000000"],["75245.70000000","0.00000000"],["74869.47000000","0.00000000"],["74495.13000000","0.00000000"],["74122.65000000","0.00000000"],["73752.04000000","0.00000000"],["73383.28000000","0.00000000"],["73016.36000000","0.00000000"],["70846.20000000","0.00448000"],["62974.40000000","0.00031000"],["62974.00000000","0.00000000"]],"a":[["78718.00000000","0.87911000"],["78721.16000000","0.00325000"],["78812.84000000","0.00529000"],["79111.59000000","0.00000000"],["79507.15000000","0.00000000"],["79904.69000000","0.00000000"],["80304.21000000","0.00000000"],["80705.73000000","0.00000000"],["80800.00000000","9.81193000"],["81109.26000000","0.00000000"],["81514.81000000","0.00000000"],["81922.38000000","0.00000000"],["82331.99000000","0.00000000"],["82743.65000000","0.00000000"],["83157.37000000","0.00000000"],["83573.16000000","0.00000000"],["83991.02000000","0.00000000"],["84410.98000000","0.00000000"],["84833.03000000","0.00000000"]]}}
{"rx_ns": 15153587400, "frame": {"e":"depthUpdate","E":1787603072614,"s":"BTCUSDT","U":99076627020,"u":99076627026,"b":[["78660.29000000","0.00406000"],["77911.45000000","0.00400000"],["77100.37000000","0.00000000"],["70846.20000000","0.00432000"],["62974.40000000","0.00000000"]],"a":[["78718.00000000","0.87704000"]]}}
{"rx_ns": 15253241800, "frame": {"e":"depthUpdate","E":1787603072714,"s":"BTCUSDT","U":99076627027,"u":99076627040,"b":[["78694.33000000","0.00007000"],["78665.25000000","0.00007000"],["78636.75000000","0.02116000"],["70846.20000000","0.00432000"],["62974.39000000","0.00000000"]],"a":[["78741.57000000","0.00007000"],["80720.20000000","0.00000000"]]}}
{"rx_ns": 15354565200, "frame": {"e":"depthUpdate","E":1787603072814,"s":"BTCUSDT","U":99076627041,"u":99076627129,"b":[["78717.99000000","2.98253000"],["78717.98000000","0.00055000"],["78717.97000000","0.00027000"],["78717.96000000","1.21952000"],["78717.91000000","0.00000000"],["78716.45000000","0.00000000"],["78715.82000000","0.00318000"],["78715.80000000","0.00014000"],["78715.27000000","0.00014000"],["78714.38000000","0.02000000"],["78714.03000000","0.00007000"],["78713.18000000","0.00000000"],["78704.97000000","0.00000000"],["78678.61000000","0.00000000"],["78677.10000000","0.00000000"],["78674.44000000","0.02462000"],["78581.59000000","0.00000000"],["78510.76000000","0.00000000"]],"a":[["78718.00000000","0.67435000"],["78720.77000000","0.00007000"],["78720.81000000","0.00007000"],["78720.95000000","0.00000000"],["78721.16000000","0.00000000"],["78723.72000000","0.00000000"],["78724.59000000","0.00000000"],["78725.11000000","0.00000000"],["78725.99000000","0.00508000"],["78726.45000000","0.00318000"],["78727.77000000","0.00000000"],["78728.01000000","0.05182000"],["78730.97000000","0.00000000"],["78730.98000000","0.00000000"],["78732.07000000","0.00000000"],["78732.54000000","0.00400000"],["78732.60000000","0.02000000"],["78732.83000000","1.21952000"],["78732.84000000","0.00000000"],["78757.33000000","0.00007000"],["78764.63000000","0.00000000"],["78796.67000000","0.00000000"],["79030.09000000","7.59291000"]]}}
{"rx_ns": 15452973400, "frame": {"e":"depthUpdate","E":1787603072914,"s":"BTCUSDT","U":99076627130,"u":99076627165,"b":[["78717.99000000","2.98260000"],["78717.98000000","0.00062000"],["78717.96000000","1.21959000"],["78714.87000000","0.04773000"],["78636.75000000","0.00000000"],["70846.20000000","0.00432000"]],"a":[["78718.00000000","0.67421000"],["78718.01000000","0.00069000"],["78720.38000000","0.05405000"],["78720.52000000","0.04848000"],["78720.77000000","0.00000000"],["78720.81000000","0.00000000"],["78722.00000000","0.02414000"],["78724.00000000","0.02407000"],["78724.32000000","0.00317000"],["78753.17000000","0.02506000"],["78756.00000000","0.02400000"]]}}
{"rx_ns": 15557274500, "frame": {"e":"depthUpdate","E":1787603073014,"s":"BTCUSDT","U":99076627166,"u":99076627205,"b":[["78636.75000000","0.02116000"],["78581.59000000","0.00406000"],["78324.40000000","0.01008000"],["77932.77000000","0.01000000"],["77543.11000000","0.01000000"],["77155.39000000","0.01000000"],["76769.62000000","0.01000000"],["76385.77000000","0.01000000"],["76003.84000000","0.01000000"],["75623.82000000","0.01000000"],["75245.70000000","0.01000000"],["74869.47000000","0.01000000"],["74495.13000000","0.01000000"],["74122.65000000","0.01000000"],["73752.04000000","0.01000000"],["73383.28000000","0.01000000"],["73016.36000000","0.01000000"],["70846.20000000","0.00432000"],["62974.40000000","0.00031000"]],"a":[["78718.00000000","0.89338000"],["78718.10000000","0.22187000"],["79111.59000000","0.01000000"],["79507.15000000","0.01000000"],["79904.69000000","0.01000000"],["80304.21000000","0.01000000"],["80705.73000000","0.01000000"],["81109.26000000","0.01000000"],["81514.81000000","0.01000000"],["81922.38000000","0.01000000"],["82331.99000000","0.01000000"],["82743.65000000","0.01000000"],["83157.37000000","0.01000000"],["83573.16000000","0.01000000"],["83991.02000000","0.01000000"],["84410.98000000","0.01000000"],["84833.03000000","0.01000000"]]}}
{"rx_ns": 15656068700, "frame": {"e":"depthUpdate","E":1787603073114,"s":"BTCUSDT","U":99076627206,"u":99076627591,"b":[["78717.99000000","0.19403000"],["78717.98000000","0.00048000"],["78717.97000000","0.00013000"],["78717.96000000","0.00021000"],["78717.91000000","0.00014000"],["78717.86000000","0.00000000"],["78717.85000000","0.00014000"],["78717.10000000","0.00000000"],["78716.45000000","0.00000000"],["78716.44000000","0.00007000"],["78715.82000000","0.00000000"],["78715.80000000","0.00007000"],["78714.88000000","0.00014000"],["78714.38000000","0.00000000"],["78714.14000000","0.04032000"],["78714.03000000","1.21952000"],["78714.02000000","0.00000000"],["78714.01000000","0.00007000"],["78714.00000000","0.24284000"],["78713.40000000","0.00000000"],["78712.31000000","0.00000000"],["78711.93000000","0.00007000"],["78711.70000000","1.92715000"],["78711.69000000","0.00000000"],["78711.57000000","0.00000000"],["78711.19000000","0.00000000"],["78710.14000000","0.31765000"],["78710.12000000","0.00000000"],["78710.11000000","0.21930000"],["78710.06000000","0.12712000"],["78709.74000000","0.00000000"],["78709.31000000","0.00000000"],["78709.14000000","0.00000000"],["78708.97000000","0.00027000"],["78708.88000000","0.00000000"],["78708.67000000","0.00000000"],["78708.62000000","0.00000000"],["78708.47000000","0.02000000"],["78708.22000000","0.00000000"],["78707.95000000","0.00000000"],["78707.71000000","0.00007000"],["78707.36000000","0.00000000"],["78707.12000000","0.00000000"],["78707.10000000","0.00000000"],["78707.02000000","0.00000000"],["78707.01000000","0.00007000"],["78706.91000000","0.00000000"],["78706.87000000","0.00000000"],["78706.81000000","0.00000000"],["78706.75000000","0.00000000"],["78706.68000000","0.00000000"],["78706.65000000","0.00000000"],["78706.62000000","0.00048000"],["78706.47000000","0.00000000"],["78706.27000000","0.00000000"],["78705.99000000","0.00000000"],["78705.81000000","0.00000000"],["78705.58000000","0.00000000"],["78705.42000000","0.00000000"],["78705.40000000","0.00000000"],["78705.35000000","0.00000000"],["78705.32000000","0.00000000"],["78705.30000000","0.00000000"],["78705.29000000","0.00635000"],["78705.27000000","0.00000000"],["78705.24000000","0.00000000"],["78705.05000000","0.00000000"],["78704.67000000","0.00000000"],["78704.57000000","0.00000000"],["78703.87000000","0.01000000"],["78703.72000000","0.00000000"],["78703.58000000","0.00000000"],["78703.47000000","0.02000000"],["78702.46000000","0.00000000"],["78702.08000000","0.00400000"],["78702.05000000","0.00000000"],["78701.93000000","0.00000000"],["78701.88000000","0.00635000"],["78701.48000000","0.00000000"],["78700.91000000","0.00000000"],["78700.36000000","0.00400000"],["78699.38000000","0.00000000"],["78693.45000000","0.00000000"],["78692.56000000","0.00000000"],["78685.94000000","0.00000000"],["78680.82000000","0.00314000"],["78679.75000000","0.63556000"],["78677.10000000","0.00007000"],["78676.55000000","0.34321000"],["78675.07000000","0.00000000"],["78673.23000000","0.00007000"],["78669.81000000","0.34324000"],["78655.94000000","0.00000000"],["78636.75000000","0.00000000"],["78615.82000000","0.00000000"],["78402.65000000","7.65368000"],["78399.96000000","0.21930000"],["70846.20000000","0.00416000"],["70846.19000000","0.00000000"]],"a":[["78718.00000000","1.09794000"],["78718.01000000","0.00027000"],["78718.09000000","0.00014000"],["78718.10000000","0.22194000"],["78718.67000000","0.00318000"],["78719.14000000","0.00000000"],["78719.25000000","0.00014000"],["78719.82000000","0.00014000"],["78719.83000000","0.03000000"],["78719.99000000","0.31780000"],["78720.10000000","0.00027000"],["78720.36000000","0.00000000"],["78720.37000000","0.00000000"],["78720.38000000","0.05412000"],["78720.51000000","0.00635000"],["78720.68000000","0.00320000"],["78721.32000000","0.00335000"],["78721.44000000","0.00000000"],["78721.77000000","0.00000000"],["78721.98000000","0.00000000"],["78721.99000000","0.00000000"],["78722.94000000","0.00400000"],["78723.47000000","0.00000000"],["78723.99000000","0.00000000"],["78724.00000000","0.02400000"],["78724.10000000","0.02000000"],["78724.80000000","0.00008000"],["78725.99000000","0.00000000"],["78726.61000000","0.00000000"],["78727.80000000","3.48691000"],["78727.81000000","0.00000000"],["78727.88000000","0.00000000"],["78727.99000000","0.00157000"],["78728.43000000","0.00000000"],["78728.99000000","0.00000000"],["78729.13000000","0.00000000"],["78730.33000000","0.00000000"],["78730.63000000","0.00000000"],["78732.60000000","0.00000000"],["78733.46000000","0.34296000"],["78733.90000000","0.12701000"],["78736.14000000","0.00000000"],["78737.52000000","0.36224000"],["78737.53000000","0.00000000"],["78738.05000000","0.00000000"],["78753.97000000","1.25722000"],["78754.06000000","0.02340000"],["78757.20000000","0.00000000"],["78764.04000000","0.00400000"],["78764.80000000","0.00000000"],["78766.78000000","0.00000000"],["78767.28000000","0.00000000"],["78777.27000000","0.00000000"],["78785.33000000","0.00000000"],["78786.43000000","0.00000000"],["78787.48000000","0.00000000"],["78800.64000000","0.00000000"],["78810.62000000","0.00316000"],["78815.74000000","0.00000000"],["79030.09000000","0.00000000"],["79103.65000000","0.01270000"]]}}
{"rx_ns": 15756903200, "frame": {"e":"depthUpdate","E":1787603073214,"s":"BTCUSDT","U":99076627592,"u":99076627674,"b":[["78717.99000000","0.06309000"],["78717.96000000","0.00014000"],["78717.90000000","0.05007000"],["78717.85000000","0.00007000"],["78716.53000000","0.00000000"],["78716.52000000","0.00014000"],["78716.44000000","0.00000000"],["78715.26000000","0.49024000"],["78714.88000000","0.00014000"],["78714.87000000","0.04780000"],["78714.16000000","0.01397000"],["78714.15000000","0.00007000"],["78714.14000000","0.04039000"],["78714.04000000","1.21952000"],["78714.03000000","0.00000000"],["78714.00000000","0.24277000"],["78713.28000000","0.00000000"],["78711.71000000","1.90515000"],["78711.70000000","0.00000000"],["78710.26000000","0.00000000"],["78710.06000000","0.00000000"],["78708.57000000","0.00000000"],["78707.04000000","0.00048000"],["78684.00000000","0.02400000"],["78668.14000000","0.00400000"],["78662.66000000","0.00400000"],["78581.59000000","0.00000000"],["78510.76000000","0.00406000"],["70846.20000000","0.00448000"],["62974.40000000","0.00000000"]],"a":[["78718.00000000","1.09848000"],["78718.01000000","0.00020000"],["78719.41000000","0.00014000"],["78719.42000000","0.02175000"],["78719.43000000","0.26063000"],["78719.83000000","0.03007000"],["78719.98000000","0.00000000"],["78719.99000000","0.31773000"],["78720.20000000","0.00400000"],["78720.38000000","0.05405000"],["78720.51000000","0.00642000"],["78720.52000000","0.04841000"],["78721.78000000","0.04841000"],["78722.00000000","0.02407000"],["78724.60000000","0.02161000"],["78725.23000000","0.00000000"],["78761.30000000","0.00400000"],["78762.32000000","0.00000000"],["78764.04000000","0.00000000"],["78828.77000000","0.05742000"],["78900.13000000","0.00000000"]]}}
{"rx_ns": 15853216200, "frame": {"e":"depthUpdate","E":1787603073314,"s":"BTCUSDT","U":99076627675,"u":99076627713,"b":[["78717.99000000","0.06232000"],["78717.98000000","0.00041000"],["78717.90000000","0.05007000"],["78716.52000000","0.00007000"],["78714.14000000","0.04039000"],["78714.04000000","1.21959000"],["78714.00000000","0.24284000"],["78710.00000000","0.02430000"],["78708.40000000","0.00068000"],["78533.83000000","0.00778000"],["78529.42000000","0.00000000"],["72420.55000000","0.00014000"],["70846.20000000","0.00432000"],["70846.00000000","0.00020000"],["62974.00000000","0.00000000"]],"a":[["78718.00000000","1.10040000"],["78719.26000000","0.04041000"],["78719.42000000","0.02182000"],["78720.38000000","0.05412000"],["78720.51000000","0.00635000"],["78721.02000000","0.25410000"],["78727.82000000","0.00000000"],["78730.70000000","0.00000000"]]}}
{"rx_ns": 15961459300, "frame": {"e":"depthUpdate","E":1787603073414,"s":"BTCUSDT","U":99076627714,"u":99076627732,"b":[["78715.26000000","0.00014000"],["78711.71000000","0.00000000"],["78707.19000000","0.00048000"],["78699.64000000","0.00000000"],["78683.65000000","0.00007000"],["78660.29000000","0.00000000"],["78646.52000000","0.86887000"],["78628.81000000","0.00000000"],["78581.32000000","0.00000000"],["78510.76000000","0.00000000"],["70846.20000000","0.00432000"],["70846.00000000","0.00000000"]],"a":[["78719.09000000","0.00007000"],["78721.02000000","0.00000000"],["78766.31000000","0.86754000"],["78844.14000000","0.00000000"]]}}
{"rx_ns": 16053149400, "frame": {"e":"depthUpdate","E":1787603073514,"s":"BTCUSDT","U":99076627733,"u":99076627783,"b":[["78717.99000000","0.02902000"],["78717.98000000","0.00041000"],["78717.90000000","0.05007000"],["78715.27000000","0.00000000"],["78715.26000000","0.00007000"],["78714.17000000","0.00014000"],["78714.00000000","0.24291000"],["78710.14000000","0.31772000"],["78324.40000000","0.00008000"],["77932.77000000","0.00000000"],["77543.11000000","0.00000000"],["77155.39000000","0.00000000"],["76769.62000000","0.00000000"],["76385.77000000","0.00000000"],["76003.84000000","0.00000000"],["75623.82000000","0.00000000"],["75245.70000000","0.00000000"],["74869.47000000","0.00000000"],["74495.13000000","0.00000000"],["74122.65000000","0.00000000"],["73752.04000000","0.00000000"],["73383.28000000","0.00000000"],["73016.36000000","0.00000000"],["70846.20000000","0.00432000"],["62974.40000000","0.00031000"]],"a":[["78720.38000000","0.05412000"],["78723.31000000","0.38115000"],["79111.59000000","0.00000000"],["79507.15000000","0.00000000"],["79904.69000000","0.00000000"],["80304.21000000","0.00000000"],["80705.73000000","0.00000000"],["81109.26000000","0.00000000"],["81514.81000000","0.00000000"],["81922.38000000","0.00000000"],["82331.99000000","0.00000000"],["82743.65000000","0.00000000"],["83157.37000000","0.00000000"],["83573.16000000","0.00000000"],["83991.02000000","0.00000000"],["84410.98000000","0.00000000"],["84833.03000000","0.00000000"]]}}
{"rx_ns": 16155336400, "frame": {"e":"depthUpdate","E":1787603073614,"s":"BTCUSDT","U":99076627784,"u":99076627962,"b":[["78717.99000000","0.00000000"],["78717.98000000","0.00000000"],["78717.97000000","0.00000000"],["78717.96000000","0.00000000"],["78717.95000000","0.05105000"],["78717.94000000","0.00035000"],["78714.15000000","0.00014000"],["78714.05000000","0.00007000"],["78714.00000000","0.24298000"],["78712.90000000","0.02324000"],["78712.00000000","0.02407000"],["78710.86000000","0.26049000"],["78707.24000000","0.00000000"],["78706.45000000","0.08576000"],["78701.47000000","0.00000000"],["78655.74000000","0.00406000"],["78596.58000000","0.80000000"],["78594.41000000","0.00000000"],["78317.01000000","0.00007000"],["70846.20000000","0.00016000"],["70846.16000000","0.00032000"],["70846.15000000","0.00045000"],["62974.40000000","0.00000000"]],"a":[["78717.96000000","2.96526000"],["78717.97000000","0.00020000"],["78717.98000000","0.00013000"],["78717.99000000","0.00206000"],["78718.00000000","0.27364000"],["78718.01000000","0.00000000"],["78718.02000000","0.00000000"],["78719.25000000","0.00007000"],["78719.41000000","0.00000000"],["78719.82000000","0.00000000"],["78719.98000000","0.00014000"],["78720.38000000","0.05405000"],["78729.74000000","0.00000000"],["78733.48000000","0.04857000"],["78734.27000000","0.00000000"],["78741.89000000","0.09709000"],["78749.87000000","0.00000000"],["78816.75000000","0.02789000"],["78828.16000000","0.00000000"]]}}
{"rx_ns": 16255091700, "frame": {"e":"depthUpdate","E":1787603073714,"s":"BTCUSDT","U":99076627963,"u":99076628253,"b":[["78717.95000000","0.00000000"],["78717.94000000","0.00000000"],["78717.91000000","0.00000000"],["78717.90000000","0.00000000"],["78717.85000000","0.00000000"],["78717.78000000","0.00000000"],["78716.56000000","0.00000000"],["78716.52000000","0.00000000"],["78716.00000000","0.00000000"],["78715.99000000","0.00000000"],["78715.93000000","0.00000000"],["78715.80000000","0.00000000"],["78715.79000000","0.00000000"],["78715.26000000","0.00000000"],["78715.25000000","0.00000000"],["78714.88000000","0.00000000"],["78714.87000000","0.00000000"],["78714.17000000","0.00000000"],["78714.16000000","0.00000000"],["78714.15000000","0.00000000"],["78714.14000000","0.52552000"],["78714.13000000","0.00042000"],["78714.05000000","0.00014000"],["78714.01000000","0.00021000"],["78713.70000000","0.00000000"],["78712.90000000","0.00007000"],["78712.35000000","0.00000000"],["78711.64000000","0.00007000"],["78710.87000000","0.00014000"],["78710.86000000","0.26056000"],["78710.38000000","0.00007000"],["78710.15000000","0.00014000"],["78710.14000000","0.31779000"],["78710.12000000","0.00007000"],["78710.11000000","0.21937000"],["78709.34000000","0.02515000"],["78708.40000000","0.00000000"],["78707.19000000","0.00000000"],["78707.04000000","0.00000000"],["78706.45000000","0.00000000"],["78703.34000000","0.08576000"],["78700.36000000","0.00000000"],["78699.38000000","0.00400000"],["78694.33000000","0.00000000"],["78694.08000000","1.21956000"],["78690.48000000","0.00007000"],["78678.00000000","0.02400000"],["78677.10000000","0.00014000"],["78674.00000000","0.03400000"],["78654.56000000","0.00000000"],["78652.01000000","0.00317000"],["78634.39000000","0.00000000"],["78630.01000000","0.00315000"],["78629.96000000","0.02116000"],["78613.21000000","2.77178000"],["78533.83000000","0.00000000"],["78518.23000000","0.00785000"],["76934.14000000","0.00900000"],["70846.16000000","0.00000000"],["70842.73000000","0.00036000"],["62974.36000000","0.00009000"]],"a":[["78714.15000000","1.75492000"],["78714.16000000","0.00020000"],["78714.17000000","0.00013000"],["78714.87000000","0.00000000"],["78714.88000000","0.00000000"],["78715.26000000","0.00000000"],["78715.27000000","0.00000000"],["78715.80000000","0.00014000"],["78715.94000000","0.00000000"],["78716.00000000","0.00000000"],["78716.53000000","0.00000000"],["78716.57000000","0.00000000"],["78716.70000000","0.00014000"],["78716.71000000","0.05439000"],["78717.64000000","0.00014000"],["78717.65000000","0.04007000"],["78717.79000000","0.00000000"],["78717.86000000","0.00000000"],["78717.91000000","0.00000000"],["78717.92000000","0.00000000"],["78717.94000000","0.00000000"],["78717.95000000","0.00206000"],["78717.96000000","0.83882000"],["78717.97000000","0.00000000"],["78717.98000000","0.00000000"],["78717.99000000","0.00014000"],["78718.00000000","0.23863000"],["78718.09000000","0.00007000"],["78719.25000000","0.00000000"],["78719.26000000","0.00007000"],["78719.42000000","0.02168000"],["78719.43000000","0.00014000"],["78719.98000000","0.00000000"],["78719.99000000","0.31780000"],["78720.00000000","0.03100000"],["78720.38000000","0.00007000"],["78720.48000000","0.00007000"],["78720.52000000","0.00000000"],["78721.78000000","0.00000000"],["78722.01000000","0.00007000"],["78722.16000000","0.12702000"],["78722.68000000","0.00000000"],["78723.97000000","0.00007000"],["78724.01000000","0.00000000"],["78724.61000000","0.02057000"],["78729.90000000","0.09394000"],["78730.37000000","0.04857000"],["78732.61000000","0.06588000"],["78733.48000000","0.00000000"],["78733.75000000","0.00000000"],["78733.90000000","0.00000000"],["78734.57000000","0.07611000"],["78737.72000000","0.00007000"],["78739.69000000","0.00000000"],["78741.57000000","0.00000000"],["78741.65000000","0.00000000"],["78742.68000000","0.00000000"],["78754.00000000","0.03400000"],["78754.50000000","0.00000000"],["78758.00000000","0.02400000"],["78763.38000000","0.00317000"],["78767.19000000","0.00000000"],["78784.63000000","0.00000000"],["78785.33000000","0.00316000"],["78789.86000000","0.00000000"],["78827.83000000","0.00000000"],["78936.11000000","0.00000000"],["81205.66000000","0.00000000"]]}}
{"rx_ns": 16353234000, "frame": {"e":"depthUpdate","E":1787603073814,"s":"BTCUSDT","U":99076628254,"u":99076628322,"b":[["78714.14000000","0.52566000"],["78714.13000000","0.00056000"],["78714.00000000","0.24298000"],["78712.90000000","0.00000000"],["78712.00000000","0.02407000"],["78711.64000000","0.00000000"],["78710.86000000","0.26056000"],["78710.38000000","0.00000000"],["78710.17000000","0.00000000"],["78710.14000000","0.33143000"],["78710.11000000","0.21944000"],["78710.03000000","1.21959000"],["78710.00000000","0.02437000"],["78709.67000000","0.00000000"],["78709.39000000","0.00474000"],["78708.89000000","0.02274000"],["78708.11000000","0.00000000"],["78708.00000000","0.05014000"],["78707.83000000","0.00320000"],["78707.63000000","0.02728000"],["78706.37000000","0.02729000"],["78676.91000000","0.00000000"],["78629.96000000","0.00000000"],["78506.22000000","0.00406000"],["70842.73000000","0.00052000"]],"a":[["78714.15000000","2.00251000"],["78715.40000000","0.00014000"],["78715.41000000","0.04077000"],["78716.66000000","0.00014000"],["78716.67000000","0.04893000"],["78716.71000000","0.05446000"],["78717.65000000","0.04014000"],["78717.93000000","0.04893000"],["78717.95000000","0.00007000"],["78717.96000000","0.23633000"],["78717.99000000","0.00000000"],["78718.00000000","0.23763000"],["78718.09000000","0.00000000"],["78718.10000000","0.00007000"],["78719.26000000","0.00000000"],["78719.42000000","0.02161000"],["78719.43000000","0.00007000"],["78719.98000000","0.00000000"],["78754.06000000","0.00000000"]]}}
{"rx_ns": 16453267800, "frame": {"e":"depthUpdate","E":1787603073914,"s":"BTCUSDT","U":99076628323,"u":99076628352,"b":[["78714.14000000","0.52762000"],["78714.13000000","0.00056000"],["78701.73000000","0.02200000"],["78697.74000000","0.02000000"],["78642.68000000","0.02200000"],["78640.87000000","0.02000000"],["72420.55000000","0.00000000"],["70842.73000000","0.00068000"],["62974.00000000","0.00300000"]],"a":[["78714.15000000","2.00351000"],["78715.41000000","0.04084000"],["78716.67000000","0.04900000"],["78717.65000000","0.04014000"],["78717.93000000","0.04900000"],["78718.00000000","0.23756000"],["78718.10000000","0.00000000"],["78719.83000000","0.03000000"],["78719.99000000","0.31773000"]]}}
{"rx_ns": 16555760400, "frame": {"e":"depthUpdate","E":1787603074014,"s":"BTCUSDT","U":99076628353,"u":99076628399,"b":[["78714.14000000","0.52779000"],["78695.09000000","0.00406000"],["78687.53000000","0.00000000"],["78642.68000000","0.00000000"],["78640.87000000","0.00000000"],["78509.90000000","0.02032000"],["78506.51000000","0.00000000"],["78320.56000000","0.01000000"],["78317.01000000","0.00000000"],["77928.96000000","0.01000000"],["77539.32000000","0.01000000"],["77151.62000000","0.01000000"],["76765.86000000","0.01000000"],["76382.03000000","0.01000000"],["76000.12000000","0.01007000"],["75620.12000000","0.01000000"],["75242.02000000","0.01000000"],["74865.81000000","0.01000000"],["74491.48000000","0.01000000"],["74119.02000000","0.01000000"],["73748.43000000","0.01000000"],["73379.69000000","0.01000000"],["73012.79000000","0.01000000"],["70842.73000000","0.00100000"],["62974.00000000","0.00000000"],["62971.32000000","0.00031000"]],"a":[["78715.94000000","0.00007000"],["78718.66000000","0.31767000"],["78719.09000000","0.00000000"],["78719.87000000","0.00000000"],["78719.99000000","0.00007000"],["78721.45000000","0.00000000"],["79107.73000000","0.01000000"],["79503.26000000","0.01000000"],["79900.78000000","0.01000000"],["80300.28000000","0.01000000"],["80701.79000000","0.01000000"],["81105.29000000","0.01000000"],["81510.82000000","0.01000000"],["81918.38000000","0.01011000"],["82327.97000000","0.01000000"],["82739.61000000","0.01000000"],["83153.31000000","0.01000000"],["83569.07000000","0.01000000"],["83986.92000000","0.01000000"],["84406.85000000","0.01000000"],["84828.89000000","0.01000000"]]}}
{"rx_ns": 16654581100, "frame": {"e":"depthUpdate","E":1787603074114,"s":"BTCUSDT","U":99076628400,"u":99076628408,"b":[["78691.25000000","0.12707000"],["78009.53000000","0.00040000"]],"a":[["78714.15000000","1.99589000"],["78718.00000000","0.23753000"],["78738.48000000","0.12700000"],["78741.00000000","0.70000000"]]}}
{"rx_ns": 16753447600, "frame": {"e":"depthUpdate","E":1787603074214,"s":"BTCUSDT","U":99076628409,"u":99076628416,"b":[["78714.14000000","0.52786000"],["78624.26000000","0.00406000"],["70842.73000000","0.00132000"],["62971.32000000","0.00000000"]],"a":[["78714.15000000","1.99602000"]]}}
{"rx_ns": 16853497300, "frame": {"e":"depthUpdate","E":1787603074314,"s":"BTCUSDT","U":99076628417,"u":99076628433,"b":[["78714.14000000","0.31800000"],["78687.12000000","0.04545000"],["78677.51000000","0.00000000"],["78675.36000000","0.09573000"],["78386.06000000","0.00000000"],["78310.45000000","0.01525000"],["70842.73000000","0.00148000"],["62971.00000000","0.00000000"]],"a":[["78714.15000000","1.99942000"],["78714.91000000","0.00328000"],["78715.40000000","0.00522000"],["78717.96000000","0.23125000"],["78718.66000000","0.31774000"],["78719.64000000","0.01270000"],["78719.68000000","0.06350000"],["78770.22000000","0.02401000"]]}}
{"rx_ns": 16959740200, "frame": {"e":"depthUpdate","E":1787603074414,"s":"BTCUSDT","U":99076628434,"u":99076628465,"b":[["78708.00000000","0.05014000"],["78706.14000000","0.00000000"],["78705.29000000","0.00000000"],["78702.46000000","0.00635000"],["78695.09000000","0.00000000"],["78655.74000000","0.00000000"],["78624.26000000","0.00000000"],["78577.04000000","0.00000000"],["78506.22000000","0.00000000"],["77781.66000000","0.00000000"],["77309.31000000","0.00000000"],["76836.95000000","0.00000000"],["76364.59000000","0.00000000"],["75892.23000000","0.00000000"],["75419.87000000","0.00000000"],["74947.51000000","0.00000000"],["74475.16000000","0.00000000"],["74002.80000000","0.00025000"],["73530.44000000","0.00000000"],["70842.73000000","0.00164000"],["70842.00000000","0.00235000"]],"a":[["78714.15000000","2.25989000"],["78716.71000000","0.05446000"],["78717.63000000","0.00007000"],["78717.64000000","0.31781000"],["78717.95000000","0.00000000"],["78718.43000000","0.00007000"],["78718.66000000","0.00007000"],["78742.10000000","0.00000000"],["78781.46000000","0.00000000"],["78813.04000000","0.00000000"],["78860.29000000","0.00000000"],["78931.09000000","0.00000000"]]}}
{"rx_ns": 17054133700, "frame": {"e":"depthUpdate","E":1787603074515,"s":"BTCUSDT","U":99076628466,"u":99076628523,"b":[["78714.14000000","0.52995000"],["78708.00000000","0.05021000"],["78707.84000000","0.36224000"],["78320.56000000","0.00000000"],["78317.01000000","0.00007000"],["77928.96000000","0.00000000"],["77539.32000000","0.00000000"],["77151.62000000","0.00000000"],["76765.86000000","0.00000000"],["76382.03000000","0.00000000"],["76000.12000000","0.00007000"],["75620.12000000","0.00000000"],["75242.02000000","0.00000000"],["74865.81000000","0.00000000"],["74491.48000000","0.00000000"],["74119.02000000","0.00000000"],["73748.43000000","0.00000000"],["73379.69000000","0.00000000"],["73012.79000000","0.00000000"],["70842.73000000","0.00164000"],["70842.00000000","0.00225000"],["62971.32000000","0.00031000"]],"a":[["78714.15000000","2.22295000"],["78714.91000000","0.00000000"],["78715.40000000","0.00529000"],["78716.48000000","0.00329000"],["78716.71000000","0.05446000"],["78718.00000000","0.23746000"],["79107.73000000","0.00000000"],["79503.26000000","0.00000000"],["79900.78000000","0.00000000"],["80300.28000000","0.00000000"],["80701.79000000","0.00000000"],["81105.29000000","0.00000000"],["81510.82000000","0.00000000"],["81918.38000000","0.00011000"],["82327.97000000","0.00000000"],["82739.61000000","0.00000000"],["83153.31000000","0.00000000"],["83569.07000000","0.00000000"],["83986.92000000","0.00000000"],["84406.85000000","0.00000000"],["84828.89000000","0.00000000"]]}}
{"rx_ns": 17154671600, "frame": {"e":"depthUpdate","E":1787603074614,"s":"BTCUSDT","U":99076628524,"u":99076628536,"b":[["78714.14000000","0.53015000"],["78714.13000000","0.00069000"],["78714.12000000","0.00013000"],["78692.49000000","0.00406000"],["78675.36000000","0.00000000"],["70842.73000000","0.00180000"],["62971.32000000","0.00000000"]],"a":[["78714.15000000","2.26422000"]]}}
{"rx_ns": 17253934100, "frame": {"e":"depthUpdate","E":1787603074715,"s":"BTCUSDT","U":99076628537,"u":99076628558,"b":[["78690.48000000","0.00000000"],["78680.82000000","0.00000000"],["78678.00000000","0.72400000"],["78670.58000000","0.00319000"],["78657.06000000","0.00007000"],["78629.96000000","0.02116000"],["70846.15000000","0.00036000"],["70846.14000000","0.00009000"],["70842.73000000","0.00180000"],["62971.31000000","0.00000000"]],"a":[["78714.15000000","2.23946000"],["78717.63000000","0.00000000"],["78717.64000000","0.00014000"],["78717.92000000","0.00007000"],["78718.00000000","0.24446000"],["78718.66000000","0.31774000"],["78720.00000000","0.02400000"],["78737.72000000","0.00000000"],["78805.50000000","0.00314000"],["78810.62000000","0.00000000"]]}}
{"rx_ns": 17352868700, "frame": {"e":"depthUpdate","E":1787603074814,"s":"BTCUSDT","U":99076628559,"u":99076628574,"b":[["78714.14000000","0.53005000"],["78709.90000000","0.00332000"],["78690.48000000","0.00007000"],["78675.20000000","0.09436000"],["78629.96000000","0.00000000"],["78518.23000000","0.00007000"],["78510.34000000","0.00778000"],["70842.73000000","0.00196000"]],"a":[["78714.91000000","0.00330000"],["78716.71000000","0.05446000"],["78718.00000000","0.24453000"],["78737.72000000","0.00007000"],["78809.43000000","0.00406000"]]}}
{"rx_ns": 17454304700, "frame": {"e":"depthUpdate","E":1787603074914,"s":"BTCUSDT","U":99076628575,"u":99076628578,"b":[["70842.73000000","0.00212000"]],"a":[["78714.15000000","2.23963000"]]}}
{"rx_ns": 17552971900, "frame": {"e":"depthUpdate","E":1787603075014,"s":"BTCUSDT","U":99076628579,"u":99076628585,"b":[["78714.14000000","0.31803000"],["78679.76000000","1.21952000"],["78642.68000000","0.02200000"],["78629.96000000","0.02116000"],["70842.73000000","0.00196000"],["62971.32000000","0.00031000"]],"a":[["78738.56000000","0.00406000"]]}}
{"rx_ns": 17654932800, "frame": {"e":"depthUpdate","E":1787603075115,"s":"BTCUSDT","U":99076628586,"u":99076628630,"b":[["78629.96000000","0.00000000"],["78320.56000000","0.01000000"],["78005.71000000","0.00010000"],["77928.96000000","0.01000000"],["77539.32000000","0.01000000"],["77151.62000000","0.01000000"],["76765.86000000","0.01000000"],["76382.03000000","0.01000000"],["76000.12000000","0.01007000"],["75620.12000000","0.01000000"],["75242.02000000","0.01000000"],["74865.81000000","0.01000000"],["74491.48000000","0.01000000"],["74119.02000000","0.01000000"],["73748.43000000","0.01000000"],["73379.69000000","0.01000000"],["73012.79000000","0.01000000"],["70842.73000000","0.00228000"],["70842.00000000","0.00245000"]],"a":[["78714.15000000","2.23973000"],["78715.15000000","0.00007000"],["78720.01000000","0.00013000"],["78722.01000000","0.00000000"],["78723.55000000","0.00000000"],["78811.75000000","0.00025000"],["78815.60000000","0.00000000"],["79107.73000000","0.01000000"],["79503.26000000","0.01000000"],["79900.78000000","0.01000000"],["80300.28000000","0.01000000"],["80701.79000000","0.01000000"],["81105.29000000","0.01000000"],["81510.82000000","0.01000000"],["81918.38000000","0.01011000"],["82327.97000000","0.01000000"],["82739.61000000","0.01000000"],["83153.31000000","0.01000000"],["83569.07000000","0.01000000"],["83986.92000000","0.01000000"],["84406.85000000","0.01000000"],["84828.89000000","0.01000000"]]}}
{"rx_ns": 17753252800, "frame": {"e":"depthUpdate","E":1787603075214,"s":"BTCUSDT","U":99076628631,"u":99076628639,"b":[["78714.14000000","0.54232000"],["70842.73000000","0.00228000"],["70842.00000000","0.00235000"],["62971.32000000","0.00000000"]],"a":[["78714.15000000","2.23873000"],["78927.54000000","0.00406000"]]}}
{"rx_ns": 17854627300, "frame": {"e":"depthUpdate","E":1787603075314,"s":"BTCUSDT","U":99076628640,"u":99076628648,"b":[["78714.14000000","0.31803000"],["78629.96000000","0.02116000"],["70842.73000000","0.00244000"],["70842.00000000","0.00225000"],["62974.00000000","0.00000000"]],"a":[]}}
{"rx_ns": 17952918200, "frame": {"e":"depthUpdate","E":1787603075414,"s":"BTCUSDT","U":99076628649,"u":99076628660,"b":[["78714.14000000","0.52305000"],["78708.47000000","0.00000000"],["78706.87000000","0.02000000"],["78663.75000000","0.00400000"],["78663.20000000","0.00015000"],["78662.66000000","0.00000000"],["78629.96000000","0.00000000"],["78574.45000000","0.00406000"]],"a":[["78718.66000000","0.31767000"],["78719.64000000","0.00000000"],["78719.68000000","0.00000000"]]}}
{"rx_ns": 18052827200, "frame": {"e":"depthUpdate","E":1787603075514,"s":"BTCUSDT","U":99076628661,"u":99076628690,"b":[["78714.14000000","0.31376000"],["78714.13000000","0.00069000"],["78710.12000000","0.00000000"],["78710.11000000","0.00014000"],["78710.04000000","0.00007000"],["78709.90000000","0.00000000"],["70842.73000000","0.00260000"],["70842.00000000","0.00235000"],["62971.32000000","0.00031000"]],"a":[["78740.75000000","0.00400000"],["78761.30000000","0.00000000"],["78803.72000000","0.93647000"],["78808.94000000","0.00000000"]]}}
{"rx_ns": 18157564400, "frame": {"e":"depthUpdate","E":1787603075614,"s":"BTCUSDT","U":99076628691,"u":99076628742,"b":[["78714.14000000","0.31581000"],["78710.14000000","0.33143000"],["78710.11000000","0.00007000"],["78709.39000000","0.00152000"],["78707.83000000","0.00000000"],["78628.00000000","0.02600000"],["78621.66000000","0.00406000"],["78320.56000000","0.00000000"],["77928.96000000","0.00000000"],["77539.32000000","0.00000000"],["77151.62000000","0.00000000"],["76765.86000000","0.00000000"],["76382.03000000","0.00000000"],["76000.12000000","0.00007000"],["75620.12000000","0.00000000"],["75242.02000000","0.00000000"],["74865.81000000","0.00000000"],["74491.48000000","0.00000000"],["74119.02000000","0.00000000"],["73748.43000000","0.00000000"],["73379.69000000","0.00000000"],["73012.79000000","0.00000000"],["70842.73000000","0.00260000"],["70842.00000000","0.00235000"],["62971.32000000","0.00000000"]],"a":[["78723.30000000","1.21952000"],["78733.76000000","0.34296000"],["78749.86000000","0.00000000"],["78776.19000000","0.00000000"],["79107.73000000","0.00000000"],["79503.26000000","0.00000000"],["79900.78000000","0.00000000"],["80300.28000000","0.00000000"],["80701.79000000","0.00000000"],["81105.29000000","0.00000000"],["81510.82000000","0.00000000"],["81918.38000000","0.00011000"],["82327.97000000","0.00000000"],["82739.61000000","0.00000000"],["83153.31000000","0.00000000"],["83569.07000000","0.00000000"],["83986.92000000","0.00000000"],["84406.85000000","0.00000000"],["84828.89000000","0.00000000"]]}}
{"rx_ns": 18255299100, "frame": {"e":"depthUpdate","E":1787603075714,"s":"BTCUSDT","U":99076628743,"u":99076629071,"b":[["78714.14000000","0.00000000"],["78714.13000000","0.00000000"],["78714.12000000","0.00000000"],["78714.05000000","0.00000000"],["78714.04000000","0.00000000"],["78714.01000000","0.00000000"],["78714.00000000","0.01650000"],["78713.99000000","0.00475000"],["78712.01000000","0.00014000"],["78710.87000000","0.00000000"],["78710.86000000","0.00007000"],["78710.14000000","0.01378000"],["78710.04000000","0.00014000"],["78709.39000000","0.00000000"],["78709.34000000","0.02522000"],["78708.97000000","0.00000000"],["78708.89000000","0.02281000"],["78708.06000000","0.00007000"],["78708.00000000","0.02421000"],["78707.84000000","0.00000000"],["78707.81000000","0.00000000"],["78707.57000000","0.00000000"],["78707.52000000","0.00000000"],["78707.20000000","0.00000000"],["78706.87000000","0.00000000"],["78706.66000000","0.00000000"],["78706.01000000","0.00014000"],["78706.00000000","0.15112000"],["78705.17000000","0.00000000"],["78705.02000000","0.00007000"],["78705.01000000","0.26053000"],["78704.34000000","0.00000000"],["78703.92000000","0.00047000"],["78703.87000000","0.00000000"],["78703.58000000","1.90522000"],["78703.50000000","0.00069000"],["78703.47000000","0.00000000"],["78703.39000000","0.00048000"],["78703.36000000","0.31768000"],["78702.46000000","0.00000000"],["78702.45000000","0.00000000"],["78702.08000000","0.00000000"],["78701.88000000","0.00000000"],["78701.21000000","0.00000000"],["78700.75000000","0.00000000"],["78700.70000000","0.00152000"],["78699.38000000","0.00000000"],["78699.31000000","0.00000000"],["78698.57000000","0.02000000"],["78698.52000000","0.00635000"],["78698.51000000","0.00000000"],["78698.18000000","0.00635000"],["78697.75000000","0.00000000"],["78697.74000000","0.00000000"],["78697.66000000","0.00762000"],["78697.50000000","0.00000000"],["78697.37000000","0.00000000"],["78697.17000000","0.03000000"],["78696.47000000","0.00000000"],["78696.46000000","0.00000000"],["78695.67000000","0.08000000"],["78694.17000000","0.00400000"],["78694.09000000","0.00400000"],["78692.98000000","0.00000000"],["78692.50000000","0.00000000"],["78690.41000000","0.00000000"],["78690.00000000","0.02400000"],["78686.48000000","0.00000000"],["78683.66000000","0.13246000"],["78679.30000000","0.00635000"],["78671.23000000","0.63562000"],["78670.00000000","0.11212000"],["78669.36000000","0.00007000"],["78666.12000000","0.00007000"],["78613.21000000","0.00000000"],["78596.58000000","0.00000000"],["78592.45000000","0.80000000"],["70842.73000000","0.00020000"],["70842.00000000","0.00225000"],["62971.31000000","0.00000000"]],"a":[["78714.01000000","3.18715000"],["78714.02000000","0.20032000"],["78714.03000000","0.00013000"],["78714.05000000","0.00000000"],["78714.06000000","0.00007000"],["78714.13000000","0.00000000"],["78714.14000000","0.02367000"],["78714.15000000","0.95884000"],["78714.16000000","0.00000000"],["78714.17000000","0.00000000"],["78715.40000000","0.00007000"],["78716.46000000","0.00000000"],["78716.47000000","0.00000000"],["78716.66000000","0.00000000"],["78716.70000000","0.00000000"],["78716.71000000","0.05439000"],["78717.64000000","0.00000000"],["78717.92000000","0.00635000"],["78717.95000000","0.00014000"],["78717.96000000","0.22750000"],["78717.99000000","0.00014000"],["78718.00000000","0.24439000"],["78718.66000000","0.00000000"],["78720.51000000","0.00000000"],["78726.04000000","0.34300000"],["78728.56000000","0.00000000"],["78730.00000000","0.11559000"],["78732.14000000","0.63513000"],["78733.45000000","0.43588000"],["78733.90000000","0.04647000"],["78736.50000000","0.00000000"],["78748.84000000","0.00000000"],["78752.49000000","0.00429000"],["78755.27000000","0.00000000"],["78757.98000000","0.00000000"],["78758.17000000","0.00000000"],["78758.29000000","0.00424000"],["78763.39000000","0.00000000"],["78768.97000000","0.00000000"],["78770.27000000","0.00000000"],["78785.34000000","0.00000000"],["78794.00000000","0.11687000"],["78813.67000000","0.00007000"],["78843.25000000","0.00000000"],["78960.65000000","0.02763000"],["78961.05000000","0.01887000"],["78964.70000000","0.01913000"],["78964.76000000","0.01901000"],["79012.90000000","0.00000000"],["79013.01000000","0.00000000"],["79017.36000000","0.00000000"],["79017.47000000","0.00000000"],["79098.02000000","0.00635000"]]}}
{"rx_ns": 18353202800, "frame": {"e":"depthUpdate","E":1787603075814,"s":"BTCUSDT","U":99076629072,"u":99076629419,"b":[["78714.00000000","0.00000000"],["78713.99000000","0.00000000"],["78713.98000000","0.00000000"],["78713.56000000","0.00000000"],["78712.30000000","0.00000000"],["78712.01000000","0.00000000"],["78712.00000000","0.02570000"],["78711.99000000","0.00056000"],["78711.93000000","0.00000000"],["78710.86000000","0.00000000"],["78710.36000000","0.00014000"],["78710.35000000","0.05000000"],["78710.31000000","0.00014000"],["78710.30000000","0.05000000"],["78710.25000000","0.00000000"],["78708.00000000","0.02421000"],["78707.76000000","0.00000000"],["78707.71000000","0.00000000"],["78707.63000000","0.02735000"],["78707.51000000","0.00000000"],["78706.37000000","0.02736000"],["78706.05000000","0.00000000"],["78705.79000000","0.00000000"],["78705.02000000","0.00000000"],["78704.19000000","0.00007000"],["78703.59000000","0.00000000"],["78703.58000000","1.90515000"],["78703.34000000","0.00000000"],["78701.31000000","0.08576000"],["78698.26000000","0.00014000"],["78696.87000000","0.00000000"],["78695.07000000","0.04000000"],["78694.86000000","0.02600000"],["78694.09000000","0.00000000"],["78694.07000000","0.02800000"],["78692.50000000","0.00400000"],["78690.48000000","0.00000000"],["78690.33000000","0.00007000"],["78688.39000000","0.00126000"],["78674.00000000","0.02400000"],["78673.23000000","0.00014000"],["78672.00000000","0.03400000"],["78665.49000000","0.00007000"],["78665.47000000","0.00000000"],["78662.47000000","0.00000000"],["78658.25000000","0.00400000"],["78655.02000000","0.00007000"],["78652.01000000","0.00000000"],["78651.44000000","0.00436000"],["78650.01000000","0.00317000"],["78629.21000000","0.02600000"],["78628.41000000","0.02800000"],["78592.45000000","0.00000000"],["78591.98000000","0.00000000"],["78591.78000000","0.80000000"],["78483.33000000","0.00009000"],["77769.57000000","0.00042000"],["70846.14000000","0.00000000"],["70842.60000000","0.00000000"]],"a":[["78712.01000000","3.57967000"],["78712.02000000","0.00020000"],["78712.03000000","0.00013000"],["78712.76000000","0.00014000"],["78712.77000000","0.04007000"],["78713.57000000","0.00000000"],["78713.99000000","0.07514000"],["78714.00000000","0.71139000"],["78714.01000000","0.72379000"],["78714.02000000","0.00007000"],["78714.03000000","0.00000000"],["78714.13000000","0.00000000"],["78714.14000000","0.02182000"],["78714.15000000","0.24731000"],["78714.57000000","0.05432000"],["78715.40000000","0.00000000"],["78716.00000000","0.00400000"],["78716.71000000","0.00007000"],["78717.10000000","0.00008000"],["78717.65000000","0.00000000"],["78717.93000000","0.04893000"],["78717.95000000","0.00000000"],["78717.96000000","0.22743000"],["78717.99000000","0.00000000"],["78720.33000000","0.00007000"],["78721.32000000","0.00342000"],["78725.11000000","0.02000000"],["78725.90000000","0.04000000"],["78727.76000000","0.09963000"],["78728.01000000","0.04782000"],["78728.33000000","0.04857000"],["78729.78000000","0.00000000"],["78729.90000000","0.00000000"],["78730.37000000","0.00000000"],["78735.56000000","0.00000000"],["78735.62000000","0.00126000"],["78736.28000000","0.00000000"],["78736.35000000","0.00000000"],["78737.57000000","0.00007000"],["78737.72000000","0.00000000"],["78751.94000000","0.00000000"],["78757.25000000","0.00400000"],["78757.36000000","0.00000000"],["78757.54000000","0.00430000"],["78759.84000000","0.00000000"],["78760.00000000","0.02400000"],["78777.81000000","0.00000000"],["78812.07000000","0.00000000"],["78815.73000000","0.04536000"],["78819.95000000","0.00000000"],["78856.67000000","0.00406000"],["79008.53000000","0.00000000"]]}}
{"rx_ns": 18456003900, "frame": {"e":"depthUpdate","E":1787603075914,"s":"BTCUSDT","U":99076629420,"u":99076629637,"b":[["78712.00000000","0.02562000"],["78711.99000000","0.00056000"],["78710.36000000","0.00000000"],["78710.35000000","0.00014000"],["78710.31000000","0.00000000"],["78710.30000000","0.00007000"],["78710.15000000","0.00000000"],["78710.14000000","0.00014000"],["78710.10000000","0.05000000"],["78710.05000000","0.05000000"],["78710.04000000","0.00000000"],["78710.03000000","0.00007000"],["78710.01000000","0.00014000"],["78709.40000000","0.00000000"],["78709.34000000","0.00007000"],["78708.89000000","0.00007000"],["78708.01000000","0.00014000"],["78707.63000000","0.00000000"],["78706.37000000","0.00000000"],["78706.00000000","0.02407000"],["78705.87000000","0.00000000"],["78705.28000000","0.00000000"],["78705.02000000","0.00000000"],["78705.01000000","0.26060000"],["78703.59000000","1.90915000"],["78703.58000000","0.00000000"],["78701.43000000","0.12706000"],["78699.83000000","0.00000000"],["78698.85000000","0.36224000"],["78698.36000000","0.00000000"],["78698.18000000","0.00000000"],["78697.86000000","0.00000000"],["78697.37000000","0.11000000"],["78697.17000000","0.00000000"],["78696.40000000","0.00000000"],["78695.67000000","0.00000000"],["78695.37000000","0.00635000"],["78694.90000000","0.02410000"],["78694.17000000","0.00000000"],["78692.50000000","0.00000000"],["78691.77000000","0.02400000"],["78691.56000000","0.00000000"],["78691.55000000","1.90515000"],["78691.25000000","0.00000000"],["78690.63000000","0.36224000"],["78690.18000000","0.02000000"],["78690.12000000","0.02000000"],["78688.87000000","0.00000000"],["78687.12000000","0.00000000"],["78685.69000000","0.12708000"],["78678.00000000","0.02400000"],["78675.20000000","0.00000000"],["78674.44000000","0.00000000"],["78672.70000000","0.00000000"],["78670.58000000","0.00000000"],["78669.05000000","0.00000000"],["78666.82000000","0.04598000"],["78664.45000000","0.02000000"],["78663.63000000","0.00000000"],["78661.00000000","0.00400000"],["78659.48000000","0.00000000"],["78656.47000000","0.00018000"],["78652.08000000","0.00631000"],["78646.52000000","0.00000000"],["78640.87000000","0.02000000"],["78637.41000000","0.02400000"],["78634.28000000","0.02400000"],["78632.70000000","0.02000000"],["78616.74000000","1.90515000"],["78613.14000000","0.00000000"],["78592.11000000","0.80000000"],["78591.78000000","0.00000000"],["78587.54000000","0.05924000"],["78586.14000000","0.00000000"],["78483.84000000","0.09956000"],["78393.25000000","0.00000000"],["78380.20000000","0.00027000"],["70840.80000000","0.00032000"]],"a":[["78712.01000000","3.59586000"],["78712.77000000","0.04014000"],["78713.31000000","0.00014000"],["78713.32000000","0.12000000"],["78713.98000000","0.00000000"],["78713.99000000","0.00021000"],["78714.00000000","0.63255000"],["78714.01000000","0.11617000"],["78714.02000000","0.00000000"],["78714.14000000","0.02168000"],["78714.15000000","0.00348000"],["78714.57000000","0.05439000"],["78715.41000000","0.00007000"],["78716.67000000","0.00000000"],["78716.71000000","0.00000000"],["78717.18000000","0.12703000"],["78717.93000000","0.00000000"],["78717.95000000","0.00000000"],["78718.00000000","0.24439000"],["78718.89000000","0.25410000"],["78719.43000000","0.00000000"],["78719.99000000","0.00000000"],["78720.01000000","0.00000000"],["78720.10000000","0.00184000"],["78720.38000000","0.00000000"],["78721.31000000","0.00227000"],["78721.83000000","0.00007000"],["78722.16000000","0.00000000"],["78725.12000000","0.00000000"],["78726.45000000","0.00000000"],["78727.53000000","0.06588000"],["78727.99000000","0.00000000"],["78729.49000000","0.07612000"],["78730.83000000","0.00000000"],["78731.33000000","0.00000000"],["78732.61000000","0.00000000"],["78732.92000000","0.12701000"],["78734.57000000","0.00000000"],["78734.79000000","0.00000000"],["78738.48000000","0.00000000"],["78744.93000000","0.02489000"],["78752.00000000","0.03400000"],["78753.17000000","0.00000000"],["78754.00000000","0.02400000"],["78760.22000000","0.88704000"],["78760.60000000","0.00000000"],["78764.53000000","0.00634000"],["78766.31000000","0.00000000"],["78773.53000000","0.00000000"],["78773.60000000","0.91137000"],["78774.49000000","0.00000000"],["78785.14000000","0.04764000"],["78787.87000000","0.00000000"],["78805.50000000","0.00000000"],["78807.76000000","0.21930000"],["78816.57000000","0.00012000"],["78819.92000000","0.00000000"],["78822.58000000","0.00000000"],["78828.72000000","0.00000000"],["78834.48000000","0.00000000"],["78834.81000000","0.00000000"],["78898.65000000","0.00000000"],["78931.38000000","0.00000000"],["78979.17000000","0.00000000"]]}}
{"rx_ns": 18553288700, "frame": {"e":"depthUpdate","E":1787603076014,"s":"BTCUSDT","U":99076629638,"u":99076629762,"b":[["78712.00000000","0.02513000"],["78711.99000000","0.00049000"],["78710.35000000","0.00000000"],["78710.30000000","0.00000000"],["78710.14000000","0.00007000"],["78710.11000000","0.00007000"],["78710.10000000","0.00007000"],["78710.06000000","0.00000000"],["78710.05000000","0.00007000"],["78710.03000000","0.00000000"],["78710.00000000","0.02437000"],["78709.34000000","0.00000000"],["78708.89000000","0.00000000"],["78708.00000000","0.03785000"],["78706.76000000","0.00014000"],["78706.75000000","0.02274000"],["78706.17000000","0.00000000"],["78706.00000000","0.02414000"],["78705.50000000","0.00007000"],["78705.49000000","0.02729000"],["78705.02000000","0.00007000"],["78705.01000000","0.26067000"],["78704.23000000","0.02729000"],["78704.19000000","0.00014000"],["78704.01000000","0.00000000"],["78704.00000000","0.02407000"],["78703.71000000","0.00602000"],["78703.08000000","0.00000000"],["78699.97000000","0.02515000"],["78694.90000000","0.02602000"],["78690.98000000","0.02000000"],["78690.19000000","0.02000000"],["78690.11000000","0.02200000"],["78688.76000000","0.00000000"],["78669.82000000","0.50433000"],["78653.14000000","0.00406000"],["78650.69000000","0.01131000"],["78640.89000000","0.02000000"],["78640.87000000","0.00000000"],["78633.50000000","0.02000000"],["78632.63000000","0.02200000"],["78583.34000000","0.00000000"],["78576.60000000","0.04093000"],["78551.85000000","0.01990000"],["78498.84000000","0.00007000"],["78494.91000000","0.00000000"],["62969.60000000","0.00046000"]],"a":[["78712.01000000","3.62355000"],["78712.77000000","0.04014000"],["78713.27000000","0.04077000"],["78713.32000000","0.12007000"],["78713.99000000","0.00014000"],["78714.00000000","0.03663000"],["78714.14000000","0.02168000"],["78714.15000000","0.00341000"],["78714.53000000","0.04893000"],["78714.56000000","0.00000000"],["78714.57000000","0.05446000"],["78715.41000000","0.00000000"],["78715.79000000","0.04893000"],["78717.18000000","0.12710000"],["78718.00000000","0.24432000"],["78718.89000000","0.25417000"],["78719.15000000","0.00000000"],["78719.89000000","0.21930000"],["78749.91000000","0.00621000"],["78779.35000000","0.00419000"],["78822.71000000","0.00019000"],["78828.81000000","0.00031000"],["78966.02000000","0.00032000"]]}}
{"rx_ns": 18653338000, "frame": {"e":"depthUpdate","E":1787603076114,"s":"BTCUSDT","U":99076629763,"u":99076629842,"b":[["78712.00000000","0.02513000"],["78710.10000000","0.00000000"],["78710.05000000","0.00000000"],["78708.00000000","0.03785000"],["78706.75000000","0.02281000"],["78706.00000000","0.02414000"],["78705.49000000","0.02736000"],["78705.01000000","0.26067000"],["78703.71000000","0.00595000"],["78680.29000000","0.00000000"],["78680.27000000","0.00000000"],["78639.98000000","0.86894000"],["78629.21000000","0.00000000"],["78551.85000000","0.00000000"],["78518.35000000","0.01990000"],["78509.90000000","0.00042000"],["78488.05000000","0.01990000"],["78318.44000000","0.01000000"],["77926.84000000","0.01000000"],["77537.21000000","0.01000000"],["77297.28000000","0.00043000"],["77149.52000000","0.01000000"],["76763.77000000","0.01000000"],["76379.96000000","0.01000000"],["75998.06000000","0.01023000"],["75618.07000000","0.01000000"],["75239.98000000","0.01000000"],["74863.78000000","0.01000000"],["74489.46000000","0.01000000"],["74117.01000000","0.01000000"],["73746.42000000","0.01000000"],["73377.69000000","0.01000000"],["73010.80000000","0.01000000"],["70840.80000000","0.00064000"]],"a":[["78712.01000000","3.30593000"],["78712.75000000","0.00014000"],["78712.76000000","0.31783000"],["78712.77000000","0.04014000"],["78713.27000000","0.04084000"],["78714.00000000","0.03649000"],["78714.14000000","0.02168000"],["78714.53000000","0.04900000"],["78714.57000000","0.05446000"],["78717.18000000","0.12703000"],["78728.83000000","0.02515000"],["78742.61000000","0.00000000"],["78759.76000000","0.86762000"],["79105.58000000","0.01000000"],["79501.10000000","0.01000000"],["79898.61000000","0.01000000"],["80298.10000000","0.01000000"],["80699.59000000","0.01000000"],["81103.09000000","0.01000000"],["81508.61000000","0.01000000"],["81916.15000000","0.01000000"],["82325.73000000","0.01000000"],["82737.36000000","0.01000000"],["83151.04000000","0.01000000"],["83566.80000000","0.01000000"],["83984.63000000","0.01007000"],["84404.56000000","0.01000000"],["84826.58000000","0.01000000"]]}}
{"rx_ns": 18752806800, "frame": {"e":"depthUpdate","E":1787603076214,"s":"BTCUSDT","U":99076629843,"u":99076629860,"b":[["78704.19000000","0.00007000"],["78691.00000000","0.02400000"],["78639.27000000","0.02400000"],["78633.50000000","0.00000000"],["78632.70000000","0.00000000"],["78630.01000000","0.00000000"],["78628.41000000","0.00000000"],["78628.01000000","0.00315000"],["78503.62000000","0.00406000"],["70840.80000000","0.00096000"],["62969.60000000","0.00015000"]],"a":[["78712.01000000","3.30600000"],["78712.79000000","0.00007000"],["78714.57000000","0.05439000"],["78715.94000000","0.00000000"],["78718.89000000","0.00007000"]]}}
{"rx_ns": 18853402300, "frame": {"e":"depthUpdate","E":1787603076314,"s":"BTCUSDT","U":99076629861,"u":99076629886,"b":[["78703.23000000","0.02513000"],["78679.63000000","0.00000000"],["78679.55000000","0.53767000"],["78654.19000000","1.07171000"],["78645.25000000","0.02200000"],["78644.75000000","0.02000000"],["78639.27000000","0.00000000"],["78637.41000000","0.00000000"],["78634.28000000","0.00000000"],["78626.36000000","0.02116000"],["78510.34000000","0.00000000"],["78504.57000000","0.00779000"],["62971.00000000","0.00000000"],["62970.00000000","0.00000000"]],"a":[["78716.00000000","0.00900000"],["78718.00000000","0.24669000"],["78721.83000000","0.02007000"],["78725.44000000","0.02600000"],["78741.00000000","0.00000000"],["78792.86000000","0.00000000"]]}}
{"rx_ns": 18953935100, "frame": {"e":"depthUpdate","E":1787603076414,"s":"BTCUSDT","U":99076629887,"u":99076629910,"b":[["78703.23000000","0.00000000"],["78702.92000000","0.00000000"],["78692.49000000","0.00000000"],["78673.39000000","0.09710000"],["78663.73000000","0.02822000"],["78653.14000000","0.00000000"],["78626.36000000","0.00000000"],["78621.66000000","0.00000000"],["78574.45000000","0.00000000"],["78503.62000000","0.00000000"],["76825.00000000","0.00090000"],["70840.80000000","0.00128000"]],"a":[["78734.80000000","0.00000000"],["78738.44000000","0.00000000"],["78738.56000000","0.00000000"],["78774.23000000","0.00007000"],["78777.93000000","0.00000000"],["78809.43000000","0.00000000"],["78818.34000000","0.00000000"],["78856.67000000","0.00000000"],["78927.54000000","0.00000000"]]}}
{"rx_ns": 19062684200, "frame": {"e":"depthUpdate","E":1787603076514,"s":"BTCUSDT","U":99076629911,"u":99076629916,"b":[["78632.63000000","0.00000000"],["70840.80000000","0.00144000"],["70840.00000000","0.14240000"],["62969.60000000","0.00046000"]],"a":[["79700.00000000","1.58826000"]]}}
{"rx_ns": 19158708100, "frame": {"e":"depthUpdate","E":1787603076614,"s":"BTCUSDT","U":99076629917,"u":99076629960,"b":[["78712.00000000","0.03393000"],["78711.99000000","0.00062000"],["78711.98000000","0.00013000"],["78675.00000000","0.70000000"],["78500.48000000","0.00406000"],["78318.44000000","0.00000000"],["77926.84000000","0.00000000"],["77537.21000000","0.00000000"],["77149.52000000","0.00000000"],["76763.77000000","0.00000000"],["76379.96000000","0.00000000"],["75998.06000000","0.00023000"],["75618.07000000","0.00000000"],["75239.98000000","0.00000000"],["74863.78000000","0.00000000"],["74489.46000000","0.00000000"],["74117.01000000","0.00000000"],["73746.42000000","0.00000000"],["73377.69000000","0.00000000"],["73010.80000000","0.00000000"],["70840.80000000","0.00144000"],["62969.60000000","0.00015000"]],"a":[["78712.01000000","3.30613000"],["78718.00000000","0.24676000"],["78719.14000000","0.01270000"],["78719.18000000","0.06350000"],["79105.58000000","0.00000000"],["79501.10000000","0.00000000"],["79898.61000000","0.00000000"],["80298.10000000","0.00000000"],["80699.59000000","0.00000000"],["81103.09000000","0.00000000"],["81508.61000000","0.00000000"],["81916.15000000","0.00000000"],["82325.73000000","0.00000000"],["82737.36000000","0.00000000"],["83151.04000000","0.00000000"],["83566.80000000","0.00000000"],["83984.63000000","0.00007000"],["84404.56000000","0.00000000"],["84826.58000000","0.00000000"]]}}
{"rx_ns": 19255160400, "frame": {"e":"depthUpdate","E":1787603076714,"s":"BTCUSDT","U":99076629961,"u":99076629975,"b":[["78712.00000000","0.03836000"],["78704.19000000","0.00014000"],["76352.71000000","0.00043000"],["70840.80000000","0.00160000"],["62969.60000000","0.00035000"]],"a":[["78712.01000000","3.30620000"],["78712.75000000","0.00000000"],["78712.76000000","0.00014000"],["78713.25000000","0.00014000"],["78713.26000000","0.31769000"]]}}
{"rx_ns": 19353189800, "frame": {"e":"depthUpdate","E":1787603076814,"s":"BTCUSDT","U":99076629976,"u":99076629994,"b":[["78712.00000000","0.03586000"],["78690.33000000","0.00000000"],["78688.34000000","0.00007000"],["78618.51000000","0.00406000"],["78301.00000000","0.05000000"],["78001.00000000","0.00681000"],["70840.80000000","0.00176000"],["62969.60000000","0.00015000"]],"a":[["78712.01000000","3.30620000"],["78712.77000000","0.04014000"],["78713.58000000","0.00007000"],["78716.38000000","0.00007000"],["78735.58000000","0.00407000"],["78737.57000000","0.00000000"],["78746.00000000","0.74561000"],["78930.06000000","0.01990000"],["78947.17000000","0.00000000"]]}}
{"rx_ns": 19455133200, "frame": {"e":"depthUpdate","E":1787603076914,"s":"BTCUSDT","U":99076629995,"u":99076630009,"b":[["78712.00000000","0.03593000"],["78702.50000000","0.03586000"],["78701.31000000","0.00000000"],["78700.46000000","0.08576000"],["78640.87000000","0.02000000"],["70840.80000000","0.00160000"]],"a":[["78717.96000000","0.22750000"],["78717.99000000","0.30000000"],["78719.26000000","0.00230000"],["78727.48000000","0.04857000"],["78728.33000000","0.00000000"],["78745.85000000","0.02849000"],["78761.72000000","0.00000000"]]}}
{"rx_ns": 19553443900, "frame": {"e":"depthUpdate","E":1787603077015,"s":"BTCUSDT","U":99076630010,"u":99076630018,"b":[["78712.00000000","0.03729000"],["78707.01000000","0.00000000"],["78673.39000000","0.00000000"],["78672.21000000","0.09460000"],["75880.43000000","0.00057000"],["70840.80000000","0.00192000"],["62969.60000000","0.00046000"]],"a":[["78735.40000000","0.00406000"]]}}
{"rx_ns": 19654879200, "frame": {"e":"depthUpdate","E":1787603077114,"s":"BTCUSDT","U":99076630019,"u":99076630184,"b":[["78712.00000000","0.42151000"],["78711.99000000","0.00083000"],["78711.98000000","0.00014000"],["78711.97000000","0.00007000"],["78708.17000000","0.00000000"],["78705.00000000","0.00000000"],["78704.95000000","0.00000000"],["78704.23000000","0.02736000"],["78703.71000000","0.00595000"],["78702.50000000","0.00000000"],["78701.85000000","0.00000000"],["78701.37000000","0.00000000"],["78700.94000000","0.00318000"],["78697.43000000","0.00317000"],["78693.49000000","0.00321000"],["78689.55000000","0.00330000"],["78685.61000000","0.00317000"],["78679.55000000","0.00000000"],["78665.49000000","0.00000000"],["78501.75000000","0.00007000"],["78493.89000000","0.00007000"],["78318.42000000","0.01031000"],["78005.71000000","0.00000000"],["77926.82000000","0.01000000"],["77537.19000000","0.01000000"],["77149.50000000","0.01000000"],["76763.76000000","0.01000000"],["76379.94000000","0.01000000"],["75998.04000000","0.01000000"],["75618.05000000","0.01000000"],["75239.96000000","0.01000000"],["74863.76000000","0.01000000"],["74489.44000000","0.01000000"],["74116.99000000","0.01000000"],["73746.41000000","0.01000000"],["73377.67000000","0.01000000"],["73010.79000000","0.01000000"],["70840.80000000","0.00192000"]],"a":[["78712.01000000","2.25407000"],["78713.24000000","0.00000000"],["78713.25000000","0.00000000"],["78713.26000000","0.00021000"],["78713.99000000","0.31783000"],["78714.14000000","0.00007000"],["78714.15000000","0.00331000"],["78715.64000000","0.00192000"],["78718.00000000","0.24669000"],["78719.14000000","0.00000000"],["78719.18000000","0.00000000"],["78723.12000000","0.00000000"],["78723.31000000","0.00000000"],["78809.60000000","0.00025000"],["78811.75000000","0.00000000"],["79105.58000000","0.01000000"],["79501.10000000","0.01000000"],["79898.61000000","0.01000000"],["80298.10000000","0.01000000"],["80699.59000000","0.01000000"],["81103.09000000","0.01000000"],["81508.61000000","0.01000000"],["81916.15000000","0.01000000"],["82325.73000000","0.01000000"],["82737.36000000","0.01000000"],["83151.04000000","0.01000000"],["83566.80000000","0.01000000"],["83984.63000000","0.01007000"],["84404.56000000","0.01000000"],["84826.58000000","0.01000000"]]}}
{"rx_ns": 19754719200, "frame": {"e":"depthUpdate","E":1787603077214,"s":"BTCUSDT","U":99076630185,"u":99076630208,"b":[["78712.00000000","0.42260000"],["78711.97000000","0.00000000"],["78649.99000000","0.00406000"],["78639.27000000","0.02400000"],["78493.89000000","0.00000000"],["70840.80000000","0.00208000"],["62969.60000000","0.00015000"]],"a":[["78712.01000000","2.25219000"],["78712.77000000","0.04014000"],["78713.26000000","0.00014000"],["78713.32000000","0.12007000"],["78713.99000000","0.31790000"],["78714.01000000","0.11617000"],["78714.14000000","0.00000000"],["78714.57000000","0.05446000"],["78722.45000000","0.00000000"]]}}
{"rx_ns": 19853437800, "frame": {"e":"depthUpdate","E":1787603077314,"s":"BTCUSDT","U":99076630209,"u":99076630237,"b":[["78712.00000000","0.41892000"],["78711.99000000","0.00090000"],["78711.23000000","0.00007000"],["75408.14000000","0.00044000"],["62970.00000000","0.00000000"]],"a":[["78712.01000000","2.25411000"],["78715.64000000","0.00000000"],["78722.42000000","0.00000000"],["78741.55000000","0.02000000"],["78745.17000000","0.02600000"],["78786.90000000","0.02600000"],["78792.86000000","0.00000000"],["78838.01000000","0.01990000"],["78864.65000000","0.00000000"]]}}
{"rx_ns": 19954891300, "frame": {"e":"depthUpdate","E":1787603077414,"s":"BTCUSDT","U":99076630238,"u":99076630251,"b":[["78680.34000000","0.51851000"],["78666.36000000","0.00400000"],["78658.25000000","0.00000000"],["78652.97000000","0.00007000"],["70840.80000000","0.00224000"]],"a":[["78712.01000000","2.25182000"],["78786.90000000","0.00000000"],["78839.94000000","0.00000000"],["78876.70000000","0.00102000"],["78924.37000000","0.00406000"]]}}
{"rx_ns": 20059010200, "frame": {"e":"depthUpdate","E":1787603077514,"s":"BTCUSDT","U":99076630252,"u":99076630257,"b":[["78655.89000000","0.87146000"],["78607.99000000","2.77199000"],["78510.34000000","0.00778000"],["78504.57000000","0.00000000"],["70840.80000000","0.00224000"],["62969.60000000","0.00046000"]],"a":[]}}
{"rx_ns": 20162946800, "frame": {"e":"depthUpdate","E":1787603077615,"s":"BTCUSDT","U":99076630258,"u":99076630305,"b":[["78712.00000000","0.00243000"],["78703.71000000","0.00602000"],["78318.42000000","0.00031000"],["77926.82000000","0.00000000"],["77537.19000000","0.00000000"],["77149.50000000","0.00000000"],["76763.76000000","0.00000000"],["76379.94000000","0.00000000"],["75998.04000000","0.00000000"],["75618.05000000","0.00000000"],["75239.96000000","0.00000000"],["74935.86000000","0.00044000"],["74863.76000000","0.00000000"],["74489.44000000","0.00000000"],["74116.99000000","0.00000000"],["73746.41000000","0.00000000"],["73377.67000000","0.00000000"],["73010.79000000","0.00000000"],["70840.80000000","0.00240000"],["70840.00000000","0.14240000"],["62969.60000000","0.00015000"]],"a":[["78712.01000000","2.25183000"],["78853.51000000","0.00406000"],["78879.35000000","0.00000000"],["79034.46000000","0.00506000"],["79105.58000000","0.00000000"],["79501.10000000","0.00000000"],["79898.61000000","0.00000000"],["80298.10000000","0.00000000"],["80699.59000000","0.00000000"],["81103.09000000","0.00000000"],["81508.61000000","0.00000000"],["81916.15000000","0.00000000"],["82325.73000000","0.00000000"],["82737.36000000","0.00000000"],["83151.04000000","0.00000000"],["83566.80000000","0.00000000"],["83984.63000000","0.00007000"],["84404.56000000","0.00000000"],["84826.58000000","0.00000000"]]}}
{"rx_ns": 20259264600, "frame": {"e":"depthUpdate","E":1787603077714,"s":"BTCUSDT","U":99076630306,"u":99076630716,"b":[["78712.00000000","0.00000000"],["78711.99000000","0.00000000"],["78711.98000000","0.00000000"],["78711.23000000","0.00000000"],["78710.64000000","0.00000000"],["78710.62000000","0.00000000"],["78710.14000000","0.00000000"],["78710.11000000","0.00000000"],["78710.01000000","0.00000000"],["78710.00000000","0.00000000"],["78709.68000000","0.00000000"],["78708.21000000","0.00000000"],["78708.06000000","0.00000000"],["78708.01000000","0.00000000"],["78708.00000000","0.00000000"],["78706.76000000","0.00000000"],["78706.75000000","0.00000000"],["78706.62000000","0.00000000"],["78706.16000000","0.00000000"],["78706.11000000","0.00000000"],["78706.01000000","0.00000000"],["78706.00000000","0.00000000"],["78705.80000000","0.00000000"],["78705.50000000","0.00000000"],["78705.49000000","0.00000000"],["78705.02000000","0.00000000"],["78705.01000000","0.84878000"],["78705.00000000","0.05042000"],["78704.96000000","0.00014000"],["78704.95000000","0.05000000"],["78704.56000000","0.00000000"],["78704.24000000","0.00000000"],["78704.23000000","0.00007000"],["78704.19000000","0.00007000"],["78704.12000000","0.00000000"],["78704.01000000","0.00014000"],["78703.92000000","0.00000000"],["78703.60000000","1.90515000"],["78703.59000000","0.00007000"],["78703.58000000","0.00014000"],["78703.57000000","1.21959000"],["78703.50000000","0.00000000"],["78703.39000000","0.00000000"],["78703.37000000","0.00007000"],["78703.36000000","0.31782000"],["78702.80000000","0.00000000"],["78702.24000000","0.00000000"],["78702.07000000","0.00000000"],["78702.00000000","0.02407000"],["78701.87000000","0.00000000"],["78701.79000000","0.02807000"],["78701.43000000","0.00007000"],["78701.41000000","0.00000000"],["78701.14000000","0.00334000"],["78700.94000000","0.00000000"],["78700.67000000","0.00000000"],["78700.46000000","0.00007000"],["78700.35000000","0.00007000"],["78699.56000000","0.00326000"],["78695.26000000","0.08576000"],["78695.11000000","0.00007000"],["78694.90000000","0.02410000"],["78693.26000000","0.00326000"],["78691.96000000","0.00007000"],["78691.89000000","0.00000000"],["78690.12000000","0.14708000"],["78687.00000000","0.03238000"],["78685.69000000","0.00000000"],["78685.38000000","0.00327000"],["78681.67000000","0.00000000"],["78681.58000000","0.12709000"],["78680.31000000","0.00254000"],["78677.50000000","0.00321000"],["78672.21000000","0.00000000"],["78672.15000000","0.00000000"],["78672.00000000","0.02400000"],["78669.62000000","0.00330000"],["78669.36000000","0.00014000"],["78668.61000000","0.02524000"],["78666.12000000","0.00000000"],["78665.49000000","0.00007000"],["78665.00000000","0.01000000"],["78663.73000000","0.00000000"],["78662.40000000","0.05554000"],["78652.91000000","0.00400000"],["78650.01000000","0.00000000"],["78642.74000000","0.00316000"],["78628.01000000","0.00000000"],["78626.36000000","0.02116000"],["78621.27000000","0.00316000"],["78607.99000000","0.00000000"],["78601.04000000","0.00007000"],["78571.48000000","0.00000000"],["78564.04000000","0.00127000"],["78551.73000000","0.00000000"],["78543.06000000","0.00127000"],["78494.76000000","0.00007000"],["78490.83000000","0.00080000"],["78403.41000000","0.00000000"],["78366.58000000","1.76766000"],["78317.01000000","0.00014000"],["70840.80000000","0.00009000"],["70834.51000000","0.00016000"]],"a":[["78705.02000000","1.86062000"],["78705.03000000","0.00020000"],["78705.04000000","0.00013000"],["78705.49000000","0.00000000"],["78705.50000000","0.00000000"],["78706.01000000","0.00000000"],["78706.76000000","0.00000000"],["78707.57000000","0.00014000"],["78707.58000000","0.05440000"],["78708.01000000","0.00000000"],["78708.06000000","0.00014000"],["78708.85000000","0.00508000"],["78708.86000000","0.00027000"],["78710.01000000","0.00000000"],["78710.12000000","0.00000000"],["78710.15000000","0.00000000"],["78710.63000000","0.00000000"],["78710.65000000","0.00000000"],["78711.24000000","0.00000000"],["78711.93000000","0.00014000"],["78711.99000000","0.00014000"],["78712.00000000","0.28254000"],["78712.01000000","0.31517000"],["78712.02000000","0.00000000"],["78712.03000000","0.00000000"],["78712.09000000","0.00400000"],["78712.76000000","0.00014000"],["78713.05000000","0.00000000"],["78713.06000000","0.00000000"],["78713.26000000","0.00000000"],["78713.27000000","0.00007000"],["78713.31000000","0.00007000"],["78713.56000000","0.00007000"],["78713.99000000","0.31776000"],["78714.00000000","0.00649000"],["78714.03000000","0.00007000"],["78714.53000000","0.00007000"],["78714.57000000","0.00007000"],["78714.84000000","0.00007000"],["78715.00000000","0.00007000"],["78715.79000000","0.00000000"],["78717.18000000","0.12710000"],["78717.47000000","0.00400000"],["78718.00000000","0.24662000"],["78718.77000000","0.00007000"],["78718.89000000","0.00000000"],["78720.77000000","0.11276000"],["78721.32000000","1.90857000"],["78722.28000000","0.04857000"],["78723.08000000","0.25410000"],["78723.48000000","0.00000000"],["78723.87000000","0.38116000"],["78726.63000000","0.00000000"],["78727.48000000","0.00000000"],["78727.76000000","0.00007000"],["78732.92000000","0.00000000"],["78734.39000000","0.39722000"],["78734.84000000","0.00010000"],["78736.84000000","0.00000000"],["78738.70000000","0.00000000"],["78742.53000000","0.00000000"],["78742.71000000","0.00010000"],["78745.00000000","0.01000000"],["78746.76000000","0.00000000"],["78750.63000000","0.00000000"],["78752.00000000","0.02400000"],["78754.87000000","0.00315000"],["78754.88000000","0.00000000"],["78757.25000000","0.00000000"],["78763.38000000","0.00000000"],["78771.66000000","0.00000000"],["78773.71000000","0.00000000"],["78774.23000000","0.00000000"],["78775.67000000","0.00317000"],["78778.00000000","0.02400000"],["78785.33000000","0.00000000"],["78790.66000000","0.00000000"],["78813.63000000","0.80000000"],["78832.97000000","0.00127000"],["78841.60000000","0.00000000"],["78845.90000000","0.00000000"],["78855.28000000","0.00127000"],["78865.99000000","0.00000000"],["78893.17000000","0.00000000"],["78922.81000000","0.00000000"],["78926.74000000","0.00000000"],["78929.06000000","0.00000000"],["79003.32000000","0.00000000"],["79105.44000000","0.00000000"]]}}
{"rx_ns": 20353496100, "frame": {"e":"depthUpdate","E":1787603077814,"s":"BTCUSDT","U":99076630717,"u":99076630830,"b":[["78705.01000000","3.38276000"],["78705.00000000","0.05077000"],["78704.95000000","0.05014000"],["78704.23000000","0.00000000"],["78703.71000000","0.00602000"],["78703.70000000","0.00014000"],["78703.69000000","0.26056000"],["78703.61000000","0.00414000"],["78703.60000000","1.90522000"],["78703.59000000","0.00000000"],["78703.58000000","0.00000000"],["78703.37000000","0.00000000"],["78701.79000000","0.02800000"],["78700.28000000","0.01245000"],["78699.19000000","0.12713000"],["78699.02000000","0.02075000"],["78697.92000000","0.03224000"],["78697.76000000","0.02490000"],["78696.50000000","0.02490000"],["78688.34000000","0.00000000"],["78680.31000000","0.13453000"],["78658.29000000","0.00400000"],["78655.60000000","0.00000000"],["78652.91000000","0.00000000"],["78626.36000000","0.00000000"],["70834.51000000","0.00032000"],["62969.60000000","0.00015000"],["62964.01000000","0.00000000"]],"a":[["78705.02000000","1.35380000"],["78706.27000000","0.00014000"],["78706.28000000","0.04277000"],["78707.53000000","0.00014000"],["78707.54000000","0.05132000"],["78707.58000000","0.05454000"],["78708.79000000","0.00007000"],["78708.80000000","0.05132000"],["78708.85000000","0.00007000"],["78708.86000000","0.00000000"],["78710.43000000","0.00027000"],["78711.92000000","0.00508000"],["78712.00000000","0.02360000"],["78712.01000000","0.29517000"],["78712.29000000","0.00007000"],["78712.76000000","0.00000000"],["78712.77000000","0.04007000"],["78712.79000000","0.00000000"],["78713.27000000","0.00000000"],["78713.31000000","0.00000000"],["78713.58000000","0.00000000"],["78714.00000000","0.00014000"],["78714.01000000","0.11610000"],["78714.53000000","0.00000000"],["78715.15000000","0.00000000"],["78717.09000000","0.00635000"],["78718.00000000","0.24655000"],["78720.68000000","0.00000000"],["78724.32000000","0.00000000"],["78735.58000000","0.00400000"],["78806.27000000","0.00406000"],["79192.53000000","0.00608000"]]}}
{"rx_ns": 20460697200, "frame": {"e":"depthUpdate","E":1787603077914,"s":"BTCUSDT","U":99076630831,"u":99076630883,"b":[["78705.01000000","3.38279000"],["78705.00000000","0.00063000"],["78704.96000000","0.00000000"],["78704.95000000","0.00014000"],["78704.19000000","0.00014000"],["78703.71000000","0.00602000"],["78703.69000000","0.26063000"],["78703.58000000","0.00014000"],["78703.37000000","0.00007000"],["78703.36000000","0.31789000"],["78703.30000000","0.05000000"],["78703.25000000","0.05000000"],["78702.00000000","0.02400000"],["78699.19000000","0.00000000"],["78681.36000000","0.00007000"],["78665.49000000","0.00000000"],["70834.51000000","0.00048000"]],"a":[["78705.02000000","1.35397000"],["78706.28000000","0.04284000"],["78707.54000000","0.05139000"],["78707.58000000","0.05454000"],["78708.79000000","0.00014000"],["78708.80000000","0.05139000"],["78708.85000000","0.00000000"],["78711.92000000","0.00515000"],["78713.32000000","0.12000000"],["78713.99000000","0.31769000"],["78714.00000000","0.00007000"],["78716.00000000","0.01600000"],["78720.76000000","0.00007000"],["78723.42000000","0.02000000"],["78728.59000000","0.00007000"],["78733.74000000","0.00000000"],["78816.57000000","0.00000000"],["78822.71000000","0.00000000"],["78828.81000000","0.00000000"]]}}
{"rx_ns": 20557329900, "frame": {"e":"depthUpdate","E":1787603078014,"s":"BTCUSDT","U":99076630884,"u":99076630923,"b":[["78705.01000000","3.38258000"],["78705.00000000","0.00056000"],["78704.95000000","0.00007000"],["78703.36000000","0.31782000"],["78703.30000000","0.00007000"],["78703.25000000","0.00007000"],["78702.55000000","0.05000000"],["78689.34000000","0.00406000"],["78383.76000000","0.00008000"],["74463.57000000","0.00044000"],["70840.80000000","0.00000000"],["70840.79000000","0.00009000"],["70834.51000000","0.00064000"],["62964.01000000","0.00031000"]],"a":[["78705.02000000","1.34781000"],["78708.87000000","0.00007000"],["78712.77000000","0.04014000"],["78717.44000000","0.00007000"],["78719.42000000","0.04161000"],["78722.58000000","0.02000000"],["78723.34000000","0.02600000"],["78723.43000000","0.02000000"],["78732.90000000","0.02000000"],["78768.47000000","0.00000000"],["78777.18000000","0.00000000"],["78809.58000000","0.00012000"],["78815.72000000","0.00019000"],["78824.90000000","0.00000000"]]}}
{"rx_ns": 20653359700, "frame": {"e":"depthUpdate","E":1787603078114,"s":"BTCUSDT","U":99076630924,"u":99076630972,"b":[["78703.36000000","0.31782000"],["78703.30000000","0.00000000"],["78703.25000000","0.00000000"],["78702.55000000","0.00007000"],["78702.40000000","0.05000000"],["78702.35000000","0.05000000"],["78702.00000000","0.02407000"],["78701.11000000","0.00000000"],["78311.48000000","0.01000000"],["77996.66000000","0.00010000"],["77919.92000000","0.01000000"],["77530.32000000","0.01000000"],["77142.67000000","0.01000000"],["76756.96000000","0.01000000"],["76373.17000000","0.01000000"],["75991.31000000","0.01000000"],["75611.35000000","0.01000000"],["75233.29000000","0.01000000"],["74857.13000000","0.01000000"],["74482.84000000","0.01000000"],["74110.43000000","0.01000000"],["73739.88000000","0.01000000"],["73371.18000000","0.01000000"],["73004.32000000","0.01000000"],["70834.51000000","0.00096000"]],"a":[["78705.02000000","1.34791000"],["78729.07000000","0.00000000"],["78732.86000000","0.00000000"],["78732.90000000","0.00000000"],["78736.51000000","0.00000000"],["78821.81000000","0.00031000"],["79098.55000000","0.01000000"],["79494.04000000","0.01000000"],["79891.51000000","0.01008000"],["80290.97000000","0.01000000"],["80692.43000000","0.01000000"],["81095.89000000","0.01000000"],["81501.37000000","0.01000000"],["81908.87000000","0.01000000"],["82318.42000000","0.01000000"],["82730.01000000","0.01000000"],["83143.66000000","0.01000000"],["83559.38000000","0.01000000"],["83977.18000000","0.01000000"],["84397.06000000","0.01000000"],["84819.05000000","0.01000000"]]}}
{"rx_ns": 20753212900, "frame": {"e":"depthUpdate","E":1787603078214,"s":"BTCUSDT","U":99076630973,"u":99076631000,"b":[["78705.01000000","3.38279000"],["78703.36000000","0.31789000"],["78702.55000000","0.00000000"],["78702.40000000","0.00014000"],["78702.35000000","0.00007000"],["78702.00000000","0.02400000"],["78671.76000000","0.09750000"],["78571.30000000","0.00406000"],["78267.31000000","0.00000000"],["78175.73000000","0.01526000"],["62964.01000000","0.00000000"]],"a":[["78705.02000000","1.34804000"],["78710.00000000","0.00700000"],["78712.00000000","0.03060000"],["78714.00000000","0.00707000"],["78716.00000000","0.02300000"],["78718.00000000","0.25355000"],["78722.60000000","0.02000000"],["78732.08000000","0.00000000"],["78776.32000000","0.00000000"],["78800.09000000","0.00529000"],["78812.84000000","0.00000000"]]}}
{"rx_ns": 20853963600, "frame": {"e":"depthUpdate","E":1787603078314,"s":"BTCUSDT","U":99076631001,"u":99076631032,"b":[["78705.01000000","3.38265000"],["78703.36000000","0.31782000"],["78702.40000000","0.00000000"],["78702.35000000","0.00000000"],["78702.00000000","0.02407000"],["78701.79000000","0.02807000"],["78626.36000000","0.02116000"],["73991.29000000","0.00045000"],["70834.51000000","0.00128000"],["62964.00000000","0.00000000"]],"a":[["78705.02000000","1.99838000"],["78707.23000000","0.00327000"],["78708.80000000","0.05139000"],["78710.00000000","0.00707000"],["78711.17000000","0.00324000"],["78712.01000000","0.07587000"],["78712.77000000","0.04007000"],["78732.10000000","0.00000000"],["78734.20000000","0.00000000"],["78739.96000000","0.00000000"],["78776.33000000","0.00000000"]]}}
{"rx_ns": 20955268800, "frame": {"e":"depthUpdate","E":1787603078414,"s":"BTCUSDT","U":99076631033,"u":99076631062,"b":[["78703.37000000","0.00014000"],["78690.28000000","0.00007000"],["78689.34000000","0.00000000"],["78649.99000000","0.00000000"],["78626.36000000","0.00000000"],["78618.51000000","0.00000000"],["78571.30000000","0.00000000"],["78500.48000000","0.00000000"],["70834.51000000","0.00144000"]],"a":[["78705.02000000","1.18398000"],["78707.23000000","0.00000000"],["78707.67000000","0.00322000"],["78712.01000000","0.07580000"],["78713.99000000","0.00000000"],["78714.01000000","0.11617000"],["78714.90000000","0.31768000"],["78721.32000000","0.00342000"],["78735.40000000","0.00000000"],["78741.00000000","0.70000000"],["78774.77000000","0.00000000"],["78790.00000000","0.02400000"],["78790.65000000","1.90515000"],["78806.27000000","0.00000000"],["78815.64000000","0.21930000"],["78837.94000000","0.00160000"],["78853.51000000","0.00000000"],["78924.37000000","0.00000000"],["79350.92000000","0.00115000"]]}}
{"rx_ns": 21054236200, "frame": {"e":"depthUpdate","E":1787603078514,"s":"BTCUSDT","U":99076631063,"u":99076631075,"b":[["78699.81000000","0.12713000"],["78662.40000000","0.02800000"],["70834.51000000","0.00144000"],["62964.01000000","0.00031000"]],"a":[["78710.00000000","0.01207000"],["78710.24000000","0.00007000"],["78712.00000000","0.03560000"],["78712.01000000","0.07443000"],["78714.00000000","0.01207000"],["78714.56000000","0.00137000"],["78717.96000000","0.22736000"],["79668.65000000","0.00026000"]]}}
{"rx_ns": 21160196800, "frame": {"e":"depthUpdate","E":1787603078614,"s":"BTCUSDT","U":99076631076,"u":99076631122,"b":[["78705.01000000","3.38278000"],["78705.00000000","0.00069000"],["78704.99000000","0.00013000"],["78703.36000000","0.31782000"],["78699.81000000","0.00000000"],["78699.54000000","0.00000000"],["78518.36000000","0.00778000"],["78510.34000000","0.00000000"],["78311.48000000","0.00000000"],["77919.92000000","0.00000000"],["77530.32000000","0.00000000"],["77142.67000000","0.00000000"],["76756.96000000","0.00000000"],["76373.17000000","0.00000000"],["75991.31000000","0.00000000"],["75611.35000000","0.00000000"],["75233.29000000","0.00000000"],["74857.13000000","0.00000000"],["74482.84000000","0.00000000"],["74110.43000000","0.00000000"],["73739.88000000","0.00000000"],["73519.00000000","0.00045000"],["73371.18000000","0.00000000"],["73004.32000000","0.00000000"],["70834.51000000","0.00160000"],["70834.00000000","0.00000000"],["62964.01000000","0.00000000"]],"a":[["78716.00000000","0.02800000"],["78919.72000000","0.00406000"],["79098.55000000","0.00000000"],["79494.04000000","0.00000000"],["79827.99000000","0.00038000"],["79891.51000000","0.00008000"],["80290.97000000","0.00000000"],["80692.43000000","0.00000000"],["81095.89000000","0.00000000"],["81501.37000000","0.00000000"],["81908.87000000","0.00000000"],["82318.42000000","0.00000000"],["82730.01000000","0.00000000"],["83143.66000000","0.00000000"],["83559.38000000","0.00000000"],["83977.18000000","0.00000000"],["84397.06000000","0.00000000"],["84819.05000000","0.00000000"]]}}
{"rx_ns": 21253113500, "frame": {"e":"depthUpdate","E":1787603078714,"s":"BTCUSDT","U":99076631123,"u":99076631146,"b":[["78705.01000000","3.38285000"],["78702.65000000","0.00000000"],["78702.60000000","0.00000000"],["78701.59000000","0.00321000"],["78626.36000000","0.02116000"],["70834.51000000","0.00176000"]],"a":[["78705.02000000","1.63262000"],["78706.54000000","0.00014000"],["78706.55000000","0.04025000"],["78711.99000000","0.00000000"],["78712.77000000","0.00000000"],["78718.50000000","0.01270000"],["78718.54000000","0.06350000"],["78721.94000000","0.12702000"],["78877.35000000","0.00160000"],["79987.65000000","0.00033000"]]}}
{"rx_ns": 21352931500, "frame": {"e":"depthUpdate","E":1787603078814,"s":"BTCUSDT","U":99076631147,"u":99076631167,"b":[["78700.42000000","0.00000000"],["78699.91000000","0.00000000"],["78684.69000000","0.00406000"],["78626.36000000","0.00000000"],["70834.51000000","0.00176000"],["62964.01000000","0.00000000"]],"a":[["78705.02000000","1.63262000"],["78706.28000000","0.04284000"],["78706.55000000","0.04032000"],["78712.01000000","0.07436000"],["78714.15000000","0.00324000"],["78714.34000000","0.00007000"],["80147.63000000","0.00522000"]]}}
{"rx_ns": 21453161200, "frame": {"e":"depthUpdate","E":1787603078914,"s":"BTCUSDT","U":99076631168,"u":99076631202,"b":[["78702.45000000","0.05000000"],["78702.40000000","0.05000000"],["78700.41000000","0.00000000"],["78700.28000000","0.13958000"],["78681.36000000","0.00007000"],["72420.55000000","0.00014000"],["70834.51000000","0.00192000"]],"a":[["78705.02000000","1.63359000"],["78705.03000000","0.00069000"],["78706.50000000","0.00007000"],["78718.67000000","0.02318000"],["78721.82000000","0.02000000"],["78723.39000000","0.02000000"],["78728.59000000","0.00007000"],["78772.39000000","0.02000000"]]}}
{"rx_ns": 21554737600, "frame": {"e":"depthUpdate","E":1787603079014,"s":"BTCUSDT","U":99076631203,"u":99076631228,"b":[["78703.36000000","0.31796000"],["78702.45000000","0.00007000"],["78702.40000000","0.00007000"],["78702.00000000","0.02400000"],["78701.79000000","0.02800000"],["78700.48000000","0.00000000"],["78700.42000000","0.12713000"],["78700.28000000","0.01245000"],["78662.35000000","0.02838000"],["78566.66000000","0.00413000"],["70834.51000000","0.00192000"],["62964.01000000","0.00031000"]],"a":[["78705.02000000","1.63359000"],["78728.11000000","0.00000000"],["78768.47000000","0.02000000"],["78771.56000000","0.02000000"]]}}
{"rx_ns": 21655002700, "frame": {"e":"depthUpdate","E":1787603079114,"s":"BTCUSDT","U":99076631229,"u":99076631252,"b":[["78703.36000000","0.31789000"],["78702.50000000","0.00000000"],["78702.45000000","0.00000000"],["78702.40000000","0.00000000"],["78702.03000000","0.12713000"],["78702.00000000","0.02407000"],["78701.79000000","0.02807000"],["78700.53000000","0.00000000"],["78700.42000000","0.00000000"],["78680.34000000","0.00000000"],["78654.19000000","0.00000000"],["70834.51000000","0.00208000"]],"a":[["78731.28000000","0.00014000"],["78732.85000000","0.00000000"],["78802.60000000","0.00025000"],["78809.60000000","0.00000000"]]}}
{"rx_ns": 21753195200, "frame": {"e":"depthUpdate","E":1787603079214,"s":"BTCUSDT","U":99076631253,"u":99076631266,"b":[["78703.36000000","0.31796000"],["78702.60000000","0.00000000"],["78702.55000000","0.05000000"],["78702.03000000","0.00007000"],["78701.79000000","0.02800000"],["78495.84000000","0.00406000"],["70834.51000000","0.00224000"],["62964.01000000","0.00000000"]],"a":[["78705.02000000","1.63366000"],["78771.57000000","0.02000000"]]}}
{"rx_ns": 21854415800, "frame": {"e":"depthUpdate","E":1787603079314,"s":"BTCUSDT","U":99076631267,"u":99076631324,"b":[["78703.36000000","0.31796000"],["78702.55000000","0.00007000"],["78702.03000000","0.00000000"],["78700.76000000","0.00000000"],["78700.73000000","0.12713000"],["78700.69000000","0.00000000"],["78700.54000000","0.00000000"],["78311.48000000","0.01000000"],["77919.92000000","0.01000000"],["77530.32000000","0.01000000"],["77142.67000000","0.01000000"],["76756.96000000","0.01000000"],["76373.17000000","0.01000000"],["75991.31000000","0.01000000"],["75611.35000000","0.01000000"],["75233.29000000","0.01000000"],["74857.13000000","0.01000000"],["74482.84000000","0.01000000"],["74110.43000000","0.01000000"],["73739.88000000","0.01000000"],["73371.18000000","0.01000000"],["73004.32000000","0.01000000"],["70834.51000000","0.00224000"],["62970.00000000","0.00000000"]],"a":[["78705.02000000","1.63314000"],["78705.03000000","0.00076000"],["78708.00000000","0.00500000"],["78710.00000000","0.01707000"],["78712.00000000","0.04060000"],["78714.00000000","0.01707000"],["79098.55000000","0.01000000"],["79494.04000000","0.01000000"],["79891.51000000","0.01008000"],["80290.97000000","0.01000000"],["80307.93000000","0.00221000"],["80692.43000000","0.01000000"],["81095.89000000","0.01000000"],["81501.37000000","0.01000000"],["81908.87000000","0.01000000"],["82318.42000000","0.01000000"],["82730.01000000","0.01000000"],["83143.66000000","0.01000000"],["83559.38000000","0.01000000"],["83977.18000000","0.01000000"],["84397.06000000","0.01000000"],["84819.05000000","0.01000000"]]}}
{"rx_ns": 21953196400, "frame": {"e":"depthUpdate","E":1787603079414,"s":"BTCUSDT","U":99076631325,"u":99076631347,"b":[["78703.36000000","0.31789000"],["78702.55000000","0.00000000"],["78701.79000000","0.02807000"],["78700.73000000","0.00000000"],["78700.56000000","0.00000000"],["78695.35000000","0.00400000"],["78665.46000000","0.00318000"],["70834.51000000","0.00224000"],["70834.00000000","0.00010000"]],"a":[["78707.29000000","0.00007000"],["78707.58000000","0.05454000"],["78708.00000000","0.00507000"],["78712.00000000","0.04053000"],["78730.76000000","0.00406000"],["78795.26000000","0.00316000"],["80468.55000000","0.00255000"]]}}
{"rx_ns": 22053291100, "frame": {"e":"depthUpdate","E":1787603079514,"s":"BTCUSDT","U":99076631348,"u":99076631359,"b":[["78701.46000000","0.12713000"],["78682.43000000","0.52456000"],["78657.83000000","1.04683000"],["72420.55000000","0.00000000"],["70834.00000000","0.00000000"],["62964.01000000","0.00031000"]],"a":[["78708.20000000","0.00007000"],["78714.15000000","0.00317000"],["78714.57000000","0.00000000"],["80629.49000000","0.00299000"]]}}
{"rx_ns": 22153011200, "frame": {"e":"depthUpdate","E":1787603079614,"s":"BTCUSDT","U":99076631360,"u":99076631380,"b":[["78703.36000000","0.31789000"],["78701.46000000","0.00000000"],["78701.37000000","0.00000000"],["78701.21000000","0.00000000"],["78701.01000000","0.00000000"],["78700.54000000","0.12713000"],["78689.14000000","0.06526000"],["78687.17000000","0.07532000"],["78626.36000000","0.02116000"],["70834.51000000","0.00240000"],["62964.01000000","0.00000000"]],"a":[["78848.86000000","0.00406000"],["80790.75000000","0.00335000"]]}}
