{"rx_ns": 13959792050600, "frame": {"stream":"btcusdt@depth20","data":{"lastUpdateId":99118678220,"bids":[["79861.77000000","7.26516000"],["79861.76000000","0.00027000"],["79861.75000000","0.00013000"],["79861.67000000","1.43957000"],["79861.66000000","0.56596000"],["79861.65000000","2.20621000"],["79861.32000000","0.00014000"],["79861.05000000","0.00007000"],["79861.04000000","0.47744000"],["79860.50000000","0.07521000"],["79860.43000000","0.57287000"],["79860.42000000","1.04953000"],["79860.18000000","0.00400000"],["79859.38000000","0.00802000"],["79859.21000000","0.33675000"],["79859.00000000","0.05254000"],["79858.66000000","0.00079000"],["79858.65000000","0.00014000"],["79858.17000000","0.02100000"],["79858.16000000","0.00126000"]],"asks":[["79861.78000000","0.01058000"],["79861.79000000","0.00077000"],["79862.01000000","0.00007000"],["79862.09000000","0.00007000"],["79862.14000000","0.00007000"],["79863.05000000","0.00007000"],["79863.06000000","0.01828000"],["79864.14000000","0.00074000"],["79864.18000000","0.00370000"],["79864.33000000","0.00007000"],["79864.34000000","0.02166000"],["79864.58000000","0.00007000"],["79864.59000000","0.04807000"],["79865.19000000","0.00007000"],["79865.29000000","0.00007000"],["79865.32000000","0.00007000"],["79865.43000000","0.00007000"],["79865.44000000","0.00014000"],["79865.61000000","0.00007000"],["79865.62000000","0.02166000"]]}}}
{"rx_ns": 13959792145400, "frame": {"stream":"btcusdt@depth@100ms","data":{"e":"depthUpdate","E":1787650955014,"s":"BTCUSDT","U":99118678170,"u":99118678220,"b":[["79861.67000000","1.43957000"],["79861.66000000","0.56596000"],["79861.65000000","2.20621000"],["79844.13000000","0.00000000"],["79832.10000000","1.24041000"],["79830.00000000","0.07187000"],["79799.89000000","0.00000000"],["79688.90000000","4.39763000"],["78663.84000000","0.00046000"],["78661.32000000","0.00000000"],["71875.60000000","0.00048000"],["71875.00000000","0.01227000"],["71873.29000000","0.00000000"],["71873.28000000","0.00008000"],["63889.42000000","0.00031000"]],"a":[["79861.78000000","0.01058000"],["79865.28000000","0.00000000"],["79865.29000000","0.00007000"],["79865.44000000","0.00014000"],["79866.05000000","0.00014000"],["79868.28000000","0.00007000"],["79869.06000000","0.00007000"],["79870.93000000","0.00000000"],["79871.42000000","0.00000000"],["79871.53000000","0.00000000"],["79871.72000000","0.00000000"],["79871.93000000","0.00000000"],["79872.53000000","0.16477000"],["79874.17000000","0.00000000"],["79874.28000000","0.00000000"],["79875.95000000","0.00024000"],["79879.10000000","0.00000000"],["79886.45000000","0.00000000"],["79887.44000000","0.00000000"],["79905.58000000","0.33798000"],["79907.48000000","0.00000000"],["79907.76000000","0.00007000"],["79939.52000000","1.23875000"],["79951.31000000","0.00000000"],["80057.42000000","4.59196000"],["81059.71000000","0.00030000"]]}}}
{"rx_ns": 13959900748700, "frame": {"stream":"btcusdt@depth@100ms","data":{"e":"depthUpdate","E":1787650955114,"s":"BTCUSDT","U":99118678221,"u":99118678642,"b":[["79863.05000000","8.31982000"],["79863.04000000","0.00027000"],["79863.03000000","0.00013000"],["79862.75000000","0.00400000"],["79862.43000000","0.00000000"],["79862.13000000","0.00000000"],["79862.00000000","0.00000000"],["79861.81000000","0.00000000"],["79861.78000000","0.07500000"],["79861.77000000","3.17162000"],["79861.76000000","0.00000000"],["79861.75000000","0.00000000"],["79861.67000000","0.00014000"],["79861.65000000","0.22698000"],["79861.29000000","0.08000000"],["79860.86000000","0.00161000"],["79860.72000000","0.00008000"],["79860.50000000","0.00014000"],["79860.43000000","0.57294000"],["79860.40000000","0.05254000"],["79859.38000000","0.00000000"],["79859.22000000","0.15970000"],["79859.00000000","0.00007000"],["79858.15000000","0.03358000"],["79858.10000000","0.00000000"],["79856.94000000","0.00690000"],["79856.82000000","0.00000000"],["79855.54000000","0.00000000"],["79855.14000000","0.15770000"],["79855.13000000","0.00000000"],["79854.92000000","0.00000000"],["79854.82000000","0.00000000"],["79854.72000000","0.36593000"],["79852.79000000","0.00000000"],["79851.54000000","0.00007000"],["79851.46000000","0.33821000"],["79850.95000000","0.08566000"],["79850.26000000","0.00000000"],["79849.59000000","0.00000000"],["79846.66000000","0.00000000"],["79845.96000000","0.02465000"],["79845.15000000","0.00000000"],["79845.08000000","0.00000000"],["79842.03000000","0.00007000"],["79839.97000000","0.00000000"],["79837.79000000","0.00000000"],["79823.00000000","0.01000000"],["79822.62000000","0.00000000"],["79822.50000000","0.00000000"],["79821.00000000","0.00000000"],["79809.36000000","0.00427000"],["79797.35000000","0.00000000"],["79775.32000000","0.00000000"],["79761.16000000","0.00025000"],["79758.60000000","0.00000000"],["79644.19000000","0.00771000"],["79641.60000000","0.00000000"],["79535.12000000","0.00000000"],["71876.75000000","0.00032000"],["71875.60000000","0.00000000"],["71875.00000000","0.01227000"],["63889.42000000","0.00031000"]],"a":[["79861.78000000","0.00000000"],["79861.79000000","0.00000000"],["79862.01000000","0.00000000"],["79862.09000000","0.00000000"],["79862.14000000","0.00000000"],["79863.05000000","0.00000000"],["79863.06000000","0.00073000"],["79863.07000000","0.00049000"],["79864.14000000","0.00000000"],["79864.18000000","0.00000000"],["79864.33000000","0.00000000"],["79864.34000000","0.00014000"],["79864.58000000","0.00000000"],["79864.59000000","0.00021000"],["79865.43000000","0.00000000"],["79865.44000000","0.00000000"],["79865.61000000","0.00000000"],["79865.62000000","0.00021000"],["79865.98000000","0.00007000"],["79865.99000000","0.04786000"],["79866.04000000","0.00000000"],["79866.05000000","0.00000000"],["79866.15000000","0.00000000"],["79866.16000000","0.00000000"],["79866.53000000","0.00000000"],["79866.54000000","0.00021000"],["79866.77000000","0.00000000"],["79866.78000000","0.06138000"],["79867.14000000","0.00000000"],["79867.15000000","0.00021000"],["79867.39000000","0.00014000"],["79867.40000000","0.06138000"],["79867.75000000","0.00000000"],["79867.76000000","0.00014000"],["79867.98000000","0.00007000"],["79867.99000000","0.06145000"],["79868.00000000","0.02435000"],["79868.26000000","0.00000000"],["79868.27000000","0.00014000"],["79868.63000000","0.00007000"],["79868.64000000","0.06145000"],["79868.79000000","0.00007000"],["79869.08000000","0.00007000"],["79869.09000000","0.06138000"],["79869.10000000","0.00021000"],["79869.58000000","0.00007000"],["79869.59000000","0.06060000"],["79869.98000000","0.00007000"],["79869.99000000","0.06067000"],["79870.01000000","0.00000000"],["79871.10000000","0.00007000"],["79871.11000000","0.06138000"],["79871.12000000","0.00000000"],["79871.70000000","0.06138000"],["79871.92000000","0.40375000"],["79872.52000000","0.06138000"],["79872.53000000","0.00000000"],["79873.59000000","0.06138000"],["79873.60000000","0.00000000"],["79873.99000000","0.06138000"],["79874.25000000","0.00000000"],["79875.11000000","0.42275000"],["79875.18000000","0.00000000"],["79875.61000000","0.08576000"],["79875.95000000","0.00000000"],["79875.96000000","0.23143000"],["79875.97000000","0.00000000"],["79877.54000000","0.00007000"],["79877.55000000","0.00027000"],["79877.85000000","0.00000000"],["79878.88000000","0.00000000"],["79881.24000000","0.00626000"],["79881.74000000","0.00000000"],["79882.53000000","0.00000000"],["79883.95000000","1.29736000"],["79888.96000000","0.00000000"],["79890.26000000","0.03000000"],["79893.80000000","0.00000000"],["79895.25000000","0.00000000"],["79895.91000000","0.00400000"],["79896.86000000","0.00000000"],["79897.68000000","0.00000000"],["79900.50000000","0.00000000"],["79902.00000000","0.02400000"],["79902.97000000","0.04559000"],["79903.00000000","0.01000000"],["79904.47000000","1.01683000"],["79911.63000000","0.00007000"],["79921.86000000","0.00400000"],["79933.75000000","0.00000000"],["79935.86000000","0.00400000"],["79951.59000000","0.00000000"],["79953.71000000","0.00000000"],["79954.96000000","0.00000000"],["79955.07000000","0.00000000"],["79955.22000000","0.00000000"],["79958.25000000","0.00000000"],["79960.81000000","0.00025000"],["79965.59000000","1.95396000"],["79965.71000000","0.00000000"],["79967.82000000","0.02062000"],["80013.65000000","0.00000000"],["80015.76000000","0.00400000"],["80079.02000000","0.00000000"],["80085.55000000","0.00000000"],["80087.67000000","0.00400000"],["80093.29000000","0.01961000"],["80131.56000000","0.00000000"],["80143.10000000","0.00025000"],["81059.71000000","0.00000000"]]}}}
{"rx_ns": 13959992792600, "frame": {"stream":"btcusdt@depth@100ms","data":{"e":"depthUpdate","E":1787650955214,"s":"BTCUSDT","U":99118678643,"u":99118679014,"b":[["79864.33000000","4.91655000"],["79864.32000000","0.00027000"],["79864.31000000","0.00013000"],["79863.71000000","0.00000000"],["79863.09000000","0.00000000"],["79863.06000000","1.89150000"],["79863.05000000","3.03852000"],["79863.04000000","0.00000000"],["79863.03000000","0.00000000"],["79861.78000000","0.07514000"],["79861.77000000","0.66906000"],["79861.68000000","0.05246000"],["79861.67000000","0.00000000"],["79861.65000000","0.22691000"],["79861.29000000","0.08014000"],["79861.05000000","0.00000000"],["79861.04000000","0.47751000"],["79860.92000000","0.00822000"],["79860.50000000","0.00000000"],["79860.43000000","0.57301000"],["79860.42000000","1.04939000"],["79860.40000000","0.00007000"],["79859.64000000","0.01370000"],["79859.21000000","0.33272000"],["79858.36000000","0.01644000"],["79858.35000000","0.00013000"],["79858.00000000","0.02428000"],["79857.08000000","0.01644000"],["79856.34000000","0.00015000"],["79856.00000000","0.02407000"],["79855.67000000","0.00000000"],["79855.64000000","0.00000000"],["79853.66000000","0.00000000"],["79852.82000000","0.00007000"],["79852.62000000","0.08566000"],["79851.54000000","0.00000000"],["79850.95000000","0.00000000"],["79849.12000000","0.00007000"],["79848.36000000","0.00008000"],["79844.36000000","0.00008000"],["79844.00000000","0.02400000"],["79843.24000000","0.00000000"],["79840.37000000","0.00008000"],["79839.25000000","0.00000000"],["79836.38000000","0.00008000"],["79835.25000000","0.00000000"],["79832.38000000","0.00008000"],["79831.26000000","0.00000000"],["79828.39000000","0.00008000"],["79827.27000000","0.00000000"],["79826.78000000","0.00000000"],["79824.40000000","0.00008000"],["79823.27000000","0.00000000"],["79819.28000000","0.00000000"],["79799.85000000","0.00000000"],["79798.65000000","0.00000000"],["79796.80000000","0.00313000"],["79795.08000000","0.00312000"],["79793.97000000","0.00000000"],["79792.96000000","0.11982000"],["79791.61000000","0.00000000"],["79790.01000000","0.00000000"],["79786.86000000","0.00000000"],["79775.71000000","0.00000000"],["79754.93000000","0.00000000"],["79751.91000000","0.00394000"],["79749.49000000","0.00000000"],["79747.89000000","0.02692000"],["79739.82000000","0.00000000"],["79716.79000000","0.00125000"],["79711.27000000","0.00000000"],["79707.03000000","0.00000000"],["79638.61000000","0.00400000"],["79635.19000000","0.00000000"],["79546.58000000","0.00031000"],["71876.75000000","0.00000000"],["63889.42000000","0.00000000"]],"a":[["79863.06000000","0.00000000"],["79863.07000000","0.00000000"],["79864.33000000","0.00000000"],["79864.34000000","0.01936000"],["79864.35000000","0.00069000"],["79864.36000000","0.00013000"],["79864.59000000","0.00007000"],["79865.32000000","0.00000000"],["79865.61000000","0.00007000"],["79865.62000000","0.02118000"],["79865.92000000","0.00000000"],["79865.98000000","0.00000000"],["79865.99000000","0.00035000"],["79866.54000000","0.00000000"],["79866.77000000","0.00007000"],["79866.78000000","0.06159000"],["79866.89000000","0.00007000"],["79866.90000000","0.02118000"],["79867.15000000","0.00000000"],["79867.21000000","0.00000000"],["79867.26000000","0.00007000"],["79867.27000000","0.04772000"],["79867.40000000","0.06152000"],["79867.64000000","0.00000000"],["79867.76000000","0.00000000"],["79867.99000000","0.06159000"],["79868.00000000","0.02428000"],["79868.27000000","0.00000000"],["79868.64000000","0.06159000"],["79869.09000000","0.06152000"],["79869.10000000","0.00007000"],["79869.59000000","0.06074000"],["79869.65000000","0.00000000"],["79869.98000000","0.00000000"],["79869.99000000","0.06060000"],["79870.32000000","0.00013000"],["79871.10000000","0.00000000"],["79872.33000000","0.00008000"],["79875.19000000","0.00007000"],["79875.61000000","0.00000000"],["79875.96000000","0.23136000"],["79877.28000000","0.08576000"],["79877.54000000","0.00007000"],["79879.18000000","0.00150000"],["79880.31000000","0.00008000"],["79881.08000000","0.00007000"],["79883.18000000","0.00000000"],["79884.31000000","0.00008000"],["79887.17000000","0.00000000"],["79888.30000000","0.00008000"],["79891.16000000","0.04000000"],["79892.29000000","0.00008000"],["79895.16000000","0.00000000"],["79896.29000000","0.00008000"],["79898.96000000","0.11223000"],["79899.15000000","0.00000000"],["79900.28000000","0.00015000"],["79901.37000000","0.00000000"],["79903.00000000","0.00000000"],["79903.89000000","0.00014000"],["79904.27000000","0.00008000"],["79905.00000000","0.01400000"],["79907.40000000","0.00000000"],["79927.36000000","0.00000000"],["79928.15000000","0.00000000"],["79931.59000000","0.00311000"],["79932.70000000","0.00311000"],["79955.41000000","0.00000000"],["80006.57000000","0.00000000"],["80006.84000000","0.00000000"],["80011.58000000","0.00125000"],["80011.99000000","0.00125000"],["80015.76000000","0.00000000"],["80577.94000000","0.00187000"]]}}}
{"rx_ns": 13960091970800, "frame": {"stream":"btcusdt@depth@100ms","data":{"e":"depthUpdate","E":1787650955314,"s":"BTCUSDT","U":99118679015,"u":99118679109,"b":[["79864.33000000","4.92033000"],["79863.07000000","0.00007000"],["79863.06000000","1.89171000"],["79863.05000000","2.35549000"],["79862.10000000","0.00007000"],["79861.78000000","0.07521000"],["79861.77000000","0.66906000"],["79861.67000000","0.00007000"],["79861.04000000","0.47730000"],["79860.92000000","0.00000000"],["79860.43000000","0.57287000"],["79859.64000000","0.00000000"],["79859.21000000","0.33265000"],["79858.36000000","0.00000000"],["79858.00000000","0.02421000"],["79857.08000000","0.00000000"],["79824.00000000","0.03407000"],["79823.00000000","0.00000000"],["79816.02000000","0.00012000"],["79813.47000000","0.00000000"],["79790.29000000","0.00400000"],["79777.84000000","0.01282000"],["79721.99000000","1.50310000"],["79706.70000000","0.00000000"],["71877.90000000","0.00032000"],["71877.00000000","0.00010000"],["63891.00000000","0.00000000"]],"a":[["79864.34000000","0.00149000"],["79864.35000000","0.00062000"],["79865.61000000","0.00000000"],["79865.62000000","0.00021000"],["79865.93000000","0.00000000"],["79865.99000000","0.00021000"],["79866.78000000","0.06159000"],["79866.89000000","0.00000000"],["79866.90000000","0.00021000"],["79867.27000000","0.04786000"],["79869.09000000","0.06152000"],["79869.59000000","0.06060000"],["79869.98000000","0.00007000"],["79872.93000000","0.00007000"],["79877.54000000","0.00000000"],["79887.99000000","0.00000000"],["79890.63000000","0.00000000"],["79902.88000000","0.02480000"],["79906.49000000","0.25000000"],["79965.44000000","0.00556000"],["80010.14000000","0.00000000"],["80010.15000000","0.00000000"],["80025.50000000","1.50310000"]]}}}
{"rx_ns": 13960193512000, "frame": {"stream":"btcusdt@depth@100ms","data":{"e":"depthUpdate","E":1787650955414,"s":"BTCUSDT","U":99118679110,"u":99118679173,"b":[["79864.33000000","5.02027000"],["79862.45000000","0.00842000"],["79861.29000000","0.08021000"],["79861.17000000","0.01403000"],["79860.43000000","0.57287000"],["79859.89000000","0.01684000"],["79859.21000000","0.33272000"],["79858.61000000","0.01684000"],["79856.28000000","0.00094000"],["79856.27000000","0.00000000"],["79856.02000000","0.00000000"],["79845.00000000","0.70000000"],["79749.49000000","0.20250000"],["79735.60000000","0.00012000"],["79724.69000000","0.00000000"],["71877.90000000","0.00048000"],["71877.00000000","0.00000000"],["71873.28000000","0.00000000"]],"a":[["79864.34000000","0.01213000"],["79864.35000000","0.00076000"],["79865.61000000","0.00007000"],["79865.62000000","0.01733000"],["79866.78000000","0.06159000"],["79866.89000000","0.00007000"],["79866.90000000","0.02079000"],["79868.00000000","0.02435000"],["79868.17000000","0.00007000"],["79868.18000000","0.02072000"],["79869.58000000","0.00000000"],["79869.59000000","0.06074000"],["79869.98000000","0.00000000"],["79869.99000000","0.06060000"],["79871.14000000","0.00334000"],["79872.93000000","0.00014000"],["79873.90000000","0.15305000"],["79893.19000000","0.00012000"],["79955.59000000","0.11994000"],["79965.44000000","0.00000000"],["79975.87000000","0.00000000"],["79978.56000000","0.00000000"],["79982.72000000","0.00000000"]]}}}
{"rx_ns": 13960296956000, "frame": {"stream":"btcusdt@depth@100ms","data":{"e":"depthUpdate","E":1787650955514,"s":"BTCUSDT","U":99118679174,"u":99118679244,"b":[["79864.33000000","5.04358000"],["79863.05000000","2.35549000"],["79862.45000000","0.00856000"],["79861.29000000","0.08007000"],["79860.43000000","0.57294000"],["79855.14000000","0.00000000"],["79853.44000000","0.00000000"],["79758.36000000","0.00400000"],["79648.40000000","0.00771000"],["79644.19000000","0.00000000"],["79000.00000000","24.86746000"],["71877.90000000","0.00064000"],["63891.47000000","0.00031000"]],"a":[["79864.34000000","0.06220000"],["79865.29000000","0.00000000"],["79865.57000000","0.00007000"],["79865.58000000","0.06138000"],["79865.62000000","0.01754000"],["79866.19000000","0.00007000"],["79866.20000000","0.06138000"],["79866.78000000","0.06159000"],["79866.88000000","0.00007000"],["79866.90000000","0.02093000"],["79868.00000000","0.02435000"],["79868.18000000","0.02086000"],["79868.63000000","0.00000000"],["79868.64000000","0.06145000"],["79869.08000000","0.00000000"],["79869.09000000","0.06138000"],["79869.59000000","0.06060000"],["79871.98000000","0.16001000"],["79872.80000000","0.00000000"],["79873.90000000","0.00000000"],["79898.96000000","0.02000000"],["79899.55000000","0.09248000"],["79907.16000000","0.33797000"],["79911.99000000","1.72219000"],["79912.00000000","0.72400000"],["79912.71000000","0.00000000"],["79919.29000000","0.00400000"],["79921.86000000","0.00000000"],["79981.00000000","0.00019000"],["79986.98000000","0.00160000"]]}}}
{"rx_ns": 13960392310200, "frame": {"stream":"btcusdt@depth@100ms","data":{"e":"depthUpdate","E":1787650955614,"s":"BTCUSDT","U":99118679245,"u":99118679278,"b":[["79864.33000000","5.08400000"],["79858.02000000","0.00000000"],["79853.52000000","0.00400000"],["79840.00000000","0.28024000"],["79824.36000000","0.00000000"],["71877.90000000","0.00096000"],["63891.47000000","0.00000000"],["63891.00000000","0.00000000"]],"a":[["79864.34000000","0.06220000"],["79865.58000000","0.06152000"],["79865.62000000","0.01754000"],["79866.20000000","0.06152000"],["79868.00000000","0.02421000"],["79868.17000000","0.00000000"],["79868.18000000","0.02072000"],["79875.94000000","0.57017000"],["79875.95000000","1.04939000"],["79875.96000000","0.00000000"],["79918.00000000","0.02800000"],["79919.29000000","0.00000000"]]}}}
{"rx_ns": 13960492608600, "frame": {"stream":"btcusdt@depth@100ms","data":{"e":"depthUpdate","E":1787650955714,"s":"BTCUSDT","U":99118679279,"u":99118679429,"b":[["79864.33000000","2.69653000"],["79863.06000000","1.21735000"],["79863.05000000","0.17872000"],["79862.76000000","0.00000000"],["79862.45000000","0.00856000"],["79861.79000000","0.00007000"],["79861.66000000","0.38840000"],["79861.05000000","0.00007000"],["79860.49000000","0.00007000"],["79860.45000000","0.00007000"],["79860.44000000","1.87684000"],["79860.43000000","0.57294000"],["79859.90000000","0.00626000"],["79859.21000000","0.33272000"],["79858.71000000","0.00000000"],["79858.61000000","0.01691000"],["79858.41000000","0.00007000"],["79858.36000000","0.00626000"],["79858.04000000","0.00902000"],["79857.50000000","0.00400000"],["79856.88000000","0.00000000"],["79856.55000000","0.00000000"],["79855.08000000","1.45210000"],["79855.07000000","1.87677000"],["79854.70000000","0.00000000"],["79848.13000000","0.00000000"],["79846.13000000","0.09373000"],["79844.13000000","0.10306000"],["79842.16000000","0.00000000"],["79840.16000000","0.00000000"],["79830.21000000","0.00400000"],["73480.61000000","0.00014000"],["71877.90000000","0.00112000"],["71877.00000000","0.00000000"]],"a":[["79864.34000000","0.99057000"],["79864.35000000","0.00090000"],["79864.95000000","0.00007000"],["79864.96000000","0.06145000"],["79865.56000000","0.00007000"],["79865.57000000","0.09959000"],["79865.88000000","0.00026000"],["79866.89000000","0.00007000"],["79867.26000000","0.00007000"],["79867.39000000","0.00014000"],["79867.98000000","0.00000000"],["79867.99000000","0.06152000"],["79868.18000000","0.02079000"],["79868.63000000","0.13761000"],["79869.06000000","0.00014000"],["79871.12000000","0.06491000"],["79871.89000000","0.06138000"],["79871.90000000","1.04939000"],["79871.91000000","0.00000000"],["79871.92000000","0.91611000"],["79871.98000000","0.00000000"],["79872.52000000","0.00000000"],["79872.92000000","0.00650000"],["79873.59000000","0.00000000"],["79873.98000000","1.87677000"],["79873.99000000","0.00000000"],["79875.10000000","0.00000000"],["79875.11000000","0.00000000"],["79875.94000000","1.05741000"],["79877.55000000","0.00000000"],["79879.02000000","1.87677000"],["79881.24000000","0.00000000"],["79889.75000000","0.02000000"],["79890.57000000","0.02000000"],["79890.65000000","0.12517000"],["79894.43000000","0.33803000"],["79906.33000000","0.02480000"],["79907.16000000","0.00000000"],["79907.76000000","0.00000000"],["79911.63000000","0.00000000"],["79915.52000000","0.00400000"],["79918.00000000","0.02400000"],["79947.35000000","0.02000000"],["79949.43000000","0.00000000"],["79983.69000000","0.00018000"],["79987.86000000","0.00031000"],["80026.97000000","0.00160000"]]}}}
{"rx_ns": 13960594417100, "frame": {"stream":"btcusdt@depth@100ms","data":{"e":"depthUpdate","E":1787650955814,"s":"BTCUSDT","U":99118679430,"u":99118679465,"b":[["79861.05000000","0.00007000"],["79860.97000000","0.03197000"],["79860.45000000","0.00007000"],["79860.44000000","1.87684000"],["79858.00000000","0.02407000"],["71877.90000000","0.00128000"],["71877.00000000","0.00000000"]],"a":[["79864.34000000","0.99078000"],["79864.96000000","0.06159000"],["79865.29000000","0.00007000"],["79865.56000000","0.00000000"],["79865.57000000","0.00007000"],["79865.88000000","0.00000000"],["79867.40000000","0.06138000"],["79867.98000000","0.00007000"],["79867.99000000","0.06138000"],["79868.18000000","0.02086000"],["79868.37000000","0.14642000"],["79871.12000000","0.00000000"],["79886.57000000","0.33806000"],["79905.58000000","0.00000000"]]}}}
{"rx_ns": 13960691991000, "frame": {"stream":"btcusdt@depth@100ms","data":{"e":"depthUpdate","E":1787650955914,"s":"BTCUSDT","U":99118679466,"u":99118679487,"b":[["79861.04000000","0.47737000"],["79857.43000000","0.02600000"],["79856.64000000","0.02000000"],["79844.08000000","0.00000000"],["79798.65000000","0.80885000"],["79797.53000000","0.02087000"],["79710.46000000","0.00400000"],["78905.95000000","0.00042000"],["71877.90000000","0.00144000"],["71877.00000000","0.00010000"],["63891.00000000","0.00000000"]],"a":[["79864.34000000","0.99078000"],["79864.96000000","0.06159000"],["79877.36000000","0.00000000"],["79907.76000000","0.00007000"],["79947.35000000","0.00000000"]]}}}
{"rx_ns": 13960792067800, "frame": {"stream":"btcusdt@depth20","data":{"lastUpdateId":99118679522,"bids":[["79864.33000000","2.69653000"],["79864.32000000","0.00027000"],["79864.31000000","0.00013000"],["79863.07000000","0.00007000"],["79863.06000000","1.21735000"],["79863.05000000","0.17872000"],["79862.75000000","0.00400000"],["79862.45000000","0.00856000"],["79862.10000000","0.00007000"],["79861.79000000","0.00007000"],["79861.78000000","0.07521000"],["79861.77000000","0.66906000"],["79861.68000000","0.05246000"],["79861.67000000","0.00007000"],["79861.66000000","0.38840000"],["79861.65000000","0.22691000"],["79861.32000000","0.00014000"],["79861.29000000","0.08007000"],["79861.17000000","0.01403000"],["79861.05000000","0.00007000"]],"asks":[["79864.34000000","0.99148000"],["79864.35000000","0.00090000"],["79864.36000000","0.00013000"],["79864.59000000","0.00007000"],["79864.95000000","0.00007000"],["79864.96000000","0.06159000"],["79865.19000000","0.00007000"],["79865.29000000","0.00007000"],["79865.56000000","0.00007000"],["79865.57000000","0.09955000"],["79865.58000000","0.06152000"],["79865.61000000","0.00007000"],["79865.62000000","0.01754000"],["79865.99000000","0.00021000"],["79866.19000000","0.00007000"],["79866.20000000","0.06152000"],["79866.71000000","0.00007000"],["79866.77000000","0.00007000"],["79866.78000000","0.06159000"],["79866.88000000","0.00007000"]]}}}
{"rx_ns": 13960792192800, "frame": {"stream":"btcusdt@depth@100ms","data":{"e":"depthUpdate","E":1787650956014,"s":"BTCUSDT","U":99118679488,"u":99118679522,"b":[["79861.05000000","0.00007000"],["79860.45000000","0.00007000"],["79860.44000000","1.87684000"],["79856.69000000","0.02200000"],["79856.62000000","0.02400000"],["79854.31000000","0.02400000"],["79850.00000000","0.12811000"],["79844.94000000","0.00000000"],["79400.00000000","2.02810000"],["78666.36000000","0.00030000"],["78663.84000000","0.00016000"],["71877.90000000","0.00160000"],["71877.00000000","0.00010000"],["63891.47000000","0.00031000"],["63891.46000000","0.00000000"]],"a":[["79864.34000000","0.99148000"],["79865.56000000","0.00007000"],["79865.57000000","0.09955000"],["79866.89000000","0.00007000"],["79867.26000000","0.00007000"],["79867.39000000","0.00014000"],["79867.98000000","0.00000000"],["79870.30000000","0.00000000"],["79874.41000000","0.00718000"],["81062.31000000","0.00030000"]]}}}
{"rx_ns": 13960892626600, "frame": {"stream":"btcusdt@depth@100ms","data":{"e":"depthUpdate","E":1787650956114,"s":"BTCUSDT","U":99118679523,"u":99118679563,"b":[["79864.33000000","2.69642000"],["79861.05000000","0.00007000"],["79860.45000000","0.00007000"],["79860.44000000","1.87684000"],["79846.25000000","0.00000000"],["79843.90000000","0.00000000"],["79843.84000000","0.00000000"],["71877.90000000","0.00144000"],["71877.89000000","0.00008000"],["71877.00000000","0.00000000"],["63891.46000000","0.00000000"]],"a":[["79864.34000000","0.76861000"],["79864.96000000","0.06159000"],["79865.56000000","0.00000000"],["79865.57000000","0.00021000"],["79867.98000000","0.00007000"],["79872.61000000","0.00915000"],["79872.92000000","0.00024000"],["79875.18000000","0.00626000"],["79895.91000000","0.00000000"],["79935.86000000","0.00000000"],["79967.82000000","0.01662000"],["80016.74000000","0.00400000"],["80087.67000000","0.00000000"]]}}}
{"rx_ns": 13960995234600, "frame": {"stream":"btcusdt@depth@100ms","data":{"e":"depthUpdate","E":1787650956214,"s":"BTCUSDT","U":99118679564,"u":99118679582,"b":[["79864.33000000","2.69652000"],["79849.12000000","0.00007000"],["78426.77000000","0.00042000"],["71877.90000000","0.00176000"],["63891.47000000","0.00000000"]],"a":[["79864.34000000","0.76861000"],["79864.96000000","0.06159000"],["79865.57000000","0.00007000"],["79867.40000000","0.06152000"],["79881.08000000","0.00007000"],["80583.11000000","0.00010000"]]}}}
{"rx_ns": 13961093053800, "frame": {"stream":"btcusdt@depth@100ms","data":{"e":"depthUpdate","E":1787650956314,"s":"BTCUSDT","U":99118679583,"u":99118679594,"b":[["79797.53000000","0.00000000"],["73480.61000000","0.00000000"],["71877.90000000","0.00176000"],["63891.00000000","0.00000000"]],"a":[["79864.34000000","0.81869000"],["79866.09000000","0.00007000"],["79897.98000000","0.00400000"]]}}}
{"rx_ns": 13961194063400, "frame": {"stream":"btcusdt@depth@100ms","data":{"e":"depthUpdate","E":1787650956414,"s":"BTCUSDT","U":99118679595,"u":99118679616,"b":[["79864.33000000","2.69598000"],["79861.05000000","0.00007000"],["79860.45000000","0.00007000"],["79860.44000000","1.87684000"],["71877.90000000","0.00192000"]],"a":[["79864.34000000","0.81799000"],["79865.56000000","0.00007000"],["79865.57000000","0.09961000"],["79866.89000000","0.00007000"],["79867.26000000","0.00007000"],["79867.39000000","0.00014000"],["79867.98000000","0.00000000"],["79873.81000000","0.00069000"]]}}}
{"rx_ns": 13961292030800, "frame": {"stream":"btcusdt@depth@100ms","data":{"e":"depthUpdate","E":1787650956514,"s":"BTCUSDT","U":99118679617,"u":99118679632,"b":[["63891.47000000","0.00031000"]],"a":[["79864.34000000","0.81799000"],["79864.96000000","0.06159000"],["79865.57000000","0.09975000"],["79867.40000000","0.06138000"],["79869.06000000","0.00007000"],["79909.00000000","0.70000000"],["79969.89000000","0.00400000"]]}}}
{"rx_ns": 13961392601900, "frame": {"stream":"btcusdt@depth@100ms","data":{"e":"depthUpdate","E":1787650956614,"s":"BTCUSDT","U":99118679633,"u":99118679645,"b":[["77947.58000000","0.00042000"],["71877.90000000","0.00208000"],["63891.47000000","0.00000000"]],"a":[["79864.34000000","0.86944000"]]}}}
{"rx_ns": 13961496849500, "frame": {"stream":"btcusdt@depth@100ms","data":{"e":"depthUpdate","E":1787650956714,"s":"BTCUSDT","U":99118679646,"u":99118679662,"b":[["79864.33000000","2.62170000"],["79849.94000000","0.12523000"],["79797.53000000","0.02087000"],["79648.40000000","0.00000000"],["79644.19000000","0.00771000"],["71877.90000000","0.00208000"]],"a":[["79864.34000000","0.86807000"],["79866.88000000","0.00000000"],["79867.87000000","0.00083000"],["79867.91000000","0.00415000"],["79924.87000000","0.00007000"],["79931.61000000","0.00007000"],["80089.74000000","0.00400000"]]}}}
{"rx_ns": 13961593232000, "frame": {"stream":"btcusdt@depth@100ms","data":{"e":"depthUpdate","E":1787650956814,"s":"BTCUSDT","U":99118679663,"u":99118679665,"b":[["79797.53000000","0.00000000"],["71877.90000000","0.00224000"]],"a":[["79869.06000000","0.00014000"]]}}}
{"rx_ns": 13961694723700, "frame": {"stream":"btcusdt@depth@100ms","data":{"e":"depthUpdate","E":1787650956914,"s":"BTCUSDT","U":99118679666,"u":99118679674,"b":[["79837.40000000","0.02600000"],["79836.61000000","0.02000000"],["77468.40000000","0.00043000"],["71877.90000000","0.00224000"]],"a":[["79897.98000000","0.00000000"],["79937.93000000","0.00400000"],["79969.89000000","0.00000000"],["80089.74000000","0.00000000"]]}}}
{"rx_ns": 13961793060100, "frame": {"stream":"btcusdt@depth20","data":{"lastUpdateId":99118679696,"bids":[["79864.33000000","2.62170000"],["79864.32000000","0.00027000"],["79864.31000000","0.00013000"],["79863.07000000","0.00007000"],["79863.06000000","1.21735000"],["79863.05000000","0.17872000"],["79862.75000000","0.00400000"],["79862.45000000","0.00856000"],["79862.10000000","0.00007000"],["79861.79000000","0.00007000"],["79861.78000000","0.07521000"],["79861.77000000","0.66906000"],["79861.68000000","0.05246000"],["79861.67000000","0.00007000"],["79861.66000000","0.38840000"],["79861.65000000","0.22691000"],["79861.32000000","0.00014000"],["79861.29000000","0.08007000"],["79861.17000000","0.01403000"],["79861.05000000","0.00007000"]],"asks":[["79864.34000000","0.86807000"],["79864.35000000","0.00090000"],["79864.36000000","0.00013000"],["79864.59000000","0.00007000"],["79864.95000000","0.00007000"],["79864.96000000","0.06159000"],["79865.19000000","0.00007000"],["79865.29000000","0.00007000"],["79865.56000000","0.00007000"],["79865.57000000","0.09975000"],["79865.58000000","0.06152000"],["79865.61000000","0.00007000"],["79865.62000000","0.01754000"],["79865.99000000","0.00021000"],["79866.09000000","0.00007000"],["79866.19000000","0.00007000"],["79866.20000000","0.06152000"],["79866.71000000","0.00007000"],["79866.77000000","0.00007000"],["79866.78000000","0.06159000"]]}}}
{"rx_ns": 13961793240800, "frame": {"stream":"btcusdt@depth@100ms","data":{"e":"depthUpdate","E":1787650957014,"s":"BTCUSDT","U":99118679675,"u":99118679696,"b":[["79859.22000000","0.16103000"],["79836.66000000","0.02200000"],["79836.59000000","0.02400000"],["79834.28000000","1.90077000"],["79797.53000000","0.02087000"],["79788.01000000","0.01444000"],["79784.98000000","0.00000000"],["79784.12000000","0.00000000"],["79783.45000000","0.62589000"],["79772.89000000","0.00000000"],["78666.36000000","0.00030000"],["71877.90000000","0.00240000"],["63891.47000000","0.00031000"],["63891.46000000","0.00000000"],["63891.00000000","0.00000000"]],"a":[["81062.31000000","0.00030000"]]}}}
{"rx_ns": 13961892399100, "frame": {"stream":"btcusdt@depth@100ms","data":{"e":"depthUpdate","E":1787650957115,"s":"BTCUSDT","U":99118679697,"u":99118679743,"b":[["79864.33000000","2.62170000"],["79861.05000000","0.00007000"],["79860.45000000","0.00007000"],["79860.44000000","1.87684000"],["79797.53000000","0.00000000"],["79763.72000000","0.00025000"],["79761.16000000","0.00000000"],["71877.90000000","0.00256000"],["71877.00000000","0.00000000"],["63891.46000000","0.00000000"]],"a":[["79865.56000000","0.00000000"],["79865.57000000","0.00021000"],["79867.26000000","0.00007000"],["79867.39000000","0.00014000"],["79867.98000000","0.00007000"],["79877.24000000","0.00000000"],["79898.00000000","0.03200000"],["79960.81000000","0.00000000"],["79963.38000000","0.00025000"]]}}}
{"rx_ns": 13961992188400, "frame": {"stream":"btcusdt@depth@100ms","data":{"e":"depthUpdate","E":1787650957214,"s":"BTCUSDT","U":99118679744,"u":99118679760,"b":[["79849.12000000","0.00000000"],["79797.53000000","0.02087000"],["79783.88000000","0.00000000"],["76989.21000000","0.00043000"],["71877.90000000","0.00256000"],["63891.47000000","0.00000000"]],"a":[["79864.34000000","0.86807000"],["79864.96000000","0.06159000"],["79865.57000000","0.00007000"],["79867.40000000","0.06152000"],["79881.08000000","0.00000000"]]}}}
{"rx_ns": 13962094982200, "frame": {"stream":"btcusdt@depth@100ms","data":{"e":"depthUpdate","E":1787650957314,"s":"BTCUSDT","U":99118679761,"u":99118679931,"b":[["79864.33000000","2.13860000"],["79864.21000000","0.00000000"],["79863.06000000","1.14235000"],["79863.05000000","0.13872000"],["79861.77000000","0.36906000"],["79861.05000000","0.00007000"],["79860.45000000","0.00000000"],["79860.44000000","0.00007000"],["79860.43000000","0.36663000"],["79859.90000000","0.00000000"],["79858.61000000","0.01684000"],["79858.36000000","0.00000000"],["79858.01000000","0.00626000"],["79856.01000000","0.00626000"],["79849.12000000","0.00007000"],["79797.53000000","0.00000000"],["79783.45000000","0.00000000"],["71877.90000000","0.00272000"],["71877.89000000","0.00000000"],["71877.88000000","0.00008000"],["63891.00000000","0.00000000"]],"a":[["79864.34000000","1.29141000"],["79865.56000000","0.00007000"],["79865.57000000","0.09959000"],["79866.78000000","0.06166000"],["79866.82000000","0.00007000"],["79866.83000000","0.09326000"],["79866.89000000","0.00000000"],["79867.26000000","0.00007000"],["79867.39000000","0.00014000"],["79867.98000000","0.00000000"],["79868.18000000","0.02079000"],["79868.37000000","0.00000000"],["79868.63000000","0.22665000"],["79868.64000000","0.06152000"],["79868.68000000","0.42275000"],["79869.09000000","0.00000000"],["79869.59000000","0.00007000"],["79869.99000000","0.00007000"],["79871.88000000","0.19019000"],["79871.89000000","0.00000000"],["79873.36000000","0.00400000"],["79873.81000000","0.00000000"],["79875.84000000","0.00400000"],["79878.07000000","0.36586000"],["79881.08000000","0.00007000"],["79887.48000000","0.33813000"],["79888.08000000","0.00000000"],["79894.43000000","0.00000000"],["79907.76000000","0.00000000"],["79914.15000000","0.00000000"],["79915.52000000","0.00000000"],["80089.76000000","0.00400000"]]}}}
{"rx_ns": 13962193294400, "frame": {"stream":"btcusdt@depth@100ms","data":{"e":"depthUpdate","E":1787650957414,"s":"BTCUSDT","U":99118679932,"u":99118679972,"b":[["79859.21000000","0.33261000"],["79851.46000000","0.00000000"],["79845.00000000","0.00000000"],["79840.54000000","0.33826000"],["79783.94000000","0.00000000"],["79736.06000000","0.00000000"],["71877.90000000","0.00256000"]],"a":[["79864.34000000","1.44233000"],["79864.35000000","0.00083000"],["79864.96000000","0.06159000"],["79865.57000000","0.09973000"],["79866.78000000","0.06166000"],["79866.82000000","0.00000000"],["79866.83000000","0.00014000"],["79866.89000000","0.00007000"],["79867.27000000","0.04772000"],["79867.40000000","0.06138000"],["79868.64000000","0.06145000"],["79871.88000000","0.00000000"],["79871.89000000","0.19019000"],["79883.51000000","0.00000000"],["79907.82000000","1.23924000"],["79939.52000000","0.00000000"],["79975.64000000","0.00000000"]]}}}
{"rx_ns": 13962294710200, "frame": {"stream":"btcusdt@depth@100ms","data":{"e":"depthUpdate","E":1787650957514,"s":"BTCUSDT","U":99118679973,"u":99118680012,"b":[["79864.33000000","2.23853000"],["79862.90000000","0.00007000"],["79790.88000000","0.00000000"],["79727.48000000","0.04534000"],["79685.35000000","0.01139000"],["76510.02000000","0.00043000"],["71877.90000000","0.00288000"],["63891.47000000","0.00031000"]],"a":[["79864.34000000","1.44301000"],["79865.19000000","0.00014000"],["79866.78000000","0.06159000"],["79866.83000000","0.00000000"],["79867.27000000","0.04786000"],["79867.40000000","0.06145000"],["79867.98000000","0.09522000"],["79868.18000000","0.02072000"],["79868.63000000","0.00000000"],["79868.64000000","0.06138000"],["79868.68000000","0.00000000"],["79871.48000000","0.00000000"],["79871.88000000","0.06139000"],["79871.89000000","0.19019000"],["79871.90000000","1.05630000"],["79883.30000000","0.00000000"],["79907.81000000","1.50325000"],["79967.04000000","0.02804000"],["79969.91000000","0.00400000"],["80089.76000000","0.00000000"],["80183.44000000","0.01935000"]]}}}
{"rx_ns": 13962392516600, "frame": {"stream":"btcusdt@depth@100ms","data":{"e":"depthUpdate","E":1787650957614,"s":"BTCUSDT","U":99118680013,"u":99118680015,"b":[["71877.90000000","0.00288000"],["63891.47000000","0.00000000"]],"a":[]}}}
{"rx_ns": 13962492213200, "frame": {"stream":"btcusdt@depth@100ms","data":{"e":"depthUpdate","E":1787650957714,"s":"BTCUSDT","U":99118680016,"u":99118680025,"b":[["79860.97000000","0.00000000"],["79855.65000000","0.00250000"],["79849.25000000","0.00000000"],["71877.90000000","0.00288000"]],"a":[["79870.54000000","0.06139000"],["79909.20000000","0.00400000"],["79909.27000000","0.00000000"],["80089.78000000","0.00400000"],["80260.48000000","0.00000000"]]}}}
{"rx_ns": 13962595496700, "frame": {"stream":"btcusdt@depth@100ms","data":{"e":"depthUpdate","E":1787650957814,"s":"BTCUSDT","U":99118680026,"u":99118680028,"b":[["79861.04000000","0.47730000"],["76030.84000000","0.00043000"],["71877.90000000","0.00304000"]],"a":[]}}}
{"rx_ns": 13962691988700, "frame": {"stream":"btcusdt@depth@100ms","data":{"e":"depthUpdate","E":1787650957914,"s":"BTCUSDT","U":99118680029,"u":99118680041,"b":[["79864.33000000","2.23863000"],["79861.06000000","0.00009000"],["79644.19000000","0.00000000"],["79637.50000000","0.00799000"],["71877.90000000","0.00320000"],["71877.88000000","0.00000000"]],"a":[["79864.34000000","1.44288000"],["79867.87000000","0.00000000"],["79867.91000000","0.00000000"],["79871.89000000","0.00000000"],["79876.72000000","0.00000000"],["79883.74000000","0.19019000"]]}}}
{"rx_ns": 13962794688200, "frame": {"stream":"btcusdt@depth20","data":{"lastUpdateId":99118680078,"bids":[["79864.33000000","2.23863000"],["79864.32000000","0.00027000"],["79864.31000000","0.00013000"],["79863.07000000","0.00007000"],["79863.06000000","1.14235000"],["79863.05000000","0.13872000"],["79862.90000000","0.00007000"],["79862.75000000","0.00400000"],["79862.45000000","0.00856000"],["79862.10000000","0.00007000"],["79861.79000000","0.00007000"],["79861.78000000","0.07521000"],["79861.77000000","0.36906000"],["79861.68000000","0.05246000"],["79861.67000000","0.00007000"],["79861.66000000","0.38840000"],["79861.65000000","0.22691000"],["79861.32000000","0.00014000"],["79861.29000000","0.08007000"],["79861.17000000","0.01403000"]],"asks":[["79864.34000000","1.44281000"],["79864.35000000","0.00069000"],["79864.36000000","0.00013000"],["79864.59000000","0.00007000"],["79864.95000000","0.00007000"],["79864.96000000","0.06159000"],["79865.19000000","0.00014000"],["79865.29000000","0.00007000"],["79865.56000000","0.00007000"],["79865.57000000","0.21317000"],["79865.58000000","0.00014000"],["79865.62000000","0.01761000"],["79865.99000000","0.00014000"],["79866.09000000","0.00007000"],["79866.14000000","0.00007000"],["79866.15000000","0.42275000"],["79866.20000000","0.00014000"],["79866.71000000","0.00007000"],["79866.78000000","0.00021000"],["79866.90000000","0.02093000"]]}}}
{"rx_ns": 13962794770000, "frame": {"stream":"btcusdt@depth@100ms","data":{"e":"depthUpdate","E":1787650958014,"s":"BTCUSDT","U":99118680042,"u":99118680078,"b":[["78666.36000000","0.00030000"],["71877.90000000","0.00320000"],["63891.47000000","0.00031000"]],"a":[["79864.34000000","1.44281000"],["79864.35000000","0.00069000"],["79865.57000000","0.21317000"],["79865.58000000","0.00014000"],["79865.61000000","0.00000000"],["79865.62000000","0.01761000"],["79865.99000000","0.00014000"],["79866.14000000","0.00007000"],["79866.15000000","0.42275000"],["79866.19000000","0.00000000"],["79866.20000000","0.00014000"],["79866.77000000","0.00000000"],["79866.78000000","0.00021000"],["79866.89000000","0.00000000"],["79867.39000000","0.00007000"],["79867.40000000","0.00007000"],["79867.97000000","0.00007000"],["79867.99000000","0.00000000"],["79868.00000000","0.02414000"],["79868.64000000","0.00000000"],["79870.53000000","0.00007000"],["79906.00000000","0.72400000"],["81062.31000000","0.00030000"]]}}}
{"rx_ns": 13962896162700, "frame": {"stream":"btcusdt@depth@100ms","data":{"e":"depthUpdate","E":1787650958114,"s":"BTCUSDT","U":99118680079,"u":99118680148,"b":[["79864.33000000","2.19926000"],["79864.32000000","0.00076000"],["79860.43000000","0.36670000"],["79860.01000000","0.04042000"],["79836.00000000","0.72400000"],["75551.65000000","0.00044000"],["71877.90000000","0.00336000"],["63891.46000000","0.00020000"]],"a":[["79864.34000000","1.44275000"],["79864.35000000","0.00069000"],["79865.57000000","0.14692000"],["79865.58000000","0.00000000"],["79865.61000000","0.00007000"],["79865.62000000","0.01754000"],["79866.15000000","0.42289000"],["79866.20000000","0.00000000"],["79866.78000000","0.00007000"],["79867.27000000","0.04786000"],["79867.98000000","0.09536000"],["79868.00000000","0.02428000"],["79868.18000000","0.02079000"],["79869.91000000","0.00014000"],["79869.92000000","0.06139000"]]}}}
{"rx_ns": 13962993938300, "frame": {"stream":"btcusdt@depth@100ms","data":{"e":"depthUpdate","E":1787650958214,"s":"BTCUSDT","U":99118680149,"u":99118680164,"b":[["79795.03000000","0.02087000"],["79772.48000000","0.00000000"],["71877.90000000","0.00336000"],["71877.00000000","0.00000000"],["63891.47000000","0.00000000"],["63891.46000000","0.00000000"]],"a":[["79864.34000000","1.44275000"],["79898.00000000","0.02800000"],["79937.93000000","0.00000000"],["79965.91000000","0.00400000"],["79969.91000000","0.00000000"],["80085.75000000","0.00400000"],["80089.78000000","0.00000000"]]}}}
{"rx_ns": 13963092153400, "frame": {"stream":"btcusdt@depth@100ms","data":{"e":"depthUpdate","E":1787650958314,"s":"BTCUSDT","U":99118680165,"u":99118680176,"b":[["79849.12000000","0.00007000"],["79795.03000000","0.00000000"],["79720.73000000","0.01961000"],["79708.80000000","0.00000000"],["71877.90000000","0.00352000"],["63891.00000000","0.00000000"]],"a":[["79881.08000000","0.00007000"],["79894.00000000","0.23050000"]]}}}
{"rx_ns": 13963191935500, "frame": {"stream":"btcusdt@depth@100ms","data":{"e":"depthUpdate","E":1787650958414,"s":"BTCUSDT","U":99118680177,"u":99118680180,"b":[["79795.03000000","0.02087000"],["75072.47000000","0.00044000"],["67000.00000000","36.58303000"],["63891.00000000","0.00300000"]],"a":[]}}}
{"rx_ns": 13963292553300, "frame": {"stream":"btcusdt@depth@100ms","data":{"e":"depthUpdate","E":1787650958514,"s":"BTCUSDT","U":99118680181,"u":99118680189,"b":[["79795.03000000","0.00000000"],["71877.90000000","0.00368000"],["63891.47000000","0.00031000"],["63891.00000000","0.00000000"]],"a":[["79894.00000000","0.22650000"],["79933.95000000","0.00400000"],["79965.91000000","0.00000000"]]}}}
{"rx_ns": 13963392636200, "frame": {"stream":"btcusdt@depth@100ms","data":{"e":"depthUpdate","E":1787650958614,"s":"BTCUSDT","U":99118680190,"u":99118680198,"b":[["71877.90000000","0.00392000"],["63891.47000000","0.00000000"]],"a":[["79864.34000000","1.43047000"],["79924.31000000","0.00000000"]]}}}
{"rx_ns": 13963492622500, "frame": {"stream":"btcusdt@depth@100ms","data":{"e":"depthUpdate","E":1787650958714,"s":"BTCUSDT","U":99118680199,"u":99118680202,"b":[["79855.13000000","0.05652000"],["74593.28000000","0.00044000"]],"a":[["79864.34000000","1.43036000"],["79893.92000000","0.00400000"]]}}}
{"rx_ns": 13963591943200, "frame": {"stream":"btcusdt@depth@100ms","data":{"e":"depthUpdate","E":1787650958814,"s":"BTCUSDT","U":99118680203,"u":99118680208,"b":[["71877.90000000","0.00408000"]],"a":[["79864.34000000","1.42887000"]]}}}
{"rx_ns": 13963694088400, "frame": {"stream":"btcusdt@depth@100ms","data":{"e":"depthUpdate","E":1787650958914,"s":"BTCUSDT","U":99118680209,"u":99118680218,"b":[["79826.32000000","0.00132000"],["79795.03000000","0.02087000"],["71877.90000000","0.00408000"]],"a":[["79893.92000000","0.00000000"],["79899.55000000","0.00000000"],["79933.95000000","0.00000000"],["79955.59000000","0.00000000"],["79955.63000000","0.12309000"],["79965.83000000","0.00400000"]]}}}
{"rx_ns": 13963795603600, "frame": {"stream":"btcusdt@depth20","data":{"lastUpdateId":99118680233,"bids":[["79864.33000000","2.19919000"],["79864.32000000","0.00076000"],["79864.31000000","0.00013000"],["79863.07000000","0.00007000"],["79863.06000000","1.14235000"],["79863.05000000","0.13872000"],["79862.90000000","0.00007000"],["79862.75000000","0.00400000"],["79862.45000000","0.00856000"],["79862.10000000","0.00007000"],["79861.79000000","0.00007000"],["79861.78000000","0.07521000"],["79861.77000000","0.36906000"],["79861.68000000","0.05246000"],["79861.67000000","0.00007000"],["79861.66000000","0.38840000"],["79861.65000000","0.22691000"],["79861.32000000","0.00014000"],["79861.29000000","0.08007000"],["79861.17000000","0.01403000"]],"asks":[["79864.34000000","1.42894000"],["79864.35000000","0.00069000"],["79864.36000000","0.00013000"],["79864.59000000","0.00007000"],["79864.95000000","0.00007000"],["79864.96000000","0.06159000"],["79865.19000000","0.00014000"],["79865.29000000","0.00007000"],["79865.56000000","0.00007000"],["79865.57000000","0.14692000"],["79865.61000000","0.00007000"],["79865.62000000","0.01754000"],["79865.99000000","0.00014000"],["79866.09000000","0.00007000"],["79866.14000000","0.00007000"],["79866.15000000","0.42289000"],["79866.71000000","0.00007000"],["79866.78000000","0.00007000"],["79866.90000000","0.02093000"],["79867.26000000","0.00007000"]]}}}
{"rx_ns": 13963795805700, "frame": {"stream":"btcusdt@depth@100ms","data":{"e":"depthUpdate","E":1787650959014,"s":"BTCUSDT","U":99118680219,"u":99118680233,"b":[["79864.33000000","2.19919000"],["79795.03000000","0.00000000"],["78666.36000000","0.00030000"],["71877.90000000","0.00408000"],["63891.47000000","0.00031000"]],"a":[["79864.34000000","1.42894000"],["79868.18000000","0.02086000"],["79868.40000000","0.00929000"],["79900.16000000","0.09389000"],["81062.31000000","0.00030000"]]}}}
{"rx_ns": 13963925286800, "frame": {"stream":"btcusdt@depth@100ms","data":{"e":"depthUpdate","E":1787650959114,"s":"BTCUSDT","U":99118680234,"u":99118680244,"b":[["79780.81000000","0.62589000"],["71877.90000000","0.00424000"],["63891.46000000","0.00000000"],["63891.00000000","0.00000000"]],"a":[["79893.98000000","0.00400000"]]}}}
{"rx_ns": 13963994354500, "frame": {"stream":"btcusdt@depth@100ms","data":{"e":"depthUpdate","E":1787650959214,"s":"BTCUSDT","U":99118680245,"u":99118680254,"b":[["79864.33000000","2.19926000"],["71877.90000000","0.00440000"],["71877.00000000","0.00000000"],["63891.47000000","0.00000000"],["63891.46000000","0.00000000"]],"a":[["79864.34000000","1.42887000"]]}}}
{"rx_ns": 13964092235900, "frame": {"stream":"btcusdt@depth@100ms","data":{"e":"depthUpdate","E":1787650959314,"s":"BTCUSDT","U":99118680255,"u":99118680268,"b":[["79849.12000000","0.00007000"],["71877.90000000","0.00424000"],["63891.00000000","0.00000000"]],"a":[["79867.18000000","0.00063000"],["79881.08000000","0.00007000"],["79933.93000000","0.00400000"]]}}}
{"rx_ns": 13964192279200, "frame": {"stream":"btcusdt@depth@100ms","data":{"e":"depthUpdate","E":1787650959414,"s":"BTCUSDT","U":99118680269,"u":99118680273,"b":[["71877.90000000","0.00456000"]],"a":[["79876.36000000","0.00000000"],["79933.93000000","0.00000000"]]}}}
{"rx_ns": 13964292620800, "frame": {"stream":"btcusdt@depth@100ms","data":{"e":"depthUpdate","E":1787650959514,"s":"BTCUSDT","U":99118680274,"u":99118680278,"b":[["71877.90000000","0.00440000"],["63891.47000000","0.00031000"]],"a":[["79933.81000000","0.00400000"]]}}}
{"rx_ns": 13964392162400, "frame": {"stream":"btcusdt@depth@100ms","data":{"e":"depthUpdate","E":1787650959614,"s":"BTCUSDT","U":99118680279,"u":99118680289,"b":[["71877.90000000","0.00432000"],["71877.89000000","0.00008000"],["63891.47000000","0.00000000"]],"a":[["79864.34000000","1.22570000"],["79871.10000000","0.00007000"]]}}}
{"rx_ns": 13964491983000, "frame": {"stream":"btcusdt@depth@100ms","data":{"e":"depthUpdate","E":1787650959714,"s":"BTCUSDT","U":99118680290,"u":99118680398,"b":[["79864.33000000","2.19926000"],["79861.05000000","0.00007000"],["79860.44000000","0.00007000"],["79860.43000000","0.36670000"]],"a":[["79864.34000000","1.09862000"],["79864.35000000","0.00076000"],["79867.27000000","0.04793000"],["79867.96000000","0.00007000"],["79867.97000000","0.06145000"],["79868.40000000","0.00943000"],["79868.67000000","0.00007000"],["79868.68000000","0.06138000"],["79868.92000000","0.00698000"],["79869.29000000","0.00007000"],["79869.30000000","0.06138000"],["79869.91000000","0.00007000"],["79870.53000000","0.00000000"],["79871.10000000","0.00000000"]]}}}
{"rx_ns": 13964596760400, "frame": {"stream":"btcusdt@depth@100ms","data":{"e":"depthUpdate","E":1787650959814,"s":"BTCUSDT","U":99118680399,"u":99118680440,"b":[["79864.33000000","2.28565000"],["79861.05000000","0.00007000"],["79860.44000000","0.00007000"],["79860.43000000","0.36670000"],["71877.90000000","0.00432000"]],"a":[["79864.34000000","0.72777000"],["79864.35000000","0.00069000"],["79864.95000000","0.00000000"],["79864.96000000","0.00021000"],["79865.19000000","0.00007000"],["79867.27000000","0.04793000"],["79867.97000000","0.06159000"],["79868.00000000","0.02414000"],["79868.40000000","0.00014000"],["79868.92000000","0.00007000"],["79869.91000000","0.00014000"],["79873.75000000","0.00048000"]]}}}
{"rx_ns": 13964700594600, "frame": {"stream":"btcusdt@depth@100ms","data":{"e":"depthUpdate","E":1787650959914,"s":"BTCUSDT","U":99118680441,"u":99118680468,"b":[["79864.33000000","2.29316000"],["79864.32000000","0.00062000"],["79862.76000000","0.00007000"],["79861.06000000","0.00000000"],["79855.14000000","0.00400000"],["79855.13000000","0.00000000"],["71877.90000000","0.00448000"],["63891.00000000","0.00300000"]],"a":[["79864.34000000","0.72777000"],["79864.96000000","0.00007000"],["79868.00000000","0.02428000"],["79871.87000000","0.00400000"],["79909.00000000","0.00000000"]]}}}
{"rx_ns": 13964793433800, "frame": {"stream":"btcusdt@depth20","data":{"lastUpdateId":99118680482,"bids":[["79864.33000000","2.29309000"],["79864.32000000","0.00055000"],["79864.31000000","0.00013000"],["79863.07000000","0.00007000"],["79863.06000000","1.14235000"],["79863.05000000","0.13872000"],["79862.90000000","0.00007000"],["79862.76000000","0.00007000"],["79862.75000000","0.00400000"],["79862.45000000","0.00856000"],["79862.10000000","0.00007000"],["79861.79000000","0.00007000"],["79861.78000000","0.07521000"],["79861.77000000","0.36906000"],["79861.68000000","0.05246000"],["79861.67000000","0.00007000"],["79861.66000000","0.38840000"],["79861.65000000","0.22691000"],["79861.32000000","0.00014000"],["79861.29000000","0.08007000"]],"asks":[["79864.34000000","0.72777000"],["79864.35000000","0.00069000"],["79864.36000000","0.00013000"],["79864.59000000","0.00007000"],["79864.96000000","0.00007000"],["79865.19000000","0.00007000"],["79865.29000000","0.00007000"],["79865.56000000","0.00007000"],["79865.57000000","0.14692000"],["79865.61000000","0.00007000"],["79865.62000000","0.01754000"],["79865.99000000","0.00014000"],["79866.09000000","0.00007000"],["79866.14000000","0.00007000"],["79866.15000000","0.42289000"],["79866.71000000","0.00007000"],["79866.78000000","0.00007000"],["79866.90000000","0.02093000"],["79867.18000000","0.00063000"],["79867.26000000","0.00007000"]]}}}
{"rx_ns": 13964793520800, "frame": {"stream":"btcusdt@depth@100ms","data":{"e":"depthUpdate","E":1787650960014,"s":"BTCUSDT","U":99118680469,"u":99118680482,"b":[["79864.33000000","2.29309000"],["79864.32000000","0.00055000"],["79806.96000000","0.04696000"],["79795.91000000","0.00000000"],["79795.03000000","0.00000000"],["78666.36000000","0.00030000"],["71877.90000000","0.00432000"],["71877.00000000","0.00010000"],["63891.47000000","0.00031000"],["63891.00000000","0.00000000"]],"a":[["81062.31000000","0.00030000"]]}}}
{"rx_ns": 13964901394100, "frame": {"stream":"btcusdt@depth@100ms","data":{"e":"depthUpdate","E":1787650960114,"s":"BTCUSDT","U":99118680483,"u":99118680503,"b":[["79861.05000000","0.00007000"],["79860.44000000","0.00007000"],["79860.43000000","0.36670000"],["71877.90000000","0.00448000"],["71877.00000000","0.00000000"],["63891.46000000","0.00000000"]],"a":[["79864.34000000","0.72784000"],["79867.98000000","0.17865000"],["79868.68000000","0.06145000"],["79869.27000000","0.00007000"],["79869.28000000","0.19652000"],["79869.91000000","0.00007000"],["79967.99000000","0.00556000"]]}}}
{"rx_ns": 13964993021300, "frame": {"stream":"btcusdt@depth@100ms","data":{"e":"depthUpdate","E":1787650960215,"s":"BTCUSDT","U":99118680504,"u":99118680511,"b":[["71877.90000000","0.00432000"],["71877.00000000","0.00000000"],["63891.47000000","0.00000000"],["63891.46000000","0.00000000"]],"a":[]}}}
{"rx_ns": 13965091952400, "frame": {"stream":"btcusdt@depth@100ms","data":{"e":"depthUpdate","E":1787650960314,"s":"BTCUSDT","U":99118680512,"u":99118680518,"b":[["79855.11000000","0.12305000"],["79849.12000000","0.00000000"],["71877.90000000","0.00448000"],["71877.00000000","0.00010000"],["63891.00000000","0.00000000"]],"a":[["79865.29000000","0.00000000"],["79881.08000000","0.00000000"]]}}}
{"rx_ns": 13965193038300, "frame": {"stream":"btcusdt@depth@100ms","data":{"e":"depthUpdate","E":1787650960414,"s":"BTCUSDT","U":99118680519,"u":99118680540,"b":[["79864.33000000","2.29274000"],["79864.32000000","0.00027000"],["79860.44000000","1.87684000"],["79849.12000000","0.00007000"],["71877.90000000","0.00432000"],["71877.00000000","0.00000000"]],"a":[["79864.34000000","0.39862000"],["79871.87000000","0.00000000"],["79881.08000000","0.00007000"]]}}}
{"rx_ns": 13965294213000, "frame": {"stream":"btcusdt@depth@100ms","data":{"e":"depthUpdate","E":1787650960514,"s":"BTCUSDT","U":99118680541,"u":99118680666,"b":[["79863.07000000","0.00407000"],["79862.76000000","0.00000000"],["79861.05000000","0.00007000"],["79860.45000000","0.00007000"],["79860.44000000","1.87684000"],["79860.43000000","0.36663000"],["79855.14000000","0.00000000"],["79795.03000000","0.02087000"],["71877.90000000","0.00448000"],["63891.47000000","0.00031000"]],"a":[["79864.34000000","0.33131000"],["79864.35000000","0.00069000"],["79865.56000000","0.00000000"],["79865.57000000","0.00014000"],["79865.62000000","0.01768000"],["79866.14000000","0.00000000"],["79866.15000000","0.00014000"],["79866.19000000","0.00007000"],["79866.20000000","0.06138000"],["79866.81000000","0.00007000"],["79866.82000000","0.06138000"],["79866.89000000","0.00007000"],["79867.18000000","0.00000000"],["79867.27000000","0.04800000"],["79867.43000000","0.00007000"],["79867.44000000","0.06138000"],["79867.96000000","0.00007000"],["79867.97000000","0.06152000"],["79867.98000000","0.00014000"],["79867.99000000","0.00007000"],["79868.17000000","0.00007000"],["79868.18000000","0.02093000"],["79868.66000000","0.00000000"],["79868.67000000","0.17718000"],["79869.27000000","0.00000000"],["79869.29000000","0.00000000"],["79869.91000000","0.00007000"],["79869.99000000","0.00000000"],["79870.53000000","0.00000000"],["79871.87000000","0.00400000"],["79871.90000000","0.00000000"],["79871.92000000","0.29265000"],["79873.02000000","0.06138000"],["79873.64000000","0.06138000"],["79873.69000000","0.00069000"],["79873.98000000","0.00000000"],["79873.99000000","0.06138000"],["79893.98000000","0.00000000"],["79898.01000000","0.00400000"],["79907.76000000","0.00007000"],["79933.81000000","0.00000000"],["79937.96000000","0.00400000"],["79965.83000000","0.00000000"],["79969.92000000","0.00400000"],["80085.75000000","0.00000000"],["80089.77000000","0.00400000"]]}}}
{"rx_ns": 13965395229100, "frame": {"stream":"btcusdt@depth@100ms","data":{"e":"depthUpdate","E":1787650960614,"s":"BTCUSDT","U":99118680667,"u":99118680733,"b":[["79864.33000000","2.29281000"],["79863.08000000","0.00007000"],["79863.07000000","0.01207000"],["79861.66000000","0.38840000"],["79861.05000000","0.00007000"],["79860.45000000","0.00007000"],["79860.44000000","1.87677000"],["79840.00000000","0.98024000"],["79795.03000000","0.00000000"],["79634.11000000","0.00000000"],["71877.90000000","0.00432000"],["63891.47000000","0.00000000"]],"a":[["79864.34000000","0.33116000"],["79864.96000000","0.00000000"],["79865.57000000","0.00000000"],["79865.58000000","0.06138000"],["79865.62000000","0.01761000"],["79865.99000000","0.00007000"],["79866.15000000","0.00000000"],["79866.20000000","0.06152000"],["79866.82000000","0.06152000"],["79867.27000000","0.04800000"],["79867.40000000","0.00000000"],["79867.44000000","0.06152000"],["79867.97000000","0.06152000"],["79867.98000000","0.00000000"],["79868.00000000","0.02421000"],["79868.28000000","0.00000000"],["79869.10000000","0.00000000"],["79869.59000000","0.00000000"],["79871.87000000","0.00000000"],["79875.93000000","0.01200000"],["79898.01000000","0.00000000"],["79907.76000000","0.00000000"],["79937.96000000","0.00000000"],["79969.92000000","0.00000000"],["80089.76000000","0.00400000"],["80089.77000000","0.00000000"]]}}}
{"rx_ns": 13965496077400, "frame": {"stream":"btcusdt@depth@100ms","data":{"e":"depthUpdate","E":1787650960714,"s":"BTCUSDT","U":99118680734,"u":99118680838,"b":[["79864.33000000","2.19295000"],["79863.08000000","0.00407000"],["79861.66000000","0.38840000"],["79861.65000000","0.22677000"],["79861.05000000","0.00007000"],["79860.45000000","0.00007000"],["79638.42000000","0.01961000"],["71877.90000000","0.00448000"],["71877.00000000","0.00000000"],["65687.50000000","0.00293000"],["65375.00000000","0.00210000"],["65062.50000000","0.00146000"],["64750.00000000","0.16166000"],["64437.50000000","0.00168000"],["64125.00000000","0.01166000"],["63812.50000000","0.00165000"],["63500.00000000","18.88367000"],["63187.50000000","0.00146000"],["62875.00000000","0.00723000"],["62562.50000000","0.00146000"],["62250.00000000","5.64286000"],["61937.50000000","0.00170000"],["61625.00000000","0.00232000"],["61312.50000000","0.00259000"],["61000.00000000","59.85012000"]],"a":[["79864.34000000","0.33130000"],["79864.35000000","0.00076000"],["79865.57000000","0.00007000"],["79865.58000000","0.06152000"],["79867.43000000","0.00007000"],["79867.96000000","0.00007000"],["79867.99000000","0.00007000"],["79868.00000000","0.02407000"],["79868.17000000","0.00000000"],["79875.70000000","0.00000000"],["79875.72000000","0.00000000"],["79875.73000000","0.00400000"],["79875.74000000","0.00000000"],["79875.76000000","0.00000000"],["79875.92000000","0.01200000"],["79875.93000000","0.00000000"],["79937.95000000","0.00400000"]]}}}
{"rx_ns": 13965597899000, "frame": {"stream":"btcusdt@depth@100ms","data":{"e":"depthUpdate","E":1787650960814,"s":"BTCUSDT","U":99118680839,"u":99118680864,"b":[["79864.33000000","2.19344000"],["79864.32000000","0.00069000"],["79727.48000000","0.00000000"],["71877.90000000","0.00432000"],["71877.00000000","0.00000000"]],"a":[["79864.34000000","0.67763000"],["79967.04000000","0.00000000"]]}}}
{"rx_ns": 13965693363200, "frame": {"stream":"btcusdt@depth@100ms","data":{"e":"depthUpdate","E":1787650960914,"s":"BTCUSDT","U":99118680865,"u":99118680876,"b":[["79864.33000000","2.29344000"],["79795.03000000","0.02087000"],["79737.09000000","0.04410000"],["79644.19000000","0.00771000"],["79637.50000000","0.00028000"],["71877.90000000","0.00432000"]],"a":[["79864.34000000","0.87255000"],["79898.00000000","0.03200000"],["79976.67000000","0.02804000"]]}}}
{"rx_ns": 13965791734500, "frame": {"stream":"btcusdt@depth20","data":{"lastUpdateId":99118680940,"bids":[["79864.33000000","2.29344000"],["79864.32000000","0.00062000"],["79864.31000000","0.00013000"],["79863.09000000","0.00007000"],["79863.08000000","0.01200000"],["79863.07000000","0.00007000"],["79863.06000000","1.14235000"],["79863.05000000","0.13872000"],["79862.90000000","0.00007000"],["79862.75000000","0.00400000"],["79862.45000000","0.00856000"],["79862.10000000","0.00007000"],["79861.79000000","0.00007000"],["79861.78000000","0.07521000"],["79861.77000000","0.36906000"],["79861.68000000","0.05246000"],["79861.67000000","0.00007000"],["79861.66000000","0.38840000"],["79861.65000000","0.22677000"],["79861.32000000","0.00014000"]],"asks":[["79864.34000000","0.67770000"],["79864.35000000","0.00076000"],["79864.36000000","0.00013000"],["79864.59000000","0.00007000"],["79865.19000000","0.00007000"],["79865.57000000","0.00007000"],["79865.58000000","0.06152000"],["79865.61000000","0.00007000"],["79865.62000000","0.01761000"],["79865.99000000","0.00007000"],["79866.09000000","0.00007000"],["79866.19000000","0.00007000"],["79866.20000000","0.06152000"],["79866.71000000","0.00007000"],["79866.78000000","0.00007000"],["79866.81000000","0.00007000"],["79866.82000000","0.06152000"],["79866.89000000","0.00007000"],["79866.90000000","0.02093000"],["79867.26000000","0.00007000"]]}}}
{"rx_ns": 13965791886900, "frame": {"stream":"btcusdt@depth@100ms","data":{"e":"depthUpdate","E":1787650961014,"s":"BTCUSDT","U":99118680877,"u":99118680940,"b":[["79864.33000000","2.29344000"],["79864.32000000","0.00062000"],["79863.09000000","0.00007000"],["79863.08000000","0.01200000"],["79863.07000000","0.00007000"],["79862.76000000","0.00000000"],["79861.66000000","0.38840000"],["79861.05000000","0.00007000"],["79860.45000000","0.00007000"],["79860.44000000","1.87677000"],["79859.48000000","0.00400000"],["79859.21000000","0.33254000"],["79858.00000000","0.02400000"],["79855.12000000","0.00000000"],["79100.00000000","3.39473000"],["78666.36000000","0.00030000"],["71877.90000000","0.00432000"],["71877.00000000","0.00010000"],["63891.47000000","0.00031000"]],"a":[["79864.34000000","0.67770000"],["79868.18000000","0.02100000"],["79868.41000000","0.30323000"],["79868.42000000","0.42275000"],["79868.67000000","0.00000000"],["79873.86000000","0.00400000"],["81062.31000000","0.00030000"]]}}}
{"rx_ns": 13965892303900, "frame": {"stream":"btcusdt@depth@100ms","data":{"e":"depthUpdate","E":1787650961114,"s":"BTCUSDT","U":99118680941,"u":99118680976,"b":[["79864.33000000","2.29302000"],["79864.32000000","0.00027000"],["79795.03000000","0.00000000"],["71877.90000000","0.00432000"],["71877.00000000","0.00000000"],["63891.46000000","0.00000000"]],"a":[["79864.34000000","0.33137000"],["79868.18000000","0.02100000"],["79868.40000000","0.06145000"],["79868.68000000","0.00007000"],["79868.92000000","0.00000000"],["79869.30000000","0.00000000"],["79873.86000000","0.00000000"],["79875.47000000","0.00400000"],["79907.76000000","0.00007000"],["79969.91000000","0.00400000"]]}}}
{"rx_ns": 13965991633600, "frame": {"stream":"btcusdt@depth@100ms","data":{"e":"depthUpdate","E":1787650961214,"s":"BTCUSDT","U":99118680977,"u":99118681001,"b":[["79861.66000000","0.38840000"],["79861.05000000","0.00007000"],["79860.45000000","0.00007000"],["71877.90000000","0.00416000"],["63891.47000000","0.00000000"],["63891.46000000","0.00000000"]],"a":[["79864.34000000","0.33151000"],["79864.35000000","0.00083000"],["79864.95000000","0.00007000"],["79864.96000000","0.06138000"],["79867.26000000","0.00007000"],["79867.43000000","0.00007000"],["79867.96000000","0.00007000"],["79867.99000000","0.00000000"],["79876.69000000","0.12528000"],["79886.01000000","0.00617000"],["79969.91000000","0.00000000"]]}}}
{"rx_ns": 13966091915900, "frame": {"stream":"btcusdt@depth@100ms","data":{"e":"depthUpdate","E":1787650961314,"s":"BTCUSDT","U":99118681002,"u":99118681024,"b":[["79688.90000000","0.00000000"],["78926.47000000","0.00000000"],["73480.61000000","0.00014000"],["71877.90000000","0.00432000"],["71877.00000000","0.00000000"],["63891.00000000","0.00000000"]],"a":[["79864.34000000","0.33151000"],["79864.96000000","0.06152000"],["79867.97000000","0.06138000"],["79876.69000000","0.00000000"],["79969.93000000","0.00400000"],["80057.42000000","0.00000000"]]}}}
{"rx_ns": 13966200013600, "frame": {"stream":"btcusdt@depth@100ms","data":{"e":"depthUpdate","E":1787650961414,"s":"BTCUSDT","U":99118681025,"u":99118681049,"b":[["79864.33000000","2.16140000"],["79863.08000000","0.01214000"],["79849.12000000","0.00007000"],["71877.90000000","0.00448000"],["71877.89000000","0.00000000"]],"a":[["79864.34000000","0.46550000"],["79865.29000000","0.00007000"],["79867.18000000","0.00063000"],["79881.08000000","0.00007000"],["79955.63000000","0.00000000"]]}}}
{"rx_ns": 13966292179600, "frame": {"stream":"btcusdt@depth@100ms","data":{"e":"depthUpdate","E":1787650961514,"s":"BTCUSDT","U":99118681050,"u":99118681061,"b":[["79689.14000000","4.47229000"],["71877.90000000","0.00432000"],["63891.47000000","0.00031000"]],"a":[["79864.34000000","0.43760000"],["79868.18000000","0.02093000"],["79869.92000000","0.00000000"],["79873.02000000","0.00000000"],["79912.00000000","0.02400000"],["80057.16000000","4.46779000"]]}}}
{"rx_ns": 13966391736200, "frame": {"stream":"btcusdt@depth@100ms","data":{"e":"depthUpdate","E":1787650961614,"s":"BTCUSDT","U":99118681062,"u":99118681068,"b":[["79783.45000000","0.62589000"],["79780.81000000","0.00000000"],["63891.47000000","0.00000000"],["63891.00000000","0.00000000"]],"a":[["79864.34000000","0.43747000"],["79870.54000000","0.00000000"]]}}}
{"rx_ns": 13966493915400, "frame": {"stream":"btcusdt@depth@100ms","data":{"e":"depthUpdate","E":1787650961714,"s":"BTCUSDT","U":99118681069,"u":99118681074,"b":[["79644.19000000","0.00000000"],["79641.60000000","0.00771000"],["79161.14000000","0.00031000"],["71877.90000000","0.00416000"]],"a":[["79907.76000000","0.00000000"]]}}}
{"rx_ns": 13966591926600, "frame": {"stream":"btcusdt@depth@100ms","data":{"e":"depthUpdate","E":1787650961814,"s":"BTCUSDT","U":99118681075,"u":99118681084,"b":[["79864.33000000","2.15890000"],["71877.90000000","0.00432000"]],"a":[["79864.34000000","0.43897000"],["79871.92000000","0.89796000"],["79873.64000000","0.00000000"],["79873.98000000","1.87677000"],["79873.99000000","0.00000000"],["79877.11000000","0.12528000"]]}}}
{"rx_ns": 13966691983000, "frame": {"stream":"btcusdt@depth@100ms","data":{"e":"depthUpdate","E":1787650961914,"s":"BTCUSDT","U":99118681085,"u":99118681103,"b":[["79864.33000000","2.15879000"],["79842.51000000","1.31339000"],["79842.18000000","0.00000000"],["79841.00000000","0.70000000"],["79795.03000000","0.02087000"],["73480.61000000","0.00000000"],["71877.90000000","0.00416000"],["63891.00000000","0.00200000"]],"a":[["79864.34000000","0.43890000"],["79868.18000000","0.02100000"],["79868.39000000","0.04631000"],["79868.41000000","0.16572000"],["79868.68000000","0.00000000"],["79869.28000000","0.00000000"],["79877.11000000","0.00000000"],["79955.64000000","0.12231000"]]}}}
{"rx_ns": 13966795805400, "frame": {"stream":"btcusdt@depth20","data":{"lastUpdateId":99118681109,"bids":[["79864.33000000","2.15879000"],["79864.32000000","0.00027000"],["79864.31000000","0.00013000"],["79863.09000000","0.00007000"],["79863.08000000","0.01214000"],["79863.07000000","0.00007000"],["79863.06000000","1.14235000"],["79863.05000000","0.13872000"],["79862.90000000","0.00007000"],["79862.75000000","0.00400000"],["79862.45000000","0.00856000"],["79862.10000000","0.00007000"],["79861.79000000","0.00007000"],["79861.78000000","0.07521000"],["79861.77000000","0.36906000"],["79861.68000000","0.05246000"],["79861.67000000","0.00007000"],["79861.66000000","0.38840000"],["79861.65000000","0.22677000"],["79861.32000000","0.00014000"]],"asks":[["79864.34000000","0.43890000"],["79864.35000000","0.00083000"],["79864.36000000","0.00013000"],["79864.59000000","0.00007000"],["79864.95000000","0.00007000"],["79864.96000000","0.06152000"],["79865.19000000","0.00007000"],["79865.29000000","0.00007000"],["79865.57000000","0.00007000"],["79865.58000000","0.06152000"],["79865.61000000","0.00007000"],["79865.62000000","0.01761000"],["79865.99000000","0.00007000"],["79866.09000000","0.00007000"],["79866.19000000","0.00007000"],["79866.20000000","0.06152000"],["79866.71000000","0.00007000"],["79866.78000000","0.00007000"],["79866.81000000","0.00007000"],["79866.82000000","0.06152000"]]}}}
{"rx_ns": 13966796160700, "frame": {"stream":"btcusdt@depth@100ms","data":{"e":"depthUpdate","E":1787650962014,"s":"BTCUSDT","U":99118681104,"u":99118681109,"b":[["79795.03000000","0.00000000"],["71877.90000000","0.00432000"],["63891.47000000","0.00031000"],["63891.00000000","0.00000000"]],"a":[]}}}
{"rx_ns": 13966892094500, "frame": {"stream":"btcusdt@depth@100ms","data":{"e":"depthUpdate","E":1787650962114,"s":"BTCUSDT","U":99118681110,"u":99118681118,"b":[["78666.36000000","0.00030000"],["71877.90000000","0.00416000"],["63891.46000000","0.00000000"]],"a":[["81062.31000000","0.00030000"]]}}}
{"rx_ns": 13966992522300, "frame": {"stream":"btcusdt@depth@100ms","data":{"e":"depthUpdate","E":1787650962214,"s":"BTCUSDT","U":99118681119,"u":99118681122,"b":[["71877.90000000","0.00432000"],["63891.47000000","0.00000000"],["63891.46000000","0.00000000"]],"a":[]}}}
{"rx_ns": 13967091986400, "frame": {"stream":"btcusdt@depth@100ms","data":{"e":"depthUpdate","E":1787650962314,"s":"BTCUSDT","U":99118681123,"u":99118681130,"b":[["71877.90000000","0.00416000"],["71877.00000000","0.00000000"],["63891.00000000","0.00000000"]],"a":[["79890.25000000","0.00000000"]]}}}
{"rx_ns": 13967192337100, "frame": {"stream":"btcusdt@depth@100ms","data":{"e":"depthUpdate","E":1787650962414,"s":"BTCUSDT","U":99118681131,"u":99118681136,"b":[["79849.12000000","0.00007000"],["71877.90000000","0.00432000"]],"a":[["79881.08000000","0.00007000"]]}}}
{"rx_ns": 13967293059900, "frame": {"stream":"btcusdt@depth@100ms","data":{"e":"depthUpdate","E":1787650962514,"s":"BTCUSDT","U":99118681137,"u":99118681170,"b":[["79864.33000000","2.05921000"],["79864.32000000","0.00062000"],["79861.80000000","0.00007000"],["79860.44000000","0.00000000"],["79859.48000000","0.00000000"],["79858.26000000","0.00400000"],["79836.00000000","0.02400000"],["79795.03000000","0.02087000"],["71877.90000000","0.00400000"],["63891.47000000","0.00031000"]],"a":[["79864.34000000","0.98136000"],["79865.57000000","0.09980000"],["79867.52000000","0.14688000"],["79868.39000000","0.00000000"],["79868.40000000","0.06138000"],["79870.54000000","0.05532000"],["79871.91000000","1.04939000"]]}}}
{"rx_ns": 13967391839200, "frame": {"stream":"btcusdt@depth@100ms","data":{"e":"depthUpdate","E":1787650962614,"s":"BTCUSDT","U":99118681171,"u":99118681269,"b":[["79864.33000000","2.05970000"],["79864.32000000","0.00076000"],["79863.09000000","0.00000000"],["79863.08000000","0.00014000"],["79861.66000000","0.38840000"],["79861.05000000","0.00007000"],["79860.45000000","0.00000000"],["79860.44000000","0.00007000"],["79860.43000000","0.36670000"],["79858.26000000","0.00000000"],["79856.94000000","0.01090000"],["79855.12000000","0.01200000"],["79840.00000000","0.28024000"],["79795.03000000","0.00000000"],["71877.90000000","0.00416000"],["63891.47000000","0.00000000"]],"a":[["79864.34000000","1.18732000"],["79864.96000000","0.06159000"],["79865.56000000","0.00007000"],["79865.57000000","0.15945000"],["79865.62000000","0.01768000"],["79865.65000000","0.00007000"],["79865.66000000","0.09529000"],["79866.81000000","0.00007000"],["79866.89000000","0.00000000"],["79867.26000000","0.00007000"],["79867.43000000","0.00007000"],["79867.44000000","0.06145000"],["79867.52000000","0.00000000"],["79867.96000000","0.00000000"],["79868.18000000","0.02093000"],["79868.41000000","0.17209000"],["79868.42000000","0.42282000"],["79871.33000000","0.00400000"],["79871.86000000","0.19019000"],["79871.87000000","0.01200000"],["79873.69000000","0.00000000"],["79875.47000000","0.00000000"],["79875.92000000","0.00000000"],["79883.74000000","0.00000000"],["79908.75000000","0.00400000"],["79909.20000000","0.00000000"]]}}}
{"rx_ns": 13967492253000, "frame": {"stream":"btcusdt@depth@100ms","data":{"e":"depthUpdate","E":1787650962714,"s":"BTCUSDT","U":99118681270,"u":99118681310,"b":[["79864.33000000","2.15933000"],["79864.32000000","0.00076000"],["79863.08000000","0.00000000"],["79861.68000000","0.05260000"],["79790.34000000","0.00009000"],["71877.90000000","0.00416000"],["71877.89000000","0.00008000"]],"a":[["79864.34000000","1.18729000"],["79865.62000000","0.01768000"],["79865.66000000","0.09543000"],["79867.27000000","0.04786000"],["79867.44000000","0.06138000"],["79871.86000000","0.00000000"],["79883.30000000","0.19019000"]]}}}
{"rx_ns": 13967595064600, "frame": {"stream":"btcusdt@depth@100ms","data":{"e":"depthUpdate","E":1787650962814,"s":"BTCUSDT","U":99118681311,"u":99118681337,"b":[["79864.33000000","2.15940000"],["79861.05000000","0.00007000"],["79860.44000000","0.00007000"],["79860.43000000","0.36670000"],["79854.34000000","0.00009000"],["79850.25000000","0.99455000"],["79824.39000000","0.07954000"],["71877.90000000","0.00400000"]],"a":[["79864.34000000","1.18736000"],["79864.42000000","0.00007000"],["79864.43000000","0.12214000"],["79865.57000000","0.11618000"],["79865.61000000","0.00000000"],["79865.65000000","0.00000000"],["79865.66000000","0.00014000"],["79867.18000000","0.00000000"],["79867.26000000","0.00007000"],["79867.43000000","0.00007000"],["79867.96000000","0.00007000"],["79873.75000000","0.00000000"]]}}}
{"rx_ns": 13967699763400, "frame": {"stream":"btcusdt@depth@100ms","data":{"e":"depthUpdate","E":1787650962914,"s":"BTCUSDT","U":99118681338,"u":99118681361,"b":[["79815.73000000","0.00654000"],["79685.35000000","0.00297000"],["71877.90000000","0.00432000"]],"a":[["79864.34000000","1.18728000"],["79864.43000000","0.12228000"],["79865.62000000","0.01761000"],["79865.66000000","0.00000000"],["79873.67000000","0.00047000"],["80183.44000000","0.01637000"]]}}}
{"rx_ns": 13967792714100, "frame": {"stream":"btcusdt@depth20","data":{"lastUpdateId":99118681449,"bids":[["79864.33000000","2.13845000"],["79864.32000000","0.00076000"],["79864.31000000","0.00013000"],["79863.06000000","0.00021000"],["79863.05000000","0.13872000"],["79862.90000000","0.00007000"],["79862.75000000","0.00400000"],["79862.45000000","0.00856000"],["79862.10000000","0.00007000"],["79861.79000000","0.00007000"],["79861.78000000","0.60866000"],["79861.77000000","0.36906000"],["79861.69000000","0.00007000"],["79861.68000000","0.05260000"],["79861.67000000","0.00007000"],["79861.66000000","0.31340000"],["79861.65000000","0.22677000"],["79861.32000000","0.00014000"],["79861.30000000","0.00007000"],["79861.29000000","0.08007000"]],"asks":[["79864.34000000","1.20935000"],["79864.35000000","0.00090000"],["79864.36000000","0.00013000"],["79864.42000000","0.00007000"],["79864.43000000","0.12228000"],["79864.59000000","0.00007000"],["79864.95000000","0.00007000"],["79864.96000000","0.06159000"],["79865.19000000","0.00007000"],["79865.29000000","0.00007000"],["79865.56000000","0.00007000"],["79865.57000000","0.11618000"],["79865.58000000","0.06152000"],["79865.62000000","0.01761000"],["79865.99000000","0.00007000"],["79866.09000000","0.00007000"],["79866.19000000","0.00007000"],["79866.20000000","0.06152000"],["79866.71000000","0.00007000"],["79866.78000000","0.00007000"]]}}}
{"rx_ns": 13967792803200, "frame": {"stream":"btcusdt@depth@100ms","data":{"e":"depthUpdate","E":1787650963014,"s":"BTCUSDT","U":99118681362,"u":99118681449,"b":[["79864.33000000","2.13845000"],["79864.32000000","0.00076000"],["79863.07000000","0.00000000"],["79863.06000000","0.00021000"],["79861.80000000","0.00000000"],["79861.78000000","0.60866000"],["79861.69000000","0.00007000"],["79861.66000000","0.31340000"],["79861.30000000","0.00007000"],["79861.05000000","0.00007000"],["79860.44000000","0.00007000"],["79860.43000000","0.36663000"],["79860.42000000","0.00000000"],["79859.90000000","0.00010000"],["79859.23000000","0.00000000"],["79859.22000000","0.16103000"],["79857.13000000","0.00400000"],["79856.94000000","0.00690000"],["79855.13000000","0.00800000"],["79855.12000000","0.00400000"],["79855.08000000","0.78987000"],["79855.07000000","0.00000000"],["79854.72000000","0.00007000"],["79852.62000000","0.00000000"],["79851.74000000","0.08566000"],["79842.38000000","0.00000000"],["79832.83000000","0.04480000"],["79798.65000000","1.48440000"],["79795.03000000","0.02087000"],["79641.60000000","0.00000000"],["79638.43000000","0.00771000"],["71877.90000000","0.00416000"],["71877.89000000","0.00000000"],["71877.88000000","0.00008000"],["63891.47000000","0.00031000"]],"a":[["79864.34000000","1.20935000"],["79864.35000000","0.00090000"],["79867.26000000","0.00007000"],["79867.43000000","0.00007000"],["79867.96000000","0.00007000"],["79872.70000000","0.00000000"],["79873.67000000","0.00000000"],["79876.40000000","0.08576000"],["79876.99000000","0.00000000"],["79877.28000000","0.00000000"],["79888.50000000","0.00400000"],["79906.50000000","0.00400000"],["79906.68000000","0.00000000"],["79908.75000000","0.00000000"]]}}}
{"rx_ns": 13967892244200, "frame": {"stream":"btcusdt@depth@100ms","data":{"e":"depthUpdate","E":1787650963114,"s":"BTCUSDT","U":99118681450,"u":99118681481,"b":[["79864.33000000","2.13845000"],["79863.06000000","0.00007000"],["79859.89000000","0.01691000"],["79859.24000000","0.49725000"],["79859.23000000","1.04939000"],["79859.22000000","0.00133000"],["79851.63000000","0.00000000"],["79832.10000000","0.00000000"],["79807.02000000","1.24080000"],["79799.04000000","1.24093000"],["79795.03000000","0.00000000"],["79737.09000000","0.00000000"],["78666.36000000","0.00030000"],["71877.90000000","0.00432000"],["63891.46000000","0.00000000"]],"a":[["79864.34000000","1.21488000"],["79865.19000000","0.00014000"],["79976.67000000","0.00000000"],["81062.31000000","0.00030000"]]}}}
{"rx_ns": 13967995546500, "frame": {"stream":"btcusdt@depth@100ms","data":{"e":"depthUpdate","E":1787650963214,"s":"BTCUSDT","U":99118681482,"u":99118681494,"b":[["79864.33000000","2.13859000"],["79727.55000000","0.04534000"],["79435.12000000","0.01515000"],["79338.00000000","0.01516000"],["79314.54000000","0.00000000"],["79000.00000000","24.98642000"],["78997.01000000","0.00000000"],["71877.90000000","0.00416000"],["63891.47000000","0.00000000"],["63891.46000000","0.00000000"]],"a":[["79864.34000000","1.21441000"],["79873.88000000","0.00047000"],["79967.10000000","0.02804000"]]}}}
{"rx_ns": 13968098699600, "frame": {"stream":"btcusdt@depth@100ms","data":{"e":"depthUpdate","E":1787650963314,"s":"BTCUSDT","U":99118681495,"u":99118681513,"b":[["79864.33000000","2.13846000"],["79783.45000000","0.00000000"],["71877.90000000","0.00432000"],["71877.88000000","0.00000000"],["63891.00000000","0.00000000"]],"a":[["79864.34000000","1.21489000"],["79873.88000000","0.00000000"],["79876.16000000","0.12528000"],["79876.25000000","0.00000000"],["79960.31000000","1.95360000"],["79965.59000000","0.00036000"]]}}}
{"rx_ns": 13968192336200, "frame": {"stream":"btcusdt@depth@100ms","data":{"e":"depthUpdate","E":1787650963414,"s":"BTCUSDT","U":99118681514,"u":99118681530,"b":[["79855.11000000","0.00000000"],["79849.12000000","0.00000000"],["71877.90000000","0.00416000"],["71877.00000000","0.00000000"]],"a":[["79865.19000000","0.00007000"],["79876.16000000","0.00000000"],["79881.08000000","0.00000000"],["79893.94000000","0.00400000"],["79898.00000000","0.02800000"],["79933.89000000","0.00400000"],["79937.95000000","0.00000000"],["79965.85000000","0.00400000"],["79969.93000000","0.00000000"],["80085.69000000","0.00400000"],["80089.76000000","0.00000000"]]}}}
{"rx_ns": 13968295162000, "frame": {"stream":"btcusdt@depth@100ms","data":{"e":"depthUpdate","E":1787650963514,"s":"BTCUSDT","U":99118681531,"u":99118681542,"b":[["79849.12000000","0.00007000"],["71877.90000000","0.00432000"],["63891.47000000","0.00031000"]],"a":[["79881.08000000","0.00007000"],["79893.94000000","0.00400000"],["79933.89000000","0.00400000"],["79965.85000000","0.00400000"],["80085.69000000","0.00400000"]]}}}
{"rx_ns": 13968404284600, "frame": {"stream":"btcusdt@depth@100ms","data":{"e":"depthUpdate","E":1787650963614,"s":"BTCUSDT","U":99118681543,"u":99118681560,"b":[["79855.10000000","1.32452000"],["79855.09000000","1.87677000"],["79855.08000000","0.00000000"],["71877.90000000","0.00416000"],["63891.47000000","0.00000000"]],"a":[["79864.34000000","1.21171000"],["79876.40000000","0.08576000"],["79876.59000000","0.12528000"],["79933.89000000","0.00000000"],["79933.96000000","0.00400000"],["79965.85000000","0.00000000"],["79965.92000000","0.00400000"],["80085.69000000","0.00000000"],["80085.76000000","0.00400000"]]}}}
{"rx_ns": 13968491696000, "frame": {"stream":"btcusdt@depth@100ms","data":{"e":"depthUpdate","E":1787650963714,"s":"BTCUSDT","U":99118681561,"u":99118681568,"b":[["79856.92000000","0.02703000"],["71877.90000000","0.00432000"]],"a":[["79864.34000000","1.21779000"],["79873.88000000","0.00047000"],["79965.92000000","0.00000000"],["80085.76000000","0.00000000"]]}}}
{"rx_ns": 13968592868500, "frame": {"stream":"btcusdt@depth@100ms","data":{"e":"depthUpdate","E":1787650963814,"s":"BTCUSDT","U":99118681569,"u":99118681570,"b":[["71877.90000000","0.00416000"]],"a":[["80085.73000000","0.00400000"]]}}}
{"rx_ns": 13968692209200, "frame": {"stream":"btcusdt@depth@100ms","data":{"e":"depthUpdate","E":1787650963914,"s":"BTCUSDT","U":99118681571,"u":99118681573,"b":[["71877.90000000","0.00432000"]],"a":[]}}}
{"rx_ns": 13968792259200, "frame": {"stream":"btcusdt@depth20","data":{"lastUpdateId":99118681579,"bids":[["79864.33000000","2.13846000"],["79864.32000000","0.00076000"],["79864.31000000","0.00013000"],["79863.06000000","0.00007000"],["79863.05000000","0.13872000"],["79862.90000000","0.00007000"],["79862.75000000","0.00400000"],["79862.45000000","0.00856000"],["79862.10000000","0.00007000"],["79861.79000000","0.00007000"],["79861.78000000","0.60866000"],["79861.77000000","0.36906000"],["79861.69000000","0.00007000"],["79861.68000000","0.05260000"],["79861.67000000","0.00007000"],["79861.66000000","0.31340000"],["79861.65000000","0.22677000"],["79861.32000000","0.00014000"],["79861.30000000","0.00007000"],["79861.29000000","0.08007000"]],"asks":[["79864.34000000","1.21779000"],["79864.35000000","0.00090000"],["79864.36000000","0.00013000"],["79864.42000000","0.00007000"],["79864.43000000","0.12228000"],["79864.59000000","0.00007000"],["79864.95000000","0.00007000"],["79864.96000000","0.06159000"],["79865.19000000","0.00007000"],["79865.29000000","0.00007000"],["79865.56000000","0.00007000"],["79865.57000000","0.11618000"],["79865.58000000","0.06152000"],["79865.62000000","0.01761000"],["79865.99000000","0.00007000"],["79866.09000000","0.00007000"],["79866.19000000","0.00007000"],["79866.20000000","0.06152000"],["79866.71000000","0.00007000"],["79866.78000000","0.00007000"]]}}}
{"rx_ns": 13968792329100, "frame": {"stream":"btcusdt@depth@100ms","data":{"e":"depthUpdate","E":1787650964014,"s":"BTCUSDT","U":99118681574,"u":99118681579,"b":[["71877.90000000","0.00416000"],["63891.47000000","0.00031000"]],"a":[["79965.89000000","0.00000000"]]}}}
{"rx_ns": 13968892119300, "frame": {"stream":"btcusdt@depth@100ms","data":{"e":"depthUpdate","E":1787650964114,"s":"BTCUSDT","U":99118681580,"u":99118681658,"b":[["79864.33000000","2.15660000"],["79864.32000000","0.00034000"],["79861.65000000","0.22691000"],["79861.30000000","0.00007000"],["79861.05000000","0.00007000"],["79860.44000000","0.00007000"],["79807.23000000","0.79339000"],["78666.36000000","0.00030000"],["71877.90000000","0.00400000"]],"a":[["79864.34000000","0.82945000"],["79864.35000000","0.00069000"],["79864.42000000","0.00000000"],["79864.43000000","0.00014000"],["79864.95000000","0.00000000"],["79864.96000000","0.00021000"],["79865.57000000","0.06310000"],["79865.58000000","0.00014000"],["79865.61000000","0.00007000"],["79866.19000000","0.00000000"],["79866.20000000","0.00014000"],["79866.89000000","0.00007000"],["79867.17000000","0.00063000"],["79867.96000000","0.00007000"],["79867.99000000","0.00007000"],["79868.17000000","0.00007000"],["79871.33000000","0.00000000"],["79873.59000000","0.00400000"],["79876.38000000","0.00000000"],["79876.59000000","0.00000000"],["81062.31000000","0.00030000"]]}}}
{"rx_ns": 13968993127100, "frame": {"stream":"btcusdt@depth@100ms","data":{"e":"depthUpdate","E":1787650964215,"s":"BTCUSDT","U":99118681659,"u":99118681703,"b":[["79827.75000000","0.00400000"],["79827.66000000","0.00000000"],["71877.90000000","0.00416000"],["63891.47000000","0.00000000"],["63891.46000000","0.00000000"]],"a":[["79864.34000000","1.01407000"],["79864.43000000","0.00000000"],["79864.96000000","0.00007000"],["79865.29000000","0.00000000"],["79865.57000000","0.06310000"],["79865.58000000","0.00000000"],["79865.62000000","0.01754000"],["79866.20000000","0.00000000"],["79867.27000000","0.04800000"],["79867.44000000","0.06152000"],["79867.97000000","0.06152000"],["79873.61000000","0.00048000"],["79876.57000000","0.12528000"],["79965.89000000","0.00400000"]]}}}
{"rx_ns": 13969093569500, "frame": {"stream":"btcusdt@depth@100ms","data":{"e":"depthUpdate","E":1787650964314,"s":"BTCUSDT","U":99118681704,"u":99118681715,"b":[["79864.33000000","2.15660000"],["79864.32000000","0.00034000"],["71877.90000000","0.00416000"],["63891.00000000","0.00000000"]],"a":[["79876.57000000","0.00000000"],["79965.89000000","0.00000000"]]}}}
{"rx_ns": 13969191952700, "frame": {"stream":"btcusdt@depth@100ms","data":{"e":"depthUpdate","E":1787650964414,"s":"BTCUSDT","U":99118681716,"u":99118681748,"b":[["79864.33000000","2.15674000"],["79864.32000000","0.00048000"],["79861.30000000","0.00007000"],["79861.05000000","0.00007000"],["79860.44000000","0.00007000"],["71877.90000000","0.00416000"]],"a":[["79864.34000000","1.01468000"],["79865.57000000","0.11648000"],["79865.62000000","0.01761000"],["79866.00000000","0.00007000"],["79866.01000000","0.20581000"],["79867.96000000","0.00007000"],["79867.99000000","0.00000000"],["79868.17000000","0.00000000"],["79868.39000000","0.00007000"],["79873.61000000","0.00000000"],["79893.94000000","0.00000000"],["79933.96000000","0.00000000"],["79965.92000000","0.00000000"],["79986.98000000","0.00000000"],["80085.73000000","0.00000000"]]}}}
{"rx_ns": 13969292458300, "frame": {"stream":"btcusdt@depth@100ms","data":{"e":"depthUpdate","E":1787650964514,"s":"BTCUSDT","U":99118681749,"u":99118681765,"b":[["79849.12000000","0.00007000"],["71877.90000000","0.00424000"],["71877.00000000","0.00000000"],["63891.47000000","0.00031000"]],"a":[["79864.34000000","0.99476000"],["79865.62000000","0.01761000"],["79881.08000000","0.00007000"],["79992.37000000","0.01961000"],["80000.38000000","0.00000000"]]}}}
{"rx_ns": 13969392157900, "frame": {"stream":"btcusdt@depth@100ms","data":{"e":"depthUpdate","E":1787650964614,"s":"BTCUSDT","U":99118681766,"u":99118681774,"b":[["79864.33000000","2.15992000"],["71877.90000000","0.00440000"],["63891.47000000","0.00000000"]],"a":[["79876.66000000","0.12528000"],["80026.97000000","0.00000000"],["80089.77000000","0.00400000"]]}}}
{"rx_ns": 13969494470700, "frame": {"stream":"btcusdt@depth@100ms","data":{"e":"depthUpdate","E":1787650964714,"s":"BTCUSDT","U":99118681775,"u":99118681823,"b":[["79864.33000000","2.16034000"],["79864.32000000","0.00076000"],["71877.90000000","0.00424000"]],"a":[["79864.34000000","1.08107000"],["79865.03000000","0.00007000"],["79865.04000000","0.03652000"],["79865.55000000","0.00007000"],["79865.56000000","0.06145000"],["79865.57000000","0.07593000"],["79865.62000000","0.01761000"],["79865.99000000","0.00014000"],["79866.00000000","0.06138000"],["79866.01000000","0.00000000"],["79866.09000000","0.00000000"],["79866.89000000","0.00007000"],["79867.26000000","0.00007000"],["79867.43000000","0.00007000"],["79867.96000000","0.00000000"],["79868.39000000","0.00000000"],["79871.87000000","0.01200000"],["79883.30000000","0.00000000"],["79883.74000000","0.19019000"],["79992.37000000","0.00000000"],["80260.59000000","0.00018000"]]}}}
{"rx_ns": 13969600697500, "frame": {"stream":"btcusdt@depth@100ms","data":{"e":"depthUpdate","E":1787650964814,"s":"BTCUSDT","U":99118681824,"u":99118682120,"b":[["79864.33000000","2.15822000"],["79864.32000000","0.00027000"],["79863.07000000","0.00007000"],["79863.05000000","0.13872000"],["79862.48000000","0.00000000"],["79862.47000000","0.00000000"],["79862.45000000","0.00863000"],["79862.42000000","0.00000000"],["79861.86000000","0.00000000"],["79861.85000000","0.00007000"],["79861.80000000","0.00000000"],["79861.79000000","0.00007000"],["79861.78000000","1.06880000"],["79861.70000000","0.00007000"],["79861.69000000","1.87677000"],["79861.67000000","0.00007000"],["79861.66000000","0.31333000"],["79861.30000000","0.00000000"],["79861.10000000","0.00400000"],["79861.05000000","0.00007000"],["79860.44000000","0.00007000"],["79860.43000000","0.36656000"],["79860.40000000","0.00000000"],["79859.90000000","0.00000000"],["79859.25000000","0.00007000"],["79859.24000000","0.49732000"],["79859.22000000","0.00000000"],["79859.21000000","0.33247000"],["79858.65000000","0.00000000"],["79857.13000000","0.00000000"],["79856.01000000","0.01826000"],["79855.13000000","0.00000000"],["79855.12000000","0.00000000"],["79855.11000000","0.36586000"],["79781.46000000","0.00000000"],["79710.60000000","0.00000000"],["71877.90000000","0.00432000"],["71877.89000000","0.00008000"]],"a":[["79864.34000000","0.79627000"],["79864.35000000","0.00069000"],["79865.03000000","0.00000000"],["79865.04000000","0.00021000"],["79865.55000000","0.00000000"],["79865.56000000","0.00014000"],["79865.57000000","0.00014000"],["79865.62000000","0.01768000"],["79865.99000000","0.00007000"],["79866.00000000","0.00014000"],["79866.19000000","0.00007000"],["79866.20000000","0.06138000"],["79866.81000000","0.00007000"],["79866.82000000","0.06152000"],["79867.27000000","0.04793000"],["79867.43000000","0.00007000"],["79867.44000000","0.06145000"],["79867.97000000","0.00000000"],["79867.98000000","0.00007000"],["79867.99000000","0.06145000"],["79868.17000000","0.00007000"],["79868.18000000","0.02086000"],["79868.40000000","0.00000000"],["79868.41000000","0.00000000"],["79868.42000000","0.00007000"],["79868.68000000","0.06145000"],["79869.06000000","0.00007000"],["79869.30000000","0.06145000"],["79869.92000000","0.06138000"],["79869.99000000","0.00000000"],["79870.00000000","0.02400000"],["79870.54000000","0.06138000"],["79871.11000000","0.00000000"],["79871.16000000","0.06138000"],["79871.70000000","0.00000000"],["79871.78000000","0.06138000"],["79871.86000000","0.01200000"],["79871.87000000","0.00000000"],["79871.88000000","0.00000000"],["79871.91000000","0.00000000"],["79871.92000000","0.00000000"],["79871.99000000","0.00000000"],["79872.40000000","0.06138000"],["79872.92000000","0.00000000"],["79873.02000000","0.06138000"],["79873.59000000","0.00000000"],["79873.64000000","0.06138000"],["79873.96000000","0.99893000"],["79873.97000000","1.87677000"],["79873.98000000","0.00000000"],["79873.99000000","0.00000000"],["79874.00000000","0.02400000"],["79874.40000000","0.00017000"],["79874.43000000","0.00000000"],["79875.17000000","0.00000000"],["79875.18000000","0.00000000"],["79875.73000000","0.00000000"],["79875.83000000","0.00400000"],["79875.92000000","0.00000000"],["79875.93000000","1.04939000"],["79875.94000000","0.90444000"],["79875.95000000","0.00000000"],["79876.66000000","0.00000000"],["79876.90000000","0.00000000"],["79877.21000000","0.00400000"],["79877.99000000","0.00626000"],["79879.01000000","1.87677000"],["79879.02000000","0.00000000"],["79886.57000000","0.00000000"],["79890.26000000","0.00000000"],["79890.46000000","0.03000000"],["79891.16000000","0.00000000"],["79892.26000000","0.00000000"],["79894.26000000","0.12000000"],["79897.25000000","0.00000000"],["79898.01000000","0.00400000"],["79899.98000000","0.82415000"],["79900.12000000","0.33800000"],["79902.88000000","0.00000000"],["79903.20000000","0.00000000"],["79907.76000000","0.00007000"],["79907.81000000","1.02439000"],["79907.82000000","0.00000000"],["79911.79000000","0.00000000"],["79940.27000000","1.23874000"],["79960.31000000","0.00000000"],["80014.53000000","0.00000000"],["80023.19000000","0.00000000"],["80060.17000000","0.01961000"]]}}}
{"rx_ns": 13969691932500, "frame": {"stream":"btcusdt@depth@100ms","data":{"e":"depthUpdate","E":1787650964914,"s":"BTCUSDT","U":99118682121,"u":99118682198,"b":[["79864.33000000","2.15763000"],["79861.79000000","0.01207000"],["79861.77000000","0.36906000"],["79860.44000000","0.00007000"],["79859.25000000","0.00007000"],["79859.24000000","0.49732000"],["79856.01000000","0.00626000"],["71877.90000000","0.00416000"]],"a":[["79864.34000000","0.80241000"],["79864.96000000","0.00000000"],["79865.04000000","0.00000000"],["79865.56000000","0.00000000"],["79865.57000000","0.00000000"],["79865.62000000","0.01761000"],["79866.00000000","0.00000000"],["79866.20000000","0.06152000"],["79866.88000000","0.00007000"],["79867.44000000","0.06159000"],["79867.99000000","0.06159000"],["79868.00000000","0.02428000"],["79868.16000000","0.00007000"],["79868.17000000","0.12462000"],["79869.06000000","0.00014000"],["79870.00000000","0.02407000"],["79871.86000000","0.00000000"],["79873.95000000","0.01200000"],["79873.96000000","0.95566000"],["79874.90000000","0.00048000"],["79876.75000000","0.00000000"],["79892.31000000","0.02480000"],["79905.37000000","1.20229000"],["79907.76000000","0.00000000"]]}}}
{"rx_ns": 13969796295400, "frame": {"stream":"btcusdt@depth20","data":{"lastUpdateId":99118682260,"bids":[["79864.33000000","2.15763000"],["79864.32000000","0.00027000"],["79864.31000000","0.00013000"],["79863.07000000","0.00007000"],["79863.06000000","0.00007000"],["79863.05000000","0.13872000"],["79862.90000000","0.00007000"],["79862.75000000","0.00400000"],["79862.45000000","0.00863000"],["79862.10000000","0.00007000"],["79861.85000000","0.00007000"],["79861.79000000","0.01221000"],["79861.78000000","0.60866000"],["79861.77000000","0.36906000"],["79861.69000000","0.00007000"],["79861.68000000","0.05260000"],["79861.67000000","0.00007000"],["79861.66000000","0.31340000"],["79861.65000000","0.22677000"],["79861.32000000","0.00014000"]],"asks":[["79864.34000000","1.00409000"],["79864.35000000","0.00069000"],["79864.36000000","0.00013000"],["79864.59000000","0.00007000"],["79865.19000000","0.00007000"],["79865.61000000","0.00007000"],["79865.62000000","0.01761000"],["79865.99000000","0.00007000"],["79866.19000000","0.00007000"],["79866.20000000","0.06159000"],["79866.71000000","0.00007000"],["79866.78000000","0.00007000"],["79866.80000000","0.00007000"],["79866.81000000","0.12204000"],["79866.82000000","0.06152000"],["79866.88000000","0.00007000"],["79866.89000000","0.00007000"],["79866.90000000","0.02100000"],["79866.93000000","0.00007000"],["79866.94000000","0.21559000"]]}}}
{"rx_ns": 13969796386600, "frame": {"stream":"btcusdt@depth@100ms","data":{"e":"depthUpdate","E":1787650965014,"s":"BTCUSDT","U":99118682199,"u":99118682260,"b":[["79862.45000000","0.00863000"],["79861.79000000","0.01221000"],["79861.78000000","0.60866000"],["79861.70000000","0.00000000"],["79861.69000000","0.00007000"],["79861.66000000","0.31340000"],["79861.65000000","0.22677000"],["79861.30000000","0.00007000"],["79861.05000000","0.00007000"],["79860.44000000","0.00007000"],["79859.25000000","0.00000000"],["79859.24000000","0.49725000"],["71877.90000000","0.00432000"],["63891.47000000","0.00031000"]],"a":[["79864.34000000","1.00409000"],["79866.20000000","0.06159000"],["79866.80000000","0.00007000"],["79866.81000000","0.12204000"],["79866.90000000","0.02100000"],["79866.93000000","0.00007000"],["79866.94000000","0.21559000"],["79867.99000000","0.06152000"],["79868.00000000","0.02428000"],["79868.16000000","0.00000000"],["79868.17000000","0.11424000"],["79873.65000000","0.00000000"],["79876.70000000","0.00000000"],["79876.77000000","0.00000000"],["79898.78000000","0.49768000"],["79903.69000000","0.10000000"],["79909.58000000","0.00000000"],["79922.75000000","1.01890000"],["79969.92000000","0.00400000"]]}}}
{"rx_ns": 13969892033500, "frame": {"stream":"btcusdt@depth@100ms","data":{"e":"depthUpdate","E":1787650965114,"s":"BTCUSDT","U":99118682261,"u":99118682334,"b":[["79864.33000000","2.15777000"],["79864.32000000","0.00034000"],["79863.07000000","0.00000000"],["79861.79000000","0.00021000"],["79861.77000000","0.36906000"],["79861.70000000","0.00009000"],["79861.30000000","0.00007000"],["79861.10000000","0.00000000"],["79861.05000000","0.00007000"],["79860.44000000","0.00007000"],["79859.55000000","0.00400000"],["79855.12000000","0.01200000"],["79845.96000000","0.00000000"],["79843.83000000","0.02499000"],["79780.81000000","0.62589000"],["78666.36000000","0.00030000"],["71877.90000000","0.00416000"],["71877.89000000","0.00000000"],["71877.00000000","0.00010000"]],"a":[["79864.34000000","0.99254000"],["79864.35000000","0.00076000"],["79864.52000000","0.00007000"],["79864.53000000","0.02475000"],["79865.19000000","0.00014000"],["79865.58000000","0.06138000"],["79866.20000000","0.06159000"],["79866.81000000","0.12218000"],["79866.90000000","0.02107000"],["79866.93000000","0.00000000"],["79866.94000000","0.00014000"],["79867.07000000","0.00007000"],["79867.08000000","0.42271000"],["79867.26000000","0.00007000"],["79867.43000000","0.00007000"],["79867.98000000","0.00000000"],["79867.99000000","0.06138000"],["79868.00000000","0.02414000"],["79873.15000000","0.00400000"],["79876.77000000","0.12528000"],["79877.21000000","0.00000000"],["80093.29000000","0.00000000"],["81062.31000000","0.00030000"]]}}}
{"rx_ns": 13969992834200, "frame": {"stream":"btcusdt@depth@100ms","data":{"e":"depthUpdate","E":1787650965214,"s":"BTCUSDT","U":99118682335,"u":99118682432,"b":[["79864.33000000","2.15783000"],["79864.32000000","0.00048000"],["79863.06000000","0.00000000"],["79863.05000000","0.00975000"],["79862.45000000","0.00863000"],["79861.79000000","0.00007000"],["79861.65000000","0.22691000"],["79861.30000000","0.00007000"],["79861.05000000","0.00007000"],["79860.44000000","0.00007000"],["79859.55000000","0.00000000"],["79859.25000000","0.00007000"],["79858.37000000","0.00000000"],["79857.21000000","0.00400000"],["79855.11000000","0.00000000"],["79644.19000000","0.00771000"],["79638.43000000","0.00000000"],["71877.90000000","0.00432000"],["71877.00000000","0.00000000"],["63891.47000000","0.00000000"],["63891.46000000","0.00000000"]],"a":[["79864.34000000","0.99795000"],["79864.35000000","0.00076000"],["79864.53000000","0.02496000"],["79865.57000000","0.00007000"],["79865.58000000","0.06152000"],["79866.09000000","0.00007000"],["79866.81000000","0.16852000"],["79866.89000000","0.00007000"],["79866.90000000","0.02100000"],["79866.94000000","0.00000000"],["79867.07000000","0.00007000"],["79867.08000000","0.42285000"],["79867.26000000","0.00007000"],["79867.27000000","0.04779000"],["79867.43000000","0.00000000"],["79867.44000000","0.06145000"],["79870.31000000","0.00016000"],["79872.61000000","0.00000000"],["79874.40000000","0.00000000"],["79874.90000000","0.00000000"],["79876.77000000","0.00000000"],["79885.58000000","0.33806000"],["79901.70000000","0.00000000"],["79907.62000000","1.23924000"],["79937.96000000","0.00400000"],["79940.27000000","0.00000000"],["79967.10000000","0.00000000"],["79975.10000000","0.02804000"],["80083.24000000","0.01961000"]]}}}
{"rx_ns": 13970091693500, "frame": {"stream":"btcusdt@depth@100ms","data":{"e":"depthUpdate","E":1787650965314,"s":"BTCUSDT","U":99118682433,"u":99118682476,"b":[["79864.33000000","2.15804000"],["79864.32000000","0.00069000"],["71877.90000000","0.00416000"],["71877.00000000","0.00010000"],["63891.46000000","0.00000000"],["63891.00000000","0.00000000"]],"a":[["79864.34000000","0.99616000"],["79864.35000000","0.00083000"],["79864.53000000","0.02503000"],["79864.95000000","0.00007000"],["79864.96000000","0.06138000"],["79866.81000000","0.16852000"],["79866.89000000","0.00000000"],["79867.07000000","0.00007000"],["79867.26000000","0.00007000"],["79937.96000000","0.00000000"]]}}}
{"rx_ns": 13970192516000, "frame": {"stream":"btcusdt@depth@100ms","data":{"e":"depthUpdate","E":1787650965414,"s":"BTCUSDT","U":99118682477,"u":99118682513,"b":[["79864.33000000","2.15804000"],["79864.32000000","0.00069000"],["79795.03000000","0.02087000"],["71877.90000000","0.00432000"],["71877.00000000","0.00000000"]],"a":[["79864.34000000","0.99616000"],["79864.53000000","0.02503000"],["79864.96000000","0.06152000"],["79866.88000000","0.00000000"],["79867.08000000","0.42271000"],["79870.31000000","0.00000000"],["79871.66000000","0.00017000"],["79898.01000000","0.00000000"],["79903.00000000","0.70000000"],["79906.00000000","0.02400000"],["79937.97000000","0.00000000"],["79969.92000000","0.00000000"],["79992.11000000","0.00160000"],["80089.77000000","0.00000000"]]}}}
{"rx_ns": 13970291788400, "frame": {"stream":"btcusdt@depth@100ms","data":{"e":"depthUpdate","E":1787650965514,"s":"BTCUSDT","U":99118682514,"u":99118682526,"b":[["79864.33000000","2.15818000"],["79864.32000000","0.00076000"],["79849.12000000","0.00007000"],["79795.03000000","0.00000000"],["71877.90000000","0.00416000"],["63891.47000000","0.00031000"]],"a":[["79881.08000000","0.00007000"]]}}}
{"rx_ns": 13970399004500, "frame": {"stream":"btcusdt@depth@100ms","data":{"e":"depthUpdate","E":1787650965614,"s":"BTCUSDT","U":99118682527,"u":99118682559,"b":[["79864.33000000","2.15776000"],["79864.32000000","0.00041000"],["79795.03000000","0.02087000"],["79644.19000000","0.00000000"],["79641.60000000","0.00771000"],["71877.90000000","0.00416000"],["71877.00000000","0.00000000"],["63891.47000000","0.00000000"]],"a":[["79867.27000000","0.04772000"],["79867.44000000","0.00000000"],["79867.99000000","0.00000000"],["79868.68000000","0.00007000"],["79891.37000000","0.04613000"],["79902.97000000","0.00000000"],["79965.93000000","0.00400000"],["80032.10000000","0.00160000"]]}}}
{"rx_ns": 13970492692500, "frame": {"stream":"btcusdt@depth@100ms","data":{"e":"depthUpdate","E":1787650965714,"s":"BTCUSDT","U":99118682560,"u":99118682564,"b":[["79795.03000000","0.00000000"],["71877.90000000","0.00424000"],["71877.00000000","0.00000000"]],"a":[["79864.34000000","0.99603000"]]}}}
{"rx_ns": 13970591778100, "frame": {"stream":"btcusdt@depth@100ms","data":{"e":"depthUpdate","E":1787650965814,"s":"BTCUSDT","U":99118682565,"u":99118682578,"b":[["79864.33000000","2.15797000"],["79864.32000000","0.00062000"],["71877.90000000","0.00440000"],["71877.00000000","0.00000000"]],"a":[["79864.34000000","0.99110000"],["79924.05000000","0.00200000"],["80085.77000000","0.00400000"]]}}}
{"rx_ns": 13970691994200, "frame": {"stream":"btcusdt@depth@100ms","data":{"e":"depthUpdate","E":1787650965914,"s":"BTCUSDT","U":99118682579,"u":99118682586,"b":[["79864.33000000","2.05672000"],["71877.90000000","0.00448000"],["71877.89000000","0.00008000"],["71877.00000000","0.00010000"]],"a":[["79876.67000000","0.12528000"]]}}}
{"rx_ns": 13970797012300, "frame": {"stream":"btcusdt@depth20","data":{"lastUpdateId":99118682598,"bids":[["79864.33000000","2.05693000"],["79864.32000000","0.00076000"],["79864.31000000","0.00013000"],["79863.05000000","0.00975000"],["79862.90000000","0.00007000"],["79862.75000000","0.00400000"],["79862.45000000","0.00863000"],["79862.10000000","0.00007000"],["79861.85000000","0.00007000"],["79861.79000000","0.00007000"],["79861.78000000","0.60866000"],["79861.77000000","0.36906000"],["79861.70000000","0.00009000"],["79861.69000000","0.00007000"],["79861.68000000","0.05260000"],["79861.67000000","0.00007000"],["79861.66000000","0.31340000"],["79861.65000000","0.22691000"],["79861.32000000","0.00014000"],["79861.30000000","0.00007000"]],"asks":[["79864.34000000","0.99110000"],["79864.35000000","0.00083000"],["79864.36000000","0.00013000"],["79864.52000000","0.00007000"],["79864.53000000","0.02503000"],["79864.59000000","0.00007000"],["79864.95000000","0.00007000"],["79864.96000000","0.06152000"],["79865.19000000","0.00014000"],["79865.57000000","0.00007000"],["79865.58000000","0.06152000"],["79865.61000000","0.00007000"],["79865.62000000","0.01761000"],["79865.99000000","0.00007000"],["79866.09000000","0.00007000"],["79866.19000000","0.00007000"],["79866.20000000","0.06159000"],["79866.71000000","0.00007000"],["79866.78000000","0.00007000"],["79866.80000000","0.00007000"]]}}}
{"rx_ns": 13970797172200, "frame": {"stream":"btcusdt@depth@100ms","data":{"e":"depthUpdate","E":1787650966014,"s":"BTCUSDT","U":99118682587,"u":99118682598,"b":[["79864.33000000","2.05693000"],["79864.32000000","0.00076000"],["71877.90000000","0.00416000"],["71877.00000000","0.00010000"],["63891.47000000","0.00031000"]],"a":[["79876.67000000","0.00000000"],["79933.97000000","0.00400000"]]}}}
{"rx_ns": 13970891654700, "frame": {"stream":"btcusdt@depth@100ms","data":{"e":"depthUpdate","E":1787650966114,"s":"BTCUSDT","U":99118682599,"u":99118682605,"b":[["79864.33000000","2.15686000"],["79719.52000000","0.00000000"],["71877.90000000","0.00448000"],["71877.00000000","0.00000000"]],"a":[["79904.47000000","1.68224000"]]}}}
{"rx_ns": 13971000633800, "kind": "control", "ctl": {"op": "ping", "recv_ns": 13970915582300, "pong_ns": 13970915704900, "payload_len": 13, "payload_b64": "MTc4NzY1MDk2NjEzOA=="}, "frame": null}
{"rx_ns": 13971000633800, "frame": {"stream":"btcusdt@depth@100ms","data":{"e":"depthUpdate","E":1787650966214,"s":"BTCUSDT","U":99118682606,"u":99118682624,"b":[["79864.33000000","2.15644000"],["79864.32000000","0.00041000"],["71877.90000000","0.00432000"],["63891.47000000","0.00000000"],["63891.46000000","0.00000000"]],"a":[["79894.02000000","0.00400000"],["79933.97000000","0.00000000"]]}}}
{"rx_ns": 13971091353100, "frame": {"stream":"btcusdt@depth@100ms","data":{"e":"depthUpdate","E":1787650966314,"s":"BTCUSDT","U":99118682625,"u":99118682631,"b":[["79795.03000000","0.02087000"],["71877.90000000","0.00432000"],["63891.46000000","0.00000000"],["63891.00000000","0.00000000"]],"a":[]}}}
{"rx_ns": 13971192287100, "frame": {"stream":"btcusdt@depth@100ms","data":{"e":"depthUpdate","E":1787650966414,"s":"BTCUSDT","U":99118682632,"u":99118682642,"b":[["79864.33000000","2.15644000"],["79864.32000000","0.00034000"],["79795.03000000","0.00000000"],["71877.90000000","0.00432000"]],"a":[["79864.34000000","0.58047000"],["79864.53000000","0.00028000"],["79894.02000000","0.00000000"],["79933.97000000","0.00400000"]]}}}
{"rx_ns": 13971294939800, "frame": {"stream":"btcusdt@depth@100ms","data":{"e":"depthUpdate","E":1787650966514,"s":"BTCUSDT","U":99118682643,"u":99118682710,"b":[["79864.33000000","2.15658000"],["79864.32000000","0.00041000"],["79863.54000000","0.00007000"],["79863.53000000","0.03224000"],["79861.30000000","0.00007000"],["79861.05000000","0.00007000"],["79860.44000000","0.00007000"],["79859.25000000","0.00000000"],["79849.12000000","0.00007000"],["79441.38000000","0.00000000"],["71877.90000000","0.00448000"],["63891.47000000","0.00031000"]],"a":[["79864.34000000","0.57999000"],["79864.52000000","0.00000000"],["79864.53000000","0.00014000"],["79867.07000000","0.00007000"],["79867.08000000","0.42285000"],["79867.26000000","0.00007000"],["79868.16000000","0.00007000"],["79873.15000000","0.00000000"],["79873.80000000","0.00048000"],["79874.25000000","0.00400000"],["79881.08000000","0.00007000"]]}}}
{"rx_ns": 13971392717000, "frame": {"stream":"btcusdt@depth@100ms","data":{"e":"depthUpdate","E":1787650966615,"s":"BTCUSDT","U":99118682711,"u":99118682731,"b":[["79864.33000000","2.15124000"],["78666.36000000","0.00030000"],["71877.90000000","0.00432000"],["71877.89000000","0.00000000"],["63891.47000000","0.00000000"],["63891.00000000","0.00000000"]],"a":[["79864.34000000","0.77139000"],["79867.75000000","0.21326000"],["79893.96000000","0.00400000"],["79902.00000000","0.72400000"],["79903.00000000","0.00000000"],["79933.97000000","0.00000000"],["81062.31000000","0.00030000"]]}}}
{"rx_ns": 13971499642300, "frame": {"stream":"btcusdt@depth@100ms","data":{"e":"depthUpdate","E":1787650966714,"s":"BTCUSDT","U":99118682732,"u":99118682764,"b":[["79861.30000000","0.00007000"],["79861.05000000","0.00007000"],["79860.44000000","0.00007000"],["79854.14000000","1.20229000"],["79852.04000000","0.00000000"],["79795.03000000","0.02087000"],["71877.90000000","0.00448000"],["71877.00000000","0.00020000"]],"a":[["79864.34000000","0.77146000"],["79867.07000000","0.00007000"],["79867.26000000","0.00007000"],["79867.27000000","0.04779000"],["79867.74000000","0.00007000"],["79868.16000000","0.00000000"]]}}}
{"rx_ns": 13971597701400, "frame": {"stream":"btcusdt@depth@100ms","data":{"e":"depthUpdate","E":1787650966814,"s":"BTCUSDT","U":99118682765,"u":99118682786,"b":[["79861.30000000","0.00007000"],["79861.05000000","0.00007000"],["79860.44000000","0.00007000"],["71877.90000000","0.00432000"],["71877.00000000","0.00000000"]],"a":[["79864.34000000","0.77146000"],["79864.35000000","0.00090000"],["79866.20000000","0.06166000"],["79866.74000000","0.00007000"],["79866.75000000","0.02937000"],["79867.26000000","0.00007000"],["79867.27000000","0.04772000"],["79867.74000000","0.00000000"],["79867.75000000","0.00000000"],["79933.96000000","0.00400000"]]}}}
{"rx_ns": 13971692490000, "frame": {"stream":"btcusdt@depth@100ms","data":{"e":"depthUpdate","E":1787650966914,"s":"BTCUSDT","U":99118682787,"u":99118682803,"b":[["79795.03000000","0.00000000"],["73480.61000000","0.00014000"],["71877.90000000","0.00448000"],["62400.00000000","1.30543000"]],"a":[["79865.29000000","0.00007000"],["79866.20000000","0.06166000"],["79866.75000000","0.02951000"],["79867.08000000","0.42271000"],["79933.96000000","0.00000000"],["79960.31000000","1.95361000"]]}}}
{"rx_ns": 13971794213300, "frame": {"stream":"btcusdt@depth20","data":{"lastUpdateId":99118682819,"bids":[["79864.33000000","1.72842000"],["79864.32000000","0.00041000"],["79864.31000000","0.00013000"],["79863.54000000","0.00007000"],["79863.53000000","0.03224000"],["79863.05000000","0.00975000"],["79862.90000000","0.00007000"],["79862.75000000","0.00400000"],["79862.45000000","0.00863000"],["79862.10000000","0.00007000"],["79861.85000000","0.00007000"],["79861.79000000","0.00007000"],["79861.78000000","0.60866000"],["79861.77000000","0.36906000"],["79861.70000000","0.00009000"],["79861.69000000","0.00007000"],["79861.68000000","0.05260000"],["79861.67000000","0.00007000"],["79861.66000000","0.31340000"],["79861.65000000","0.22691000"]],"asks":[["79864.34000000","1.07868000"],["79864.35000000","0.00090000"],["79864.36000000","0.00013000"],["79864.53000000","0.00014000"],["79864.59000000","0.00007000"],["79864.95000000","0.00007000"],["79864.96000000","0.06152000"],["79865.19000000","0.00014000"],["79865.29000000","0.00007000"],["79865.57000000","0.00007000"],["79865.58000000","0.06152000"],["79865.61000000","0.00007000"],["79865.62000000","0.01761000"],["79865.69000000","0.16237000"],["79865.99000000","0.00007000"],["79866.09000000","0.00007000"],["79866.19000000","0.00007000"],["79866.20000000","0.06166000"],["79866.71000000","0.00007000"],["79866.74000000","0.00007000"]]}}}
{"rx_ns": 13971794361000, "frame": {"stream":"btcusdt@depth@100ms","data":{"e":"depthUpdate","E":1787650967014,"s":"BTCUSDT","U":99118682804,"u":99118682819,"b":[["79864.33000000","1.72842000"],["79860.43000000","0.26197000"],["79741.50000000","0.20250000"],["71877.90000000","0.00432000"],["63891.47000000","0.00031000"]],"a":[["79864.34000000","1.07868000"],["79865.69000000","0.16237000"],["79866.75000000","0.00014000"],["79867.07000000","0.06145000"],["79933.98000000","0.00407000"],["79999.01000000","0.01307000"]]}}}
{"rx_ns": 13971891929200, "frame": {"stream":"btcusdt@depth@100ms","data":{"e":"depthUpdate","E":1787650967114,"s":"BTCUSDT","U":99118682820,"u":99118682868,"b":[["79864.33000000","1.72863000"],["79864.32000000","0.00055000"],["79861.30000000","0.00007000"],["79861.05000000","0.00007000"],["79860.44000000","0.00007000"],["71877.90000000","0.00432000"]],"a":[["79864.34000000","1.07903000"],["79864.35000000","0.00083000"],["79865.62000000","0.01768000"],["79865.68000000","0.00007000"],["79865.69000000","0.16251000"],["79866.20000000","0.06159000"],["79866.74000000","0.00000000"],["79866.75000000","0.00000000"],["79866.81000000","0.16852000"],["79866.90000000","0.02107000"],["79867.06000000","0.00007000"],["79867.07000000","0.06145000"],["79867.26000000","0.00000000"],["79873.80000000","0.00000000"],["79933.98000000","0.00007000"]]}}}
{"rx_ns": 13971992415300, "frame": {"stream":"btcusdt@depth@100ms","data":{"e":"depthUpdate","E":1787650967214,"s":"BTCUSDT","U":99118682869,"u":99118682896,"b":[["79864.33000000","1.72877000"],["79864.32000000","0.00062000"],["79863.98000000","0.00007000"],["79863.97000000","0.42271000"],["79861.69000000","0.00000000"],["79861.30000000","0.00000000"],["79861.05000000","0.00007000"],["79860.44000000","0.00007000"],["79859.25000000","0.00007000"],["79709.72000000","0.00202000"],["71877.90000000","0.00432000"],["63891.47000000","0.00000000"],["63891.46000000","0.00000000"]],"a":[["79866.81000000","0.16852000"],["79867.06000000","0.00007000"],["79867.07000000","0.06145000"],["79933.95000000","0.00400000"],["80022.44000000","0.00202000"]]}}}
{"rx_ns": 13972092606600, "frame": {"stream":"btcusdt@depth@100ms","data":{"e":"depthUpdate","E":1787650967314,"s":"BTCUSDT","U":99118682897,"u":99118682928,"b":[["79864.33000000","1.72883000"],["79861.65000000","0.22677000"],["79861.05000000","0.00007000"],["79860.44000000","0.00007000"],["79859.25000000","0.00007000"],["71877.90000000","0.00432000"],["63891.46000000","0.00000000"],["63891.00000000","0.00000000"]],"a":[["79864.34000000","1.07923000"],["79864.54000000","0.00007000"],["79864.55000000","0.07163000"],["79865.68000000","0.00000000"],["79865.69000000","0.00014000"],["79866.81000000","0.16852000"],["79867.06000000","0.00007000"],["79867.07000000","0.06145000"],["79933.95000000","0.00000000"]]}}}
{"rx_ns": 13972196322600, "frame": {"stream":"btcusdt@depth@100ms","data":{"e":"depthUpdate","E":1787650967414,"s":"BTCUSDT","U":99118682929,"u":99118682956,"b":[["79864.33000000","1.72859000"],["79863.97000000","0.42285000"],["79795.03000000","0.02087000"],["73480.61000000","0.00000000"],["71877.90000000","0.00448000"]],"a":[["79864.34000000","1.07913000"],["79864.55000000","0.07177000"],["79865.29000000","0.00000000"],["79865.62000000","0.01761000"],["79865.69000000","0.00000000"],["79933.92000000","0.00400000"]]}}}
{"rx_ns": 13972297247900, "frame": {"stream":"btcusdt@depth@100ms","data":{"e":"depthUpdate","E":1787650967514,"s":"BTCUSDT","U":99118682957,"u":99118682967,"b":[["79849.12000000","0.00000000"],["79795.03000000","0.00000000"],["75000.00000000","113.38296000"],["71877.90000000","0.00432000"],["63891.47000000","0.00031000"]],"a":[["79864.34000000","1.12900000"],["79867.15000000","0.00063000"],["79867.17000000","0.00000000"],["79881.08000000","0.00000000"]]}}}
{"rx_ns": 13972409115800, "frame": {"stream":"btcusdt@depth@100ms","data":{"e":"depthUpdate","E":1787650967614,"s":"BTCUSDT","U":99118682968,"u":99118682980,"b":[["79864.33000000","1.72846000"],["79849.12000000","0.00007000"],["78666.36000000","0.00030000"],["71877.90000000","0.00432000"],["71877.89000000","0.00008000"],["63891.47000000","0.00000000"],["63891.00000000","0.00000000"]],"a":[["79881.08000000","0.00007000"],["81062.31000000","0.00030000"]]}}}
{"rx_ns": 13972501087500, "frame": {"stream":"btcusdt@depth@100ms","data":{"e":"depthUpdate","E":1787650967714,"s":"BTCUSDT","U":99118682981,"u":99118683002,"b":[["79864.33000000","1.62846000"],["79864.32000000","0.00062000"],["79689.14000000","0.00000000"],["71877.90000000","0.00432000"]],"a":[["79864.34000000","1.12920000"],["79864.35000000","0.00090000"],["80057.16000000","0.00000000"]]}}}
{"rx_ns": 13972591526200, "frame": {"stream":"btcusdt@depth@100ms","data":{"e":"depthUpdate","E":1787650967814,"s":"BTCUSDT","U":99118683003,"u":99118683040,"b":[["79864.33000000","1.62846000"],["79864.32000000","0.00062000"],["79795.03000000","0.02087000"],["79718.74000000","0.00654000"],["79713.21000000","0.00000000"],["71877.90000000","0.00448000"],["71877.00000000","0.00000000"]],"a":[["79864.34000000","1.13160000"]]}}}
{"rx_ns": 13972701515300, "frame": {"stream":"btcusdt@depth@100ms","data":{"e":"depthUpdate","E":1787650967914,"s":"BTCUSDT","U":99118683041,"u":99118683051,"b":[["79850.25000000","0.99435000"],["79795.03000000","0.02087000"],["79790.34000000","0.00000000"],["79727.55000000","0.00000000"],["79686.66000000","4.59860000"],["71877.90000000","0.00416000"]],"a":[["79927.53000000","0.00218000"],["79975.10000000","0.00000000"],["80056.19000000","4.55669000"]]}}}
{"rx_ns": 13972807799900, "frame": {"stream":"btcusdt@depth20","data":{"lastUpdateId":99118683103,"bids":[["79864.33000000","1.73010000"],["79864.32000000","0.00076000"],["79864.31000000","0.00013000"],["79863.97000000","0.00014000"],["79863.54000000","0.00007000"],["79863.53000000","0.03224000"],["79863.05000000","0.00975000"],["79862.90000000","0.00007000"],["79862.75000000","0.00400000"],["79862.45000000","0.00863000"],["79862.10000000","0.00007000"],["79861.85000000","0.00007000"],["79861.79000000","0.00007000"],["79861.78000000","0.60866000"],["79861.77000000","0.36906000"],["79861.70000000","0.00009000"],["79861.69000000","0.00007000"],["79861.68000000","0.05260000"],["79861.67000000","0.00007000"],["79861.66000000","0.31340000"]],"asks":[["79864.34000000","1.13011000"],["79864.35000000","0.00090000"],["79864.36000000","0.00013000"],["79864.53000000","0.00014000"],["79864.54000000","0.00007000"],["79864.55000000","0.07177000"],["79864.59000000","0.00007000"],["79864.95000000","0.11820000"],["79864.96000000","0.06152000"],["79865.19000000","0.00014000"],["79865.57000000","0.00007000"],["79865.58000000","0.06152000"],["79865.61000000","0.00007000"],["79865.62000000","0.01761000"],["79865.99000000","0.00007000"],["79866.09000000","0.00007000"],["79866.19000000","0.00007000"],["79866.20000000","0.06159000"],["79866.71000000","0.00007000"],["79866.78000000","0.00007000"]]}}}
{"rx_ns": 13972807904500, "frame": {"stream":"btcusdt@depth@100ms","data":{"e":"depthUpdate","E":1787650968014,"s":"BTCUSDT","U":99118683052,"u":99118683103,"b":[["79864.33000000","1.73010000"],["79864.32000000","0.00076000"],["79863.98000000","0.00000000"],["79863.97000000","0.00014000"],["79861.69000000","0.00007000"],["79861.30000000","0.00007000"],["79861.05000000","0.00007000"],["79860.44000000","0.00007000"],["79859.25000000","0.00000000"],["79857.44000000","0.00250000"],["79854.34000000","0.00028000"],["79824.39000000","0.07962000"],["79795.03000000","0.00000000"],["79734.16000000","0.04910000"],["79721.99000000","0.00000000"],["79713.68000000","1.50049000"],["79709.72000000","0.00000000"],["79641.60000000","0.00000000"],["79638.43000000","0.00771000"],["77468.40000000","0.00043000"],["71877.90000000","0.00448000"],["71877.89000000","0.00000000"],["71877.88000000","0.00008000"],["63891.47000000","0.00031000"]],"a":[["79864.34000000","1.13011000"],["79864.95000000","0.11820000"],["79866.81000000","0.00021000"],["79866.90000000","0.02100000"],["79867.07000000","0.06138000"],["79867.08000000","0.00000000"],["79867.26000000","0.00007000"],["79873.40000000","0.00250000"],["79876.82000000","0.00000000"],["79973.73000000","0.02804000"],["80017.16000000","1.50049000"],["80022.44000000","0.00000000"],["80025.50000000","0.00000000"]]}}}
{"rx_ns": 13972891984800, "frame": {"stream":"btcusdt@depth@100ms","data":{"e":"depthUpdate","E":1787650968114,"s":"BTCUSDT","U":99118683104,"u":99118683147,"b":[["79864.33000000","1.73010000"],["79863.97000000","0.00000000"],["79863.53000000","0.03238000"],["79861.30000000","0.00007000"],["79861.05000000","0.00007000"],["79860.44000000","0.00007000"],["71877.90000000","0.00432000"]],"a":[["79864.34000000","1.13011000"],["79864.55000000","0.07184000"],["79864.94000000","0.00007000"],["79864.95000000","0.11834000"],["79865.61000000","0.00000000"],["79866.20000000","0.06159000"],["79866.80000000","0.00000000"],["79866.81000000","0.00007000"],["79867.06000000","0.00007000"],["79867.26000000","0.00007000"],["79868.16000000","0.00007000"]]}}}
{"rx_ns": 13972991996000, "frame": {"stream":"btcusdt@depth@100ms","data":{"e":"depthUpdate","E":1787650968214,"s":"BTCUSDT","U":99118683148,"u":99118683160,"b":[["79864.33000000","1.73010000"],["79864.32000000","0.00076000"],["71877.90000000","0.00448000"],["63891.47000000","0.00000000"],["63891.46000000","0.00000000"]],"a":[["79864.34000000","1.13018000"],["79864.35000000","0.00097000"],["79886.01000000","0.00610000"]]}}}
{"rx_ns": 13973092025500, "frame": {"stream":"btcusdt@depth@100ms","data":{"e":"depthUpdate","E":1787650968314,"s":"BTCUSDT","U":99118683161,"u":99118683167,"b":[["79864.33000000","1.73017000"],["79720.73000000","0.00000000"],["71877.90000000","0.00432000"],["63891.46000000","0.00000000"],["63891.00000000","0.00000000"]],"a":[]}}}
{"rx_ns": 13973191787100, "frame": {"stream":"btcusdt@depth@100ms","data":{"e":"depthUpdate","E":1787650968414,"s":"BTCUSDT","U":99118683168,"u":99118683177,"b":[["79864.33000000","1.72996000"],["79864.32000000","0.00069000"],["79729.09000000","0.01961000"],["79724.62000000","0.00020000"],["71877.90000000","0.00448000"]],"a":[["80004.15000000","0.00020000"]]}}}
{"rx_ns": 13973292969900, "frame": {"stream":"btcusdt@depth@100ms","data":{"e":"depthUpdate","E":1787650968514,"s":"BTCUSDT","U":99118683178,"u":99118683183,"b":[["79795.03000000","0.02087000"],["79641.60000000","0.00771000"],["79638.43000000","0.00000000"],["71877.90000000","0.00432000"],["63891.47000000","0.00031000"]],"a":[]}}}
{"rx_ns": 13973394656500, "frame": {"stream":"btcusdt@depth@100ms","data":{"e":"depthUpdate","E":1787650968614,"s":"BTCUSDT","U":99118683184,"u":99118683194,"b":[["79849.12000000","0.00007000"],["79795.03000000","0.00000000"],["78666.36000000","0.00030000"],["71877.90000000","0.00432000"],["63891.47000000","0.00000000"]],"a":[["79881.08000000","0.00007000"],["81062.31000000","0.00030000"]]}}}
{"rx_ns": 13973492070900, "frame": {"stream":"btcusdt@depth@100ms","data":{"e":"depthUpdate","E":1787650968714,"s":"BTCUSDT","U":99118683195,"u":99118683198,"b":[["79864.33000000","1.75277000"],["71877.90000000","0.00432000"]],"a":[]}}}
{"rx_ns": 13973592326600, "frame": {"stream":"btcusdt@depth@100ms","data":{"e":"depthUpdate","E":1787650968814,"s":"BTCUSDT","U":99118683199,"u":99118683206,"b":[["79864.33000000","1.75324000"],["79856.34000000","0.00051000"],["79848.35000000","0.00036000"],["71877.90000000","0.00432000"]],"a":[]}}}
{"rx_ns": 13973693054600, "frame": {"stream":"btcusdt@depth@100ms","data":{"e":"depthUpdate","E":1787650968914,"s":"BTCUSDT","U":99118683207,"u":99118683212,"b":[["79840.37000000","0.00044000"],["79832.38000000","0.00044000"],["71877.90000000","0.00448000"],["71877.00000000","0.00000000"]],"a":[["79864.34000000","1.12989000"]]}}}
{"rx_ns": 13973796396300, "frame": {"stream":"btcusdt@depth20","data":{"lastUpdateId":99118683220,"bids":[["79864.33000000","1.75345000"],["79864.32000000","0.00076000"],["79864.31000000","0.00013000"],["79863.54000000","0.00007000"],["79863.53000000","0.03238000"],["79863.05000000","0.00975000"],["79862.90000000","0.00007000"],["79862.75000000","0.00400000"],["79862.45000000","0.00863000"],["79862.10000000","0.00007000"],["79861.85000000","0.00007000"],["79861.79000000","0.00007000"],["79861.78000000","0.60866000"],["79861.77000000","0.36906000"],["79861.70000000","0.00009000"],["79861.69000000","0.00007000"],["79861.68000000","0.05260000"],["79861.67000000","0.00007000"],["79861.66000000","0.31340000"],["79861.65000000","0.22677000"]],"asks":[["79864.34000000","1.12989000"],["79864.35000000","0.00097000"],["79864.36000000","0.00013000"],["79864.53000000","0.00014000"],["79864.54000000","0.00007000"],["79864.55000000","0.07184000"],["79864.59000000","0.00007000"],["79864.94000000","0.00007000"],["79864.95000000","0.11834000"],["79864.96000000","0.06152000"],["79865.19000000","0.00014000"],["79865.57000000","0.00007000"],["79865.58000000","0.06152000"],["79865.62000000","0.01761000"],["79865.99000000","0.00007000"],["79866.09000000","0.00007000"],["79866.19000000","0.00007000"],["79866.20000000","0.06159000"],["79866.71000000","0.00007000"],["79866.78000000","0.00007000"]]}}}
{"rx_ns": 13973796526100, "frame": {"stream":"btcusdt@depth@100ms","data":{"e":"depthUpdate","E":1787650969014,"s":"BTCUSDT","U":99118683213,"u":99118683220,"b":[["79864.33000000","1.75345000"],["79864.32000000","0.00076000"],["71877.90000000","0.00432000"],["63891.47000000","0.00031000"]],"a":[]}}}
{"rx_ns": 13973892133400, "frame": {"stream":"btcusdt@depth@100ms","data":{"e":"depthUpdate","E":1787650969114,"s":"BTCUSDT","U":99118683221,"u":99118683224,"b":[["79795.03000000","0.02087000"],["71877.90000000","0.00448000"]],"a":[]}}}
{"rx_ns": 13973991471100, "frame": {"stream":"btcusdt@depth@100ms","data":{"e":"depthUpdate","E":1787650969214,"s":"BTCUSDT","U":99118683225,"u":99118683232,"b":[["79795.03000000","0.00000000"],["71877.90000000","0.00416000"],["63891.47000000","0.00000000"],["63891.46000000","0.00000000"]],"a":[["79864.34000000","0.91487000"]]}}}
{"rx_ns": 13974091985300, "frame": {"stream":"btcusdt@depth@100ms","data":{"e":"depthUpdate","E":1787650969314,"s":"BTCUSDT","U":99118683233,"u":99118683250,"b":[["79864.33000000","1.75303000"],["79864.32000000","0.00048000"],["71877.90000000","0.00448000"],["63891.46000000","0.00000000"],["63891.00000000","0.00000000"]],"a":[["79864.34000000","1.11724000"]]}}}
{"rx_ns": 13974191657300, "frame": {"stream":"btcusdt@depth@100ms","data":{"e":"depthUpdate","E":1787650969414,"s":"BTCUSDT","U":99118683251,"u":99118683256,"b":[["79864.33000000","1.75370000"],["71877.90000000","0.00432000"]],"a":[["79864.34000000","1.11737000"],["79886.01000000","0.00000000"]]}}}
{"rx_ns": 13974291680100, "frame": {"stream":"btcusdt@depth@100ms","data":{"e":"depthUpdate","E":1787650969514,"s":"BTCUSDT","U":99118683257,"u":99118683261,"b":[["71877.90000000","0.00432000"],["63891.47000000","0.00031000"]],"a":[]}}}
{"rx_ns": 13974392349300, "frame": {"stream":"btcusdt@depth@100ms","data":{"e":"depthUpdate","E":1787650969614,"s":"BTCUSDT","U":99118683262,"u":99118683271,"b":[["79849.12000000","0.00007000"],["78666.36000000","0.00030000"],["71877.90000000","0.00432000"],["63891.47000000","0.00000000"]],"a":[["79881.08000000","0.00007000"],["81062.31000000","0.00030000"]]}}}
{"rx_ns": 13974491619000, "frame": {"stream":"btcusdt@depth@100ms","data":{"e":"depthUpdate","E":1787650969714,"s":"BTCUSDT","U":99118683272,"u":99118683275,"b":[["79795.03000000","0.02087000"],["71877.90000000","0.00448000"]],"a":[]}}}
{"rx_ns": 13974592128800, "frame": {"stream":"btcusdt@depth@100ms","data":{"e":"depthUpdate","E":1787650969814,"s":"BTCUSDT","U":99118683276,"u":99118683278,"b":[["79795.03000000","0.00000000"],["71877.90000000","0.00416000"]],"a":[]}}}
{"rx_ns": 13974698753400, "frame": {"stream":"btcusdt@depth@100ms","data":{"e":"depthUpdate","E":1787650969914,"s":"BTCUSDT","U":99118683279,"u":99118683282,"b":[["79855.11000000","0.00400000"],["71877.90000000","0.00448000"]],"a":[["79873.94000000","0.00400000"]]}}}
{"rx_ns": 13974797300400, "frame": {"stream":"btcusdt@depth20","data":{"lastUpdateId":99118683296,"bids":[["79864.33000000","1.74092000"],["79864.32000000","0.00048000"],["79864.31000000","0.00013000"],["79863.54000000","0.00007000"],["79863.53000000","0.03238000"],["79863.05000000","0.00975000"],["79862.90000000","0.00007000"],["79862.75000000","0.00400000"],["79862.45000000","0.00863000"],["79862.10000000","0.00007000"],["79861.85000000","0.00007000"],["79861.79000000","0.00007000"],["79861.78000000","0.60866000"],["79861.77000000","0.36906000"],["79861.70000000","0.00009000"],["79861.69000000","0.00007000"],["79861.68000000","0.05260000"],["79861.67000000","0.00007000"],["79861.66000000","0.31340000"],["79861.65000000","0.22677000"]],"asks":[["79864.34000000","1.11244000"],["79864.35000000","0.00705000"],["79864.36000000","0.00013000"],["79864.53000000","0.00014000"],["79864.54000000","0.00007000"],["79864.55000000","0.07184000"],["79864.59000000","0.00007000"],["79864.94000000","0.00007000"],["79864.95000000","0.11834000"],["79864.96000000","0.06152000"],["79865.19000000","0.00014000"],["79865.57000000","0.00007000"],["79865.58000000","0.06152000"],["79865.62000000","0.01761000"],["79865.99000000","0.00007000"],["79866.09000000","0.00007000"],["79866.19000000","0.00007000"],["79866.20000000","0.06159000"],["79866.71000000","0.00007000"],["79866.78000000","0.00007000"]]}}}
{"rx_ns": 13974797402600, "frame": {"stream":"btcusdt@depth@100ms","data":{"e":"depthUpdate","E":1787650970014,"s":"BTCUSDT","U":99118683283,"u":99118683296,"b":[["79864.33000000","1.74092000"],["79864.32000000","0.00048000"],["71877.90000000","0.00432000"],["71877.00000000","0.00010000"],["63891.47000000","0.00031000"]],"a":[["79864.34000000","1.11244000"],["79864.35000000","0.00705000"]]}}}
{"rx_ns": 13974892237500, "frame": {"stream":"btcusdt@depth@100ms","data":{"e":"depthUpdate","E":1787650970114,"s":"BTCUSDT","U":99118683297,"u":99118683334,"b":[["79864.33000000","1.74134000"],["79864.32000000","0.00076000"],["79863.54000000","0.00000000"],["79863.53000000","0.00014000"],["79859.25000000","0.00007000"],["71877.90000000","0.00416000"],["71877.00000000","0.00000000"]],"a":[["79864.34000000","1.11244000"],["79864.35000000","0.00719000"],["79865.19000000","0.00007000"],["79866.90000000","0.02086000"],["79867.06000000","0.00007000"],["79867.26000000","0.00007000"],["79867.27000000","0.04779000"],["79867.98000000","0.00007000"],["79867.99000000","0.06138000"],["79868.16000000","0.00000000"],["79868.68000000","0.06145000"],["79871.87000000","0.00912000"]]}}}
{"rx_ns": 13974992311700, "frame": {"stream":"btcusdt@depth@100ms","data":{"e":"depthUpdate","E":1787650970214,"s":"BTCUSDT","U":99118683335,"u":99118683361,"b":[["79864.33000000","2.08140000"],["79863.53000000","0.00000000"],["79861.70000000","0.00000000"],["79861.65000000","0.22691000"],["79860.45000000","0.00013000"],["63891.47000000","0.00000000"],["63891.46000000","0.00020000"]],"a":[["79864.34000000","1.45679000"],["79864.96000000","0.00014000"],["79872.03000000","0.00400000"],["79875.83000000","0.00000000"]]}}}
{"rx_ns": 13975095431600, "frame": {"stream":"btcusdt@depth@100ms","data":{"e":"depthUpdate","E":1787650970314,"s":"BTCUSDT","U":99118683362,"u":99118683415,"b":[["79864.33000000","2.08140000"],["79864.32000000","0.00076000"],["79861.05000000","0.00007000"],["79860.44000000","0.00007000"],["79859.25000000","0.00007000"],["79842.51000000","0.88181000"],["79841.00000000","0.00000000"],["71877.90000000","0.00416000"],["71877.88000000","0.00000000"],["71877.00000000","0.00000000"],["63891.46000000","0.00000000"],["63891.00000000","0.00000000"]],"a":[["79864.34000000","1.43859000"],["79864.35000000","0.00712000"],["79864.53000000","0.00007000"],["79864.95000000","0.11827000"],["79864.96000000","0.00000000"],["79865.61000000","0.00007000"],["79866.89000000","0.00007000"],["79866.90000000","0.02100000"],["79867.06000000","0.00007000"],["79867.26000000","0.00007000"],["79867.98000000","0.00000000"],["79871.87000000","0.00000000"],["79872.26000000","0.00932000"],["79873.88000000","0.00000000"]]}}}
{"rx_ns": 13975194624600, "frame": {"stream":"btcusdt@depth@100ms","data":{"e":"depthUpdate","E":1787650970414,"s":"BTCUSDT","U":99118683416,"u":99118683428,"b":[["79864.33000000","2.06249000"],["79858.01000000","0.00000000"],["79857.55000000","0.00626000"],["79857.22000000","0.00626000"],["79856.01000000","0.00000000"],["79714.29000000","0.00125000"],["79710.01000000","0.00000000"],["71877.90000000","0.00432000"],["71877.00000000","0.00000000"]],"a":[["79864.34000000","1.43907000"],["79865.19000000","0.00014000"],["79871.66000000","0.00643000"],["79877.99000000","0.00000000"],["79931.99000000","0.00312000"],["79932.70000000","0.00000000"]]}}}
{"rx_ns": 13975292592100, "frame": {"stream":"btcusdt@depth@100ms","data":{"e":"depthUpdate","E":1787650970514,"s":"BTCUSDT","U":99118683429,"u":99118683433,"b":[["79858.18000000","0.00626000"],["79857.55000000","0.00000000"],["79685.35000000","0.00863000"],["71877.90000000","0.00416000"],["63891.47000000","0.00031000"]],"a":[["80183.44000000","0.02274000"]]}}}
{"rx_ns": 13975393834000, "frame": {"stream":"btcusdt@depth@100ms","data":{"e":"depthUpdate","E":1787650970614,"s":"BTCUSDT","U":99118683434,"u":99118683459,"b":[["79864.33000000","2.06249000"],["79864.32000000","0.00076000"],["79849.12000000","0.00000000"],["79847.64000000","0.00400000"],["79827.75000000","0.00000000"],["78666.36000000","0.00030000"],["71877.90000000","0.00432000"],["63891.47000000","0.00000000"]],"a":[["79871.66000000","0.00017000"],["79871.99000000","0.00626000"],["79881.08000000","0.00000000"],["79896.60000000","0.00400000"],["79904.76000000","0.00400000"],["79905.00000000","0.01000000"],["79906.50000000","0.00000000"],["81062.31000000","0.00030000"]]}}}
{"rx_ns": 13975492132800, "frame": {"stream":"btcusdt@depth@100ms","data":{"e":"depthUpdate","E":1787650970714,"s":"BTCUSDT","U":99118683460,"u":99118683479,"b":[["79864.33000000","1.97992000"],["79856.34000000","0.00283000"],["79849.12000000","0.00007000"],["79848.35000000","0.00268000"],["79840.37000000","0.00276000"],["79832.38000000","0.00276000"],["71877.90000000","0.00416000"],["71877.00000000","0.00000000"]],"a":[["79864.34000000","1.43859000"],["79873.77000000","0.00048000"],["79881.08000000","0.00007000"]]}}}
{"rx_ns": 13975591835400, "frame": {"stream":"btcusdt@depth@100ms","data":{"e":"depthUpdate","E":1787650970814,"s":"BTCUSDT","U":99118683480,"u":99118683484,"b":[["71877.90000000","0.00432000"],["71877.00000000","0.00000000"]],"a":[["79901.00000000","0.70000000"],["79902.00000000","0.02400000"]]}}}
{"rx_ns": 13975702915400, "frame": {"stream":"btcusdt@depth@100ms","data":{"e":"depthUpdate","E":1787650970914,"s":"BTCUSDT","U":99118683485,"u":99118683488,"b":[["71877.90000000","0.00416000"],["71877.00000000","0.00010000"]],"a":[]}}}
{"rx_ns": 13975794019100, "frame": {"stream":"btcusdt@depth20","data":{"lastUpdateId":99118683498,"bids":[["79864.33000000","1.97992000"],["79864.32000000","0.00076000"],["79864.31000000","0.00013000"],["79863.05000000","0.00975000"],["79862.90000000","0.00007000"],["79862.75000000","0.00400000"],["79862.45000000","0.00863000"],["79862.10000000","0.00007000"],["79861.85000000","0.00007000"],["79861.79000000","0.00007000"],["79861.78000000","0.60866000"],["79861.77000000","0.36906000"],["79861.69000000","0.00007000"],["79861.68000000","0.05260000"],["79861.67000000","0.00007000"],["79861.66000000","0.31340000"],["79861.65000000","0.22691000"],["79861.32000000","0.00014000"],["79861.30000000","0.00007000"],["79861.29000000","0.08007000"]],"asks":[["79864.34000000","1.43859000"],["79864.35000000","0.00712000"],["79864.36000000","0.00013000"],["79864.53000000","0.00007000"],["79864.54000000","0.00007000"],["79864.55000000","0.07184000"],["79864.59000000","0.00007000"],["79864.94000000","0.00007000"],["79864.95000000","0.11827000"],["79865.19000000","0.00014000"],["79865.57000000","0.00007000"],["79865.58000000","0.06152000"],["79865.61000000","0.00007000"],["79865.62000000","0.01761000"],["79865.99000000","0.00007000"],["79866.09000000","0.00007000"],["79866.19000000","0.00007000"],["79866.20000000","0.06159000"],["79866.71000000","0.00007000"],["79866.78000000","0.00007000"]]}}}
{"rx_ns": 13975794163400, "frame": {"stream":"btcusdt@depth@100ms","data":{"e":"depthUpdate","E":1787650971014,"s":"BTCUSDT","U":99118683489,"u":99118683498,"b":[["79858.18000000","0.00000000"],["79857.55000000","0.00626000"],["79837.00000000","0.70000000"],["71877.90000000","0.00432000"],["71877.00000000","0.00010000"],["63891.47000000","0.00031000"]],"a":[]}}}
{"rx_ns": 13975893386300, "frame": {"stream":"btcusdt@depth@100ms","data":{"e":"depthUpdate","E":1787650971114,"s":"BTCUSDT","U":99118683499,"u":99118683508,"b":[["71877.90000000","0.00400000"],["71877.00000000","0.00000000"],["66000.00000000","20.28158000"],["63891.00000000","0.00000000"]],"a":[]}}}
