{"captured_at": "2026-08-25T09:40:47.563412+00:00", "url": "wss://data-stream.binance.vision/stream?streams=btcusdt@depth@100ms/btcusdt@depth20", "venue": "binance", "symbol": "BTCUSDT", "streams": ["depth@100ms", "depth20"], "combined": true, "rest_url": "https://data-api.binance.vision/api/v3/depth?symbol=BTCUSDT&limit=1000", "rest_limit": 1000, "rest_weight_per_fetch": 50, "snapshot_every_s": 25.0, "tool_version": "0.1.0", "clock": "perf_counter_ns", "capture_mode": "baseline", "cycles": 1, "origin_sent": null, "handshake_status": "HTTP/1.1 101 Switching Protocols"}
{"rx_ns": 13852801400200, "frame": {"stream":"btcusdt@depth20","data":{"lastUpdateId":99118576892,"bids":[["79857.99000000","2.52951000"],["79857.98000000","0.00027000"],["79857.97000000","0.00013000"],["79857.45000000","0.00014000"],["79856.97000000","0.00007000"],["79856.96000000","0.36600000"],["79856.95000000","0.00407000"],["79856.94000000","0.25296000"],["79856.93000000","0.31334000"],["79856.92000000","0.50599000"],["79856.85000000","0.00730000"],["79856.72000000","0.00014000"],["79856.71000000","0.01767000"],["79856.04000000","0.00014000"],["79855.74000000","0.00633000"],["79855.73000000","0.00007000"],["79855.72000000","1.12594000"],["79855.71000000","0.00007000"],["79855.70000000","0.02254000"],["79855.69000000","0.00021000"]],"asks":[["79858.00000000","1.15263000"],["79858.01000000","0.00069000"],["79858.02000000","0.00013000"],["79858.16000000","0.00007000"],["79858.38000000","0.00007000"],["79858.42000000","0.00007000"],["79859.35000000","0.00007000"],["79859.49000000","0.00007000"],["79859.99000000","0.00007000"],["79860.00000000","0.02428000"],["79860.03000000","0.00837000"],["79860.30000000","0.00007000"],["79860.49000000","0.00007000"],["79860.89000000","0.00007000"],["79860.90000000","0.04854000"],["79860.99000000","0.00358000"],["79861.02000000","0.00007000"],["79861.03000000","0.01804000"],["79861.08000000","0.00007000"],["79861.09000000","0.13284000"]]}}}
{"rx_ns": 13852801501800, "frame": {"stream":"btcusdt@depth@100ms","data":{"e":"depthUpdate","E":1787650848014,"s":"BTCUSDT","U":99118576885,"u":99118576892,"b":[["79790.63000000","0.00000000"],["79778.17000000","0.62594000"],["79775.53000000","0.00000000"],["71872.20000000","0.00432000"],["63886.40000000","0.00031000"]],"a":[["79873.89000000","0.00250000"]]}}}
{"rx_ns": 13852900375300, "frame": {"stream":"btcusdt@depth@100ms","data":{"e":"depthUpdate","E":1787650848115,"s":"BTCUSDT","U":99118576893,"u":99118576917,"b":[["79855.73000000","0.03464000"],["79855.31000000","0.05193000"],["79854.41000000","0.00000000"],["79842.78000000","0.00007000"],["79842.77000000","0.00000000"],["79688.58000000","4.45182000"],["78660.12000000","0.00030000"],["71872.20000000","0.00448000"]],"a":[["79858.00000000","0.71284000"],["79861.10000000","0.00007000"],["79861.72000000","0.00007000"],["79867.92000000","0.06317000"],["79868.52000000","0.06317000"],["79873.86000000","0.00250000"],["79873.89000000","0.00000000"],["79874.74000000","0.00007000"],["80053.17000000","4.45702000"],["81055.87000000","0.00030000"]]}}}
{"rx_ns": 13853007125400, "frame": {"stream":"btcusdt@depth@100ms","data":{"e":"depthUpdate","E":1787650848214,"s":"BTCUSDT","U":99118576918,"u":99118576974,"b":[["79857.99000000","2.52962000"],["79855.74000000","0.00647000"],["79855.73000000","0.00014000"],["79855.72000000","1.12580000"],["79855.65000000","1.04946000"],["79855.31000000","0.05200000"],["79855.23000000","0.00626000"],["79854.02000000","0.00007000"],["79854.01000000","1.87684000"],["79854.00000000","0.81768000"],["79853.10000000","0.00000000"],["79843.93000000","0.03457000"],["77942.64000000","0.00023000"],["71872.20000000","0.00432000"],["71872.19000000","0.00000000"],["71872.18000000","0.00008000"],["63886.40000000","0.00000000"],["63886.39000000","0.00000000"]],"a":[["79858.00000000","0.71238000"],["79858.01000000","0.00062000"],["79860.90000000","0.04847000"],["79861.09000000","0.09211000"],["79861.10000000","0.00000000"],["79861.31000000","0.01397000"],["79861.71000000","0.00007000"],["79861.72000000","0.06317000"],["79862.00000000","0.02421000"],["79862.34000000","0.05728000"],["79862.95000000","0.00007000"],["79863.39000000","0.00007000"],["79863.57000000","0.00007000"],["79866.96000000","0.06317000"],["79873.83000000","0.00250000"],["79873.86000000","0.00000000"]]}}}
{"rx_ns": 13853096492300, "frame": {"stream":"btcusdt@depth@100ms","data":{"e":"depthUpdate","E":1787650848314,"s":"BTCUSDT","U":99118576975,"u":99118577023,"b":[["79857.99000000","2.53624000"],["79857.15000000","0.00400000"],["79855.74000000","0.00021000"],["79855.73000000","0.00007000"],["79855.72000000","1.12587000"],["79855.65000000","1.04946000"],["79855.44000000","0.00000000"],["79854.78000000","0.00400000"],["79854.02000000","0.00007000"],["79854.01000000","1.87684000"],["79821.00000000","0.00000000"],["79818.21000000","0.00000000"],["71872.20000000","0.00432000"],["63886.00000000","0.05602000"]],"a":[["79858.00000000","0.36996000"],["79860.03000000","0.00844000"],["79860.88000000","0.00007000"],["79860.89000000","0.06324000"],["79861.08000000","0.00000000"],["79861.09000000","0.00007000"],["79861.30000000","0.00000000"],["79861.31000000","0.01397000"],["79861.72000000","0.06324000"],["79862.34000000","0.05721000"],["79862.95000000","0.00007000"],["79862.96000000","0.06324000"],["79863.39000000","0.00000000"],["79863.40000000","0.00000000"],["79863.57000000","0.00007000"],["79864.80000000","0.00000000"],["79865.99000000","0.26574000"],["79902.18000000","0.00400000"]]}}}
{"rx_ns": 13853200115200, "frame": {"stream":"btcusdt@depth@100ms","data":{"e":"depthUpdate","E":1787650848414,"s":"BTCUSDT","U":99118577024,"u":99118577053,"b":[["79856.71000000","0.01767000"],["79855.74000000","0.00007000"],["79855.72000000","1.12594000"],["79855.70000000","0.02261000"],["79853.44000000","0.30281000"],["77784.74000000","0.00023000"],["71872.20000000","0.00432000"],["63886.39000000","0.00000000"]],"a":[["79858.00000000","0.37196000"],["79860.03000000","0.00851000"],["79860.47000000","0.00007000"],["79860.48000000","0.06317000"],["79860.89000000","0.06331000"],["79861.03000000","0.01797000"],["79861.09000000","0.00000000"],["79873.77000000","0.00250000"],["79873.83000000","0.00000000"],["79902.00000000","0.02400000"]]}}}
{"rx_ns": 13853296307900, "frame": {"stream":"btcusdt@depth@100ms","data":{"e":"depthUpdate","E":1787650848514,"s":"BTCUSDT","U":99118577054,"u":99118577072,"b":[["71872.20000000","0.00432000"],["71872.00000000","0.00000000"],["63886.40000000","0.00031000"]],"a":[["79858.00000000","0.37196000"],["79860.03000000","0.00851000"],["79860.48000000","0.06324000"],["79862.00000000","0.02414000"],["79864.46000000","0.00202000"],["79864.55000000","0.33819000"],["79868.53000000","0.17422000"],["79870.00000000","0.22278000"],["79873.74000000","0.00400000"],["79873.77000000","0.00000000"]]}}}
{"rx_ns": 13853396243000, "frame": {"stream":"btcusdt@depth@100ms","data":{"e":"depthUpdate","E":1787650848614,"s":"BTCUSDT","U":99118577073,"u":99118577097,"b":[["79857.99000000","2.53374000"],["79850.28000000","1.20241000"],["79836.01000000","0.00007000"],["79830.00000000","0.12046000"],["79714.83000000","0.00000000"],["71872.20000000","0.00448000"],["63886.40000000","0.00000000"]],"a":[["79864.54000000","0.30220000"],["79865.43000000","0.00000000"],["79867.67000000","0.18422000"],["79868.53000000","0.10939000"],["79870.00000000","0.02400000"],["79870.18000000","0.00000000"],["79875.36000000","0.00000000"],["79875.93000000","0.00000000"],["80018.32000000","0.00000000"]]}}}
{"rx_ns": 13853496234000, "frame": {"stream":"btcusdt@depth@100ms","data":{"e":"depthUpdate","E":1787650848714,"s":"BTCUSDT","U":99118577098,"u":99118577104,"b":[["79652.29000000","0.00771000"],["79647.23000000","0.00000000"],["77627.15000000","0.00023000"],["71872.20000000","0.00432000"]],"a":[["79867.92000000","0.00000000"],["79870.33000000","0.12528000"]]}}}
{"rx_ns": 13853599941200, "frame": {"stream":"btcusdt@depth@100ms","data":{"e":"depthUpdate","E":1787650848814,"s":"BTCUSDT","U":99118577105,"u":99118577108,"b":[["79831.52000000","0.00000000"],["79828.15000000","0.02497000"],["71872.20000000","0.00448000"]],"a":[["79870.33000000","0.00000000"]]}}}
{"rx_ns": 13853696520300, "frame": {"stream":"btcusdt@depth@100ms","data":{"e":"depthUpdate","E":1787650848914,"s":"BTCUSDT","U":99118577109,"u":99118577117,"b":[["79857.99000000","2.53411000"],["77469.89000000","0.00023000"],["71872.20000000","0.00432000"],["63886.00000000","0.05902000"]],"a":[["79866.80000000","0.06517000"],["79867.67000000","0.00000000"],["79872.02000000","0.00007000"]]}}}
{"rx_ns": 13853796553900, "frame": {"stream":"btcusdt@depth20","data":{"lastUpdateId":99118577144,"bids":[["79857.99000000","2.53411000"],["79857.98000000","0.00027000"],["79857.97000000","0.00013000"],["79857.45000000","0.00014000"],["79857.15000000","0.00400000"],["79856.97000000","0.00007000"],["79856.96000000","0.36600000"],["79856.95000000","0.00407000"],["79856.94000000","0.25296000"],["79856.93000000","0.31334000"],["79856.92000000","0.50599000"],["79856.85000000","0.00730000"],["79856.72000000","0.00014000"],["79856.71000000","0.01767000"],["79856.04000000","0.00014000"],["79855.74000000","0.00007000"],["79855.73000000","0.03464000"],["79855.72000000","1.12594000"],["79855.71000000","0.00007000"],["79855.70000000","0.02261000"]],"asks":[["79858.00000000","0.37203000"],["79858.01000000","0.00062000"],["79858.02000000","0.00013000"],["79858.16000000","0.00007000"],["79858.38000000","0.00007000"],["79858.42000000","0.00007000"],["79859.35000000","0.00007000"],["79859.49000000","0.00007000"],["79859.85000000","0.00007000"],["79859.86000000","0.06317000"],["79859.99000000","0.00007000"],["79860.00000000","0.02428000"],["79860.03000000","0.00851000"],["79860.30000000","0.00007000"],["79860.47000000","0.00007000"],["79860.48000000","0.06324000"],["79860.49000000","0.00007000"],["79860.88000000","0.00007000"],["79860.89000000","0.06331000"],["79860.90000000","0.04847000"]]}}}
{"rx_ns": 13853796703900, "frame": {"stream":"btcusdt@depth@100ms","data":{"e":"depthUpdate","E":1787650849014,"s":"BTCUSDT","U":99118577118,"u":99118577144,"b":[["79855.73000000","0.03464000"],["79855.65000000","1.04946000"],["79854.02000000","0.00007000"],["79854.01000000","1.87684000"],["79843.93000000","0.00000000"],["79835.00000000","0.70000000"],["79832.00000000","0.02407000"],["79792.23000000","0.02500000"],["71872.20000000","0.00448000"],["63886.40000000","0.00031000"],["63886.00000000","0.05602000"]],"a":[["79858.00000000","0.37203000"],["79859.85000000","0.00007000"],["79859.86000000","0.06317000"],["79861.71000000","0.00007000"],["79861.99000000","0.00007000"],["79862.33000000","0.00007000"],["79862.95000000","0.00000000"],["79863.57000000","0.00000000"],["79870.40000000","0.06317000"]]}}}
{"rx_ns": 13853897458100, "frame": {"stream":"btcusdt@depth@100ms","data":{"e":"depthUpdate","E":1787650849114,"s":"BTCUSDT","U":99118577145,"u":99118577177,"b":[["79856.97000000","0.00007000"],["79856.95000000","0.00007000"],["79856.71000000","0.01760000"],["79855.73000000","0.03471000"],["79855.70000000","0.02254000"],["79835.01000000","0.53917000"],["79834.70000000","0.00000000"],["79792.23000000","0.00413000"],["78660.12000000","0.00030000"],["71872.20000000","0.00416000"]],"a":[["79858.00000000","0.37210000"],["79859.86000000","0.06324000"],["79860.47000000","0.00007000"],["79861.72000000","0.06317000"],["79864.54000000","0.32425000"],["79865.87000000","0.15623000"],["79866.80000000","0.00000000"],["81055.87000000","0.00030000"]]}}}
{"rx_ns": 13853997286400, "frame": {"stream":"btcusdt@depth@100ms","data":{"e":"depthUpdate","E":1787650849214,"s":"BTCUSDT","U":99118577178,"u":99118577188,"b":[["79857.99000000","2.51533000"],["79842.78000000","0.00007000"],["77312.94000000","0.00023000"],["71872.20000000","0.00448000"],["63886.40000000","0.00000000"]],"a":[["79858.00000000","0.37203000"],["79864.95000000","0.09357000"],["79865.87000000","0.00000000"],["79874.74000000","0.00007000"]]}}}
{"rx_ns": 13854100581900, "frame": {"stream":"btcusdt@depth@100ms","data":{"e":"depthUpdate","E":1787650849317,"s":"BTCUSDT","U":99118577189,"u":99118577205,"b":[["79857.99000000","2.50907000"],["79856.71000000","0.01774000"],["79856.05000000","0.00626000"],["79853.99000000","0.00127000"],["79852.04000000","0.00000000"],["71872.20000000","0.00432000"],["63886.39000000","0.00000000"],["63886.00000000","0.05602000"]],"a":[["79858.00000000","0.72701000"]]}}}
{"rx_ns": 13854196422700, "frame": {"stream":"btcusdt@depth@100ms","data":{"e":"depthUpdate","E":1787650849414,"s":"BTCUSDT","U":99118577206,"u":99118577221,"b":[["79856.71000000","0.01774000"],["79856.05000000","0.00640000"],["79855.72000000","1.12580000"],["77156.31000000","0.00023000"],["71872.20000000","0.00432000"],["63886.39000000","0.00000000"]],"a":[["79864.08000000","0.12085000"],["79864.95000000","0.00000000"],["79872.02000000","0.00014000"]]}}}
{"rx_ns": 13854296515900, "kind": "rest", "req": {"method": "GET", "url": "https://data-api.binance.vision/api/v3/depth?symbol=BTCUSDT&limit=1000", "limit": 1000, "weight": 50, "sent_ns": 13852628829000, "status": 200, "used_weight_1m": "50", "recv_ns": 13854219502600}, "frame": {"lastUpdateId":99118577117,"bids":[["79857.99000000","2.53411000"],["79857.98000000","0.00027000"],["79857.97000000","0.00013000"],["79857.45000000","0.00014000"],["79857.15000000","0.00400000"],["79856.97000000","0.00007000"],["79856.96000000","0.36600000"],["79856.95000000","0.00407000"],["79856.94000000","0.25296000"],["79856.93000000","0.31334000"],["79856.92000000","0.50599000"],["79856.85000000","0.00730000"],["79856.72000000","0.00014000"],["79856.71000000","0.01767000"],["79856.04000000","0.00014000"],["79855.74000000","0.00007000"],["79855.73000000","0.00007000"],["79855.72000000","1.12594000"],["79855.71000000","0.00007000"],["79855.70000000","0.02261000"],["79855.69000000","0.00021000"],["79855.66000000","0.00007000"],["79855.65000000","1.04946000"],["79855.64000000","0.83832000"],["79855.43000000","0.02095000"],["79855.31000000","0.05200000"],["79855.23000000","0.00626000"],["79855.22000000","0.00007000"],["79855.21000000","0.00014000"],["79855.09000000","0.00007000"],["79854.86000000","0.00250000"],["79854.78000000","0.00400000"],["79854.69000000","0.00007000"],["79854.26000000","0.00007000"],["79854.24000000","0.00007000"],["79854.15000000","0.02095000"],["79854.02000000","0.00007000"],["79854.01000000","1.87684000"],["79854.00000000","0.81768000"],["79853.99000000","0.00134000"],["79853.58000000","0.00014000"],["79853.44000000","0.30281000"],["79853.09000000","0.00007000"],["79852.99000000","0.07894000"],["79852.65000000","0.00008000"],["79852.23000000","0.00400000"],["79852.19000000","0.00007000"],["79852.04000000","0.00007000"],["79852.01000000","0.00013000"],["79851.99000000","0.00066000"],["79851.71000000","0.12573000"],["79851.45000000","0.00939000"],["79851.32000000","1.22152000"],["79851.31000000","1.04939000"],["79851.19000000","0.12523000"],["79850.54000000","0.00162000"],["79850.28000000","1.20241000"],["79850.11000000","0.00007000"],["79850.10000000","0.00026000"],["79850.00000000","0.02700000"],["79849.85000000","0.00693000"],["79849.80000000","0.03224000"],["79849.71000000","0.00014000"],["79849.61000000","0.00400000"],["79848.93000000","0.20250000"],["79848.50000000","0.37579000"],["79848.34000000","0.00007000"],["79848.03000000","0.36593000"],["79848.01000000","1.87677000"],["79848.00000000","0.02425000"],["79847.70000000","0.00007000"],["79847.38000000","0.00400000"],["79847.11000000","0.02000000"],["79847.10000000","0.71913000"],["79847.09000000","1.04939000"],["79847.04000000","0.02400000"],["79847.01000000","0.02600000"],["79846.76000000","0.49543000"],["79846.52000000","0.00007000"],["79846.33000000","0.00924000"],["79846.25000000","0.02000000"],["79846.21000000","0.02200000"],["79846.15000000","0.02400000"],["79846.00000000","0.02407000"],["79845.96000000","0.00007000"],["79845.85000000","0.00711000"],["79845.84000000","0.00014000"],["79845.66000000","0.00010000"],["79845.15000000","0.00407000"],["79845.07000000","0.33823000"],["79844.74000000","0.00708000"],["79844.58000000","0.00008000"],["79844.42000000","0.33823000"],["79844.34000000","0.01369000"],["79844.04000000","0.12524000"],["79844.01000000","0.00007000"],["79844.00000000","0.02410000"],["79843.99000000","0.00189000"],["79843.96000000","0.02000000"],["79843.93000000","0.03457000"],["79843.92000000","0.02200000"],["79843.88000000","0.00007000"],["79843.79000000","0.09510000"],["79843.32000000","0.33824000"],["79843.16000000","0.04000000"],["79843.02000000","0.02200000"],["79842.92000000","0.00400000"],["79842.78000000","0.00007000"],["79842.76000000","1.18407000"],["79842.75000000","1.87677000"],["79842.73000000","1.04939000"],["79842.64000000","0.00007000"],["79842.56000000","0.02000000"],["79842.51000000","0.06936000"],["79842.16000000","0.02000000"],["79842.15000000","0.02000000"],["79842.02000000","0.00008000"],["79842.01000000","0.00007000"],["79842.00000000","0.02400000"],["79841.99000000","0.22390000"],["79841.97000000","0.00014000"],["79841.96000000","0.00007000"],["79841.85000000","0.03224000"],["79841.81000000","0.00007000"],["79841.71000000","0.00007000"],["79841.48000000","0.00026000"],["79840.41000000","0.00705000"],["79840.29000000","0.00400000"],["79840.12000000","0.62639000"],["79840.01000000","0.36586000"],["79840.00000000","0.32302000"],["79839.79000000","0.12677000"],["79839.73000000","0.00007000"],["79838.76000000","0.00007000"],["79838.47000000","0.00626000"],["79838.46000000","0.00400000"],["79838.42000000","0.00007000"],["79838.10000000","0.00014000"],["79838.06000000","0.04470000"],["79838.00000000","0.02400000"],["79837.81000000","0.09469000"],["79837.68000000","0.00010000"],["79837.65000000","0.00007000"],["79837.61000000","0.33826000"],["79836.84000000","0.43378000"],["79836.51000000","0.00008000"],["79836.45000000","1.28149000"],["79836.44000000","1.04939000"],["79836.30000000","0.26800000"],["79836.12000000","0.00400000"],["79836.06000000","0.12525000"],["79836.02000000","1.87677000"],["79836.01000000","0.00007000"],["79836.00000000","0.02400000"],["79835.81000000","0.10373000"],["79835.58000000","0.00007000"],["79835.53000000","0.00946000"],["79835.44000000","0.00059000"],["79835.24000000","0.00008000"],["79834.88000000","0.00007000"],["79834.70000000","0.56249000"],["79834.38000000","0.00400000"],["79834.23000000","0.00014000"],["79834.03000000","0.00007000"],["79834.00000000","0.02400000"],["79833.55000000","0.00012000"],["79833.50000000","0.00007000"],["79833.38000000","0.00026000"],["79832.08000000","0.00007000"],["79832.06000000","1.04939000"],["79832.00000000","0.72407000"],["79831.92000000","0.00400000"],["79831.81000000","0.36586000"],["79831.80000000","0.20250000"],["79831.43000000","0.00007000"],["79831.24000000","0.00008000"],["79831.00000000","0.00007000"],["79830.46000000","1.36096000"],["79830.36000000","0.00014000"],["79830.23000000","0.37588000"],["79830.03000000","0.00007000"],["79830.01000000","0.00400000"],["79830.00000000","0.12046000"],["79829.88000000","0.00400000"],["79829.83000000","0.00400000"],["79829.82000000","0.00007000"],["79829.70000000","0.00010000"],["79829.35000000","0.00007000"],["79829.34000000","1.87677000"],["79829.28000000","0.12897000"],["79828.71000000","0.00400000"],["79828.44000000","0.00008000"],["79828.15000000","0.02497000"],["79828.00000000","0.02400000"],["79827.99000000","1.04939000"],["79827.85000000","0.92639000"],["79827.83000000","0.20631000"],["79827.28000000","0.00007000"],["79827.25000000","0.00008000"],["79827.12000000","0.00007000"],["79826.49000000","0.00014000"],["79826.34000000","0.00400000"],["79826.33000000","0.00010000"],["79826.32000000","0.00007000"],["79826.30000000","0.00052000"],["79826.12000000","0.01143000"],["79826.00000000","0.02400000"],["79825.96000000","0.00400000"],["79825.39000000","0.00026000"],["79825.34000000","0.42967000"],["79825.33000000","0.00541000"],["79825.20000000","0.00007000"],["79824.50000000","0.03224000"],["79824.23000000","1.87677000"],["79824.00000000","0.02407000"],["79823.96000000","0.05104000"],["79823.90000000","0.00125000"],["79823.81000000","0.36586000"],["79823.80000000","1.00762000"],["79823.79000000","1.04939000"],["79823.16000000","0.00007000"],["79823.13000000","0.00007000"],["79823.10000000","0.00400000"],["79822.62000000","0.00014000"],["79822.34000000","0.83262000"],["79822.29000000","0.62653000"],["79822.16000000","0.20250000"],["79822.05000000","0.00008000"],["79822.00000000","0.02400000"],["79821.72000000","0.00010000"],["79821.19000000","0.50992000"],["79821.05000000","0.00007000"],["79820.54000000","1.24057000"],["79820.37000000","0.00008000"],["79820.00000000","0.11797000"],["79819.99000000","0.00007000"],["79819.44000000","1.57841000"],["79819.43000000","1.87677000"],["79819.40000000","1.04939000"],["79819.36000000","0.00007000"],["79819.27000000","0.00008000"],["79818.98000000","0.00007000"],["79818.88000000","0.02100000"],["79818.75000000","0.00014000"],["79818.18000000","0.99203000"],["79818.06000000","0.00015000"],["79818.00000000","0.73400000"],["79817.50000000","0.03224000"],["79817.15000000","0.00026000"],["79817.09000000","0.34827000"],["79816.95000000","0.01157000"],["79816.90000000","0.00007000"],["79816.35000000","0.00007000"],["79816.15000000","0.62250000"],["79816.12000000","0.00011000"],["79816.00000000","0.02400000"],["79815.80000000","0.00072000"],["79815.50000000","0.36586000"],["79815.27000000","0.00008000"],["79815.06000000","0.54151000"],["79815.05000000","1.04939000"],["79815.00000000","0.00187000"],["79814.82000000","0.00007000"],["79814.27000000","0.00007000"],["79814.02000000","0.20250000"],["79814.01000000","0.00007000"],["79814.00000000","0.14936000"],["79813.74000000","0.00010000"],["79812.98000000","0.00010000"],["79812.75000000","0.00007000"],["79812.30000000","0.00008000"],["79812.00000000","0.02400000"],["79811.62000000","0.02541000"],["79811.60000000","0.00007000"],["79811.35000000","1.01177000"],["79811.34000000","1.87677000"],["79811.30000000","0.20631000"],["79810.79000000","0.00427000"],["79810.69000000","0.00615000"],["79810.67000000","0.00007000"],["79810.65000000","1.04939000"],["79810.29000000","0.02000000"],["79810.28000000","0.00007000"],["79810.00000000","0.02400000"],["79809.62000000","0.02541000"],["79809.16000000","0.00026000"],["79808.60000000","0.00007000"],["79808.00000000","0.02407000"],["79807.96000000","1.61408000"],["79807.19000000","0.00007000"],["79806.61000000","0.36711000"],["79806.60000000","0.06139000"],["79806.55000000","1.87677000"],["79806.52000000","0.00007000"],["79806.48000000","1.04939000"],["79806.44000000","0.00013000"],["79806.01000000","0.20250000"],["79806.00000000","0.02400000"],["79805.83000000","0.00012000"],["79805.76000000","0.00010000"],["79805.46000000","0.00424000"],["79805.15000000","0.02400000"],["79805.01000000","0.37600000"],["79804.91000000","0.00427000"],["79804.79000000","0.82263000"],["79804.59000000","0.00654000"],["79804.45000000","0.00007000"],["79804.30000000","0.02000000"],["79804.23000000","0.02208000"],["79804.22000000","0.02400000"],["79804.02000000","0.00007000"],["79804.00000000","0.02400000"],["79803.84000000","0.02207000"],["79803.35000000","0.00654000"],["79802.62000000","0.02000000"],["79802.37000000","0.00007000"],["79802.35000000","1.20055000"],["79802.34000000","1.04939000"],["79802.22000000","0.02000000"],["79802.09000000","0.00007000"],["79802.00000000","0.02400000"],["79800.92000000","0.00007000"],["79800.86000000","0.00026000"],["79800.30000000","0.00007000"],["79800.03000000","1.87677000"],["79800.00000000","0.82870000"],["79798.97000000","0.59501000"],["79798.23000000","0.00007000"],["79798.07000000","1.04939000"],["79798.06000000","0.00007000"],["79798.05000000","0.36586000"],["79798.00000000","0.02400000"],["79797.99000000","0.00200000"],["79797.78000000","0.00010000"],["79797.43000000","0.20250000"],["79796.16000000","0.00008000"],["79796.15000000","0.00007000"],["79796.08000000","0.00007000"],["79796.05000000","0.00007000"],["79796.00000000","0.02400000"],["79795.68000000","0.70572000"],["79795.67000000","1.24095000"],["79794.59000000","0.03224000"],["79794.58000000","0.00007000"],["79794.03000000","0.00007000"],["79794.00000000","0.02400000"],["79793.78000000","1.04939000"],["79793.68000000","0.01701000"],["79793.48000000","0.00253000"],["79792.66000000","0.00026000"],["79792.23000000","0.00413000"],["79792.03000000","0.00007000"],["79792.00000000","0.02414000"],["79791.21000000","0.82277000"],["79791.03000000","0.02614000"],["79790.85000000","0.30361000"],["79790.84000000","1.87677000"],["79790.58000000","0.00270000"],["79790.57000000","0.04224000"],["79790.26000000","0.00312000"],["79790.25000000","0.02000000"],["79790.00000000","0.02400000"],["79789.80000000","0.00010000"],["79789.73000000","1.04939000"],["79789.61000000","0.12331000"],["79789.43000000","0.20250000"],["79788.79000000","0.00536000"],["79788.77000000","0.00011000"],["79788.59000000","0.36586000"],["79788.53000000","0.00007000"],["79788.32000000","0.00007000"],["79788.09000000","0.00008000"],["79788.01000000","0.11461000"],["79788.00000000","0.02400000"],["79787.85000000","0.00007000"],["79787.36000000","0.00112000"],["79787.10000000","0.02200000"],["79787.05000000","0.02000000"],["79786.92000000","0.04697000"],["79786.30000000","0.02000000"],["79786.29000000","0.02000000"],["79786.17000000","0.02000000"],["79786.12000000","0.00014000"],["79786.05000000","0.00400000"],["79786.00000000","0.02400000"],["79785.69000000","2.92616000"],["79785.39000000","0.02541000"],["79785.17000000","0.02400000"],["79784.32000000","0.02000000"],["79784.25000000","0.02200000"],["79784.24000000","0.02400000"],["79784.04000000","0.00007000"],["79784.00000000","0.02400000"],["79783.70000000","0.00007000"],["79782.80000000","0.00007000"],["79782.00000000","0.02426000"],["79781.82000000","0.00010000"],["79781.80000000","0.03224000"],["79781.43000000","0.20250000"],["79780.99000000","0.00014000"],["79780.57000000","0.00007000"],["79780.56000000","0.00007000"],["79780.48000000","1.41525000"],["79780.02000000","0.00008000"],["79780.00000000","0.02400000"],["79779.15000000","1.99735000"],["79778.86000000","0.00100000"],["79778.18000000","0.00067000"],["79778.17000000","0.62594000"],["79778.16000000","0.00007000"],["79778.13000000","0.00007000"],["79778.00000000","0.02400000"],["79777.70000000","0.02200000"],["79777.06000000","0.03224000"],["79777.00000000","0.00012000"],["79776.36000000","0.02000000"],["79776.11000000","0.00007000"],["79776.10000000","1.87677000"],["79776.00000000","0.02407000"],["79775.97000000","0.02000000"],["79775.71000000","0.00018000"],["79775.41000000","0.00007000"],["79775.28000000","1.04939000"],["79774.14000000","0.00008000"],["79774.13000000","0.00009000"],["79774.00000000","0.02400000"],["79773.97000000","0.00026000"],["79773.84000000","0.00010000"],["79773.61000000","0.00010000"],["79773.51000000","0.04572000"],["79773.43000000","0.20250000"],["79773.13000000","0.00007000"],["79772.80000000","0.00007000"],["79772.69000000","0.00020000"],["79772.58000000","3.40281000"],["79772.00000000","0.02400000"],["79771.95000000","0.00008000"],["79771.26000000","0.00007000"],["79771.05000000","0.02600000"],["79770.99000000","0.00007000"],["79770.82000000","2.32416000"],["79770.39000000","0.36586000"],["79770.15000000","0.00007000"],["79770.00000000","0.02917000"],["79769.79000000","3.76170000"],["79769.69000000","1.04939000"],["79769.41000000","0.03224000"],["79769.12000000","0.00010000"],["79768.85000000","0.00007000"],["79768.08000000","0.00007000"],["79768.00000000","0.02400000"],["79767.12000000","0.02200000"],["79767.07000000","0.02000000"],["79766.71000000","0.00007000"],["79766.66000000","0.00016000"],["79766.32000000","0.02000000"],["79766.31000000","0.02000000"],["79766.19000000","0.02000000"],["79766.00000000","0.02482000"],["79765.99000000","0.00026000"],["79765.86000000","0.00010000"],["79765.44000000","0.20250000"],["79765.25000000","0.01253000"],["79765.04000000","0.00014000"],["79764.70000000","0.00541000"],["79764.51000000","0.00007000"],["79764.00000000","0.02400000"],["79763.88000000","0.00008000"],["79762.96000000","0.00007000"],["79762.46000000","0.04585000"],["79762.26000000","0.36586000"],["79762.12000000","0.00007000"],["79762.00000000","0.02400000"],["79761.89000000","0.00200000"],["79761.88000000","0.00008000"],["79761.84000000","1.24148000"],["79760.16000000","0.00390000"],["79760.08000000","0.00007000"],["79760.00000000","0.02625000"],["79759.28000000","0.00218000"],["79758.00000000","0.02400000"],["79757.99000000","0.00007000"],["79757.88000000","0.00010000"],["79757.62000000","0.00007000"],["79757.52000000","0.00026000"],["79757.45000000","0.20250000"],["79757.41000000","0.00231000"],["79757.38000000","0.00059000"],["79757.28000000","0.00007000"],["79756.79000000","0.03224000"],["79756.43000000","0.00501000"],["79756.00000000","0.02400000"],["79755.93000000","0.00007000"],["79755.81000000","0.00008000"],["79755.14000000","0.00072000"],["79755.00000000","0.09659000"],["79754.67000000","0.00007000"],["79754.20000000","0.00126000"],["79754.18000000","0.00007000"],["79754.12000000","0.00400000"],["79754.00000000","0.02400000"],["79752.24000000","0.00014000"],["79752.12000000","0.00007000"],["79752.06000000","0.00007000"],["79752.00000000","0.02400000"],["79751.41000000","0.00270000"],["79750.52000000","0.00007000"],["79750.00000000","0.02799000"],["79749.90000000","0.00010000"],["79749.52000000","0.00007000"],["79749.46000000","0.20250000"],["79749.37000000","0.00026000"],["79748.08000000","0.00007000"],["79748.00000000","0.02400000"],["79747.88000000","0.36586000"],["79747.74000000","0.00008000"],["79746.89000000","0.00160000"],["79746.37000000","0.00007000"],["79746.04000000","0.08730000"],["79746.00000000","0.02400000"],["79745.46000000","0.00016000"],["79744.74000000","0.00007000"],["79744.00000000","0.02407000"],["79743.95000000","0.00200000"],["79743.94000000","0.00752000"],["79743.28000000","0.25000000"],["79742.44000000","0.01306000"],["79742.19000000","0.00007000"],["79742.00000000","0.02400000"],["79741.92000000","0.00010000"],["79741.76000000","0.00007000"],["79741.47000000","0.20250000"],["79741.34000000","0.00394000"],["79740.15000000","0.00026000"],["79740.00000000","0.05014000"],["79739.67000000","0.00008000"],["79739.48000000","0.00007000"],["79738.93000000","0.00100000"],["79738.83000000","0.00016000"],["79738.21000000","0.00007000"],["79738.00000000","0.02400000"],["79737.27000000","0.12897000"],["79736.72000000","0.07529000"],["79736.67000000","0.00007000"],["79736.47000000","0.00376000"],["79736.16000000","0.00007000"],["79736.04000000","0.00007000"],["79736.01000000","0.00007000"],["79736.00000000","0.02400000"],["79734.24000000","0.00010000"],["79734.01000000","0.00125000"],["79734.00000000","0.02407000"],["79733.94000000","0.00010000"],["79733.69000000","0.00007000"],["79733.50000000","0.36586000"],["79732.48000000","0.00059000"],["79732.00000000","0.02400000"],["79731.98000000","0.00026000"],["79731.70000000","0.00007000"],["79731.60000000","0.00008000"],["79730.76000000","0.00035000"],["79730.22000000","0.00014000"],["79730.00000000","0.03474000"],["79729.79000000","0.00007000"],["79729.72000000","0.00111000"],["79729.70000000","0.00007000"],["79729.27000000","0.00012000"],["79729.04000000","0.00042000"],["79728.65000000","0.00012000"],["79728.64000000","0.00007000"],["79728.57000000","0.00020000"],["79728.40000000","0.00413000"],["79728.00000000","0.02400000"],["79727.74000000","0.01961000"],["79727.60000000","0.04410000"],["79727.14000000","0.00009000"],["79727.11000000","0.00048000"],["79727.00000000","0.00251000"],["79726.86000000","0.00007000"],["79726.69000000","3.76373000"],["79726.68000000","0.00008000"],["79726.24000000","0.00007000"],["79726.00000000","0.02400000"],["79725.96000000","0.00010000"],["79725.64000000","0.00007000"],["79724.07000000","0.00007000"],["79724.00000000","0.02426000"],["79723.98000000","0.00260000"],["79723.52000000","0.00010000"],["79723.40000000","0.00009000"],["79722.24000000","0.00007000"],["79722.00000000","0.02400000"],["79721.94000000","0.00007000"],["79721.64000000","0.00007000"],["79721.57000000","0.00007000"],["79721.30000000","0.03224000"],["79720.20000000","0.00397000"],["79720.00000000","0.02550000"],["79719.42000000","0.00007000"],["79719.12000000","0.36586000"],["79718.52000000","0.00007000"],["79718.16000000","0.00009000"],["79718.00000000","0.02400000"],["79717.58000000","0.00023000"],["79717.43000000","0.00170000"],["79717.34000000","0.00007000"],["79716.78000000","0.00062000"],["79716.74000000","0.80000000"],["79716.66000000","0.00010000"],["79716.45000000","0.00007000"],["79716.03000000","0.00008000"],["79716.00000000","0.02400000"],["79715.91000000","0.00026000"],["79715.53000000","0.00017000"],["79715.46000000","0.00008000"],["79715.28000000","0.00007000"],["79714.36000000","0.00007000"],["79714.31000000","0.00020000"],["79714.28000000","0.00013000"],["79714.20000000","0.00016000"],["79714.00000000","0.02400000"],["79713.90000000","0.00165000"],["79713.76000000","0.00010000"],["79713.56000000","0.00007000"],["79713.45000000","0.00014000"],["79712.53000000","0.00008000"],["79712.00000000","0.02407000"],["79711.26000000","0.00035000"],["79711.24000000","0.02576000"],["79711.23000000","0.05082000"],["79711.00000000","0.00270000"],["79710.76000000","0.00011000"],["79710.75000000","0.00030000"],["79710.72000000","0.00007000"],["79710.54000000","0.00007000"],["79710.01000000","0.00125000"],["79710.00000000","0.02467000"],["79709.77000000","0.03499000"],["79709.57000000","0.00007000"],["79709.06000000","0.00007000"],["79708.33000000","0.00007000"],["79708.00000000","0.02400000"],["79707.66000000","0.00015000"],["79707.50000000","0.00026000"],["79707.44000000","0.00021000"],["79706.59000000","0.03224000"],["79706.27000000","0.00007000"],["79706.23000000","0.00400000"],["79706.00000000","0.02400000"],["79705.88000000","0.00959000"],["79705.59000000","0.00007000"],["79705.45000000","0.00022000"],["79705.00000000","0.00010000"],["79704.92000000","0.00007000"],["79704.88000000","0.00007000"],["79704.74000000","0.36586000"],["79704.24000000","0.00007000"],["79704.00000000","0.02462000"],["79703.75000000","0.00013000"],["79703.74000000","0.00091000"],["79703.71000000","0.00021000"],["79703.56000000","0.00023000"],["79703.52000000","0.00123000"],["79703.38000000","0.00007000"],["79703.19000000","0.00044000"],["79702.92000000","0.00008000"],["79702.91000000","0.07182000"],["79702.82000000","0.00015000"],["79702.64000000","0.00007000"],["79702.54000000","0.00024000"],["79702.00000000","0.02424000"],["79701.79000000","0.00008000"],["79701.66000000","0.00013000"],["79701.60000000","0.00007000"],["79701.33000000","0.00010000"],["79701.32000000","0.00034000"],["79700.91000000","0.00023000"],["79700.90000000","0.01267000"],["79700.89000000","0.00024000"],["79700.88000000","0.00010000"],["79700.85000000","0.00109000"],["79700.51000000","0.00033000"],["79700.48000000","0.00016000"],["79700.29000000","0.00013000"],["79700.28000000","0.05082000"],["79700.15000000","0.00093000"],["79700.10000000","0.00012000"],["79700.04000000","0.05623000"],["79700.00000000","1.18142000"],["79699.86000000","0.00079000"],["79699.77000000","0.00010000"],["79699.72000000","0.00012000"],["79699.59000000","0.00043000"],["79699.51000000","0.00026000"],["79699.47000000","0.09188000"],["79699.39000000","0.00007000"],["79699.32000000","0.00008000"],["79699.20000000","0.00007000"],["79699.02000000","0.00015000"],["79699.00000000","0.13279000"],["79698.79000000","0.00013000"],["79698.70000000","0.00007000"],["79698.63000000","0.00008000"],["79698.48000000","0.00007000"],["79697.89000000","0.00007000"],["79697.86000000","0.00012000"],["79697.56000000","0.00007000"],["79697.50000000","0.00654000"],["79697.09000000","0.00010000"],["79696.96000000","0.00010000"],["79696.91000000","0.00007000"],["79696.86000000","0.00013000"],["79696.59000000","0.00015000"],["79696.39000000","0.00032000"],["79696.10000000","0.00007000"],["79695.64000000","0.00012000"],["79695.39000000","0.00011000"],["79695.21000000","0.03224000"],["79695.12000000","0.00010000"],["79694.95000000","0.00380000"],["79694.87000000","0.00010000"],["79694.84000000","0.00134000"],["79694.71000000","0.00009000"],["79694.66000000","0.00007000"],["79694.44000000","0.00031000"],["79694.34000000","0.00035000"],["79694.28000000","0.00008000"],["79694.22000000","0.00048000"],["79694.05000000","0.00050000"],["79694.00000000","0.00087000"],["79693.69000000","0.00012000"],["79693.58000000","0.00020000"],["79693.43000000","0.00118000"],["79693.33000000","0.00019000"],["79693.13000000","0.00072000"],["79692.59000000","0.00025000"],["79692.55000000","0.00007000"],["79692.48000000","0.00007000"],["79692.32000000","0.00951000"],["79692.30000000","0.00056000"],["79692.22000000","0.00028000"],["79692.07000000","0.00530000"],["79691.61000000","0.36586000"],["79691.34000000","0.00009000"],["79691.01000000","0.00100000"],["79690.79000000","0.00020000"],["79690.52000000","0.00159000"],["79690.50000000","0.00022000"],["79690.37000000","0.00008000"],["79690.35000000","0.00014000"],["79690.31000000","0.00009000"],["79690.30000000","0.00007000"],["79690.00000000","0.00050000"],["79689.83000000","0.00007000"],["79689.80000000","0.00026000"],["79689.65000000","0.00007000"],["79689.59000000","0.00030000"],["79689.44000000","0.00026000"],["79689.19000000","0.00028000"],["79689.16000000","0.00122000"],["79688.88000000","0.00013000"],["79688.76000000","0.00012000"],["79688.63000000","0.00098000"],["79688.58000000","4.45182000"],["79688.40000000","0.00019000"],["79688.34000000","0.00007000"],["79688.28000000","0.00007000"],["79687.85000000","0.00009000"],["79687.77000000","0.00023000"],["79687.55000000","0.00007000"],["79687.50000000","0.00685000"],["79687.44000000","0.00007000"],["79687.36000000","0.00023000"],["79687.12000000","0.00012000"],["79687.03000000","0.00010000"],["79686.99000000","0.00023000"],["79686.89000000","0.01000000"],["79686.72000000","0.00014000"],["79686.68000000","0.00007000"],["79685.71000000","0.00008000"],["79685.56000000","0.00013000"],["79684.94000000","0.00045000"],["79684.66000000","0.00025000"],["79684.65000000","0.00501000"],["79684.56000000","0.00007000"],["79684.52000000","0.00007000"],["79684.21000000","0.00457000"],["79684.15000000","0.00013000"],["79683.74000000","0.00007000"],["79683.66000000","0.11607000"],["79683.58000000","0.00021000"],["79683.54000000","0.00007000"],["79683.48000000","0.00023000"],["79683.18000000","0.00008000"],["79683.15000000","0.00374000"],["79683.07000000","0.00008000"],["79682.75000000","0.00020000"],["79682.72000000","0.00007000"],["79682.35000000","0.00008000"],["79682.12000000","0.00007000"],["79681.92000000","0.00007000"],["79681.85000000","0.00007000"],["79681.81000000","0.00010000"],["79681.62000000","0.00025000"],["79681.51000000","0.00132000"],["79681.46000000","0.00026000"],["79681.39000000","0.00011000"],["79681.02000000","0.36586000"],["79681.01000000","3.76589000"],["79680.97000000","0.00010000"],["79680.88000000","0.00014000"],["79680.85000000","0.00007000"],["79680.82000000","0.00010000"],["79680.38000000","0.00023000"],["79680.36000000","0.00148000"],["79680.32000000","0.00050000"],["79680.11000000","0.00019000"],["79680.00000000","0.02056000"],["79679.90000000","0.00144000"],["79679.89000000","0.00033000"],["79679.31000000","0.00007000"],["79679.17000000","0.00010000"],["79679.06000000","0.00010000"],["79679.02000000","0.00009000"],["79678.57000000","0.00028000"],["79678.27000000","0.00048000"],["79678.17000000","0.00007000"],["79677.97000000","0.00010000"],["79677.58000000","0.00012000"],["79677.53000000","0.00009000"],["79677.47000000","0.00454000"],["79677.41000000","0.00130000"],["79677.21000000","0.00011000"],["79677.06000000","0.00007000"],["79676.94000000","0.01389000"],["79676.89000000","0.00245000"],["79676.76000000","0.00039000"],["79676.60000000","0.00190000"],["79676.47000000","0.00653000"],["79676.40000000","0.00091000"],["79676.32000000","1.20000000"],["79675.91000000","0.00007000"],["79675.86000000","0.00053000"],["79675.78000000","0.00021000"],["79675.70000000","0.00008000"],["79675.67000000","0.00156000"],["79675.51000000","0.00007000"],["79675.33000000","0.00090000"],["79675.00000000","0.00012000"],["79674.66000000","0.00014000"],["79674.64000000","0.01572000"],["79674.47000000","0.00060000"],["79674.41000000","0.00094000"],["79674.33000000","0.00007000"],["79674.14000000","0.00057000"],["79673.70000000","0.00013000"],["79673.64000000","0.00007000"],["79673.37000000","0.00026000"],["79673.33000000","0.00025000"],["79673.20000000","0.00020000"],["79673.14000000","0.00008000"],["79672.84000000","0.00062000"],["79672.69000000","0.00012000"],["79672.31000000","0.00010000"],["79672.02000000","0.00007000"],["79672.01000000","0.00270000"],["79671.91000000","0.00007000"],["79671.90000000","0.00200000"],["79671.39000000","0.00010000"],["79670.91000000","0.11607000"],["79670.66000000","0.00007000"],["79670.58000000","0.00031000"],["79670.26000000","0.00012000"],["79670.14000000","0.00016000"],["79670.01000000","0.00013000"],["79670.00000000","0.00074000"],["79669.97000000","0.00008000"],["79669.86000000","0.00013000"],["79669.78000000","0.00078000"],["79669.77000000","0.00125000"],["79669.70000000","0.00007000"],["79669.48000000","0.00105000"],["79668.89000000","0.00368000"],["79668.59000000","0.00044000"],["79668.58000000","0.00065000"],["79668.49000000","0.00010000"],["79668.13000000","0.00864000"],["79668.00000000","0.03000000"],["79667.91000000","0.00007000"],["79667.46000000","0.00009000"],["79667.45000000","0.00043000"],["79667.27000000","0.00269000"],["79667.17000000","0.00008000"],["79667.09000000","0.03229000"],["79667.04000000","0.00008000"],["79667.03000000","0.00029000"],["79666.66000000","0.03573000"],["79666.65000000","0.36586000"],["79666.60000000","0.00011000"],["79666.55000000","0.00124000"],["79666.52000000","0.00034000"],["79666.40000000","0.00010000"],["79666.28000000","0.00137000"],["79666.19000000","0.00602000"],["79666.10000000","0.00007000"],["79666.00000000","0.00215000"],["79665.88000000","0.00281000"],["79665.61000000","0.00007000"],["79665.36000000","0.00038000"],["79665.35000000","0.00011000"],["79665.25000000","0.01255000"],["79665.22000000","0.00007000"],["79664.73000000","0.00009000"],["79664.62000000","0.00414000"],["79664.39000000","0.00055000"],["79664.16000000","0.00007000"],["79664.01000000","0.00055000"],["79663.92000000","0.00007000"],["79663.85000000","0.00048000"],["79663.83000000","0.06000000"],["79663.55000000","0.00011000"],["79663.45000000","0.00062000"],["79663.37000000","0.00007000"],["79663.24000000","0.00022000"],["79663.14000000","0.00012000"],["79663.08000000","0.00020000"],["79663.03000000","0.00007000"],["79662.85000000","0.00183000"],["79662.56000000","0.00007000"],["79662.33000000","0.00031000"],["79662.03000000","0.00031000"],["79661.66000000","0.00014000"],["79661.65000000","0.00012000"],["79661.30000000","0.00413000"],["79661.26000000","0.00007000"],["79661.19000000","0.00023000"],["79661.18000000","0.00007000"],["79661.15000000","0.00070000"],["79661.11000000","0.00011000"],["79660.93000000","0.00007000"],["79660.69000000","0.00008000"],["79660.60000000","0.23795000"],["79660.00000000","0.00390000"],["79659.82000000","0.00010000"],["79659.78000000","0.00012000"],["79659.77000000","0.00010000"],["79659.75000000","0.00011000"],["79659.53000000","0.00008000"],["79659.36000000","0.00007000"],["79659.09000000","0.00075000"],["79658.95000000","0.11607000"],["79658.92000000","0.00023000"],["79658.70000000","0.00036000"],["79658.36000000","0.00007000"],["79658.26000000","0.00065000"],["79658.01000000","0.00087000"],["79657.99000000","0.00010000"],["79657.90000000","0.06552000"],["79657.87000000","0.00010000"],["79657.78000000","0.00007000"],["79657.44000000","0.00011000"],["79657.35000000","0.00026000"],["79657.14000000","0.00134000"],["79656.94000000","0.00007000"],["79656.71000000","0.00016000"],["79656.64000000","0.00065000"],["79656.50000000","0.00048000"],["79656.49000000","0.00008000"],["79656.43000000","0.00009000"],["79656.25000000","0.00023000"],["79656.22000000","0.00752000"],["79655.94000000","0.01762000"],["79655.50000000","0.00010000"],["79655.44000000","0.00014000"],["79655.36000000","0.00017000"],["79655.17000000","0.00122000"],["79654.94000000","0.00017000"],["79654.76000000","0.00007000"],["79654.67000000","0.00080000"],["79654.56000000","0.00080000"],["79654.47000000","0.00007000"],["79654.27000000","0.00012000"],["79654.11000000","0.00008000"],["79653.84000000","0.00090000"],["79653.57000000","0.00044000"],["79652.73000000","0.00028000"],["79652.70000000","0.00280000"],["79652.52000000","0.00007000"],["79652.36000000","0.00013000"],["79652.29000000","0.00771000"],["79652.28000000","0.36586000"],["79652.25000000","0.00007000"],["79652.15000000","0.00178000"],["79651.98000000","0.00181000"],["79651.21000000","0.00023000"],["79651.20000000","0.00010000"],["79651.15000000","0.00116000"],["79650.98000000","0.00009000"],["79650.97000000","0.00048000"],["79650.90000000","0.00008000"]],"asks":[["79858.00000000","0.37196000"],["79858.01000000","0.00062000"],["79858.02000000","0.00013000"],["79858.16000000","0.00007000"],["79858.38000000","0.00007000"],["79858.42000000","0.00007000"],["79859.35000000","0.00007000"],["79859.49000000","0.00007000"],["79859.99000000","0.00007000"],["79860.00000000","0.02428000"],["79860.03000000","0.00851000"],["79860.30000000","0.00007000"],["79860.47000000","0.00007000"],["79860.48000000","0.06324000"],["79860.49000000","0.00007000"],["79860.88000000","0.00007000"],["79860.89000000","0.06331000"],["79860.90000000","0.04847000"],["79860.99000000","0.00358000"],["79861.02000000","0.00007000"],["79861.03000000","0.01797000"],["79861.18000000","0.00007000"],["79861.31000000","0.01397000"],["79861.32000000","0.00007000"],["79861.71000000","0.00007000"],["79861.72000000","0.06324000"],["79861.99000000","0.00007000"],["79862.00000000","0.02414000"],["79862.04000000","0.00007000"],["79862.33000000","0.00007000"],["79862.34000000","0.05721000"],["79862.56000000","0.00007000"],["79862.59000000","0.01660000"],["79862.95000000","0.00007000"],["79862.96000000","0.06324000"],["79863.57000000","0.00007000"],["79863.58000000","0.06324000"],["79863.87000000","0.01667000"],["79863.98000000","0.00013000"],["79864.00000000","0.02414000"],["79864.20000000","0.06317000"],["79864.25000000","0.00007000"],["79864.46000000","0.00202000"],["79864.54000000","0.30220000"],["79864.55000000","0.33819000"],["79864.63000000","0.00007000"],["79864.74000000","0.00007000"],["79864.82000000","0.06317000"],["79864.87000000","0.00320000"],["79864.92000000","0.00008000"],["79865.19000000","0.00007000"],["79865.21000000","0.00026000"],["79865.44000000","0.06317000"],["79865.92000000","0.00007000"],["79865.97000000","0.00014000"],["79865.99000000","0.26574000"],["79866.00000000","0.02400000"],["79866.68000000","0.06317000"],["79866.71000000","0.00007000"],["79866.80000000","0.06517000"],["79866.96000000","0.06317000"],["79866.97000000","0.12520000"],["79867.03000000","0.00125000"],["79867.17000000","0.00070000"],["79867.44000000","0.00007000"],["79867.48000000","0.00007000"],["79867.49000000","0.00048000"],["79868.00000000","0.02400000"],["79868.52000000","0.06317000"],["79868.53000000","0.10939000"],["79868.79000000","0.00015000"],["79868.82000000","0.00400000"],["79868.91000000","0.00927000"],["79869.06000000","0.00014000"],["79869.16000000","0.06317000"],["79869.78000000","0.06317000"],["79869.80000000","0.00007000"],["79869.83000000","0.00010000"],["79869.97000000","0.00007000"],["79870.00000000","0.02400000"],["79870.51000000","0.00710000"],["79870.63000000","0.00007000"],["79870.86000000","0.00007000"],["79871.02000000","0.06317000"],["79871.26000000","0.00156000"],["79871.37000000","0.00400000"],["79871.64000000","0.06317000"],["79871.82000000","0.06317000"],["79871.83000000","0.25745000"],["79872.00000000","0.02407000"],["79872.02000000","0.00007000"],["79872.08000000","0.08576000"],["79872.88000000","0.06317000"],["79872.92000000","0.00626000"],["79872.93000000","0.00014000"],["79872.94000000","0.00007000"],["79872.97000000","0.01623000"],["79873.30000000","0.00026000"],["79873.50000000","0.06317000"],["79873.55000000","0.00047000"],["79873.68000000","0.00007000"],["79873.74000000","0.00400000"],["79873.78000000","0.00100000"],["79873.97000000","0.00008000"],["79873.98000000","0.00015000"],["79874.00000000","0.02400000"],["79874.12000000","0.06317000"],["79874.21000000","0.00047000"],["79874.28000000","0.09464000"],["79874.59000000","0.06317000"],["79874.60000000","0.02000000"],["79874.62000000","0.02000000"],["79874.69000000","0.01200000"],["79874.72000000","0.20631000"],["79874.74000000","0.00007000"],["79875.02000000","0.00007000"],["79875.37000000","0.02000000"],["79875.43000000","0.02000000"],["79875.49000000","0.02000000"],["79875.55000000","0.02000000"],["79875.94000000","1.02267000"],["79875.95000000","2.92616000"],["79875.98000000","0.00007000"],["79876.00000000","0.02400000"],["79876.11000000","0.00400000"],["79876.27000000","0.10368000"],["79876.80000000","0.00014000"],["79876.86000000","0.00008000"],["79876.97000000","0.00694000"],["79877.09000000","0.00007000"],["79877.41000000","0.12519000"],["79877.75000000","0.02000000"],["79877.76000000","0.00192000"],["79877.81000000","0.00010000"],["79877.97000000","0.20258000"],["79877.99000000","0.00007000"],["79878.00000000","0.02400000"],["79878.02000000","0.00007000"],["79878.48000000","0.00400000"],["79878.53000000","0.02000000"],["79878.68000000","0.02000000"],["79878.88000000","0.00007000"],["79879.16000000","0.02000000"],["79879.17000000","0.01000000"],["79879.33000000","0.04200000"],["79879.56000000","0.04000000"],["79879.64000000","0.02253000"],["79879.80000000","0.00007000"],["79879.94000000","0.00400000"],["79879.98000000","0.19019000"],["79880.00000000","0.11825000"],["79880.14000000","0.00007000"],["79880.46000000","0.00250000"],["79880.67000000","0.00014000"],["79880.70000000","0.86031000"],["79880.73000000","0.02000000"],["79880.77000000","0.00250000"],["79880.96000000","0.00938000"],["79881.25000000","0.00007000"],["79881.37000000","0.02000000"],["79881.39000000","0.00400000"],["79881.44000000","0.00007000"],["79881.92000000","1.41525000"],["79881.93000000","0.00626000"],["79881.94000000","0.00007000"],["79882.00000000","0.02400000"],["79882.04000000","1.87677000"],["79882.17000000","0.12000000"],["79882.48000000","0.12518000"],["79882.63000000","0.00007000"],["79882.87000000","0.00072000"],["79882.92000000","0.00400000"],["79882.98000000","0.00012000"],["79883.05000000","0.00077000"],["79883.13000000","0.00026000"],["79883.32000000","0.00007000"],["79883.98000000","0.00400000"],["79884.00000000","0.02400000"],["79884.54000000","0.00014000"],["79884.93000000","0.00008000"],["79885.18000000","0.00007000"],["79885.20000000","1.03779000"],["79885.29000000","0.00625000"],["79885.40000000","0.00007000"],["79885.59000000","0.00400000"],["79885.79000000","0.00010000"],["79885.95000000","0.00008000"],["79886.00000000","0.02400000"],["79886.58000000","0.00500000"],["79887.35000000","1.87677000"],["79887.48000000","0.00007000"],["79887.60000000","1.04939000"],["79887.88000000","0.33805000"],["79888.00000000","0.58999000"],["79888.19000000","0.00012000"],["79888.41000000","0.00014000"],["79888.68000000","0.00400000"],["79888.84000000","0.00007000"],["79888.95000000","0.00912000"],["79889.20000000","0.00007000"],["79889.48000000","0.00573000"],["79889.56000000","0.00007000"],["79889.74000000","0.54054000"],["79889.94000000","0.00008000"],["79890.00000000","0.12039000"],["79890.24000000","0.00059000"],["79891.28000000","0.00026000"],["79891.52000000","0.36586000"],["79891.63000000","0.00007000"],["79891.66000000","1.04939000"],["79891.98000000","0.00400000"],["79892.00000000","0.02400000"],["79892.25000000","0.01270000"],["79892.28000000","0.00014000"],["79892.48000000","0.00007000"],["79892.50000000","0.00400000"],["79892.81000000","0.00112000"],["79892.92000000","0.02000000"],["79893.00000000","0.00008000"],["79893.01000000","0.62190000"],["79893.08000000","0.00130000"],["79893.71000000","0.00007000"],["79893.77000000","0.00010000"],["79893.94000000","0.00008000"],["79893.95000000","1.52939000"],["79893.96000000","1.87677000"],["79894.00000000","0.02400000"],["79894.42000000","0.03224000"],["79894.68000000","0.42957000"],["79894.69000000","0.00007000"],["79894.74000000","0.00007000"],["79895.28000000","0.33802000"],["79895.67000000","1.38741000"],["79895.76000000","0.00007000"],["79895.78000000","0.00010000"],["79895.84000000","0.50446000"],["79896.00000000","0.02400000"],["79896.04000000","0.10000000"],["79896.15000000","0.00014000"],["79896.44000000","0.00400000"],["79896.53000000","0.86297000"],["79896.96000000","0.00007000"],["79897.36000000","0.62595000"],["79897.86000000","0.00007000"],["79897.91000000","0.00007000"],["79897.93000000","0.00008000"],["79898.00000000","0.03400000"],["79898.01000000","0.00007000"],["79898.04000000","0.00375000"],["79898.13000000","0.02480000"],["79898.40000000","0.00400000"],["79898.66000000","0.00189000"],["79898.91000000","1.87677000"],["79899.00000000","0.70000000"],["79899.28000000","0.00026000"],["79899.48000000","0.09388000"],["79899.94000000","0.00007000"],["79899.98000000","1.25701000"],["79899.99000000","1.04939000"],["79900.00000000","1.02675000"],["79900.02000000","0.00007000"],["79900.28000000","0.02000000"],["79900.46000000","0.00007000"],["79900.80000000","0.20250000"],["79901.07000000","0.00008000"],["79901.15000000","0.04643000"],["79901.28000000","0.02493000"],["79901.57000000","0.02000000"],["79901.75000000","0.00010000"],["79901.86000000","0.36586000"],["79901.96000000","0.33799000"],["79901.98000000","0.02000000"],["79902.00000000","0.02400000"],["79902.02000000","0.00007000"],["79902.18000000","0.00400000"],["79902.23000000","0.02000000"],["79902.40000000","0.01270000"],["79902.79000000","0.00007000"],["79903.76000000","1.18887000"],["79903.77000000","1.87677000"],["79903.89000000","0.00007000"],["79904.00000000","0.02407000"],["79904.10000000","0.00007000"],["79904.55000000","0.00400000"],["79904.72000000","0.00007000"],["79905.24000000","0.00007000"],["79905.98000000","0.00007000"],["79906.00000000","0.02400000"],["79906.01000000","0.00200000"],["79906.02000000","0.00375000"],["79906.25000000","1.20242000"],["79906.41000000","0.80833000"],["79907.36000000","1.23922000"],["79907.40000000","0.00007000"],["79907.52000000","0.00026000"],["79908.00000000","0.02400000"],["79908.25000000","0.00007000"],["79908.54000000","1.18878000"],["79908.55000000","1.04939000"],["79908.79000000","0.20250000"],["79908.96000000","0.02000000"],["79909.01000000","1.87677000"],["79909.14000000","0.00008000"],["79909.39000000","0.02000000"],["79909.44000000","0.62585000"],["79909.73000000","0.00010000"],["79909.83000000","0.02000000"],["79909.85000000","0.36586000"],["79909.98000000","0.02000000"],["79909.99000000","0.00270000"],["79910.00000000","0.02400000"],["79910.12000000","0.02000000"],["79910.33000000","0.00895000"],["79910.51000000","0.00007000"],["79910.82000000","0.00621000"],["79911.12000000","0.00425000"],["79911.46000000","0.03224000"],["79911.72000000","0.00007000"],["79911.78000000","0.02000000"],["79911.98000000","0.00007000"],["79912.00000000","0.02626000"],["79912.48000000","0.00007000"],["79912.64000000","0.41788000"],["79912.67000000","0.02000000"],["79912.90000000","0.02000000"],["79913.00000000","0.05000000"],["79913.01000000","0.34474000"],["79913.14000000","0.97258000"],["79913.15000000","0.00427000"],["79913.70000000","0.00427000"],["79913.77000000","0.02000000"],["79913.88000000","0.00007000"],["79913.94000000","0.00100000"],["79913.99000000","0.00007000"],["79914.00000000","0.02400000"],["79914.48000000","0.00007000"],["79915.63000000","0.00026000"],["79915.79000000","0.00007000"],["79915.80000000","0.01139000"],["79915.98000000","0.00007000"],["79916.00000000","0.02400000"],["79916.10000000","0.00007000"],["79916.61000000","0.01270000"],["79916.78000000","0.20250000"],["79916.84000000","0.02200000"],["79917.21000000","0.00008000"],["79917.52000000","0.00218000"],["79917.71000000","0.00010000"],["79917.90000000","0.99008000"],["79917.91000000","1.04939000"],["79917.92000000","0.36586000"],["79918.00000000","0.02400000"],["79918.36000000","0.00007000"],["79918.43000000","0.83162000"],["79918.60000000","1.87677000"],["79918.64000000","0.00007000"],["79919.36000000","0.00075000"],["79919.58000000","0.25000000"],["79919.99000000","0.84160000"],["79920.00000000","1.02767000"],["79920.24000000","0.00007000"],["79920.26000000","0.02000000"],["79920.37000000","0.00007000"],["79920.60000000","0.82144000"],["79920.72000000","0.00007000"],["79920.78000000","1.23901000"],["79921.06000000","0.00007000"],["79921.54000000","0.02000000"],["79921.96000000","0.02000000"],["79922.00000000","0.02400000"],["79922.01000000","0.01876000"],["79922.21000000","0.02000000"],["79922.42000000","0.00413000"],["79922.47000000","0.00007000"],["79922.69000000","0.03024000"],["79922.80000000","0.00007000"],["79923.70000000","0.00026000"],["79924.00000000","0.02400000"],["79924.31000000","0.00200000"],["79924.60000000","0.00007000"],["79925.28000000","0.00008000"],["79925.52000000","0.00311000"],["79925.53000000","0.17850000"],["79925.54000000","0.20250000"],["79925.69000000","0.00010000"],["79926.00000000","0.02400000"],["79926.29000000","0.36586000"],["79926.51000000","0.00110000"],["79926.95000000","0.00007000"],["79926.98000000","0.00007000"],["79927.68000000","0.00007000"],["79928.00000000","0.02407000"],["79928.15000000","1.53543000"],["79928.16000000","1.04939000"],["79928.18000000","1.87677000"],["79928.69000000","0.03224000"],["79928.94000000","0.02000000"],["79929.04000000","0.04698000"],["79929.28000000","1.23888000"],["79929.37000000","0.02000000"],["79929.82000000","0.02000000"],["79929.85000000","0.00007000"],["79929.90000000","0.00007000"],["79929.96000000","0.02000000"],["79930.00000000","0.02400000"],["79930.09000000","0.02000000"],["79931.76000000","0.02000000"],["79931.97000000","0.00007000"],["79932.00000000","0.02400000"],["79932.09000000","0.00026000"],["79932.39000000","0.00400000"],["79932.66000000","0.02000000"],["79933.08000000","0.00007000"],["79933.19000000","0.00007000"],["79933.67000000","0.00010000"],["79933.71000000","0.49239000"],["79933.72000000","1.23881000"],["79933.75000000","0.02000000"],["79933.98000000","0.00007000"],["79934.00000000","0.02400000"],["79935.15000000","0.00010000"],["79935.37000000","0.00070000"],["79935.45000000","0.36586000"],["79935.76000000","0.00007000"],["79935.86000000","0.00008000"],["79935.99000000","0.00007000"],["79936.00000000","0.02407000"],["79936.82000000","0.02200000"],["79937.34000000","0.00007000"],["79937.73000000","0.94615000"],["79937.74000000","1.04939000"],["79937.76000000","1.87677000"],["79937.91000000","0.01696000"],["79938.00000000","0.02400000"],["79938.01000000","0.20250000"],["79938.07000000","0.00007000"],["79939.90000000","0.87026000"],["79939.99000000","0.00047000"],["79940.00000000","0.24051000"],["79940.09000000","0.00537000"],["79940.18000000","2.31259000"],["79941.06000000","0.00007000"],["79941.11000000","0.00026000"],["79941.42000000","0.00008000"],["79941.65000000","0.00010000"],["79942.00000000","0.02400000"],["79943.20000000","0.00200000"],["79943.52000000","0.00007000"],["79943.58000000","0.00007000"],["79943.59000000","0.38248000"],["79943.64000000","0.00007000"],["79943.65000000","0.00007000"],["79943.69000000","1.12375000"],["79943.84000000","0.03224000"],["79944.00000000","0.02400000"],["79945.68000000","0.00021000"],["79945.82000000","0.00007000"],["79945.89000000","0.00100000"],["79945.99000000","0.00007000"],["79946.00000000","0.02400000"],["79946.19000000","0.00014000"],["79947.34000000","1.04939000"],["79947.35000000","1.87677000"],["79947.59000000","1.99314000"],["79947.99000000","0.10577000"],["79948.00000000","0.22650000"],["79949.32000000","0.00007000"],["79949.33000000","0.00026000"],["79949.63000000","0.00010000"],["79949.81000000","0.00007000"],["79949.99000000","0.00270000"],["79950.00000000","0.03129000"],["79950.19000000","0.09327000"],["79951.28000000","0.00007000"],["79951.62000000","2.09800000"],["79951.63000000","0.36586000"],["79952.00000000","0.02400000"],["79952.91000000","0.11830000"],["79953.16000000","0.00007000"],["79953.97000000","0.00007000"],["79953.99000000","0.00274000"],["79954.00000000","0.02400000"],["79954.47000000","2.92616000"],["79954.48000000","3.75301000"],["79955.00000000","0.00011000"],["79955.15000000","0.00007000"],["79955.45000000","0.00012000"],["79955.51000000","0.40000000"],["79956.00000000","0.02400000"],["79957.03000000","0.00025000"],["79957.15000000","0.00007000"],["79957.28000000","0.03224000"],["79957.39000000","0.00026000"],["79957.56000000","0.00008000"],["79957.61000000","0.00010000"],["79957.85000000","1.11488000"],["79958.00000000","0.02400000"],["79958.13000000","0.00007000"],["79958.33000000","0.09823000"],["79958.40000000","0.00239000"],["79958.54000000","0.00500000"],["79959.04000000","0.00007000"],["79959.11000000","1.04939000"],["79959.12000000","3.43911000"],["79959.18000000","0.20250000"],["79959.21000000","0.00197000"],["79959.22000000","0.00491000"],["79959.42000000","0.00007000"],["79959.88000000","0.97033000"],["79959.89000000","0.36586000"],["79959.96000000","0.00360000"],["79960.00000000","1.02515000"],["79960.31000000","1.95350000"],["79960.74000000","0.01151000"],["79960.96000000","0.00010000"],["79961.00000000","0.00202000"],["79961.44000000","0.00007000"],["79961.79000000","0.00007000"],["79962.00000000","0.02400000"],["79962.04000000","0.04557000"],["79962.68000000","0.00090000"],["79963.65000000","0.00007000"],["79963.73000000","0.00380000"],["79963.99000000","0.01558000"],["79964.00000000","0.02400000"],["79964.13000000","0.00078000"],["79964.37000000","0.00007000"],["79964.44000000","0.00400000"],["79964.78000000","0.00018000"],["79964.80000000","0.00017000"],["79964.96000000","0.00007000"],["79965.16000000","0.00070000"],["79965.59000000","0.00036000"],["79965.87000000","0.00088000"],["79966.00000000","0.02400000"],["79966.04000000","0.00032000"],["79966.29000000","0.00018000"],["79966.60000000","0.00012000"],["79966.80000000","0.00014000"],["79967.15000000","0.02804000"],["79967.46000000","0.00007000"],["79967.51000000","0.00016000"],["79967.61000000","0.00025000"],["79967.84000000","0.12628000"],["79968.00000000","0.02420000"],["79968.01000000","0.00151000"],["79968.15000000","0.00007000"],["79968.48000000","0.36586000"],["79969.87000000","0.00176000"],["79970.00000000","0.02450000"],["79970.02000000","0.00011000"],["79970.50000000","0.00375000"],["79970.57000000","0.00010000"],["79970.58000000","0.00009000"],["79970.60000000","0.00053000"],["79971.08000000","0.00049000"],["79971.44000000","0.00007000"],["79972.00000000","0.02400000"],["79972.72000000","0.20250000"],["79972.97000000","0.29314000"],["79972.98000000","0.03224000"],["79973.25000000","0.00007000"],["79973.56000000","0.00007000"],["79973.57000000","0.00010000"],["79973.70000000","0.00008000"],["79974.00000000","0.02400000"],["79974.29000000","0.92475000"],["79974.34000000","0.00026000"],["79974.52000000","0.00010000"],["79974.65000000","0.00012000"],["79974.76000000","0.00007000"],["79975.00000000","0.00024000"],["79975.89000000","0.12425000"],["79976.00000000","0.02400000"],["79976.12000000","0.00007000"],["79976.15000000","0.00007000"],["79976.26000000","0.00016000"],["79976.70000000","0.36586000"],["79977.34000000","0.00018000"],["79977.76000000","0.00007000"],["79977.90000000","0.00011000"],["79978.00000000","0.02400000"],["79978.27000000","0.00104000"],["79978.47000000","0.00007000"],["79979.11000000","0.00048000"],["79979.89000000","0.38661000"],["79980.00000000","1.02719000"],["79980.70000000","0.20250000"],["79981.00000000","0.00007000"],["79981.51000000","0.00031000"],["79981.81000000","0.01580000"],["79982.00000000","0.02400000"],["79982.09000000","0.02500000"],["79982.38000000","0.00020000"],["79982.41000000","0.00026000"],["79982.45000000","0.00007000"],["79983.55000000","0.00117000"],["79983.79000000","1.13752000"],["79983.80000000","3.75164000"],["79984.00000000","0.02400000"],["79984.98000000","0.00014000"],["79985.16000000","0.00007000"],["79985.34000000","0.00007000"],["79985.44000000","0.00040000"],["79985.45000000","0.00029000"],["79985.71000000","0.00013000"],["79985.76000000","0.00145000"],["79985.82000000","0.00100000"],["79985.98000000","0.02000000"],["79986.00000000","0.02400000"],["79986.02000000","0.00375000"],["79986.29000000","0.05721000"],["79986.41000000","0.00412000"],["79987.56000000","0.43474000"],["79987.63000000","0.80000000"],["79988.00000000","0.02400000"],["79988.17000000","0.03224000"],["79988.33000000","0.00394000"],["79988.68000000","0.20250000"],["79989.32000000","0.00007000"],["79989.84000000","0.00008000"],["79989.96000000","0.00035000"],["79989.99000000","0.00270000"],["79990.00000000","0.02817000"],["79990.08000000","0.00007000"],["79990.23000000","0.04653000"],["79990.65000000","0.00026000"],["79991.99000000","0.01620000"],["79992.00000000","0.02400000"],["79992.16000000","0.00016000"],["79992.87000000","0.00007000"],["79993.73000000","0.00007000"],["79993.80000000","0.00020000"],["79994.00000000","0.02400000"],["79994.02000000","0.00375000"],["79994.15000000","0.00007000"],["79994.28000000","0.00011000"],["79994.55000000","0.00036000"],["79994.94000000","0.00007000"],["79995.38000000","0.01961000"],["79995.56000000","0.00007000"],["79996.00000000","0.02400000"],["79996.06000000","0.00038000"],["79996.18000000","0.07454000"],["79996.66000000","0.20250000"],["79996.85000000","0.00007000"],["79997.44000000","0.00069000"],["79997.62000000","0.00041000"],["79998.00000000","0.02400000"],["79998.36000000","0.00378000"],["79998.83000000","0.00026000"],["79999.00000000","0.00461000"],["79999.01000000","0.01307000"],["79999.03000000","0.01059000"],["79999.10000000","0.00010000"],["79999.17000000","0.00007000"],["79999.38000000","0.00007000"],["79999.55000000","0.00022000"],["79999.60000000","0.00136000"],["79999.85000000","0.00010000"],["79999.90000000","1.34998000"],["79999.92000000","0.00310000"],["79999.94000000","0.00010000"],["80000.00000000","3.37529000"],["80000.17000000","0.04451000"],["80001.35000000","0.10018000"],["80001.80000000","0.00007000"],["80001.83000000","0.00010000"],["80002.12000000","0.00008000"],["80002.42000000","0.00007000"],["80002.51000000","0.00007000"],["80003.61000000","0.00124000"],["80003.99000000","0.00409000"],["80004.62000000","0.00125000"],["80004.63000000","0.07108000"],["80004.64000000","0.20250000"],["80004.85000000","0.00268000"],["80005.00000000","0.00025000"],["80005.04000000","0.00007000"],["80005.54000000","0.00017000"],["80005.64000000","0.03134000"],["80005.95000000","0.00009000"],["80005.98000000","0.00008000"],["80006.05000000","0.00007000"],["80006.59000000","0.00033000"],["80006.85000000","0.00026000"],["80007.19000000","0.00018000"],["80007.44000000","0.00010000"],["80008.00000000","0.00087000"],["80008.04000000","0.00007000"],["80008.52000000","0.00022000"],["80008.56000000","0.00016000"],["80009.02000000","0.00007000"],["80009.70000000","0.00007000"],["80010.00000000","0.00057000"],["80010.03000000","0.00065000"],["80011.59000000","0.00025000"],["80012.23000000","0.00007000"],["80012.37000000","0.00400000"],["80012.46000000","0.03224000"],["80012.61000000","1.18135000"],["80012.62000000","0.20250000"],["80012.68000000","0.00008000"],["80013.36000000","0.00007000"],["80013.42000000","0.00007000"],["80013.72000000","0.00011000"],["80013.89000000","0.00010000"],["80013.94000000","0.00011000"],["80014.26000000","3.75021000"],["80014.31000000","0.00010000"],["80014.71000000","0.00055000"],["80014.90000000","0.00026000"],["80015.29000000","0.00045000"],["80015.37000000","0.00008000"],["80015.71000000","0.00008000"],["80016.06000000","0.00007000"],["80016.21000000","0.00007000"],["80016.66000000","0.00010000"],["80017.15000000","0.00076000"],["80017.64000000","0.00027000"],["80018.81000000","0.00007000"],["80018.82000000","0.00007000"],["80019.09000000","1.11940000"],["80019.10000000","3.74998000"],["80019.33000000","0.00010000"],["80019.50000000","0.07720000"],["80019.99000000","0.00869000"],["80020.00000000","0.00078000"],["80020.60000000","0.20250000"],["80021.13000000","0.03224000"],["80021.19000000","0.00007000"],["80021.34000000","0.00007000"],["80021.42000000","0.00030000"],["80021.57000000","0.00024000"],["80021.85000000","0.00007000"],["80022.12000000","0.00008000"],["80022.22000000","0.00055000"],["80022.66000000","0.01448000"],["80022.76000000","0.00014000"],["80023.13000000","0.00007000"],["80023.25000000","0.00094000"],["80023.28000000","0.00011000"],["80023.30000000","0.00026000"],["80023.52000000","0.00030000"],["80023.77000000","0.00014000"],["80024.70000000","0.00011000"],["80024.83000000","0.00023000"],["80025.00000000","0.00043000"],["80025.16000000","0.00013000"],["80025.67000000","0.00007000"],["80025.75000000","0.00145000"],["80025.83000000","0.00007000"],["80026.29000000","0.00041000"],["80026.63000000","0.00007000"],["80027.39000000","0.00008000"],["80027.71000000","0.00226000"],["80028.44000000","0.00039000"],["80028.57000000","0.06621000"],["80028.58000000","0.20250000"],["80029.22000000","0.00007000"],["80029.37000000","0.00011000"],["80029.38000000","0.00008000"],["80029.41000000","0.00156000"],["80029.84000000","0.04256000"],["80029.98000000","0.00270000"],["80030.00000000","0.01142000"],["80030.01000000","0.00077000"],["80030.07000000","0.00013000"],["80030.10000000","0.00009000"],["80030.30000000","0.00010000"],["80031.25000000","0.00007000"],["80031.31000000","0.00026000"],["80031.35000000","0.00122000"],["80031.41000000","0.00007000"],["80031.91000000","0.00007000"],["80032.00000000","0.00007000"],["80032.15000000","0.02278000"],["80032.16000000","0.06930000"],["80032.69000000","0.00008000"],["80033.06000000","0.00010000"],["80033.17000000","0.00010000"],["80033.31000000","0.00265000"],["80033.33000000","0.00077000"],["80033.42000000","0.00139000"],["80033.52000000","0.00025000"],["80033.73000000","0.00109000"],["80033.74000000","0.00100000"],["80034.28000000","0.00053000"],["80034.90000000","0.00007000"],["80035.45000000","0.00007000"],["80035.57000000","0.17543000"],["80035.58000000","0.34723000"],["80035.76000000","0.02000000"],["80036.03000000","0.00012000"],["80036.56000000","0.20250000"],["80036.64000000","0.00007000"],["80037.03000000","0.00043000"],["80037.19000000","0.00007000"],["80037.22000000","0.00015000"],["80037.44000000","0.00126000"],["80037.53000000","0.00007000"],["80037.64000000","0.00010000"],["80037.68000000","0.00041000"],["80038.18000000","0.00187000"],["80038.26000000","0.00008000"],["80038.52000000","0.03224000"],["80038.85000000","0.00072000"],["80038.93000000","0.00040000"],["80039.79000000","0.00007000"],["80039.81000000","0.00050000"],["80039.84000000","0.00026000"],["80039.88000000","0.00410000"],["80040.00000000","0.00195000"],["80040.01000000","0.00052000"],["80040.24000000","0.00009000"],["80040.55000000","0.00150000"],["80040.78000000","0.01602000"],["80040.80000000","0.00010000"],["80040.93000000","0.00313000"],["80041.22000000","0.00016000"],["80041.64000000","0.00007000"],["80041.77000000","0.00014000"],["80042.15000000","0.00050000"],["80042.47000000","0.00007000"],["80042.50000000","0.00090000"],["80042.73000000","0.00109000"],["80042.85000000","0.00007000"],["80043.25000000","0.00010000"],["80043.46000000","0.00010000"],["80043.78000000","0.00007000"],["80044.17000000","0.00012000"],["80044.54000000","0.20250000"],["80044.63000000","0.00028000"],["80045.24000000","3.42306000"],["80045.29000000","0.00010000"],["80045.39000000","0.00007000"],["80045.42000000","0.00008000"],["80045.63000000","0.00007000"],["80045.95000000","0.00044000"],["80047.05000000","0.00031000"],["80047.75000000","0.00045000"],["80047.77000000","0.00007000"],["80047.88000000","0.00026000"],["80048.04000000","0.00007000"],["80049.06000000","0.00007000"],["80049.66000000","0.00125000"],["80049.87000000","0.00020000"],["80050.00000000","1.00087000"],["80050.28000000","0.00007000"],["80050.53000000","0.11607000"],["80051.13000000","0.00007000"],["80051.58000000","0.00007000"],["80051.76000000","0.00007000"],["80051.92000000","0.00007000"],["80051.99000000","0.00007000"],["80052.13000000","0.00012000"],["80052.44000000","0.00011000"],["80052.52000000","0.20250000"],["80052.98000000","0.00040000"],["80053.04000000","0.00007000"],["80053.17000000","4.45702000"],["80053.26000000","0.00010000"],["80053.50000000","0.00129000"],["80053.52000000","0.00018000"],["80053.58000000","0.00007000"],["80053.64000000","0.00057000"],["80053.81000000","0.00007000"],["80054.31000000","0.00010000"],["80054.40000000","0.00058000"],["80054.46000000","0.00237000"],["80055.00000000","0.00007000"],["80055.26000000","0.00007000"],["80055.92000000","0.00053000"],["80056.01000000","0.01234000"],["80056.27000000","0.00026000"],["80056.60000000","0.00025000"],["80056.73000000","0.00007000"],["80056.74000000","0.00164000"],["80057.14000000","0.00048000"],["80057.25000000","0.00074000"],["80057.49000000","0.00256000"],["80057.59000000","0.00028000"],["80057.61000000","0.00007000"],["80058.32000000","0.00007000"],["80058.82000000","0.00025000"],["80059.11000000","0.00042000"],["80059.43000000","0.00007000"],["80059.92000000","0.00007000"],["80060.00000000","0.00176000"],["80060.24000000","0.00013000"],["80060.40000000","0.00034000"],["80060.50000000","0.20250000"],["80060.52000000","0.00007000"],["80060.58000000","0.00029000"],["80061.53000000","0.00046000"],["80062.10000000","0.00007000"],["80062.54000000","0.11607000"],["80062.56000000","0.00014000"],["80062.82000000","0.00007000"],["80063.61000000","0.00007000"],["80063.82000000","0.00009000"],["80064.00000000","0.00007000"],["80064.15000000","0.00017000"],["80064.72000000","0.00026000"],["80065.00000000","0.00018000"],["80065.13000000","3.74783000"],["80065.15000000","0.00032000"],["80065.65000000","0.02105000"],["80066.09000000","0.00007000"],["80066.66000000","0.00058000"],["80066.84000000","0.00381000"],["80067.46000000","0.00007000"],["80067.99000000","0.00007000"],["80068.00000000","0.00025000"],["80068.75000000","0.00019000"],["80068.89000000","0.00007000"],["80068.90000000","0.00007000"],["80069.18000000","0.00223000"],["80069.99000000","0.00269000"],["80070.00000000","0.00057000"],["80071.26000000","0.00007000"],["80071.42000000","0.00017000"],["80072.13000000","0.00008000"],["80072.21000000","0.00107000"],["80073.03000000","0.00008000"],["80073.12000000","0.00056000"],["80073.18000000","0.00026000"],["80073.58000000","0.00007000"],["80073.59000000","0.00007000"],["80073.64000000","0.00012000"],["80074.10000000","0.00374000"],["80074.16000000","0.00021000"],["80074.17000000","0.00007000"],["80074.39000000","0.01253000"],["80074.55000000","0.11607000"],["80074.67000000","0.00056000"],["80074.73000000","0.00007000"],["80075.00000000","0.00033000"],["80075.18000000","0.00013000"],["80076.46000000","0.20250000"],["80076.50000000","0.00023000"],["80076.60000000","0.00045000"],["80076.70000000","0.00023000"],["80076.73000000","0.00021000"],["80076.80000000","0.00010000"],["80076.81000000","0.00007000"],["80076.92000000","0.00007000"],["80077.39000000","0.00007000"],["80077.58000000","0.00026000"],["80077.62000000","0.00049000"],["80077.87000000","0.00007000"],["80078.32000000","0.01961000"],["80079.13000000","0.00011000"],["80079.30000000","0.00026000"],["80079.31000000","0.00018000"],["80079.33000000","0.00009000"],["80079.46000000","0.00007000"],["80079.76000000","0.00010000"],["80079.84000000","0.00260000"],["80080.00000000","0.00090000"],["80080.39000000","0.00016000"],["80080.50000000","0.00007000"],["80080.83000000","0.00007000"],["80081.25000000","0.00012000"],["80081.50000000","0.00026000"],["80081.65000000","0.00007000"],["80082.11000000","0.00374000"],["80082.19000000","0.00016000"],["80082.30000000","0.00067000"],["80082.35000000","0.00007000"],["80083.20000000","0.00007000"],["80083.33000000","0.00007000"],["80083.43000000","0.00007000"],["80083.76000000","0.00008000"],["80083.83000000","0.00007000"],["80083.96000000","0.00010000"],["80084.02000000","0.01262000"],["80084.25000000","0.00400000"],["80084.40000000","0.00007000"],["80084.74000000","0.00007000"],["80085.42000000","0.00027000"],["80085.63000000","0.00011000"],["80086.27000000","0.00672000"],["80086.28000000","0.00013000"],["80086.37000000","0.00019000"],["80086.57000000","0.11607000"],["80086.68000000","0.00008000"],["80087.57000000","0.00008000"],["80087.62000000","0.00011000"],["80087.68000000","0.00250000"],["80088.23000000","0.00010000"],["80088.88000000","0.00202000"],["80088.94000000","0.00240000"],["80089.13000000","0.00008000"],["80089.32000000","0.00190000"],["80089.55000000","0.00007000"],["80089.70000000","0.00026000"],["80089.95000000","0.00013000"],["80090.00000000","0.00050000"],["80090.03000000","0.00007000"]]}}
{"rx_ns": 13854296515900, "frame": {"stream":"btcusdt@depth@100ms","data":{"e":"depthUpdate","E":1787650849514,"s":"BTCUSDT","U":99118577222,"u":99118577232,"b":[["79733.02000000","0.04410000"],["79727.60000000","0.00000000"],["73465.69000000","0.00014000"],["71872.20000000","0.01954000"],["71872.00000000","0.00000000"],["63886.40000000","0.00031000"]],"a":[["79858.00000000","0.72701000"]]}}}
{"rx_ns": 13854397246200, "frame": {"stream":"btcusdt@depth@100ms","data":{"e":"depthUpdate","E":1787650849615,"s":"BTCUSDT","U":99118577233,"u":99118577244,"b":[["79844.06000000","0.04527000"],["79838.06000000","0.00000000"],["79792.23000000","0.02500000"],["71872.20000000","0.00448000"],["63886.40000000","0.00000000"]],"a":[["79869.56000000","0.12528000"],["79887.93000000","0.04634000"],["79899.98000000","0.84031000"],["79901.15000000","0.00000000"]]}}}
{"rx_ns": 13854497616000, "frame": {"stream":"btcusdt@depth@100ms","data":{"e":"depthUpdate","E":1787650849714,"s":"BTCUSDT","U":99118577245,"u":99118577252,"b":[["79792.23000000","0.00413000"],["79689.00000000","0.00125000"],["77000.00000000","84.90337000"],["71872.20000000","0.00416000"]],"a":[["79858.00000000","0.69739000"],["79868.53000000","0.15165000"],["79869.56000000","0.00000000"]]}}}
{"rx_ns": 13854596429200, "frame": {"stream":"btcusdt@depth@100ms","data":{"e":"depthUpdate","E":1787650849814,"s":"BTCUSDT","U":99118577253,"u":99118577256,"b":[["71872.20000000","0.00432000"]],"a":[["79858.00000000","0.70359000"]]}}}
{"rx_ns": 13854699354600, "frame": {"stream":"btcusdt@depth@100ms","data":{"e":"depthUpdate","E":1787650849914,"s":"BTCUSDT","U":99118577257,"u":99118577272,"b":[["79857.16000000","0.00025000"],["79856.97000000","0.00407000"],["79792.23000000","0.02500000"],["79652.29000000","0.00000000"],["79647.23000000","0.00771000"],["71872.20000000","0.00432000"],["71872.18000000","0.00000000"]],"a":[["79858.00000000","0.70210000"],["79874.27000000","0.00400000"],["79876.54000000","0.02253000"],["79876.70000000","0.00250000"],["79879.64000000","0.00000000"],["79880.46000000","0.00000000"],["79896.04000000","0.00000000"],["79897.35000000","0.10000000"],["81203.07000000","0.00012000"]]}}}
{"rx_ns": 13854809384700, "frame": {"stream":"btcusdt@depth20","data":{"lastUpdateId":99118577279,"bids":[["79857.99000000","2.50907000"],["79857.98000000","0.00027000"],["79857.97000000","0.00013000"],["79857.45000000","0.00014000"],["79857.16000000","0.00025000"],["79857.15000000","0.00400000"],["79856.97000000","0.00407000"],["79856.96000000","0.36600000"],["79856.95000000","0.00007000"],["79856.94000000","0.25296000"],["79856.93000000","0.31334000"],["79856.92000000","0.50599000"],["79856.85000000","0.00730000"],["79856.72000000","0.00014000"],["79856.71000000","0.01774000"],["79856.05000000","0.00640000"],["79856.04000000","0.00014000"],["79855.74000000","0.00007000"],["79855.73000000","0.03471000"],["79855.72000000","1.12580000"]],"asks":[["79858.00000000","0.70210000"],["79858.01000000","0.00062000"],["79858.02000000","0.00013000"],["79858.16000000","0.00007000"],["79858.38000000","0.00007000"],["79858.42000000","0.00007000"],["79859.35000000","0.00007000"],["79859.49000000","0.00007000"],["79859.85000000","0.00007000"],["79859.86000000","0.06324000"],["79859.99000000","0.00007000"],["79860.00000000","0.02428000"],["79860.03000000","0.00851000"],["79860.30000000","0.00007000"],["79860.47000000","0.00007000"],["79860.48000000","0.06324000"],["79860.49000000","0.00007000"],["79860.88000000","0.00007000"],["79860.89000000","0.06331000"],["79860.90000000","0.04847000"]]}}}
{"rx_ns": 13854809491100, "frame": {"stream":"btcusdt@depth@100ms","data":{"e":"depthUpdate","E":1787650850014,"s":"BTCUSDT","U":99118577273,"u":99118577279,"b":[["79792.23000000","0.00413000"],["73465.69000000","0.00000000"],["71872.20000000","0.00432000"],["63886.40000000","0.00031000"]],"a":[]}}}
{"rx_ns": 13854896608200, "frame": {"stream":"btcusdt@depth@100ms","data":{"e":"depthUpdate","E":1787650850114,"s":"BTCUSDT","U":99118577280,"u":99118577289,"b":[["79857.99000000","2.51157000"],["79792.23000000","0.02500000"],["79714.56000000","1.50056000"],["78660.12000000","0.00030000"],["71872.20000000","0.00448000"]],"a":[["79873.48000000","0.00250000"],["80018.04000000","1.50056000"],["81055.87000000","0.00030000"]]}}}
{"rx_ns": 13854996374300, "frame": {"stream":"btcusdt@depth@100ms","data":{"e":"depthUpdate","E":1787650850214,"s":"BTCUSDT","U":99118577290,"u":99118577300,"b":[["79849.24000000","0.00520000"],["79842.78000000","0.00007000"],["79792.23000000","0.00413000"],["71872.20000000","0.00432000"],["63886.40000000","0.00000000"]],"a":[["79873.47000000","0.00250000"],["79873.48000000","0.00000000"],["79874.74000000","0.00007000"]]}}}
{"rx_ns": 13855096186200, "frame": {"stream":"btcusdt@depth@100ms","data":{"e":"depthUpdate","E":1787650850314,"s":"BTCUSDT","U":99118577301,"u":99118577310,"b":[["71872.20000000","0.00448000"],["63886.39000000","0.00000000"],["63886.00000000","0.05602000"]],"a":[["79858.00000000","0.70360000"],["79862.73000000","0.12068000"],["79864.08000000","0.00000000"]]}}}
{"rx_ns": 13855197858000, "frame": {"stream":"btcusdt@depth@100ms","data":{"e":"depthUpdate","E":1787650850414,"s":"BTCUSDT","U":99118577311,"u":99118577314,"b":[["71872.20000000","0.00432000"],["63886.39000000","0.00000000"],["63886.00000000","0.05902000"]],"a":[]}}}
{"rx_ns": 13855296465100, "frame": {"stream":"btcusdt@depth@100ms","data":{"e":"depthUpdate","E":1787650850514,"s":"BTCUSDT","U":99118577315,"u":99118577324,"b":[["71872.20000000","0.00448000"],["71872.00000000","0.00000000"],["63886.40000000","0.00031000"],["63886.00000000","0.05602000"]],"a":[["79858.00000000","0.70263000"],["79862.59000000","0.01667000"]]}}}
{"rx_ns": 13855400844700, "frame": {"stream":"btcusdt@depth@100ms","data":{"e":"depthUpdate","E":1787650850614,"s":"BTCUSDT","U":99118577325,"u":99118577338,"b":[["79857.99000000","2.51164000"],["79856.98000000","0.00007000"],["79856.97000000","0.01207000"],["71872.20000000","0.00432000"],["63886.40000000","0.00000000"]],"a":[["79873.47000000","0.00000000"],["79873.48000000","0.00250000"],["79874.27000000","0.01200000"],["79900.39000000","0.00400000"],["79904.55000000","0.00000000"]]}}}
{"rx_ns": 13855496263900, "frame": {"stream":"btcusdt@depth@100ms","data":{"e":"depthUpdate","E":1787650850714,"s":"BTCUSDT","U":99118577339,"u":99118577350,"b":[["79857.99000000","2.51164000"],["79856.98000000","0.00407000"],["79856.97000000","0.01214000"],["79855.73000000","0.03464000"],["79792.23000000","0.02500000"],["71872.20000000","0.00448000"]],"a":[["79858.00000000","0.70255000"],["79866.96000000","0.00000000"],["79869.67000000","0.00400000"]]}}}
{"rx_ns": 13855596291200, "frame": {"stream":"btcusdt@depth@100ms","data":{"e":"depthUpdate","E":1787650850814,"s":"BTCUSDT","U":99118577351,"u":99118577354,"b":[["71872.20000000","0.00432000"]],"a":[["80255.10000000","0.00018000"]]}}}
{"rx_ns": 13855696802600, "frame": {"stream":"btcusdt@depth@100ms","data":{"e":"depthUpdate","E":1787650850914,"s":"BTCUSDT","U":99118577355,"u":99118577357,"b":[["71872.20000000","0.00448000"]],"a":[]}}}
{"rx_ns": 13855801675500, "frame": {"stream":"btcusdt@depth20","data":{"lastUpdateId":99118577373,"bids":[["79857.99000000","2.51188000"],["79857.98000000","0.00027000"],["79857.97000000","0.00013000"],["79857.45000000","0.00014000"],["79857.15000000","0.00400000"],["79856.98000000","0.00407000"],["79856.97000000","0.01214000"],["79856.96000000","0.36600000"],["79856.95000000","0.00007000"],["79856.94000000","0.25296000"],["79856.93000000","0.31334000"],["79856.92000000","0.50599000"],["79856.85000000","0.00730000"],["79856.72000000","0.00014000"],["79856.71000000","0.01774000"],["79856.44000000","0.00400000"],["79856.05000000","0.00640000"],["79856.04000000","0.00014000"],["79855.74000000","0.00007000"],["79855.73000000","0.03464000"]],"asks":[["79858.00000000","0.34550000"],["79858.01000000","0.00062000"],["79858.02000000","0.00013000"],["79858.16000000","0.00007000"],["79858.38000000","0.00007000"],["79858.42000000","0.00007000"],["79859.35000000","0.00007000"],["79859.49000000","0.00007000"],["79859.85000000","0.00007000"],["79859.86000000","0.06324000"],["79859.99000000","0.00007000"],["79860.00000000","0.02428000"],["79860.03000000","0.00851000"],["79860.30000000","0.00007000"],["79860.47000000","0.00007000"],["79860.48000000","0.06324000"],["79860.49000000","0.00007000"],["79860.88000000","0.00007000"],["79860.89000000","0.06331000"],["79860.90000000","0.04847000"]]}}}
{"rx_ns": 13855801804700, "frame": {"stream":"btcusdt@depth@100ms","data":{"e":"depthUpdate","E":1787650851015,"s":"BTCUSDT","U":99118577358,"u":99118577373,"b":[["79857.99000000","2.51188000"],["79857.16000000","0.00000000"],["79856.44000000","0.00400000"],["79792.23000000","0.00413000"],["71872.20000000","0.00416000"],["63886.40000000","0.00031000"]],"a":[["79858.00000000","0.34550000"],["79862.59000000","0.01660000"],["79862.73000000","0.00000000"],["79864.53000000","0.05850000"],["79864.82000000","0.00000000"],["79870.82000000","0.00000000"],["79872.26000000","0.00400000"]]}}}
{"rx_ns": 13855898000400, "frame": {"stream":"btcusdt@depth@100ms","data":{"e":"depthUpdate","E":1787650851114,"s":"BTCUSDT","U":99118577374,"u":99118577393,"b":[["79857.99000000","2.51814000"],["79856.05000000","0.00014000"],["78660.12000000","0.00030000"],["71872.20000000","0.00448000"],["63886.00000000","0.05602000"]],"a":[["79864.54000000","0.20405000"],["79865.99000000","0.06324000"],["79868.53000000","0.10939000"],["79869.67000000","0.00000000"],["79870.98000000","0.00400000"],["81055.87000000","0.00030000"]]}}}
{"rx_ns": 13856005352100, "frame": {"stream":"btcusdt@depth@100ms","data":{"e":"depthUpdate","E":1787650851214,"s":"BTCUSDT","U":99118577394,"u":99118577415,"b":[["79856.97000000","0.01221000"],["79856.71000000","0.01767000"],["79856.05000000","0.00000000"],["79855.73000000","0.03471000"],["79850.00000000","0.12093000"],["79842.78000000","0.00007000"],["79792.23000000","0.02500000"],["71872.20000000","0.00432000"],["63886.40000000","0.00000000"]],"a":[["79868.53000000","0.16591000"],["79870.14000000","0.16905000"],["79873.47000000","0.00250000"],["79873.48000000","0.00000000"],["79874.74000000","0.00007000"]]}}}
{"rx_ns": 13856097819800, "frame": {"stream":"btcusdt@depth@100ms","data":{"e":"depthUpdate","E":1787650851314,"s":"BTCUSDT","U":99118577416,"u":99118577445,"b":[["79857.99000000","4.39484000"],["79854.02000000","0.00000000"],["79854.01000000","1.87677000"],["79792.23000000","0.00413000"],["71872.20000000","0.00416000"],["63886.39000000","0.00000000"],["63886.00000000","0.05602000"]],"a":[["79859.86000000","0.00007000"],["79860.48000000","0.00007000"],["79865.44000000","0.00000000"],["79865.99000000","0.00007000"],["79868.91000000","0.00000000"],["79870.51000000","0.00000000"],["79870.69000000","0.00000000"],["79872.26000000","0.00000000"],["79873.47000000","0.00000000"],["79873.89000000","0.00400000"],["80508.63000000","0.00000000"]]}}}
{"rx_ns": 13856196233200, "frame": {"stream":"btcusdt@depth@100ms","data":{"e":"depthUpdate","E":1787650851414,"s":"BTCUSDT","U":99118577446,"u":99118577472,"b":[["79854.02000000","0.00007000"],["79667.74000000","0.00678000"],["79650.12000000","0.00000000"],["71872.20000000","0.00432000"],["63886.39000000","0.00000000"]],"a":[["79858.00000000","0.34550000"],["79859.85000000","0.00000000"],["79859.86000000","0.00000000"],["79860.03000000","0.00844000"],["79860.47000000","0.00000000"],["79860.48000000","0.00000000"],["79861.72000000","0.06324000"],["79862.95000000","0.00007000"],["79863.57000000","0.00007000"],["79865.99000000","0.20257000"],["79866.96000000","0.06317000"],["79867.92000000","0.06317000"],["79870.89000000","0.00710000"],["79873.49000000","0.00000000"],["79873.50000000","0.06567000"],["80029.84000000","0.00000000"],["80165.72000000","0.01588000"]]}}}
{"rx_ns": 13856296993600, "frame": {"stream":"btcusdt@depth@100ms","data":{"e":"depthUpdate","E":1787650851514,"s":"BTCUSDT","U":99118577473,"u":99118577487,"b":[["79857.99000000","4.39491000"],["79652.29000000","0.00771000"],["79647.23000000","0.00000000"],["71872.20000000","0.00432000"],["63886.40000000","0.00031000"]],"a":[["79858.00000000","0.34750000"],["79865.98000000","0.06317000"],["79865.99000000","0.00007000"],["79869.23000000","0.07185000"],["79870.14000000","0.00000000"],["79873.50000000","0.06317000"],["79874.35000000","0.00250000"],["79899.00000000","0.00000000"]]}}}
{"rx_ns": 13856396777100, "frame": {"stream":"btcusdt@depth@100ms","data":{"e":"depthUpdate","E":1787650851614,"s":"BTCUSDT","U":99118577488,"u":99118577502,"b":[["79780.81000000","0.62594000"],["79778.17000000","0.00000000"],["79733.02000000","0.00000000"],["79724.68000000","0.04534000"],["71872.20000000","0.00448000"],["71872.00000000","0.00000000"],["63886.40000000","0.00000000"]],"a":[["79869.61000000","0.12528000"],["79874.35000000","0.00000000"],["79874.36000000","0.00000000"],["79874.37000000","0.00250000"]]}}}
{"rx_ns": 13856496683200, "frame": {"stream":"btcusdt@depth@100ms","data":{"e":"depthUpdate","E":1787650851714,"s":"BTCUSDT","U":99118577503,"u":99118577505,"b":[["71872.20000000","0.00432000"]],"a":[["79872.02000000","0.00007000"],["80843.95000000","0.00030000"]]}}}
{"rx_ns": 13856597908100, "frame": {"stream":"btcusdt@depth@100ms","data":{"e":"depthUpdate","E":1787650851814,"s":"BTCUSDT","U":99118577506,"u":99118577516,"b":[["79857.99000000","4.39482000"],["78983.31000000","0.00000000"],["71872.20000000","0.00448000"],["71872.19000000","0.00008000"]],"a":[["79858.00000000","0.34743000"],["79862.00000000","0.02421000"],["79865.99000000","0.20257000"],["79874.36000000","0.00250000"],["79874.37000000","0.00000000"]]}}}
{"rx_ns": 13856696394200, "frame": {"stream":"btcusdt@depth@100ms","data":{"e":"depthUpdate","E":1787650851914,"s":"BTCUSDT","U":99118577517,"u":99118577521,"b":[["79792.23000000","0.02500000"],["71872.20000000","0.00432000"],["63886.00000000","0.05902000"]],"a":[]}}}
{"rx_ns": 13856806719400, "frame": {"stream":"btcusdt@depth20","data":{"lastUpdateId":99118577524,"bids":[["79857.99000000","4.39482000"],["79857.98000000","0.00027000"],["79857.97000000","0.00013000"],["79857.45000000","0.00014000"],["79857.15000000","0.00400000"],["79856.98000000","0.00407000"],["79856.97000000","0.01221000"],["79856.96000000","0.36600000"],["79856.95000000","0.00007000"],["79856.94000000","0.25296000"],["79856.93000000","0.31334000"],["79856.92000000","0.50599000"],["79856.85000000","0.00730000"],["79856.72000000","0.00014000"],["79856.71000000","0.01767000"],["79856.44000000","0.00400000"],["79856.04000000","0.00014000"],["79855.74000000","0.00007000"],["79855.73000000","0.03471000"],["79855.72000000","1.12580000"]],"asks":[["79858.00000000","0.34743000"],["79858.01000000","0.00062000"],["79858.02000000","0.00013000"],["79858.16000000","0.00007000"],["79858.38000000","0.00007000"],["79858.42000000","0.00007000"],["79859.35000000","0.00007000"],["79859.49000000","0.00007000"],["79859.99000000","0.00007000"],["79860.00000000","0.02428000"],["79860.03000000","0.00844000"],["79860.30000000","0.00007000"],["79860.49000000","0.00007000"],["79860.88000000","0.00007000"],["79860.89000000","0.06331000"],["79860.90000000","0.04847000"],["79860.99000000","0.00358000"],["79861.02000000","0.00007000"],["79861.03000000","0.01797000"],["79861.18000000","0.00007000"]]}}}
{"rx_ns": 13856806934200, "frame": {"stream":"btcusdt@depth@100ms","data":{"e":"depthUpdate","E":1787650852014,"s":"BTCUSDT","U":99118577522,"u":99118577524,"b":[["79792.23000000","0.00413000"],["63886.40000000","0.00031000"],["63886.00000000","0.05602000"]],"a":[]}}}
{"rx_ns": 13856896273900, "frame": {"stream":"btcusdt@depth@100ms","data":{"e":"depthUpdate","E":1787650852114,"s":"BTCUSDT","U":99118577525,"u":99118577534,"b":[["79792.23000000","0.02500000"],["78660.12000000","0.00030000"],["71872.20000000","0.00416000"]],"a":[["79874.35000000","0.00250000"],["79874.36000000","0.00000000"],["81055.87000000","0.00030000"]]}}}
{"rx_ns": 13856996463600, "frame": {"stream":"btcusdt@depth@100ms","data":{"e":"depthUpdate","E":1787650852214,"s":"BTCUSDT","U":99118577535,"u":99118577541,"b":[["79842.78000000","0.00000000"],["71872.20000000","0.00432000"],["63886.40000000","0.00000000"]],"a":[["79865.99000000","0.00007000"],["79874.74000000","0.00000000"],["79904.00000000","0.72407000"]]}}}
{"rx_ns": 13857098017100, "frame": {"stream":"btcusdt@depth@100ms","data":{"e":"depthUpdate","E":1787650852314,"s":"BTCUSDT","U":99118577542,"u":99118577550,"b":[["79842.78000000","0.00007000"],["79792.23000000","0.00413000"],["71872.20000000","0.00416000"],["63886.39000000","0.00000000"],["63886.00000000","0.05602000"]],"a":[["79858.00000000","0.34543000"],["79874.74000000","0.00007000"]]}}}
{"rx_ns": 13857197993000, "frame": {"stream":"btcusdt@depth@100ms","data":{"e":"depthUpdate","E":1787650852414,"s":"BTCUSDT","U":99118577551,"u":99118577576,"b":[["79857.46000000","0.00626000"],["79855.23000000","0.00000000"],["71872.20000000","0.00432000"],["71872.19000000","0.00000000"],["71872.18000000","0.00008000"],["63886.39000000","0.00000000"]],"a":[["79858.00000000","0.32665000"],["79860.03000000","0.00851000"],["79860.47000000","0.00007000"],["79860.48000000","0.06317000"],["79865.44000000","0.06317000"],["79870.98000000","0.00000000"],["79871.43000000","0.00000000"],["79871.91000000","0.00400000"],["79871.99000000","0.00000000"],["79873.23000000","0.00400000"],["79873.89000000","0.00000000"],["79874.27000000","0.00000000"],["79875.93000000","0.01200000"]]}}}
{"rx_ns": 13857301606300, "frame": {"stream":"btcusdt@depth@100ms","data":{"e":"depthUpdate","E":1787650852514,"s":"BTCUSDT","U":99118577577,"u":99118577597,"b":[["79857.99000000","4.39489000"],["79857.46000000","0.00633000"],["79855.73000000","0.03464000"],["79855.31000000","0.05193000"],["71872.20000000","0.00416000"],["63886.40000000","0.00031000"]],"a":[["79858.00000000","0.27665000"],["79860.03000000","0.00851000"],["79860.48000000","0.06324000"],["79862.00000000","0.02414000"],["79874.34000000","0.00250000"],["79874.35000000","0.00000000"]]}}}
{"rx_ns": 13857396884300, "frame": {"stream":"btcusdt@depth@100ms","data":{"e":"depthUpdate","E":1787650852614,"s":"BTCUSDT","U":99118577598,"u":99118577601,"b":[["79792.23000000","0.02500000"],["71872.20000000","0.00416000"],["63886.40000000","0.00000000"]],"a":[]}}}
{"rx_ns": 13857499228300, "frame": {"stream":"btcusdt@depth@100ms","data":{"e":"depthUpdate","E":1787650852714,"s":"BTCUSDT","U":99118577602,"u":99118577608,"b":[["79792.23000000","0.00413000"],["79727.74000000","0.00000000"],["71872.20000000","0.00416000"],["71872.00000000","0.00000000"]],"a":[["79858.00000000","0.27656000"]]}}}
{"rx_ns": 13857596804900, "frame": {"stream":"btcusdt@depth@100ms","data":{"e":"depthUpdate","E":1787650852815,"s":"BTCUSDT","U":99118577609,"u":99118577616,"b":[["79732.90000000","0.01961000"],["71872.20000000","0.00416000"]],"a":[["79874.33000000","0.00250000"],["79874.34000000","0.00000000"],["79965.44000000","0.00556000"]]}}}
{"rx_ns": 13857698672500, "frame": {"stream":"btcusdt@depth@100ms","data":{"e":"depthUpdate","E":1787650852914,"s":"BTCUSDT","U":99118577617,"u":99118577617,"b":[["71872.20000000","0.00400000"]],"a":[]}}}
{"rx_ns": 13857809085100, "frame": {"stream":"btcusdt@depth20","data":{"lastUpdateId":99118577624,"bids":[["79857.99000000","4.39489000"],["79857.98000000","0.00027000"],["79857.97000000","0.00013000"],["79857.46000000","0.00633000"],["79857.45000000","0.00014000"],["79857.15000000","0.00400000"],["79856.98000000","0.00407000"],["79856.97000000","0.01221000"],["79856.96000000","0.36600000"],["79856.95000000","0.00007000"],["79856.94000000","0.25296000"],["79856.93000000","0.31334000"],["79856.92000000","0.50599000"],["79856.85000000","0.00730000"],["79856.72000000","0.00014000"],["79856.71000000","0.01767000"],["79856.44000000","0.00400000"],["79856.04000000","0.00014000"],["79855.74000000","0.00007000"],["79855.73000000","0.03464000"]],"asks":[["79858.00000000","0.26550000"],["79858.01000000","0.00062000"],["79858.02000000","0.00013000"],["79858.16000000","0.00007000"],["79858.38000000","0.00007000"],["79858.42000000","0.00007000"],["79859.35000000","0.00007000"],["79859.49000000","0.00007000"],["79859.99000000","0.00007000"],["79860.00000000","0.02428000"],["79860.03000000","0.00851000"],["79860.30000000","0.00007000"],["79860.47000000","0.00007000"],["79860.48000000","0.06324000"],["79860.49000000","0.00007000"],["79860.88000000","0.00007000"],["79860.89000000","0.06331000"],["79860.90000000","0.04847000"],["79860.99000000","0.00358000"],["79861.02000000","0.00007000"]]}}}
{"rx_ns": 13857809155400, "frame": {"stream":"btcusdt@depth@100ms","data":{"e":"depthUpdate","E":1787650853014,"s":"BTCUSDT","U":99118577618,"u":99118577624,"b":[["71872.20000000","0.00416000"],["71872.18000000","0.00000000"],["63886.40000000","0.00031000"]],"a":[["79858.00000000","0.26550000"]]}}}
{"rx_ns": 13858152325000, "frame": {"stream":"btcusdt@depth@100ms","data":{"e":"depthUpdate","E":1787650853114,"s":"BTCUSDT","U":99118577625,"u":99118579822,"b":[["79873.29000000","4.00519000"],["79873.28000000","0.00027000"],["79873.27000000","0.00013000"],["79872.93000000","0.00014000"],["79872.67000000","0.00000000"],["79872.54000000","0.00000000"],["79872.25000000","0.00000000"],["79872.09000000","0.00007000"],["79872.08000000","0.13163000"],["79872.07000000","0.00021000"],["79872.05000000","0.00000000"],["79872.00000000","0.00007000"],["79871.99000000","0.08494000"],["79871.97000000","0.00000000"],["79871.43000000","0.00000000"],["79870.81000000","0.00000000"],["79870.65000000","0.00000000"],["79870.64000000","0.00024000"],["79870.63000000","0.05256000"],["79870.19000000","0.00000000"],["79870.01000000","0.00000000"],["79870.00000000","0.00007000"],["79869.99000000","0.00021000"],["79869.63000000","0.00000000"],["79869.62000000","0.00000000"],["79869.60000000","0.00021000"],["79869.57000000","0.00000000"],["79869.07000000","0.00007000"],["79869.06000000","0.12541000"],["79868.95000000","0.00000000"],["79868.53000000","0.00007000"],["79868.52000000","0.08494000"],["79868.33000000","0.00000000"],["79868.20000000","0.00007000"],["79868.19000000","0.08494000"],["79867.99000000","0.00021000"],["79867.96000000","0.00026000"],["79867.91000000","0.00000000"],["79867.71000000","0.00000000"],["79867.09000000","0.00000000"],["79866.96000000","0.00000000"],["79866.95000000","0.00000000"],["79866.67000000","0.00000000"],["79866.47000000","0.00000000"],["79866.00000000","0.00400000"],["79865.99000000","0.00000000"],["79865.97000000","0.00000000"],["79865.85000000","0.00000000"],["79865.43000000","0.00000000"],["79865.23000000","0.00000000"],["79865.19000000","0.00014000"],["79864.86000000","0.00000000"],["79864.61000000","0.00000000"],["79864.54000000","0.00000000"],["79864.53000000","0.00000000"],["79864.52000000","0.00021000"],["79864.29000000","0.00007000"],["79864.19000000","0.00014000"],["79864.18000000","0.00000000"],["79864.08000000","0.00008000"],["79864.01000000","0.00372000"],["79864.00000000","0.90049000"],["79863.99000000","3.26441000"],["79863.98000000","0.00000000"],["79863.97000000","0.00000000"],["79863.87000000","0.00000000"],["79863.86000000","0.30021000"],["79863.85000000","0.00000000"],["79863.84000000","0.00400000"],["79863.57000000","0.30007000"],["79863.56000000","0.00007000"],["79862.95000000","0.30983000"],["79862.94000000","0.00000000"],["79862.59000000","0.00000000"],["79862.58000000","0.00000000"],["79862.55000000","0.00000000"],["79862.34000000","0.07507000"],["79862.33000000","0.75763000"],["79862.32000000","1.07460000"],["79862.03000000","0.00000000"],["79862.00000000","0.00000000"],["79861.99000000","0.28650000"],["79861.71000000","0.00000000"],["79861.70000000","0.08576000"],["79861.68000000","0.00400000"],["79861.62000000","0.00010000"],["79861.32000000","0.00014000"],["79861.31000000","0.00000000"],["79861.30000000","0.00000000"],["79861.29000000","0.00007000"],["79861.10000000","0.00007000"],["79861.08000000","0.00000000"],["79861.03000000","0.00000000"],["79861.02000000","0.00000000"],["79860.98000000","0.00000000"],["79860.90000000","0.00000000"],["79860.89000000","0.00000000"],["79860.88000000","0.20250000"],["79860.87000000","0.00000000"],["79860.48000000","0.00000000"],["79860.47000000","0.52066000"],["79860.46000000","0.00000000"],["79860.39000000","0.00000000"],["79860.30000000","0.00000000"],["79860.29000000","0.24794000"],["79860.19000000","0.00000000"],["79860.13000000","0.00000000"],["79860.07000000","0.00000000"],["79860.02000000","0.00000000"],["79860.00000000","0.00000000"],["79859.99000000","0.67958000"],["79859.98000000","0.00000000"],["79859.81000000","0.00000000"],["79859.65000000","0.00000000"],["79859.59000000","0.00000000"],["79859.52000000","0.00400000"],["79859.48000000","0.00000000"],["79859.37000000","0.00000000"],["79859.34000000","0.00000000"],["79859.32000000","0.00007000"],["79859.19000000","0.00162000"],["79858.75000000","0.00000000"],["79858.41000000","0.00007000"],["79858.37000000","0.00000000"],["79858.20000000","0.00026000"],["79858.15000000","0.00000000"],["79858.13000000","0.00000000"],["79858.08000000","0.00007000"],["79858.01000000","0.00000000"],["79858.00000000","0.80839000"],["79857.99000000","0.47610000"],["79857.98000000","0.00000000"],["79857.97000000","0.00000000"],["79857.91000000","0.00007000"],["79857.62000000","0.00000000"],["79857.46000000","0.00000000"],["79857.37000000","0.00000000"],["79857.15000000","0.37975000"],["79856.99000000","0.00000000"],["79856.98000000","0.00000000"],["79856.97000000","0.00000000"],["79856.96000000","0.36586000"],["79856.95000000","0.00000000"],["79856.94000000","0.00000000"],["79856.93000000","0.00000000"],["79856.92000000","0.28908000"],["79856.85000000","0.00716000"],["79856.72000000","0.00000000"],["79856.71000000","0.00000000"],["79856.44000000","0.00000000"],["79856.34000000","0.00007000"],["79856.10000000","0.00008000"],["79856.04000000","0.00000000"],["79856.00000000","0.00007000"],["79855.74000000","0.00000000"],["79855.73000000","0.03457000"],["79855.71000000","0.00007000"],["79855.69000000","0.00000000"],["79855.66000000","0.00000000"],["79855.65000000","1.04939000"],["79855.64000000","0.62594000"],["79855.48000000","0.00060000"],["79855.43000000","0.00000000"],["79855.31000000","0.00000000"],["79855.22000000","0.00000000"],["79855.21000000","0.00000000"],["79855.09000000","0.00000000"],["79854.72000000","0.00000000"],["79854.69000000","0.00000000"],["79854.31000000","0.00000000"],["79854.24000000","0.00000000"],["79854.15000000","0.00000000"],["79854.02000000","1.87677000"],["79854.01000000","0.00007000"],["79854.00000000","0.23544000"],["79853.99000000","0.00000000"],["79853.81000000","0.00012000"],["79853.64000000","0.00010000"],["79853.09000000","0.00000000"],["79852.49000000","0.33820000"],["79852.10000000","0.00008000"],["79852.01000000","0.00000000"],["79852.00000000","0.00000000"],["79851.99000000","0.00066000"],["79851.92000000","0.33820000"],["79851.53000000","0.00000000"],["79851.19000000","0.00000000"],["79850.93000000","0.09467000"],["79850.88000000","0.00400000"],["79850.54000000","0.00000000"],["79850.40000000","0.00007000"],["79850.33000000","0.00000000"],["79850.22000000","0.00000000"],["79850.02000000","0.00007000"],["79850.00000000","0.12343000"],["79849.99000000","0.00000000"],["79848.93000000","0.30622000"],["79848.50000000","0.37579000"],["79848.34000000","0.00000000"],["79848.11000000","0.00008000"],["79847.99000000","0.00000000"],["79846.36000000","0.00000000"],["79846.00000000","0.02400000"],["79845.61000000","0.09459000"],["79845.15000000","0.00400000"],["79844.88000000","0.00000000"],["79844.42000000","0.00000000"],["79844.34000000","0.00000000"],["79844.11000000","0.00008000"],["79844.04000000","0.00000000"],["79843.79000000","0.00000000"],["79843.32000000","0.00000000"],["79842.89000000","0.00000000"],["79842.78000000","0.00000000"],["79842.51000000","0.00000000"],["79842.02000000","0.00000000"],["79841.99000000","0.00000000"],["79841.96000000","0.00000000"],["79841.62000000","0.50987000"],["79840.41000000","0.00000000"],["79840.12000000","0.62647000"],["79840.03000000","0.00000000"],["79839.90000000","0.00125000"],["79839.79000000","0.00932000"],["79837.81000000","0.00000000"],["79837.61000000","0.00000000"],["79837.52000000","0.34823000"],["79836.84000000","0.00000000"],["79836.45000000","0.78414000"],["79836.30000000","0.00000000"],["79836.26000000","0.02541000"],["79836.13000000","0.00008000"],["79836.06000000","0.00000000"],["79836.03000000","0.00000000"],["79835.81000000","0.00000000"],["79835.56000000","0.00400000"],["79835.44000000","0.00000000"],["79835.24000000","0.00000000"],["79833.55000000","0.00000000"],["79832.13000000","0.00008000"],["79832.04000000","0.00000000"],["79832.00000000","0.02400000"],["79831.92000000","0.00000000"],["79831.70000000","1.52728000"],["79831.69000000","1.24040000"],["79831.24000000","0.00000000"],["79831.00000000","0.00000000"],["79830.92000000","0.00400000"],["79830.46000000","0.00000000"],["79830.36000000","0.00000000"],["79830.23000000","0.00000000"],["79830.00000000","0.11795000"],["79829.88000000","0.00000000"],["79829.82000000","0.00021000"],["79828.90000000","0.64145000"],["79828.71000000","0.00000000"],["79828.15000000","0.00000000"],["79828.05000000","0.00000000"],["79827.25000000","0.00000000"],["79827.12000000","0.00007000"],["79826.49000000","0.00000000"],["79826.34000000","0.00000000"],["79824.96000000","0.00000000"],["79824.05000000","0.00000000"],["79823.90000000","0.00000000"],["79823.10000000","0.00000000"],["79822.62000000","0.00000000"],["79822.34000000","0.00000000"],["79822.05000000","0.00000000"],["79821.19000000","0.00000000"],["79820.06000000","0.00000000"],["79820.00000000","0.03400000"],["79819.27000000","0.00000000"],["79818.75000000","0.00000000"],["79818.00000000","0.72400000"],["79817.09000000","0.00000000"],["79816.95000000","0.00000000"],["79816.15000000","0.00000000"],["79815.32000000","0.82252000"],["79815.27000000","0.00000000"],["79807.96000000","2.27424000"],["79806.52000000","0.00000000"],["79804.79000000","0.00000000"],["79804.56000000","3.40074000"],["79802.37000000","0.00000000"],["79800.43000000","2.32267000"],["79800.30000000","0.00000000"],["79798.97000000","0.00000000"],["79796.15000000","0.00000000"],["79795.68000000","0.00000000"],["79794.60000000","0.00312000"],["79794.58000000","0.00000000"],["79793.09000000","0.04605000"],["79792.20000000","0.00008000"],["79792.00000000","0.02407000"],["79790.85000000","0.00000000"],["79790.26000000","0.00000000"],["79788.79000000","0.00000000"],["79788.01000000","0.00000000"],["79787.36000000","0.00000000"],["79785.39000000","0.00000000"],["79782.47000000","0.00000000"],["79776.10000000","0.00000000"],["79775.28000000","0.00000000"],["79774.14000000","0.00000000"],["79772.58000000","0.00000000"],["79770.82000000","0.00000000"],["79769.79000000","0.00000000"],["79769.69000000","0.00000000"],["79762.46000000","0.00000000"],["79741.47000000","0.00000000"],["79728.47000000","1.50056000"],["79726.24000000","0.00000000"],["79714.57000000","0.00125000"],["79714.56000000","0.00000000"],["79712.33000000","0.00008000"],["79711.24000000","0.00000000"],["79710.01000000","0.00000000"],["79702.61000000","0.00000000"],["79696.36000000","1.20000000"],["79694.28000000","0.00000000"],["79676.32000000","0.00000000"],["79652.28000000","0.00000000"],["79632.45000000","0.00008000"],["79624.27000000","0.00000000"],["79615.63000000","0.00019000"],["79610.45000000","0.00000000"],["79552.58000000","0.00008000"],["79545.39000000","0.00000000"],["79544.40000000","0.00000000"],["79535.78000000","0.00000000"],["79528.63000000","1.74181000"],["79489.90000000","0.00000000"],["79472.71000000","0.00008000"],["79464.54000000","0.00000000"],["79455.92000000","0.00000000"],["79392.84000000","0.00008000"],["79384.68000000","0.00000000"],["79376.07000000","0.00000000"],["79312.97000000","0.00008000"],["79304.81000000","0.00000000"],["79296.21000000","0.00630000"],["79233.09000000","0.00008000"],["79224.95000000","0.00000000"],["79216.36000000","0.00000000"],["79076.87000000","0.00400000"],["79076.74000000","0.00400000"],["78675.19000000","0.00030000"],["78660.12000000","0.00000000"],["71885.97000000","0.00032000"],["71872.20000000","0.00000000"],["67845.30000000","0.00000000"]],"a":[["79858.00000000","0.00000000"],["79858.01000000","0.00000000"],["79858.02000000","0.00000000"],["79858.16000000","0.00000000"],["79858.38000000","0.00000000"],["79858.42000000","0.00000000"],["79859.35000000","0.00000000"],["79859.49000000","0.00000000"],["79859.99000000","0.00000000"],["79860.00000000","0.00000000"],["79860.03000000","0.00000000"],["79860.30000000","0.00000000"],["79860.47000000","0.00000000"],["79860.48000000","0.00000000"],["79860.49000000","0.00000000"],["79860.88000000","0.00000000"],["79860.89000000","0.00000000"],["79860.90000000","0.00000000"],["79860.99000000","0.00000000"],["79861.02000000","0.00000000"],["79861.03000000","0.00000000"],["79861.18000000","0.00000000"],["79861.31000000","0.00000000"],["79861.32000000","0.00000000"],["79861.71000000","0.00000000"],["79861.72000000","0.00000000"],["79861.99000000","0.00000000"],["79862.00000000","0.00000000"],["79862.04000000","0.00000000"],["79862.33000000","0.00000000"],["79862.34000000","0.00000000"],["79862.56000000","0.00000000"],["79862.58000000","0.00000000"],["79862.59000000","0.00000000"],["79862.61000000","0.00000000"],["79862.65000000","0.00000000"],["79862.95000000","0.00000000"],["79862.96000000","0.00000000"],["79863.21000000","0.00000000"],["79863.57000000","0.00000000"],["79863.58000000","0.00000000"],["79863.86000000","0.00000000"],["79863.87000000","0.00000000"],["79863.98000000","0.00000000"],["79863.99000000","0.00000000"],["79864.00000000","0.00000000"],["79864.01000000","0.00000000"],["79864.19000000","0.00000000"],["79864.20000000","0.00000000"],["79864.25000000","0.00000000"],["79864.46000000","0.00000000"],["79864.52000000","0.00000000"],["79864.53000000","0.00000000"],["79864.54000000","0.00000000"],["79864.55000000","0.00000000"],["79864.63000000","0.00000000"],["79864.74000000","0.00000000"],["79864.87000000","0.00000000"],["79864.92000000","0.00000000"],["79865.19000000","0.00000000"],["79865.21000000","0.00000000"],["79865.24000000","0.00000000"],["79865.43000000","0.00000000"],["79865.44000000","0.00000000"],["79865.92000000","0.00000000"],["79865.97000000","0.00000000"],["79865.98000000","0.00000000"],["79865.99000000","0.00000000"],["79866.00000000","0.00000000"],["79866.68000000","0.00000000"],["79866.71000000","0.00000000"],["79866.91000000","0.00000000"],["79866.96000000","0.00000000"],["79866.97000000","0.00000000"],["79867.03000000","0.00000000"],["79867.17000000","0.00000000"],["79867.44000000","0.00000000"],["79867.48000000","0.00000000"],["79867.49000000","0.00000000"],["79867.92000000","0.00000000"],["79867.99000000","0.00000000"],["79868.00000000","0.00000000"],["79868.52000000","0.00000000"],["79868.53000000","0.00000000"],["79868.79000000","0.00000000"],["79868.82000000","0.00000000"],["79869.06000000","0.00000000"],["79869.16000000","0.00000000"],["79869.23000000","0.00000000"],["79869.60000000","0.00000000"],["79869.61000000","0.00000000"],["79869.78000000","0.00000000"],["79869.80000000","0.00000000"],["79869.83000000","0.00000000"],["79869.97000000","0.00000000"],["79869.99000000","0.00000000"],["79870.00000000","0.00000000"],["79870.33000000","0.00000000"],["79870.40000000","0.00000000"],["79870.63000000","0.00000000"],["79870.86000000","0.00000000"],["79870.89000000","0.00000000"],["79871.01000000","0.00000000"],["79871.02000000","0.00000000"],["79871.26000000","0.00000000"],["79871.37000000","0.00000000"],["79871.64000000","0.00000000"],["79871.82000000","0.00000000"],["79871.83000000","0.00000000"],["79871.91000000","0.00000000"],["79871.99000000","0.00000000"],["79872.00000000","0.00000000"],["79872.02000000","0.00000000"],["79872.07000000","0.00000000"],["79872.08000000","0.00000000"],["79872.88000000","0.00000000"],["79872.92000000","0.00000000"],["79872.93000000","0.00000000"],["79872.94000000","0.00000000"],["79872.97000000","0.00000000"],["79873.23000000","0.00000000"],["79873.30000000","0.80988000"],["79873.31000000","0.00035000"],["79873.50000000","0.00000000"],["79873.54000000","0.00000000"],["79873.55000000","0.00000000"],["79873.74000000","0.00000000"],["79873.82000000","0.00000000"],["79873.92000000","0.00000000"],["79873.97000000","0.00000000"],["79873.98000000","0.00007000"],["79873.99000000","0.00007000"],["79874.00000000","0.02407000"],["79874.03000000","0.00000000"],["79874.12000000","0.00000000"],["79874.21000000","0.00000000"],["79874.27000000","0.00000000"],["79874.28000000","0.00007000"],["79874.33000000","0.00000000"],["79874.46000000","0.00000000"],["79874.59000000","0.00007000"],["79874.60000000","0.02007000"],["79874.61000000","0.00000000"],["79874.62000000","0.00007000"],["79874.69000000","0.00000000"],["79874.72000000","0.00000000"],["79874.74000000","0.00000000"],["79875.16000000","0.00000000"],["79875.36000000","0.00007000"],["79875.37000000","0.02007000"],["79875.42000000","0.00000000"],["79875.43000000","0.00007000"],["79875.48000000","0.00007000"],["79875.49000000","0.02007000"],["79875.54000000","0.00007000"],["79875.55000000","0.02007000"],["79875.78000000","0.00000000"],["79875.89000000","0.00000000"],["79875.92000000","0.00000000"],["79875.93000000","0.00000000"],["79875.94000000","0.00000000"],["79875.95000000","0.00000000"],["79875.98000000","0.00000000"],["79875.99000000","0.00007000"],["79876.00000000","0.02414000"],["79876.10000000","0.00007000"],["79876.12000000","0.00000000"],["79876.13000000","0.00000000"],["79876.21000000","0.00007000"],["79876.22000000","0.04775000"],["79876.26000000","0.00000000"],["79876.27000000","0.00007000"],["79876.40000000","0.06316000"],["79876.52000000","0.00007000"],["79876.53000000","0.10396000"],["79876.54000000","0.00007000"],["79876.68000000","0.00000000"],["79876.69000000","0.00000000"],["79876.70000000","0.00000000"],["79876.80000000","0.00007000"],["79876.86000000","0.00000000"],["79876.97000000","0.00000000"],["79877.01000000","0.00000000"],["79877.02000000","0.05734000"],["79877.26000000","0.00000000"],["79877.41000000","0.00000000"],["79877.56000000","0.00007000"],["79877.63000000","0.00007000"],["79877.64000000","0.06153000"],["79877.75000000","0.02014000"],["79877.76000000","0.00000000"],["79877.97000000","0.00000000"],["79878.04000000","0.33819000"],["79878.26000000","0.05985000"],["79878.30000000","0.00007000"],["79878.53000000","0.00007000"],["79878.62000000","0.00000000"],["79878.68000000","0.02014000"],["79878.74000000","0.00000000"],["79878.88000000","0.05962000"],["79878.91000000","0.00202000"],["79879.16000000","0.02007000"],["79879.17000000","0.00000000"],["79879.32000000","0.00007000"],["79879.33000000","0.04221000"],["79879.50000000","0.06316000"],["79879.51000000","0.00693000"],["79879.55000000","0.00000000"],["79879.56000000","0.04014000"],["79879.80000000","0.00000000"],["79879.97000000","0.26639000"],["79879.98000000","0.20250000"],["79879.99000000","0.00000000"],["79880.00000000","0.02435000"],["79880.12000000","0.00000000"],["79880.67000000","0.00014000"],["79880.69000000","0.00000000"],["79880.70000000","0.00000000"],["79880.73000000","0.00000000"],["79880.74000000","0.06316000"],["79880.77000000","0.00000000"],["79881.29000000","0.00015000"],["79881.33000000","0.00156000"],["79881.36000000","0.06316000"],["79881.37000000","0.00000000"],["79881.91000000","0.00000000"],["79881.92000000","0.00000000"],["79881.93000000","0.00000000"],["79881.98000000","0.06316000"],["79882.02000000","0.00000000"],["79882.04000000","0.00000000"],["79882.16000000","0.00000000"],["79882.17000000","0.00000000"],["79882.48000000","0.00000000"],["79882.60000000","0.06316000"],["79882.74000000","0.00711000"],["79883.20000000","0.06316000"],["79883.21000000","0.12518000"],["79883.22000000","0.00000000"],["79883.30000000","0.00000000"],["79883.35000000","0.00000000"],["79883.36000000","0.00000000"],["79883.37000000","0.00000000"],["79883.40000000","0.00000000"],["79883.84000000","0.06316000"],["79883.96000000","0.00000000"],["79884.46000000","0.06316000"],["79884.48000000","0.00007000"],["79884.54000000","0.00014000"],["79884.57000000","0.00000000"],["79884.75000000","0.00190000"],["79884.79000000","0.00000000"],["79885.07000000","0.06316000"],["79885.08000000","0.00000000"],["79885.19000000","0.06316000"],["79885.20000000","0.33102000"],["79885.29000000","0.00625000"],["79885.95000000","0.00000000"],["79886.32000000","0.06316000"],["79886.37000000","0.00000000"],["79886.48000000","0.00000000"],["79886.60000000","0.00008000"],["79886.74000000","0.00686000"],["79886.94000000","0.06316000"],["79887.24000000","0.00000000"],["79887.33000000","0.05902000"],["79887.34000000","1.04939000"],["79887.35000000","0.00000000"],["79887.56000000","0.00000000"],["79887.58000000","0.00000000"],["79887.59000000","0.00000000"],["79887.60000000","0.00000000"],["79887.67000000","0.00007000"],["79887.77000000","0.00000000"],["79887.88000000","0.00000000"],["79887.93000000","0.00000000"],["79887.96000000","0.00125000"],["79887.97000000","0.00000000"],["79888.00000000","1.00194000"],["79888.19000000","0.00000000"],["79888.22000000","0.00000000"],["79888.41000000","0.00014000"],["79888.47000000","0.00000000"],["79888.49000000","0.00000000"],["79888.94000000","0.00626000"],["79889.07000000","1.87677000"],["79889.48000000","0.00000000"],["79889.74000000","0.20250000"],["79889.77000000","0.15000000"],["79889.94000000","0.00000000"],["79890.00000000","0.11788000"],["79890.04000000","0.00007000"],["79890.24000000","0.00000000"],["79890.28000000","0.00000000"],["79890.60000000","0.00008000"],["79890.74000000","0.00704000"],["79891.41000000","0.09462000"],["79891.51000000","1.04939000"],["79891.52000000","0.00000000"],["79891.66000000","0.00000000"],["79892.25000000","0.00000000"],["79892.49000000","0.00000000"],["79892.81000000","0.36698000"],["79892.89000000","0.02253000"],["79893.01000000","0.00000000"],["79893.19000000","0.00250000"],["79893.41000000","0.10366000"],["79893.65000000","0.00000000"],["79893.94000000","0.19019000"],["79893.95000000","1.08461000"],["79894.27000000","0.00000000"],["79894.42000000","0.00000000"],["79894.59000000","0.00008000"],["79894.61000000","0.01100000"],["79894.68000000","0.00000000"],["79894.74000000","0.00696000"],["79894.84000000","0.02000000"],["79895.84000000","0.00000000"],["79896.00000000","0.02407000"],["79896.34000000","0.00000000"],["79896.43000000","0.00626000"],["79896.53000000","0.60032000"],["79897.35000000","0.10000000"],["79897.36000000","0.00000000"],["79897.93000000","0.00000000"],["79898.00000000","0.02400000"],["79898.13000000","0.00000000"],["79898.27000000","0.00000000"],["79898.58000000","0.00008000"],["79899.48000000","0.00000000"],["79900.00000000","1.12313000"],["79900.02000000","0.00014000"],["79900.07000000","0.00250000"],["79902.26000000","0.00000000"],["79902.31000000","0.00000000"],["79902.58000000","0.00008000"],["79902.78000000","0.42953000"],["79903.36000000","0.00000000"],["79903.76000000","0.78665000"],["79903.89000000","0.00014000"],["79904.00000000","0.72407000"],["79904.72000000","0.00007000"],["79904.88000000","0.00400000"],["79906.25000000","0.00000000"],["79906.34000000","0.00000000"],["79906.41000000","0.00000000"],["79906.57000000","0.00008000"],["79906.67000000","0.00000000"],["79906.94000000","0.00000000"],["79907.27000000","0.00000000"],["79907.36000000","0.00000000"],["79907.40000000","0.00000000"],["79907.76000000","0.00014000"],["79907.77000000","0.00000000"],["79907.79000000","0.33796000"],["79908.44000000","0.00012000"],["79909.20000000","0.00400000"],["79909.31000000","0.64081000"],["79910.46000000","0.00059000"],["79910.57000000","0.00008000"],["79911.63000000","0.00014000"],["79911.85000000","0.34359000"],["79911.86000000","0.62583000"],["79912.64000000","0.00000000"],["79913.14000000","0.00000000"],["79913.52000000","0.00400000"],["79914.00000000","0.03400000"],["79915.50000000","0.00007000"],["79915.80000000","0.00000000"],["79917.52000000","0.00000000"],["79917.66000000","0.04641000"],["79918.42000000","0.00573000"],["79918.43000000","0.00000000"],["79919.37000000","0.00000000"],["79919.58000000","0.00000000"],["79920.60000000","0.00000000"],["79922.80000000","0.00000000"],["79925.52000000","0.00000000"],["79926.51000000","0.00000000"],["79928.93000000","0.00312000"],["79933.35000000","0.00008000"],["79935.86000000","0.00000000"],["79935.97000000","0.25000000"],["79940.18000000","0.00000000"],["79941.44000000","0.00218000"],["79942.33000000","1.23868000"],["79943.86000000","0.00000000"],["79945.56000000","0.01270000"],["79947.55000000","0.00110000"],["79947.59000000","0.00000000"],["79951.62000000","1.11655000"],["79952.91000000","0.00000000"],["79953.42000000","0.00008000"],["79953.99000000","0.00000000"],["79954.48000000","0.00000000"],["79955.91000000","0.00000000"],["79955.99000000","0.00000000"],["79958.12000000","0.00000000"],["79959.42000000","0.00007000"],["79959.56000000","0.00000000"],["79959.85000000","0.00000000"],["79959.88000000","0.42413000"],["79960.08000000","0.00000000"],["79960.31000000","0.00000000"],["79960.71000000","0.00000000"],["79960.94000000","0.00000000"],["79961.49000000","0.00000000"],["79961.59000000","0.12171000"],["79962.04000000","0.00000000"],["79962.95000000","0.00000000"],["79963.99000000","0.58337000"],["79964.06000000","1.87677000"],["79965.44000000","0.00000000"],["79967.84000000","0.42419000"],["79969.49000000","0.00274000"],["79969.50000000","1.04939000"],["79990.23000000","0.00000000"],["79991.08000000","0.36586000"],["80001.35000000","0.00000000"],["80004.62000000","0.00000000"],["80009.99000000","0.00125000"],["80015.71000000","0.00000000"],["80018.04000000","0.00000000"],["80023.73000000","0.00000000"],["80032.00000000","1.50063000"],["80033.30000000","0.00008000"],["80074.36000000","3.74739000"],["80078.32000000","0.00000000"],["80086.76000000","0.00007000"],["80089.28000000","0.01961000"],["80090.75000000","0.00007000"],["80095.57000000","0.00000000"],["80096.00000000","0.00007000"],["80103.59000000","0.00000000"],["80113.17000000","0.00008000"],["80137.18000000","0.00000000"],["80149.63000000","0.00032000"],["80213.35000000","0.00000000"],["80244.16000000","0.20250000"],["80247.44000000","0.00000000"],["80255.28000000","0.00000000"],["80256.69000000","0.54998000"],["80263.32000000","0.00000000"],["80272.37000000","0.00626000"],["80272.92000000","0.00008000"],["80414.99000000","0.00000000"],["80423.05000000","0.00000000"],["80432.66000000","0.00008000"],["80494.85000000","0.00000000"],["80502.91000000","0.00000000"],["80512.54000000","0.00008000"],["81055.87000000","0.00000000"],["81071.40000000","0.00092000"]]}}}
{"rx_ns": 13858152813700, "frame": {"stream":"btcusdt@depth@100ms","data":{"e":"depthUpdate","E":1787650853214,"s":"BTCUSDT","U":99118579823,"u":99118580229,"b":[["79873.29000000","4.04741000"],["79873.28000000","0.01178000"],["79872.16000000","0.00250000"],["79872.08000000","0.44491000"],["79872.07000000","0.00007000"],["79872.02000000","0.00007000"],["79872.01000000","0.01919000"],["79871.99000000","0.08515000"],["79870.74000000","0.00007000"],["79870.73000000","0.02302000"],["79870.64000000","0.00007000"],["79870.63000000","0.05277000"],["79870.56000000","0.00007000"],["79870.55000000","0.03231000"],["79869.99000000","0.00000000"],["79869.60000000","0.00000000"],["79869.46000000","0.00007000"],["79869.45000000","0.02303000"],["79869.07000000","0.00007000"],["79869.06000000","0.12555000"],["79868.53000000","0.00000000"],["79868.52000000","0.08508000"],["79868.20000000","0.00000000"],["79868.19000000","0.08515000"],["79868.16000000","0.00400000"],["79867.99000000","0.00000000"],["79867.97000000","0.01607000"],["79866.11000000","0.36586000"],["79864.95000000","0.00000000"],["79864.52000000","0.00000000"],["79864.19000000","0.00000000"],["79864.00000000","0.90063000"],["79863.86000000","0.30014000"],["79863.84000000","0.30400000"],["79862.95000000","0.30976000"],["79862.74000000","0.08576000"],["79862.33000000","0.46456000"],["79861.99000000","0.28650000"],["79861.70000000","0.00000000"],["79860.72000000","0.00008000"],["79860.00000000","0.09392000"],["79859.53000000","0.00626000"],["79858.33000000","0.00718000"],["79858.01000000","0.36586000"],["79858.00000000","0.61331000"],["79857.99000000","0.27023000"],["79856.96000000","0.00000000"],["79854.87000000","0.42951000"],["79846.79000000","0.01147000"],["79844.74000000","0.00000000"],["79840.00000000","0.32051000"],["79838.47000000","0.00000000"],["79835.56000000","0.00000000"],["79834.38000000","0.00000000"],["79833.00000000","0.01000000"],["79831.33000000","0.83252000"],["79830.92000000","0.00000000"],["79827.85000000","0.61403000"],["79825.34000000","0.00000000"],["79823.07000000","0.00628000"],["79822.26000000","0.00426000"],["79820.00000000","0.02400000"],["79810.79000000","0.00000000"],["79810.69000000","0.00000000"],["79805.83000000","0.00000000"],["79805.46000000","0.00000000"],["79805.20000000","0.00532000"],["79804.91000000","0.00000000"],["79803.63000000","0.00111000"],["79775.71000000","0.00000000"],["79732.11000000","0.04034000"],["79724.68000000","0.00000000"],["79699.47000000","0.00000000"],["79638.88000000","0.00000000"],["79635.35000000","0.00000000"],["79632.90000000","0.00000000"],["79628.91000000","0.00000000"],["79554.25000000","0.00035000"],["79076.87000000","0.00000000"],["79076.74000000","0.00000000"],["71885.97000000","0.00048000"],["67892.30000000","0.00051000"],["63886.40000000","0.00000000"]],"a":[["79873.30000000","0.23259000"],["79873.31000000","0.00028000"],["79873.98000000","0.00000000"],["79874.00000000","0.02428000"],["79874.53000000","0.05616000"],["79874.54000000","0.06316000"],["79874.59000000","0.00000000"],["79874.60000000","0.00014000"],["79874.80000000","0.00000000"],["79875.15000000","0.00007000"],["79875.16000000","0.06316000"],["79875.36000000","0.00000000"],["79875.37000000","0.00014000"],["79875.48000000","0.00000000"],["79875.49000000","0.00014000"],["79875.54000000","0.00000000"],["79875.55000000","0.00021000"],["79875.77000000","0.00007000"],["79875.78000000","0.06061000"],["79876.00000000","0.02421000"],["79876.11000000","0.00000000"],["79876.22000000","0.04789000"],["79876.39000000","0.00007000"],["79876.40000000","0.06323000"],["79876.52000000","0.00007000"],["79876.53000000","0.23300000"],["79876.65000000","0.00726000"],["79877.01000000","0.00007000"],["79877.63000000","0.00007000"],["79877.64000000","0.06160000"],["79877.75000000","0.00014000"],["79877.93000000","0.01217000"],["79877.99000000","0.06323000"],["79878.04000000","0.33819000"],["79878.26000000","0.00000000"],["79878.36000000","0.00000000"],["79878.68000000","0.00014000"],["79878.88000000","0.06056000"],["79879.16000000","0.00007000"],["79879.21000000","0.01452000"],["79879.27000000","0.00000000"],["79879.31000000","0.00000000"],["79879.32000000","0.00000000"],["79879.33000000","0.00007000"],["79879.51000000","0.00000000"],["79879.56000000","0.00000000"],["79879.96000000","0.06316000"],["79879.97000000","0.20323000"],["79879.98000000","0.00000000"],["79880.49000000","0.01452000"],["79880.74000000","0.06316000"],["79881.29000000","0.20272000"],["79881.36000000","0.05726000"],["79882.45000000","0.00069000"],["79882.61000000","0.00047000"],["79882.95000000","0.00048000"],["79882.98000000","0.00000000"],["79883.34000000","0.00048000"],["79884.45000000","0.10930000"],["79884.74000000","0.00000000"],["79885.20000000","0.00000000"],["79885.29000000","0.00000000"],["79886.32000000","0.06316000"],["79887.32000000","0.02400000"],["79887.34000000","0.00000000"],["79887.99000000","0.06316000"],["79888.13000000","0.00250000"],["79888.24000000","0.00000000"],["79888.65000000","0.00400000"],["79889.36000000","0.03013000"],["79889.77000000","0.03000000"],["79889.89000000","0.00000000"],["79890.00000000","0.02400000"],["79892.50000000","0.00000000"],["79892.68000000","0.12000000"],["79894.33000000","0.00400000"],["79894.61000000","0.00000000"],["79895.28000000","0.00000000"],["79895.67000000","1.04939000"],["79900.00000000","1.12062000"],["79901.28000000","0.00000000"],["79903.76000000","0.57893000"],["79904.00000000","0.02407000"],["79907.04000000","0.00400000"],["79907.31000000","0.00011000"],["79908.10000000","0.00000000"],["79909.57000000","0.00000000"],["79910.00000000","0.12037000"],["79910.82000000","0.00000000"],["79911.12000000","0.00000000"],["79912.22000000","0.33795000"],["79913.15000000","0.00000000"],["79913.70000000","0.00000000"],["79917.59000000","0.02480000"],["79918.81000000","1.20239000"],["79919.37000000","0.00007000"],["79920.82000000","0.00425000"],["79921.63000000","0.00618000"],["79923.81000000","0.00429000"],["79924.00000000","0.02830000"],["79925.53000000","0.40230000"],["79927.44000000","0.83152000"],["79932.39000000","0.00000000"],["79934.28000000","0.00400000"],["79939.90000000","0.54190000"],["79939.96000000","0.01140000"],["79961.59000000","0.00000000"],["79961.81000000","0.00000000"],["79962.03000000","0.00000000"],["79962.18000000","0.00000000"],["79962.92000000","0.00000000"],["79963.20000000","0.00000000"],["79964.18000000","0.00000000"],["79964.30000000","0.12274000"],["79964.44000000","0.00000000"],["79966.24000000","0.00400000"],["79967.15000000","0.00000000"],["79967.84000000","0.98089000"],["79970.66000000","1.99257000"],["79986.22000000","0.04559000"],["80012.37000000","0.00000000"],["80014.18000000","0.00400000"],["80016.24000000","0.10015000"],["80019.43000000","0.04586000"],["80084.25000000","0.00000000"],["80086.08000000","0.00400000"],["80094.74000000","0.00007000"],["80098.73000000","0.00007000"],["80102.72000000","0.00007000"],["80105.52000000","0.00007000"],["80106.71000000","0.00007000"],["80576.71000000","0.00000000"]]}}}
{"rx_ns": 13858260441800, "frame": {"stream":"btcusdt@depth@100ms","data":{"e":"depthUpdate","E":1787650853314,"s":"BTCUSDT","U":99118580230,"u":99118580434,"b":[["79873.29000000","4.05435000"],["79873.28000000","0.01192000"],["79872.16000000","0.00000000"],["79872.08000000","0.44491000"],["79872.07000000","0.00000000"],["79872.02000000","0.00000000"],["79872.01000000","0.01933000"],["79871.99000000","0.08515000"],["79871.35000000","0.00250000"],["79870.74000000","0.00000000"],["79870.73000000","0.02316000"],["79870.63000000","0.05277000"],["79870.55000000","0.03245000"],["79869.46000000","0.00000000"],["79869.45000000","0.02317000"],["79869.06000000","0.12541000"],["79868.53000000","0.00007000"],["79868.52000000","0.08494000"],["79868.20000000","0.00000000"],["79868.19000000","0.08501000"],["79867.21000000","0.00162000"],["79866.03000000","0.00007000"],["79864.00000000","0.90049000"],["79863.99000000","3.26427000"],["79862.95000000","0.30983000"],["79860.47000000","0.00000000"],["79859.99000000","0.33528000"],["79859.19000000","0.00000000"],["79857.92000000","0.00189000"],["79851.99000000","0.00052000"],["79843.99000000","0.00000000"],["79840.26000000","0.02448000"],["79830.03000000","0.00000000"],["79825.96000000","0.00000000"],["79818.56000000","0.00435000"],["79818.02000000","0.00429000"],["79805.01000000","0.00000000"],["79797.70000000","0.00626000"],["79796.79000000","0.00400000"],["79786.05000000","0.00000000"],["79764.85000000","0.00400000"],["79754.12000000","0.00000000"],["79732.11000000","0.00000000"],["79730.34000000","0.09310000"],["79716.95000000","0.00400000"],["79706.23000000","0.00000000"],["79688.20000000","3.76555000"],["79644.14000000","0.00000000"],["79634.38000000","0.00000000"],["71885.97000000","0.00064000"],["63898.63000000","0.00000000"],["63886.00000000","0.05602000"]],"a":[["79873.30000000","0.23280000"],["79873.31000000","0.00049000"],["79874.00000000","0.02435000"],["79874.52000000","0.00007000"],["79874.53000000","0.00014000"],["79874.54000000","0.06323000"],["79874.60000000","0.00007000"],["79875.16000000","0.06323000"],["79875.37000000","0.00007000"],["79875.49000000","0.00007000"],["79875.55000000","0.00014000"],["79875.78000000","0.06068000"],["79876.21000000","0.00007000"],["79876.39000000","0.00007000"],["79876.52000000","0.00007000"],["79877.01000000","0.00000000"],["79877.63000000","0.00000000"],["79878.02000000","0.00000000"],["79878.68000000","0.00007000"],["79878.88000000","0.00007000"],["79878.91000000","0.00000000"],["79879.16000000","0.00000000"],["79879.33000000","0.00000000"],["79879.46000000","0.00000000"],["79879.59000000","0.00000000"],["79880.74000000","0.00000000"],["79881.29000000","0.20272000"],["79881.36000000","0.00000000"],["79881.63000000","0.21576000"],["79881.98000000","0.00000000"],["79884.44000000","0.00000000"],["79884.46000000","0.00000000"],["79887.31000000","0.00250000"],["79887.32000000","0.01200000"],["79887.98000000","0.01200000"],["79888.13000000","0.00000000"],["79888.52000000","0.00000000"],["79888.65000000","0.00000000"],["79888.69000000","0.00000000"],["79888.70000000","0.00000000"],["79891.78000000","0.00000000"],["79892.68000000","0.04000000"],["79893.36000000","0.04466000"],["79894.33000000","0.00000000"],["79894.58000000","0.08000000"],["79898.66000000","0.00000000"],["79912.51000000","0.00189000"],["79917.66000000","0.00000000"],["79919.37000000","0.00000000"],["79934.28000000","0.00000000"],["79937.91000000","0.00000000"],["79940.09000000","0.00000000"],["79947.99000000","0.07793000"],["79950.19000000","0.00000000"],["79952.73000000","0.01723000"],["79964.30000000","0.00000000"],["79964.64000000","0.11932000"],["79966.24000000","0.00000000"],["79968.42000000","0.09306000"],["79986.36000000","0.02804000"],["79995.38000000","0.00000000"],["80005.87000000","0.00000000"],["80014.18000000","0.00000000"],["80023.14000000","0.00400000"],["80086.08000000","0.00000000"],["80095.05000000","0.00400000"],["80106.71000000","0.00000000"]]}}}
{"rx_ns": 13858260574900, "frame": {"stream":"btcusdt@depth@100ms","data":{"e":"depthUpdate","E":1787650853414,"s":"BTCUSDT","U":99118580435,"u":99118580476,"b":[["79873.27000000","0.00026000"],["79872.09000000","0.26038000"],["79872.08000000","0.31335000"],["79870.32000000","0.00400000"],["79868.20000000","0.00007000"],["79862.33000000","0.69886000"],["79862.04000000","0.00007000"],["79836.12000000","0.00000000"],["79818.18000000","0.00000000"],["79746.75000000","0.04409000"],["79729.27000000","0.00000000"],["79726.68000000","0.00000000"],["79645.10000000","0.00400000"],["71885.97000000","0.00080000"],["63898.63000000","0.00020000"]],"a":[["79873.30000000","0.23273000"],["79873.31000000","0.00042000"],["79874.00000000","0.02435000"],["79874.52000000","0.00000000"],["79874.53000000","0.00007000"],["79876.53000000","0.23307000"],["79877.01000000","0.00007000"],["79880.32000000","0.00292000"],["79893.36000000","0.00000000"],["79898.59000000","0.04561000"],["79905.80000000","0.50577000"],["79929.77000000","1.00219000"],["79954.96000000","0.00535000"],["79974.56000000","0.00007000"],["79974.65000000","0.00000000"],["79977.34000000","0.00000000"],["79981.51000000","0.00000000"],["80044.84000000","0.00000000"],["80074.41000000","0.01961000"],["80089.28000000","0.00000000"],["80098.68000000","0.01961000"]]}}}
{"rx_ns": 13858302023600, "frame": {"stream":"btcusdt@depth@100ms","data":{"e":"depthUpdate","E":1787650853514,"s":"BTCUSDT","U":99118580477,"u":99118580519,"b":[["79873.29000000","4.05435000"],["79873.28000000","0.01199000"],["79872.49000000","0.00007000"],["79872.10000000","0.00007000"],["79872.09000000","0.26052000"],["79869.45000000","0.02303000"],["79864.00000000","1.22479000"],["79863.87000000","0.31310000"],["79862.33000000","0.69879000"],["79862.00000000","0.00700000"],["79860.00000000","0.10092000"],["79858.74000000","0.33817000"],["79858.00000000","0.62031000"],["79857.31000000","0.00007000"],["79856.43000000","0.02000000"],["79856.00000000","0.00707000"],["79855.71000000","0.00000000"],["79854.00000000","0.24244000"],["79853.44000000","0.00000000"],["79841.71000000","0.00000000"],["79819.44000000","1.00142000"],["79816.47000000","0.02000000"],["79744.55000000","0.00012000"],["79741.95000000","0.00008000"],["71885.97000000","0.00112000"],["63898.64000000","0.00031000"],["63898.63000000","0.00000000"]],"a":[["79880.25000000","0.12526000"],["79891.64000000","0.02000000"],["79898.59000000","0.00000000"],["79903.02000000","0.04432000"],["79909.29000000","0.33796000"],["79919.37000000","0.00007000"],["79942.19000000","0.02000000"]]}}}
{"rx_ns": 13858396563100, "frame": {"stream":"btcusdt@depth@100ms","data":{"e":"depthUpdate","E":1787650853614,"s":"BTCUSDT","U":99118580520,"u":99118580595,"b":[["79873.29000000","3.65757000"],["79871.36000000","0.00010000"],["79870.55000000","0.03252000"],["79870.33000000","0.00633000"],["79870.09000000","0.00007000"],["79870.01000000","0.00626000"],["79867.97000000","0.00007000"],["79866.12000000","0.00400000"],["79866.11000000","0.36593000"],["79865.20000000","0.01200000"],["79863.87000000","0.61310000"],["79863.57000000","0.30000000"],["79863.56000000","0.00000000"],["79862.95000000","0.00969000"],["79862.34000000","0.07500000"],["79860.88000000","0.00000000"],["79857.24000000","0.02000000"],["79856.44000000","0.02000000"],["79852.00000000","0.00700000"],["79843.16000000","0.02000000"],["79817.28000000","0.02000000"],["79816.47000000","0.04000000"],["79806.23000000","0.02087000"],["79674.65000000","0.00771000"],["79652.29000000","0.00000000"],["63899.00000000","0.13788000"],["63898.64000000","0.00000000"]],"a":[["79873.30000000","0.89923000"],["79873.31000000","0.00049000"],["79873.90000000","0.00007000"],["79873.91000000","0.08233000"],["79873.92000000","0.06318000"],["79875.99000000","0.00007000"],["79876.21000000","0.00007000"],["79876.39000000","0.00007000"],["79876.52000000","0.00000000"],["79876.53000000","0.17929000"],["79877.01000000","0.00000000"],["79878.88000000","0.06325000"],["79880.02000000","0.03322000"],["79880.25000000","0.00000000"],["79881.28000000","0.06318000"],["79881.29000000","0.20265000"],["79881.63000000","0.00000000"],["79884.44000000","0.06318000"],["79890.85000000","0.02000000"],["79891.64000000","0.04200000"],["79919.37000000","0.00000000"],["79943.24000000","0.00400000"],["79953.73000000","0.02000000"],["79956.80000000","0.02200000"]]}}}
{"rx_ns": 13858496023200, "frame": {"stream":"btcusdt@depth@100ms","data":{"e":"depthUpdate","E":1787650853714,"s":"BTCUSDT","U":99118580596,"u":99118580642,"b":[["79870.55000000","0.03245000"],["79869.07000000","0.00007000"],["79868.53000000","0.00007000"],["79868.20000000","0.00007000"],["79863.87000000","0.30000000"],["79858.16000000","0.00007000"],["79843.96000000","0.00000000"],["79843.84000000","0.33823000"],["79843.16000000","0.00000000"],["79838.76000000","0.00000000"],["79806.23000000","0.00000000"],["79766.32000000","0.00000000"],["79746.75000000","0.00000000"],["71885.97000000","0.00144000"]],"a":[["79873.30000000","0.87853000"],["79873.91000000","0.08240000"],["79873.92000000","0.06325000"],["79876.22000000","0.04803000"],["79876.24000000","0.00007000"],["79876.25000000","0.27768000"],["79876.26000000","0.15705000"],["79876.39000000","0.00000000"],["79876.40000000","0.06316000"],["79876.53000000","0.00021000"],["79880.02000000","0.00000000"],["79885.32000000","0.00007000"],["79902.23000000","0.00000000"],["79909.92000000","0.09310000"],["79989.98000000","0.00012000"],["79992.66000000","0.00018000"],["79996.83000000","0.00031000"]]}}}
{"rx_ns": 13858598127900, "frame": {"stream":"btcusdt@depth@100ms","data":{"e":"depthUpdate","E":1787650853814,"s":"BTCUSDT","U":99118580643,"u":99118580695,"b":[["79873.29000000","3.99569000"],["79871.36000000","0.00000000"],["79871.35000000","0.00000000"],["79869.51000000","0.00250000"],["79866.11000000","0.36600000"],["79866.08000000","0.19196000"],["79861.24000000","0.02600000"],["79861.10000000","0.02407000"],["79860.32000000","0.02000000"],["79858.02000000","0.51932000"],["79858.00000000","0.27628000"],["79857.24000000","0.04200000"],["79856.79000000","0.02000000"],["79856.39000000","0.04000000"],["79855.56000000","0.51665000"],["79850.00000000","0.12343000"],["79842.15000000","0.00000000"],["79836.71000000","0.00400000"],["79835.00000000","0.00000000"],["79821.28000000","0.02600000"],["79818.00000000","0.02400000"],["79817.27000000","0.02200000"],["79816.43000000","0.02000000"],["79767.07000000","0.00000000"],["79745.39000000","0.04409000"],["71885.97000000","0.00144000"],["63899.00000000","0.13788000"]],"a":[["79876.22000000","0.04803000"],["79878.04000000","0.00000000"],["79885.48000000","0.00250000"],["79886.85000000","0.02000000"],["79886.88000000","0.02000000"],["79887.31000000","0.00000000"],["79887.69000000","0.02000000"],["79890.84000000","0.02000000"],["79891.30000000","0.02000000"],["79891.69000000","0.02000000"],["79891.70000000","0.02000000"],["79901.98000000","0.00000000"],["79941.52000000","0.02000000"],["79941.94000000","0.02000000"],["79948.92000000","0.02000000"],["79949.35000000","0.02000000"],["79950.08000000","0.02000000"],["79951.74000000","0.02000000"],["79952.64000000","0.02000000"],["79953.73000000","0.00000000"]]}}}
{"rx_ns": 13858699438600, "frame": {"stream":"btcusdt@depth@100ms","data":{"e":"depthUpdate","E":1787650853914,"s":"BTCUSDT","U":99118580696,"u":99118580731,"b":[["79873.29000000","3.99576000"],["79866.03000000","0.00000000"],["79860.44000000","0.02200000"],["79860.40000000","0.02400000"],["79847.04000000","0.00000000"],["79846.25000000","0.00000000"],["79843.02000000","0.00000000"],["79842.16000000","0.00000000"],["79835.01000000","0.33078000"],["79785.17000000","0.00000000"],["79784.32000000","0.00000000"],["79745.39000000","0.00000000"],["71885.97000000","0.00160000"]],"a":[["79873.30000000","0.69264000"],["79876.25000000","0.17318000"],["79876.40000000","0.00000000"],["79877.75000000","0.00007000"],["79880.44000000","0.00000000"],["79884.02000000","0.00007000"],["79887.63000000","0.02000000"],["79887.69000000","0.04000000"],["79890.00000000","0.11788000"],["79901.13000000","0.33799000"],["79949.35000000","0.00000000"],["79949.80000000","0.02000000"],["79949.94000000","0.02000000"],["79950.08000000","0.00000000"],["79986.36000000","0.00000000"]]}}}
{"rx_ns": 13858797981300, "frame": {"stream":"btcusdt@depth20","data":{"lastUpdateId":99118580784,"bids":[["79873.29000000","3.99576000"],["79873.28000000","0.01199000"],["79873.27000000","0.00026000"],["79872.93000000","0.00014000"],["79872.49000000","0.00007000"],["79872.10000000","0.00007000"],["79872.09000000","0.26052000"],["79872.08000000","0.31335000"],["79872.01000000","0.01933000"],["79872.00000000","0.00007000"],["79871.99000000","0.08515000"],["79871.69000000","0.00007000"],["79870.73000000","0.02316000"],["79870.64000000","0.00007000"],["79870.63000000","0.05277000"],["79870.56000000","0.00007000"],["79870.55000000","0.03245000"],["79870.45000000","0.00250000"],["79870.33000000","0.00633000"],["79870.32000000","0.00400000"]],"asks":[["79873.30000000","0.90858000"],["79873.31000000","0.00049000"],["79873.68000000","0.00007000"],["79873.78000000","0.00100000"],["79873.90000000","0.00007000"],["79873.91000000","0.08240000"],["79873.92000000","0.06325000"],["79873.99000000","0.00007000"],["79874.00000000","0.02435000"],["79874.28000000","0.00007000"],["79874.53000000","0.00007000"],["79874.54000000","0.06323000"],["79874.60000000","0.00007000"],["79874.62000000","0.00007000"],["79875.02000000","0.00007000"],["79875.15000000","0.00007000"],["79875.16000000","0.06323000"],["79875.37000000","0.00007000"],["79875.43000000","0.00007000"],["79875.49000000","0.00007000"]]}}}
{"rx_ns": 13858798078600, "frame": {"stream":"btcusdt@depth@100ms","data":{"e":"depthUpdate","E":1787650854014,"s":"BTCUSDT","U":99118580732,"u":99118580784,"b":[["79871.69000000","0.00007000"],["79870.45000000","0.00250000"],["79869.51000000","0.00000000"],["79869.07000000","0.00007000"],["79868.53000000","0.00007000"],["79868.20000000","0.00007000"],["79858.02000000","0.54132000"],["79847.01000000","0.00000000"],["79846.21000000","0.00000000"],["79846.15000000","0.00000000"],["79843.92000000","0.00000000"],["79842.56000000","0.00000000"],["79791.03000000","0.00014000"],["79771.05000000","0.00000000"],["79739.67000000","0.00000000"],["79736.04000000","0.04540000"],["71885.97000000","0.00160000"],["71885.00000000","0.00060000"],["63898.64000000","0.00031000"]],"a":[["79873.30000000","0.90858000"],["79876.00000000","0.02435000"],["79876.02000000","0.00007000"],["79876.03000000","0.27314000"],["79876.04000000","0.33812000"],["79876.22000000","0.04789000"],["79876.24000000","0.00000000"],["79876.25000000","0.00000000"],["79876.53000000","0.00014000"],["79877.02000000","0.00000000"],["79885.48000000","0.00000000"],["79886.42000000","0.00250000"],["79890.03000000","0.02000000"],["79900.28000000","0.00000000"],["79901.57000000","0.00000000"],["79903.28000000","0.00400000"],["79910.33000000","0.00007000"],["79940.24000000","0.02000000"],["79948.92000000","0.00000000"],["79949.80000000","0.00000000"],["79975.61000000","0.02804000"]]}}}
{"rx_ns": 13858896894800, "frame": {"stream":"btcusdt@depth@100ms","data":{"e":"depthUpdate","E":1787650854115,"s":"BTCUSDT","U":99118580785,"u":99118580818,"b":[["79870.45000000","0.00000000"],["79869.24000000","0.00250000"],["79864.64000000","0.00007000"],["79862.57000000","0.00007000"],["79860.45000000","0.02000000"],["79860.29000000","0.20711000"],["79858.08000000","0.00007000"],["79857.34000000","0.12522000"],["79854.28000000","0.00007000"],["79849.35000000","0.12523000"],["79766.31000000","0.00000000"],["79766.19000000","0.00000000"],["78675.19000000","0.00030000"],["71885.97000000","0.00176000"],["71885.00000000","0.00040000"]],"a":[["79876.00000000","0.02435000"],["79876.03000000","0.27321000"],["79876.22000000","0.04782000"],["79876.80000000","0.00014000"],["79885.21000000","0.00250000"],["79886.42000000","0.00000000"],["79889.29000000","0.12517000"],["79890.04000000","0.00007000"],["79897.28000000","0.12516000"],["79932.88000000","0.02000000"],["79952.64000000","0.00000000"],["79956.80000000","0.00000000"],["81071.40000000","0.00092000"]]}}}
{"rx_ns": 13858996936300, "frame": {"stream":"btcusdt@depth@100ms","data":{"e":"depthUpdate","E":1787650854214,"s":"BTCUSDT","U":99118580819,"u":99118580848,"b":[["79873.29000000","3.98170000"],["79872.11000000","0.00008000"],["79872.01000000","0.02538000"],["79870.55000000","0.03252000"],["79867.30000000","0.00013000"],["79863.86000000","0.30000000"],["79847.11000000","0.00000000"],["79839.76000000","1.37213000"],["79839.75000000","1.24027000"],["79836.45000000","0.00000000"],["71885.96000000","0.00008000"],["63898.64000000","0.00000000"]],"a":[["79873.30000000","0.90837000"],["79877.64000000","0.00007000"],["79877.99000000","0.00007000"],["79879.29000000","0.00013000"],["79880.67000000","0.00014000"],["79881.18000000","0.12526000"],["79903.28000000","0.00000000"],["79943.24000000","0.00000000"],["79975.20000000","0.00000000"],["80023.14000000","0.00000000"],["80095.05000000","0.00000000"],["80592.15000000","0.00010000"]]}}}
{"rx_ns": 13859096298600, "frame": {"stream":"btcusdt@depth@100ms","data":{"e":"depthUpdate","E":1787650854314,"s":"BTCUSDT","U":99118580849,"u":99118580867,"b":[["79873.29000000","3.97487000"],["79857.88000000","0.33818000"],["79843.84000000","0.00000000"],["79806.23000000","0.02087000"],["79767.12000000","0.00000000"],["79688.58000000","0.00000000"],["71885.97000000","0.00192000"],["63898.63000000","0.00000000"],["63886.00000000","0.05602000"]],"a":[["79873.30000000","0.89683000"],["79881.18000000","0.00000000"],["79949.94000000","0.00000000"],["79951.74000000","0.00000000"],["80053.17000000","0.00000000"]]}}}
{"rx_ns": 13859197750500, "frame": {"stream":"btcusdt@depth@100ms","data":{"e":"depthUpdate","E":1787650854414,"s":"BTCUSDT","U":99118580868,"u":99118580879,"b":[["79873.29000000","3.97999000"],["79830.02000000","0.00311000"],["79815.06000000","0.53839000"],["79805.21000000","0.00311000"],["79794.60000000","0.00000000"],["79750.01000000","0.00125000"],["79734.01000000","0.00000000"],["71885.97000000","0.00192000"]],"a":[["79911.85000000","0.60870000"],["79912.00000000","0.72626000"],["79928.93000000","0.00000000"],["79939.98000000","0.00313000"],["80009.99000000","0.00000000"],["80019.98000000","0.00125000"],["80033.73000000","0.00000000"],["80049.65000000","0.00110000"],["80098.02000000","0.00400000"]]}}}
{"rx_ns": 13859297367900, "frame": {"stream":"btcusdt@depth@100ms","data":{"e":"depthUpdate","E":1787650854514,"s":"BTCUSDT","U":99118580880,"u":99118580900,"b":[["79866.11000000","0.36593000"],["79866.08000000","0.00000000"],["79855.56000000","0.00000000"],["79854.00000000","0.23559000"],["79849.85000000","0.00000000"],["79845.85000000","0.00000000"],["79839.79000000","0.00000000"],["79835.53000000","0.00000000"],["79697.36000000","4.41777000"],["71885.97000000","0.00192000"],["63898.64000000","0.00031000"],["63898.63000000","0.00000000"]],"a":[["79874.87000000","0.00007000"],["79880.71000000","0.00000000"],["79880.74000000","0.00000000"],["79890.01000000","0.00007000"],["80065.47000000","4.51615000"]]}}}
{"rx_ns": 13859399598700, "frame": {"stream":"btcusdt@depth@100ms","data":{"e":"depthUpdate","E":1787650854614,"s":"BTCUSDT","U":99118580901,"u":99118580910,"b":[["79872.01000000","0.01933000"],["79847.00000000","0.70000000"],["79806.23000000","0.00000000"],["71885.97000000","0.00224000"],["63898.64000000","0.00000000"]],"a":[["79873.30000000","0.89696000"],["79873.31000000","0.00062000"],["79873.32000000","0.00013000"],["80026.10000000","0.00400000"]]}}}
{"rx_ns": 13859502612600, "frame": {"stream":"btcusdt@depth@100ms","data":{"e":"depthUpdate","E":1787650854714,"s":"BTCUSDT","U":99118580911,"u":99118580920,"b":[["79873.29000000","3.99598000"],["79869.45000000","0.02310000"],["79869.29000000","0.00716000"],["79865.30000000","0.00933000"],["79865.29000000","0.00695000"],["79864.00000000","1.22472000"],["79863.99000000","3.26420000"],["71885.97000000","0.00224000"]],"a":[]}}}
{"rx_ns": 13859598402800, "frame": {"stream":"btcusdt@depth@100ms","data":{"e":"depthUpdate","E":1787650854814,"s":"BTCUSDT","U":99118580921,"u":99118580933,"b":[["79866.09000000","0.08761000"],["79854.94000000","0.50480000"],["79840.97000000","0.02400000"],["79840.18000000","0.02000000"],["79836.72000000","0.02000000"],["79836.29000000","0.02000000"],["79801.29000000","0.02600000"],["79785.17000000","0.02400000"],["79784.32000000","0.02000000"],["79674.65000000","0.00000000"],["79670.92000000","0.00771000"],["71885.97000000","0.00224000"]],"a":[["79978.16000000","0.00400000"]]}}}
{"rx_ns": 13859696509900, "frame": {"stream":"btcusdt@depth@100ms","data":{"e":"depthUpdate","E":1787650854914,"s":"BTCUSDT","U":99118580934,"u":99118581263,"b":[["79873.29000000","0.41600000"],["79872.93000000","0.00007000"],["79872.11000000","0.00000000"],["79872.10000000","0.00000000"],["79872.09000000","0.00014000"],["79872.08000000","0.00028000"],["79872.02000000","0.00007000"],["79872.00000000","0.00000000"],["79871.99000000","0.00028000"],["79870.74000000","0.00007000"],["79870.56000000","0.00000000"],["79870.55000000","0.00021000"],["79870.33000000","0.00000000"],["79870.32000000","0.00000000"],["79870.01000000","0.00000000"],["79869.46000000","0.00007000"],["79869.45000000","0.02303000"],["79869.29000000","0.00000000"],["79869.24000000","0.00000000"],["79869.06000000","0.12534000"],["79868.79000000","0.08000000"],["79868.54000000","0.00000000"],["79868.53000000","0.00000000"],["79868.52000000","0.00007000"],["79868.20000000","0.00000000"],["79868.19000000","0.00014000"],["79868.16000000","0.00000000"],["79867.96000000","0.00000000"],["79867.21000000","0.00000000"],["79866.12000000","0.00000000"],["79866.11000000","0.00007000"],["79866.10000000","0.00007000"],["79866.09000000","0.08768000"],["79866.00000000","0.00000000"],["79865.91000000","0.00007000"],["79865.90000000","0.31316000"],["79865.30000000","0.00940000"],["79865.29000000","0.00702000"],["79865.20000000","0.00000000"],["79865.19000000","0.00007000"],["79864.65000000","0.00000000"],["79864.03000000","0.00007000"],["79864.02000000","0.06086000"],["79864.01000000","0.02379000"],["79864.00000000","0.90749000"],["79863.99000000","1.09846000"],["79862.96000000","0.00000000"],["79862.95000000","0.00000000"],["79862.74000000","0.00000000"],["79862.58000000","0.00007000"],["79862.32000000","1.04939000"],["79861.69000000","0.00013000"],["79861.52000000","0.08576000"],["79861.32000000","0.00007000"],["79860.73000000","0.00626000"],["79860.29000000","0.01097000"],["79860.00000000","0.00700000"],["79859.99000000","0.20631000"],["79859.53000000","0.00000000"],["79858.74000000","0.00000000"],["79858.03000000","0.36586000"],["79858.02000000","0.35965000"],["79858.01000000","0.00000000"],["79857.88000000","0.00000000"],["79857.45000000","0.00007000"],["79857.35000000","0.00626000"],["79857.15000000","0.00400000"],["79856.96000000","0.00162000"],["79855.73000000","0.00000000"],["79854.87000000","0.00000000"],["79853.58000000","0.00007000"],["79852.49000000","0.00000000"],["79851.93000000","0.00400000"],["79851.92000000","0.00000000"],["79851.82000000","0.33820000"],["79850.94000000","0.00626000"],["79850.00000000","0.12092000"],["79848.94000000","0.03457000"],["79847.71000000","0.42955000"],["79844.06000000","0.00000000"],["79841.91000000","0.33824000"],["79840.33000000","0.02200000"],["79840.27000000","0.02400000"],["79840.00000000","0.32302000"],["79839.75000000","0.00000000"],["79838.71000000","0.33826000"],["79835.14000000","0.61875000"],["79835.13000000","0.62643000"],["79835.01000000","0.00000000"],["79832.89000000","0.33828000"],["79831.85000000","0.00400000"],["79831.69000000","0.00000000"],["79830.36000000","0.00007000"],["79830.01000000","0.00000000"],["79829.83000000","0.00000000"],["79829.82000000","0.00014000"],["79827.15000000","0.00400000"],["79822.45000000","0.00400000"],["79800.10000000","1.24089000"],["79785.17000000","0.00000000"],["79784.32000000","0.00000000"],["79774.13000000","0.00000000"],["79741.47000000","0.20250000"],["79553.10000000","7.54390000"],["79545.63000000","0.00000000"],["71885.97000000","0.00240000"],["71885.96000000","0.00000000"],["71885.95000000","0.00008000"]],"a":[["79873.30000000","4.02150000"],["79873.31000000","0.00020000"],["79873.35000000","0.05000000"],["79873.36000000","0.00698000"],["79873.90000000","0.00000000"],["79873.91000000","0.03535000"],["79873.92000000","0.00007000"],["79873.99000000","0.00000000"],["79874.00000000","0.02428000"],["79874.15000000","0.00400000"],["79874.53000000","0.00000000"],["79874.54000000","0.00014000"],["79874.86000000","0.00026000"],["79875.02000000","0.08854000"],["79875.15000000","0.00000000"],["79875.16000000","0.00007000"],["79875.36000000","0.00000000"],["79875.77000000","0.00000000"],["79875.78000000","0.00007000"],["79875.99000000","0.00000000"],["79876.00000000","0.02428000"],["79876.02000000","0.00000000"],["79876.03000000","0.58313000"],["79876.04000000","0.00000000"],["79876.21000000","0.00000000"],["79876.22000000","0.04782000"],["79876.26000000","0.00000000"],["79876.46000000","0.00905000"],["79876.57000000","0.00000000"],["79876.65000000","0.00733000"],["79877.02000000","0.00000000"],["79877.27000000","0.00250000"],["79877.58000000","0.00688000"],["79877.64000000","0.00007000"],["79877.93000000","0.01217000"],["79878.26000000","0.00000000"],["79878.69000000","1.87677000"],["79878.82000000","0.00000000"],["79878.88000000","0.00007000"],["79879.50000000","0.00000000"],["79879.96000000","0.00000000"],["79879.97000000","0.87461000"],["79880.36000000","0.00695000"],["79880.74000000","0.00000000"],["79880.83000000","0.02000000"],["79881.27000000","0.01600000"],["79881.28000000","0.00000000"],["79881.98000000","0.00000000"],["79882.16000000","0.03224000"],["79882.45000000","0.00000000"],["79882.60000000","0.00000000"],["79882.61000000","0.00000000"],["79882.82000000","0.00000000"],["79882.95000000","0.00000000"],["79883.09000000","0.36586000"],["79883.20000000","0.00000000"],["79883.34000000","0.00000000"],["79883.53000000","0.00000000"],["79883.54000000","1.87677000"],["79883.84000000","0.00000000"],["79884.44000000","0.00000000"],["79884.45000000","0.43725000"],["79885.07000000","0.00000000"],["79885.19000000","0.00000000"],["79885.21000000","0.00000000"],["79886.30000000","1.04939000"],["79886.32000000","0.00000000"],["79886.94000000","0.00000000"],["79887.32000000","0.00800000"],["79887.33000000","0.00000000"],["79887.92000000","0.03013000"],["79887.97000000","0.00000000"],["79887.98000000","0.00000000"],["79887.99000000","0.00000000"],["79888.94000000","0.00000000"],["79889.36000000","0.00000000"],["79892.35000000","0.03224000"],["79894.44000000","0.33802000"],["79894.58000000","0.41802000"],["79894.74000000","0.00007000"],["79894.84000000","0.00000000"],["79899.49000000","0.62593000"],["79907.79000000","0.00000000"],["79909.29000000","0.00000000"],["79911.04000000","0.02444000"],["79911.75000000","0.00000000"],["79912.22000000","0.00000000"],["79913.52000000","0.00000000"],["79915.50000000","0.00000000"],["79933.71000000","0.12260000"],["79933.72000000","0.00000000"]]}}}
{"rx_ns": 13859797017700, "frame": {"stream":"btcusdt@depth20","data":{"lastUpdateId":99118581386,"bids":[["79873.29000000","0.37771000"],["79873.28000000","0.01192000"],["79873.27000000","0.00026000"],["79872.93000000","0.00007000"],["79872.49000000","0.00007000"],["79872.08000000","0.00014000"],["79872.02000000","0.00007000"],["79872.01000000","0.01933000"],["79871.99000000","0.00014000"],["79871.69000000","0.00007000"],["79870.74000000","0.00007000"],["79870.73000000","0.02316000"],["79870.64000000","0.00007000"],["79870.63000000","0.05284000"],["79870.61000000","0.00007000"],["79870.60000000","0.33812000"],["79870.55000000","0.00007000"],["79870.09000000","0.00007000"],["79870.00000000","0.00007000"],["79869.46000000","0.00007000"]],"asks":[["79873.30000000","4.15646000"],["79873.31000000","0.00020000"],["79873.32000000","0.00013000"],["79873.34000000","0.02620000"],["79873.35000000","0.05014000"],["79873.36000000","0.00007000"],["79873.68000000","0.00007000"],["79873.78000000","0.00100000"],["79873.91000000","0.00007000"],["79874.00000000","0.02428000"],["79874.15000000","0.00400000"],["79874.18000000","0.00712000"],["79874.28000000","0.00007000"],["79874.54000000","0.00007000"],["79874.60000000","0.00007000"],["79874.62000000","0.00007000"],["79874.86000000","0.00026000"],["79874.87000000","0.00007000"],["79875.02000000","0.00014000"],["79875.37000000","0.00007000"]]}}}
{"rx_ns": 13859797291700, "frame": {"stream":"btcusdt@depth@100ms","data":{"e":"depthUpdate","E":1787650855014,"s":"BTCUSDT","U":99118581264,"u":99118581386,"b":[["79873.29000000","0.37771000"],["79873.28000000","0.01192000"],["79872.09000000","0.00000000"],["79872.08000000","0.00014000"],["79872.01000000","0.01933000"],["79871.99000000","0.00014000"],["79870.63000000","0.05284000"],["79870.61000000","0.00007000"],["79870.60000000","0.33812000"],["79870.55000000","0.00007000"],["79869.45000000","0.02317000"],["79869.25000000","0.04026000"],["79869.06000000","0.12562000"],["79868.80000000","0.00007000"],["79868.79000000","0.08021000"],["79866.42000000","0.00026000"],["79866.11000000","0.00014000"],["79866.10000000","0.06324000"],["79866.09000000","0.08782000"],["79865.91000000","0.00000000"],["79865.29000000","0.00716000"],["79865.19000000","0.00014000"],["79864.62000000","0.66630000"],["79864.61000000","0.00000000"],["79864.03000000","0.00000000"],["79864.02000000","0.00000000"],["79864.01000000","0.02372000"],["79864.00000000","0.08207000"],["79862.65000000","0.00192000"],["79861.91000000","0.00250000"],["79861.71000000","0.00048000"],["79861.69000000","0.00060000"],["79861.32000000","0.00014000"],["79857.45000000","0.00014000"],["79853.58000000","0.00014000"],["79847.00000000","0.00000000"],["79837.88000000","0.02200000"],["79833.35000000","0.00008000"],["79806.23000000","0.02087000"],["79793.41000000","0.00020000"],["79784.25000000","0.00000000"],["79780.81000000","0.00000000"],["78999.88000000","0.00231000"],["71885.97000000","0.00256000"],["63898.64000000","0.00031000"]],"a":[["79873.30000000","4.15646000"],["79873.34000000","0.02620000"],["79873.35000000","0.05014000"],["79873.36000000","0.00007000"],["79873.91000000","0.00007000"],["79873.92000000","0.00000000"],["79874.00000000","0.02428000"],["79874.18000000","0.00712000"],["79874.54000000","0.00007000"],["79875.02000000","0.00014000"],["79875.16000000","0.00000000"],["79875.55000000","0.00007000"],["79875.78000000","0.00000000"],["79876.03000000","0.58313000"],["79876.22000000","0.04789000"],["79884.75000000","0.00000000"],["79910.00000000","0.11786000"],["79946.20000000","0.00400000"],["79967.84000000","1.52061000"],["79970.87000000","1.95350000"]]}}}
{"rx_ns": 13859901559200, "frame": {"stream":"btcusdt@depth@100ms","data":{"e":"depthUpdate","E":1787650855114,"s":"BTCUSDT","U":99118581387,"u":99118581452,"b":[["79873.29000000","0.35051000"],["79870.63000000","0.05284000"],["79870.60000000","0.33826000"],["79869.45000000","0.02324000"],["79869.26000000","0.00007000"],["79869.25000000","0.04040000"],["79869.06000000","0.12555000"],["79868.79000000","0.08007000"],["79866.72000000","0.00007000"],["79866.10000000","0.06317000"],["79866.09000000","0.00007000"],["79865.29000000","0.00702000"],["79861.91000000","0.00000000"],["79861.78000000","0.00250000"],["79860.49000000","0.00007000"],["79844.49000000","0.04459000"],["79840.33000000","0.04200000"],["79806.23000000","0.00000000"],["79776.36000000","0.00000000"],["79772.66000000","0.00025000"],["79757.38000000","0.00034000"],["78675.19000000","0.00030000"],["73465.69000000","0.00014000"],["71885.97000000","0.00256000"],["71885.00000000","0.00060000"]],"a":[["79873.30000000","4.16173000"],["79873.34000000","0.04252000"],["79873.35000000","0.05007000"],["79873.36000000","0.00000000"],["79873.91000000","0.00000000"],["79874.00000000","0.02428000"],["79874.18000000","0.00719000"],["79874.86000000","0.00000000"],["79875.02000000","0.00007000"],["79875.67000000","0.00007000"],["79876.46000000","0.00912000"],["79957.03000000","0.00000000"],["79972.35000000","0.00025000"],["81071.40000000","0.00092000"]]}}}
{"rx_ns": 13859996600800, "frame": {"stream":"btcusdt@depth@100ms","data":{"e":"depthUpdate","E":1787650855214,"s":"BTCUSDT","U":99118581453,"u":99118581487,"b":[["79873.29000000","0.35194000"],["79867.09000000","0.05886000"],["79866.47000000","0.06106000"],["79865.23000000","0.06317000"],["79864.63000000","0.06317000"],["79863.84000000","0.30000000"],["79858.08000000","0.00007000"],["79834.20000000","0.00400000"],["79797.84000000","1.24092000"],["79775.97000000","0.00000000"],["79674.65000000","0.00771000"],["79670.92000000","0.00000000"],["71885.97000000","0.00272000"],["71885.00000000","0.00040000"],["63898.64000000","0.00000000"]],"a":[["79873.30000000","4.15555000"],["79875.99000000","0.00626000"],["79878.36000000","0.00000000"],["79878.68000000","0.01207000"],["79881.27000000","0.00400000"],["79882.30000000","1.04939000"],["79890.04000000","0.00007000"],["79903.29000000","0.02480000"],["79906.24000000","0.00400000"],["79917.59000000","0.00000000"],["79946.20000000","0.00000000"],["79959.88000000","1.06374000"],["79960.14000000","2.31199000"]]}}}
{"rx_ns": 13860103625000, "frame": {"stream":"btcusdt@depth@100ms","data":{"e":"depthUpdate","E":1787650855316,"s":"BTCUSDT","U":99118581488,"u":99118581509,"b":[["79873.29000000","0.37681000"],["79868.79000000","0.04014000"],["79867.09000000","0.05893000"],["79863.99000000","1.01846000"],["79861.79000000","0.08000000"],["79790.25000000","0.00000000"],["79784.24000000","0.00000000"],["71885.97000000","0.00272000"],["63899.00000000","0.13788000"],["63898.63000000","0.00020000"]],"a":[["79874.18000000","0.00726000"],["79875.99000000","0.00633000"],["79876.46000000","0.00905000"]]}}}
{"rx_ns": 13860199321700, "frame": {"stream":"btcusdt@depth@100ms","data":{"e":"depthUpdate","E":1787650855414,"s":"BTCUSDT","U":99118581510,"u":99118581528,"b":[["79870.60000000","0.33833000"],["79869.78000000","0.00591000"],["79868.19000000","0.00007000"],["79861.45000000","0.14809000"],["79846.76000000","0.00000000"],["79809.22000000","0.04696000"],["79786.92000000","0.00000000"],["79777.70000000","0.00000000"],["79730.22000000","0.00000000"],["71885.97000000","0.00288000"],["63898.63000000","0.00000000"]],"a":[["79906.24000000","0.00000000"],["79946.04000000","0.00000000"],["79978.16000000","0.00000000"],["80026.10000000","0.00000000"],["80098.02000000","0.00000000"]]}}}
{"rx_ns": 13860297632000, "frame": {"stream":"btcusdt@depth@100ms","data":{"e":"depthUpdate","E":1787650855514,"s":"BTCUSDT","U":99118581529,"u":99118581546,"b":[["79870.60000000","0.33833000"],["79869.78000000","0.00605000"],["79869.06000000","0.12548000"],["79847.10000000","0.48379000"],["79636.66000000","0.01961000"],["79630.52000000","0.00000000"],["63898.64000000","0.00031000"],["63898.63000000","0.00000000"]],"a":[["79877.27000000","0.00000000"],["79877.38000000","0.00250000"],["79887.34000000","0.33805000"]]}}}
{"rx_ns": 13860396334600, "frame": {"stream":"btcusdt@depth@100ms","data":{"e":"depthUpdate","E":1787650855614,"s":"BTCUSDT","U":99118581547,"u":99118581560,"b":[["79860.44000000","0.00000000"],["79840.33000000","0.02000000"],["79829.50000000","0.00400000"],["79822.45000000","0.00000000"],["79804.23000000","0.00008000"],["79690.35000000","0.00000000"],["73465.69000000","0.00000000"],["71885.97000000","0.00304000"],["63898.64000000","0.00000000"]],"a":[["79877.38000000","0.00000000"],["79877.39000000","0.00250000"],["79887.63000000","0.00000000"],["79903.76000000","0.86484000"],["79905.00000000","0.70000000"],["79909.83000000","0.00000000"],["79929.82000000","0.00000000"],["80021.94000000","0.00400000"]]}}}
{"rx_ns": 13860496136300, "frame": {"stream":"btcusdt@depth@100ms","data":{"e":"depthUpdate","E":1787650855714,"s":"BTCUSDT","U":99118581561,"u":99118581565,"b":[["79873.29000000","0.36681000"],["71885.97000000","0.00304000"]],"a":[["79877.39000000","0.00000000"],["79877.40000000","0.00250000"]]}}}
{"rx_ns": 13860608164200, "frame": {"stream":"btcusdt@depth@100ms","data":{"e":"depthUpdate","E":1787650855821,"s":"BTCUSDT","U":99118581566,"u":99118581590,"b":[["79873.29000000","0.34201000"],["79868.79000000","0.04021000"],["79868.44000000","0.00558000"],["79864.00000000","0.08907000"],["79862.00000000","0.01400000"],["79860.00000000","0.01400000"],["79858.00000000","0.28328000"],["79856.00000000","0.01407000"],["79854.00000000","0.24259000"],["79852.00000000","0.01400000"],["79849.24000000","0.00000000"],["79845.61000000","0.00000000"],["79838.35000000","0.09532000"],["79827.85000000","0.89814000"],["79826.82000000","1.03542000"],["79800.13000000","0.02087000"],["71885.97000000","0.00320000"]],"a":[["79902.08000000","0.00400000"],["79985.76000000","0.00000000"]]}}}
{"rx_ns": 13860697796300, "frame": {"stream":"btcusdt@depth@100ms","data":{"e":"depthUpdate","E":1787650855914,"s":"BTCUSDT","U":99118581591,"u":99118581613,"b":[["79873.29000000","0.36681000"],["79869.78000000","0.00014000"],["79864.64000000","0.01207000"],["79864.01000000","0.01172000"],["79864.00000000","0.09407000"],["79855.11000000","0.02200000"],["79815.15000000","0.02200000"],["79800.13000000","0.00000000"],["71885.97000000","0.00320000"]],"a":[["79873.33000000","0.00007000"],["79873.34000000","0.04259000"],["79873.99000000","0.00007000"],["79875.99000000","0.00640000"],["79876.02000000","0.00007000"],["79876.21000000","0.00007000"],["79884.38000000","0.02000000"],["79904.36000000","0.02000000"],["79924.34000000","0.02000000"]]}}}
{"rx_ns": 13860803085300, "frame": {"stream":"btcusdt@depth20","data":{"lastUpdateId":99118581642,"bids":[["79873.29000000","0.56924000"],["79873.28000000","0.01192000"],["79873.27000000","0.00026000"],["79872.93000000","0.00007000"],["79872.49000000","0.00007000"],["79872.08000000","0.00014000"],["79872.02000000","0.00007000"],["79872.01000000","0.01933000"],["79871.99000000","0.00014000"],["79871.69000000","0.00007000"],["79870.74000000","0.00007000"],["79870.73000000","0.02316000"],["79870.64000000","0.00007000"],["79870.63000000","0.05284000"],["79870.61000000","0.00007000"],["79870.60000000","0.33826000"],["79870.55000000","0.00007000"],["79870.09000000","0.00007000"],["79870.00000000","0.00007000"],["79869.46000000","0.00007000"]],"asks":[["79873.30000000","4.15555000"],["79873.31000000","0.00020000"],["79873.32000000","0.00013000"],["79873.33000000","0.00007000"],["79873.34000000","0.04259000"],["79873.35000000","0.05007000"],["79873.68000000","0.00007000"],["79873.78000000","0.00100000"],["79873.99000000","0.00007000"],["79874.00000000","0.02428000"],["79874.15000000","0.00400000"],["79874.18000000","0.00726000"],["79874.28000000","0.00007000"],["79874.54000000","0.00007000"],["79874.60000000","0.00007000"],["79874.62000000","0.00007000"],["79874.87000000","0.00007000"],["79875.02000000","0.00007000"],["79875.37000000","0.00007000"],["79875.43000000","0.00007000"]]}}}
{"rx_ns": 13860803184700, "frame": {"stream":"btcusdt@depth@100ms","data":{"e":"depthUpdate","E":1787650856014,"s":"BTCUSDT","U":99118581614,"u":99118581642,"b":[["79873.29000000","0.56924000"],["79870.60000000","0.33826000"],["79869.78000000","0.00000000"],["79869.06000000","0.12562000"],["79864.00000000","0.09907000"],["79862.00000000","0.02400000"],["79860.00000000","0.02400000"],["79858.00000000","0.29328000"],["79856.00000000","0.02407000"],["79854.00000000","0.25259000"],["79852.00000000","0.02400000"],["71885.97000000","0.00336000"],["63898.64000000","0.00031000"]],"a":[["79942.04000000","0.00400000"]]}}}
{"rx_ns": 13860907080600, "frame": {"stream":"btcusdt@depth@100ms","data":{"e":"depthUpdate","E":1787650856114,"s":"BTCUSDT","U":99118581643,"u":99118581673,"b":[["79873.29000000","0.54549000"],["79873.28000000","0.01241000"],["79868.80000000","0.00014000"],["79810.38000000","0.00007000"],["71885.97000000","0.00336000"]],"a":[["79884.38000000","0.04000000"],["80025.75000000","0.00000000"],["81071.40000000","0.00092000"]]}}}
{"rx_ns": 13860996966600, "frame": {"stream":"btcusdt@depth@100ms","data":{"e":"depthUpdate","E":1787650856214,"s":"BTCUSDT","U":99118581674,"u":99118581688,"b":[["79873.29000000","0.57029000"],["79871.99000000","0.00686000"],["79858.08000000","0.00007000"],["78675.19000000","0.00030000"],["71885.97000000","0.00352000"],["71885.00000000","0.00040000"],["63898.64000000","0.00000000"]],"a":[["79890.04000000","0.00007000"],["79892.92000000","0.00000000"],["79900.00000000","1.12313000"],["79910.00000000","0.12037000"],["80093.85000000","0.00400000"]]}}}
{"rx_ns": 13861096189000, "frame": {"stream":"btcusdt@depth@100ms","data":{"e":"depthUpdate","E":1787650856314,"s":"BTCUSDT","U":99118581689,"u":99118581711,"b":[["79873.29000000","0.57043000"],["79873.28000000","0.01248000"],["79872.01000000","0.01933000"],["79871.99000000","0.00700000"],["79869.06000000","0.12548000"],["79868.44000000","0.00565000"],["79867.59000000","0.00717000"],["79837.00000000","0.70000000"],["79821.12000000","0.00012000"],["79674.65000000","0.00000000"],["79647.23000000","0.00771000"],["71885.97000000","0.00368000"],["63899.00000000","0.13788000"]],"a":[["79873.30000000","4.16175000"],["79898.28000000","0.00012000"]]}}}
{"rx_ns": 13861196426000, "frame": {"stream":"btcusdt@depth@100ms","data":{"e":"depthUpdate","E":1787650856414,"s":"BTCUSDT","U":99118581712,"u":99118581720,"b":[["79873.29000000","0.55165000"],["71885.97000000","0.00352000"],["71885.95000000","0.00000000"],["63898.63000000","0.00000000"]],"a":[["79910.00000000","0.11786000"],["79942.04000000","0.00000000"],["79974.00000000","0.02400000"]]}}}
{"rx_ns": 13861302256900, "frame": {"stream":"btcusdt@depth@100ms","data":{"e":"depthUpdate","E":1787650856514,"s":"BTCUSDT","U":99118581721,"u":99118581729,"b":[["79860.40000000","0.00000000"],["79840.27000000","0.00000000"],["79804.22000000","0.00000000"],["79667.74000000","0.02177000"],["71885.97000000","0.00384000"],["63898.64000000","0.00031000"],["63898.63000000","0.00000000"]],"a":[["79873.30000000","4.15966000"],["79887.69000000","0.02000000"],["79909.98000000","0.00000000"],["79929.96000000","0.00000000"],["80029.84000000","0.02856000"],["80165.72000000","0.00000000"]]}}}
{"rx_ns": 13861399126200, "frame": {"stream":"btcusdt@depth@100ms","data":{"e":"depthUpdate","E":1787650856614,"s":"BTCUSDT","U":99118581730,"u":99118581735,"b":[["79873.29000000","0.52685000"],["71885.97000000","0.00384000"],["63898.64000000","0.00000000"]],"a":[["79873.30000000","4.16066000"],["79942.03000000","0.00400000"]]}}}
{"rx_ns": 13861508356500, "frame": {"stream":"btcusdt@depth@100ms","data":{"e":"depthUpdate","E":1787650856714,"s":"BTCUSDT","U":99118581736,"u":99118581806,"b":[["79873.29000000","0.97548000"],["79870.82000000","0.00007000"],["79870.81000000","0.06317000"],["79870.65000000","0.00007000"],["79870.64000000","0.06324000"],["79869.46000000","0.00000000"],["79869.45000000","0.02331000"],["79869.41000000","0.00934000"],["79869.08000000","0.00007000"],["79869.07000000","0.06324000"],["79869.06000000","0.12541000"],["79868.80000000","0.00007000"],["79868.79000000","0.04028000"],["79868.44000000","0.00007000"],["79868.36000000","0.00559000"],["79868.33000000","0.06317000"],["79867.71000000","0.06317000"],["79866.11000000","0.00007000"],["79865.29000000","0.00695000"],["79864.65000000","0.03456000"],["79862.36000000","1.20870000"],["79862.35000000","1.87677000"],["79862.33000000","0.07801000"],["79848.94000000","0.00000000"],["79830.47000000","1.24041000"],["79797.84000000","0.00000000"],["71885.97000000","0.00400000"]],"a":[["79873.30000000","2.28120000"],["79873.31000000","0.00048000"],["79875.99000000","0.00014000"],["79878.68000000","0.00014000"],["79879.20000000","0.00626000"],["79882.16000000","0.00000000"],["79882.29000000","0.01200000"]]}}}
{"rx_ns": 13861597878600, "frame": {"stream":"btcusdt@depth@100ms","data":{"e":"depthUpdate","E":1787650856814,"s":"BTCUSDT","U":99118581807,"u":99118581984,"b":[["79873.29000000","2.02116000"],["79873.28000000","0.01248000"],["79871.99000000","0.00707000"],["79870.83000000","0.00007000"],["79870.82000000","1.04939000"],["79870.81000000","0.00014000"],["79870.74000000","0.00000000"],["79870.73000000","0.02323000"],["79870.65000000","0.00000000"],["79870.64000000","0.00021000"],["79870.61000000","0.00000000"],["79870.60000000","0.00014000"],["79869.45000000","0.02317000"],["79869.26000000","0.00000000"],["79869.25000000","0.04033000"],["79869.08000000","0.00000000"],["79869.07000000","0.00007000"],["79869.06000000","0.12548000"],["79868.79000000","0.04014000"],["79868.53000000","0.00000000"],["79868.45000000","0.00015000"],["79868.33000000","0.00000000"],["79867.72000000","0.00000000"],["79867.71000000","0.00000000"],["79867.59000000","0.00724000"],["79867.10000000","0.00626000"],["79867.09000000","0.00000000"],["79866.47000000","0.00000000"],["79866.44000000","0.00007000"],["79866.43000000","1.00426000"],["79866.42000000","1.04965000"],["79866.11000000","0.00000000"],["79866.10000000","0.00000000"],["79866.09000000","0.00000000"],["79865.90000000","0.00000000"],["79865.35000000","0.00250000"],["79865.30000000","0.00933000"],["79865.23000000","0.00000000"],["79864.92000000","0.03224000"],["79864.63000000","0.00000000"],["79864.62000000","0.00000000"],["79864.46000000","0.00000000"],["79862.74000000","0.00000000"],["79862.65000000","0.00000000"],["79862.58000000","0.00000000"],["79861.78000000","0.00000000"],["79861.69000000","0.00047000"],["79860.73000000","0.00000000"],["79859.81000000","0.33817000"],["79858.04000000","0.57576000"],["79858.02000000","0.02200000"],["79856.15000000","0.37576000"],["79853.35000000","0.33819000"],["79852.30000000","0.33820000"],["79841.91000000","0.00000000"],["79838.71000000","0.00000000"],["79835.14000000","0.00000000"],["79835.13000000","0.00000000"],["79832.89000000","0.00000000"],["79830.36000000","0.00000000"],["79829.82000000","0.00021000"],["79780.48000000","0.36586000"]],"a":[["79873.30000000","1.94592000"],["79873.31000000","0.00048000"],["79874.18000000","0.00014000"],["79875.99000000","0.00007000"],["79876.46000000","0.00007000"],["79876.65000000","0.00726000"],["79876.89000000","0.00000000"],["79877.40000000","0.00000000"],["79877.58000000","0.00000000"],["79878.27000000","0.00000000"],["79878.68000000","0.00014000"],["79878.70000000","0.00000000"],["79879.20000000","0.00000000"],["79880.43000000","0.00000000"],["79880.83000000","0.00000000"],["79881.27000000","0.00000000"],["79881.31000000","0.00250000"],["79881.93000000","0.00626000"],["79882.29000000","0.00000000"],["79883.07000000","0.00189000"],["79885.99000000","0.00400000"],["79886.29000000","0.00400000"],["79887.32000000","0.00000000"],["79887.33000000","0.00400000"],["79887.34000000","0.02000000"],["79903.29000000","0.00000000"],["79909.13000000","0.33796000"],["79909.44000000","0.00000000"],["79918.81000000","0.00000000"],["79939.90000000","0.89435000"],["79942.95000000","1.23867000"],["79967.84000000","0.98089000"],["79970.87000000","0.00000000"],["79973.99000000","0.00400000"]]}}}
{"rx_ns": 13861707325500, "frame": {"stream":"btcusdt@depth@100ms","data":{"e":"depthUpdate","E":1787650856915,"s":"BTCUSDT","U":99118581985,"u":99118582048,"b":[["79873.29000000","2.02295000"],["79871.99000000","0.00700000"],["79870.82000000","1.04953000"],["79870.81000000","0.00000000"],["79870.73000000","0.02323000"],["79870.64000000","0.00007000"],["79870.63000000","0.05284000"],["79870.60000000","0.00000000"],["79870.52000000","0.00719000"],["79869.45000000","0.02331000"],["79869.41000000","0.00948000"],["79869.06000000","0.12541000"],["79868.52000000","0.00000000"],["79868.19000000","0.00000000"],["79867.97000000","0.00000000"],["79867.10000000","0.00633000"],["79865.30000000","0.00940000"],["79865.29000000","0.00702000"],["79855.07000000","0.02400000"],["79815.10000000","0.02400000"],["79795.17000000","0.02200000"],["71885.97000000","0.00416000"],["71885.96000000","0.00008000"]],"a":[["79874.00000000","0.02428000"],["79874.18000000","0.00007000"],["79876.22000000","0.04782000"],["79876.46000000","0.00000000"],["79876.65000000","0.00733000"],["79877.93000000","0.01224000"],["79878.68000000","0.00414000"],["79884.37000000","0.02000000"],["79885.99000000","0.00000000"],["79900.24000000","0.02480000"],["79904.35000000","0.02000000"],["79905.00000000","0.00000000"],["79908.54000000","1.64243000"],["79910.13000000","1.20235000"],["79924.33000000","0.02000000"]]}}}
{"rx_ns": 13861807033800, "frame": {"stream":"btcusdt@depth20","data":{"lastUpdateId":99118582071,"bids":[["79873.29000000","1.99822000"],["79873.28000000","0.01255000"],["79873.27000000","0.00026000"],["79872.93000000","0.00007000"],["79872.49000000","0.00007000"],["79872.08000000","0.00014000"],["79872.02000000","0.00007000"],["79872.01000000","0.01933000"],["79871.99000000","0.00700000"],["79871.69000000","0.00007000"],["79870.83000000","0.00007000"],["79870.82000000","1.04953000"],["79870.73000000","0.02323000"],["79870.64000000","0.00007000"],["79870.63000000","0.05284000"],["79870.55000000","0.00007000"],["79870.52000000","0.00733000"],["79870.09000000","0.00007000"],["79870.00000000","0.00007000"],["79869.45000000","0.02331000"]],"asks":[["79873.30000000","1.94592000"],["79873.31000000","0.00048000"],["79873.32000000","0.00013000"],["79873.33000000","0.00007000"],["79873.34000000","0.08964000"],["79873.35000000","0.05014000"],["79873.38000000","0.00007000"],["79873.39000000","0.17629000"],["79873.68000000","0.00007000"],["79873.78000000","0.00100000"],["79873.99000000","0.00007000"],["79874.00000000","0.02428000"],["79874.15000000","0.00400000"],["79874.18000000","0.00007000"],["79874.28000000","0.00007000"],["79874.54000000","0.00007000"],["79874.60000000","0.00007000"],["79874.62000000","0.00007000"],["79874.87000000","0.00007000"],["79875.02000000","0.00007000"]]}}}
{"rx_ns": 13861807183400, "frame": {"stream":"btcusdt@depth@100ms","data":{"e":"depthUpdate","E":1787650857014,"s":"BTCUSDT","U":99118582049,"u":99118582071,"b":[["79873.29000000","1.99822000"],["79873.28000000","0.01255000"],["79870.63000000","0.05284000"],["79870.52000000","0.00733000"],["79869.41000000","0.00934000"],["79867.59000000","0.00731000"],["79867.10000000","0.00007000"],["79865.36000000","0.00626000"],["79850.28000000","0.00000000"],["71885.97000000","0.00416000"],["63898.64000000","0.00031000"]],"a":[["79873.30000000","1.94592000"],["79873.34000000","0.08964000"],["79873.35000000","0.05014000"],["79873.38000000","0.00007000"],["79873.39000000","0.17629000"]]}}}
{"rx_ns": 13861896476000, "frame": {"stream":"btcusdt@depth@100ms","data":{"e":"depthUpdate","E":1787650857114,"s":"BTCUSDT","U":99118582072,"u":99118582089,"b":[["79873.29000000","2.02302000"],["79858.84000000","1.20235000"],["79714.31000000","0.00000000"],["71885.97000000","0.00432000"]],"a":[["79873.30000000","1.94599000"],["79873.31000000","0.00055000"],["79873.35000000","0.05014000"],["79873.39000000","0.17636000"],["79876.03000000","0.50854000"],["79877.93000000","0.01217000"],["79931.11000000","0.00007000"],["79935.26000000","0.00007000"],["81071.40000000","0.00092000"],["83000.00000000","113.26074000"]]}}}
{"rx_ns": 13862001493900, "frame": {"stream":"btcusdt@depth@100ms","data":{"e":"depthUpdate","E":1787650857214,"s":"BTCUSDT","U":99118582090,"u":99118582104,"b":[["79873.29000000","1.88904000"],["79872.93000000","0.00014000"],["79858.85000000","0.93695000"],["79858.08000000","0.00007000"],["79858.04000000","0.00000000"],["79780.81000000","0.62582000"],["79663.84000000","0.00771000"],["79647.23000000","0.00000000"],["78675.19000000","0.00030000"],["71885.97000000","0.00432000"],["63898.64000000","0.00000000"]],"a":[["79873.30000000","2.14849000"],["79890.04000000","0.00007000"]]}}}
{"rx_ns": 13862096363300, "frame": {"stream":"btcusdt@depth@100ms","data":{"e":"depthUpdate","E":1787650857314,"s":"BTCUSDT","U":99118582105,"u":99118582136,"b":[["79873.29000000","1.62080000"],["79870.52000000","0.00014000"],["79870.41000000","0.00709000"],["79868.45000000","0.00000000"],["79866.73000000","0.00012000"],["79864.00000000","0.09914000"],["79861.45000000","0.00000000"],["79857.99000000","0.27012000"],["79832.07000000","0.32041000"],["79802.35000000","0.00000000"],["79800.13000000","0.02087000"],["71885.97000000","0.00432000"],["71885.00000000","0.00040000"],["63899.00000000","0.13788000"]],"a":[["79873.30000000","2.14842000"],["79873.31000000","0.00048000"],["79878.68000000","0.00407000"],["79878.74000000","0.12528000"]]}}}
{"rx_ns": 13862201337200, "frame": {"stream":"btcusdt@depth@100ms","data":{"e":"depthUpdate","E":1787650857414,"s":"BTCUSDT","U":99118582137,"u":99118582183,"b":[["79873.29000000","1.61892000"],["79873.28000000","0.01255000"],["79872.93000000","0.00007000"],["79870.63000000","0.05284000"],["79870.52000000","0.00000000"],["79870.41000000","0.00014000"],["79869.45000000","0.02324000"],["79869.41000000","0.00000000"],["79867.59000000","0.00724000"],["79866.44000000","0.00407000"],["79865.37000000","0.00007000"],["79865.36000000","0.00000000"],["79865.35000000","0.00000000"],["79864.65000000","0.00000000"],["79864.01000000","0.00772000"],["79863.58000000","0.00818000"],["79862.36000000","0.60162000"],["79862.35000000","0.00000000"],["79859.81000000","0.00000000"],["79858.88000000","0.03457000"],["79858.87000000","1.49713000"],["79858.86000000","1.87677000"],["79858.85000000","0.00000000"],["79840.02000000","0.33825000"],["79800.13000000","0.00000000"],["79745.49000000","0.00008000"],["79728.47000000","0.00000000"],["71885.96000000","0.00000000"],["71885.95000000","0.00008000"],["63898.63000000","0.00000000"]],"a":[["79873.30000000","2.14831000"],["79881.31000000","0.00000000"],["80032.00000000","0.00007000"],["81250.00000000","1.88944000"]]}}}
{"rx_ns": 13862323643700, "frame": {"stream":"btcusdt@depth@100ms","data":{"e":"depthUpdate","E":1787650857514,"s":"BTCUSDT","U":99118582184,"u":99118582210,"b":[["79870.63000000","0.05277000"],["79870.41000000","0.00000000"],["79869.45000000","0.02324000"],["79869.25000000","0.04047000"],["79866.44000000","0.00007000"],["79864.64000000","0.00007000"],["79860.32000000","0.00000000"],["79858.89000000","0.00400000"],["79840.18000000","0.00000000"],["79804.30000000","0.00000000"],["71885.97000000","0.00432000"],["63898.64000000","0.00031000"],["63898.63000000","0.00000000"]],"a":[["79878.68000000","0.00414000"],["79887.69000000","0.00000000"],["79910.12000000","0.00000000"],["79930.09000000","0.00000000"]]}}}
{"rx_ns": 13862397573400, "frame": {"stream":"btcusdt@depth@100ms","data":{"e":"depthUpdate","E":1787650857614,"s":"BTCUSDT","U":99118582211,"u":99118582219,"b":[["79863.08000000","0.00400000"],["79861.43000000","0.25071000"],["79827.15000000","0.00000000"],["79705.61000000","0.00008000"],["79663.84000000","0.00000000"],["79647.23000000","0.00771000"],["71885.97000000","0.00448000"],["63898.64000000","0.00000000"]],"a":[]}}}
{"rx_ns": 13862498655900, "frame": {"stream":"btcusdt@depth@100ms","data":{"e":"depthUpdate","E":1787650857714,"s":"BTCUSDT","U":99118582220,"u":99118582226,"b":[["79873.29000000","1.61892000"],["79873.28000000","0.01248000"],["71885.97000000","0.00416000"]],"a":[["79873.30000000","2.14845000"],["79878.74000000","0.00000000"]]}}}
{"rx_ns": 13862600756200, "frame": {"stream":"btcusdt@depth@100ms","data":{"e":"depthUpdate","E":1787650857814,"s":"BTCUSDT","U":99118582227,"u":99118582238,"b":[["79873.29000000","1.61892000"],["79855.09000000","0.02000000"],["79842.00000000","0.72400000"],["79815.13000000","0.02000000"],["71885.97000000","0.00448000"]],"a":[["79884.28000000","0.02000000"],["79904.26000000","0.02000000"],["79924.24000000","0.02000000"],["80001.09000000","0.00151000"],["80255.10000000","0.00000000"]]}}}
{"rx_ns": 13862698471900, "frame": {"stream":"btcusdt@depth@100ms","data":{"e":"depthUpdate","E":1787650857914,"s":"BTCUSDT","U":99118582239,"u":99118582251,"b":[["79873.29000000","1.62639000"],["79866.44000000","0.00407000"],["79858.89000000","0.00000000"],["79795.12000000","0.02400000"],["71885.97000000","0.00432000"]],"a":[["79873.30000000","2.14852000"],["79876.91000000","0.00932000"],["79878.18000000","0.00695000"],["79908.00000000","0.72400000"]]}}}
{"rx_ns": 13862797872000, "frame": {"stream":"btcusdt@depth20","data":{"lastUpdateId":99118582271,"bids":[["79873.29000000","1.71314000"],["79873.28000000","0.01248000"],["79873.27000000","0.00026000"],["79872.93000000","0.00007000"],["79872.49000000","0.00007000"],["79872.08000000","0.00014000"],["79872.02000000","0.00007000"],["79872.01000000","0.01933000"],["79871.99000000","0.00700000"],["79871.69000000","0.00007000"],["79870.83000000","0.00007000"],["79870.82000000","1.04953000"],["79870.73000000","0.02323000"],["79870.64000000","0.00007000"],["79870.63000000","0.05284000"],["79870.55000000","0.00007000"],["79870.09000000","0.00007000"],["79870.00000000","0.00007000"],["79869.61000000","0.00939000"],["79869.45000000","0.02324000"]],"asks":[["79873.30000000","1.94277000"],["79873.31000000","0.00048000"],["79873.32000000","0.00013000"],["79873.33000000","0.00007000"],["79873.34000000","0.08964000"],["79873.35000000","0.05014000"],["79873.38000000","0.00007000"],["79873.39000000","0.17636000"],["79873.68000000","0.00007000"],["79873.78000000","0.00100000"],["79873.99000000","0.00007000"],["79874.00000000","0.02428000"],["79874.15000000","0.00400000"],["79874.18000000","0.00007000"],["79874.28000000","0.00007000"],["79874.54000000","0.00007000"],["79874.60000000","0.00007000"],["79874.62000000","0.00007000"],["79874.87000000","0.00007000"],["79875.02000000","0.00007000"]]}}}
{"rx_ns": 13862797979600, "frame": {"stream":"btcusdt@depth@100ms","data":{"e":"depthUpdate","E":1787650858014,"s":"BTCUSDT","U":99118582252,"u":99118582271,"b":[["79873.29000000","1.71314000"],["79870.63000000","0.05284000"],["79869.61000000","0.00939000"],["79865.37000000","0.00000000"],["79864.00000000","0.09907000"],["79863.58000000","0.00626000"],["71885.97000000","0.00432000"],["63898.64000000","0.00031000"]],"a":[["79873.30000000","1.94277000"],["79876.65000000","0.00740000"],["79882.29000000","1.04939000"],["79882.30000000","0.00000000"],["79993.80000000","0.00000000"]]}}}
{"rx_ns": 13862897192400, "frame": {"stream":"btcusdt@depth@100ms","data":{"e":"depthUpdate","E":1787650858115,"s":"BTCUSDT","U":99118582272,"u":99118582298,"b":[["79873.29000000","1.71314000"],["79873.28000000","0.01255000"],["79870.63000000","0.05291000"],["79869.91000000","0.00692000"],["79869.61000000","0.00953000"],["79869.25000000","0.04033000"],["79867.59000000","0.00731000"],["79866.46000000","0.00007000"],["79866.45000000","0.36586000"],["79864.02000000","1.87677000"],["79864.01000000","0.00400000"],["71885.97000000","0.00432000"]],"a":[["79873.30000000","1.93912000"],["79929.03000000","0.00007000"],["79936.89000000","0.00007000"],["80041.09000000","0.00151000"],["81071.40000000","0.00092000"]]}}}
{"rx_ns": 13862996072000, "frame": {"stream":"btcusdt@depth@100ms","data":{"e":"depthUpdate","E":1787650858214,"s":"BTCUSDT","U":99118582299,"u":99118582334,"b":[["79873.29000000","1.71321000"],["79873.28000000","0.01262000"],["79870.63000000","0.05291000"],["79869.91000000","0.00706000"],["79869.45000000","0.02310000"],["79867.59000000","0.00724000"],["79866.46000000","0.00000000"],["79866.45000000","0.00000000"],["79864.03000000","0.00000000"],["79864.02000000","0.00000000"],["79858.08000000","0.00000000"],["78675.19000000","0.00030000"],["71885.97000000","0.00448000"],["63898.64000000","0.00000000"]],"a":[["79873.30000000","2.14062000"],["79890.04000000","0.00000000"],["79967.84000000","1.52061000"],["79970.87000000","1.95350000"]]}}}
{"rx_ns": 13863095915700, "frame": {"stream":"btcusdt@depth@100ms","data":{"e":"depthUpdate","E":1787650858314,"s":"BTCUSDT","U":99118582335,"u":99118582350,"b":[["79866.45000000","0.00000000"],["79864.00000000","0.09914000"],["79858.08000000","0.00007000"],["79810.43000000","0.00100000"],["79587.10000000","0.00000000"],["71885.97000000","0.00432000"],["71885.00000000","0.00040000"],["63899.00000000","0.13788000"]],"a":[["79873.78000000","0.00000000"],["79890.04000000","0.00007000"],["80377.13000000","0.00100000"]]}}}
{"rx_ns": 13863198464400, "frame": {"stream":"btcusdt@depth@100ms","data":{"e":"depthUpdate","E":1787650858415,"s":"BTCUSDT","U":99118582351,"u":99118582355,"b":[["71885.97000000","0.00448000"],["71885.95000000","0.00000000"],["63898.63000000","0.00000000"]],"a":[["79873.30000000","2.13913000"]]}}}
{"rx_ns": 13863297940800, "frame": {"stream":"btcusdt@depth@100ms","data":{"e":"depthUpdate","E":1787650858514,"s":"BTCUSDT","U":99118582356,"u":99118582366,"b":[["79864.00000000","0.09914000"],["79861.10000000","0.00007000"],["79840.97000000","0.00000000"],["79805.15000000","0.00000000"],["71885.97000000","0.00432000"],["63898.64000000","0.00031000"],["63898.63000000","0.00000000"]],"a":[["79873.30000000","2.13899000"],["79886.88000000","0.00000000"],["79909.39000000","0.00000000"],["79929.37000000","0.00000000"]]}}}
{"rx_ns": 13863396751600, "frame": {"stream":"btcusdt@depth@100ms","data":{"e":"depthUpdate","E":1787650858614,"s":"BTCUSDT","U":99118582367,"u":99118582373,"b":[["71885.97000000","0.00432000"],["63898.64000000","0.00000000"],["61168.00000000","0.02428000"]],"a":[["79978.19000000","0.00556000"]]}}}
{"rx_ns": 13863596658700, "frame": {"stream":"btcusdt@depth@100ms","data":{"e":"depthUpdate","E":1787650858814,"s":"BTCUSDT","U":99118582374,"u":99118582384,"b":[["79872.63000000","0.02000000"],["79855.92000000","0.02400000"],["79815.96000000","0.02400000"],["79795.14000000","0.02000000"],["71885.97000000","0.00432000"]],"a":[["79883.42000000","0.02000000"],["79903.41000000","0.02000000"],["79923.39000000","0.02000000"]]}}}
{"rx_ns": 13863697546100, "frame": {"stream":"btcusdt@depth@100ms","data":{"e":"depthUpdate","E":1787650858914,"s":"BTCUSDT","U":99118582385,"u":99118582403,"b":[["79873.29000000","1.71321000"],["79873.28000000","0.01269000"],["79872.64000000","0.00007000"],["79872.63000000","0.02014000"],["79872.01000000","0.02559000"],["79871.99000000","0.00028000"],["79869.61000000","0.00939000"],["79866.45000000","0.00007000"],["71885.97000000","0.00432000"]],"a":[["87860.62000000","0.00000000"]]}}}
