{"rx_ns": 14001091495600, "frame": {"stream":"btcusdt@depth@100ms","data":{"e":"depthUpdate","E":1787650996314,"s":"BTCUSDT","U":99118705286,"u":99118705404,"b":[["79818.00000000","2.02853000"],["79817.41000000","0.00007000"],["79817.40000000","0.06084000"],["79817.39000000","0.04957000"],["79816.77000000","0.00007000"],["79816.76000000","0.06091000"],["79816.35000000","0.02494000"],["79816.15000000","0.00007000"],["79816.14000000","0.06077000"],["79816.00000000","0.02435000"],["79815.55000000","0.00007000"],["79815.53000000","0.00960000"],["79815.22000000","0.00007000"],["79815.21000000","0.06077000"],["79815.20000000","0.00407000"],["79815.19000000","1.04873000"],["71836.20000000","0.00440000"],["63854.00000000","0.00015000"]],"a":[["79818.01000000","0.31377000"],["79818.02000000","0.00048000"],["79819.24000000","0.00000000"],["79819.29000000","0.02254000"],["79819.86000000","0.00000000"],["79819.87000000","0.00014000"],["79820.46000000","0.00000000"],["79820.47000000","0.00007000"],["79820.48000000","0.12185000"],["79820.77000000","0.05092000"],["79821.10000000","0.00000000"],["79821.72000000","0.00007000"],["79821.73000000","0.06077000"],["79821.84000000","0.00007000"],["79821.85000000","0.02701000"],["79822.34000000","0.00007000"],["79822.35000000","0.06091000"],["79822.77000000","0.00007000"],["79822.78000000","0.06084000"],["79822.79000000","0.15240000"],["79823.58000000","0.00007000"],["79823.59000000","0.06084000"],["79824.20000000","0.00000000"],["79824.21000000","0.06098000"],["79824.36000000","0.00400000"],["79824.37000000","0.06098000"],["79824.38000000","0.00000000"],["79825.98000000","0.00000000"],["79826.48000000","0.00000000"],["79827.49000000","0.00047000"],["79827.69000000","0.00033000"],["80044.61000000","0.00400000"]]}}}
{"rx_ns": 14001192932000, "frame": {"stream":"btcusdt@depth@100ms","data":{"e":"depthUpdate","E":1787650996414,"s":"BTCUSDT","U":99118705405,"u":99118705443,"b":[["79818.00000000","1.92659000"],["79817.40000000","0.06098000"],["79816.35000000","0.02494000"],["79815.54000000","0.06077000"],["79815.53000000","0.00946000"],["71836.20000000","0.00424000"]],"a":[["79820.77000000","0.05092000"],["79821.73000000","0.06091000"],["79821.85000000","0.02701000"],["79822.35000000","0.06105000"],["79822.78000000","0.06098000"],["79822.79000000","0.15226000"],["79824.21000000","0.06084000"],["79824.37000000","0.06084000"],["79915.43000000","1.95361000"]]}}}
{"rx_ns": 14001291922300, "frame": {"stream":"btcusdt@depth@100ms","data":{"e":"depthUpdate","E":1787650996514,"s":"BTCUSDT","U":99118705444,"u":99118705472,"b":[["79818.00000000","1.92645000"],["79816.14000000","0.06091000"],["79815.55000000","0.00007000"],["79815.22000000","0.00007000"],["79815.20000000","0.00407000"],["79786.33000000","0.03000000"],["71836.20000000","0.00440000"],["63854.40000000","0.00031000"]],"a":[["79818.01000000","0.26369000"],["79820.46000000","0.00007000"],["79820.47000000","0.06084000"],["79820.77000000","0.05099000"],["79821.10000000","0.00007000"],["79821.11000000","0.06077000"],["79821.84000000","0.00007000"],["79822.34000000","0.00007000"],["79822.77000000","0.00000000"],["79822.78000000","0.06091000"],["79823.58000000","0.00000000"]]}}}
{"rx_ns": 14001391404500, "frame": {"stream":"btcusdt@depth@100ms","data":{"e":"depthUpdate","E":1787650996614,"s":"BTCUSDT","U":99118705473,"u":99118705494,"b":[["71836.20000000","0.00424000"],["71836.00000000","0.00000000"],["63854.40000000","0.00000000"]],"a":[["79818.01000000","0.26369000"],["79819.29000000","0.02254000"],["79820.47000000","0.06098000"],["79820.77000000","0.05099000"],["79821.11000000","0.06091000"],["79822.35000000","0.06091000"],["79822.78000000","0.06077000"]]}}}
{"rx_ns": 14001495962600, "frame": {"stream":"btcusdt@depth@100ms","data":{"e":"depthUpdate","E":1787650996714,"s":"BTCUSDT","U":99118705495,"u":99118705574,"b":[["79818.00000000","1.92743000"],["79817.99000000","0.00076000"],["79817.40000000","0.00021000"],["79816.76000000","0.00014000"],["79816.45000000","0.00097000"],["79816.14000000","0.00014000"],["79815.56000000","0.00014000"],["79815.55000000","0.00007000"],["79815.54000000","0.00000000"],["79815.22000000","0.00007000"],["79815.21000000","0.00000000"],["79815.20000000","0.00407000"],["79815.18000000","0.00000000"],["79814.03000000","0.00626000"],["79814.02000000","0.00000000"],["79812.03000000","0.00626000"],["79745.04000000","0.02088000"],["71836.20000000","0.00424000"],["63854.40000000","0.00000000"]],"a":[["79818.01000000","0.80057000"],["79818.02000000","0.00055000"],["79818.63000000","0.06077000"],["79818.75000000","0.00014000"],["79819.15000000","0.37363000"],["79819.16000000","0.33829000"],["79819.22000000","0.00202000"],["79819.86000000","0.00007000"],["79819.87000000","0.06091000"],["79820.48000000","0.00014000"],["79821.10000000","0.00007000"],["79821.72000000","0.00007000"],["79821.74000000","0.08084000"],["79821.84000000","0.00000000"],["79822.34000000","0.00000000"],["79822.79000000","0.00000000"],["79824.38000000","1.87677000"],["79834.66000000","0.12535000"],["79852.96000000","0.00400000"],["80217.72000000","0.00000000"]]}}}
{"rx_ns": 14001591232400, "frame": {"stream":"btcusdt@depth@100ms","data":{"e":"depthUpdate","E":1787650996814,"s":"BTCUSDT","U":99118705575,"u":99118705792,"b":[["79818.00000000","1.79205000"],["79817.99000000","0.00083000"],["79817.41000000","0.00000000"],["79817.40000000","0.00007000"],["79817.39000000","0.01912000"],["79816.77000000","0.00000000"],["79816.76000000","0.00000000"],["79816.45000000","0.00083000"],["79816.35000000","0.02501000"],["79816.30000000","0.00007000"],["79816.25000000","0.00702000"],["79816.15000000","0.00000000"],["79816.14000000","0.00000000"],["79816.00000000","0.02421000"],["79815.56000000","0.00000000"],["79815.55000000","0.00000000"],["79815.53000000","0.00953000"],["79815.22000000","0.00000000"],["79815.20000000","0.00007000"],["79815.19000000","0.44972000"],["79814.91000000","0.00007000"],["79814.90000000","0.04024000"],["79814.03000000","0.00014000"],["79814.00000000","0.02421000"],["79813.68000000","0.00007000"],["79813.61000000","0.03238000"],["79812.50000000","0.00626000"],["79812.49000000","0.00007000"],["79812.25000000","0.01249000"],["79811.92000000","0.00007000"],["79811.32000000","0.00007000"],["79808.25000000","0.00720000"],["79807.96000000","0.00000000"],["79807.74000000","0.00048000"],["79807.24000000","0.00048000"],["79806.98000000","0.00191000"],["79804.25000000","0.00713000"],["79802.81000000","0.00000000"],["79800.31000000","0.00626000"],["79800.25000000","0.00690000"],["79755.34000000","1.24161000"],["79745.04000000","0.00000000"],["71836.20000000","0.00424000"],["63854.40000000","0.00000000"]],"a":[["79818.01000000","0.99341000"],["79818.02000000","0.00069000"],["79818.62000000","0.00007000"],["79818.63000000","0.06098000"],["79818.94000000","0.00007000"],["79819.14000000","0.00007000"],["79819.15000000","0.37377000"],["79819.16000000","0.33843000"],["79819.28000000","0.00000000"],["79819.29000000","0.02261000"],["79819.80000000","0.00007000"],["79819.81000000","0.12853000"],["79819.86000000","0.00000000"],["79819.87000000","0.00021000"],["79820.47000000","0.06091000"],["79820.48000000","0.00000000"],["79820.56000000","0.00014000"],["79821.10000000","0.00007000"],["79821.11000000","0.06077000"],["79821.72000000","0.00007000"],["79821.73000000","0.06077000"],["79821.74000000","0.00000000"],["79821.85000000","0.02687000"],["79822.34000000","0.00007000"],["79822.35000000","0.06084000"],["79824.35000000","0.00011000"],["79824.37000000","1.36665000"],["79824.39000000","0.10459000"],["79825.22000000","0.42750000"],["79827.49000000","0.00000000"],["79827.68000000","0.00626000"],["79827.69000000","0.00000000"],["79827.70000000","0.00000000"],["79831.62000000","0.00000000"],["79834.66000000","0.00000000"],["79839.65000000","0.00000000"],["81015.29000000","0.00030000"]]}}}
{"rx_ns": 14001706460500, "frame": {"stream":"btcusdt@depth@100ms","data":{"e":"depthUpdate","E":1787650996914,"s":"BTCUSDT","U":99118705793,"u":99118705844,"b":[["79818.00000000","1.79062000"],["79817.99000000","0.00083000"],["79816.35000000","0.02494000"],["79816.25000000","0.00014000"],["79816.00000000","0.02428000"],["79815.74000000","0.00694000"],["79814.90000000","0.04017000"],["79814.03000000","0.00000000"],["79790.00000000","0.12051000"],["71836.20000000","0.00400000"],["71836.19000000","0.00008000"]],"a":[["79818.01000000","0.99494000"],["79818.02000000","0.00069000"],["79819.29000000","0.02261000"],["79819.81000000","0.12867000"],["79819.87000000","0.00007000"],["79820.46000000","0.00000000"],["79820.47000000","0.00014000"],["79821.11000000","0.00000000"],["79822.77000000","0.00007000"],["79827.81000000","0.00000000"],["79828.14000000","0.00710000"],["79834.89000000","0.00000000"],["79972.74000000","0.00400000"]]}}}
{"rx_ns": 14001792285300, "frame": {"stream":"btcusdt@depth20","data":{"lastUpdateId":99118705885,"bids":[["79818.00000000","1.79062000"],["79817.99000000","0.00083000"],["79817.98000000","0.00013000"],["79817.40000000","0.00007000"],["79817.39000000","0.01912000"],["79817.29000000","0.00007000"],["79816.90000000","0.00007000"],["79816.66000000","0.00007000"],["79816.45000000","0.00083000"],["79816.36000000","0.00007000"],["79816.35000000","0.02494000"],["79816.31000000","0.00007000"],["79816.30000000","0.00007000"],["79816.01000000","0.00007000"],["79816.00000000","0.02428000"],["79815.98000000","0.00007000"],["79815.74000000","0.00708000"],["79815.66000000","0.00400000"],["79815.53000000","0.00953000"],["79815.48000000","0.00134000"]],"asks":[["79818.01000000","0.99302000"],["79818.02000000","0.00062000"],["79818.03000000","0.00013000"],["79818.54000000","0.00014000"],["79818.62000000","0.00007000"],["79818.63000000","0.06098000"],["79818.75000000","0.00014000"],["79818.94000000","0.00007000"],["79819.14000000","0.00007000"],["79819.15000000","0.37377000"],["79819.16000000","0.33843000"],["79819.22000000","0.00202000"],["79819.29000000","0.02254000"],["79819.74000000","0.00007000"],["79819.80000000","0.00007000"],["79819.81000000","0.12867000"],["79820.56000000","0.00014000"],["79820.57000000","0.02701000"],["79820.76000000","0.00007000"],["79820.77000000","0.05092000"]]}}}
{"rx_ns": 14001792379500, "frame": {"stream":"btcusdt@depth@100ms","data":{"e":"depthUpdate","E":1787650997015,"s":"BTCUSDT","U":99118705845,"u":99118705885,"b":[["79816.35000000","0.02494000"],["79816.25000000","0.00000000"],["79816.00000000","0.02428000"],["79815.74000000","0.00708000"],["79755.35000000","0.41546000"],["79755.01000000","0.00000000"],["71836.20000000","0.00416000"],["63854.40000000","0.00031000"]],"a":[["79818.01000000","0.99302000"],["79818.02000000","0.00062000"],["79819.29000000","0.02254000"],["79819.81000000","0.12867000"],["79819.87000000","0.00000000"],["79820.47000000","0.00000000"],["79820.77000000","0.05092000"],["79821.10000000","0.00000000"],["79821.73000000","0.06091000"],["79823.58000000","0.00007000"],["79827.73000000","0.00189000"],["79834.77000000","0.00000000"],["79835.29000000","0.12535000"]]}}}
{"rx_ns": 14001891876000, "frame": {"stream":"btcusdt@depth@100ms","data":{"e":"depthUpdate","E":1787650997114,"s":"BTCUSDT","U":99118705886,"u":99118705900,"b":[["79818.00000000","1.78956000"],["79809.70000000","0.00000000"],["79745.04000000","0.02088000"],["79594.84000000","0.00400000"],["79593.65000000","0.00000000"],["79589.96000000","0.00771000"],["71836.20000000","0.00416000"]],"a":[["79818.01000000","0.99434000"],["79852.96000000","0.00000000"],["79892.89000000","0.00000000"],["79924.83000000","0.00000000"],["79972.74000000","0.00000000"],["80044.61000000","0.00000000"]]}}}
{"rx_ns": 14001991439200, "frame": {"stream":"btcusdt@depth@100ms","data":{"e":"depthUpdate","E":1787650997214,"s":"BTCUSDT","U":99118705901,"u":99118705911,"b":[["79802.80000000","0.00007000"],["79773.33000000","0.00007000"],["79756.74000000","0.00007000"],["79745.04000000","0.00000000"],["78620.73000000","0.00030000"],["71836.20000000","0.00416000"],["63854.40000000","0.00000000"]],"a":[["79834.74000000","0.00007000"]]}}}
{"rx_ns": 14002092597000, "frame": {"stream":"btcusdt@depth@100ms","data":{"e":"depthUpdate","E":1787650997314,"s":"BTCUSDT","U":99118705912,"u":99118706070,"b":[["79818.00000000","1.87352000"],["79817.99000000","0.00027000"],["79817.41000000","0.00000000"],["79817.40000000","0.00007000"],["79817.39000000","0.00014000"],["79816.77000000","0.00000000"],["79816.76000000","0.00000000"],["79816.36000000","0.03303000"],["79816.35000000","0.02501000"],["79816.15000000","0.00007000"],["79816.14000000","0.06077000"],["79815.74000000","0.00715000"],["79815.55000000","0.00007000"],["79815.54000000","0.06077000"],["79815.53000000","0.00960000"],["79815.21000000","0.00007000"],["79815.20000000","0.06084000"],["79815.19000000","0.44979000"],["79814.92000000","0.00000000"],["79814.91000000","0.00007000"],["79814.90000000","0.04017000"],["79814.28000000","0.00000000"],["79814.02000000","0.00626000"],["79814.00000000","0.02421000"],["79813.68000000","0.00007000"],["79812.49000000","0.00000000"],["79812.25000000","0.01242000"],["79812.03000000","0.00000000"],["79811.92000000","0.00000000"],["79811.32000000","0.00000000"],["71836.20000000","0.00416000"],["63854.00000000","0.00015000"]],"a":[["79818.01000000","0.47955000"],["79818.02000000","0.00048000"],["79818.62000000","0.00000000"],["79818.63000000","0.00021000"],["79819.15000000","0.14032000"],["79819.80000000","0.00000000"],["79819.81000000","0.00014000"],["79820.56000000","0.00021000"],["79821.72000000","0.00000000"],["79821.73000000","0.06091000"],["79821.84000000","0.00007000"],["79821.85000000","0.02694000"],["79822.34000000","0.00007000"],["79822.35000000","0.06084000"],["79822.77000000","0.00000000"],["79822.78000000","0.00000000"],["79822.96000000","0.00007000"],["79822.97000000","0.06077000"],["79823.58000000","0.00007000"],["79823.59000000","0.06084000"],["79824.19000000","0.00007000"],["79824.20000000","0.06084000"],["79824.21000000","0.00007000"],["79824.35000000","0.06077000"],["79824.36000000","0.00400000"],["79824.37000000","0.74516000"],["79824.38000000","0.00000000"],["79824.39000000","0.10459000"],["79825.18000000","0.00000000"],["79825.21000000","0.00000000"],["79826.48000000","0.00009000"],["79827.11000000","0.00017000"],["79827.68000000","0.00000000"],["79829.63000000","0.00000000"],["79831.41000000","0.00626000"],["79835.29000000","0.00000000"],["79881.24000000","0.00000000"],["79960.99000000","0.00000000"],["80040.48000000","0.00400000"]]}}}
{"rx_ns": 14002191291700, "frame": {"stream":"btcusdt@depth@100ms","data":{"e":"depthUpdate","E":1787650997414,"s":"BTCUSDT","U":99118706071,"u":99118706140,"b":[["79818.00000000","1.87355000"],["79817.40000000","0.00000000"],["79817.39000000","0.00000000"],["79816.37000000","0.00007000"],["79816.36000000","0.03317000"],["79816.35000000","0.02501000"],["79816.14000000","0.06091000"],["79815.74000000","0.00715000"],["79815.54000000","0.06091000"],["79815.53000000","0.00960000"],["79815.20000000","0.06084000"],["79815.19000000","0.44958000"],["79814.91000000","0.00007000"],["79814.90000000","0.04010000"],["79814.00000000","0.02407000"],["79813.68000000","0.00007000"],["79810.65000000","0.03142000"],["71836.20000000","0.00432000"]],"a":[["79818.01000000","0.47969000"],["79818.63000000","0.00007000"],["79819.15000000","0.19501000"],["79819.29000000","0.02247000"],["79819.81000000","0.00000000"],["79821.72000000","0.00007000"],["79821.84000000","0.00000000"],["79821.85000000","0.02708000"],["79822.35000000","0.06098000"]]}}}
{"rx_ns": 14002291482600, "frame": {"stream":"btcusdt@depth@100ms","data":{"e":"depthUpdate","E":1787650997514,"s":"BTCUSDT","U":99118706141,"u":99118706153,"b":[["79818.00000000","1.87403000"],["79816.36000000","0.01419000"],["79816.15000000","0.00000000"],["79816.14000000","0.00014000"],["79812.49000000","0.00007000"],["71836.20000000","0.00416000"],["63854.40000000","0.00031000"]],"a":[["79818.01000000","0.68219000"],["79968.62000000","0.00400000"]]}}}
{"rx_ns": 14002395349800, "frame": {"stream":"btcusdt@depth@100ms","data":{"e":"depthUpdate","E":1787650997616,"s":"BTCUSDT","U":99118706154,"u":99118706179,"b":[["79816.76000000","0.06077000"],["79816.35000000","0.02494000"],["79816.14000000","0.06077000"],["79815.20000000","0.06098000"],["79813.68000000","0.06084000"],["79812.49000000","0.00000000"],["79806.84000000","0.00400000"],["79782.36000000","0.00000000"],["71836.20000000","0.00432000"],["63854.40000000","0.00000000"],["63854.00000000","0.00015000"]],"a":[["79818.01000000","0.47969000"],["79821.73000000","0.00014000"],["79825.17000000","0.20089000"],["79842.30000000","0.04633000"],["79857.95000000","0.00000000"],["79862.22000000","0.00400000"],["79862.28000000","0.00000000"]]}}}
{"rx_ns": 14002497574500, "frame": {"stream":"btcusdt@depth@100ms","data":{"e":"depthUpdate","E":1787650997714,"s":"BTCUSDT","U":99118706180,"u":99118706253,"b":[["79818.00000000","1.87417000"],["79816.78000000","0.00007000"],["79816.77000000","0.05148000"],["79816.76000000","0.06091000"],["79816.37000000","0.00000000"],["79816.36000000","0.00021000"],["79816.35000000","0.02501000"],["79816.15000000","0.00007000"],["79815.21000000","0.00007000"],["79815.20000000","0.06084000"],["79814.91000000","0.00007000"],["79814.00000000","0.02414000"],["79813.68000000","0.06077000"],["71836.20000000","0.00416000"],["71836.00000000","0.00000000"],["63854.40000000","0.00000000"]],"a":[["79820.77000000","0.05085000"],["79821.72000000","0.00000000"],["79821.73000000","0.00000000"],["79822.97000000","0.06091000"],["79823.58000000","0.00007000"],["79824.19000000","0.00007000"],["79824.34000000","0.00007000"],["79824.40000000","0.19045000"],["79920.71000000","0.00400000"]]}}}
{"rx_ns": 14002598740100, "frame": {"stream":"btcusdt@depth@100ms","data":{"e":"depthUpdate","E":1787650997814,"s":"BTCUSDT","U":99118706254,"u":99118706294,"b":[["79818.00000000","1.79262000"],["79816.77000000","0.04749000"],["79816.76000000","0.06091000"],["79816.36000000","0.00007000"],["79816.14000000","0.06091000"],["79745.04000000","0.02088000"],["79684.56000000","0.00007000"],["79682.90000000","0.04936000"],["71836.20000000","0.00459000"],["63854.40000000","0.00000000"],["63854.00000000","0.00015000"]],"a":[["79818.01000000","0.68192000"],["79824.12000000","0.03368000"],["79825.17000000","0.00000000"],["79922.32000000","0.02804000"],["79923.98000000","0.00000000"]]}}}
{"rx_ns": 14002695567200, "frame": {"stream":"btcusdt@depth@100ms","data":{"e":"depthUpdate","E":1787650997914,"s":"BTCUSDT","U":99118706295,"u":99118706312,"b":[["79814.00000000","0.02407000"],["79813.68000000","0.00000000"],["71836.20000000","0.00443000"]],"a":[["79818.01000000","0.68199000"],["79822.97000000","0.06098000"],["79822.98000000","0.00007000"],["79822.99000000","0.20016000"],["79823.59000000","0.06084000"],["79824.12000000","0.00000000"],["79824.40000000","0.19038000"],["79848.84000000","0.00400000"],["79910.15000000","1.95361000"],["79915.43000000","0.00000000"],["81015.29000000","0.00030000"]]}}}
{"rx_ns": 14002794807400, "frame": {"stream":"btcusdt@depth20","data":{"lastUpdateId":99118706323,"bids":[["79818.00000000","1.77581000"],["79817.99000000","0.00027000"],["79817.98000000","0.00013000"],["79817.29000000","0.00007000"],["79816.90000000","0.00007000"],["79816.78000000","0.00007000"],["79816.77000000","0.04749000"],["79816.76000000","0.06091000"],["79816.66000000","0.00007000"],["79816.45000000","0.00083000"],["79816.36000000","0.00007000"],["79816.35000000","0.02501000"],["79816.31000000","0.00007000"],["79816.30000000","0.00007000"],["79816.15000000","0.00007000"],["79816.14000000","0.06091000"],["79816.01000000","0.00007000"],["79816.00000000","0.02428000"],["79815.98000000","0.00007000"],["79815.74000000","0.00715000"]],"asks":[["79818.01000000","0.68199000"],["79818.02000000","0.00048000"],["79818.03000000","0.00013000"],["79818.54000000","0.00014000"],["79818.63000000","0.00007000"],["79818.75000000","0.00014000"],["79818.94000000","0.00007000"],["79819.14000000","0.00007000"],["79819.15000000","0.19501000"],["79819.16000000","0.33843000"],["79819.22000000","0.00202000"],["79819.29000000","0.02247000"],["79819.74000000","0.00007000"],["79820.56000000","0.00021000"],["79820.57000000","0.02701000"],["79820.76000000","0.00007000"],["79820.77000000","0.05085000"],["79821.85000000","0.02708000"],["79822.34000000","0.00007000"],["79822.35000000","0.06098000"]]}}}
{"rx_ns": 14002795078500, "frame": {"stream":"btcusdt@depth@100ms","data":{"e":"depthUpdate","E":1787650998014,"s":"BTCUSDT","U":99118706313,"u":99118706323,"b":[["79818.00000000","1.77581000"],["79745.04000000","0.00000000"],["71836.20000000","0.00459000"],["71836.19000000","0.00000000"],["63854.40000000","0.00031000"]],"a":[["79822.97000000","0.06098000"]]}}}
{"rx_ns": 14002890989900, "frame": {"stream":"btcusdt@depth@100ms","data":{"e":"depthUpdate","E":1787650998114,"s":"BTCUSDT","U":99118706324,"u":99118706327,"b":[["71836.20000000","0.00443000"]],"a":[["79888.77000000","0.00400000"]]}}}
{"rx_ns": 14003001453600, "frame": {"stream":"btcusdt@depth@100ms","data":{"e":"depthUpdate","E":1787650998214,"s":"BTCUSDT","U":99118706328,"u":99118706341,"b":[["79818.00000000","1.77556000"],["79816.76000000","0.00014000"],["79802.80000000","0.00000000"],["79593.65000000","0.00771000"],["79589.96000000","0.00000000"],["79580.46000000","0.00015000"],["79568.48000000","0.00000000"],["79490.54000000","0.10000000"],["79478.57000000","0.10000000"],["78620.73000000","0.00030000"],["71836.20000000","0.00443000"],["63854.40000000","0.00000000"]],"a":[["79834.74000000","0.00000000"],["79888.77000000","0.00000000"]]}}}
{"rx_ns": 14003091795600, "frame": {"stream":"btcusdt@depth@100ms","data":{"e":"depthUpdate","E":1787650998314,"s":"BTCUSDT","U":99118706342,"u":99118706377,"b":[["79818.00000000","1.77549000"],["79816.77000000","0.03031000"],["79816.76000000","0.00000000"],["79815.20000000","0.06098000"],["79814.91000000","0.00007000"],["79813.68000000","0.00007000"],["79802.80000000","0.00007000"],["79779.55000000","0.00007000"],["79620.99000000","0.00007000"],["71836.20000000","0.00443000"],["63854.00000000","0.00015000"]],"a":[["79822.98000000","0.00007000"],["79823.58000000","0.00007000"],["79824.19000000","0.00007000"],["79824.34000000","0.00000000"],["79834.74000000","0.00007000"],["79888.86000000","0.00400000"]]}}}
{"rx_ns": 14003192460500, "frame": {"stream":"btcusdt@depth@100ms","data":{"e":"depthUpdate","E":1787650998414,"s":"BTCUSDT","U":99118706378,"u":99118706396,"b":[["79818.00000000","1.85054000"],["79816.14000000","0.00014000"],["79815.54000000","0.00014000"],["79815.20000000","0.00021000"],["79814.90000000","0.04003000"],["79814.02000000","0.00000000"],["79813.61000000","0.03245000"],["79812.99000000","0.00626000"],["79761.89000000","0.00000000"],["71836.20000000","0.00443000"]],"a":[["79818.01000000","0.70550000"],["79821.73000000","0.06077000"]]}}}
{"rx_ns": 14003295223900, "frame": {"stream":"btcusdt@depth@100ms","data":{"e":"depthUpdate","E":1787650998515,"s":"BTCUSDT","U":99118706397,"u":99118706491,"b":[["79818.00000000","1.84997000"],["79816.77000000","0.01529000"],["79816.35000000","0.02494000"],["79816.15000000","0.00000000"],["79816.14000000","0.00000000"],["79815.74000000","0.00708000"],["79815.55000000","0.00000000"],["79815.54000000","0.00000000"],["79815.53000000","0.00960000"],["79815.21000000","0.00000000"],["79815.20000000","0.00007000"],["79815.19000000","0.44972000"],["79814.90000000","0.04017000"],["79814.00000000","0.02421000"],["79812.49000000","0.00007000"],["79811.92000000","0.00007000"],["79811.32000000","0.00007000"],["71836.20000000","0.00451000"],["63854.40000000","0.00031000"]],"a":[["79818.01000000","0.70557000"],["79818.02000000","0.00055000"],["79818.62000000","0.00007000"],["79818.63000000","0.06084000"],["79819.13000000","0.00007000"],["79819.14000000","0.06084000"],["79820.56000000","0.00014000"],["79820.77000000","0.05099000"],["79821.11000000","0.06077000"],["79821.55000000","0.00007000"],["79821.56000000","0.04312000"],["79821.72000000","0.00007000"],["79821.73000000","0.06091000"],["79822.34000000","0.00007000"],["79822.96000000","0.00007000"],["79822.97000000","0.06077000"],["79822.98000000","0.00000000"],["79822.99000000","0.00000000"],["79823.58000000","0.00000000"],["79824.19000000","0.00000000"],["79824.32000000","0.06077000"],["79824.33000000","1.32877000"],["79824.34000000","1.87677000"],["79824.35000000","0.00000000"],["79824.37000000","0.00007000"],["79825.18000000","0.00018000"],["79827.11000000","0.00000000"],["79860.09000000","0.00400000"],["79862.22000000","0.00000000"]]}}}
{"rx_ns": 14003391520600, "frame": {"stream":"btcusdt@depth@100ms","data":{"e":"depthUpdate","E":1787650998614,"s":"BTCUSDT","U":99118706492,"u":99118706825,"b":[["79818.00000000","0.94922000"],["79817.99000000","0.00083000"],["79816.78000000","0.00000000"],["79816.77000000","0.00014000"],["79816.36000000","0.00000000"],["79816.35000000","0.00014000"],["79815.74000000","0.00014000"],["79815.66000000","0.00000000"],["79815.53000000","0.00953000"],["79815.20000000","0.00000000"],["79815.19000000","0.00014000"],["79814.90000000","0.04024000"],["79814.88000000","0.00007000"],["79814.62000000","0.00202000"],["79814.52000000","0.00701000"],["79814.01000000","0.00014000"],["79813.68000000","0.00000000"],["79813.67000000","0.00000000"],["79813.61000000","0.00007000"],["79813.51000000","0.00000000"],["79812.99000000","0.00000000"],["79812.50000000","0.00000000"],["79812.49000000","0.00007000"],["79812.01000000","0.00007000"],["79811.92000000","0.00007000"],["79811.32000000","0.00000000"],["79811.31000000","0.00000000"],["79811.28000000","0.00007000"],["79810.65000000","0.00000000"],["79809.56000000","0.00000000"],["79809.55000000","0.00250000"],["79808.74000000","0.06077000"],["79808.09000000","0.00626000"],["79808.08000000","0.06077000"],["79807.87000000","0.00626000"],["79807.46000000","0.06077000"],["79806.85000000","0.06077000"],["79806.69000000","0.06077000"],["79806.68000000","0.17037000"],["79806.67000000","0.00000000"],["79805.66000000","0.00000000"],["79804.68000000","0.00000000"],["79804.36000000","0.06077000"],["79804.24000000","0.00000000"],["79803.93000000","0.06077000"],["79801.79000000","0.00000000"],["79800.31000000","0.00000000"],["79800.11000000","0.00000000"],["79800.01000000","0.00000000"],["79800.00000000","0.82877000"],["79798.18000000","0.00000000"],["79798.17000000","0.00000000"],["79797.63000000","0.00626000"],["79797.04000000","0.28757000"],["79796.55000000","0.00156000"],["79795.13000000","0.62657000"],["79790.00000000","0.11800000"],["79788.01000000","0.14727000"],["79786.90000000","0.33848000"],["79784.75000000","0.00000000"],["79780.88000000","0.33851000"],["79780.00000000","0.12052000"],["79779.45000000","0.00000000"],["79779.38000000","0.62688000"],["79779.15000000","0.51413000"],["79776.18000000","0.00007000"],["79775.71000000","0.00400000"],["79774.89000000","0.00000000"],["79747.47000000","1.24173000"],["79743.95000000","0.00000000"],["79743.40000000","0.00000000"],["79743.29000000","0.80816000"],["79735.93000000","0.00000000"],["79726.72000000","1.07299000"],["79673.90000000","0.00000000"],["79670.90000000","0.00654000"],["71836.20000000","0.00451000"],["63854.40000000","0.00000000"]],"a":[["79818.01000000","1.44722000"],["79818.02000000","0.00062000"],["79818.63000000","0.06105000"],["79819.11000000","0.00007000"],["79819.12000000","0.82442000"],["79819.13000000","1.87677000"],["79819.14000000","0.00014000"],["79819.15000000","0.00021000"],["79819.29000000","0.02254000"],["79819.87000000","0.00007000"],["79820.20000000","0.00007000"],["79820.21000000","0.00000000"],["79820.49000000","0.00000000"],["79820.57000000","0.02694000"],["79820.76000000","0.00000000"],["79820.77000000","0.05092000"],["79821.10000000","0.00000000"],["79821.11000000","0.00014000"],["79821.55000000","0.00000000"],["79821.56000000","0.00000000"],["79821.71000000","0.00000000"],["79821.72000000","0.00000000"],["79821.73000000","0.00000000"],["79821.75000000","0.00400000"],["79821.85000000","0.02687000"],["79822.34000000","0.00000000"],["79822.35000000","0.00000000"],["79822.95000000","0.00633000"],["79822.96000000","0.00000000"],["79822.97000000","0.00000000"],["79823.59000000","0.00007000"],["79823.88000000","0.00400000"],["79824.20000000","0.00000000"],["79824.31000000","0.19019000"],["79824.32000000","0.00000000"],["79824.40000000","0.19024000"],["79824.46000000","0.00000000"],["79826.01000000","0.00400000"],["79826.48000000","0.00000000"],["79827.73000000","0.00000000"],["79831.41000000","0.00000000"],["79838.86000000","0.33826000"],["79839.84000000","0.00000000"],["79846.75000000","0.62635000"],["79853.70000000","0.00400000"],["79854.11000000","0.00000000"],["79856.14000000","0.00000000"],["79858.17000000","0.00000000"],["79860.09000000","0.00000000"],["79861.87000000","0.00000000"],["79893.94000000","0.00000000"],["79939.78000000","0.08496000"],["79939.79000000","0.00000000"]]}}}
{"rx_ns": 14003494507700, "frame": {"stream":"btcusdt@depth@100ms","data":{"e":"depthUpdate","E":1787650998714,"s":"BTCUSDT","U":99118706826,"u":99118706941,"b":[["79818.00000000","1.13200000"],["79817.99000000","0.00083000"],["79816.77000000","0.00000000"],["79816.45000000","0.00076000"],["79816.35000000","0.00000000"],["79816.00000000","0.02421000"],["79815.74000000","0.00000000"],["79815.53000000","0.00953000"],["79815.19000000","0.00000000"],["79815.09000000","0.00007000"],["79815.08000000","0.02480000"],["79814.90000000","0.04024000"],["79814.52000000","0.00715000"],["79814.00000000","0.02428000"],["79812.50000000","0.00007000"],["79812.49000000","0.10472000"],["79812.48000000","0.31352000"],["79812.25000000","0.01256000"],["79812.01000000","0.00000000"],["79812.00000000","0.02421000"],["79811.91000000","0.12543000"],["79811.39000000","0.00007000"],["79811.38000000","0.15827000"],["79811.37000000","0.01007000"],["79811.27000000","0.14007000"],["79809.32000000","0.06077000"],["79808.81000000","0.00070000"],["79806.73000000","0.00156000"],["79802.77000000","1.20277000"],["79796.55000000","0.00000000"],["79793.00000000","0.00000000"],["79788.01000000","0.13016000"],["79782.22000000","0.00400000"],["79775.71000000","0.00000000"],["71836.20000000","0.00467000"],["63854.40000000","0.00000000"]],"a":[["79818.01000000","1.44879000"],["79818.02000000","0.00055000"],["79818.63000000","0.06105000"],["79819.12000000","0.82456000"],["79819.13000000","1.87691000"],["79819.14000000","0.00000000"],["79819.15000000","0.00007000"],["79819.29000000","0.02247000"],["79819.87000000","0.00000000"],["79820.20000000","0.00000000"],["79820.77000000","0.05085000"],["79821.11000000","0.00000000"],["79821.85000000","0.02701000"],["79822.95000000","0.00626000"],["79824.31000000","0.00000000"],["79824.40000000","0.19031000"],["79833.98000000","0.19419000"]]}}}
{"rx_ns": 14003591773200, "frame": {"stream":"btcusdt@depth@100ms","data":{"e":"depthUpdate","E":1787650998814,"s":"BTCUSDT","U":99118706942,"u":99118706976,"b":[["79818.00000000","1.45901000"],["79815.53000000","0.00953000"],["79815.08000000","0.02494000"],["79814.00000000","0.02428000"],["79812.49000000","0.10486000"],["79812.25000000","0.01242000"],["79812.00000000","0.02407000"],["79682.90000000","0.00000000"],["79632.50000000","0.01303000"],["71836.20000000","0.00435000"],["63854.40000000","0.00000000"]],"a":[["79818.01000000","1.40951000"],["79821.85000000","0.02694000"],["79822.81000000","0.00007000"],["79822.95000000","0.00000000"],["79824.40000000","0.19038000"],["79825.17000000","0.00626000"],["79889.91000000","0.00535000"],["79903.91000000","0.00000000"],["79922.32000000","0.00000000"],["79994.45000000","0.00000000"],["80130.27000000","0.00304000"]]}}}
{"rx_ns": 14003691136700, "frame": {"stream":"btcusdt@depth@100ms","data":{"e":"depthUpdate","E":1787650998914,"s":"BTCUSDT","U":99118706977,"u":99118707005,"b":[["79818.00000000","1.45880000"],["79800.62000000","0.37603000"],["79796.27000000","0.51606000"],["79786.33000000","0.02600000"],["79747.47000000","0.00000000"],["79746.40000000","0.00000000"],["79738.84000000","0.02088000"],["79714.49000000","0.00000000"],["79710.45000000","0.00400000"],["79681.21000000","0.04936000"],["79666.62000000","0.00000000"],["79662.58000000","0.00400000"],["79594.84000000","0.00000000"],["79590.78000000","0.00400000"],["71836.20000000","0.00440000"],["71836.00000000","0.00000000"]],"a":[["79818.01000000","1.40958000"],["79821.85000000","0.02694000"],["79920.62000000","0.02804000"],["81015.29000000","0.00030000"]]}}}
{"rx_ns": 14003795616000, "frame": {"stream":"btcusdt@depth20","data":{"lastUpdateId":99118707204,"bids":[["79818.00000000","1.56796000"],["79817.99000000","0.00083000"],["79817.98000000","0.00013000"],["79817.29000000","0.00007000"],["79816.90000000","0.00007000"],["79816.66000000","0.00007000"],["79816.45000000","0.00076000"],["79816.41000000","0.12654000"],["79816.40000000","0.33836000"],["79816.31000000","0.00007000"],["79816.30000000","0.00007000"],["79816.15000000","0.00007000"],["79816.01000000","0.00007000"],["79816.00000000","0.02428000"],["79815.98000000","0.00007000"],["79815.55000000","0.00007000"],["79815.54000000","0.06077000"],["79815.53000000","0.00953000"],["79815.48000000","0.00134000"],["79815.09000000","0.00007000"]],"asks":[["79818.01000000","0.88553000"],["79818.02000000","0.00055000"],["79818.03000000","0.00013000"],["79818.54000000","0.00014000"],["79818.63000000","0.00028000"],["79818.75000000","0.00014000"],["79818.94000000","0.00007000"],["79819.11000000","0.00007000"],["79819.12000000","0.14247000"],["79819.13000000","0.00014000"],["79819.15000000","0.00007000"],["79819.16000000","0.33843000"],["79819.22000000","0.00202000"],["79819.29000000","0.02247000"],["79819.74000000","0.00007000"],["79820.56000000","0.00021000"],["79820.57000000","0.02694000"],["79820.76000000","0.00007000"],["79820.77000000","0.05085000"],["79821.75000000","0.00400000"]]}}}
{"rx_ns": 14003795825400, "frame": {"stream":"btcusdt@depth@100ms","data":{"e":"depthUpdate","E":1787650999014,"s":"BTCUSDT","U":99118707006,"u":99118707204,"b":[["79818.00000000","1.56796000"],["79817.99000000","0.00083000"],["79816.41000000","0.12654000"],["79816.40000000","0.33836000"],["79816.15000000","0.00007000"],["79816.14000000","0.00000000"],["79816.00000000","0.02428000"],["79815.55000000","0.00007000"],["79815.54000000","0.06077000"],["79814.91000000","0.00007000"],["79814.90000000","0.06098000"],["79814.88000000","0.00014000"],["79814.62000000","0.00000000"],["79814.52000000","0.00722000"],["79814.29000000","0.00007000"],["79814.28000000","0.06077000"],["79814.01000000","0.00007000"],["79814.00000000","0.02442000"],["79813.77000000","0.00007000"],["79813.76000000","0.03231000"],["79813.68000000","0.00007000"],["79813.67000000","0.14205000"],["79813.66000000","0.00014000"],["79813.05000000","0.00000000"],["79813.04000000","0.06077000"],["79812.76000000","0.00626000"],["79812.51000000","0.00000000"],["79812.50000000","0.06077000"],["79812.49000000","0.00014000"],["79811.92000000","0.00000000"],["79811.39000000","0.00000000"],["79811.38000000","0.70478000"],["79811.37000000","0.01000000"],["79811.28000000","0.00000000"],["79811.27000000","0.14000000"],["79809.32000000","0.00000000"],["79808.89000000","0.02118000"],["79808.81000000","0.00000000"],["79808.74000000","0.00000000"],["79808.32000000","0.00000000"],["79808.31000000","1.87677000"],["79808.09000000","0.00000000"],["79808.08000000","0.00000000"],["79807.46000000","0.00000000"],["79806.85000000","0.00000000"],["79806.70000000","0.36586000"],["79806.69000000","0.00000000"],["79804.36000000","0.00000000"],["79803.93000000","0.00000000"],["79800.00000000","0.92276000"],["79790.00000000","0.12051000"],["79780.05000000","0.00414000"],["79779.15000000","0.51013000"],["79738.84000000","0.00000000"],["71836.20000000","0.00424000"],["63854.40000000","0.00031000"]],"a":[["79818.01000000","0.88553000"],["79818.02000000","0.00055000"],["79818.62000000","0.00000000"],["79818.63000000","0.00028000"],["79819.12000000","0.14247000"],["79819.13000000","0.00014000"],["79820.56000000","0.00021000"],["79820.76000000","0.00007000"],["79821.84000000","0.00007000"],["79821.85000000","0.02708000"],["79822.81000000","0.00000000"],["79822.96000000","0.00007000"],["79822.97000000","0.06077000"],["79823.58000000","0.00007000"],["79823.59000000","0.06084000"],["79823.93000000","0.00007000"],["79823.94000000","0.04000000"],["79824.20000000","0.00007000"],["79824.21000000","0.06091000"],["79824.32000000","0.06084000"],["79824.33000000","0.75597000"],["79824.34000000","0.00000000"],["79824.40000000","0.19031000"],["79824.77000000","0.00716000"],["79825.16000000","0.00008000"],["79825.17000000","0.00000000"],["79825.21000000","0.00000000"],["79825.88000000","0.00937000"],["79828.13000000","0.00626000"]]}}}
{"rx_ns": 14003901245000, "frame": {"stream":"btcusdt@depth@100ms","data":{"e":"depthUpdate","E":1787650999114,"s":"BTCUSDT","U":99118707205,"u":99118707312,"b":[["79818.00000000","1.56626000"],["79817.99000000","0.00027000"],["79816.42000000","0.00007000"],["79816.41000000","0.12668000"],["79816.40000000","0.00014000"],["79816.15000000","0.00000000"],["79816.00000000","0.02421000"],["79815.55000000","0.00000000"],["79815.54000000","0.00014000"],["79815.09000000","0.00007000"],["79814.90000000","0.00021000"],["79814.77000000","0.00400000"],["79814.52000000","0.00708000"],["79814.28000000","0.00000000"],["79814.00000000","0.02421000"],["79813.05000000","0.00007000"],["79813.04000000","0.06084000"],["79812.49000000","0.00000000"],["79812.48000000","0.31338000"],["79808.32000000","1.04939000"],["79782.26000000","0.00400000"],["79780.05000000","0.00014000"],["79776.18000000","0.00000000"],["71836.20000000","0.00440000"]],"a":[["79818.01000000","0.83860000"],["79818.02000000","0.00048000"],["79818.63000000","0.00014000"],["79819.12000000","0.14247000"],["79819.13000000","0.00000000"],["79821.73000000","0.05861000"],["79821.75000000","0.00000000"],["79821.85000000","0.02715000"],["79822.34000000","0.00007000"],["79822.35000000","0.06077000"],["79822.97000000","0.06091000"],["79823.59000000","0.06098000"],["79862.51000000","0.00400000"]]}}}
{"rx_ns": 14003993251900, "frame": {"stream":"btcusdt@depth@100ms","data":{"e":"depthUpdate","E":1787650999215,"s":"BTCUSDT","U":99118707313,"u":99118707527,"b":[["79818.00000000","1.56710000"],["79817.99000000","0.00076000"],["79816.42000000","0.00000000"],["79816.41000000","0.00014000"],["79816.40000000","0.00000000"],["79816.00000000","0.02421000"],["79815.54000000","0.00000000"],["79815.08000000","0.02494000"],["79814.91000000","0.00000000"],["79814.90000000","0.00007000"],["79814.52000000","0.00715000"],["79814.29000000","0.00000000"],["79814.01000000","0.00014000"],["79814.00000000","0.02435000"],["79813.76000000","0.03245000"],["79813.05000000","0.00007000"],["79813.04000000","0.06077000"],["79812.76000000","0.00000000"],["79812.51000000","0.00007000"],["79812.49000000","0.00007000"],["79811.92000000","0.00007000"],["79811.61000000","0.00626000"],["79776.18000000","0.00007000"],["78620.73000000","0.00030000"],["71836.20000000","0.00424000"],["63854.40000000","0.00000000"]],"a":[["79818.01000000","1.13597000"],["79818.62000000","0.00007000"],["79818.63000000","0.06091000"],["79819.10000000","0.00007000"],["79819.11000000","0.06084000"],["79819.12000000","0.20716000"],["79820.56000000","0.00014000"],["79820.77000000","0.05099000"],["79821.10000000","0.00007000"],["79821.11000000","0.05458000"],["79821.72000000","0.00007000"],["79821.73000000","0.05875000"],["79821.84000000","0.00000000"],["79821.85000000","0.02715000"],["79822.34000000","0.00007000"],["79822.35000000","0.06091000"],["79822.96000000","0.00007000"],["79822.97000000","0.06077000"],["79823.58000000","0.00007000"],["79823.59000000","0.06084000"],["79823.93000000","0.00000000"],["79824.20000000","0.00000000"],["79824.30000000","1.39098000"],["79824.31000000","1.87677000"],["79824.32000000","0.00007000"],["79824.33000000","0.00410000"],["79824.40000000","0.19024000"]]}}}
{"rx_ns": 14004091199000, "frame": {"stream":"btcusdt@depth@100ms","data":{"e":"depthUpdate","E":1787650999314,"s":"BTCUSDT","U":99118707528,"u":99118707592,"b":[["79818.00000000","1.56696000"],["79817.99000000","0.00076000"],["79816.41000000","0.00000000"],["79813.67000000","0.14219000"],["79802.80000000","0.00007000"],["79782.26000000","0.00000000"],["79781.63000000","0.00007000"],["79742.36000000","0.00000000"],["79710.45000000","0.00000000"],["79662.58000000","0.00000000"],["79615.73000000","0.00290000"],["79590.78000000","0.00000000"],["71836.20000000","0.00440000"],["63854.00000000","0.00015000"]],"a":[["79818.01000000","1.32653000"],["79818.02000000","0.00055000"],["79818.63000000","0.06105000"],["79819.11000000","0.06098000"],["79820.77000000","0.05099000"],["79821.11000000","0.05472000"],["79821.73000000","0.05861000"],["79821.85000000","0.02701000"],["79822.35000000","0.06077000"],["79824.29000000","0.19019000"],["79833.98000000","0.00400000"],["79834.74000000","0.00007000"],["79860.34000000","0.00400000"],["79862.51000000","0.00000000"]]}}}
{"rx_ns": 14004192068200, "frame": {"stream":"btcusdt@depth@100ms","data":{"e":"depthUpdate","E":1787650999414,"s":"BTCUSDT","U":99118707593,"u":99118707610,"b":[["79818.00000000","1.56703000"],["79812.48000000","0.31345000"],["79812.44000000","0.00007000"],["79812.43000000","0.04003000"],["79593.65000000","0.00000000"],["79589.96000000","0.00771000"],["71836.20000000","0.00424000"]],"a":[["79818.01000000","1.14168000"],["79821.11000000","0.05479000"],["79821.12000000","0.00007000"],["79821.13000000","0.18135000"],["79822.96000000","0.00000000"],["79823.58000000","0.00000000"],["79824.29000000","0.00000000"],["79833.98000000","0.19419000"],["80026.29000000","0.00041000"]]}}}
{"rx_ns": 14004291732700, "frame": {"stream":"btcusdt@depth@100ms","data":{"e":"depthUpdate","E":1787650999515,"s":"BTCUSDT","U":99118707611,"u":99118707661,"b":[["79818.00000000","1.56710000"],["79817.99000000","0.00090000"],["79816.46000000","0.00007000"],["79816.45000000","0.10912000"],["79816.44000000","0.33829000"],["79814.88000000","0.00007000"],["79814.00000000","0.02428000"],["79813.66000000","0.00007000"],["79813.05000000","0.00000000"],["79813.04000000","0.00000000"],["79812.51000000","0.00000000"],["79812.50000000","0.00000000"],["79812.49000000","0.00007000"],["79812.44000000","0.00000000"],["79811.92000000","0.00007000"],["79748.71000000","0.82234000"],["79594.81000000","0.00400000"],["71836.20000000","0.00440000"],["63854.40000000","0.00031000"]],"a":[["79818.01000000","1.32598000"],["79821.11000000","0.05479000"],["79821.12000000","0.00007000"],["79821.72000000","0.00007000"],["79822.34000000","0.00007000"],["79946.30000000","0.01962000"]]}}}
{"rx_ns": 14004392201300, "frame": {"stream":"btcusdt@depth@100ms","data":{"e":"depthUpdate","E":1787650999614,"s":"BTCUSDT","U":99118707662,"u":99118707689,"b":[["79818.00000000","1.56710000"],["79817.08000000","0.00711000"],["79816.45000000","0.10926000"],["79813.67000000","0.14205000"],["71836.20000000","0.00440000"],["63854.40000000","0.00000000"]],"a":[["79818.01000000","1.32604000"],["79819.29000000","0.02254000"],["79820.00000000","0.00007000"],["79820.01000000","0.05412000"],["79821.11000000","0.05472000"],["79821.12000000","0.00000000"],["79821.13000000","0.00000000"],["79824.29000000","0.00000000"],["79833.96000000","0.19019000"],["79833.97000000","0.00015000"],["79833.98000000","0.00400000"]]}}}
{"rx_ns": 14004491644400, "frame": {"stream":"btcusdt@depth@100ms","data":{"e":"depthUpdate","E":1787650999714,"s":"BTCUSDT","U":99118707690,"u":99118707719,"b":[["79818.00000000","1.56724000"],["79817.99000000","0.00097000"],["79817.08000000","0.00725000"],["79816.44000000","0.33898000"],["79815.09000000","0.00117000"],["79813.76000000","0.03231000"],["79790.00000000","0.82051000"],["79714.49000000","0.00400000"],["71836.20000000","0.00440000"],["63854.40000000","0.00020000"]],"a":[["79819.29000000","0.02254000"],["79820.01000000","0.05426000"],["79821.11000000","0.05458000"],["79946.30000000","0.00000000"],["80014.67000000","0.01962000"]]}}}
{"rx_ns": 14004593665200, "frame": {"stream":"btcusdt@depth@100ms","data":{"e":"depthUpdate","E":1787650999815,"s":"BTCUSDT","U":99118707720,"u":99118707733,"b":[["63854.40000000","0.00000000"]],"a":[["79818.01000000","1.14029000"],["79822.82000000","0.00007000"],["79823.10000000","0.00015000"],["79823.11000000","0.00008000"],["79824.29000000","0.00000000"],["79825.16000000","0.00000000"],["79825.18000000","0.00000000"],["79833.96000000","0.00000000"],["79833.98000000","0.19419000"]]}}}
{"rx_ns": 14004691938900, "frame": {"stream":"btcusdt@depth@100ms","data":{"e":"depthUpdate","E":1787650999914,"s":"BTCUSDT","U":99118707734,"u":99118707787,"b":[["79818.00000000","1.56319000"],["79817.08000000","0.00014000"],["79817.01000000","0.00710000"],["79816.44000000","0.33912000"],["79813.77000000","0.06084000"],["79813.68000000","0.00007000"],["79813.67000000","0.41166000"],["79813.04000000","0.06077000"],["79812.50000000","0.06084000"],["79812.49000000","1.04946000"],["79811.92000000","0.00000000"],["79808.33000000","0.00400000"],["79666.62000000","0.00400000"],["71836.20000000","0.00440000"]],"a":[["79818.01000000","0.84264000"],["79818.62000000","0.00000000"],["79818.63000000","0.00028000"],["79819.10000000","0.00000000"],["79819.11000000","0.00021000"],["79820.77000000","0.05085000"],["79821.10000000","0.00000000"],["79821.11000000","0.00000000"],["79821.72000000","0.00000000"],["79821.73000000","0.00000000"],["79822.96000000","0.00007000"],["79823.10000000","0.00000000"],["79823.11000000","0.00000000"],["79823.58000000","0.00007000"],["79823.93000000","0.00022000"],["79824.20000000","0.00407000"],["79824.29000000","0.00008000"],["79946.30000000","0.01962000"],["80014.67000000","0.00000000"],["81015.29000000","0.00030000"]]}}}
{"rx_ns": 14004794231300, "frame": {"stream":"btcusdt@depth20","data":{"lastUpdateId":99118708011,"bids":[["79818.00000000","1.68302000"],["79817.99000000","0.00027000"],["79817.98000000","0.00020000"],["79817.97000000","0.03224000"],["79817.39000000","0.06464000"],["79817.38000000","0.06077000"],["79817.29000000","0.00007000"],["79817.01000000","0.00724000"],["79816.90000000","0.00007000"],["79816.77000000","0.00007000"],["79816.76000000","0.06084000"],["79816.66000000","0.00007000"],["79816.47000000","0.00007000"],["79816.46000000","0.06084000"],["79816.45000000","0.00090000"],["79816.44000000","0.00083000"],["79816.31000000","0.00007000"],["79816.30000000","0.00007000"],["79816.01000000","0.00007000"],["79816.00000000","0.02428000"]],"asks":[["79818.01000000","0.43953000"],["79818.02000000","0.00048000"],["79818.03000000","0.00013000"],["79818.54000000","0.00014000"],["79818.63000000","0.00014000"],["79818.75000000","0.00014000"],["79818.94000000","0.00007000"],["79819.12000000","0.00014000"],["79819.15000000","0.00007000"],["79819.16000000","0.33843000"],["79819.22000000","0.00202000"],["79819.28000000","0.00007000"],["79819.29000000","0.02254000"],["79819.74000000","0.00007000"],["79820.01000000","0.00014000"],["79820.56000000","0.00021000"],["79820.57000000","0.02694000"],["79820.76000000","0.00007000"],["79820.77000000","0.05085000"],["79821.73000000","0.06077000"]]}}}
{"rx_ns": 14004794329300, "frame": {"stream":"btcusdt@depth@100ms","data":{"e":"depthUpdate","E":1787651000014,"s":"BTCUSDT","U":99118707788,"u":99118708011,"b":[["79818.00000000","1.68302000"],["79817.99000000","0.00027000"],["79817.98000000","0.00020000"],["79817.97000000","0.03224000"],["79817.39000000","0.06464000"],["79817.38000000","0.06077000"],["79817.08000000","0.00000000"],["79817.01000000","0.00724000"],["79816.77000000","0.00007000"],["79816.76000000","0.06084000"],["79816.47000000","0.00007000"],["79816.46000000","0.06084000"],["79816.45000000","0.00090000"],["79816.44000000","0.00083000"],["79816.01000000","0.00007000"],["79816.00000000","0.02428000"],["79815.55000000","0.00007000"],["79815.54000000","0.06077000"],["79815.53000000","0.00960000"],["79815.10000000","0.00626000"],["79815.09000000","0.00117000"],["79815.08000000","0.02501000"],["79814.91000000","0.00633000"],["79814.90000000","0.06084000"],["79814.88000000","0.00014000"],["79814.52000000","0.00722000"],["79814.29000000","0.00000000"],["79814.28000000","0.06077000"],["79814.01000000","0.00007000"],["79814.00000000","0.02428000"],["79813.78000000","1.05420000"],["79813.77000000","1.87677000"],["79813.68000000","0.00000000"],["79813.67000000","0.00007000"],["79813.05000000","0.00000000"],["79813.04000000","0.00000000"],["79812.50000000","0.00000000"],["79812.49000000","1.04939000"],["79812.25000000","0.01235000"],["79812.00000000","0.02400000"],["79811.91000000","0.12529000"],["79811.61000000","0.00000000"],["79811.38000000","1.00502000"],["79808.03000000","0.37599000"],["79807.87000000","0.00000000"],["79806.71000000","0.35246000"],["79806.68000000","0.00000000"],["79805.36000000","0.33840000"],["79803.60000000","0.33841000"],["79797.03000000","0.00000000"],["79796.97000000","0.33844000"],["79788.01000000","0.05165000"],["79786.90000000","0.00000000"],["79780.88000000","0.00000000"],["79780.00000000","0.11801000"],["79776.18000000","0.00000000"],["79755.35000000","0.04483000"],["79755.34000000","0.00000000"],["71836.20000000","0.00448000"],["71836.19000000","0.00008000"],["71836.00000000","0.00010000"],["63854.40000000","0.00031000"]],"a":[["79818.01000000","0.43953000"],["79818.02000000","0.00048000"],["79818.63000000","0.00014000"],["79819.11000000","0.00000000"],["79819.12000000","0.00014000"],["79819.28000000","0.00007000"],["79820.00000000","0.00000000"],["79820.01000000","0.00014000"],["79820.56000000","0.00021000"],["79820.77000000","0.05085000"],["79821.73000000","0.06077000"],["79821.84000000","0.00007000"],["79821.85000000","0.02715000"],["79822.35000000","0.06091000"],["79823.58000000","0.00007000"],["79823.93000000","0.00007000"],["79824.20000000","0.00800000"],["79824.21000000","0.06098000"],["79824.29000000","0.00000000"],["79824.30000000","0.81380000"],["79824.31000000","0.00000000"],["79824.36000000","0.00000000"],["79824.76000000","0.00000000"],["79824.77000000","0.00000000"],["79825.18000000","0.00000000"],["79825.87000000","0.00000000"],["79825.88000000","0.00000000"],["79827.11000000","0.00029000"],["79828.13000000","0.00000000"],["79828.14000000","0.00000000"],["79831.41000000","0.00626000"],["79833.98000000","0.00400000"],["79835.13000000","0.12525000"],["79838.86000000","0.00000000"],["79839.12000000","0.00000000"],["79840.98000000","0.19019000"],["79846.75000000","0.00000000"],["79860.34000000","0.34217000"],["79891.78000000","1.23949000"]]}}}
{"rx_ns": 14004895576800, "frame": {"stream":"btcusdt@depth@100ms","data":{"e":"depthUpdate","E":1787651000114,"s":"BTCUSDT","U":99118708012,"u":99118708103,"b":[["79818.00000000","1.68318000"],["79817.97000000","0.03238000"],["79817.40000000","0.00007000"],["79817.39000000","0.04753000"],["79817.38000000","0.00007000"],["79817.01000000","0.00724000"],["79816.76000000","0.06091000"],["79816.46000000","0.06084000"],["79816.45000000","0.00076000"],["79816.44000000","0.00069000"],["79816.00000000","0.02421000"],["79815.55000000","0.00007000"],["79815.53000000","0.00946000"],["79815.09000000","0.00117000"],["79815.08000000","0.02487000"],["79814.91000000","0.00633000"],["79814.52000000","0.00708000"],["79814.29000000","0.00007000"],["79814.00000000","0.02428000"],["79813.80000000","0.06077000"],["79813.79000000","0.00400000"],["79813.76000000","0.03224000"],["79813.67000000","0.00000000"],["79812.48000000","0.31338000"],["79810.24000000","0.00250000"],["79808.33000000","0.00000000"],["79786.30000000","0.00400000"],["79726.72000000","0.47586000"],["79666.57000000","1.50097000"],["71836.20000000","0.00416000"],["71836.00000000","0.00000000"]],"a":[["79818.01000000","0.44130000"],["79818.63000000","0.00007000"],["79819.12000000","0.00000000"],["79819.29000000","0.02240000"],["79820.01000000","0.00000000"],["79820.77000000","0.05085000"],["79821.72000000","0.00007000"],["79821.73000000","0.06084000"],["79822.34000000","0.00007000"],["79822.96000000","0.00007000"],["79822.97000000","0.06084000"],["79823.58000000","0.00007000"],["79823.93000000","0.00000000"],["79823.94000000","0.04007000"],["79826.20000000","0.00250000"],["79827.94000000","0.00188000"],["79967.75000000","0.55881000"],["79969.87000000","1.50273000"]]}}}
{"rx_ns": 14004991274800, "frame": {"stream":"btcusdt@depth@100ms","data":{"e":"depthUpdate","E":1787651000214,"s":"BTCUSDT","U":99118708104,"u":99118708288,"b":[["79818.00000000","1.47853000"],["79817.99000000","0.00083000"],["79817.98000000","0.00013000"],["79817.97000000","0.00014000"],["79817.40000000","0.00000000"],["79817.39000000","0.00007000"],["79817.38000000","0.00000000"],["79817.01000000","0.00014000"],["79816.77000000","0.00000000"],["79816.76000000","0.00014000"],["79816.47000000","0.00000000"],["79816.46000000","0.00007000"],["79815.55000000","0.00000000"],["79815.54000000","0.00007000"],["79815.53000000","0.00939000"],["79815.10000000","0.00000000"],["79814.91000000","0.00000000"],["79814.90000000","0.00007000"],["79814.52000000","0.00701000"],["79814.29000000","0.00000000"],["79814.28000000","0.00000000"],["79814.01000000","0.00014000"],["79814.00000000","0.02421000"],["79813.81000000","0.00000000"],["79813.80000000","0.00000000"],["79813.79000000","0.00407000"],["79813.78000000","0.44126000"],["79813.77000000","0.00007000"],["79813.76000000","0.03231000"],["79812.99000000","0.00000000"],["79812.50000000","0.00633000"],["79812.49000000","1.04946000"],["79811.92000000","0.00007000"],["79811.49000000","0.00626000"],["79810.24000000","0.00000000"],["79808.86000000","0.00250000"],["79744.14000000","0.02088000"],["78620.73000000","0.00030000"],["71836.20000000","0.00448000"],["63854.40000000","0.00000000"]],"a":[["79818.01000000","0.72212000"],["79818.02000000","0.00055000"],["79818.62000000","0.00007000"],["79818.63000000","0.06084000"],["79819.14000000","0.00007000"],["79819.15000000","0.28351000"],["79819.28000000","0.00000000"],["79819.29000000","0.02254000"],["79819.59000000","0.00007000"],["79819.60000000","0.19665000"],["79819.86000000","0.00007000"],["79819.87000000","0.06077000"],["79820.48000000","0.00007000"],["79820.49000000","0.06077000"],["79820.56000000","0.00014000"],["79820.76000000","0.00007000"],["79820.77000000","0.05092000"],["79821.10000000","0.00007000"],["79821.11000000","0.06077000"],["79821.72000000","0.00007000"],["79821.84000000","0.00000000"],["79822.34000000","0.00000000"],["79822.96000000","0.00000000"],["79823.58000000","0.00000000"],["79823.87000000","0.00029000"],["79824.28000000","1.55886000"],["79824.29000000","1.87677000"],["79824.30000000","0.00000000"],["79824.81000000","0.00250000"],["79826.20000000","0.00000000"],["79827.11000000","0.00000000"],["79840.98000000","0.00000000"],["79946.30000000","0.00000000"],["79955.99000000","0.01962000"]]}}}
{"rx_ns": 14005094406100, "frame": {"stream":"btcusdt@depth@100ms","data":{"e":"depthUpdate","E":1787651000314,"s":"BTCUSDT","U":99118708289,"u":99118708407,"b":[["79818.00000000","1.27589000"],["79817.99000000","0.00076000"],["79817.97000000","0.00000000"],["79817.39000000","0.00000000"],["79817.01000000","0.00000000"],["79816.76000000","0.00000000"],["79816.46000000","0.00000000"],["79816.00000000","0.02414000"],["79815.54000000","0.00000000"],["79815.53000000","0.00946000"],["79815.08000000","0.02487000"],["79814.52000000","0.00708000"],["79814.00000000","0.02428000"],["79813.79000000","0.00007000"],["79813.78000000","0.44133000"],["79813.76000000","0.03231000"],["79812.43000000","0.04010000"],["79812.25000000","0.01242000"],["79812.00000000","0.02407000"],["79811.49000000","0.00000000"],["79811.39000000","0.00007000"],["79810.07000000","0.00626000"],["79808.33000000","0.00400000"],["79808.03000000","0.00000000"],["79802.80000000","0.00007000"],["79786.30000000","0.00000000"],["79785.78000000","0.00007000"],["79754.93000000","1.24161000"],["79746.40000000","0.00400000"],["79744.14000000","0.00000000"],["79735.93000000","0.62625000"],["79610.48000000","0.00007000"],["71836.20000000","0.00432000"],["71836.00000000","0.00010000"],["63854.00000000","0.00015000"]],"a":[["79818.01000000","0.92477000"],["79818.02000000","0.00069000"],["79818.32000000","0.00007000"],["79818.33000000","0.04930000"],["79818.63000000","0.06091000"],["79819.15000000","0.28358000"],["79819.29000000","0.02254000"],["79819.59000000","0.00000000"],["79819.60000000","0.00014000"],["79819.87000000","0.06084000"],["79820.49000000","0.06084000"],["79820.77000000","0.05085000"],["79821.73000000","0.06077000"],["79821.85000000","0.02701000"],["79822.35000000","0.06077000"],["79822.97000000","0.06077000"],["79824.19000000","0.19019000"],["79824.21000000","0.06091000"],["79824.28000000","1.36867000"],["79824.37000000","0.00000000"],["79827.94000000","0.00000000"],["79828.06000000","0.00693000"],["79833.98000000","0.00400000"],["79834.17000000","0.00000000"],["79834.74000000","0.00007000"]]}}}
{"rx_ns": 14005191186800, "frame": {"stream":"btcusdt@depth@100ms","data":{"e":"depthUpdate","E":1787651000414,"s":"BTCUSDT","U":99118708408,"u":99118708441,"b":[["79818.00000000","1.47814000"],["79813.76000000","0.03238000"],["79812.50000000","0.00640000"],["79808.86000000","0.00000000"],["79808.06000000","0.00250000"],["79776.18000000","0.00007000"],["71836.20000000","0.00432000"],["71836.19000000","0.00000000"],["71836.00000000","0.00000000"],["64000.00000000","66.60215000"]],"a":[["79818.01000000","0.90408000"],["79818.33000000","0.04937000"],["79819.29000000","0.02254000"],["79819.60000000","0.00007000"],["79824.01000000","0.00250000"],["79824.19000000","0.00000000"],["79824.21000000","0.06084000"],["79824.81000000","0.00000000"],["79833.98000000","0.19419000"]]}}}
{"rx_ns": 14005296122800, "frame": {"stream":"btcusdt@depth@100ms","data":{"e":"depthUpdate","E":1787651000514,"s":"BTCUSDT","U":99118708442,"u":99118708455,"b":[["79786.31000000","0.00400000"],["79593.65000000","0.00771000"],["79589.96000000","0.00000000"],["71836.20000000","0.00432000"],["63854.40000000","0.00031000"]],"a":[["79818.01000000","0.90401000"],["79818.02000000","0.00062000"],["79818.32000000","0.00000000"],["79818.33000000","0.00007000"],["79822.34000000","0.00007000"]]}}}
{"rx_ns": 14005391461700, "frame": {"stream":"btcusdt@depth@100ms","data":{"e":"depthUpdate","E":1787651000614,"s":"BTCUSDT","U":99118708456,"u":99118708492,"b":[["79818.00000000","1.81618000"],["79809.44000000","0.00250000"],["79808.33000000","0.01200000"],["79808.06000000","0.00000000"],["79791.00000000","0.70000000"],["79790.00000000","0.12051000"],["79786.31000000","0.00000000"],["79776.18000000","0.00000000"],["79744.14000000","0.02088000"],["71836.20000000","0.00448000"],["63854.40000000","0.00000000"]],"a":[["79818.01000000","0.72390000"],["79818.33000000","0.00000000"],["79819.86000000","0.00000000"],["79819.87000000","0.00007000"],["79820.77000000","0.05092000"],["79822.96000000","0.00007000"],["79823.87000000","0.00000000"],["79824.01000000","0.00000000"],["79824.19000000","0.00800000"],["79825.18000000","0.00028000"],["79825.39000000","0.00250000"],["79859.94000000","0.00400000"],["79860.34000000","0.33817000"]]}}}
{"rx_ns": 14005495481500, "frame": {"stream":"btcusdt@depth@100ms","data":{"e":"depthUpdate","E":1787651000714,"s":"BTCUSDT","U":99118708493,"u":99118708511,"b":[["79808.34000000","0.00400000"],["79786.32000000","0.00800000"],["79744.14000000","0.00000000"],["71836.20000000","0.00416000"],["71836.00000000","0.00000000"]],"a":[["79818.01000000","0.72383000"],["79818.02000000","0.00055000"],["79819.29000000","0.02247000"],["79819.60000000","0.00000000"],["79819.87000000","0.00000000"],["79821.11000000","0.06084000"],["79823.94000000","0.04014000"],["79824.18000000","0.00400000"],["79824.79000000","0.00705000"],["79826.58000000","0.00400000"]]}}}
{"rx_ns": 14005596575500, "frame": {"stream":"btcusdt@depth@100ms","data":{"e":"depthUpdate","E":1787651000814,"s":"BTCUSDT","U":99118708512,"u":99118708528,"b":[["79803.65000000","0.00000000"],["79797.41000000","0.02435000"],["79786.32000000","0.00400000"],["79747.37000000","0.00000000"],["79717.61000000","0.05774000"],["71836.20000000","0.00448000"],["71836.00000000","0.00000000"],["63854.40000000","0.00000000"]],"a":[["79818.01000000","0.92169000"],["79857.92000000","0.02475000"],["79864.36000000","0.00000000"]]}}}
{"rx_ns": 14005690908700, "frame": {"stream":"btcusdt@depth@100ms","data":{"e":"depthUpdate","E":1787651000914,"s":"BTCUSDT","U":99118708529,"u":99118708541,"b":[["79786.29000000","0.00400000"],["79593.03000000","0.01962000"],["79589.04000000","0.00000000"],["71836.20000000","0.00432000"]],"a":[["79839.33000000","0.33826000"],["79846.85000000","0.62635000"],["79860.34000000","0.00000000"],["79891.78000000","0.00000000"],["80257.64000000","0.00000000"],["81015.29000000","0.00030000"]]}}}
{"rx_ns": 14005800562400, "frame": {"stream":"btcusdt@depth20","data":{"lastUpdateId":99118708649,"bids":[["79818.00000000","1.90014000"],["79817.99000000","0.00027000"],["79817.98000000","0.00013000"],["79817.29000000","0.00007000"],["79816.98000000","0.00695000"],["79816.90000000","0.00007000"],["79816.66000000","0.00007000"],["79816.45000000","0.00076000"],["79816.44000000","0.00069000"],["79816.31000000","0.00007000"],["79816.30000000","0.00007000"],["79816.01000000","0.00007000"],["79816.00000000","0.02428000"],["79815.98000000","0.00007000"],["79815.55000000","0.00007000"],["79815.54000000","0.06077000"],["79815.53000000","0.00953000"],["79815.48000000","0.00134000"],["79815.09000000","0.00117000"],["79815.08000000","0.02494000"]],"asks":[["79818.01000000","0.43669000"],["79818.02000000","0.00055000"],["79818.03000000","0.00013000"],["79818.54000000","0.00014000"],["79818.62000000","0.00007000"],["79818.63000000","0.06098000"],["79818.75000000","0.00014000"],["79818.94000000","0.00007000"],["79819.14000000","0.00007000"],["79819.15000000","0.28365000"],["79819.16000000","0.33843000"],["79819.22000000","0.00202000"],["79819.29000000","0.02261000"],["79819.74000000","0.00007000"],["79820.36000000","0.00007000"],["79820.37000000","0.19745000"],["79820.49000000","0.00014000"],["79820.56000000","0.00014000"],["79820.57000000","0.02694000"],["79820.76000000","0.00007000"]]}}}
{"rx_ns": 14005800647000, "frame": {"stream":"btcusdt@depth@100ms","data":{"e":"depthUpdate","E":1787651001014,"s":"BTCUSDT","U":99118708542,"u":99118708649,"b":[["79818.00000000","1.90014000"],["79817.99000000","0.00027000"],["79816.98000000","0.00695000"],["79816.00000000","0.02428000"],["79815.55000000","0.00007000"],["79815.54000000","0.06077000"],["79815.53000000","0.00953000"],["79815.08000000","0.02494000"],["79814.91000000","0.00007000"],["79814.90000000","0.06084000"],["79814.52000000","0.00722000"],["79814.29000000","0.00007000"],["79814.28000000","0.06077000"],["79814.00000000","0.02442000"],["79813.80000000","0.00007000"],["79813.79000000","0.06084000"],["79813.78000000","0.44140000"],["79813.77000000","0.00000000"],["79813.76000000","0.03252000"],["79813.05000000","0.00007000"],["79813.04000000","0.06084000"],["79812.51000000","0.06077000"],["79812.50000000","0.00640000"],["79812.49000000","1.04939000"],["79812.44000000","0.00400000"],["79811.92000000","0.00000000"],["79811.39000000","0.00000000"],["79670.06000000","0.01962000"],["79658.29000000","0.00000000"],["71836.20000000","0.00448000"],["71836.00000000","0.00010000"],["63854.40000000","0.00031000"]],"a":[["79818.01000000","0.43669000"],["79818.63000000","0.06098000"],["79819.15000000","0.28365000"],["79819.29000000","0.02261000"],["79820.36000000","0.00007000"],["79820.37000000","0.19745000"],["79820.48000000","0.00000000"],["79820.49000000","0.00014000"],["79820.77000000","0.05092000"],["79821.10000000","0.00000000"],["79821.11000000","0.00014000"],["79821.72000000","0.00000000"],["79821.73000000","0.00000000"],["79823.58000000","0.00007000"],["79824.20000000","0.00807000"],["79824.28000000","0.81325000"],["79824.29000000","0.00000000"],["79824.79000000","0.00000000"],["79825.18000000","0.00018000"],["79825.66000000","0.00908000"],["79825.98000000","0.00012000"],["79826.58000000","0.00000000"],["79826.81000000","0.00000000"],["79828.31000000","0.00400000"],["79829.16000000","0.00400000"],["79833.98000000","0.00400000"],["79839.65000000","0.19019000"]]}}}
{"rx_ns": 14005891643100, "frame": {"stream":"btcusdt@depth@100ms","data":{"e":"depthUpdate","E":1787651001114,"s":"BTCUSDT","U":99118708650,"u":99118708709,"b":[["79818.00000000","1.89972000"],["79816.98000000","0.00709000"],["79816.00000000","0.02428000"],["79815.54000000","0.06091000"],["79815.08000000","0.02494000"],["79814.90000000","0.06098000"],["79814.52000000","0.00722000"],["79814.00000000","0.02428000"],["79813.78000000","0.44126000"],["79813.76000000","0.03238000"],["79812.50000000","0.00626000"],["79681.21000000","0.00000000"],["71836.20000000","0.00432000"],["71836.00000000","0.00020000"]],"a":[["79818.01000000","0.43016000"],["79819.29000000","0.02254000"],["79820.37000000","0.19759000"],["79820.49000000","0.00000000"],["79820.77000000","0.05085000"],["79821.11000000","0.00000000"],["79821.85000000","0.02715000"],["79824.21000000","0.06091000"],["79825.18000000","0.00000000"],["79826.48000000","0.00018000"],["79827.79000000","0.00188000"],["79920.62000000","0.00000000"]]}}}
{"rx_ns": 14005991292200, "frame": {"stream":"btcusdt@depth@100ms","data":{"e":"depthUpdate","E":1787651001214,"s":"BTCUSDT","U":99118708710,"u":99118708805,"b":[["79818.00000000","1.97816000"],["79817.40000000","0.00000000"],["79816.98000000","0.00723000"],["79816.78000000","0.00007000"],["79816.77000000","0.04413000"],["79816.76000000","0.00007000"],["79816.61000000","0.00400000"],["79816.15000000","0.00007000"],["79816.14000000","0.06077000"],["79814.91000000","0.00007000"],["79814.90000000","0.06105000"],["79814.53000000","0.00626000"],["79814.29000000","0.00007000"],["79814.01000000","0.00014000"],["79814.00000000","0.02414000"],["79813.82000000","0.00000000"],["79813.81000000","1.10094000"],["79813.80000000","1.87677000"],["79813.79000000","0.00000000"],["79813.78000000","0.00000000"],["79813.76000000","0.03231000"],["79813.05000000","0.00000000"],["79813.04000000","0.00000000"],["79812.51000000","0.00000000"],["79812.44000000","0.00000000"],["79812.25000000","0.01235000"],["79812.00000000","0.02400000"],["79811.05000000","0.00250000"],["79810.07000000","0.00000000"],["79809.44000000","0.00000000"],["79689.73000000","0.04912000"],["78620.73000000","0.00030000"],["71836.20000000","0.00432000"],["71836.00000000","0.00000000"],["63854.40000000","0.00000000"]],"a":[["79818.01000000","0.43009000"],["79818.02000000","0.00055000"],["79818.62000000","0.00000000"],["79818.63000000","0.00021000"],["79819.15000000","0.22606000"],["79821.85000000","0.02701000"],["79822.34000000","0.00000000"],["79822.35000000","0.00000000"],["79822.96000000","0.00000000"],["79822.97000000","0.06077000"],["79823.93000000","0.00007000"],["79824.26000000","0.00007000"],["79824.27000000","0.05604000"],["79824.28000000","0.75248000"],["79824.38000000","0.00007000"],["79825.39000000","0.00000000"],["79825.59000000","0.00689000"],["79825.98000000","0.00000000"],["79826.48000000","0.00000000"],["79827.00000000","0.00250000"],["79827.26000000","0.00015000"],["79827.78000000","0.00019000"],["79828.31000000","0.00000000"],["79829.16000000","0.00000000"],["79829.46000000","0.00400000"],["79830.37000000","0.00000000"],["79831.78000000","0.00400000"],["79929.17000000","0.02804000"]]}}}
{"rx_ns": 14006090741200, "frame": {"stream":"btcusdt@depth@100ms","data":{"e":"depthUpdate","E":1787651001314,"s":"BTCUSDT","U":99118708806,"u":99118708880,"b":[["79818.00000000","1.97824000"],["79816.98000000","0.00723000"],["79816.77000000","0.02709000"],["79816.14000000","0.06091000"],["79814.90000000","0.06091000"],["79814.52000000","0.00708000"],["79814.29000000","0.00007000"],["79814.01000000","0.00014000"],["79814.00000000","0.02421000"],["79813.82000000","0.01607000"],["79808.34000000","0.00000000"],["79808.33000000","0.00000000"],["79802.80000000","0.00000000"],["79796.15000000","0.00007000"],["79605.22000000","0.00007000"],["71836.20000000","0.00432000"],["63854.00000000","0.00015000"]],"a":[["79818.01000000","0.43016000"],["79818.63000000","0.00007000"],["79821.85000000","0.02708000"],["79822.96000000","0.00007000"],["79822.97000000","0.06091000"],["79823.93000000","0.00000000"],["79824.20000000","0.00807000"],["79824.21000000","0.06098000"],["79824.26000000","0.00007000"],["79824.27000000","0.05604000"],["79824.28000000","0.75255000"],["79824.38000000","0.00000000"],["79834.74000000","0.00000000"]]}}}
{"rx_ns": 14006191567200, "frame": {"stream":"btcusdt@depth@100ms","data":{"e":"depthUpdate","E":1787651001414,"s":"BTCUSDT","U":99118708881,"u":99118708923,"b":[["79818.00000000","1.97870000"],["79816.34000000","0.00400000"],["79814.29000000","0.00007000"],["79814.01000000","0.00014000"],["79813.82000000","0.01607000"],["79811.90000000","0.00250000"],["79811.05000000","0.00000000"],["79807.74000000","0.00000000"],["79803.93000000","0.25488000"],["79802.80000000","0.00007000"],["79797.04000000","0.00000000"],["79782.22000000","0.00000000"],["71836.20000000","0.00432000"]],"a":[["79818.01000000","0.31677000"],["79818.75000000","0.00007000"],["79819.15000000","0.00021000"],["79820.36000000","0.00000000"],["79820.37000000","0.00014000"],["79820.56000000","0.00021000"],["79823.88000000","0.00000000"],["79823.93000000","0.00007000"],["79824.20000000","0.00807000"],["79824.26000000","0.00007000"],["79824.27000000","0.05597000"],["79825.59000000","0.00000000"],["79825.66000000","0.00000000"],["79827.00000000","0.00000000"],["79827.86000000","0.00250000"],["79828.06000000","0.00000000"],["79834.74000000","0.00007000"],["79839.33000000","0.00000000"],["79859.95000000","0.33817000"],["79864.30000000","0.00400000"],["80217.72000000","0.00007000"]]}}}
{"rx_ns": 14006296082900, "frame": {"stream":"btcusdt@depth@100ms","data":{"e":"depthUpdate","E":1787651001514,"s":"BTCUSDT","U":99118708924,"u":99118708986,"b":[["79818.00000000","1.98061000"],["79814.29000000","0.00007000"],["79814.01000000","0.00014000"],["79813.82000000","0.01607000"],["79808.64000000","0.00048000"],["79807.24000000","0.00000000"],["79806.98000000","0.00000000"],["71836.20000000","0.00448000"],["63854.40000000","0.00031000"]],"a":[["79818.01000000","0.31665000"],["79818.02000000","0.00048000"],["79819.14000000","0.00000000"],["79819.15000000","0.00007000"],["79819.28000000","0.00007000"],["79819.29000000","0.02247000"],["79820.37000000","0.00000000"],["79820.77000000","0.05092000"],["79821.72000000","0.00007000"],["79821.73000000","0.06077000"],["79821.84000000","0.00007000"],["79821.85000000","0.02715000"],["79822.34000000","0.00007000"],["79822.35000000","0.06077000"],["79823.58000000","0.00007000"],["79823.59000000","0.06098000"],["79823.93000000","0.00000000"],["79823.94000000","0.04028000"],["79824.20000000","0.00800000"],["79824.26000000","0.00000000"]]}}}
{"rx_ns": 14006394304600, "frame": {"stream":"btcusdt@depth@100ms","data":{"e":"depthUpdate","E":1787651001614,"s":"BTCUSDT","U":99118708987,"u":99118709059,"b":[["79818.00000000","1.98182000"],["79816.78000000","0.00000000"],["79816.77000000","0.00014000"],["79816.61000000","0.00000000"],["79816.15000000","0.00000000"],["79816.14000000","0.00014000"],["79815.55000000","0.00000000"],["79815.54000000","0.00014000"],["79815.39000000","0.00400000"],["79814.90000000","0.06105000"],["79814.53000000","0.00000000"],["79814.01000000","0.00014000"],["79813.83000000","0.00007000"],["79813.82000000","0.01607000"],["79813.81000000","1.10101000"],["79812.99000000","0.00626000"],["79812.50000000","0.00633000"],["79808.30000000","0.02447000"],["79803.93000000","0.00000000"],["79800.63000000","0.48473000"],["79795.87000000","0.04618000"],["79781.87000000","0.00000000"],["71836.20000000","0.00440000"],["63854.40000000","0.00000000"]],"a":[["79818.01000000","0.44034000"],["79818.02000000","0.00055000"],["79818.63000000","0.05640000"],["79819.14000000","0.00007000"],["79819.15000000","0.06084000"],["79819.29000000","0.02254000"],["79820.48000000","0.00007000"],["79820.49000000","0.06077000"],["79820.77000000","0.05099000"],["79821.10000000","0.00007000"],["79821.11000000","0.06077000"],["79821.72000000","0.00007000"],["79821.73000000","0.06091000"],["79821.84000000","0.00000000"],["79821.85000000","0.02715000"],["79822.34000000","0.00007000"],["79822.35000000","0.06091000"],["79822.53000000","0.20866000"],["79822.96000000","0.00000000"],["79823.58000000","0.00000000"],["79823.59000000","0.06084000"],["79823.94000000","0.04014000"],["79943.15000000","0.00394000"],["79967.28000000","0.00000000"]]}}}
{"rx_ns": 14006492714500, "frame": {"stream":"btcusdt@depth@100ms","data":{"e":"depthUpdate","E":1787651001714,"s":"BTCUSDT","U":99118709060,"u":99118709125,"b":[["79818.00000000","1.98182000"],["79816.98000000","0.00709000"],["79816.77000000","0.00000000"],["79816.76000000","0.00000000"],["79816.14000000","0.00000000"],["79816.00000000","0.02421000"],["79815.54000000","0.00000000"],["79814.90000000","0.06098000"],["79814.52000000","0.00722000"],["79814.28000000","0.06091000"],["79813.76000000","0.03238000"],["71836.20000000","0.00456000"]],"a":[["79818.01000000","0.44055000"],["79818.62000000","0.00007000"],["79818.63000000","0.05654000"],["79819.15000000","0.06098000"],["79819.29000000","0.02254000"],["79820.49000000","0.06091000"],["79820.77000000","0.05099000"],["79821.11000000","0.06091000"],["79821.73000000","0.06077000"],["79821.85000000","0.02701000"],["79822.35000000","0.06084000"],["79822.97000000","0.06077000"],["79857.76000000","0.00400000"],["79864.30000000","0.00000000"]]}}}
{"rx_ns": 14006592128000, "frame": {"stream":"btcusdt@depth@100ms","data":{"e":"depthUpdate","E":1787651001814,"s":"BTCUSDT","U":99118709126,"u":99118709150,"b":[["79818.00000000","1.98143000"],["79813.82000000","0.01607000"],["79813.81000000","1.10101000"],["79812.50000000","0.00633000"],["79741.21000000","0.62625000"],["79735.93000000","0.00000000"],["71836.20000000","0.00440000"],["63854.40000000","0.00000000"]],"a":[["79818.01000000","0.64292000"],["79821.11000000","0.06098000"],["79821.69000000","0.00007000"],["79821.70000000","0.03229000"],["79822.34000000","0.00000000"],["79822.35000000","0.06077000"],["79822.53000000","0.00000000"]]}}}
{"rx_ns": 14006701829700, "frame": {"stream":"btcusdt@depth@100ms","data":{"e":"depthUpdate","E":1787651001914,"s":"BTCUSDT","U":99118709151,"u":99118709182,"b":[["79818.00000000","1.97743000"],["79814.00000000","0.02435000"],["79813.82000000","0.01607000"],["79813.81000000","1.10101000"],["79812.50000000","0.00633000"],["79808.69000000","0.00000000"],["79744.14000000","0.02088000"],["71836.20000000","0.00456000"],["63854.40000000","0.00000000"]],"a":[["79818.01000000","0.64291000"],["79818.62000000","0.00000000"],["79818.63000000","0.00021000"],["79820.48000000","0.00000000"],["79820.49000000","0.00014000"],["79821.11000000","0.06098000"],["79822.34000000","0.00007000"],["81015.29000000","0.00030000"]]}}}
{"rx_ns": 14006799166000, "frame": {"stream":"btcusdt@depth20","data":{"lastUpdateId":99118709246,"bids":[["79818.00000000","1.97743000"],["79817.99000000","0.00027000"],["79817.98000000","0.00013000"],["79817.29000000","0.00007000"],["79816.98000000","0.00709000"],["79816.90000000","0.00007000"],["79816.66000000","0.00007000"],["79816.45000000","0.00076000"],["79816.44000000","0.00069000"],["79816.34000000","0.00400000"],["79816.31000000","0.00007000"],["79816.30000000","0.00007000"],["79816.01000000","0.00007000"],["79816.00000000","0.02421000"],["79815.98000000","0.00007000"],["79815.53000000","0.00953000"],["79815.48000000","0.00134000"],["79815.39000000","0.00400000"],["79815.09000000","0.00117000"],["79815.08000000","0.02494000"]],"asks":[["79818.01000000","0.64403000"],["79818.02000000","0.00055000"],["79818.03000000","0.00013000"],["79818.54000000","0.00014000"],["79818.63000000","0.05691000"],["79818.75000000","0.00007000"],["79818.94000000","0.00007000"],["79819.14000000","0.00007000"],["79819.15000000","0.31349000"],["79819.16000000","0.33843000"],["79819.22000000","0.00202000"],["79819.28000000","0.00007000"],["79819.29000000","0.02247000"],["79819.74000000","0.00007000"],["79820.49000000","0.06077000"],["79820.56000000","0.00021000"],["79820.57000000","0.02694000"],["79820.76000000","0.00007000"],["79820.77000000","0.05099000"],["79821.10000000","0.00007000"]]}}}
{"rx_ns": 14006799334200, "frame": {"stream":"btcusdt@depth@100ms","data":{"e":"depthUpdate","E":1787651002014,"s":"BTCUSDT","U":99118709183,"u":99118709246,"b":[["79816.00000000","0.02421000"],["79815.55000000","0.00000000"],["79815.54000000","0.00000000"],["79814.91000000","0.00000000"],["79814.90000000","0.00021000"],["79814.29000000","0.00000000"],["79814.28000000","0.00014000"],["79813.83000000","0.00007000"],["79813.81000000","1.04024000"],["79812.50000000","0.00633000"],["79812.49000000","1.04946000"],["79744.14000000","0.00000000"],["79743.29000000","1.23943000"],["71836.20000000","0.00424000"],["63854.40000000","0.00031000"]],"a":[["79818.01000000","0.64403000"],["79818.02000000","0.00055000"],["79818.63000000","0.05691000"],["79819.15000000","0.31349000"],["79819.29000000","0.02247000"],["79820.49000000","0.06077000"],["79821.69000000","0.00007000"],["79821.70000000","0.03243000"],["79821.72000000","0.00007000"],["79821.73000000","0.06091000"],["79822.34000000","0.00007000"],["79825.18000000","0.00032000"],["79827.78000000","0.00000000"]]}}}
{"rx_ns": 14006891610300, "frame": {"stream":"btcusdt@depth@100ms","data":{"e":"depthUpdate","E":1787651002114,"s":"BTCUSDT","U":99118709247,"u":99118709516,"b":[["79818.00000000","2.10390000"],["79817.38000000","0.06077000"],["79816.98000000","0.00723000"],["79816.78000000","0.00007000"],["79816.77000000","0.04531000"],["79816.76000000","0.06084000"],["79816.15000000","0.00007000"],["79816.14000000","0.06077000"],["79816.00000000","0.02428000"],["79815.55000000","0.00007000"],["79815.54000000","0.06077000"],["79815.09000000","0.00117000"],["79815.08000000","0.02494000"],["79814.91000000","0.00007000"],["79814.90000000","0.06084000"],["79814.52000000","0.00722000"],["79814.29000000","0.00007000"],["79814.28000000","0.06077000"],["79814.01000000","0.00014000"],["79814.00000000","0.02442000"],["79813.84000000","0.00000000"],["79813.83000000","0.06077000"],["79813.82000000","0.01614000"],["79813.81000000","1.04031000"],["79813.76000000","0.03231000"],["79812.50000000","0.00000000"],["79812.49000000","1.04939000"],["79812.39000000","0.00250000"],["79811.90000000","0.00000000"],["79811.39000000","0.00000000"],["79810.84000000","0.00000000"],["79808.71000000","0.00000000"],["79808.30000000","0.02255000"],["79807.81000000","0.37599000"],["79792.00000000","0.72414000"],["79791.00000000","0.00000000"],["79754.93000000","0.00000000"],["79744.14000000","0.02088000"],["79743.29000000","1.22232000"],["75862.00000000","3.46673000"],["73475.18000000","0.00014000"],["71836.20000000","0.00456000"]],"a":[["79818.01000000","0.31372000"],["79818.02000000","0.00048000"],["79818.62000000","0.00000000"],["79818.63000000","0.00021000"],["79818.75000000","0.00007000"],["79819.14000000","0.00000000"],["79819.15000000","0.00021000"],["79819.28000000","0.00007000"],["79819.29000000","0.02254000"],["79820.48000000","0.00000000"],["79820.49000000","0.00014000"],["79820.56000000","0.00021000"],["79820.77000000","0.05092000"],["79821.10000000","0.00000000"],["79821.11000000","0.00014000"],["79821.69000000","0.00000000"],["79821.70000000","0.00000000"],["79821.72000000","0.00000000"],["79821.73000000","0.00000000"],["79821.84000000","0.00007000"],["79821.85000000","0.02694000"],["79822.34000000","0.00000000"],["79822.35000000","0.00000000"],["79822.96000000","0.00007000"],["79822.97000000","0.06077000"],["79823.58000000","0.00007000"],["79823.93000000","0.00007000"],["79823.94000000","0.04007000"],["79824.18000000","0.00400000"],["79824.19000000","0.00000000"],["79824.20000000","0.00007000"],["79824.21000000","0.06098000"],["79824.27000000","0.06084000"],["79825.13000000","0.00000000"],["79825.18000000","0.00000000"],["79825.90000000","0.00000000"],["79826.48000000","0.00000000"],["79826.79000000","0.00000000"],["79827.26000000","0.00000000"],["79827.78000000","0.00032000"],["79827.86000000","0.00000000"],["79827.96000000","0.00000000"],["79828.00000000","1.09929000"],["79828.35000000","0.00250000"],["79828.43000000","0.00027000"],["79829.46000000","0.00000000"],["79829.71000000","0.00000000"],["79831.08000000","0.00000000"],["79831.13000000","0.00400000"],["79831.14000000","0.00000000"],["79831.41000000","0.00000000"],["79831.78000000","0.00000000"],["79832.34000000","0.00000000"],["79832.35000000","0.00000000"],["79832.36000000","0.00000000"],["79833.88000000","0.00400000"],["79833.96000000","0.00626000"],["79833.98000000","0.02000000"],["79843.20000000","0.00000000"],["79845.83000000","0.00000000"],["79846.85000000","0.00000000"],["79850.32000000","0.42980000"],["79858.11000000","0.00000000"],["79893.51000000","1.23946000"],["80217.72000000","0.00007000"]]}}}
{"rx_ns": 14006991551100, "frame": {"stream":"btcusdt@depth@100ms","data":{"e":"depthUpdate","E":1787651002214,"s":"BTCUSDT","U":99118709517,"u":99118709689,"b":[["79818.00000000","1.98612000"],["79817.39000000","0.00000000"],["79817.38000000","0.00014000"],["79816.98000000","0.00730000"],["79816.80000000","0.00007000"],["79816.79000000","0.01711000"],["79816.78000000","0.00000000"],["79816.77000000","0.00014000"],["79816.76000000","0.00021000"],["79816.14000000","0.06091000"],["79816.00000000","0.02428000"],["79815.54000000","0.06091000"],["79815.09000000","0.00117000"],["79815.08000000","0.02480000"],["79814.91000000","0.00007000"],["79814.52000000","0.00708000"],["79814.29000000","0.00007000"],["79814.01000000","0.00014000"],["79814.00000000","0.02428000"],["79813.84000000","0.00007000"],["79813.82000000","0.01600000"],["79813.81000000","1.04017000"],["79813.66000000","0.00000000"],["79813.61000000","0.00000000"],["79812.48000000","0.31331000"],["79812.43000000","0.04003000"],["79808.64000000","0.00000000"],["79744.14000000","0.00000000"],["78620.73000000","0.00030000"],["71836.20000000","0.00440000"],["71836.00000000","0.00000000"],["63854.40000000","0.00000000"]],"a":[["79818.01000000","0.31027000"],["79818.02000000","0.00055000"],["79818.63000000","0.00007000"],["79819.15000000","0.00007000"],["79819.29000000","0.02247000"],["79820.49000000","0.06077000"],["79820.77000000","0.05099000"],["79821.10000000","0.00007000"],["79821.11000000","0.05808000"],["79821.72000000","0.00007000"],["79821.73000000","0.06077000"],["79821.85000000","0.02715000"],["79822.34000000","0.00007000"],["79822.35000000","0.06077000"],["79822.96000000","0.00007000"],["79822.97000000","0.06091000"],["79823.58000000","0.00007000"],["79823.59000000","0.06098000"],["79823.93000000","0.00000000"],["79823.94000000","0.04028000"],["79824.20000000","0.01600000"],["79824.27000000","0.06077000"],["79824.39000000","0.10466000"],["79826.01000000","0.00000000"],["79827.36000000","0.00000000"],["79833.98000000","0.00400000"],["79840.56000000","0.02480000"],["79844.01000000","0.49934000"],["79855.87000000","1.20283000"],["79862.12000000","0.00400000"],["79866.48000000","0.00400000"]]}}}
{"rx_ns": 14007098559000, "frame": {"stream":"btcusdt@depth@100ms","data":{"e":"depthUpdate","E":1787651002314,"s":"BTCUSDT","U":99118709690,"u":99118709777,"b":[["79818.00000000","1.98605000"],["79817.38000000","0.00000000"],["79816.98000000","0.00723000"],["79816.80000000","0.00000000"],["79816.79000000","0.00014000"],["79816.77000000","0.00000000"],["79816.76000000","0.00007000"],["79816.15000000","0.00000000"],["79816.14000000","0.00014000"],["79815.08000000","0.02494000"],["79814.90000000","0.06098000"],["79814.29000000","0.00007000"],["79814.01000000","0.00014000"],["79814.00000000","0.02421000"],["79813.84000000","0.00007000"],["79813.82000000","0.01607000"],["79813.81000000","1.04024000"],["79599.97000000","0.00007000"],["71836.20000000","0.00440000"],["63854.00000000","0.00015000"]],"a":[["79818.01000000","0.30986000"],["79818.02000000","0.00062000"],["79819.14000000","0.00007000"],["79819.15000000","0.06084000"],["79819.29000000","0.02254000"],["79820.48000000","0.00007000"],["79820.49000000","0.06091000"],["79820.77000000","0.05099000"],["79821.11000000","0.05822000"],["79821.72000000","0.00007000"],["79821.73000000","0.06091000"],["79821.84000000","0.00000000"],["79821.85000000","0.02715000"],["79822.34000000","0.00007000"],["79822.96000000","0.00000000"],["79822.97000000","0.06077000"],["79823.58000000","0.00000000"],["79823.59000000","0.06084000"],["79823.94000000","0.04014000"],["79824.93000000","0.18666000"],["79827.45000000","0.00048000"]]}}}
{"rx_ns": 14007193112100, "frame": {"stream":"btcusdt@depth@100ms","data":{"e":"depthUpdate","E":1787651002414,"s":"BTCUSDT","U":99118709778,"u":99118709808,"b":[["79818.00000000","1.98589000"],["79816.98000000","0.00709000"],["79816.79000000","0.00000000"],["79816.76000000","0.00000000"],["79816.14000000","0.00000000"],["79814.52000000","0.00722000"],["79802.80000000","0.00007000"],["71836.20000000","0.00440000"]],"a":[["79818.01000000","0.31000000"],["79819.15000000","0.06098000"],["79821.85000000","0.02701000"],["79834.74000000","0.00007000"],["79910.15000000","0.00000000"]]}}}
{"rx_ns": 14007298312600, "frame": {"stream":"btcusdt@depth@100ms","data":{"e":"depthUpdate","E":1787651002514,"s":"BTCUSDT","U":99118709809,"u":99118709818,"b":[["71836.20000000","0.00456000"],["63854.40000000","0.00031000"]],"a":[["79818.01000000","0.31048000"],["79819.57000000","0.00066000"],["79819.61000000","0.00330000"],["79827.45000000","0.00000000"],["79864.30000000","0.00400000"],["79866.48000000","0.00000000"]]}}}
{"rx_ns": 14007394181700, "frame": {"stream":"btcusdt@depth@100ms","data":{"e":"depthUpdate","E":1787651002614,"s":"BTCUSDT","U":99118709819,"u":99118709831,"b":[["79818.00000000","1.98597000"],["79784.39000000","0.00400000"],["79784.04000000","0.00007000"],["71836.20000000","0.00432000"],["71836.19000000","0.00008000"],["63854.40000000","0.00000000"]],"a":[["79818.01000000","0.30959000"],["79818.02000000","0.00069000"],["79856.00000000","1.17283000"],["79864.30000000","0.00000000"]]}}}
{"rx_ns": 14007493191200, "frame": {"stream":"btcusdt@depth@100ms","data":{"e":"depthUpdate","E":1787651002714,"s":"BTCUSDT","U":99118709832,"u":99118709874,"b":[["79818.00000000","1.97971000"],["79816.00000000","0.02435000"],["79815.56000000","0.00626000"],["79815.55000000","0.00000000"],["79815.54000000","0.00014000"],["79813.82000000","0.01607000"],["79813.81000000","1.04024000"],["79812.50000000","0.00007000"],["79746.05000000","0.00000000"],["79678.28000000","0.00000000"],["73475.18000000","0.00000000"],["71836.20000000","0.00432000"]],"a":[["79818.01000000","0.44150000"],["79818.62000000","0.00007000"],["79818.63000000","0.06084000"],["79820.76000000","0.00007000"],["79821.10000000","0.00007000"],["79821.72000000","0.00007000"],["79822.34000000","0.00000000"],["79822.97000000","0.06084000"],["79823.40000000","0.04568000"],["79824.93000000","0.00000000"]]}}}
{"rx_ns": 14007591018300, "frame": {"stream":"btcusdt@depth@100ms","data":{"e":"depthUpdate","E":1787651002814,"s":"BTCUSDT","U":99118709875,"u":99118709900,"b":[["79816.00000000","0.02428000"],["79815.54000000","0.00000000"],["79795.00000000","0.70000000"],["79792.00000000","0.02414000"],["71836.20000000","0.00432000"],["63854.40000000","0.00000000"]],"a":[["79818.01000000","0.44171000"],["79818.63000000","0.06098000"],["79821.73000000","0.06077000"],["79821.85000000","0.02708000"],["79822.33000000","0.19061000"],["79822.97000000","0.06077000"],["79823.40000000","0.00000000"]]}}}
{"rx_ns": 14007691297500, "frame": {"stream":"btcusdt@depth@100ms","data":{"e":"depthUpdate","E":1787651002914,"s":"BTCUSDT","U":99118709901,"u":99118709913,"b":[["79818.00000000","1.97923000"],["79814.91000000","0.00000000"],["79814.90000000","0.00021000"],["79813.83000000","0.06084000"],["79808.73000000","0.02848000"],["71836.20000000","0.00432000"],["63854.40000000","0.00000000"]],"a":[["81015.29000000","0.00030000"]]}}}
{"rx_ns": 14007796325200, "frame": {"stream":"btcusdt@depth20","data":{"lastUpdateId":99118709936,"bids":[["79818.00000000","1.97923000"],["79817.99000000","0.00027000"],["79817.98000000","0.00013000"],["79817.29000000","0.00007000"],["79816.98000000","0.00709000"],["79816.90000000","0.00007000"],["79816.66000000","0.00007000"],["79816.45000000","0.00076000"],["79816.44000000","0.00069000"],["79816.34000000","0.00400000"],["79816.31000000","0.00007000"],["79816.30000000","0.00007000"],["79816.01000000","0.00007000"],["79816.00000000","0.02428000"],["79815.98000000","0.00007000"],["79815.56000000","0.00640000"],["79815.53000000","0.00953000"],["79815.48000000","0.00134000"],["79815.39000000","0.00400000"],["79815.09000000","0.00117000"]],"asks":[["79818.01000000","0.43849000"],["79818.02000000","0.00069000"],["79818.03000000","0.00013000"],["79818.54000000","0.00014000"],["79818.62000000","0.00007000"],["79818.63000000","0.06098000"],["79818.75000000","0.00007000"],["79818.94000000","0.00007000"],["79819.14000000","0.00007000"],["79819.15000000","0.06098000"],["79819.16000000","0.33843000"],["79819.22000000","0.00202000"],["79819.28000000","0.00007000"],["79819.29000000","0.02254000"],["79819.57000000","0.00066000"],["79819.61000000","0.00330000"],["79819.74000000","0.00007000"],["79820.48000000","0.00007000"],["79820.49000000","0.06091000"],["79820.56000000","0.00021000"]]}}}
{"rx_ns": 14007796630800, "frame": {"stream":"btcusdt@depth@100ms","data":{"e":"depthUpdate","E":1787651003014,"s":"BTCUSDT","U":99118709914,"u":99118709936,"b":[["79815.56000000","0.00640000"],["79815.08000000","0.02494000"],["79814.90000000","0.00007000"],["71836.20000000","0.00448000"],["71836.19000000","0.00000000"],["63854.40000000","0.00031000"]],"a":[["79818.01000000","0.43849000"],["79848.84000000","0.00000000"],["79852.92000000","0.00400000"],["79888.86000000","0.00000000"],["79892.85000000","0.00400000"],["79920.71000000","0.00000000"],["79924.79000000","0.00400000"],["79968.62000000","0.00000000"],["79972.70000000","0.00400000"],["80040.48000000","0.00000000"],["80044.57000000","0.00400000"]]}}}
{"rx_ns": 14007904133300, "frame": {"stream":"btcusdt@depth@100ms","data":{"e":"depthUpdate","E":1787651003114,"s":"BTCUSDT","U":99118709937,"u":99118709987,"b":[["79818.00000000","2.02320000"],["79816.14000000","0.06077000"],["79815.54000000","0.06077000"],["79814.90000000","0.06084000"],["79814.28000000","0.06091000"],["79814.00000000","0.02435000"],["79812.50000000","0.00007000"],["79744.14000000","0.02088000"],["71836.20000000","0.00432000"]],"a":[["79818.01000000","0.29109000"],["79818.63000000","0.00021000"],["79819.15000000","0.00021000"],["79820.49000000","0.00014000"],["79821.10000000","0.05602000"],["79821.11000000","0.00014000"],["79821.72000000","0.06084000"],["79821.73000000","0.00000000"],["79822.32000000","0.06077000"],["79822.35000000","0.00000000"],["79822.96000000","0.06077000"],["79822.97000000","0.00000000"],["79824.26000000","0.06077000"],["79824.27000000","0.00000000"],["79840.56000000","0.00000000"],["79855.87000000","0.00000000"]]}}}
{"rx_ns": 14007993100900, "frame": {"stream":"btcusdt@depth@100ms","data":{"e":"depthUpdate","E":1787651003214,"s":"BTCUSDT","U":99118709988,"u":99118710130,"b":[["79818.00000000","2.02382000"],["79816.98000000","0.00716000"],["79816.16000000","0.00000000"],["79816.15000000","0.00000000"],["79816.14000000","0.00014000"],["79815.56000000","0.00647000"],["79815.55000000","0.00007000"],["79815.54000000","0.00014000"],["79815.08000000","0.02494000"],["79814.91000000","0.00007000"],["79814.90000000","0.00007000"],["79814.52000000","0.00708000"],["79814.28000000","0.06077000"],["79814.01000000","0.00014000"],["79814.00000000","0.02421000"],["79813.84000000","0.00007000"],["79813.83000000","0.06077000"],["79813.82000000","0.01607000"],["79813.81000000","1.04024000"],["79812.50000000","0.00000000"],["79808.73000000","0.02800000"],["79744.14000000","0.00000000"],["78620.73000000","0.00030000"],["71836.20000000","0.00448000"],["63854.40000000","0.00000000"]],"a":[["79818.01000000","0.51913000"],["79818.02000000","0.00062000"],["79818.62000000","0.00007000"],["79818.63000000","0.06084000"],["79819.14000000","0.00007000"],["79819.15000000","0.06084000"],["79819.29000000","0.02254000"],["79820.48000000","0.00007000"],["79820.49000000","0.06077000"],["79820.77000000","0.05092000"],["79821.09000000","0.00007000"],["79821.10000000","0.05616000"],["79821.11000000","0.00000000"],["79821.71000000","0.00007000"],["79821.72000000","0.06091000"],["79821.84000000","0.00000000"],["79821.85000000","0.02715000"],["79822.31000000","0.00007000"],["79822.32000000","0.06091000"],["79822.33000000","0.19068000"],["79824.21000000","0.06091000"],["79833.21000000","0.00000000"],["79841.45000000","0.02480000"],["79856.46000000","1.20284000"]]}}}
{"rx_ns": 14008091717800, "frame": {"stream":"btcusdt@depth@100ms","data":{"e":"depthUpdate","E":1787651003314,"s":"BTCUSDT","U":99118710131,"u":99118710229,"b":[["79818.00000000","2.02335000"],["79816.98000000","0.00709000"],["79816.14000000","0.00000000"],["79815.56000000","0.00640000"],["79815.55000000","0.00000000"],["79815.54000000","0.00000000"],["79815.08000000","0.02494000"],["79814.91000000","0.00000000"],["79814.52000000","0.00715000"],["79814.29000000","0.00000000"],["79814.28000000","0.00014000"],["79814.00000000","0.02414000"],["79813.84000000","0.00000000"],["79813.83000000","0.00007000"],["79813.82000000","0.01607000"],["79813.81000000","1.04024000"],["79812.99000000","0.00633000"],["79812.50000000","0.00007000"],["79812.49000000","1.04946000"],["79812.48000000","0.31338000"],["79811.39000000","0.00007000"],["79808.73000000","0.02847000"],["71836.20000000","0.00432000"],["71836.00000000","0.00000000"],["63854.00000000","0.00015000"]],"a":[["79818.01000000","0.64833000"],["79818.63000000","0.06098000"],["79819.15000000","0.06098000"],["79819.29000000","0.02254000"],["79820.49000000","0.06091000"],["79820.76000000","0.00007000"],["79821.09000000","0.00007000"],["79821.71000000","0.00007000"],["79821.72000000","0.06077000"],["79821.85000000","0.02701000"],["79822.31000000","0.00000000"],["79822.32000000","0.06077000"],["79829.91000000","0.00400000"],["79833.88000000","0.00000000"]]}}}
{"rx_ns": 14008191458000, "frame": {"stream":"btcusdt@depth@100ms","data":{"e":"depthUpdate","E":1787651003414,"s":"BTCUSDT","U":99118710230,"u":99118710249,"b":[["79818.00000000","2.02335000"],["79814.52000000","0.00715000"],["79814.28000000","0.00000000"],["79814.00000000","0.02428000"],["79802.80000000","0.00007000"],["79741.21000000","0.00000000"],["71836.20000000","0.00448000"]],"a":[["79825.99000000","1.04967000"],["79828.43000000","0.00000000"],["79834.74000000","0.00007000"],["79910.15000000","1.95361000"],["79945.71000000","0.00000000"]]}}}
{"rx_ns": 14008291114900, "frame": {"stream":"btcusdt@depth@100ms","data":{"e":"depthUpdate","E":1787651003514,"s":"BTCUSDT","U":99118710250,"u":99118710261,"b":[["79818.00000000","2.02327000"],["79813.82000000","0.01621000"],["79744.14000000","0.02088000"],["71836.20000000","0.00432000"],["63854.40000000","0.00031000"]],"a":[["79818.01000000","0.64819000"],["79833.67000000","0.00000000"]]}}}
{"rx_ns": 14008391157000, "frame": {"stream":"btcusdt@depth@100ms","data":{"e":"depthUpdate","E":1787651003614,"s":"BTCUSDT","U":99118710262,"u":99118710275,"b":[["79818.00000000","2.02319000"],["79744.14000000","0.00000000"],["71836.20000000","0.00432000"],["63854.40000000","0.00000000"],["63854.00000000","0.00215000"]],"a":[["79818.01000000","0.44562000"],["79818.02000000","0.00055000"],["79819.57000000","0.00000000"],["79819.61000000","0.00000000"],["79985.68000000","0.00000000"]]}}}
{"rx_ns": 14008495926300, "frame": {"stream":"btcusdt@depth@100ms","data":{"e":"depthUpdate","E":1787651003714,"s":"BTCUSDT","U":99118710276,"u":99118710285,"b":[["79818.00000000","2.02367000"],["79808.73000000","0.02800000"],["71836.20000000","0.00432000"],["63854.00000000","0.00015000"]],"a":[["79818.01000000","0.49549000"],["79825.99000000","1.04947000"],["79827.11000000","0.00021000"]]}}}
{"rx_ns": 14008591416400, "frame": {"stream":"btcusdt@depth@100ms","data":{"e":"depthUpdate","E":1787651003814,"s":"BTCUSDT","U":99118710286,"u":99118710297,"b":[["79818.00000000","2.02367000"],["71836.20000000","0.00432000"],["63854.40000000","0.00000000"],["63854.00000000","0.00015000"]],"a":[["79818.01000000","0.46909000"],["79825.82000000","0.00903000"],["79833.85000000","0.00000000"]]}}}
{"rx_ns": 14008700804100, "frame": {"stream":"btcusdt@depth@100ms","data":{"e":"depthUpdate","E":1787651003914,"s":"BTCUSDT","U":99118710298,"u":99118710308,"b":[["79818.00000000","2.02375000"],["71836.20000000","0.00400000"],["63854.40000000","0.00000000"]],"a":[["79818.01000000","0.67172000"],["79821.12000000","0.04130000"],["79822.33000000","0.00007000"],["81015.29000000","0.00030000"]]}}}
{"rx_ns": 14008794272400, "frame": {"stream":"btcusdt@depth20","data":{"lastUpdateId":99118710330,"bids":[["79818.00000000","2.02139000"],["79817.99000000","0.00027000"],["79817.98000000","0.00013000"],["79817.29000000","0.00007000"],["79816.98000000","0.00709000"],["79816.90000000","0.00007000"],["79816.66000000","0.00007000"],["79816.45000000","0.00076000"],["79816.44000000","0.00069000"],["79816.34000000","0.00400000"],["79816.31000000","0.00007000"],["79816.30000000","0.00007000"],["79816.01000000","0.00007000"],["79816.00000000","0.02428000"],["79815.98000000","0.00007000"],["79815.56000000","0.00640000"],["79815.53000000","0.00953000"],["79815.48000000","0.00134000"],["79815.39000000","0.00400000"],["79815.09000000","0.00117000"]],"asks":[["79818.01000000","0.67165000"],["79818.02000000","0.00055000"],["79818.03000000","0.00013000"],["79818.54000000","0.00014000"],["79818.62000000","0.00007000"],["79818.63000000","0.06098000"],["79818.75000000","0.00007000"],["79818.94000000","0.00007000"],["79819.14000000","0.00007000"],["79819.15000000","0.06098000"],["79819.16000000","0.33843000"],["79819.22000000","0.00202000"],["79819.28000000","0.00007000"],["79819.29000000","0.02254000"],["79819.74000000","0.00007000"],["79820.48000000","0.00007000"],["79820.49000000","0.06091000"],["79820.56000000","0.00021000"],["79820.57000000","0.02694000"],["79820.76000000","0.00007000"]]}}}
{"rx_ns": 14008794423900, "frame": {"stream":"btcusdt@depth@100ms","data":{"e":"depthUpdate","E":1787651004014,"s":"BTCUSDT","U":99118710309,"u":99118710330,"b":[["79818.00000000","2.02139000"],["79817.99000000","0.00027000"],["79808.54000000","0.00047000"],["79808.42000000","0.00000000"],["71836.20000000","0.00432000"],["63854.40000000","0.00031000"]],"a":[["79818.01000000","0.67165000"],["79821.10000000","0.05623000"],["79821.11000000","0.00007000"],["79826.81000000","0.00707000"],["79827.35000000","0.00400000"],["79831.13000000","0.00000000"]]}}}
{"rx_ns": 14008891946200, "frame": {"stream":"btcusdt@depth@100ms","data":{"e":"depthUpdate","E":1787651004115,"s":"BTCUSDT","U":99118710331,"u":99118710337,"b":[["79818.00000000","2.02139000"],["79808.42000000","0.00190000"],["71836.20000000","0.00416000"]],"a":[["79834.47000000","0.12535000"]]}}}
{"rx_ns": 14008991507300, "frame": {"stream":"btcusdt@depth@100ms","data":{"e":"depthUpdate","E":1787651004214,"s":"BTCUSDT","U":99118710338,"u":99118710448,"b":[["79818.00000000","1.85843000"],["79817.99000000","0.00076000"],["79815.56000000","0.00014000"],["79815.39000000","0.00000000"],["79813.82000000","0.01628000"],["79813.81000000","0.44437000"],["79813.80000000","0.00000000"],["79813.77000000","0.00007000"],["79813.76000000","0.03238000"],["79813.05000000","0.00000000"],["79813.00000000","0.00626000"],["79812.43000000","0.04010000"],["79812.39000000","0.00000000"],["79811.92000000","0.00007000"],["79811.84000000","0.00400000"],["79810.84000000","0.00250000"],["79807.81000000","0.00000000"],["79755.35000000","0.40972000"],["79754.88000000","1.24161000"],["78620.73000000","0.00030000"],["71836.20000000","0.00416000"],["63854.40000000","0.00000000"]],"a":[["79818.01000000","1.00666000"],["79818.75000000","0.00014000"],["79819.15000000","0.33288000"],["79819.28000000","0.00000000"],["79819.29000000","0.02268000"],["79819.80000000","0.00007000"],["79819.81000000","0.18200000"],["79819.86000000","0.00007000"],["79819.87000000","0.06077000"],["79820.56000000","0.00014000"],["79821.09000000","0.00007000"],["79821.11000000","0.00000000"],["79821.12000000","0.00000000"],["79821.71000000","0.00007000"],["79822.31000000","0.00000000"],["79824.17000000","0.06077000"],["79824.18000000","1.35652000"],["79824.19000000","1.87677000"],["79824.21000000","0.00014000"],["79824.26000000","0.00000000"],["79824.28000000","0.00000000"],["79824.32000000","0.00031000"],["79824.38000000","0.00017000"],["79824.39000000","0.10459000"],["79826.79000000","0.00250000"],["79827.11000000","0.00000000"],["79827.78000000","0.00000000"],["79827.79000000","0.00588000"],["79828.35000000","0.00000000"],["79834.46000000","0.12535000"],["79834.47000000","0.00000000"],["79839.27000000","0.33826000"],["79859.95000000","0.00000000"],["79862.12000000","0.00000000"],["80217.72000000","0.00000000"]]}}}
{"rx_ns": 14009091260100, "frame": {"stream":"btcusdt@depth@100ms","data":{"e":"depthUpdate","E":1787651004314,"s":"BTCUSDT","U":99118710449,"u":99118710535,"b":[["79818.00000000","1.85843000"],["79817.99000000","0.00076000"],["79816.00000000","0.02421000"],["79815.56000000","0.00000000"],["79813.83000000","0.00000000"],["79813.82000000","0.00028000"],["79813.81000000","0.42896000"],["79812.99000000","0.00007000"],["79812.25000000","0.01242000"],["79811.28000000","0.00626000"],["79810.84000000","0.00000000"],["79809.57000000","0.00250000"],["79808.33000000","0.01600000"],["79808.24000000","0.00048000"],["79795.00000000","0.00000000"],["71836.00000000","0.00000000"],["63854.00000000","0.00015000"]],"a":[["79818.01000000","0.99058000"],["79818.02000000","0.00069000"],["79818.63000000","0.06105000"],["79818.98000000","0.00007000"],["79818.99000000","0.06534000"],["79819.29000000","0.02268000"],["79819.80000000","0.00000000"],["79819.81000000","0.00014000"],["79819.87000000","0.06091000"],["79820.77000000","0.05078000"],["79821.10000000","0.05602000"],["79824.21000000","0.00007000"],["79825.53000000","0.00250000"],["79825.74000000","0.00400000"],["79826.79000000","0.00000000"],["79829.91000000","0.00000000"],["79848.94000000","0.00400000"],["79852.92000000","0.00000000"],["79859.78000000","0.00573000"],["79877.62000000","0.00000000"],["79888.87000000","0.00400000"],["79892.85000000","0.00000000"],["79920.81000000","0.00400000"],["79924.79000000","0.00000000"],["79968.72000000","0.00400000"],["79972.70000000","0.00000000"],["80040.58000000","0.00400000"],["80044.57000000","0.00000000"]]}}}
{"rx_ns": 14009191160500, "frame": {"stream":"btcusdt@depth@100ms","data":{"e":"depthUpdate","E":1787651004414,"s":"BTCUSDT","U":99118710536,"u":99118710587,"b":[["79814.00000000","0.02428000"],["79813.82000000","0.00014000"],["79813.76000000","0.03252000"],["79809.57000000","0.00000000"],["79808.35000000","0.00250000"],["79802.80000000","0.00007000"],["79776.18000000","0.00007000"],["79690.29000000","0.00034000"],["71836.20000000","0.00416000"]],"a":[["79818.01000000","1.12451000"],["79818.63000000","0.06105000"],["79818.98000000","0.00000000"],["79818.99000000","0.00014000"],["79819.29000000","0.02261000"],["79819.81000000","0.00000000"],["79822.31000000","0.00007000"],["79824.30000000","0.00250000"],["79825.53000000","0.00000000"],["79834.74000000","0.00007000"],["79848.94000000","0.00400000"],["79888.87000000","0.00400000"],["79920.81000000","0.00400000"],["79968.72000000","0.00400000"],["80040.58000000","0.00400000"]]}}}
{"rx_ns": 14009293342900, "frame": {"stream":"btcusdt@depth@100ms","data":{"e":"depthUpdate","E":1787651004514,"s":"BTCUSDT","U":99118710588,"u":99118710623,"b":[["79818.00000000","1.85836000"],["79632.50000000","0.00000000"],["79630.91000000","0.02284000"],["71836.20000000","0.00440000"],["63854.40000000","0.00031000"]],"a":[["79818.01000000","1.13746000"],["79818.02000000","0.00062000"],["79818.63000000","0.06098000"],["79818.99000000","0.00000000"],["79820.77000000","0.05092000"],["79823.94000000","0.04021000"],["79824.79000000","0.00689000"],["79834.46000000","0.00000000"],["79848.94000000","0.00000000"],["79888.87000000","0.00000000"],["79920.81000000","0.00000000"],["79920.82000000","0.00400000"],["79968.72000000","0.00000000"],["79992.85000000","0.00588000"],["80040.58000000","0.00000000"],["80130.27000000","0.00000000"],["80346.96000000","0.00000000"],["80427.41000000","0.00000000"]]}}}
{"rx_ns": 14009392935500, "frame": {"stream":"btcusdt@depth@100ms","data":{"e":"depthUpdate","E":1787651004614,"s":"BTCUSDT","U":99118710624,"u":99118710638,"b":[["79650.44000000","0.00034000"],["71836.20000000","0.00424000"],["63854.40000000","0.00000000"]],"a":[["79818.01000000","1.14588000"],["79818.51000000","0.00066000"],["79818.55000000","0.00330000"],["79823.94000000","0.00021000"]]}}}
{"rx_ns": 14009491378000, "frame": {"stream":"btcusdt@depth@100ms","data":{"e":"depthUpdate","E":1787651004714,"s":"BTCUSDT","U":99118710639,"u":99118710698,"b":[["79818.00000000","1.69691000"],["79815.98000000","0.00071000"],["79811.84000000","0.00000000"],["79811.22000000","0.00000000"],["79811.08000000","0.00000000"],["79810.98000000","0.00000000"],["79808.34000000","0.00800000"],["79808.33000000","0.00400000"],["71836.20000000","0.00440000"]],"a":[["79818.01000000","1.02700000"],["79822.31000000","0.00007000"],["79846.91000000","0.62635000"],["79888.88000000","0.00400000"],["79893.51000000","0.00000000"]]}}}
{"rx_ns": 14009591210700, "frame": {"stream":"btcusdt@depth@100ms","data":{"e":"depthUpdate","E":1787651004814,"s":"BTCUSDT","U":99118710699,"u":99118710706,"b":[["71836.20000000","0.00424000"],["63854.40000000","0.00000000"]],"a":[["79818.01000000","1.22363000"]]}}}
{"rx_ns": 14009691924200, "frame": {"stream":"btcusdt@depth@100ms","data":{"e":"depthUpdate","E":1787651004915,"s":"BTCUSDT","U":99118710707,"u":99118710723,"b":[["79752.14000000","0.03132000"],["79744.14000000","0.02088000"],["71836.20000000","0.00440000"],["63854.40000000","0.00000000"]],"a":[["79818.01000000","1.22370000"],["79818.02000000","0.00069000"],["79827.64000000","0.00000000"],["79827.79000000","0.00400000"],["79833.34000000","0.00000000"],["79833.36000000","0.00000000"],["80040.59000000","0.00400000"],["81015.29000000","0.00030000"]]}}}
{"rx_ns": 14009791128900, "frame": {"stream":"btcusdt@depth20","data":{"lastUpdateId":99118710734,"bids":[["79818.00000000","1.69691000"],["79817.99000000","0.00076000"],["79817.98000000","0.00013000"],["79817.29000000","0.00007000"],["79816.98000000","0.00709000"],["79816.90000000","0.00007000"],["79816.66000000","0.00007000"],["79816.45000000","0.00076000"],["79816.44000000","0.00069000"],["79816.34000000","0.00400000"],["79816.31000000","0.00007000"],["79816.30000000","0.00007000"],["79816.01000000","0.00007000"],["79816.00000000","0.02421000"],["79815.98000000","0.00071000"],["79815.53000000","0.00953000"],["79815.48000000","0.00134000"],["79815.09000000","0.00117000"],["79815.08000000","0.02494000"],["79814.90000000","0.00007000"]],"asks":[["79818.01000000","1.22383000"],["79818.02000000","0.00069000"],["79818.03000000","0.00013000"],["79818.51000000","0.00066000"],["79818.54000000","0.00014000"],["79818.55000000","0.00330000"],["79818.62000000","0.00007000"],["79818.63000000","0.06098000"],["79818.75000000","0.00014000"],["79818.94000000","0.00007000"],["79819.14000000","0.00007000"],["79819.15000000","0.33288000"],["79819.16000000","0.33843000"],["79819.22000000","0.00202000"],["79819.29000000","0.02261000"],["79819.74000000","0.00007000"],["79819.86000000","0.00007000"],["79819.87000000","0.06091000"],["79820.48000000","0.00007000"],["79820.49000000","0.06091000"]]}}}
{"rx_ns": 14009791235000, "frame": {"stream":"btcusdt@depth@100ms","data":{"e":"depthUpdate","E":1787651005014,"s":"BTCUSDT","U":99118710724,"u":99118710734,"b":[["79788.01000000","0.25521000"],["79787.00000000","0.70000000"],["71836.20000000","0.00424000"],["63854.40000000","0.00031000"]],"a":[["79818.01000000","1.22383000"],["79827.62000000","0.00188000"]]}}}
{"rx_ns": 14009893171000, "frame": {"stream":"btcusdt@depth@100ms","data":{"e":"depthUpdate","E":1787651005114,"s":"BTCUSDT","U":99118710735,"u":99118710751,"b":[["79814.88000000","0.00007000"],["79808.35000000","0.00000000"],["79807.53000000","0.00250000"],["79752.14000000","0.00000000"],["79744.14000000","0.00000000"],["71836.20000000","0.00440000"],["71836.00000000","0.00000000"]],"a":[["79818.01000000","1.22575000"],["79823.48000000","0.00250000"],["79824.30000000","0.00000000"],["79827.62000000","0.00000000"],["79848.95000000","0.00400000"]]}}}
{"rx_ns": 14009990973900, "frame": {"stream":"btcusdt@depth@100ms","data":{"e":"depthUpdate","E":1787651005214,"s":"BTCUSDT","U":99118710752,"u":99118710763,"b":[["79735.93000000","0.62625000"],["79593.65000000","0.00000000"],["79593.04000000","0.00771000"],["78620.73000000","0.00030000"],["71836.20000000","0.00424000"],["63854.40000000","0.00000000"]],"a":[["79818.01000000","1.22383000"],["79827.63000000","0.00188000"],["79833.30000000","0.00000000"]]}}}
{"rx_ns": 14010091183200, "frame": {"stream":"btcusdt@depth@100ms","data":{"e":"depthUpdate","E":1787651005314,"s":"BTCUSDT","U":99118710764,"u":99118710777,"b":[["71836.20000000","0.00440000"],["71836.00000000","0.00010000"],["63854.00000000","0.00015000"]],"a":[["79825.62000000","0.00400000"],["79833.30000000","0.00000000"],["79848.95000000","0.00000000"],["79859.94000000","0.00000000"],["79968.73000000","0.00400000"]]}}}
{"rx_ns": 14010193533200, "frame": {"stream":"btcusdt@depth@100ms","data":{"e":"depthUpdate","E":1787651005414,"s":"BTCUSDT","U":99118710778,"u":99118710803,"b":[["79818.00000000","1.89941000"],["79802.80000000","0.00000000"],["71836.20000000","0.00416000"],["71836.19000000","0.00008000"],["71836.00000000","0.00000000"]],"a":[["79818.01000000","1.22453000"],["79818.02000000","0.00062000"],["79819.86000000","0.00000000"],["79819.87000000","0.00014000"],["79822.95000000","0.00007000"],["79827.63000000","0.00188000"],["79833.62000000","0.00000000"],["79834.74000000","0.00000000"]]}}}
{"rx_ns": 14010291421200, "frame": {"stream":"btcusdt@depth@100ms","data":{"e":"depthUpdate","E":1787651005514,"s":"BTCUSDT","U":99118710804,"u":99118710821,"b":[["79818.00000000","1.89835000"],["79802.80000000","0.00007000"],["71836.20000000","0.00416000"],["63854.40000000","0.00031000"]],"a":[["79818.01000000","1.22428000"],["79819.29000000","0.02254000"],["79819.87000000","0.00000000"],["79821.10000000","0.05616000"],["79834.74000000","0.00007000"],["79848.87000000","0.00000000"]]}}}
{"rx_ns": 14010391309100, "frame": {"stream":"btcusdt@depth@100ms","data":{"e":"depthUpdate","E":1787651005614,"s":"BTCUSDT","U":99118710822,"u":99118710867,"b":[["79818.00000000","1.36839000"],["79816.98000000","0.00014000"],["79813.00000000","0.00000000"],["79812.49000000","0.00007000"],["79811.28000000","0.00000000"],["79809.17000000","0.00626000"],["79808.55000000","0.00626000"],["79808.31000000","0.00000000"],["79807.93000000","0.00000000"],["79807.53000000","0.00000000"],["79806.10000000","0.00250000"],["79805.36000000","0.00000000"],["79800.63000000","0.00000000"],["79796.98000000","0.29813000"],["79795.13000000","0.00000000"],["79791.23000000","0.62658000"],["79788.00000000","0.72400000"],["79787.00000000","0.00000000"],["79784.40000000","0.00000000"],["79764.42000000","0.00000000"],["79744.14000000","0.02088000"],["79593.65000000","0.00771000"],["79593.04000000","0.00000000"],["71836.20000000","0.00416000"],["63854.40000000","0.00000000"]],"a":[["79818.01000000","1.24906000"],["79818.02000000","0.00048000"],["79818.51000000","0.00000000"],["79818.55000000","0.00000000"],["79819.87000000","0.06077000"],["79821.08000000","0.00014000"],["79821.09000000","0.00027000"],["79821.71000000","0.00000000"],["79822.05000000","0.00250000"],["79822.31000000","0.00000000"],["79822.94000000","0.00626000"],["79822.95000000","0.00000000"],["79823.48000000","0.00000000"],["79824.16000000","0.19019000"],["79824.32000000","0.00007000"],["79824.38000000","0.00000000"],["79833.12000000","0.12536000"],["79833.96000000","0.00000000"],["79834.86000000","0.00000000"],["79839.65000000","0.00000000"],["79854.46000000","0.30000000"],["79879.28000000","0.00000000"],["79899.25000000","0.00000000"]]}}}
{"rx_ns": 14010491215500, "frame": {"stream":"btcusdt@depth@100ms","data":{"e":"depthUpdate","E":1787651005714,"s":"BTCUSDT","U":99118710868,"u":99118710979,"b":[["79818.00000000","0.96831000"],["79817.99000000","0.00076000"],["79816.98000000","0.00000000"],["79816.34000000","0.00000000"],["79814.77000000","0.00000000"],["79813.82000000","0.00007000"],["79813.81000000","0.00014000"],["79813.76000000","0.00021000"],["79812.50000000","0.00000000"],["79812.44000000","0.00007000"],["79812.01000000","0.00007000"],["79812.00000000","0.02407000"],["79811.38000000","0.42965000"],["79808.34000000","0.00000000"],["79808.33000000","0.00000000"],["79806.71000000","0.14657000"],["79806.70000000","0.00000000"],["79806.10000000","0.00000000"],["79804.46000000","0.01200000"],["79795.87000000","0.00000000"],["79793.29000000","0.04586000"],["79788.01000000","0.24037000"],["79785.51000000","0.33849000"],["79781.34000000","0.00400000"],["79777.06000000","0.03624000"],["79744.14000000","0.00000000"],["71836.20000000","0.00416000"],["71836.19000000","0.00000000"],["71836.00000000","0.00000000"]],"a":[["79818.01000000","1.30198000"],["79818.02000000","0.00048000"],["79819.29000000","0.02261000"],["79819.86000000","0.00400000"],["79819.87000000","0.06091000"],["79821.10000000","0.05602000"],["79822.00000000","0.00400000"],["79822.05000000","0.00000000"],["79822.32000000","0.06084000"],["79823.59000000","0.06091000"],["79824.14000000","0.00400000"],["79825.74000000","0.00000000"],["79827.63000000","0.00000000"],["79833.12000000","0.00000000"],["79840.10000000","0.33826000"],["79848.88000000","0.00400000"],["79851.96000000","0.00400000"],["79852.08000000","0.00000000"],["79853.70000000","0.00000000"],["79856.00000000","1.16883000"],["79857.76000000","0.00000000"]]}}}
{"rx_ns": 14010605195600, "frame": {"stream":"btcusdt@depth@100ms","data":{"e":"depthUpdate","E":1787651005821,"s":"BTCUSDT","U":99118710980,"u":99118711287,"b":[["79818.00000000","0.42192000"],["79817.99000000","0.00076000"],["79816.28000000","0.00000000"],["79816.27000000","0.00000000"],["79816.00000000","0.02421000"],["79815.53000000","0.00035000"],["79815.36000000","0.00000000"],["79815.08000000","0.02494000"],["79814.75000000","0.00000000"],["79814.53000000","0.00000000"],["79814.52000000","0.00014000"],["79814.41000000","0.00000000"],["79814.00000000","0.02428000"],["79813.82000000","0.00000000"],["79813.81000000","0.00000000"],["79813.78000000","0.00007000"],["79813.77000000","0.02000000"],["79813.76000000","0.00007000"],["79813.70000000","0.00307000"],["79813.43000000","0.00000000"],["79813.42000000","0.00000000"],["79812.77000000","0.00000000"],["79812.76000000","0.00000000"],["79812.48000000","0.31352000"],["79812.44000000","0.00000000"],["79812.43000000","0.00021000"],["79812.01000000","0.00007000"],["79811.39000000","0.00000000"],["79811.38000000","0.01484000"],["79811.37000000","0.00000000"],["79811.28000000","0.00000000"],["79811.27000000","0.00000000"],["79811.24000000","0.00000000"],["79811.01000000","0.00007000"],["79809.27000000","0.07000000"],["79809.17000000","0.00000000"],["79808.73000000","0.00000000"],["79808.65000000","0.00000000"],["79808.55000000","0.00000000"],["79808.32000000","0.00000000"],["79807.86000000","0.00000000"],["79807.85000000","0.00000000"],["79807.83000000","0.00000000"],["79807.80000000","0.00070000"],["79807.22000000","0.00000000"],["79807.21000000","0.00000000"],["79806.85000000","0.05509000"],["79806.72000000","0.05668000"],["79806.02000000","0.06077000"],["79805.54000000","0.00000000"],["79805.40000000","0.00626000"],["79805.08000000","0.06077000"],["79805.07000000","0.08000000"],["79805.00000000","0.00626000"],["79804.46000000","0.00000000"],["79804.36000000","0.05709000"],["79804.32000000","0.00000000"],["79804.31000000","0.00000000"],["79804.24000000","0.00000000"],["79804.23000000","0.00008000"],["79803.93000000","0.06077000"],["79803.85000000","0.00000000"],["79803.83000000","0.00000000"],["79803.69000000","0.00000000"],["79803.61000000","0.01200000"],["79803.60000000","0.00000000"],["79803.53000000","0.00000000"],["79803.52000000","0.96063000"],["79803.51000000","0.00000000"],["79803.25000000","0.00000000"],["79802.08000000","0.00000000"],["79801.27000000","0.00250000"],["79800.62000000","0.00000000"],["79798.66000000","0.00000000"],["79797.63000000","0.00000000"],["79796.98000000","0.00000000"],["79794.09000000","0.00626000"],["79793.97000000","0.31522000"],["79793.29000000","0.00000000"],["79791.67000000","0.04461000"],["79790.00000000","0.11800000"],["79780.00000000","0.12052000"],["79772.31000000","0.00007000"],["79768.44000000","0.00007000"],["79759.60000000","0.00000000"],["79757.59000000","0.00000000"],["79747.75000000","0.00000000"],["79747.61000000","1.24173000"],["79743.29000000","1.09851000"],["79742.70000000","0.00000000"],["79742.52000000","0.00536000"],["79735.93000000","0.00000000"],["79726.72000000","0.57816000"],["79689.73000000","0.00000000"],["79680.30000000","0.04936000"],["71836.20000000","0.00400000"],["71836.00000000","0.00000000"],["63854.40000000","0.00000000"]],"a":[["79818.01000000","3.18743000"],["79818.02000000","0.00027000"],["79818.62000000","0.00000000"],["79818.63000000","0.06105000"],["79818.97000000","0.00000000"],["79819.13000000","0.77964000"],["79819.14000000","1.87677000"],["79819.15000000","0.00014000"],["79819.20000000","0.00000000"],["79819.39000000","0.00000000"],["79819.87000000","0.00014000"],["79820.37000000","0.00008000"],["79820.48000000","0.00000000"],["79820.49000000","0.00014000"],["79820.76000000","0.00000000"],["79820.77000000","0.05085000"],["79821.08000000","0.00000000"],["79821.09000000","0.00000000"],["79821.10000000","0.00000000"],["79821.72000000","0.00000000"],["79821.85000000","0.02687000"],["79822.32000000","0.00000000"],["79822.33000000","0.00000000"],["79822.94000000","0.00000000"],["79822.96000000","0.00000000"],["79823.23000000","0.00000000"],["79823.59000000","0.00007000"],["79823.94000000","0.00014000"],["79824.16000000","0.00000000"],["79824.17000000","0.00000000"],["79824.20000000","0.01607000"],["79827.35000000","0.00000000"],["79830.07000000","0.02000000"],["79832.76000000","0.33829000"],["79833.24000000","0.19019000"],["79833.98000000","0.27427000"],["79835.83000000","0.02000000"],["79836.43000000","0.01000000"],["79836.50000000","0.62660000"],["79838.06000000","0.00000000"],["79840.00000000","0.12052000"],["79842.00000000","0.02400000"],["79844.03000000","0.12000000"],["79844.83000000","0.00000000"],["79845.82000000","0.00000000"],["79847.01000000","0.00000000"],["79848.88000000","0.00000000"],["79852.66000000","0.00000000"],["79856.00000000","1.80559000"],["79858.01000000","1.24001000"],["79861.51000000","0.00000000"],["79868.20000000","0.00000000"],["79919.71000000","0.02804000"],["79929.17000000","0.00000000"],["79930.41000000","0.80000000"],["79931.99000000","0.01480000"],["79934.70000000","0.00000000"],["79934.71000000","0.00000000"],["80012.00000000","0.00000000"],["80012.85000000","0.00000000"],["80137.42000000","0.00000000"],["80216.28000000","0.00626000"],["80241.11000000","0.00000000"]]}}}
{"rx_ns": 14010691248300, "frame": {"stream":"btcusdt@depth@100ms","data":{"e":"depthUpdate","E":1787651005914,"s":"BTCUSDT","U":99118711288,"u":99118711415,"b":[["79818.00000000","0.42335000"],["79817.99000000","0.00076000"],["79816.00000000","0.02421000"],["79815.53000000","0.00014000"],["79815.08000000","0.02494000"],["79814.90000000","0.00000000"],["79814.52000000","0.00000000"],["79814.00000000","0.02428000"],["79813.77000000","0.02021000"],["79813.38000000","0.00909000"],["79812.48000000","0.31352000"],["79812.43000000","0.00007000"],["79812.25000000","0.01256000"],["79812.00000000","0.02421000"],["79811.91000000","0.12536000"],["79811.48000000","0.00000000"],["79811.38000000","0.01491000"],["79808.08000000","0.05802000"],["79807.46000000","0.06077000"],["79806.73000000","0.22196000"],["79806.71000000","0.00000000"],["79801.29000000","0.00000000"],["79801.27000000","0.00000000"],["79796.93000000","0.02800000"],["79796.86000000","0.02600000"],["79792.47000000","0.02200000"],["79792.07000000","0.04400000"],["79791.67000000","0.00000000"],["79788.80000000","0.04582000"],["79788.01000000","0.05165000"],["79788.00000000","0.02400000"],["79786.33000000","0.00000000"],["79786.29000000","0.00000000"],["79772.78000000","0.00400000"],["79748.62000000","0.02000000"],["79746.40000000","0.00000000"],["79746.37000000","0.02607000"],["79746.01000000","0.02400000"],["79742.45000000","0.00000000"],["79740.34000000","0.01691000"],["79734.14000000","0.02800000"],["79729.69000000","0.02200000"],["79729.29000000","0.02200000"],["79714.49000000","0.00000000"],["79700.01000000","0.29367000"],["79666.62000000","0.00000000"],["79594.81000000","0.00000000"],["79558.33000000","0.00007000"],["71836.20000000","0.00416000"],["71836.00000000","0.00010000"],["63854.40000000","0.00000000"]],"a":[["79818.01000000","3.18743000"],["79818.63000000","0.06098000"],["79819.12000000","1.04939000"],["79819.13000000","0.72503000"],["79819.14000000","1.87691000"],["79819.15000000","0.00000000"],["79819.29000000","0.02247000"],["79819.79000000","0.00400000"],["79819.87000000","0.00000000"],["79820.49000000","0.00000000"],["79820.77000000","0.05085000"],["79821.85000000","0.02701000"],["79824.39000000","0.10466000"],["79824.40000000","0.19031000"],["79846.31000000","0.00191000"],["79848.84000000","0.00000000"],["79864.85000000","0.03600000"],["79918.86000000","0.00000000"],["79925.14000000","0.00000000"],["79945.71000000","0.00125000"],["79951.56000000","0.00000000"],["79985.68000000","0.00125000"],["81015.29000000","0.00030000"]]}}}
{"rx_ns": 14010798422100, "frame": {"stream":"btcusdt@depth20","data":{"lastUpdateId":99118711473,"bids":[["79818.00000000","0.42329000"],["79817.99000000","0.00083000"],["79817.98000000","0.00013000"],["79817.29000000","0.00007000"],["79816.90000000","0.00007000"],["79816.66000000","0.00007000"],["79816.45000000","0.00076000"],["79816.44000000","0.00069000"],["79816.31000000","0.00007000"],["79816.30000000","0.00007000"],["79816.01000000","0.00007000"],["79816.00000000","0.02421000"],["79815.98000000","0.00071000"],["79815.53000000","0.00014000"],["79815.48000000","0.00134000"],["79815.09000000","0.00117000"],["79815.08000000","0.02494000"],["79814.88000000","0.00007000"],["79814.82000000","0.00007000"],["79814.01000000","0.00014000"]],"asks":[["79818.01000000","3.19065000"],["79818.02000000","0.00027000"],["79818.03000000","0.00013000"],["79818.54000000","0.00014000"],["79818.63000000","0.00021000"],["79818.75000000","0.00014000"],["79818.94000000","0.00007000"],["79819.12000000","1.04953000"],["79819.13000000","0.72503000"],["79819.14000000","1.87691000"],["79819.16000000","0.33843000"],["79819.22000000","0.00202000"],["79819.29000000","0.02247000"],["79819.74000000","0.00007000"],["79819.79000000","0.00400000"],["79819.86000000","0.00400000"],["79820.37000000","0.00008000"],["79820.56000000","0.00014000"],["79820.57000000","0.02701000"],["79820.76000000","0.00626000"]]}}}
{"rx_ns": 14010798684200, "frame": {"stream":"btcusdt@depth@100ms","data":{"e":"depthUpdate","E":1787651006014,"s":"BTCUSDT","U":99118711416,"u":99118711473,"b":[["79818.00000000","0.42329000"],["79817.99000000","0.00083000"],["79813.77000000","0.02014000"],["79813.38000000","0.00000000"],["79812.43000000","0.00949000"],["79812.25000000","0.00559000"],["79811.38000000","0.01498000"],["79811.08000000","0.00718000"],["79809.45000000","0.00000000"],["79809.32000000","0.06077000"],["79808.70000000","0.06077000"],["79803.61000000","0.00000000"],["79803.53000000","0.01200000"],["79801.26000000","0.00250000"],["79779.20000000","0.00400000"],["79768.44000000","0.00000000"],["79494.05000000","0.01904000"],["71836.20000000","0.00432000"],["71836.00000000","0.00010000"],["63854.40000000","0.00031000"]],"a":[["79818.01000000","3.19065000"],["79818.63000000","0.00021000"],["79819.12000000","1.04953000"],["79820.57000000","0.02701000"],["79820.76000000","0.00626000"],["79821.85000000","0.02687000"],["79838.01000000","0.05277000"],["79840.99000000","0.00947000"],["79850.01000000","0.40881000"],["79901.04000000","0.09218000"]]}}}
{"rx_ns": 14010893206100, "frame": {"stream":"btcusdt@depth@100ms","data":{"e":"depthUpdate","E":1787651006114,"s":"BTCUSDT","U":99118711474,"u":99118711514,"b":[["79813.77000000","0.02014000"],["79812.48000000","0.31352000"],["79801.26000000","0.00000000"],["79801.23000000","0.00250000"],["79796.15000000","0.02207000"],["79796.07000000","0.02400000"],["79793.76000000","0.02400000"],["79790.44000000","0.59986000"],["79784.45000000","0.00000000"],["79781.12000000","0.00400000"],["79756.20000000","0.02200000"],["79744.49000000","0.02400000"],["79734.14000000","0.00000000"],["79730.94000000","0.00000000"],["71836.20000000","0.00416000"],["71836.00000000","0.00000000"]],"a":[["79818.01000000","3.19065000"],["79818.63000000","0.00007000"],["79820.57000000","0.02701000"],["79820.76000000","0.00640000"],["79831.33000000","0.02000000"],["79851.31000000","0.02000000"]]}}}
{"rx_ns": 14010990729600, "kind": "control", "ctl": {"op": "ping", "recv_ns": 14010928069400, "pong_ns": 14010928215200, "payload_len": 13, "payload_b64": "MTc4NzY1MTAwNjE1MQ=="}, "frame": null}
{"rx_ns": 14010990729600, "frame": {"stream":"btcusdt@depth@100ms","data":{"e":"depthUpdate","E":1787651006214,"s":"BTCUSDT","U":99118711515,"u":99118711538,"b":[["79818.00000000","0.32426000"],["79810.56000000","0.06077000"],["79810.02000000","0.00015000"],["79810.01000000","0.06129000"],["79809.27000000","0.03000000"],["79808.89000000","0.00000000"],["79805.07000000","0.12000000"],["79802.04000000","0.00258000"],["79801.23000000","0.00000000"],["79768.44000000","0.00007000"],["79751.30000000","0.02000000"],["79742.41000000","0.12004000"],["79729.69000000","0.00000000"],["78620.73000000","0.00000000"],["71836.20000000","0.00432000"],["63854.40000000","0.00000000"]],"a":[["79818.01000000","3.19072000"],["79818.75000000","0.00714000"],["79821.85000000","0.02694000"],["79822.75000000","0.00712000"],["79914.44000000","0.00556000"],["79916.99000000","0.00025000"]]}}}
{"rx_ns": 14011091483000, "frame": {"stream":"btcusdt@depth@100ms","data":{"e":"depthUpdate","E":1787651006314,"s":"BTCUSDT","U":99118711539,"u":99118711564,"b":[["79818.00000000","0.32433000"],["79810.57000000","0.00007000"],["79802.04000000","0.00008000"],["79802.01000000","0.00250000"],["79789.89000000","0.62680000"],["79779.38000000","0.00000000"],["79729.29000000","0.00000000"],["79589.64000000","0.00400000"],["78620.73000000","0.00030000"],["71836.20000000","0.00416000"],["63854.00000000","0.00015000"]],"a":[["79818.01000000","3.19072000"],["79818.75000000","0.00728000"],["79819.79000000","0.00000000"],["79820.77000000","0.05071000"],["79820.95000000","0.00400000"]]}}}
{"rx_ns": 14011191000800, "frame": {"stream":"btcusdt@depth@100ms","data":{"e":"depthUpdate","E":1787651006414,"s":"BTCUSDT","U":99118711565,"u":99118711590,"b":[["79818.00000000","0.42919000"],["79817.99000000","0.00076000"],["79813.70000000","0.00000000"],["79812.22000000","0.00202000"],["79803.55000000","1.52443000"],["79803.54000000","1.87677000"],["79803.52000000","0.00000000"],["79802.04000000","0.00258000"],["79802.01000000","0.00000000"],["79768.44000000","0.00000000"],["79739.64000000","0.02088000"],["71836.20000000","0.00432000"],["71836.00000000","0.00020000"]],"a":[["79845.00000000","0.70000000"],["79870.00000000","0.02400000"],["79884.28000000","0.00000000"]]}}}
{"rx_ns": 14011290991000, "frame": {"stream":"btcusdt@depth@100ms","data":{"e":"depthUpdate","E":1787651006514,"s":"BTCUSDT","U":99118711591,"u":99118711604,"b":[["79818.00000000","0.42926000"],["79802.80000000","0.00007000"],["79796.07000000","0.00000000"],["79783.00000000","0.33850000"],["79764.47000000","0.00000000"],["79747.64000000","0.03132000"],["79744.49000000","0.00000000"],["71836.20000000","0.00416000"],["71836.00000000","0.00000000"],["63854.40000000","0.00031000"]],"a":[["79818.53000000","0.00010000"],["79833.18000000","0.02190000"],["79833.32000000","0.33829000"],["79834.74000000","0.00007000"],["79834.93000000","0.00000000"],["79847.75000000","0.00400000"],["79879.35000000","0.00000000"],["79899.33000000","0.00000000"]]}}}
{"rx_ns": 14011391176600, "frame": {"stream":"btcusdt@depth@100ms","data":{"e":"depthUpdate","E":1787651006614,"s":"BTCUSDT","U":99118711605,"u":99118711626,"b":[["79818.00000000","0.42933000"],["79817.99000000","0.00083000"],["79813.77000000","0.02021000"],["79812.50000000","0.00007000"],["79812.49000000","0.06084000"],["79811.88000000","0.33829000"],["79811.39000000","0.00007000"],["79811.38000000","0.13395000"],["79810.02000000","0.00008000"],["79798.85000000","0.37604000"],["79789.89000000","0.00000000"],["79780.00000000","0.82052000"],["79774.92000000","0.00400000"],["79772.78000000","0.00000000"],["79747.64000000","0.00000000"],["79739.64000000","0.00000000"],["79730.65000000","0.62625000"],["71836.20000000","0.00432000"],["63854.40000000","0.00000000"]],"a":[["81000.00000000","31.68437000"],["82000.00000000","122.72268000"]]}}}
{"rx_ns": 14011493266300, "frame": {"stream":"btcusdt@depth@100ms","data":{"e":"depthUpdate","E":1787651006714,"s":"BTCUSDT","U":99118711627,"u":99118711748,"b":[["79818.00000000","1.19593000"],["79817.99000000","0.00104000"],["79815.08000000","0.02501000"],["79814.29000000","0.00007000"],["79814.28000000","0.06077000"],["79813.77000000","0.02028000"],["79813.67000000","0.00007000"],["79813.66000000","0.06084000"],["79813.05000000","0.00007000"],["79813.04000000","0.06077000"],["79812.49000000","0.06098000"],["79812.01000000","0.00000000"],["79812.00000000","0.02414000"],["79811.92000000","0.23798000"],["79811.91000000","0.12543000"],["79811.89000000","0.00000000"],["79811.39000000","0.00000000"],["79811.38000000","0.00014000"],["79810.57000000","0.00000000"],["79810.56000000","0.00000000"],["79810.01000000","0.00052000"],["79809.33000000","0.00000000"],["79809.32000000","0.00000000"],["79808.70000000","0.00000000"],["79806.74000000","0.06077000"],["79806.73000000","0.16366000"],["79806.72000000","0.00000000"],["79806.02000000","0.00000000"],["79805.08000000","0.00000000"],["79804.36000000","0.00000000"],["79803.93000000","0.06077000"],["79803.56000000","0.00000000"],["79798.65000000","0.36586000"],["79793.70000000","0.04000000"],["79785.17000000","0.00000000"],["79775.13000000","0.00400000"],["79774.92000000","0.00000000"],["79745.21000000","0.02000000"],["79729.33000000","0.02000000"],["79709.31000000","0.00400000"],["79593.65000000","0.00000000"],["79582.86000000","0.00771000"],["71836.20000000","0.00416000"]],"a":[["79818.01000000","1.27933000"],["79818.02000000","0.00041000"],["79818.53000000","0.00000000"],["79818.62000000","0.00007000"],["79818.63000000","0.06098000"],["79818.75000000","0.00028000"],["79818.92000000","0.00000000"],["79819.01000000","0.00000000"],["79819.10000000","0.00007000"],["79819.11000000","0.51876000"],["79819.12000000","1.04953000"],["79819.13000000","0.00014000"],["79819.14000000","0.00014000"],["79819.15000000","0.00007000"],["79819.73000000","0.00000000"],["79820.75000000","0.00023000"],["79820.76000000","0.00014000"],["79820.95000000","0.00000000"],["79822.57000000","0.00000000"],["79824.17000000","0.00000000"],["79824.18000000","1.35652000"],["79824.40000000","0.19431000"],["79825.61000000","0.00626000"],["80054.62000000","3.43481000"]]}}}
{"rx_ns": 14011591319400, "frame": {"stream":"btcusdt@depth@100ms","data":{"e":"depthUpdate","E":1787651006814,"s":"BTCUSDT","U":99118711749,"u":99118711840,"b":[["79818.00000000","0.83447000"],["79817.99000000","0.00090000"],["79815.08000000","0.02494000"],["79814.29000000","0.00000000"],["79814.28000000","0.00014000"],["79813.77000000","0.02028000"],["79813.67000000","0.00000000"],["79813.66000000","0.00021000"],["79813.04000000","0.06091000"],["79812.48000000","0.31338000"],["79812.25000000","0.00545000"],["79811.93000000","0.00007000"],["79729.33000000","0.00000000"],["71836.20000000","0.00432000"]],"a":[["79818.01000000","1.27847000"],["79818.02000000","0.00027000"],["79818.35000000","0.00000000"],["79818.63000000","0.06098000"],["79818.75000000","0.00925000"],["79819.11000000","0.51890000"],["79819.12000000","1.04953000"],["79819.13000000","0.00000000"],["79819.14000000","0.00000000"],["79819.29000000","0.02247000"],["79819.43000000","0.00000000"],["79819.91000000","0.00700000"],["79820.57000000","0.02694000"],["79820.76000000","0.00000000"],["79820.77000000","0.05085000"],["79821.85000000","0.02708000"],["79822.75000000","0.00719000"],["79824.17000000","0.06077000"]]}}}
{"rx_ns": 14011701838800, "frame": {"stream":"btcusdt@depth@100ms","data":{"e":"depthUpdate","E":1787651006914,"s":"BTCUSDT","U":99118711841,"u":99118711893,"b":[["79818.00000000","0.81992000"],["79817.99000000","0.00097000"],["79815.08000000","0.02494000"],["79814.28000000","0.00000000"],["79814.00000000","0.02435000"],["79813.84000000","0.00719000"],["79813.77000000","0.02028000"],["79813.66000000","0.00007000"],["79812.48000000","0.31352000"],["79812.43000000","0.00963000"],["79797.62000000","0.35844000"],["79794.51000000","0.02400000"],["79785.97000000","0.00000000"],["79741.22000000","0.00400000"],["71836.20000000","0.00416000"],["63854.40000000","0.00000000"]],"a":[["79818.01000000","1.67834000"],["79818.63000000","0.06098000"],["79818.75000000","0.00939000"],["79819.29000000","0.02254000"],["79819.91000000","0.00714000"],["79820.77000000","0.05071000"],["79821.85000000","0.02694000"],["81015.29000000","0.00030000"]]}}}
{"rx_ns": 14011791177400, "frame": {"stream":"btcusdt@depth20","data":{"lastUpdateId":99118711921,"bids":[["79818.00000000","0.94961000"],["79817.99000000","0.00097000"],["79817.98000000","0.00013000"],["79817.29000000","0.00007000"],["79816.90000000","0.00007000"],["79816.66000000","0.00007000"],["79816.45000000","0.00076000"],["79816.44000000","0.00069000"],["79816.31000000","0.00007000"],["79816.30000000","0.00007000"],["79816.01000000","0.00007000"],["79816.00000000","0.02421000"],["79815.98000000","0.00071000"],["79815.53000000","0.00014000"],["79815.48000000","0.00134000"],["79815.09000000","0.00117000"],["79815.08000000","0.02494000"],["79814.88000000","0.00007000"],["79814.82000000","0.00007000"],["79814.01000000","0.00014000"]],"asks":[["79818.01000000","1.27847000"],["79818.02000000","0.00027000"],["79818.03000000","0.00013000"],["79818.54000000","0.00014000"],["79818.62000000","0.00007000"],["79818.63000000","0.06098000"],["79818.75000000","0.00939000"],["79818.94000000","0.00007000"],["79819.10000000","0.00007000"],["79819.11000000","0.51890000"],["79819.12000000","1.04953000"],["79819.15000000","0.00007000"],["79819.16000000","0.33843000"],["79819.22000000","0.00202000"],["79819.29000000","0.02254000"],["79819.74000000","0.00007000"],["79819.86000000","0.00400000"],["79819.91000000","0.00714000"],["79820.37000000","0.00008000"],["79820.56000000","0.00014000"]]}}}
{"rx_ns": 14011791288800, "frame": {"stream":"btcusdt@depth@100ms","data":{"e":"depthUpdate","E":1787651007014,"s":"BTCUSDT","U":99118711894,"u":99118711921,"b":[["79818.00000000","0.94961000"],["79814.00000000","0.02435000"],["79813.84000000","0.00733000"],["79812.43000000","0.00949000"],["79790.00000000","0.12051000"],["79788.01000000","0.11148000"],["79748.62000000","0.00000000"],["79739.64000000","0.02088000"],["71836.20000000","0.00440000"],["63854.40000000","0.00031000"]],"a":[["79818.01000000","1.27847000"]]}}}
{"rx_ns": 14011891303300, "frame": {"stream":"btcusdt@depth@100ms","data":{"e":"depthUpdate","E":1787651007114,"s":"BTCUSDT","U":99118711922,"u":99118711956,"b":[["79818.00000000","0.82372000"],["79810.01000000","0.00041000"],["79802.04000000","0.00008000"],["79802.03000000","0.00041000"],["79797.62000000","0.38244000"],["79794.05000000","0.00049000"],["79788.58000000","0.00000000"],["79786.07000000","0.00049000"],["79757.67000000","0.02400000"],["79736.22000000","0.02200000"],["79666.57000000","0.00000000"],["79661.44000000","0.00400000"],["79589.96000000","0.00771000"],["79582.86000000","0.00000000"],["71836.20000000","0.00408000"],["63854.00000000","0.00015000"]],"a":[["79818.01000000","1.27597000"],["79820.75000000","0.00012000"],["79821.84000000","0.00014000"],["79829.95000000","0.00000000"],["79831.36000000","0.02000000"],["79851.33000000","0.02000000"],["79871.28000000","0.02000000"],["79969.87000000","0.00176000"]]}}}
{"rx_ns": 14011993311800, "frame": {"stream":"btcusdt@depth@100ms","data":{"e":"depthUpdate","E":1787651007214,"s":"BTCUSDT","U":99118711957,"u":99118712013,"b":[["79818.00000000","0.86372000"],["79817.99000000","0.00090000"],["79813.78000000","0.00000000"],["79813.77000000","0.00028000"],["79811.89000000","0.00007000"],["79811.01000000","0.00014000"],["79806.02000000","0.06077000"],["79805.13000000","0.00000000"],["79805.12000000","0.12486000"],["79803.93000000","0.00000000"],["79800.61000000","0.02000000"],["79785.00000000","0.70000000"],["79739.64000000","0.00000000"],["71836.20000000","0.00424000"],["63854.40000000","0.00000000"]],"a":[["79818.01000000","1.27690000"],["79818.02000000","0.00027000"],["79818.75000000","0.00028000"],["79818.79000000","0.00929000"],["79819.91000000","0.00014000"],["79819.97000000","0.00711000"],["79820.75000000","0.00000000"],["79821.99000000","0.00016000"],["79822.75000000","0.00726000"],["79823.59000000","0.05543000"],["79824.12000000","0.00000000"],["79824.15000000","0.06077000"],["79824.16000000","0.00800000"],["79824.17000000","0.00000000"],["79824.18000000","1.35252000"],["79824.20000000","0.00007000"],["79824.40000000","0.19031000"],["79824.67000000","0.00400000"],["79836.50000000","0.00000000"],["79839.84000000","0.62660000"],["79967.75000000","0.13066000"],["80536.36000000","0.00010000"]]}}}
{"rx_ns": 14012091647100, "frame": {"stream":"btcusdt@depth@100ms","data":{"e":"depthUpdate","E":1787651007314,"s":"BTCUSDT","U":99118712014,"u":99118712061,"b":[["79818.00000000","0.86365000"],["79817.99000000","0.00083000"],["79813.84000000","0.00733000"],["79813.77000000","0.00014000"],["79813.05000000","0.00000000"],["79813.04000000","0.00014000"],["79812.43000000","0.00963000"],["79812.01000000","0.00007000"],["79806.02000000","0.00000000"],["79791.26000000","0.00000000"],["78620.73000000","0.00030000"],["71836.20000000","0.00424000"],["63854.00000000","0.00015000"]],"a":[["79818.63000000","0.06105000"],["79818.75000000","0.00014000"],["79818.79000000","0.00943000"],["79819.29000000","0.02254000"],["79819.91000000","0.00000000"],["79819.97000000","0.00725000"],["79822.75000000","0.00719000"],["79823.59000000","0.05550000"]]}}}
{"rx_ns": 14012192731800, "frame": {"stream":"btcusdt@depth@100ms","data":{"e":"depthUpdate","E":1787651007414,"s":"BTCUSDT","U":99118712062,"u":99118712079,"b":[["79818.00000000","0.85846000"],["79816.31000000","0.00588000"],["79813.84000000","0.00733000"],["79813.77000000","0.00007000"],["79813.66000000","0.00000000"],["79813.04000000","0.00000000"],["79812.25000000","0.00559000"],["71836.20000000","0.00408000"]],"a":[["79818.01000000","1.27680000"]]}}}
{"rx_ns": 14012291192700, "frame": {"stream":"btcusdt@depth@100ms","data":{"e":"depthUpdate","E":1787651007514,"s":"BTCUSDT","U":99118712080,"u":99118712099,"b":[["79818.00000000","0.85846000"],["79816.31000000","0.00602000"],["79812.25000000","0.00545000"],["79811.01000000","0.00007000"],["79802.80000000","0.00007000"],["79797.62000000","0.36244000"],["79768.60000000","0.00000000"],["79747.64000000","0.03132000"],["79739.64000000","0.02088000"],["71836.20000000","0.00440000"],["71836.00000000","0.00000000"],["63854.40000000","0.00031000"]],"a":[["79834.74000000","0.00007000"],["79836.51000000","0.09541000"],["79874.28000000","0.00000000"],["79894.25000000","0.00000000"]]}}}
{"rx_ns": 14012391174600, "frame": {"stream":"btcusdt@depth@100ms","data":{"e":"depthUpdate","E":1787651007614,"s":"BTCUSDT","U":99118712100,"u":99118712120,"b":[["79818.00000000","0.85853000"],["79817.99000000","0.00090000"],["79813.84000000","0.00740000"],["79812.51000000","0.00007000"],["79812.50000000","0.12425000"],["79812.01000000","0.00000000"],["79811.92000000","0.22314000"],["79811.01000000","0.00014000"],["79806.27000000","0.00007000"],["79806.26000000","0.00000000"],["79806.02000000","0.06077000"],["79747.64000000","0.00000000"],["79739.64000000","0.00000000"],["71836.20000000","0.00424000"],["63854.40000000","0.00000000"]],"a":[["79818.01000000","1.27687000"],["79904.87000000","1.95361000"],["79910.15000000","0.00000000"]]}}}
{"rx_ns": 14012491958500, "frame": {"stream":"btcusdt@depth@100ms","data":{"e":"depthUpdate","E":1787651007714,"s":"BTCUSDT","U":99118712121,"u":99118712147,"b":[["79818.00000000","0.92769000"],["79817.99000000","0.00097000"],["79813.84000000","0.00740000"],["79812.50000000","0.12439000"],["79812.43000000","0.00949000"],["79812.22000000","0.00000000"],["79811.92000000","0.10069000"],["79811.91000000","0.12536000"],["79811.89000000","0.00000000"],["79811.88000000","0.00000000"],["79808.70000000","0.06077000"],["79805.13000000","0.06077000"],["73432.57000000","0.00014000"],["71836.20000000","0.00440000"]],"a":[]}}}
{"rx_ns": 14012590691500, "frame": {"stream":"btcusdt@depth@100ms","data":{"e":"depthUpdate","E":1787651007814,"s":"BTCUSDT","U":99118712148,"u":99118712154,"b":[["78200.00000000","4.66756000"],["71836.20000000","0.00424000"]],"a":[["79818.01000000","1.27555000"],["79818.02000000","0.00027000"]]}}}
{"rx_ns": 14012691606100, "frame": {"stream":"btcusdt@depth@100ms","data":{"e":"depthUpdate","E":1787651007914,"s":"BTCUSDT","U":99118712155,"u":99118712209,"b":[["79818.00000000","1.29260000"],["79817.99000000","0.00104000"],["79813.84000000","0.00747000"],["79813.05000000","0.00007000"],["79813.04000000","0.06077000"],["79812.49000000","0.00021000"],["79811.92000000","0.16032000"],["79810.56000000","0.00000000"],["79810.01000000","0.00041000"],["79809.32000000","0.06077000"],["79805.13000000","0.00000000"],["79803.93000000","0.00000000"],["79803.56000000","0.00000000"],["79800.58000000","0.02000000"],["79760.62000000","0.02000000"],["79739.64000000","0.02088000"],["71836.20000000","0.00432000"],["71836.19000000","0.00008000"],["63854.40000000","0.00020000"]],"a":[["79818.01000000","1.27583000"],["79818.02000000","0.00055000"],["79823.59000000","0.00007000"],["79824.15000000","0.00000000"],["79831.28000000","0.02000000"],["79833.98000000","0.00400000"],["79836.00000000","1.34178000"],["79837.99000000","0.39446000"],["79851.26000000","0.02000000"],["80257.64000000","0.00018000"],["81015.29000000","0.00030000"]]}}}
{"rx_ns": 14012793490700, "frame": {"stream":"btcusdt@depth20","data":{"lastUpdateId":99118712239,"bids":[["79818.00000000","1.29323000"],["79817.99000000","0.00097000"],["79817.98000000","0.00013000"],["79817.29000000","0.00007000"],["79816.90000000","0.00007000"],["79816.66000000","0.00007000"],["79816.45000000","0.00076000"],["79816.44000000","0.00069000"],["79816.31000000","0.00602000"],["79816.30000000","0.00007000"],["79816.01000000","0.00007000"],["79816.00000000","0.02421000"],["79815.98000000","0.00071000"],["79815.53000000","0.00014000"],["79815.48000000","0.00134000"],["79815.09000000","0.00117000"],["79815.08000000","0.02494000"],["79814.88000000","0.00007000"],["79814.82000000","0.00007000"],["79814.01000000","0.00014000"]],"asks":[["79818.01000000","1.27583000"],["79818.02000000","0.00055000"],["79818.03000000","0.00013000"],["79818.54000000","0.00014000"],["79818.62000000","0.00007000"],["79818.63000000","0.06105000"],["79818.75000000","0.00014000"],["79818.79000000","0.00943000"],["79818.94000000","0.00007000"],["79819.10000000","0.00007000"],["79819.11000000","0.51890000"],["79819.12000000","1.04953000"],["79819.15000000","0.00007000"],["79819.16000000","0.33843000"],["79819.22000000","0.00202000"],["79819.29000000","0.02254000"],["79819.74000000","0.00007000"],["79819.86000000","0.00400000"],["79819.97000000","0.00725000"],["79820.37000000","0.00008000"]]}}}
{"rx_ns": 14012793593400, "frame": {"stream":"btcusdt@depth@100ms","data":{"e":"depthUpdate","E":1787651008014,"s":"BTCUSDT","U":99118712210,"u":99118712239,"b":[["79818.00000000","1.29323000"],["79817.99000000","0.00097000"],["79813.84000000","0.00747000"],["79813.04000000","0.06091000"],["79812.50000000","0.12432000"],["79812.49000000","0.00007000"],["79808.98000000","0.00000000"],["79807.80000000","0.00000000"],["79788.01000000","0.31275000"],["79763.45000000","0.00000000"],["79753.57000000","0.04698000"],["79739.64000000","0.00000000"],["76000.00000000","61.76995000"],["71836.20000000","0.00432000"],["63854.40000000","0.00031000"]],"a":[]}}}
{"rx_ns": 14012893329400, "frame": {"stream":"btcusdt@depth@100ms","data":{"e":"depthUpdate","E":1787651008114,"s":"BTCUSDT","U":99118712240,"u":99118712257,"b":[["79818.00000000","1.49248000"],["79737.69000000","0.02400000"],["71836.20000000","0.00448000"]],"a":[["79818.01000000","1.27174000"],["79818.02000000","0.00048000"],["79818.63000000","0.06112000"],["79818.79000000","0.00014000"],["79819.06000000","0.00920000"],["79819.29000000","0.02261000"],["79819.97000000","0.00014000"],["79820.32000000","0.00719000"],["79821.84000000","0.00000000"],["79821.99000000","0.00000000"],["79823.11000000","0.00042000"],["79871.31000000","0.02000000"]]}}}
{"rx_ns": 14012990436800, "frame": {"stream":"btcusdt@depth@100ms","data":{"e":"depthUpdate","E":1787651008214,"s":"BTCUSDT","U":99118712258,"u":99118712283,"b":[["79818.00000000","1.49258000"],["71836.20000000","0.00432000"],["63854.40000000","0.00000000"]],"a":[["79818.01000000","1.27062000"],["79818.63000000","0.06105000"],["79818.79000000","0.00000000"],["79819.06000000","0.00934000"],["79819.29000000","0.02254000"],["79819.97000000","0.00000000"],["79820.32000000","0.00733000"],["80536.36000000","0.00020000"]]}}}
{"rx_ns": 14013090774500, "frame": {"stream":"btcusdt@depth@100ms","data":{"e":"depthUpdate","E":1787651008314,"s":"BTCUSDT","U":99118712284,"u":99118712294,"b":[["79818.00000000","1.47377000"],["79813.04000000","0.00014000"],["78620.73000000","0.00030000"],["73432.57000000","0.00000000"],["71836.20000000","0.00448000"],["71836.19000000","0.00000000"],["63854.00000000","0.00015000"]],"a":[]}}}
{"rx_ns": 14013191663500, "frame": {"stream":"btcusdt@depth@100ms","data":{"e":"depthUpdate","E":1787651008414,"s":"BTCUSDT","U":99118712295,"u":99118712312,"b":[["79818.00000000","0.91078000"],["79817.99000000","0.00090000"],["79813.84000000","0.00740000"],["79813.05000000","0.00000000"],["79813.04000000","0.00000000"],["79812.43000000","0.00963000"],["79739.64000000","0.02088000"],["71836.20000000","0.00432000"]],"a":[["79824.15000000","0.06046000"]]}}}
{"rx_ns": 14013290887400, "frame": {"stream":"btcusdt@depth@100ms","data":{"e":"depthUpdate","E":1787651008514,"s":"BTCUSDT","U":99118712313,"u":99118712323,"b":[["79818.00000000","0.91008000"],["79808.92000000","0.00069000"],["79802.80000000","0.00000000"],["79739.64000000","0.00000000"],["71836.20000000","0.00448000"],["63854.40000000","0.00031000"]],"a":[["79818.01000000","1.26999000"],["79822.75000000","0.00726000"],["79834.74000000","0.00000000"],["81150.00000000","0.24094000"]]}}}
{"rx_ns": 14013391283000, "frame": {"stream":"btcusdt@depth@100ms","data":{"e":"depthUpdate","E":1787651008614,"s":"BTCUSDT","U":99118712324,"u":99118712363,"b":[["79818.00000000","0.80044000"],["79811.01000000","0.00007000"],["79802.80000000","0.00007000"],["79796.86000000","0.00000000"],["79766.35000000","0.00000000"],["79746.37000000","0.00007000"],["79733.29000000","0.62625000"],["79730.65000000","0.00000000"],["71836.20000000","0.00432000"],["71836.00000000","0.00000000"],["63854.40000000","0.00000000"]],"a":[["79818.01000000","3.14655000"],["79818.02000000","0.00027000"],["79818.62000000","0.00000000"],["79818.63000000","0.00028000"],["79819.09000000","1.02036000"],["79819.10000000","1.87677000"],["79819.11000000","0.00021000"],["79822.75000000","0.00719000"],["79824.15000000","0.00000000"],["79834.74000000","0.00007000"],["79835.71000000","0.00000000"],["79839.54000000","0.04552000"],["79842.30000000","0.00000000"],["79873.47000000","0.00000000"],["79893.44000000","0.00000000"]]}}}
{"rx_ns": 14013490711400, "frame": {"stream":"btcusdt@depth@100ms","data":{"e":"depthUpdate","E":1787651008714,"s":"BTCUSDT","U":99118712364,"u":99118712414,"b":[["79818.00000000","0.89310000"],["79817.99000000","0.00097000"],["79813.84000000","0.00747000"],["79812.52000000","0.00007000"],["79812.51000000","0.06084000"],["79805.13000000","0.06077000"],["71836.20000000","0.00416000"]],"a":[["79818.01000000","3.25670000"],["79818.02000000","0.00055000"],["79818.63000000","0.00014000"],["79819.06000000","0.00934000"],["79819.08000000","0.00007000"],["79819.09000000","1.02057000"],["79819.10000000","1.87691000"],["79819.11000000","0.00007000"],["79819.73000000","0.00016000"],["79823.11000000","0.00020000"]]}}}
{"rx_ns": 14013592282400, "frame": {"stream":"btcusdt@depth@100ms","data":{"e":"depthUpdate","E":1787651008814,"s":"BTCUSDT","U":99118712415,"u":99118712435,"b":[["79818.00000000","0.78439000"],["79813.84000000","0.00747000"],["79812.51000000","0.06098000"],["79812.43000000","0.00949000"],["71836.20000000","0.00432000"]],"a":[["79818.01000000","3.20670000"]]}}}
{"rx_ns": 14013690764600, "frame": {"stream":"btcusdt@depth@100ms","data":{"e":"depthUpdate","E":1787651008914,"s":"BTCUSDT","U":99118712436,"u":99118712450,"b":[["79811.01000000","0.00014000"],["79801.44000000","0.02600000"],["79761.49000000","0.02600000"],["79740.65000000","0.02000000"],["71836.20000000","0.00432000"],["63854.40000000","0.00000000"]],"a":[["79830.44000000","0.02000000"],["79850.41000000","0.02000000"],["79871.23000000","0.02000000"],["81015.29000000","0.00030000"]]}}}
{"rx_ns": 14013792409400, "frame": {"stream":"btcusdt@depth20","data":{"lastUpdateId":99118712506,"bids":[["79818.00000000","1.20750000"],["79817.99000000","0.00111000"],["79817.98000000","0.00013000"],["79817.29000000","0.00007000"],["79816.90000000","0.00007000"],["79816.66000000","0.00007000"],["79816.45000000","0.00076000"],["79816.44000000","0.00069000"],["79816.31000000","0.00602000"],["79816.30000000","0.00007000"],["79816.01000000","0.00007000"],["79816.00000000","0.02421000"],["79815.98000000","0.00071000"],["79815.53000000","0.00014000"],["79815.48000000","0.00134000"],["79815.09000000","0.00117000"],["79815.08000000","0.02501000"],["79814.88000000","0.00007000"],["79814.82000000","0.00007000"],["79814.29000000","0.00007000"]],"asks":[["79818.01000000","1.24520000"],["79818.02000000","0.00055000"],["79818.03000000","0.00013000"],["79818.54000000","0.00014000"],["79818.63000000","0.00014000"],["79818.75000000","0.00014000"],["79818.94000000","0.00007000"],["79819.06000000","0.00014000"],["79819.08000000","0.06084000"],["79819.09000000","0.46085000"],["79819.10000000","0.00014000"],["79819.11000000","0.00007000"],["79819.12000000","1.04953000"],["79819.15000000","0.00007000"],["79819.16000000","0.33843000"],["79819.22000000","0.00202000"],["79819.29000000","0.02261000"],["79819.60000000","0.00928000"],["79819.74000000","0.00007000"],["79819.86000000","0.00400000"]]}}}
{"rx_ns": 14013792545800, "frame": {"stream":"btcusdt@depth@100ms","data":{"e":"depthUpdate","E":1787651009014,"s":"BTCUSDT","U":99118712451,"u":99118712506,"b":[["79818.00000000","1.20750000"],["79817.99000000","0.00111000"],["79815.08000000","0.02501000"],["79814.29000000","0.00007000"],["79814.28000000","0.06077000"],["79813.84000000","0.00754000"],["79813.67000000","0.00007000"],["79813.66000000","0.06084000"],["79813.05000000","0.00007000"],["79813.04000000","0.06077000"],["79811.92000000","0.16025000"],["79810.56000000","0.06077000"],["79810.17000000","0.00400000"],["79810.01000000","0.06118000"],["79806.73000000","0.23371000"],["79804.36000000","0.00000000"],["79803.93000000","0.00000000"],["79803.56000000","0.00000000"],["79777.32000000","0.00400000"],["79777.06000000","0.03224000"],["79775.13000000","0.00000000"],["79589.96000000","0.00000000"],["79582.86000000","0.00771000"],["71836.20000000","0.00432000"],["63854.40000000","0.00031000"]],"a":[["79818.01000000","1.24520000"],["79819.06000000","0.00014000"],["79819.08000000","0.06084000"],["79819.09000000","0.46085000"],["79819.10000000","0.00014000"],["79819.29000000","0.02261000"],["79819.60000000","0.00928000"],["79819.73000000","0.00000000"],["79820.32000000","0.00014000"],["79821.84000000","0.00017000"],["79824.17000000","0.00007000"],["79824.18000000","1.35259000"],["79824.40000000","0.19024000"]]}}}
{"rx_ns": 14013890729000, "frame": {"stream":"btcusdt@depth@100ms","data":{"e":"depthUpdate","E":1787651009114,"s":"BTCUSDT","U":99118712507,"u":99118712569,"b":[["79818.00000000","1.41000000"],["79815.08000000","0.02501000"],["79814.28000000","0.06091000"],["79813.84000000","0.00754000"],["79813.66000000","0.06098000"],["79813.04000000","0.06091000"],["79812.51000000","0.06084000"],["79812.50000000","0.12418000"],["79812.48000000","0.31338000"],["79810.56000000","0.00000000"],["79808.92000000","0.00000000"],["79806.02000000","0.00000000"],["79805.13000000","0.00000000"],["71836.20000000","0.00432000"]],"a":[["79818.01000000","1.24527000"],["79818.63000000","0.00007000"],["79819.06000000","0.00000000"],["79819.07000000","0.00007000"],["79819.08000000","0.06098000"],["79819.09000000","0.46085000"],["79819.10000000","0.00000000"],["79819.29000000","0.02254000"],["79819.60000000","0.00942000"],["79820.32000000","0.00000000"],["79820.77000000","0.05085000"],["79824.17000000","0.00000000"],["79824.18000000","1.35252000"]]}}}
{"rx_ns": 14013991456200, "frame": {"stream":"btcusdt@depth@100ms","data":{"e":"depthUpdate","E":1787651009214,"s":"BTCUSDT","U":99118712570,"u":99118712591,"b":[["79818.00000000","1.41076000"],["79817.99000000","0.00118000"],["79815.37000000","0.00202000"],["79809.04000000","0.00000000"],["79772.31000000","0.00000000"],["79733.29000000","0.00000000"],["79730.65000000","0.62625000"],["79684.24000000","0.05312000"],["79680.30000000","0.00000000"],["71836.20000000","0.00448000"],["63854.40000000","0.00000000"]],"a":[["79818.01000000","1.24527000"],["79818.02000000","0.00055000"],["79919.71000000","0.00000000"],["79923.66000000","0.02804000"]]}}}
{"rx_ns": 14014090877800, "frame": {"stream":"btcusdt@depth@100ms","data":{"e":"depthUpdate","E":1787651009314,"s":"BTCUSDT","U":99118712592,"u":99118712603,"b":[["79818.00000000","1.41069000"],["79817.99000000","0.00111000"],["79814.29000000","0.00000000"],["79814.28000000","0.00014000"],["79739.64000000","0.02088000"],["78620.73000000","0.00030000"],["71836.20000000","0.00416000"],["63854.00000000","0.00015000"]],"a":[["79818.01000000","1.24539000"]]}}}
{"rx_ns": 14014194672400, "frame": {"stream":"btcusdt@depth@100ms","data":{"e":"depthUpdate","E":1787651009414,"s":"BTCUSDT","U":99118712604,"u":99118712623,"b":[["79818.00000000","1.41533000"],["79817.99000000","0.00111000"],["79815.37000000","0.00000000"],["79815.08000000","0.02494000"],["79814.28000000","0.00000000"],["79812.51000000","0.06098000"],["71836.20000000","0.00448000"]],"a":[["79824.17000000","0.00007000"],["79824.18000000","1.35259000"],["79833.18000000","0.00000000"]]}}}
{"rx_ns": 14014291553300, "frame": {"stream":"btcusdt@depth@100ms","data":{"e":"depthUpdate","E":1787651009514,"s":"BTCUSDT","U":99118712624,"u":99118712643,"b":[["79818.00000000","1.41540000"],["79817.99000000","0.00118000"],["79815.94000000","0.00202000"],["79815.08000000","0.02501000"],["79814.89000000","0.00007000"],["79814.88000000","0.33836000"],["79813.67000000","0.00000000"],["79813.66000000","0.00021000"],["79810.01000000","0.00041000"],["79747.64000000","0.03133000"],["79739.64000000","0.00000000"],["71836.20000000","0.00432000"],["63854.40000000","0.00031000"]],"a":[]}}}
{"rx_ns": 14014391016200, "frame": {"stream":"btcusdt@depth@100ms","data":{"e":"depthUpdate","E":1787651009614,"s":"BTCUSDT","U":99118712644,"u":99118712678,"b":[["79818.00000000","1.41533000"],["79817.99000000","0.00111000"],["79815.08000000","0.02501000"],["79814.88000000","0.33850000"],["79813.84000000","0.00754000"],["79813.66000000","0.00007000"],["79813.05000000","0.00000000"],["79813.04000000","0.00014000"],["79811.92000000","0.16032000"],["79802.80000000","0.00007000"],["79747.64000000","0.00000000"],["79630.91000000","0.01100000"],["71836.20000000","0.00448000"],["63854.40000000","0.00000000"],["63854.00000000","0.00015000"]],"a":[["79818.01000000","1.24546000"],["79818.62000000","0.00007000"],["79818.63000000","0.06084000"],["79821.84000000","0.00000000"],["79823.10000000","0.00021000"],["79824.17000000","0.00000000"],["79824.18000000","1.35252000"],["79834.74000000","0.00007000"],["79992.85000000","0.04288000"]]}}}
{"rx_ns": 14014491707900, "frame": {"stream":"btcusdt@depth@100ms","data":{"e":"depthUpdate","E":1787651009714,"s":"BTCUSDT","U":99118712679,"u":99118712718,"b":[["79818.00000000","0.90208000"],["79817.99000000","0.00104000"],["79813.84000000","0.00747000"],["79813.66000000","0.00000000"],["79813.04000000","0.00000000"],["79812.52000000","0.00000000"],["79812.51000000","0.00021000"],["79812.50000000","0.12432000"],["79733.29000000","0.62625000"],["79730.65000000","0.00000000"],["71836.20000000","0.00440000"],["71836.00000000","0.00000000"]],"a":[["79818.01000000","1.24531000"],["79818.63000000","0.06098000"],["79820.77000000","0.05071000"],["79822.75000000","0.00726000"],["79824.15000000","0.06077000"],["79824.17000000","0.00000000"],["79824.18000000","1.35252000"]]}}}
{"rx_ns": 14014591407200, "frame": {"stream":"btcusdt@depth@100ms","data":{"e":"depthUpdate","E":1787651009814,"s":"BTCUSDT","U":99118712719,"u":99118712735,"b":[["79818.00000000","1.24707000"],["79815.94000000","0.00000000"],["79813.84000000","0.00747000"],["79812.51000000","0.00007000"],["79812.48000000","0.31352000"],["79772.31000000","0.00007000"],["71836.20000000","0.00456000"],["63854.00000000","0.00215000"]],"a":[]}}}
{"rx_ns": 14014698461100, "frame": {"stream":"btcusdt@depth@100ms","data":{"e":"depthUpdate","E":1787651009914,"s":"BTCUSDT","U":99118712736,"u":99118712749,"b":[["79818.00000000","1.24700000"],["79817.99000000","0.00097000"],["79806.75000000","0.00400000"],["79741.51000000","0.02600000"],["71836.20000000","0.00440000"],["63854.40000000","0.00000000"],["63854.00000000","0.00015000"]],"a":[["79824.14000000","0.00800000"],["79870.39000000","0.02000000"],["81015.29000000","0.00030000"]]}}}
{"rx_ns": 14014802199900, "frame": {"stream":"btcusdt@depth20","data":{"lastUpdateId":99118712755,"bids":[["79818.00000000","1.24700000"],["79817.99000000","0.00097000"],["79817.98000000","0.00013000"],["79817.29000000","0.00007000"],["79816.90000000","0.00007000"],["79816.66000000","0.00007000"],["79816.45000000","0.00076000"],["79816.44000000","0.00069000"],["79816.31000000","0.00602000"],["79816.30000000","0.00007000"],["79816.01000000","0.00007000"],["79816.00000000","0.02421000"],["79815.98000000","0.00071000"],["79815.53000000","0.00014000"],["79815.48000000","0.00134000"],["79815.09000000","0.00117000"],["79815.08000000","0.02501000"],["79814.89000000","0.00007000"],["79814.88000000","0.33850000"],["79814.82000000","0.00007000"]],"asks":[["79818.01000000","1.24531000"],["79818.02000000","0.00055000"],["79818.03000000","0.00013000"],["79818.54000000","0.00014000"],["79818.62000000","0.00007000"],["79818.63000000","0.06098000"],["79818.75000000","0.00014000"],["79818.94000000","0.00007000"],["79819.07000000","0.00007000"],["79819.08000000","0.06098000"],["79819.09000000","0.46085000"],["79819.11000000","0.00007000"],["79819.12000000","1.04953000"],["79819.15000000","0.00007000"],["79819.16000000","0.33843000"],["79819.22000000","0.00202000"],["79819.29000000","0.02254000"],["79819.60000000","0.00942000"],["79819.74000000","0.00007000"],["79819.86000000","0.00400000"]]}}}
{"rx_ns": 14014802338200, "frame": {"stream":"btcusdt@depth@100ms","data":{"e":"depthUpdate","E":1787651010014,"s":"BTCUSDT","U":99118712750,"u":99118712755,"b":[["71836.20000000","0.00456000"],["71836.00000000","0.00010000"],["63854.40000000","0.00031000"]],"a":[["86422.88000000","0.18910000"]]}}}
