{"rx_ns": 42926007603200, "frame": {"channel":"book","type":"update","data":[{"symbol":"BTC/USD","bids":[],"asks":[{"price":62810.3,"qty":0.00222509},{"price":62805.5,"qty":1.59575715}],"checksum":1484136085,"timestamp":"2026-08-16T23:37:40.629948Z"}]}}
{"rx_ns": 42926044782400, "frame": {"channel":"book","type":"update","data":[{"symbol":"BTC/USD","bids":[{"price":62791.2,"qty":0.01714221}],"asks":[],"checksum":3418464235,"timestamp":"2026-08-16T23:37:40.649890Z"}]}}
{"rx_ns": 42926227856900, "frame": {"channel":"book","type":"update","data":[{"symbol":"BTC/USD","bids":[],"asks":[{"price":62844.5,"qty":0.03230254}],"checksum":3418464235,"timestamp":"2026-08-16T23:37:40.849839Z"}]}}
{"rx_ns": 42926319997400, "frame": {"channel":"book","type":"update","data":[{"symbol":"BTC/USD","bids":[{"price":62778.0,"qty":0.00422324}],"asks":[],"checksum":3418464235,"timestamp":"2026-08-16T23:37:40.944414Z"}]}}
{"rx_ns": 42926323548700, "frame": {"channel":"book","type":"update","data":[{"symbol":"BTC/USD","bids":[{"price":62777.9,"qty":0.15928208}],"asks":[],"checksum":3418464235,"timestamp":"2026-08-16T23:37:40.946574Z"}]}}
{"rx_ns": 42926392352000, "frame": {"channel":"book","type":"update","data":[{"symbol":"BTC/USD","bids":[],"asks":[{"price":62794.2,"qty":0.00000000},{"price":62874.0,"qty":0.60000000}],"checksum":3667834091,"timestamp":"2026-08-16T23:37:40.986079Z"}]}}
{"rx_ns": 42926408935600, "frame": {"channel":"book","type":"update","data":[{"symbol":"BTC/USD","bids":[{"price":62791.2,"qty":0.01724221}],"asks":[],"checksum":280341157,"timestamp":"2026-08-16T23:37:41.018446Z"}]}}
{"rx_ns": 42926411647300, "frame": {"channel":"book","type":"update","data":[{"symbol":"BTC/USD","bids":[{"price":62760.0,"qty":0.03516560}],"asks":[],"checksum":280341157,"timestamp":"2026-08-16T23:37:41.034598Z"}]}}
{"rx_ns": 42926466760700, "frame": {"channel":"book","type":"update","data":[{"symbol":"BTC/USD","bids":[{"price":62791.2,"qty":0.01565021},{"price":62791.2,"qty":0.01534221}],"asks":[],"checksum":21505966,"timestamp":"2026-08-16T23:37:41.083592Z"}]}}
{"rx_ns": 42926562279500, "frame": {"channel":"book","type":"update","data":[{"symbol":"BTC/USD","bids":[{"price":62777.9,"qty":0.95573946}],"asks":[],"checksum":21505966,"timestamp":"2026-08-16T23:37:41.174196Z"}]}}
{"rx_ns": 42926564310400, "frame": {"channel":"book","type":"update","data":[{"symbol":"BTC/USD","bids":[{"price":62775.0,"qty":0.00000000},{"price":62710.2,"qty":0.00159400}],"asks":[],"checksum":21505966,"timestamp":"2026-08-16T23:37:41.177071Z"}]}}
{"rx_ns": 42926608423900, "frame": {"channel":"book","type":"update","data":[{"symbol":"BTC/USD","bids":[{"price":62728.9,"qty":0.00000000},{"price":62709.2,"qty":0.43000000}],"asks":[],"checksum":21505966,"timestamp":"2026-08-16T23:37:41.207347Z"}]}}
{"rx_ns": 42926612894500, "frame": {"channel":"book","type":"update","data":[{"symbol":"BTC/USD","bids":[{"price":62726.0,"qty":0.05187046}],"asks":[],"checksum":21505966,"timestamp":"2026-08-16T23:37:41.211458Z"}]}}
{"rx_ns": 42926612944800, "frame": {"channel":"book","type":"update","data":[{"symbol":"BTC/USD","bids":[{"price":62729.0,"qty":5.50418744}],"asks":[],"checksum":21505966,"timestamp":"2026-08-16T23:37:41.211597Z"}]}}
{"rx_ns": 42926690400300, "frame": {"channel":"heartbeat"}}
{"rx_ns": 42926726061500, "frame": {"channel":"book","type":"update","data":[{"symbol":"BTC/USD","bids":[],"asks":[{"price":62828.2,"qty":0.00000000},{"price":62875.0,"qty":0.04717193}],"checksum":21505966,"timestamp":"2026-08-16T23:37:41.342709Z"}]}}
{"rx_ns": 42926726165300, "frame": {"channel":"book","type":"update","data":[{"symbol":"BTC/USD","bids":[],"asks":[{"price":62832.9,"qty":0.00000000},{"price":62875.2,"qty":5.56658959}],"checksum":21505966,"timestamp":"2026-08-16T23:37:41.342739Z"}]}}
{"rx_ns": 42926726183900, "frame": {"channel":"book","type":"update","data":[{"symbol":"BTC/USD","bids":[],"asks":[{"price":62828.5,"qty":0.00000000},{"price":62875.3,"qty":0.01000000}],"checksum":21505966,"timestamp":"2026-08-16T23:37:41.342763Z"}]}}
{"rx_ns": 42926726209700, "frame": {"channel":"book","type":"update","data":[{"symbol":"BTC/USD","bids":[],"asks":[{"price":62810.0,"qty":0.50000000}],"checksum":21505966,"timestamp":"2026-08-16T23:37:41.349935Z"}]}}
{"rx_ns": 42926726234700, "frame": {"channel":"book","type":"update","data":[{"symbol":"BTC/USD","bids":[],"asks":[{"price":62828.4,"qty":0.74659916}],"checksum":21505966,"timestamp":"2026-08-16T23:37:41.350220Z"}]}}
{"rx_ns": 42926726247000, "frame": {"channel":"book","type":"update","data":[{"symbol":"BTC/USD","bids":[],"asks":[{"price":62832.8,"qty":1.55750852}],"checksum":21505966,"timestamp":"2026-08-16T23:37:41.350306Z"}]}}
{"rx_ns": 42926726269600, "frame": {"channel":"book","type":"update","data":[{"symbol":"BTC/USD","bids":[],"asks":[{"price":62828.7,"qty":0.80875095}],"checksum":21505966,"timestamp":"2026-08-16T23:37:41.350715Z"}]}}
{"rx_ns": 42926816811600, "frame": {"channel":"book","type":"update","data":[{"symbol":"BTC/USD","bids":[],"asks":[{"price":62791.3,"qty":4.27921369}],"checksum":647521170,"timestamp":"2026-08-16T23:37:41.438542Z"}]}}
{"rx_ns": 42926816946000, "frame": {"channel":"book","type":"update","data":[{"symbol":"BTC/USD","bids":[],"asks":[{"price":62791.3,"qty":4.20121369}],"checksum":261096058,"timestamp":"2026-08-16T23:37:41.440266Z"}]}}
{"rx_ns": 42926816969100, "frame": {"channel":"book","type":"update","data":[{"symbol":"BTC/USD","bids":[{"price":62754.1,"qty":0.00000000},{"price":62710.2,"qty":0.00159400},{"price":62753.6,"qty":0.00323497}],"asks":[],"checksum":261096058,"timestamp":"2026-08-16T23:37:41.441285Z"}]}}
{"rx_ns": 42926817001600, "frame": {"channel":"book","type":"update","data":[{"symbol":"BTC/USD","bids":[{"price":62783.2,"qty":0.00000000},{"price":62709.2,"qty":0.43000000},{"price":62781.8,"qty":0.00318497}],"asks":[],"checksum":1390939081,"timestamp":"2026-08-16T23:37:41.441568Z"}]}}
{"rx_ns": 42926817017200, "frame": {"channel":"book","type":"update","data":[{"symbol":"BTC/USD","bids":[],"asks":[{"price":62801.8,"qty":0.00000000},{"price":62874.0,"qty":0.60000000},{"price":62801.3,"qty":0.00318497}],"checksum":1390939081,"timestamp":"2026-08-16T23:37:41.441883Z"}]}}
{"rx_ns": 42926817030300, "frame": {"channel":"book","type":"update","data":[{"symbol":"BTC/USD","bids":[],"asks":[{"price":62830.9,"qty":0.03429038},{"price":62829.5,"qty":0.00318497}],"checksum":1390939081,"timestamp":"2026-08-16T23:37:41.442125Z"}]}}
{"rx_ns": 42926912930100, "frame": {"channel":"book","type":"update","data":[{"symbol":"BTC/USD","bids":[{"price":62788.1,"qty":0.00000000},{"price":62709.2,"qty":0.43000000}],"asks":[],"checksum":497105662,"timestamp":"2026-08-16T23:37:41.534207Z"}]}}
{"rx_ns": 42926913014400, "frame": {"channel":"book","type":"update","data":[{"symbol":"BTC/USD","bids":[{"price":62785.0,"qty":0.05598472}],"asks":[],"checksum":1117164306,"timestamp":"2026-08-16T23:37:41.535486Z"}]}}
{"rx_ns": 42926913029700, "frame": {"channel":"book","type":"update","data":[{"symbol":"BTC/USD","bids":[],"asks":[{"price":62792.2,"qty":0.00000000},{"price":62874.0,"qty":0.60000000},{"price":62791.3,"qty":4.25719841}],"checksum":2174995255,"timestamp":"2026-08-16T23:37:41.535585Z"}]}}
{"rx_ns": 42926913052800, "frame": {"channel":"book","type":"update","data":[{"symbol":"BTC/USD","bids":[],"asks":[{"price":62791.3,"qty":4.33519841}],"checksum":3976925027,"timestamp":"2026-08-16T23:37:41.537605Z"}]}}
{"rx_ns": 42926913072800, "frame": {"channel":"book","type":"update","data":[{"symbol":"BTC/USD","bids":[],"asks":[{"price":62873.1,"qty":0.06960000}],"checksum":3976925027,"timestamp":"2026-08-16T23:37:41.538480Z"}]}}
{"rx_ns": 42927509965400, "frame": {"channel":"book","type":"update","data":[{"symbol":"BTC/USD","bids":[{"price":62754.2,"qty":0.00000000},{"price":62709.2,"qty":0.43000000},{"price":62753.7,"qty":0.00303507}],"asks":[],"checksum":3976925027,"timestamp":"2026-08-16T23:37:42.138280Z"}]}}
{"rx_ns": 42927554871200, "frame": {"channel":"book","type":"update","data":[{"symbol":"BTC/USD","bids":[{"price":62780.1,"qty":0.00000000},{"price":62709.2,"qty":0.43000000}],"asks":[],"checksum":3976925027,"timestamp":"2026-08-16T23:37:42.183097Z"}]}}
{"rx_ns": 42927562350100, "frame": {"channel":"book","type":"update","data":[{"symbol":"BTC/USD","bids":[{"price":62780.7,"qty":0.79642261}],"asks":[],"checksum":2379088104,"timestamp":"2026-08-16T23:37:42.185445Z"}]}}
{"rx_ns": 42927562408300, "frame": {"channel":"book","type":"update","data":[{"symbol":"BTC/USD","bids":[{"price":62775.6,"qty":0.01031774}],"asks":[],"checksum":2379088104,"timestamp":"2026-08-16T23:37:42.186099Z"}]}}
{"rx_ns": 42927562441300, "frame": {"channel":"book","type":"update","data":[{"symbol":"BTC/USD","bids":[{"price":62775.6,"qty":0.00000000},{"price":62710.2,"qty":0.00159400}],"asks":[],"checksum":2379088104,"timestamp":"2026-08-16T23:37:42.188696Z"}]}}
{"rx_ns": 42927565227000, "frame": {"channel":"book","type":"update","data":[{"symbol":"BTC/USD","bids":[{"price":62785.0,"qty":0.00000000},{"price":62709.2,"qty":0.43000000},{"price":62788.1,"qty":0.05598472}],"asks":[],"checksum":2631890220,"timestamp":"2026-08-16T23:37:42.190838Z"}]}}
{"rx_ns": 42927565272800, "frame": {"channel":"book","type":"update","data":[{"symbol":"BTC/USD","bids":[],"asks":[{"price":62791.3,"qty":4.27921369},{"price":62792.2,"qty":0.05598472}],"checksum":361417521,"timestamp":"2026-08-16T23:37:42.190910Z"}]}}
{"rx_ns": 42927566809400, "frame": {"channel":"book","type":"update","data":[{"symbol":"BTC/USD","bids":[],"asks":[{"price":62791.3,"qty":4.20121369}],"checksum":3144853786,"timestamp":"2026-08-16T23:37:42.193696Z"}]}}
{"rx_ns": 42927570073700, "frame": {"channel":"book","type":"update","data":[{"symbol":"BTC/USD","bids":[],"asks":[{"price":62791.3,"qty":4.13176919}],"checksum":3836476284,"timestamp":"2026-08-16T23:37:42.196444Z"}]}}
{"rx_ns": 42927570116000, "frame": {"channel":"book","type":"update","data":[{"symbol":"BTC/USD","bids":[],"asks":[{"price":62796.6,"qty":0.00000000},{"price":62874.0,"qty":0.60000000},{"price":62799.0,"qty":0.18489680}],"checksum":3836476284,"timestamp":"2026-08-16T23:37:42.197709Z"}]}}
{"rx_ns": 42927577241400, "frame": {"channel":"book","type":"update","data":[{"symbol":"BTC/USD","bids":[],"asks":[{"price":62844.5,"qty":0.00000000},{"price":62874.0,"qty":0.60000000}],"checksum":3836476284,"timestamp":"2026-08-16T23:37:42.202380Z"}]}}
{"rx_ns": 42927577311900, "frame": {"channel":"book","type":"update","data":[{"symbol":"BTC/USD","bids":[],"asks":[{"price":62873.1,"qty":0.06960000}],"checksum":3836476284,"timestamp":"2026-08-16T23:37:42.206037Z"}]}}
{"rx_ns": 42927602851600, "frame": {"channel":"book","type":"update","data":[{"symbol":"BTC/USD","bids":[],"asks":[{"price":62805.5,"qty":0.00000000},{"price":62874.0,"qty":0.60000000},{"price":62809.9,"qty":1.59575715}],"checksum":3836476284,"timestamp":"2026-08-16T23:37:42.230474Z"}]}}
{"rx_ns": 42927602934400, "frame": {"channel":"book","type":"update","data":[{"symbol":"BTC/USD","bids":[{"price":62763.1,"qty":0.00000000},{"price":62709.2,"qty":0.43000000},{"price":62766.1,"qty":0.10293774}],"asks":[],"checksum":3836476284,"timestamp":"2026-08-16T23:37:42.230498Z"}]}}
{"rx_ns": 42927669693700, "frame": {"channel":"heartbeat"}}
{"rx_ns": 42927967872200, "frame": {"channel":"book","type":"update","data":[{"symbol":"BTC/USD","bids":[],"asks":[{"price":62827.1,"qty":0.00000000},{"price":62874.0,"qty":0.60000000}],"checksum":3836476284,"timestamp":"2026-08-16T23:37:42.593162Z"}]}}
{"rx_ns": 42927967973300, "frame": {"channel":"book","type":"update","data":[{"symbol":"BTC/USD","bids":[],"asks":[{"price":62816.3,"qty":0.89135400}],"checksum":3836476284,"timestamp":"2026-08-16T23:37:42.594338Z"}]}}
{"rx_ns": 42928013618300, "frame": {"channel":"book","type":"update","data":[{"symbol":"BTC/USD","bids":[],"asks":[{"price":62818.6,"qty":0.00000000},{"price":62874.0,"qty":0.60000000},{"price":62801.9,"qty":0.03097706}],"checksum":3836476284,"timestamp":"2026-08-16T23:37:42.638089Z"}]}}
{"rx_ns": 42928159341000, "frame": {"channel":"book","type":"update","data":[{"symbol":"BTC/USD","bids":[{"price":62777.9,"qty":0.79645738}],"asks":[],"checksum":3836476284,"timestamp":"2026-08-16T23:37:42.778430Z"}]}}
{"rx_ns": 42928175026500, "frame": {"channel":"book","type":"update","data":[{"symbol":"BTC/USD","bids":[{"price":62778.6,"qty":0.24745577}],"asks":[],"checksum":3836476284,"timestamp":"2026-08-16T23:37:42.796330Z"}]}}
{"rx_ns": 42928246619200, "frame": {"channel":"book","type":"update","data":[{"symbol":"BTC/USD","bids":[{"price":62777.9,"qty":0.00000000},{"price":62709.2,"qty":0.43000000}],"asks":[],"checksum":3836476284,"timestamp":"2026-08-16T23:37:42.866418Z"}]}}
{"rx_ns": 42928246669000, "frame": {"channel":"book","type":"update","data":[{"symbol":"BTC/USD","bids":[],"asks":[{"price":62791.3,"qty":4.06216919}],"checksum":1902995337,"timestamp":"2026-08-16T23:37:42.866484Z"}]}}
{"rx_ns": 42928246814900, "frame": {"channel":"book","type":"update","data":[{"symbol":"BTC/USD","bids":[{"price":62779.0,"qty":0.79644427}],"asks":[],"checksum":1902995337,"timestamp":"2026-08-16T23:37:42.867916Z"}]}}
{"rx_ns": 42928246825700, "frame": {"channel":"book","type":"update","data":[{"symbol":"BTC/USD","bids":[{"price":62778.6,"qty":0.08817369}],"asks":[],"checksum":1902995337,"timestamp":"2026-08-16T23:37:42.867990Z"}]}}
{"rx_ns": 42928249410000, "frame": {"channel":"book","type":"update","data":[{"symbol":"BTC/USD","bids":[{"price":62778.0,"qty":0.01462836}],"asks":[],"checksum":1902995337,"timestamp":"2026-08-16T23:37:42.870270Z"}]}}
{"rx_ns": 42928253323100, "frame": {"channel":"book","type":"update","data":[{"symbol":"BTC/USD","bids":[{"price":62778.0,"qty":0.00422324}],"asks":[],"checksum":1902995337,"timestamp":"2026-08-16T23:37:42.871255Z"}]}}
{"rx_ns": 42928262223100, "frame": {"channel":"book","type":"update","data":[{"symbol":"BTC/USD","bids":[],"asks":[{"price":62844.8,"qty":0.03220062}],"checksum":1902995337,"timestamp":"2026-08-16T23:37:42.879046Z"}]}}
{"rx_ns": 42928264724700, "frame": {"channel":"book","type":"update","data":[{"symbol":"BTC/USD","bids":[{"price":62780.7,"qty":0.00000000},{"price":62709.2,"qty":0.43000000}],"asks":[],"checksum":4158919224,"timestamp":"2026-08-16T23:37:42.880556Z"}]}}
{"rx_ns": 42928264759500, "frame": {"channel":"book","type":"update","data":[{"symbol":"BTC/USD","bids":[{"price":62773.1,"qty":0.00000000},{"price":62707.9,"qty":0.00079734}],"asks":[],"checksum":4158919224,"timestamp":"2026-08-16T23:37:42.880955Z"}]}}
{"rx_ns": 42928265616800, "frame": {"channel":"book","type":"update","data":[{"symbol":"BTC/USD","bids":[{"price":62781.6,"qty":0.79641162}],"asks":[],"checksum":3037433,"timestamp":"2026-08-16T23:37:42.883016Z"}]}}
{"rx_ns": 42928265664500, "frame": {"channel":"book","type":"update","data":[{"symbol":"BTC/USD","bids":[{"price":62775.6,"qty":0.79648738}],"asks":[],"checksum":3037433,"timestamp":"2026-08-16T23:37:42.883301Z"}]}}
{"rx_ns": 42928265676000, "frame": {"channel":"book","type":"update","data":[{"symbol":"BTC/USD","bids":[{"price":62778.0,"qty":0.01462836}],"asks":[],"checksum":3037433,"timestamp":"2026-08-16T23:37:42.883344Z"}]}}
{"rx_ns": 42928270923700, "frame": {"channel":"book","type":"update","data":[{"symbol":"BTC/USD","bids":[{"price":62778.0,"qty":0.00422324}],"asks":[],"checksum":3037433,"timestamp":"2026-08-16T23:37:42.886733Z"}]}}
{"rx_ns": 42928277874100, "frame": {"channel":"book","type":"update","data":[{"symbol":"BTC/USD","bids":[{"price":62779.0,"qty":0.95572635}],"asks":[],"checksum":3037433,"timestamp":"2026-08-16T23:37:42.896527Z"}]}}
{"rx_ns": 42928326895100, "frame": {"channel":"book","type":"update","data":[{"symbol":"BTC/USD","bids":[],"asks":[{"price":62844.8,"qty":0.00000000},{"price":62874.0,"qty":0.60000000}],"checksum":3037433,"timestamp":"2026-08-16T23:37:42.946802Z"}]}}
{"rx_ns": 42928329204000, "frame": {"channel":"book","type":"update","data":[{"symbol":"BTC/USD","bids":[],"asks":[{"price":62873.1,"qty":0.06960000}],"checksum":3037433,"timestamp":"2026-08-16T23:37:42.950383Z"}]}}
{"rx_ns": 42928337918600, "frame": {"channel":"book","type":"update","data":[{"symbol":"BTC/USD","bids":[{"price":62771.3,"qty":0.00000000},{"price":62709.2,"qty":0.43000000},{"price":62773.7,"qty":0.03185598}],"asks":[],"checksum":3037433,"timestamp":"2026-08-16T23:37:42.960077Z"}]}}
{"rx_ns": 42928352750000, "frame": {"channel":"book","type":"update","data":[{"symbol":"BTC/USD","bids":[{"price":62778.0,"qty":0.00740907}],"asks":[],"checksum":3037433,"timestamp":"2026-08-16T23:37:42.979509Z"}]}}
{"rx_ns": 42928397172600, "frame": {"channel":"book","type":"update","data":[{"symbol":"BTC/USD","bids":[],"asks":[{"price":62800.8,"qty":0.00000000},{"price":62874.0,"qty":0.60000000},{"price":62805.5,"qty":0.19620257}],"checksum":3037433,"timestamp":"2026-08-16T23:37:43.025629Z"}]}}
{"rx_ns": 42928483129100, "frame": {"channel":"book","type":"update","data":[{"symbol":"BTC/USD","bids":[{"price":62779.1,"qty":0.08000431}],"asks":[],"checksum":3037433,"timestamp":"2026-08-16T23:37:43.110660Z"}]}}
{"rx_ns": 42928513992100, "frame": {"channel":"book","type":"update","data":[{"symbol":"BTC/USD","bids":[],"asks":[{"price":62805.5,"qty":0.00000000},{"price":62874.0,"qty":0.60000000},{"price":62801.3,"qty":0.19938754}],"checksum":3037433,"timestamp":"2026-08-16T23:37:43.141309Z"}]}}
{"rx_ns": 42928670260000, "frame": {"channel":"heartbeat"}}
{"rx_ns": 42928746585500, "frame": {"channel":"book","type":"update","data":[{"symbol":"BTC/USD","bids":[],"asks":[{"price":62799.1,"qty":0.00000000},{"price":62875.0,"qty":0.04717193}],"checksum":3037433,"timestamp":"2026-08-16T23:37:43.371769Z"}]}}
{"rx_ns": 42928746654500, "frame": {"channel":"book","type":"update","data":[{"symbol":"BTC/USD","bids":[],"asks":[{"price":62802.4,"qty":0.06000000}],"checksum":3037433,"timestamp":"2026-08-16T23:37:43.371976Z"}]}}
{"rx_ns": 42928747960500, "frame": {"channel":"book","type":"update","data":[{"symbol":"BTC/USD","bids":[],"asks":[{"price":62799.0,"qty":0.00000000},{"price":62875.0,"qty":0.04717193},{"price":62800.8,"qty":0.18489680}],"checksum":3037433,"timestamp":"2026-08-16T23:37:43.372955Z"}]}}
{"rx_ns": 42928922222400, "frame": {"channel":"book","type":"update","data":[{"symbol":"BTC/USD","bids":[{"price":62726.0,"qty":0.00000000},{"price":62709.2,"qty":0.43000000}],"asks":[],"checksum":3037433,"timestamp":"2026-08-16T23:37:43.549825Z"}]}}
{"rx_ns": 42928922278200, "frame": {"channel":"book","type":"update","data":[{"symbol":"BTC/USD","bids":[{"price":62729.0,"qty":0.00000000},{"price":62707.9,"qty":0.00079734}],"asks":[],"checksum":3037433,"timestamp":"2026-08-16T23:37:43.549903Z"}]}}
{"rx_ns": 42928926322200, "frame": {"channel":"book","type":"update","data":[{"symbol":"BTC/USD","bids":[{"price":62729.1,"qty":5.19296466}],"asks":[],"checksum":3037433,"timestamp":"2026-08-16T23:37:43.553028Z"}]}}
{"rx_ns": 42928926355600, "frame": {"channel":"book","type":"update","data":[{"symbol":"BTC/USD","bids":[{"price":62728.1,"qty":0.21072376}],"asks":[],"checksum":3037433,"timestamp":"2026-08-16T23:37:43.553233Z"}]}}
{"rx_ns": 42928932096200, "frame": {"channel":"book","type":"update","data":[{"symbol":"BTC/USD","bids":[],"asks":[{"price":62808.1,"qty":0.00159200}],"checksum":3037433,"timestamp":"2026-08-16T23:37:43.561021Z"}]}}
{"rx_ns": 42928983231700, "frame": {"channel":"book","type":"update","data":[{"symbol":"BTC/USD","bids":[],"asks":[{"price":62828.4,"qty":0.00000000},{"price":62874.0,"qty":0.60000000}],"checksum":3037433,"timestamp":"2026-08-16T23:37:43.610207Z"}]}}
{"rx_ns": 42928983305000, "frame": {"channel":"book","type":"update","data":[{"symbol":"BTC/USD","bids":[],"asks":[{"price":62832.8,"qty":0.00000000},{"price":62875.0,"qty":0.04717193}],"checksum":3037433,"timestamp":"2026-08-16T23:37:43.610225Z"}]}}
{"rx_ns": 42928983319100, "frame": {"channel":"book","type":"update","data":[{"symbol":"BTC/USD","bids":[],"asks":[{"price":62828.7,"qty":0.00000000},{"price":62875.2,"qty":5.56658959}],"checksum":3037433,"timestamp":"2026-08-16T23:37:43.610408Z"}]}}
{"rx_ns": 42928988958500, "frame": {"channel":"book","type":"update","data":[{"symbol":"BTC/USD","bids":[],"asks":[{"price":62828.3,"qty":0.37368842}],"checksum":3037433,"timestamp":"2026-08-16T23:37:43.617895Z"}]}}
{"rx_ns": 42928992150500, "frame": {"channel":"book","type":"update","data":[{"symbol":"BTC/USD","bids":[],"asks":[{"price":62828.6,"qty":1.02628222}],"checksum":3037433,"timestamp":"2026-08-16T23:37:43.617915Z"}]}}
{"rx_ns": 42928992232900, "frame": {"channel":"book","type":"update","data":[{"symbol":"BTC/USD","bids":[],"asks":[{"price":62832.7,"qty":1.25196935}],"checksum":3037433,"timestamp":"2026-08-16T23:37:43.618464Z"}]}}
{"rx_ns": 42929031698300, "frame": {"channel":"book","type":"update","data":[{"symbol":"BTC/USD","bids":[],"asks":[{"price":62810.3,"qty":0.00000000},{"price":62874.0,"qty":0.60000000},{"price":62809.8,"qty":0.00222509}],"checksum":3037433,"timestamp":"2026-08-16T23:37:43.660018Z"}]}}
{"rx_ns": 42929670270900, "frame": {"channel":"heartbeat"}}
{"rx_ns": 42929855655100, "frame": {"channel":"book","type":"update","data":[{"symbol":"BTC/USD","bids":[{"price":62721.0,"qty":0.00000000},{"price":62709.2,"qty":0.43000000},{"price":62738.1,"qty":0.70609000}],"asks":[],"checksum":3037433,"timestamp":"2026-08-16T23:37:44.481982Z"}]}}
{"rx_ns": 42929855729800, "frame": {"channel":"book","type":"update","data":[{"symbol":"BTC/USD","bids":[{"price":62718.0,"qty":0.00015944},{"price":62752.5,"qty":0.35581000}],"asks":[],"checksum":3037433,"timestamp":"2026-08-16T23:37:44.482073Z"}]}}
{"rx_ns": 42930117914700, "frame": {"channel":"book","type":"update","data":[{"symbol":"BTC/USD","bids":[],"asks":[{"price":62846.2,"qty":0.03257960}],"checksum":3037433,"timestamp":"2026-08-16T23:37:44.746059Z"}]}}
{"rx_ns": 42930374594500, "frame": {"channel":"book","type":"update","data":[{"symbol":"BTC/USD","bids":[],"asks":[{"price":62846.9,"qty":0.00000000},{"price":62874.0,"qty":0.60000000},{"price":62846.1,"qty":0.00660000}],"checksum":3037433,"timestamp":"2026-08-16T23:37:45.003165Z"}]}}
{"rx_ns": 42930521642600, "frame": {"channel":"book","type":"update","data":[{"symbol":"BTC/USD","bids":[],"asks":[{"price":62791.3,"qty":4.06201926}],"checksum":4116625613,"timestamp":"2026-08-16T23:37:45.146951Z"}]}}
{"rx_ns": 42930521694900, "frame": {"channel":"book","type":"update","data":[{"symbol":"BTC/USD","bids":[],"asks":[{"price":62804.0,"qty":0.13109402}],"checksum":4116625613,"timestamp":"2026-08-16T23:37:45.149599Z"}]}}
{"rx_ns": 42930527315100, "frame": {"channel":"book","type":"update","data":[{"symbol":"BTC/USD","bids":[],"asks":[{"price":62791.3,"qty":4.14001926}],"checksum":2432504321,"timestamp":"2026-08-16T23:37:45.150387Z"}]}}
{"rx_ns": 42930617974200, "frame": {"channel":"book","type":"update","data":[{"symbol":"BTC/USD","bids":[{"price":62729.6,"qty":0.00000000},{"price":62710.2,"qty":0.00159400}],"asks":[],"checksum":2432504321,"timestamp":"2026-08-16T23:37:45.245983Z"}]}}
{"rx_ns": 42930619140500, "frame": {"channel":"book","type":"update","data":[{"symbol":"BTC/USD","bids":[],"asks":[{"price":62859.1,"qty":0.00000000},{"price":62871.7,"qty":5.56689713}],"checksum":2432504321,"timestamp":"2026-08-16T23:37:45.246221Z"}]}}
{"rx_ns": 42930621452400, "frame": {"channel":"book","type":"update","data":[{"symbol":"BTC/USD","bids":[],"asks":[{"price":62810.4,"qty":0.00000000},{"price":62874.0,"qty":0.60000000}],"checksum":2432504321,"timestamp":"2026-08-16T23:37:45.250146Z"}]}}
{"rx_ns": 42930624450100, "frame": {"channel":"book","type":"update","data":[{"symbol":"BTC/USD","bids":[],"asks":[{"price":62873.1,"qty":0.06960000}],"checksum":2432504321,"timestamp":"2026-08-16T23:37:45.252350Z"}]}}
{"rx_ns": 42930671582400, "frame": {"channel":"heartbeat"}}
{"rx_ns": 42930845467300, "frame": {"channel":"book","type":"update","data":[{"symbol":"BTC/USD","bids":[],"asks":[{"price":62862.7,"qty":0.00000000},{"price":62874.0,"qty":0.60000000}],"checksum":2432504321,"timestamp":"2026-08-16T23:37:45.474028Z"}]}}
{"rx_ns": 42931268813800, "frame": {"channel":"book","type":"update","data":[{"symbol":"BTC/USD","bids":[{"price":62729.1,"qty":0.00000000},{"price":62709.2,"qty":0.43000000}],"asks":[],"checksum":2432504321,"timestamp":"2026-08-16T23:37:45.891091Z"}]}}
{"rx_ns": 42931268861500, "frame": {"channel":"book","type":"update","data":[{"symbol":"BTC/USD","bids":[{"price":62728.1,"qty":0.00000000},{"price":62707.9,"qty":0.00079734}],"asks":[],"checksum":2432504321,"timestamp":"2026-08-16T23:37:45.891103Z"}]}}
{"rx_ns": 42931270942700, "frame": {"channel":"book","type":"update","data":[{"symbol":"BTC/USD","bids":[{"price":62728.1,"qty":0.50654749}],"asks":[],"checksum":2432504321,"timestamp":"2026-08-16T23:37:45.894478Z"}]}}
{"rx_ns": 42931270989800, "frame": {"channel":"book","type":"update","data":[{"symbol":"BTC/USD","bids":[{"price":62729.2,"qty":4.75365972}],"asks":[],"checksum":2432504321,"timestamp":"2026-08-16T23:37:45.894544Z"}]}}
{"rx_ns": 42931321989900, "frame": {"channel":"book","type":"update","data":[{"symbol":"BTC/USD","bids":[],"asks":[{"price":62828.6,"qty":0.00000000},{"price":62875.0,"qty":0.04717193}],"checksum":2432504321,"timestamp":"2026-08-16T23:37:45.949743Z"}]}}
{"rx_ns": 42931322053000, "frame": {"channel":"book","type":"update","data":[{"symbol":"BTC/USD","bids":[],"asks":[{"price":62832.7,"qty":0.00000000},{"price":62875.2,"qty":5.56658959}],"checksum":2432504321,"timestamp":"2026-08-16T23:37:45.949820Z"}]}}
{"rx_ns": 42931322064100, "frame": {"channel":"book","type":"update","data":[{"symbol":"BTC/USD","bids":[],"asks":[{"price":62828.3,"qty":0.00000000},{"price":62875.9,"qty":0.47930876}],"checksum":2432504321,"timestamp":"2026-08-16T23:37:45.949849Z"}]}}
{"rx_ns": 42931329740100, "frame": {"channel":"book","type":"update","data":[{"symbol":"BTC/USD","bids":[],"asks":[{"price":62832.6,"qty":1.59069739}],"checksum":2432504321,"timestamp":"2026-08-16T23:37:45.956164Z"}]}}
{"rx_ns": 42931329794100, "frame": {"channel":"book","type":"update","data":[{"symbol":"BTC/USD","bids":[],"asks":[{"price":62828.5,"qty":1.05735811}],"checksum":2432504321,"timestamp":"2026-08-16T23:37:45.956216Z"}]}}
{"rx_ns": 42931673590700, "frame": {"channel":"heartbeat"}}
{"rx_ns": 42932103620000, "frame": {"channel":"book","type":"update","data":[{"symbol":"BTC/USD","bids":[],"asks":[{"price":62846.2,"qty":0.00000000},{"price":62875.2,"qty":5.56658959}],"checksum":2432504321,"timestamp":"2026-08-16T23:37:46.730209Z"}]}}
{"rx_ns": 42932135001200, "frame": {"channel":"book","type":"update","data":[{"symbol":"BTC/USD","bids":[{"price":62781.6,"qty":0.00000000},{"price":62707.9,"qty":0.00079734}],"asks":[],"checksum":2612230967,"timestamp":"2026-08-16T23:37:46.763838Z"}]}}
{"rx_ns": 42932136632300, "frame": {"channel":"book","type":"update","data":[{"symbol":"BTC/USD","bids":[{"price":62779.0,"qty":0.15928208}],"asks":[],"checksum":2612230967,"timestamp":"2026-08-16T23:37:46.763931Z"}]}}
{"rx_ns": 42932137138100, "frame": {"channel":"book","type":"update","data":[{"symbol":"BTC/USD","bids":[{"price":62782.3,"qty":0.79640177}],"asks":[],"checksum":665890636,"timestamp":"2026-08-16T23:37:46.765548Z"}]}}
{"rx_ns": 42932137153600, "frame": {"channel":"book","type":"update","data":[{"symbol":"BTC/USD","bids":[{"price":62780.2,"qty":0.79642925}],"asks":[],"checksum":665890636,"timestamp":"2026-08-16T23:37:46.765886Z"}]}}
{"rx_ns": 42932358879400, "frame": {"channel":"book","type":"update","data":[{"symbol":"BTC/USD","bids":[],"asks":[{"price":62846.1,"qty":0.00000000},{"price":62875.9,"qty":0.47930876},{"price":62846.9,"qty":0.00660000}],"checksum":665890636,"timestamp":"2026-08-16T23:37:46.987516Z"}]}}
{"rx_ns": 42932443375300, "frame": {"channel":"book","type":"update","data":[{"symbol":"BTC/USD","bids":[],"asks":[{"price":62792.3,"qty":0.00000000},{"price":62875.9,"qty":0.47930876}],"checksum":3071886888,"timestamp":"2026-08-16T23:37:47.066992Z"}]}}
{"rx_ns": 42932443427600, "frame": {"channel":"book","type":"update","data":[{"symbol":"BTC/USD","bids":[],"asks":[{"price":62791.3,"qty":3.98073718}],"checksum":2794503,"timestamp":"2026-08-16T23:37:47.067184Z"}]}}
{"rx_ns": 42932445258000, "frame": {"channel":"book","type":"update","data":[{"symbol":"BTC/USD","bids":[],"asks":[{"price":62791.3,"qty":3.90273718}],"checksum":1286414513,"timestamp":"2026-08-16T23:37:47.070032Z"}]}}
{"rx_ns": 42932445305400, "frame": {"channel":"book","type":"update","data":[{"symbol":"BTC/USD","bids":[],"asks":[{"price":62792.2,"qty":0.00000000},{"price":62876.4,"qty":0.23890000},{"price":62792.3,"qty":0.05598472}],"checksum":365014320,"timestamp":"2026-08-16T23:37:47.070176Z"}]}}
{"rx_ns": 42932495442600, "frame": {"channel":"book","type":"update","data":[{"symbol":"BTC/USD","bids":[],"asks":[{"price":62791.3,"qty":4.06201926}],"checksum":2346082661,"timestamp":"2026-08-16T23:37:47.123472Z"}]}}
{"rx_ns": 42932498262900, "frame": {"channel":"book","type":"update","data":[{"symbol":"BTC/USD","bids":[],"asks":[{"price":62791.3,"qty":4.14001926}],"checksum":4000697257,"timestamp":"2026-08-16T23:37:47.127333Z"}]}}
{"rx_ns": 42932577993500, "frame": {"channel":"book","type":"update","data":[{"symbol":"BTC/USD","bids":[],"asks":[{"price":62821.9,"qty":0.00000000},{"price":62876.4,"qty":0.23890000},{"price":62821.8,"qty":0.28000000}],"checksum":4000697257,"timestamp":"2026-08-16T23:37:47.206201Z"}]}}
{"rx_ns": 42932671987600, "frame": {"channel":"heartbeat"}}
{"rx_ns": 42932764896300, "frame": {"channel":"book","type":"update","data":[{"symbol":"BTC/USD","bids":[{"price":62725.7,"qty":0.00000000},{"price":62709.2,"qty":0.43000000}],"asks":[],"checksum":4000697257,"timestamp":"2026-08-16T23:37:47.393366Z"}]}}
{"rx_ns": 42932766622600, "frame": {"channel":"book","type":"update","data":[{"symbol":"BTC/USD","bids":[],"asks":[{"price":62847.5,"qty":0.03140444}],"checksum":4000697257,"timestamp":"2026-08-16T23:37:47.394223Z"}]}}
{"rx_ns": 42932766715800, "frame": {"channel":"book","type":"update","data":[{"symbol":"BTC/USD","bids":[{"price":62734.8,"qty":0.55709900}],"asks":[],"checksum":4000697257,"timestamp":"2026-08-16T23:37:47.394799Z"}]}}
{"rx_ns": 42932788446900, "frame": {"channel":"book","type":"update","data":[{"symbol":"BTC/USD","bids":[],"asks":[{"price":62862.7,"qty":0.00600000}],"checksum":4000697257,"timestamp":"2026-08-16T23:37:47.416997Z"}]}}
{"rx_ns": 42932858429300, "frame": {"channel":"book","type":"update","data":[{"symbol":"BTC/USD","bids":[],"asks":[{"price":62796.7,"qty":0.00000000},{"price":62875.2,"qty":5.56658959}],"checksum":1818694345,"timestamp":"2026-08-16T23:37:47.477347Z"}]}}
{"rx_ns": 42932858507800, "frame": {"channel":"book","type":"update","data":[{"symbol":"BTC/USD","bids":[],"asks":[{"price":62799.1,"qty":0.50933400}],"checksum":1818694345,"timestamp":"2026-08-16T23:37:47.479508Z"}]}}
{"rx_ns": 42932858549800, "frame": {"channel":"book","type":"update","data":[{"symbol":"BTC/USD","bids":[{"price":62782.3,"qty":0.00000000},{"price":62709.2,"qty":0.43000000}],"asks":[],"checksum":1222293778,"timestamp":"2026-08-16T23:37:47.481592Z"}]}}
{"rx_ns": 42932858566000, "frame": {"channel":"book","type":"update","data":[{"symbol":"BTC/USD","bids":[],"asks":[{"price":62847.5,"qty":0.00000000},{"price":62875.2,"qty":5.56658959}],"checksum":1222293778,"timestamp":"2026-08-16T23:37:47.481617Z"}]}}
{"rx_ns": 42932858577700, "frame": {"channel":"book","type":"update","data":[{"symbol":"BTC/USD","bids":[{"price":62783.1,"qty":0.79639225}],"asks":[],"checksum":3503003054,"timestamp":"2026-08-16T23:37:47.483113Z"}]}}
{"rx_ns": 42932940998200, "frame": {"channel":"book","type":"update","data":[{"symbol":"BTC/USD","bids":[{"price":62772.2,"qty":0.03185537}],"asks":[],"checksum":3503003054,"timestamp":"2026-08-16T23:37:47.562505Z"}]}}
{"rx_ns": 42932941096100, "frame": {"channel":"book","type":"update","data":[{"symbol":"BTC/USD","bids":[{"price":62772.2,"qty":0.00000000},{"price":62709.2,"qty":0.43000000}],"asks":[],"checksum":3503003054,"timestamp":"2026-08-16T23:37:47.565674Z"}]}}
{"rx_ns": 42932941530900, "frame": {"channel":"book","type":"update","data":[{"symbol":"BTC/USD","bids":[{"price":62773.7,"qty":0.07963767}],"asks":[],"checksum":3503003054,"timestamp":"2026-08-16T23:37:47.569572Z"}]}}
{"rx_ns": 42932946678300, "frame": {"channel":"book","type":"update","data":[{"symbol":"BTC/USD","bids":[{"price":62775.4,"qty":0.03185507}],"asks":[],"checksum":3503003054,"timestamp":"2026-08-16T23:37:47.572863Z"}]}}
{"rx_ns": 42932986001600, "frame": {"channel":"book","type":"update","data":[{"symbol":"BTC/USD","bids":[],"asks":[{"price":62801.3,"qty":0.00318497},{"price":62805.5,"qty":0.19620257}],"checksum":3503003054,"timestamp":"2026-08-16T23:37:47.614400Z"}]}}
{"rx_ns": 42933062522600, "frame": {"channel":"book","type":"update","data":[{"symbol":"BTC/USD","bids":[{"price":62761.5,"qty":0.00000000},{"price":62709.2,"qty":0.43000000}],"asks":[],"checksum":3503003054,"timestamp":"2026-08-16T23:37:47.659253Z"}]}}
{"rx_ns": 42933062585800, "frame": {"channel":"book","type":"update","data":[{"symbol":"BTC/USD","bids":[],"asks":[{"price":62799.1,"qty":0.00000000},{"price":62875.2,"qty":5.56658959}],"checksum":3503003054,"timestamp":"2026-08-16T23:37:47.659480Z"}]}}
{"rx_ns": 42933062601500, "frame": {"channel":"book","type":"update","data":[{"symbol":"BTC/USD","bids":[{"price":62772.2,"qty":0.39256500}],"asks":[],"checksum":3503003054,"timestamp":"2026-08-16T23:37:47.660221Z"}]}}
{"rx_ns": 42933062613100, "frame": {"channel":"book","type":"update","data":[{"symbol":"BTC/USD","bids":[],"asks":[{"price":62795.4,"qty":0.50933300}],"checksum":2417761487,"timestamp":"2026-08-16T23:37:47.660358Z"}]}}
{"rx_ns": 42933605058400, "frame": {"channel":"book","type":"update","data":[{"symbol":"BTC/USD","bids":[],"asks":[{"price":62828.5,"qty":0.00000000},{"price":62875.2,"qty":5.56658959}],"checksum":2417761487,"timestamp":"2026-08-16T23:37:48.223796Z"}]}}
{"rx_ns": 42933605529700, "frame": {"channel":"book","type":"update","data":[{"symbol":"BTC/USD","bids":[],"asks":[{"price":62832.6,"qty":0.00000000},{"price":62875.3,"qty":0.01000000}],"checksum":2417761487,"timestamp":"2026-08-16T23:37:48.224215Z"}]}}
{"rx_ns": 42933613373100, "frame": {"channel":"book","type":"update","data":[{"symbol":"BTC/USD","bids":[],"asks":[{"price":62828.4,"qty":1.05735811}],"checksum":2417761487,"timestamp":"2026-08-16T23:37:48.227368Z"}]}}
{"rx_ns": 42933613436800, "frame": {"channel":"book","type":"update","data":[{"symbol":"BTC/USD","bids":[],"asks":[{"price":62832.5,"qty":1.74219238}],"checksum":2417761487,"timestamp":"2026-08-16T23:37:48.227426Z"}]}}
{"rx_ns": 42933681636800, "frame": {"channel":"book","type":"update","data":[{"symbol":"BTC/USD","bids":[{"price":62728.1,"qty":0.00000000},{"price":62709.2,"qty":0.43000000}],"asks":[],"checksum":2417761487,"timestamp":"2026-08-16T23:37:48.294996Z"}]}}
{"rx_ns": 42933681687200, "frame": {"channel":"book","type":"update","data":[{"symbol":"BTC/USD","bids":[{"price":62729.2,"qty":0.00159400}],"asks":[],"checksum":2417761487,"timestamp":"2026-08-16T23:37:48.295016Z"}]}}
{"rx_ns": 42933681714700, "frame": {"channel":"heartbeat"}}
{"rx_ns": 42933697644300, "frame": {"channel":"book","type":"update","data":[{"symbol":"BTC/USD","bids":[{"price":62728.2,"qty":1.00499022}],"asks":[],"checksum":2417761487,"timestamp":"2026-08-16T23:37:48.315628Z"}]}}
{"rx_ns": 42933697716500, "frame": {"channel":"book","type":"update","data":[{"symbol":"BTC/USD","bids":[{"price":62729.3,"qty":4.15555540}],"asks":[],"checksum":2417761487,"timestamp":"2026-08-16T23:37:48.315848Z"}]}}
{"rx_ns": 42933728037700, "frame": {"channel":"book","type":"update","data":[{"symbol":"BTC/USD","bids":[],"asks":[{"price":62821.8,"qty":0.00000000},{"price":62875.2,"qty":5.56658959},{"price":62821.7,"qty":0.28000000}],"checksum":2417761487,"timestamp":"2026-08-16T23:37:48.352639Z"}]}}
{"rx_ns": 42933760215100, "frame": {"channel":"book","type":"update","data":[{"symbol":"BTC/USD","bids":[],"asks":[{"price":62805.5,"qty":0.00000000},{"price":62875.2,"qty":5.56658959},{"price":62801.3,"qty":0.19938754}],"checksum":2417761487,"timestamp":"2026-08-16T23:37:48.385458Z"}]}}
{"rx_ns": 42933760291800, "frame": {"channel":"book","type":"update","data":[{"symbol":"BTC/USD","bids":[{"price":62783.1,"qty":0.00000000},{"price":62710.2,"qty":0.00159400}],"asks":[],"checksum":1079557880,"timestamp":"2026-08-16T23:37:48.385734Z"}]}}
{"rx_ns": 42933760322700, "frame": {"channel":"book","type":"update","data":[{"symbol":"BTC/USD","bids":[{"price":62781.6,"qty":0.79641163}],"asks":[],"checksum":3975812723,"timestamp":"2026-08-16T23:37:48.387190Z"}]}}
{"rx_ns": 42933768964800, "frame": {"channel":"book","type":"update","data":[{"symbol":"BTC/USD","bids":[],"asks":[{"price":62847.7,"qty":0.03223883}],"checksum":3975812723,"timestamp":"2026-08-16T23:37:48.396021Z"}]}}
{"rx_ns": 42934383714200, "frame": {"channel":"book","type":"update","data":[{"symbol":"BTC/USD","bids":[{"price":62775.4,"qty":0.00000000},{"price":62710.2,"qty":0.00159400},{"price":62773.1,"qty":0.07963874}],"asks":[],"checksum":3975812723,"timestamp":"2026-08-16T23:37:49.008425Z"}]}}
{"rx_ns": 42934543672200, "frame": {"channel":"book","type":"update","data":[{"symbol":"BTC/USD","bids":[{"price":62760.0,"qty":0.00000000},{"price":62710.2,"qty":0.00159400}],"asks":[],"checksum":3975812723,"timestamp":"2026-08-16T23:37:49.169761Z"}]}}
{"rx_ns": 42934663237800, "frame": {"channel":"book","type":"update","data":[{"symbol":"BTC/USD","bids":[{"price":62766.1,"qty":0.00000000},{"price":62709.2,"qty":0.43000000},{"price":62765.7,"qty":0.10293839}],"asks":[],"checksum":3975812723,"timestamp":"2026-08-16T23:37:49.289896Z"}]}}
{"rx_ns": 42934676441200, "frame": {"channel":"heartbeat"}}
{"rx_ns": 42934687681400, "frame": {"channel":"book","type":"update","data":[{"symbol":"BTC/USD","bids":[{"price":62765.7,"qty":0.00000000},{"price":62709.2,"qty":0.43000000},{"price":62766.1,"qty":0.10293774}],"asks":[],"checksum":3975812723,"timestamp":"2026-08-16T23:37:49.301900Z"}]}}
{"rx_ns": 42934687747300, "frame": {"channel":"book","type":"update","data":[{"symbol":"BTC/USD","bids":[{"price":62729.6,"qty":0.05384617}],"asks":[],"checksum":3975812723,"timestamp":"2026-08-16T23:37:49.307978Z"}]}}
{"rx_ns": 42934687762700, "frame": {"channel":"book","type":"update","data":[{"symbol":"BTC/USD","bids":[],"asks":[{"price":62858.0,"qty":0.06448727}],"checksum":3975812723,"timestamp":"2026-08-16T23:37:49.309770Z"}]}}
{"rx_ns": 42935283480600, "frame": {"channel":"book","type":"update","data":[{"symbol":"BTC/USD","bids":[],"asks":[{"price":62794.1,"qty":0.46828931}],"checksum":347180296,"timestamp":"2026-08-16T23:37:49.911196Z"}]}}
{"rx_ns": 42935444912800, "frame": {"channel":"book","type":"update","data":[{"symbol":"BTC/USD","bids":[{"price":62781.6,"qty":0.00000000},{"price":62710.2,"qty":0.00159400}],"asks":[],"checksum":1768795173,"timestamp":"2026-08-16T23:37:50.072055Z"}]}}
{"rx_ns": 42935448934100, "frame": {"channel":"book","type":"update","data":[{"symbol":"BTC/USD","bids":[{"price":62782.3,"qty":0.79640231}],"asks":[],"checksum":1708808869,"timestamp":"2026-08-16T23:37:50.074516Z"}]}}
{"rx_ns": 42935529179800, "frame": {"channel":"book","type":"update","data":[{"symbol":"BTC/USD","bids":[],"asks":[{"price":62793.6,"qty":0.00000000},{"price":62875.0,"qty":0.04717193},{"price":62791.3,"qty":4.14801926}],"checksum":177492051,"timestamp":"2026-08-16T23:37:50.110773Z"}]}}
{"rx_ns": 42935625834800, "frame": {"channel":"book","type":"update","data":[{"symbol":"BTC/USD","bids":[{"price":62779.0,"qty":0.00000000},{"price":62710.2,"qty":0.00159400}],"asks":[],"checksum":177492051,"timestamp":"2026-08-16T23:37:50.236721Z"}]}}
{"rx_ns": 42935625892500, "frame": {"channel":"book","type":"update","data":[{"symbol":"BTC/USD","bids":[{"price":62774.8,"qty":0.00000000},{"price":62709.2,"qty":0.43000000}],"asks":[],"checksum":177492051,"timestamp":"2026-08-16T23:37:50.236944Z"}]}}
{"rx_ns": 42935630224500, "frame": {"channel":"book","type":"update","data":[{"symbol":"BTC/USD","bids":[{"price":62766.1,"qty":0.00000000},{"price":62707.9,"qty":0.00079734},{"price":62765.7,"qty":0.10293839}],"asks":[],"checksum":177492051,"timestamp":"2026-08-16T23:37:50.251262Z"}]}}
{"rx_ns": 42935645206100, "frame": {"channel":"book","type":"update","data":[{"symbol":"BTC/USD","bids":[{"price":62765.7,"qty":0.00000000},{"price":62707.9,"qty":0.00079734},{"price":62766.1,"qty":0.10293774}],"asks":[],"checksum":177492051,"timestamp":"2026-08-16T23:37:50.270941Z"}]}}
{"rx_ns": 42935687551900, "frame": {"channel":"heartbeat"}}
{"rx_ns": 42935718805300, "frame": {"channel":"book","type":"update","data":[{"symbol":"BTC/USD","bids":[{"price":62779.0,"qty":0.15928208}],"asks":[],"checksum":177492051,"timestamp":"2026-08-16T23:37:50.334876Z"}]}}
{"rx_ns": 42935923424800, "frame": {"channel":"book","type":"update","data":[{"symbol":"BTC/USD","bids":[{"price":62766.1,"qty":0.00000000},{"price":62709.2,"qty":0.43000000},{"price":62765.7,"qty":0.10293839}],"asks":[],"checksum":177492051,"timestamp":"2026-08-16T23:37:50.550806Z"}]}}
{"rx_ns": 42935949247200, "frame": {"channel":"book","type":"update","data":[{"symbol":"BTC/USD","bids":[],"asks":[{"price":62828.4,"qty":0.00000000},{"price":62875.2,"qty":5.56658959}],"checksum":177492051,"timestamp":"2026-08-16T23:37:50.572938Z"}]}}
{"rx_ns": 42935949315800, "frame": {"channel":"book","type":"update","data":[{"symbol":"BTC/USD","bids":[],"asks":[{"price":62832.5,"qty":0.00000000},{"price":62875.3,"qty":0.01000000}],"checksum":177492051,"timestamp":"2026-08-16T23:37:50.573128Z"}]}}
{"rx_ns": 42935949337600, "frame": {"channel":"book","type":"update","data":[{"symbol":"BTC/USD","bids":[],"asks":[{"price":62828.3,"qty":0.62229558}],"checksum":177492051,"timestamp":"2026-08-16T23:37:50.576448Z"}]}}
{"rx_ns": 42935949354600, "frame": {"channel":"book","type":"update","data":[{"symbol":"BTC/USD","bids":[],"asks":[{"price":62828.7,"qty":1.11950990}],"checksum":177492051,"timestamp":"2026-08-16T23:37:50.576533Z"}]}}
{"rx_ns": 42935949370500, "frame": {"channel":"book","type":"update","data":[{"symbol":"BTC/USD","bids":[],"asks":[{"price":62832.4,"qty":0.77432123}],"checksum":177492051,"timestamp":"2026-08-16T23:37:50.576934Z"}]}}
{"rx_ns": 42935990612900, "frame": {"channel":"book","type":"update","data":[{"symbol":"BTC/USD","bids":[{"price":62728.2,"qty":0.00000000},{"price":62709.2,"qty":0.43000000}],"asks":[],"checksum":177492051,"timestamp":"2026-08-16T23:37:50.618114Z"}]}}
{"rx_ns": 42935990663400, "frame": {"channel":"book","type":"update","data":[{"symbol":"BTC/USD","bids":[{"price":62729.3,"qty":0.00000000},{"price":62707.9,"qty":0.00079734}],"asks":[],"checksum":177492051,"timestamp":"2026-08-16T23:37:50.618161Z"}]}}
{"rx_ns": 42936007468100, "frame": {"channel":"book","type":"update","data":[{"symbol":"BTC/USD","bids":[{"price":62728.3,"qty":1.71918054}],"asks":[],"checksum":177492051,"timestamp":"2026-08-16T23:37:50.631809Z"}]}}
{"rx_ns": 42936007532300, "frame": {"channel":"book","type":"update","data":[{"symbol":"BTC/USD","bids":[{"price":62729.4,"qty":3.20183877}],"asks":[],"checksum":177492051,"timestamp":"2026-08-16T23:37:50.631929Z"}]}}
{"rx_ns": 42936042230000, "frame": {"channel":"book","type":"update","data":[{"symbol":"BTC/USD","bids":[{"price":62759.9,"qty":0.03471414}],"asks":[],"checksum":177492051,"timestamp":"2026-08-16T23:37:50.670908Z"}]}}
{"rx_ns": 42936043871600, "frame": {"channel":"book","type":"update","data":[{"symbol":"BTC/USD","bids":[{"price":62724.2,"qty":6.18395346}],"asks":[],"checksum":177492051,"timestamp":"2026-08-16T23:37:50.672400Z"}]}}
{"rx_ns": 42936045722400, "frame": {"channel":"book","type":"update","data":[{"symbol":"BTC/USD","bids":[],"asks":[{"price":62794.0,"qty":0.64949617}],"checksum":449672467,"timestamp":"2026-08-16T23:37:50.672432Z"}]}}
{"rx_ns": 42936045753500, "frame": {"channel":"book","type":"update","data":[{"symbol":"BTC/USD","bids":[{"price":62771.6,"qty":0.04193000}],"asks":[],"checksum":449672467,"timestamp":"2026-08-16T23:37:50.672475Z"}]}}
{"rx_ns": 42936045766400, "frame": {"channel":"book","type":"update","data":[{"symbol":"BTC/USD","bids":[{"price":62774.1,"qty":0.41082131}],"asks":[],"checksum":449672467,"timestamp":"2026-08-16T23:37:50.672522Z"}]}}
{"rx_ns": 42936045778900, "frame": {"channel":"book","type":"update","data":[{"symbol":"BTC/USD","bids":[],"asks":[{"price":62803.9,"qty":0.17891592}],"checksum":449672467,"timestamp":"2026-08-16T23:37:50.672641Z"}]}}
{"rx_ns": 42936045789800, "frame": {"channel":"book","type":"update","data":[{"symbol":"BTC/USD","bids":[],"asks":[{"price":62791.5,"qty":0.60522203}],"checksum":2215648505,"timestamp":"2026-08-16T23:37:50.672706Z"}]}}
{"rx_ns": 42936045800700, "frame": {"channel":"book","type":"update","data":[{"symbol":"BTC/USD","bids":[],"asks":[{"price":62837.4,"qty":2.37517679}],"checksum":2215648505,"timestamp":"2026-08-16T23:37:50.672718Z"}]}}
{"rx_ns": 42936049974900, "frame": {"channel":"book","type":"update","data":[{"symbol":"BTC/USD","bids":[{"price":62754.9,"qty":2.38018932}],"asks":[],"checksum":2215648505,"timestamp":"2026-08-16T23:37:50.673271Z"}]}}
{"rx_ns": 42936050091000, "frame": {"channel":"book","type":"update","data":[{"symbol":"BTC/USD","bids":[],"asks":[{"price":62833.0,"qty":4.47750000}],"checksum":2215648505,"timestamp":"2026-08-16T23:37:50.673347Z"}]}}
{"rx_ns": 42936050107000, "frame": {"channel":"book","type":"update","data":[{"symbol":"BTC/USD","bids":[],"asks":[{"price":62800.8,"qty":1.09420926}],"checksum":2215648505,"timestamp":"2026-08-16T23:37:50.673375Z"}]}}
{"rx_ns": 42936050116600, "frame": {"channel":"book","type":"update","data":[{"symbol":"BTC/USD","bids":[{"price":62739.7,"qty":2.58964516}],"asks":[],"checksum":2215648505,"timestamp":"2026-08-16T23:37:50.673785Z"}]}}
{"rx_ns": 42936050125300, "frame": {"channel":"book","type":"update","data":[{"symbol":"BTC/USD","bids":[],"asks":[{"price":62864.1,"qty":1.66191821}],"checksum":2215648505,"timestamp":"2026-08-16T23:37:50.673801Z"}]}}
{"rx_ns": 42936050133600, "frame": {"channel":"book","type":"update","data":[{"symbol":"BTC/USD","bids":[{"price":62746.6,"qty":3.01302065}],"asks":[],"checksum":2215648505,"timestamp":"2026-08-16T23:37:50.673932Z"}]}}
{"rx_ns": 42936050144700, "frame": {"channel":"book","type":"update","data":[{"symbol":"BTC/USD","bids":[],"asks":[{"price":62809.9,"qty":4.12118759}],"checksum":2215648505,"timestamp":"2026-08-16T23:37:50.673949Z"}]}}
{"rx_ns": 42936050154000, "frame": {"channel":"book","type":"update","data":[{"symbol":"BTC/USD","bids":[],"asks":[{"price":62818.9,"qty":2.68320903}],"checksum":2215648505,"timestamp":"2026-08-16T23:37:50.673998Z"}]}}
{"rx_ns": 42936050162600, "frame": {"channel":"book","type":"update","data":[{"symbol":"BTC/USD","bids":[{"price":62728.1,"qty":1.21764893}],"asks":[],"checksum":2215648505,"timestamp":"2026-08-16T23:37:50.674025Z"}]}}
{"rx_ns": 42936050170400, "frame": {"channel":"book","type":"update","data":[{"symbol":"BTC/USD","bids":[{"price":62765.7,"qty":1.33011695}],"asks":[],"checksum":2215648505,"timestamp":"2026-08-16T23:37:50.674054Z"}]}}
{"rx_ns": 42936050179500, "frame": {"channel":"book","type":"update","data":[{"symbol":"BTC/USD","bids":[],"asks":[{"price":62856.3,"qty":0.45271838}],"checksum":2215648505,"timestamp":"2026-08-16T23:37:50.674073Z"}]}}
{"rx_ns": 42936050187300, "frame": {"channel":"book","type":"update","data":[{"symbol":"BTC/USD","bids":[],"asks":[{"price":62845.3,"qty":2.37487879}],"checksum":2215648505,"timestamp":"2026-08-16T23:37:50.674094Z"}]}}
{"rx_ns": 42936050279800, "frame": {"channel":"book","type":"update","data":[{"symbol":"BTC/USD","bids":[{"price":62768.6,"qty":0.40304452}],"asks":[],"checksum":2215648505,"timestamp":"2026-08-16T23:37:50.674386Z"}]}}
{"rx_ns": 42936050322900, "frame": {"channel":"book","type":"update","data":[{"symbol":"BTC/USD","bids":[{"price":62752.9,"qty":0.61430234}],"asks":[],"checksum":2215648505,"timestamp":"2026-08-16T23:37:50.674456Z"}]}}
{"rx_ns": 42936050335000, "frame": {"channel":"book","type":"update","data":[{"symbol":"BTC/USD","bids":[],"asks":[{"price":62828.7,"qty":3.54160937}],"checksum":2215648505,"timestamp":"2026-08-16T23:37:50.674551Z"}]}}
{"rx_ns": 42936050344300, "frame": {"channel":"book","type":"update","data":[{"symbol":"BTC/USD","bids":[],"asks":[{"price":62835.9,"qty":0.82337489}],"checksum":2215648505,"timestamp":"2026-08-16T23:37:50.675361Z"}]}}
{"rx_ns": 42936050354300, "frame": {"channel":"book","type":"update","data":[{"symbol":"BTC/USD","bids":[],"asks":[{"price":62815.6,"qty":0.48392662}],"checksum":2215648505,"timestamp":"2026-08-16T23:37:50.675596Z"}]}}
{"rx_ns": 42936050363500, "frame": {"channel":"book","type":"update","data":[{"symbol":"BTC/USD","bids":[{"price":62749.2,"qty":0.06877231}],"asks":[],"checksum":2215648505,"timestamp":"2026-08-16T23:37:50.675785Z"}]}}
{"rx_ns": 42936050372900, "frame": {"channel":"book","type":"update","data":[{"symbol":"BTC/USD","bids":[{"price":62757.8,"qty":0.03177001}],"asks":[],"checksum":2215648505,"timestamp":"2026-08-16T23:37:50.675798Z"}]}}
{"rx_ns": 42936050419400, "frame": {"channel":"book","type":"update","data":[{"symbol":"BTC/USD","bids":[],"asks":[{"price":62813.2,"qty":0.02077560}],"checksum":2215648505,"timestamp":"2026-08-16T23:37:50.676202Z"}]}}
{"rx_ns": 42936050439200, "frame": {"channel":"book","type":"update","data":[{"symbol":"BTC/USD","bids":[{"price":62742.9,"qty":0.02138782}],"asks":[],"checksum":2215648505,"timestamp":"2026-08-16T23:37:50.676343Z"}]}}
{"rx_ns": 42936378207300, "frame": {"channel":"book","type":"update","data":[{"symbol":"BTC/USD","bids":[{"price":62765.7,"qty":1.22717856},{"price":62765.8,"qty":0.10293823}],"asks":[],"checksum":2215648505,"timestamp":"2026-08-16T23:37:51.005979Z"}]}}
{"rx_ns": 42936378257700, "frame": {"channel":"book","type":"update","data":[{"symbol":"BTC/USD","bids":[],"asks":[{"price":62809.9,"qty":2.52543044},{"price":62809.8,"qty":1.59798224}],"checksum":2215648505,"timestamp":"2026-08-16T23:37:51.006158Z"}]}}
{"rx_ns": 42936471402000, "frame": {"channel":"book","type":"update","data":[{"symbol":"BTC/USD","bids":[],"asks":[{"price":62851.9,"qty":0.00000000},{"price":62861.3,"qty":0.15888884}],"checksum":2215648505,"timestamp":"2026-08-16T23:37:51.098724Z"}]}}
{"rx_ns": 42936574711000, "frame": {"channel":"book","type":"update","data":[{"symbol":"BTC/USD","bids":[],"asks":[{"price":62858.0,"qty":0.00829947}],"checksum":2215648505,"timestamp":"2026-08-16T23:37:51.203453Z"}]}}
{"rx_ns": 42936611802600, "frame": {"channel":"book","type":"update","data":[{"symbol":"BTC/USD","bids":[{"price":62759.9,"qty":0.00000000},{"price":62724.2,"qty":6.18395346}],"asks":[],"checksum":2215648505,"timestamp":"2026-08-16T23:37:51.240600Z"}]}}
{"rx_ns": 42936696199700, "frame": {"channel":"heartbeat"}}
{"rx_ns": 42936706381200, "frame": {"channel":"book","type":"update","data":[{"symbol":"BTC/USD","bids":[],"asks":[{"price":62837.2,"qty":0.00830597}],"checksum":2215648505,"timestamp":"2026-08-16T23:37:51.325070Z"}]}}
{"rx_ns": 42936714377400, "frame": {"channel":"book","type":"update","data":[{"symbol":"BTC/USD","bids":[],"asks":[{"price":62851.8,"qty":0.00000000},{"price":62861.3,"qty":0.15888884},{"price":62854.1,"qty":0.00385951}],"checksum":2215648505,"timestamp":"2026-08-16T23:37:51.334267Z"}]}}
{"rx_ns": 42936940542600, "frame": {"channel":"book","type":"update","data":[{"symbol":"BTC/USD","bids":[],"asks":[{"price":62854.1,"qty":0.00000000},{"price":62861.3,"qty":0.15888884},{"price":62851.7,"qty":0.00385951}],"checksum":2215648505,"timestamp":"2026-08-16T23:37:51.566587Z"}]}}
{"rx_ns": 42936944943900, "frame": {"channel":"book","type":"update","data":[{"symbol":"BTC/USD","bids":[],"asks":[{"price":62851.7,"qty":0.00000000},{"price":62861.3,"qty":0.15888884},{"price":62854.1,"qty":0.00385951}],"checksum":2215648505,"timestamp":"2026-08-16T23:37:51.571279Z"}]}}
{"rx_ns": 42937088647100, "frame": {"channel":"book","type":"update","data":[{"symbol":"BTC/USD","bids":[],"asks":[{"price":62858.2,"qty":0.05391725}],"checksum":2215648505,"timestamp":"2026-08-16T23:37:51.703674Z"}]}}
{"rx_ns": 42937088694100, "frame": {"channel":"book","type":"update","data":[{"symbol":"BTC/USD","bids":[],"asks":[{"price":62821.6,"qty":0.35249249}],"checksum":2215648505,"timestamp":"2026-08-16T23:37:51.706299Z"}]}}
{"rx_ns": 42937088703900, "frame": {"channel":"book","type":"update","data":[{"symbol":"BTC/USD","bids":[],"asks":[{"price":62825.6,"qty":0.07154500}],"checksum":2215648505,"timestamp":"2026-08-16T23:37:51.707440Z"}]}}
{"rx_ns": 42937375046900, "frame": {"channel":"book","type":"update","data":[{"symbol":"BTC/USD","bids":[{"price":62765.8,"qty":0.00000000},{"price":62724.1,"qty":15.00000000},{"price":62765.7,"qty":1.33011695}],"asks":[],"checksum":2215648505,"timestamp":"2026-08-16T23:37:52.003972Z"}]}}
{"rx_ns": 42937565648100, "frame": {"channel":"book","type":"update","data":[{"symbol":"BTC/USD","bids":[{"price":62763.0,"qty":0.70843100}],"asks":[],"checksum":2215648505,"timestamp":"2026-08-16T23:37:52.193381Z"}]}}
{"rx_ns": 42937565723800, "frame": {"channel":"book","type":"update","data":[{"symbol":"BTC/USD","bids":[{"price":62766.1,"qty":0.89135700}],"asks":[],"checksum":2215648505,"timestamp":"2026-08-16T23:37:52.194669Z"}]}}
{"rx_ns": 42937665217500, "frame": {"channel":"book","type":"update","data":[{"symbol":"BTC/USD","bids":[{"price":62759.9,"qty":0.03515865}],"asks":[],"checksum":2215648505,"timestamp":"2026-08-16T23:37:52.290730Z"}]}}
{"rx_ns": 42937675080100, "frame": {"channel":"heartbeat"}}
{"rx_ns": 42937777036100, "frame": {"channel":"book","type":"update","data":[{"symbol":"BTC/USD","bids":[],"asks":[{"price":62791.3,"qty":4.22763328}],"checksum":3875586520,"timestamp":"2026-08-16T23:37:52.405728Z"}]}}
{"rx_ns": 42937875254900, "frame": {"channel":"book","type":"update","data":[{"symbol":"BTC/USD","bids":[{"price":62765.7,"qty":1.22717856},{"price":62766.1,"qty":0.99429474}],"asks":[],"checksum":3875586520,"timestamp":"2026-08-16T23:37:52.503587Z"}]}}
{"rx_ns": 42938291481600, "frame": {"channel":"book","type":"update","data":[{"symbol":"BTC/USD","bids":[],"asks":[{"price":62832.4,"qty":0.01598519}],"checksum":3875586520,"timestamp":"2026-08-16T23:37:52.917560Z"}]}}
{"rx_ns": 42938291584200, "frame": {"channel":"book","type":"update","data":[{"symbol":"BTC/USD","bids":[],"asks":[{"price":62828.3,"qty":0.00000000},{"price":62860.7,"qty":0.15930000}],"checksum":3875586520,"timestamp":"2026-08-16T23:37:52.917589Z"}]}}
{"rx_ns": 42938291606400, "frame": {"channel":"book","type":"update","data":[{"symbol":"BTC/USD","bids":[],"asks":[{"price":62828.7,"qty":2.42209947}],"checksum":3875586520,"timestamp":"2026-08-16T23:37:52.917876Z"}]}}
{"rx_ns": 42938291638300, "frame": {"channel":"book","type":"update","data":[{"symbol":"BTC/USD","bids":[{"price":62776.1,"qty":0.46828931}],"asks":[],"checksum":3875586520,"timestamp":"2026-08-16T23:37:52.919808Z"}]}}
{"rx_ns": 42938293776800, "frame": {"channel":"book","type":"update","data":[{"symbol":"BTC/USD","bids":[],"asks":[{"price":62828.6,"qty":1.58564833}],"checksum":3875586520,"timestamp":"2026-08-16T23:37:52.921056Z"}]}}
{"rx_ns": 42938330800600, "frame": {"channel":"book","type":"update","data":[{"symbol":"BTC/USD","bids":[{"price":62729.4,"qty":0.00000000},{"price":62725.9,"qty":5.57982866}],"asks":[],"checksum":3875586520,"timestamp":"2026-08-16T23:37:52.958650Z"}]}}
{"rx_ns": 42938330850400, "frame": {"channel":"book","type":"update","data":[{"symbol":"BTC/USD","bids":[{"price":62728.3,"qty":0.00000000},{"price":62724.2,"qty":6.18395346}],"asks":[],"checksum":3875586520,"timestamp":"2026-08-16T23:37:52.958672Z"}]}}
{"rx_ns": 42938344266400, "frame": {"channel":"book","type":"update","data":[{"symbol":"BTC/USD","bids":[{"price":62729.5,"qty":3.49741351}],"asks":[],"checksum":3875586520,"timestamp":"2026-08-16T23:37:52.972885Z"}]}}
{"rx_ns": 42938672854200, "frame": {"channel":"heartbeat"}}
{"rx_ns": 42939399764200, "frame": {"channel":"book","type":"update","data":[{"symbol":"BTC/USD","bids":[],"asks":[{"price":62820.1,"qty":0.00000000},{"price":62860.7,"qty":0.15930000}],"checksum":3875586520,"timestamp":"2026-08-16T23:37:54.028071Z"}]}}
{"rx_ns": 42939401533500, "frame": {"channel":"book","type":"update","data":[{"symbol":"BTC/USD","bids":[],"asks":[{"price":62821.5,"qty":1.02987080}],"checksum":3875586520,"timestamp":"2026-08-16T23:37:54.030562Z"}]}}
{"rx_ns": 42939646499300, "frame": {"channel":"book","type":"update","data":[{"symbol":"BTC/USD","bids":[{"price":62763.8,"qty":0.00000000},{"price":62724.2,"qty":6.18395346}],"asks":[],"checksum":3875586520,"timestamp":"2026-08-16T23:37:54.263700Z"}]}}
{"rx_ns": 42939676368900, "frame": {"channel":"heartbeat"}}
{"rx_ns": 42940637818000, "frame": {"channel":"book","type":"update","data":[{"symbol":"BTC/USD","bids":[{"price":62729.5,"qty":0.00000000},{"price":62724.1,"qty":15.00000000}],"asks":[],"checksum":3875586520,"timestamp":"2026-08-16T23:37:55.263265Z"}]}}
{"rx_ns": 42940640080200, "frame": {"channel":"book","type":"update","data":[{"symbol":"BTC/USD","bids":[{"price":62729.6,"qty":3.13925699}],"asks":[],"checksum":3875586520,"timestamp":"2026-08-16T23:37:55.267882Z"}]}}
{"rx_ns": 42940662837800, "frame": {"channel":"book","type":"update","data":[{"symbol":"BTC/USD","bids":[],"asks":[{"price":62828.6,"qty":0.00000000},{"price":62860.7,"qty":0.15930000}],"checksum":3875586520,"timestamp":"2026-08-16T23:37:55.283985Z"}]}}
{"rx_ns": 42940662924100, "frame": {"channel":"book","type":"update","data":[{"symbol":"BTC/USD","bids":[],"asks":[{"price":62860.5,"qty":0.06960000}],"checksum":3875586520,"timestamp":"2026-08-16T23:37:55.286985Z"}]}}
{"rx_ns": 42940668311700, "frame": {"channel":"book","type":"update","data":[{"symbol":"BTC/USD","bids":[],"asks":[{"price":62828.5,"qty":1.63614666}],"checksum":3875586520,"timestamp":"2026-08-16T23:37:55.291253Z"}]}}
{"rx_ns": 42940673643000, "frame": {"channel":"heartbeat"}}
{"rx_ns": 42941221967400, "frame": {"channel":"book","type":"update","data":[{"symbol":"BTC/USD","bids":[{"price":62764.8,"qty":0.01300000}],"asks":[],"checksum":3875586520,"timestamp":"2026-08-16T23:37:55.850832Z"}]}}
{"rx_ns": 42941347494500, "frame": {"channel":"book","type":"update","data":[{"symbol":"BTC/USD","bids":[{"price":62766.1,"qty":0.89135700},{"price":62766.2,"qty":0.10293757}],"asks":[],"checksum":3875586520,"timestamp":"2026-08-16T23:37:55.976302Z"}]}}
{"rx_ns": 42941422451200, "frame": {"channel":"book","type":"update","data":[{"symbol":"BTC/USD","bids":[{"price":62767.8,"qty":0.01400000}],"asks":[],"checksum":3875586520,"timestamp":"2026-08-16T23:37:56.051341Z"}]}}
{"rx_ns": 42941444216600, "frame": {"channel":"book","type":"update","data":[{"symbol":"BTC/USD","bids":[],"asks":[{"price":62849.6,"qty":0.02478000}],"checksum":3875586520,"timestamp":"2026-08-16T23:37:56.072849Z"}]}}
{"rx_ns": 42941676175800, "frame": {"channel":"heartbeat"}}
{"rx_ns": 42942674244500, "frame": {"channel":"heartbeat"}}
{"rx_ns": 42942814945300, "frame": {"channel":"book","type":"update","data":[{"symbol":"BTC/USD","bids":[{"price":62766.2,"qty":0.00000000},{"price":62725.9,"qty":5.57982866},{"price":62766.1,"qty":0.99429474}],"asks":[],"checksum":3875586520,"timestamp":"2026-08-16T23:37:57.444116Z"}]}}
{"rx_ns": 42942834406500, "frame": {"channel":"book","type":"update","data":[{"symbol":"BTC/USD","bids":[{"price":62782.3,"qty":0.00000000},{"price":62724.2,"qty":6.18395346}],"asks":[],"checksum":3137474675,"timestamp":"2026-08-16T23:37:57.462017Z"}]}}
{"rx_ns": 42942837318900, "frame": {"channel":"book","type":"update","data":[{"symbol":"BTC/USD","bids":[{"price":62780.2,"qty":0.00000000},{"price":62724.1,"qty":15.00000000}],"asks":[],"checksum":3137474675,"timestamp":"2026-08-16T23:37:57.462300Z"}]}}
{"rx_ns": 42942837466100, "frame": {"channel":"book","type":"update","data":[{"symbol":"BTC/USD","bids":[{"price":62781.2,"qty":0.79641642}],"asks":[],"checksum":2348352488,"timestamp":"2026-08-16T23:37:57.463743Z"}]}}
{"rx_ns": 42942837480700, "frame": {"channel":"book","type":"update","data":[{"symbol":"BTC/USD","bids":[{"price":62779.0,"qty":0.95572575}],"asks":[],"checksum":2348352488,"timestamp":"2026-08-16T23:37:57.463893Z"}]}}
{"rx_ns": 42942837491500, "frame": {"channel":"book","type":"update","data":[{"symbol":"BTC/USD","bids":[{"price":62778.0,"qty":0.00422324}],"asks":[],"checksum":2348352488,"timestamp":"2026-08-16T23:37:57.464869Z"}]}}
{"rx_ns": 42942865959300, "frame": {"channel":"book","type":"update","data":[{"symbol":"BTC/USD","bids":[],"asks":[{"price":62809.8,"qty":0.00222509},{"price":62805.5,"qty":1.59575715}],"checksum":2348352488,"timestamp":"2026-08-16T23:37:57.492715Z"}]}}
{"rx_ns": 42942866019100, "frame": {"channel":"book","type":"update","data":[{"symbol":"BTC/USD","bids":[{"price":62766.1,"qty":0.89135700},{"price":62763.1,"qty":0.10294266}],"asks":[],"checksum":2348352488,"timestamp":"2026-08-16T23:37:57.492732Z"}]}}
{"rx_ns": 42942934639800, "frame": {"channel":"book","type":"update","data":[{"symbol":"BTC/USD","bids":[],"asks":[{"price":62828.5,"qty":0.00000000},{"price":62858.8,"qty":0.03187000}],"checksum":2348352488,"timestamp":"2026-08-16T23:37:57.561077Z"}]}}
{"rx_ns": 42942936380100, "frame": {"channel":"book","type":"update","data":[{"symbol":"BTC/USD","bids":[],"asks":[{"price":62828.4,"qty":1.58176385}],"checksum":2348352488,"timestamp":"2026-08-16T23:37:57.564383Z"}]}}
{"rx_ns": 42943009559900, "frame": {"channel":"book","type":"update","data":[{"symbol":"BTC/USD","bids":[{"price":62729.6,"qty":0.05384617}],"asks":[],"checksum":2348352488,"timestamp":"2026-08-16T23:37:57.636228Z"}]}}
{"rx_ns": 42943019847900, "frame": {"channel":"book","type":"update","data":[{"symbol":"BTC/USD","bids":[{"price":62729.7,"qty":3.28207961}],"asks":[],"checksum":2348352488,"timestamp":"2026-08-16T23:37:57.648041Z"}]}}
{"rx_ns": 42943128549300, "frame": {"channel":"book","type":"update","data":[{"symbol":"BTC/USD","bids":[{"price":62772.2,"qty":0.00000000},{"price":62725.9,"qty":5.57982866}],"asks":[],"checksum":2348352488,"timestamp":"2026-08-16T23:37:57.692819Z"}]}}
{"rx_ns": 42943128601700, "frame": {"channel":"book","type":"update","data":[{"symbol":"BTC/USD","bids":[{"price":62774.1,"qty":0.00000000},{"price":62724.2,"qty":6.18395346}],"asks":[],"checksum":2348352488,"timestamp":"2026-08-16T23:37:57.694475Z"}]}}
{"rx_ns": 42943128615400, "frame": {"channel":"book","type":"update","data":[{"symbol":"BTC/USD","bids":[{"price":62768.4,"qty":0.46659100}],"asks":[],"checksum":2348352488,"timestamp":"2026-08-16T23:37:57.695429Z"}]}}
{"rx_ns": 42943128624900, "frame": {"channel":"book","type":"update","data":[{"symbol":"BTC/USD","bids":[{"price":62774.1,"qty":0.29364066}],"asks":[],"checksum":2348352488,"timestamp":"2026-08-16T23:37:57.695644Z"}]}}
{"rx_ns": 42943128633600, "frame": {"channel":"book","type":"update","data":[{"symbol":"BTC/USD","bids":[{"price":62729.6,"qty":0.00000000},{"price":62725.9,"qty":5.57982866}],"asks":[],"checksum":2348352488,"timestamp":"2026-08-16T23:37:57.718259Z"}]}}
{"rx_ns": 42943176645900, "frame": {"channel":"book","type":"update","data":[{"symbol":"BTC/USD","bids":[{"price":62784.0,"qty":0.00000000},{"price":62724.2,"qty":6.18395346},{"price":62784.6,"qty":0.00009500}],"asks":[],"checksum":606211463,"timestamp":"2026-08-16T23:37:57.792094Z"}]}}
{"rx_ns": 42943187417400, "frame": {"channel":"book","type":"update","data":[{"symbol":"BTC/USD","bids":[{"price":62790.4,"qty":0.00000000},{"price":62724.2,"qty":6.18395346}],"asks":[],"checksum":2525654230,"timestamp":"2026-08-16T23:37:57.796850Z"}]}}
{"rx_ns": 42943187501100, "frame": {"channel":"book","type":"update","data":[{"symbol":"BTC/USD","bids":[{"price":62789.4,"qty":0.02131292}],"asks":[],"checksum":1647631820,"timestamp":"2026-08-16T23:37:57.798280Z"}]}}
{"rx_ns": 42943187530700, "frame": {"channel":"book","type":"update","data":[{"symbol":"BTC/USD","bids":[{"price":62788.1,"qty":0.00000000},{"price":62724.2,"qty":6.18395346},{"price":62789.4,"qty":0.07729764}],"asks":[],"checksum":2990073840,"timestamp":"2026-08-16T23:37:57.799340Z"}]}}
{"rx_ns": 42943336174100, "frame": {"channel":"book","type":"update","data":[{"symbol":"BTC/USD","bids":[{"price":62789.4,"qty":0.05598472}],"asks":[],"checksum":2035133278,"timestamp":"2026-08-16T23:37:57.965246Z"}]}}
{"rx_ns": 42943337644200, "frame": {"channel":"book","type":"update","data":[{"symbol":"BTC/USD","bids":[{"price":62790.3,"qty":0.02131292}],"asks":[],"checksum":1413053836,"timestamp":"2026-08-16T23:37:57.965451Z"}]}}
{"rx_ns": 42943344864800, "frame": {"channel":"book","type":"update","data":[{"symbol":"BTC/USD","bids":[{"price":62789.4,"qty":0.00000000},{"price":62724.2,"qty":6.18395346},{"price":62788.1,"qty":0.05598472}],"asks":[],"checksum":3943424355,"timestamp":"2026-08-16T23:37:57.966568Z"}]}}
{"rx_ns": 42943589211000, "frame": {"channel":"book","type":"update","data":[{"symbol":"BTC/USD","bids":[{"price":62729.3,"qty":0.05588540}],"asks":[],"checksum":3943424355,"timestamp":"2026-08-16T23:37:58.218191Z"}]}}
{"rx_ns": 42943596236100, "frame": {"channel":"book","type":"update","data":[{"symbol":"BTC/USD","bids":[],"asks":[{"price":62821.7,"qty":0.00000000},{"price":62858.8,"qty":0.03187000},{"price":62821.6,"qty":0.63249249}],"checksum":3943424355,"timestamp":"2026-08-16T23:37:58.223567Z"}]}}
{"rx_ns": 42943678920400, "frame": {"channel":"heartbeat"}}
{"rx_ns": 42943696543700, "frame": {"channel":"book","type":"update","data":[{"symbol":"BTC/USD","bids":[{"price":62781.2,"qty":0.00000000},{"price":62725.9,"qty":5.57982866}],"asks":[],"checksum":4184755948,"timestamp":"2026-08-16T23:37:58.324198Z"}]}}
{"rx_ns": 42943696597100, "frame": {"channel":"book","type":"update","data":[{"symbol":"BTC/USD","bids":[{"price":62779.0,"qty":0.15928208}],"asks":[],"checksum":4184755948,"timestamp":"2026-08-16T23:37:58.324456Z"}]}}
{"rx_ns": 42943699772500, "frame": {"channel":"book","type":"update","data":[{"symbol":"BTC/USD","bids":[{"price":62782.2,"qty":0.79640364}],"asks":[],"checksum":1603464115,"timestamp":"2026-08-16T23:37:58.325751Z"}]}}
{"rx_ns": 42943699835400, "frame": {"channel":"book","type":"update","data":[{"symbol":"BTC/USD","bids":[{"price":62780.0,"qty":0.79643093}],"asks":[],"checksum":1603464115,"timestamp":"2026-08-16T23:37:58.326027Z"}]}}
{"rx_ns": 42943856756900, "frame": {"channel":"book","type":"update","data":[{"symbol":"BTC/USD","bids":[],"asks":[{"price":62825.4,"qty":0.00000000},{"price":62858.9,"qty":0.00159000},{"price":62807.2,"qty":0.02905654}],"checksum":1603464115,"timestamp":"2026-08-16T23:37:58.480579Z"}]}}
{"rx_ns": 42943864988900, "frame": {"channel":"book","type":"update","data":[{"symbol":"BTC/USD","bids":[{"price":62771.4,"qty":0.00000000},{"price":62728.0,"qty":7.97091264},{"price":62765.1,"qty":0.00039831}],"asks":[],"checksum":1603464115,"timestamp":"2026-08-16T23:37:58.486627Z"}]}}
{"rx_ns": 42943865055100, "frame": {"channel":"book","type":"update","data":[{"symbol":"BTC/USD","bids":[{"price":62772.7,"qty":0.00000000},{"price":62728.0,"qty":7.97091264},{"price":62766.0,"qty":0.47625540}],"asks":[],"checksum":1603464115,"timestamp":"2026-08-16T23:37:58.487044Z"}]}}
{"rx_ns": 42944136756900, "frame": {"channel":"book","type":"update","data":[{"symbol":"BTC/USD","bids":[],"asks":[{"price":62805.5,"qty":0.00000000},{"price":62860.7,"qty":0.15930000},{"price":62809.8,"qty":1.59798224}],"checksum":1603464115,"timestamp":"2026-08-16T23:37:58.766060Z"}]}}
{"rx_ns": 42944140874100, "frame": {"channel":"book","type":"update","data":[{"symbol":"BTC/USD","bids":[],"asks":[{"price":62860.5,"qty":0.06960000}],"checksum":1603464115,"timestamp":"2026-08-16T23:37:58.769948Z"}]}}
{"rx_ns": 42944341154000, "frame": {"channel":"book","type":"update","data":[{"symbol":"BTC/USD","bids":[{"price":62752.0,"qty":0.00000000},{"price":62725.9,"qty":5.57982866},{"price":62745.7,"qty":0.00162380}],"asks":[],"checksum":1603464115,"timestamp":"2026-08-16T23:37:58.969797Z"}]}}
{"rx_ns": 42944342177200, "frame": {"channel":"book","type":"update","data":[{"symbol":"BTC/USD","bids":[],"asks":[{"price":62827.5,"qty":0.00000000},{"price":62860.7,"qty":0.15930000},{"price":62821.1,"qty":0.00198855}],"checksum":1603464115,"timestamp":"2026-08-16T23:37:58.970931Z"}]}}
{"rx_ns": 42944352142700, "frame": {"channel":"book","type":"update","data":[{"symbol":"BTC/USD","bids":[{"price":62791.2,"qty":0.16822674}],"asks":[],"checksum":685865189,"timestamp":"2026-08-16T23:37:58.979902Z"}]}}
{"rx_ns": 42944353594500, "frame": {"channel":"book","type":"update","data":[{"symbol":"BTC/USD","bids":[],"asks":[{"price":62791.3,"qty":4.21578028}],"checksum":329939991,"timestamp":"2026-08-16T23:37:58.980162Z"}]}}
{"rx_ns": 42944353647300, "frame": {"channel":"book","type":"update","data":[{"symbol":"BTC/USD","bids":[{"price":62772.0,"qty":0.24087933}],"asks":[],"checksum":329939991,"timestamp":"2026-08-16T23:37:58.980742Z"}]}}
{"rx_ns": 42944355221000, "frame": {"channel":"book","type":"update","data":[{"symbol":"BTC/USD","bids":[],"asks":[{"price":62791.3,"qty":4.13778028}],"checksum":3227652704,"timestamp":"2026-08-16T23:37:58.982804Z"}]}}
{"rx_ns": 42944361500300, "frame": {"channel":"book","type":"update","data":[{"symbol":"BTC/USD","bids":[],"asks":[{"price":62791.3,"qty":4.14963328}],"checksum":1345564600,"timestamp":"2026-08-16T23:37:58.986083Z"}]}}
{"rx_ns": 42944361575300, "frame": {"channel":"book","type":"update","data":[{"symbol":"BTC/USD","bids":[{"price":62791.2,"qty":0.01534221}],"asks":[],"checksum":2324436219,"timestamp":"2026-08-16T23:37:58.986350Z"}]}}
{"rx_ns": 42944361591200, "frame": {"channel":"book","type":"update","data":[{"symbol":"BTC/USD","bids":[{"price":62772.0,"qty":0.00318614}],"asks":[],"checksum":2324436219,"timestamp":"2026-08-16T23:37:58.987187Z"}]}}
{"rx_ns": 42944370047700, "frame": {"channel":"book","type":"update","data":[{"symbol":"BTC/USD","bids":[],"asks":[{"price":62799.4,"qty":0.06000000}],"checksum":2324436219,"timestamp":"2026-08-16T23:37:58.998615Z"}]}}
{"rx_ns": 42944370122300, "frame": {"channel":"book","type":"update","data":[{"symbol":"BTC/USD","bids":[],"asks":[{"price":62802.4,"qty":0.00000000},{"price":62860.5,"qty":0.06960000}],"checksum":2324436219,"timestamp":"2026-08-16T23:37:58.998656Z"}]}}
{"rx_ns": 42944371522600, "frame": {"channel":"book","type":"update","data":[{"symbol":"BTC/USD","bids":[],"asks":[{"price":62860.5,"qty":0.00000000},{"price":62860.7,"qty":0.15930000}],"checksum":2324436219,"timestamp":"2026-08-16T23:37:58.999731Z"}]}}
{"rx_ns": 42944373777400, "frame": {"channel":"book","type":"update","data":[{"symbol":"BTC/USD","bids":[],"asks":[{"price":62860.5,"qty":0.06960000}],"checksum":2324436219,"timestamp":"2026-08-16T23:37:59.002300Z"}]}}
{"rx_ns": 42944490072100, "frame": {"channel":"book","type":"update","data":[{"symbol":"BTC/USD","bids":[{"price":62763.1,"qty":0.00000000},{"price":62725.9,"qty":5.57982866},{"price":62765.8,"qty":0.10293823}],"asks":[],"checksum":2324436219,"timestamp":"2026-08-16T23:37:59.113578Z"}]}}
{"rx_ns": 42944510662900, "frame": {"channel":"book","type":"update","data":[{"symbol":"BTC/USD","bids":[],"asks":[{"price":62791.3,"qty":3.99035120}],"checksum":2025312224,"timestamp":"2026-08-16T23:37:59.137994Z"}]}}
{"rx_ns": 42944510720800, "frame": {"channel":"book","type":"update","data":[{"symbol":"BTC/USD","bids":[],"asks":[{"price":62794.1,"qty":0.00000000},{"price":62860.7,"qty":0.15930000}],"checksum":1916296984,"timestamp":"2026-08-16T23:37:59.138271Z"}]}}
{"rx_ns": 42944518459200, "frame": {"channel":"book","type":"update","data":[{"symbol":"BTC/USD","bids":[],"asks":[{"price":62791.3,"qty":4.06835120}],"checksum":1984973282,"timestamp":"2026-08-16T23:37:59.140834Z"}]}}
{"rx_ns": 42944531161100, "frame": {"channel":"book","type":"update","data":[{"symbol":"BTC/USD","bids":[],"asks":[{"price":62795.4,"qty":0.00000000},{"price":62860.9,"qty":0.00198855}],"checksum":818920400,"timestamp":"2026-08-16T23:37:59.159814Z"}]}}
{"rx_ns": 42944534034400, "frame": {"channel":"book","type":"update","data":[{"symbol":"BTC/USD","bids":[],"asks":[{"price":62798.3,"qty":0.50933000}],"checksum":818920400,"timestamp":"2026-08-16T23:37:59.161222Z"}]}}
{"rx_ns": 42944534116400, "frame": {"channel":"book","type":"update","data":[{"symbol":"BTC/USD","bids":[],"asks":[{"price":62800.8,"qty":0.90931246},{"price":62803.3,"qty":0.19589680}],"checksum":818920400,"timestamp":"2026-08-16T23:37:59.161452Z"}]}}
{"rx_ns": 42944534132700, "frame": {"channel":"book","type":"update","data":[{"symbol":"BTC/USD","bids":[],"asks":[{"price":62794.0,"qty":0.00000000},{"price":62860.9,"qty":0.00198855}],"checksum":893320615,"timestamp":"2026-08-16T23:37:59.161502Z"}]}}
{"rx_ns": 42944538648800, "frame": {"channel":"book","type":"update","data":[{"symbol":"BTC/USD","bids":[{"price":62765.8,"qty":0.00000000},{"price":62725.9,"qty":5.57982866},{"price":62766.1,"qty":0.99429474}],"asks":[],"checksum":893320615,"timestamp":"2026-08-16T23:37:59.161987Z"}]}}
{"rx_ns": 42944538701800, "frame": {"channel":"book","type":"update","data":[{"symbol":"BTC/USD","bids":[],"asks":[{"price":62794.7,"qty":0.35767591}],"checksum":898131639,"timestamp":"2026-08-16T23:37:59.163348Z"}]}}
{"rx_ns": 42944538714300, "frame": {"channel":"book","type":"update","data":[{"symbol":"BTC/USD","bids":[{"price":62791.2,"qty":0.16822674}],"asks":[],"checksum":803645041,"timestamp":"2026-08-16T23:37:59.163385Z"}]}}
{"rx_ns": 42944538723600, "frame": {"channel":"book","type":"update","data":[{"symbol":"BTC/USD","bids":[],"asks":[{"price":62791.3,"qty":4.05649820}],"checksum":1371655920,"timestamp":"2026-08-16T23:37:59.163674Z"}]}}
{"rx_ns": 42944543223400, "frame": {"channel":"book","type":"update","data":[{"symbol":"BTC/USD","bids":[{"price":62772.0,"qty":0.24087933}],"asks":[],"checksum":1371655920,"timestamp":"2026-08-16T23:37:59.165223Z"}]}}
{"rx_ns": 42944543279200, "frame": {"channel":"book","type":"update","data":[{"symbol":"BTC/USD","bids":[{"price":62791.2,"qty":0.01534221}],"asks":[],"checksum":2744933050,"timestamp":"2026-08-16T23:37:59.166784Z"}]}}
{"rx_ns": 42944543292000, "frame": {"channel":"book","type":"update","data":[{"symbol":"BTC/USD","bids":[],"asks":[{"price":62791.3,"qty":4.06835120}],"checksum":898131639,"timestamp":"2026-08-16T23:37:59.167287Z"}]}}
{"rx_ns": 42944586451700, "frame": {"channel":"book","type":"update","data":[{"symbol":"BTC/USD","bids":[],"asks":[{"price":62791.3,"qty":4.22763328}],"checksum":382030878,"timestamp":"2026-08-16T23:37:59.215111Z"}]}}
{"rx_ns": 42944588754000, "frame": {"channel":"book","type":"update","data":[{"symbol":"BTC/USD","bids":[],"asks":[{"price":62803.3,"qty":0.01100000},{"price":62796.0,"qty":0.18489680}],"checksum":3171989201,"timestamp":"2026-08-16T23:37:59.216226Z"}]}}
{"rx_ns": 42944678191000, "frame": {"channel":"heartbeat"}}
{"rx_ns": 42944696946200, "frame": {"channel":"book","type":"update","data":[{"symbol":"BTC/USD","bids":[],"asks":[{"price":62801.3,"qty":0.00318497},{"price":62803.8,"qty":0.19620257}],"checksum":3171989201,"timestamp":"2026-08-16T23:37:59.303524Z"}]}}
{"rx_ns": 42944815807300, "frame": {"channel":"book","type":"update","data":[{"symbol":"BTC/USD","bids":[],"asks":[{"price":62803.8,"qty":0.00000000},{"price":62860.7,"qty":0.15930000},{"price":62800.7,"qty":0.19620257}],"checksum":3171989201,"timestamp":"2026-08-16T23:37:59.444049Z"}]}}
{"rx_ns": 42945165008800, "frame": {"channel":"book","type":"update","data":[{"symbol":"BTC/USD","bids":[],"asks":[{"price":62847.7,"qty":0.00000000},{"price":62860.7,"qty":0.15930000}],"checksum":3171989201,"timestamp":"2026-08-16T23:37:59.793643Z"}]}}
{"rx_ns": 42945167873000, "frame": {"channel":"book","type":"update","data":[{"symbol":"BTC/USD","bids":[],"asks":[{"price":62860.5,"qty":0.06960000}],"checksum":3171989201,"timestamp":"2026-08-16T23:37:59.796024Z"}]}}
{"rx_ns": 42945273689100, "frame": {"channel":"book","type":"update","data":[{"symbol":"BTC/USD","bids":[],"asks":[{"price":62828.4,"qty":0.00000000},{"price":62860.7,"qty":0.15930000}],"checksum":3171989201,"timestamp":"2026-08-16T23:37:59.902644Z"}]}}
{"rx_ns": 42945277489900, "frame": {"channel":"book","type":"update","data":[{"symbol":"BTC/USD","bids":[],"asks":[{"price":62828.3,"qty":1.52446766}],"checksum":3171989201,"timestamp":"2026-08-16T23:37:59.905742Z"}]}}
{"rx_ns": 42945328952600, "frame": {"channel":"book","type":"update","data":[{"symbol":"BTC/USD","bids":[],"asks":[{"price":62849.0,"qty":0.03227757}],"checksum":3171989201,"timestamp":"2026-08-16T23:37:59.958086Z"}]}}
{"rx_ns": 42945378906100, "frame": {"channel":"book","type":"update","data":[{"symbol":"BTC/USD","bids":[{"price":62766.1,"qty":0.89135700},{"price":62766.2,"qty":0.10293757}],"asks":[],"checksum":3171989201,"timestamp":"2026-08-16T23:38:00.008126Z"}]}}
{"rx_ns": 42945428802400, "frame": {"channel":"book","type":"update","data":[{"symbol":"BTC/USD","bids":[{"price":62729.7,"qty":0.00000000},{"price":62725.9,"qty":5.57982866}],"asks":[],"checksum":3171989201,"timestamp":"2026-08-16T23:38:00.057132Z"}]}}
{"rx_ns": 42945438664900, "frame": {"channel":"book","type":"update","data":[{"symbol":"BTC/USD","bids":[{"price":62729.8,"qty":3.17577043}],"asks":[],"checksum":3171989201,"timestamp":"2026-08-16T23:38:00.063338Z"}]}}
{"rx_ns": 42945688560100, "frame": {"channel":"heartbeat"}}
{"rx_ns": 42945746966900, "frame": {"channel":"book","type":"update","data":[{"symbol":"BTC/USD","bids":[],"asks":[{"price":62798.3,"qty":0.00000000},{"price":62860.7,"qty":0.15930000}],"checksum":3171989201,"timestamp":"2026-08-16T23:38:00.369803Z"}]}}
{"rx_ns": 42945747037100, "frame": {"channel":"book","type":"update","data":[{"symbol":"BTC/USD","bids":[],"asks":[{"price":62794.7,"qty":0.86700591}],"checksum":428792094,"timestamp":"2026-08-16T23:38:00.371023Z"}]}}
{"rx_ns": 42945747060000, "frame": {"channel":"book","type":"update","data":[{"symbol":"BTC/USD","bids":[],"asks":[{"price":62794.7,"qty":0.50933000}],"checksum":1292753551,"timestamp":"2026-08-16T23:38:00.372165Z"}]}}
{"rx_ns": 42945747071200, "frame": {"channel":"book","type":"update","data":[{"symbol":"BTC/USD","bids":[],"asks":[{"price":62860.5,"qty":0.06960000}],"checksum":1292753551,"timestamp":"2026-08-16T23:38:00.372201Z"}]}}
{"rx_ns": 42945747080000, "frame": {"channel":"book","type":"update","data":[{"symbol":"BTC/USD","bids":[],"asks":[{"price":62796.0,"qty":0.00000000},{"price":62860.7,"qty":0.15930000},{"price":62800.6,"qty":0.18489680}],"checksum":3872929856,"timestamp":"2026-08-16T23:38:00.372309Z"}]}}
{"rx_ns": 42945750975100, "frame": {"channel":"book","type":"update","data":[{"symbol":"BTC/USD","bids":[],"asks":[{"price":62794.6,"qty":0.56490261}],"checksum":3974163983,"timestamp":"2026-08-16T23:38:00.373369Z"}]}}
{"rx_ns": 42946249003500, "frame": {"channel":"book","type":"update","data":[{"symbol":"BTC/USD","bids":[],"asks":[{"price":62792.3,"qty":0.00000000},{"price":62860.7,"qty":0.15930000}],"checksum":475638106,"timestamp":"2026-08-16T23:38:00.864877Z"}]}}
{"rx_ns": 42946249096100, "frame": {"channel":"book","type":"update","data":[{"symbol":"BTC/USD","bids":[{"price":62788.1,"qty":0.00000000},{"price":62725.9,"qty":5.57982866},{"price":62791.2,"qty":0.07132693}],"asks":[],"checksum":4218590375,"timestamp":"2026-08-16T23:38:00.866106Z"}]}}
{"rx_ns": 42946249110800, "frame": {"channel":"book","type":"update","data":[{"symbol":"BTC/USD","bids":[],"asks":[{"price":62794.5,"qty":0.05598472}],"checksum":1184025778,"timestamp":"2026-08-16T23:38:00.866246Z"}]}}
{"rx_ns": 42946249119100, "frame": {"channel":"book","type":"update","data":[{"symbol":"BTC/USD","bids":[{"price":62772.0,"qty":0.00318614}],"asks":[],"checksum":1184025778,"timestamp":"2026-08-16T23:38:00.866868Z"}]}}
{"rx_ns": 42946249133500, "frame": {"channel":"book","type":"update","data":[{"symbol":"BTC/USD","bids":[],"asks":[{"price":62800.6,"qty":0.00000000},{"price":62860.7,"qty":0.15930000},{"price":62794.4,"qty":0.18489680}],"checksum":368929866,"timestamp":"2026-08-16T23:38:00.867378Z"}]}}
{"rx_ns": 42946250044200, "frame": {"channel":"book","type":"update","data":[{"symbol":"BTC/USD","bids":[],"asks":[{"price":62791.3,"qty":4.14963328}],"checksum":3236139778,"timestamp":"2026-08-16T23:38:00.877944Z"}]}}
{"rx_ns": 42946596400700, "frame": {"channel":"book","type":"update","data":[{"symbol":"BTC/USD","bids":[],"asks":[{"price":62821.6,"qty":0.35249249},{"price":62821.5,"qty":1.30987080}],"checksum":3236139778,"timestamp":"2026-08-16T23:38:01.216625Z"}]}}
{"rx_ns": 42946600405900, "frame": {"channel":"book","type":"update","data":[{"symbol":"BTC/USD","bids":[],"asks":[{"price":62794.5,"qty":0.00000000},{"price":62860.7,"qty":0.15930000},{"price":62794.3,"qty":0.05598472}],"checksum":4184523727,"timestamp":"2026-08-16T23:38:01.217742Z"}]}}
{"rx_ns": 42946609710500, "frame": {"channel":"book","type":"update","data":[{"symbol":"BTC/USD","bids":[],"asks":[{"price":62794.4,"qty":0.00000000},{"price":62860.7,"qty":0.15930000},{"price":62800.6,"qty":0.18489680}],"checksum":1888054188,"timestamp":"2026-08-16T23:38:01.219094Z"}]}}
{"rx_ns": 42946609788700, "frame": {"channel":"book","type":"update","data":[{"symbol":"BTC/USD","bids":[],"asks":[{"price":62794.3,"qty":0.00000000},{"price":62860.7,"qty":0.15930000},{"price":62794.5,"qty":0.05598472}],"checksum":2475439098,"timestamp":"2026-08-16T23:38:01.220351Z"}]}}
{"rx_ns": 42946639731900, "frame": {"channel":"book","type":"update","data":[{"symbol":"BTC/USD","bids":[],"asks":[{"price":62798.0,"qty":0.00000000},{"price":62860.7,"qty":0.15930000}],"checksum":2475439098,"timestamp":"2026-08-16T23:38:01.264969Z"}]}}
{"rx_ns": 42946639792100, "frame": {"channel":"book","type":"update","data":[{"symbol":"BTC/USD","bids":[],"asks":[{"price":62800.6,"qty":0.00000000},{"price":62860.9,"qty":0.00198855},{"price":62794.4,"qty":0.18489680}],"checksum":3236139778,"timestamp":"2026-08-16T23:38:01.266302Z"}]}}
{"rx_ns": 42946639811600, "frame": {"channel":"book","type":"update","data":[{"symbol":"BTC/USD","bids":[],"asks":[{"price":62860.5,"qty":0.06960000}],"checksum":3236139778,"timestamp":"2026-08-16T23:38:01.267661Z"}]}}
{"rx_ns": 42946662820600, "frame": {"channel":"book","type":"update","data":[{"symbol":"BTC/USD","bids":[{"price":62778.0,"qty":0.00740907}],"asks":[],"checksum":3236139778,"timestamp":"2026-08-16T23:38:01.287196Z"}]}}
{"rx_ns": 42946662909200, "frame": {"channel":"book","type":"update","data":[{"symbol":"BTC/USD","bids":[],"asks":[{"price":62791.5,"qty":0.00000000},{"price":62860.7,"qty":0.15930000}],"checksum":2870577217,"timestamp":"2026-08-16T23:38:01.289997Z"}]}}
{"rx_ns": 42946667722100, "frame": {"channel":"book","type":"update","data":[{"symbol":"BTC/USD","bids":[{"price":62779.0,"qty":0.00000000},{"price":62724.2,"qty":6.18395346}],"asks":[],"checksum":2870577217,"timestamp":"2026-08-16T23:38:01.290351Z"}]}}
{"rx_ns": 42946667758200, "frame": {"channel":"book","type":"update","data":[{"symbol":"BTC/USD","bids":[],"asks":[{"price":62794.6,"qty":0.00000000},{"price":62860.9,"qty":0.00198855}],"checksum":2703318542,"timestamp":"2026-08-16T23:38:01.291350Z"}]}}
{"rx_ns": 42946667771700, "frame": {"channel":"book","type":"update","data":[{"symbol":"BTC/USD","bids":[],"asks":[{"price":62791.3,"qty":3.99035120}],"checksum":1394246933,"timestamp":"2026-08-16T23:38:01.291370Z"}]}}
{"rx_ns": 42946667781300, "frame": {"channel":"book","type":"update","data":[{"symbol":"BTC/USD","bids":[],"asks":[{"price":62795.6,"qty":0.46828931}],"checksum":871322194,"timestamp":"2026-08-16T23:38:01.291398Z"}]}}
{"rx_ns": 42946667790000, "frame": {"channel":"book","type":"update","data":[{"symbol":"BTC/USD","bids":[{"price":62765.6,"qty":0.00000000},{"price":62724.1,"qty":15.00000000}],"asks":[],"checksum":871322194,"timestamp":"2026-08-16T23:38:01.291444Z"}]}}
{"rx_ns": 42946667799400, "frame": {"channel":"book","type":"update","data":[{"symbol":"BTC/USD","bids":[{"price":62782.2,"qty":0.00000000},{"price":62723.7,"qty":5.64716200}],"asks":[],"checksum":689505975,"timestamp":"2026-08-16T23:38:01.291524Z"}]}}
{"rx_ns": 42946676081700, "frame": {"channel":"book","type":"update","data":[{"symbol":"BTC/USD","bids":[],"asks":[{"price":62800.0,"qty":0.00000000},{"price":62860.9,"qty":0.00198855}],"checksum":689505975,"timestamp":"2026-08-16T23:38:01.292055Z"}]}}
{"rx_ns": 42946676138400, "frame": {"channel":"book","type":"update","data":[{"symbol":"BTC/USD","bids":[],"asks":[{"price":62791.7,"qty":0.00000000},{"price":62861.3,"qty":0.15888884}],"checksum":1670636267,"timestamp":"2026-08-16T23:38:01.292162Z"}]}}
{"rx_ns": 42946676151100, "frame": {"channel":"book","type":"update","data":[{"symbol":"BTC/USD","bids":[{"price":62780.0,"qty":0.00000000},{"price":62720.2,"qty":0.00711998}],"asks":[],"checksum":1670636267,"timestamp":"2026-08-16T23:38:01.292220Z"}]}}
{"rx_ns": 42946676160700, "frame": {"channel":"book","type":"update","data":[{"symbol":"BTC/USD","bids":[{"price":62780.1,"qty":0.28793577}],"asks":[],"checksum":1670636267,"timestamp":"2026-08-16T23:38:01.292297Z"}]}}
{"rx_ns": 42946676169300, "frame": {"channel":"book","type":"update","data":[{"symbol":"BTC/USD","bids":[],"asks":[{"price":62802.0,"qty":0.00422162}],"checksum":1670636267,"timestamp":"2026-08-16T23:38:01.292318Z"}]}}
{"rx_ns": 42946676177700, "frame": {"channel":"book","type":"update","data":[{"symbol":"BTC/USD","bids":[{"price":62728.0,"qty":0.00000000},{"price":62720.2,"qty":0.00711998}],"asks":[],"checksum":1670636267,"timestamp":"2026-08-16T23:38:01.292329Z"}]}}
{"rx_ns": 42946676186900, "frame": {"channel":"book","type":"update","data":[{"symbol":"BTC/USD","bids":[],"asks":[{"price":62808.0,"qty":0.00636861}],"checksum":1670636267,"timestamp":"2026-08-16T23:38:01.292346Z"}]}}
{"rx_ns": 42946676194800, "frame": {"channel":"book","type":"update","data":[{"symbol":"BTC/USD","bids":[{"price":62782.5,"qty":0.15928208}],"asks":[],"checksum":4220277771,"timestamp":"2026-08-16T23:38:01.292628Z"}]}}
{"rx_ns": 42946676202500, "frame": {"channel":"book","type":"update","data":[{"symbol":"BTC/USD","bids":[{"price":62791.2,"qty":0.09263985}],"asks":[],"checksum":2961876508,"timestamp":"2026-08-16T23:38:01.292747Z"}]}}
{"rx_ns": 42946676212200, "frame": {"channel":"book","type":"update","data":[{"symbol":"BTC/USD","bids":[],"asks":[{"price":62792.4,"qty":0.00000000},{"price":62862.0,"qty":0.15142628}],"checksum":1091779999,"timestamp":"2026-08-16T23:38:01.292799Z"}]}}
{"rx_ns": 42946676221100, "frame": {"channel":"book","type":"update","data":[{"symbol":"BTC/USD","bids":[],"asks":[{"price":62794.4,"qty":0.00000000},{"price":62862.7,"qty":0.00600000},{"price":62800.6,"qty":0.18489680}],"checksum":2980483900,"timestamp":"2026-08-16T23:38:01.293486Z"}]}}
{"rx_ns": 42946676231300, "frame": {"channel":"book","type":"update","data":[{"symbol":"BTC/USD","bids":[],"asks":[{"price":62794.8,"qty":0.00000000},{"price":62862.7,"qty":0.00600000}],"checksum":2520603607,"timestamp":"2026-08-16T23:38:01.293560Z"}]}}
{"rx_ns": 42946676239700, "frame": {"channel":"book","type":"update","data":[{"symbol":"BTC/USD","bids":[{"price":62776.1,"qty":0.00000000},{"price":62720.2,"qty":0.00711998}],"asks":[],"checksum":2520603607,"timestamp":"2026-08-16T23:38:01.293570Z"}]}}
{"rx_ns": 42946676248100, "frame": {"channel":"book","type":"update","data":[{"symbol":"BTC/USD","bids":[{"price":62775.6,"qty":0.00000000},{"price":62719.9,"qty":2.12501460}],"asks":[],"checksum":2520603607,"timestamp":"2026-08-16T23:38:01.293659Z"}]}}
{"rx_ns": 42946676257300, "frame": {"channel":"book","type":"update","data":[{"symbol":"BTC/USD","bids":[],"asks":[{"price":62791.6,"qty":0.00000000},{"price":62864.1,"qty":1.66191821}],"checksum":2661133330,"timestamp":"2026-08-16T23:38:01.293959Z"}]}}
{"rx_ns": 42946676265700, "frame": {"channel":"book","type":"update","data":[{"symbol":"BTC/USD","bids":[{"price":62772.0,"qty":0.24087933}],"asks":[],"checksum":2661133330,"timestamp":"2026-08-16T23:38:01.294315Z"}]}}
{"rx_ns": 42946676273500, "frame": {"channel":"book","type":"update","data":[{"symbol":"BTC/USD","bids":[],"asks":[{"price":62800.9,"qty":0.00000000},{"price":62864.2,"qty":5.56756520}],"checksum":2661133330,"timestamp":"2026-08-16T23:38:01.294650Z"}]}}
{"rx_ns": 42946676282400, "frame": {"channel":"book","type":"update","data":[{"symbol":"BTC/USD","bids":[],"asks":[{"price":62810.9,"qty":0.00000000},{"price":62866.5,"qty":0.00005100}],"checksum":2661133330,"timestamp":"2026-08-16T23:38:01.294772Z"}]}}
{"rx_ns": 42946676296200, "frame": {"channel":"book","type":"update","data":[{"symbol":"BTC/USD","bids":[{"price":62752.5,"qty":0.00000000},{"price":62718.0,"qty":0.00015944},{"price":62718.0,"qty":0.35596944}],"asks":[],"checksum":2661133330,"timestamp":"2026-08-16T23:38:01.294805Z"}]}}
{"rx_ns": 42946680094700, "frame": {"channel":"book","type":"update","data":[{"symbol":"BTC/USD","bids":[{"price":62738.1,"qty":0.00000000},{"price":62714.4,"qty":0.16488958},{"price":62721.0,"qty":0.70609000}],"asks":[],"checksum":2661133330,"timestamp":"2026-08-16T23:38:01.295309Z"}]}}
{"rx_ns": 42946680152700, "frame": {"channel":"book","type":"update","data":[{"symbol":"BTC/USD","bids":[{"price":62776.2,"qty":0.38096420}],"asks":[],"checksum":2661133330,"timestamp":"2026-08-16T23:38:01.295846Z"}]}}
{"rx_ns": 42946680167600, "frame": {"channel":"book","type":"update","data":[{"symbol":"BTC/USD","bids":[{"price":62765.7,"qty":0.00000000},{"price":62718.0,"qty":0.35596944}],"asks":[],"checksum":2661133330,"timestamp":"2026-08-16T23:38:01.296258Z"}]}}
{"rx_ns": 42946680180200, "frame": {"channel":"book","type":"update","data":[{"symbol":"BTC/USD","bids":[],"asks":[{"price":62802.0,"qty":0.00000000},{"price":62871.6,"qty":0.69495739}],"checksum":2661133330,"timestamp":"2026-08-16T23:38:01.296621Z"}]}}
{"rx_ns": 42946680191800, "frame": {"channel":"book","type":"update","data":[{"symbol":"BTC/USD","bids":[],"asks":[{"price":62808.0,"qty":0.00318430}],"checksum":2661133330,"timestamp":"2026-08-16T23:38:01.297320Z"}]}}
{"rx_ns": 42946680201800, "frame": {"channel":"book","type":"update","data":[{"symbol":"BTC/USD","bids":[{"price":62723.9,"qty":0.06960000}],"asks":[],"checksum":2661133330,"timestamp":"2026-08-16T23:38:01.297431Z"}]}}
{"rx_ns": 42946680210300, "frame": {"channel":"book","type":"update","data":[{"symbol":"BTC/USD","bids":[],"asks":[{"price":62814.0,"qty":0.00318401}],"checksum":2661133330,"timestamp":"2026-08-16T23:38:01.297688Z"}]}}
{"rx_ns": 42946680217100, "frame": {"channel":"book","type":"update","data":[{"symbol":"BTC/USD","bids":[],"asks":[{"price":62797.6,"qty":0.79620930}],"checksum":708478009,"timestamp":"2026-08-16T23:38:01.297767Z"}]}}
{"rx_ns": 42946680223700, "frame": {"channel":"book","type":"update","data":[{"symbol":"BTC/USD","bids":[],"asks":[{"price":62799.6,"qty":0.79618411}],"checksum":2132157746,"timestamp":"2026-08-16T23:38:01.297960Z"}]}}
{"rx_ns": 42946680229700, "frame": {"channel":"book","type":"update","data":[{"symbol":"BTC/USD","bids":[],"asks":[{"price":62811.1,"qty":2.38811661}],"checksum":2132157746,"timestamp":"2026-08-16T23:38:01.297998Z"}]}}
{"rx_ns": 42946680235700, "frame": {"channel":"book","type":"update","data":[{"symbol":"BTC/USD","bids":[],"asks":[{"price":62809.8,"qty":0.00222509}],"checksum":2132157746,"timestamp":"2026-08-16T23:38:01.298046Z"}]}}
{"rx_ns": 42946680241700, "frame": {"channel":"book","type":"update","data":[{"symbol":"BTC/USD","bids":[],"asks":[{"price":62849.0,"qty":0.00000000},{"price":62864.1,"qty":1.66191821}],"checksum":2132157746,"timestamp":"2026-08-16T23:38:01.298062Z"}]}}
{"rx_ns": 42946680251200, "frame": {"channel":"book","type":"update","data":[{"symbol":"BTC/USD","bids":[],"asks":[{"price":62845.9,"qty":7.95597941}],"checksum":2132157746,"timestamp":"2026-08-16T23:38:01.298404Z"}]}}
{"rx_ns": 42946680257300, "frame": {"channel":"book","type":"update","data":[{"symbol":"BTC/USD","bids":[{"price":62786.1,"qty":0.79635444}],"asks":[],"checksum":4111564792,"timestamp":"2026-08-16T23:38:01.298586Z"}]}}
{"rx_ns": 42946680263300, "frame": {"channel":"book","type":"update","data":[{"symbol":"BTC/USD","bids":[{"price":62791.2,"qty":0.16223985}],"asks":[],"checksum":49408415,"timestamp":"2026-08-16T23:38:01.298704Z"}]}}
{"rx_ns": 42946680270800, "frame": {"channel":"book","type":"update","data":[{"symbol":"BTC/USD","bids":[{"price":62780.4,"qty":0.79642633}],"asks":[],"checksum":49408415,"timestamp":"2026-08-16T23:38:01.298804Z"}]}}
{"rx_ns": 42946680280100, "frame": {"channel":"book","type":"update","data":[{"symbol":"BTC/USD","bids":[{"price":62769.8,"qty":2.38968125}],"asks":[],"checksum":49408415,"timestamp":"2026-08-16T23:38:01.298974Z"}]}}
{"rx_ns": 42946680288400, "frame": {"channel":"book","type":"update","data":[{"symbol":"BTC/USD","bids":[{"price":62762.7,"qty":7.96651154}],"asks":[],"checksum":49408415,"timestamp":"2026-08-16T23:38:01.299126Z"}]}}
{"rx_ns": 42946680296700, "frame": {"channel":"book","type":"update","data":[{"symbol":"BTC/USD","bids":[{"price":62786.1,"qty":0.00000000},{"price":62723.7,"qty":5.64716200}],"asks":[],"checksum":4258733990,"timestamp":"2026-08-16T23:38:01.299147Z"}]}}
{"rx_ns": 42946680307900, "frame": {"channel":"book","type":"update","data":[{"symbol":"BTC/USD","bids":[{"price":62769.8,"qty":0.00000000},{"price":62721.0,"qty":0.70609000}],"asks":[],"checksum":4258733990,"timestamp":"2026-08-16T23:38:01.299572Z"}]}}
{"rx_ns": 42946680317900, "frame": {"channel":"book","type":"update","data":[{"symbol":"BTC/USD","bids":[{"price":62780.1,"qty":0.00000000},{"price":62720.2,"qty":0.00711998}],"asks":[],"checksum":4258733990,"timestamp":"2026-08-16T23:38:01.299659Z"}]}}
{"rx_ns": 42946680324600, "frame": {"channel":"book","type":"update","data":[{"symbol":"BTC/USD","bids":[],"asks":[{"price":62797.6,"qty":0.00000000},{"price":62864.1,"qty":1.66191821}],"checksum":270957255,"timestamp":"2026-08-16T23:38:01.299872Z"}]}}
{"rx_ns": 42946680332300, "frame": {"channel":"book","type":"update","data":[{"symbol":"BTC/USD","bids":[{"price":62782.5,"qty":0.00000000},{"price":62719.9,"qty":2.12501460}],"asks":[],"checksum":2368727334,"timestamp":"2026-08-16T23:38:01.300272Z"}]}}
{"rx_ns": 42946680338800, "frame": {"channel":"book","type":"update","data":[{"symbol":"BTC/USD","bids":[],"asks":[{"price":62799.6,"qty":0.00000000},{"price":62864.2,"qty":5.56756520}],"checksum":1532045062,"timestamp":"2026-08-16T23:38:01.300360Z"}]}}
{"rx_ns": 42946680345600, "frame": {"channel":"book","type":"update","data":[{"symbol":"BTC/USD","bids":[],"asks":[{"price":62794.7,"qty":0.00000000},{"price":62866.5,"qty":0.00005100}],"checksum":3147494362,"timestamp":"2026-08-16T23:38:01.300382Z"}]}}
{"rx_ns": 42946770226300, "frame": {"channel":"book","type":"update","data":[{"symbol":"BTC/USD","bids":[],"asks":[{"price":62836.5,"qty":0.00000000},{"price":62871.6,"qty":0.69495739}],"checksum":3147494362,"timestamp":"2026-08-16T23:38:01.300698Z"}]}}
{"rx_ns": 42946770283400, "frame": {"channel":"book","type":"update","data":[{"symbol":"BTC/USD","bids":[{"price":62780.4,"qty":0.00000000},{"price":62718.0,"qty":0.35596944}],"asks":[],"checksum":2093402930,"timestamp":"2026-08-16T23:38:01.301848Z"}]}}
{"rx_ns": 42946770295300, "frame": {"channel":"book","type":"update","data":[{"symbol":"BTC/USD","bids":[{"price":62790.3,"qty":0.00000000},{"price":62714.4,"qty":0.16488958}],"asks":[],"checksum":3037536373,"timestamp":"2026-08-16T23:38:01.302062Z"}]}}
{"rx_ns": 42946770305200, "frame": {"channel":"book","type":"update","data":[{"symbol":"BTC/USD","bids":[{"price":62766.2,"qty":0.00000000},{"price":62713.3,"qty":0.10643220},{"price":62768.7,"qty":0.29059895}],"asks":[],"checksum":3037536373,"timestamp":"2026-08-16T23:38:01.302462Z"}]}}
{"rx_ns": 42946770315800, "frame": {"channel":"book","type":"update","data":[{"symbol":"BTC/USD","bids":[],"asks":[{"price":62858.2,"qty":0.00000000},{"price":62871.7,"qty":5.56689713}],"checksum":3037536373,"timestamp":"2026-08-16T23:38:01.303207Z"}]}}
{"rx_ns": 42946770325100, "frame": {"channel":"book","type":"update","data":[{"symbol":"BTC/USD","bids":[],"asks":[{"price":62791.3,"qty":0.19944872},{"price":62803.3,"qty":3.80113501}],"checksum":4056512674,"timestamp":"2026-08-16T23:38:01.303977Z"}]}}
{"rx_ns": 42946770334700, "frame": {"channel":"book","type":"update","data":[{"symbol":"BTC/USD","bids":[],"asks":[{"price":62807.2,"qty":0.02865913}],"checksum":4056512674,"timestamp":"2026-08-16T23:38:01.305196Z"}]}}
{"rx_ns": 42946770408200, "frame": {"channel":"book","type":"update","data":[{"symbol":"BTC/USD","bids":[{"price":62718.0,"qty":0.00015944},{"price":62723.6,"qty":0.35581000}],"asks":[],"checksum":4056512674,"timestamp":"2026-08-16T23:38:01.305581Z"}]}}
{"rx_ns": 42946770418800, "frame": {"channel":"book","type":"update","data":[{"symbol":"BTC/USD","bids":[],"asks":[{"price":62801.4,"qty":0.00000000},{"price":62874.0,"qty":0.60000000}],"checksum":4056512674,"timestamp":"2026-08-16T23:38:01.305753Z"}]}}
{"rx_ns": 42946770427500, "frame": {"channel":"book","type":"update","data":[{"symbol":"BTC/USD","bids":[],"asks":[{"price":62815.6,"qty":0.29690768}],"checksum":4056512674,"timestamp":"2026-08-16T23:38:01.305968Z"}]}}
{"rx_ns": 42946770436800, "frame": {"channel":"book","type":"update","data":[{"symbol":"BTC/USD","bids":[{"price":62782.3,"qty":0.46828931}],"asks":[],"checksum":649679329,"timestamp":"2026-08-16T23:38:01.306370Z"}]}}
{"rx_ns": 42946770444800, "frame": {"channel":"book","type":"update","data":[{"symbol":"BTC/USD","bids":[{"price":62782.6,"qty":0.04851164}],"asks":[],"checksum":1286896507,"timestamp":"2026-08-16T23:38:01.307070Z"}]}}
{"rx_ns": 42946770452700, "frame": {"channel":"book","type":"update","data":[{"symbol":"BTC/USD","bids":[],"asks":[{"price":62818.8,"qty":0.00000000},{"price":62875.0,"qty":0.04717193}],"checksum":1286896507,"timestamp":"2026-08-16T23:38:01.307212Z"}]}}
{"rx_ns": 42946770461300, "frame": {"channel":"book","type":"update","data":[{"symbol":"BTC/USD","bids":[],"asks":[{"price":62804.6,"qty":0.50933000}],"checksum":1286896507,"timestamp":"2026-08-16T23:38:01.307223Z"}]}}
{"rx_ns": 42946770469000, "frame": {"channel":"book","type":"update","data":[{"symbol":"BTC/USD","bids":[{"price":62772.0,"qty":0.23769319}],"asks":[],"checksum":1286896507,"timestamp":"2026-08-16T23:38:01.307316Z"}]}}
{"rx_ns": 42946770476800, "frame": {"channel":"book","type":"update","data":[{"symbol":"BTC/USD","bids":[{"price":62782.3,"qty":0.00000000},{"price":62718.0,"qty":0.00015944}],"asks":[],"checksum":1053413852,"timestamp":"2026-08-16T23:38:01.308098Z"}]}}
{"rx_ns": 42946770487900, "frame": {"channel":"book","type":"update","data":[{"symbol":"BTC/USD","bids":[],"asks":[{"price":62791.3,"qty":0.18031524}],"checksum":1836424615,"timestamp":"2026-08-16T23:38:01.308425Z"}]}}
{"rx_ns": 42946770496000, "frame": {"channel":"book","type":"update","data":[{"symbol":"BTC/USD","bids":[],"asks":[{"price":62814.0,"qty":0.00000000},{"price":62875.0,"qty":0.04717193}],"checksum":1836424615,"timestamp":"2026-08-16T23:38:01.308460Z"}]}}
{"rx_ns": 42946770504400, "frame": {"channel":"book","type":"update","data":[{"symbol":"BTC/USD","bids":[],"asks":[{"price":62820.0,"qty":0.00318370}],"checksum":1836424615,"timestamp":"2026-08-16T23:38:01.308623Z"}]}}
{"rx_ns": 42946770512200, "frame": {"channel":"book","type":"update","data":[{"symbol":"BTC/USD","bids":[{"price":62721.0,"qty":0.00000000},{"price":62714.4,"qty":0.16488958},{"price":62726.7,"qty":0.70609000}],"asks":[],"checksum":1836424615,"timestamp":"2026-08-16T23:38:01.308721Z"}]}}
{"rx_ns": 42946770521500, "frame": {"channel":"book","type":"update","data":[{"symbol":"BTC/USD","bids":[{"price":62776.2,"qty":0.00000000},{"price":62714.4,"qty":0.16488958}],"asks":[],"checksum":1836424615,"timestamp":"2026-08-16T23:38:01.308767Z"}]}}
{"rx_ns": 42946770530200, "frame": {"channel":"heartbeat"}}
{"rx_ns": 42946798872700, "frame": {"channel":"book","type":"update","data":[{"symbol":"BTC/USD","bids":[],"asks":[{"price":62804.0,"qty":0.00000000},{"price":62875.0,"qty":0.04717193}],"checksum":1836424615,"timestamp":"2026-08-16T23:38:01.310128Z"}]}}
{"rx_ns": 42946798937600, "frame": {"channel":"book","type":"update","data":[{"symbol":"BTC/USD","bids":[],"asks":[{"price":62833.1,"qty":0.00000000},{"price":62875.1,"qty":1.87899731}],"checksum":1836424615,"timestamp":"2026-08-16T23:38:01.310221Z"}]}}
{"rx_ns": 42946798955100, "frame": {"channel":"book","type":"update","data":[{"symbol":"BTC/USD","bids":[],"asks":[{"price":62794.8,"qty":0.15928208}],"checksum":229245831,"timestamp":"2026-08-16T23:38:01.310298Z"}]}}
{"rx_ns": 42946798967400, "frame": {"channel":"book","type":"update","data":[{"symbol":"BTC/USD","bids":[],"asks":[{"price":62799.3,"qty":0.01791000}],"checksum":3057330669,"timestamp":"2026-08-16T23:38:01.310738Z"}]}}
{"rx_ns": 42946798977900, "frame": {"channel":"book","type":"update","data":[{"symbol":"BTC/USD","bids":[],"asks":[{"price":62795.6,"qty":0.00000000},{"price":62875.0,"qty":0.04717193}],"checksum":3759523045,"timestamp":"2026-08-16T23:38:01.311585Z"}]}}
{"rx_ns": 42946798988300, "frame": {"channel":"book","type":"update","data":[{"symbol":"BTC/USD","bids":[{"price":62779.1,"qty":0.06960000}],"asks":[],"checksum":3759523045,"timestamp":"2026-08-16T23:38:01.311915Z"}]}}
{"rx_ns": 42946798998000, "frame": {"channel":"book","type":"update","data":[{"symbol":"BTC/USD","bids":[{"price":62780.2,"qty":0.01145513}],"asks":[],"checksum":3759523045,"timestamp":"2026-08-16T23:38:01.312162Z"}]}}
{"rx_ns": 42946799008100, "frame": {"channel":"book","type":"update","data":[{"symbol":"BTC/USD","bids":[{"price":62780.2,"qty":0.00000000},{"price":62714.4,"qty":0.16488958}],"asks":[],"checksum":3759523045,"timestamp":"2026-08-16T23:38:01.312192Z"}]}}
{"rx_ns": 42946799018400, "frame": {"channel":"book","type":"update","data":[{"symbol":"BTC/USD","bids":[{"price":62780.5,"qty":0.07234750}],"asks":[],"checksum":739450336,"timestamp":"2026-08-16T23:38:01.312302Z"}]}}
{"rx_ns": 42946799026400, "frame": {"channel":"book","type":"update","data":[{"symbol":"BTC/USD","bids":[],"asks":[{"price":62816.3,"qty":0.00000000},{"price":62875.1,"qty":1.87899731}],"checksum":739450336,"timestamp":"2026-08-16T23:38:01.312516Z"}]}}
{"rx_ns": 42946799036300, "frame": {"channel":"book","type":"update","data":[{"symbol":"BTC/USD","bids":[{"price":62782.6,"qty":0.00000000},{"price":62713.3,"qty":0.10643220}],"asks":[],"checksum":3662340389,"timestamp":"2026-08-16T23:38:01.315139Z"}]}}
{"rx_ns": 42946799045800, "frame": {"channel":"book","type":"update","data":[{"symbol":"BTC/USD","bids":[],"asks":[{"price":62826.5,"qty":0.89136100}],"checksum":3662340389,"timestamp":"2026-08-16T23:38:01.315579Z"}]}}
{"rx_ns": 42946799052200, "frame": {"channel":"book","type":"update","data":[{"symbol":"BTC/USD","bids":[{"price":62717.6,"qty":0.06960000}],"asks":[],"checksum":3662340389,"timestamp":"2026-08-16T23:38:01.316033Z"}]}}
{"rx_ns": 42946799058100, "frame": {"channel":"book","type":"update","data":[{"symbol":"BTC/USD","bids":[],"asks":[{"price":62833.0,"qty":0.00000000},{"price":62875.1,"qty":1.87899731}],"checksum":3662340389,"timestamp":"2026-08-16T23:38:01.316073Z"}]}}
{"rx_ns": 42946799067000, "frame": {"channel":"book","type":"update","data":[{"symbol":"BTC/USD","bids":[{"price":62780.6,"qty":0.06848480}],"asks":[],"checksum":1474485455,"timestamp":"2026-08-16T23:38:01.316742Z"}]}}
{"rx_ns": 42946799073900, "frame": {"channel":"book","type":"update","data":[{"symbol":"BTC/USD","bids":[{"price":62733.8,"qty":0.00000000},{"price":62714.4,"qty":0.16488958}],"asks":[],"checksum":1474485455,"timestamp":"2026-08-16T23:38:01.316814Z"}]}}
{"rx_ns": 42946799082700, "frame": {"channel":"book","type":"update","data":[{"symbol":"BTC/USD","bids":[],"asks":[{"price":62800.8,"qty":0.00000000},{"price":62875.2,"qty":5.56658959}],"checksum":1474485455,"timestamp":"2026-08-16T23:38:01.317073Z"}]}}
{"rx_ns": 42946799089900, "frame": {"channel":"book","type":"update","data":[{"symbol":"BTC/USD","bids":[],"asks":[{"price":62794.8,"qty":0.00000000},{"price":62875.3,"qty":0.01000000}],"checksum":3365392916,"timestamp":"2026-08-16T23:38:01.317192Z"}]}}
{"rx_ns": 42946799096400, "frame": {"channel":"book","type":"update","data":[{"symbol":"BTC/USD","bids":[],"asks":[{"price":62799.9,"qty":0.79618083}],"checksum":1560795841,"timestamp":"2026-08-16T23:38:01.317721Z"}]}}
{"rx_ns": 42946799102300, "frame": {"channel":"book","type":"update","data":[{"symbol":"BTC/USD","bids":[{"price":62717.6,"qty":0.00000000},{"price":62713.3,"qty":0.10643220}],"asks":[],"checksum":1560795841,"timestamp":"2026-08-16T23:38:01.317977Z"}]}}
{"rx_ns": 42946799180800, "frame": {"channel":"book","type":"update","data":[{"symbol":"BTC/USD","bids":[],"asks":[{"price":62866.8,"qty":0.06960000}],"checksum":1560795841,"timestamp":"2026-08-16T23:38:01.318065Z"}]}}
{"rx_ns": 42946799188600, "frame": {"channel":"book","type":"update","data":[{"symbol":"BTC/USD","bids":[{"price":62735.9,"qty":0.00000000},{"price":62712.7,"qty":0.15985195}],"asks":[],"checksum":1560795841,"timestamp":"2026-08-16T23:38:01.318684Z"}]}}
{"rx_ns": 42946799195500, "frame": {"channel":"book","type":"update","data":[{"symbol":"BTC/USD","bids":[],"asks":[{"price":62809.9,"qty":0.00000000},{"price":62875.2,"qty":5.56658959}],"checksum":1560795841,"timestamp":"2026-08-16T23:38:01.318857Z"}]}}
{"rx_ns": 42946799202200, "frame": {"channel":"book","type":"update","data":[{"symbol":"BTC/USD","bids":[],"asks":[{"price":62799.9,"qty":0.00000000},{"price":62875.3,"qty":0.01000000}],"checksum":3365392916,"timestamp":"2026-08-16T23:38:01.319003Z"}]}}
{"rx_ns": 42946799210100, "frame": {"channel":"book","type":"update","data":[{"symbol":"BTC/USD","bids":[{"price":62768.7,"qty":0.18766548},{"price":62774.2,"qty":0.13159865}],"asks":[],"checksum":3365392916,"timestamp":"2026-08-16T23:38:01.319197Z"}]}}
{"rx_ns": 42946799218800, "frame": {"channel":"book","type":"update","data":[{"symbol":"BTC/USD","bids":[{"price":62752.8,"qty":0.00000000},{"price":62712.2,"qty":1.70978979}],"asks":[],"checksum":3365392916,"timestamp":"2026-08-16T23:38:01.319671Z"}]}}
{"rx_ns": 42946799227400, "frame": {"channel":"book","type":"update","data":[{"symbol":"BTC/USD","bids":[],"asks":[{"price":62800.5,"qty":0.12400653}],"checksum":3787501510,"timestamp":"2026-08-16T23:38:01.320079Z"}]}}
{"rx_ns": 42946799242700, "frame": {"channel":"book","type":"update","data":[{"symbol":"BTC/USD","bids":[],"asks":[{"price":62800.6,"qty":0.00000000},{"price":62875.9,"qty":0.00159000},{"price":62803.2,"qty":0.18489680}],"checksum":2574780886,"timestamp":"2026-08-16T23:38:01.320100Z"}]}}
{"rx_ns": 42946799259300, "frame": {"channel":"book","type":"update","data":[{"symbol":"BTC/USD","bids":[],"asks":[{"price":62873.1,"qty":0.06960000}],"checksum":2574780886,"timestamp":"2026-08-16T23:38:01.320119Z"}]}}
{"rx_ns": 42946799267900, "frame": {"channel":"book","type":"update","data":[{"symbol":"BTC/USD","bids":[{"price":62766.0,"qty":0.00796609}],"asks":[],"checksum":2574780886,"timestamp":"2026-08-16T23:38:01.321620Z"}]}}
{"rx_ns": 42946799276400, "frame": {"channel":"book","type":"update","data":[{"symbol":"BTC/USD","bids":[{"price":62717.6,"qty":0.06960000}],"asks":[],"checksum":2574780886,"timestamp":"2026-08-16T23:38:01.322282Z"}]}}
{"rx_ns": 42946799284800, "frame": {"channel":"book","type":"update","data":[{"symbol":"BTC/USD","bids":[{"price":62724.1,"qty":0.00000000},{"price":62712.2,"qty":1.70978979}],"asks":[],"checksum":2574780886,"timestamp":"2026-08-16T23:38:01.322968Z"}]}}
{"rx_ns": 42946799328500, "frame": {"channel":"book","type":"update","data":[{"symbol":"BTC/USD","bids":[{"price":62723.6,"qty":0.00000000},{"price":62712.1,"qty":5.65674500},{"price":62723.8,"qty":0.35581000}],"asks":[],"checksum":2574780886,"timestamp":"2026-08-16T23:38:01.323501Z"}]}}
{"rx_ns": 42946799341800, "frame": {"channel":"book","type":"update","data":[{"symbol":"BTC/USD","bids":[],"asks":[{"price":62800.7,"qty":0.00000000},{"price":62875.3,"qty":0.01000000},{"price":62805.5,"qty":0.19620257}],"checksum":1273973075,"timestamp":"2026-08-16T23:38:01.323612Z"}]}}
{"rx_ns": 42946799351700, "frame": {"channel":"book","type":"update","data":[{"symbol":"BTC/USD","bids":[{"price":62774.2,"qty":0.02867420},{"price":62775.7,"qty":0.10292200}],"asks":[],"checksum":1273973075,"timestamp":"2026-08-16T23:38:01.324011Z"}]}}
{"rx_ns": 42946799360400, "frame": {"channel":"book","type":"update","data":[{"symbol":"BTC/USD","bids":[],"asks":[{"price":62803.3,"qty":0.01100000},{"price":62805.5,"qty":3.98616031}],"checksum":1273973075,"timestamp":"2026-08-16T23:38:01.324907Z"}]}}
{"rx_ns": 42946799369200, "frame": {"channel":"book","type":"update","data":[{"symbol":"BTC/USD","bids":[{"price":62752.9,"qty":0.00000000},{"price":62712.2,"qty":1.70978979}],"asks":[],"checksum":1273973075,"timestamp":"2026-08-16T23:38:01.325018Z"}]}}
{"rx_ns": 42946799377900, "frame": {"channel":"book","type":"update","data":[{"symbol":"BTC/USD","bids":[],"asks":[{"price":62799.3,"qty":0.00000000},{"price":62875.3,"qty":0.01000000}],"checksum":1005810463,"timestamp":"2026-08-16T23:38:01.325271Z"}]}}
{"rx_ns": 42946799387100, "frame": {"channel":"book","type":"update","data":[{"symbol":"BTC/USD","bids":[],"asks":[{"price":62800.5,"qty":0.00005100}],"checksum":485387837,"timestamp":"2026-08-16T23:38:01.325338Z"}]}}
{"rx_ns": 42946799395400, "frame": {"channel":"book","type":"update","data":[{"symbol":"BTC/USD","bids":[],"asks":[{"price":62805.6,"qty":0.00000000},{"price":62875.9,"qty":0.00159000}],"checksum":485387837,"timestamp":"2026-08-16T23:38:01.325382Z"}]}}
{"rx_ns": 42946799405600, "frame": {"channel":"book","type":"update","data":[{"symbol":"BTC/USD","bids":[{"price":62784.0,"qty":0.00318553}],"asks":[],"checksum":557502852,"timestamp":"2026-08-16T23:38:01.327190Z"}]}}
{"rx_ns": 42946799414400, "frame": {"channel":"book","type":"update","data":[{"symbol":"BTC/USD","bids":[],"asks":[{"price":62799.8,"qty":0.36163073}],"checksum":300246037,"timestamp":"2026-08-16T23:38:01.327208Z"}]}}
{"rx_ns": 42946799423200, "frame": {"channel":"book","type":"update","data":[{"symbol":"BTC/USD","bids":[],"asks":[{"price":62799.8,"qty":0.00000000},{"price":62875.9,"qty":0.00159000}],"checksum":557502852,"timestamp":"2026-08-16T23:38:01.327228Z"}]}}
{"rx_ns": 42946799432300, "frame": {"channel":"book","type":"update","data":[{"symbol":"BTC/USD","bids":[],"asks":[{"price":62821.5,"qty":1.02987080},{"price":62825.6,"qty":0.35154500}],"checksum":557502852,"timestamp":"2026-08-16T23:38:01.327623Z"}]}}
{"rx_ns": 42946799442800, "frame": {"channel":"book","type":"update","data":[{"symbol":"BTC/USD","bids":[],"asks":[{"price":62794.5,"qty":0.00000000},{"price":62876.0,"qty":0.47771147}],"checksum":3533723450,"timestamp":"2026-08-16T23:38:01.327642Z"}]}}
{"rx_ns": 42946799451200, "frame": {"channel":"book","type":"update","data":[{"symbol":"BTC/USD","bids":[{"price":62791.2,"qty":0.09263985}],"asks":[],"checksum":4224961254,"timestamp":"2026-08-16T23:38:01.327917Z"}]}}
{"rx_ns": 42946799459000, "frame": {"channel":"book","type":"update","data":[{"symbol":"BTC/USD","bids":[],"asks":[{"price":62791.3,"qty":0.25991524}],"checksum":1140291382,"timestamp":"2026-08-16T23:38:01.328326Z"}]}}
{"rx_ns": 42946799466900, "frame": {"channel":"book","type":"update","data":[{"symbol":"BTC/USD","bids":[{"price":62775.7,"qty":0.00000000},{"price":62712.2,"qty":1.70978979},{"price":62774.2,"qty":0.13159865}],"asks":[],"checksum":1140291382,"timestamp":"2026-08-16T23:38:01.330877Z"}]}}
{"rx_ns": 42946799476700, "frame": {"channel":"book","type":"update","data":[{"symbol":"BTC/USD","bids":[{"price":62774.2,"qty":0.10292445}],"asks":[],"checksum":1140291382,"timestamp":"2026-08-16T23:38:01.330896Z"}]}}
{"rx_ns": 42946799506300, "frame": {"channel":"book","type":"update","data":[{"symbol":"BTC/USD","bids":[],"asks":[{"price":62804.6,"qty":0.00000000},{"price":62876.4,"qty":0.23890000}],"checksum":1140291382,"timestamp":"2026-08-16T23:38:01.332065Z"}]}}
{"rx_ns": 42946799516700, "frame": {"channel":"book","type":"update","data":[{"symbol":"BTC/USD","bids":[],"asks":[{"price":62791.8,"qty":0.00000000},{"price":62878.8,"qty":0.11123578}],"checksum":2004382442,"timestamp":"2026-08-16T23:38:01.332349Z"}]}}
{"rx_ns": 42946799525400, "frame": {"channel":"book","type":"update","data":[{"symbol":"BTC/USD","bids":[],"asks":[{"price":62791.3,"qty":0.33791524}],"checksum":3085037868,"timestamp":"2026-08-16T23:38:01.332493Z"}]}}
{"rx_ns": 42946799533600, "frame": {"channel":"book","type":"update","data":[{"symbol":"BTC/USD","bids":[],"asks":[{"price":62805.5,"qty":0.19620257},{"price":62803.3,"qty":3.80107593}],"checksum":689102351,"timestamp":"2026-08-16T23:38:01.333382Z"}]}}
{"rx_ns": 42946799568000, "frame": {"channel":"book","type":"update","data":[{"symbol":"BTC/USD","bids":[],"asks":[{"price":62851.0,"qty":15.00000000}],"checksum":689102351,"timestamp":"2026-08-16T23:38:01.333719Z"}]}}
{"rx_ns": 42946799577600, "frame": {"channel":"book","type":"update","data":[{"symbol":"BTC/USD","bids":[],"asks":[{"price":62791.3,"qty":0.25846517}],"checksum":2683164719,"timestamp":"2026-08-16T23:38:01.334122Z"}]}}
{"rx_ns": 42946799585800, "frame": {"channel":"book","type":"update","data":[{"symbol":"BTC/USD","bids":[],"asks":[{"price":62815.6,"qty":0.00000000},{"price":62878.8,"qty":0.11123578}],"checksum":2683164719,"timestamp":"2026-08-16T23:38:01.334402Z"}]}}
{"rx_ns": 42946799594600, "frame": {"channel":"book","type":"update","data":[{"symbol":"BTC/USD","bids":[],"asks":[{"price":62803.2,"qty":1.63214579}],"checksum":3125685034,"timestamp":"2026-08-16T23:38:01.335930Z"}]}}
{"rx_ns": 42946799602600, "frame": {"channel":"book","type":"update","data":[{"symbol":"BTC/USD","bids":[{"price":62773.1,"qty":0.00000000},{"price":62712.1,"qty":5.65674500},{"price":62775.4,"qty":0.03185508}],"asks":[],"checksum":3125685034,"timestamp":"2026-08-16T23:38:01.336530Z"}]}}
{"rx_ns": 42946799611900, "frame": {"channel":"book","type":"update","data":[{"symbol":"BTC/USD","bids":[{"price":62791.2,"qty":0.25192193}],"asks":[],"checksum":2664822469,"timestamp":"2026-08-16T23:38:01.337133Z"}]}}
{"rx_ns": 42946799619600, "frame": {"channel":"book","type":"update","data":[{"symbol":"BTC/USD","bids":[{"price":62773.7,"qty":0.04778169}],"asks":[],"checksum":2664822469,"timestamp":"2026-08-16T23:38:01.340190Z"}]}}
{"rx_ns": 42946799627200, "frame": {"channel":"book","type":"update","data":[{"symbol":"BTC/USD","bids":[{"price":62773.7,"qty":0.00000000},{"price":62712.1,"qty":5.65674500}],"asks":[],"checksum":2664822469,"timestamp":"2026-08-16T23:38:01.340235Z"}]}}
{"rx_ns": 42946799635900, "frame": {"channel":"book","type":"update","data":[{"symbol":"BTC/USD","bids":[],"asks":[{"price":62809.8,"qty":0.00000000},{"price":62879.0,"qty":0.00297725},{"price":62805.4,"qty":0.00222509}],"checksum":2664822469,"timestamp":"2026-08-16T23:38:01.340716Z"}]}}
{"rx_ns": 42946799645000, "frame": {"channel":"book","type":"update","data":[{"symbol":"BTC/USD","bids":[{"price":62791.2,"qty":0.33152193}],"asks":[],"checksum":2305038319,"timestamp":"2026-08-16T23:38:01.341635Z"}]}}
{"rx_ns": 42946799653600, "frame": {"channel":"book","type":"update","data":[{"symbol":"BTC/USD","bids":[{"price":62726.7,"qty":0.00000000},{"price":62710.2,"qty":0.00159400},{"price":62726.9,"qty":0.70609000}],"asks":[],"checksum":2305038319,"timestamp":"2026-08-16T23:38:01.341911Z"}]}}
{"rx_ns": 42946799662800, "frame": {"channel":"book","type":"update","data":[{"symbol":"BTC/USD","bids":[],"asks":[{"price":62854.1,"qty":0.00000000},{"price":62879.0,"qty":0.00297725}],"checksum":2305038319,"timestamp":"2026-08-16T23:38:01.342863Z"}]}}
{"rx_ns": 42946799671200, "frame": {"channel":"book","type":"update","data":[{"symbol":"BTC/USD","bids":[{"price":62739.3,"qty":15.00000000}],"asks":[],"checksum":2305038319,"timestamp":"2026-08-16T23:38:01.343123Z"}]}}
{"rx_ns": 42946799678900, "frame": {"channel":"book","type":"update","data":[{"symbol":"BTC/USD","bids":[{"price":62791.2,"qty":0.25192193}],"asks":[],"checksum":2664822469,"timestamp":"2026-08-16T23:38:01.343577Z"}]}}
{"rx_ns": 42946799686700, "frame": {"channel":"book","type":"update","data":[{"symbol":"BTC/USD","bids":[{"price":62775.4,"qty":0.00000000},{"price":62712.1,"qty":5.65674500},{"price":62778.2,"qty":0.07963274}],"asks":[],"checksum":2664822469,"timestamp":"2026-08-16T23:38:01.344059Z"}]}}
{"rx_ns": 42946799695700, "frame": {"channel":"book","type":"update","data":[{"symbol":"BTC/USD","bids":[],"asks":[{"price":62791.3,"qty":0.17886517}],"checksum":4148880007,"timestamp":"2026-08-16T23:38:01.344185Z"}]}}
{"rx_ns": 42946799703500, "frame": {"channel":"book","type":"update","data":[{"symbol":"BTC/USD","bids":[],"asks":[{"price":62803.9,"qty":0.00000000},{"price":62879.7,"qty":0.00200000}],"checksum":4148880007,"timestamp":"2026-08-16T23:38:01.344827Z"}]}}
{"rx_ns": 42946799711900, "frame": {"channel":"book","type":"update","data":[{"symbol":"BTC/USD","bids":[],"asks":[{"price":62791.3,"qty":0.39786514}],"checksum":1224939851,"timestamp":"2026-08-16T23:38:01.344930Z"}]}}
{"rx_ns": 42946799720400, "frame": {"channel":"book","type":"update","data":[{"symbol":"BTC/USD","bids":[],"asks":[{"price":62832.0,"qty":1.40486793}],"checksum":1224939851,"timestamp":"2026-08-16T23:38:01.345344Z"}]}}
{"rx_ns": 42946799728200, "frame": {"channel":"book","type":"update","data":[{"symbol":"BTC/USD","bids":[],"asks":[{"price":62791.3,"qty":0.47746514}],"checksum":2103821309,"timestamp":"2026-08-16T23:38:01.346358Z"}]}}
{"rx_ns": 42946799735900, "frame": {"channel":"book","type":"update","data":[{"symbol":"BTC/USD","bids":[{"price":62791.2,"qty":0.33152193}],"asks":[],"checksum":1792287447,"timestamp":"2026-08-16T23:38:01.346785Z"}]}}
{"rx_ns": 42946799743500, "frame": {"channel":"book","type":"update","data":[{"symbol":"BTC/USD","bids":[],"asks":[{"price":62791.3,"qty":0.39786514}],"checksum":1588787297,"timestamp":"2026-08-16T23:38:01.346966Z"}]}}
{"rx_ns": 42946799751200, "frame": {"channel":"book","type":"update","data":[{"symbol":"BTC/USD","bids":[{"price":62778.0,"qty":0.00318583}],"asks":[],"checksum":1588787297,"timestamp":"2026-08-16T23:38:01.347039Z"}]}}
{"rx_ns": 42946799760000, "frame": {"channel":"book","type":"update","data":[{"symbol":"BTC/USD","bids":[{"price":62791.2,"qty":0.25192193}],"asks":[],"checksum":1224939851,"timestamp":"2026-08-16T23:38:01.347147Z"}]}}
{"rx_ns": 42946799767700, "frame": {"channel":"book","type":"update","data":[{"symbol":"BTC/USD","bids":[],"asks":[{"price":62791.3,"qty":0.47746514}],"checksum":2103821309,"timestamp":"2026-08-16T23:38:01.347180Z"}]}}
{"rx_ns": 42946799775600, "frame": {"channel":"book","type":"update","data":[{"symbol":"BTC/USD","bids":[{"price":62777.9,"qty":0.07187345}],"asks":[],"checksum":2103821309,"timestamp":"2026-08-16T23:38:01.347759Z"}]}}
{"rx_ns": 42946799783400, "frame": {"channel":"book","type":"update","data":[{"symbol":"BTC/USD","bids":[{"price":62778.8,"qty":0.03185309}],"asks":[],"checksum":2103821309,"timestamp":"2026-08-16T23:38:01.348111Z"}]}}
{"rx_ns": 42946799804000, "frame": {"channel":"book","type":"update","data":[{"symbol":"BTC/USD","bids":[{"price":62774.9,"qty":0.02867388}],"asks":[],"checksum":2103821309,"timestamp":"2026-08-16T23:38:01.350907Z"}]}}
{"rx_ns": 42946799813200, "frame": {"channel":"book","type":"update","data":[{"symbol":"BTC/USD","bids":[],"asks":[{"price":62815.5,"qty":1.59575715}],"checksum":2103821309,"timestamp":"2026-08-16T23:38:01.353537Z"}]}}
{"rx_ns": 42946799820900, "frame": {"channel":"book","type":"update","data":[{"symbol":"BTC/USD","bids":[],"asks":[{"price":62805.4,"qty":0.00000000},{"price":62879.0,"qty":0.00297725},{"price":62803.1,"qty":0.00222509}],"checksum":3870000262,"timestamp":"2026-08-16T23:38:01.354200Z"}]}}
{"rx_ns": 42946799830400, "frame": {"channel":"book","type":"update","data":[{"symbol":"BTC/USD","bids":[],"asks":[{"price":62811.0,"qty":0.71285281}],"checksum":3870000262,"timestamp":"2026-08-16T23:38:01.354452Z"}]}}
{"rx_ns": 42946799838300, "frame": {"channel":"book","type":"update","data":[{"symbol":"BTC/USD","bids":[],"asks":[{"price":62846.9,"qty":0.00000000},{"price":62878.8,"qty":0.11123578}],"checksum":3870000262,"timestamp":"2026-08-16T23:38:01.355823Z"}]}}
{"rx_ns": 42946799847100, "frame": {"channel":"book","type":"update","data":[{"symbol":"BTC/USD","bids":[{"price":62763.0,"qty":0.00000000},{"price":62713.3,"qty":0.10643220}],"asks":[],"checksum":3870000262,"timestamp":"2026-08-16T23:38:01.356770Z"}]}}
{"rx_ns": 42946799855700, "frame": {"channel":"book","type":"update","data":[{"symbol":"BTC/USD","bids":[{"price":62779.5,"qty":0.71004400}],"asks":[],"checksum":3870000262,"timestamp":"2026-08-16T23:38:01.357109Z"}]}}
{"rx_ns": 42946799883400, "frame": {"channel":"book","type":"update","data":[{"symbol":"BTC/USD","bids":[{"price":62778.0,"qty":0.00000000},{"price":62713.3,"qty":0.10643220}],"asks":[],"checksum":3870000262,"timestamp":"2026-08-16T23:38:01.358542Z"}]}}
{"rx_ns": 42946799893200, "frame": {"channel":"book","type":"update","data":[{"symbol":"BTC/USD","bids":[],"asks":[{"price":62803.1,"qty":0.00000000},{"price":62879.0,"qty":0.00297725}],"checksum":2103821309,"timestamp":"2026-08-16T23:38:01.359716Z"}]}}
{"rx_ns": 42946799902000, "frame": {"channel":"book","type":"update","data":[{"symbol":"BTC/USD","bids":[],"asks":[{"price":62823.3,"qty":0.00000000},{"price":62879.7,"qty":0.00200000}],"checksum":2103821309,"timestamp":"2026-08-16T23:38:01.359836Z"}]}}
{"rx_ns": 42946799911100, "frame": {"channel":"book","type":"update","data":[{"symbol":"BTC/USD","bids":[{"price":62724.2,"qty":0.00000000},{"price":62712.7,"qty":0.15985195}],"asks":[],"checksum":2103821309,"timestamp":"2026-08-16T23:38:01.361977Z"}]}}
{"rx_ns": 42946799919600, "frame": {"channel":"book","type":"update","data":[{"symbol":"BTC/USD","bids":[],"asks":[{"price":62794.2,"qty":0.00005100}],"checksum":1846346802,"timestamp":"2026-08-16T23:38:01.362358Z"}]}}
{"rx_ns": 42946799927800, "frame": {"channel":"book","type":"update","data":[{"symbol":"BTC/USD","bids":[],"asks":[{"price":62799.4,"qty":0.00000000},{"price":62879.7,"qty":0.00200000}],"checksum":1436342704,"timestamp":"2026-08-16T23:38:01.362888Z"}]}}
{"rx_ns": 42946799936300, "frame": {"channel":"book","type":"update","data":[{"symbol":"BTC/USD","bids":[],"asks":[{"price":62879.4,"qty":0.06960000}],"checksum":1436342704,"timestamp":"2026-08-16T23:38:01.363006Z"}]}}
{"rx_ns": 42946799956400, "frame": {"channel":"book","type":"update","data":[{"symbol":"BTC/USD","bids":[{"price":62780.6,"qty":0.30523348}],"asks":[],"checksum":1180419952,"timestamp":"2026-08-16T23:38:01.364522Z"}]}}
{"rx_ns": 42946799965300, "frame": {"channel":"book","type":"update","data":[{"symbol":"BTC/USD","bids":[{"price":62778.2,"qty":0.00000000},{"price":62712.6,"qty":1.50000000}],"asks":[],"checksum":1180419952,"timestamp":"2026-08-16T23:38:01.364602Z"}]}}
{"rx_ns": 42946799973900, "frame": {"channel":"book","type":"update","data":[{"symbol":"BTC/USD","bids":[],"asks":[{"price":62803.1,"qty":0.00222509}],"checksum":2712371193,"timestamp":"2026-08-16T23:38:01.365427Z"}]}}
{"rx_ns": 42946799981700, "frame": {"channel":"book","type":"update","data":[{"symbol":"BTC/USD","bids":[{"price":62791.2,"qty":0.33152193}],"asks":[],"checksum":2047281102,"timestamp":"2026-08-16T23:38:01.365847Z"}]}}
{"rx_ns": 42946799989500, "frame": {"channel":"book","type":"update","data":[{"symbol":"BTC/USD","bids":[{"price":62789.7,"qty":0.79630822}],"asks":[],"checksum":4019963876,"timestamp":"2026-08-16T23:38:01.366121Z"}]}}
{"rx_ns": 42946799997200, "frame": {"channel":"book","type":"update","data":[{"symbol":"BTC/USD","bids":[{"price":62728.7,"qty":5.57957533}],"asks":[],"checksum":4019963876,"timestamp":"2026-08-16T23:38:01.366214Z"}]}}
{"rx_ns": 42946800004900, "frame": {"channel":"book","type":"update","data":[{"symbol":"BTC/USD","bids":[{"price":62778.8,"qty":0.00000000},{"price":62712.7,"qty":0.15985195},{"price":62780.1,"qty":0.07963030}],"asks":[],"checksum":4019963876,"timestamp":"2026-08-16T23:38:01.366425Z"}]}}
{"rx_ns": 42946800015000, "frame": {"channel":"book","type":"update","data":[{"symbol":"BTC/USD","bids":[{"price":62791.2,"qty":0.25192193}],"asks":[],"checksum":1476251283,"timestamp":"2026-08-16T23:38:01.367614Z"}]}}
{"rx_ns": 42946800022900, "frame": {"channel":"book","type":"update","data":[{"symbol":"BTC/USD","bids":[{"price":62791.2,"qty":0.33152193}],"asks":[],"checksum":4019963876,"timestamp":"2026-08-16T23:38:01.368102Z"}]}}
{"rx_ns": 42946800030700, "frame": {"channel":"book","type":"update","data":[{"symbol":"BTC/USD","bids":[],"asks":[{"price":62796.1,"qty":0.00000000},{"price":62879.4,"qty":0.06960000}],"checksum":202930260,"timestamp":"2026-08-16T23:38:01.370298Z"}]}}
{"rx_ns": 42946800039300, "frame": {"channel":"book","type":"update","data":[{"symbol":"BTC/USD","bids":[],"asks":[{"price":62812.6,"qty":0.00000000},{"price":62879.7,"qty":0.00200000}],"checksum":202930260,"timestamp":"2026-08-16T23:38:01.370615Z"}]}}
{"rx_ns": 42946800048900, "frame": {"channel":"book","type":"update","data":[{"symbol":"BTC/USD","bids":[],"asks":[{"price":62803.2,"qty":1.44724899},{"price":62810.9,"qty":0.18489680}],"checksum":748753257,"timestamp":"2026-08-16T23:38:01.370680Z"}]}}
{"rx_ns": 42946800057500, "frame": {"channel":"book","type":"update","data":[{"symbol":"BTC/USD","bids":[{"price":62780.7,"qty":0.03185211}],"asks":[],"checksum":1456095657,"timestamp":"2026-08-16T23:38:01.372911Z"}]}}
{"rx_ns": 42946800065400, "frame": {"channel":"book","type":"update","data":[{"symbol":"BTC/USD","bids":[],"asks":[{"price":62825.6,"qty":0.07154500},{"price":62826.6,"qty":0.28000000}],"checksum":1456095657,"timestamp":"2026-08-16T23:38:01.374299Z"}]}}
{"rx_ns": 42946800759000, "frame": {"channel":"book","type":"update","data":[{"symbol":"BTC/USD","bids":[],"asks":[{"price":62791.3,"qty":0.39786514}],"checksum":2013377784,"timestamp":"2026-08-16T23:38:01.377286Z"}]}}
{"rx_ns": 42946800801400, "frame": {"channel":"book","type":"update","data":[{"symbol":"BTC/USD","bids":[],"asks":[{"price":62803.1,"qty":0.00000000},{"price":62879.4,"qty":0.06960000}],"checksum":2942002923,"timestamp":"2026-08-16T23:38:01.377312Z"}]}}
{"rx_ns": 42946800819100, "frame": {"channel":"book","type":"update","data":[{"symbol":"BTC/USD","bids":[],"asks":[{"price":62815.5,"qty":0.00000000},{"price":62879.7,"qty":0.00200000},{"price":62816.2,"qty":1.59575715}],"checksum":2942002923,"timestamp":"2026-08-16T23:38:01.377709Z"}]}}
{"rx_ns": 42946800835000, "frame": {"channel":"book","type":"update","data":[{"symbol":"BTC/USD","bids":[{"price":62774.2,"qty":0.00000000},{"price":62713.3,"qty":0.10643220},{"price":62776.2,"qty":0.10292118}],"asks":[],"checksum":2942002923,"timestamp":"2026-08-16T23:38:01.377830Z"}]}}
{"rx_ns": 42946800848500, "frame": {"channel":"book","type":"update","data":[{"symbol":"BTC/USD","bids":[],"asks":[{"price":62792.6,"qty":0.32999995}],"checksum":2745058805,"timestamp":"2026-08-16T23:38:01.377909Z"}]}}
{"rx_ns": 42946800866700, "frame": {"channel":"book","type":"update","data":[{"symbol":"BTC/USD","bids":[],"asks":[{"price":62810.3,"qty":0.13109402}],"checksum":2745058805,"timestamp":"2026-08-16T23:38:01.377940Z"}]}}
{"rx_ns": 42946800883600, "frame": {"channel":"book","type":"update","data":[{"symbol":"BTC/USD","bids":[],"asks":[{"price":62846.8,"qty":0.02057681}],"checksum":2745058805,"timestamp":"2026-08-16T23:38:01.378833Z"}]}}
{"rx_ns": 42946800895700, "frame": {"channel":"book","type":"update","data":[{"symbol":"BTC/USD","bids":[],"asks":[{"price":62803.2,"qty":1.50323371}],"checksum":620378616,"timestamp":"2026-08-16T23:38:01.379888Z"}]}}
{"rx_ns": 42946800906200, "frame": {"channel":"book","type":"update","data":[{"symbol":"BTC/USD","bids":[],"asks":[{"price":62818.8,"qty":0.46828931}],"checksum":620378616,"timestamp":"2026-08-16T23:38:01.379989Z"}]}}
{"rx_ns": 42946800915500, "frame": {"channel":"book","type":"update","data":[{"symbol":"BTC/USD","bids":[{"price":62780.5,"qty":0.06101297}],"asks":[],"checksum":620378616,"timestamp":"2026-08-16T23:38:01.382498Z"}]}}
{"rx_ns": 42946801500200, "frame": {"channel":"book","type":"update","data":[{"symbol":"BTC/USD","bids":[],"asks":[{"price":62854.2,"qty":0.06960000},{"price":62860.6,"qty":0.01613461}],"checksum":620378616,"timestamp":"2026-08-16T23:38:01.382592Z"}]}}
{"rx_ns": 42946801522800, "frame": {"channel":"book","type":"update","data":[{"symbol":"BTC/USD","bids":[{"price":62781.7,"qty":0.01050463}],"asks":[],"checksum":2311275496,"timestamp":"2026-08-16T23:38:01.382769Z"}]}}
{"rx_ns": 42946801534100, "frame": {"channel":"book","type":"update","data":[{"symbol":"BTC/USD","bids":[],"asks":[{"price":62816.2,"qty":0.00000000},{"price":62876.0,"qty":0.47771147},{"price":62818.7,"qty":1.59575715}],"checksum":2311275496,"timestamp":"2026-08-16T23:38:01.383877Z"}]}}
{"rx_ns": 42946801585100, "frame": {"channel":"book","type":"update","data":[{"symbol":"BTC/USD","bids":[{"price":62791.2,"qty":0.40796420}],"asks":[],"checksum":1748223774,"timestamp":"2026-08-16T23:38:01.387898Z"}]}}
{"rx_ns": 42946801618000, "frame": {"channel":"book","type":"update","data":[{"symbol":"BTC/USD","bids":[],"asks":[{"price":62791.3,"qty":0.38601214}],"checksum":4243915096,"timestamp":"2026-08-16T23:38:01.388130Z"}]}}
{"rx_ns": 42946801637300, "frame": {"channel":"book","type":"update","data":[{"symbol":"BTC/USD","bids":[],"asks":[{"price":62791.3,"qty":0.39193864}],"checksum":300863609,"timestamp":"2026-08-16T23:38:01.395214Z"}]}}
{"rx_ns": 42946801646300, "frame": {"channel":"book","type":"update","data":[{"symbol":"BTC/USD","bids":[],"asks":[{"price":62826.6,"qty":0.00000000},{"price":62876.0,"qty":0.47771147},{"price":62827.7,"qty":0.28000000}],"checksum":300863609,"timestamp":"2026-08-16T23:38:01.395402Z"}]}}
{"rx_ns": 42946801655200, "frame": {"channel":"book","type":"update","data":[{"symbol":"BTC/USD","bids":[{"price":62791.2,"qty":0.33152193}],"asks":[],"checksum":4028519567,"timestamp":"2026-08-16T23:38:01.395515Z"}]}}
{"rx_ns": 42946804919300, "frame": {"channel":"book","type":"update","data":[{"symbol":"BTC/USD","bids":[],"asks":[{"price":62818.7,"qty":0.00000000},{"price":62876.0,"qty":0.47771147},{"price":62816.2,"qty":1.59575715}],"checksum":4028519567,"timestamp":"2026-08-16T23:38:01.395838Z"}]}}
{"rx_ns": 42946804966600, "frame": {"channel":"book","type":"update","data":[{"symbol":"BTC/USD","bids":[{"price":62780.1,"qty":0.00000000},{"price":62713.3,"qty":0.10643220}],"asks":[],"checksum":4028519567,"timestamp":"2026-08-16T23:38:01.399023Z"}]}}
{"rx_ns": 42946804980500, "frame": {"channel":"book","type":"update","data":[{"symbol":"BTC/USD","bids":[{"price":62729.3,"qty":0.00000000},{"price":62712.7,"qty":0.15985195}],"asks":[],"checksum":4028519567,"timestamp":"2026-08-16T23:38:01.400953Z"}]}}
{"rx_ns": 42946804990200, "frame": {"channel":"book","type":"update","data":[{"symbol":"BTC/USD","bids":[],"asks":[{"price":62816.2,"qty":0.00000000},{"price":62876.0,"qty":0.47771147},{"price":62818.7,"qty":1.59575715}],"checksum":4028519567,"timestamp":"2026-08-16T23:38:01.401980Z"}]}}
{"rx_ns": 42946805000400, "frame": {"channel":"book","type":"update","data":[{"symbol":"BTC/USD","bids":[{"price":62780.7,"qty":0.00000000},{"price":62712.6,"qty":1.50000000},{"price":62782.2,"qty":0.07962767}],"asks":[],"checksum":3698360267,"timestamp":"2026-08-16T23:38:01.402328Z"}]}}
{"rx_ns": 42946805029900, "frame": {"channel":"book","type":"update","data":[{"symbol":"BTC/USD","bids":[],"asks":[{"price":62809.9,"qty":0.00222509}],"checksum":3698360267,"timestamp":"2026-08-16T23:38:01.402374Z"}]}}
{"rx_ns": 42946805040500, "frame": {"channel":"book","type":"update","data":[{"symbol":"BTC/USD","bids":[{"price":62782.3,"qty":0.02785521}],"asks":[],"checksum":36566971,"timestamp":"2026-08-16T23:38:01.404864Z"}]}}
{"rx_ns": 42946805049000, "frame": {"channel":"book","type":"update","data":[{"symbol":"BTC/USD","bids":[],"asks":[{"price":62815.6,"qty":0.03083852}],"checksum":36566971,"timestamp":"2026-08-16T23:38:01.405425Z"}]}}
{"rx_ns": 42946805058600, "frame": {"channel":"book","type":"update","data":[{"symbol":"BTC/USD","bids":[{"price":62779.2,"qty":0.46828931}],"asks":[],"checksum":36566971,"timestamp":"2026-08-16T23:38:01.405517Z"}]}}
{"rx_ns": 42946805067100, "frame": {"channel":"book","type":"update","data":[{"symbol":"BTC/USD","bids":[{"price":62791.2,"qty":0.40112193}],"asks":[],"checksum":1427311536,"timestamp":"2026-08-16T23:38:01.405989Z"}]}}
{"rx_ns": 42946805075700, "frame": {"channel":"book","type":"update","data":[{"symbol":"BTC/USD","bids":[{"price":62782.8,"qty":0.03185106}],"asks":[],"checksum":520131817,"timestamp":"2026-08-16T23:38:01.406242Z"}]}}
{"rx_ns": 42946805084600, "frame": {"channel":"book","type":"update","data":[{"symbol":"BTC/USD","bids":[{"price":62766.0,"qty":1.41283402}],"asks":[],"checksum":520131817,"timestamp":"2026-08-16T23:38:01.407067Z"}]}}
{"rx_ns": 42946806375200, "frame": {"channel":"book","type":"update","data":[{"symbol":"BTC/USD","bids":[],"asks":[{"price":62827.7,"qty":0.00000000},{"price":62875.3,"qty":0.01000000},{"price":62829.3,"qty":0.28000000}],"checksum":520131817,"timestamp":"2026-08-16T23:38:01.413454Z"}]}}
{"rx_ns": 42946811141400, "frame": {"channel":"book","type":"update","data":[{"symbol":"BTC/USD","bids":[{"price":62790.0,"qty":0.00318523}],"asks":[],"checksum":3664566073,"timestamp":"2026-08-16T23:38:01.417007Z"}]}}
{"rx_ns": 42946816959200, "frame": {"channel":"book","type":"update","data":[{"symbol":"BTC/USD","bids":[],"asks":[{"price":62791.3,"qty":0.17293867}],"checksum":2146273835,"timestamp":"2026-08-16T23:38:01.420254Z"}]}}
{"rx_ns": 42946817012100, "frame": {"channel":"book","type":"update","data":[{"symbol":"BTC/USD","bids":[],"asks":[{"price":62801.3,"qty":0.79934706}],"checksum":4026838791,"timestamp":"2026-08-16T23:38:01.420518Z"}]}}
{"rx_ns": 42946817024700, "frame": {"channel":"book","type":"update","data":[{"symbol":"BTC/USD","bids":[{"price":62790.9,"qty":0.79629279}],"asks":[],"checksum":1494215353,"timestamp":"2026-08-16T23:38:01.420755Z"}]}}
{"rx_ns": 42946817036100, "frame": {"channel":"book","type":"update","data":[{"symbol":"BTC/USD","bids":[],"asks":[{"price":62811.1,"qty":0.00000000},{"price":62875.3,"qty":0.01000000}],"checksum":1494215353,"timestamp":"2026-08-16T23:38:01.420871Z"}]}}
{"rx_ns": 42946822392200, "frame": {"channel":"book","type":"update","data":[{"symbol":"BTC/USD","bids":[],"asks":[{"price":62805.5,"qty":0.00000000},{"price":62875.9,"qty":0.00159000},{"price":62809.7,"qty":0.19620257}],"checksum":1494215353,"timestamp":"2026-08-16T23:38:01.421941Z"}]}}
{"rx_ns": 42946822893900, "frame": {"channel":"book","type":"update","data":[{"symbol":"BTC/USD","bids":[],"asks":[{"price":62801.2,"qty":0.24785175}],"checksum":1335722306,"timestamp":"2026-08-16T23:38:01.422842Z"}]}}
{"rx_ns": 42946822908600, "frame": {"channel":"book","type":"update","data":[{"symbol":"BTC/USD","bids":[],"asks":[{"price":62809.9,"qty":0.24579835}],"checksum":1335722306,"timestamp":"2026-08-16T23:38:01.423160Z"}]}}
{"rx_ns": 42946822918700, "frame": {"channel":"book","type":"update","data":[{"symbol":"BTC/USD","bids":[],"asks":[{"price":62811.0,"qty":0.00000000},{"price":62875.3,"qty":0.01000000}],"checksum":1335722306,"timestamp":"2026-08-16T23:38:01.424422Z"}]}}
{"rx_ns": 42946836176700, "frame": {"channel":"book","type":"update","data":[{"symbol":"BTC/USD","bids":[{"price":62791.2,"qty":0.47756420}],"asks":[],"checksum":1624915639,"timestamp":"2026-08-16T23:38:01.425221Z"}]}}
{"rx_ns": 42946836229400, "frame": {"channel":"book","type":"update","data":[{"symbol":"BTC/USD","bids":[],"asks":[{"price":62791.3,"qty":0.16701217}],"checksum":2129717806,"timestamp":"2026-08-16T23:38:01.425584Z"}]}}
{"rx_ns": 42946836240500, "frame": {"channel":"book","type":"update","data":[{"symbol":"BTC/USD","bids":[],"asks":[{"price":62810.9,"qty":0.00000000},{"price":62875.9,"qty":0.00159000},{"price":62813.2,"qty":0.20567240}],"checksum":2129717806,"timestamp":"2026-08-16T23:38:01.425724Z"}]}}
{"rx_ns": 42946836252700, "frame": {"channel":"book","type":"update","data":[{"symbol":"BTC/USD","bids":[{"price":62791.2,"qty":0.51299470}],"asks":[],"checksum":3436849565,"timestamp":"2026-08-16T23:38:01.426130Z"}]}}
{"rx_ns": 42946836277500, "frame": {"channel":"book","type":"update","data":[{"symbol":"BTC/USD","bids":[],"asks":[{"price":62813.1,"qty":0.07596729}],"checksum":3436849565,"timestamp":"2026-08-16T23:38:01.427944Z"}]}}
{"rx_ns": 42946836294100, "frame": {"channel":"book","type":"update","data":[{"symbol":"BTC/USD","bids":[],"asks":[{"price":62813.2,"qty":0.18489680}],"checksum":3436849565,"timestamp":"2026-08-16T23:38:01.428277Z"}]}}
{"rx_ns": 42946836311000, "frame": {"channel":"book","type":"update","data":[{"symbol":"BTC/USD","bids":[{"price":62781.7,"qty":0.00005100}],"asks":[],"checksum":3436849565,"timestamp":"2026-08-16T23:38:01.430000Z"}]}}
{"rx_ns": 42946836320100, "frame": {"channel":"book","type":"update","data":[{"symbol":"BTC/USD","bids":[],"asks":[{"price":62808.5,"qty":0.50933000}],"checksum":3436849565,"timestamp":"2026-08-16T23:38:01.430215Z"}]}}
{"rx_ns": 42946836328700, "frame": {"channel":"book","type":"update","data":[{"symbol":"BTC/USD","bids":[],"asks":[{"price":62791.3,"qty":0.17293867}],"checksum":3539008772,"timestamp":"2026-08-16T23:38:01.430362Z"}]}}
{"rx_ns": 42946836336700, "frame": {"channel":"book","type":"update","data":[{"symbol":"BTC/USD","bids":[{"price":62791.2,"qty":0.43655243}],"asks":[],"checksum":663456826,"timestamp":"2026-08-16T23:38:01.430384Z"}]}}
{"rx_ns": 42946836344900, "frame": {"channel":"book","type":"update","data":[{"symbol":"BTC/USD","bids":[],"asks":[{"price":62803.3,"qty":0.01100000},{"price":62805.5,"qty":3.79000002}],"checksum":1651018148,"timestamp":"2026-08-16T23:38:01.430522Z"}]}}
{"rx_ns": 42946836366500, "frame": {"channel":"book","type":"update","data":[{"symbol":"BTC/USD","bids":[],"asks":[{"price":62792.6,"qty":0.00000000},{"price":62875.2,"qty":5.56658959}],"checksum":4065363213,"timestamp":"2026-08-16T23:38:01.431411Z"}]}}
{"rx_ns": 42946836376200, "frame": {"channel":"book","type":"update","data":[{"symbol":"BTC/USD","bids":[],"asks":[{"price":62805.2,"qty":0.15928208}],"checksum":4065363213,"timestamp":"2026-08-16T23:38:01.432225Z"}]}}
{"rx_ns": 42946836384400, "frame": {"channel":"book","type":"update","data":[{"symbol":"BTC/USD","bids":[],"asks":[{"price":62808.4,"qty":0.15203501}],"checksum":4065363213,"timestamp":"2026-08-16T23:38:01.432317Z"}]}}
{"rx_ns": 42946836392300, "frame": {"channel":"book","type":"update","data":[{"symbol":"BTC/USD","bids":[{"price":62733.9,"qty":0.00000000},{"price":62718.0,"qty":0.00015944},{"price":62736.6,"qty":0.01940591}],"asks":[],"checksum":4065363213,"timestamp":"2026-08-16T23:38:01.433044Z"}]}}
{"rx_ns": 42946836412900, "frame": {"channel":"book","type":"update","data":[{"symbol":"BTC/USD","bids":[],"asks":[{"price":62829.3,"qty":0.00000000},{"price":62875.1,"qty":1.87899731},{"price":62830.5,"qty":0.28000000}],"checksum":4065363213,"timestamp":"2026-08-16T23:38:01.435519Z"}]}}
{"rx_ns": 42946851303800, "frame": {"channel":"book","type":"update","data":[{"symbol":"BTC/USD","bids":[],"asks":[{"price":62801.3,"qty":0.00318497}],"checksum":3341713082,"timestamp":"2026-08-16T23:38:01.438830Z"}]}}
{"rx_ns": 42946851357300, "frame": {"channel":"book","type":"update","data":[{"symbol":"BTC/USD","bids":[],"asks":[{"price":62805.5,"qty":0.00000000},{"price":62875.1,"qty":1.87899731},{"price":62803.8,"qty":3.79004932}],"checksum":3341713082,"timestamp":"2026-08-16T23:38:01.440038Z"}]}}
{"rx_ns": 42946851408300, "frame": {"channel":"book","type":"update","data":[{"symbol":"BTC/USD","bids":[],"asks":[{"price":62801.2,"qty":0.00000000},{"price":62875.1,"qty":1.87899731}],"checksum":2411606937,"timestamp":"2026-08-16T23:38:01.440435Z"}]}}
{"rx_ns": 42946851447400, "frame": {"channel":"book","type":"update","data":[{"symbol":"BTC/USD","bids":[],"asks":[{"price":62809.9,"qty":0.24357326},{"price":62805.1,"qty":0.00222509}],"checksum":2411606937,"timestamp":"2026-08-16T23:38:01.446240Z"}]}}
{"rx_ns": 42946851470300, "frame": {"channel":"book","type":"update","data":[{"symbol":"BTC/USD","bids":[],"asks":[{"price":62813.2,"qty":0.00000000},{"price":62875.1,"qty":1.87899731},{"price":62803.1,"qty":0.18489680}],"checksum":1576967647,"timestamp":"2026-08-16T23:38:01.450030Z"}]}}
{"rx_ns": 42946851489900, "frame": {"channel":"book","type":"update","data":[{"symbol":"BTC/USD","bids":[],"asks":[{"price":62822.2,"qty":0.00039741}],"checksum":1576967647,"timestamp":"2026-08-16T23:38:01.450408Z"}]}}
{"rx_ns": 42946851506300, "frame": {"channel":"book","type":"update","data":[{"symbol":"BTC/USD","bids":[],"asks":[{"price":62813.1,"qty":0.00000000},{"price":62875.0,"qty":0.04717193}],"checksum":1576967647,"timestamp":"2026-08-16T23:38:01.451977Z"}]}}
{"rx_ns": 42946851515800, "frame": {"channel":"book","type":"update","data":[{"symbol":"BTC/USD","bids":[],"asks":[{"price":62813.1,"qty":0.02077560}],"checksum":1576967647,"timestamp":"2026-08-16T23:38:01.452271Z"}]}}
{"rx_ns": 42946851533800, "frame": {"channel":"book","type":"update","data":[{"symbol":"BTC/USD","bids":[{"price":62782.2,"qty":0.00000000},{"price":62718.0,"qty":0.00015944},{"price":62782.8,"qty":0.07962549}],"asks":[],"checksum":2497695024,"timestamp":"2026-08-16T23:38:01.454728Z"}]}}
{"rx_ns": 42946851545200, "frame": {"channel":"book","type":"update","data":[{"symbol":"BTC/USD","bids":[],"asks":[{"price":62830.5,"qty":0.00000000},{"price":62875.0,"qty":0.04717193},{"price":62832.1,"qty":0.28000000}],"checksum":2497695024,"timestamp":"2026-08-16T23:38:01.454886Z"}]}}
{"rx_ns": 42946851555300, "frame": {"channel":"book","type":"update","data":[{"symbol":"BTC/USD","bids":[{"price":62782.3,"qty":0.00000000},{"price":62714.4,"qty":0.16488958}],"asks":[],"checksum":2497695024,"timestamp":"2026-08-16T23:38:01.455962Z"}]}}
{"rx_ns": 42946851573200, "frame": {"channel":"book","type":"update","data":[{"symbol":"BTC/USD","bids":[{"price":62782.9,"qty":0.02473415}],"asks":[],"checksum":1175219547,"timestamp":"2026-08-16T23:38:01.456292Z"}]}}
{"rx_ns": 42946851581900, "frame": {"channel":"book","type":"update","data":[{"symbol":"BTC/USD","bids":[{"price":62784.6,"qty":0.03194519}],"asks":[],"checksum":1495402573,"timestamp":"2026-08-16T23:38:01.458182Z"}]}}
{"rx_ns": 42946851599000, "frame": {"channel":"book","type":"update","data":[{"symbol":"BTC/USD","bids":[{"price":62791.2,"qty":0.51299470}],"asks":[],"checksum":2250514465,"timestamp":"2026-08-16T23:38:01.473079Z"}]}}
{"rx_ns": 42946851607800, "frame": {"channel":"book","type":"update","data":[{"symbol":"BTC/USD","bids":[],"asks":[{"price":62791.3,"qty":0.16701217}],"checksum":344924315,"timestamp":"2026-08-16T23:38:01.473325Z"}]}}
{"rx_ns": 42946863097600, "frame": {"channel":"book","type":"update","data":[{"symbol":"BTC/USD","bids":[],"asks":[{"price":62864.9,"qty":0.05411369}],"checksum":344924315,"timestamp":"2026-08-16T23:38:01.481955Z"}]}}
{"rx_ns": 42946873031300, "frame": {"channel":"book","type":"update","data":[{"symbol":"BTC/USD","bids":[],"asks":[{"price":62803.8,"qty":0.00000000},{"price":62874.0,"qty":0.60000000},{"price":62800.7,"qty":3.79023544}],"checksum":419626156,"timestamp":"2026-08-16T23:38:01.490106Z"}]}}
{"rx_ns": 42946873116500, "frame": {"channel":"book","type":"update","data":[{"symbol":"BTC/USD","bids":[],"asks":[{"price":62832.1,"qty":0.00000000},{"price":62874.0,"qty":0.60000000},{"price":62833.3,"qty":0.28000000}],"checksum":419626156,"timestamp":"2026-08-16T23:38:01.491509Z"}]}}
{"rx_ns": 42946873129800, "frame": {"channel":"book","type":"update","data":[{"symbol":"BTC/USD","bids":[],"asks":[{"price":62803.1,"qty":0.00000000},{"price":62874.0,"qty":0.60000000},{"price":62810.0,"qty":0.68489680}],"checksum":1199063658,"timestamp":"2026-08-16T23:38:01.491630Z"}]}}
{"rx_ns": 42946873140900, "frame": {"channel":"book","type":"update","data":[{"symbol":"BTC/USD","bids":[],"asks":[{"price":62803.2,"qty":0.05598472}],"checksum":946213074,"timestamp":"2026-08-16T23:38:01.491768Z"}]}}
{"rx_ns": 42946873152000, "frame": {"channel":"book","type":"update","data":[{"symbol":"BTC/USD","bids":[],"asks":[{"price":62805.2,"qty":0.00000000},{"price":62875.0,"qty":0.04717193}],"checksum":946213074,"timestamp":"2026-08-16T23:38:01.492105Z"}]}}
{"rx_ns": 42946873163800, "frame": {"channel":"book","type":"update","data":[{"symbol":"BTC/USD","bids":[],"asks":[{"price":62803.0,"qty":0.14418735}],"checksum":1826028569,"timestamp":"2026-08-16T23:38:01.492214Z"}]}}
{"rx_ns": 42946873291400, "frame": {"channel":"book","type":"update","data":[{"symbol":"BTC/USD","bids":[],"asks":[{"price":62800.6,"qty":1.14158264}],"checksum":1717098453,"timestamp":"2026-08-16T23:38:01.492281Z"}]}}
{"rx_ns": 42946873306900, "frame": {"channel":"book","type":"update","data":[{"symbol":"BTC/USD","bids":[],"asks":[{"price":62803.0,"qty":0.23318300}],"checksum":1397514330,"timestamp":"2026-08-16T23:38:01.493504Z"}]}}
{"rx_ns": 42946873317100, "frame": {"channel":"book","type":"update","data":[{"symbol":"BTC/USD","bids":[],"asks":[{"price":62805.1,"qty":0.00000000},{"price":62874.0,"qty":0.60000000},{"price":62818.6,"qty":0.00222509}],"checksum":1397514330,"timestamp":"2026-08-16T23:38:01.493518Z"}]}}
{"rx_ns": 42946873327700, "frame": {"channel":"book","type":"update","data":[{"symbol":"BTC/USD","bids":[],"asks":[{"price":62803.0,"qty":0.08899565}],"checksum":3043819628,"timestamp":"2026-08-16T23:38:01.493691Z"}]}}
{"rx_ns": 42946873337400, "frame": {"channel":"book","type":"update","data":[{"symbol":"BTC/USD","bids":[],"asks":[{"price":62803.0,"qty":0.00000000},{"price":62874.0,"qty":0.60000000}],"checksum":3061168335,"timestamp":"2026-08-16T23:38:01.493772Z"}]}}
{"rx_ns": 42946875823000, "frame": {"channel":"book","type":"update","data":[{"symbol":"BTC/USD","bids":[],"asks":[{"price":62806.0,"qty":0.11000000}],"checksum":3061168335,"timestamp":"2026-08-16T23:38:01.494324Z"}]}}
{"rx_ns": 42946875952700, "frame": {"channel":"book","type":"update","data":[{"symbol":"BTC/USD","bids":[],"asks":[{"price":62803.1,"qty":0.04078576}],"checksum":2575515575,"timestamp":"2026-08-16T23:38:01.495495Z"}]}}
{"rx_ns": 42946880270900, "frame": {"channel":"book","type":"update","data":[{"symbol":"BTC/USD","bids":[],"asks":[{"price":62803.1,"qty":0.06840638}],"checksum":1021186483,"timestamp":"2026-08-16T23:38:01.496145Z"}]}}
{"rx_ns": 42946887435500, "frame": {"channel":"book","type":"update","data":[{"symbol":"BTC/USD","bids":[],"asks":[{"price":62800.7,"qty":0.00000000},{"price":62874.0,"qty":0.60000000},{"price":62803.3,"qty":3.80117314}],"checksum":185101305,"timestamp":"2026-08-16T23:38:01.506831Z"}]}}
{"rx_ns": 42946887506200, "frame": {"channel":"book","type":"update","data":[{"symbol":"BTC/USD","bids":[],"asks":[{"price":62800.6,"qty":0.00000000},{"price":62875.0,"qty":0.04717193}],"checksum":4201044545,"timestamp":"2026-08-16T23:38:01.508174Z"}]}}
{"rx_ns": 42946893815700, "frame": {"channel":"book","type":"update","data":[{"symbol":"BTC/USD","bids":[],"asks":[{"price":62803.1,"qty":0.04078576}],"checksum":2342090726,"timestamp":"2026-08-16T23:38:01.510058Z"}]}}
{"rx_ns": 42946893867700, "frame": {"channel":"book","type":"update","data":[{"symbol":"BTC/USD","bids":[],"asks":[{"price":62803.1,"qty":0.00000000},{"price":62875.1,"qty":1.87899731}],"checksum":627270606,"timestamp":"2026-08-16T23:38:01.510068Z"}]}}
{"rx_ns": 42946893896000, "frame": {"channel":"book","type":"update","data":[{"symbol":"BTC/USD","bids":[],"asks":[{"price":62873.1,"qty":0.06960000}],"checksum":627270606,"timestamp":"2026-08-16T23:38:01.510174Z"}]}}
{"rx_ns": 42946893913000, "frame": {"channel":"book","type":"update","data":[{"symbol":"BTC/USD","bids":[],"asks":[{"price":62803.2,"qty":1.24426073}],"checksum":3440525999,"timestamp":"2026-08-16T23:38:01.512772Z"}]}}
{"rx_ns": 42946893929400, "frame": {"channel":"book","type":"update","data":[{"symbol":"BTC/USD","bids":[],"asks":[{"price":62810.0,"qty":0.50000000},{"price":62813.3,"qty":0.25449680}],"checksum":3440525999,"timestamp":"2026-08-16T23:38:01.514153Z"}]}}
{"rx_ns": 42946893946400, "frame": {"channel":"book","type":"update","data":[{"symbol":"BTC/USD","bids":[],"asks":[{"price":62813.1,"qty":0.07331118}],"checksum":3440525999,"timestamp":"2026-08-16T23:38:01.517272Z"}]}}
{"rx_ns": 42946903759800, "frame": {"channel":"book","type":"update","data":[{"symbol":"BTC/USD","bids":[{"price":62791.2,"qty":0.49815064}],"asks":[],"checksum":1037109929,"timestamp":"2026-08-16T23:38:01.526113Z"}]}}
{"rx_ns": 42946903813300, "frame": {"channel":"book","type":"update","data":[{"symbol":"BTC/USD","bids":[],"asks":[{"price":62809.7,"qty":0.00000000},{"price":62875.1,"qty":1.87899731}],"checksum":1037109929,"timestamp":"2026-08-16T23:38:01.526874Z"}]}}
{"rx_ns": 42946908173100, "frame": {"channel":"book","type":"update","data":[{"symbol":"BTC/USD","bids":[],"asks":[{"price":62818.7,"qty":0.00000000},{"price":62875.2,"qty":5.56658959}],"checksum":1037109929,"timestamp":"2026-08-16T23:38:01.530565Z"}]}}
{"rx_ns": 42946908249500, "frame": {"channel":"book","type":"update","data":[{"symbol":"BTC/USD","bids":[{"price":62776.2,"qty":0.00000000},{"price":62714.4,"qty":0.16488958}],"asks":[],"checksum":1037109929,"timestamp":"2026-08-16T23:38:01.530606Z"}]}}
{"rx_ns": 42946908292200, "frame": {"channel":"book","type":"update","data":[{"symbol":"BTC/USD","bids":[],"asks":[{"price":62803.3,"qty":0.01100000}],"checksum":1806738532,"timestamp":"2026-08-16T23:38:01.531194Z"}]}}
{"rx_ns": 42946914639800, "frame": {"channel":"book","type":"update","data":[{"symbol":"BTC/USD","bids":[{"price":62717.6,"qty":0.06960000}],"asks":[],"checksum":1806738532,"timestamp":"2026-08-16T23:38:01.532907Z"}]}}
{"rx_ns": 42946914690000, "frame": {"channel":"book","type":"update","data":[{"symbol":"BTC/USD","bids":[],"asks":[{"price":62813.3,"qty":0.06960000},{"price":62815.6,"qty":0.21573532}],"checksum":1806738532,"timestamp":"2026-08-16T23:38:01.534312Z"}]}}
{"rx_ns": 42946914702200, "frame": {"channel":"book","type":"update","data":[{"symbol":"BTC/USD","bids":[],"asks":[{"price":62803.2,"qty":0.05598472}],"checksum":2462213399,"timestamp":"2026-08-16T23:38:01.534540Z"}]}}
{"rx_ns": 42946914726300, "frame": {"channel":"book","type":"update","data":[{"symbol":"BTC/USD","bids":[],"asks":[{"price":62803.2,"qty":0.11289404}],"checksum":3921496087,"timestamp":"2026-08-16T23:38:01.534865Z"}]}}
{"rx_ns": 42946914735500, "frame": {"channel":"book","type":"update","data":[{"symbol":"BTC/USD","bids":[],"asks":[{"price":62813.1,"qty":0.02077560}],"checksum":3921496087,"timestamp":"2026-08-16T23:38:01.536479Z"}]}}
{"rx_ns": 42946936522500, "frame": {"channel":"book","type":"update","data":[{"symbol":"BTC/USD","bids":[],"asks":[{"price":62803.2,"qty":0.05690932},{"price":62803.1,"qty":0.05598472}],"checksum":1616801797,"timestamp":"2026-08-16T23:38:01.563709Z"}]}}
{"rx_ns": 42946937903200, "frame": {"channel":"book","type":"update","data":[{"symbol":"BTC/USD","bids":[],"asks":[{"price":62815.6,"qty":0.03083852},{"price":62813.2,"qty":0.18489680}],"checksum":1616801797,"timestamp":"2026-08-16T23:38:01.565338Z"}]}}
{"rx_ns": 42946939651200, "frame": {"channel":"book","type":"update","data":[{"symbol":"BTC/USD","bids":[],"asks":[{"price":62813.1,"qty":0.07331118}],"checksum":1616801797,"timestamp":"2026-08-16T23:38:01.567340Z"}]}}
{"rx_ns": 42946963868300, "frame": {"channel":"book","type":"update","data":[{"symbol":"BTC/USD","bids":[{"price":62780.5,"qty":0.00000000},{"price":62714.4,"qty":0.16488958}],"asks":[],"checksum":1616801797,"timestamp":"2026-08-16T23:38:01.586891Z"}]}}
{"rx_ns": 42946963943800, "frame": {"channel":"book","type":"update","data":[{"symbol":"BTC/USD","bids":[{"price":62785.1,"qty":0.06142600}],"asks":[],"checksum":1095941684,"timestamp":"2026-08-16T23:38:01.586981Z"}]}}
{"rx_ns": 42946963956800, "frame": {"channel":"book","type":"update","data":[{"symbol":"BTC/USD","bids":[],"asks":[{"price":62813.2,"qty":0.00000000},{"price":62875.1,"qty":1.87899731},{"price":62813.0,"qty":0.18489680}],"checksum":1095941684,"timestamp":"2026-08-16T23:38:01.588218Z"}]}}
{"rx_ns": 42946963978800, "frame": {"channel":"book","type":"update","data":[{"symbol":"BTC/USD","bids":[],"asks":[{"price":62813.1,"qty":0.02077560}],"checksum":1095941684,"timestamp":"2026-08-16T23:38:01.590667Z"}]}}
{"rx_ns": 42946963988800, "frame": {"channel":"book","type":"update","data":[{"symbol":"BTC/USD","bids":[{"price":62785.2,"qty":0.02788652}],"asks":[],"checksum":1560325775,"timestamp":"2026-08-16T23:38:01.590703Z"}]}}
{"rx_ns": 42946964042500, "frame": {"channel":"book","type":"update","data":[{"symbol":"BTC/USD","bids":[],"asks":[{"price":62813.1,"qty":0.00000000},{"price":62875.1,"qty":1.87899731}],"checksum":1560325775,"timestamp":"2026-08-16T23:38:01.590795Z"}]}}
{"rx_ns": 42946967092900, "frame": {"channel":"book","type":"update","data":[{"symbol":"BTC/USD","bids":[],"asks":[{"price":62812.9,"qty":0.07596729}],"checksum":1560325775,"timestamp":"2026-08-16T23:38:01.592235Z"}]}}
{"rx_ns": 42946969149100, "frame": {"channel":"book","type":"update","data":[{"symbol":"BTC/USD","bids":[{"price":62790.9,"qty":0.80575127}],"asks":[],"checksum":2889111423,"timestamp":"2026-08-16T23:38:01.593612Z"}]}}
{"rx_ns": 42946982561200, "frame": {"channel":"book","type":"update","data":[{"symbol":"BTC/USD","bids":[{"price":62782.8,"qty":0.04777443}],"asks":[],"checksum":2889111423,"timestamp":"2026-08-16T23:38:01.607964Z"}]}}
{"rx_ns": 42946984574700, "frame": {"channel":"book","type":"update","data":[{"symbol":"BTC/USD","bids":[],"asks":[{"price":62813.0,"qty":0.00000000},{"price":62875.1,"qty":1.87899731},{"price":62812.8,"qty":0.18489680}],"checksum":2889111423,"timestamp":"2026-08-16T23:38:01.609869Z"}]}}
{"rx_ns": 42946984675400, "frame": {"channel":"book","type":"update","data":[{"symbol":"BTC/USD","bids":[{"price":62782.9,"qty":0.00000000},{"price":62714.4,"qty":0.16488958}],"asks":[],"checksum":2889111423,"timestamp":"2026-08-16T23:38:01.610421Z"}]}}
{"rx_ns": 42946984698700, "frame": {"channel":"book","type":"update","data":[{"symbol":"BTC/USD","bids":[],"asks":[{"price":62845.8,"qty":0.00660000}],"checksum":2889111423,"timestamp":"2026-08-16T23:38:01.610446Z"}]}}
{"rx_ns": 42946990108400, "frame": {"channel":"book","type":"update","data":[{"symbol":"BTC/USD","bids":[],"asks":[{"price":62812.9,"qty":0.00000000},{"price":62875.0,"qty":0.04717193}],"checksum":2889111423,"timestamp":"2026-08-16T23:38:01.611002Z"}]}}
{"rx_ns": 42946990180000, "frame": {"channel":"book","type":"update","data":[{"symbol":"BTC/USD","bids":[{"price":62782.8,"qty":0.00000000},{"price":62713.3,"qty":0.10643220}],"asks":[],"checksum":2889111423,"timestamp":"2026-08-16T23:38:01.611083Z"}]}}
{"rx_ns": 42946990194700, "frame": {"channel":"book","type":"update","data":[{"symbol":"BTC/USD","bids":[{"price":62784.6,"qty":0.00009500},{"price":62785.9,"qty":0.07962319}],"asks":[],"checksum":3761237606,"timestamp":"2026-08-16T23:38:01.611190Z"}]}}
{"rx_ns": 42946990205100, "frame": {"channel":"book","type":"update","data":[{"symbol":"BTC/USD","bids":[],"asks":[{"price":62812.7,"qty":0.07596729}],"checksum":3761237606,"timestamp":"2026-08-16T23:38:01.611399Z"}]}}
{"rx_ns": 42946994141000, "frame": {"channel":"book","type":"update","data":[{"symbol":"BTC/USD","bids":[{"price":62717.6,"qty":0.06960000}],"asks":[],"checksum":3761237606,"timestamp":"2026-08-16T23:38:01.612403Z"}]}}
{"rx_ns": 42946994201300, "frame": {"channel":"book","type":"update","data":[{"symbol":"BTC/USD","bids":[{"price":62786.0,"qty":0.04214676}],"asks":[],"checksum":3678940694,"timestamp":"2026-08-16T23:38:01.612998Z"}]}}
{"rx_ns": 42946994216700, "frame": {"channel":"book","type":"update","data":[{"symbol":"BTC/USD","bids":[{"price":62785.2,"qty":0.00000000},{"price":62717.6,"qty":0.06960000}],"asks":[],"checksum":3724522284,"timestamp":"2026-08-16T23:38:01.613103Z"}]}}
{"rx_ns": 42946994258400, "frame": {"channel":"book","type":"update","data":[{"symbol":"BTC/USD","bids":[{"price":62717.6,"qty":0.00000000},{"price":62714.4,"qty":0.16488958}],"asks":[],"checksum":3724522284,"timestamp":"2026-08-16T23:38:01.614406Z"}]}}
{"rx_ns": 42946994306600, "frame": {"channel":"book","type":"update","data":[{"symbol":"BTC/USD","bids":[{"price":62786.5,"qty":0.03184927}],"asks":[],"checksum":1394507087,"timestamp":"2026-08-16T23:38:01.614788Z"}]}}
{"rx_ns": 42947001852900, "frame": {"channel":"book","type":"update","data":[{"symbol":"BTC/USD","bids":[],"asks":[{"price":62823.3,"qty":0.00094656}],"checksum":1394507087,"timestamp":"2026-08-16T23:38:01.620732Z"}]}}
{"rx_ns": 42947001943800, "frame": {"channel":"book","type":"update","data":[{"symbol":"BTC/USD","bids":[],"asks":[{"price":62850.9,"qty":0.00385951}],"checksum":1394507087,"timestamp":"2026-08-16T23:38:01.621124Z"}]}}
{"rx_ns": 42947002056600, "frame": {"channel":"book","type":"update","data":[{"symbol":"BTC/USD","bids":[],"asks":[{"price":62814.6,"qty":0.19072285}],"checksum":1394507087,"timestamp":"2026-08-16T23:38:01.623524Z"}]}}
{"rx_ns": 42947002852900, "frame": {"channel":"book","type":"update","data":[{"symbol":"BTC/USD","bids":[],"asks":[{"price":62812.7,"qty":0.12318580}],"checksum":1394507087,"timestamp":"2026-08-16T23:38:01.624852Z"}]}}
{"rx_ns": 42947006501300, "frame": {"channel":"book","type":"update","data":[{"symbol":"BTC/USD","bids":[{"price":62790.9,"qty":0.79629279}],"asks":[],"checksum":3998399402,"timestamp":"2026-08-16T23:38:01.626926Z"}]}}
{"rx_ns": 42947013656400, "frame": {"channel":"book","type":"update","data":[{"symbol":"BTC/USD","bids":[{"price":62791.2,"qty":0.50761108}],"asks":[],"checksum":1112264871,"timestamp":"2026-08-16T23:38:01.627057Z"}]}}
{"rx_ns": 42947013732000, "frame": {"channel":"book","type":"update","data":[{"symbol":"BTC/USD","bids":[],"asks":[{"price":62791.3,"qty":0.08901217}],"checksum":2078237671,"timestamp":"2026-08-16T23:38:01.629975Z"}]}}
{"rx_ns": 42947013751800, "frame": {"channel":"book","type":"update","data":[{"symbol":"BTC/USD","bids":[],"asks":[{"price":62825.7,"qty":0.00000000},{"price":62871.7,"qty":5.56689713}],"checksum":2078237671,"timestamp":"2026-08-16T23:38:01.630870Z"}]}}
{"rx_ns": 42947013768800, "frame": {"channel":"book","type":"update","data":[{"symbol":"BTC/USD","bids":[],"asks":[{"price":62812.8,"qty":0.00000000},{"price":62874.0,"qty":0.60000000},{"price":62809.8,"qty":0.18489680}],"checksum":2078237671,"timestamp":"2026-08-16T23:38:01.631274Z"}]}}
{"rx_ns": 42947015465900, "frame": {"channel":"book","type":"update","data":[{"symbol":"BTC/USD","bids":[],"asks":[{"price":62808.5,"qty":0.00000000},{"price":62874.0,"qty":0.60000000}],"checksum":2078237671,"timestamp":"2026-08-16T23:38:01.632064Z"}]}}
{"rx_ns": 42947015487600, "frame": {"channel":"book","type":"update","data":[{"symbol":"BTC/USD","bids":[],"asks":[{"price":62815.0,"qty":0.50830200}],"checksum":2078237671,"timestamp":"2026-08-16T23:38:01.633537Z"}]}}
{"rx_ns": 42947017997600, "frame": {"channel":"book","type":"update","data":[{"symbol":"BTC/USD","bids":[],"asks":[{"price":62812.7,"qty":0.07596729}],"checksum":2078237671,"timestamp":"2026-08-16T23:38:01.635667Z"}]}}
{"rx_ns": 42947018078800, "frame": {"channel":"book","type":"update","data":[{"symbol":"BTC/USD","bids":[],"asks":[{"price":62808.4,"qty":0.00000000},{"price":62874.0,"qty":0.60000000}],"checksum":2078237671,"timestamp":"2026-08-16T23:38:01.635837Z"}]}}
{"rx_ns": 42947018094800, "frame": {"channel":"book","type":"update","data":[{"symbol":"BTC/USD","bids":[],"asks":[{"price":62812.7,"qty":0.21972225}],"checksum":2078237671,"timestamp":"2026-08-16T23:38:01.635937Z"}]}}
{"rx_ns": 42947018106400, "frame": {"channel":"book","type":"update","data":[{"symbol":"BTC/USD","bids":[],"asks":[{"price":62815.0,"qty":0.00000000},{"price":62875.0,"qty":0.04717193}],"checksum":2078237671,"timestamp":"2026-08-16T23:38:01.636419Z"}]}}
{"rx_ns": 42947018138900, "frame": {"channel":"book","type":"update","data":[{"symbol":"BTC/USD","bids":[],"asks":[{"price":62812.7,"qty":0.07596729}],"checksum":2078237671,"timestamp":"2026-08-16T23:38:01.637761Z"}]}}
{"rx_ns": 42947018162800, "frame": {"channel":"book","type":"update","data":[{"symbol":"BTC/USD","bids":[],"asks":[{"price":62873.1,"qty":0.06960000}],"checksum":2078237671,"timestamp":"2026-08-16T23:38:01.639159Z"}]}}
{"rx_ns": 42947021065600, "frame": {"channel":"book","type":"update","data":[{"symbol":"BTC/USD","bids":[],"asks":[{"price":62864.9,"qty":0.00000000},{"price":62875.0,"qty":0.04717193}],"checksum":2078237671,"timestamp":"2026-08-16T23:38:01.641271Z"}]}}
{"rx_ns": 42947021208100, "frame": {"channel":"book","type":"update","data":[{"symbol":"BTC/USD","bids":[{"price":62735.1,"qty":0.05409205}],"asks":[],"checksum":2078237671,"timestamp":"2026-08-16T23:38:01.641917Z"}]}}
{"rx_ns": 42947023120500, "frame": {"channel":"book","type":"update","data":[{"symbol":"BTC/USD","bids":[],"asks":[{"price":62804.2,"qty":3.79012888}],"checksum":2078237671,"timestamp":"2026-08-16T23:38:01.644736Z"}]}}
{"rx_ns": 42947023198700, "frame": {"channel":"book","type":"update","data":[{"symbol":"BTC/USD","bids":[],"asks":[{"price":62803.2,"qty":1.18098705}],"checksum":937304535,"timestamp":"2026-08-16T23:38:01.646064Z"}]}}
{"rx_ns": 42947030744100, "frame": {"channel":"book","type":"update","data":[{"symbol":"BTC/USD","bids":[],"asks":[{"price":62818.6,"qty":0.19842766}],"checksum":937304535,"timestamp":"2026-08-16T23:38:01.649890Z"}]}}
{"rx_ns": 42947037165500, "frame": {"channel":"book","type":"update","data":[{"symbol":"BTC/USD","bids":[{"price":62791.2,"qty":0.43801108}],"asks":[],"checksum":2664679184,"timestamp":"2026-08-16T23:38:01.651306Z"}]}}
{"rx_ns": 42947037223700, "frame": {"channel":"book","type":"update","data":[{"symbol":"BTC/USD","bids":[],"asks":[{"price":62818.7,"qty":1.59575715}],"checksum":2664679184,"timestamp":"2026-08-16T23:38:01.651453Z"}]}}
{"rx_ns": 42947037257600, "frame": {"channel":"book","type":"update","data":[{"symbol":"BTC/USD","bids":[{"price":62774.2,"qty":0.10292445}],"asks":[],"checksum":2664679184,"timestamp":"2026-08-16T23:38:01.651672Z"}]}}
{"rx_ns": 42947037270500, "frame": {"channel":"book","type":"update","data":[{"symbol":"BTC/USD","bids":[],"asks":[{"price":62809.8,"qty":0.00000000},{"price":62874.0,"qty":0.60000000},{"price":62813.3,"qty":0.25449680}],"checksum":2664679184,"timestamp":"2026-08-16T23:38:01.652727Z"}]}}
{"rx_ns": 42947037299500, "frame": {"channel":"book","type":"update","data":[{"symbol":"BTC/USD","bids":[],"asks":[{"price":62791.3,"qty":0.16701217}],"checksum":1019368375,"timestamp":"2026-08-16T23:38:01.654290Z"}]}}
{"rx_ns": 42947037312100, "frame": {"channel":"book","type":"update","data":[{"symbol":"BTC/USD","bids":[],"asks":[{"price":62822.3,"qty":0.23769319}],"checksum":1019368375,"timestamp":"2026-08-16T23:38:01.655152Z"}]}}
{"rx_ns": 42947037322100, "frame": {"channel":"book","type":"update","data":[{"symbol":"BTC/USD","bids":[],"asks":[{"price":62812.7,"qty":0.12318580}],"checksum":1019368375,"timestamp":"2026-08-16T23:38:01.655181Z"}]}}
{"rx_ns": 42947037329200, "frame": {"channel":"book","type":"update","data":[{"symbol":"BTC/USD","bids":[{"price":62766.2,"qty":0.79660710}],"asks":[],"checksum":1019368375,"timestamp":"2026-08-16T23:38:01.655526Z"}]}}
{"rx_ns": 42947042358100, "frame": {"channel":"book","type":"update","data":[{"symbol":"BTC/USD","bids":[],"asks":[{"price":62807.6,"qty":0.46828931}],"checksum":1019368375,"timestamp":"2026-08-16T23:38:01.661891Z"}]}}
{"rx_ns": 42947042421300, "frame": {"channel":"book","type":"update","data":[{"symbol":"BTC/USD","bids":[],"asks":[{"price":62804.5,"qty":0.15928208}],"checksum":1019368375,"timestamp":"2026-08-16T23:38:01.662027Z"}]}}
{"rx_ns": 42947042459900, "frame": {"channel":"book","type":"update","data":[{"symbol":"BTC/USD","bids":[],"asks":[{"price":62818.6,"qty":0.00222509},{"price":62813.2,"qty":0.19620257}],"checksum":1019368375,"timestamp":"2026-08-16T23:38:01.662240Z"}]}}
{"rx_ns": 42947046489300, "frame": {"channel":"book","type":"update","data":[{"symbol":"BTC/USD","bids":[],"asks":[{"price":62812.7,"qty":0.04721851}],"checksum":1019368375,"timestamp":"2026-08-16T23:38:01.663915Z"}]}}
{"rx_ns": 42947046568200, "frame": {"channel":"book","type":"update","data":[{"symbol":"BTC/USD","bids":[],"asks":[{"price":62807.5,"qty":0.14121008}],"checksum":1019368375,"timestamp":"2026-08-16T23:38:01.663934Z"}]}}
{"rx_ns": 42947046581000, "frame": {"channel":"book","type":"update","data":[{"symbol":"BTC/USD","bids":[],"asks":[{"price":62812.7,"qty":0.00000000},{"price":62866.8,"qty":0.06960000}],"checksum":1019368375,"timestamp":"2026-08-16T23:38:01.664188Z"}]}}
{"rx_ns": 42947046618800, "frame": {"channel":"book","type":"update","data":[{"symbol":"BTC/USD","bids":[],"asks":[{"price":62813.1,"qty":0.19146453}],"checksum":1019368375,"timestamp":"2026-08-16T23:38:01.666335Z"}]}}
{"rx_ns": 42947053996100, "frame": {"channel":"book","type":"update","data":[{"symbol":"BTC/USD","bids":[],"asks":[{"price":62813.2,"qty":0.00000000},{"price":62871.6,"qty":0.69495739},{"price":62815.5,"qty":0.19620257}],"checksum":1019368375,"timestamp":"2026-08-16T23:38:01.680960Z"}]}}
{"rx_ns": 42947054090100, "frame": {"channel":"book","type":"update","data":[{"symbol":"BTC/USD","bids":[],"asks":[{"price":62813.1,"qty":0.32436260}],"checksum":1019368375,"timestamp":"2026-08-16T23:38:01.682116Z"}]}}
{"rx_ns": 42947054109300, "frame": {"channel":"book","type":"update","data":[{"symbol":"BTC/USD","bids":[],"asks":[{"price":62813.1,"qty":0.13289807}],"checksum":1019368375,"timestamp":"2026-08-16T23:38:01.682132Z"}]}}
{"rx_ns": 42947054122600, "frame": {"channel":"book","type":"update","data":[{"symbol":"BTC/USD","bids":[],"asks":[{"price":62813.3,"qty":0.06960000},{"price":62803.0,"qty":0.18489680}],"checksum":3719964212,"timestamp":"2026-08-16T23:38:01.682160Z"}]}}
{"rx_ns": 42947055225200, "frame": {"channel":"book","type":"update","data":[{"symbol":"BTC/USD","bids":[],"asks":[{"price":62813.1,"qty":0.00000000},{"price":62866.5,"qty":0.00005100}],"checksum":3719964212,"timestamp":"2026-08-16T23:38:01.683622Z"}]}}
{"rx_ns": 42947077588400, "frame": {"channel":"book","type":"update","data":[{"symbol":"BTC/USD","bids":[],"asks":[{"price":62813.1,"qty":0.07770637}],"checksum":3719964212,"timestamp":"2026-08-16T23:38:01.683935Z"}]}}
{"rx_ns": 42947077634000, "frame": {"channel":"book","type":"update","data":[{"symbol":"BTC/USD","bids":[],"asks":[{"price":62804.5,"qty":0.00000000},{"price":62866.5,"qty":0.00005100}],"checksum":3719964212,"timestamp":"2026-08-16T23:38:01.691650Z"}]}}
{"rx_ns": 42947077649800, "frame": {"channel":"book","type":"update","data":[{"symbol":"BTC/USD","bids":[{"price":62789.6,"qty":0.46828931}],"asks":[],"checksum":1684759509,"timestamp":"2026-08-16T23:38:01.691752Z"}]}}
{"rx_ns": 42947077661300, "frame": {"channel":"book","type":"update","data":[{"symbol":"BTC/USD","bids":[],"asks":[{"price":62803.8,"qty":0.15928208}],"checksum":1684759509,"timestamp":"2026-08-16T23:38:01.698945Z"}]}}
{"rx_ns": 42947087576700, "frame": {"channel":"book","type":"update","data":[{"symbol":"BTC/USD","bids":[],"asks":[{"price":62858.9,"qty":0.03402362}],"checksum":1684759509,"timestamp":"2026-08-16T23:38:01.713188Z"}]}}
{"rx_ns": 42947087656500, "frame": {"channel":"book","type":"update","data":[{"symbol":"BTC/USD","bids":[{"price":62746.7,"qty":0.03130303}],"asks":[],"checksum":1684759509,"timestamp":"2026-08-16T23:38:01.713338Z"}]}}
{"rx_ns": 42947092312300, "frame": {"channel":"book","type":"update","data":[{"symbol":"BTC/USD","bids":[{"price":62791.2,"qty":0.53801108}],"asks":[],"checksum":275618112,"timestamp":"2026-08-16T23:38:01.718733Z"}]}}
{"rx_ns": 42947107143700, "frame": {"channel":"book","type":"update","data":[{"symbol":"BTC/USD","bids":[],"asks":[{"price":62803.1,"qty":0.00000000},{"price":62866.5,"qty":0.00005100},{"price":62801.8,"qty":0.05598472}],"checksum":1583429609,"timestamp":"2026-08-16T23:38:01.733468Z"}]}}
{"rx_ns": 42947110283900, "frame": {"channel":"book","type":"update","data":[{"symbol":"BTC/USD","bids":[],"asks":[{"price":62801.7,"qty":0.02595809}],"checksum":2579754582,"timestamp":"2026-08-16T23:38:01.737902Z"}]}}
{"rx_ns": 42947110349300, "frame": {"channel":"book","type":"update","data":[{"symbol":"BTC/USD","bids":[],"asks":[{"price":62816.2,"qty":0.50831200}],"checksum":2579754582,"timestamp":"2026-08-16T23:38:01.738093Z"}]}}
{"rx_ns": 42947146692400, "frame": {"channel":"book","type":"update","data":[{"symbol":"BTC/USD","bids":[{"price":62726.2,"qty":0.35581000}],"asks":[],"checksum":2579754582,"timestamp":"2026-08-16T23:38:01.767074Z"}]}}
{"rx_ns": 42947146840800, "frame": {"channel":"book","type":"update","data":[{"symbol":"BTC/USD","bids":[{"price":62726.9,"qty":0.00000000},{"price":62723.9,"qty":0.06960000},{"price":62729.3,"qty":0.70609000}],"asks":[],"checksum":2579754582,"timestamp":"2026-08-16T23:38:01.767292Z"}]}}
{"rx_ns": 42947146887900, "frame": {"channel":"book","type":"update","data":[{"symbol":"BTC/USD","bids":[],"asks":[{"price":62823.5,"qty":0.00000000},{"price":62864.1,"qty":1.66191821},{"price":62842.6,"qty":0.71540000}],"checksum":2579754582,"timestamp":"2026-08-16T23:38:01.767364Z"}]}}
{"rx_ns": 42947146909800, "frame": {"channel":"book","type":"update","data":[{"symbol":"BTC/USD","bids":[],"asks":[{"price":62821.6,"qty":0.00000000},{"price":62864.1,"qty":1.66191821}],"checksum":2579754582,"timestamp":"2026-08-16T23:38:01.769982Z"}]}}
{"rx_ns": 42947155622100, "frame": {"channel":"book","type":"update","data":[{"symbol":"BTC/USD","bids":[],"asks":[{"price":62804.2,"qty":0.00000000},{"price":62864.2,"qty":5.56756520},{"price":62810.2,"qty":3.79014856}],"checksum":2579754582,"timestamp":"2026-08-16T23:38:01.782901Z"}]}}
{"rx_ns": 42947155804000, "frame": {"channel":"book","type":"update","data":[{"symbol":"BTC/USD","bids":[],"asks":[{"price":62803.0,"qty":0.00000000},{"price":62864.2,"qty":5.56756520},{"price":62809.8,"qty":0.18489680}],"checksum":365274667,"timestamp":"2026-08-16T23:38:01.783930Z"}]}}
{"rx_ns": 42947156826300, "frame": {"channel":"book","type":"update","data":[{"symbol":"BTC/USD","bids":[],"asks":[{"price":62803.2,"qty":0.05690932}],"checksum":935383986,"timestamp":"2026-08-16T23:38:01.784114Z"}]}}
{"rx_ns": 42947156856700, "frame": {"channel":"book","type":"update","data":[{"symbol":"BTC/USD","bids":[],"asks":[{"price":62803.2,"qty":0.00000000},{"price":62864.2,"qty":5.56756520}],"checksum":1257083400,"timestamp":"2026-08-16T23:38:01.784185Z"}]}}
{"rx_ns": 42947156869300, "frame": {"channel":"book","type":"update","data":[{"symbol":"BTC/USD","bids":[],"asks":[{"price":62802.9,"qty":0.15964672}],"checksum":2703775025,"timestamp":"2026-08-16T23:38:01.784356Z"}]}}
{"rx_ns": 42947161043000, "frame": {"channel":"book","type":"update","data":[{"symbol":"BTC/USD","bids":[],"asks":[{"price":62802.9,"qty":0.00000000},{"price":62864.2,"qty":5.56756520}],"checksum":1257083400,"timestamp":"2026-08-16T23:38:01.785264Z"}]}}
{"rx_ns": 42947161105800, "frame": {"channel":"book","type":"update","data":[{"symbol":"BTC/USD","bids":[],"asks":[{"price":62803.3,"qty":0.11217152}],"checksum":3354329682,"timestamp":"2026-08-16T23:38:01.785485Z"}]}}
{"rx_ns": 42947161120500, "frame": {"channel":"book","type":"update","data":[{"symbol":"BTC/USD","bids":[],"asks":[{"price":62818.6,"qty":0.00000000},{"price":62866.5,"qty":0.00005100},{"price":62809.8,"qty":0.18712189}],"checksum":3354329682,"timestamp":"2026-08-16T23:38:01.786527Z"}]}}
{"rx_ns": 42947161158200, "frame": {"channel":"book","type":"update","data":[{"symbol":"BTC/USD","bids":[],"asks":[{"price":62809.9,"qty":1.28860055}],"checksum":3354329682,"timestamp":"2026-08-16T23:38:01.788164Z"}]}}
{"rx_ns": 42947170171300, "frame": {"channel":"book","type":"update","data":[{"symbol":"BTC/USD","bids":[{"price":62768.4,"qty":0.00000000},{"price":62723.7,"qty":5.64716200}],"asks":[],"checksum":3354329682,"timestamp":"2026-08-16T23:38:01.797406Z"}]}}
{"rx_ns": 42947172606600, "frame": {"channel":"book","type":"update","data":[{"symbol":"BTC/USD","bids":[{"price":62780.6,"qty":0.78625848}],"asks":[],"checksum":3354329682,"timestamp":"2026-08-16T23:38:01.798593Z"}]}}
{"rx_ns": 42947172671200, "frame": {"channel":"book","type":"update","data":[{"symbol":"BTC/USD","bids":[{"price":62723.9,"qty":0.06960000}],"asks":[],"checksum":3354329682,"timestamp":"2026-08-16T23:38:01.799741Z"}]}}
{"rx_ns": 42947172692400, "frame": {"channel":"book","type":"update","data":[{"symbol":"BTC/USD","bids":[{"price":62780.6,"qty":0.54950980}],"asks":[],"checksum":3354329682,"timestamp":"2026-08-16T23:38:01.799767Z"}]}}
{"rx_ns": 42947172704000, "frame": {"channel":"book","type":"update","data":[{"symbol":"BTC/USD","bids":[{"price":62780.6,"qty":0.48102500}],"asks":[],"checksum":3354329682,"timestamp":"2026-08-16T23:38:01.799778Z"}]}}
{"rx_ns": 42947172722000, "frame": {"channel":"book","type":"update","data":[{"symbol":"BTC/USD","bids":[{"price":62780.7,"qty":0.54248520}],"asks":[],"checksum":3354329682,"timestamp":"2026-08-16T23:38:01.800013Z"}]}}
{"rx_ns": 42947182454200, "frame": {"channel":"book","type":"update","data":[{"symbol":"BTC/USD","bids":[],"asks":[{"price":62810.2,"qty":0.00000000},{"price":62871.6,"qty":0.69495739},{"price":62803.0,"qty":3.79014773}],"checksum":2193339348,"timestamp":"2026-08-16T23:38:01.805420Z"}]}}
{"rx_ns": 42947182535100, "frame": {"channel":"book","type":"update","data":[{"symbol":"BTC/USD","bids":[],"asks":[{"price":62803.3,"qty":0.01100000}],"checksum":912214613,"timestamp":"2026-08-16T23:38:01.806716Z"}]}}
{"rx_ns": 42947182567600, "frame": {"channel":"book","type":"update","data":[{"symbol":"BTC/USD","bids":[],"asks":[{"price":62809.9,"qty":0.24357326}],"checksum":912214613,"timestamp":"2026-08-16T23:38:01.806867Z"}]}}
{"rx_ns": 42947182581000, "frame": {"channel":"book","type":"update","data":[{"symbol":"BTC/USD","bids":[],"asks":[{"price":62802.9,"qty":1.23581412}],"checksum":212343242,"timestamp":"2026-08-16T23:38:01.806876Z"}]}}
{"rx_ns": 42947246226800, "frame": {"channel":"book","type":"update","data":[{"symbol":"BTC/USD","bids":[],"asks":[{"price":62858.0,"qty":0.00000000},{"price":62866.5,"qty":0.00005100}],"checksum":212343242,"timestamp":"2026-08-16T23:38:01.869780Z"}]}}
{"rx_ns": 42947246308400, "frame": {"channel":"book","type":"update","data":[{"symbol":"BTC/USD","bids":[{"price":62739.7,"qty":6.52529627}],"asks":[],"checksum":212343242,"timestamp":"2026-08-16T23:38:01.871022Z"}]}}
{"rx_ns": 42947246321800, "frame": {"channel":"book","type":"update","data":[{"symbol":"BTC/USD","bids":[{"price":62762.8,"qty":2.37800369}],"asks":[],"checksum":212343242,"timestamp":"2026-08-16T23:38:01.871094Z"}]}}
{"rx_ns": 42947246340200, "frame": {"channel":"book","type":"update","data":[{"symbol":"BTC/USD","bids":[],"asks":[{"price":62803.0,"qty":0.00000000},{"price":62871.6,"qty":0.69495739},{"price":62804.7,"qty":3.79014221}],"checksum":1409775982,"timestamp":"2026-08-16T23:38:01.873526Z"}]}}
{"rx_ns": 42947285622200, "frame": {"channel":"book","type":"update","data":[{"symbol":"BTC/USD","bids":[],"asks":[{"price":62801.8,"qty":0.00000000},{"price":62871.6,"qty":0.69495739},{"price":62801.6,"qty":0.05598472}],"checksum":3336317953,"timestamp":"2026-08-16T23:38:01.914008Z"}]}}
{"rx_ns": 42947287431200, "frame": {"channel":"book","type":"update","data":[{"symbol":"BTC/USD","bids":[],"asks":[{"price":62801.7,"qty":0.00000000},{"price":62871.6,"qty":0.69495739}],"checksum":2721529374,"timestamp":"2026-08-16T23:38:01.915243Z"}]}}
{"rx_ns": 42947288955700, "frame": {"channel":"book","type":"update","data":[{"symbol":"BTC/USD","bids":[],"asks":[{"price":62801.6,"qty":0.00000000},{"price":62871.7,"qty":5.56689713},{"price":62801.8,"qty":0.05598472}],"checksum":148534162,"timestamp":"2026-08-16T23:38:01.916306Z"}]}}
{"rx_ns": 42947289588600, "frame": {"channel":"book","type":"update","data":[{"symbol":"BTC/USD","bids":[],"asks":[{"price":62801.5,"qty":0.02595809}],"checksum":3873333868,"timestamp":"2026-08-16T23:38:01.916582Z"}]}}
{"rx_ns": 42947292849000, "frame": {"channel":"book","type":"update","data":[{"symbol":"BTC/USD","bids":[{"price":62778.6,"qty":0.00000000},{"price":62725.9,"qty":5.57982866}],"asks":[],"checksum":3873333868,"timestamp":"2026-08-16T23:38:01.921180Z"}]}}
{"rx_ns": 42947296219200, "frame": {"channel":"book","type":"update","data":[{"symbol":"BTC/USD","bids":[],"asks":[{"price":62804.8,"qty":0.36000000}],"checksum":3873333868,"timestamp":"2026-08-16T23:38:01.922125Z"}]}}
{"rx_ns": 42947324529300, "frame": {"channel":"book","type":"update","data":[{"symbol":"BTC/USD","bids":[],"asks":[{"price":62798.5,"qty":0.79619769}],"checksum":3994432474,"timestamp":"2026-08-16T23:38:01.951290Z"}]}}
{"rx_ns": 42947329960100, "frame": {"channel":"book","type":"update","data":[{"symbol":"BTC/USD","bids":[],"asks":[{"price":62804.9,"qty":0.79611719}],"checksum":3994432474,"timestamp":"2026-08-16T23:38:01.951523Z"}]}}
{"rx_ns": 42947330000700, "frame": {"channel":"book","type":"update","data":[{"symbol":"BTC/USD","bids":[],"asks":[{"price":62815.4,"qty":2.38794946}],"checksum":3994432474,"timestamp":"2026-08-16T23:38:01.952013Z"}]}}
{"rx_ns": 42947330009700, "frame": {"channel":"book","type":"update","data":[{"symbol":"BTC/USD","bids":[{"price":62785.3,"qty":0.79636458}],"asks":[],"checksum":1200474295,"timestamp":"2026-08-16T23:38:01.952195Z"}]}}
{"rx_ns": 42947330018900, "frame": {"channel":"book","type":"update","data":[{"symbol":"BTC/USD","bids":[],"asks":[{"price":62809.8,"qty":0.00222509},{"price":62808.1,"qty":0.18648880}],"checksum":1200474295,"timestamp":"2026-08-16T23:38:01.952490Z"}]}}
{"rx_ns": 42947330028500, "frame": {"channel":"book","type":"update","data":[{"symbol":"BTC/USD","bids":[{"price":62779.3,"qty":2.38932015}],"asks":[],"checksum":1200474295,"timestamp":"2026-08-16T23:38:01.952594Z"}]}}
{"rx_ns": 42947330036200, "frame": {"channel":"book","type":"update","data":[{"symbol":"BTC/USD","bids":[{"price":62770.6,"qty":7.96550556}],"asks":[],"checksum":1200474295,"timestamp":"2026-08-16T23:38:01.952688Z"}]}}
{"rx_ns": 42947394329600, "frame": {"channel":"book","type":"update","data":[{"symbol":"BTC/USD","bids":[{"price":62790.9,"qty":0.00000000},{"price":62728.1,"qty":1.21764893}],"asks":[],"checksum":611048089,"timestamp":"2026-08-16T23:38:02.015099Z"}]}}
{"rx_ns": 42947394405300, "frame": {"channel":"book","type":"update","data":[{"symbol":"BTC/USD","bids":[],"asks":[{"price":62808.1,"qty":0.00159200},{"price":62802.8,"qty":0.18489680}],"checksum":3772208152,"timestamp":"2026-08-16T23:38:02.016303Z"}]}}
{"rx_ns": 42947394419300, "frame": {"channel":"book","type":"update","data":[{"symbol":"BTC/USD","bids":[{"price":62787.7,"qty":0.79633307}],"asks":[],"checksum":891024067,"timestamp":"2026-08-16T23:38:02.016504Z"}]}}
{"rx_ns": 42947427847500, "frame": {"channel":"book","type":"update","data":[{"symbol":"BTC/USD","bids":[],"asks":[{"price":62791.3,"qty":0.32629915}],"checksum":229335932,"timestamp":"2026-08-16T23:38:02.051685Z"}]}}
{"rx_ns": 42947427904900, "frame": {"channel":"book","type":"update","data":[{"symbol":"BTC/USD","bids":[],"asks":[{"price":62792.6,"qty":0.23893047}],"checksum":4222463003,"timestamp":"2026-08-16T23:38:02.051887Z"}]}}
{"rx_ns": 42947490170300, "frame": {"channel":"book","type":"update","data":[{"symbol":"BTC/USD","bids":[],"asks":[{"price":62801.8,"qty":0.00000000},{"price":62861.3,"qty":0.15888884},{"price":62801.4,"qty":0.05598472}],"checksum":2044321105,"timestamp":"2026-08-16T23:38:02.097799Z"}]}}
{"rx_ns": 42947490267400, "frame": {"channel":"book","type":"update","data":[{"symbol":"BTC/USD","bids":[],"asks":[{"price":62818.7,"qty":0.00000000},{"price":62861.3,"qty":0.15888884},{"price":62815.3,"qty":1.59575715}],"checksum":2044321105,"timestamp":"2026-08-16T23:38:02.101819Z"}]}}
{"rx_ns": 42947548320900, "frame": {"channel":"book","type":"update","data":[{"symbol":"BTC/USD","bids":[],"asks":[{"price":62800.5,"qty":0.79622378}],"checksum":1300289455,"timestamp":"2026-08-16T23:38:02.174830Z"}]}}
{"rx_ns": 42947552177000, "frame": {"channel":"book","type":"update","data":[{"symbol":"BTC/USD","bids":[],"asks":[{"price":62801.5,"qty":0.00000000},{"price":62861.3,"qty":0.15888884}],"checksum":3235744262,"timestamp":"2026-08-16T23:38:02.176527Z"}]}}
{"rx_ns": 42947552235900, "frame": {"channel":"book","type":"update","data":[{"symbol":"BTC/USD","bids":[],"asks":[{"price":62801.4,"qty":0.00000000},{"price":62862.0,"qty":0.15142628},{"price":62801.8,"qty":0.05598472}],"checksum":3718659307,"timestamp":"2026-08-16T23:38:02.177553Z"}]}}
{"rx_ns": 42947552251000, "frame": {"channel":"book","type":"update","data":[{"symbol":"BTC/USD","bids":[],"asks":[{"price":62800.4,"qty":0.31977330}],"checksum":1196011240,"timestamp":"2026-08-16T23:38:02.178032Z"}]}}
{"rx_ns": 42947561373800, "frame": {"channel":"book","type":"update","data":[{"symbol":"BTC/USD","bids":[],"asks":[{"price":62814.0,"qty":0.00197241}],"checksum":1196011240,"timestamp":"2026-08-16T23:38:02.190149Z"}]}}
{"rx_ns": 42947571358300, "frame": {"channel":"book","type":"update","data":[{"symbol":"BTC/USD","bids":[],"asks":[{"price":62804.7,"qty":0.00000000},{"price":62860.9,"qty":0.00198855},{"price":62802.7,"qty":3.79013973}],"checksum":1196011240,"timestamp":"2026-08-16T23:38:02.200254Z"}]}}
{"rx_ns": 42947571917700, "frame": {"channel":"book","type":"update","data":[{"symbol":"BTC/USD","bids":[],"asks":[{"price":62802.8,"qty":0.00000000},{"price":62860.9,"qty":0.00198855},{"price":62802.6,"qty":0.18489680}],"checksum":1196011240,"timestamp":"2026-08-16T23:38:02.201466Z"}]}}
{"rx_ns": 42947576203400, "frame": {"channel":"book","type":"update","data":[{"symbol":"BTC/USD","bids":[],"asks":[{"price":62802.9,"qty":0.00000000},{"price":62860.9,"qty":0.00198855}],"checksum":1196011240,"timestamp":"2026-08-16T23:38:02.201490Z"}]}}
{"rx_ns": 42947578288500, "frame": {"channel":"book","type":"update","data":[{"symbol":"BTC/USD","bids":[],"asks":[{"price":62800.4,"qty":1.41024762}],"checksum":128466214,"timestamp":"2026-08-16T23:38:02.202897Z"}]}}
{"rx_ns": 42947603744100, "frame": {"channel":"book","type":"update","data":[{"symbol":"BTC/USD","bids":[],"asks":[{"price":62828.3,"qty":0.00000000},{"price":62861.3,"qty":0.15888884}],"checksum":128466214,"timestamp":"2026-08-16T23:38:02.232156Z"}]}}
{"rx_ns": 42947606307300, "frame": {"channel":"book","type":"update","data":[{"symbol":"BTC/USD","bids":[],"asks":[{"price":62803.8,"qty":0.00000000},{"price":62862.0,"qty":0.15142628}],"checksum":128466214,"timestamp":"2026-08-16T23:38:02.233239Z"}]}}
{"rx_ns": 42947606336900, "frame": {"channel":"book","type":"update","data":[{"symbol":"BTC/USD","bids":[],"asks":[{"price":62802.6,"qty":0.00000000},{"price":62862.7,"qty":0.00600000},{"price":62804.7,"qty":0.18489680}],"checksum":128466214,"timestamp":"2026-08-16T23:38:02.233348Z"}]}}
{"rx_ns": 42947606348600, "frame": {"channel":"book","type":"update","data":[{"symbol":"BTC/USD","bids":[],"asks":[{"price":62845.2,"qty":1.30782169}],"checksum":128466214,"timestamp":"2026-08-16T23:38:02.233527Z"}]}}
{"rx_ns": 42947611103100, "frame": {"channel":"book","type":"update","data":[{"symbol":"BTC/USD","bids":[],"asks":[{"price":62791.3,"qty":0.16701217}],"checksum":928540820,"timestamp":"2026-08-16T23:38:02.239204Z"}]}}
{"rx_ns": 42947615383100, "frame": {"channel":"book","type":"update","data":[{"symbol":"BTC/USD","bids":[{"price":62785.1,"qty":0.00000000},{"price":62728.1,"qty":1.21764893}],"asks":[],"checksum":928540820,"timestamp":"2026-08-16T23:38:02.242671Z"}]}}
{"rx_ns": 42947619259100, "frame": {"channel":"book","type":"update","data":[{"symbol":"BTC/USD","bids":[],"asks":[{"price":62803.7,"qty":0.15933308}],"checksum":928540820,"timestamp":"2026-08-16T23:38:02.246659Z"}]}}
{"rx_ns": 42947630365900, "frame": {"channel":"book","type":"update","data":[{"symbol":"BTC/USD","bids":[],"asks":[{"price":62792.6,"qty":0.00000000},{"price":62862.0,"qty":0.15142628}],"checksum":3606142446,"timestamp":"2026-08-16T23:38:02.259228Z"}]}}
{"rx_ns": 42947680435200, "frame": {"channel":"book","type":"update","data":[{"symbol":"BTC/USD","bids":[{"price":62789.6,"qty":0.00000000},{"price":62726.2,"qty":0.35581000}],"asks":[],"checksum":2821419149,"timestamp":"2026-08-16T23:38:02.301332Z"}]}}
{"rx_ns": 42947680486100, "frame": {"channel":"book","type":"update","data":[{"symbol":"BTC/USD","bids":[{"price":62791.2,"qty":0.37872900}],"asks":[],"checksum":2070382073,"timestamp":"2026-08-16T23:38:02.301656Z"}]}}
{"rx_ns": 42947680511100, "frame": {"channel":"book","type":"update","data":[{"symbol":"BTC/USD","bids":[{"price":62787.7,"qty":0.00000000},{"price":62725.9,"qty":5.57982866}],"asks":[],"checksum":3106539854,"timestamp":"2026-08-16T23:38:02.302758Z"}]}}
{"rx_ns": 42947680520200, "frame": {"channel":"book","type":"update","data":[{"symbol":"BTC/USD","bids":[{"price":62789.7,"qty":0.00000000},{"price":62723.7,"qty":5.64716200}],"asks":[],"checksum":1758851182,"timestamp":"2026-08-16T23:38:02.303852Z"}]}}
{"rx_ns": 42947680536700, "frame": {"channel":"book","type":"update","data":[{"symbol":"BTC/USD","bids":[],"asks":[{"price":62804.7,"qty":0.00000000},{"price":62862.7,"qty":0.00600000},{"price":62800.3,"qty":0.18489680}],"checksum":281573904,"timestamp":"2026-08-16T23:38:02.304861Z"}]}}
{"rx_ns": 42947680546400, "frame": {"channel":"book","type":"update","data":[{"symbol":"BTC/USD","bids":[{"price":62790.3,"qty":0.79630010}],"asks":[],"checksum":3189950789,"timestamp":"2026-08-16T23:38:02.305204Z"}]}}
{"rx_ns": 42947680553300, "frame": {"channel":"book","type":"update","data":[{"symbol":"BTC/USD","bids":[],"asks":[{"price":62801.8,"qty":0.00000000},{"price":62862.7,"qty":0.00600000},{"price":62797.3,"qty":0.05598472}],"checksum":998545642,"timestamp":"2026-08-16T23:38:02.306628Z"}]}}
{"rx_ns": 42947690109600, "frame": {"channel":"heartbeat"}}
{"rx_ns": 42947690156500, "frame": {"channel":"book","type":"update","data":[{"symbol":"BTC/USD","bids":[{"price":62746.7,"qty":0.00000000},{"price":62723.7,"qty":5.64716200}],"asks":[],"checksum":998545642,"timestamp":"2026-08-16T23:38:02.310697Z"}]}}
{"rx_ns": 42947711040100, "frame": {"channel":"book","type":"update","data":[{"symbol":"BTC/USD","bids":[{"price":62723.9,"qty":0.06960000}],"asks":[],"checksum":998545642,"timestamp":"2026-08-16T23:38:02.314729Z"}]}}
{"rx_ns": 42947711093100, "frame": {"channel":"book","type":"update","data":[{"symbol":"BTC/USD","bids":[],"asks":[{"price":62816.2,"qty":0.00000000},{"price":62862.7,"qty":0.00600000}],"checksum":998545642,"timestamp":"2026-08-16T23:38:02.317871Z"}]}}
{"rx_ns": 42947711112200, "frame": {"channel":"book","type":"update","data":[{"symbol":"BTC/USD","bids":[],"asks":[{"price":62798.5,"qty":0.00000000},{"price":62864.1,"qty":1.66191821}],"checksum":3086434746,"timestamp":"2026-08-16T23:38:02.323408Z"}]}}
{"rx_ns": 42947711126800, "frame": {"channel":"book","type":"update","data":[{"symbol":"BTC/USD","bids":[],"asks":[{"price":62797.6,"qty":0.79620942}],"checksum":2051201836,"timestamp":"2026-08-16T23:38:02.325565Z"}]}}
{"rx_ns": 42947711138800, "frame": {"channel":"book","type":"update","data":[{"symbol":"BTC/USD","bids":[{"price":62788.1,"qty":0.79632832}],"asks":[],"checksum":3135450395,"timestamp":"2026-08-16T23:38:02.326051Z"}]}}
{"rx_ns": 42947717867300, "frame": {"channel":"book","type":"update","data":[{"symbol":"BTC/USD","bids":[],"asks":[{"price":62803.7,"qty":0.00005100}],"checksum":3135450395,"timestamp":"2026-08-16T23:38:02.334959Z"}]}}
{"rx_ns": 42947720306900, "frame": {"channel":"book","type":"update","data":[{"symbol":"BTC/USD","bids":[],"asks":[{"price":62803.5,"qty":0.15928208}],"checksum":3135450395,"timestamp":"2026-08-16T23:38:02.346588Z"}]}}
{"rx_ns": 42947734632900, "frame": {"channel":"book","type":"update","data":[{"symbol":"BTC/USD","bids":[{"price":62791.2,"qty":0.53801108}],"asks":[],"checksum":1773131887,"timestamp":"2026-08-16T23:38:02.363802Z"}]}}
{"rx_ns": 42947743119300, "frame": {"channel":"book","type":"update","data":[{"symbol":"BTC/USD","bids":[{"price":62753.7,"qty":0.00000000},{"price":62723.7,"qty":5.64716200}],"asks":[],"checksum":1773131887,"timestamp":"2026-08-16T23:38:02.370053Z"}]}}
{"rx_ns": 42947747376900, "frame": {"channel":"book","type":"update","data":[{"symbol":"BTC/USD","bids":[{"price":62723.9,"qty":0.06960000}],"asks":[],"checksum":1773131887,"timestamp":"2026-08-16T23:38:02.375332Z"}]}}
{"rx_ns": 42947760868000, "frame": {"channel":"book","type":"update","data":[{"symbol":"BTC/USD","bids":[],"asks":[{"price":62802.7,"qty":0.00000000},{"price":62862.7,"qty":0.00600000},{"price":62804.7,"qty":3.79013059}],"checksum":1773131887,"timestamp":"2026-08-16T23:38:02.389815Z"}]}}
{"rx_ns": 42947762572800, "frame": {"channel":"book","type":"update","data":[{"symbol":"BTC/USD","bids":[],"asks":[{"price":62800.4,"qty":0.31977330}],"checksum":3591996418,"timestamp":"2026-08-16T23:38:02.391244Z"}]}}
{"rx_ns": 42947764963100, "frame": {"channel":"book","type":"update","data":[{"symbol":"BTC/USD","bids":[],"asks":[{"price":62800.3,"qty":0.00000000},{"price":62862.7,"qty":0.00600000},{"price":62804.6,"qty":0.18489680}],"checksum":3431303827,"timestamp":"2026-08-16T23:38:02.392167Z"}]}}
{"rx_ns": 42947766788800, "frame": {"channel":"book","type":"update","data":[{"symbol":"BTC/USD","bids":[],"asks":[{"price":62804.6,"qty":1.69418676}],"checksum":3431303827,"timestamp":"2026-08-16T23:38:02.393564Z"}]}}
{"rx_ns": 42947789345900, "frame": {"channel":"book","type":"update","data":[{"symbol":"BTC/USD","bids":[],"asks":[{"price":62811.8,"qty":0.50838100}],"checksum":3431303827,"timestamp":"2026-08-16T23:38:02.417892Z"}]}}
{"rx_ns": 42947802762600, "frame": {"channel":"book","type":"update","data":[{"symbol":"BTC/USD","bids":[{"price":62729.8,"qty":0.00000000},{"price":62723.7,"qty":5.64716200}],"asks":[],"checksum":3431303827,"timestamp":"2026-08-16T23:38:02.430544Z"}]}}
{"rx_ns": 42947804175300, "frame": {"channel":"book","type":"update","data":[{"symbol":"BTC/USD","bids":[{"price":62788.2,"qty":0.09538420}],"asks":[],"checksum":1852948902,"timestamp":"2026-08-16T23:38:02.431141Z"}]}}
{"rx_ns": 42947805918200, "frame": {"channel":"book","type":"update","data":[{"symbol":"BTC/USD","bids":[{"price":62740.2,"qty":4.47875121}],"asks":[],"checksum":1852948902,"timestamp":"2026-08-16T23:38:02.434436Z"}]}}
{"rx_ns": 42947810935700, "frame": {"channel":"book","type":"update","data":[{"symbol":"BTC/USD","bids":[{"price":62740.5,"qty":0.28952815}],"asks":[],"checksum":1852948902,"timestamp":"2026-08-16T23:38:02.434562Z"}]}}
{"rx_ns": 42947820932100, "frame": {"channel":"book","type":"update","data":[{"symbol":"BTC/USD","bids":[],"asks":[{"price":62804.7,"qty":0.00000000},{"price":62862.0,"qty":0.15142628},{"price":62801.7,"qty":3.79017557}],"checksum":954533511,"timestamp":"2026-08-16T23:38:02.449845Z"}]}}
{"rx_ns": 42947822719500, "frame": {"channel":"book","type":"update","data":[{"symbol":"BTC/USD","bids":[],"asks":[{"price":62804.6,"qty":0.18489680}],"checksum":954533511,"timestamp":"2026-08-16T23:38:02.451363Z"}]}}
{"rx_ns": 42947826335600, "frame": {"channel":"book","type":"update","data":[{"symbol":"BTC/USD","bids":[],"asks":[{"price":62804.6,"qty":0.00000000},{"price":62862.0,"qty":0.15142628},{"price":62807.5,"qty":0.32610688}],"checksum":954533511,"timestamp":"2026-08-16T23:38:02.452639Z"}]}}
{"rx_ns": 42947826421800, "frame": {"channel":"book","type":"update","data":[{"symbol":"BTC/USD","bids":[],"asks":[{"price":62800.4,"qty":1.33835519}],"checksum":2770451842,"timestamp":"2026-08-16T23:38:02.452884Z"}]}}
{"rx_ns": 42947829136700, "frame": {"channel":"book","type":"update","data":[{"symbol":"BTC/USD","bids":[],"asks":[{"price":62801.7,"qty":0.00000000},{"price":62862.7,"qty":0.00600000},{"price":62803.3,"qty":3.80117556}],"checksum":1664539394,"timestamp":"2026-08-16T23:38:02.457258Z"}]}}
{"rx_ns": 42947829207400, "frame": {"channel":"book","type":"update","data":[{"symbol":"BTC/USD","bids":[],"asks":[{"price":62800.4,"qty":0.31977330}],"checksum":4277297159,"timestamp":"2026-08-16T23:38:02.458306Z"}]}}
{"rx_ns": 42947850110200, "frame": {"channel":"book","type":"update","data":[{"symbol":"BTC/USD","bids":[],"asks":[{"price":62803.2,"qty":1.58092341}],"checksum":929163324,"timestamp":"2026-08-16T23:38:02.479125Z"}]}}
{"rx_ns": 42947850605200, "frame": {"channel":"book","type":"update","data":[{"symbol":"BTC/USD","bids":[],"asks":[{"price":62807.5,"qty":0.14121008},{"price":62803.1,"qty":0.18489680}],"checksum":1022581689,"timestamp":"2026-08-16T23:38:02.480284Z"}]}}
{"rx_ns": 42947885515200, "frame": {"channel":"book","type":"update","data":[{"symbol":"BTC/USD","bids":[{"price":62790.3,"qty":0.00000000},{"price":62725.9,"qty":5.57982866}],"asks":[],"checksum":2968216295,"timestamp":"2026-08-16T23:38:02.513380Z"}]}}
{"rx_ns": 42947888885900, "frame": {"channel":"book","type":"update","data":[{"symbol":"BTC/USD","bids":[{"price":62791.2,"qty":1.33430100}],"asks":[],"checksum":3015141924,"timestamp":"2026-08-16T23:38:02.514741Z"}]}}
{"rx_ns": 42947888913900, "frame": {"channel":"book","type":"update","data":[{"symbol":"BTC/USD","bids":[{"price":62791.2,"qty":1.31298808}],"asks":[],"checksum":3012899845,"timestamp":"2026-08-16T23:38:02.515729Z"}]}}
{"rx_ns": 42947896486100, "frame": {"channel":"book","type":"update","data":[{"symbol":"BTC/USD","bids":[{"price":62790.1,"qty":0.02131292}],"asks":[],"checksum":1406743130,"timestamp":"2026-08-16T23:38:02.516967Z"}]}}
{"rx_ns": 42947896530700, "frame": {"channel":"book","type":"update","data":[{"symbol":"BTC/USD","bids":[],"asks":[{"price":62803.3,"qty":0.01100000},{"price":62804.7,"qty":3.79017042}],"checksum":1406743130,"timestamp":"2026-08-16T23:38:02.517251Z"}]}}
{"rx_ns": 42947896543700, "frame": {"channel":"book","type":"update","data":[{"symbol":"BTC/USD","bids":[{"price":62766.2,"qty":0.00000000},{"price":62725.9,"qty":5.57982866}],"asks":[],"checksum":1406743130,"timestamp":"2026-08-16T23:38:02.518031Z"}]}}
{"rx_ns": 42947937829700, "frame": {"channel":"book","type":"update","data":[{"symbol":"BTC/USD","bids":[],"asks":[{"price":62815.5,"qty":0.00000000},{"price":62861.3,"qty":0.15888884},{"price":62811.7,"qty":0.19620257}],"checksum":1406743130,"timestamp":"2026-08-16T23:38:02.564260Z"}]}}
{"rx_ns": 42947970413700, "frame": {"channel":"book","type":"update","data":[{"symbol":"BTC/USD","bids":[],"asks":[{"price":62797.6,"qty":0.00000000},{"price":62861.3,"qty":0.15888884}],"checksum":224948055,"timestamp":"2026-08-16T23:38:02.599550Z"}]}}
{"rx_ns": 42947972300600, "frame": {"channel":"book","type":"update","data":[{"symbol":"BTC/USD","bids":[{"price":62788.1,"qty":0.00000000},{"price":62723.7,"qty":5.64716200}],"asks":[],"checksum":2213627627,"timestamp":"2026-08-16T23:38:02.600078Z"}]}}
{"rx_ns": 42947979149100, "frame": {"channel":"book","type":"update","data":[{"symbol":"BTC/USD","bids":[{"price":62745.8,"qty":0.03196865}],"asks":[],"checksum":2213627627,"timestamp":"2026-08-16T23:38:02.601083Z"}]}}
{"rx_ns": 42947979183900, "frame": {"channel":"book","type":"update","data":[{"symbol":"BTC/USD","bids":[],"asks":[{"price":62798.9,"qty":0.79619324}],"checksum":2344649299,"timestamp":"2026-08-16T23:38:02.601679Z"}]}}
{"rx_ns": 42948004422600, "frame": {"channel":"book","type":"update","data":[{"symbol":"BTC/USD","bids":[{"price":62753.7,"qty":0.00303453}],"asks":[],"checksum":2344649299,"timestamp":"2026-08-16T23:38:02.632495Z"}]}}
{"rx_ns": 42948012195100, "frame": {"channel":"book","type":"update","data":[{"symbol":"BTC/USD","bids":[{"price":62766.0,"qty":1.56471201}],"asks":[],"checksum":2344649299,"timestamp":"2026-08-16T23:38:02.641204Z"}]}}
{"rx_ns": 42948012504500, "frame": {"channel":"book","type":"update","data":[{"symbol":"BTC/USD","bids":[{"price":62734.6,"qty":0.15820365}],"asks":[],"checksum":2344649299,"timestamp":"2026-08-16T23:38:02.642200Z"}]}}
{"rx_ns": 42948036419300, "frame": {"channel":"book","type":"update","data":[{"symbol":"BTC/USD","bids":[],"asks":[{"price":62804.7,"qty":0.00000000},{"price":62861.3,"qty":0.15888884},{"price":62812.5,"qty":3.79014574}],"checksum":2344649299,"timestamp":"2026-08-16T23:38:02.664679Z"}]}}
{"rx_ns": 42948039514000, "frame": {"channel":"book","type":"update","data":[{"symbol":"BTC/USD","bids":[],"asks":[{"price":62803.1,"qty":0.00000000},{"price":62861.3,"qty":0.15888884},{"price":62807.5,"qty":0.32610688}],"checksum":709001415,"timestamp":"2026-08-16T23:38:02.666078Z"}]}}
{"rx_ns": 42948039560300, "frame": {"channel":"book","type":"update","data":[{"symbol":"BTC/USD","bids":[],"asks":[{"price":62803.2,"qty":0.00000000},{"price":62862.0,"qty":0.15142628}],"checksum":4096236737,"timestamp":"2026-08-16T23:38:02.666114Z"}]}}
{"rx_ns": 42948039573100, "frame": {"channel":"book","type":"update","data":[{"symbol":"BTC/USD","bids":[],"asks":[{"price":62813.1,"qty":0.00000000},{"price":62862.7,"qty":0.00600000}],"checksum":4096236737,"timestamp":"2026-08-16T23:38:02.666145Z"}]}}
{"rx_ns": 42948041752600, "frame": {"channel":"book","type":"update","data":[{"symbol":"BTC/USD","bids":[],"asks":[{"price":62804.7,"qty":0.37793598}],"checksum":4096236737,"timestamp":"2026-08-16T23:38:02.667587Z"}]}}
{"rx_ns": 42948041802900, "frame": {"channel":"book","type":"update","data":[{"symbol":"BTC/USD","bids":[],"asks":[{"price":62809.9,"qty":0.36755940}],"checksum":4096236737,"timestamp":"2026-08-16T23:38:02.667729Z"}]}}
{"rx_ns": 42948070092700, "frame": {"channel":"book","type":"update","data":[{"symbol":"BTC/USD","bids":[],"asks":[{"price":62811.8,"qty":0.00000000},{"price":62862.7,"qty":0.00600000}],"checksum":4096236737,"timestamp":"2026-08-16T23:38:02.697685Z"}]}}
{"rx_ns": 42948070411100, "frame": {"channel":"book","type":"update","data":[{"symbol":"BTC/USD","bids":[],"asks":[{"price":62809.9,"qty":0.24357326}],"checksum":4096236737,"timestamp":"2026-08-16T23:38:02.699057Z"}]}}
{"rx_ns": 42948072633200, "frame": {"channel":"book","type":"update","data":[{"symbol":"BTC/USD","bids":[],"asks":[{"price":62812.4,"qty":1.68598715}],"checksum":4096236737,"timestamp":"2026-08-16T23:38:02.700684Z"}]}}
{"rx_ns": 42948169920600, "frame": {"channel":"book","type":"update","data":[{"symbol":"BTC/USD","bids":[],"asks":[{"price":62810.8,"qty":0.50840900}],"checksum":4096236737,"timestamp":"2026-08-16T23:38:02.797547Z"}]}}
{"rx_ns": 42948317482100, "frame": {"channel":"book","type":"update","data":[{"symbol":"BTC/USD","bids":[{"price":62790.1,"qty":0.00000000},{"price":62726.2,"qty":0.35581000}],"asks":[],"checksum":3637943102,"timestamp":"2026-08-16T23:38:02.945809Z"}]}}
{"rx_ns": 42948321117000, "frame": {"channel":"book","type":"update","data":[{"symbol":"BTC/USD","bids":[{"price":62791.0,"qty":0.02131292}],"asks":[],"checksum":3263878484,"timestamp":"2026-08-16T23:38:02.946098Z"}]}}
{"rx_ns": 42948321166500, "frame": {"channel":"book","type":"update","data":[{"symbol":"BTC/USD","bids":[],"asks":[{"price":62815.6,"qty":0.00000000},{"price":62862.0,"qty":0.15142628}],"checksum":3263878484,"timestamp":"2026-08-16T23:38:02.947008Z"}]}}
{"rx_ns": 42948322976600, "frame": {"channel":"book","type":"update","data":[{"symbol":"BTC/USD","bids":[],"asks":[{"price":62809.9,"qty":0.36756776}],"checksum":3263878484,"timestamp":"2026-08-16T23:38:02.949979Z"}]}}
{"rx_ns": 42948325070300, "frame": {"channel":"book","type":"update","data":[{"symbol":"BTC/USD","bids":[{"price":62791.2,"qty":1.38258808}],"asks":[],"checksum":2996446060,"timestamp":"2026-08-16T23:38:02.953201Z"}]}}
{"rx_ns": 42948327881800, "frame": {"channel":"book","type":"update","data":[{"symbol":"BTC/USD","bids":[{"price":62774.1,"qty":1.09014750}],"asks":[],"checksum":2996446060,"timestamp":"2026-08-16T23:38:02.956366Z"}]}}
