{"rx_ns": 42899845024500, "frame": {"channel":"book","type":"update","data":[{"symbol":"BTC/USD","bids":[],"asks":[{"price":62795.9,"qty":0.00000000},{"price":62881.2,"qty":0.16061732},{"price":62794.8,"qty":5.71821514}],"checksum":1018442104,"timestamp":"2026-08-16T23:37:14.466073Z"}]}}
{"rx_ns": 42899845076100, "frame": {"channel":"book","type":"update","data":[{"symbol":"BTC/USD","bids":[{"price":62778.0,"qty":0.00518991}],"asks":[],"checksum":1018442104,"timestamp":"2026-08-16T23:37:14.466413Z"}]}}
{"rx_ns": 42899845148000, "frame": {"channel":"book","type":"update","data":[{"symbol":"BTC/USD","bids":[{"price":62755.7,"qty":0.00000000},{"price":62699.7,"qty":5.58216167}],"asks":[],"checksum":1018442104,"timestamp":"2026-08-16T23:37:14.470443Z"}]}}
{"rx_ns": 42899849660000, "frame": {"channel":"book","type":"update","data":[{"symbol":"BTC/USD","bids":[{"price":62781.6,"qty":0.79641109}],"asks":[],"checksum":3367639601,"timestamp":"2026-08-16T23:37:14.474890Z"}]}}
{"rx_ns": 42899849706500, "frame": {"channel":"book","type":"update","data":[{"symbol":"BTC/USD","bids":[{"price":62780.1,"qty":0.79642987}],"asks":[],"checksum":3367639601,"timestamp":"2026-08-16T23:37:14.475105Z"}]}}
{"rx_ns": 42899849716900, "frame": {"channel":"book","type":"update","data":[{"symbol":"BTC/USD","bids":[{"price":62775.3,"qty":0.79649059}],"asks":[],"checksum":3367639601,"timestamp":"2026-08-16T23:37:14.475127Z"}]}}
{"rx_ns": 42899854750800, "frame": {"channel":"book","type":"update","data":[{"symbol":"BTC/USD","bids":[],"asks":[{"price":62863.8,"qty":0.00000000},{"price":62883.3,"qty":0.02184000}],"checksum":3367639601,"timestamp":"2026-08-16T23:37:14.479811Z"}]}}
{"rx_ns": 42899860096900, "frame": {"channel":"book","type":"update","data":[{"symbol":"BTC/USD","bids":[{"price":62779.8,"qty":0.00000000},{"price":62703.0,"qty":0.01531807}],"asks":[],"checksum":3367639601,"timestamp":"2026-08-16T23:37:14.487480Z"}]}}
{"rx_ns": 42899865276800, "frame": {"channel":"book","type":"update","data":[{"symbol":"BTC/USD","bids":[{"price":62745.8,"qty":0.16424251}],"asks":[],"checksum":3367639601,"timestamp":"2026-08-16T23:37:14.491422Z"}]}}
{"rx_ns": 42899865331300, "frame": {"channel":"book","type":"update","data":[{"symbol":"BTC/USD","bids":[{"price":62781.6,"qty":0.00000000},{"price":62703.0,"qty":0.01531807}],"asks":[],"checksum":1018442104,"timestamp":"2026-08-16T23:37:14.491767Z"}]}}
{"rx_ns": 42899871075900, "frame": {"channel":"book","type":"update","data":[{"symbol":"BTC/USD","bids":[{"price":62714.4,"qty":0.16488958}],"asks":[],"checksum":1018442104,"timestamp":"2026-08-16T23:37:14.492429Z"}]}}
{"rx_ns": 42899872382200, "frame": {"channel":"book","type":"update","data":[{"symbol":"BTC/USD","bids":[{"price":62779.2,"qty":0.15927785}],"asks":[],"checksum":1018442104,"timestamp":"2026-08-16T23:37:14.495971Z"}]}}
{"rx_ns": 42899883959300, "frame": {"channel":"book","type":"update","data":[{"symbol":"BTC/USD","bids":[{"price":62780.1,"qty":0.00000000},{"price":62703.8,"qty":0.05517271}],"asks":[],"checksum":1018442104,"timestamp":"2026-08-16T23:37:14.511302Z"}]}}
{"rx_ns": 42899886000700, "frame": {"channel":"book","type":"update","data":[{"symbol":"BTC/USD","bids":[{"price":62779.5,"qty":0.00000000},{"price":62703.0,"qty":0.01531807}],"asks":[],"checksum":1018442104,"timestamp":"2026-08-16T23:37:14.513724Z"}]}}
{"rx_ns": 42899887335300, "frame": {"channel":"book","type":"update","data":[{"symbol":"BTC/USD","bids":[{"price":62763.0,"qty":1.59959300}],"asks":[],"checksum":1018442104,"timestamp":"2026-08-16T23:37:14.513972Z"}]}}
{"rx_ns": 42899893908100, "frame": {"channel":"book","type":"update","data":[{"symbol":"BTC/USD","bids":[{"price":62771.8,"qty":0.00000000},{"price":62699.9,"qty":1.50000000}],"asks":[],"checksum":1018442104,"timestamp":"2026-08-16T23:37:14.521318Z"}]}}
{"rx_ns": 42899897496700, "frame": {"channel":"book","type":"update","data":[{"symbol":"BTC/USD","bids":[{"price":62764.7,"qty":0.00080000}],"asks":[],"checksum":1018442104,"timestamp":"2026-08-16T23:37:14.523919Z"}]}}
{"rx_ns": 42899899334100, "frame": {"channel":"book","type":"update","data":[{"symbol":"BTC/USD","bids":[{"price":62794.7,"qty":0.02354864}],"asks":[],"checksum":1509198837,"timestamp":"2026-08-16T23:37:14.527268Z"}]}}
{"rx_ns": 42899937770500, "frame": {"channel":"book","type":"update","data":[{"symbol":"BTC/USD","bids":[{"price":62774.0,"qty":0.98138619}],"asks":[],"checksum":1509198837,"timestamp":"2026-08-16T23:37:14.565745Z"}]}}
{"rx_ns": 42899953443600, "frame": {"channel":"book","type":"update","data":[{"symbol":"BTC/USD","bids":[{"price":62757.6,"qty":0.00000000},{"price":62699.9,"qty":1.50000000}],"asks":[],"checksum":1509198837,"timestamp":"2026-08-16T23:37:14.580011Z"}]}}
{"rx_ns": 42899953486500, "frame": {"channel":"book","type":"update","data":[{"symbol":"BTC/USD","bids":[],"asks":[{"price":62852.1,"qty":0.00000000},{"price":62883.7,"qty":1.31257213}],"checksum":1509198837,"timestamp":"2026-08-16T23:37:14.580280Z"}]}}
{"rx_ns": 42899955116700, "frame": {"channel":"book","type":"update","data":[{"symbol":"BTC/USD","bids":[{"price":62744.8,"qty":2.12530196}],"asks":[{"price":62836.0,"qty":2.73779804}],"checksum":1509198837,"timestamp":"2026-08-16T23:37:14.582236Z"}]}}
{"rx_ns": 42899956802800, "frame": {"channel":"book","type":"update","data":[{"symbol":"BTC/USD","bids":[{"price":62753.2,"qty":0.00000000},{"price":62699.9,"qty":1.50000000}],"asks":[],"checksum":1509198837,"timestamp":"2026-08-16T23:37:14.583558Z"}]}}
{"rx_ns": 42899956854600, "frame": {"channel":"book","type":"update","data":[{"symbol":"BTC/USD","bids":[],"asks":[{"price":62836.5,"qty":0.02057681}],"checksum":1509198837,"timestamp":"2026-08-16T23:37:14.583736Z"}]}}
{"rx_ns": 42899956866300, "frame": {"channel":"book","type":"update","data":[{"symbol":"BTC/USD","bids":[{"price":62779.2,"qty":0.00000000},{"price":62699.7,"qty":5.58216167}],"asks":[],"checksum":1509198837,"timestamp":"2026-08-16T23:37:14.583904Z"}]}}
{"rx_ns": 42899960316500, "frame": {"channel":"book","type":"update","data":[{"symbol":"BTC/USD","bids":[{"price":62745.8,"qty":0.00000000},{"price":62699.4,"qty":0.05598472}],"asks":[],"checksum":1509198837,"timestamp":"2026-08-16T23:37:14.584580Z"}]}}
{"rx_ns": 42899960359600, "frame": {"channel":"book","type":"update","data":[{"symbol":"BTC/USD","bids":[],"asks":[{"price":62794.8,"qty":5.82821514}],"checksum":3355188604,"timestamp":"2026-08-16T23:37:14.584606Z"}]}}
{"rx_ns": 42899964762000, "frame": {"channel":"book","type":"update","data":[{"symbol":"BTC/USD","bids":[{"price":62781.6,"qty":0.79641120}],"asks":[],"checksum":2227588130,"timestamp":"2026-08-16T23:37:14.586742Z"}]}}
{"rx_ns": 42899964817700, "frame": {"channel":"book","type":"update","data":[{"symbol":"BTC/USD","bids":[{"price":62787.4,"qty":0.00000000},{"price":62699.4,"qty":0.05598472},{"price":62785.3,"qty":0.00318620}],"asks":[],"checksum":3685692380,"timestamp":"2026-08-16T23:37:14.586887Z"}]}}
{"rx_ns": 42899964834100, "frame": {"channel":"book","type":"update","data":[{"symbol":"BTC/USD","bids":[],"asks":[{"price":62806.8,"qty":0.00005100},{"price":62804.8,"qty":0.00318620}],"checksum":3685692380,"timestamp":"2026-08-16T23:37:14.587188Z"}]}}
{"rx_ns": 42899964864700, "frame": {"channel":"book","type":"update","data":[{"symbol":"BTC/USD","bids":[{"price":62766.1,"qty":0.00000000},{"price":62699.4,"qty":0.05598472},{"price":62760.4,"qty":0.10294709}],"asks":[],"checksum":3685692380,"timestamp":"2026-08-16T23:37:14.590421Z"}]}}
{"rx_ns": 42899964876800, "frame": {"channel":"book","type":"update","data":[{"symbol":"BTC/USD","bids":[],"asks":[{"price":62818.7,"qty":0.00222509},{"price":62805.5,"qty":1.59575715}],"checksum":3685692380,"timestamp":"2026-08-16T23:37:14.590484Z"}]}}
{"rx_ns": 42899966427000, "frame": {"channel":"book","type":"update","data":[{"symbol":"BTC/USD","bids":[{"price":62785.9,"qty":0.00009500}],"asks":[],"checksum":2271829500,"timestamp":"2026-08-16T23:37:14.592494Z"}]}}
{"rx_ns": 42899968331500, "frame": {"channel":"book","type":"update","data":[{"symbol":"BTC/USD","bids":[],"asks":[{"price":62805.5,"qty":0.00000000},{"price":62881.0,"qty":0.00829460},{"price":62813.4,"qty":1.59575715}],"checksum":2271829500,"timestamp":"2026-08-16T23:37:14.595220Z"}]}}
{"rx_ns": 42899973455400, "frame": {"channel":"book","type":"update","data":[{"symbol":"BTC/USD","bids":[{"price":62778.6,"qty":0.15927785}],"asks":[],"checksum":2271829500,"timestamp":"2026-08-16T23:37:14.596240Z"}]}}
{"rx_ns": 42899973525100, "frame": {"channel":"book","type":"update","data":[{"symbol":"BTC/USD","bids":[{"price":62778.6,"qty":0.00000000},{"price":62699.9,"qty":1.50000000}],"asks":[],"checksum":2271829500,"timestamp":"2026-08-16T23:37:14.599194Z"}]}}
{"rx_ns": 42899983328000, "frame": {"channel":"book","type":"update","data":[{"symbol":"BTC/USD","bids":[{"price":62738.9,"qty":0.03209525}],"asks":[],"checksum":2271829500,"timestamp":"2026-08-16T23:37:14.610473Z"}]}}
{"rx_ns": 42899983376300, "frame": {"channel":"book","type":"update","data":[{"symbol":"BTC/USD","bids":[],"asks":[{"price":62834.6,"qty":0.00000000},{"price":62881.0,"qty":0.00829460},{"price":62818.6,"qty":0.03591094}],"checksum":2271829500,"timestamp":"2026-08-16T23:37:14.610545Z"}]}}
{"rx_ns": 42899989110100, "frame": {"channel":"book","type":"update","data":[{"symbol":"BTC/USD","bids":[{"price":62781.6,"qty":0.00000000},{"price":62699.9,"qty":1.50000000}],"asks":[],"checksum":2271829500,"timestamp":"2026-08-16T23:37:14.616567Z"}]}}
{"rx_ns": 42899990834000, "frame": {"channel":"book","type":"update","data":[{"symbol":"BTC/USD","bids":[{"price":62777.9,"qty":0.15927785}],"asks":[],"checksum":2271829500,"timestamp":"2026-08-16T23:37:14.617307Z"}]}}
{"rx_ns": 42899999484400, "frame": {"channel":"book","type":"update","data":[{"symbol":"BTC/USD","bids":[{"price":62770.9,"qty":0.00023889}],"asks":[],"checksum":2271829500,"timestamp":"2026-08-16T23:37:14.626471Z"}]}}
{"rx_ns": 42900004077800, "frame": {"channel":"book","type":"update","data":[{"symbol":"BTC/USD","bids":[{"price":62781.2,"qty":0.00000000},{"price":62703.0,"qty":0.01531807}],"asks":[],"checksum":2271829500,"timestamp":"2026-08-16T23:37:14.630044Z"}]}}
{"rx_ns": 42900007631300, "frame": {"channel":"book","type":"update","data":[{"symbol":"BTC/USD","bids":[{"price":62793.1,"qty":0.00000000},{"price":62699.9,"qty":1.50000000}],"asks":[],"checksum":2258769787,"timestamp":"2026-08-16T23:37:14.633646Z"}]}}
{"rx_ns": 42900011448900, "frame": {"channel":"book","type":"update","data":[{"symbol":"BTC/USD","bids":[{"price":62774.0,"qty":0.74369300}],"asks":[],"checksum":2258769787,"timestamp":"2026-08-16T23:37:14.635225Z"}]}}
{"rx_ns": 42900011545600, "frame": {"channel":"book","type":"update","data":[{"symbol":"BTC/USD","bids":[{"price":62791.7,"qty":0.02131292}],"asks":[],"checksum":4005069483,"timestamp":"2026-08-16T23:37:14.636339Z"}]}}
{"rx_ns": 42900016441800, "frame": {"channel":"book","type":"update","data":[{"symbol":"BTC/USD","bids":[{"price":62774.0,"qty":0.98138619}],"asks":[],"checksum":4005069483,"timestamp":"2026-08-16T23:37:14.637742Z"}]}}
{"rx_ns": 42900019033400, "frame": {"channel":"book","type":"update","data":[{"symbol":"BTC/USD","bids":[{"price":62738.9,"qty":0.00000000},{"price":62699.9,"qty":1.50000000}],"asks":[],"checksum":4005069483,"timestamp":"2026-08-16T23:37:14.644197Z"}]}}
{"rx_ns": 42900023220000, "frame": {"channel":"book","type":"update","data":[{"symbol":"BTC/USD","bids":[],"asks":[{"price":62813.4,"qty":0.00000000},{"price":62881.0,"qty":0.00829460},{"price":62805.5,"qty":1.59575715}],"checksum":4005069483,"timestamp":"2026-08-16T23:37:14.651441Z"}]}}
{"rx_ns": 42900058829000, "frame": {"channel":"book","type":"update","data":[{"symbol":"BTC/USD","bids":[],"asks":[{"price":62796.9,"qty":0.79621764}],"checksum":1516177984,"timestamp":"2026-08-16T23:37:14.685621Z"}]}}
{"rx_ns": 42900063434100, "frame": {"channel":"book","type":"update","data":[{"symbol":"BTC/USD","bids":[],"asks":[{"price":62844.4,"qty":0.00000000},{"price":62881.0,"qty":0.00829460}],"checksum":1516177984,"timestamp":"2026-08-16T23:37:14.686751Z"}]}}
{"rx_ns": 42900068280000, "frame": {"channel":"book","type":"update","data":[{"symbol":"BTC/USD","bids":[{"price":62780.2,"qty":0.00000000},{"price":62699.7,"qty":5.58216167}],"asks":[],"checksum":1516177984,"timestamp":"2026-08-16T23:37:14.695525Z"}]}}
{"rx_ns": 42900075110300, "frame": {"channel":"book","type":"update","data":[{"symbol":"BTC/USD","bids":[],"asks":[{"price":62805.5,"qty":0.00000000},{"price":62881.2,"qty":0.16061732},{"price":62810.8,"qty":1.59575715}],"checksum":1516177984,"timestamp":"2026-08-16T23:37:14.698645Z"}]}}
{"rx_ns": 42900121675800, "frame": {"channel":"book","type":"update","data":[{"symbol":"BTC/USD","bids":[],"asks":[{"price":62808.0,"qty":0.00000000},{"price":62881.2,"qty":0.16061732}],"checksum":1516177984,"timestamp":"2026-08-16T23:37:14.749783Z"}]}}
{"rx_ns": 42900122978700, "frame": {"channel":"book","type":"update","data":[{"symbol":"BTC/USD","bids":[],"asks":[{"price":62824.3,"qty":0.00000000},{"price":62882.9,"qty":0.47664271},{"price":62822.5,"qty":0.28000000}],"checksum":1516177984,"timestamp":"2026-08-16T23:37:14.750061Z"}]}}
{"rx_ns": 42900141249300, "frame": {"channel":"book","type":"update","data":[{"symbol":"BTC/USD","bids":[],"asks":[{"price":62822.5,"qty":0.00000000},{"price":62882.9,"qty":0.47664271},{"price":62822.3,"qty":0.28000000}],"checksum":1516177984,"timestamp":"2026-08-16T23:37:14.767933Z"}]}}
{"rx_ns": 42900192297800, "frame": {"channel":"book","type":"update","data":[{"symbol":"BTC/USD","bids":[{"price":62771.3,"qty":0.00000000},{"price":62696.3,"qty":0.00410338}],"asks":[],"checksum":1516177984,"timestamp":"2026-08-16T23:37:14.816779Z"}]}}
{"rx_ns": 42900192390400, "frame": {"channel":"book","type":"update","data":[{"symbol":"BTC/USD","bids":[{"price":62779.8,"qty":0.79643385}],"asks":[],"checksum":1516177984,"timestamp":"2026-08-16T23:37:14.818407Z"}]}}
{"rx_ns": 42900192406000, "frame": {"channel":"book","type":"update","data":[{"symbol":"BTC/USD","bids":[{"price":62766.3,"qty":2.38981666}],"asks":[],"checksum":1516177984,"timestamp":"2026-08-16T23:37:14.818509Z"}]}}
{"rx_ns": 42900194534600, "frame": {"channel":"book","type":"update","data":[{"symbol":"BTC/USD","bids":[{"price":62750.7,"qty":0.15920000}],"asks":[],"checksum":1516177984,"timestamp":"2026-08-16T23:37:14.820275Z"}]}}
{"rx_ns": 42900194622100, "frame": {"channel":"book","type":"update","data":[{"symbol":"BTC/USD","bids":[{"price":62753.2,"qty":0.23900000}],"asks":[],"checksum":1516177984,"timestamp":"2026-08-16T23:37:14.822390Z"}]}}
{"rx_ns": 42900287789000, "frame": {"channel":"book","type":"update","data":[{"symbol":"BTC/USD","bids":[{"price":62779.8,"qty":0.00000000},{"price":62703.0,"qty":0.01531807}],"asks":[],"checksum":1516177984,"timestamp":"2026-08-16T23:37:14.915753Z"}]}}
{"rx_ns": 42900289605100, "frame": {"channel":"book","type":"update","data":[{"symbol":"BTC/USD","bids":[{"price":62781.0,"qty":0.79641900}],"asks":[],"checksum":1516177984,"timestamp":"2026-08-16T23:37:14.917261Z"}]}}
{"rx_ns": 42900299076900, "frame": {"channel":"book","type":"update","data":[{"symbol":"BTC/USD","bids":[],"asks":[{"price":62805.1,"qty":0.00000000},{"price":62882.1,"qty":0.47664869},{"price":62800.6,"qty":0.19620257}],"checksum":2299750211,"timestamp":"2026-08-16T23:37:14.927024Z"}]}}
{"rx_ns": 42900300555800, "frame": {"channel":"book","type":"update","data":[{"symbol":"BTC/USD","bids":[],"asks":[{"price":62800.7,"qty":0.00000000},{"price":62882.1,"qty":0.47664869},{"price":62800.5,"qty":0.18489680}],"checksum":1064814256,"timestamp":"2026-08-16T23:37:14.928208Z"}]}}
{"rx_ns": 42900303704800, "frame": {"channel":"book","type":"update","data":[{"symbol":"BTC/USD","bids":[{"price":62737.8,"qty":0.03207068}],"asks":[],"checksum":1064814256,"timestamp":"2026-08-16T23:37:14.931465Z"}]}}
{"rx_ns": 42900309657600, "frame": {"channel":"book","type":"update","data":[{"symbol":"BTC/USD","bids":[],"asks":[{"price":62800.5,"qty":0.18494780}],"checksum":120429725,"timestamp":"2026-08-16T23:37:14.937667Z"}]}}
{"rx_ns": 42900311153800, "frame": {"channel":"book","type":"update","data":[{"symbol":"BTC/USD","bids":[],"asks":[{"price":62828.7,"qty":0.00000000},{"price":62882.1,"qty":0.47664869}],"checksum":120429725,"timestamp":"2026-08-16T23:37:14.939197Z"}]}}
{"rx_ns": 42900381703400, "frame": {"channel":"book","type":"update","data":[{"symbol":"BTC/USD","bids":[],"asks":[{"price":62820.9,"qty":0.00000000},{"price":62883.3,"qty":0.02184000}],"checksum":120429725,"timestamp":"2026-08-16T23:37:15.006758Z"}]}}
{"rx_ns": 42900381762200, "frame": {"channel":"book","type":"update","data":[{"symbol":"BTC/USD","bids":[],"asks":[{"price":62809.7,"qty":0.02865799}],"checksum":120429725,"timestamp":"2026-08-16T23:37:15.006962Z"}]}}
{"rx_ns": 42900383138400, "frame": {"channel":"book","type":"update","data":[{"symbol":"BTC/USD","bids":[{"price":62760.4,"qty":0.00000000},{"price":62703.8,"qty":0.05517271},{"price":62766.1,"qty":0.10293774}],"asks":[],"checksum":120429725,"timestamp":"2026-08-16T23:37:15.008724Z"}]}}
{"rx_ns": 42900383181300, "frame": {"channel":"book","type":"update","data":[{"symbol":"BTC/USD","bids":[{"price":62777.9,"qty":0.00000000},{"price":62703.8,"qty":0.05517271}],"asks":[],"checksum":120429725,"timestamp":"2026-08-16T23:37:15.010744Z"}]}}
{"rx_ns": 42900392213700, "frame": {"channel":"book","type":"update","data":[{"symbol":"BTC/USD","bids":[{"price":62777.8,"qty":0.26927785}],"asks":[],"checksum":120429725,"timestamp":"2026-08-16T23:37:15.016908Z"}]}}
{"rx_ns": 42900392298600, "frame": {"channel":"book","type":"update","data":[{"symbol":"BTC/USD","bids":[{"price":62794.7,"qty":0.02364864}],"asks":[],"checksum":2532399212,"timestamp":"2026-08-16T23:37:15.017770Z"}]}}
{"rx_ns": 42900448157400, "frame": {"channel":"book","type":"update","data":[{"symbol":"BTC/USD","bids":[{"price":62791.7,"qty":0.00000000},{"price":62703.0,"qty":0.01531807}],"asks":[],"checksum":3206063212,"timestamp":"2026-08-16T23:37:15.074258Z"}]}}
{"rx_ns": 42900448234900, "frame": {"channel":"book","type":"update","data":[{"symbol":"BTC/USD","bids":[{"price":62792.6,"qty":0.02131292}],"asks":[],"checksum":557000923,"timestamp":"2026-08-16T23:37:15.074420Z"}]}}
{"rx_ns": 42900448250000, "frame": {"channel":"book","type":"update","data":[{"symbol":"BTC/USD","bids":[{"price":62774.0,"qty":0.74369300}],"asks":[],"checksum":557000923,"timestamp":"2026-08-16T23:37:15.074931Z"}]}}
{"rx_ns": 42900510878800, "frame": {"channel":"book","type":"update","data":[{"symbol":"BTC/USD","bids":[],"asks":[{"price":62851.2,"qty":0.00000000},{"price":62883.3,"qty":0.02184000},{"price":62849.6,"qty":0.00660000}],"checksum":557000923,"timestamp":"2026-08-16T23:37:15.132935Z"}]}}
{"rx_ns": 42900535777200, "frame": {"channel":"book","type":"update","data":[{"symbol":"BTC/USD","bids":[{"price":62771.7,"qty":0.07963975}],"asks":[],"checksum":557000923,"timestamp":"2026-08-16T23:37:15.162912Z"}]}}
{"rx_ns": 42900538117700, "frame": {"channel":"book","type":"update","data":[{"symbol":"BTC/USD","bids":[{"price":62772.3,"qty":0.03185589}],"asks":[],"checksum":557000923,"timestamp":"2026-08-16T23:37:15.166228Z"}]}}
{"rx_ns": 42900546838300, "frame": {"channel":"book","type":"update","data":[{"symbol":"BTC/USD","bids":[{"price":62781.0,"qty":0.00000000},{"price":62703.8,"qty":0.05517271}],"asks":[],"checksum":557000923,"timestamp":"2026-08-16T23:37:15.173645Z"}]}}
{"rx_ns": 42900549866700, "frame": {"channel":"book","type":"update","data":[{"symbol":"BTC/USD","bids":[{"price":62781.7,"qty":0.79640946}],"asks":[],"checksum":557000923,"timestamp":"2026-08-16T23:37:15.175631Z"}]}}
{"rx_ns": 42900549911400, "frame": {"channel":"book","type":"update","data":[{"symbol":"BTC/USD","bids":[{"price":62779.5,"qty":0.79643772}],"asks":[],"checksum":557000923,"timestamp":"2026-08-16T23:37:15.175742Z"}]}}
{"rx_ns": 42900549925900, "frame": {"channel":"book","type":"update","data":[{"symbol":"BTC/USD","bids":[],"asks":[{"price":62831.5,"qty":0.00000000},{"price":62883.3,"qty":0.02184000},{"price":62833.0,"qty":0.00318620}],"checksum":557000923,"timestamp":"2026-08-16T23:37:15.175870Z"}]}}
{"rx_ns": 42900549939800, "frame": {"channel":"book","type":"update","data":[{"symbol":"BTC/USD","bids":[{"price":62755.5,"qty":0.00000000},{"price":62706.5,"qty":0.00162380},{"price":62757.1,"qty":0.00318620}],"asks":[],"checksum":557000923,"timestamp":"2026-08-16T23:37:15.176169Z"}]}}
{"rx_ns": 42900574991100, "frame": {"channel":"book","type":"update","data":[{"symbol":"BTC/USD","bids":[],"asks":[{"price":62827.0,"qty":0.00094656}],"checksum":557000923,"timestamp":"2026-08-16T23:37:15.201050Z"}]}}
{"rx_ns": 42900594548500, "frame": {"channel":"book","type":"update","data":[{"symbol":"BTC/USD","bids":[],"asks":[{"price":62818.7,"qty":0.00000000},{"price":62882.1,"qty":0.47664869},{"price":62810.7,"qty":0.00222509}],"checksum":557000923,"timestamp":"2026-08-16T23:37:15.221225Z"}]}}
{"rx_ns": 42900663507500, "frame": {"channel":"heartbeat"}}
{"rx_ns": 42900699568900, "frame": {"channel":"book","type":"update","data":[{"symbol":"BTC/USD","bids":[{"price":62737.7,"qty":0.00000000},{"price":62706.5,"qty":0.00162380}],"asks":[],"checksum":557000923,"timestamp":"2026-08-16T23:37:15.327456Z"}]}}
{"rx_ns": 42900703624100, "frame": {"channel":"book","type":"update","data":[{"symbol":"BTC/USD","bids":[{"price":62741.1,"qty":0.00000000},{"price":62703.8,"qty":0.05517271}],"asks":[],"checksum":557000923,"timestamp":"2026-08-16T23:37:15.327548Z"}]}}
{"rx_ns": 42900703702400, "frame": {"channel":"book","type":"update","data":[{"symbol":"BTC/USD","bids":[{"price":62705.0,"qty":0.06960000}],"asks":[],"checksum":557000923,"timestamp":"2026-08-16T23:37:15.331253Z"}]}}
{"rx_ns": 42900705347900, "frame": {"channel":"book","type":"update","data":[{"symbol":"BTC/USD","bids":[{"price":62729.3,"qty":1.09961085}],"asks":[],"checksum":557000923,"timestamp":"2026-08-16T23:37:15.333164Z"}]}}
{"rx_ns": 42900708214400, "frame": {"channel":"book","type":"update","data":[{"symbol":"BTC/USD","bids":[{"price":62726.0,"qty":1.62741235}],"asks":[],"checksum":557000923,"timestamp":"2026-08-16T23:37:15.333267Z"}]}}
{"rx_ns": 42900708280900, "frame": {"channel":"book","type":"update","data":[{"symbol":"BTC/USD","bids":[{"price":62726.1,"qty":3.05282538}],"asks":[],"checksum":557000923,"timestamp":"2026-08-16T23:37:15.333412Z"}]}}
{"rx_ns": 42900712680900, "frame": {"channel":"book","type":"update","data":[{"symbol":"BTC/USD","bids":[],"asks":[{"price":62810.3,"qty":0.00318419}],"checksum":557000923,"timestamp":"2026-08-16T23:37:15.337357Z"}]}}
{"rx_ns": 42900712757500, "frame": {"channel":"book","type":"update","data":[{"symbol":"BTC/USD","bids":[],"asks":[{"price":62821.7,"qty":0.00000000},{"price":62881.2,"qty":0.16061732}],"checksum":557000923,"timestamp":"2026-08-16T23:37:15.337465Z"}]}}
{"rx_ns": 42900780888900, "frame": {"channel":"book","type":"update","data":[{"symbol":"BTC/USD","bids":[{"price":62722.2,"qty":0.00000000},{"price":62707.9,"qty":0.00079734},{"price":62719.8,"qty":0.35581000}],"asks":[],"checksum":557000923,"timestamp":"2026-08-16T23:37:15.407839Z"}]}}
{"rx_ns": 42900780966400, "frame": {"channel":"book","type":"update","data":[{"symbol":"BTC/USD","bids":[{"price":62725.3,"qty":0.00000000},{"price":62707.9,"qty":0.00079734},{"price":62722.8,"qty":0.70609000}],"asks":[],"checksum":557000923,"timestamp":"2026-08-16T23:37:15.407868Z"}]}}
{"rx_ns": 42900786697600, "frame": {"channel":"book","type":"update","data":[{"symbol":"BTC/USD","bids":[{"price":62737.8,"qty":0.00000000},{"price":62707.9,"qty":0.00079734}],"asks":[],"checksum":557000923,"timestamp":"2026-08-16T23:37:15.411176Z"}]}}
{"rx_ns": 42900786770000, "frame": {"channel":"book","type":"update","data":[{"symbol":"BTC/USD","bids":[{"price":62766.1,"qty":0.00000000},{"price":62706.5,"qty":0.00162380},{"price":62763.1,"qty":0.10294266}],"asks":[],"checksum":557000923,"timestamp":"2026-08-16T23:37:15.411466Z"}]}}
{"rx_ns": 42900800218900, "frame": {"channel":"book","type":"update","data":[{"symbol":"BTC/USD","bids":[{"price":62775.3,"qty":0.00000000},{"price":62706.5,"qty":0.00162380}],"asks":[],"checksum":557000923,"timestamp":"2026-08-16T23:37:15.413155Z"}]}}
{"rx_ns": 42900800287600, "frame": {"channel":"book","type":"update","data":[{"symbol":"BTC/USD","bids":[{"price":62781.7,"qty":0.00000000},{"price":62703.0,"qty":0.01531807}],"asks":[],"checksum":557000923,"timestamp":"2026-08-16T23:37:15.415798Z"}]}}
{"rx_ns": 42900800472600, "frame": {"channel":"book","type":"update","data":[{"symbol":"BTC/USD","bids":[{"price":62760.3,"qty":0.00000000},{"price":62699.9,"qty":1.50000000}],"asks":[],"checksum":557000923,"timestamp":"2026-08-16T23:37:15.417123Z"}]}}
{"rx_ns": 42900800490000, "frame": {"channel":"book","type":"update","data":[{"symbol":"BTC/USD","bids":[{"price":62779.5,"qty":0.00000000},{"price":62699.7,"qty":5.58216167}],"asks":[],"checksum":557000923,"timestamp":"2026-08-16T23:37:15.417439Z"}]}}
{"rx_ns": 42900800503600, "frame": {"channel":"book","type":"update","data":[{"symbol":"BTC/USD","bids":[{"price":62729.2,"qty":0.00159400}],"asks":[],"checksum":557000923,"timestamp":"2026-08-16T23:37:15.417963Z"}]}}
{"rx_ns": 42900807534700, "frame": {"channel":"book","type":"update","data":[{"symbol":"BTC/USD","bids":[{"price":62705.0,"qty":0.06960000}],"asks":[],"checksum":557000923,"timestamp":"2026-08-16T23:37:15.419385Z"}]}}
{"rx_ns": 42900807590900, "frame": {"channel":"book","type":"update","data":[{"symbol":"BTC/USD","bids":[{"price":62777.5,"qty":0.79646257}],"asks":[],"checksum":557000923,"timestamp":"2026-08-16T23:37:15.420641Z"}]}}
{"rx_ns": 42900807600900, "frame": {"channel":"book","type":"update","data":[{"symbol":"BTC/USD","bids":[{"price":62772.7,"qty":0.80448897}],"asks":[],"checksum":557000923,"timestamp":"2026-08-16T23:37:15.420787Z"}]}}
{"rx_ns": 42900807610200, "frame": {"channel":"book","type":"update","data":[{"symbol":"BTC/USD","bids":[{"price":62753.2,"qty":0.00000000},{"price":62699.9,"qty":1.50000000}],"asks":[],"checksum":557000923,"timestamp":"2026-08-16T23:37:15.421929Z"}]}}
{"rx_ns": 42900807620000, "frame": {"channel":"book","type":"update","data":[{"symbol":"BTC/USD","bids":[{"price":62777.5,"qty":0.00000000},{"price":62699.7,"qty":5.58216167}],"asks":[],"checksum":557000923,"timestamp":"2026-08-16T23:37:15.423575Z"}]}}
{"rx_ns": 42900807628500, "frame": {"channel":"book","type":"update","data":[{"symbol":"BTC/USD","bids":[{"price":62760.9,"qty":0.03445108}],"asks":[],"checksum":557000923,"timestamp":"2026-08-16T23:37:15.425644Z"}]}}
{"rx_ns": 42900807635900, "frame": {"channel":"book","type":"update","data":[{"symbol":"BTC/USD","bids":[{"price":62778.0,"qty":0.00000000},{"price":62699.7,"qty":5.58216167}],"asks":[],"checksum":557000923,"timestamp":"2026-08-16T23:37:15.426592Z"}]}}
{"rx_ns": 42900858941200, "frame": {"channel":"book","type":"update","data":[{"symbol":"BTC/USD","bids":[{"price":62773.6,"qty":0.23769319}],"asks":[],"checksum":557000923,"timestamp":"2026-08-16T23:37:15.483877Z"}]}}
{"rx_ns": 42900882415000, "frame": {"channel":"book","type":"update","data":[{"symbol":"BTC/USD","bids":[{"price":62776.0,"qty":0.79648231}],"asks":[],"checksum":557000923,"timestamp":"2026-08-16T23:37:15.504359Z"}]}}
{"rx_ns": 42900893826600, "frame": {"channel":"book","type":"update","data":[{"symbol":"BTC/USD","bids":[],"asks":[{"price":62803.7,"qty":0.00005100}],"checksum":557000923,"timestamp":"2026-08-16T23:37:15.516031Z"}]}}
{"rx_ns": 42900893868000, "frame": {"channel":"book","type":"update","data":[{"symbol":"BTC/USD","bids":[{"price":62777.8,"qty":0.11000000}],"asks":[],"checksum":557000923,"timestamp":"2026-08-16T23:37:15.516578Z"}]}}
{"rx_ns": 42900895334400, "frame": {"channel":"book","type":"update","data":[{"symbol":"BTC/USD","bids":[],"asks":[{"price":62842.1,"qty":0.00000000},{"price":62881.2,"qty":0.16061732},{"price":62822.6,"qty":0.11123578}],"checksum":557000923,"timestamp":"2026-08-16T23:37:15.519557Z"}]}}
{"rx_ns": 42900908182800, "frame": {"channel":"book","type":"update","data":[{"symbol":"BTC/USD","bids":[{"price":62752.8,"qty":0.00000000},{"price":62699.9,"qty":1.50000000}],"asks":[],"checksum":557000923,"timestamp":"2026-08-16T23:37:15.531999Z"}]}}
{"rx_ns": 42900908236500, "frame": {"channel":"book","type":"update","data":[{"symbol":"BTC/USD","bids":[{"price":62775.4,"qty":0.15927785}],"asks":[],"checksum":557000923,"timestamp":"2026-08-16T23:37:15.532132Z"}]}}
{"rx_ns": 42900908248300, "frame": {"channel":"book","type":"update","data":[{"symbol":"BTC/USD","bids":[{"price":62776.8,"qty":0.10331161}],"asks":[],"checksum":557000923,"timestamp":"2026-08-16T23:37:15.532171Z"}]}}
{"rx_ns": 42900908257200, "frame": {"channel":"book","type":"update","data":[{"symbol":"BTC/USD","bids":[{"price":62766.0,"qty":0.00000000},{"price":62699.9,"qty":1.50000000}],"asks":[],"checksum":557000923,"timestamp":"2026-08-16T23:37:15.532963Z"}]}}
{"rx_ns": 42900908267000, "frame": {"channel":"book","type":"update","data":[{"symbol":"BTC/USD","bids":[{"price":62750.7,"qty":0.00000000},{"price":62699.7,"qty":5.58216167}],"asks":[],"checksum":557000923,"timestamp":"2026-08-16T23:37:15.533711Z"}]}}
{"rx_ns": 42900913972200, "frame": {"channel":"book","type":"update","data":[{"symbol":"BTC/USD","bids":[{"price":62760.9,"qty":0.00000000},{"price":62698.8,"qty":0.05517271}],"asks":[],"checksum":557000923,"timestamp":"2026-08-16T23:37:15.535423Z"}]}}
{"rx_ns": 42900914022500, "frame": {"channel":"book","type":"update","data":[{"symbol":"BTC/USD","bids":[{"price":62776.0,"qty":0.00000000},{"price":62696.3,"qty":0.00410338}],"asks":[],"checksum":557000923,"timestamp":"2026-08-16T23:37:15.536756Z"}]}}
{"rx_ns": 42900915603400, "frame": {"channel":"book","type":"update","data":[{"symbol":"BTC/USD","bids":[{"price":62779.3,"qty":0.79644014}],"asks":[],"checksum":557000923,"timestamp":"2026-08-16T23:37:15.539469Z"}]}}
{"rx_ns": 42900926359200, "frame": {"channel":"book","type":"update","data":[{"symbol":"BTC/USD","bids":[{"price":62771.7,"qty":0.00000000},{"price":62696.3,"qty":0.00410338}],"asks":[],"checksum":557000923,"timestamp":"2026-08-16T23:37:15.553202Z"}]}}
{"rx_ns": 42900930249400, "frame": {"channel":"book","type":"update","data":[{"symbol":"BTC/USD","bids":[{"price":62698.7,"qty":0.06960000}],"asks":[],"checksum":557000923,"timestamp":"2026-08-16T23:37:15.556043Z"}]}}
{"rx_ns": 42900930311300, "frame": {"channel":"book","type":"update","data":[{"symbol":"BTC/USD","bids":[{"price":62772.3,"qty":0.00000000},{"price":62696.3,"qty":0.00410338}],"asks":[],"checksum":557000923,"timestamp":"2026-08-16T23:37:15.556512Z"}]}}
{"rx_ns": 42900935958600, "frame": {"channel":"book","type":"update","data":[{"symbol":"BTC/USD","bids":[{"price":62775.4,"qty":0.00000000},{"price":62696.2,"qty":0.07974964}],"asks":[],"checksum":557000923,"timestamp":"2026-08-16T23:37:15.561843Z"}]}}
{"rx_ns": 42900943644800, "frame": {"channel":"book","type":"update","data":[{"symbol":"BTC/USD","bids":[{"price":62788.1,"qty":0.00000000},{"price":62692.2,"qty":0.00136326}],"asks":[],"checksum":3176470186,"timestamp":"2026-08-16T23:37:15.570473Z"}]}}
{"rx_ns": 42900952692200, "frame": {"channel":"book","type":"update","data":[{"symbol":"BTC/USD","bids":[{"price":62780.4,"qty":0.05598472}],"asks":[],"checksum":2641248790,"timestamp":"2026-08-16T23:37:15.572362Z"}]}}
{"rx_ns": 42900959391500, "frame": {"channel":"book","type":"update","data":[{"symbol":"BTC/USD","bids":[{"price":62779.3,"qty":0.00000000},{"price":62692.2,"qty":0.00136326}],"asks":[],"checksum":2641248790,"timestamp":"2026-08-16T23:37:15.582316Z"}]}}
{"rx_ns": 42900963117000, "frame": {"channel":"book","type":"update","data":[{"symbol":"BTC/USD","bids":[{"price":62794.7,"qty":0.00849813}],"asks":[],"checksum":2615511242,"timestamp":"2026-08-16T23:37:15.590050Z"}]}}
{"rx_ns": 42900968212400, "frame": {"channel":"book","type":"update","data":[{"symbol":"BTC/USD","bids":[{"price":62773.6,"qty":0.00000000},{"price":62692.1,"qty":0.00119632}],"asks":[],"checksum":2615511242,"timestamp":"2026-08-16T23:37:15.594127Z"}]}}
{"rx_ns": 42900971774000, "frame": {"channel":"book","type":"update","data":[{"symbol":"BTC/USD","bids":[{"price":62776.2,"qty":0.15927785}],"asks":[],"checksum":2615511242,"timestamp":"2026-08-16T23:37:15.596249Z"}]}}
{"rx_ns": 42900981115400, "frame": {"channel":"book","type":"update","data":[{"symbol":"BTC/USD","bids":[],"asks":[{"price":62803.9,"qty":0.00000000},{"price":62881.2,"qty":0.16061732}],"checksum":2615511242,"timestamp":"2026-08-16T23:37:15.608241Z"}]}}
{"rx_ns": 42900981274700, "frame": {"channel":"book","type":"update","data":[{"symbol":"BTC/USD","bids":[],"asks":[{"price":62799.1,"qty":0.06000000}],"checksum":3466112437,"timestamp":"2026-08-16T23:37:15.608264Z"}]}}
{"rx_ns": 42900990881300, "frame": {"channel":"book","type":"update","data":[{"symbol":"BTC/USD","bids":[{"price":62760.0,"qty":0.00000000},{"price":62692.1,"qty":0.00119632}],"asks":[],"checksum":3466112437,"timestamp":"2026-08-16T23:37:15.618463Z"}]}}
{"rx_ns": 42901009365500, "frame": {"channel":"book","type":"update","data":[{"symbol":"BTC/USD","bids":[{"price":62750.7,"qty":0.00050000}],"asks":[],"checksum":3466112437,"timestamp":"2026-08-16T23:37:15.636421Z"}]}}
{"rx_ns": 42901024679700, "frame": {"channel":"book","type":"update","data":[{"symbol":"BTC/USD","bids":[{"price":62735.6,"qty":0.03195923}],"asks":[],"checksum":3466112437,"timestamp":"2026-08-16T23:37:15.647230Z"}]}}
{"rx_ns": 42901087118300, "frame": {"channel":"book","type":"update","data":[{"symbol":"BTC/USD","bids":[],"asks":[{"price":62796.1,"qty":0.00000000},{"price":62881.2,"qty":0.16061732}],"checksum":516116918,"timestamp":"2026-08-16T23:37:15.710466Z"}]}}
{"rx_ns": 42901094868900, "frame": {"channel":"book","type":"update","data":[{"symbol":"BTC/USD","bids":[{"price":62777.8,"qty":0.15522003}],"asks":[],"checksum":516116918,"timestamp":"2026-08-16T23:37:15.719311Z"}]}}
{"rx_ns": 42901121248200, "frame": {"channel":"book","type":"update","data":[{"symbol":"BTC/USD","bids":[{"price":62776.2,"qty":0.00000000},{"price":62695.9,"qty":0.02364864}],"asks":[],"checksum":516116918,"timestamp":"2026-08-16T23:37:15.747737Z"}]}}
{"rx_ns": 42901149681000, "frame": {"channel":"book","type":"update","data":[{"symbol":"BTC/USD","bids":[{"price":62696.3,"qty":0.00000000},{"price":62692.2,"qty":0.00136326},{"price":62698.8,"qty":0.05927648}],"asks":[],"checksum":516116918,"timestamp":"2026-08-16T23:37:15.776800Z"}]}}
{"rx_ns": 42901149984500, "frame": {"channel":"book","type":"update","data":[{"symbol":"BTC/USD","bids":[{"price":62775.7,"qty":0.15927785}],"asks":[],"checksum":516116918,"timestamp":"2026-08-16T23:37:15.778599Z"}]}}
{"rx_ns": 42901153092700, "frame": {"channel":"book","type":"update","data":[{"symbol":"BTC/USD","bids":[{"price":62698.8,"qty":0.05517271},{"price":62696.3,"qty":0.00410376}],"asks":[],"checksum":516116918,"timestamp":"2026-08-16T23:37:15.781067Z"}]}}
{"rx_ns": 42901161907400, "frame": {"channel":"book","type":"update","data":[{"symbol":"BTC/USD","bids":[{"price":62779.9,"qty":0.79643245}],"asks":[],"checksum":516116918,"timestamp":"2026-08-16T23:37:15.782428Z"}]}}
{"rx_ns": 42901161989800, "frame": {"channel":"book","type":"update","data":[{"symbol":"BTC/USD","bids":[{"price":62735.9,"qty":7.96991464}],"asks":[],"checksum":516116918,"timestamp":"2026-08-16T23:37:15.782761Z"}]}}
{"rx_ns": 42901176133100, "frame": {"channel":"book","type":"update","data":[{"symbol":"BTC/USD","bids":[],"asks":[{"price":62844.9,"qty":0.00000000},{"price":62881.4,"qty":0.47653062}],"checksum":516116918,"timestamp":"2026-08-16T23:37:15.803691Z"}]}}
{"rx_ns": 42901179766900, "frame": {"channel":"book","type":"update","data":[{"symbol":"BTC/USD","bids":[],"asks":[{"price":62835.9,"qty":2.80707668}],"checksum":516116918,"timestamp":"2026-08-16T23:37:15.807544Z"}]}}
{"rx_ns": 42901317540400, "frame": {"channel":"book","type":"update","data":[{"symbol":"BTC/USD","bids":[{"price":62775.7,"qty":0.00000000},{"price":62696.3,"qty":0.00410376}],"asks":[],"checksum":516116918,"timestamp":"2026-08-16T23:37:15.944540Z"}]}}
{"rx_ns": 42901318150300, "frame": {"channel":"book","type":"update","data":[{"symbol":"BTC/USD","bids":[{"price":62748.9,"qty":0.15920000}],"asks":[],"checksum":516116918,"timestamp":"2026-08-16T23:37:15.945988Z"}]}}
{"rx_ns": 42901318177400, "frame": {"channel":"book","type":"update","data":[{"symbol":"BTC/USD","bids":[{"price":62775.8,"qty":0.16246379}],"asks":[],"checksum":516116918,"timestamp":"2026-08-16T23:37:15.946107Z"}]}}
{"rx_ns": 42901318189700, "frame": {"channel":"book","type":"update","data":[{"symbol":"BTC/USD","bids":[{"price":62751.4,"qty":0.23900000}],"asks":[],"checksum":516116918,"timestamp":"2026-08-16T23:37:15.946242Z"}]}}
{"rx_ns": 42901375515200, "frame": {"channel":"book","type":"update","data":[{"symbol":"BTC/USD","bids":[{"price":62698.8,"qty":0.05927645}],"asks":[],"checksum":516116918,"timestamp":"2026-08-16T23:37:16.003038Z"}]}}
{"rx_ns": 42901389077100, "frame": {"channel":"book","type":"update","data":[{"symbol":"BTC/USD","bids":[{"price":62775.8,"qty":0.00318594}],"asks":[],"checksum":516116918,"timestamp":"2026-08-16T23:37:16.016558Z"}]}}
{"rx_ns": 42901412603300, "frame": {"channel":"book","type":"update","data":[{"symbol":"BTC/USD","bids":[{"price":62776.4,"qty":0.17526304}],"asks":[],"checksum":516116918,"timestamp":"2026-08-16T23:37:16.039697Z"}]}}
{"rx_ns": 42901530998600, "frame": {"channel":"book","type":"update","data":[{"symbol":"BTC/USD","bids":[],"asks":[{"price":62810.8,"qty":0.00000000},{"price":62881.4,"qty":0.47653062},{"price":62805.2,"qty":1.59575715}],"checksum":516116918,"timestamp":"2026-08-16T23:37:16.159053Z"}]}}
{"rx_ns": 42901533101700, "frame": {"channel":"book","type":"update","data":[{"symbol":"BTC/USD","bids":[{"price":62761.8,"qty":0.00000000},{"price":62696.2,"qty":0.07974964}],"asks":[],"checksum":516116918,"timestamp":"2026-08-16T23:37:16.160524Z"}]}}
{"rx_ns": 42901534383900, "frame": {"channel":"book","type":"update","data":[{"symbol":"BTC/USD","bids":[{"price":62785.3,"qty":0.00000000},{"price":62692.2,"qty":0.00136326},{"price":62785.2,"qty":0.00318620}],"asks":[],"checksum":4141138199,"timestamp":"2026-08-16T23:37:16.161334Z"}]}}
{"rx_ns": 42901534455000, "frame": {"channel":"book","type":"update","data":[{"symbol":"BTC/USD","bids":[],"asks":[{"price":62804.8,"qty":0.00000000},{"price":62881.4,"qty":0.47653062},{"price":62804.6,"qty":0.00318620}],"checksum":4141138199,"timestamp":"2026-08-16T23:37:16.161720Z"}]}}
{"rx_ns": 42901538727900, "frame": {"channel":"book","type":"update","data":[{"symbol":"BTC/USD","bids":[{"price":62698.7,"qty":0.06960000}],"asks":[],"checksum":4141138199,"timestamp":"2026-08-16T23:37:16.162975Z"}]}}
{"rx_ns": 42901550804800, "frame": {"channel":"book","type":"update","data":[{"symbol":"BTC/USD","bids":[{"price":62776.9,"qty":0.79647111}],"asks":[],"checksum":4141138199,"timestamp":"2026-08-16T23:37:16.174427Z"}]}}
{"rx_ns": 42901561052700, "frame": {"channel":"book","type":"update","data":[{"symbol":"BTC/USD","bids":[{"price":62698.8,"qty":0.05517271}],"asks":[],"checksum":4141138199,"timestamp":"2026-08-16T23:37:16.187233Z"}]}}
{"rx_ns": 42901581054200, "frame": {"channel":"book","type":"update","data":[{"symbol":"BTC/USD","bids":[{"price":62779.9,"qty":0.00000000},{"price":62696.3,"qty":0.00410372}],"asks":[],"checksum":4141138199,"timestamp":"2026-08-16T23:37:16.193503Z"}]}}
{"rx_ns": 42901581156900, "frame": {"channel":"book","type":"update","data":[{"symbol":"BTC/USD","bids":[{"price":62779.2,"qty":0.79644162}],"asks":[],"checksum":4141138199,"timestamp":"2026-08-16T23:37:16.194866Z"}]}}
{"rx_ns": 42901669035800, "frame": {"channel":"heartbeat"}}
{"rx_ns": 42901707669100, "frame": {"channel":"book","type":"update","data":[{"symbol":"BTC/USD","bids":[{"price":62776.4,"qty":0.01598519}],"asks":[],"checksum":4141138199,"timestamp":"2026-08-16T23:37:16.335011Z"}]}}
{"rx_ns": 42901723536600, "frame": {"channel":"book","type":"update","data":[{"symbol":"BTC/USD","bids":[{"price":62776.5,"qty":0.15927785}],"asks":[],"checksum":4141138199,"timestamp":"2026-08-16T23:37:16.346588Z"}]}}
{"rx_ns": 42901754532500, "frame": {"channel":"book","type":"update","data":[{"symbol":"BTC/USD","bids":[{"price":62779.2,"qty":0.00000000},{"price":62698.8,"qty":0.05517271}],"asks":[],"checksum":4141138199,"timestamp":"2026-08-16T23:37:16.382165Z"}]}}
{"rx_ns": 42901757568600, "frame": {"channel":"book","type":"update","data":[{"symbol":"BTC/USD","bids":[{"price":62776.9,"qty":0.00000000},{"price":62696.3,"qty":0.00410372}],"asks":[],"checksum":4141138199,"timestamp":"2026-08-16T23:37:16.382432Z"}]}}
{"rx_ns": 42901757682700, "frame": {"channel":"book","type":"update","data":[{"symbol":"BTC/USD","bids":[{"price":62780.2,"qty":0.79642883}],"asks":[],"checksum":4141138199,"timestamp":"2026-08-16T23:37:16.383897Z"}]}}
{"rx_ns": 42902029975300, "frame": {"channel":"book","type":"update","data":[{"symbol":"BTC/USD","bids":[{"price":62785.9,"qty":0.00000000},{"price":62696.3,"qty":0.00410372},{"price":62784.5,"qty":0.00009500}],"asks":[],"checksum":1439235734,"timestamp":"2026-08-16T23:37:16.643557Z"}]}}
{"rx_ns": 42902052120300, "frame": {"channel":"book","type":"update","data":[{"symbol":"BTC/USD","bids":[{"price":62773.2,"qty":0.65558762}],"asks":[],"checksum":1439235734,"timestamp":"2026-08-16T23:37:16.679654Z"}]}}
{"rx_ns": 42902052627500, "frame": {"channel":"book","type":"update","data":[{"symbol":"BTC/USD","bids":[{"price":62752.8,"qty":1.96676284}],"asks":[],"checksum":1439235734,"timestamp":"2026-08-16T23:37:16.679941Z"}]}}
{"rx_ns": 42902052670700, "frame": {"channel":"book","type":"update","data":[{"symbol":"BTC/USD","bids":[{"price":62766.0,"qty":0.65558762}],"asks":[],"checksum":1439235734,"timestamp":"2026-08-16T23:37:16.679955Z"}]}}
{"rx_ns": 42902071218700, "frame": {"channel":"book","type":"update","data":[{"symbol":"BTC/USD","bids":[{"price":62776.5,"qty":0.00000000},{"price":62699.9,"qty":1.50000000}],"asks":[],"checksum":1439235734,"timestamp":"2026-08-16T23:37:16.693969Z"}]}}
{"rx_ns": 42902071311000, "frame": {"channel":"book","type":"update","data":[{"symbol":"BTC/USD","bids":[],"asks":[{"price":62800.8,"qty":0.00000000},{"price":62882.0,"qty":0.47640779}],"checksum":619817487,"timestamp":"2026-08-16T23:37:16.695067Z"}]}}
{"rx_ns": 42902071338500, "frame": {"channel":"book","type":"update","data":[{"symbol":"BTC/USD","bids":[{"price":62776.6,"qty":0.15927785}],"asks":[],"checksum":619817487,"timestamp":"2026-08-16T23:37:16.696004Z"}]}}
{"rx_ns": 42902071351100, "frame": {"channel":"book","type":"update","data":[{"symbol":"BTC/USD","bids":[],"asks":[{"price":62796.7,"qty":0.50925300}],"checksum":3087092893,"timestamp":"2026-08-16T23:37:16.696084Z"}]}}
{"rx_ns": 42902071361400, "frame": {"channel":"book","type":"update","data":[{"symbol":"BTC/USD","bids":[{"price":62757.1,"qty":0.00000000},{"price":62699.9,"qty":1.50000000},{"price":62756.9,"qty":0.00318620}],"asks":[],"checksum":3087092893,"timestamp":"2026-08-16T23:37:16.696139Z"}]}}
{"rx_ns": 42902071385700, "frame": {"channel":"book","type":"update","data":[{"symbol":"BTC/USD","bids":[],"asks":[{"price":62833.0,"qty":0.00000000},{"price":62882.0,"qty":0.47640779},{"price":62832.9,"qty":0.00318620}],"checksum":3087092893,"timestamp":"2026-08-16T23:37:16.696395Z"}]}}
{"rx_ns": 42902071409900, "frame": {"channel":"book","type":"update","data":[{"symbol":"BTC/USD","bids":[],"asks":[{"price":62800.5,"qty":0.00005100},{"price":62799.0,"qty":0.18489680}],"checksum":4103853375,"timestamp":"2026-08-16T23:37:16.697294Z"}]}}
{"rx_ns": 42902191240500, "frame": {"channel":"book","type":"update","data":[{"symbol":"BTC/USD","bids":[{"price":62760.3,"qty":0.03458441}],"asks":[],"checksum":4103853375,"timestamp":"2026-08-16T23:37:16.818381Z"}]}}
{"rx_ns": 42902321755700, "frame": {"channel":"book","type":"update","data":[{"symbol":"BTC/USD","bids":[{"price":62776.6,"qty":0.00000000},{"price":62703.0,"qty":0.01531807}],"asks":[],"checksum":4103853375,"timestamp":"2026-08-16T23:37:16.944495Z"}]}}
{"rx_ns": 42902321829100, "frame": {"channel":"book","type":"update","data":[{"symbol":"BTC/USD","bids":[{"price":62776.7,"qty":0.15927785}],"asks":[],"checksum":4103853375,"timestamp":"2026-08-16T23:37:16.946161Z"}]}}
{"rx_ns": 42902380605500, "frame": {"channel":"book","type":"update","data":[{"symbol":"BTC/USD","bids":[],"asks":[{"price":62810.7,"qty":0.00000000},{"price":62881.2,"qty":0.16061732},{"price":62805.1,"qty":0.00222509}],"checksum":4103853375,"timestamp":"2026-08-16T23:37:17.006791Z"}]}}
{"rx_ns": 42902546525400, "frame": {"channel":"book","type":"update","data":[{"symbol":"BTC/USD","bids":[{"price":62778.0,"qty":0.79645716}],"asks":[],"checksum":4103853375,"timestamp":"2026-08-16T23:37:17.174991Z"}]}}
{"rx_ns": 42902596261100, "frame": {"channel":"book","type":"update","data":[{"symbol":"BTC/USD","bids":[],"asks":[{"price":62796.1,"qty":0.40200000}],"checksum":251141378,"timestamp":"2026-08-16T23:37:17.224347Z"}]}}
{"rx_ns": 42902596686100, "frame": {"channel":"book","type":"update","data":[{"symbol":"BTC/USD","bids":[],"asks":[{"price":62799.0,"qty":0.00000000},{"price":62881.0,"qty":0.00829460},{"price":62795.9,"qty":0.18489680}],"checksum":3282933231,"timestamp":"2026-08-16T23:37:17.225632Z"}]}}
{"rx_ns": 42902664320000, "frame": {"channel":"heartbeat"}}
{"rx_ns": 42902737914600, "frame": {"channel":"book","type":"update","data":[{"symbol":"BTC/USD","bids":[{"price":62776.7,"qty":0.00000000},{"price":62703.0,"qty":0.01531807}],"asks":[],"checksum":3282933231,"timestamp":"2026-08-16T23:37:17.363642Z"}]}}
{"rx_ns": 42902742754300, "frame": {"channel":"book","type":"update","data":[{"symbol":"BTC/USD","bids":[{"price":62705.0,"qty":0.06960000}],"asks":[],"checksum":3282933231,"timestamp":"2026-08-16T23:37:17.369984Z"}]}}
{"rx_ns": 42902770660800, "frame": {"channel":"book","type":"update","data":[{"symbol":"BTC/USD","bids":[{"price":62776.8,"qty":0.26258946}],"asks":[],"checksum":3282933231,"timestamp":"2026-08-16T23:37:17.396279Z"}]}}
{"rx_ns": 42902770748400, "frame": {"channel":"book","type":"update","data":[{"symbol":"BTC/USD","bids":[{"price":62755.6,"qty":0.00000000},{"price":62703.0,"qty":0.01531807},{"price":62757.0,"qty":0.00303506}],"asks":[],"checksum":3282933231,"timestamp":"2026-08-16T23:37:17.397167Z"}]}}
{"rx_ns": 42902778850600, "frame": {"channel":"book","type":"update","data":[{"symbol":"BTC/USD","bids":[{"price":62776.8,"qty":0.10331161}],"asks":[],"checksum":3282933231,"timestamp":"2026-08-16T23:37:17.406066Z"}]}}
{"rx_ns": 42902818129100, "frame": {"channel":"book","type":"update","data":[{"symbol":"BTC/USD","bids":[{"price":62776.0,"qty":0.15927785}],"asks":[],"checksum":3282933231,"timestamp":"2026-08-16T23:37:17.446170Z"}]}}
{"rx_ns": 42903115291800, "frame": {"channel":"book","type":"update","data":[{"symbol":"BTC/USD","bids":[{"price":62726.0,"qty":0.00000000},{"price":62703.0,"qty":0.01531807}],"asks":[],"checksum":3282933231,"timestamp":"2026-08-16T23:37:17.743778Z"}]}}
{"rx_ns": 42903115344400, "frame": {"channel":"book","type":"update","data":[{"symbol":"BTC/USD","bids":[{"price":62729.3,"qty":0.00000000},{"price":62699.9,"qty":1.50000000}],"asks":[],"checksum":3282933231,"timestamp":"2026-08-16T23:37:17.743798Z"}]}}
{"rx_ns": 42903115354900, "frame": {"channel":"book","type":"update","data":[{"symbol":"BTC/USD","bids":[{"price":62726.1,"qty":0.00000000},{"price":62699.7,"qty":5.58216167}],"asks":[],"checksum":3282933231,"timestamp":"2026-08-16T23:37:17.743824Z"}]}}
{"rx_ns": 42903121752300, "frame": {"channel":"book","type":"update","data":[{"symbol":"BTC/USD","bids":[{"price":62705.0,"qty":0.06960000}],"asks":[],"checksum":3282933231,"timestamp":"2026-08-16T23:37:17.746689Z"}]}}
{"rx_ns": 42903127021000, "frame": {"channel":"book","type":"update","data":[{"symbol":"BTC/USD","bids":[{"price":62726.2,"qty":7.09028259}],"asks":[],"checksum":3282933231,"timestamp":"2026-08-16T23:37:17.755116Z"}]}}
{"rx_ns": 42903128135700, "frame": {"channel":"book","type":"update","data":[{"symbol":"BTC/USD","bids":[{"price":62785.2,"qty":0.00318497}],"asks":[],"checksum":95103724,"timestamp":"2026-08-16T23:37:17.756276Z"}]}}
{"rx_ns": 42903128154700, "frame": {"channel":"book","type":"update","data":[{"symbol":"BTC/USD","bids":[],"asks":[{"price":62804.6,"qty":0.00318497}],"checksum":95103724,"timestamp":"2026-08-16T23:37:17.756519Z"}]}}
{"rx_ns": 42903141701200, "frame": {"channel":"book","type":"update","data":[{"symbol":"BTC/USD","bids":[{"price":62776.0,"qty":0.00000000},{"price":62699.9,"qty":1.50000000}],"asks":[],"checksum":95103724,"timestamp":"2026-08-16T23:37:17.770103Z"}]}}
{"rx_ns": 42903168881200, "frame": {"channel":"book","type":"update","data":[{"symbol":"BTC/USD","bids":[{"price":62776.7,"qty":0.15927785}],"asks":[],"checksum":95103724,"timestamp":"2026-08-16T23:37:17.796245Z"}]}}
{"rx_ns": 42903227292500, "frame": {"channel":"book","type":"update","data":[{"symbol":"BTC/USD","bids":[{"price":62762.8,"qty":0.01300000}],"asks":[],"checksum":95103724,"timestamp":"2026-08-16T23:37:17.855483Z"}]}}
{"rx_ns": 42903316638800, "frame": {"channel":"book","type":"update","data":[{"symbol":"BTC/USD","bids":[{"price":62776.7,"qty":0.00000000},{"price":62703.0,"qty":0.01531807}],"asks":[],"checksum":95103724,"timestamp":"2026-08-16T23:37:17.944337Z"}]}}
{"rx_ns": 42903317117600, "frame": {"channel":"book","type":"update","data":[{"symbol":"BTC/USD","bids":[{"price":62776.8,"qty":0.26258946}],"asks":[],"checksum":95103724,"timestamp":"2026-08-16T23:37:17.946079Z"}]}}
{"rx_ns": 42903486741700, "frame": {"channel":"book","type":"update","data":[{"symbol":"BTC/USD","bids":[],"asks":[{"price":62858.0,"qty":0.00829947}],"checksum":95103724,"timestamp":"2026-08-16T23:37:18.115083Z"}]}}
{"rx_ns": 42903526355800, "frame": {"channel":"book","type":"update","data":[{"symbol":"BTC/USD","bids":[],"asks":[{"price":62835.9,"qty":0.00000000},{"price":62879.7,"qty":0.00200000}],"checksum":95103724,"timestamp":"2026-08-16T23:37:18.153054Z"}]}}
{"rx_ns": 42903526863700, "frame": {"channel":"book","type":"update","data":[{"symbol":"BTC/USD","bids":[],"asks":[{"price":62835.8,"qty":2.93210861}],"checksum":95103724,"timestamp":"2026-08-16T23:37:18.155386Z"}]}}
{"rx_ns": 42903665023500, "frame": {"channel":"heartbeat"}}
{"rx_ns": 42903845790200, "frame": {"channel":"book","type":"update","data":[{"symbol":"BTC/USD","bids":[],"asks":[{"price":62862.6,"qty":0.05406507}],"checksum":95103724,"timestamp":"2026-08-16T23:37:18.473682Z"}]}}
{"rx_ns": 42903847552600, "frame": {"channel":"book","type":"update","data":[{"symbol":"BTC/USD","bids":[{"price":62730.0,"qty":0.05466476}],"asks":[],"checksum":95103724,"timestamp":"2026-08-16T23:37:18.474626Z"}]}}
{"rx_ns": 42903859059000, "frame": {"channel":"book","type":"update","data":[{"symbol":"BTC/USD","bids":[{"price":62756.9,"qty":0.00318497}],"asks":[],"checksum":95103724,"timestamp":"2026-08-16T23:37:18.487068Z"}]}}
{"rx_ns": 42903859157700, "frame": {"channel":"book","type":"update","data":[{"symbol":"BTC/USD","bids":[],"asks":[{"price":62832.9,"qty":0.00318497}],"checksum":95103724,"timestamp":"2026-08-16T23:37:18.487317Z"}]}}
{"rx_ns": 42903868817000, "frame": {"channel":"book","type":"update","data":[{"symbol":"BTC/USD","bids":[{"price":62761.2,"qty":0.00000000},{"price":62703.0,"qty":0.01531807}],"asks":[],"checksum":95103724,"timestamp":"2026-08-16T23:37:18.496619Z"}]}}
{"rx_ns": 42903978050100, "frame": {"channel":"book","type":"update","data":[{"symbol":"BTC/USD","bids":[{"price":62776.8,"qty":0.10331161}],"asks":[],"checksum":95103724,"timestamp":"2026-08-16T23:37:18.605750Z"}]}}
{"rx_ns": 42904018282200, "frame": {"channel":"book","type":"update","data":[{"symbol":"BTC/USD","bids":[{"price":62776.9,"qty":0.15927785}],"asks":[],"checksum":95103724,"timestamp":"2026-08-16T23:37:18.646348Z"}]}}
{"rx_ns": 42904024564400, "frame": {"channel":"book","type":"update","data":[{"symbol":"BTC/USD","bids":[{"price":62776.9,"qty":0.00000000},{"price":62703.0,"qty":0.01531807}],"asks":[],"checksum":95103724,"timestamp":"2026-08-16T23:37:18.652250Z"}]}}
{"rx_ns": 42904069422100, "frame": {"channel":"book","type":"update","data":[{"symbol":"BTC/USD","bids":[{"price":62777.5,"qty":0.15927785}],"asks":[],"checksum":95103724,"timestamp":"2026-08-16T23:37:18.696301Z"}]}}
{"rx_ns": 42904070499500, "frame": {"channel":"book","type":"update","data":[{"symbol":"BTC/USD","bids":[{"price":62784.5,"qty":0.00000000},{"price":62703.0,"qty":0.01531807},{"price":62784.6,"qty":0.00009500}],"asks":[],"checksum":2695053696,"timestamp":"2026-08-16T23:37:18.696875Z"}]}}
{"rx_ns": 42904104224600, "frame": {"channel":"book","type":"update","data":[{"symbol":"BTC/USD","bids":[{"price":62751.5,"qty":0.00830604}],"asks":[],"checksum":2695053696,"timestamp":"2026-08-16T23:37:18.732357Z"}]}}
{"rx_ns": 42904228614400, "frame": {"channel":"book","type":"update","data":[{"symbol":"BTC/USD","bids":[{"price":62730.0,"qty":0.00000000},{"price":62703.0,"qty":0.01531807}],"asks":[],"checksum":2695053696,"timestamp":"2026-08-16T23:37:18.856044Z"}]}}
{"rx_ns": 42904236559100, "frame": {"channel":"book","type":"update","data":[{"symbol":"BTC/USD","bids":[{"price":62705.0,"qty":0.06960000}],"asks":[],"checksum":2695053696,"timestamp":"2026-08-16T23:37:18.861876Z"}]}}
{"rx_ns": 42904264403300, "frame": {"channel":"book","type":"update","data":[{"symbol":"BTC/USD","bids":[{"price":62760.3,"qty":0.00000000},{"price":62703.0,"qty":0.01531807}],"asks":[],"checksum":2695053696,"timestamp":"2026-08-16T23:37:18.892295Z"}]}}
{"rx_ns": 42904316441200, "frame": {"channel":"book","type":"update","data":[{"symbol":"BTC/USD","bids":[{"price":62777.5,"qty":0.00000000},{"price":62699.9,"qty":1.50000000}],"asks":[],"checksum":2695053696,"timestamp":"2026-08-16T23:37:18.944545Z"}]}}
{"rx_ns": 42904317969200, "frame": {"channel":"book","type":"update","data":[{"symbol":"BTC/USD","bids":[{"price":62777.6,"qty":0.15927785}],"asks":[],"checksum":2695053696,"timestamp":"2026-08-16T23:37:18.946033Z"}]}}
{"rx_ns": 42904370256100, "frame": {"channel":"book","type":"update","data":[{"symbol":"BTC/USD","bids":[{"price":62780.2,"qty":0.00000000},{"price":62699.9,"qty":1.50000000}],"asks":[],"checksum":2695053696,"timestamp":"2026-08-16T23:37:18.995943Z"}]}}
{"rx_ns": 42904383860700, "frame": {"channel":"book","type":"update","data":[{"symbol":"BTC/USD","bids":[{"price":62777.6,"qty":0.00000000},{"price":62699.7,"qty":5.58216167}],"asks":[],"checksum":2695053696,"timestamp":"2026-08-16T23:37:18.997391Z"}]}}
{"rx_ns": 42904383919500, "frame": {"channel":"book","type":"update","data":[{"symbol":"BTC/USD","bids":[{"price":62780.8,"qty":0.79642089}],"asks":[],"checksum":3988989950,"timestamp":"2026-08-16T23:37:18.997686Z"}]}}
{"rx_ns": 42904383933500, "frame": {"channel":"book","type":"update","data":[{"symbol":"BTC/USD","bids":[{"price":62728.0,"qty":7.97091264}],"asks":[],"checksum":3988989950,"timestamp":"2026-08-16T23:37:18.998076Z"}]}}
{"rx_ns": 42904383943900, "frame": {"channel":"book","type":"update","data":[{"symbol":"BTC/USD","bids":[{"price":62719.8,"qty":0.00000000},{"price":62699.9,"qty":1.50000000},{"price":62718.0,"qty":0.35596944}],"asks":[],"checksum":3988989950,"timestamp":"2026-08-16T23:37:18.998167Z"}]}}
{"rx_ns": 42904383957000, "frame": {"channel":"book","type":"update","data":[{"symbol":"BTC/USD","bids":[{"price":62722.8,"qty":0.00000000},{"price":62699.7,"qty":5.58216167},{"price":62721.0,"qty":0.70609000}],"asks":[],"checksum":3988989950,"timestamp":"2026-08-16T23:37:18.998332Z"}]}}
{"rx_ns": 42904383992300, "frame": {"channel":"book","type":"update","data":[{"symbol":"BTC/USD","bids":[{"price":62778.0,"qty":0.00000000},{"price":62699.7,"qty":5.58216167}],"asks":[],"checksum":3988989950,"timestamp":"2026-08-16T23:37:18.999861Z"}]}}
{"rx_ns": 42904384005800, "frame": {"channel":"book","type":"update","data":[{"symbol":"BTC/USD","bids":[{"price":62780.4,"qty":0.00000000},{"price":62698.8,"qty":0.05517271},{"price":62788.1,"qty":0.05598472}],"asks":[],"checksum":3101889628,"timestamp":"2026-08-16T23:37:19.000345Z"}]}}
{"rx_ns": 42904384024500, "frame": {"channel":"book","type":"update","data":[{"symbol":"BTC/USD","bids":[{"price":62780.8,"qty":0.00000000},{"price":62698.8,"qty":0.05517271}],"asks":[],"checksum":3101889628,"timestamp":"2026-08-16T23:37:19.001500Z"}]}}
{"rx_ns": 42904384035400, "frame": {"channel":"book","type":"update","data":[{"symbol":"BTC/USD","bids":[{"price":62772.7,"qty":0.00796524}],"asks":[],"checksum":3101889628,"timestamp":"2026-08-16T23:37:19.001764Z"}]}}
{"rx_ns": 42904384057000, "frame": {"channel":"book","type":"update","data":[{"symbol":"BTC/USD","bids":[{"price":62779.1,"qty":0.79644281}],"asks":[],"checksum":3101889628,"timestamp":"2026-08-16T23:37:19.003216Z"}]}}
{"rx_ns": 42904384067400, "frame": {"channel":"book","type":"update","data":[{"symbol":"BTC/USD","bids":[{"price":62775.1,"qty":0.79649335}],"asks":[],"checksum":3101889628,"timestamp":"2026-08-16T23:37:19.003617Z"}]}}
{"rx_ns": 42904388736500, "frame": {"channel":"book","type":"update","data":[{"symbol":"BTC/USD","bids":[{"price":62779.0,"qty":0.15927785}],"asks":[],"checksum":3101889628,"timestamp":"2026-08-16T23:37:19.016947Z"}]}}
{"rx_ns": 42904491348100, "frame": {"channel":"book","type":"update","data":[{"symbol":"BTC/USD","bids":[{"price":62775.9,"qty":0.00966536}],"asks":[],"checksum":3101889628,"timestamp":"2026-08-16T23:37:19.118998Z"}]}}
{"rx_ns": 42904546836900, "frame": {"channel":"book","type":"update","data":[{"symbol":"BTC/USD","bids":[{"price":62781.5,"qty":0.79641282}],"asks":[],"checksum":3101889628,"timestamp":"2026-08-16T23:37:19.173891Z"}]}}
{"rx_ns": 42904550528400, "frame": {"channel":"book","type":"update","data":[{"symbol":"BTC/USD","bids":[{"price":62775.9,"qty":0.00000000},{"price":62705.0,"qty":0.06960000}],"asks":[],"checksum":3101889628,"timestamp":"2026-08-16T23:37:19.177097Z"}]}}
{"rx_ns": 42904672999400, "frame": {"channel":"heartbeat"}}
{"rx_ns": 42904727443100, "frame": {"channel":"book","type":"update","data":[{"symbol":"BTC/USD","bids":[{"price":62729.9,"qty":0.05598378}],"asks":[],"checksum":3101889628,"timestamp":"2026-08-16T23:37:19.355953Z"}]}}
{"rx_ns": 42904735524400, "frame": {"channel":"book","type":"update","data":[{"symbol":"BTC/USD","bids":[{"price":62773.2,"qty":0.00000000},{"price":62703.0,"qty":0.01531807}],"asks":[],"checksum":3101889628,"timestamp":"2026-08-16T23:37:19.363789Z"}]}}
{"rx_ns": 42904739921500, "frame": {"channel":"book","type":"update","data":[{"symbol":"BTC/USD","bids":[{"price":62779.0,"qty":0.00000000},{"price":62699.9,"qty":1.50000000}],"asks":[],"checksum":3101889628,"timestamp":"2026-08-16T23:37:19.363878Z"}]}}
{"rx_ns": 42904739994200, "frame": {"channel":"book","type":"update","data":[{"symbol":"BTC/USD","bids":[{"price":62705.0,"qty":0.06960000}],"asks":[],"checksum":3101889628,"timestamp":"2026-08-16T23:37:19.365065Z"}]}}
{"rx_ns": 42904768070100, "frame": {"channel":"book","type":"update","data":[{"symbol":"BTC/USD","bids":[{"price":62779.7,"qty":0.15927785}],"asks":[],"checksum":3101889628,"timestamp":"2026-08-16T23:37:19.396214Z"}]}}
{"rx_ns": 42904842665000, "frame": {"channel":"book","type":"update","data":[{"symbol":"BTC/USD","bids":[{"price":62779.7,"qty":0.00000000},{"price":62703.0,"qty":0.01531807}],"asks":[],"checksum":3101889628,"timestamp":"2026-08-16T23:37:19.470344Z"}]}}
{"rx_ns": 42904870024500, "frame": {"channel":"book","type":"update","data":[{"symbol":"BTC/USD","bids":[{"price":62779.6,"qty":0.15927785}],"asks":[],"checksum":3101889628,"timestamp":"2026-08-16T23:37:19.496011Z"}]}}
{"rx_ns": 42904881771900, "frame": {"channel":"book","type":"update","data":[{"symbol":"BTC/USD","bids":[],"asks":[{"price":62798.0,"qty":0.00000000},{"price":62879.7,"qty":0.00200000}],"checksum":1265967782,"timestamp":"2026-08-16T23:37:19.510016Z"}]}}
{"rx_ns": 42904883427200, "frame": {"channel":"book","type":"update","data":[{"symbol":"BTC/USD","bids":[{"price":62781.5,"qty":0.00000000},{"price":62703.0,"qty":0.01531807}],"asks":[],"checksum":1265967782,"timestamp":"2026-08-16T23:37:19.510131Z"}]}}
{"rx_ns": 42904883505200, "frame": {"channel":"book","type":"update","data":[{"symbol":"BTC/USD","bids":[{"price":62779.6,"qty":0.00000000},{"price":62699.9,"qty":1.50000000}],"asks":[],"checksum":1265967782,"timestamp":"2026-08-16T23:37:19.510426Z"}]}}
{"rx_ns": 42904889097000, "frame": {"channel":"book","type":"update","data":[{"symbol":"BTC/USD","bids":[{"price":62779.1,"qty":0.00000000},{"price":62699.7,"qty":5.58216167}],"asks":[],"checksum":1265967782,"timestamp":"2026-08-16T23:37:19.510978Z"}]}}
{"rx_ns": 42904889141500, "frame": {"channel":"book","type":"update","data":[{"symbol":"BTC/USD","bids":[{"price":62788.1,"qty":0.00000000},{"price":62698.8,"qty":0.05517271},{"price":62791.3,"qty":0.05598472}],"asks":[],"checksum":1870932767,"timestamp":"2026-08-16T23:37:19.511362Z"}]}}
{"rx_ns": 42904889155400, "frame": {"channel":"book","type":"update","data":[{"symbol":"BTC/USD","bids":[],"asks":[{"price":62805.2,"qty":0.00000000},{"price":62880.9,"qty":0.00297725},{"price":62810.8,"qty":1.59575715}],"checksum":1870932767,"timestamp":"2026-08-16T23:37:19.512530Z"}]}}
{"rx_ns": 42904889166500, "frame": {"channel":"book","type":"update","data":[{"symbol":"BTC/USD","bids":[],"asks":[{"price":62879.4,"qty":0.06960000}],"checksum":1870932767,"timestamp":"2026-08-16T23:37:19.512901Z"}]}}
{"rx_ns": 42904889195100, "frame": {"channel":"book","type":"update","data":[{"symbol":"BTC/USD","bids":[{"price":62783.0,"qty":0.79639330}],"asks":[],"checksum":1870932767,"timestamp":"2026-08-16T23:37:19.513371Z"}]}}
{"rx_ns": 42904889205700, "frame": {"channel":"book","type":"update","data":[{"symbol":"BTC/USD","bids":[{"price":62780.8,"qty":0.79642153}],"asks":[],"checksum":1870932767,"timestamp":"2026-08-16T23:37:19.513620Z"}]}}
{"rx_ns": 42904889214300, "frame": {"channel":"book","type":"update","data":[{"symbol":"BTC/USD","bids":[],"asks":[{"price":62795.9,"qty":0.00000000},{"price":62879.7,"qty":0.00200000},{"price":62810.3,"qty":0.18808099}],"checksum":1630239249,"timestamp":"2026-08-16T23:37:19.514959Z"}]}}
{"rx_ns": 42904893054100, "frame": {"channel":"book","type":"update","data":[{"symbol":"BTC/USD","bids":[{"price":62782.1,"qty":0.06960000}],"asks":[],"checksum":1630239249,"timestamp":"2026-08-16T23:37:19.516187Z"}]}}
{"rx_ns": 42904896168900, "frame": {"channel":"book","type":"update","data":[{"symbol":"BTC/USD","bids":[{"price":62777.5,"qty":0.00953744}],"asks":[],"checksum":1630239249,"timestamp":"2026-08-16T23:37:19.519395Z"}]}}
{"rx_ns": 42904896214000, "frame": {"channel":"book","type":"update","data":[{"symbol":"BTC/USD","bids":[{"price":62777.5,"qty":0.00000000},{"price":62705.0,"qty":0.06960000}],"asks":[],"checksum":1630239249,"timestamp":"2026-08-16T23:37:19.519855Z"}]}}
{"rx_ns": 42904899011300, "frame": {"channel":"book","type":"update","data":[{"symbol":"BTC/USD","bids":[{"price":62792.6,"qty":0.00000000},{"price":62703.0,"qty":0.01531807}],"asks":[],"checksum":2712969851,"timestamp":"2026-08-16T23:37:19.523057Z"}]}}
{"rx_ns": 42904899051500, "frame": {"channel":"book","type":"update","data":[{"symbol":"BTC/USD","bids":[{"price":62793.5,"qty":0.02131292}],"asks":[],"checksum":3095074458,"timestamp":"2026-08-16T23:37:19.523640Z"}]}}
{"rx_ns": 42904918074600, "frame": {"channel":"book","type":"update","data":[{"symbol":"BTC/USD","bids":[{"price":62780.9,"qty":0.15927785}],"asks":[],"checksum":3095074458,"timestamp":"2026-08-16T23:37:19.546261Z"}]}}
{"rx_ns": 42904924715500, "frame": {"channel":"book","type":"update","data":[{"symbol":"BTC/USD","bids":[{"price":62763.1,"qty":0.00000000},{"price":62705.0,"qty":0.06960000},{"price":62766.1,"qty":0.10293774}],"asks":[],"checksum":3095074458,"timestamp":"2026-08-16T23:37:19.550147Z"}]}}
{"rx_ns": 42904928443500, "frame": {"channel":"book","type":"update","data":[{"symbol":"BTC/USD","bids":[{"price":62778.0,"qty":0.00318583}],"asks":[],"checksum":3095074458,"timestamp":"2026-08-16T23:37:19.556862Z"}]}}
{"rx_ns": 42904938867600, "frame": {"channel":"book","type":"update","data":[{"symbol":"BTC/USD","bids":[],"asks":[{"price":62805.1,"qty":0.00000000},{"price":62880.9,"qty":0.00297725},{"price":62810.7,"qty":0.00222509}],"checksum":3095074458,"timestamp":"2026-08-16T23:37:19.562652Z"}]}}
{"rx_ns": 42904953821900, "frame": {"channel":"book","type":"update","data":[{"symbol":"BTC/USD","bids":[{"price":62785.2,"qty":0.00000000},{"price":62706.5,"qty":0.00162380},{"price":62785.1,"qty":0.00318497}],"asks":[],"checksum":4120057597,"timestamp":"2026-08-16T23:37:19.581084Z"}]}}
{"rx_ns": 42904953892700, "frame": {"channel":"book","type":"update","data":[{"symbol":"BTC/USD","bids":[],"asks":[{"price":62804.6,"qty":0.00000000},{"price":62880.9,"qty":0.00297725},{"price":62804.5,"qty":0.00318497}],"checksum":4120057597,"timestamp":"2026-08-16T23:37:19.581392Z"}]}}
{"rx_ns": 42904991598400, "frame": {"channel":"book","type":"update","data":[{"symbol":"BTC/USD","bids":[{"price":62783.0,"qty":0.00000000},{"price":62706.5,"qty":0.00162380}],"asks":[],"checksum":4120057597,"timestamp":"2026-08-16T23:37:19.619079Z"}]}}
{"rx_ns": 42904992952700, "frame": {"channel":"book","type":"update","data":[{"symbol":"BTC/USD","bids":[{"price":62782.1,"qty":0.86600506}],"asks":[],"checksum":4120057597,"timestamp":"2026-08-16T23:37:19.620601Z"}]}}
{"rx_ns": 42904993646600, "frame": {"channel":"book","type":"update","data":[{"symbol":"BTC/USD","bids":[{"price":62778.4,"qty":0.00951371}],"asks":[],"checksum":4120057597,"timestamp":"2026-08-16T23:37:19.622725Z"}]}}
{"rx_ns": 42904995171100, "frame": {"channel":"book","type":"update","data":[{"symbol":"BTC/USD","bids":[{"price":62778.4,"qty":0.00000000},{"price":62706.5,"qty":0.00162380}],"asks":[],"checksum":4120057597,"timestamp":"2026-08-16T23:37:19.623442Z"}]}}
{"rx_ns": 42905029229900, "frame": {"channel":"book","type":"update","data":[{"symbol":"BTC/USD","bids":[],"asks":[{"price":62800.6,"qty":0.00000000},{"price":62880.9,"qty":0.00297725},{"price":62805.1,"qty":0.19620257}],"checksum":4094946014,"timestamp":"2026-08-16T23:37:19.657336Z"}]}}
{"rx_ns": 42905067509900, "frame": {"channel":"book","type":"update","data":[{"symbol":"BTC/USD","bids":[{"price":62780.9,"qty":0.00000000},{"price":62703.0,"qty":0.01531807}],"asks":[],"checksum":4094946014,"timestamp":"2026-08-16T23:37:19.686509Z"}]}}
{"rx_ns": 42905067578800, "frame": {"channel":"book","type":"update","data":[{"symbol":"BTC/USD","bids":[{"price":62705.0,"qty":0.06960000}],"asks":[],"checksum":4094946014,"timestamp":"2026-08-16T23:37:19.690526Z"}]}}
{"rx_ns": 42905068400100, "frame": {"channel":"book","type":"update","data":[{"symbol":"BTC/USD","bids":[{"price":62780.8,"qty":0.95569938}],"asks":[],"checksum":4094946014,"timestamp":"2026-08-16T23:37:19.696666Z"}]}}
{"rx_ns": 42905082446700, "frame": {"channel":"book","type":"update","data":[{"symbol":"BTC/USD","bids":[{"price":62777.4,"qty":0.65558762}],"asks":[],"checksum":4094946014,"timestamp":"2026-08-16T23:37:19.702535Z"}]}}
{"rx_ns": 42905082540600, "frame": {"channel":"book","type":"update","data":[{"symbol":"BTC/USD","bids":[{"price":62780.8,"qty":0.79642153}],"asks":[],"checksum":4094946014,"timestamp":"2026-08-16T23:37:19.710251Z"}]}}
{"rx_ns": 42905118426700, "frame": {"channel":"book","type":"update","data":[{"symbol":"BTC/USD","bids":[{"price":62780.9,"qty":0.15927785}],"asks":[],"checksum":4094946014,"timestamp":"2026-08-16T23:37:19.746313Z"}]}}
{"rx_ns": 42905316024100, "frame": {"channel":"book","type":"update","data":[{"symbol":"BTC/USD","bids":[{"price":62780.9,"qty":0.00000000},{"price":62706.5,"qty":0.00162380}],"asks":[],"checksum":4094946014,"timestamp":"2026-08-16T23:37:19.944377Z"}]}}
{"rx_ns": 42905318397600, "frame": {"channel":"book","type":"update","data":[{"symbol":"BTC/USD","bids":[{"price":62780.8,"qty":0.95569938}],"asks":[],"checksum":4094946014,"timestamp":"2026-08-16T23:37:19.946183Z"}]}}
{"rx_ns": 42905390214600, "frame": {"channel":"book","type":"update","data":[{"symbol":"BTC/USD","bids":[{"price":62780.8,"qty":0.79642153}],"asks":[],"checksum":4094946014,"timestamp":"2026-08-16T23:37:20.016688Z"}]}}
{"rx_ns": 42905390298600, "frame": {"channel":"book","type":"update","data":[{"symbol":"BTC/USD","bids":[{"price":62756.9,"qty":0.00000000},{"price":62703.0,"qty":0.01531807},{"price":62757.0,"qty":0.00622003}],"asks":[],"checksum":4094946014,"timestamp":"2026-08-16T23:37:20.018671Z"}]}}
{"rx_ns": 42905392699700, "frame": {"channel":"book","type":"update","data":[{"symbol":"BTC/USD","bids":[{"price":62705.0,"qty":0.06960000}],"asks":[],"checksum":4094946014,"timestamp":"2026-08-16T23:37:20.020961Z"}]}}
{"rx_ns": 42905418900000, "frame": {"channel":"book","type":"update","data":[{"symbol":"BTC/USD","bids":[{"price":62780.3,"qty":0.15951669}],"asks":[],"checksum":4094946014,"timestamp":"2026-08-16T23:37:20.046251Z"}]}}
{"rx_ns": 42905443004200, "frame": {"channel":"book","type":"update","data":[{"symbol":"BTC/USD","bids":[{"price":62726.2,"qty":0.00000000},{"price":62703.0,"qty":0.01531807}],"asks":[],"checksum":4094946014,"timestamp":"2026-08-16T23:37:20.070190Z"}]}}
{"rx_ns": 42905445930400, "frame": {"channel":"book","type":"update","data":[{"symbol":"BTC/USD","bids":[{"price":62728.1,"qty":6.07181596}],"asks":[],"checksum":4094946014,"timestamp":"2026-08-16T23:37:20.073851Z"}]}}
{"rx_ns": 42905586484400, "frame": {"channel":"book","type":"update","data":[{"symbol":"BTC/USD","bids":[{"price":62780.3,"qty":0.00023884}],"asks":[],"checksum":4094946014,"timestamp":"2026-08-16T23:37:20.214867Z"}]}}
{"rx_ns": 42905620275500, "frame": {"channel":"book","type":"update","data":[{"symbol":"BTC/USD","bids":[{"price":62780.2,"qty":0.15927785}],"asks":[],"checksum":4094946014,"timestamp":"2026-08-16T23:37:20.246387Z"}]}}
{"rx_ns": 42905644976300, "frame": {"channel":"book","type":"update","data":[{"symbol":"BTC/USD","bids":[{"price":62757.0,"qty":0.00318497},{"price":62757.1,"qty":0.00303489}],"asks":[],"checksum":4094946014,"timestamp":"2026-08-16T23:37:20.272180Z"}]}}
{"rx_ns": 42905665689200, "frame": {"channel":"heartbeat"}}
{"rx_ns": 42905677450000, "frame": {"channel":"book","type":"update","data":[{"symbol":"BTC/USD","bids":[],"asks":[{"price":62805.1,"qty":0.00000000},{"price":62880.9,"qty":0.00297725},{"price":62801.3,"qty":0.19620257}],"checksum":2268677733,"timestamp":"2026-08-16T23:37:20.303710Z"}]}}
{"rx_ns": 42905867195900, "frame": {"channel":"book","type":"update","data":[{"symbol":"BTC/USD","bids":[],"asks":[{"price":62835.8,"qty":0.00000000},{"price":62880.9,"qty":0.00297725}],"checksum":2268677733,"timestamp":"2026-08-16T23:37:20.495199Z"}]}}
{"rx_ns": 42905873049500, "frame": {"channel":"book","type":"update","data":[{"symbol":"BTC/USD","bids":[],"asks":[{"price":62835.7,"qty":3.19427315}],"checksum":2268677733,"timestamp":"2026-08-16T23:37:20.501214Z"}]}}
{"rx_ns": 42905968731800, "frame": {"channel":"book","type":"update","data":[{"symbol":"BTC/USD","bids":[{"price":62760.3,"qty":0.03506393}],"asks":[],"checksum":2268677733,"timestamp":"2026-08-16T23:37:20.595210Z"}]}}
{"rx_ns": 42906084226300, "frame": {"channel":"book","type":"update","data":[{"symbol":"BTC/USD","bids":[{"price":62772.2,"qty":0.03185537}],"asks":[],"checksum":2268677733,"timestamp":"2026-08-16T23:37:20.710298Z"}]}}
{"rx_ns": 42906122730100, "frame": {"channel":"book","type":"update","data":[{"symbol":"BTC/USD","bids":[{"price":62784.6,"qty":0.00000000},{"price":62709.2,"qty":0.43000000},{"price":62785.8,"qty":0.00009500}],"asks":[],"checksum":43290064,"timestamp":"2026-08-16T23:37:20.749720Z"}]}}
{"rx_ns": 42906316741100, "frame": {"channel":"book","type":"update","data":[{"symbol":"BTC/USD","bids":[{"price":62780.2,"qty":0.00000000},{"price":62709.2,"qty":0.43000000}],"asks":[],"checksum":43290064,"timestamp":"2026-08-16T23:37:20.944748Z"}]}}
{"rx_ns": 42906320926800, "frame": {"channel":"book","type":"update","data":[{"symbol":"BTC/USD","bids":[{"price":62780.1,"qty":0.15927785}],"asks":[],"checksum":43290064,"timestamp":"2026-08-16T23:37:20.946304Z"}]}}
{"rx_ns": 42906374262600, "frame": {"channel":"book","type":"update","data":[{"symbol":"BTC/USD","bids":[],"asks":[{"price":62878.7,"qty":0.02131292}],"checksum":43290064,"timestamp":"2026-08-16T23:37:21.002676Z"}]}}
{"rx_ns": 42906593923300, "frame": {"channel":"book","type":"update","data":[{"symbol":"BTC/USD","bids":[],"asks":[{"price":62878.7,"qty":0.00000000},{"price":62880.9,"qty":0.00297725}],"checksum":43290064,"timestamp":"2026-08-16T23:37:21.221979Z"}]}}
{"rx_ns": 42906666209900, "frame": {"channel":"heartbeat"}}
{"rx_ns": 42906815860600, "frame": {"channel":"book","type":"update","data":[{"symbol":"BTC/USD","bids":[],"asks":[{"price":62878.8,"qty":0.13254870}],"checksum":43290064,"timestamp":"2026-08-16T23:37:21.443678Z"}]}}
{"rx_ns": 42906858879800, "frame": {"channel":"book","type":"update","data":[{"symbol":"BTC/USD","bids":[],"asks":[{"price":62804.5,"qty":0.00000000},{"price":62881.2,"qty":0.16061732},{"price":62804.7,"qty":0.00318497}],"checksum":43290064,"timestamp":"2026-08-16T23:37:21.487323Z"}]}}
{"rx_ns": 42906860088900, "frame": {"channel":"book","type":"update","data":[{"symbol":"BTC/USD","bids":[{"price":62785.1,"qty":0.00000000},{"price":62709.2,"qty":0.43000000},{"price":62785.2,"qty":0.00318497}],"asks":[],"checksum":4885239,"timestamp":"2026-08-16T23:37:21.487557Z"}]}}
{"rx_ns": 42906953796900, "frame": {"channel":"book","type":"update","data":[{"symbol":"BTC/USD","bids":[],"asks":[{"price":62880.9,"qty":0.00000000},{"price":62881.2,"qty":0.16061732}],"checksum":4885239,"timestamp":"2026-08-16T23:37:21.579737Z"}]}}
{"rx_ns": 42907007517000, "frame": {"channel":"book","type":"update","data":[{"symbol":"BTC/USD","bids":[{"price":62771.6,"qty":0.07963844}],"asks":[],"checksum":4885239,"timestamp":"2026-08-16T23:37:21.635473Z"}]}}
{"rx_ns": 42907031709700, "frame": {"channel":"book","type":"update","data":[{"symbol":"BTC/USD","bids":[],"asks":[{"price":62878.8,"qty":0.11123578}],"checksum":4885239,"timestamp":"2026-08-16T23:37:21.659952Z"}]}}
{"rx_ns": 42907067723000, "frame": {"channel":"book","type":"update","data":[{"symbol":"BTC/USD","bids":[{"price":62780.1,"qty":0.00000000},{"price":62709.6,"qty":0.04678000}],"asks":[],"checksum":4885239,"timestamp":"2026-08-16T23:37:21.686388Z"}]}}
{"rx_ns": 42907067818000, "frame": {"channel":"book","type":"update","data":[{"symbol":"BTC/USD","bids":[{"price":62780.0,"qty":0.15927785}],"asks":[],"checksum":4885239,"timestamp":"2026-08-16T23:37:21.696148Z"}]}}
{"rx_ns": 42907229424100, "frame": {"channel":"book","type":"update","data":[{"symbol":"BTC/USD","bids":[],"asks":[{"price":62862.6,"qty":0.00000000},{"price":62883.3,"qty":0.49794402}],"checksum":4885239,"timestamp":"2026-08-16T23:37:21.855493Z"}]}}
{"rx_ns": 42907258826200, "frame": {"channel":"book","type":"update","data":[{"symbol":"BTC/USD","bids":[],"asks":[{"price":62879.2,"qty":0.02131292}],"checksum":4885239,"timestamp":"2026-08-16T23:37:21.887022Z"}]}}
{"rx_ns": 42907382979900, "frame": {"channel":"book","type":"update","data":[{"symbol":"BTC/USD","bids":[{"price":62766.1,"qty":0.00000000},{"price":62709.6,"qty":0.04678000},{"price":62766.4,"qty":0.10293724}],"asks":[],"checksum":4885239,"timestamp":"2026-08-16T23:37:22.007221Z"}]}}
{"rx_ns": 42907485787500, "frame": {"channel":"book","type":"update","data":[{"symbol":"BTC/USD","bids":[],"asks":[{"price":62879.2,"qty":0.00000000},{"price":62883.3,"qty":0.49794402}],"checksum":4885239,"timestamp":"2026-08-16T23:37:22.112885Z"}]}}
{"rx_ns": 42907583715400, "frame": {"channel":"book","type":"update","data":[{"symbol":"BTC/USD","bids":[],"asks":[{"price":62883.3,"qty":0.02184000}],"checksum":4885239,"timestamp":"2026-08-16T23:37:22.211721Z"}]}}
{"rx_ns": 42907666889000, "frame": {"channel":"heartbeat"}}
{"rx_ns": 42907705492100, "frame": {"channel":"book","type":"update","data":[{"symbol":"BTC/USD","bids":[],"asks":[{"price":62879.4,"qty":0.09091292}],"checksum":4885239,"timestamp":"2026-08-16T23:37:22.333936Z"}]}}
{"rx_ns": 42907728944600, "frame": {"channel":"book","type":"update","data":[{"symbol":"BTC/USD","bids":[],"asks":[{"price":62859.1,"qty":0.05498096}],"checksum":4885239,"timestamp":"2026-08-16T23:37:22.356901Z"}]}}
{"rx_ns": 42907769037500, "frame": {"channel":"book","type":"update","data":[{"symbol":"BTC/USD","bids":[{"price":62728.1,"qty":0.00000000},{"price":62709.6,"qty":0.04678000}],"asks":[],"checksum":4885239,"timestamp":"2026-08-16T23:37:22.395720Z"}]}}
{"rx_ns": 42907774176900, "frame": {"channel":"book","type":"update","data":[{"symbol":"BTC/USD","bids":[{"price":62728.2,"qty":5.98015357}],"asks":[],"checksum":4885239,"timestamp":"2026-08-16T23:37:22.399500Z"}]}}
{"rx_ns": 42907918960000, "frame": {"channel":"book","type":"update","data":[{"symbol":"BTC/USD","bids":[],"asks":[{"price":62879.4,"qty":0.06960000}],"checksum":4885239,"timestamp":"2026-08-16T23:37:22.547212Z"}]}}
{"rx_ns": 42908111013200, "frame": {"channel":"book","type":"update","data":[{"symbol":"BTC/USD","bids":[{"price":62780.0,"qty":0.00000000},{"price":62709.6,"qty":0.04678000}],"asks":[],"checksum":4885239,"timestamp":"2026-08-16T23:37:22.739029Z"}]}}
{"rx_ns": 42908119666100, "frame": {"channel":"book","type":"update","data":[{"symbol":"BTC/USD","bids":[{"price":62779.9,"qty":0.15927762}],"asks":[],"checksum":4885239,"timestamp":"2026-08-16T23:37:22.746103Z"}]}}
{"rx_ns": 42908137540200, "frame": {"channel":"book","type":"update","data":[{"symbol":"BTC/USD","bids":[{"price":62765.9,"qty":0.00000000},{"price":62709.6,"qty":0.04678000}],"asks":[],"checksum":4885239,"timestamp":"2026-08-16T23:37:22.765792Z"}]}}
{"rx_ns": 42908137628700, "frame": {"channel":"book","type":"update","data":[{"symbol":"BTC/USD","bids":[{"price":62777.8,"qty":0.11000000}],"asks":[],"checksum":4885239,"timestamp":"2026-08-16T23:37:22.765979Z"}]}}
{"rx_ns": 42908153435700, "frame": {"channel":"book","type":"update","data":[{"symbol":"BTC/USD","bids":[],"asks":[{"price":62878.9,"qty":0.02131292}],"checksum":4885239,"timestamp":"2026-08-16T23:37:22.781166Z"}]}}
{"rx_ns": 42908159893800, "frame": {"channel":"book","type":"update","data":[{"symbol":"BTC/USD","bids":[],"asks":[{"price":62835.7,"qty":0.01598519}],"checksum":4885239,"timestamp":"2026-08-16T23:37:22.787591Z"}]}}
{"rx_ns": 42908166040700, "frame": {"channel":"book","type":"update","data":[{"symbol":"BTC/USD","bids":[],"asks":[{"price":62835.6,"qty":3.15643772}],"checksum":4885239,"timestamp":"2026-08-16T23:37:22.790145Z"}]}}
{"rx_ns": 42908281836200, "frame": {"channel":"book","type":"update","data":[{"symbol":"BTC/USD","bids":[{"price":62771.6,"qty":0.00000000},{"price":62709.2,"qty":0.43000000},{"price":62772.2,"qty":0.07963741}],"asks":[],"checksum":4885239,"timestamp":"2026-08-16T23:37:22.909829Z"}]}}
{"rx_ns": 42908284816900, "frame": {"channel":"book","type":"update","data":[{"symbol":"BTC/USD","bids":[{"price":62773.8,"qty":0.03185496}],"asks":[],"checksum":4885239,"timestamp":"2026-08-16T23:37:22.913100Z"}]}}
{"rx_ns": 42908370604000, "frame": {"channel":"book","type":"update","data":[{"symbol":"BTC/USD","bids":[],"asks":[{"price":62878.9,"qty":0.00000000},{"price":62879.7,"qty":0.00200000}],"checksum":4885239,"timestamp":"2026-08-16T23:37:22.996754Z"}]}}
{"rx_ns": 42908370677500, "frame": {"channel":"book","type":"update","data":[{"symbol":"BTC/USD","bids":[{"price":62791.3,"qty":0.00000000},{"price":62709.2,"qty":0.43000000},{"price":62791.2,"qty":0.05762772}],"asks":[],"checksum":2245812262,"timestamp":"2026-08-16T23:37:22.998072Z"}]}}
{"rx_ns": 42908529242700, "frame": {"channel":"book","type":"update","data":[{"symbol":"BTC/USD","bids":[{"price":62768.7,"qty":0.18766548}],"asks":[],"checksum":2245812262,"timestamp":"2026-08-16T23:37:23.156469Z"}]}}
{"rx_ns": 42908588079900, "frame": {"channel":"book","type":"update","data":[{"symbol":"BTC/USD","bids":[],"asks":[{"price":62879.1,"qty":0.02131292}],"checksum":2245812262,"timestamp":"2026-08-16T23:37:23.216150Z"}]}}
{"rx_ns": 42908666117500, "frame": {"channel":"heartbeat"}}
{"rx_ns": 42908837846200, "frame": {"channel":"book","type":"update","data":[{"symbol":"BTC/USD","bids":[{"price":62778.6,"qty":0.08817369}],"asks":[],"checksum":2245812262,"timestamp":"2026-08-16T23:37:23.465919Z"}]}}
{"rx_ns": 42908971554300, "frame": {"channel":"book","type":"update","data":[{"symbol":"BTC/USD","bids":[{"price":62779.9,"qty":0.00000000},{"price":62709.6,"qty":0.04678000}],"asks":[],"checksum":2245812262,"timestamp":"2026-08-16T23:37:23.596119Z"}]}}
{"rx_ns": 42908979553100, "frame": {"channel":"book","type":"update","data":[{"symbol":"BTC/USD","bids":[],"asks":[{"price":62879.1,"qty":0.00000000},{"price":62879.7,"qty":0.00200000}],"checksum":2245812262,"timestamp":"2026-08-16T23:37:23.607916Z"}]}}
{"rx_ns": 42909020211900, "frame": {"channel":"book","type":"update","data":[{"symbol":"BTC/USD","bids":[{"price":62779.8,"qty":0.15927762}],"asks":[],"checksum":2245812262,"timestamp":"2026-08-16T23:37:23.646306Z"}]}}
{"rx_ns": 42909202806400, "frame": {"channel":"book","type":"update","data":[{"symbol":"BTC/USD","bids":[],"asks":[{"price":62879.0,"qty":0.02131292}],"checksum":2245812262,"timestamp":"2026-08-16T23:37:23.830832Z"}]}}
{"rx_ns": 42909508068500, "frame": {"channel":"book","type":"update","data":[{"symbol":"BTC/USD","bids":[],"asks":[{"price":62879.0,"qty":0.00000000},{"price":62879.7,"qty":0.00200000}],"checksum":2245812262,"timestamp":"2026-08-16T23:37:24.136578Z"}]}}
{"rx_ns": 42909666038300, "frame": {"channel":"heartbeat"}}
{"rx_ns": 42909737015900, "frame": {"channel":"book","type":"update","data":[{"symbol":"BTC/USD","bids":[],"asks":[{"price":62878.9,"qty":0.02131292}],"checksum":2245812262,"timestamp":"2026-08-16T23:37:24.365281Z"}]}}
{"rx_ns": 42909956729300, "frame": {"channel":"book","type":"update","data":[{"symbol":"BTC/USD","bids":[],"asks":[{"price":62878.9,"qty":0.00000000},{"price":62879.7,"qty":0.00200000}],"checksum":2245812262,"timestamp":"2026-08-16T23:37:24.584714Z"}]}}
{"rx_ns": 42910058510700, "frame": {"channel":"book","type":"update","data":[{"symbol":"BTC/USD","bids":[{"price":62779.8,"qty":0.00000000},{"price":62709.6,"qty":0.04678000}],"asks":[],"checksum":2245812262,"timestamp":"2026-08-16T23:37:24.686614Z"}]}}
{"rx_ns": 42910068040700, "frame": {"channel":"book","type":"update","data":[{"symbol":"BTC/USD","bids":[{"price":62779.7,"qty":0.15927762}],"asks":[],"checksum":2245812262,"timestamp":"2026-08-16T23:37:24.696326Z"}]}}
{"rx_ns": 42910114651500, "frame": {"channel":"book","type":"update","data":[{"symbol":"BTC/USD","bids":[{"price":62728.2,"qty":0.00000000},{"price":62709.6,"qty":0.04678000}],"asks":[],"checksum":2245812262,"timestamp":"2026-08-16T23:37:24.742481Z"}]}}
{"rx_ns": 42910119076400, "frame": {"channel":"book","type":"update","data":[{"symbol":"BTC/USD","bids":[{"price":62728.3,"qty":5.91673390}],"asks":[],"checksum":2245812262,"timestamp":"2026-08-16T23:37:24.745507Z"}]}}
{"rx_ns": 42910188287400, "frame": {"channel":"book","type":"update","data":[{"symbol":"BTC/USD","bids":[],"asks":[{"price":62879.0,"qty":0.02131292}],"checksum":2245812262,"timestamp":"2026-08-16T23:37:24.815135Z"}]}}
{"rx_ns": 42910228124500, "frame": {"channel":"book","type":"update","data":[{"symbol":"BTC/USD","bids":[{"price":62785.8,"qty":0.00000000},{"price":62709.6,"qty":0.04678000},{"price":62784.6,"qty":0.00009500}],"asks":[],"checksum":2977238349,"timestamp":"2026-08-16T23:37:24.854528Z"}]}}
{"rx_ns": 42910380848100, "frame": {"channel":"book","type":"update","data":[{"symbol":"BTC/USD","bids":[],"asks":[{"price":62809.7,"qty":0.00000000},{"price":62879.7,"qty":0.00200000}],"checksum":2977238349,"timestamp":"2026-08-16T23:37:25.008283Z"}]}}
{"rx_ns": 42910380920400, "frame": {"channel":"book","type":"update","data":[{"symbol":"BTC/USD","bids":[],"asks":[{"price":62808.9,"qty":0.02865835}],"checksum":2977238349,"timestamp":"2026-08-16T23:37:25.008318Z"}]}}
{"rx_ns": 42910418652400, "frame": {"channel":"book","type":"update","data":[{"symbol":"BTC/USD","bids":[],"asks":[{"price":62879.0,"qty":0.00000000},{"price":62879.7,"qty":0.00200000}],"checksum":2977238349,"timestamp":"2026-08-16T23:37:25.046845Z"}]}}
{"rx_ns": 42910535123300, "frame": {"channel":"book","type":"update","data":[{"symbol":"BTC/USD","bids":[],"asks":[{"price":62835.6,"qty":0.00000000},{"price":62881.2,"qty":0.16061732}],"checksum":2977238349,"timestamp":"2026-08-16T23:37:25.162982Z"}]}}
{"rx_ns": 42910542565400, "frame": {"channel":"book","type":"update","data":[{"symbol":"BTC/USD","bids":[],"asks":[{"price":62835.5,"qty":3.10436132}],"checksum":2977238349,"timestamp":"2026-08-16T23:37:25.166822Z"}]}}
{"rx_ns": 42910590299900, "frame": {"channel":"book","type":"update","data":[{"symbol":"BTC/USD","bids":[],"asks":[{"price":62878.7,"qty":0.00297725}],"checksum":2977238349,"timestamp":"2026-08-16T23:37:25.218389Z"}]}}
{"rx_ns": 42910649143500, "frame": {"channel":"book","type":"update","data":[{"symbol":"BTC/USD","bids":[],"asks":[{"price":62878.9,"qty":0.02131292}],"checksum":2977238349,"timestamp":"2026-08-16T23:37:25.276377Z"}]}}
{"rx_ns": 42910666455800, "frame": {"channel":"heartbeat"}}
{"rx_ns": 42910715024400, "frame": {"channel":"book","type":"update","data":[{"symbol":"BTC/USD","bids":[],"asks":[{"price":62810.3,"qty":0.18489680}],"checksum":2977238349,"timestamp":"2026-08-16T23:37:25.338879Z"}]}}
{"rx_ns": 42910715100200, "frame": {"channel":"book","type":"update","data":[{"symbol":"BTC/USD","bids":[],"asks":[{"price":62809.9,"qty":0.00323521}],"checksum":2977238349,"timestamp":"2026-08-16T23:37:25.339166Z"}]}}
{"rx_ns": 42910890431500, "frame": {"channel":"book","type":"update","data":[{"symbol":"BTC/USD","bids":[],"asks":[{"price":62878.9,"qty":0.00000000},{"price":62879.7,"qty":0.00200000}],"checksum":2977238349,"timestamp":"2026-08-16T23:37:25.518507Z"}]}}
{"rx_ns": 42910894192200, "frame": {"channel":"book","type":"update","data":[{"symbol":"BTC/USD","bids":[],"asks":[{"price":62879.4,"qty":0.06960000}],"checksum":2977238349,"timestamp":"2026-08-16T23:37:25.522295Z"}]}}
{"rx_ns": 42910962248800, "frame": {"channel":"book","type":"update","data":[{"symbol":"BTC/USD","bids":[{"price":62794.7,"qty":0.00810000},{"price":62794.7,"qty":0.00010000},{"price":62794.7,"qty":0.00000013}],"asks":[],"checksum":4023025237,"timestamp":"2026-08-16T23:37:25.588038Z"}]}}
{"rx_ns": 42910971944600, "frame": {"channel":"book","type":"update","data":[{"symbol":"BTC/USD","bids":[],"asks":[{"price":62794.8,"qty":5.75861514}],"checksum":3588718414,"timestamp":"2026-08-16T23:37:25.590596Z"}]}}
{"rx_ns": 42910971999000, "frame": {"channel":"book","type":"update","data":[{"symbol":"BTC/USD","bids":[{"price":62757.0,"qty":0.00000000},{"price":62709.6,"qty":0.04678000},{"price":62756.5,"qty":0.00318497}],"asks":[],"checksum":3588718414,"timestamp":"2026-08-16T23:37:25.590865Z"}]}}
{"rx_ns": 42910972018500, "frame": {"channel":"book","type":"update","data":[{"symbol":"BTC/USD","bids":[{"price":62785.2,"qty":0.00000000},{"price":62709.6,"qty":0.04678000},{"price":62784.7,"qty":0.00318497}],"asks":[],"checksum":2402876717,"timestamp":"2026-08-16T23:37:25.591031Z"}]}}
{"rx_ns": 42910972033900, "frame": {"channel":"book","type":"update","data":[{"symbol":"BTC/USD","bids":[],"asks":[{"price":62804.7,"qty":0.00000000},{"price":62879.7,"qty":0.00200000},{"price":62804.2,"qty":0.00318497}],"checksum":2402876717,"timestamp":"2026-08-16T23:37:25.591329Z"}]}}
{"rx_ns": 42910972050600, "frame": {"channel":"book","type":"update","data":[{"symbol":"BTC/USD","bids":[],"asks":[{"price":62832.9,"qty":0.00000000},{"price":62879.7,"qty":0.00200000},{"price":62832.4,"qty":0.01917016}],"checksum":2402876717,"timestamp":"2026-08-16T23:37:25.591665Z"}]}}
{"rx_ns": 42910972065000, "frame": {"channel":"book","type":"update","data":[{"symbol":"BTC/USD","bids":[{"price":62794.7,"qty":0.00000000},{"price":62709.6,"qty":0.04678000},{"price":62794.3,"qty":0.00000000},{"price":62709.2,"qty":0.43000000}],"asks":[{"price":62793.6,"qty":0.00014887}],"checksum":2848284173,"timestamp":"2026-08-16T23:37:25.592135Z"}]}}
{"rx_ns": 42910972086200, "frame": {"channel":"book","type":"update","data":[{"symbol":"BTC/USD","bids":[],"asks":[{"price":62793.6,"qty":0.01180152}],"checksum":1914264378,"timestamp":"2026-08-16T23:37:25.592450Z"}]}}
{"rx_ns": 42910972170200, "frame": {"channel":"book","type":"update","data":[{"symbol":"BTC/USD","bids":[],"asks":[{"price":62794.8,"qty":5.74676267}],"checksum":1285553076,"timestamp":"2026-08-16T23:37:25.592670Z"}]}}
{"rx_ns": 42910972188100, "frame": {"channel":"book","type":"update","data":[{"symbol":"BTC/USD","bids":[],"asks":[{"price":62847.2,"qty":0.00000000},{"price":62879.7,"qty":0.00200000}],"checksum":1285553076,"timestamp":"2026-08-16T23:37:25.593220Z"}]}}
{"rx_ns": 42910975339200, "frame": {"channel":"book","type":"update","data":[{"symbol":"BTC/USD","bids":[],"asks":[{"price":62794.7,"qty":0.11000000}],"checksum":3043339451,"timestamp":"2026-08-16T23:37:25.593295Z"}]}}
{"rx_ns": 42910975390500, "frame": {"channel":"book","type":"update","data":[{"symbol":"BTC/USD","bids":[],"asks":[{"price":62794.8,"qty":5.72659973}],"checksum":2264016189,"timestamp":"2026-08-16T23:37:25.593662Z"}]}}
{"rx_ns": 42910975402000, "frame": {"channel":"book","type":"update","data":[{"symbol":"BTC/USD","bids":[],"asks":[{"price":62794.8,"qty":5.67061501},{"price":62794.7,"qty":0.16598472}],"checksum":4271627307,"timestamp":"2026-08-16T23:37:25.593718Z"}]}}
{"rx_ns": 42910975414000, "frame": {"channel":"book","type":"update","data":[{"symbol":"BTC/USD","bids":[],"asks":[{"price":62810.3,"qty":0.00000000},{"price":62879.7,"qty":0.00200000},{"price":62794.7,"qty":0.35088152}],"checksum":429499939,"timestamp":"2026-08-16T23:37:25.593747Z"}]}}
{"rx_ns": 42910975426300, "frame": {"channel":"book","type":"update","data":[{"symbol":"BTC/USD","bids":[],"asks":[{"price":62794.8,"qty":5.59261501}],"checksum":3916550877,"timestamp":"2026-08-16T23:37:25.593774Z"}]}}
{"rx_ns": 42910975435000, "frame": {"channel":"book","type":"update","data":[{"symbol":"BTC/USD","bids":[],"asks":[{"price":62794.8,"qty":5.43338102}],"checksum":39271468,"timestamp":"2026-08-16T23:37:25.593801Z"}]}}
{"rx_ns": 42910975446000, "frame": {"channel":"book","type":"update","data":[{"symbol":"BTC/USD","bids":[],"asks":[{"price":62796.0,"qty":0.00000000},{"price":62881.2,"qty":0.16061732}],"checksum":1926668286,"timestamp":"2026-08-16T23:37:25.593997Z"}]}}
{"rx_ns": 42910975455600, "frame": {"channel":"book","type":"update","data":[{"symbol":"BTC/USD","bids":[],"asks":[{"price":62793.6,"qty":0.08140152}],"checksum":2008821468,"timestamp":"2026-08-16T23:37:25.594134Z"}]}}
{"rx_ns": 42910975464100, "frame": {"channel":"book","type":"update","data":[{"symbol":"BTC/USD","bids":[],"asks":[{"price":62833.1,"qty":15.00000000}],"checksum":2008821468,"timestamp":"2026-08-16T23:37:25.594151Z"}]}}
{"rx_ns": 42910975472100, "frame": {"channel":"book","type":"update","data":[{"symbol":"BTC/USD","bids":[],"asks":[{"price":62793.6,"qty":0.16100152}],"checksum":4192410485,"timestamp":"2026-08-16T23:37:25.594750Z"}]}}
{"rx_ns": 42910975481000, "frame": {"channel":"book","type":"update","data":[{"symbol":"BTC/USD","bids":[],"asks":[{"price":62793.6,"qty":0.95726101}],"checksum":3060720704,"timestamp":"2026-08-16T23:37:25.595756Z"}]}}
{"rx_ns": 42910975494000, "frame": {"channel":"book","type":"update","data":[{"symbol":"BTC/USD","bids":[{"price":62779.7,"qty":0.00000000},{"price":62707.9,"qty":0.00079734}],"asks":[],"checksum":3060720704,"timestamp":"2026-08-16T23:37:25.595956Z"}]}}
{"rx_ns": 42910975507100, "frame": {"channel":"book","type":"update","data":[{"symbol":"BTC/USD","bids":[],"asks":[{"price":62793.6,"qty":1.11653863}],"checksum":3151525005,"timestamp":"2026-08-16T23:37:25.596229Z"}]}}
{"rx_ns": 42910975518000, "frame": {"channel":"book","type":"update","data":[{"symbol":"BTC/USD","bids":[{"price":62793.5,"qty":0.03646524}],"asks":[],"checksum":155797922,"timestamp":"2026-08-16T23:37:25.596279Z"}]}}
{"rx_ns": 42910975553700, "frame": {"channel":"book","type":"update","data":[{"symbol":"BTC/USD","bids":[],"asks":[{"price":62798.0,"qty":0.00422189}],"checksum":3717398103,"timestamp":"2026-08-16T23:37:25.598790Z"}]}}
{"rx_ns": 42910975564400, "frame": {"channel":"book","type":"update","data":[{"symbol":"BTC/USD","bids":[],"asks":[{"price":62800.0,"qty":0.00422176}],"checksum":81595150,"timestamp":"2026-08-16T23:37:25.598975Z"}]}}
{"rx_ns": 42910975576700, "frame": {"channel":"book","type":"update","data":[{"symbol":"BTC/USD","bids":[],"asks":[{"price":62802.0,"qty":0.00740624}],"checksum":81595150,"timestamp":"2026-08-16T23:37:25.599093Z"}]}}
{"rx_ns": 42910975597300, "frame": {"channel":"book","type":"update","data":[{"symbol":"BTC/USD","bids":[],"asks":[{"price":62794.8,"qty":5.35378102}],"checksum":1645088991,"timestamp":"2026-08-16T23:37:25.604095Z"}]}}
{"rx_ns": 42910986351400, "frame": {"channel":"book","type":"update","data":[{"symbol":"BTC/USD","bids":[],"asks":[{"price":62809.9,"qty":0.00318421}],"checksum":1645088991,"timestamp":"2026-08-16T23:37:25.610708Z"}]}}
{"rx_ns": 42910986427400, "frame": {"channel":"book","type":"update","data":[{"symbol":"BTC/USD","bids":[{"price":62781.7,"qty":0.00005100}],"asks":[],"checksum":3490493081,"timestamp":"2026-08-16T23:37:25.610754Z"}]}}
{"rx_ns": 42911007533200, "frame": {"channel":"book","type":"update","data":[{"symbol":"BTC/USD","bids":[{"price":62782.0,"qty":0.00422297}],"asks":[],"checksum":2028456910,"timestamp":"2026-08-16T23:37:25.635416Z"}]}}
{"rx_ns": 42911010754000, "frame": {"channel":"book","type":"update","data":[{"symbol":"BTC/USD","bids":[{"price":62780.0,"qty":0.00422310}],"asks":[],"checksum":2028456910,"timestamp":"2026-08-16T23:37:25.635555Z"}]}}
{"rx_ns": 42911010817800, "frame": {"channel":"book","type":"update","data":[{"symbol":"BTC/USD","bids":[{"price":62778.0,"qty":0.00740907}],"asks":[],"checksum":2028456910,"timestamp":"2026-08-16T23:37:25.635640Z"}]}}
{"rx_ns": 42911011415500, "frame": {"channel":"book","type":"update","data":[{"symbol":"BTC/USD","bids":[],"asks":[{"price":62794.7,"qty":0.16598472},{"price":62794.6,"qty":0.18489680}],"checksum":2936487497,"timestamp":"2026-08-16T23:37:25.636612Z"}]}}
{"rx_ns": 42911020644100, "frame": {"channel":"book","type":"update","data":[{"symbol":"BTC/USD","bids":[{"price":62779.9,"qty":0.15927762}],"asks":[],"checksum":2936487497,"timestamp":"2026-08-16T23:37:25.646247Z"}]}}
{"rx_ns": 42911077498300, "frame": {"channel":"book","type":"update","data":[{"symbol":"BTC/USD","bids":[{"price":62779.9,"qty":0.00000000},{"price":62710.2,"qty":0.00159400}],"asks":[],"checksum":2936487497,"timestamp":"2026-08-16T23:37:25.686564Z"}]}}
{"rx_ns": 42911077547400, "frame": {"channel":"book","type":"update","data":[{"symbol":"BTC/USD","bids":[],"asks":[{"price":62794.8,"qty":5.24378102}],"checksum":2828043326,"timestamp":"2026-08-16T23:37:25.693952Z"}]}}
{"rx_ns": 42911077560200, "frame": {"channel":"book","type":"update","data":[{"symbol":"BTC/USD","bids":[],"asks":[{"price":62793.6,"qty":1.22653863}],"checksum":4002292958,"timestamp":"2026-08-16T23:37:25.694724Z"}]}}
{"rx_ns": 42911077569200, "frame": {"channel":"book","type":"update","data":[{"symbol":"BTC/USD","bids":[],"asks":[{"price":62793.6,"qty":1.24584855}],"checksum":517189455,"timestamp":"2026-08-16T23:37:25.695944Z"}]}}
{"rx_ns": 42911077577700, "frame": {"channel":"book","type":"update","data":[{"symbol":"BTC/USD","bids":[{"price":62779.8,"qty":0.15927762}],"asks":[],"checksum":517189455,"timestamp":"2026-08-16T23:37:25.696259Z"}]}}
{"rx_ns": 42911077586500, "frame": {"channel":"book","type":"update","data":[{"symbol":"BTC/USD","bids":[],"asks":[{"price":62793.6,"qty":1.32384855}],"checksum":3478771735,"timestamp":"2026-08-16T23:37:25.696482Z"}]}}
{"rx_ns": 42911104094700, "frame": {"channel":"book","type":"update","data":[{"symbol":"BTC/USD","bids":[{"price":62793.5,"qty":0.03686337}],"asks":[],"checksum":4007975360,"timestamp":"2026-08-16T23:37:25.730121Z"}]}}
{"rx_ns": 42911122717700, "frame": {"channel":"book","type":"update","data":[{"symbol":"BTC/USD","bids":[],"asks":[{"price":62794.8,"qty":1.45304952},{"price":62793.6,"qty":5.11469074}],"checksum":1352614562,"timestamp":"2026-08-16T23:37:25.747207Z"}]}}
{"rx_ns": 42911124943900, "frame": {"channel":"book","type":"update","data":[{"symbol":"BTC/USD","bids":[],"asks":[{"price":62794.6,"qty":0.00000000},{"price":62878.8,"qty":0.11123578},{"price":62796.6,"qty":0.18489680}],"checksum":2032201701,"timestamp":"2026-08-16T23:37:25.749991Z"}]}}
{"rx_ns": 42911157187800, "frame": {"channel":"book","type":"update","data":[{"symbol":"BTC/USD","bids":[{"price":62793.5,"qty":0.03726150}],"asks":[],"checksum":429493614,"timestamp":"2026-08-16T23:37:25.785284Z"}]}}
{"rx_ns": 42911159236800, "frame": {"channel":"book","type":"update","data":[{"symbol":"BTC/USD","bids":[],"asks":[{"price":62794.7,"qty":0.11000000},{"price":62793.6,"qty":5.17067546}],"checksum":4161908341,"timestamp":"2026-08-16T23:37:25.786608Z"}]}}
{"rx_ns": 42911170190300, "frame": {"channel":"book","type":"update","data":[{"symbol":"BTC/USD","bids":[],"asks":[{"price":62794.7,"qty":0.00000000},{"price":62878.8,"qty":0.11123578}],"checksum":4002293099,"timestamp":"2026-08-16T23:37:25.795179Z"}]}}
{"rx_ns": 42911170284700, "frame": {"channel":"book","type":"update","data":[{"symbol":"BTC/USD","bids":[],"asks":[{"price":62796.6,"qty":0.00000000},{"price":62878.9,"qty":0.02131292},{"price":62808.9,"qty":0.21355515}],"checksum":2833370573,"timestamp":"2026-08-16T23:37:25.796418Z"}]}}
{"rx_ns": 42911229709000, "frame": {"channel":"book","type":"update","data":[{"symbol":"BTC/USD","bids":[{"price":62793.5,"qty":0.03765963}],"asks":[],"checksum":3045787538,"timestamp":"2026-08-16T23:37:25.840329Z"}]}}
{"rx_ns": 42911236402800, "frame": {"channel":"book","type":"update","data":[{"symbol":"BTC/USD","bids":[],"asks":[{"price":62827.0,"qty":0.00000000},{"price":62879.7,"qty":0.00200000},{"price":62825.3,"qty":0.00094656}],"checksum":3045787538,"timestamp":"2026-08-16T23:37:25.845841Z"}]}}
{"rx_ns": 42911236520800, "frame": {"channel":"book","type":"update","data":[{"symbol":"BTC/USD","bids":[{"price":62757.1,"qty":0.00000000},{"price":62710.2,"qty":0.00159400},{"price":62755.5,"qty":0.00303487}],"asks":[],"checksum":3045787538,"timestamp":"2026-08-16T23:37:25.846163Z"}]}}
{"rx_ns": 42911236881000, "frame": {"channel":"book","type":"update","data":[{"symbol":"BTC/USD","bids":[],"asks":[{"price":62849.6,"qty":0.00000000},{"price":62879.7,"qty":0.00200000},{"price":62847.8,"qty":0.00660000}],"checksum":3045787538,"timestamp":"2026-08-16T23:37:25.852800Z"}]}}
{"rx_ns": 42911293515500, "frame": {"channel":"book","type":"update","data":[{"symbol":"BTC/USD","bids":[{"price":62793.5,"qty":0.03805776}],"asks":[],"checksum":2383411611,"timestamp":"2026-08-16T23:37:25.896149Z"}]}}
{"rx_ns": 42911299798200, "frame": {"channel":"book","type":"update","data":[{"symbol":"BTC/USD","bids":[],"asks":[{"price":62842.8,"qty":0.04012144}],"checksum":2383411611,"timestamp":"2026-08-16T23:37:25.903702Z"}]}}
{"rx_ns": 42911344327200, "frame": {"channel":"book","type":"update","data":[{"symbol":"BTC/USD","bids":[{"price":62793.5,"qty":0.03845589}],"asks":[],"checksum":353784763,"timestamp":"2026-08-16T23:37:25.952216Z"}]}}
{"rx_ns": 42911347488900, "frame": {"channel":"book","type":"update","data":[{"symbol":"BTC/USD","bids":[],"asks":[{"price":62794.8,"qty":1.45265139},{"price":62793.6,"qty":5.17107359}],"checksum":1812003054,"timestamp":"2026-08-16T23:37:25.959958Z"}]}}
{"rx_ns": 42911347555700, "frame": {"channel":"book","type":"update","data":[{"symbol":"BTC/USD","bids":[{"price":62793.5,"qty":0.01714297}],"asks":[],"checksum":2124107990,"timestamp":"2026-08-16T23:37:25.965743Z"}]}}
{"rx_ns": 42911347585800, "frame": {"channel":"book","type":"update","data":[{"symbol":"BTC/USD","bids":[{"price":62792.3,"qty":0.02131292}],"asks":[],"checksum":1277878187,"timestamp":"2026-08-16T23:37:25.966882Z"}]}}
{"rx_ns": 42911352349200, "frame": {"channel":"book","type":"update","data":[{"symbol":"BTC/USD","bids":[{"price":62793.5,"qty":0.01674484}],"asks":[],"checksum":4035872163,"timestamp":"2026-08-16T23:37:25.976331Z"}]}}
{"rx_ns": 42911408183100, "frame": {"channel":"book","type":"update","data":[{"symbol":"BTC/USD","bids":[{"price":62793.5,"qty":0.01634671}],"asks":[],"checksum":711502303,"timestamp":"2026-08-16T23:37:26.036421Z"}]}}
{"rx_ns": 42911469715000, "frame": {"channel":"book","type":"update","data":[{"symbol":"BTC/USD","bids":[{"price":62793.5,"qty":0.01594858}],"asks":[],"checksum":4156906713,"timestamp":"2026-08-16T23:37:26.097856Z"}]}}
{"rx_ns": 42911479045700, "frame": {"channel":"book","type":"update","data":[{"symbol":"BTC/USD","bids":[{"price":62755.5,"qty":0.00000000},{"price":62710.2,"qty":0.00159400},{"price":62755.6,"qty":0.00303487}],"asks":[],"checksum":4156906713,"timestamp":"2026-08-16T23:37:26.107314Z"}]}}
{"rx_ns": 42911509190800, "frame": {"channel":"book","type":"update","data":[{"symbol":"BTC/USD","bids":[{"price":62755.6,"qty":0.00000000},{"price":62710.2,"qty":0.00159400},{"price":62755.5,"qty":0.00303487}],"asks":[],"checksum":4156906713,"timestamp":"2026-08-16T23:37:26.136032Z"}]}}
{"rx_ns": 42911535064800, "frame": {"channel":"book","type":"update","data":[{"symbol":"BTC/USD","bids":[{"price":62793.5,"qty":0.01555045}],"asks":[],"checksum":2717056460,"timestamp":"2026-08-16T23:37:26.163306Z"}]}}
{"rx_ns": 42911560078500, "frame": {"channel":"book","type":"update","data":[{"symbol":"BTC/USD","bids":[],"asks":[{"price":62797.4,"qty":0.00005100}],"checksum":1942515925,"timestamp":"2026-08-16T23:37:26.187901Z"}]}}
{"rx_ns": 42911611262000, "frame": {"channel":"book","type":"update","data":[{"symbol":"BTC/USD","bids":[],"asks":[{"price":62794.8,"qty":1.45165139}],"checksum":1238281393,"timestamp":"2026-08-16T23:37:26.239707Z"}]}}
{"rx_ns": 42911667779000, "frame": {"channel":"heartbeat"}}
{"rx_ns": 42911714183500, "frame": {"channel":"book","type":"update","data":[{"symbol":"BTC/USD","bids":[],"asks":[{"price":62813.5,"qty":0.00000000},{"price":62878.8,"qty":0.11123578}],"checksum":1238281393,"timestamp":"2026-08-16T23:37:26.342953Z"}]}}
{"rx_ns": 42911955112400, "frame": {"channel":"book","type":"update","data":[{"symbol":"BTC/USD","bids":[],"asks":[{"price":62859.4,"qty":0.00000000},{"price":62879.7,"qty":0.00200000},{"price":62854.2,"qty":0.08573600}],"checksum":1238281393,"timestamp":"2026-08-16T23:37:26.583257Z"}]}}
{"rx_ns": 42911957528300, "frame": {"channel":"book","type":"update","data":[{"symbol":"BTC/USD","bids":[],"asks":[{"price":62879.4,"qty":0.06960000}],"checksum":1238281393,"timestamp":"2026-08-16T23:37:26.585861Z"}]}}
{"rx_ns": 42912014141100, "frame": {"channel":"book","type":"update","data":[{"symbol":"BTC/USD","bids":[],"asks":[{"price":62879.1,"qty":0.05762772}],"checksum":1238281393,"timestamp":"2026-08-16T23:37:26.634267Z"}]}}
{"rx_ns": 42912221420700, "frame": {"channel":"book","type":"update","data":[{"symbol":"BTC/USD","bids":[],"asks":[{"price":62879.1,"qty":0.00000000},{"price":62879.7,"qty":0.00200000}],"checksum":1238281393,"timestamp":"2026-08-16T23:37:26.849935Z"}]}}
{"rx_ns": 42912223134900, "frame": {"channel":"book","type":"update","data":[{"symbol":"BTC/USD","bids":[],"asks":[{"price":62879.4,"qty":0.06960000}],"checksum":1238281393,"timestamp":"2026-08-16T23:37:26.851422Z"}]}}
{"rx_ns": 42912286603400, "frame": {"channel":"book","type":"update","data":[{"symbol":"BTC/USD","bids":[{"price":62784.6,"qty":0.00000000},{"price":62710.2,"qty":0.00159400},{"price":62785.2,"qty":0.00009500}],"asks":[],"checksum":3188426293,"timestamp":"2026-08-16T23:37:26.913423Z"}]}}
{"rx_ns": 42912389960200, "frame": {"channel":"book","type":"update","data":[{"symbol":"BTC/USD","bids":[{"price":62793.5,"qty":0.01565045}],"asks":[],"checksum":3170033834,"timestamp":"2026-08-16T23:37:27.018565Z"}]}}
{"rx_ns": 42912447575300, "frame": {"channel":"book","type":"update","data":[{"symbol":"BTC/USD","bids":[],"asks":[{"price":62879.0,"qty":0.05762772}],"checksum":3170033834,"timestamp":"2026-08-16T23:37:27.075873Z"}]}}
{"rx_ns": 42912466319700, "frame": {"channel":"book","type":"update","data":[{"symbol":"BTC/USD","bids":[{"price":62728.3,"qty":0.00000000},{"price":62710.2,"qty":0.00159400}],"asks":[],"checksum":3170033834,"timestamp":"2026-08-16T23:37:27.094005Z"}]}}
{"rx_ns": 42912470021500, "frame": {"channel":"book","type":"update","data":[{"symbol":"BTC/USD","bids":[{"price":62728.4,"qty":5.85081252}],"asks":[],"checksum":3170033834,"timestamp":"2026-08-16T23:37:27.098211Z"}]}}
{"rx_ns": 42912528157100, "frame": {"channel":"book","type":"update","data":[{"symbol":"BTC/USD","bids":[{"price":62779.8,"qty":0.00000000},{"price":62710.2,"qty":0.00159400}],"asks":[],"checksum":3170033834,"timestamp":"2026-08-16T23:37:27.155973Z"}]}}
{"rx_ns": 42912529918600, "frame": {"channel":"book","type":"update","data":[{"symbol":"BTC/USD","bids":[{"price":62756.5,"qty":0.00000000},{"price":62709.2,"qty":0.43000000},{"price":62755.9,"qty":0.00318497}],"asks":[],"checksum":3170033834,"timestamp":"2026-08-16T23:37:27.158087Z"}]}}
{"rx_ns": 42912529974700, "frame": {"channel":"book","type":"update","data":[{"symbol":"BTC/USD","bids":[{"price":62784.7,"qty":0.00000000},{"price":62709.2,"qty":0.43000000},{"price":62784.1,"qty":0.00318497}],"asks":[],"checksum":1073902054,"timestamp":"2026-08-16T23:37:27.158354Z"}]}}
{"rx_ns": 42912531573000, "frame": {"channel":"book","type":"update","data":[{"symbol":"BTC/USD","bids":[],"asks":[{"price":62804.2,"qty":0.00000000},{"price":62879.7,"qty":0.00200000},{"price":62803.6,"qty":0.00318497}],"checksum":1073902054,"timestamp":"2026-08-16T23:37:27.158597Z"}]}}
{"rx_ns": 42912531595700, "frame": {"channel":"book","type":"update","data":[{"symbol":"BTC/USD","bids":[],"asks":[{"price":62832.4,"qty":0.01598519},{"price":62831.8,"qty":0.00318497}],"checksum":1073902054,"timestamp":"2026-08-16T23:37:27.158854Z"}]}}
{"rx_ns": 42912531607400, "frame": {"channel":"book","type":"update","data":[{"symbol":"BTC/USD","bids":[{"price":62711.3,"qty":0.06960000}],"asks":[],"checksum":1073902054,"timestamp":"2026-08-16T23:37:27.159209Z"}]}}
{"rx_ns": 42912569779300, "frame": {"channel":"book","type":"update","data":[{"symbol":"BTC/USD","bids":[{"price":62779.7,"qty":0.15927762}],"asks":[],"checksum":1073902054,"timestamp":"2026-08-16T23:37:27.196330Z"}]}}
{"rx_ns": 42912666643300, "frame": {"channel":"heartbeat"}}
{"rx_ns": 42912680049400, "frame": {"channel":"book","type":"update","data":[{"symbol":"BTC/USD","bids":[],"asks":[{"price":62793.6,"qty":5.17207359}],"checksum":1479992716,"timestamp":"2026-08-16T23:37:27.305061Z"}]}}
{"rx_ns": 42912715948400, "frame": {"channel":"book","type":"update","data":[{"symbol":"BTC/USD","bids":[],"asks":[{"price":62812.3,"qty":0.50000000}],"checksum":1479992716,"timestamp":"2026-08-16T23:37:27.343985Z"}]}}
{"rx_ns": 42912802988600, "frame": {"channel":"book","type":"update","data":[{"symbol":"BTC/USD","bids":[],"asks":[{"price":62835.5,"qty":0.00000000},{"price":62878.8,"qty":0.11123578}],"checksum":1479992716,"timestamp":"2026-08-16T23:37:27.430079Z"}]}}
{"rx_ns": 42912803038100, "frame": {"channel":"book","type":"update","data":[{"symbol":"BTC/USD","bids":[],"asks":[{"price":62828.7,"qty":0.77767506}],"checksum":1479992716,"timestamp":"2026-08-16T23:37:27.430254Z"}]}}
{"rx_ns": 42912803049800, "frame": {"channel":"book","type":"update","data":[{"symbol":"BTC/USD","bids":[],"asks":[{"price":62832.6,"qty":1.88640395}],"checksum":1479992716,"timestamp":"2026-08-16T23:37:27.430298Z"}]}}
{"rx_ns": 42912830286900, "frame": {"channel":"book","type":"update","data":[{"symbol":"BTC/USD","bids":[],"asks":[{"price":62793.6,"qty":5.18007359}],"checksum":1023654041,"timestamp":"2026-08-16T23:37:27.456429Z"}]}}
{"rx_ns": 42913069649300, "frame": {"channel":"book","type":"update","data":[{"symbol":"BTC/USD","bids":[{"price":62780.8,"qty":0.00000000},{"price":62710.2,"qty":0.00159400}],"asks":[],"checksum":1023654041,"timestamp":"2026-08-16T23:37:27.693381Z"}]}}
{"rx_ns": 42913069698000, "frame": {"channel":"book","type":"update","data":[{"symbol":"BTC/USD","bids":[{"price":62779.6,"qty":0.79643604}],"asks":[],"checksum":1023654041,"timestamp":"2026-08-16T23:37:27.694854Z"}]}}
{"rx_ns": 42913069709500, "frame": {"channel":"book","type":"update","data":[{"symbol":"BTC/USD","bids":[{"price":62778.6,"qty":0.09784428}],"asks":[],"checksum":1023654041,"timestamp":"2026-08-16T23:37:27.696264Z"}]}}
{"rx_ns": 42913069718200, "frame": {"channel":"book","type":"update","data":[{"symbol":"BTC/USD","bids":[{"price":62778.6,"qty":0.08817369}],"asks":[],"checksum":1023654041,"timestamp":"2026-08-16T23:37:27.697244Z"}]}}
{"rx_ns": 42913509528500, "frame": {"channel":"book","type":"update","data":[{"symbol":"BTC/USD","bids":[{"price":62755.5,"qty":0.00000000},{"price":62710.2,"qty":0.00159400},{"price":62756.0,"qty":0.00303489}],"asks":[],"checksum":1023654041,"timestamp":"2026-08-16T23:37:28.135644Z"}]}}
{"rx_ns": 42913669405700, "frame": {"channel":"heartbeat"}}
{"rx_ns": 42914336678000, "frame": {"channel":"book","type":"update","data":[{"symbol":"BTC/USD","bids":[{"price":62785.2,"qty":0.00000000},{"price":62710.2,"qty":0.00159400},{"price":62784.6,"qty":0.00009500}],"asks":[],"checksum":2216900534,"timestamp":"2026-08-16T23:37:28.964640Z"}]}}
{"rx_ns": 42914668162400, "frame": {"channel":"heartbeat"}}
{"rx_ns": 42914820317100, "frame": {"channel":"book","type":"update","data":[{"symbol":"BTC/USD","bids":[{"price":62728.4,"qty":0.00000000},{"price":62710.2,"qty":0.00159400}],"asks":[],"checksum":2216900534,"timestamp":"2026-08-16T23:37:29.445445Z"}]}}
{"rx_ns": 42914823744500, "frame": {"channel":"book","type":"update","data":[{"symbol":"BTC/USD","bids":[{"price":62728.5,"qty":5.75930456}],"asks":[],"checksum":2216900534,"timestamp":"2026-08-16T23:37:29.450676Z"}]}}
{"rx_ns": 42914823798100, "frame": {"channel":"book","type":"update","data":[{"symbol":"BTC/USD","bids":[{"price":62711.3,"qty":0.06960000}],"asks":[],"checksum":2216900534,"timestamp":"2026-08-16T23:37:29.451356Z"}]}}
{"rx_ns": 42915101826200, "frame": {"channel":"book","type":"update","data":[{"symbol":"BTC/USD","bids":[{"price":62718.0,"qty":0.00015944},{"price":62744.8,"qty":2.48111196}],"asks":[],"checksum":2216900534,"timestamp":"2026-08-16T23:37:29.730018Z"}]}}
{"rx_ns": 42915102012500, "frame": {"channel":"book","type":"update","data":[{"symbol":"BTC/USD","bids":[],"asks":[{"price":62856.4,"qty":1.42037000}],"checksum":2216900534,"timestamp":"2026-08-16T23:37:29.730059Z"}]}}
{"rx_ns": 42915102356700, "frame": {"channel":"book","type":"update","data":[{"symbol":"BTC/USD","bids":[{"price":62721.0,"qty":0.00000000},{"price":62710.2,"qty":0.00159400},{"price":62731.8,"qty":0.70609000}],"asks":[],"checksum":2216900534,"timestamp":"2026-08-16T23:37:29.730132Z"}]}}
{"rx_ns": 42915102380900, "frame": {"channel":"book","type":"update","data":[{"symbol":"BTC/USD","bids":[],"asks":[{"price":62839.9,"qty":0.00000000},{"price":62876.4,"qty":0.23890000},{"price":62823.5,"qty":0.71540000}],"checksum":2216900534,"timestamp":"2026-08-16T23:37:29.730190Z"}]}}
{"rx_ns": 42915118540400, "frame": {"channel":"book","type":"update","data":[{"symbol":"BTC/USD","bids":[],"asks":[{"price":62828.7,"qty":0.00000000},{"price":62876.4,"qty":0.23890000}],"checksum":2216900534,"timestamp":"2026-08-16T23:37:29.746328Z"}]}}
{"rx_ns": 42915118609200, "frame": {"channel":"book","type":"update","data":[{"symbol":"BTC/USD","bids":[],"asks":[{"price":62832.6,"qty":0.00000000},{"price":62878.8,"qty":0.11123578}],"checksum":2216900534,"timestamp":"2026-08-16T23:37:29.746403Z"}]}}
{"rx_ns": 42915121462300, "frame": {"channel":"book","type":"update","data":[{"symbol":"BTC/USD","bids":[],"asks":[{"price":62828.6,"qty":0.99520632}],"checksum":2216900534,"timestamp":"2026-08-16T23:37:29.750041Z"}]}}
{"rx_ns": 42915121530700, "frame": {"channel":"book","type":"update","data":[{"symbol":"BTC/USD","bids":[],"asks":[{"price":62832.5,"qty":1.42633504}],"checksum":2216900534,"timestamp":"2026-08-16T23:37:29.750122Z"}]}}
{"rx_ns": 42915667700500, "frame": {"channel":"heartbeat"}}
{"rx_ns": 42916454016000, "frame": {"channel":"book","type":"update","data":[{"symbol":"BTC/USD","bids":[{"price":62782.1,"qty":0.79640506}],"asks":[],"checksum":3358324374,"timestamp":"2026-08-16T23:37:31.082701Z"}]}}
{"rx_ns": 42916459401900, "frame": {"channel":"book","type":"update","data":[{"symbol":"BTC/USD","bids":[{"price":62780.9,"qty":0.06960000}],"asks":[],"checksum":3358324374,"timestamp":"2026-08-16T23:37:31.083984Z"}]}}
{"rx_ns": 42916496172000, "frame": {"channel":"book","type":"update","data":[{"symbol":"BTC/USD","bids":[{"price":62782.0,"qty":0.00000000},{"price":62710.2,"qty":0.00159400}],"asks":[],"checksum":688615201,"timestamp":"2026-08-16T23:37:31.124655Z"}]}}
{"rx_ns": 42916498919900, "frame": {"channel":"book","type":"update","data":[{"symbol":"BTC/USD","bids":[{"price":62711.3,"qty":0.06960000}],"asks":[],"checksum":688615201,"timestamp":"2026-08-16T23:37:31.127715Z"}]}}
{"rx_ns": 42916566467100, "frame": {"channel":"book","type":"update","data":[{"symbol":"BTC/USD","bids":[{"price":62780.9,"qty":0.00000000},{"price":62710.2,"qty":0.00159400}],"asks":[],"checksum":688615201,"timestamp":"2026-08-16T23:37:31.194906Z"}]}}
{"rx_ns": 42916578485800, "frame": {"channel":"book","type":"update","data":[{"symbol":"BTC/USD","bids":[{"price":62791.2,"qty":0.00164300}],"asks":[],"checksum":416759365,"timestamp":"2026-08-16T23:37:31.206414Z"}]}}
{"rx_ns": 42916581160400, "frame": {"channel":"book","type":"update","data":[{"symbol":"BTC/USD","bids":[{"price":62785.0,"qty":0.05598472}],"asks":[],"checksum":1400058470,"timestamp":"2026-08-16T23:37:31.207772Z"}]}}
{"rx_ns": 42916586837600, "frame": {"channel":"book","type":"update","data":[{"symbol":"BTC/USD","bids":[{"price":62779.7,"qty":0.00000000},{"price":62710.2,"qty":0.00159400}],"asks":[],"checksum":1400058470,"timestamp":"2026-08-16T23:37:31.214769Z"}]}}
{"rx_ns": 42916590390600, "frame": {"channel":"book","type":"update","data":[{"symbol":"BTC/USD","bids":[{"price":62766.4,"qty":0.00000000},{"price":62709.2,"qty":0.43000000},{"price":62763.1,"qty":0.10294266}],"asks":[],"checksum":1400058470,"timestamp":"2026-08-16T23:37:31.214801Z"}]}}
{"rx_ns": 42916590438700, "frame": {"channel":"book","type":"update","data":[{"symbol":"BTC/USD","bids":[],"asks":[{"price":62810.8,"qty":0.00000000},{"price":62876.4,"qty":0.23890000},{"price":62805.2,"qty":1.59575715}],"checksum":1400058470,"timestamp":"2026-08-16T23:37:31.215075Z"}]}}
{"rx_ns": 42916590583900, "frame": {"channel":"book","type":"update","data":[{"symbol":"BTC/USD","bids":[],"asks":[{"price":62810.7,"qty":0.00000000},{"price":62876.4,"qty":0.23890000},{"price":62805.1,"qty":0.00222509}],"checksum":1400058470,"timestamp":"2026-08-16T23:37:31.219200Z"}]}}
{"rx_ns": 42916593168800, "frame": {"channel":"book","type":"update","data":[{"symbol":"BTC/USD","bids":[],"asks":[{"price":62808.9,"qty":0.02865835},{"price":62796.6,"qty":0.18489680}],"checksum":2789801949,"timestamp":"2026-08-16T23:37:31.220461Z"}]}}
{"rx_ns": 42916593276400, "frame": {"channel":"book","type":"update","data":[{"symbol":"BTC/USD","bids":[{"price":62782.1,"qty":0.00000000},{"price":62709.2,"qty":0.43000000}],"asks":[],"checksum":1782937448,"timestamp":"2026-08-16T23:37:31.220769Z"}]}}
{"rx_ns": 42916594678400, "frame": {"channel":"book","type":"update","data":[{"symbol":"BTC/USD","bids":[{"price":62781.4,"qty":0.79641314}],"asks":[],"checksum":1782937448,"timestamp":"2026-08-16T23:37:31.222402Z"}]}}
{"rx_ns": 42916621066600, "frame": {"channel":"book","type":"update","data":[{"symbol":"BTC/USD","bids":[{"price":62779.2,"qty":0.15927762}],"asks":[],"checksum":1782937448,"timestamp":"2026-08-16T23:37:31.246426Z"}]}}
{"rx_ns": 42916659606600, "frame": {"channel":"book","type":"update","data":[{"symbol":"BTC/USD","bids":[{"price":62779.2,"qty":0.00000000},{"price":62710.2,"qty":0.00159400}],"asks":[],"checksum":1782937448,"timestamp":"2026-08-16T23:37:31.287828Z"}]}}
{"rx_ns": 42916670524300, "frame": {"channel":"heartbeat"}}
{"rx_ns": 42916693167300, "frame": {"channel":"book","type":"update","data":[{"symbol":"BTC/USD","bids":[{"price":62778.1,"qty":0.15927762}],"asks":[],"checksum":1782937448,"timestamp":"2026-08-16T23:37:31.296402Z"}]}}
{"rx_ns": 42916693249200, "frame": {"channel":"book","type":"update","data":[{"symbol":"BTC/USD","bids":[{"price":62778.0,"qty":0.00422324}],"asks":[],"checksum":1782937448,"timestamp":"2026-08-16T23:37:31.302588Z"}]}}
{"rx_ns": 42916699558600, "frame": {"channel":"book","type":"update","data":[{"symbol":"BTC/USD","bids":[{"price":62792.3,"qty":0.00000000},{"price":62710.2,"qty":0.00159400}],"asks":[],"checksum":3752802498,"timestamp":"2026-08-16T23:37:31.324194Z"}]}}
{"rx_ns": 42916699622000, "frame": {"channel":"book","type":"update","data":[{"symbol":"BTC/USD","bids":[{"price":62791.0,"qty":0.02131292}],"asks":[],"checksum":3211923694,"timestamp":"2026-08-16T23:37:31.325700Z"}]}}
{"rx_ns": 42916702477100, "frame": {"channel":"book","type":"update","data":[{"symbol":"BTC/USD","bids":[{"price":62780.0,"qty":0.00000000},{"price":62710.2,"qty":0.00159400}],"asks":[],"checksum":3211923694,"timestamp":"2026-08-16T23:37:31.329785Z"}]}}
{"rx_ns": 42916746328400, "frame": {"channel":"book","type":"update","data":[{"symbol":"BTC/USD","bids":[],"asks":[{"price":62804.0,"qty":0.00000000},{"price":62875.9,"qty":0.00159000}],"checksum":3211923694,"timestamp":"2026-08-16T23:37:31.374495Z"}]}}
{"rx_ns": 42916762745600, "frame": {"channel":"book","type":"update","data":[{"symbol":"BTC/USD","bids":[{"price":62793.5,"qty":0.00049813}],"asks":[],"checksum":1313096917,"timestamp":"2026-08-16T23:37:31.379798Z"}]}}
{"rx_ns": 42916762815200, "frame": {"channel":"book","type":"update","data":[{"symbol":"BTC/USD","bids":[{"price":62755.9,"qty":0.00000000},{"price":62709.2,"qty":0.43000000},{"price":62754.7,"qty":0.00318497}],"asks":[],"checksum":1313096917,"timestamp":"2026-08-16T23:37:31.381869Z"}]}}
{"rx_ns": 42916762848600, "frame": {"channel":"book","type":"update","data":[{"symbol":"BTC/USD","bids":[{"price":62784.1,"qty":0.00000000},{"price":62709.2,"qty":0.43000000},{"price":62783.0,"qty":0.00318497}],"asks":[],"checksum":4263316697,"timestamp":"2026-08-16T23:37:31.382176Z"}]}}
{"rx_ns": 42916762910700, "frame": {"channel":"book","type":"update","data":[{"symbol":"BTC/USD","bids":[],"asks":[{"price":62803.6,"qty":0.00000000},{"price":62876.4,"qty":0.23890000},{"price":62802.4,"qty":0.00318497}],"checksum":4263316697,"timestamp":"2026-08-16T23:37:31.382425Z"}]}}
{"rx_ns": 42916762924000, "frame": {"channel":"book","type":"update","data":[{"symbol":"BTC/USD","bids":[],"asks":[{"price":62831.8,"qty":0.00000000},{"price":62876.4,"qty":0.23890000},{"price":62830.7,"qty":0.00318497}],"checksum":4263316697,"timestamp":"2026-08-16T23:37:31.382686Z"}]}}
{"rx_ns": 42916796830300, "frame": {"channel":"book","type":"update","data":[{"symbol":"BTC/USD","bids":[{"price":62781.4,"qty":0.00000000},{"price":62709.2,"qty":0.43000000}],"asks":[],"checksum":4263316697,"timestamp":"2026-08-16T23:37:31.423248Z"}]}}
{"rx_ns": 42916798284300, "frame": {"channel":"book","type":"update","data":[{"symbol":"BTC/USD","bids":[{"price":62791.0,"qty":0.00000000},{"price":62707.9,"qty":0.00079734}],"asks":[],"checksum":1579795993,"timestamp":"2026-08-16T23:37:31.424241Z"}]}}
{"rx_ns": 42916798341900, "frame": {"channel":"book","type":"update","data":[{"symbol":"BTC/USD","bids":[{"price":62792.0,"qty":0.02131292}],"asks":[],"checksum":2438003544,"timestamp":"2026-08-16T23:37:31.424431Z"}]}}
{"rx_ns": 42916798356500, "frame": {"channel":"book","type":"update","data":[{"symbol":"BTC/USD","bids":[{"price":62780.7,"qty":0.79642200}],"asks":[],"checksum":2438003544,"timestamp":"2026-08-16T23:37:31.424860Z"}]}}
{"rx_ns": 42916802732000, "frame": {"channel":"book","type":"update","data":[{"symbol":"BTC/USD","bids":[{"price":62779.6,"qty":0.00000000},{"price":62709.2,"qty":0.43000000}],"asks":[],"checksum":2438003544,"timestamp":"2026-08-16T23:37:31.429927Z"}]}}
{"rx_ns": 42916804069600, "frame": {"channel":"book","type":"update","data":[{"symbol":"BTC/USD","bids":[{"price":62778.4,"qty":0.79645161}],"asks":[],"checksum":2438003544,"timestamp":"2026-08-16T23:37:31.431470Z"}]}}
{"rx_ns": 42916805909800, "frame": {"channel":"book","type":"update","data":[{"symbol":"BTC/USD","bids":[],"asks":[{"price":62805.3,"qty":0.00000000},{"price":62876.4,"qty":0.23890000}],"checksum":2438003544,"timestamp":"2026-08-16T23:37:31.433890Z"}]}}
{"rx_ns": 42916812416000, "frame": {"channel":"book","type":"update","data":[{"symbol":"BTC/USD","bids":[{"price":62780.7,"qty":0.00000000},{"price":62709.2,"qty":0.43000000}],"asks":[],"checksum":2438003544,"timestamp":"2026-08-16T23:37:31.434515Z"}]}}
{"rx_ns": 42916812477600, "frame": {"channel":"book","type":"update","data":[{"symbol":"BTC/USD","bids":[],"asks":[{"price":62800.9,"qty":2.38850205}],"checksum":2438003544,"timestamp":"2026-08-16T23:37:31.435905Z"}]}}
{"rx_ns": 42916812516900, "frame": {"channel":"book","type":"update","data":[{"symbol":"BTC/USD","bids":[{"price":62778.4,"qty":0.00000000},{"price":62707.9,"qty":0.00079734}],"asks":[],"checksum":2438003544,"timestamp":"2026-08-16T23:37:31.436780Z"}]}}
{"rx_ns": 42916826169600, "frame": {"channel":"book","type":"update","data":[{"symbol":"BTC/USD","bids":[{"price":62763.1,"qty":0.00000000},{"price":62706.5,"qty":0.00162380},{"price":62761.6,"qty":0.10294512}],"asks":[],"checksum":2438003544,"timestamp":"2026-08-16T23:37:31.446246Z"}]}}
{"rx_ns": 42916835686100, "frame": {"channel":"book","type":"update","data":[{"symbol":"BTC/USD","bids":[{"price":62773.8,"qty":0.00000000},{"price":62706.5,"qty":0.00162380},{"price":62771.4,"qty":0.08003931}],"asks":[],"checksum":2438003544,"timestamp":"2026-08-16T23:37:31.461571Z"}]}}
{"rx_ns": 42916837277700, "frame": {"channel":"book","type":"update","data":[{"symbol":"BTC/USD","bids":[{"price":62761.6,"qty":0.00000000},{"price":62703.0,"qty":0.01531807},{"price":62763.1,"qty":0.10294266}],"asks":[],"checksum":2438003544,"timestamp":"2026-08-16T23:37:31.466367Z"}]}}
{"rx_ns": 42916859157000, "frame": {"channel":"book","type":"update","data":[{"symbol":"BTC/USD","bids":[],"asks":[{"price":62805.1,"qty":0.00000000},{"price":62876.4,"qty":0.23890000},{"price":62810.8,"qty":0.00222509}],"checksum":2438003544,"timestamp":"2026-08-16T23:37:31.486089Z"}]}}
{"rx_ns": 42916890925500, "frame": {"channel":"book","type":"update","data":[{"symbol":"BTC/USD","bids":[{"price":62792.0,"qty":0.00000000},{"price":62703.0,"qty":0.01531807}],"asks":[],"checksum":1579795993,"timestamp":"2026-08-16T23:37:31.517946Z"}]}}
{"rx_ns": 42916894806500, "frame": {"channel":"book","type":"update","data":[{"symbol":"BTC/USD","bids":[{"price":62789.8,"qty":0.02131292}],"asks":[],"checksum":2234111488,"timestamp":"2026-08-16T23:37:31.519441Z"}]}}
{"rx_ns": 42916896634900, "frame": {"channel":"book","type":"update","data":[{"symbol":"BTC/USD","bids":[{"price":62778.1,"qty":0.00000000},{"price":62703.0,"qty":0.01531807}],"asks":[],"checksum":2234111488,"timestamp":"2026-08-16T23:37:31.522877Z"}]}}
{"rx_ns": 42916896690600, "frame": {"channel":"book","type":"update","data":[{"symbol":"BTC/USD","bids":[{"price":62777.4,"qty":0.00000000},{"price":62699.9,"qty":1.50000000}],"asks":[],"checksum":2234111488,"timestamp":"2026-08-16T23:37:31.522997Z"}]}}
{"rx_ns": 42916902971600, "frame": {"channel":"book","type":"update","data":[{"symbol":"BTC/USD","bids":[{"price":62780.4,"qty":0.79642650}],"asks":[],"checksum":2234111488,"timestamp":"2026-08-16T23:37:31.528145Z"}]}}
{"rx_ns": 42916903027100, "frame": {"channel":"book","type":"update","data":[{"symbol":"BTC/USD","bids":[{"price":62705.0,"qty":0.06960000}],"asks":[],"checksum":2234111488,"timestamp":"2026-08-16T23:37:31.528889Z"}]}}
{"rx_ns": 42916904169800, "frame": {"channel":"book","type":"update","data":[{"symbol":"BTC/USD","bids":[{"price":62729.9,"qty":0.00000000},{"price":62703.0,"qty":0.01531807}],"asks":[],"checksum":2234111488,"timestamp":"2026-08-16T23:37:31.531379Z"}]}}
{"rx_ns": 42916904195700, "frame": {"channel":"book","type":"update","data":[{"symbol":"BTC/USD","bids":[{"price":62760.3,"qty":0.00000000},{"price":62699.9,"qty":1.50000000}],"asks":[],"checksum":2234111488,"timestamp":"2026-08-16T23:37:31.531509Z"}]}}
{"rx_ns": 42916920601700, "frame": {"channel":"book","type":"update","data":[{"symbol":"BTC/USD","bids":[{"price":62777.3,"qty":0.15927762}],"asks":[],"checksum":2234111488,"timestamp":"2026-08-16T23:37:31.547000Z"}]}}
{"rx_ns": 42916962822500, "frame": {"channel":"book","type":"update","data":[{"symbol":"BTC/USD","bids":[{"price":62715.2,"qty":0.00000000},{"price":62699.9,"qty":1.50000000}],"asks":[],"checksum":2234111488,"timestamp":"2026-08-16T23:37:31.590612Z"}]}}
{"rx_ns": 42917005285900, "frame": {"channel":"book","type":"update","data":[{"symbol":"BTC/USD","bids":[{"price":62756.0,"qty":0.00000000},{"price":62699.7,"qty":5.58216167},{"price":62755.5,"qty":0.00303503}],"asks":[],"checksum":2234111488,"timestamp":"2026-08-16T23:37:31.633262Z"}]}}
{"rx_ns": 42917012438200, "frame": {"channel":"book","type":"update","data":[{"symbol":"BTC/USD","bids":[{"price":62789.8,"qty":0.00000000},{"price":62699.7,"qty":5.58216167}],"asks":[],"checksum":3318361441,"timestamp":"2026-08-16T23:37:31.640783Z"}]}}
{"rx_ns": 42917013911500, "frame": {"channel":"book","type":"update","data":[{"symbol":"BTC/USD","bids":[{"price":62790.7,"qty":0.02131292}],"asks":[],"checksum":2833757300,"timestamp":"2026-08-16T23:37:31.640984Z"}]}}
{"rx_ns": 42917122746500, "frame": {"channel":"book","type":"update","data":[{"symbol":"BTC/USD","bids":[{"price":62777.3,"qty":0.00000000},{"price":62699.7,"qty":5.58216167}],"asks":[],"checksum":2833757300,"timestamp":"2026-08-16T23:37:31.747976Z"}]}}
{"rx_ns": 42917147179200, "frame": {"channel":"book","type":"update","data":[{"symbol":"BTC/USD","bids":[{"price":62790.7,"qty":0.00000000},{"price":62698.8,"qty":0.05517271}],"asks":[],"checksum":3318361441,"timestamp":"2026-08-16T23:37:31.775513Z"}]}}
{"rx_ns": 42917149380800, "frame": {"channel":"book","type":"update","data":[{"symbol":"BTC/USD","bids":[{"price":62791.7,"qty":0.02131292}],"asks":[],"checksum":2131541990,"timestamp":"2026-08-16T23:37:31.775860Z"}]}}
{"rx_ns": 42917158199500, "frame": {"channel":"book","type":"update","data":[{"symbol":"BTC/USD","bids":[{"price":62728.5,"qty":0.00011160}],"asks":[],"checksum":2131541990,"timestamp":"2026-08-16T23:37:31.784701Z"}]}}
{"rx_ns": 42917168760100, "frame": {"channel":"book","type":"update","data":[{"symbol":"BTC/USD","bids":[{"price":62728.6,"qty":5.73009945}],"asks":[],"checksum":2131541990,"timestamp":"2026-08-16T23:37:31.794984Z"}]}}
{"rx_ns": 42917170020100, "frame": {"channel":"book","type":"update","data":[{"symbol":"BTC/USD","bids":[{"price":62777.4,"qty":0.15927762}],"asks":[],"checksum":2131541990,"timestamp":"2026-08-16T23:37:31.796164Z"}]}}
{"rx_ns": 42917172068200, "frame": {"channel":"book","type":"update","data":[{"symbol":"BTC/USD","bids":[{"price":62774.1,"qty":0.65558669}],"asks":[],"checksum":2131541990,"timestamp":"2026-08-16T23:37:31.800119Z"}]}}
{"rx_ns": 42917380046900, "frame": {"channel":"book","type":"update","data":[{"symbol":"BTC/USD","bids":[],"asks":[{"price":62805.2,"qty":0.00000000},{"price":62876.4,"qty":0.23890000},{"price":62805.5,"qty":1.59575715}],"checksum":2131541990,"timestamp":"2026-08-16T23:37:32.006215Z"}]}}
{"rx_ns": 42917403782600, "frame": {"channel":"book","type":"update","data":[{"symbol":"BTC/USD","bids":[{"price":62729.7,"qty":0.05433528}],"asks":[],"checksum":2131541990,"timestamp":"2026-08-16T23:37:32.031564Z"}]}}
{"rx_ns": 42917417182500, "frame": {"channel":"book","type":"update","data":[{"symbol":"BTC/USD","bids":[],"asks":[{"price":62828.6,"qty":0.00000000},{"price":62876.4,"qty":0.23890000}],"checksum":2131541990,"timestamp":"2026-08-16T23:37:32.039178Z"}]}}
{"rx_ns": 42917417248900, "frame": {"channel":"book","type":"update","data":[{"symbol":"BTC/USD","bids":[],"asks":[{"price":62832.5,"qty":0.00000000},{"price":62878.8,"qty":0.11123578}],"checksum":2131541990,"timestamp":"2026-08-16T23:37:32.039221Z"}]}}
{"rx_ns": 42917420173100, "frame": {"channel":"book","type":"update","data":[{"symbol":"BTC/USD","bids":[],"asks":[{"price":62828.5,"qty":0.99520632}],"checksum":2131541990,"timestamp":"2026-08-16T23:37:32.047875Z"}]}}
{"rx_ns": 42917420209600, "frame": {"channel":"book","type":"update","data":[{"symbol":"BTC/USD","bids":[],"asks":[{"price":62832.4,"qty":1.46902607}],"checksum":2131541990,"timestamp":"2026-08-16T23:37:32.048324Z"}]}}
{"rx_ns": 42917548360200, "frame": {"channel":"book","type":"update","data":[{"symbol":"BTC/USD","bids":[{"price":62778.3,"qty":0.79645294}],"asks":[],"checksum":2131541990,"timestamp":"2026-08-16T23:37:32.175965Z"}]}}
{"rx_ns": 42917627365900, "frame": {"channel":"book","type":"update","data":[{"symbol":"BTC/USD","bids":[],"asks":[{"price":62793.6,"qty":5.17992472},{"price":62793.6,"qty":5.17809965}],"checksum":3025085744,"timestamp":"2026-08-16T23:37:32.249350Z"}]}}
{"rx_ns": 42917627421000, "frame": {"channel":"book","type":"update","data":[{"symbol":"BTC/USD","bids":[],"asks":[{"price":62793.6,"qty":5.10009965}],"checksum":4240877949,"timestamp":"2026-08-16T23:37:32.251395Z"}]}}
{"rx_ns": 42917668759800, "frame": {"channel":"heartbeat"}}
{"rx_ns": 42917706537800, "frame": {"channel":"book","type":"update","data":[{"symbol":"BTC/USD","bids":[{"price":62777.4,"qty":0.00000000},{"price":62706.5,"qty":0.00162380}],"asks":[],"checksum":4240877949,"timestamp":"2026-08-16T23:37:32.335022Z"}]}}
{"rx_ns": 42917717920400, "frame": {"channel":"book","type":"update","data":[{"symbol":"BTC/USD","bids":[{"price":62777.5,"qty":0.15927762}],"asks":[],"checksum":4240877949,"timestamp":"2026-08-16T23:37:32.346237Z"}]}}
{"rx_ns": 42917796162600, "frame": {"channel":"book","type":"update","data":[{"symbol":"BTC/USD","bids":[{"price":62731.8,"qty":0.00000000},{"price":62706.5,"qty":0.00162380},{"price":62721.0,"qty":0.70609000}],"asks":[],"checksum":4240877949,"timestamp":"2026-08-16T23:37:32.421955Z"}]}}
{"rx_ns": 42917796231900, "frame": {"channel":"book","type":"update","data":[{"symbol":"BTC/USD","bids":[{"price":62744.8,"qty":2.12530196},{"price":62718.0,"qty":0.35596944}],"asks":[],"checksum":4240877949,"timestamp":"2026-08-16T23:37:32.422048Z"}]}}
{"rx_ns": 42917820040400, "frame": {"channel":"book","type":"update","data":[{"symbol":"BTC/USD","bids":[{"price":62777.5,"qty":0.00000000},{"price":62706.5,"qty":0.00162380}],"asks":[],"checksum":4240877949,"timestamp":"2026-08-16T23:37:32.446641Z"}]}}
{"rx_ns": 42917868149100, "frame": {"channel":"book","type":"update","data":[{"symbol":"BTC/USD","bids":[{"price":62778.1,"qty":0.15927762}],"asks":[],"checksum":4240877949,"timestamp":"2026-08-16T23:37:32.496261Z"}]}}
{"rx_ns": 42918360514100, "frame": {"channel":"book","type":"update","data":[{"symbol":"BTC/USD","bids":[],"asks":[{"price":62830.7,"qty":0.00000000},{"price":62878.8,"qty":0.11123578},{"price":62831.0,"qty":0.00318497}],"checksum":4240877949,"timestamp":"2026-08-16T23:37:32.987006Z"}]}}
{"rx_ns": 42918360602800, "frame": {"channel":"book","type":"update","data":[{"symbol":"BTC/USD","bids":[],"asks":[{"price":62802.4,"qty":0.00000000},{"price":62878.8,"qty":0.11123578},{"price":62802.7,"qty":0.00318497}],"checksum":4240877949,"timestamp":"2026-08-16T23:37:32.987293Z"}]}}
{"rx_ns": 42918360627200, "frame": {"channel":"book","type":"update","data":[{"symbol":"BTC/USD","bids":[{"price":62783.0,"qty":0.00000000},{"price":62706.5,"qty":0.00162380},{"price":62783.3,"qty":0.00318497}],"asks":[],"checksum":2942104313,"timestamp":"2026-08-16T23:37:32.987579Z"}]}}
{"rx_ns": 42918360638700, "frame": {"channel":"book","type":"update","data":[{"symbol":"BTC/USD","bids":[{"price":62754.7,"qty":0.00000000},{"price":62706.5,"qty":0.00162380},{"price":62755.0,"qty":0.01364628}],"asks":[],"checksum":2942104313,"timestamp":"2026-08-16T23:37:32.987748Z"}]}}
{"rx_ns": 42918670203000, "frame": {"channel":"heartbeat"}}
{"rx_ns": 42918820421600, "frame": {"channel":"book","type":"update","data":[{"symbol":"BTC/USD","bids":[{"price":62778.1,"qty":0.00000000},{"price":62703.0,"qty":0.01531807}],"asks":[],"checksum":2942104313,"timestamp":"2026-08-16T23:37:33.446844Z"}]}}
{"rx_ns": 42918821523500, "frame": {"channel":"book","type":"update","data":[{"symbol":"BTC/USD","bids":[{"price":62705.0,"qty":0.06960000}],"asks":[],"checksum":2942104313,"timestamp":"2026-08-16T23:37:33.450308Z"}]}}
{"rx_ns": 42918867526900, "frame": {"channel":"book","type":"update","data":[{"symbol":"BTC/USD","bids":[{"price":62778.2,"qty":0.15927762}],"asks":[],"checksum":2942104313,"timestamp":"2026-08-16T23:37:33.496205Z"}]}}
{"rx_ns": 42919531256600, "frame": {"channel":"book","type":"update","data":[{"symbol":"BTC/USD","bids":[{"price":62728.6,"qty":0.00000000},{"price":62703.0,"qty":0.01531807}],"asks":[],"checksum":2942104313,"timestamp":"2026-08-16T23:37:34.158568Z"}]}}
{"rx_ns": 42919535542300, "frame": {"channel":"book","type":"update","data":[{"symbol":"BTC/USD","bids":[{"price":62705.0,"qty":0.06960000}],"asks":[],"checksum":2942104313,"timestamp":"2026-08-16T23:37:34.163250Z"}]}}
{"rx_ns": 42919535628500, "frame": {"channel":"book","type":"update","data":[{"symbol":"BTC/USD","bids":[{"price":62728.7,"qty":5.60856230}],"asks":[],"checksum":2942104313,"timestamp":"2026-08-16T23:37:34.163557Z"}]}}
{"rx_ns": 42919668172900, "frame": {"channel":"heartbeat"}}
{"rx_ns": 42919758494800, "frame": {"channel":"book","type":"update","data":[{"symbol":"BTC/USD","bids":[],"asks":[{"price":62828.5,"qty":0.00000000},{"price":62878.8,"qty":0.11123578}],"checksum":2942104313,"timestamp":"2026-08-16T23:37:34.386845Z"}]}}
{"rx_ns": 42919759841100, "frame": {"channel":"book","type":"update","data":[{"symbol":"BTC/USD","bids":[],"asks":[{"price":62832.4,"qty":0.01598519}],"checksum":2942104313,"timestamp":"2026-08-16T23:37:34.386956Z"}]}}
{"rx_ns": 42919761231300, "frame": {"channel":"book","type":"update","data":[{"symbol":"BTC/USD","bids":[],"asks":[{"price":62832.7,"qty":0.00000000},{"price":62879.5,"qty":0.02131292}],"checksum":2942104313,"timestamp":"2026-08-16T23:37:34.387949Z"}]}}
{"rx_ns": 42919764156200, "frame": {"channel":"book","type":"update","data":[{"symbol":"BTC/USD","bids":[],"asks":[{"price":62879.4,"qty":0.06960000}],"checksum":2942104313,"timestamp":"2026-08-16T23:37:34.390662Z"}]}}
{"rx_ns": 42919778128300, "frame": {"channel":"book","type":"update","data":[{"symbol":"BTC/USD","bids":[],"asks":[{"price":62828.4,"qty":0.93305453}],"checksum":2942104313,"timestamp":"2026-08-16T23:37:34.402226Z"}]}}
{"rx_ns": 42919778194800, "frame": {"channel":"book","type":"update","data":[{"symbol":"BTC/USD","bids":[],"asks":[{"price":62828.7,"qty":0.99520632}],"checksum":2942104313,"timestamp":"2026-08-16T23:37:34.402490Z"}]}}
{"rx_ns": 42919778215300, "frame": {"channel":"book","type":"update","data":[{"symbol":"BTC/USD","bids":[],"asks":[{"price":62832.3,"qty":0.54356640}],"checksum":2942104313,"timestamp":"2026-08-16T23:37:34.402604Z"}]}}
{"rx_ns": 42920104415200, "frame": {"channel":"book","type":"update","data":[{"symbol":"BTC/USD","bids":[{"price":62762.8,"qty":0.00000000},{"price":62703.0,"qty":0.01531807}],"asks":[],"checksum":2942104313,"timestamp":"2026-08-16T23:37:34.731674Z"}]}}
{"rx_ns": 42920105884700, "frame": {"channel":"book","type":"update","data":[{"symbol":"BTC/USD","bids":[{"price":62705.0,"qty":0.06960000}],"asks":[],"checksum":2942104313,"timestamp":"2026-08-16T23:37:34.734274Z"}]}}
{"rx_ns": 42920213335300, "frame": {"channel":"book","type":"update","data":[{"symbol":"BTC/USD","bids":[{"price":62778.2,"qty":0.00000000},{"price":62703.0,"qty":0.01531807}],"asks":[],"checksum":2942104313,"timestamp":"2026-08-16T23:37:34.841538Z"}]}}
{"rx_ns": 42920217979600, "frame": {"channel":"book","type":"update","data":[{"symbol":"BTC/USD","bids":[{"price":62778.3,"qty":0.95573056}],"asks":[],"checksum":2942104313,"timestamp":"2026-08-16T23:37:34.846358Z"}]}}
{"rx_ns": 42920260938700, "frame": {"channel":"book","type":"update","data":[{"symbol":"BTC/USD","bids":[],"asks":[{"price":62820.1,"qty":1.02959330}],"checksum":2942104313,"timestamp":"2026-08-16T23:37:34.889805Z"}]}}
{"rx_ns": 42920382940600, "frame": {"channel":"book","type":"update","data":[{"symbol":"BTC/USD","bids":[],"asks":[{"price":62808.9,"qty":0.00000000},{"price":62875.9,"qty":0.00159000}],"checksum":2942104313,"timestamp":"2026-08-16T23:37:35.010370Z"}]}}
{"rx_ns": 42920383007200, "frame": {"channel":"book","type":"update","data":[{"symbol":"BTC/USD","bids":[],"asks":[{"price":62807.2,"qty":0.02865913}],"checksum":2942104313,"timestamp":"2026-08-16T23:37:35.010442Z"}]}}
{"rx_ns": 42920668503500, "frame": {"channel":"heartbeat"}}
{"rx_ns": 42920714004100, "frame": {"channel":"book","type":"update","data":[{"symbol":"BTC/USD","bids":[],"asks":[{"price":62809.9,"qty":0.00000000},{"price":62875.9,"qty":0.00159000}],"checksum":2942104313,"timestamp":"2026-08-16T23:37:35.340816Z"}]}}
{"rx_ns": 42920716107100, "frame": {"channel":"book","type":"update","data":[{"symbol":"BTC/USD","bids":[],"asks":[{"price":62808.0,"qty":0.00318430}],"checksum":2942104313,"timestamp":"2026-08-16T23:37:35.341098Z"}]}}
{"rx_ns": 42921403870700, "frame": {"channel":"book","type":"update","data":[{"symbol":"BTC/USD","bids":[{"price":62760.0,"qty":0.03422757}],"asks":[],"checksum":2942104313,"timestamp":"2026-08-16T23:37:36.032038Z"}]}}
{"rx_ns": 42921671992600, "frame": {"channel":"heartbeat"}}
{"rx_ns": 42921721678100, "frame": {"channel":"book","type":"update","data":[{"symbol":"BTC/USD","bids":[{"price":62763.8,"qty":0.01300000}],"asks":[],"checksum":2942104313,"timestamp":"2026-08-16T23:37:36.349635Z"}]}}
{"rx_ns": 42921762502800, "frame": {"channel":"book","type":"update","data":[{"symbol":"BTC/USD","bids":[],"asks":[{"price":62866.0,"qty":0.00000000},{"price":62875.9,"qty":0.00159000}],"checksum":2942104313,"timestamp":"2026-08-16T23:37:36.390930Z"}]}}
{"rx_ns": 42921762906100, "frame": {"channel":"book","type":"update","data":[{"symbol":"BTC/USD","bids":[],"asks":[{"price":62848.0,"qty":0.55709100}],"checksum":2942104313,"timestamp":"2026-08-16T23:37:36.391952Z"}]}}
{"rx_ns": 42921882654900, "frame": {"channel":"book","type":"update","data":[{"symbol":"BTC/USD","bids":[{"price":62728.7,"qty":0.00000000},{"price":62703.0,"qty":0.01531807}],"asks":[],"checksum":2942104313,"timestamp":"2026-08-16T23:37:36.503748Z"}]}}
{"rx_ns": 42921882742600, "frame": {"channel":"book","type":"update","data":[{"symbol":"BTC/USD","bids":[{"price":62705.0,"qty":0.06960000}],"asks":[],"checksum":2942104313,"timestamp":"2026-08-16T23:37:36.505212Z"}]}}
{"rx_ns": 42921889858800, "frame": {"channel":"book","type":"update","data":[{"symbol":"BTC/USD","bids":[{"price":62728.8,"qty":5.50085814}],"asks":[],"checksum":2942104313,"timestamp":"2026-08-16T23:37:36.509950Z"}]}}
{"rx_ns": 42922025625600, "frame": {"channel":"book","type":"update","data":[{"symbol":"BTC/USD","bids":[],"asks":[{"price":62828.7,"qty":0.00000000},{"price":62875.9,"qty":0.00159000}],"checksum":2942104313,"timestamp":"2026-08-16T23:37:36.654291Z"}]}}
{"rx_ns": 42922025714000, "frame": {"channel":"book","type":"update","data":[{"symbol":"BTC/USD","bids":[],"asks":[{"price":62828.4,"qty":0.00000000},{"price":62876.4,"qty":0.23890000}],"checksum":2942104313,"timestamp":"2026-08-16T23:37:36.654312Z"}]}}
{"rx_ns": 42922029183200, "frame": {"channel":"book","type":"update","data":[{"symbol":"BTC/USD","bids":[],"asks":[{"price":62832.3,"qty":0.00000000},{"price":62878.8,"qty":0.11123578}],"checksum":2942104313,"timestamp":"2026-08-16T23:37:36.654586Z"}]}}
{"rx_ns": 42922047053000, "frame": {"channel":"book","type":"update","data":[{"symbol":"BTC/USD","bids":[],"asks":[{"price":62833.0,"qty":0.93656722}],"checksum":2942104313,"timestamp":"2026-08-16T23:37:36.672615Z"}]}}
{"rx_ns": 42922047159400, "frame": {"channel":"book","type":"update","data":[{"symbol":"BTC/USD","bids":[],"asks":[{"price":62828.6,"qty":1.05735811}],"checksum":2942104313,"timestamp":"2026-08-16T23:37:36.672660Z"}]}}
{"rx_ns": 42922047174800, "frame": {"channel":"book","type":"update","data":[{"symbol":"BTC/USD","bids":[],"asks":[{"price":62828.3,"qty":0.77767506}],"checksum":2942104313,"timestamp":"2026-08-16T23:37:36.672707Z"}]}}
{"rx_ns": 42922172428500, "frame": {"channel":"book","type":"update","data":[{"symbol":"BTC/USD","bids":[],"asks":[{"price":62793.6,"qty":5.09877786}],"checksum":1980689788,"timestamp":"2026-08-16T23:37:36.798277Z"}]}}
{"rx_ns": 42922182481300, "frame": {"channel":"book","type":"update","data":[{"symbol":"BTC/USD","bids":[],"asks":[{"price":62793.6,"qty":5.17677786}],"checksum":528254587,"timestamp":"2026-08-16T23:37:36.800332Z"}]}}
{"rx_ns": 42922199800500, "frame": {"channel":"book","type":"update","data":[{"symbol":"BTC/USD","bids":[{"price":62775.1,"qty":0.00000000},{"price":62703.0,"qty":0.01531807}],"asks":[],"checksum":528254587,"timestamp":"2026-08-16T23:37:36.827998Z"}]}}
{"rx_ns": 42922200235900, "frame": {"channel":"book","type":"update","data":[{"symbol":"BTC/USD","bids":[{"price":62766.3,"qty":0.00000000},{"price":62699.9,"qty":1.50000000}],"asks":[],"checksum":528254587,"timestamp":"2026-08-16T23:37:36.829754Z"}]}}
{"rx_ns": 42922202096500, "frame": {"channel":"book","type":"update","data":[{"symbol":"BTC/USD","bids":[{"price":62780.4,"qty":0.00000000},{"price":62699.7,"qty":5.58216167}],"asks":[],"checksum":528254587,"timestamp":"2026-08-16T23:37:36.829815Z"}]}}
{"rx_ns": 42922202148000, "frame": {"channel":"book","type":"update","data":[{"symbol":"BTC/USD","bids":[{"price":62778.3,"qty":0.15927762}],"asks":[],"checksum":528254587,"timestamp":"2026-08-16T23:37:36.829942Z"}]}}
{"rx_ns": 42922203810900, "frame": {"channel":"book","type":"update","data":[{"symbol":"BTC/USD","bids":[{"price":62705.0,"qty":0.06960000}],"asks":[],"checksum":528254587,"timestamp":"2026-08-16T23:37:36.831408Z"}]}}
{"rx_ns": 42922205792600, "frame": {"channel":"book","type":"update","data":[{"symbol":"BTC/USD","bids":[{"price":62772.8,"qty":0.79652267}],"asks":[],"checksum":528254587,"timestamp":"2026-08-16T23:37:36.832610Z"}]}}
{"rx_ns": 42922205812300, "frame": {"channel":"book","type":"update","data":[{"symbol":"BTC/USD","bids":[{"price":62770.7,"qty":0.80110368}],"asks":[],"checksum":528254587,"timestamp":"2026-08-16T23:37:36.832787Z"}]}}
{"rx_ns": 42922205821500, "frame": {"channel":"book","type":"update","data":[{"symbol":"BTC/USD","bids":[{"price":62768.0,"qty":0.79658337}],"asks":[],"checksum":528254587,"timestamp":"2026-08-16T23:37:36.832906Z"}]}}
{"rx_ns": 42922205828600, "frame": {"channel":"book","type":"update","data":[{"symbol":"BTC/USD","bids":[{"price":62760.6,"qty":2.39003338}],"asks":[],"checksum":528254587,"timestamp":"2026-08-16T23:37:36.833300Z"}]}}
{"rx_ns": 42922208950100, "frame": {"channel":"book","type":"update","data":[{"symbol":"BTC/USD","bids":[{"price":62775.0,"qty":0.01017606}],"asks":[],"checksum":528254587,"timestamp":"2026-08-16T23:37:36.833821Z"}]}}
{"rx_ns": 42922208982900, "frame": {"channel":"book","type":"update","data":[{"symbol":"BTC/USD","bids":[{"price":62772.8,"qty":0.00000000},{"price":62706.5,"qty":0.00162380}],"asks":[],"checksum":528254587,"timestamp":"2026-08-16T23:37:36.834736Z"}]}}
{"rx_ns": 42922208998500, "frame": {"channel":"book","type":"update","data":[{"symbol":"BTC/USD","bids":[{"price":62735.6,"qty":0.00000000},{"price":62705.0,"qty":0.06960000}],"asks":[],"checksum":528254587,"timestamp":"2026-08-16T23:37:36.835513Z"}]}}
{"rx_ns": 42922210672200, "frame": {"channel":"book","type":"update","data":[{"symbol":"BTC/USD","bids":[{"price":62705.0,"qty":0.00000000},{"price":62703.0,"qty":0.01531807}],"asks":[],"checksum":528254587,"timestamp":"2026-08-16T23:37:36.835897Z"}]}}
{"rx_ns": 42922210705600, "frame": {"channel":"book","type":"update","data":[{"symbol":"BTC/USD","bids":[{"price":62770.7,"qty":0.00455372}],"asks":[],"checksum":528254587,"timestamp":"2026-08-16T23:37:36.836771Z"}]}}
{"rx_ns": 42922212212300, "frame": {"channel":"book","type":"update","data":[{"symbol":"BTC/USD","bids":[{"price":62705.0,"qty":0.06960000}],"asks":[],"checksum":528254587,"timestamp":"2026-08-16T23:37:36.838374Z"}]}}
{"rx_ns": 42922235407600, "frame": {"channel":"book","type":"update","data":[{"symbol":"BTC/USD","bids":[{"price":62768.0,"qty":0.00000000},{"price":62703.0,"qty":0.01531807}],"asks":[],"checksum":528254587,"timestamp":"2026-08-16T23:37:36.863779Z"}]}}
{"rx_ns": 42922316218300, "frame": {"channel":"book","type":"update","data":[{"symbol":"BTC/USD","bids":[{"price":62778.3,"qty":0.00000000},{"price":62699.9,"qty":1.50000000}],"asks":[],"checksum":528254587,"timestamp":"2026-08-16T23:37:36.944785Z"}]}}
{"rx_ns": 42922317882700, "frame": {"channel":"book","type":"update","data":[{"symbol":"BTC/USD","bids":[{"price":62778.4,"qty":0.15927762}],"asks":[],"checksum":528254587,"timestamp":"2026-08-16T23:37:36.946337Z"}]}}
{"rx_ns": 42922376859400, "frame": {"channel":"book","type":"update","data":[{"symbol":"BTC/USD","bids":[{"price":62760.6,"qty":0.00000000},{"price":62699.9,"qty":1.50000000}],"asks":[],"checksum":528254587,"timestamp":"2026-08-16T23:37:37.004904Z"}]}}
{"rx_ns": 42922378273600, "frame": {"channel":"book","type":"update","data":[{"symbol":"BTC/USD","bids":[{"price":62779.2,"qty":0.79644107}],"asks":[],"checksum":528254587,"timestamp":"2026-08-16T23:37:37.006141Z"}]}}
{"rx_ns": 42922438189500, "frame": {"channel":"book","type":"update","data":[{"symbol":"BTC/USD","bids":[{"price":62764.7,"qty":0.00000000},{"price":62699.9,"qty":1.50000000}],"asks":[{"price":62822.2,"qty":0.00000000},{"price":62875.9,"qty":0.00159000}],"checksum":528254587,"timestamp":"2026-08-16T23:37:37.063503Z"}]}}
{"rx_ns": 42922443573100, "frame": {"channel":"book","type":"update","data":[{"symbol":"BTC/USD","bids":[{"price":62733.8,"qty":0.03248407}],"asks":[],"checksum":528254587,"timestamp":"2026-08-16T23:37:37.069696Z"}]}}
{"rx_ns": 42922443609100, "frame": {"channel":"book","type":"update","data":[{"symbol":"BTC/USD","bids":[],"asks":[{"price":62851.4,"qty":0.00000000},{"price":62876.4,"qty":0.23890000}],"checksum":528254587,"timestamp":"2026-08-16T23:37:37.070033Z"}]}}
{"rx_ns": 42922546142200, "frame": {"channel":"book","type":"update","data":[{"symbol":"BTC/USD","bids":[{"price":62777.0,"qty":0.79647000}],"asks":[],"checksum":528254587,"timestamp":"2026-08-16T23:37:37.174177Z"}]}}
{"rx_ns": 42922547294000, "frame": {"channel":"book","type":"update","data":[{"symbol":"BTC/USD","bids":[{"price":62773.1,"qty":0.79651925}],"asks":[],"checksum":528254587,"timestamp":"2026-08-16T23:37:37.174633Z"}]}}
{"rx_ns": 42922547318900, "frame": {"channel":"book","type":"update","data":[{"symbol":"BTC/USD","bids":[{"price":62765.6,"qty":2.38984101}],"asks":[],"checksum":528254587,"timestamp":"2026-08-16T23:37:37.174743Z"}]}}
{"rx_ns": 42922550226800, "frame": {"channel":"book","type":"update","data":[{"symbol":"BTC/USD","bids":[{"price":62775.0,"qty":0.00000000},{"price":62706.5,"qty":0.00162380}],"asks":[],"checksum":528254587,"timestamp":"2026-08-16T23:37:37.177001Z"}]}}
{"rx_ns": 42922618941800, "frame": {"channel":"book","type":"update","data":[{"symbol":"BTC/USD","bids":[],"asks":[{"price":62842.8,"qty":0.07141442}],"checksum":528254587,"timestamp":"2026-08-16T23:37:37.247540Z"}]}}
{"rx_ns": 42922670007500, "frame": {"channel":"heartbeat"}}
{"rx_ns": 42922729721400, "frame": {"channel":"book","type":"update","data":[{"symbol":"BTC/USD","bids":[{"price":62779.2,"qty":0.00000000},{"price":62703.0,"qty":0.01531807}],"asks":[],"checksum":528254587,"timestamp":"2026-08-16T23:37:37.358118Z"}]}}
{"rx_ns": 42922731101100, "frame": {"channel":"book","type":"update","data":[{"symbol":"BTC/USD","bids":[{"price":62779.8,"qty":0.79643358}],"asks":[],"checksum":528254587,"timestamp":"2026-08-16T23:37:37.359600Z"}]}}
{"rx_ns": 42922732619500, "frame": {"channel":"book","type":"update","data":[{"symbol":"BTC/USD","bids":[{"price":62774.8,"qty":0.01015299}],"asks":[],"checksum":528254587,"timestamp":"2026-08-16T23:37:37.361149Z"}]}}
{"rx_ns": 42922734029000, "frame": {"channel":"book","type":"update","data":[{"symbol":"BTC/USD","bids":[{"price":62774.8,"qty":0.00000000},{"price":62706.5,"qty":0.00162380}],"asks":[],"checksum":528254587,"timestamp":"2026-08-16T23:37:37.362197Z"}]}}
{"rx_ns": 42922898569000, "frame": {"channel":"book","type":"update","data":[{"symbol":"BTC/USD","bids":[{"price":62760.0,"qty":0.00000000},{"price":62703.0,"qty":0.01531807}],"asks":[],"checksum":528254587,"timestamp":"2026-08-16T23:37:37.525970Z"}]}}
{"rx_ns": 42922901231100, "frame": {"channel":"book","type":"update","data":[{"symbol":"BTC/USD","bids":[{"price":62705.0,"qty":0.06960000}],"asks":[],"checksum":528254587,"timestamp":"2026-08-16T23:37:37.529853Z"}]}}
{"rx_ns": 42922918497100, "frame": {"channel":"book","type":"update","data":[{"symbol":"BTC/USD","bids":[],"asks":[{"price":62842.8,"qty":0.04012144}],"checksum":528254587,"timestamp":"2026-08-16T23:37:37.546936Z"}]}}
{"rx_ns": 42923004706200, "frame": {"channel":"book","type":"update","data":[{"symbol":"BTC/USD","bids":[{"price":62762.2,"qty":0.00080000}],"asks":[{"price":62812.6,"qty":0.00080000}],"checksum":528254587,"timestamp":"2026-08-16T23:37:37.633332Z"}]}}
{"rx_ns": 42923221294200, "frame": {"channel":"book","type":"update","data":[{"symbol":"BTC/USD","bids":[{"price":62778.4,"qty":0.00000000},{"price":62703.0,"qty":0.01531807}],"asks":[],"checksum":528254587,"timestamp":"2026-08-16T23:37:37.846234Z"}]}}
{"rx_ns": 42923221349600, "frame": {"channel":"book","type":"update","data":[{"symbol":"BTC/USD","bids":[],"asks":[{"price":62843.4,"qty":0.03222929}],"checksum":528254587,"timestamp":"2026-08-16T23:37:37.846932Z"}]}}
{"rx_ns": 42923221379400, "frame": {"channel":"book","type":"update","data":[{"symbol":"BTC/USD","bids":[{"price":62705.0,"qty":0.06960000}],"asks":[],"checksum":528254587,"timestamp":"2026-08-16T23:37:37.847832Z"}]}}
{"rx_ns": 42923268686600, "frame": {"channel":"book","type":"update","data":[{"symbol":"BTC/USD","bids":[{"price":62778.3,"qty":0.15927762}],"asks":[],"checksum":528254587,"timestamp":"2026-08-16T23:37:37.896400Z"}]}}
{"rx_ns": 42923578182700, "frame": {"channel":"book","type":"update","data":[{"symbol":"BTC/USD","bids":[],"asks":[{"price":62822.3,"qty":0.00000000},{"price":62875.9,"qty":0.00159000},{"price":62822.1,"qty":0.28000000}],"checksum":528254587,"timestamp":"2026-08-16T23:37:38.204802Z"}]}}
{"rx_ns": 42923597006000, "frame": {"channel":"book","type":"update","data":[{"symbol":"BTC/USD","bids":[],"asks":[{"price":62822.1,"qty":0.00000000},{"price":62875.9,"qty":0.00159000},{"price":62821.9,"qty":0.28000000}],"checksum":528254587,"timestamp":"2026-08-16T23:37:38.224782Z"}]}}
{"rx_ns": 42923669552900, "frame": {"channel":"heartbeat"}}
{"rx_ns": 42923743969800, "frame": {"channel":"book","type":"update","data":[{"symbol":"BTC/USD","bids":[],"asks":[{"price":62805.5,"qty":0.00000000},{"price":62875.9,"qty":0.00159000},{"price":62810.8,"qty":1.59798224}],"checksum":528254587,"timestamp":"2026-08-16T23:37:38.371757Z"}]}}
{"rx_ns": 42923744039200, "frame": {"channel":"book","type":"update","data":[{"symbol":"BTC/USD","bids":[{"price":62763.1,"qty":0.00000000},{"price":62703.0,"qty":0.01531807},{"price":62765.7,"qty":0.10293839}],"asks":[],"checksum":528254587,"timestamp":"2026-08-16T23:37:38.371835Z"}]}}
{"rx_ns": 42923762004800, "frame": {"channel":"book","type":"update","data":[{"symbol":"BTC/USD","bids":[{"price":62765.7,"qty":0.00000000},{"price":62703.0,"qty":0.01531807},{"price":62763.1,"qty":0.10294266}],"asks":[],"checksum":528254587,"timestamp":"2026-08-16T23:37:38.390396Z"}]}}
{"rx_ns": 42923853053800, "frame": {"channel":"book","type":"update","data":[{"symbol":"BTC/USD","bids":[],"asks":[{"price":62810.8,"qty":0.00222509},{"price":62805.5,"qty":1.59575715}],"checksum":528254587,"timestamp":"2026-08-16T23:37:38.481381Z"}]}}
{"rx_ns": 42923944692600, "frame": {"channel":"book","type":"update","data":[{"symbol":"BTC/USD","bids":[{"price":62763.1,"qty":0.00000000},{"price":62703.0,"qty":0.01531807},{"price":62765.7,"qty":0.10293839}],"asks":[],"checksum":528254587,"timestamp":"2026-08-16T23:37:38.572661Z"}]}}
{"rx_ns": 42923944760800, "frame": {"channel":"book","type":"update","data":[{"symbol":"BTC/USD","bids":[],"asks":[{"price":62805.5,"qty":0.00000000},{"price":62875.9,"qty":0.00159000},{"price":62810.8,"qty":1.59798224}],"checksum":528254587,"timestamp":"2026-08-16T23:37:38.572705Z"}]}}
{"rx_ns": 42923952700000, "frame": {"channel":"book","type":"update","data":[{"symbol":"BTC/USD","bids":[{"price":62777.0,"qty":0.00000000},{"price":62703.0,"qty":0.01531807}],"asks":[],"checksum":528254587,"timestamp":"2026-08-16T23:37:38.578207Z"}]}}
{"rx_ns": 42923952764400, "frame": {"channel":"book","type":"update","data":[{"symbol":"BTC/USD","bids":[{"price":62779.8,"qty":0.00000000},{"price":62699.9,"qty":1.50000000}],"asks":[],"checksum":528254587,"timestamp":"2026-08-16T23:37:38.578417Z"}]}}
{"rx_ns": 42923952801800, "frame": {"channel":"book","type":"update","data":[{"symbol":"BTC/USD","bids":[{"price":62780.4,"qty":0.79642601}],"asks":[],"checksum":528254587,"timestamp":"2026-08-16T23:37:38.580133Z"}]}}
{"rx_ns": 42923952813800, "frame": {"channel":"book","type":"update","data":[{"symbol":"BTC/USD","bids":[{"price":62778.3,"qty":0.95573092}],"asks":[],"checksum":528254587,"timestamp":"2026-08-16T23:37:38.580383Z"}]}}
{"rx_ns": 42923954064900, "frame": {"channel":"book","type":"update","data":[{"symbol":"BTC/USD","bids":[{"price":62705.0,"qty":0.06960000}],"asks":[],"checksum":528254587,"timestamp":"2026-08-16T23:37:38.580975Z"}]}}
{"rx_ns": 42923955811000, "frame": {"channel":"book","type":"update","data":[{"symbol":"BTC/USD","bids":[{"price":62775.1,"qty":0.01018783}],"asks":[],"checksum":528254587,"timestamp":"2026-08-16T23:37:38.582173Z"}]}}
{"rx_ns": 42923955857100, "frame": {"channel":"book","type":"update","data":[{"symbol":"BTC/USD","bids":[{"price":62775.1,"qty":0.00000000},{"price":62703.0,"qty":0.01531807}],"asks":[],"checksum":528254587,"timestamp":"2026-08-16T23:37:38.583906Z"}]}}
{"rx_ns": 42923957949600, "frame": {"channel":"book","type":"update","data":[{"symbol":"BTC/USD","bids":[{"price":62705.0,"qty":0.06960000}],"asks":[],"checksum":528254587,"timestamp":"2026-08-16T23:37:38.587172Z"}]}}
{"rx_ns": 42923996282400, "frame": {"channel":"book","type":"update","data":[{"symbol":"BTC/USD","bids":[{"price":62765.7,"qty":0.00000000},{"price":62703.0,"qty":0.01531807},{"price":62763.1,"qty":0.10294266}],"asks":[],"checksum":528254587,"timestamp":"2026-08-16T23:37:38.621424Z"}]}}
{"rx_ns": 42924012304300, "frame": {"channel":"book","type":"update","data":[{"symbol":"BTC/USD","bids":[{"price":62763.1,"qty":0.00000000},{"price":62703.0,"qty":0.01531807},{"price":62766.1,"qty":0.10293774}],"asks":[],"checksum":528254587,"timestamp":"2026-08-16T23:37:38.639408Z"}]}}
{"rx_ns": 42924037278500, "frame": {"channel":"book","type":"update","data":[{"symbol":"BTC/USD","bids":[],"asks":[{"price":62843.4,"qty":0.00000000},{"price":62876.4,"qty":0.23890000}],"checksum":528254587,"timestamp":"2026-08-16T23:37:38.665633Z"}]}}
{"rx_ns": 42924129582000, "frame": {"channel":"book","type":"update","data":[{"symbol":"BTC/USD","bids":[{"price":62780.4,"qty":0.00000000},{"price":62703.0,"qty":0.01531807}],"asks":[],"checksum":528254587,"timestamp":"2026-08-16T23:37:38.757125Z"}]}}
{"rx_ns": 42924131788700, "frame": {"channel":"book","type":"update","data":[{"symbol":"BTC/USD","bids":[{"price":62785.0,"qty":0.00000000},{"price":62699.9,"qty":1.50000000},{"price":62788.1,"qty":0.05598472}],"asks":[],"checksum":366735595,"timestamp":"2026-08-16T23:37:38.758685Z"}]}}
{"rx_ns": 42924131850900, "frame": {"channel":"book","type":"update","data":[{"symbol":"BTC/USD","bids":[{"price":62781.1,"qty":0.79641687}],"asks":[],"checksum":366735595,"timestamp":"2026-08-16T23:37:38.759138Z"}]}}
{"rx_ns": 42924131863400, "frame": {"channel":"book","type":"update","data":[{"symbol":"BTC/USD","bids":[{"price":62775.3,"qty":0.01021271}],"asks":[],"checksum":366735595,"timestamp":"2026-08-16T23:37:38.760804Z"}]}}
{"rx_ns": 42924134706700, "frame": {"channel":"book","type":"update","data":[{"symbol":"BTC/USD","bids":[{"price":62775.3,"qty":0.00000000},{"price":62705.0,"qty":0.06960000}],"asks":[],"checksum":366735595,"timestamp":"2026-08-16T23:37:38.762954Z"}]}}
{"rx_ns": 42924138410900, "frame": {"channel":"book","type":"update","data":[{"symbol":"BTC/USD","bids":[{"price":62780.9,"qty":0.06960000}],"asks":[],"checksum":366735595,"timestamp":"2026-08-16T23:37:38.764305Z"}]}}
{"rx_ns": 42924150505500, "frame": {"channel":"book","type":"update","data":[{"symbol":"BTC/USD","bids":[{"price":62778.3,"qty":0.79645330}],"asks":[],"checksum":366735595,"timestamp":"2026-08-16T23:37:38.778713Z"}]}}
{"rx_ns": 42924168194200, "frame": {"channel":"book","type":"update","data":[{"symbol":"BTC/USD","bids":[{"price":62779.0,"qty":0.15927762}],"asks":[],"checksum":366735595,"timestamp":"2026-08-16T23:37:38.796422Z"}]}}
{"rx_ns": 42924230365600, "frame": {"channel":"book","type":"update","data":[{"symbol":"BTC/USD","bids":[{"price":62728.8,"qty":0.00000000},{"price":62706.5,"qty":0.00162380}],"asks":[],"checksum":366735595,"timestamp":"2026-08-16T23:37:38.857771Z"}]}}
{"rx_ns": 42924234605400, "frame": {"channel":"book","type":"update","data":[{"symbol":"BTC/USD","bids":[{"price":62728.9,"qty":5.41503508}],"asks":[],"checksum":366735595,"timestamp":"2026-08-16T23:37:38.860372Z"}]}}
{"rx_ns": 42924374713700, "frame": {"channel":"book","type":"update","data":[{"symbol":"BTC/USD","bids":[{"price":62771.4,"qty":0.00039827},{"price":62773.6,"qty":0.03185600}],"asks":[],"checksum":366735595,"timestamp":"2026-08-16T23:37:39.003271Z"}]}}
{"rx_ns": 42924378932100, "frame": {"channel":"book","type":"update","data":[{"symbol":"BTC/USD","bids":[],"asks":[{"price":62828.3,"qty":0.00000000},{"price":62878.8,"qty":0.11123578}],"checksum":366735595,"timestamp":"2026-08-16T23:37:39.007502Z"}]}}
{"rx_ns": 42924381872400, "frame": {"channel":"book","type":"update","data":[{"symbol":"BTC/USD","bids":[],"asks":[{"price":62828.6,"qty":0.00000000},{"price":62879.7,"qty":0.00200000}],"checksum":366735595,"timestamp":"2026-08-16T23:37:39.007794Z"}]}}
{"rx_ns": 42924381949500, "frame": {"channel":"book","type":"update","data":[{"symbol":"BTC/USD","bids":[],"asks":[{"price":62833.0,"qty":0.00000000},{"price":62880.0,"qty":0.47683277}],"checksum":366735595,"timestamp":"2026-08-16T23:37:39.008389Z"}]}}
{"rx_ns": 42924383422600, "frame": {"channel":"book","type":"update","data":[{"symbol":"BTC/USD","bids":[],"asks":[{"price":62879.4,"qty":0.06960000}],"checksum":366735595,"timestamp":"2026-08-16T23:37:39.011590Z"}]}}
{"rx_ns": 42924391136400, "frame": {"channel":"book","type":"update","data":[{"symbol":"BTC/USD","bids":[],"asks":[{"price":62828.2,"qty":0.37368842}],"checksum":366735595,"timestamp":"2026-08-16T23:37:39.013146Z"}]}}
{"rx_ns": 42924391201300, "frame": {"channel":"book","type":"update","data":[{"symbol":"BTC/USD","bids":[],"asks":[{"price":62832.9,"qty":1.44170226}],"checksum":366735595,"timestamp":"2026-08-16T23:37:39.013242Z"}]}}
{"rx_ns": 42924391211500, "frame": {"channel":"book","type":"update","data":[{"symbol":"BTC/USD","bids":[],"asks":[{"price":62828.5,"qty":0.87090274}],"checksum":366735595,"timestamp":"2026-08-16T23:37:39.013261Z"}]}}
{"rx_ns": 42924495501200, "frame": {"channel":"book","type":"update","data":[{"symbol":"BTC/USD","bids":[{"price":62793.5,"qty":0.00033098}],"asks":[],"checksum":751092168,"timestamp":"2026-08-16T23:37:39.121185Z"}]}}
{"rx_ns": 42924591735300, "frame": {"channel":"book","type":"update","data":[{"symbol":"BTC/USD","bids":[{"price":62784.6,"qty":0.00000000},{"price":62707.9,"qty":0.00079734},{"price":62784.0,"qty":0.00009500}],"asks":[],"checksum":3071590662,"timestamp":"2026-08-16T23:37:39.220089Z"}]}}
{"rx_ns": 42924669206300, "frame": {"channel":"heartbeat"}}
{"rx_ns": 42925070117600, "frame": {"channel":"book","type":"update","data":[{"symbol":"BTC/USD","bids":[{"price":62793.5,"qty":0.00010000},{"price":62793.5,"qty":0.00000098}],"asks":[],"checksum":640876754,"timestamp":"2026-08-16T23:37:39.696630Z"}]}}
{"rx_ns": 42925073021500, "frame": {"channel":"book","type":"update","data":[{"symbol":"BTC/USD","bids":[],"asks":[{"price":62793.6,"qty":5.10717786}],"checksum":3053448393,"timestamp":"2026-08-16T23:37:39.698369Z"}]}}
{"rx_ns": 42925073095800, "frame": {"channel":"book","type":"update","data":[{"symbol":"BTC/USD","bids":[],"asks":[{"price":62793.6,"qty":5.02917786}],"checksum":470850293,"timestamp":"2026-08-16T23:37:39.698536Z"}]}}
{"rx_ns": 42925073110000, "frame": {"channel":"book","type":"update","data":[{"symbol":"BTC/USD","bids":[{"price":62783.3,"qty":0.00000000},{"price":62707.9,"qty":0.00079734},{"price":62783.2,"qty":0.00318497}],"asks":[],"checksum":2612416950,"timestamp":"2026-08-16T23:37:39.698879Z"}]}}
{"rx_ns": 42925073124000, "frame": {"channel":"book","type":"update","data":[{"symbol":"BTC/USD","bids":[],"asks":[{"price":62831.0,"qty":0.00000000},{"price":62878.4,"qty":0.02131292},{"price":62830.9,"qty":0.03747535}],"checksum":2612416950,"timestamp":"2026-08-16T23:37:39.699180Z"}]}}
{"rx_ns": 42925076288000, "frame": {"channel":"book","type":"update","data":[{"symbol":"BTC/USD","bids":[{"price":62793.5,"qty":0.00000000},{"price":62707.9,"qty":0.00079734}],"asks":[{"price":62791.8,"qty":0.00019902}],"checksum":1847579405,"timestamp":"2026-08-16T23:37:39.700974Z"}]}}
{"rx_ns": 42925076383700, "frame": {"channel":"book","type":"update","data":[{"symbol":"BTC/USD","bids":[],"asks":[{"price":62791.8,"qty":0.01185194}],"checksum":4024195837,"timestamp":"2026-08-16T23:37:39.701453Z"}]}}
{"rx_ns": 42925076398400, "frame": {"channel":"book","type":"update","data":[{"symbol":"BTC/USD","bids":[],"asks":[{"price":62793.6,"qty":5.02067207}],"checksum":2396385677,"timestamp":"2026-08-16T23:37:39.701570Z"}]}}
{"rx_ns": 42925076409100, "frame": {"channel":"book","type":"update","data":[{"symbol":"BTC/USD","bids":[],"asks":[{"price":62793.5,"qty":0.11000000}],"checksum":2550666438,"timestamp":"2026-08-16T23:37:39.702085Z"}]}}
{"rx_ns": 42925076432400, "frame": {"channel":"book","type":"update","data":[{"symbol":"BTC/USD","bids":[],"asks":[{"price":62793.6,"qty":4.96468735},{"price":62793.5,"qty":0.16598472}],"checksum":1925322800,"timestamp":"2026-08-16T23:37:39.702512Z"}]}}
{"rx_ns": 42925076445700, "frame": {"channel":"book","type":"update","data":[{"symbol":"BTC/USD","bids":[],"asks":[{"price":62796.9,"qty":0.00000000},{"price":62876.4,"qty":0.23890000}],"checksum":3215782809,"timestamp":"2026-08-16T23:37:39.702547Z"}]}}
{"rx_ns": 42925076457200, "frame": {"channel":"book","type":"update","data":[{"symbol":"BTC/USD","bids":[],"asks":[{"price":62793.6,"qty":4.80540973}],"checksum":1002541753,"timestamp":"2026-08-16T23:37:39.702581Z"}]}}
{"rx_ns": 42925076466600, "frame": {"channel":"book","type":"update","data":[{"symbol":"BTC/USD","bids":[],"asks":[{"price":62793.6,"qty":4.78609981}],"checksum":659995938,"timestamp":"2026-08-16T23:37:39.702595Z"}]}}
{"rx_ns": 42925076476300, "frame": {"channel":"book","type":"update","data":[{"symbol":"BTC/USD","bids":[],"asks":[{"price":62791.8,"qty":0.08145194}],"checksum":2242350871,"timestamp":"2026-08-16T23:37:39.702751Z"}]}}
{"rx_ns": 42925079905200, "frame": {"channel":"book","type":"update","data":[{"symbol":"BTC/USD","bids":[],"asks":[{"price":62791.8,"qty":0.16105194}],"checksum":3504772867,"timestamp":"2026-08-16T23:37:39.702910Z"}]}}
{"rx_ns": 42925079949700, "frame": {"channel":"book","type":"update","data":[{"symbol":"BTC/USD","bids":[],"asks":[{"price":62796.6,"qty":0.00000000},{"price":62878.4,"qty":0.02131292},{"price":62793.4,"qty":0.18489680}],"checksum":4088771495,"timestamp":"2026-08-16T23:37:39.703274Z"}]}}
{"rx_ns": 42925079963200, "frame": {"channel":"book","type":"update","data":[{"symbol":"BTC/USD","bids":[],"asks":[{"price":62791.8,"qty":0.95733425}],"checksum":410721376,"timestamp":"2026-08-16T23:37:39.704214Z"}]}}
{"rx_ns": 42925079973900, "frame": {"channel":"book","type":"update","data":[{"symbol":"BTC/USD","bids":[{"price":62755.0,"qty":0.01046131},{"price":62754.1,"qty":0.00318497}],"asks":[],"checksum":410721376,"timestamp":"2026-08-16T23:37:39.704585Z"}]}}
{"rx_ns": 42925079984100, "frame": {"channel":"book","type":"update","data":[{"symbol":"BTC/USD","bids":[],"asks":[{"price":62802.7,"qty":0.00000000},{"price":62878.4,"qty":0.02131292},{"price":62801.8,"qty":0.00318497}],"checksum":410721376,"timestamp":"2026-08-16T23:37:39.704648Z"}]}}
{"rx_ns": 42925080063900, "frame": {"channel":"book","type":"update","data":[{"symbol":"BTC/USD","bids":[{"price":62791.7,"qty":0.03646524}],"asks":[],"checksum":1415153699,"timestamp":"2026-08-16T23:37:39.704846Z"}]}}
{"rx_ns": 42925085053500, "frame": {"channel":"book","type":"update","data":[{"symbol":"BTC/USD","bids":[],"asks":[{"price":62793.6,"qty":4.70649981}],"checksum":1468185855,"timestamp":"2026-08-16T23:37:39.711171Z"}]}}
{"rx_ns": 42925110469400, "frame": {"channel":"book","type":"update","data":[{"symbol":"BTC/USD","bids":[{"price":62780.5,"qty":0.06101297}],"asks":[],"checksum":1468185855,"timestamp":"2026-08-16T23:37:39.738789Z"}]}}
{"rx_ns": 42925111549900, "frame": {"channel":"book","type":"update","data":[{"symbol":"BTC/USD","bids":[],"asks":[{"price":62793.4,"qty":0.00000000},{"price":62878.4,"qty":0.02131292},{"price":62796.6,"qty":0.18489680}],"checksum":2324392335,"timestamp":"2026-08-16T23:37:39.740178Z"}]}}
{"rx_ns": 42925118779300, "frame": {"channel":"book","type":"update","data":[{"symbol":"BTC/USD","bids":[],"asks":[{"price":62791.8,"qty":1.11661187}],"checksum":3340241787,"timestamp":"2026-08-16T23:37:39.746370Z"}]}}
{"rx_ns": 42925174269100, "frame": {"channel":"book","type":"update","data":[{"symbol":"BTC/USD","bids":[],"asks":[{"price":62793.6,"qty":4.59649981}],"checksum":2073847771,"timestamp":"2026-08-16T23:37:39.802690Z"}]}}
{"rx_ns": 42925175526600, "frame": {"channel":"book","type":"update","data":[{"symbol":"BTC/USD","bids":[],"asks":[{"price":62791.8,"qty":1.22661187}],"checksum":1647664858,"timestamp":"2026-08-16T23:37:39.803386Z"}]}}
{"rx_ns": 42925177196400, "frame": {"channel":"book","type":"update","data":[{"symbol":"BTC/USD","bids":[],"asks":[{"price":62791.8,"qty":1.30461187}],"checksum":2108117186,"timestamp":"2026-08-16T23:37:39.805104Z"}]}}
{"rx_ns": 42925203568000, "frame": {"channel":"book","type":"update","data":[{"symbol":"BTC/USD","bids":[],"asks":[{"price":62794.2,"qty":0.00005100}],"checksum":3847940669,"timestamp":"2026-08-16T23:37:39.830167Z"}]}}
{"rx_ns": 42925213214900, "frame": {"channel":"book","type":"update","data":[{"symbol":"BTC/USD","bids":[{"price":62791.7,"qty":0.03686339}],"asks":[],"checksum":2967582984,"timestamp":"2026-08-16T23:37:39.842035Z"}]}}
{"rx_ns": 42925221920600, "frame": {"channel":"book","type":"update","data":[{"symbol":"BTC/USD","bids":[],"asks":[{"price":62793.6,"qty":0.80565762},{"price":62797.6,"qty":3.79087127}],"checksum":2496475101,"timestamp":"2026-08-16T23:37:39.850717Z"}]}}
{"rx_ns": 42925229728800, "frame": {"channel":"book","type":"update","data":[{"symbol":"BTC/USD","bids":[],"asks":[{"price":62797.6,"qty":0.00000000},{"price":62875.9,"qty":0.00159000},{"price":62791.8,"qty":5.09548326}],"checksum":1271504441,"timestamp":"2026-08-16T23:37:39.857866Z"}]}}
{"rx_ns": 42925241621300, "frame": {"channel":"book","type":"update","data":[{"symbol":"BTC/USD","bids":[{"price":62774.1,"qty":0.00000000},{"price":62709.2,"qty":0.43000000}],"asks":[],"checksum":1271504441,"timestamp":"2026-08-16T23:37:39.864874Z"}]}}
{"rx_ns": 42925241675700, "frame": {"channel":"book","type":"update","data":[{"symbol":"BTC/USD","bids":[{"price":62779.0,"qty":0.00000000},{"price":62707.9,"qty":0.00079734}],"asks":[],"checksum":1271504441,"timestamp":"2026-08-16T23:37:39.865345Z"}]}}
{"rx_ns": 42925241707200, "frame": {"channel":"book","type":"update","data":[{"symbol":"BTC/USD","bids":[],"asks":[{"price":62793.5,"qty":0.11000000},{"price":62793.4,"qty":0.05598472}],"checksum":2664721418,"timestamp":"2026-08-16T23:37:39.867085Z"}]}}
{"rx_ns": 42925245007200, "frame": {"channel":"book","type":"update","data":[{"symbol":"BTC/USD","bids":[{"price":62780.9,"qty":0.00000000},{"price":62706.5,"qty":0.00162380}],"asks":[],"checksum":2664721418,"timestamp":"2026-08-16T23:37:39.870421Z"}]}}
{"rx_ns": 42925245042200, "frame": {"channel":"book","type":"update","data":[{"symbol":"BTC/USD","bids":[{"price":62766.1,"qty":0.00000000},{"price":62703.0,"qty":0.01531807}],"asks":[],"checksum":2664721418,"timestamp":"2026-08-16T23:37:39.870587Z"}]}}
{"rx_ns": 42925253329100, "frame": {"channel":"book","type":"update","data":[{"symbol":"BTC/USD","bids":[{"price":62745.1,"qty":0.00000000},{"price":62699.9,"qty":1.50000000}],"asks":[],"checksum":2664721418,"timestamp":"2026-08-16T23:37:39.871446Z"}]}}
{"rx_ns": 42925253374300, "frame": {"channel":"book","type":"update","data":[{"symbol":"BTC/USD","bids":[{"price":62725.7,"qty":0.55709300}],"asks":[],"checksum":2664721418,"timestamp":"2026-08-16T23:37:39.873658Z"}]}}
{"rx_ns": 42925258691300, "frame": {"channel":"book","type":"update","data":[{"symbol":"BTC/USD","bids":[{"price":62705.0,"qty":0.06960000}],"asks":[],"checksum":2664721418,"timestamp":"2026-08-16T23:37:39.876063Z"}]}}
{"rx_ns": 42925258749200, "frame": {"channel":"book","type":"update","data":[{"symbol":"BTC/USD","bids":[{"price":62766.0,"qty":0.00000000},{"price":62703.0,"qty":0.01531807}],"asks":[],"checksum":2664721418,"timestamp":"2026-08-16T23:37:39.876124Z"}]}}
{"rx_ns": 42925258768700, "frame": {"channel":"book","type":"update","data":[{"symbol":"BTC/USD","bids":[{"price":62781.1,"qty":0.00000000},{"price":62699.9,"qty":1.50000000}],"asks":[],"checksum":3413766371,"timestamp":"2026-08-16T23:37:39.876467Z"}]}}
{"rx_ns": 42925258782900, "frame": {"channel":"book","type":"update","data":[{"symbol":"BTC/USD","bids":[],"asks":[{"price":62844.0,"qty":0.03230891}],"checksum":3413766371,"timestamp":"2026-08-16T23:37:39.876734Z"}]}}
{"rx_ns": 42925265629500, "frame": {"channel":"book","type":"update","data":[{"symbol":"BTC/USD","bids":[{"price":62778.3,"qty":0.00000000},{"price":62699.7,"qty":5.58216167}],"asks":[],"checksum":3413766371,"timestamp":"2026-08-16T23:37:39.882011Z"}]}}
{"rx_ns": 42925265680400, "frame": {"channel":"book","type":"update","data":[{"symbol":"BTC/USD","bids":[{"price":62780.2,"qty":0.79642904}],"asks":[],"checksum":3413766371,"timestamp":"2026-08-16T23:37:39.884548Z"}]}}
{"rx_ns": 42925265690800, "frame": {"channel":"book","type":"update","data":[{"symbol":"BTC/USD","bids":[{"price":62788.1,"qty":0.00000000},{"price":62699.7,"qty":5.58216167}],"asks":[],"checksum":318673332,"timestamp":"2026-08-16T23:37:39.885241Z"}]}}
{"rx_ns": 42925265700600, "frame": {"channel":"book","type":"update","data":[{"symbol":"BTC/USD","bids":[{"price":62780.2,"qty":0.00000000},{"price":62698.8,"qty":0.05517271}],"asks":[],"checksum":318673332,"timestamp":"2026-08-16T23:37:39.885377Z"}]}}
{"rx_ns": 42925275770300, "frame": {"channel":"book","type":"update","data":[{"symbol":"BTC/USD","bids":[],"asks":[{"price":62810.8,"qty":0.00222509},{"price":62805.5,"qty":1.59575715}],"checksum":318673332,"timestamp":"2026-08-16T23:37:39.887535Z"}]}}
{"rx_ns": 42925275844700, "frame": {"channel":"book","type":"update","data":[{"symbol":"BTC/USD","bids":[{"price":62777.1,"qty":0.79646752}],"asks":[],"checksum":318673332,"timestamp":"2026-08-16T23:37:39.890512Z"}]}}
{"rx_ns": 42925275857600, "frame": {"channel":"book","type":"update","data":[{"symbol":"BTC/USD","bids":[{"price":62785.0,"qty":0.05598472}],"asks":[],"checksum":3674695736,"timestamp":"2026-08-16T23:37:39.891600Z"}]}}
{"rx_ns": 42925275867600, "frame": {"channel":"book","type":"update","data":[{"symbol":"BTC/USD","bids":[{"price":62776.7,"qty":0.01037554}],"asks":[],"checksum":3674695736,"timestamp":"2026-08-16T23:37:39.892386Z"}]}}
{"rx_ns": 42925279090800, "frame": {"channel":"book","type":"update","data":[{"symbol":"BTC/USD","bids":[{"price":62791.7,"qty":0.03726154}],"asks":[],"checksum":3546013139,"timestamp":"2026-08-16T23:37:39.899575Z"}]}}
{"rx_ns": 42925279140700, "frame": {"channel":"book","type":"update","data":[{"symbol":"BTC/USD","bids":[],"asks":[{"price":62793.5,"qty":0.00000000},{"price":62875.2,"qty":5.56658959}],"checksum":2149974504,"timestamp":"2026-08-16T23:37:39.904141Z"}]}}
{"rx_ns": 42925282148300, "frame": {"channel":"book","type":"update","data":[{"symbol":"BTC/USD","bids":[{"price":62777.1,"qty":0.00000000},{"price":62699.9,"qty":1.50000000}],"asks":[],"checksum":2149974504,"timestamp":"2026-08-16T23:37:39.909802Z"}]}}
{"rx_ns": 42925285744500, "frame": {"channel":"book","type":"update","data":[{"symbol":"BTC/USD","bids":[],"asks":[{"price":62805.5,"qty":0.00000000},{"price":62875.3,"qty":0.01000000},{"price":62810.8,"qty":1.59798224}],"checksum":2149974504,"timestamp":"2026-08-16T23:37:39.911565Z"}]}}
{"rx_ns": 42925285786000, "frame": {"channel":"book","type":"update","data":[{"symbol":"BTC/USD","bids":[],"asks":[{"price":62791.8,"qty":5.11625024}],"checksum":2399616079,"timestamp":"2026-08-16T23:37:39.912576Z"}]}}
{"rx_ns": 42925294537100, "frame": {"channel":"book","type":"update","data":[{"symbol":"BTC/USD","bids":[{"price":62791.7,"qty":0.01594862}],"asks":[],"checksum":3773226174,"timestamp":"2026-08-16T23:37:39.921447Z"}]}}
{"rx_ns": 42925296254100, "frame": {"channel":"book","type":"update","data":[{"symbol":"BTC/USD","bids":[{"price":62790.4,"qty":0.02131292}],"asks":[],"checksum":1757913779,"timestamp":"2026-08-16T23:37:39.923416Z"}]}}
{"rx_ns": 42925296305800, "frame": {"channel":"book","type":"update","data":[{"symbol":"BTC/USD","bids":[{"price":62763.1,"qty":0.10294266}],"asks":[],"checksum":1757913779,"timestamp":"2026-08-16T23:37:39.923971Z"}]}}
{"rx_ns": 42925311248900, "frame": {"channel":"book","type":"update","data":[{"symbol":"BTC/USD","bids":[{"price":62763.1,"qty":0.00000000},{"price":62703.0,"qty":0.01531807},{"price":62765.7,"qty":0.10293839}],"asks":[],"checksum":1757913779,"timestamp":"2026-08-16T23:37:39.936017Z"}]}}
{"rx_ns": 42925311524100, "frame": {"channel":"book","type":"update","data":[{"symbol":"BTC/USD","bids":[],"asks":[{"price":62854.1,"qty":0.00000000},{"price":62875.9,"qty":0.00159000},{"price":62851.8,"qty":0.00385951}],"checksum":1757913779,"timestamp":"2026-08-16T23:37:39.938769Z"}]}}
{"rx_ns": 42925315349400, "frame": {"channel":"book","type":"update","data":[{"symbol":"BTC/USD","bids":[],"asks":[{"price":62810.8,"qty":0.00222509},{"price":62805.5,"qty":1.59575715}],"checksum":1757913779,"timestamp":"2026-08-16T23:37:39.942302Z"}]}}
{"rx_ns": 42925315377600, "frame": {"channel":"book","type":"update","data":[{"symbol":"BTC/USD","bids":[{"price":62765.7,"qty":0.00000000},{"price":62703.0,"qty":0.01531807},{"price":62763.1,"qty":0.10294266}],"asks":[],"checksum":1757913779,"timestamp":"2026-08-16T23:37:39.943121Z"}]}}
{"rx_ns": 42925321949300, "frame": {"channel":"book","type":"update","data":[{"symbol":"BTC/USD","bids":[{"price":62778.2,"qty":0.15927762}],"asks":[],"checksum":1757913779,"timestamp":"2026-08-16T23:37:39.944655Z"}]}}
{"rx_ns": 42925322001600, "frame": {"channel":"book","type":"update","data":[{"symbol":"BTC/USD","bids":[{"price":62729.7,"qty":0.00000000},{"price":62705.0,"qty":0.06960000}],"asks":[],"checksum":1757913779,"timestamp":"2026-08-16T23:37:39.945975Z"}]}}
{"rx_ns": 42925327701300, "frame": {"channel":"book","type":"update","data":[{"symbol":"BTC/USD","bids":[],"asks":[{"price":62825.3,"qty":0.00000000},{"price":62875.3,"qty":0.01000000},{"price":62823.3,"qty":0.00094656}],"checksum":1757913779,"timestamp":"2026-08-16T23:37:39.955936Z"}]}}
{"rx_ns": 42925334507800, "frame": {"channel":"book","type":"update","data":[{"symbol":"BTC/USD","bids":[{"price":62755.5,"qty":0.00000000},{"price":62703.0,"qty":0.01531807},{"price":62753.7,"qty":0.00303499}],"asks":[],"checksum":1757913779,"timestamp":"2026-08-16T23:37:39.956252Z"}]}}
{"rx_ns": 42925334562700, "frame": {"channel":"book","type":"update","data":[{"symbol":"BTC/USD","bids":[{"price":62791.7,"qty":0.01634677}],"asks":[],"checksum":917966638,"timestamp":"2026-08-16T23:37:39.957029Z"}]}}
{"rx_ns": 42925337175000, "frame": {"channel":"book","type":"update","data":[{"symbol":"BTC/USD","bids":[],"asks":[{"price":62847.8,"qty":0.00000000},{"price":62875.3,"qty":0.01000000},{"price":62846.9,"qty":0.00660000}],"checksum":917966638,"timestamp":"2026-08-16T23:37:39.964487Z"}]}}
{"rx_ns": 42925337227300, "frame": {"channel":"book","type":"update","data":[{"symbol":"BTC/USD","bids":[],"asks":[{"price":62797.1,"qty":0.00000000},{"price":62875.3,"qty":0.01000000}],"checksum":103604441,"timestamp":"2026-08-16T23:37:39.965056Z"}]}}
{"rx_ns": 42925356612600, "frame": {"channel":"book","type":"update","data":[{"symbol":"BTC/USD","bids":[{"price":62773.6,"qty":0.00000000},{"price":62703.0,"qty":0.01531807},{"price":62771.3,"qty":0.07964105}],"asks":[],"checksum":103604441,"timestamp":"2026-08-16T23:37:39.983431Z"}]}}
{"rx_ns": 42925385985400, "frame": {"channel":"book","type":"update","data":[{"symbol":"BTC/USD","bids":[{"price":62791.7,"qty":0.01674492}],"asks":[],"checksum":1915702950,"timestamp":"2026-08-16T23:37:40.013405Z"}]}}
{"rx_ns": 42925389826200, "frame": {"channel":"book","type":"update","data":[{"symbol":"BTC/USD","bids":[{"price":62779.7,"qty":0.79643526}],"asks":[],"checksum":1915702950,"timestamp":"2026-08-16T23:37:40.018601Z"}]}}
{"rx_ns": 42925398772900, "frame": {"channel":"book","type":"update","data":[{"symbol":"BTC/USD","bids":[{"price":62779.1,"qty":0.06960000}],"asks":[],"checksum":1915702950,"timestamp":"2026-08-16T23:37:40.024698Z"}]}}
{"rx_ns": 42925444286000, "frame": {"channel":"book","type":"update","data":[{"symbol":"BTC/USD","bids":[{"price":62791.7,"qty":0.01714307}],"asks":[],"checksum":2770044821,"timestamp":"2026-08-16T23:37:40.072281Z"}]}}
{"rx_ns": 42925448985000, "frame": {"channel":"book","type":"update","data":[{"symbol":"BTC/USD","bids":[{"price":62766.0,"qty":0.65558669}],"asks":[],"checksum":2770044821,"timestamp":"2026-08-16T23:37:40.073083Z"}]}}
{"rx_ns": 42925449029800, "frame": {"channel":"book","type":"update","data":[{"symbol":"BTC/USD","bids":[{"price":62774.9,"qty":0.65558669}],"asks":[],"checksum":2770044821,"timestamp":"2026-08-16T23:37:40.073146Z"}]}}
{"rx_ns": 42925449042000, "frame": {"channel":"book","type":"update","data":[{"symbol":"BTC/USD","bids":[],"asks":[{"price":62793.4,"qty":0.00000000},{"price":62875.9,"qty":0.00159000},{"price":62791.8,"qty":5.17223496}],"checksum":3886578281,"timestamp":"2026-08-16T23:37:40.073489Z"}]}}
{"rx_ns": 42925449071800, "frame": {"channel":"book","type":"update","data":[{"symbol":"BTC/USD","bids":[{"price":62778.2,"qty":0.00000000},{"price":62709.2,"qty":0.43000000}],"asks":[],"checksum":3886578281,"timestamp":"2026-08-16T23:37:40.074338Z"}]}}
{"rx_ns": 42925449083600, "frame": {"channel":"book","type":"update","data":[{"symbol":"BTC/USD","bids":[],"asks":[{"price":62796.6,"qty":0.00000000},{"price":62876.4,"qty":0.23890000},{"price":62799.0,"qty":0.18489680}],"checksum":2438922597,"timestamp":"2026-08-16T23:37:40.074785Z"}]}}
{"rx_ns": 42925451679800, "frame": {"channel":"book","type":"update","data":[{"symbol":"BTC/USD","bids":[],"asks":[{"price":62793.6,"qty":0.80525949},{"price":62791.8,"qty":5.17263311}],"checksum":2963904680,"timestamp":"2026-08-16T23:37:40.079635Z"}]}}
{"rx_ns": 42925469411600, "frame": {"channel":"book","type":"update","data":[{"symbol":"BTC/USD","bids":[{"price":62791.7,"qty":0.01674492}],"asks":[],"checksum":1738363291,"timestamp":"2026-08-16T23:37:40.096347Z"}]}}
{"rx_ns": 42925469476800, "frame": {"channel":"book","type":"update","data":[{"symbol":"BTC/USD","bids":[{"price":62778.0,"qty":0.16350086}],"asks":[],"checksum":1738363291,"timestamp":"2026-08-16T23:37:40.096799Z"}]}}
{"rx_ns": 42925472466200, "frame": {"channel":"book","type":"update","data":[{"symbol":"BTC/USD","bids":[{"price":62791.7,"qty":0.00159260},{"price":62791.7,"qty":0.00119445},{"price":62791.7,"qty":0.00079630},{"price":62791.7,"qty":0.00039815},{"price":62791.7,"qty":0.00000092}],"asks":[],"checksum":2063019841,"timestamp":"2026-08-16T23:37:40.098682Z"}]}}
{"rx_ns": 42925480636300, "frame": {"channel":"book","type":"update","data":[{"symbol":"BTC/USD","bids":[],"asks":[{"price":62801.3,"qty":0.00000000},{"price":62876.4,"qty":0.23890000}],"checksum":2063019841,"timestamp":"2026-08-16T23:37:40.105581Z"}]}}
{"rx_ns": 42925480677400, "frame": {"channel":"book","type":"update","data":[{"symbol":"BTC/USD","bids":[],"asks":[{"price":62805.5,"qty":0.00000000},{"price":62878.3,"qty":0.00297725}],"checksum":2063019841,"timestamp":"2026-08-16T23:37:40.106337Z"}]}}
{"rx_ns": 42925480752200, "frame": {"channel":"book","type":"update","data":[{"symbol":"BTC/USD","bids":[{"price":62763.1,"qty":0.00000000},{"price":62707.9,"qty":0.00079734}],"asks":[],"checksum":2063019841,"timestamp":"2026-08-16T23:37:40.106432Z"}]}}
{"rx_ns": 42925480763700, "frame": {"channel":"book","type":"update","data":[{"symbol":"BTC/USD","bids":[],"asks":[{"price":62799.0,"qty":0.00000000},{"price":62878.8,"qty":0.11123578},{"price":62810.3,"qty":0.18489680}],"checksum":232506524,"timestamp":"2026-08-16T23:37:40.107048Z"}]}}
{"rx_ns": 42925485629400, "frame": {"channel":"book","type":"update","data":[{"symbol":"BTC/USD","bids":[],"asks":[{"price":62791.8,"qty":1.38176172}],"checksum":2374695972,"timestamp":"2026-08-16T23:37:40.109986Z"}]}}
{"rx_ns": 42925520302500, "frame": {"channel":"book","type":"update","data":[{"symbol":"BTC/USD","bids":[],"asks":[{"price":62844.0,"qty":0.00000000},{"price":62878.8,"qty":0.11123578}],"checksum":2374695972,"timestamp":"2026-08-16T23:37:40.147368Z"}]}}
{"rx_ns": 42925588883800, "frame": {"channel":"book","type":"update","data":[{"symbol":"BTC/USD","bids":[],"asks":[{"price":62805.5,"qty":1.59575715}],"checksum":2374695972,"timestamp":"2026-08-16T23:37:40.216001Z"}]}}
{"rx_ns": 42925588933600, "frame": {"channel":"book","type":"update","data":[{"symbol":"BTC/USD","bids":[{"price":62763.1,"qty":0.10294266}],"asks":[],"checksum":2374695972,"timestamp":"2026-08-16T23:37:40.216116Z"}]}}
{"rx_ns": 42925588949200, "frame": {"channel":"book","type":"update","data":[{"symbol":"BTC/USD","bids":[{"price":62753.7,"qty":0.00000000},{"price":62707.9,"qty":0.00079734},{"price":62754.2,"qty":0.00303501}],"asks":[],"checksum":2374695972,"timestamp":"2026-08-16T23:37:40.216204Z"}]}}
{"rx_ns": 42925590493400, "frame": {"channel":"book","type":"update","data":[{"symbol":"BTC/USD","bids":[],"asks":[{"price":62810.3,"qty":0.00000000},{"price":62878.8,"qty":0.11123578},{"price":62805.4,"qty":0.18489680}],"checksum":2374695972,"timestamp":"2026-08-16T23:37:40.217374Z"}]}}
{"rx_ns": 42925592362600, "frame": {"channel":"book","type":"update","data":[{"symbol":"BTC/USD","bids":[],"asks":[{"price":62800.8,"qty":0.19620257}],"checksum":2374695972,"timestamp":"2026-08-16T23:37:40.219571Z"}]}}
{"rx_ns": 42925595167900, "frame": {"channel":"book","type":"update","data":[{"symbol":"BTC/USD","bids":[],"asks":[{"price":62810.8,"qty":0.00000000},{"price":62878.3,"qty":0.00297725},{"price":62800.8,"qty":0.19842766}],"checksum":2374695972,"timestamp":"2026-08-16T23:37:40.220915Z"}]}}
{"rx_ns": 42925602594300, "frame": {"channel":"book","type":"update","data":[{"symbol":"BTC/USD","bids":[],"asks":[{"price":62791.8,"qty":5.17264463}],"checksum":3391432564,"timestamp":"2026-08-16T23:37:40.230040Z"}]}}
{"rx_ns": 42925647267800, "frame": {"channel":"book","type":"update","data":[{"symbol":"BTC/USD","bids":[],"asks":[{"price":62818.8,"qty":0.00000000},{"price":62878.8,"qty":0.11123578}],"checksum":3391432564,"timestamp":"2026-08-16T23:37:40.274963Z"}]}}
{"rx_ns": 42925647320000, "frame": {"channel":"book","type":"update","data":[{"symbol":"BTC/USD","bids":[],"asks":[{"price":62805.6,"qty":0.00000000},{"price":62879.2,"qty":0.03686339}],"checksum":3391432564,"timestamp":"2026-08-16T23:37:40.274992Z"}]}}
{"rx_ns": 42925647331700, "frame": {"channel":"book","type":"update","data":[{"symbol":"BTC/USD","bids":[{"price":62752.8,"qty":0.00000000},{"price":62707.9,"qty":0.00079734}],"asks":[],"checksum":3391432564,"timestamp":"2026-08-16T23:37:40.275127Z"}]}}
{"rx_ns": 42925651474000, "frame": {"channel":"book","type":"update","data":[{"symbol":"BTC/USD","bids":[],"asks":[{"price":62794.8,"qty":0.79624427}],"checksum":2870120382,"timestamp":"2026-08-16T23:37:40.275203Z"}]}}
{"rx_ns": 42925651527600, "frame": {"channel":"book","type":"update","data":[{"symbol":"BTC/USD","bids":[{"price":62774.9,"qty":0.00000000},{"price":62706.5,"qty":0.00162380}],"asks":[],"checksum":2870120382,"timestamp":"2026-08-16T23:37:40.275330Z"}]}}
{"rx_ns": 42925651543700, "frame": {"channel":"book","type":"update","data":[{"symbol":"BTC/USD","bids":[{"price":62766.0,"qty":0.00000000},{"price":62703.0,"qty":0.01531807}],"asks":[],"checksum":2870120382,"timestamp":"2026-08-16T23:37:40.275518Z"}]}}
{"rx_ns": 42925651555900, "frame": {"channel":"book","type":"update","data":[{"symbol":"BTC/USD","bids":[],"asks":[{"price":62805.4,"qty":0.00000000},{"price":62879.6,"qty":0.47693310},{"price":62810.4,"qty":0.31599082}],"checksum":2870120382,"timestamp":"2026-08-16T23:37:40.276525Z"}]}}
{"rx_ns": 42925654066200, "frame": {"channel":"book","type":"update","data":[{"symbol":"BTC/USD","bids":[{"price":62705.0,"qty":0.06960000}],"asks":[],"checksum":2870120382,"timestamp":"2026-08-16T23:37:40.278488Z"}]}}
{"rx_ns": 42925654084800, "frame": {"channel":"book","type":"update","data":[{"symbol":"BTC/USD","bids":[],"asks":[{"price":62791.8,"qty":5.44164463}],"checksum":690156824,"timestamp":"2026-08-16T23:37:40.278905Z"}]}}
{"rx_ns": 42925654093500, "frame": {"channel":"book","type":"update","data":[{"symbol":"BTC/USD","bids":[],"asks":[{"price":62879.4,"qty":0.06960000}],"checksum":690156824,"timestamp":"2026-08-16T23:37:40.279395Z"}]}}
{"rx_ns": 42925654112400, "frame": {"channel":"book","type":"update","data":[{"symbol":"BTC/USD","bids":[{"price":62779.7,"qty":0.00000000},{"price":62703.0,"qty":0.01531807}],"asks":[],"checksum":690156824,"timestamp":"2026-08-16T23:37:40.280995Z"}]}}
{"rx_ns": 42925656256500, "frame": {"channel":"book","type":"update","data":[{"symbol":"BTC/USD","bids":[{"price":62778.8,"qty":0.79644624}],"asks":[],"checksum":690156824,"timestamp":"2026-08-16T23:37:40.282591Z"}]}}
{"rx_ns": 42925656286100, "frame": {"channel":"book","type":"update","data":[{"symbol":"BTC/USD","bids":[],"asks":[{"price":62800.8,"qty":0.19620257},{"price":62810.3,"qty":0.00222509}],"checksum":690156824,"timestamp":"2026-08-16T23:37:40.282698Z"}]}}
{"rx_ns": 42925656296300, "frame": {"channel":"book","type":"update","data":[{"symbol":"BTC/USD","bids":[{"price":62776.8,"qty":0.89978347}],"asks":[],"checksum":690156824,"timestamp":"2026-08-16T23:37:40.282896Z"}]}}
{"rx_ns": 42925656983400, "frame": {"channel":"book","type":"update","data":[{"symbol":"BTC/USD","bids":[{"price":62776.7,"qty":0.00000000},{"price":62703.0,"qty":0.01531807}],"asks":[],"checksum":690156824,"timestamp":"2026-08-16T23:37:40.285786Z"}]}}
{"rx_ns": 42925662784500, "frame": {"channel":"book","type":"update","data":[{"symbol":"BTC/USD","bids":[],"asks":[{"price":62879.0,"qty":0.47705970}],"checksum":690156824,"timestamp":"2026-08-16T23:37:40.290298Z"}]}}
{"rx_ns": 42925683673800, "frame": {"channel":"heartbeat"}}
{"rx_ns": 42925716140700, "frame": {"channel":"book","type":"update","data":[{"symbol":"BTC/USD","bids":[{"price":62791.7,"qty":0.00000000},{"price":62699.9,"qty":1.50000000}],"asks":[],"checksum":320454299,"timestamp":"2026-08-16T23:37:40.337287Z"}]}}
{"rx_ns": 42925716212900, "frame": {"channel":"book","type":"update","data":[{"symbol":"BTC/USD","bids":[],"asks":[{"price":62791.7,"qty":0.11000000}],"checksum":3908996609,"timestamp":"2026-08-16T23:37:40.338082Z"}]}}
{"rx_ns": 42925716239400, "frame": {"channel":"book","type":"update","data":[{"symbol":"BTC/USD","bids":[],"asks":[{"price":62793.6,"qty":0.00900000}],"checksum":3676949702,"timestamp":"2026-08-16T23:37:40.338420Z"}]}}
{"rx_ns": 42925716671200, "frame": {"channel":"book","type":"update","data":[{"symbol":"BTC/USD","bids":[{"price":62791.2,"qty":0.00159200}],"asks":[],"checksum":2514593829,"timestamp":"2026-08-16T23:37:40.338449Z"}]}}
{"rx_ns": 42925716690900, "frame": {"channel":"book","type":"update","data":[{"symbol":"BTC/USD","bids":[],"asks":[{"price":62810.4,"qty":0.13109402},{"price":62800.7,"qty":0.18489680}],"checksum":2514593829,"timestamp":"2026-08-16T23:37:40.338483Z"}]}}
{"rx_ns": 42925716701900, "frame": {"channel":"book","type":"update","data":[{"symbol":"BTC/USD","bids":[],"asks":[{"price":62791.8,"qty":5.38565991},{"price":62791.7,"qty":0.16598472}],"checksum":1363035562,"timestamp":"2026-08-16T23:37:40.338497Z"}]}}
{"rx_ns": 42925716711200, "frame": {"channel":"book","type":"update","data":[{"symbol":"BTC/USD","bids":[],"asks":[{"price":62791.3,"qty":0.06960000}],"checksum":2760898864,"timestamp":"2026-08-16T23:37:40.338510Z"}]}}
{"rx_ns": 42925716721900, "frame": {"channel":"book","type":"update","data":[{"symbol":"BTC/USD","bids":[],"asks":[{"price":62791.8,"qty":5.22638229}],"checksum":307271300,"timestamp":"2026-08-16T23:37:40.338580Z"}]}}
{"rx_ns": 42925716730000, "frame": {"channel":"book","type":"update","data":[{"symbol":"BTC/USD","bids":[],"asks":[{"price":62818.8,"qty":1.40486793}],"checksum":307271300,"timestamp":"2026-08-16T23:37:40.338883Z"}]}}
{"rx_ns": 42925716737800, "frame": {"channel":"book","type":"update","data":[{"symbol":"BTC/USD","bids":[],"asks":[{"price":62791.8,"qty":5.15678229}],"checksum":407443951,"timestamp":"2026-08-16T23:37:40.339116Z"}]}}
{"rx_ns": 42925716745900, "frame": {"channel":"book","type":"update","data":[{"symbol":"BTC/USD","bids":[],"asks":[{"price":62791.8,"qty":4.36049998}],"checksum":3955429569,"timestamp":"2026-08-16T23:37:40.339375Z"}]}}
{"rx_ns": 42925716755300, "frame": {"channel":"book","type":"update","data":[{"symbol":"BTC/USD","bids":[],"asks":[{"price":62791.8,"qty":4.33973300}],"checksum":1895754000,"timestamp":"2026-08-16T23:37:40.339499Z"}]}}
{"rx_ns": 42925716764200, "frame": {"channel":"book","type":"update","data":[{"symbol":"BTC/USD","bids":[],"asks":[{"price":62792.3,"qty":0.46828931}],"checksum":758658748,"timestamp":"2026-08-16T23:37:40.339512Z"}]}}
{"rx_ns": 42925716772100, "frame": {"channel":"book","type":"update","data":[{"symbol":"BTC/USD","bids":[{"price":62766.0,"qty":0.46828931}],"asks":[],"checksum":758658748,"timestamp":"2026-08-16T23:37:40.339535Z"}]}}
{"rx_ns": 42925716803200, "frame": {"channel":"book","type":"update","data":[{"symbol":"BTC/USD","bids":[{"price":62752.8,"qty":1.40486793}],"asks":[],"checksum":758658748,"timestamp":"2026-08-16T23:37:40.339549Z"}]}}
{"rx_ns": 42925716813100, "frame": {"channel":"book","type":"update","data":[{"symbol":"BTC/USD","bids":[{"price":62774.8,"qty":0.46828931}],"asks":[],"checksum":758658748,"timestamp":"2026-08-16T23:37:40.339567Z"}]}}
{"rx_ns": 42925716821500, "frame": {"channel":"book","type":"update","data":[{"symbol":"BTC/USD","bids":[],"asks":[{"price":62805.6,"qty":0.46828931}],"checksum":758658748,"timestamp":"2026-08-16T23:37:40.339637Z"}]}}
{"rx_ns": 42925716830700, "frame": {"channel":"book","type":"update","data":[{"symbol":"BTC/USD","bids":[],"asks":[{"price":62791.7,"qty":0.24558472}],"checksum":81208305,"timestamp":"2026-08-16T23:37:40.339811Z"}]}}
{"rx_ns": 42925716839300, "frame": {"channel":"book","type":"update","data":[{"symbol":"BTC/USD","bids":[],"asks":[{"price":62791.7,"qty":0.32358472}],"checksum":3540620598,"timestamp":"2026-08-16T23:37:40.339882Z"}]}}
{"rx_ns": 42925716847700, "frame": {"channel":"book","type":"update","data":[{"symbol":"BTC/USD","bids":[],"asks":[{"price":62791.8,"qty":4.26173300}],"checksum":1676821098,"timestamp":"2026-08-16T23:37:40.339952Z"}]}}
{"rx_ns": 42925716856300, "frame": {"channel":"book","type":"update","data":[{"symbol":"BTC/USD","bids":[],"asks":[{"price":62791.3,"qty":0.14760000}],"checksum":261477611,"timestamp":"2026-08-16T23:37:40.340052Z"}]}}
{"rx_ns": 42925716865300, "frame": {"channel":"book","type":"update","data":[{"symbol":"BTC/USD","bids":[],"asks":[{"price":62791.7,"qty":0.24398472}],"checksum":3521529220,"timestamp":"2026-08-16T23:37:40.340148Z"}]}}
{"rx_ns": 42925716875700, "frame": {"channel":"book","type":"update","data":[{"symbol":"BTC/USD","bids":[],"asks":[{"price":62791.8,"qty":4.18213300}],"checksum":514637132,"timestamp":"2026-08-16T23:37:40.340220Z"}]}}
{"rx_ns": 42925716884300, "frame": {"channel":"book","type":"update","data":[{"symbol":"BTC/USD","bids":[],"asks":[{"price":62791.3,"qty":0.22720000}],"checksum":2081597679,"timestamp":"2026-08-16T23:37:40.340235Z"}]}}
{"rx_ns": 42925716893000, "frame": {"channel":"book","type":"update","data":[{"symbol":"BTC/USD","bids":[],"asks":[{"price":62791.7,"qty":0.16598472}],"checksum":1548786186,"timestamp":"2026-08-16T23:37:40.340556Z"}]}}
{"rx_ns": 42925716902300, "frame": {"channel":"book","type":"update","data":[{"symbol":"BTC/USD","bids":[],"asks":[{"price":62791.8,"qty":4.17048008}],"checksum":2175776341,"timestamp":"2026-08-16T23:37:40.340824Z"}]}}
{"rx_ns": 42925716910400, "frame": {"channel":"book","type":"update","data":[{"symbol":"BTC/USD","bids":[],"asks":[{"price":62791.6,"qty":0.79628485}],"checksum":1960831144,"timestamp":"2026-08-16T23:37:40.340983Z"}]}}
{"rx_ns": 42925716919700, "frame": {"channel":"book","type":"update","data":[{"symbol":"BTC/USD","bids":[{"price":62791.2,"qty":0.01674406}],"asks":[],"checksum":1610156619,"timestamp":"2026-08-16T23:37:40.341008Z"}]}}
{"rx_ns": 42925716929100, "frame": {"channel":"book","type":"update","data":[{"symbol":"BTC/USD","bids":[],"asks":[{"price":62791.8,"qty":4.17028106}],"checksum":900183268,"timestamp":"2026-08-16T23:37:40.341170Z"}]}}
{"rx_ns": 42925716939200, "frame": {"channel":"book","type":"update","data":[{"symbol":"BTC/USD","bids":[],"asks":[{"price":62812.3,"qty":0.00000000},{"price":62875.2,"qty":5.56658959}],"checksum":900183268,"timestamp":"2026-08-16T23:37:40.341260Z"}]}}
{"rx_ns": 42925716950000, "frame": {"channel":"book","type":"update","data":[{"symbol":"BTC/USD","bids":[],"asks":[{"price":62792.4,"qty":0.79627492}],"checksum":1124412163,"timestamp":"2026-08-16T23:37:40.341278Z"}]}}
{"rx_ns": 42925716978400, "frame": {"channel":"book","type":"update","data":[{"symbol":"BTC/USD","bids":[],"asks":[{"price":62791.3,"qty":0.29664450}],"checksum":2030218429,"timestamp":"2026-08-16T23:37:40.341867Z"}]}}
{"rx_ns": 42925718388300, "frame": {"channel":"book","type":"update","data":[{"symbol":"BTC/USD","bids":[],"asks":[{"price":62791.3,"qty":0.30849750}],"checksum":3185453586,"timestamp":"2026-08-16T23:37:40.345695Z"}]}}
{"rx_ns": 42925720545600, "frame": {"channel":"book","type":"update","data":[{"symbol":"BTC/USD","bids":[],"asks":[{"price":62791.3,"qty":0.46777958}],"checksum":1131500464,"timestamp":"2026-08-16T23:37:40.346222Z"}]}}
{"rx_ns": 42925739187800, "frame": {"channel":"book","type":"update","data":[{"symbol":"BTC/USD","bids":[{"price":62778.8,"qty":0.00000000},{"price":62703.0,"qty":0.01531807}],"asks":[],"checksum":1131500464,"timestamp":"2026-08-16T23:37:40.367538Z"}]}}
{"rx_ns": 42925744243100, "frame": {"channel":"book","type":"update","data":[{"symbol":"BTC/USD","bids":[],"asks":[{"price":62800.7,"qty":0.00000000},{"price":62875.2,"qty":5.56658959},{"price":62796.6,"qty":0.18489680}],"checksum":1131500464,"timestamp":"2026-08-16T23:37:40.370108Z"}]}}
{"rx_ns": 42925744304200, "frame": {"channel":"book","type":"update","data":[{"symbol":"BTC/USD","bids":[{"price":62705.0,"qty":0.06960000}],"asks":[],"checksum":1131500464,"timestamp":"2026-08-16T23:37:40.370719Z"}]}}
{"rx_ns": 42925744333700, "frame": {"channel":"book","type":"update","data":[{"symbol":"BTC/USD","bids":[],"asks":[{"price":62793.6,"qty":0.00800000}],"checksum":1950458168,"timestamp":"2026-08-16T23:37:40.371352Z"}]}}
{"rx_ns": 42925772562800, "frame": {"channel":"book","type":"update","data":[{"symbol":"BTC/USD","bids":[{"price":62776.8,"qty":0.10331161}],"asks":[],"checksum":1950458168,"timestamp":"2026-08-16T23:37:40.398036Z"}]}}
{"rx_ns": 42925777048900, "frame": {"channel":"book","type":"update","data":[{"symbol":"BTC/USD","bids":[{"price":62780.1,"qty":0.79642992}],"asks":[],"checksum":1950458168,"timestamp":"2026-08-16T23:37:40.399417Z"}]}}
{"rx_ns": 42925777110100, "frame": {"channel":"book","type":"update","data":[{"symbol":"BTC/USD","bids":[{"price":62785.0,"qty":0.00000000},{"price":62705.0,"qty":0.06960000},{"price":62788.1,"qty":0.05598472}],"asks":[],"checksum":1681865187,"timestamp":"2026-08-16T23:37:40.399697Z"}]}}
{"rx_ns": 42925777127000, "frame": {"channel":"book","type":"update","data":[{"symbol":"BTC/USD","bids":[],"asks":[{"price":62791.7,"qty":0.11000000},{"price":62792.2,"qty":0.05598472}],"checksum":2238506126,"timestamp":"2026-08-16T23:37:40.399746Z"}]}}
{"rx_ns": 42925784295800, "frame": {"channel":"book","type":"update","data":[{"symbol":"BTC/USD","bids":[{"price":62775.0,"qty":0.01020752}],"asks":[],"checksum":2238506126,"timestamp":"2026-08-16T23:37:40.404043Z"}]}}
{"rx_ns": 42925794469400, "frame": {"channel":"book","type":"update","data":[{"symbol":"BTC/USD","bids":[],"asks":[{"price":62805.5,"qty":0.00000000},{"price":62875.0,"qty":0.04717193},{"price":62810.3,"qty":1.59798224}],"checksum":2238506126,"timestamp":"2026-08-16T23:37:40.422708Z"}]}}
{"rx_ns": 42925811008300, "frame": {"channel":"book","type":"update","data":[{"symbol":"BTC/USD","bids":[],"asks":[{"price":62791.8,"qty":4.06028106}],"checksum":3749819463,"timestamp":"2026-08-16T23:37:40.438553Z"}]}}
{"rx_ns": 42925819888900, "frame": {"channel":"book","type":"update","data":[{"symbol":"BTC/USD","bids":[{"price":62729.6,"qty":0.05456069}],"asks":[],"checksum":3749819463,"timestamp":"2026-08-16T23:37:40.447330Z"}]}}
{"rx_ns": 42925822699900, "frame": {"channel":"book","type":"update","data":[{"symbol":"BTC/USD","bids":[{"price":62791.2,"qty":0.01714221}],"asks":[],"checksum":3753061460,"timestamp":"2026-08-16T23:37:40.450122Z"}]}}
{"rx_ns": 42925863478100, "frame": {"channel":"book","type":"update","data":[{"symbol":"BTC/USD","bids":[],"asks":[{"price":62791.8,"qty":0.26939815},{"price":62791.3,"qty":4.25868206}],"checksum":4138607178,"timestamp":"2026-08-16T23:37:40.491040Z"}]}}
{"rx_ns": 42925884138000, "frame": {"channel":"book","type":"update","data":[{"symbol":"BTC/USD","bids":[{"price":62791.2,"qty":0.01754036}],"asks":[],"checksum":1696178996,"timestamp":"2026-08-16T23:37:40.505906Z"}]}}
{"rx_ns": 42925930174800, "frame": {"channel":"book","type":"update","data":[{"symbol":"BTC/USD","bids":[],"asks":[{"price":62791.3,"qty":4.27781554}],"checksum":3458916970,"timestamp":"2026-08-16T23:37:40.556316Z"}]}}
{"rx_ns": 42925937218400, "frame": {"channel":"book","type":"update","data":[{"symbol":"BTC/USD","bids":[{"price":62791.2,"qty":0.01793851}],"asks":[],"checksum":2324819886,"timestamp":"2026-08-16T23:37:40.563664Z"}]}}
{"rx_ns": 42925952846600, "frame": {"channel":"book","type":"update","data":[{"symbol":"BTC/USD","bids":[],"asks":[{"price":62791.8,"qty":0.26900000},{"price":62791.3,"qty":4.27821369}],"checksum":483201873,"timestamp":"2026-08-16T23:37:40.573800Z"}]}}
{"rx_ns": 42925960319500, "frame": {"channel":"book","type":"update","data":[{"symbol":"BTC/USD","bids":[{"price":62791.2,"qty":0.01754036}],"asks":[],"checksum":1484136085,"timestamp":"2026-08-16T23:37:40.587931Z"}]}}
