{"captured_at": "2026-08-18T20:43:52.818766+00:00", "url": "wss://ws.kraken.com/v2", "venue": "kraken", "symbol": "MINA/GBP", "depth": 25, "subscribe": "{\"method\":\"subscribe\",\"params\":{\"channel\":\"book\",\"symbol\":[\"MINA/GBP\"],\"depth\":25,\"snapshot\":true}}", "tool_version": "0.2.0", "clock": "perf_counter_ns", "capture_mode": "resubscribe", "cycles": 1, "origin_sent": null, "handshake_status": "HTTP/1.1 101 Switching Protocols"}
{"rx_ns": 23835133694100, "dir": "tx", "frame": {"method":"subscribe","params":{"channel":"book","symbol":["MINA/GBP"],"depth":25,"snapshot":true}}}
{"rx_ns": 23835133737300, "frame": {"channel":"status","type":"update","data":[{"version":"2.0.10","system":"online","api_version":"v2","connection_id":6437862339878838704}]}}
{"rx_ns": 23835154863000, "frame": {"method":"subscribe","result":{"channel":"book","depth":25,"snapshot":true,"symbol":"MINA/GBP"},"success":true,"time_in":"2026-08-18T20:43:55.546900Z","time_out":"2026-08-18T20:43:55.546939Z"}}
{"rx_ns": 23835352219500, "frame": {"channel":"heartbeat"}}
{"rx_ns": 23835399720600, "frame": {"channel":"book","type":"snapshot","data":[{"symbol":"MINA/GBP","bids":[{"price":0.0294,"qty":22500.50544743},{"price":0.0293,"qty":25260.79829263},{"price":0.0292,"qty":18831.49589194},{"price":0.0284,"qty":5287.46119218},{"price":0.0283,"qty":13306.45662928},{"price":0.0281,"qty":1794.68812000},{"price":0.0277,"qty":514.47653429},{"price":0.0272,"qty":523.93382352},{"price":0.0270,"qty":370.37037037},{"price":0.0267,"qty":533.74531835},{"price":0.0259,"qty":21854.79478871},{"price":0.0256,"qty":1000.00000000},{"price":0.0240,"qty":90.00000000},{"price":0.0225,"qty":2222.22222223},{"price":0.0210,"qty":2000.00000000},{"price":0.0182,"qty":3000.00000000},{"price":0.0124,"qty":90.00000000},{"price":0.0100,"qty":50.00000000},{"price":0.0086,"qty":50.00000000},{"price":0.0080,"qty":90.00000000},{"price":0.0070,"qty":120.00000000},{"price":0.0057,"qty":877.19298245},{"price":0.0050,"qty":120.00000000},{"price":0.0040,"qty":200.00000000},{"price":0.0030,"qty":143.33333334}],"asks":[{"price":0.0295,"qty":23717.15468719},{"price":0.0296,"qty":37310.55543978},{"price":0.0297,"qty":19850.17161350},{"price":0.0298,"qty":20571.49589194},{"price":0.0307,"qty":1902.54600978},{"price":0.0312,"qty":1899.16478919},{"price":0.0316,"qty":1901.23996506},{"price":0.0489,"qty":1986.15467694},{"price":0.0600,"qty":1752.82392026},{"price":0.0800,"qty":3373.43721760},{"price":0.1150,"qty":67.55460411},{"price":0.1780,"qty":1814.14472703},{"price":0.2000,"qty":1814.14472703},{"price":0.2300,"qty":161.78901632},{"price":0.2600,"qty":510.62544699},{"price":0.2800,"qty":100.00000000},{"price":0.4790,"qty":2336.44859813},{"price":0.5300,"qty":90.00000000},{"price":0.5580,"qty":1792.11469534},{"price":0.5900,"qty":1209.42981802},{"price":0.6000,"qty":3017.83667372},{"price":0.6900,"qty":217.39130434},{"price":0.7000,"qty":14.77104874},{"price":0.7700,"qty":4.00000000},{"price":0.8000,"qty":9.52569933}],"checksum":2892435853,"timestamp":"2026-08-18T20:43:35.824274Z"}]}}
{"rx_ns": 23836343984300, "frame": {"channel":"heartbeat"}}
{"rx_ns": 23837346391200, "frame": {"channel":"heartbeat"}}
{"rx_ns": 23838343477000, "frame": {"channel":"heartbeat"}}
{"rx_ns": 23839346294400, "frame": {"channel":"heartbeat"}}
{"rx_ns": 23840368082600, "frame": {"channel":"heartbeat"}}
{"rx_ns": 23840536680400, "frame": {"channel":"book","type":"update","data":[{"symbol":"MINA/GBP","bids":[{"price":0.0294,"qty":1018.67572156}],"asks":[],"checksum":3798394521,"timestamp":"2026-08-18T20:44:00.932079Z"}]}}
{"rx_ns": 23840538726900, "frame": {"channel":"book","type":"update","data":[{"symbol":"MINA/GBP","bids":[],"asks":[{"price":0.0296,"qty":18831.49589194}],"checksum":87372953,"timestamp":"2026-08-18T20:44:00.932762Z"}]}}
{"rx_ns": 23840543212100, "frame": {"channel":"book","type":"update","data":[{"symbol":"MINA/GBP","bids":[{"price":0.0294,"qty":0.00000000},{"price":0.0020,"qty":5220.00000000},{"price":0.0292,"qty":19851.90405521}],"asks":[],"checksum":1818111995,"timestamp":"2026-08-18T20:44:00.934299Z"}]}}
{"rx_ns": 23840952486300, "frame": {"channel":"book","type":"update","data":[{"symbol":"MINA/GBP","bids":[{"price":0.0294,"qty":16481.18016607}],"asks":[],"checksum":2935366079,"timestamp":"2026-08-18T20:44:01.346207Z"}]}}
{"rx_ns": 23840952534600, "frame": {"channel":"book","type":"update","data":[{"symbol":"MINA/GBP","bids":[],"asks":[{"price":0.0296,"qty":31631.33320878}],"checksum":2657934669,"timestamp":"2026-08-18T20:44:01.346426Z"}]}}
{"rx_ns": 23841383554400, "frame": {"channel":"heartbeat"}}
{"rx_ns": 23842344401200, "frame": {"channel":"heartbeat"}}
{"rx_ns": 23842944700800, "frame": {"channel":"book","type":"update","data":[{"symbol":"MINA/GBP","bids":[{"price":0.0285,"qty":173.82122344}],"asks":[],"checksum":4182188741,"timestamp":"2026-08-18T20:44:03.340363Z"}]}}
{"rx_ns": 23843345590600, "frame": {"channel":"heartbeat"}}
{"rx_ns": 23844346329300, "frame": {"channel":"heartbeat"}}
{"rx_ns": 23844931683500, "frame": {"channel":"book","type":"update","data":[{"symbol":"MINA/GBP","bids":[{"price":0.0293,"qty":18831.49589194}],"asks":[],"checksum":1758443317,"timestamp":"2026-08-18T20:44:05.328245Z"}]}}
{"rx_ns": 23844933053600, "frame": {"channel":"book","type":"update","data":[{"symbol":"MINA/GBP","bids":[{"price":0.0293,"qty":21499.73184254}],"asks":[],"checksum":2494867628,"timestamp":"2026-08-18T20:44:05.330419Z"}]}}
{"rx_ns": 23845346051000, "frame": {"channel":"heartbeat"}}
{"rx_ns": 23846347117700, "frame": {"channel":"heartbeat"}}
{"rx_ns": 23847346388500, "frame": {"channel":"heartbeat"}}
{"rx_ns": 23848355935900, "frame": {"channel":"heartbeat"}}
{"rx_ns": 23849355060300, "frame": {"channel":"heartbeat"}}
{"rx_ns": 23850350064600, "frame": {"channel":"heartbeat"}}
{"rx_ns": 23851347016300, "frame": {"channel":"heartbeat"}}
{"rx_ns": 23852352129400, "frame": {"channel":"heartbeat"}}
{"rx_ns": 23853348196100, "frame": {"channel":"heartbeat"}}
{"rx_ns": 23854347574000, "frame": {"channel":"heartbeat"}}
{"rx_ns": 23855349240400, "frame": {"channel":"heartbeat"}}
{"rx_ns": 23856347863800, "frame": {"channel":"heartbeat"}}
{"rx_ns": 23857348636500, "frame": {"channel":"heartbeat"}}
{"rx_ns": 23858347561500, "frame": {"channel":"heartbeat"}}
{"rx_ns": 23859348967700, "frame": {"channel":"heartbeat"}}
{"rx_ns": 23860348108900, "frame": {"channel":"heartbeat"}}
{"rx_ns": 23861351052900, "frame": {"channel":"heartbeat"}}
{"rx_ns": 23862350427700, "frame": {"channel":"heartbeat"}}
{"rx_ns": 23863148914900, "frame": {"channel":"book","type":"update","data":[{"symbol":"MINA/GBP","bids":[],"asks":[{"price":0.0295,"qty":18831.49589194}],"checksum":258340409,"timestamp":"2026-08-18T20:44:23.542362Z"}]}}
{"rx_ns": 23863148978500, "frame": {"channel":"book","type":"update","data":[{"symbol":"MINA/GBP","bids":[{"price":0.0293,"qty":18831.49589194}],"asks":[],"checksum":4078889376,"timestamp":"2026-08-18T20:44:23.542436Z"}]}}
{"rx_ns": 23863148996400, "frame": {"channel":"book","type":"update","data":[{"symbol":"MINA/GBP","bids":[],"asks":[{"price":0.0297,"qty":18831.49589194},{"price":0.0295,"qty":19850.17161350}],"checksum":4009417639,"timestamp":"2026-08-18T20:44:23.543829Z"}]}}
{"rx_ns": 23863149011100, "frame": {"channel":"book","type":"update","data":[{"symbol":"MINA/GBP","bids":[],"asks":[{"price":0.0295,"qty":27322.32050993}],"checksum":4082599318,"timestamp":"2026-08-18T20:44:23.544217Z"}]}}
{"rx_ns": 23863149024100, "frame": {"channel":"book","type":"update","data":[{"symbol":"MINA/GBP","bids":[{"price":0.0293,"qty":25260.33438876}],"asks":[],"checksum":1105194951,"timestamp":"2026-08-18T20:44:23.544565Z"}]}}
{"rx_ns": 23863350686700, "frame": {"channel":"heartbeat"}}
{"rx_ns": 23864350238500, "frame": {"channel":"heartbeat"}}
{"rx_ns": 23865357374500, "frame": {"channel":"heartbeat"}}
{"rx_ns": 23866352147800, "frame": {"channel":"heartbeat"}}
{"rx_ns": 23867353752700, "frame": {"channel":"heartbeat"}}
{"rx_ns": 23868352344100, "frame": {"channel":"heartbeat"}}
{"rx_ns": 23869353480500, "frame": {"channel":"heartbeat"}}
{"rx_ns": 23869353635700, "dir": "tx", "frame": {"method":"unsubscribe","params":{"channel":"book","symbol":["MINA/GBP"],"depth":25}}}
{"rx_ns": 23869368127200, "frame": {"method":"unsubscribe","result":{"channel":"book","depth":25,"symbol":"MINA/GBP"},"success":true,"time_in":"2026-08-18T20:44:29.766514Z","time_out":"2026-08-18T20:44:29.766559Z"}}
{"rx_ns": 23870353255900, "frame": {"channel":"heartbeat"}}
{"rx_ns": 23870353382600, "dir": "tx", "frame": {"method":"subscribe","params":{"channel":"book","symbol":["MINA/GBP"],"depth":25,"snapshot":true}}}
{"rx_ns": 23870376326600, "frame": {"method":"subscribe","result":{"channel":"book","depth":25,"snapshot":true,"symbol":"MINA/GBP"},"success":true,"time_in":"2026-08-18T20:44:30.766551Z","time_out":"2026-08-18T20:44:30.766583Z"}}
{"rx_ns": 23870414765800, "frame": {"channel":"book","type":"snapshot","data":[{"symbol":"MINA/GBP","bids":[{"price":0.0294,"qty":16481.18016607},{"price":0.0293,"qty":25260.33438876},{"price":0.0292,"qty":19851.90405521},{"price":0.0285,"qty":173.82122344},{"price":0.0284,"qty":5287.46119218},{"price":0.0283,"qty":13306.45662928},{"price":0.0281,"qty":1794.68812000},{"price":0.0277,"qty":514.47653429},{"price":0.0272,"qty":523.93382352},{"price":0.0270,"qty":370.37037037},{"price":0.0267,"qty":533.74531835},{"price":0.0259,"qty":21854.79478871},{"price":0.0256,"qty":1000.00000000},{"price":0.0240,"qty":90.00000000},{"price":0.0225,"qty":2222.22222223},{"price":0.0210,"qty":2000.00000000},{"price":0.0182,"qty":3000.00000000},{"price":0.0124,"qty":90.00000000},{"price":0.0100,"qty":50.00000000},{"price":0.0086,"qty":50.00000000},{"price":0.0080,"qty":90.00000000},{"price":0.0070,"qty":120.00000000},{"price":0.0057,"qty":877.19298245},{"price":0.0050,"qty":120.00000000},{"price":0.0040,"qty":200.00000000}],"asks":[{"price":0.0295,"qty":27322.32050993},{"price":0.0296,"qty":31631.33320878},{"price":0.0297,"qty":18831.49589194},{"price":0.0298,"qty":20571.49589194},{"price":0.0307,"qty":1902.54600978},{"price":0.0312,"qty":1899.16478919},{"price":0.0316,"qty":1901.23996506},{"price":0.0489,"qty":1986.15467694},{"price":0.0600,"qty":1752.82392026},{"price":0.0800,"qty":3373.43721760},{"price":0.1150,"qty":67.55460411},{"price":0.1780,"qty":1814.14472703},{"price":0.2000,"qty":1814.14472703},{"price":0.2300,"qty":161.78901632},{"price":0.2600,"qty":510.62544699},{"price":0.2800,"qty":100.00000000},{"price":0.4790,"qty":2336.44859813},{"price":0.5300,"qty":90.00000000},{"price":0.5580,"qty":1792.11469534},{"price":0.5900,"qty":1209.42981802},{"price":0.6000,"qty":3017.83667372},{"price":0.6900,"qty":217.39130434},{"price":0.7000,"qty":14.77104874},{"price":0.7700,"qty":4.00000000},{"price":0.8000,"qty":9.52569933}],"checksum":1105194951,"timestamp":"2026-08-18T20:44:23.544565Z"}]}}
{"rx_ns": 23871358609800, "frame": {"channel":"heartbeat"}}
{"rx_ns": 23872361874200, "frame": {"channel":"heartbeat"}}
{"rx_ns": 23873365396900, "frame": {"channel":"heartbeat"}}
{"rx_ns": 23874358031100, "frame": {"channel":"heartbeat"}}
{"rx_ns": 23875359928300, "frame": {"channel":"heartbeat"}}
{"rx_ns": 23876358804400, "frame": {"channel":"heartbeat"}}
{"rx_ns": 23877386162300, "frame": {"channel":"heartbeat"}}
{"rx_ns": 23878359156300, "frame": {"channel":"heartbeat"}}
{"rx_ns": 23879360810000, "frame": {"channel":"heartbeat"}}
{"rx_ns": 23880360681600, "frame": {"channel":"heartbeat"}}
{"rx_ns": 23881361497400, "frame": {"channel":"heartbeat"}}
{"rx_ns": 23882359581100, "frame": {"channel":"heartbeat"}}
{"rx_ns": 23883361027900, "frame": {"channel":"heartbeat"}}
{"rx_ns": 23884359818000, "frame": {"channel":"heartbeat"}}
{"rx_ns": 23885366027000, "frame": {"channel":"heartbeat"}}
{"rx_ns": 23886360883900, "frame": {"channel":"heartbeat"}}
{"rx_ns": 23887364760200, "frame": {"channel":"heartbeat"}}
{"rx_ns": 23888360926100, "frame": {"channel":"heartbeat"}}
{"rx_ns": 23888543253000, "frame": {"channel":"book","type":"update","data":[{"symbol":"MINA/GBP","bids":[{"price":0.0294,"qty":0.00000000},{"price":0.0030,"qty":143.33333334}],"asks":[],"checksum":3787397148,"timestamp":"2026-08-18T20:44:48.930775Z"}]}}
{"rx_ns": 23888543316700, "frame": {"channel":"book","type":"update","data":[{"symbol":"MINA/GBP","bids":[],"asks":[{"price":0.0296,"qty":18831.49589194}],"checksum":2379771936,"timestamp":"2026-08-18T20:44:48.936483Z"}]}}
{"rx_ns": 23889364595400, "frame": {"channel":"heartbeat"}}
{"rx_ns": 23890364071400, "frame": {"channel":"heartbeat"}}
{"rx_ns": 23890481922400, "frame": {"channel":"book","type":"update","data":[{"symbol":"MINA/GBP","bids":[{"price":0.0294,"qty":19647.14589494}],"asks":[],"checksum":1653594502,"timestamp":"2026-08-18T20:44:50.880552Z"}]}}
{"rx_ns": 23890481970900, "frame": {"channel":"book","type":"update","data":[{"symbol":"MINA/GBP","bids":[],"asks":[{"price":0.0296,"qty":35155.02180275}],"checksum":3619301426,"timestamp":"2026-08-18T20:44:50.880658Z"}]}}
{"rx_ns": 23891383977700, "frame": {"channel":"heartbeat"}}
{"rx_ns": 23892364813900, "frame": {"channel":"heartbeat"}}
{"rx_ns": 23893364918200, "frame": {"channel":"heartbeat"}}
{"rx_ns": 23894366696100, "frame": {"channel":"heartbeat"}}
{"rx_ns": 23895367240200, "frame": {"channel":"heartbeat"}}
{"rx_ns": 23896370454700, "frame": {"channel":"heartbeat"}}
{"rx_ns": 23897368448100, "frame": {"channel":"heartbeat"}}
{"rx_ns": 23898366864600, "frame": {"channel":"heartbeat"}}
{"rx_ns": 23899372976700, "frame": {"channel":"heartbeat"}}
{"rx_ns": 23900367968200, "frame": {"channel":"heartbeat"}}
{"rx_ns": 23901372098200, "frame": {"channel":"heartbeat"}}
{"rx_ns": 23902369496400, "frame": {"channel":"heartbeat"}}
{"rx_ns": 23903369552400, "frame": {"channel":"heartbeat"}}
{"rx_ns": 23904372236100, "frame": {"channel":"heartbeat"}}
{"rx_ns": 23905370224500, "frame": {"channel":"heartbeat"}}
{"rx_ns": 23906373089000, "frame": {"channel":"heartbeat"}}
{"rx_ns": 23907371416900, "frame": {"channel":"heartbeat"}}
