{"rx_ns": 42948429243200, "frame": {"channel":"book","type":"update","data":[{"symbol":"BTC/USD","bids":[],"asks":[{"price":62797.3,"qty":0.00000000},{"price":62803.4,"qty":0.06960000}],"checksum":1376800992,"timestamp":"2026-08-16T23:38:03.054422Z"}]}}
{"rx_ns": 42948430759800, "frame": {"channel":"book","type":"update","data":[{"symbol":"BTC/USD","bids":[],"asks":[{"price":62800.4,"qty":0.00000000},{"price":62803.5,"qty":0.15928208}],"checksum":2523327288,"timestamp":"2026-08-16T23:38:03.056420Z"}]}}
{"rx_ns": 42948432414400, "frame": {"channel":"book","type":"update","data":[{"symbol":"BTC/USD","bids":[],"asks":[{"price":62798.8,"qty":0.05598472}],"checksum":3020957121,"timestamp":"2026-08-16T23:38:03.057290Z"}]}}
{"rx_ns": 42948506122700, "frame": {"channel":"book","type":"update","data":[{"symbol":"BTC/USD","bids":[{"price":62786.0,"qty":0.25613755}],"asks":[],"checksum":251579807,"timestamp":"2026-08-16T23:38:03.131269Z"}]}}
{"rx_ns": 42948554152400, "frame": {"channel":"book","type":"update","data":[{"symbol":"BTC/USD","bids":[{"price":62789.3,"qty":0.79631398}],"asks":[],"checksum":79891852,"timestamp":"2026-08-16T23:38:03.174339Z"}]}}
{"rx_ns": 42948620461500, "frame": {"channel":"book","type":"update","data":[{"symbol":"BTC/USD","bids":[{"price":62788.5,"qty":0.06164822}],"asks":[],"checksum":832162561,"timestamp":"2026-08-16T23:38:03.243681Z"}]}}
{"rx_ns": 42949021236900, "frame": {"channel":"book","type":"update","data":[{"symbol":"BTC/USD","bids":[],"asks":[{"price":62793.0,"qty":0.15928698}],"checksum":3677478602,"timestamp":"2026-08-16T23:38:03.645075Z"}]}}
{"rx_ns": 42949021296700, "frame": {"channel":"book","type":"update","data":[{"symbol":"BTC/USD","bids":[],"asks":[{"price":62794.3,"qty":0.23893047}],"checksum":502623758,"timestamp":"2026-08-16T23:38:03.645214Z"}]}}
{"rx_ns": 42949123575500, "frame": {"channel":"book","type":"update","data":[{"symbol":"BTC/USD","bids":[],"asks":[{"price":62798.9,"qty":0.00000000},{"price":62803.3,"qty":0.01100000}],"checksum":2928285168,"timestamp":"2026-08-16T23:38:03.747519Z"}]}}
{"rx_ns": 42949123718500, "frame": {"channel":"book","type":"update","data":[{"symbol":"BTC/USD","bids":[],"asks":[{"price":62798.8,"qty":0.00000000},{"price":62803.4,"qty":0.06960000},{"price":62800.4,"qty":0.05488265}],"checksum":1147329776,"timestamp":"2026-08-16T23:38:03.750065Z"}]}}
{"rx_ns": 42949123754400, "frame": {"channel":"book","type":"update","data":[{"symbol":"BTC/USD","bids":[],"asks":[{"price":62798.2,"qty":0.79620200}],"checksum":1896861654,"timestamp":"2026-08-16T23:38:03.750087Z"}]}}
{"rx_ns": 42949125970500, "frame": {"channel":"book","type":"update","data":[{"symbol":"BTC/USD","bids":[],"asks":[{"price":62800.4,"qty":0.00000000},{"price":62803.3,"qty":0.01100000},{"price":62798.1,"qty":0.05488265}],"checksum":157154957,"timestamp":"2026-08-16T23:38:03.751529Z"}]}}
{"rx_ns": 42949364869100, "frame": {"channel":"heartbeat"}}
{"rx_ns": 42949668787300, "frame": {"channel":"book","type":"update","data":[{"symbol":"BTC/USD","bids":[],"asks":[{"price":62801.3,"qty":0.00000000},{"price":62803.3,"qty":0.01100000},{"price":62801.9,"qty":0.03416203}],"checksum":484767258,"timestamp":"2026-08-16T23:38:04.293825Z"}]}}
{"rx_ns": 42949670919100, "frame": {"channel":"book","type":"update","data":[{"symbol":"BTC/USD","bids":[],"asks":[{"price":62798.1,"qty":0.00000000},{"price":62803.4,"qty":0.06960000},{"price":62798.2,"qty":0.85108465}],"checksum":2307391880,"timestamp":"2026-08-16T23:38:04.294812Z"}]}}
