{"captured_at": "2026-08-17T16:00:46.236527+00:00", "url": "wss://ws.kraken.com/v2", "venue": "kraken", "symbol": "MINA/GBP", "depth": 25, "subscribe": "{\"method\":\"subscribe\",\"params\":{\"channel\":\"book\",\"symbol\":[\"MINA/GBP\"],\"depth\":25,\"snapshot\":true}}", "tool_version": "0.1.0", "clock": "perf_counter_ns", "capture_mode": "baseline", "cycles": 1, "origin_sent": null, "handshake_status": "HTTP/1.1 101 Switching Protocols"}
{"rx_ns": 29589644597200, "frame": {"channel":"heartbeat"}}
{"rx_ns": 29590643070300, "frame": {"channel":"heartbeat"}}
{"rx_ns": 29591648293100, "frame": {"channel":"heartbeat"}}
{"rx_ns": 29592541952100, "frame": {"channel":"book","type":"update","data":[{"symbol":"MINA/GBP","bids":[{"price":0.0292,"qty":32787.04556319}],"asks":[],"checksum":2678396431,"timestamp":"2026-08-17T16:01:57.687440Z"}]}}
{"rx_ns": 29592545258800, "frame": {"channel":"book","type":"update","data":[{"symbol":"MINA/GBP","bids":[{"price":0.0292,"qty":35824.32593121}],"asks":[],"checksum":3472587026,"timestamp":"2026-08-17T16:01:57.690648Z"}]}}
{"rx_ns": 29592561117700, "frame": {"channel":"book","type":"update","data":[{"symbol":"MINA/GBP","bids":[{"price":0.0282,"qty":4118.22115000},{"price":0.0283,"qty":173.56200948}],"asks":[],"checksum":2859624699,"timestamp":"2026-08-17T16:01:57.699816Z"}]}}
{"rx_ns": 29592650883600, "frame": {"channel":"heartbeat"}}
{"rx_ns": 29593099152500, "frame": {"channel":"book","type":"update","data":[{"symbol":"MINA/GBP","bids":[],"asks":[{"price":0.0298,"qty":0.00000000},{"price":0.6900,"qty":217.39130434},{"price":0.0294,"qty":42544.91296110}],"checksum":2799961592,"timestamp":"2026-08-17T16:01:58.242817Z"}]}}
{"rx_ns": 29593657934200, "frame": {"channel":"heartbeat"}}
{"rx_ns": 29594646615600, "frame": {"channel":"heartbeat"}}
{"rx_ns": 29594690595400, "frame": {"channel":"book","type":"update","data":[{"symbol":"MINA/GBP","bids":[{"price":0.0281,"qty":0.00000000},{"price":0.0030,"qty":143.33333334}],"asks":[],"checksum":3600754918,"timestamp":"2026-08-17T16:01:59.835099Z"}]}}
{"rx_ns": 29594711895900, "frame": {"channel":"book","type":"update","data":[{"symbol":"MINA/GBP","bids":[{"price":0.0283,"qty":12690.34947244}],"asks":[],"checksum":1681760673,"timestamp":"2026-08-17T16:01:59.850618Z"}]}}
{"rx_ns": 29595656384800, "frame": {"channel":"heartbeat"}}
{"rx_ns": 29596669012400, "frame": {"channel":"heartbeat"}}
{"rx_ns": 29597656773500, "frame": {"channel":"heartbeat"}}
{"rx_ns": 29598658350100, "frame": {"channel":"heartbeat"}}
{"rx_ns": 29599648943100, "frame": {"channel":"heartbeat"}}
{"rx_ns": 29600648580800, "frame": {"channel":"heartbeat"}}
{"rx_ns": 29601674503100, "frame": {"channel":"heartbeat"}}
{"rx_ns": 29602660137100, "frame": {"channel":"heartbeat"}}
{"rx_ns": 29603655594900, "frame": {"channel":"heartbeat"}}
{"rx_ns": 29604648865100, "frame": {"channel":"heartbeat"}}
{"rx_ns": 29605688880200, "frame": {"channel":"heartbeat"}}
{"rx_ns": 29606649272100, "frame": {"channel":"heartbeat"}}
{"rx_ns": 29607768311300, "frame": {"channel":"heartbeat"}}
{"rx_ns": 29608657553100, "frame": {"channel":"heartbeat"}}
{"rx_ns": 29608939754400, "frame": {"channel":"book","type":"update","data":[{"symbol":"MINA/GBP","bids":[{"price":0.0292,"qty":32787.04556319}],"asks":[],"checksum":895733436,"timestamp":"2026-08-17T16:02:14.087666Z"}]}}
{"rx_ns": 29608940085200, "frame": {"channel":"book","type":"update","data":[{"symbol":"MINA/GBP","bids":[{"price":0.0292,"qty":39142.23996975}],"asks":[],"checksum":3911506025,"timestamp":"2026-08-17T16:02:14.090961Z"}]}}
{"rx_ns": 29608940139100, "frame": {"channel":"book","type":"update","data":[{"symbol":"MINA/GBP","bids":[],"asks":[{"price":0.0295,"qty":0.00000000},{"price":0.7000,"qty":14.77104874},{"price":0.0294,"qty":43568.80374608}],"checksum":2278356335,"timestamp":"2026-08-17T16:02:14.091230Z"}]}}
{"rx_ns": 29608949319700, "frame": {"channel":"book","type":"update","data":[{"symbol":"MINA/GBP","bids":[{"price":0.0283,"qty":12516.78746296},{"price":0.0284,"qty":173.69207282}],"asks":[],"checksum":573481871,"timestamp":"2026-08-17T16:02:14.100113Z"}]}}
{"rx_ns": 29609714609800, "frame": {"channel":"heartbeat"}}
{"rx_ns": 29610650293500, "frame": {"channel":"heartbeat"}}
{"rx_ns": 29611669596300, "frame": {"channel":"heartbeat"}}
{"rx_ns": 29612650143300, "frame": {"channel":"heartbeat"}}
{"rx_ns": 29613670359900, "frame": {"channel":"heartbeat"}}
{"rx_ns": 29614650831100, "frame": {"channel":"heartbeat"}}
{"rx_ns": 29615677960900, "frame": {"channel":"heartbeat"}}
{"rx_ns": 29616665471300, "frame": {"channel":"heartbeat"}}
{"rx_ns": 29617692648400, "frame": {"channel":"heartbeat"}}
{"rx_ns": 29618652673100, "frame": {"channel":"heartbeat"}}
{"rx_ns": 29619673858100, "frame": {"channel":"heartbeat"}}
{"rx_ns": 29620652088200, "frame": {"channel":"heartbeat"}}
{"rx_ns": 29621675563500, "frame": {"channel":"heartbeat"}}
{"rx_ns": 29622653916700, "frame": {"channel":"heartbeat"}}
{"rx_ns": 29623676381800, "frame": {"channel":"heartbeat"}}
{"rx_ns": 29624664512900, "frame": {"channel":"heartbeat"}}
{"rx_ns": 29625670464200, "frame": {"channel":"heartbeat"}}
{"rx_ns": 29626665042400, "frame": {"channel":"heartbeat"}}
{"rx_ns": 29627685289100, "frame": {"channel":"heartbeat"}}
{"rx_ns": 29628664601500, "frame": {"channel":"heartbeat"}}
{"rx_ns": 29629677770600, "frame": {"channel":"heartbeat"}}
{"rx_ns": 29630657252800, "frame": {"channel":"heartbeat"}}
{"rx_ns": 29631674946700, "frame": {"channel":"heartbeat"}}
{"rx_ns": 29632656372700, "frame": {"channel":"heartbeat"}}
{"rx_ns": 29633698431600, "frame": {"channel":"heartbeat"}}
{"rx_ns": 29634661720400, "frame": {"channel":"heartbeat"}}
{"rx_ns": 29634792644100, "frame": {"channel":"book","type":"update","data":[{"symbol":"MINA/GBP","bids":[{"price":0.0292,"qty":25186.69029850}],"asks":[],"checksum":1181674290,"timestamp":"2026-08-17T16:02:39.931507Z"}]}}
{"rx_ns": 29634795181100, "frame": {"channel":"book","type":"update","data":[{"symbol":"MINA/GBP","bids":[],"asks":[{"price":0.0294,"qty":28127.19740334}],"checksum":2095680596,"timestamp":"2026-08-17T16:02:39.936485Z"}]}}
{"rx_ns": 29635432799100, "frame": {"channel":"book","type":"update","data":[{"symbol":"MINA/GBP","bids":[{"price":0.0292,"qty":38502.94991441}],"asks":[],"checksum":2442361651,"timestamp":"2026-08-17T16:02:40.574217Z"}]}}
{"rx_ns": 29635432860400, "frame": {"channel":"book","type":"update","data":[{"symbol":"MINA/GBP","bids":[],"asks":[{"price":0.0294,"qty":47131.05141388}],"checksum":2995996182,"timestamp":"2026-08-17T16:02:40.574480Z"}]}}
{"rx_ns": 29635694754500, "frame": {"channel":"heartbeat"}}
{"rx_ns": 29636669284600, "frame": {"channel":"heartbeat"}}
{"rx_ns": 29637732607300, "frame": {"channel":"heartbeat"}}
{"rx_ns": 29638657878700, "frame": {"channel":"heartbeat"}}
{"rx_ns": 29639751259300, "frame": {"channel":"heartbeat"}}
{"rx_ns": 29640669108500, "frame": {"channel":"heartbeat"}}
{"rx_ns": 29641128853200, "frame": {"channel":"book","type":"update","data":[{"symbol":"MINA/GBP","bids":[],"asks":[{"price":0.0294,"qty":21428.38415808}],"checksum":2742321583,"timestamp":"2026-08-17T16:02:46.279149Z"}]}}
{"rx_ns": 29641680608700, "frame": {"channel":"heartbeat"}}
{"rx_ns": 29642658336900, "frame": {"channel":"heartbeat"}}
{"rx_ns": 29643020269400, "frame": {"channel":"book","type":"update","data":[{"symbol":"MINA/GBP","bids":[],"asks":[{"price":0.0294,"qty":20027.74479552},{"price":0.0301,"qty":1400.63936256}],"checksum":3613749499,"timestamp":"2026-08-17T16:02:48.171520Z"}]}}
{"rx_ns": 29643028091000, "frame": {"channel":"book","type":"update","data":[{"symbol":"MINA/GBP","bids":[],"asks":[{"price":0.0294,"qty":1023.89078498}],"checksum":3779609833,"timestamp":"2026-08-17T16:02:48.176863Z"}]}}
{"rx_ns": 29643031637600, "frame": {"channel":"book","type":"update","data":[{"symbol":"MINA/GBP","bids":[],"asks":[{"price":0.0294,"qty":0.00000000},{"price":0.7000,"qty":14.77104874},{"price":0.0295,"qty":1023.89078498}],"checksum":3008705299,"timestamp":"2026-08-17T16:02:48.178744Z"}]}}
{"rx_ns": 29643034568000, "frame": {"channel":"book","type":"update","data":[{"symbol":"MINA/GBP","bids":[],"asks":[{"price":0.0295,"qty":20222.34343061}],"checksum":649905212,"timestamp":"2026-08-17T16:02:48.186048Z"}]}}
{"rx_ns": 29643037771200, "frame": {"channel":"book","type":"update","data":[{"symbol":"MINA/GBP","bids":[],"asks":[{"price":0.0295,"qty":19198.45264563},{"price":0.0294,"qty":1023.89078498}],"checksum":3431297242,"timestamp":"2026-08-17T16:02:48.187457Z"}]}}
{"rx_ns": 29643045185600, "frame": {"channel":"book","type":"update","data":[{"symbol":"MINA/GBP","bids":[],"asks":[{"price":0.0295,"qty":0.00000000},{"price":0.6900,"qty":217.39130434}],"checksum":3779609833,"timestamp":"2026-08-17T16:02:48.196512Z"}]}}
{"rx_ns": 29643050507600, "frame": {"channel":"book","type":"update","data":[{"symbol":"MINA/GBP","bids":[],"asks":[{"price":0.0294,"qty":0.00000000},{"price":0.7000,"qty":14.77104874},{"price":0.0295,"qty":1023.89078498}],"checksum":3008705299,"timestamp":"2026-08-17T16:02:48.198008Z"}]}}
{"rx_ns": 29643056870300, "frame": {"channel":"book","type":"update","data":[{"symbol":"MINA/GBP","bids":[],"asks":[{"price":0.0295,"qty":16929.45943760}],"checksum":2176736972,"timestamp":"2026-08-17T16:02:48.207043Z"}]}}
{"rx_ns": 29643059163500, "frame": {"channel":"book","type":"update","data":[{"symbol":"MINA/GBP","bids":[],"asks":[{"price":0.0295,"qty":15905.56865262},{"price":0.0294,"qty":1023.89078498}],"checksum":2024828478,"timestamp":"2026-08-17T16:02:48.208706Z"}]}}
{"rx_ns": 29643668040400, "frame": {"channel":"heartbeat"}}
{"rx_ns": 29644659798900, "frame": {"channel":"heartbeat"}}
{"rx_ns": 29645669679000, "frame": {"channel":"heartbeat"}}
{"rx_ns": 29646666790100, "frame": {"channel":"heartbeat"}}
{"rx_ns": 29647680317500, "frame": {"channel":"heartbeat"}}
{"rx_ns": 29648680259800, "frame": {"channel":"heartbeat"}}
{"rx_ns": 29649672635500, "frame": {"channel":"heartbeat"}}
{"rx_ns": 29650663066700, "frame": {"channel":"heartbeat"}}
{"rx_ns": 29651679793800, "frame": {"channel":"heartbeat"}}
{"rx_ns": 29652663551500, "frame": {"channel":"heartbeat"}}
{"rx_ns": 29653679612000, "frame": {"channel":"heartbeat"}}
{"rx_ns": 29654661931700, "frame": {"channel":"heartbeat"}}
{"rx_ns": 29655670902900, "frame": {"channel":"heartbeat"}}
{"rx_ns": 29656662367700, "frame": {"channel":"heartbeat"}}
{"rx_ns": 29657682615500, "frame": {"channel":"heartbeat"}}
{"rx_ns": 29658688587900, "frame": {"channel":"heartbeat"}}
{"rx_ns": 29659679566800, "frame": {"channel":"heartbeat"}}
{"rx_ns": 29659704129100, "frame": {"channel":"book","type":"update","data":[{"symbol":"MINA/GBP","bids":[],"asks":[{"price":0.0294,"qty":5768.13589264}],"checksum":3717001516,"timestamp":"2026-08-17T16:03:04.844552Z"}]}}
{"rx_ns": 29659722273900, "frame": {"channel":"book","type":"update","data":[{"symbol":"MINA/GBP","bids":[],"asks":[{"price":0.0295,"qty":0.00000000},{"price":0.6900,"qty":217.39130434}],"checksum":3613539790,"timestamp":"2026-08-17T16:03:04.858877Z"}]}}
{"rx_ns": 29660676391800, "frame": {"channel":"heartbeat"}}
{"rx_ns": 29660870267400, "frame": {"channel":"book","type":"update","data":[{"symbol":"MINA/GBP","bids":[],"asks":[{"price":0.0301,"qty":0.00000000},{"price":0.7000,"qty":14.77104874},{"price":0.0303,"qty":1400.63936256}],"checksum":1228151652,"timestamp":"2026-08-17T16:03:06.003343Z"}]}}
{"rx_ns": 29660877884500, "frame": {"channel":"book","type":"update","data":[{"symbol":"MINA/GBP","bids":[],"asks":[{"price":0.0294,"qty":23960.04797493}],"checksum":2739487756,"timestamp":"2026-08-17T16:03:06.013981Z"}]}}
{"rx_ns": 29661691238900, "frame": {"channel":"heartbeat"}}
{"rx_ns": 29662672193000, "frame": {"channel":"heartbeat"}}
{"rx_ns": 29663675341600, "frame": {"channel":"heartbeat"}}
{"rx_ns": 29664422493800, "frame": {"channel":"book","type":"update","data":[{"symbol":"MINA/GBP","bids":[],"asks":[{"price":0.0303,"qty":0.00000000},{"price":0.7000,"qty":14.77104874},{"price":0.0301,"qty":1400.63936256}],"checksum":1025467046,"timestamp":"2026-08-17T16:03:09.573140Z"}]}}
{"rx_ns": 29664668134100, "frame": {"channel":"heartbeat"}}
{"rx_ns": 29665691771500, "frame": {"channel":"heartbeat"}}
{"rx_ns": 29666672306300, "frame": {"channel":"heartbeat"}}
{"rx_ns": 29667696150700, "frame": {"channel":"heartbeat"}}
{"rx_ns": 29668665790700, "frame": {"channel":"heartbeat"}}
{"rx_ns": 29669701420600, "frame": {"channel":"heartbeat"}}
{"rx_ns": 29670674131700, "frame": {"channel":"heartbeat"}}
{"rx_ns": 29671784105100, "frame": {"channel":"heartbeat"}}
{"rx_ns": 29672667207900, "frame": {"channel":"heartbeat"}}
{"rx_ns": 29673694000500, "frame": {"channel":"heartbeat"}}
{"rx_ns": 29674683542300, "frame": {"channel":"heartbeat"}}
{"rx_ns": 29675682190800, "frame": {"channel":"heartbeat"}}
{"rx_ns": 29676671171500, "frame": {"channel":"heartbeat"}}
{"rx_ns": 29677678160200, "frame": {"channel":"heartbeat"}}
{"rx_ns": 29678672404100, "frame": {"channel":"heartbeat"}}
{"rx_ns": 29679680578200, "frame": {"channel":"heartbeat"}}
{"rx_ns": 29680670528300, "frame": {"channel":"heartbeat"}}
{"rx_ns": 29681677308800, "frame": {"channel":"heartbeat"}}
{"rx_ns": 29682672938800, "frame": {"channel":"heartbeat"}}
{"rx_ns": 29682724600300, "frame": {"channel":"book","type":"update","data":[{"symbol":"MINA/GBP","bids":[],"asks":[{"price":0.0294,"qty":5768.13589264}],"checksum":3613539790,"timestamp":"2026-08-17T16:03:27.863738Z"}]}}
{"rx_ns": 29682724672800, "frame": {"channel":"book","type":"update","data":[{"symbol":"MINA/GBP","bids":[{"price":0.0292,"qty":19671.45402247}],"asks":[],"checksum":3675038410,"timestamp":"2026-08-17T16:03:27.867977Z"}]}}
{"rx_ns": 29682725440900, "frame": {"channel":"book","type":"update","data":[{"symbol":"MINA/GBP","bids":[],"asks":[{"price":0.0295,"qty":14624.76077916}],"checksum":4290962165,"timestamp":"2026-08-17T16:03:27.873870Z"}]}}
{"rx_ns": 29682725495000, "frame": {"channel":"book","type":"update","data":[{"symbol":"MINA/GBP","bids":[{"price":0.0292,"qty":13316.25961591}],"asks":[],"checksum":2001537543,"timestamp":"2026-08-17T16:03:27.874257Z"}]}}
{"rx_ns": 29682725507300, "frame": {"channel":"book","type":"update","data":[{"symbol":"MINA/GBP","bids":[{"price":0.0291,"qty":27125.45548061}],"asks":[],"checksum":2454676553,"timestamp":"2026-08-17T16:03:27.876145Z"}]}}
{"rx_ns": 29682729615300, "frame": {"channel":"book","type":"update","data":[{"symbol":"MINA/GBP","bids":[],"asks":[{"price":0.0296,"qty":0.00000000},{"price":0.6900,"qty":217.39130434}],"checksum":406014075,"timestamp":"2026-08-17T16:03:27.878829Z"}]}}
{"rx_ns": 29682749751800, "frame": {"channel":"book","type":"update","data":[{"symbol":"MINA/GBP","bids":[],"asks":[{"price":0.0295,"qty":0.00000000},{"price":0.7000,"qty":14.77104874}],"checksum":490686893,"timestamp":"2026-08-17T16:03:27.883654Z"}]}}
{"rx_ns": 29682749812200, "frame": {"channel":"book","type":"update","data":[{"symbol":"MINA/GBP","bids":[{"price":0.0292,"qty":0.00000000},{"price":0.0030,"qty":143.33333334}],"asks":[],"checksum":993834549,"timestamp":"2026-08-17T16:03:27.884063Z"}]}}
{"rx_ns": 29682749841300, "frame": {"channel":"book","type":"update","data":[{"symbol":"MINA/GBP","bids":[{"price":0.0292,"qty":3933.49760608}],"asks":[],"checksum":3475227298,"timestamp":"2026-08-17T16:03:27.885479Z"}]}}
{"rx_ns": 29682764656100, "frame": {"channel":"book","type":"update","data":[{"symbol":"MINA/GBP","bids":[],"asks":[{"price":0.0293,"qty":16131.06060873}],"checksum":4196906132,"timestamp":"2026-08-17T16:03:27.892074Z"}]}}
{"rx_ns": 29682764709900, "frame": {"channel":"book","type":"update","data":[{"symbol":"MINA/GBP","bids":[{"price":0.0291,"qty":44535.93660813}],"asks":[],"checksum":3700853941,"timestamp":"2026-08-17T16:03:27.892239Z"}]}}
{"rx_ns": 29682764739300, "frame": {"channel":"book","type":"update","data":[{"symbol":"MINA/GBP","bids":[{"price":0.0258,"qty":0.00000000},{"price":0.0030,"qty":143.33333334},{"price":0.0257,"qty":22999.46968249}],"asks":[],"checksum":3700853941,"timestamp":"2026-08-17T16:03:27.894130Z"}]}}
{"rx_ns": 29682764761700, "frame": {"channel":"book","type":"update","data":[{"symbol":"MINA/GBP","bids":[],"asks":[{"price":0.0293,"qty":0.00000000},{"price":0.7000,"qty":14.77104874}],"checksum":3918723715,"timestamp":"2026-08-17T16:03:27.902136Z"}]}}
{"rx_ns": 29682764781100, "frame": {"channel":"book","type":"update","data":[{"symbol":"MINA/GBP","bids":[{"price":0.0257,"qty":0.00000000},{"price":0.0030,"qty":143.33333334},{"price":0.0258,"qty":22910.32445116}],"asks":[],"checksum":3918723715,"timestamp":"2026-08-17T16:03:27.909071Z"}]}}
{"rx_ns": 29682765169500, "frame": {"channel":"book","type":"update","data":[{"symbol":"MINA/GBP","bids":[],"asks":[{"price":0.0293,"qty":18829.07303954}],"checksum":1513298149,"timestamp":"2026-08-17T16:03:27.917165Z"}]}}
{"rx_ns": 29682786397600, "frame": {"channel":"book","type":"update","data":[{"symbol":"MINA/GBP","bids":[{"price":0.0258,"qty":0.00000000},{"price":0.0030,"qty":143.33333334},{"price":0.0257,"qty":22999.46968249}],"asks":[],"checksum":1513298149,"timestamp":"2026-08-17T16:03:27.923930Z"}]}}
{"rx_ns": 29682861843200, "frame": {"channel":"book","type":"update","data":[{"symbol":"MINA/GBP","bids":[{"price":0.0292,"qty":0.00000000},{"price":0.0030,"qty":143.33333334}],"asks":[],"checksum":1893140798,"timestamp":"2026-08-17T16:03:28.000562Z"}]}}
{"rx_ns": 29682920993200, "frame": {"channel":"book","type":"update","data":[{"symbol":"MINA/GBP","bids":[],"asks":[{"price":0.0295,"qty":1740.00000000}],"checksum":862376561,"timestamp":"2026-08-17T16:03:28.064063Z"}]}}
{"rx_ns": 29683685708600, "frame": {"channel":"heartbeat"}}
{"rx_ns": 29684410727100, "frame": {"channel":"book","type":"update","data":[{"symbol":"MINA/GBP","bids":[{"price":0.0279,"qty":905.72811000},{"price":0.0258,"qty":974.37238000}],"asks":[],"checksum":1136973679,"timestamp":"2026-08-17T16:03:29.552327Z"}]}}
{"rx_ns": 29684410845200, "frame": {"channel":"book","type":"update","data":[{"symbol":"MINA/GBP","bids":[],"asks":[{"price":0.0294,"qty":4744.24510766},{"price":0.0293,"qty":19852.96382452}],"checksum":1213939467,"timestamp":"2026-08-17T16:03:29.553799Z"}]}}
