{"captured_at": "2026-08-16T23:37:02.871589+00:00", "url": "wss://ws.kraken.com/v2", "venue": "kraken", "symbol": "BTC/USD", "depth": 10, "subscribe": "{\"method\":\"subscribe\",\"params\":{\"channel\":\"book\",\"symbol\":[\"BTC/USD\"],\"depth\":10,\"snapshot\":true}}", "tool_version": "0.1.0", "clock": "perf_counter_ns", "capture_mode": "baseline", "cycles": 1, "origin_sent": null, "handshake_status": "HTTP/1.1 101 Switching Protocols"}
{"rx_ns": 42889692105400, "dir": "tx", "frame": {"method":"subscribe","params":{"channel":"book","symbol":["BTC/USD"],"depth":10,"snapshot":true}}}
{"rx_ns": 42889692520900, "frame": {"channel":"status","type":"update","data":[{"version":"2.0.10","system":"online","api_version":"v2","connection_id":769405522530892351}]}}
{"rx_ns": 42889707647600, "frame": {"method":"subscribe","result":{"channel":"book","depth":10,"snapshot":true,"symbol":"BTC/USD"},"success":true,"time_in":"2026-08-16T23:37:04.334090Z","time_out":"2026-08-16T23:37:04.334135Z"}}
{"rx_ns": 42889711202000, "frame": {"channel":"book","type":"snapshot","data":[{"symbol":"BTC/USD","bids":[{"price":62802.5,"qty":0.02987767},{"price":62800.7,"qty":0.05598472},{"price":62800.6,"qty":0.00005100},{"price":62797.5,"qty":0.00005100},{"price":62797.0,"qty":0.00012700},{"price":62796.2,"qty":0.00019900},{"price":62794.3,"qty":0.00005100},{"price":62794.0,"qty":0.00532806},{"price":62793.9,"qty":0.79625467},{"price":62793.1,"qty":0.00318620}],"asks":[{"price":62802.6,"qty":1.09074394},{"price":62803.7,"qty":0.05598472},{"price":62803.8,"qty":0.95536416},{"price":62803.9,"qty":1.16228981},{"price":62806.5,"qty":0.18489680},{"price":62806.6,"qty":3.79004471},{"price":62806.8,"qty":0.00005100},{"price":62807.1,"qty":0.36000000},{"price":62807.2,"qty":0.65540712},{"price":62807.4,"qty":0.50920200}],"checksum":975661613,"timestamp":"2026-08-16T23:37:04.316445Z"}]}}
{"rx_ns": 42890352382600, "frame": {"channel":"heartbeat"}}
{"rx_ns": 42890751040400, "frame": {"channel":"book","type":"update","data":[{"symbol":"BTC/USD","bids":[],"asks":[{"price":62806.6,"qty":0.00000000},{"price":62808.0,"qty":0.79607759},{"price":62803.8,"qty":4.74541363}],"checksum":265834348,"timestamp":"2026-08-16T23:37:05.376419Z"}]}}
{"rx_ns": 42890751119100, "frame": {"channel":"book","type":"update","data":[{"symbol":"BTC/USD","bids":[],"asks":[{"price":62802.6,"qty":0.98074394}],"checksum":1348273380,"timestamp":"2026-08-16T23:37:05.377468Z"}]}}
{"rx_ns": 42890752747200, "frame": {"channel":"book","type":"update","data":[{"symbol":"BTC/USD","bids":[],"asks":[{"price":62806.5,"qty":0.00000000},{"price":62809.9,"qty":0.00005100},{"price":62807.0,"qty":0.18489680}],"checksum":3676157681,"timestamp":"2026-08-16T23:37:05.377919Z"}]}}
{"rx_ns": 42890757790500, "frame": {"channel":"book","type":"update","data":[{"symbol":"BTC/USD","bids":[],"asks":[{"price":62802.6,"qty":0.90274394}],"checksum":2543465031,"timestamp":"2026-08-16T23:37:05.380457Z"}]}}
{"rx_ns": 42890775054200, "frame": {"channel":"book","type":"update","data":[{"symbol":"BTC/USD","bids":[],"asks":[{"price":62803.8,"qty":0.95536416},{"price":62806.4,"qty":3.79004364}],"checksum":441069893,"timestamp":"2026-08-16T23:37:05.399046Z"}]}}
{"rx_ns": 42891189725300, "frame": {"channel":"book","type":"update","data":[{"symbol":"BTC/USD","bids":[],"asks":[{"price":62806.4,"qty":0.00000000},{"price":62808.0,"qty":0.79607759},{"price":62803.7,"qty":3.84603600}],"checksum":3303084279,"timestamp":"2026-08-16T23:37:05.815233Z"}]}}
{"rx_ns": 42891213527500, "frame": {"channel":"book","type":"update","data":[{"symbol":"BTC/USD","bids":[],"asks":[{"price":62803.7,"qty":0.05598472},{"price":62806.9,"qty":3.79000109}],"checksum":2474031404,"timestamp":"2026-08-16T23:37:05.837728Z"}]}}
{"rx_ns": 42891214882200, "frame": {"channel":"book","type":"update","data":[{"symbol":"BTC/USD","bids":[],"asks":[{"price":62807.0,"qty":0.00000000},{"price":62808.0,"qty":0.79607759},{"price":62806.8,"qty":0.18494780}],"checksum":3569469293,"timestamp":"2026-08-16T23:37:05.839103Z"}]}}
{"rx_ns": 42891247160400, "frame": {"channel":"book","type":"update","data":[{"symbol":"BTC/USD","bids":[{"price":62802.5,"qty":0.00849808}],"asks":[],"checksum":1879693603,"timestamp":"2026-08-16T23:37:05.871705Z"}]}}
{"rx_ns": 42891251074700, "frame": {"channel":"book","type":"update","data":[{"symbol":"BTC/USD","bids":[{"price":62801.4,"qty":0.02137959}],"asks":[],"checksum":50978620,"timestamp":"2026-08-16T23:37:05.872920Z"}]}}
{"rx_ns": 42891251134500, "frame": {"channel":"book","type":"update","data":[{"symbol":"BTC/USD","bids":[{"price":62800.7,"qty":0.00000000},{"price":62793.1,"qty":0.00318620},{"price":62801.5,"qty":0.05598472}],"asks":[],"checksum":1604503902,"timestamp":"2026-08-16T23:37:05.873993Z"}]}}
{"rx_ns": 42891348451200, "frame": {"channel":"heartbeat"}}
{"rx_ns": 42891649594300, "frame": {"channel":"book","type":"update","data":[{"symbol":"BTC/USD","bids":[{"price":62801.5,"qty":0.00000000},{"price":62793.0,"qty":0.00318620}],"asks":[],"checksum":3719378320,"timestamp":"2026-08-16T23:37:06.275708Z"}]}}
{"rx_ns": 42891652463800, "frame": {"channel":"book","type":"update","data":[{"symbol":"BTC/USD","bids":[{"price":62797.6,"qty":0.05598472}],"asks":[],"checksum":2564800303,"timestamp":"2026-08-16T23:37:06.276752Z"}]}}
{"rx_ns": 42891662823400, "frame": {"channel":"book","type":"update","data":[{"symbol":"BTC/USD","bids":[{"price":62793.9,"qty":0.00000000},{"price":62793.0,"qty":0.00318620}],"asks":[],"checksum":110749926,"timestamp":"2026-08-16T23:37:06.285045Z"}]}}
{"rx_ns": 42891666026900, "frame": {"channel":"book","type":"update","data":[{"symbol":"BTC/USD","bids":[{"price":62793.2,"qty":0.79626397}],"asks":[],"checksum":2330494038,"timestamp":"2026-08-16T23:37:06.286874Z"}]}}
{"rx_ns": 42891671873700, "frame": {"channel":"book","type":"update","data":[{"symbol":"BTC/USD","bids":[],"asks":[{"price":62803.8,"qty":0.79613017}],"checksum":371959854,"timestamp":"2026-08-16T23:37:06.297387Z"}]}}
{"rx_ns": 42891706336700, "frame": {"channel":"book","type":"update","data":[{"symbol":"BTC/USD","bids":[{"price":62794.0,"qty":0.00000000},{"price":62793.0,"qty":0.00318620}],"asks":[],"checksum":2630192712,"timestamp":"2026-08-16T23:37:06.324556Z"}]}}
{"rx_ns": 42891718195400, "frame": {"channel":"book","type":"update","data":[{"symbol":"BTC/USD","bids":[],"asks":[{"price":62802.6,"qty":1.06197793}],"checksum":2871320315,"timestamp":"2026-08-16T23:37:06.334835Z"}]}}
{"rx_ns": 42891718271200, "frame": {"channel":"book","type":"update","data":[{"symbol":"BTC/USD","bids":[],"asks":[{"price":62802.6,"qty":1.13997793}],"checksum":1696580693,"timestamp":"2026-08-16T23:37:06.336631Z"}]}}
{"rx_ns": 42891737826100, "frame": {"channel":"book","type":"update","data":[{"symbol":"BTC/USD","bids":[],"asks":[{"price":62806.9,"qty":0.00000000},{"price":62809.9,"qty":0.00005100},{"price":62803.8,"qty":4.58617734}],"checksum":54414482,"timestamp":"2026-08-16T23:37:06.361885Z"}]}}
{"rx_ns": 42892129755300, "frame": {"channel":"book","type":"update","data":[{"symbol":"BTC/USD","bids":[],"asks":[{"price":62803.8,"qty":0.79613017},{"price":62806.7,"qty":3.79004495}],"checksum":1900210029,"timestamp":"2026-08-16T23:37:06.750448Z"}]}}
{"rx_ns": 42892129828000, "frame": {"channel":"book","type":"update","data":[{"symbol":"BTC/USD","bids":[],"asks":[{"price":62806.8,"qty":0.00005100},{"price":62806.6,"qty":0.18489680}],"checksum":1899318310,"timestamp":"2026-08-16T23:37:06.751983Z"}]}}
{"rx_ns": 42892313481300, "frame": {"channel":"book","type":"update","data":[{"symbol":"BTC/USD","bids":[],"asks":[{"price":62807.1,"qty":0.00000000},{"price":62808.0,"qty":0.79607759}],"checksum":4083933284,"timestamp":"2026-08-16T23:37:06.938737Z"}]}}
{"rx_ns": 42892349719900, "frame": {"channel":"heartbeat"}}
{"rx_ns": 42892680616300, "frame": {"channel":"book","type":"update","data":[{"symbol":"BTC/USD","bids":[],"asks":[{"price":62806.7,"qty":0.00000000},{"price":62809.9,"qty":0.00005100},{"price":62803.8,"qty":4.58618091}],"checksum":2043980972,"timestamp":"2026-08-16T23:37:07.300795Z"}]}}
{"rx_ns": 42892680701400, "frame": {"channel":"book","type":"update","data":[{"symbol":"BTC/USD","bids":[],"asks":[{"price":62806.6,"qty":0.00000000},{"price":62810.0,"qty":0.00756724},{"price":62807.9,"qty":0.18489680}],"checksum":235672643,"timestamp":"2026-08-16T23:37:07.302093Z"}]}}
{"rx_ns": 42892896832600, "frame": {"channel":"book","type":"update","data":[{"symbol":"BTC/USD","bids":[],"asks":[{"price":62807.1,"qty":0.36000000}],"checksum":3521650448,"timestamp":"2026-08-16T23:37:07.520640Z"}]}}
{"rx_ns": 42892898494600, "frame": {"channel":"book","type":"update","data":[{"symbol":"BTC/USD","bids":[],"asks":[{"price":62807.9,"qty":0.00000000},{"price":62809.9,"qty":0.00005100},{"price":62807.0,"qty":0.18489680}],"checksum":4056636036,"timestamp":"2026-08-16T23:37:07.521946Z"}]}}
{"rx_ns": 42892948706400, "frame": {"channel":"book","type":"update","data":[{"symbol":"BTC/USD","bids":[],"asks":[{"price":62807.2,"qty":0.00000000},{"price":62809.9,"qty":0.00005100}],"checksum":4219639166,"timestamp":"2026-08-16T23:37:07.574122Z"}]}}
{"rx_ns": 42893348255500, "frame": {"channel":"heartbeat"}}
{"rx_ns": 42893439031000, "frame": {"channel":"book","type":"update","data":[{"symbol":"BTC/USD","bids":[],"asks":[{"price":62803.8,"qty":0.79613017},{"price":62806.9,"qty":3.79000581}],"checksum":2688985755,"timestamp":"2026-08-16T23:37:08.064059Z"}]}}
{"rx_ns": 42893440850500, "frame": {"channel":"book","type":"update","data":[{"symbol":"BTC/USD","bids":[],"asks":[{"price":62807.0,"qty":0.00000000},{"price":62809.9,"qty":0.00005100},{"price":62806.8,"qty":0.18494780}],"checksum":4088415580,"timestamp":"2026-08-16T23:37:08.065495Z"}]}}
{"rx_ns": 42893462233300, "frame": {"channel":"book","type":"update","data":[{"symbol":"BTC/USD","bids":[],"asks":[{"price":62806.9,"qty":0.00000000},{"price":62810.0,"qty":0.00756724},{"price":62803.7,"qty":3.84603605}],"checksum":1080158762,"timestamp":"2026-08-16T23:37:08.087504Z"}]}}
{"rx_ns": 42893462697600, "frame": {"channel":"book","type":"update","data":[{"symbol":"BTC/USD","bids":[],"asks":[{"price":62803.7,"qty":3.79005133},{"price":62803.6,"qty":0.05598472}],"checksum":1312528143,"timestamp":"2026-08-16T23:37:08.088677Z"}]}}
{"rx_ns": 42893464742600, "frame": {"channel":"book","type":"update","data":[{"symbol":"BTC/USD","bids":[],"asks":[{"price":62806.8,"qty":0.00005100},{"price":62807.9,"qty":0.18489680}],"checksum":1201675115,"timestamp":"2026-08-16T23:37:08.088784Z"}]}}
{"rx_ns": 42893491695200, "frame": {"channel":"book","type":"update","data":[{"symbol":"BTC/USD","bids":[],"asks":[{"price":62803.7,"qty":0.00000000},{"price":62809.9,"qty":0.00005100},{"price":62806.9,"qty":3.79004418}],"checksum":440535564,"timestamp":"2026-08-16T23:37:08.117588Z"}]}}
{"rx_ns": 42893494037300, "frame": {"channel":"book","type":"update","data":[{"symbol":"BTC/USD","bids":[],"asks":[{"price":62807.9,"qty":0.00000000},{"price":62809.9,"qty":0.00005100},{"price":62806.8,"qty":0.18494780}],"checksum":2494929030,"timestamp":"2026-08-16T23:37:08.118838Z"}]}}
{"rx_ns": 42893494117200, "frame": {"channel":"book","type":"update","data":[{"symbol":"BTC/USD","bids":[],"asks":[{"price":62803.6,"qty":0.00000000},{"price":62810.0,"qty":0.00756724},{"price":62803.7,"qty":0.05598472}],"checksum":2465943611,"timestamp":"2026-08-16T23:37:08.118853Z"}]}}
{"rx_ns": 42894096236300, "frame": {"channel":"book","type":"update","data":[{"symbol":"BTC/USD","bids":[],"asks":[{"price":62806.9,"qty":0.00000000},{"price":62810.0,"qty":0.00756724},{"price":62803.6,"qty":3.79008032}],"checksum":485000038,"timestamp":"2026-08-16T23:37:08.719864Z"}]}}
{"rx_ns": 42894096315600, "frame": {"channel":"book","type":"update","data":[{"symbol":"BTC/USD","bids":[],"asks":[{"price":62806.8,"qty":0.00005100},{"price":62807.9,"qty":0.18489680}],"checksum":359862018,"timestamp":"2026-08-16T23:37:08.721198Z"}]}}
{"rx_ns": 42894096330400, "frame": {"channel":"book","type":"update","data":[{"symbol":"BTC/USD","bids":[],"asks":[{"price":62803.7,"qty":0.00000000},{"price":62809.9,"qty":0.00005100},{"price":62803.5,"qty":0.05598472}],"checksum":2947842144,"timestamp":"2026-08-16T23:37:08.721219Z"}]}}
{"rx_ns": 42894128346700, "frame": {"channel":"book","type":"update","data":[{"symbol":"BTC/USD","bids":[],"asks":[{"price":62803.6,"qty":0.00000000},{"price":62809.9,"qty":0.00005100},{"price":62806.7,"qty":3.79001496}],"checksum":1565111361,"timestamp":"2026-08-16T23:37:08.751537Z"}]}}
{"rx_ns": 42894129779900, "frame": {"channel":"book","type":"update","data":[{"symbol":"BTC/USD","bids":[],"asks":[{"price":62803.5,"qty":0.00000000},{"price":62809.9,"qty":0.00005100},{"price":62803.7,"qty":0.05598472}],"checksum":1372857659,"timestamp":"2026-08-16T23:37:08.753024Z"}]}}
{"rx_ns": 42894349514100, "frame": {"channel":"heartbeat"}}
{"rx_ns": 42894389495500, "frame": {"channel":"book","type":"update","data":[{"symbol":"BTC/USD","bids":[],"asks":[{"price":62806.7,"qty":0.00000000},{"price":62809.9,"qty":0.00005100},{"price":62803.8,"qty":4.58618103}],"checksum":1864190754,"timestamp":"2026-08-16T23:37:09.015116Z"}]}}
{"rx_ns": 42894421281100, "frame": {"channel":"book","type":"update","data":[{"symbol":"BTC/USD","bids":[],"asks":[{"price":62803.8,"qty":0.79613017},{"price":62807.0,"qty":3.78999969}],"checksum":3292457266,"timestamp":"2026-08-16T23:37:09.045279Z"}]}}
{"rx_ns": 42894424867400, "frame": {"channel":"book","type":"update","data":[{"symbol":"BTC/USD","bids":[],"asks":[{"price":62807.9,"qty":0.00000000},{"price":62809.9,"qty":0.00005100},{"price":62806.9,"qty":0.18489680}],"checksum":3897311709,"timestamp":"2026-08-16T23:37:09.047337Z"}]}}
{"rx_ns": 42894438724500, "frame": {"channel":"book","type":"update","data":[{"symbol":"BTC/USD","bids":[{"price":62793.2,"qty":0.00000000},{"price":62792.9,"qty":0.00015923}],"asks":[],"checksum":3560232215,"timestamp":"2026-08-16T23:37:09.053796Z"}]}}
{"rx_ns": 42894444656700, "frame": {"channel":"book","type":"update","data":[{"symbol":"BTC/USD","bids":[{"price":62793.8,"qty":0.79625623}],"asks":[],"checksum":3165917908,"timestamp":"2026-08-16T23:37:09.062522Z"}]}}
{"rx_ns": 42894515588500, "frame": {"channel":"book","type":"update","data":[{"symbol":"BTC/USD","bids":[],"asks":[{"price":62803.7,"qty":0.00000000},{"price":62809.9,"qty":0.00005100}],"checksum":2451645330,"timestamp":"2026-08-16T23:37:09.140594Z"}]}}
{"rx_ns": 42894518930100, "frame": {"channel":"book","type":"update","data":[{"symbol":"BTC/USD","bids":[{"price":62797.6,"qty":0.00000000},{"price":62792.9,"qty":0.00015923},{"price":62802.5,"qty":0.06448280}],"asks":[],"checksum":1825135173,"timestamp":"2026-08-16T23:37:09.141793Z"}]}}
{"rx_ns": 42894518973100, "frame": {"channel":"book","type":"update","data":[{"symbol":"BTC/USD","bids":[],"asks":[{"price":62803.9,"qty":1.21827453}],"checksum":336881173,"timestamp":"2026-08-16T23:37:09.141970Z"}]}}
{"rx_ns": 42894521203800, "frame": {"channel":"book","type":"update","data":[{"symbol":"BTC/USD","bids":[{"price":62793.0,"qty":0.00000000},{"price":62792.1,"qty":0.00318511},{"price":62793.1,"qty":0.00318620}],"asks":[],"checksum":4215722228,"timestamp":"2026-08-16T23:37:09.144533Z"}]}}
{"rx_ns": 42894773901400, "frame": {"channel":"book","type":"update","data":[{"symbol":"BTC/USD","bids":[{"price":62794.0,"qty":0.00552708}],"asks":[],"checksum":197040151,"timestamp":"2026-08-16T23:37:09.399268Z"}]}}
{"rx_ns": 42895353461400, "frame": {"channel":"heartbeat"}}
{"rx_ns": 42895594900700, "frame": {"channel":"book","type":"update","data":[{"symbol":"BTC/USD","bids":[{"price":62802.5,"qty":0.00849808}],"asks":[],"checksum":979958136,"timestamp":"2026-08-16T23:37:10.213367Z"}]}}
{"rx_ns": 42895594974900, "frame": {"channel":"book","type":"update","data":[{"symbol":"BTC/USD","bids":[{"price":62797.6,"qty":0.05598472}],"asks":[],"checksum":4106223823,"timestamp":"2026-08-16T23:37:10.214795Z"}]}}
{"rx_ns": 42895595000900, "frame": {"channel":"book","type":"update","data":[{"symbol":"BTC/USD","bids":[],"asks":[{"price":62803.9,"qty":1.16228981},{"price":62803.7,"qty":0.05598472}],"checksum":2974203201,"timestamp":"2026-08-16T23:37:10.215095Z"}]}}
{"rx_ns": 42895595014800, "frame": {"channel":"book","type":"update","data":[{"symbol":"BTC/USD","bids":[],"asks":[{"price":62802.6,"qty":1.06197793}],"checksum":613166112,"timestamp":"2026-08-16T23:37:10.215138Z"}]}}
{"rx_ns": 42895660211500, "frame": {"channel":"book","type":"update","data":[{"symbol":"BTC/USD","bids":[{"price":62793.8,"qty":0.00000000},{"price":62793.1,"qty":0.00318620}],"asks":[],"checksum":1294649062,"timestamp":"2026-08-16T23:37:10.285432Z"}]}}
{"rx_ns": 42895851215400, "frame": {"channel":"book","type":"update","data":[{"symbol":"BTC/USD","bids":[{"price":62794.0,"qty":0.00000000},{"price":62793.0,"qty":0.79626632}],"asks":[],"checksum":2847926976,"timestamp":"2026-08-16T23:37:10.474842Z"}]}}
{"rx_ns": 42895859624700, "frame": {"channel":"book","type":"update","data":[{"symbol":"BTC/USD","bids":[],"asks":[{"price":62807.0,"qty":0.00000000},{"price":62809.9,"qty":0.00005100},{"price":62803.8,"qty":4.58617735}],"checksum":1988537768,"timestamp":"2026-08-16T23:37:10.484052Z"}]}}
{"rx_ns": 42895864494300, "frame": {"channel":"book","type":"update","data":[{"symbol":"BTC/USD","bids":[],"asks":[{"price":62806.9,"qty":0.00000000},{"price":62810.0,"qty":0.00756724},{"price":62807.9,"qty":0.18489680}],"checksum":2074920805,"timestamp":"2026-08-16T23:37:10.485180Z"}]}}
{"rx_ns": 42895891557100, "frame": {"channel":"book","type":"update","data":[{"symbol":"BTC/USD","bids":[],"asks":[{"price":62802.6,"qty":1.13157793}],"checksum":2207559158,"timestamp":"2026-08-16T23:37:10.513171Z"}]}}
{"rx_ns": 42895894611800, "frame": {"channel":"book","type":"update","data":[{"symbol":"BTC/USD","bids":[],"asks":[{"price":62802.6,"qty":1.20957793}],"checksum":1974850468,"timestamp":"2026-08-16T23:37:10.515555Z"}]}}
{"rx_ns": 42895998426300, "frame": {"channel":"book","type":"update","data":[{"symbol":"BTC/USD","bids":[],"asks":[{"price":62803.9,"qty":1.81769693}],"checksum":2820170745,"timestamp":"2026-08-16T23:37:10.622759Z"}]}}
{"rx_ns": 42896000941100, "frame": {"channel":"book","type":"update","data":[{"symbol":"BTC/USD","bids":[],"asks":[{"price":62807.9,"qty":0.00000000},{"price":62810.0,"qty":0.00756724},{"price":62807.0,"qty":0.18489680}],"checksum":3636937355,"timestamp":"2026-08-16T23:37:10.623835Z"}]}}
{"rx_ns": 42896037942500, "frame": {"channel":"book","type":"update","data":[{"symbol":"BTC/USD","bids":[],"asks":[{"price":62803.8,"qty":0.79613017},{"price":62802.6,"qty":4.99970683}],"checksum":3663539781,"timestamp":"2026-08-16T23:37:10.662581Z"}]}}
{"rx_ns": 42896039242800, "frame": {"channel":"book","type":"update","data":[{"symbol":"BTC/USD","bids":[{"price":62793.1,"qty":0.00000000},{"price":62792.9,"qty":0.00015923},{"price":62793.0,"qty":0.79945252}],"asks":[],"checksum":120787881,"timestamp":"2026-08-16T23:37:10.665069Z"}]}}
{"rx_ns": 42896105369400, "frame": {"channel":"book","type":"update","data":[{"symbol":"BTC/USD","bids":[],"asks":[{"price":62808.0,"qty":0.80163538}],"checksum":966893802,"timestamp":"2026-08-16T23:37:10.731196Z"}]}}
{"rx_ns": 42896147935100, "frame": {"channel":"book","type":"update","data":[{"symbol":"BTC/USD","bids":[{"price":62793.0,"qty":0.00318620}],"asks":[],"checksum":4115027398,"timestamp":"2026-08-16T23:37:10.771692Z"}]}}
{"rx_ns": 42896349810000, "frame": {"channel":"heartbeat"}}
{"rx_ns": 42896553834000, "frame": {"channel":"book","type":"update","data":[{"symbol":"BTC/USD","bids":[],"asks":[{"price":62802.6,"qty":1.20957793},{"price":62803.6,"qty":3.79008208}],"checksum":3334117364,"timestamp":"2026-08-16T23:37:11.177506Z"}]}}
{"rx_ns": 42896553874200, "frame": {"channel":"book","type":"update","data":[{"symbol":"BTC/USD","bids":[],"asks":[{"price":62803.7,"qty":0.00000000},{"price":62809.9,"qty":0.00005100},{"price":62803.5,"qty":0.05598472}],"checksum":533271318,"timestamp":"2026-08-16T23:37:11.178829Z"}]}}
{"rx_ns": 42896586849300, "frame": {"channel":"book","type":"update","data":[{"symbol":"BTC/USD","bids":[],"asks":[{"price":62803.6,"qty":0.00000000},{"price":62809.9,"qty":0.00005100},{"price":62802.6,"qty":4.99971332}],"checksum":3762211511,"timestamp":"2026-08-16T23:37:11.210125Z"}]}}
{"rx_ns": 42896588386700, "frame": {"channel":"book","type":"update","data":[{"symbol":"BTC/USD","bids":[],"asks":[{"price":62803.5,"qty":0.00000000},{"price":62810.0,"qty":0.00756724},{"price":62803.7,"qty":0.05598472}],"checksum":1027078409,"timestamp":"2026-08-16T23:37:11.211864Z"}]}}
{"rx_ns": 42896638801000, "frame": {"channel":"book","type":"update","data":[{"symbol":"BTC/USD","bids":[],"asks":[{"price":62802.6,"qty":1.20957793},{"price":62803.6,"qty":3.79012046}],"checksum":3780872311,"timestamp":"2026-08-16T23:37:11.263989Z"}]}}
{"rx_ns": 42896685755000, "frame": {"channel":"book","type":"update","data":[{"symbol":"BTC/USD","bids":[],"asks":[{"price":62803.6,"qty":0.00000000},{"price":62809.9,"qty":0.00005100},{"price":62802.6,"qty":4.99971268}],"checksum":1382623541,"timestamp":"2026-08-16T23:37:11.311297Z"}]}}
{"rx_ns": 42896840439700, "frame": {"channel":"book","type":"update","data":[{"symbol":"BTC/USD","bids":[],"asks":[{"price":62803.9,"qty":1.16228981}],"checksum":682064655,"timestamp":"2026-08-16T23:37:11.464974Z"}]}}
{"rx_ns": 42896846025600, "frame": {"channel":"book","type":"update","data":[{"symbol":"BTC/USD","bids":[],"asks":[{"price":62802.6,"qty":4.93011268}],"checksum":4071950562,"timestamp":"2026-08-16T23:37:11.470378Z"}]}}
{"rx_ns": 42896851404100, "frame": {"channel":"book","type":"update","data":[{"symbol":"BTC/USD","bids":[{"price":62793.4,"qty":0.79626152}],"asks":[],"checksum":2617994829,"timestamp":"2026-08-16T23:37:11.473715Z"}]}}
{"rx_ns": 42896851456300, "frame": {"channel":"book","type":"update","data":[{"symbol":"BTC/USD","bids":[],"asks":[{"price":62802.6,"qty":1.13997793},{"price":62803.6,"qty":3.79008208}],"checksum":4104263212,"timestamp":"2026-08-16T23:37:11.474505Z"}]}}
{"rx_ns": 42896855106200, "frame": {"channel":"book","type":"update","data":[{"symbol":"BTC/USD","bids":[],"asks":[{"price":62803.7,"qty":0.00000000},{"price":62809.9,"qty":0.00005100},{"price":62803.5,"qty":0.05598472}],"checksum":3358027762,"timestamp":"2026-08-16T23:37:11.475874Z"}]}}
{"rx_ns": 42896870135200, "frame": {"channel":"book","type":"update","data":[{"symbol":"BTC/USD","bids":[{"price":62793.4,"qty":0.00000000},{"price":62792.9,"qty":0.00015923}],"asks":[],"checksum":181708683,"timestamp":"2026-08-16T23:37:11.495336Z"}]}}
{"rx_ns": 42896893647600, "frame": {"channel":"book","type":"update","data":[{"symbol":"BTC/USD","bids":[],"asks":[{"price":62808.0,"qty":0.79607759}],"checksum":2964866042,"timestamp":"2026-08-16T23:37:11.518945Z"}]}}
{"rx_ns": 42896949015500, "frame": {"channel":"book","type":"update","data":[{"symbol":"BTC/USD","bids":[{"price":62793.1,"qty":0.79626564}],"asks":[],"checksum":953773812,"timestamp":"2026-08-16T23:37:11.573970Z"}]}}
{"rx_ns": 42897015091500, "frame": {"channel":"book","type":"update","data":[{"symbol":"BTC/USD","bids":[],"asks":[{"price":62803.6,"qty":0.00000000},{"price":62809.9,"qty":0.00005100},{"price":62806.9,"qty":3.79004492}],"checksum":1717844585,"timestamp":"2026-08-16T23:37:11.640118Z"}]}}
{"rx_ns": 42897016538800, "frame": {"channel":"book","type":"update","data":[{"symbol":"BTC/USD","bids":[],"asks":[{"price":62803.5,"qty":0.00000000},{"price":62809.9,"qty":0.00005100},{"price":62803.7,"qty":0.05598472}],"checksum":1794747155,"timestamp":"2026-08-16T23:37:11.641389Z"}]}}
{"rx_ns": 42897016584100, "frame": {"channel":"book","type":"update","data":[{"symbol":"BTC/USD","bids":[],"asks":[{"price":62807.0,"qty":0.00000000},{"price":62809.9,"qty":0.00005100},{"price":62806.8,"qty":0.18494780}],"checksum":3992508294,"timestamp":"2026-08-16T23:37:11.641459Z"}]}}
{"rx_ns": 42897073459700, "frame": {"channel":"book","type":"update","data":[{"symbol":"BTC/USD","bids":[{"price":62793.1,"qty":0.00000000},{"price":62792.9,"qty":0.00015923}],"asks":[],"checksum":3849491617,"timestamp":"2026-08-16T23:37:11.698183Z"}]}}
{"rx_ns": 42897078229500, "frame": {"channel":"book","type":"update","data":[{"symbol":"BTC/USD","bids":[],"asks":[{"price":62802.6,"qty":1.20957793}],"checksum":1117952424,"timestamp":"2026-08-16T23:37:11.698610Z"}]}}
{"rx_ns": 42897081478900, "frame": {"channel":"book","type":"update","data":[{"symbol":"BTC/USD","bids":[],"asks":[{"price":62808.0,"qty":0.80146697}],"checksum":2471279502,"timestamp":"2026-08-16T23:37:11.704540Z"}]}}
{"rx_ns": 42897086753500, "frame": {"channel":"book","type":"update","data":[{"symbol":"BTC/USD","bids":[{"price":62801.4,"qty":0.00000000},{"price":62792.1,"qty":0.00318511}],"asks":[],"checksum":2080124398,"timestamp":"2026-08-16T23:37:11.705438Z"}]}}
{"rx_ns": 42897090225500, "frame": {"channel":"book","type":"update","data":[{"symbol":"BTC/USD","bids":[{"price":62798.8,"qty":0.02137959}],"asks":[],"checksum":934498548,"timestamp":"2026-08-16T23:37:11.712240Z"}]}}
{"rx_ns": 42897090404700, "frame": {"channel":"book","type":"update","data":[{"symbol":"BTC/USD","bids":[],"asks":[{"price":62806.9,"qty":0.00000000},{"price":62810.0,"qty":0.00756724},{"price":62802.6,"qty":4.99984308}],"checksum":3465157871,"timestamp":"2026-08-16T23:37:11.712472Z"}]}}
{"rx_ns": 42897097128500, "frame": {"channel":"book","type":"update","data":[{"symbol":"BTC/USD","bids":[],"asks":[{"price":62802.6,"qty":5.65525020}],"checksum":2187582356,"timestamp":"2026-08-16T23:37:11.714679Z"}]}}
{"rx_ns": 42897100129600, "frame": {"channel":"book","type":"update","data":[{"symbol":"BTC/USD","bids":[],"asks":[{"price":62803.7,"qty":0.00000000},{"price":62810.2,"qty":0.06000000},{"price":62802.6,"qty":5.71123492}],"checksum":3085279688,"timestamp":"2026-08-16T23:37:11.721981Z"}]}}
{"rx_ns": 42897132536100, "frame": {"channel":"book","type":"update","data":[{"symbol":"BTC/USD","bids":[{"price":62798.8,"qty":0.00000000},{"price":62792.1,"qty":0.00318511}],"asks":[],"checksum":1214962299,"timestamp":"2026-08-16T23:37:11.756737Z"}]}}
{"rx_ns": 42897138490400, "frame": {"channel":"book","type":"update","data":[{"symbol":"BTC/USD","bids":[{"price":62797.5,"qty":0.02143059}],"asks":[],"checksum":1032397851,"timestamp":"2026-08-16T23:37:11.758379Z"}]}}
{"rx_ns": 42897180898300, "frame": {"channel":"book","type":"update","data":[{"symbol":"BTC/USD","bids":[],"asks":[{"price":62806.0,"qty":0.00537797}],"checksum":3704904613,"timestamp":"2026-08-16T23:37:11.805822Z"}]}}
{"rx_ns": 42897300276400, "frame": {"channel":"book","type":"update","data":[{"symbol":"BTC/USD","bids":[],"asks":[{"price":62802.6,"qty":5.65525020},{"price":62803.7,"qty":0.05598472}],"checksum":1389439018,"timestamp":"2026-08-16T23:37:11.922993Z"}]}}
{"rx_ns": 42897300373400, "frame": {"channel":"book","type":"update","data":[{"symbol":"BTC/USD","bids":[{"price":62797.5,"qty":0.00005100}],"asks":[],"checksum":1073822854,"timestamp":"2026-08-16T23:37:11.924319Z"}]}}
{"rx_ns": 42897300386900, "frame": {"channel":"book","type":"update","data":[{"symbol":"BTC/USD","bids":[{"price":62798.8,"qty":0.02137959}],"asks":[],"checksum":1960920207,"timestamp":"2026-08-16T23:37:11.924378Z"}]}}
{"rx_ns": 42897349114100, "frame": {"channel":"heartbeat"}}
{"rx_ns": 42897369560800, "frame": {"channel":"book","type":"update","data":[{"symbol":"BTC/USD","bids":[{"price":62798.8,"qty":0.00000000},{"price":62792.1,"qty":0.00318511}],"asks":[],"checksum":1073822854,"timestamp":"2026-08-16T23:37:11.976558Z"}]}}
{"rx_ns": 42897369688800, "frame": {"channel":"book","type":"update","data":[{"symbol":"BTC/USD","bids":[{"price":62799.8,"qty":0.02137959}],"asks":[],"checksum":3642521851,"timestamp":"2026-08-16T23:37:11.976799Z"}]}}
{"rx_ns": 42897551673300, "frame": {"channel":"book","type":"update","data":[{"symbol":"BTC/USD","bids":[{"price":62793.0,"qty":0.00000000},{"price":62792.1,"qty":0.00318511},{"price":62792.9,"qty":0.00334543}],"asks":[],"checksum":826747392,"timestamp":"2026-08-16T23:37:12.176483Z"}]}}
{"rx_ns": 42897577325300, "frame": {"channel":"book","type":"update","data":[{"symbol":"BTC/USD","bids":[{"price":62799.8,"qty":0.00000000},{"price":62791.4,"qty":0.06083209}],"asks":[],"checksum":3187817973,"timestamp":"2026-08-16T23:37:12.194533Z"}]}}
{"rx_ns": 42897577404800, "frame": {"channel":"book","type":"update","data":[{"symbol":"BTC/USD","bids":[{"price":62800.7,"qty":0.02137959}],"asks":[],"checksum":585990068,"timestamp":"2026-08-16T23:37:12.194725Z"}]}}
{"rx_ns": 42898151814200, "frame": {"channel":"book","type":"update","data":[{"symbol":"BTC/USD","bids":[{"price":62800.7,"qty":0.00000000},{"price":62791.4,"qty":0.06083209}],"asks":[],"checksum":3187817973,"timestamp":"2026-08-16T23:37:12.775009Z"}]}}
{"rx_ns": 42898162334500, "frame": {"channel":"book","type":"update","data":[{"symbol":"BTC/USD","bids":[{"price":62798.4,"qty":0.02137959}],"asks":[],"checksum":3545983341,"timestamp":"2026-08-16T23:37:12.776831Z"}]}}
{"rx_ns": 42898162403200, "frame": {"channel":"book","type":"update","data":[{"symbol":"BTC/USD","bids":[],"asks":[{"price":62802.6,"qty":5.76525020}],"checksum":1486616732,"timestamp":"2026-08-16T23:37:12.778064Z"}]}}
{"rx_ns": 42898162415100, "frame": {"channel":"book","type":"update","data":[{"symbol":"BTC/USD","bids":[],"asks":[{"price":62803.7,"qty":0.00000000},{"price":62810.0,"qty":0.00756724},{"price":62802.6,"qty":5.82123492}],"checksum":2303946671,"timestamp":"2026-08-16T23:37:12.779302Z"}]}}
{"rx_ns": 42898162427300, "frame": {"channel":"book","type":"update","data":[{"symbol":"BTC/USD","bids":[{"price":62797.6,"qty":0.00000000},{"price":62791.4,"qty":0.06083209}],"asks":[],"checksum":110839787,"timestamp":"2026-08-16T23:37:12.779406Z"}]}}
{"rx_ns": 42898170667100, "frame": {"channel":"book","type":"update","data":[{"symbol":"BTC/USD","bids":[],"asks":[{"price":62805.6,"qty":0.65540712}],"checksum":1758381660,"timestamp":"2026-08-16T23:37:12.784945Z"}]}}
{"rx_ns": 42898170719800, "frame": {"channel":"book","type":"update","data":[{"symbol":"BTC/USD","bids":[],"asks":[{"price":62808.0,"qty":0.80465128}],"checksum":629431951,"timestamp":"2026-08-16T23:37:12.788738Z"}]}}
{"rx_ns": 42898179452900, "frame": {"channel":"book","type":"update","data":[{"symbol":"BTC/USD","bids":[],"asks":[{"price":62806.8,"qty":0.00005100},{"price":62805.5,"qty":0.18489680}],"checksum":3971036504,"timestamp":"2026-08-16T23:37:12.792748Z"}]}}
{"rx_ns": 42898179500200, "frame": {"channel":"book","type":"update","data":[{"symbol":"BTC/USD","bids":[],"asks":[{"price":62804.0,"qty":0.00518776}],"checksum":3551524133,"timestamp":"2026-08-16T23:37:12.797171Z"}]}}
{"rx_ns": 42898200970100, "frame": {"channel":"book","type":"update","data":[{"symbol":"BTC/USD","bids":[{"price":62794.4,"qty":0.05598472}],"asks":[],"checksum":824940461,"timestamp":"2026-08-16T23:37:12.804659Z"}]}}
{"rx_ns": 42898201029300, "frame": {"channel":"book","type":"update","data":[{"symbol":"BTC/USD","bids":[{"price":62796.2,"qty":0.00000000},{"price":62791.4,"qty":0.06083209}],"asks":[],"checksum":23065628,"timestamp":"2026-08-16T23:37:12.805182Z"}]}}
{"rx_ns": 42898201046200, "frame": {"channel":"book","type":"update","data":[{"symbol":"BTC/USD","bids":[{"price":62794.4,"qty":0.00000000},{"price":62791.2,"qty":0.00164300}],"asks":[],"checksum":2546430391,"timestamp":"2026-08-16T23:37:12.805732Z"}]}}
{"rx_ns": 42898221008600, "frame": {"channel":"book","type":"update","data":[{"symbol":"BTC/USD","bids":[{"price":62792.1,"qty":0.00000000},{"price":62790.6,"qty":0.02866671}],"asks":[],"checksum":1553735971,"timestamp":"2026-08-16T23:37:12.843222Z"}]}}
{"rx_ns": 42898255441600, "frame": {"channel":"book","type":"update","data":[{"symbol":"BTC/USD","bids":[],"asks":[{"price":62807.0,"qty":1.59575715}],"checksum":2819771186,"timestamp":"2026-08-16T23:37:12.879101Z"}]}}
{"rx_ns": 42898262064300, "frame": {"channel":"book","type":"update","data":[{"symbol":"BTC/USD","bids":[],"asks":[{"price":62807.0,"qty":0.00000000},{"price":62807.4,"qty":0.50920200}],"checksum":1553735971,"timestamp":"2026-08-16T23:37:12.885342Z"}]}}
{"rx_ns": 42898294529900, "frame": {"channel":"book","type":"update","data":[{"symbol":"BTC/USD","bids":[{"price":62792.9,"qty":0.00318620}],"asks":[],"checksum":1476275024,"timestamp":"2026-08-16T23:37:12.916965Z"}]}}
{"rx_ns": 42898301343500, "frame": {"channel":"book","type":"update","data":[{"symbol":"BTC/USD","bids":[],"asks":[{"price":62807.0,"qty":1.59575715}],"checksum":2742042945,"timestamp":"2026-08-16T23:37:12.926022Z"}]}}
{"rx_ns": 42898318499800, "frame": {"channel":"book","type":"update","data":[{"symbol":"BTC/USD","bids":[{"price":62790.6,"qty":0.00000000},{"price":62789.9,"qty":0.09703642}],"asks":[],"checksum":3235540812,"timestamp":"2026-08-16T23:37:12.940256Z"}]}}
{"rx_ns": 42898335502700, "frame": {"channel":"book","type":"update","data":[{"symbol":"BTC/USD","bids":[{"price":62798.4,"qty":0.00000000},{"price":62786.4,"qty":0.05598472}],"asks":[],"checksum":3404109272,"timestamp":"2026-08-16T23:37:12.957714Z"}]}}
{"rx_ns": 42898338719400, "frame": {"channel":"book","type":"update","data":[{"symbol":"BTC/USD","bids":[{"price":62797.0,"qty":0.02150659}],"asks":[],"checksum":4025759346,"timestamp":"2026-08-16T23:37:12.959954Z"}]}}
{"rx_ns": 42898353434500, "frame": {"channel":"heartbeat"}}
{"rx_ns": 42898384434500, "frame": {"channel":"book","type":"update","data":[{"symbol":"BTC/USD","bids":[],"asks":[{"price":62803.9,"qty":0.57289635}],"checksum":2791712775,"timestamp":"2026-08-16T23:37:12.982804Z"}]}}
{"rx_ns": 42898384477200, "frame": {"channel":"book","type":"update","data":[{"symbol":"BTC/USD","bids":[],"asks":[{"price":62805.5,"qty":0.00000000},{"price":62807.4,"qty":0.50920200},{"price":62806.9,"qty":0.18489680}],"checksum":1905968279,"timestamp":"2026-08-16T23:37:12.985101Z"}]}}
{"rx_ns": 42898384493600, "frame": {"channel":"book","type":"update","data":[{"symbol":"BTC/USD","bids":[{"price":62797.0,"qty":0.00012700}],"asks":[],"checksum":2903422294,"timestamp":"2026-08-16T23:37:13.001862Z"}]}}
{"rx_ns": 42898384504500, "frame": {"channel":"book","type":"update","data":[{"symbol":"BTC/USD","bids":[{"price":62796.0,"qty":0.02137959}],"asks":[],"checksum":3183349564,"timestamp":"2026-08-16T23:37:13.003110Z"}]}}
{"rx_ns": 42898392645800, "frame": {"channel":"book","type":"update","data":[{"symbol":"BTC/USD","bids":[{"price":62802.5,"qty":0.00049808}],"asks":[],"checksum":1327756067,"timestamp":"2026-08-16T23:37:13.011009Z"}]}}
{"rx_ns": 42898392692100, "frame": {"channel":"book","type":"update","data":[{"symbol":"BTC/USD","bids":[],"asks":[{"price":62807.0,"qty":0.00000000},{"price":62807.4,"qty":0.50920200}],"checksum":4286353542,"timestamp":"2026-08-16T23:37:13.013789Z"}]}}
{"rx_ns": 42898398253000, "frame": {"channel":"book","type":"update","data":[{"symbol":"BTC/USD","bids":[{"price":62802.5,"qty":0.00010000},{"price":62802.5,"qty":0.00000000},{"price":62786.4,"qty":0.05598472}],"asks":[{"price":62800.7,"qty":0.07084096}],"checksum":403221632,"timestamp":"2026-08-16T23:37:13.016972Z"}]}}
{"rx_ns": 42898398296500, "frame": {"channel":"book","type":"update","data":[{"symbol":"BTC/USD","bids":[],"asks":[{"price":62800.7,"qty":0.18084096}],"checksum":3091587529,"timestamp":"2026-08-16T23:37:13.018112Z"}]}}
{"rx_ns": 42898398305400, "frame": {"channel":"book","type":"update","data":[{"symbol":"BTC/USD","bids":[{"price":62800.6,"qty":0.00000000},{"price":62786.3,"qty":0.00829459}],"asks":[],"checksum":2907335323,"timestamp":"2026-08-16T23:37:13.018420Z"}]}}
{"rx_ns": 42898398313300, "frame": {"channel":"book","type":"update","data":[{"symbol":"BTC/USD","bids":[],"asks":[{"price":62802.6,"qty":5.76525020},{"price":62800.7,"qty":0.23682568}],"checksum":2873051894,"timestamp":"2026-08-16T23:37:13.018702Z"}]}}
{"rx_ns": 42898398320900, "frame": {"channel":"book","type":"update","data":[{"symbol":"BTC/USD","bids":[],"asks":[{"price":62802.6,"qty":5.74557538}],"checksum":3003994414,"timestamp":"2026-08-16T23:37:13.018736Z"}]}}
{"rx_ns": 42898398327100, "frame": {"channel":"book","type":"update","data":[{"symbol":"BTC/USD","bids":[],"asks":[{"price":62802.6,"qty":5.58634139}],"checksum":2382578928,"timestamp":"2026-08-16T23:37:13.018826Z"}]}}
{"rx_ns": 42898398333200, "frame": {"channel":"book","type":"update","data":[{"symbol":"BTC/USD","bids":[],"asks":[{"price":62800.7,"qty":0.31642568}],"checksum":180174683,"timestamp":"2026-08-16T23:37:13.018853Z"}]}}
{"rx_ns": 42898398339500, "frame": {"channel":"book","type":"update","data":[{"symbol":"BTC/USD","bids":[],"asks":[{"price":62800.7,"qty":0.38602568}],"checksum":2050336391,"timestamp":"2026-08-16T23:37:13.018873Z"}]}}
{"rx_ns": 42898398345800, "frame": {"channel":"book","type":"update","data":[{"symbol":"BTC/USD","bids":[],"asks":[{"price":62806.9,"qty":0.00000000},{"price":62807.4,"qty":0.50920200},{"price":62802.5,"qty":0.18489680}],"checksum":2142917193,"timestamp":"2026-08-16T23:37:13.019048Z"}]}}
{"rx_ns": 42898398353600, "frame": {"channel":"book","type":"update","data":[{"symbol":"BTC/USD","bids":[],"asks":[{"price":62802.6,"qty":5.51674139}],"checksum":2400985091,"timestamp":"2026-08-16T23:37:13.019602Z"}]}}
{"rx_ns": 42898408409800, "frame": {"channel":"book","type":"update","data":[{"symbol":"BTC/USD","bids":[{"price":62797.5,"qty":0.00000000},{"price":62785.0,"qty":0.79636797}],"asks":[],"checksum":2913601983,"timestamp":"2026-08-16T23:37:13.020845Z"}]}}
{"rx_ns": 42898408454300, "frame": {"channel":"book","type":"update","data":[{"symbol":"BTC/USD","bids":[],"asks":[{"price":62802.6,"qty":4.86133427}],"checksum":944096166,"timestamp":"2026-08-16T23:37:13.020917Z"}]}}
{"rx_ns": 42898408466200, "frame": {"channel":"book","type":"update","data":[{"symbol":"BTC/USD","bids":[],"asks":[{"price":62800.7,"qty":0.83629385}],"checksum":212590745,"timestamp":"2026-08-16T23:37:13.020976Z"}]}}
{"rx_ns": 42898408474800, "frame": {"channel":"book","type":"update","data":[{"symbol":"BTC/USD","bids":[],"asks":[{"price":62800.7,"qty":1.63246331}],"checksum":3135709292,"timestamp":"2026-08-16T23:37:13.021167Z"}]}}
{"rx_ns": 42898408483400, "frame": {"channel":"book","type":"update","data":[{"symbol":"BTC/USD","bids":[],"asks":[{"price":62802.6,"qty":4.06518889}],"checksum":3002962644,"timestamp":"2026-08-16T23:37:13.021327Z"}]}}
{"rx_ns": 42898408491700, "frame": {"channel":"book","type":"update","data":[{"symbol":"BTC/USD","bids":[],"asks":[{"price":62803.8,"qty":0.00000000},{"price":62807.4,"qty":0.50920200}],"checksum":2734298107,"timestamp":"2026-08-16T23:37:13.021351Z"}]}}
{"rx_ns": 42898408501100, "frame": {"channel":"book","type":"update","data":[{"symbol":"BTC/USD","bids":[],"asks":[{"price":62797.6,"qty":0.06960000}],"checksum":3405185678,"timestamp":"2026-08-16T23:37:13.021394Z"}]}}
{"rx_ns": 42898408510300, "frame": {"channel":"book","type":"update","data":[{"symbol":"BTC/USD","bids":[],"asks":[{"price":62800.7,"qty":1.56286331}],"checksum":2866389728,"timestamp":"2026-08-16T23:37:13.022022Z"}]}}
{"rx_ns": 42898408518600, "frame": {"channel":"book","type":"update","data":[{"symbol":"BTC/USD","bids":[],"asks":[{"price":62800.7,"qty":1.11259514}],"checksum":881858089,"timestamp":"2026-08-16T23:37:13.022090Z"}]}}
{"rx_ns": 42898408528500, "frame": {"channel":"book","type":"update","data":[{"symbol":"BTC/USD","bids":[],"asks":[{"price":62800.7,"qty":1.19059514}],"checksum":2532219740,"timestamp":"2026-08-16T23:37:13.023106Z"}]}}
{"rx_ns": 42898408536900, "frame": {"channel":"book","type":"update","data":[{"symbol":"BTC/USD","bids":[],"asks":[{"price":62800.7,"qty":0.39442568}],"checksum":3381156956,"timestamp":"2026-08-16T23:37:13.023127Z"}]}}
{"rx_ns": 42898408546100, "frame": {"channel":"book","type":"update","data":[{"symbol":"BTC/USD","bids":[],"asks":[{"price":62802.6,"qty":3.98558889}],"checksum":666767927,"timestamp":"2026-08-16T23:37:13.023552Z"}]}}
{"rx_ns": 42898408556400, "frame": {"channel":"book","type":"update","data":[{"symbol":"BTC/USD","bids":[],"asks":[{"price":62800.7,"qty":0.31482568}],"checksum":1885372546,"timestamp":"2026-08-16T23:37:13.023719Z"}]}}
{"rx_ns": 42898408576000, "frame": {"channel":"book","type":"update","data":[{"symbol":"BTC/USD","bids":[],"asks":[{"price":62797.6,"qty":0.14920000}],"checksum":3396078074,"timestamp":"2026-08-16T23:37:13.024133Z"}]}}
{"rx_ns": 42898408586600, "frame": {"channel":"book","type":"update","data":[{"symbol":"BTC/USD","bids":[{"price":62791.4,"qty":0.00000000},{"price":62783.3,"qty":0.06960000}],"asks":[],"checksum":3873733962,"timestamp":"2026-08-16T23:37:13.025420Z"}]}}
{"rx_ns": 42898408597300, "frame": {"channel":"book","type":"update","data":[{"symbol":"BTC/USD","bids":[],"asks":[{"price":62802.5,"qty":0.19566797}],"checksum":110438741,"timestamp":"2026-08-16T23:37:13.025555Z"}]}}
{"rx_ns": 42898408607000, "frame": {"channel":"book","type":"update","data":[{"symbol":"BTC/USD","bids":[],"asks":[{"price":62797.6,"qty":0.07960000}],"checksum":2607988117,"timestamp":"2026-08-16T23:37:13.026041Z"}]}}
{"rx_ns": 42898408667500, "frame": {"channel":"book","type":"update","data":[{"symbol":"BTC/USD","bids":[],"asks":[{"price":62797.1,"qty":0.06960000}],"checksum":3298962471,"timestamp":"2026-08-16T23:37:13.026178Z"}]}}
{"rx_ns": 42898408681000, "frame": {"channel":"book","type":"update","data":[{"symbol":"BTC/USD","bids":[{"price":62792.9,"qty":0.00000000},{"price":62781.2,"qty":0.01311942},{"price":62787.4,"qty":0.00318620}],"asks":[],"checksum":2182572719,"timestamp":"2026-08-16T23:37:13.026947Z"}]}}
{"rx_ns": 42898408693600, "frame": {"channel":"book","type":"update","data":[{"symbol":"BTC/USD","bids":[],"asks":[{"price":62806.8,"qty":0.00323720}],"checksum":2498127341,"timestamp":"2026-08-16T23:37:13.027202Z"}]}}
{"rx_ns": 42898408702600, "frame": {"channel":"book","type":"update","data":[{"symbol":"BTC/USD","bids":[],"asks":[{"price":62797.6,"qty":0.15760000}],"checksum":3089088190,"timestamp":"2026-08-16T23:37:13.027734Z"}]}}
{"rx_ns": 42898408710600, "frame": {"channel":"book","type":"update","data":[{"symbol":"BTC/USD","bids":[],"asks":[{"price":62800.7,"qty":0.23682568}],"checksum":870085212,"timestamp":"2026-08-16T23:37:13.027841Z"}]}}
{"rx_ns": 42898408719100, "frame": {"channel":"book","type":"update","data":[{"symbol":"BTC/USD","bids":[],"asks":[{"price":62797.6,"qty":0.07800000}],"checksum":3521396130,"timestamp":"2026-08-16T23:37:13.027854Z"}]}}
{"rx_ns": 42898408727200, "frame": {"channel":"book","type":"update","data":[{"symbol":"BTC/USD","bids":[],"asks":[{"price":62797.1,"qty":0.14920000}],"checksum":2992318915,"timestamp":"2026-08-16T23:37:13.027952Z"}]}}
{"rx_ns": 42898408735400, "frame": {"channel":"book","type":"update","data":[{"symbol":"BTC/USD","bids":[],"asks":[{"price":62802.6,"qty":3.90758889}],"checksum":3493395947,"timestamp":"2026-08-16T23:37:13.028083Z"}]}}
{"rx_ns": 42898410273200, "frame": {"channel":"book","type":"update","data":[{"symbol":"BTC/USD","bids":[],"asks":[{"price":62797.6,"qty":0.00000000},{"price":62807.1,"qty":0.36000000}],"checksum":3067110439,"timestamp":"2026-08-16T23:37:13.028718Z"}]}}
{"rx_ns": 42898410322900, "frame": {"channel":"book","type":"update","data":[{"symbol":"BTC/USD","bids":[],"asks":[{"price":62797.1,"qty":0.19750000}],"checksum":2525488707,"timestamp":"2026-08-16T23:37:13.028793Z"}]}}
{"rx_ns": 42898410336600, "frame": {"channel":"book","type":"update","data":[{"symbol":"BTC/USD","bids":[],"asks":[{"price":62798.7,"qty":0.79619496}],"checksum":870418109,"timestamp":"2026-08-16T23:37:13.028824Z"}]}}
{"rx_ns": 42898410346500, "frame": {"channel":"book","type":"update","data":[{"symbol":"BTC/USD","bids":[],"asks":[{"price":62797.6,"qty":0.07084444}],"checksum":3370121935,"timestamp":"2026-08-16T23:37:13.030510Z"}]}}
{"rx_ns": 42898410355500, "frame": {"channel":"book","type":"update","data":[{"symbol":"BTC/USD","bids":[],"asks":[{"price":62797.1,"qty":0.26834500}],"checksum":3431873363,"timestamp":"2026-08-16T23:37:13.030552Z"}]}}
{"rx_ns": 42898410364400, "frame": {"channel":"book","type":"update","data":[{"symbol":"BTC/USD","bids":[],"asks":[{"price":62803.4,"qty":0.06960000}],"checksum":2503302653,"timestamp":"2026-08-16T23:37:13.030906Z"}]}}
{"rx_ns": 42898425088600, "frame": {"channel":"book","type":"update","data":[{"symbol":"BTC/USD","bids":[],"asks":[{"price":62797.1,"qty":0.42757899}],"checksum":1654766325,"timestamp":"2026-08-16T23:37:13.046260Z"}]}}
{"rx_ns": 42898425151600, "frame": {"channel":"book","type":"update","data":[{"symbol":"BTC/USD","bids":[],"asks":[{"price":62802.5,"qty":0.01077117}],"checksum":2381632431,"timestamp":"2026-08-16T23:37:13.047373Z"}]}}
{"rx_ns": 42898425341400, "frame": {"channel":"book","type":"update","data":[{"symbol":"BTC/USD","bids":[],"asks":[{"price":62803.3,"qty":0.01100000}],"checksum":4090389357,"timestamp":"2026-08-16T23:37:13.047579Z"}]}}
{"rx_ns": 42898427095700, "frame": {"channel":"book","type":"update","data":[{"symbol":"BTC/USD","bids":[],"asks":[{"price":62797.1,"qty":0.76953847}],"checksum":840042318,"timestamp":"2026-08-16T23:37:13.050885Z"}]}}
{"rx_ns": 42898430280900, "frame": {"channel":"book","type":"update","data":[{"symbol":"BTC/USD","bids":[{"price":62796.0,"qty":0.00000000},{"price":62781.2,"qty":0.01311942}],"asks":[],"checksum":3655306591,"timestamp":"2026-08-16T23:37:13.051716Z"}]}}
{"rx_ns": 42898430314200, "frame": {"channel":"book","type":"update","data":[{"symbol":"BTC/USD","bids":[],"asks":[{"price":62797.1,"qty":1.42494559}],"checksum":723689792,"timestamp":"2026-08-16T23:37:13.052821Z"}]}}
{"rx_ns": 42898430324800, "frame": {"channel":"book","type":"update","data":[{"symbol":"BTC/USD","bids":[{"price":62782.2,"qty":0.15923399}],"asks":[],"checksum":1373789466,"timestamp":"2026-08-16T23:37:13.052885Z"}]}}
{"rx_ns": 42898437825700, "frame": {"channel":"book","type":"update","data":[{"symbol":"BTC/USD","bids":[{"price":62796.9,"qty":0.02137959}],"asks":[],"checksum":3685579384,"timestamp":"2026-08-16T23:37:13.057297Z"}]}}
{"rx_ns": 42898437861100, "frame": {"channel":"book","type":"update","data":[{"symbol":"BTC/USD","bids":[],"asks":[{"price":62802.5,"qty":0.00000000},{"price":62805.6,"qty":0.65540712}],"checksum":2338405213,"timestamp":"2026-08-16T23:37:13.058201Z"}]}}
{"rx_ns": 42898437872600, "frame": {"channel":"book","type":"update","data":[{"symbol":"BTC/USD","bids":[{"price":62785.0,"qty":0.00000000},{"price":62782.2,"qty":0.15923399}],"asks":[],"checksum":1847904079,"timestamp":"2026-08-16T23:37:13.058212Z"}]}}
{"rx_ns": 42898437881500, "frame": {"channel":"book","type":"update","data":[{"symbol":"BTC/USD","bids":[],"asks":[{"price":62800.7,"qty":0.24275148}],"checksum":2704872004,"timestamp":"2026-08-16T23:37:13.059838Z"}]}}
{"rx_ns": 42898437889100, "frame": {"channel":"book","type":"update","data":[{"symbol":"BTC/USD","bids":[],"asks":[{"price":62802.6,"qty":3.90166323}],"checksum":2650887292,"timestamp":"2026-08-16T23:37:13.060091Z"}]}}
{"rx_ns": 42898439252900, "frame": {"channel":"book","type":"update","data":[{"symbol":"BTC/USD","bids":[{"price":62782.2,"qty":0.00000000},{"price":62781.2,"qty":0.01311942}],"asks":[],"checksum":1925078646,"timestamp":"2026-08-16T23:37:13.062743Z"}]}}
{"rx_ns": 42898439286800, "frame": {"channel":"book","type":"update","data":[{"symbol":"BTC/USD","bids":[],"asks":[{"price":62797.6,"qty":0.07677047}],"checksum":4156579959,"timestamp":"2026-08-16T23:37:13.064062Z"}]}}
{"rx_ns": 42898447928600, "frame": {"channel":"book","type":"update","data":[{"symbol":"BTC/USD","bids":[],"asks":[{"price":62800.7,"qty":0.23682568}],"checksum":1350627905,"timestamp":"2026-08-16T23:37:13.064370Z"}]}}
{"rx_ns": 42898447962100, "frame": {"channel":"book","type":"update","data":[{"symbol":"BTC/USD","bids":[],"asks":[{"price":62797.1,"qty":1.43087166}],"checksum":3986990149,"timestamp":"2026-08-16T23:37:13.071265Z"}]}}
{"rx_ns": 42898447970300, "frame": {"channel":"book","type":"update","data":[{"symbol":"BTC/USD","bids":[],"asks":[{"price":62797.6,"qty":0.07084444}],"checksum":1759156804,"timestamp":"2026-08-16T23:37:13.071305Z"}]}}
{"rx_ns": 42898458492600, "frame": {"channel":"book","type":"update","data":[{"symbol":"BTC/USD","bids":[{"price":62783.9,"qty":0.15923399}],"asks":[],"checksum":2464825369,"timestamp":"2026-08-16T23:37:13.084050Z"}]}}
{"rx_ns": 42898463989700, "frame": {"channel":"book","type":"update","data":[{"symbol":"BTC/USD","bids":[],"asks":[{"price":62802.6,"qty":3.90126515},{"price":62800.7,"qty":0.23722376}],"checksum":2396577722,"timestamp":"2026-08-16T23:37:13.088127Z"}]}}
{"rx_ns": 42898478428400, "frame": {"channel":"book","type":"update","data":[{"symbol":"BTC/USD","bids":[{"price":62786.4,"qty":0.00000000},{"price":62781.2,"qty":0.01311942},{"price":62791.3,"qty":0.05598472}],"asks":[],"checksum":1269445095,"timestamp":"2026-08-16T23:37:13.104176Z"}]}}
{"rx_ns": 42898481623800, "frame": {"channel":"book","type":"update","data":[{"symbol":"BTC/USD","bids":[{"price":62797.0,"qty":0.00000000},{"price":62781.2,"qty":0.01311942}],"asks":[{"price":62797.0,"qty":0.00007300}],"checksum":2115243580,"timestamp":"2026-08-16T23:37:13.106889Z"}]}}
{"rx_ns": 42898488509100, "frame": {"channel":"book","type":"update","data":[{"symbol":"BTC/USD","bids":[],"asks":[{"price":62797.0,"qty":0.01172515}],"checksum":2465731891,"timestamp":"2026-08-16T23:37:13.107492Z"}]}}
{"rx_ns": 42898488552100, "frame": {"channel":"book","type":"update","data":[{"symbol":"BTC/USD","bids":[],"asks":[{"price":62797.1,"qty":1.42494559}],"checksum":6578741,"timestamp":"2026-08-16T23:37:13.107630Z"}]}}
{"rx_ns": 42898488565000, "frame": {"channel":"book","type":"update","data":[{"symbol":"BTC/USD","bids":[],"asks":[{"price":62797.0,"qty":0.08132515}],"checksum":1338619859,"timestamp":"2026-08-16T23:37:13.108117Z"}]}}
{"rx_ns": 42898488573700, "frame": {"channel":"book","type":"update","data":[{"symbol":"BTC/USD","bids":[],"asks":[{"price":62797.1,"qty":1.35534559}],"checksum":2050678557,"timestamp":"2026-08-16T23:37:13.108151Z"}]}}
{"rx_ns": 42898488584300, "frame": {"channel":"book","type":"update","data":[{"symbol":"BTC/USD","bids":[],"asks":[{"price":62797.1,"qty":1.19611160}],"checksum":1192618340,"timestamp":"2026-08-16T23:37:13.110007Z"}]}}
{"rx_ns": 42898488591000, "frame": {"channel":"book","type":"update","data":[{"symbol":"BTC/USD","bids":[],"asks":[{"price":62797.0,"qty":0.15932515}],"checksum":2238747027,"timestamp":"2026-08-16T23:37:13.110069Z"}]}}
{"rx_ns": 42898488597300, "frame": {"channel":"book","type":"update","data":[{"symbol":"BTC/USD","bids":[],"asks":[{"price":62797.1,"qty":1.14781160}],"checksum":3548517327,"timestamp":"2026-08-16T23:37:13.110097Z"}]}}
{"rx_ns": 42898488603600, "frame": {"channel":"book","type":"update","data":[{"symbol":"BTC/USD","bids":[],"asks":[{"price":62797.1,"qty":1.06821160}],"checksum":3644668436,"timestamp":"2026-08-16T23:37:13.110233Z"}]}}
{"rx_ns": 42898488609900, "frame": {"channel":"book","type":"update","data":[{"symbol":"BTC/USD","bids":[],"asks":[{"price":62797.0,"qty":0.23892515}],"checksum":4174566184,"timestamp":"2026-08-16T23:37:13.110241Z"}]}}
{"rx_ns": 42898495396400, "frame": {"channel":"book","type":"update","data":[{"symbol":"BTC/USD","bids":[],"asks":[{"price":62797.0,"qty":0.30933848}],"checksum":3662060326,"timestamp":"2026-08-16T23:37:13.116174Z"}]}}
{"rx_ns": 42898497075100, "frame": {"channel":"book","type":"update","data":[{"symbol":"BTC/USD","bids":[],"asks":[{"price":62802.6,"qty":0.11100000}],"checksum":3946368491,"timestamp":"2026-08-16T23:37:13.118066Z"}]}}
{"rx_ns": 42898497101100, "frame": {"channel":"book","type":"update","data":[{"symbol":"BTC/USD","bids":[],"asks":[{"price":62802.6,"qty":0.00100000}],"checksum":2071172721,"timestamp":"2026-08-16T23:37:13.119912Z"}]}}
{"rx_ns": 42898510672400, "frame": {"channel":"book","type":"update","data":[{"symbol":"BTC/USD","bids":[],"asks":[{"price":62802.6,"qty":3.79160819}],"checksum":504708799,"timestamp":"2026-08-16T23:37:13.122343Z"}]}}
{"rx_ns": 42898521031700, "frame": {"channel":"book","type":"update","data":[{"symbol":"BTC/USD","bids":[],"asks":[{"price":62797.0,"qty":0.46857247}],"checksum":3515650208,"timestamp":"2026-08-16T23:37:13.146148Z"}]}}
{"rx_ns": 42898527388000, "frame": {"channel":"book","type":"update","data":[{"symbol":"BTC/USD","bids":[],"asks":[{"price":62797.0,"qty":0.57857247}],"checksum":1294644508,"timestamp":"2026-08-16T23:37:13.148288Z"}]}}
{"rx_ns": 42898529979700, "frame": {"channel":"book","type":"update","data":[{"symbol":"BTC/USD","bids":[],"asks":[{"price":62802.6,"qty":3.79060819}],"checksum":2791466827,"timestamp":"2026-08-16T23:37:13.154832Z"}]}}
{"rx_ns": 42898551663800, "frame": {"channel":"book","type":"update","data":[{"symbol":"BTC/USD","bids":[],"asks":[{"price":62797.6,"qty":0.86705321}],"checksum":3480597428,"timestamp":"2026-08-16T23:37:13.174371Z"}]}}
{"rx_ns": 42898551721100, "frame": {"channel":"book","type":"update","data":[{"symbol":"BTC/USD","bids":[{"price":62786.0,"qty":0.79635491}],"asks":[],"checksum":100781553,"timestamp":"2026-08-16T23:37:13.174985Z"}]}}
{"rx_ns": 42898551732200, "frame": {"channel":"book","type":"update","data":[{"symbol":"BTC/USD","bids":[{"price":62783.8,"qty":0.79638273}],"asks":[],"checksum":658555657,"timestamp":"2026-08-16T23:37:13.175392Z"}]}}
{"rx_ns": 42898569082000, "frame": {"channel":"book","type":"update","data":[{"symbol":"BTC/USD","bids":[],"asks":[{"price":62800.7,"qty":0.18123904},{"price":62797.0,"qty":0.63455719}],"checksum":1149516300,"timestamp":"2026-08-16T23:37:13.191332Z"}]}}
{"rx_ns": 42898571259200, "frame": {"channel":"book","type":"update","data":[{"symbol":"BTC/USD","bids":[],"asks":[{"price":62802.6,"qty":0.00000000},{"price":62805.3,"qty":2.38833658},{"price":62797.1,"qty":4.85884670}],"checksum":758797259,"timestamp":"2026-08-16T23:37:13.193019Z"}]}}
{"rx_ns": 42898573253700, "frame": {"channel":"book","type":"update","data":[{"symbol":"BTC/USD","bids":[],"asks":[{"price":62805.2,"qty":0.18489680}],"checksum":2774269819,"timestamp":"2026-08-16T23:37:13.196822Z"}]}}
{"rx_ns": 42898589268300, "frame": {"channel":"book","type":"update","data":[{"symbol":"BTC/USD","bids":[{"price":62783.9,"qty":0.00000000},{"price":62783.3,"qty":0.06960000}],"asks":[],"checksum":2944484608,"timestamp":"2026-08-16T23:37:13.214943Z"}]}}
{"rx_ns": 42898592369500, "frame": {"channel":"book","type":"update","data":[{"symbol":"BTC/USD","bids":[],"asks":[{"price":62800.7,"qty":0.11039808}],"checksum":450625269,"timestamp":"2026-08-16T23:37:13.217429Z"}]}}
{"rx_ns": 42898608214100, "frame": {"channel":"book","type":"update","data":[{"symbol":"BTC/USD","bids":[],"asks":[{"price":62797.6,"qty":0.79620877}],"checksum":2106818657,"timestamp":"2026-08-16T23:37:13.232920Z"}]}}
{"rx_ns": 42898608271600, "frame": {"channel":"book","type":"update","data":[{"symbol":"BTC/USD","bids":[],"asks":[{"price":62797.1,"qty":4.78800170}],"checksum":1046123224,"timestamp":"2026-08-16T23:37:13.233010Z"}]}}
{"rx_ns": 42898623879800, "frame": {"channel":"book","type":"update","data":[{"symbol":"BTC/USD","bids":[{"price":62788.0,"qty":0.00005100}],"asks":[],"checksum":143167616,"timestamp":"2026-08-16T23:37:13.247452Z"}]}}
{"rx_ns": 42898629500700, "frame": {"channel":"book","type":"update","data":[{"symbol":"BTC/USD","bids":[],"asks":[{"price":62800.7,"qty":0.00039808}],"checksum":1755017823,"timestamp":"2026-08-16T23:37:13.250355Z"}]}}
{"rx_ns": 42898631501600, "frame": {"channel":"book","type":"update","data":[{"symbol":"BTC/USD","bids":[],"asks":[{"price":62797.1,"qty":0.99736660},{"price":62797.0,"qty":4.42520746}],"checksum":1894782819,"timestamp":"2026-08-16T23:37:13.257115Z"}]}}
{"rx_ns": 42898643445100, "frame": {"channel":"book","type":"update","data":[{"symbol":"BTC/USD","bids":[{"price":62786.0,"qty":0.00000000},{"price":62783.3,"qty":0.06960000}],"asks":[],"checksum":2973694444,"timestamp":"2026-08-16T23:37:13.266070Z"}]}}
{"rx_ns": 42898645043500, "frame": {"channel":"book","type":"update","data":[{"symbol":"BTC/USD","bids":[],"asks":[{"price":62803.9,"qty":0.63289635}],"checksum":2336368610,"timestamp":"2026-08-16T23:37:13.268214Z"}]}}
{"rx_ns": 42898654692400, "frame": {"channel":"book","type":"update","data":[{"symbol":"BTC/USD","bids":[{"price":62786.3,"qty":0.00000000},{"price":62783.2,"qty":0.15923399}],"asks":[],"checksum":2020945883,"timestamp":"2026-08-16T23:37:13.279379Z"}]}}
{"rx_ns": 42898685788300, "frame": {"channel":"book","type":"update","data":[{"symbol":"BTC/USD","bids":[{"price":62796.9,"qty":0.02177770}],"asks":[],"checksum":892994901,"timestamp":"2026-08-16T23:37:13.310230Z"}]}}
{"rx_ns": 42898709733500, "frame": {"channel":"book","type":"update","data":[{"symbol":"BTC/USD","bids":[{"price":62783.2,"qty":0.00000000},{"price":62781.2,"qty":0.01311942}],"asks":[],"checksum":2410232346,"timestamp":"2026-08-16T23:37:13.334929Z"}]}}
{"rx_ns": 42898724470900, "frame": {"channel":"book","type":"update","data":[{"symbol":"BTC/USD","bids":[{"price":62782.3,"qty":0.15923399}],"asks":[],"checksum":3447945768,"timestamp":"2026-08-16T23:37:13.346482Z"}]}}
{"rx_ns": 42898733483000, "frame": {"channel":"book","type":"update","data":[{"symbol":"BTC/USD","bids":[],"asks":[{"price":62800.8,"qty":0.50922800}],"checksum":3890578034,"timestamp":"2026-08-16T23:37:13.357957Z"}]}}
{"rx_ns": 42898755426300, "frame": {"channel":"book","type":"update","data":[{"symbol":"BTC/USD","bids":[{"price":62783.8,"qty":0.00000000},{"price":62781.2,"qty":0.01311942}],"asks":[],"checksum":2647680867,"timestamp":"2026-08-16T23:37:13.379660Z"}]}}
{"rx_ns": 42898755511800, "frame": {"channel":"book","type":"update","data":[{"symbol":"BTC/USD","bids":[],"asks":[{"price":62800.6,"qty":0.79617073}],"checksum":2684872005,"timestamp":"2026-08-16T23:37:13.381024Z"}]}}
{"rx_ns": 42898755527800, "frame": {"channel":"book","type":"update","data":[{"symbol":"BTC/USD","bids":[{"price":62785.2,"qty":0.79636550}],"asks":[],"checksum":549165233,"timestamp":"2026-08-16T23:37:13.381265Z"}]}}
{"rx_ns": 42898757131400, "frame": {"channel":"book","type":"update","data":[{"symbol":"BTC/USD","bids":[],"asks":[{"price":62803.2,"qty":0.18489680}],"checksum":941186462,"timestamp":"2026-08-16T23:37:13.382255Z"}]}}
{"rx_ns": 42898773021600, "frame": {"channel":"book","type":"update","data":[{"symbol":"BTC/USD","bids":[{"price":62796.9,"qty":0.00039811}],"asks":[],"checksum":2766704233,"timestamp":"2026-08-16T23:37:13.394510Z"}]}}
{"rx_ns": 42898773077300, "frame": {"channel":"book","type":"update","data":[{"symbol":"BTC/USD","bids":[{"price":62796.0,"qty":0.02137959}],"asks":[],"checksum":2736933280,"timestamp":"2026-08-16T23:37:13.395771Z"}]}}
{"rx_ns": 42898773096600, "frame": {"channel":"book","type":"update","data":[{"symbol":"BTC/USD","bids":[],"asks":[{"price":62797.0,"qty":4.44784873}],"checksum":57790229,"timestamp":"2026-08-16T23:37:13.397118Z"}]}}
{"rx_ns": 42898812789200, "frame": {"channel":"book","type":"update","data":[{"symbol":"BTC/USD","bids":[{"price":62789.9,"qty":0.00000000},{"price":62782.3,"qty":0.15923399}],"asks":[],"checksum":3863301526,"timestamp":"2026-08-16T23:37:13.438431Z"}]}}
{"rx_ns": 42898825254700, "frame": {"channel":"book","type":"update","data":[{"symbol":"BTC/USD","bids":[{"price":62785.2,"qty":0.00000000},{"price":62781.2,"qty":0.01311942}],"asks":[],"checksum":1376481407,"timestamp":"2026-08-16T23:37:13.450539Z"}]}}
{"rx_ns": 42898827055600, "frame": {"channel":"book","type":"update","data":[{"symbol":"BTC/USD","bids":[{"price":62782.3,"qty":0.00000000},{"price":62780.7,"qty":0.65540712}],"asks":[],"checksum":431058180,"timestamp":"2026-08-16T23:37:13.451659Z"}]}}
{"rx_ns": 42898827131300, "frame": {"channel":"book","type":"update","data":[{"symbol":"BTC/USD","bids":[{"price":62780.7,"qty":0.00000000},{"price":62780.3,"qty":0.00023884}],"asks":[],"checksum":235013936,"timestamp":"2026-08-16T23:37:13.451834Z"}]}}
{"rx_ns": 42898830539100, "frame": {"channel":"book","type":"update","data":[{"symbol":"BTC/USD","bids":[{"price":62783.3,"qty":0.00000000},{"price":62780.0,"qty":0.00518974}],"asks":[],"checksum":1524074089,"timestamp":"2026-08-16T23:37:13.453382Z"}]}}
{"rx_ns": 42898830580000, "frame": {"channel":"book","type":"update","data":[{"symbol":"BTC/USD","bids":[],"asks":[{"price":62803.2,"qty":0.00000000},{"price":62803.9,"qty":0.63289635},{"price":62800.5,"qty":0.18489680}],"checksum":739533287,"timestamp":"2026-08-16T23:37:13.453655Z"}]}}
{"rx_ns": 42898836315900, "frame": {"channel":"book","type":"update","data":[{"symbol":"BTC/USD","bids":[{"price":62796.9,"qty":0.00000000},{"price":62779.5,"qty":0.84467700}],"asks":[],"checksum":1042280290,"timestamp":"2026-08-16T23:37:13.458991Z"}]}}
{"rx_ns": 42898836364700, "frame": {"channel":"book","type":"update","data":[{"symbol":"BTC/USD","bids":[],"asks":[{"price":62796.9,"qty":0.11000000}],"checksum":684315505,"timestamp":"2026-08-16T23:37:13.459906Z"}]}}
{"rx_ns": 42898840096700, "frame": {"channel":"book","type":"update","data":[{"symbol":"BTC/USD","bids":[],"asks":[{"price":62796.1,"qty":0.06960000}],"checksum":2315581737,"timestamp":"2026-08-16T23:37:13.460980Z"}]}}
{"rx_ns": 42898840135300, "frame": {"channel":"book","type":"update","data":[{"symbol":"BTC/USD","bids":[],"asks":[{"price":62797.0,"qty":4.39186401},{"price":62796.9,"qty":0.16598472}],"checksum":1036017090,"timestamp":"2026-08-16T23:37:13.461395Z"}]}}
{"rx_ns": 42898840149800, "frame": {"channel":"book","type":"update","data":[{"symbol":"BTC/USD","bids":[],"asks":[{"price":62797.6,"qty":0.00000000},{"price":62803.3,"qty":0.01100000}],"checksum":1862507838,"timestamp":"2026-08-16T23:37:13.461460Z"}]}}
{"rx_ns": 42898840161300, "frame": {"channel":"book","type":"update","data":[{"symbol":"BTC/USD","bids":[],"asks":[{"price":62797.0,"qty":4.36922274}],"checksum":2302058582,"timestamp":"2026-08-16T23:37:13.461492Z"}]}}
{"rx_ns": 42898840170900, "frame": {"channel":"book","type":"update","data":[{"symbol":"BTC/USD","bids":[],"asks":[{"price":62800.6,"qty":0.00000000},{"price":62803.4,"qty":0.06960000}],"checksum":4111384582,"timestamp":"2026-08-16T23:37:13.461698Z"}]}}
{"rx_ns": 42898840181800, "frame": {"channel":"book","type":"update","data":[{"symbol":"BTC/USD","bids":[],"asks":[{"price":62797.0,"qty":4.28962274}],"checksum":1667611176,"timestamp":"2026-08-16T23:37:13.461816Z"}]}}
{"rx_ns": 42898840192500, "frame": {"channel":"book","type":"update","data":[{"symbol":"BTC/USD","bids":[],"asks":[{"price":62796.9,"qty":0.24558472}],"checksum":3163067179,"timestamp":"2026-08-16T23:37:13.462033Z"}]}}
{"rx_ns": 42898840202000, "frame": {"channel":"book","type":"update","data":[{"symbol":"BTC/USD","bids":[],"asks":[{"price":62797.0,"qty":4.27797059}],"checksum":2675249811,"timestamp":"2026-08-16T23:37:13.462354Z"}]}}
{"rx_ns": 42898840211300, "frame": {"channel":"book","type":"update","data":[{"symbol":"BTC/USD","bids":[],"asks":[{"price":62797.0,"qty":4.27789759}],"checksum":1022966283,"timestamp":"2026-08-16T23:37:13.462365Z"}]}}
{"rx_ns": 42898840219500, "frame": {"channel":"book","type":"update","data":[{"symbol":"BTC/USD","bids":[],"asks":[{"price":62796.9,"qty":0.32358472}],"checksum":3885899048,"timestamp":"2026-08-16T23:37:13.462445Z"}]}}
{"rx_ns": 42898840227800, "frame": {"channel":"book","type":"update","data":[{"symbol":"BTC/USD","bids":[],"asks":[{"price":62797.0,"qty":4.19989759}],"checksum":898682576,"timestamp":"2026-08-16T23:37:13.462469Z"}]}}
{"rx_ns": 42898840237100, "frame": {"channel":"book","type":"update","data":[{"symbol":"BTC/USD","bids":[{"price":62796.0,"qty":0.00000000},{"price":62778.0,"qty":0.83668569}],"asks":[],"checksum":4073369100,"timestamp":"2026-08-16T23:37:13.462645Z"}]}}
{"rx_ns": 42898840246800, "frame": {"channel":"book","type":"update","data":[{"symbol":"BTC/USD","bids":[],"asks":[{"price":62796.9,"qty":0.24398472}],"checksum":1898895313,"timestamp":"2026-08-16T23:37:13.462677Z"}]}}
{"rx_ns": 42898840255300, "frame": {"channel":"book","type":"update","data":[{"symbol":"BTC/USD","bids":[],"asks":[{"price":62796.1,"qty":0.14920000}],"checksum":3318805193,"timestamp":"2026-08-16T23:37:13.462794Z"}]}}
{"rx_ns": 42898840264500, "frame": {"channel":"book","type":"update","data":[{"symbol":"BTC/USD","bids":[],"asks":[{"price":62797.0,"qty":4.13029759}],"checksum":1121346064,"timestamp":"2026-08-16T23:37:13.462820Z"}]}}
{"rx_ns": 42898846233100, "frame": {"channel":"book","type":"update","data":[{"symbol":"BTC/USD","bids":[],"asks":[{"price":62798.0,"qty":0.00513547}],"checksum":878264134,"timestamp":"2026-08-16T23:37:13.463345Z"}]}}
{"rx_ns": 42898846282200, "frame": {"channel":"book","type":"update","data":[{"symbol":"BTC/USD","bids":[],"asks":[{"price":62797.0,"qty":4.05988426}],"checksum":2356068417,"timestamp":"2026-08-16T23:37:13.463475Z"}]}}
{"rx_ns": 42898846360400, "frame": {"channel":"book","type":"update","data":[{"symbol":"BTC/USD","bids":[],"asks":[{"price":62796.1,"qty":0.94542779}],"checksum":1759713999,"timestamp":"2026-08-16T23:37:13.463545Z"}]}}
{"rx_ns": 42898846370300, "frame": {"channel":"book","type":"update","data":[{"symbol":"BTC/USD","bids":[],"asks":[{"price":62796.9,"qty":0.16598472}],"checksum":1536495352,"timestamp":"2026-08-16T23:37:13.463625Z"}]}}
{"rx_ns": 42898846378700, "frame": {"channel":"book","type":"update","data":[{"symbol":"BTC/USD","bids":[{"price":62794.7,"qty":0.02137959}],"asks":[],"checksum":3350735210,"timestamp":"2026-08-16T23:37:13.463765Z"}]}}
{"rx_ns": 42898846387700, "frame": {"channel":"book","type":"update","data":[{"symbol":"BTC/USD","bids":[],"asks":[{"price":62796.1,"qty":1.02342779}],"checksum":3674350646,"timestamp":"2026-08-16T23:37:13.463788Z"}]}}
{"rx_ns": 42898846396100, "frame": {"channel":"book","type":"update","data":[{"symbol":"BTC/USD","bids":[],"asks":[{"price":62798.7,"qty":0.00000000},{"price":62803.4,"qty":0.06960000}],"checksum":1855476045,"timestamp":"2026-08-16T23:37:13.464269Z"}]}}
{"rx_ns": 42898846405700, "frame": {"channel":"book","type":"update","data":[{"symbol":"BTC/USD","bids":[],"asks":[{"price":62797.1,"qty":0.34195948}],"checksum":106192259,"timestamp":"2026-08-16T23:37:13.464423Z"}]}}
{"rx_ns": 42898846414700, "frame": {"channel":"book","type":"update","data":[{"symbol":"BTC/USD","bids":[{"price":62794.3,"qty":0.00000000},{"price":62778.0,"qty":0.83668569}],"asks":[],"checksum":511134499,"timestamp":"2026-08-16T23:37:13.465188Z"}]}}
{"rx_ns": 42898846423500, "frame": {"channel":"book","type":"update","data":[{"symbol":"BTC/USD","bids":[],"asks":[{"price":62796.1,"qty":1.09399949}],"checksum":3766052222,"timestamp":"2026-08-16T23:37:13.466088Z"}]}}
{"rx_ns": 42898846431900, "frame": {"channel":"book","type":"update","data":[{"symbol":"BTC/USD","bids":[],"asks":[{"price":62796.1,"qty":0.29777170}],"checksum":2386186471,"timestamp":"2026-08-16T23:37:13.466273Z"}]}}
{"rx_ns": 42898846459000, "frame": {"channel":"book","type":"update","data":[{"symbol":"BTC/USD","bids":[{"price":62794.7,"qty":0.02117959}],"asks":[],"checksum":2366283063,"timestamp":"2026-08-16T23:37:13.467505Z"}]}}
{"rx_ns": 42898846468700, "frame": {"channel":"book","type":"update","data":[{"symbol":"BTC/USD","bids":[],"asks":[{"price":62796.1,"qty":0.22817170}],"checksum":906474757,"timestamp":"2026-08-16T23:37:13.467746Z"}]}}
{"rx_ns": 42898851340400, "frame": {"channel":"book","type":"update","data":[{"symbol":"BTC/USD","bids":[],"asks":[{"price":62794.8,"qty":0.01185247}],"checksum":3404885841,"timestamp":"2026-08-16T23:37:13.471768Z"}]}}
{"rx_ns": 42898851383700, "frame": {"channel":"book","type":"update","data":[{"symbol":"BTC/USD","bids":[],"asks":[{"price":62794.8,"qty":0.08145247}],"checksum":3960111225,"timestamp":"2026-08-16T23:37:13.472960Z"}]}}
{"rx_ns": 42898851394900, "frame": {"channel":"book","type":"update","data":[{"symbol":"BTC/USD","bids":[],"asks":[{"price":62794.8,"qty":0.16105247}],"checksum":167885924,"timestamp":"2026-08-16T23:37:13.473268Z"}]}}
{"rx_ns": 42898851404600, "frame": {"channel":"book","type":"update","data":[{"symbol":"BTC/USD","bids":[],"asks":[{"price":62796.1,"qty":0.14857170}],"checksum":1757391303,"timestamp":"2026-08-16T23:37:13.473281Z"}]}}
{"rx_ns": 42898851413700, "frame": {"channel":"book","type":"update","data":[{"symbol":"BTC/USD","bids":[],"asks":[{"price":62794.8,"qty":0.23905247}],"checksum":3612973972,"timestamp":"2026-08-16T23:37:13.473401Z"}]}}
{"rx_ns": 42898851422200, "frame": {"channel":"book","type":"update","data":[{"symbol":"BTC/USD","bids":[],"asks":[{"price":62796.1,"qty":0.07057170}],"checksum":1714635624,"timestamp":"2026-08-16T23:37:13.473488Z"}]}}
{"rx_ns": 42898851430700, "frame": {"channel":"book","type":"update","data":[{"symbol":"BTC/USD","bids":[],"asks":[{"price":62800.5,"qty":0.00000000},{"price":62803.4,"qty":0.06960000}],"checksum":1729045999,"timestamp":"2026-08-16T23:37:13.474135Z"}]}}
{"rx_ns": 42898851441000, "frame": {"channel":"book","type":"update","data":[{"symbol":"BTC/USD","bids":[],"asks":[{"price":62802.0,"qty":0.00318462}],"checksum":1856495559,"timestamp":"2026-08-16T23:37:13.474914Z"}]}}
{"rx_ns": 42898874184800, "frame": {"channel":"book","type":"update","data":[{"symbol":"BTC/USD","bids":[{"price":62780.0,"qty":0.16442373}],"asks":[],"checksum":3114252206,"timestamp":"2026-08-16T23:37:13.496220Z"}]}}
{"rx_ns": 42898874225700, "frame": {"channel":"book","type":"update","data":[{"symbol":"BTC/USD","bids":[],"asks":[{"price":62797.0,"qty":3.90065027}],"checksum":4202515596,"timestamp":"2026-08-16T23:37:13.496353Z"}]}}
{"rx_ns": 42898910987800, "frame": {"channel":"book","type":"update","data":[{"symbol":"BTC/USD","bids":[],"asks":[{"price":62794.8,"qty":0.39828646}],"checksum":4106524555,"timestamp":"2026-08-16T23:37:13.535184Z"}]}}
{"rx_ns": 42898919578300, "frame": {"channel":"book","type":"update","data":[{"symbol":"BTC/USD","bids":[{"price":62778.0,"qty":0.80483233}],"asks":[],"checksum":2016943779,"timestamp":"2026-08-16T23:37:13.543280Z"}]}}
{"rx_ns": 42898933247500, "frame": {"channel":"book","type":"update","data":[{"symbol":"BTC/USD","bids":[{"price":62784.0,"qty":0.79638050}],"asks":[],"checksum":3931539391,"timestamp":"2026-08-16T23:37:13.559234Z"}]}}
{"rx_ns": 42898936568500, "frame": {"channel":"book","type":"update","data":[{"symbol":"BTC/USD","bids":[{"price":62781.3,"qty":0.79641481}],"asks":[],"checksum":4139273683,"timestamp":"2026-08-16T23:37:13.559433Z"}]}}
{"rx_ns": 42898936622000, "frame": {"channel":"book","type":"update","data":[{"symbol":"BTC/USD","bids":[],"asks":[{"price":62797.0,"qty":3.79065027}],"checksum":2113754527,"timestamp":"2026-08-16T23:37:13.560453Z"}]}}
{"rx_ns": 42898936676600, "frame": {"channel":"book","type":"update","data":[{"symbol":"BTC/USD","bids":[{"price":62782.1,"qty":0.06960000}],"asks":[],"checksum":789392036,"timestamp":"2026-08-16T23:37:13.562257Z"}]}}
{"rx_ns": 42898939897800, "frame": {"channel":"book","type":"update","data":[{"symbol":"BTC/USD","bids":[{"price":62794.7,"qty":0.02157772}],"asks":[],"checksum":2459854834,"timestamp":"2026-08-16T23:37:13.565470Z"}]}}
{"rx_ns": 42898996679800, "frame": {"channel":"book","type":"update","data":[{"symbol":"BTC/USD","bids":[{"price":62794.7,"qty":0.02197585}],"asks":[],"checksum":3863698846,"timestamp":"2026-08-16T23:37:13.620716Z"}]}}
{"rx_ns": 42898998182300, "frame": {"channel":"book","type":"update","data":[{"symbol":"BTC/USD","bids":[],"asks":[{"price":62796.9,"qty":0.11000000},{"price":62796.0,"qty":0.05598472}],"checksum":1583906534,"timestamp":"2026-08-16T23:37:13.621890Z"}]}}
{"rx_ns": 42899002763000, "frame": {"channel":"book","type":"update","data":[{"symbol":"BTC/USD","bids":[],"asks":[{"price":62797.0,"qty":0.00000000},{"price":62803.3,"qty":0.01100000},{"price":62794.8,"qty":4.18901796}],"checksum":111484047,"timestamp":"2026-08-16T23:37:13.626585Z"}]}}
{"rx_ns": 42899018136700, "frame": {"channel":"book","type":"update","data":[{"symbol":"BTC/USD","bids":[{"price":62794.7,"qty":0.00079626}],"asks":[],"checksum":495752823,"timestamp":"2026-08-16T23:37:13.641453Z"}]}}
{"rx_ns": 42899019626100, "frame": {"channel":"book","type":"update","data":[{"symbol":"BTC/USD","bids":[{"price":62793.1,"qty":0.02131292}],"asks":[],"checksum":2435127186,"timestamp":"2026-08-16T23:37:13.644602Z"}]}}
{"rx_ns": 42899028435000, "frame": {"channel":"book","type":"update","data":[{"symbol":"BTC/USD","bids":[],"asks":[{"price":62794.8,"qty":4.84442508}],"checksum":854277363,"timestamp":"2026-08-16T23:37:13.650393Z"}]}}
{"rx_ns": 42899052242600, "frame": {"channel":"book","type":"update","data":[{"symbol":"BTC/USD","bids":[{"price":62794.7,"qty":0.00119439}],"asks":[],"checksum":2813080452,"timestamp":"2026-08-16T23:37:13.676685Z"}]}}
{"rx_ns": 42899054094200, "frame": {"channel":"book","type":"update","data":[{"symbol":"BTC/USD","bids":[],"asks":[{"price":62796.1,"qty":0.00000000},{"price":62803.4,"qty":0.06960000}],"checksum":3712950378,"timestamp":"2026-08-16T23:37:13.679942Z"}]}}
{"rx_ns": 42899055675300, "frame": {"channel":"book","type":"update","data":[{"symbol":"BTC/USD","bids":[],"asks":[{"price":62796.0,"qty":0.00000000},{"price":62803.9,"qty":0.06000000},{"price":62796.8,"qty":0.05598472}],"checksum":1322700297,"timestamp":"2026-08-16T23:37:13.681212Z"}]}}
{"rx_ns": 42899107854000, "frame": {"channel":"book","type":"update","data":[{"symbol":"BTC/USD","bids":[{"price":62794.7,"qty":0.00159252}],"asks":[],"checksum":3672878434,"timestamp":"2026-08-16T23:37:13.731911Z"}]}}
{"rx_ns": 42899114691300, "frame": {"channel":"book","type":"update","data":[{"symbol":"BTC/USD","bids":[],"asks":[{"price":62800.7,"qty":0.00000000},{"price":62803.9,"qty":0.06000000},{"price":62794.8,"qty":4.84482321}],"checksum":3278123104,"timestamp":"2026-08-16T23:37:13.739975Z"}]}}
{"rx_ns": 42899132159100, "frame": {"channel":"book","type":"update","data":[{"symbol":"BTC/USD","bids":[{"price":62794.7,"qty":0.00119439}],"asks":[],"checksum":1465471755,"timestamp":"2026-08-16T23:37:13.756589Z"}]}}
{"rx_ns": 42899134021000, "frame": {"channel":"book","type":"update","data":[{"symbol":"BTC/USD","bids":[{"price":62794.7,"qty":0.01634490}],"asks":[],"checksum":405992136,"timestamp":"2026-08-16T23:37:13.757603Z"}]}}
{"rx_ns": 42899190946400, "frame": {"channel":"book","type":"update","data":[{"symbol":"BTC/USD","bids":[{"price":62794.7,"qty":0.01594677}],"asks":[],"checksum":3673217803,"timestamp":"2026-08-16T23:37:13.816573Z"}]}}
{"rx_ns": 42899210873400, "frame": {"channel":"book","type":"update","data":[{"symbol":"BTC/USD","bids":[{"price":62784.0,"qty":0.00000000},{"price":62780.3,"qty":0.00023884}],"asks":[],"checksum":30612623,"timestamp":"2026-08-16T23:37:13.834817Z"}]}}
{"rx_ns": 42899213311400, "frame": {"channel":"book","type":"update","data":[{"symbol":"BTC/USD","bids":[],"asks":[{"price":62794.8,"qty":5.64106748}],"checksum":1746669247,"timestamp":"2026-08-16T23:37:13.836517Z"}]}}
{"rx_ns": 42899213359800, "frame": {"channel":"book","type":"update","data":[{"symbol":"BTC/USD","bids":[],"asks":[{"price":62796.0,"qty":0.79622905}],"checksum":10078239,"timestamp":"2026-08-16T23:37:13.836833Z"}]}}
{"rx_ns": 42899213372400, "frame": {"channel":"book","type":"update","data":[{"symbol":"BTC/USD","bids":[{"price":62783.2,"qty":0.79639015}],"asks":[],"checksum":2264673763,"timestamp":"2026-08-16T23:37:13.837088Z"}]}}
{"rx_ns": 42899213381600, "frame": {"channel":"book","type":"update","data":[{"symbol":"BTC/USD","bids":[],"asks":[{"price":62794.8,"qty":5.66123042}],"checksum":2717124202,"timestamp":"2026-08-16T23:37:13.838243Z"}]}}
{"rx_ns": 42899213390600, "frame": {"channel":"book","type":"update","data":[{"symbol":"BTC/USD","bids":[],"asks":[{"price":62796.8,"qty":0.00000000},{"price":62803.9,"qty":0.06000000},{"price":62795.9,"qty":0.05598472}],"checksum":2863317049,"timestamp":"2026-08-16T23:37:13.838291Z"}]}}
{"rx_ns": 42899216369600, "frame": {"channel":"book","type":"update","data":[{"symbol":"BTC/USD","bids":[{"price":62794.3,"qty":0.00005100}],"asks":[],"checksum":3447956584,"timestamp":"2026-08-16T23:37:13.841308Z"}]}}
{"rx_ns": 42899250160100, "frame": {"channel":"book","type":"update","data":[{"symbol":"BTC/USD","bids":[{"price":62794.7,"qty":0.01554864}],"asks":[],"checksum":3133548343,"timestamp":"2026-08-16T23:37:13.875446Z"}]}}
{"rx_ns": 42899288339000, "frame": {"channel":"book","type":"update","data":[{"symbol":"BTC/USD","bids":[],"asks":[{"price":62796.1,"qty":0.46044544}],"checksum":1992868612,"timestamp":"2026-08-16T23:37:13.914384Z"}]}}
{"rx_ns": 42899351744500, "frame": {"channel":"heartbeat"}}
{"rx_ns": 42899410161000, "frame": {"channel":"book","type":"update","data":[{"symbol":"BTC/USD","bids":[{"price":62782.1,"qty":0.00000000},{"price":62781.2,"qty":0.01311942}],"asks":[],"checksum":2224799627,"timestamp":"2026-08-16T23:37:14.030312Z"}]}}
{"rx_ns": 42899439963600, "frame": {"channel":"book","type":"update","data":[{"symbol":"BTC/USD","bids":[{"price":62783.5,"qty":0.00015926}],"asks":[],"checksum":2565865318,"timestamp":"2026-08-16T23:37:14.065529Z"}]}}
{"rx_ns": 42899550917000, "frame": {"channel":"book","type":"update","data":[{"symbol":"BTC/USD","bids":[],"asks":[{"price":62796.9,"qty":0.90621764}],"checksum":2340148065,"timestamp":"2026-08-16T23:37:14.174120Z"}]}}
{"rx_ns": 42899553119000, "frame": {"channel":"book","type":"update","data":[{"symbol":"BTC/USD","bids":[],"asks":[{"price":62800.7,"qty":0.18489680}],"checksum":1790700499,"timestamp":"2026-08-16T23:37:14.175497Z"}]}}
{"rx_ns": 42899562560200, "frame": {"channel":"book","type":"update","data":[{"symbol":"BTC/USD","bids":[],"asks":[{"price":62801.4,"qty":0.36000000}],"checksum":369341209,"timestamp":"2026-08-16T23:37:14.185798Z"}]}}
{"rx_ns": 42899601730200, "frame": {"channel":"book","type":"update","data":[{"symbol":"BTC/USD","bids":[],"asks":[{"price":62794.8,"qty":5.66223042}],"checksum":3341616031,"timestamp":"2026-08-16T23:37:14.227458Z"}]}}
{"rx_ns": 42899811673000, "frame": {"channel":"book","type":"update","data":[{"symbol":"BTC/USD","bids":[{"price":62784.9,"qty":0.00005100}],"asks":[],"checksum":1941947137,"timestamp":"2026-08-16T23:37:14.437357Z"}]}}
{"rx_ns": 42899839236900, "frame": {"channel":"book","type":"update","data":[{"symbol":"BTC/USD","bids":[{"price":62791.3,"qty":0.00000000},{"price":62781.3,"qty":0.79641481}],"asks":[],"checksum":2533704444,"timestamp":"2026-08-16T23:37:14.464865Z"}]}}
{"rx_ns": 42899840871000, "frame": {"channel":"book","type":"update","data":[{"symbol":"BTC/USD","bids":[{"price":62781.3,"qty":0.00000000},{"price":62781.2,"qty":0.01311942}],"asks":[],"checksum":3173549658,"timestamp":"2026-08-16T23:37:14.465592Z"}]}}
{"rx_ns": 42899840909600, "frame": {"channel":"book","type":"update","data":[{"symbol":"BTC/USD","bids":[{"price":62783.2,"qty":0.00000000},{"price":62780.3,"qty":0.00023884}],"asks":[],"checksum":1602837373,"timestamp":"2026-08-16T23:37:14.465732Z"}]}}
{"rx_ns": 42899840923200, "frame": {"channel":"book","type":"update","data":[{"symbol":"BTC/USD","bids":[{"price":62788.1,"qty":0.05598472}],"asks":[],"checksum":3032084499,"timestamp":"2026-08-16T23:37:14.465999Z"}]}}
{"rx_ns": 42899840933200, "frame": {"channel":"book","type":"update","data":[{"symbol":"BTC/USD","bids":[],"asks":[{"price":62795.9,"qty":0.00000000},{"price":62802.0,"qty":0.00318462},{"price":62794.8,"qty":5.71821514}],"checksum":1018442104,"timestamp":"2026-08-16T23:37:14.466073Z"}]}}
{"rx_ns": 42899852194900, "frame": {"channel":"book","type":"update","data":[{"symbol":"BTC/USD","bids":[{"price":62781.6,"qty":0.79641109}],"asks":[],"checksum":3367639601,"timestamp":"2026-08-16T23:37:14.474890Z"}]}}
{"rx_ns": 42899869714900, "frame": {"channel":"book","type":"update","data":[{"symbol":"BTC/USD","bids":[{"price":62781.6,"qty":0.00000000},{"price":62781.2,"qty":0.01311942}],"asks":[],"checksum":1018442104,"timestamp":"2026-08-16T23:37:14.491767Z"}]}}
{"rx_ns": 42899904836200, "frame": {"channel":"book","type":"update","data":[{"symbol":"BTC/USD","bids":[{"price":62794.7,"qty":0.02354864}],"asks":[],"checksum":1509198837,"timestamp":"2026-08-16T23:37:14.527268Z"}]}}
{"rx_ns": 42899964762200, "frame": {"channel":"book","type":"update","data":[{"symbol":"BTC/USD","bids":[],"asks":[{"price":62794.8,"qty":5.82821514}],"checksum":3355188604,"timestamp":"2026-08-16T23:37:14.584606Z"}]}}
{"rx_ns": 42899966411100, "frame": {"channel":"book","type":"update","data":[{"symbol":"BTC/USD","bids":[{"price":62781.6,"qty":0.79641120}],"asks":[],"checksum":2227588130,"timestamp":"2026-08-16T23:37:14.586742Z"}]}}
{"rx_ns": 42899966458600, "frame": {"channel":"book","type":"update","data":[{"symbol":"BTC/USD","bids":[{"price":62787.4,"qty":0.00000000},{"price":62781.2,"qty":0.01311942},{"price":62785.3,"qty":0.00318620}],"asks":[],"checksum":3685692380,"timestamp":"2026-08-16T23:37:14.586887Z"}]}}
{"rx_ns": 42899973473000, "frame": {"channel":"book","type":"update","data":[{"symbol":"BTC/USD","bids":[{"price":62785.9,"qty":0.00009500}],"asks":[],"checksum":2271829500,"timestamp":"2026-08-16T23:37:14.592494Z"}]}}
{"rx_ns": 42900016442700, "frame": {"channel":"book","type":"update","data":[{"symbol":"BTC/USD","bids":[{"price":62793.1,"qty":0.00000000},{"price":62780.3,"qty":0.00023884}],"asks":[],"checksum":2258769787,"timestamp":"2026-08-16T23:37:14.633646Z"}]}}
{"rx_ns": 42900016522300, "frame": {"channel":"book","type":"update","data":[{"symbol":"BTC/USD","bids":[{"price":62791.7,"qty":0.02131292}],"asks":[],"checksum":4005069483,"timestamp":"2026-08-16T23:37:14.636339Z"}]}}
{"rx_ns": 42900063434100, "frame": {"channel":"book","type":"update","data":[{"symbol":"BTC/USD","bids":[],"asks":[{"price":62796.9,"qty":0.79621764}],"checksum":1516177984,"timestamp":"2026-08-16T23:37:14.685621Z"}]}}
{"rx_ns": 42900302360500, "frame": {"channel":"book","type":"update","data":[{"symbol":"BTC/USD","bids":[],"asks":[{"price":62800.6,"qty":0.19620257}],"checksum":2299750211,"timestamp":"2026-08-16T23:37:14.927024Z"}]}}
{"rx_ns": 42900303555500, "frame": {"channel":"book","type":"update","data":[{"symbol":"BTC/USD","bids":[],"asks":[{"price":62800.7,"qty":0.00000000},{"price":62802.0,"qty":0.00318462},{"price":62800.5,"qty":0.18489680}],"checksum":1064814256,"timestamp":"2026-08-16T23:37:14.928208Z"}]}}
{"rx_ns": 42900312626000, "frame": {"channel":"book","type":"update","data":[{"symbol":"BTC/USD","bids":[],"asks":[{"price":62800.5,"qty":0.18494780}],"checksum":120429725,"timestamp":"2026-08-16T23:37:14.937667Z"}]}}
{"rx_ns": 42900351295100, "frame": {"channel":"heartbeat"}}
{"rx_ns": 42900393215500, "frame": {"channel":"book","type":"update","data":[{"symbol":"BTC/USD","bids":[{"price":62794.7,"qty":0.02364864}],"asks":[],"checksum":2532399212,"timestamp":"2026-08-16T23:37:15.017770Z"}]}}
{"rx_ns": 42900448173200, "frame": {"channel":"book","type":"update","data":[{"symbol":"BTC/USD","bids":[{"price":62791.7,"qty":0.00000000},{"price":62781.0,"qty":0.79641900}],"asks":[],"checksum":3206063212,"timestamp":"2026-08-16T23:37:15.074258Z"}]}}
{"rx_ns": 42900449762800, "frame": {"channel":"book","type":"update","data":[{"symbol":"BTC/USD","bids":[{"price":62792.6,"qty":0.02131292}],"asks":[],"checksum":557000923,"timestamp":"2026-08-16T23:37:15.074420Z"}]}}
{"rx_ns": 42900952635100, "frame": {"channel":"book","type":"update","data":[{"symbol":"BTC/USD","bids":[{"price":62788.1,"qty":0.00000000},{"price":62780.3,"qty":0.00023884}],"asks":[],"checksum":3176470186,"timestamp":"2026-08-16T23:37:15.570473Z"}]}}
{"rx_ns": 42900952731900, "frame": {"channel":"book","type":"update","data":[{"symbol":"BTC/USD","bids":[{"price":62780.4,"qty":0.05598472}],"asks":[],"checksum":2641248790,"timestamp":"2026-08-16T23:37:15.572362Z"}]}}
{"rx_ns": 42900969964600, "frame": {"channel":"book","type":"update","data":[{"symbol":"BTC/USD","bids":[{"price":62794.7,"qty":0.00849813}],"asks":[],"checksum":2615511242,"timestamp":"2026-08-16T23:37:15.590050Z"}]}}
{"rx_ns": 42900987790300, "frame": {"channel":"book","type":"update","data":[{"symbol":"BTC/USD","bids":[],"asks":[{"price":62799.1,"qty":0.06000000}],"checksum":3466112437,"timestamp":"2026-08-16T23:37:15.608264Z"}]}}
{"rx_ns": 42901087165300, "frame": {"channel":"book","type":"update","data":[{"symbol":"BTC/USD","bids":[],"asks":[{"price":62796.1,"qty":0.00000000},{"price":62801.4,"qty":0.36000000}],"checksum":516116918,"timestamp":"2026-08-16T23:37:15.710466Z"}]}}
{"rx_ns": 42901352000100, "frame": {"channel":"heartbeat"}}
{"rx_ns": 42901538704600, "frame": {"channel":"book","type":"update","data":[{"symbol":"BTC/USD","bids":[{"price":62785.3,"qty":0.00000000},{"price":62780.3,"qty":0.00023884},{"price":62785.2,"qty":0.00318620}],"asks":[],"checksum":4141138199,"timestamp":"2026-08-16T23:37:16.161334Z"}]}}
{"rx_ns": 42902029975500, "frame": {"channel":"book","type":"update","data":[{"symbol":"BTC/USD","bids":[{"price":62785.9,"qty":0.00000000},{"price":62780.3,"qty":0.00023884},{"price":62784.5,"qty":0.00009500}],"asks":[],"checksum":1439235734,"timestamp":"2026-08-16T23:37:16.643557Z"}]}}
{"rx_ns": 42902071254600, "frame": {"channel":"book","type":"update","data":[{"symbol":"BTC/USD","bids":[],"asks":[{"price":62800.8,"qty":0.00000000},{"price":62802.0,"qty":0.00318462}],"checksum":619817487,"timestamp":"2026-08-16T23:37:16.695067Z"}]}}
{"rx_ns": 42902071324500, "frame": {"channel":"book","type":"update","data":[{"symbol":"BTC/USD","bids":[],"asks":[{"price":62796.7,"qty":0.50925300}],"checksum":3087092893,"timestamp":"2026-08-16T23:37:16.696084Z"}]}}
{"rx_ns": 42902071455900, "frame": {"channel":"book","type":"update","data":[{"symbol":"BTC/USD","bids":[],"asks":[{"price":62800.5,"qty":0.00005100},{"price":62799.0,"qty":0.18489680}],"checksum":4103853375,"timestamp":"2026-08-16T23:37:16.697294Z"}]}}
{"rx_ns": 42902351440300, "frame": {"channel":"heartbeat"}}
{"rx_ns": 42902601354100, "frame": {"channel":"book","type":"update","data":[{"symbol":"BTC/USD","bids":[],"asks":[{"price":62796.1,"qty":0.40200000}],"checksum":251141378,"timestamp":"2026-08-16T23:37:17.224347Z"}]}}
{"rx_ns": 42902601416500, "frame": {"channel":"book","type":"update","data":[{"symbol":"BTC/USD","bids":[],"asks":[{"price":62799.0,"qty":0.00000000},{"price":62800.6,"qty":0.19620257},{"price":62795.9,"qty":0.18489680}],"checksum":3282933231,"timestamp":"2026-08-16T23:37:17.225632Z"}]}}
{"rx_ns": 42903130527800, "frame": {"channel":"book","type":"update","data":[{"symbol":"BTC/USD","bids":[{"price":62785.2,"qty":0.00318497}],"asks":[],"checksum":95103724,"timestamp":"2026-08-16T23:37:17.756276Z"}]}}
{"rx_ns": 42903352253000, "frame": {"channel":"heartbeat"}}
{"rx_ns": 42904070520100, "frame": {"channel":"book","type":"update","data":[{"symbol":"BTC/USD","bids":[{"price":62784.5,"qty":0.00000000},{"price":62780.3,"qty":0.00023884},{"price":62784.6,"qty":0.00009500}],"asks":[],"checksum":2695053696,"timestamp":"2026-08-16T23:37:18.696875Z"}]}}
{"rx_ns": 42904351555400, "frame": {"channel":"heartbeat"}}
{"rx_ns": 42904383902600, "frame": {"channel":"book","type":"update","data":[{"symbol":"BTC/USD","bids":[{"price":62780.8,"qty":0.79642089}],"asks":[],"checksum":3988989950,"timestamp":"2026-08-16T23:37:18.997686Z"}]}}
{"rx_ns": 42904383970800, "frame": {"channel":"book","type":"update","data":[{"symbol":"BTC/USD","bids":[{"price":62788.1,"qty":0.05598472}],"asks":[],"checksum":3101889628,"timestamp":"2026-08-16T23:37:19.000345Z"}]}}
{"rx_ns": 42904887682200, "frame": {"channel":"book","type":"update","data":[{"symbol":"BTC/USD","bids":[],"asks":[{"price":62798.0,"qty":0.00000000},{"price":62800.6,"qty":0.19620257}],"checksum":1265967782,"timestamp":"2026-08-16T23:37:19.510016Z"}]}}
{"rx_ns": 42904889062900, "frame": {"channel":"book","type":"update","data":[{"symbol":"BTC/USD","bids":[{"price":62788.1,"qty":0.00000000},{"price":62780.3,"qty":0.00023884},{"price":62791.3,"qty":0.05598472}],"asks":[],"checksum":1870932767,"timestamp":"2026-08-16T23:37:19.511362Z"}]}}
{"rx_ns": 42904890917800, "frame": {"channel":"book","type":"update","data":[{"symbol":"BTC/USD","bids":[],"asks":[{"price":62795.9,"qty":0.00000000},{"price":62801.4,"qty":0.36000000}],"checksum":1630239249,"timestamp":"2026-08-16T23:37:19.514959Z"}]}}
{"rx_ns": 42904902798600, "frame": {"channel":"book","type":"update","data":[{"symbol":"BTC/USD","bids":[{"price":62792.6,"qty":0.00000000},{"price":62783.0,"qty":0.79639330}],"asks":[],"checksum":2712969851,"timestamp":"2026-08-16T23:37:19.523057Z"}]}}
{"rx_ns": 42904902861800, "frame": {"channel":"book","type":"update","data":[{"symbol":"BTC/USD","bids":[{"price":62793.5,"qty":0.02131292}],"asks":[],"checksum":3095074458,"timestamp":"2026-08-16T23:37:19.523640Z"}]}}
{"rx_ns": 42904956339600, "frame": {"channel":"book","type":"update","data":[{"symbol":"BTC/USD","bids":[{"price":62785.2,"qty":0.00000000},{"price":62783.0,"qty":0.79639330},{"price":62785.1,"qty":0.00318497}],"asks":[],"checksum":4120057597,"timestamp":"2026-08-16T23:37:19.581084Z"}]}}
{"rx_ns": 42905031809700, "frame": {"channel":"book","type":"update","data":[{"symbol":"BTC/USD","bids":[],"asks":[{"price":62800.6,"qty":0.00000000},{"price":62802.0,"qty":0.00318462}],"checksum":4094946014,"timestamp":"2026-08-16T23:37:19.657336Z"}]}}
{"rx_ns": 42905355726900, "frame": {"channel":"heartbeat"}}
{"rx_ns": 42905678632500, "frame": {"channel":"book","type":"update","data":[{"symbol":"BTC/USD","bids":[],"asks":[{"price":62801.3,"qty":0.19620257}],"checksum":2268677733,"timestamp":"2026-08-16T23:37:20.303710Z"}]}}
{"rx_ns": 42906129644100, "frame": {"channel":"book","type":"update","data":[{"symbol":"BTC/USD","bids":[{"price":62784.6,"qty":0.00000000},{"price":62782.1,"qty":0.86600506},{"price":62785.8,"qty":0.00009500}],"asks":[],"checksum":43290064,"timestamp":"2026-08-16T23:37:20.749720Z"}]}}
{"rx_ns": 42906352294400, "frame": {"channel":"heartbeat"}}
{"rx_ns": 42906863082100, "frame": {"channel":"book","type":"update","data":[{"symbol":"BTC/USD","bids":[{"price":62785.1,"qty":0.00000000},{"price":62782.1,"qty":0.86600506},{"price":62785.2,"qty":0.00318497}],"asks":[],"checksum":4885239,"timestamp":"2026-08-16T23:37:21.487557Z"}]}}
{"rx_ns": 42907353106600, "frame": {"channel":"heartbeat"}}
{"rx_ns": 42908353455700, "frame": {"channel":"heartbeat"}}
{"rx_ns": 42908372457700, "frame": {"channel":"book","type":"update","data":[{"symbol":"BTC/USD","bids":[{"price":62791.3,"qty":0.00000000},{"price":62782.1,"qty":0.86600506},{"price":62791.2,"qty":0.05762772}],"asks":[],"checksum":2245812262,"timestamp":"2026-08-16T23:37:22.998072Z"}]}}
{"rx_ns": 42909353333800, "frame": {"channel":"heartbeat"}}
{"rx_ns": 42910232344900, "frame": {"channel":"book","type":"update","data":[{"symbol":"BTC/USD","bids":[{"price":62785.8,"qty":0.00000000},{"price":62780.8,"qty":0.79642153},{"price":62784.6,"qty":0.00009500}],"asks":[],"checksum":2977238349,"timestamp":"2026-08-16T23:37:24.854528Z"}]}}
{"rx_ns": 42910353300200, "frame": {"channel":"heartbeat"}}
{"rx_ns": 42910967719400, "frame": {"channel":"book","type":"update","data":[{"symbol":"BTC/USD","bids":[{"price":62794.7,"qty":0.00810000},{"price":62794.7,"qty":0.00010000},{"price":62794.7,"qty":0.00000013}],"asks":[],"checksum":4023025237,"timestamp":"2026-08-16T23:37:25.588038Z"}]}}
{"rx_ns": 42910967785700, "frame": {"channel":"book","type":"update","data":[{"symbol":"BTC/USD","bids":[],"asks":[{"price":62794.8,"qty":5.75861514}],"checksum":3588718414,"timestamp":"2026-08-16T23:37:25.590596Z"}]}}
{"rx_ns": 42910967801100, "frame": {"channel":"book","type":"update","data":[{"symbol":"BTC/USD","bids":[{"price":62785.2,"qty":0.00000000},{"price":62780.8,"qty":0.79642153},{"price":62784.7,"qty":0.00318497}],"asks":[],"checksum":2402876717,"timestamp":"2026-08-16T23:37:25.591031Z"}]}}
{"rx_ns": 42910971918200, "frame": {"channel":"book","type":"update","data":[{"symbol":"BTC/USD","bids":[{"price":62794.7,"qty":0.00000000},{"price":62780.8,"qty":0.79642153},{"price":62794.3,"qty":0.00000000},{"price":62780.3,"qty":0.00023884}],"asks":[{"price":62793.6,"qty":0.00014887}],"checksum":2848284173,"timestamp":"2026-08-16T23:37:25.592135Z"}]}}
{"rx_ns": 42910971958100, "frame": {"channel":"book","type":"update","data":[{"symbol":"BTC/USD","bids":[],"asks":[{"price":62793.6,"qty":0.01180152}],"checksum":1914264378,"timestamp":"2026-08-16T23:37:25.592450Z"}]}}
{"rx_ns": 42910971971000, "frame": {"channel":"book","type":"update","data":[{"symbol":"BTC/USD","bids":[],"asks":[{"price":62794.8,"qty":5.74676267}],"checksum":1285553076,"timestamp":"2026-08-16T23:37:25.592670Z"}]}}
{"rx_ns": 42910971980200, "frame": {"channel":"book","type":"update","data":[{"symbol":"BTC/USD","bids":[],"asks":[{"price":62794.7,"qty":0.11000000}],"checksum":3043339451,"timestamp":"2026-08-16T23:37:25.593295Z"}]}}
{"rx_ns": 42910971988900, "frame": {"channel":"book","type":"update","data":[{"symbol":"BTC/USD","bids":[],"asks":[{"price":62794.8,"qty":5.72659973}],"checksum":2264016189,"timestamp":"2026-08-16T23:37:25.593662Z"}]}}
{"rx_ns": 42910971997700, "frame": {"channel":"book","type":"update","data":[{"symbol":"BTC/USD","bids":[],"asks":[{"price":62794.8,"qty":5.67061501},{"price":62794.7,"qty":0.16598472}],"checksum":4271627307,"timestamp":"2026-08-16T23:37:25.593718Z"}]}}
{"rx_ns": 42910975317400, "frame": {"channel":"book","type":"update","data":[{"symbol":"BTC/USD","bids":[],"asks":[{"price":62794.7,"qty":0.35088152}],"checksum":429499939,"timestamp":"2026-08-16T23:37:25.593747Z"}]}}
{"rx_ns": 42911000680800, "frame": {"channel":"book","type":"update","data":[{"symbol":"BTC/USD","bids":[],"asks":[{"price":62794.8,"qty":5.59261501}],"checksum":3916550877,"timestamp":"2026-08-16T23:37:25.593774Z"}]}}
{"rx_ns": 42911000742900, "frame": {"channel":"book","type":"update","data":[{"symbol":"BTC/USD","bids":[],"asks":[{"price":62794.8,"qty":5.43338102}],"checksum":39271468,"timestamp":"2026-08-16T23:37:25.593801Z"}]}}
{"rx_ns": 42911000755700, "frame": {"channel":"book","type":"update","data":[{"symbol":"BTC/USD","bids":[],"asks":[{"price":62796.0,"qty":0.00000000},{"price":62801.3,"qty":0.19620257}],"checksum":1926668286,"timestamp":"2026-08-16T23:37:25.593997Z"}]}}
{"rx_ns": 42911000770000, "frame": {"channel":"book","type":"update","data":[{"symbol":"BTC/USD","bids":[],"asks":[{"price":62793.6,"qty":0.08140152}],"checksum":2008821468,"timestamp":"2026-08-16T23:37:25.594134Z"}]}}
{"rx_ns": 42911000779900, "frame": {"channel":"book","type":"update","data":[{"symbol":"BTC/USD","bids":[],"asks":[{"price":62793.6,"qty":0.16100152}],"checksum":4192410485,"timestamp":"2026-08-16T23:37:25.594750Z"}]}}
{"rx_ns": 42911000790700, "frame": {"channel":"book","type":"update","data":[{"symbol":"BTC/USD","bids":[],"asks":[{"price":62793.6,"qty":0.95726101}],"checksum":3060720704,"timestamp":"2026-08-16T23:37:25.595756Z"}]}}
{"rx_ns": 42911000800400, "frame": {"channel":"book","type":"update","data":[{"symbol":"BTC/USD","bids":[],"asks":[{"price":62793.6,"qty":1.11653863}],"checksum":3151525005,"timestamp":"2026-08-16T23:37:25.596229Z"}]}}
{"rx_ns": 42911000810200, "frame": {"channel":"book","type":"update","data":[{"symbol":"BTC/USD","bids":[{"price":62793.5,"qty":0.03646524}],"asks":[],"checksum":155797922,"timestamp":"2026-08-16T23:37:25.596279Z"}]}}
{"rx_ns": 42911000893500, "frame": {"channel":"book","type":"update","data":[{"symbol":"BTC/USD","bids":[],"asks":[{"price":62798.0,"qty":0.00422189}],"checksum":3717398103,"timestamp":"2026-08-16T23:37:25.598790Z"}]}}
{"rx_ns": 42911000907800, "frame": {"channel":"book","type":"update","data":[{"symbol":"BTC/USD","bids":[],"asks":[{"price":62800.0,"qty":0.00422176}],"checksum":81595150,"timestamp":"2026-08-16T23:37:25.598975Z"}]}}
{"rx_ns": 42911000933000, "frame": {"channel":"book","type":"update","data":[{"symbol":"BTC/USD","bids":[],"asks":[{"price":62794.8,"qty":5.35378102}],"checksum":1645088991,"timestamp":"2026-08-16T23:37:25.604095Z"}]}}
{"rx_ns": 42911000955200, "frame": {"channel":"book","type":"update","data":[{"symbol":"BTC/USD","bids":[{"price":62781.7,"qty":0.00005100}],"asks":[],"checksum":3490493081,"timestamp":"2026-08-16T23:37:25.610754Z"}]}}
{"rx_ns": 42911010754300, "frame": {"channel":"book","type":"update","data":[{"symbol":"BTC/USD","bids":[{"price":62782.0,"qty":0.00422297}],"asks":[],"checksum":2028456910,"timestamp":"2026-08-16T23:37:25.635416Z"}]}}
{"rx_ns": 42911011700700, "frame": {"channel":"book","type":"update","data":[{"symbol":"BTC/USD","bids":[],"asks":[{"price":62794.7,"qty":0.16598472},{"price":62794.6,"qty":0.18489680}],"checksum":2936487497,"timestamp":"2026-08-16T23:37:25.636612Z"}]}}
{"rx_ns": 42911077486000, "frame": {"channel":"book","type":"update","data":[{"symbol":"BTC/USD","bids":[],"asks":[{"price":62794.8,"qty":5.24378102}],"checksum":2828043326,"timestamp":"2026-08-16T23:37:25.693952Z"}]}}
{"rx_ns": 42911077542500, "frame": {"channel":"book","type":"update","data":[{"symbol":"BTC/USD","bids":[],"asks":[{"price":62793.6,"qty":1.22653863}],"checksum":4002292958,"timestamp":"2026-08-16T23:37:25.694724Z"}]}}
{"rx_ns": 42911077557800, "frame": {"channel":"book","type":"update","data":[{"symbol":"BTC/USD","bids":[],"asks":[{"price":62793.6,"qty":1.24584855}],"checksum":517189455,"timestamp":"2026-08-16T23:37:25.695944Z"}]}}
{"rx_ns": 42911077570400, "frame": {"channel":"book","type":"update","data":[{"symbol":"BTC/USD","bids":[],"asks":[{"price":62793.6,"qty":1.32384855}],"checksum":3478771735,"timestamp":"2026-08-16T23:37:25.696482Z"}]}}
{"rx_ns": 42911105704200, "frame": {"channel":"book","type":"update","data":[{"symbol":"BTC/USD","bids":[{"price":62793.5,"qty":0.03686337}],"asks":[],"checksum":4007975360,"timestamp":"2026-08-16T23:37:25.730121Z"}]}}
{"rx_ns": 42911124945400, "frame": {"channel":"book","type":"update","data":[{"symbol":"BTC/USD","bids":[],"asks":[{"price":62794.8,"qty":1.45304952},{"price":62793.6,"qty":5.11469074}],"checksum":1352614562,"timestamp":"2026-08-16T23:37:25.747207Z"}]}}
{"rx_ns": 42911129630200, "frame": {"channel":"book","type":"update","data":[{"symbol":"BTC/USD","bids":[],"asks":[{"price":62794.6,"qty":0.00000000},{"price":62800.0,"qty":0.00422176},{"price":62796.6,"qty":0.18489680}],"checksum":2032201701,"timestamp":"2026-08-16T23:37:25.749991Z"}]}}
{"rx_ns": 42911165224700, "frame": {"channel":"book","type":"update","data":[{"symbol":"BTC/USD","bids":[{"price":62793.5,"qty":0.03726150}],"asks":[],"checksum":429493614,"timestamp":"2026-08-16T23:37:25.785284Z"}]}}
{"rx_ns": 42911165297000, "frame": {"channel":"book","type":"update","data":[{"symbol":"BTC/USD","bids":[],"asks":[{"price":62794.7,"qty":0.11000000},{"price":62793.6,"qty":5.17067546}],"checksum":4161908341,"timestamp":"2026-08-16T23:37:25.786608Z"}]}}
{"rx_ns": 42911170196700, "frame": {"channel":"book","type":"update","data":[{"symbol":"BTC/USD","bids":[],"asks":[{"price":62794.7,"qty":0.00000000},{"price":62800.0,"qty":0.00422176}],"checksum":4002293099,"timestamp":"2026-08-16T23:37:25.795179Z"}]}}
{"rx_ns": 42911171100500, "frame": {"channel":"book","type":"update","data":[{"symbol":"BTC/USD","bids":[],"asks":[{"price":62796.6,"qty":0.00000000},{"price":62800.5,"qty":0.00005100}],"checksum":2833370573,"timestamp":"2026-08-16T23:37:25.796418Z"}]}}
{"rx_ns": 42911229710200, "frame": {"channel":"book","type":"update","data":[{"symbol":"BTC/USD","bids":[{"price":62793.5,"qty":0.03765963}],"asks":[],"checksum":3045787538,"timestamp":"2026-08-16T23:37:25.840329Z"}]}}
{"rx_ns": 42911299791400, "frame": {"channel":"book","type":"update","data":[{"symbol":"BTC/USD","bids":[{"price":62793.5,"qty":0.03805776}],"asks":[],"checksum":2383411611,"timestamp":"2026-08-16T23:37:25.896149Z"}]}}
{"rx_ns": 42911344341600, "frame": {"channel":"book","type":"update","data":[{"symbol":"BTC/USD","bids":[{"price":62793.5,"qty":0.03845589}],"asks":[],"checksum":353784763,"timestamp":"2026-08-16T23:37:25.952216Z"}]}}
{"rx_ns": 42911347488800, "frame": {"channel":"book","type":"update","data":[{"symbol":"BTC/USD","bids":[],"asks":[{"price":62794.8,"qty":1.45265139},{"price":62793.6,"qty":5.17107359}],"checksum":1812003054,"timestamp":"2026-08-16T23:37:25.959958Z"}]}}
{"rx_ns": 42911347554100, "frame": {"channel":"book","type":"update","data":[{"symbol":"BTC/USD","bids":[{"price":62793.5,"qty":0.01714297}],"asks":[],"checksum":2124107990,"timestamp":"2026-08-16T23:37:25.965743Z"}]}}
{"rx_ns": 42911347578000, "frame": {"channel":"book","type":"update","data":[{"symbol":"BTC/USD","bids":[{"price":62792.3,"qty":0.02131292}],"asks":[],"checksum":1277878187,"timestamp":"2026-08-16T23:37:25.966882Z"}]}}
{"rx_ns": 42911352986900, "frame": {"channel":"book","type":"update","data":[{"symbol":"BTC/USD","bids":[{"price":62793.5,"qty":0.01674484}],"asks":[],"checksum":4035872163,"timestamp":"2026-08-16T23:37:25.976331Z"}]}}
{"rx_ns": 42911358463100, "frame": {"channel":"heartbeat"}}
{"rx_ns": 42911410629200, "frame": {"channel":"book","type":"update","data":[{"symbol":"BTC/USD","bids":[{"price":62793.5,"qty":0.01634671}],"asks":[],"checksum":711502303,"timestamp":"2026-08-16T23:37:26.036421Z"}]}}
{"rx_ns": 42911472400200, "frame": {"channel":"book","type":"update","data":[{"symbol":"BTC/USD","bids":[{"price":62793.5,"qty":0.01594858}],"asks":[],"checksum":4156906713,"timestamp":"2026-08-16T23:37:26.097856Z"}]}}
{"rx_ns": 42911537567200, "frame": {"channel":"book","type":"update","data":[{"symbol":"BTC/USD","bids":[{"price":62793.5,"qty":0.01555045}],"asks":[],"checksum":2717056460,"timestamp":"2026-08-16T23:37:26.163306Z"}]}}
{"rx_ns": 42911561993200, "frame": {"channel":"book","type":"update","data":[{"symbol":"BTC/USD","bids":[],"asks":[{"price":62797.4,"qty":0.00005100}],"checksum":1942515925,"timestamp":"2026-08-16T23:37:26.187901Z"}]}}
{"rx_ns": 42911613994200, "frame": {"channel":"book","type":"update","data":[{"symbol":"BTC/USD","bids":[],"asks":[{"price":62794.8,"qty":1.45165139}],"checksum":1238281393,"timestamp":"2026-08-16T23:37:26.239707Z"}]}}
{"rx_ns": 42912289955800, "frame": {"channel":"book","type":"update","data":[{"symbol":"BTC/USD","bids":[{"price":62784.6,"qty":0.00000000},{"price":62781.7,"qty":0.00005100},{"price":62785.2,"qty":0.00009500}],"asks":[],"checksum":3188426293,"timestamp":"2026-08-16T23:37:26.913423Z"}]}}
{"rx_ns": 42912357104400, "frame": {"channel":"heartbeat"}}
{"rx_ns": 42912392788000, "frame": {"channel":"book","type":"update","data":[{"symbol":"BTC/USD","bids":[{"price":62793.5,"qty":0.01565045}],"asks":[],"checksum":3170033834,"timestamp":"2026-08-16T23:37:27.018565Z"}]}}
{"rx_ns": 42912533157600, "frame": {"channel":"book","type":"update","data":[{"symbol":"BTC/USD","bids":[{"price":62784.7,"qty":0.00000000},{"price":62781.7,"qty":0.00005100},{"price":62784.1,"qty":0.00318497}],"asks":[],"checksum":1073902054,"timestamp":"2026-08-16T23:37:27.158354Z"}]}}
{"rx_ns": 42912680042200, "frame": {"channel":"book","type":"update","data":[{"symbol":"BTC/USD","bids":[],"asks":[{"price":62793.6,"qty":5.17207359}],"checksum":1479992716,"timestamp":"2026-08-16T23:37:27.305061Z"}]}}
{"rx_ns": 42912830311800, "frame": {"channel":"book","type":"update","data":[{"symbol":"BTC/USD","bids":[],"asks":[{"price":62793.6,"qty":5.18007359}],"checksum":1023654041,"timestamp":"2026-08-16T23:37:27.456429Z"}]}}
{"rx_ns": 42913353497400, "frame": {"channel":"heartbeat"}}
{"rx_ns": 42914338670500, "frame": {"channel":"book","type":"update","data":[{"symbol":"BTC/USD","bids":[{"price":62785.2,"qty":0.00000000},{"price":62781.7,"qty":0.00005100},{"price":62784.6,"qty":0.00009500}],"asks":[],"checksum":2216900534,"timestamp":"2026-08-16T23:37:28.964640Z"}]}}
{"rx_ns": 42914353745800, "frame": {"channel":"heartbeat"}}
{"rx_ns": 42915354254300, "frame": {"channel":"heartbeat"}}
{"rx_ns": 42916356922900, "frame": {"channel":"heartbeat"}}
{"rx_ns": 42916459422200, "frame": {"channel":"book","type":"update","data":[{"symbol":"BTC/USD","bids":[{"price":62782.1,"qty":0.79640506}],"asks":[],"checksum":3358324374,"timestamp":"2026-08-16T23:37:31.082701Z"}]}}
{"rx_ns": 42916498920200, "frame": {"channel":"book","type":"update","data":[{"symbol":"BTC/USD","bids":[{"price":62782.0,"qty":0.00000000},{"price":62781.7,"qty":0.00005100}],"asks":[],"checksum":688615201,"timestamp":"2026-08-16T23:37:31.124655Z"}]}}
{"rx_ns": 42916583061100, "frame": {"channel":"book","type":"update","data":[{"symbol":"BTC/USD","bids":[{"price":62791.2,"qty":0.00164300}],"asks":[],"checksum":416759365,"timestamp":"2026-08-16T23:37:31.206414Z"}]}}
{"rx_ns": 42916583106400, "frame": {"channel":"book","type":"update","data":[{"symbol":"BTC/USD","bids":[{"price":62785.0,"qty":0.05598472}],"asks":[],"checksum":1400058470,"timestamp":"2026-08-16T23:37:31.207772Z"}]}}
{"rx_ns": 42916596322000, "frame": {"channel":"book","type":"update","data":[{"symbol":"BTC/USD","bids":[],"asks":[{"price":62796.6,"qty":0.18489680}],"checksum":2789801949,"timestamp":"2026-08-16T23:37:31.220461Z"}]}}
{"rx_ns": 42916596363200, "frame": {"channel":"book","type":"update","data":[{"symbol":"BTC/USD","bids":[{"price":62782.1,"qty":0.00000000},{"price":62781.7,"qty":0.00005100}],"asks":[],"checksum":1782937448,"timestamp":"2026-08-16T23:37:31.220769Z"}]}}
{"rx_ns": 42916699561700, "frame": {"channel":"book","type":"update","data":[{"symbol":"BTC/USD","bids":[{"price":62792.3,"qty":0.00000000},{"price":62781.4,"qty":0.79641314}],"asks":[],"checksum":3752802498,"timestamp":"2026-08-16T23:37:31.324194Z"}]}}
{"rx_ns": 42916702477200, "frame": {"channel":"book","type":"update","data":[{"symbol":"BTC/USD","bids":[{"price":62791.0,"qty":0.02131292}],"asks":[],"checksum":3211923694,"timestamp":"2026-08-16T23:37:31.325700Z"}]}}
{"rx_ns": 42916762745400, "frame": {"channel":"book","type":"update","data":[{"symbol":"BTC/USD","bids":[{"price":62793.5,"qty":0.00049813}],"asks":[],"checksum":1313096917,"timestamp":"2026-08-16T23:37:31.379798Z"}]}}
{"rx_ns": 42916762814300, "frame": {"channel":"book","type":"update","data":[{"symbol":"BTC/USD","bids":[{"price":62784.1,"qty":0.00000000},{"price":62781.4,"qty":0.79641314},{"price":62783.0,"qty":0.00318497}],"asks":[],"checksum":4263316697,"timestamp":"2026-08-16T23:37:31.382176Z"}]}}
{"rx_ns": 42916798289900, "frame": {"channel":"book","type":"update","data":[{"symbol":"BTC/USD","bids":[{"price":62791.0,"qty":0.00000000},{"price":62780.3,"qty":0.00023884}],"asks":[],"checksum":1579795993,"timestamp":"2026-08-16T23:37:31.424241Z"}]}}
{"rx_ns": 42916798341000, "frame": {"channel":"book","type":"update","data":[{"symbol":"BTC/USD","bids":[{"price":62792.0,"qty":0.02131292}],"asks":[],"checksum":2438003544,"timestamp":"2026-08-16T23:37:31.424431Z"}]}}
{"rx_ns": 42916894806500, "frame": {"channel":"book","type":"update","data":[{"symbol":"BTC/USD","bids":[{"price":62792.0,"qty":0.00000000},{"price":62780.3,"qty":0.00023884}],"asks":[],"checksum":1579795993,"timestamp":"2026-08-16T23:37:31.517946Z"}]}}
{"rx_ns": 42916894889800, "frame": {"channel":"book","type":"update","data":[{"symbol":"BTC/USD","bids":[{"price":62789.8,"qty":0.02131292}],"asks":[],"checksum":2234111488,"timestamp":"2026-08-16T23:37:31.519441Z"}]}}
{"rx_ns": 42917015479900, "frame": {"channel":"book","type":"update","data":[{"symbol":"BTC/USD","bids":[{"price":62789.8,"qty":0.00000000},{"price":62780.4,"qty":0.79642650}],"asks":[],"checksum":3318361441,"timestamp":"2026-08-16T23:37:31.640783Z"}]}}
{"rx_ns": 42917015543900, "frame": {"channel":"book","type":"update","data":[{"symbol":"BTC/USD","bids":[{"price":62790.7,"qty":0.02131292}],"asks":[],"checksum":2833757300,"timestamp":"2026-08-16T23:37:31.640984Z"}]}}
{"rx_ns": 42917149382500, "frame": {"channel":"book","type":"update","data":[{"symbol":"BTC/USD","bids":[{"price":62790.7,"qty":0.00000000},{"price":62780.4,"qty":0.79642650}],"asks":[],"checksum":3318361441,"timestamp":"2026-08-16T23:37:31.775513Z"}]}}
{"rx_ns": 42917151097900, "frame": {"channel":"book","type":"update","data":[{"symbol":"BTC/USD","bids":[{"price":62791.7,"qty":0.02131292}],"asks":[],"checksum":2131541990,"timestamp":"2026-08-16T23:37:31.775860Z"}]}}
{"rx_ns": 42917355151100, "frame": {"channel":"heartbeat"}}
{"rx_ns": 42917627380000, "frame": {"channel":"book","type":"update","data":[{"symbol":"BTC/USD","bids":[],"asks":[{"price":62793.6,"qty":5.17992472},{"price":62793.6,"qty":5.17809965}],"checksum":3025085744,"timestamp":"2026-08-16T23:37:32.249350Z"}]}}
{"rx_ns": 42917629494200, "frame": {"channel":"book","type":"update","data":[{"symbol":"BTC/USD","bids":[],"asks":[{"price":62793.6,"qty":5.10009965}],"checksum":4240877949,"timestamp":"2026-08-16T23:37:32.251395Z"}]}}
{"rx_ns": 42918355769300, "frame": {"channel":"heartbeat"}}
{"rx_ns": 42918373614800, "frame": {"channel":"book","type":"update","data":[{"symbol":"BTC/USD","bids":[{"price":62783.0,"qty":0.00000000},{"price":62780.4,"qty":0.79642650},{"price":62783.3,"qty":0.00318497}],"asks":[],"checksum":2942104313,"timestamp":"2026-08-16T23:37:32.987579Z"}]}}
{"rx_ns": 42919359679100, "frame": {"channel":"heartbeat"}}
{"rx_ns": 42920355733600, "frame": {"channel":"heartbeat"}}
{"rx_ns": 42921356401400, "frame": {"channel":"heartbeat"}}
{"rx_ns": 42922182481400, "frame": {"channel":"book","type":"update","data":[{"symbol":"BTC/USD","bids":[],"asks":[{"price":62793.6,"qty":5.09877786}],"checksum":1980689788,"timestamp":"2026-08-16T23:37:36.798277Z"}]}}
{"rx_ns": 42922182565900, "frame": {"channel":"book","type":"update","data":[{"symbol":"BTC/USD","bids":[],"asks":[{"price":62793.6,"qty":5.17677786}],"checksum":528254587,"timestamp":"2026-08-16T23:37:36.800332Z"}]}}
{"rx_ns": 42922360477800, "frame": {"channel":"heartbeat"}}
{"rx_ns": 42923358911500, "frame": {"channel":"heartbeat"}}
{"rx_ns": 42924134641700, "frame": {"channel":"book","type":"update","data":[{"symbol":"BTC/USD","bids":[{"price":62785.0,"qty":0.00000000},{"price":62780.3,"qty":0.00023884},{"price":62788.1,"qty":0.05598472}],"asks":[],"checksum":366735595,"timestamp":"2026-08-16T23:37:38.758685Z"}]}}
{"rx_ns": 42924356420700, "frame": {"channel":"heartbeat"}}
{"rx_ns": 42924497616100, "frame": {"channel":"book","type":"update","data":[{"symbol":"BTC/USD","bids":[{"price":62793.5,"qty":0.00033098}],"asks":[],"checksum":751092168,"timestamp":"2026-08-16T23:37:39.121185Z"}]}}
{"rx_ns": 42924593850900, "frame": {"channel":"book","type":"update","data":[{"symbol":"BTC/USD","bids":[{"price":62784.6,"qty":0.00000000},{"price":62781.1,"qty":0.79641687},{"price":62784.0,"qty":0.00009500}],"asks":[],"checksum":3071590662,"timestamp":"2026-08-16T23:37:39.220089Z"}]}}
{"rx_ns": 42925071501400, "frame": {"channel":"book","type":"update","data":[{"symbol":"BTC/USD","bids":[{"price":62793.5,"qty":0.00010000},{"price":62793.5,"qty":0.00000098}],"asks":[],"checksum":640876754,"timestamp":"2026-08-16T23:37:39.696630Z"}]}}
{"rx_ns": 42925076397000, "frame": {"channel":"book","type":"update","data":[{"symbol":"BTC/USD","bids":[],"asks":[{"price":62793.6,"qty":5.10717786}],"checksum":3053448393,"timestamp":"2026-08-16T23:37:39.698369Z"}]}}
{"rx_ns": 42925076456400, "frame": {"channel":"book","type":"update","data":[{"symbol":"BTC/USD","bids":[],"asks":[{"price":62793.6,"qty":5.02917786}],"checksum":470850293,"timestamp":"2026-08-16T23:37:39.698536Z"}]}}
{"rx_ns": 42925076477500, "frame": {"channel":"book","type":"update","data":[{"symbol":"BTC/USD","bids":[{"price":62783.3,"qty":0.00000000},{"price":62781.1,"qty":0.79641687},{"price":62783.2,"qty":0.00318497}],"asks":[],"checksum":2612416950,"timestamp":"2026-08-16T23:37:39.698879Z"}]}}
{"rx_ns": 42925078323400, "frame": {"channel":"book","type":"update","data":[{"symbol":"BTC/USD","bids":[{"price":62793.5,"qty":0.00000000},{"price":62781.1,"qty":0.79641687}],"asks":[{"price":62791.8,"qty":0.00019902}],"checksum":1847579405,"timestamp":"2026-08-16T23:37:39.700974Z"}]}}
{"rx_ns": 42925078398300, "frame": {"channel":"book","type":"update","data":[{"symbol":"BTC/USD","bids":[],"asks":[{"price":62791.8,"qty":0.01185194}],"checksum":4024195837,"timestamp":"2026-08-16T23:37:39.701453Z"}]}}
{"rx_ns": 42925078412900, "frame": {"channel":"book","type":"update","data":[{"symbol":"BTC/USD","bids":[],"asks":[{"price":62793.6,"qty":5.02067207}],"checksum":2396385677,"timestamp":"2026-08-16T23:37:39.701570Z"}]}}
{"rx_ns": 42925078422700, "frame": {"channel":"book","type":"update","data":[{"symbol":"BTC/USD","bids":[],"asks":[{"price":62793.5,"qty":0.11000000}],"checksum":2550666438,"timestamp":"2026-08-16T23:37:39.702085Z"}]}}
{"rx_ns": 42925078434500, "frame": {"channel":"book","type":"update","data":[{"symbol":"BTC/USD","bids":[],"asks":[{"price":62793.6,"qty":4.96468735},{"price":62793.5,"qty":0.16598472}],"checksum":1925322800,"timestamp":"2026-08-16T23:37:39.702512Z"}]}}
{"rx_ns": 42925078445900, "frame": {"channel":"book","type":"update","data":[{"symbol":"BTC/USD","bids":[],"asks":[{"price":62796.9,"qty":0.00000000},{"price":62798.0,"qty":0.00422189}],"checksum":3215782809,"timestamp":"2026-08-16T23:37:39.702547Z"}]}}
{"rx_ns": 42925078456000, "frame": {"channel":"book","type":"update","data":[{"symbol":"BTC/USD","bids":[],"asks":[{"price":62793.6,"qty":4.80540973}],"checksum":1002541753,"timestamp":"2026-08-16T23:37:39.702581Z"}]}}
{"rx_ns": 42925078465800, "frame": {"channel":"book","type":"update","data":[{"symbol":"BTC/USD","bids":[],"asks":[{"price":62793.6,"qty":4.78609981}],"checksum":659995938,"timestamp":"2026-08-16T23:37:39.702595Z"}]}}
{"rx_ns": 42925078475300, "frame": {"channel":"book","type":"update","data":[{"symbol":"BTC/USD","bids":[],"asks":[{"price":62791.8,"qty":0.08145194}],"checksum":2242350871,"timestamp":"2026-08-16T23:37:39.702751Z"}]}}
{"rx_ns": 42925078484500, "frame": {"channel":"book","type":"update","data":[{"symbol":"BTC/USD","bids":[],"asks":[{"price":62791.8,"qty":0.16105194}],"checksum":3504772867,"timestamp":"2026-08-16T23:37:39.702910Z"}]}}
{"rx_ns": 42925084919900, "frame": {"channel":"book","type":"update","data":[{"symbol":"BTC/USD","bids":[],"asks":[{"price":62796.6,"qty":0.00000000},{"price":62799.1,"qty":0.06000000},{"price":62793.4,"qty":0.18489680}],"checksum":4088771495,"timestamp":"2026-08-16T23:37:39.703274Z"}]}}
{"rx_ns": 42925085029300, "frame": {"channel":"book","type":"update","data":[{"symbol":"BTC/USD","bids":[],"asks":[{"price":62791.8,"qty":0.95733425}],"checksum":410721376,"timestamp":"2026-08-16T23:37:39.704214Z"}]}}
{"rx_ns": 42925085070400, "frame": {"channel":"book","type":"update","data":[{"symbol":"BTC/USD","bids":[{"price":62791.7,"qty":0.03646524}],"asks":[],"checksum":1415153699,"timestamp":"2026-08-16T23:37:39.704846Z"}]}}
{"rx_ns": 42925085113800, "frame": {"channel":"book","type":"update","data":[{"symbol":"BTC/USD","bids":[],"asks":[{"price":62793.6,"qty":4.70649981}],"checksum":1468185855,"timestamp":"2026-08-16T23:37:39.711171Z"}]}}
{"rx_ns": 42925117402700, "frame": {"channel":"book","type":"update","data":[{"symbol":"BTC/USD","bids":[],"asks":[{"price":62793.4,"qty":0.00000000},{"price":62799.1,"qty":0.06000000},{"price":62796.6,"qty":0.18489680}],"checksum":2324392335,"timestamp":"2026-08-16T23:37:39.740178Z"}]}}
{"rx_ns": 42925120238000, "frame": {"channel":"book","type":"update","data":[{"symbol":"BTC/USD","bids":[],"asks":[{"price":62791.8,"qty":1.11661187}],"checksum":3340241787,"timestamp":"2026-08-16T23:37:39.746370Z"}]}}
{"rx_ns": 42925177283300, "frame": {"channel":"book","type":"update","data":[{"symbol":"BTC/USD","bids":[],"asks":[{"price":62793.6,"qty":4.59649981}],"checksum":2073847771,"timestamp":"2026-08-16T23:37:39.802690Z"}]}}
{"rx_ns": 42925177356600, "frame": {"channel":"book","type":"update","data":[{"symbol":"BTC/USD","bids":[],"asks":[{"price":62791.8,"qty":1.22661187}],"checksum":1647664858,"timestamp":"2026-08-16T23:37:39.803386Z"}]}}
{"rx_ns": 42925180366400, "frame": {"channel":"book","type":"update","data":[{"symbol":"BTC/USD","bids":[],"asks":[{"price":62791.8,"qty":1.30461187}],"checksum":2108117186,"timestamp":"2026-08-16T23:37:39.805104Z"}]}}
{"rx_ns": 42925203918300, "frame": {"channel":"book","type":"update","data":[{"symbol":"BTC/USD","bids":[],"asks":[{"price":62794.2,"qty":0.00005100}],"checksum":3847940669,"timestamp":"2026-08-16T23:37:39.830167Z"}]}}
{"rx_ns": 42925215613100, "frame": {"channel":"book","type":"update","data":[{"symbol":"BTC/USD","bids":[{"price":62791.7,"qty":0.03686339}],"asks":[],"checksum":2967582984,"timestamp":"2026-08-16T23:37:39.842035Z"}]}}
{"rx_ns": 42925225609000, "frame": {"channel":"book","type":"update","data":[{"symbol":"BTC/USD","bids":[],"asks":[{"price":62793.6,"qty":0.80565762}],"checksum":2496475101,"timestamp":"2026-08-16T23:37:39.850717Z"}]}}
{"rx_ns": 42925232838200, "frame": {"channel":"book","type":"update","data":[{"symbol":"BTC/USD","bids":[],"asks":[{"price":62791.8,"qty":5.09548326}],"checksum":1271504441,"timestamp":"2026-08-16T23:37:39.857866Z"}]}}
{"rx_ns": 42925245022700, "frame": {"channel":"book","type":"update","data":[{"symbol":"BTC/USD","bids":[],"asks":[{"price":62793.5,"qty":0.11000000},{"price":62793.4,"qty":0.05598472}],"checksum":2664721418,"timestamp":"2026-08-16T23:37:39.867085Z"}]}}
{"rx_ns": 42925255749200, "frame": {"channel":"book","type":"update","data":[{"symbol":"BTC/USD","bids":[{"price":62781.1,"qty":0.00000000},{"price":62780.5,"qty":0.06101297}],"asks":[],"checksum":3413766371,"timestamp":"2026-08-16T23:37:39.876467Z"}]}}
{"rx_ns": 42925279636900, "frame": {"channel":"book","type":"update","data":[{"symbol":"BTC/USD","bids":[{"price":62788.1,"qty":0.00000000},{"price":62780.3,"qty":0.00023884}],"asks":[],"checksum":318673332,"timestamp":"2026-08-16T23:37:39.885241Z"}]}}
{"rx_ns": 42925279701100, "frame": {"channel":"book","type":"update","data":[{"symbol":"BTC/USD","bids":[{"price":62785.0,"qty":0.05598472}],"asks":[],"checksum":3674695736,"timestamp":"2026-08-16T23:37:39.891600Z"}]}}
{"rx_ns": 42925288635500, "frame": {"channel":"book","type":"update","data":[{"symbol":"BTC/USD","bids":[{"price":62791.7,"qty":0.03726154}],"asks":[],"checksum":3546013139,"timestamp":"2026-08-16T23:37:39.899575Z"}]}}
{"rx_ns": 42925288757600, "frame": {"channel":"book","type":"update","data":[{"symbol":"BTC/USD","bids":[],"asks":[{"price":62793.5,"qty":0.00000000},{"price":62797.4,"qty":0.00005100}],"checksum":2149974504,"timestamp":"2026-08-16T23:37:39.904141Z"}]}}
{"rx_ns": 42925290220300, "frame": {"channel":"book","type":"update","data":[{"symbol":"BTC/USD","bids":[],"asks":[{"price":62791.8,"qty":5.11625024}],"checksum":2399616079,"timestamp":"2026-08-16T23:37:39.912576Z"}]}}
{"rx_ns": 42925297767700, "frame": {"channel":"book","type":"update","data":[{"symbol":"BTC/USD","bids":[{"price":62791.7,"qty":0.01594862}],"asks":[],"checksum":3773226174,"timestamp":"2026-08-16T23:37:39.921447Z"}]}}
{"rx_ns": 42925301863500, "frame": {"channel":"book","type":"update","data":[{"symbol":"BTC/USD","bids":[{"price":62790.4,"qty":0.02131292}],"asks":[],"checksum":1757913779,"timestamp":"2026-08-16T23:37:39.923416Z"}]}}
{"rx_ns": 42925331474100, "frame": {"channel":"book","type":"update","data":[{"symbol":"BTC/USD","bids":[{"price":62791.7,"qty":0.01634677}],"asks":[],"checksum":917966638,"timestamp":"2026-08-16T23:37:39.957029Z"}]}}
{"rx_ns": 42925339689300, "frame": {"channel":"book","type":"update","data":[{"symbol":"BTC/USD","bids":[],"asks":[{"price":62797.1,"qty":0.00000000},{"price":62798.0,"qty":0.00422189}],"checksum":103604441,"timestamp":"2026-08-16T23:37:39.965056Z"}]}}
{"rx_ns": 42925358710500, "frame": {"channel":"heartbeat"}}
{"rx_ns": 42925392164300, "frame": {"channel":"book","type":"update","data":[{"symbol":"BTC/USD","bids":[{"price":62791.7,"qty":0.01674492}],"asks":[],"checksum":1915702950,"timestamp":"2026-08-16T23:37:40.013405Z"}]}}
{"rx_ns": 42925448980000, "frame": {"channel":"book","type":"update","data":[{"symbol":"BTC/USD","bids":[{"price":62791.7,"qty":0.01714307}],"asks":[],"checksum":2770044821,"timestamp":"2026-08-16T23:37:40.072281Z"}]}}
{"rx_ns": 42925449045200, "frame": {"channel":"book","type":"update","data":[{"symbol":"BTC/USD","bids":[],"asks":[{"price":62793.4,"qty":0.00000000},{"price":62799.1,"qty":0.06000000},{"price":62791.8,"qty":5.17223496}],"checksum":3886578281,"timestamp":"2026-08-16T23:37:40.073489Z"}]}}
{"rx_ns": 42925451731200, "frame": {"channel":"book","type":"update","data":[{"symbol":"BTC/USD","bids":[],"asks":[{"price":62796.6,"qty":0.00000000},{"price":62800.0,"qty":0.00422176},{"price":62799.0,"qty":0.18489680}],"checksum":2438922597,"timestamp":"2026-08-16T23:37:40.074785Z"}]}}
{"rx_ns": 42925457497400, "frame": {"channel":"book","type":"update","data":[{"symbol":"BTC/USD","bids":[],"asks":[{"price":62793.6,"qty":0.80525949},{"price":62791.8,"qty":5.17263311}],"checksum":2963904680,"timestamp":"2026-08-16T23:37:40.079635Z"}]}}
{"rx_ns": 42925472435000, "frame": {"channel":"book","type":"update","data":[{"symbol":"BTC/USD","bids":[{"price":62791.7,"qty":0.01674492}],"asks":[],"checksum":1738363291,"timestamp":"2026-08-16T23:37:40.096347Z"}]}}
{"rx_ns": 42925478707700, "frame": {"channel":"book","type":"update","data":[{"symbol":"BTC/USD","bids":[{"price":62791.7,"qty":0.00159260},{"price":62791.7,"qty":0.00119445},{"price":62791.7,"qty":0.00079630},{"price":62791.7,"qty":0.00039815},{"price":62791.7,"qty":0.00000092}],"asks":[],"checksum":2063019841,"timestamp":"2026-08-16T23:37:40.098682Z"}]}}
{"rx_ns": 42925485629400, "frame": {"channel":"book","type":"update","data":[{"symbol":"BTC/USD","bids":[],"asks":[{"price":62799.0,"qty":0.00000000},{"price":62800.0,"qty":0.00422176}],"checksum":232506524,"timestamp":"2026-08-16T23:37:40.107048Z"}]}}
{"rx_ns": 42925487956800, "frame": {"channel":"book","type":"update","data":[{"symbol":"BTC/USD","bids":[],"asks":[{"price":62791.8,"qty":1.38176172}],"checksum":2374695972,"timestamp":"2026-08-16T23:37:40.109986Z"}]}}
{"rx_ns": 42925604628000, "frame": {"channel":"book","type":"update","data":[{"symbol":"BTC/USD","bids":[],"asks":[{"price":62791.8,"qty":5.17264463}],"checksum":3391432564,"timestamp":"2026-08-16T23:37:40.230040Z"}]}}
{"rx_ns": 42925651474200, "frame": {"channel":"book","type":"update","data":[{"symbol":"BTC/USD","bids":[],"asks":[{"price":62794.8,"qty":0.79624427}],"checksum":2870120382,"timestamp":"2026-08-16T23:37:40.275203Z"}]}}
{"rx_ns": 42925654103200, "frame": {"channel":"book","type":"update","data":[{"symbol":"BTC/USD","bids":[],"asks":[{"price":62791.8,"qty":5.44164463}],"checksum":690156824,"timestamp":"2026-08-16T23:37:40.278905Z"}]}}
{"rx_ns": 42925716140700, "frame": {"channel":"book","type":"update","data":[{"symbol":"BTC/USD","bids":[{"price":62791.7,"qty":0.00000000},{"price":62780.5,"qty":0.06101297}],"asks":[],"checksum":320454299,"timestamp":"2026-08-16T23:37:40.337287Z"}]}}
{"rx_ns": 42925716213500, "frame": {"channel":"book","type":"update","data":[{"symbol":"BTC/USD","bids":[],"asks":[{"price":62791.7,"qty":0.11000000}],"checksum":3908996609,"timestamp":"2026-08-16T23:37:40.338082Z"}]}}
{"rx_ns": 42925716239100, "frame": {"channel":"book","type":"update","data":[{"symbol":"BTC/USD","bids":[],"asks":[{"price":62793.6,"qty":0.00900000}],"checksum":3676949702,"timestamp":"2026-08-16T23:37:40.338420Z"}]}}
{"rx_ns": 42925716250000, "frame": {"channel":"book","type":"update","data":[{"symbol":"BTC/USD","bids":[{"price":62791.2,"qty":0.00159200}],"asks":[],"checksum":2514593829,"timestamp":"2026-08-16T23:37:40.338449Z"}]}}
{"rx_ns": 42925716258600, "frame": {"channel":"book","type":"update","data":[{"symbol":"BTC/USD","bids":[],"asks":[{"price":62791.8,"qty":5.38565991},{"price":62791.7,"qty":0.16598472}],"checksum":1363035562,"timestamp":"2026-08-16T23:37:40.338497Z"}]}}
{"rx_ns": 42925716268400, "frame": {"channel":"book","type":"update","data":[{"symbol":"BTC/USD","bids":[],"asks":[{"price":62791.3,"qty":0.06960000}],"checksum":2760898864,"timestamp":"2026-08-16T23:37:40.338510Z"}]}}
{"rx_ns": 42925716277400, "frame": {"channel":"book","type":"update","data":[{"symbol":"BTC/USD","bids":[],"asks":[{"price":62791.8,"qty":5.22638229}],"checksum":307271300,"timestamp":"2026-08-16T23:37:40.338580Z"}]}}
{"rx_ns": 42925716286400, "frame": {"channel":"book","type":"update","data":[{"symbol":"BTC/USD","bids":[],"asks":[{"price":62791.8,"qty":5.15678229}],"checksum":407443951,"timestamp":"2026-08-16T23:37:40.339116Z"}]}}
{"rx_ns": 42925716294500, "frame": {"channel":"book","type":"update","data":[{"symbol":"BTC/USD","bids":[],"asks":[{"price":62791.8,"qty":4.36049998}],"checksum":3955429569,"timestamp":"2026-08-16T23:37:40.339375Z"}]}}
{"rx_ns": 42925716303200, "frame": {"channel":"book","type":"update","data":[{"symbol":"BTC/USD","bids":[],"asks":[{"price":62791.8,"qty":4.33973300}],"checksum":1895754000,"timestamp":"2026-08-16T23:37:40.339499Z"}]}}
{"rx_ns": 42925716311600, "frame": {"channel":"book","type":"update","data":[{"symbol":"BTC/USD","bids":[],"asks":[{"price":62792.3,"qty":0.46828931}],"checksum":758658748,"timestamp":"2026-08-16T23:37:40.339512Z"}]}}
{"rx_ns": 42925716320000, "frame": {"channel":"book","type":"update","data":[{"symbol":"BTC/USD","bids":[],"asks":[{"price":62791.7,"qty":0.24558472}],"checksum":81208305,"timestamp":"2026-08-16T23:37:40.339811Z"}]}}
{"rx_ns": 42925718387000, "frame": {"channel":"book","type":"update","data":[{"symbol":"BTC/USD","bids":[],"asks":[{"price":62791.7,"qty":0.32358472}],"checksum":3540620598,"timestamp":"2026-08-16T23:37:40.339882Z"}]}}
{"rx_ns": 42925718429600, "frame": {"channel":"book","type":"update","data":[{"symbol":"BTC/USD","bids":[],"asks":[{"price":62791.8,"qty":4.26173300}],"checksum":1676821098,"timestamp":"2026-08-16T23:37:40.339952Z"}]}}
{"rx_ns": 42925718442900, "frame": {"channel":"book","type":"update","data":[{"symbol":"BTC/USD","bids":[],"asks":[{"price":62791.3,"qty":0.14760000}],"checksum":261477611,"timestamp":"2026-08-16T23:37:40.340052Z"}]}}
{"rx_ns": 42925718456000, "frame": {"channel":"book","type":"update","data":[{"symbol":"BTC/USD","bids":[],"asks":[{"price":62791.7,"qty":0.24398472}],"checksum":3521529220,"timestamp":"2026-08-16T23:37:40.340148Z"}]}}
{"rx_ns": 42925718540000, "frame": {"channel":"book","type":"update","data":[{"symbol":"BTC/USD","bids":[],"asks":[{"price":62791.8,"qty":4.18213300}],"checksum":514637132,"timestamp":"2026-08-16T23:37:40.340220Z"}]}}
{"rx_ns": 42925718555500, "frame": {"channel":"book","type":"update","data":[{"symbol":"BTC/USD","bids":[],"asks":[{"price":62791.3,"qty":0.22720000}],"checksum":2081597679,"timestamp":"2026-08-16T23:37:40.340235Z"}]}}
{"rx_ns": 42925718567500, "frame": {"channel":"book","type":"update","data":[{"symbol":"BTC/USD","bids":[],"asks":[{"price":62791.7,"qty":0.16598472}],"checksum":1548786186,"timestamp":"2026-08-16T23:37:40.340556Z"}]}}
{"rx_ns": 42925718577900, "frame": {"channel":"book","type":"update","data":[{"symbol":"BTC/USD","bids":[],"asks":[{"price":62791.8,"qty":4.17048008}],"checksum":2175776341,"timestamp":"2026-08-16T23:37:40.340824Z"}]}}
{"rx_ns": 42925718584900, "frame": {"channel":"book","type":"update","data":[{"symbol":"BTC/USD","bids":[],"asks":[{"price":62791.6,"qty":0.79628485}],"checksum":1960831144,"timestamp":"2026-08-16T23:37:40.340983Z"}]}}
{"rx_ns": 42925718591500, "frame": {"channel":"book","type":"update","data":[{"symbol":"BTC/USD","bids":[{"price":62791.2,"qty":0.01674406}],"asks":[],"checksum":1610156619,"timestamp":"2026-08-16T23:37:40.341008Z"}]}}
{"rx_ns": 42925718597700, "frame": {"channel":"book","type":"update","data":[{"symbol":"BTC/USD","bids":[],"asks":[{"price":62791.8,"qty":4.17028106}],"checksum":900183268,"timestamp":"2026-08-16T23:37:40.341170Z"}]}}
{"rx_ns": 42925718604000, "frame": {"channel":"book","type":"update","data":[{"symbol":"BTC/USD","bids":[],"asks":[{"price":62792.4,"qty":0.79627492}],"checksum":1124412163,"timestamp":"2026-08-16T23:37:40.341278Z"}]}}
{"rx_ns": 42925718628800, "frame": {"channel":"book","type":"update","data":[{"symbol":"BTC/USD","bids":[],"asks":[{"price":62791.3,"qty":0.29664450}],"checksum":2030218429,"timestamp":"2026-08-16T23:37:40.341867Z"}]}}
{"rx_ns": 42925720525300, "frame": {"channel":"book","type":"update","data":[{"symbol":"BTC/USD","bids":[],"asks":[{"price":62791.3,"qty":0.30849750}],"checksum":3185453586,"timestamp":"2026-08-16T23:37:40.345695Z"}]}}
{"rx_ns": 42925724200300, "frame": {"channel":"book","type":"update","data":[{"symbol":"BTC/USD","bids":[],"asks":[{"price":62791.3,"qty":0.46777958}],"checksum":1131500464,"timestamp":"2026-08-16T23:37:40.346222Z"}]}}
{"rx_ns": 42925746266000, "frame": {"channel":"book","type":"update","data":[{"symbol":"BTC/USD","bids":[],"asks":[{"price":62793.6,"qty":0.00800000}],"checksum":1950458168,"timestamp":"2026-08-16T23:37:40.371352Z"}]}}
{"rx_ns": 42925784312100, "frame": {"channel":"book","type":"update","data":[{"symbol":"BTC/USD","bids":[{"price":62785.0,"qty":0.00000000},{"price":62780.3,"qty":0.00023884},{"price":62788.1,"qty":0.05598472}],"asks":[],"checksum":1681865187,"timestamp":"2026-08-16T23:37:40.399697Z"}]}}
{"rx_ns": 42925784383500, "frame": {"channel":"book","type":"update","data":[{"symbol":"BTC/USD","bids":[],"asks":[{"price":62791.7,"qty":0.11000000},{"price":62792.2,"qty":0.05598472}],"checksum":2238506126,"timestamp":"2026-08-16T23:37:40.399746Z"}]}}
{"rx_ns": 42925812614300, "frame": {"channel":"book","type":"update","data":[{"symbol":"BTC/USD","bids":[],"asks":[{"price":62791.8,"qty":4.06028106}],"checksum":3749819463,"timestamp":"2026-08-16T23:37:40.438553Z"}]}}
{"rx_ns": 42925826018200, "frame": {"channel":"book","type":"update","data":[{"symbol":"BTC/USD","bids":[{"price":62791.2,"qty":0.01714221}],"asks":[],"checksum":3753061460,"timestamp":"2026-08-16T23:37:40.450122Z"}]}}
{"rx_ns": 42925873970100, "frame": {"channel":"book","type":"update","data":[{"symbol":"BTC/USD","bids":[],"asks":[{"price":62791.8,"qty":0.26939815},{"price":62791.3,"qty":4.25868206}],"checksum":4138607178,"timestamp":"2026-08-16T23:37:40.491040Z"}]}}
{"rx_ns": 42925884138000, "frame": {"channel":"book","type":"update","data":[{"symbol":"BTC/USD","bids":[{"price":62791.2,"qty":0.01754036}],"asks":[],"checksum":1696178996,"timestamp":"2026-08-16T23:37:40.505906Z"}]}}
{"rx_ns": 42925937218400, "frame": {"channel":"book","type":"update","data":[{"symbol":"BTC/USD","bids":[],"asks":[{"price":62791.3,"qty":4.27781554}],"checksum":3458916970,"timestamp":"2026-08-16T23:37:40.556316Z"}]}}
{"rx_ns": 42925943709400, "frame": {"channel":"book","type":"update","data":[{"symbol":"BTC/USD","bids":[{"price":62791.2,"qty":0.01793851}],"asks":[],"checksum":2324819886,"timestamp":"2026-08-16T23:37:40.563664Z"}]}}
{"rx_ns": 42925952842500, "frame": {"channel":"book","type":"update","data":[{"symbol":"BTC/USD","bids":[],"asks":[{"price":62791.8,"qty":0.26900000},{"price":62791.3,"qty":4.27821369}],"checksum":483201873,"timestamp":"2026-08-16T23:37:40.573800Z"}]}}
{"rx_ns": 42925973008200, "frame": {"channel":"book","type":"update","data":[{"symbol":"BTC/USD","bids":[{"price":62791.2,"qty":0.01754036}],"asks":[],"checksum":1484136085,"timestamp":"2026-08-16T23:37:40.587931Z"}]}}
{"rx_ns": 42926044794300, "frame": {"channel":"book","type":"update","data":[{"symbol":"BTC/USD","bids":[{"price":62791.2,"qty":0.01714221}],"asks":[],"checksum":3418464235,"timestamp":"2026-08-16T23:37:40.649890Z"}]}}
{"rx_ns": 42926392352100, "frame": {"channel":"heartbeat"}}
{"rx_ns": 42926406673100, "frame": {"channel":"book","type":"update","data":[{"symbol":"BTC/USD","bids":[],"asks":[{"price":62794.2,"qty":0.00000000},{"price":62796.1,"qty":0.40200000}],"checksum":3667834091,"timestamp":"2026-08-16T23:37:40.986079Z"}]}}
{"rx_ns": 42926408951500, "frame": {"channel":"book","type":"update","data":[{"symbol":"BTC/USD","bids":[{"price":62791.2,"qty":0.01724221}],"asks":[],"checksum":280341157,"timestamp":"2026-08-16T23:37:41.018446Z"}]}}
{"rx_ns": 42926466896100, "frame": {"channel":"book","type":"update","data":[{"symbol":"BTC/USD","bids":[{"price":62791.2,"qty":0.01565021},{"price":62791.2,"qty":0.01534221}],"asks":[],"checksum":21505966,"timestamp":"2026-08-16T23:37:41.083592Z"}]}}
{"rx_ns": 42926816929000, "frame": {"channel":"book","type":"update","data":[{"symbol":"BTC/USD","bids":[],"asks":[{"price":62791.3,"qty":4.27921369}],"checksum":647521170,"timestamp":"2026-08-16T23:37:41.438542Z"}]}}
{"rx_ns": 42926816989400, "frame": {"channel":"book","type":"update","data":[{"symbol":"BTC/USD","bids":[],"asks":[{"price":62791.3,"qty":4.20121369}],"checksum":261096058,"timestamp":"2026-08-16T23:37:41.440266Z"}]}}
{"rx_ns": 42926818478400, "frame": {"channel":"book","type":"update","data":[{"symbol":"BTC/USD","bids":[{"price":62783.2,"qty":0.00000000},{"price":62780.3,"qty":0.00023884},{"price":62781.8,"qty":0.00318497}],"asks":[],"checksum":1390939081,"timestamp":"2026-08-16T23:37:41.441568Z"}]}}
{"rx_ns": 42926912953400, "frame": {"channel":"book","type":"update","data":[{"symbol":"BTC/USD","bids":[{"price":62788.1,"qty":0.00000000},{"price":62780.3,"qty":0.00023884}],"asks":[],"checksum":497105662,"timestamp":"2026-08-16T23:37:41.534207Z"}]}}
{"rx_ns": 42926913142100, "frame": {"channel":"book","type":"update","data":[{"symbol":"BTC/USD","bids":[{"price":62785.0,"qty":0.05598472}],"asks":[],"checksum":1117164306,"timestamp":"2026-08-16T23:37:41.535486Z"}]}}
{"rx_ns": 42926913169200, "frame": {"channel":"book","type":"update","data":[{"symbol":"BTC/USD","bids":[],"asks":[{"price":62792.2,"qty":0.00000000},{"price":62796.6,"qty":0.18489680},{"price":62791.3,"qty":4.25719841}],"checksum":2174995255,"timestamp":"2026-08-16T23:37:41.535585Z"}]}}
{"rx_ns": 42926913211600, "frame": {"channel":"book","type":"update","data":[{"symbol":"BTC/USD","bids":[],"asks":[{"price":62791.3,"qty":4.33519841}],"checksum":3976925027,"timestamp":"2026-08-16T23:37:41.537605Z"}]}}
{"rx_ns": 42927357214300, "frame": {"channel":"heartbeat"}}
{"rx_ns": 42927562470100, "frame": {"channel":"book","type":"update","data":[{"symbol":"BTC/USD","bids":[{"price":62780.7,"qty":0.79642261}],"asks":[],"checksum":2379088104,"timestamp":"2026-08-16T23:37:42.185445Z"}]}}
{"rx_ns": 42927566821200, "frame": {"channel":"book","type":"update","data":[{"symbol":"BTC/USD","bids":[{"price":62785.0,"qty":0.00000000},{"price":62780.5,"qty":0.06101297},{"price":62788.1,"qty":0.05598472}],"asks":[],"checksum":2631890220,"timestamp":"2026-08-16T23:37:42.190838Z"}]}}
{"rx_ns": 42927566876400, "frame": {"channel":"book","type":"update","data":[{"symbol":"BTC/USD","bids":[],"asks":[{"price":62791.3,"qty":4.27921369},{"price":62792.2,"qty":0.05598472}],"checksum":361417521,"timestamp":"2026-08-16T23:37:42.190910Z"}]}}
{"rx_ns": 42927571198100, "frame": {"channel":"book","type":"update","data":[{"symbol":"BTC/USD","bids":[],"asks":[{"price":62791.3,"qty":4.20121369}],"checksum":3144853786,"timestamp":"2026-08-16T23:37:42.193696Z"}]}}
{"rx_ns": 42927575586800, "frame": {"channel":"book","type":"update","data":[{"symbol":"BTC/USD","bids":[],"asks":[{"price":62791.3,"qty":4.13176919}],"checksum":3836476284,"timestamp":"2026-08-16T23:37:42.196444Z"}]}}
{"rx_ns": 42928249449300, "frame": {"channel":"book","type":"update","data":[{"symbol":"BTC/USD","bids":[],"asks":[{"price":62791.3,"qty":4.06216919}],"checksum":1902995337,"timestamp":"2026-08-16T23:37:42.866484Z"}]}}
{"rx_ns": 42928266720000, "frame": {"channel":"book","type":"update","data":[{"symbol":"BTC/USD","bids":[{"price":62780.7,"qty":0.00000000},{"price":62780.5,"qty":0.06101297}],"asks":[],"checksum":4158919224,"timestamp":"2026-08-16T23:37:42.880556Z"}]}}
{"rx_ns": 42928270932400, "frame": {"channel":"book","type":"update","data":[{"symbol":"BTC/USD","bids":[{"price":62781.6,"qty":0.79641162}],"asks":[],"checksum":3037433,"timestamp":"2026-08-16T23:37:42.883016Z"}]}}
{"rx_ns": 42928359489300, "frame": {"channel":"heartbeat"}}
{"rx_ns": 42929357863100, "frame": {"channel":"heartbeat"}}
{"rx_ns": 42930360424700, "frame": {"channel":"heartbeat"}}
{"rx_ns": 42930524380000, "frame": {"channel":"book","type":"update","data":[{"symbol":"BTC/USD","bids":[],"asks":[{"price":62791.3,"qty":4.06201926}],"checksum":4116625613,"timestamp":"2026-08-16T23:37:45.146951Z"}]}}
{"rx_ns": 42930529322600, "frame": {"channel":"book","type":"update","data":[{"symbol":"BTC/USD","bids":[],"asks":[{"price":62791.3,"qty":4.14001926}],"checksum":2432504321,"timestamp":"2026-08-16T23:37:45.150387Z"}]}}
{"rx_ns": 42931358276500, "frame": {"channel":"heartbeat"}}
{"rx_ns": 42932138443200, "frame": {"channel":"book","type":"update","data":[{"symbol":"BTC/USD","bids":[{"price":62781.6,"qty":0.00000000},{"price":62780.5,"qty":0.06101297}],"asks":[],"checksum":2612230967,"timestamp":"2026-08-16T23:37:46.763838Z"}]}}
{"rx_ns": 42932143677500, "frame": {"channel":"book","type":"update","data":[{"symbol":"BTC/USD","bids":[{"price":62782.3,"qty":0.79640177}],"asks":[],"checksum":665890636,"timestamp":"2026-08-16T23:37:46.765548Z"}]}}
{"rx_ns": 42932358547700, "frame": {"channel":"heartbeat"}}
{"rx_ns": 42932443375700, "frame": {"channel":"book","type":"update","data":[{"symbol":"BTC/USD","bids":[],"asks":[{"price":62792.3,"qty":0.00000000},{"price":62796.7,"qty":0.50925300}],"checksum":3071886888,"timestamp":"2026-08-16T23:37:47.066992Z"}]}}
{"rx_ns": 42932443427500, "frame": {"channel":"book","type":"update","data":[{"symbol":"BTC/USD","bids":[],"asks":[{"price":62791.3,"qty":3.98073718}],"checksum":2794503,"timestamp":"2026-08-16T23:37:47.067184Z"}]}}
{"rx_ns": 42932445231500, "frame": {"channel":"book","type":"update","data":[{"symbol":"BTC/USD","bids":[],"asks":[{"price":62791.3,"qty":3.90273718}],"checksum":1286414513,"timestamp":"2026-08-16T23:37:47.070032Z"}]}}
{"rx_ns": 42932447905000, "frame": {"channel":"book","type":"update","data":[{"symbol":"BTC/USD","bids":[],"asks":[{"price":62792.2,"qty":0.00000000},{"price":62797.4,"qty":0.00005100},{"price":62792.3,"qty":0.05598472}],"checksum":365014320,"timestamp":"2026-08-16T23:37:47.070176Z"}]}}
{"rx_ns": 42932497675100, "frame": {"channel":"book","type":"update","data":[{"symbol":"BTC/USD","bids":[],"asks":[{"price":62791.3,"qty":4.06201926}],"checksum":2346082661,"timestamp":"2026-08-16T23:37:47.123472Z"}]}}
{"rx_ns": 42932501640700, "frame": {"channel":"book","type":"update","data":[{"symbol":"BTC/USD","bids":[],"asks":[{"price":62791.3,"qty":4.14001926}],"checksum":4000697257,"timestamp":"2026-08-16T23:37:47.127333Z"}]}}
{"rx_ns": 42932858797000, "frame": {"channel":"book","type":"update","data":[{"symbol":"BTC/USD","bids":[],"asks":[{"price":62796.7,"qty":0.00000000},{"price":62797.4,"qty":0.00005100}],"checksum":1818694345,"timestamp":"2026-08-16T23:37:47.477347Z"}]}}
{"rx_ns": 42932863147900, "frame": {"channel":"book","type":"update","data":[{"symbol":"BTC/USD","bids":[{"price":62782.3,"qty":0.00000000},{"price":62780.5,"qty":0.06101297}],"asks":[],"checksum":1222293778,"timestamp":"2026-08-16T23:37:47.481592Z"}]}}
{"rx_ns": 42932863199900, "frame": {"channel":"book","type":"update","data":[{"symbol":"BTC/USD","bids":[{"price":62783.1,"qty":0.79639225}],"asks":[],"checksum":3503003054,"timestamp":"2026-08-16T23:37:47.483113Z"}]}}
{"rx_ns": 42933036648100, "frame": {"channel":"book","type":"update","data":[{"symbol":"BTC/USD","bids":[],"asks":[{"price":62795.4,"qty":0.50933300}],"checksum":2417761487,"timestamp":"2026-08-16T23:37:47.660358Z"}]}}
{"rx_ns": 42933360013400, "frame": {"channel":"heartbeat"}}
{"rx_ns": 42933760232000, "frame": {"channel":"book","type":"update","data":[{"symbol":"BTC/USD","bids":[{"price":62783.1,"qty":0.00000000},{"price":62780.5,"qty":0.06101297}],"asks":[],"checksum":1079557880,"timestamp":"2026-08-16T23:37:48.385734Z"}]}}
{"rx_ns": 42933766936600, "frame": {"channel":"book","type":"update","data":[{"symbol":"BTC/USD","bids":[{"price":62781.6,"qty":0.79641163}],"asks":[],"checksum":3975812723,"timestamp":"2026-08-16T23:37:48.387190Z"}]}}
{"rx_ns": 42934369604800, "frame": {"channel":"heartbeat"}}
{"rx_ns": 42935284843900, "frame": {"channel":"book","type":"update","data":[{"symbol":"BTC/USD","bids":[],"asks":[{"price":62794.1,"qty":0.46828931}],"checksum":347180296,"timestamp":"2026-08-16T23:37:49.911196Z"}]}}
{"rx_ns": 42935360052400, "frame": {"channel":"heartbeat"}}
{"rx_ns": 42935448934300, "frame": {"channel":"book","type":"update","data":[{"symbol":"BTC/USD","bids":[{"price":62781.6,"qty":0.00000000},{"price":62780.5,"qty":0.06101297}],"asks":[],"checksum":1768795173,"timestamp":"2026-08-16T23:37:50.072055Z"}]}}
{"rx_ns": 42935449006400, "frame": {"channel":"book","type":"update","data":[{"symbol":"BTC/USD","bids":[{"price":62782.3,"qty":0.79640231}],"asks":[],"checksum":1708808869,"timestamp":"2026-08-16T23:37:50.074516Z"}]}}
{"rx_ns": 42935529179700, "frame": {"channel":"book","type":"update","data":[{"symbol":"BTC/USD","bids":[],"asks":[{"price":62793.6,"qty":0.00000000},{"price":62796.1,"qty":0.40200000},{"price":62791.3,"qty":4.14801926}],"checksum":177492051,"timestamp":"2026-08-16T23:37:50.110773Z"}]}}
{"rx_ns": 42936050333900, "frame": {"channel":"book","type":"update","data":[{"symbol":"BTC/USD","bids":[],"asks":[{"price":62794.0,"qty":0.64949617}],"checksum":449672467,"timestamp":"2026-08-16T23:37:50.672432Z"}]}}
{"rx_ns": 42936050382300, "frame": {"channel":"book","type":"update","data":[{"symbol":"BTC/USD","bids":[],"asks":[{"price":62791.5,"qty":0.60522203}],"checksum":2215648505,"timestamp":"2026-08-16T23:37:50.672706Z"}]}}
{"rx_ns": 42936361639700, "frame": {"channel":"heartbeat"}}
{"rx_ns": 42937359698600, "frame": {"channel":"heartbeat"}}
{"rx_ns": 42937779728400, "frame": {"channel":"book","type":"update","data":[{"symbol":"BTC/USD","bids":[],"asks":[{"price":62791.3,"qty":4.22763328}],"checksum":3875586520,"timestamp":"2026-08-16T23:37:52.405728Z"}]}}
{"rx_ns": 42938361689400, "frame": {"channel":"heartbeat"}}
{"rx_ns": 42939360723200, "frame": {"channel":"heartbeat"}}
{"rx_ns": 42940361317600, "frame": {"channel":"heartbeat"}}
{"rx_ns": 42941361029600, "frame": {"channel":"heartbeat"}}
{"rx_ns": 42942365665700, "frame": {"channel":"heartbeat"}}
{"rx_ns": 42942837304100, "frame": {"channel":"book","type":"update","data":[{"symbol":"BTC/USD","bids":[{"price":62782.3,"qty":0.00000000},{"price":62780.5,"qty":0.06101297}],"asks":[],"checksum":3137474675,"timestamp":"2026-08-16T23:37:57.462017Z"}]}}
{"rx_ns": 42942838898800, "frame": {"channel":"book","type":"update","data":[{"symbol":"BTC/USD","bids":[{"price":62781.2,"qty":0.79641642}],"asks":[],"checksum":2348352488,"timestamp":"2026-08-16T23:37:57.463743Z"}]}}
{"rx_ns": 42943187424800, "frame": {"channel":"book","type":"update","data":[{"symbol":"BTC/USD","bids":[{"price":62784.0,"qty":0.00000000},{"price":62780.5,"qty":0.06101297},{"price":62784.6,"qty":0.00009500}],"asks":[],"checksum":606211463,"timestamp":"2026-08-16T23:37:57.792094Z"}]}}
{"rx_ns": 42943187496800, "frame": {"channel":"book","type":"update","data":[{"symbol":"BTC/USD","bids":[{"price":62790.4,"qty":0.00000000},{"price":62780.5,"qty":0.06101297}],"asks":[],"checksum":2525654230,"timestamp":"2026-08-16T23:37:57.796850Z"}]}}
{"rx_ns": 42943187519900, "frame": {"channel":"book","type":"update","data":[{"symbol":"BTC/USD","bids":[{"price":62789.4,"qty":0.02131292}],"asks":[],"checksum":1647631820,"timestamp":"2026-08-16T23:37:57.798280Z"}]}}
{"rx_ns": 42943187537900, "frame": {"channel":"book","type":"update","data":[{"symbol":"BTC/USD","bids":[{"price":62788.1,"qty":0.00000000},{"price":62780.5,"qty":0.06101297},{"price":62789.4,"qty":0.07729764}],"asks":[],"checksum":2990073840,"timestamp":"2026-08-16T23:37:57.799340Z"}]}}
{"rx_ns": 42943344845300, "frame": {"channel":"book","type":"update","data":[{"symbol":"BTC/USD","bids":[{"price":62789.4,"qty":0.05598472}],"asks":[],"checksum":2035133278,"timestamp":"2026-08-16T23:37:57.965246Z"}]}}
{"rx_ns": 42943344917600, "frame": {"channel":"book","type":"update","data":[{"symbol":"BTC/USD","bids":[{"price":62790.3,"qty":0.02131292}],"asks":[],"checksum":1413053836,"timestamp":"2026-08-16T23:37:57.965451Z"}]}}
{"rx_ns": 42943344937200, "frame": {"channel":"book","type":"update","data":[{"symbol":"BTC/USD","bids":[{"price":62789.4,"qty":0.00000000},{"price":62780.5,"qty":0.06101297},{"price":62788.1,"qty":0.05598472}],"asks":[],"checksum":3943424355,"timestamp":"2026-08-16T23:37:57.966568Z"}]}}
{"rx_ns": 42943360913700, "frame": {"channel":"heartbeat"}}
{"rx_ns": 42943699772500, "frame": {"channel":"book","type":"update","data":[{"symbol":"BTC/USD","bids":[{"price":62781.2,"qty":0.00000000},{"price":62780.5,"qty":0.06101297}],"asks":[],"checksum":4184755948,"timestamp":"2026-08-16T23:37:58.324198Z"}]}}
{"rx_ns": 42943699859000, "frame": {"channel":"book","type":"update","data":[{"symbol":"BTC/USD","bids":[{"price":62782.2,"qty":0.79640364}],"asks":[],"checksum":1603464115,"timestamp":"2026-08-16T23:37:58.325751Z"}]}}
{"rx_ns": 42944353609300, "frame": {"channel":"book","type":"update","data":[{"symbol":"BTC/USD","bids":[{"price":62791.2,"qty":0.16822674}],"asks":[],"checksum":685865189,"timestamp":"2026-08-16T23:37:58.979902Z"}]}}
{"rx_ns": 42944355284100, "frame": {"channel":"book","type":"update","data":[{"symbol":"BTC/USD","bids":[],"asks":[{"price":62791.3,"qty":4.21578028}],"checksum":329939991,"timestamp":"2026-08-16T23:37:58.980162Z"}]}}
{"rx_ns": 42944361504300, "frame": {"channel":"book","type":"update","data":[{"symbol":"BTC/USD","bids":[],"asks":[{"price":62791.3,"qty":4.13778028}],"checksum":3227652704,"timestamp":"2026-08-16T23:37:58.982804Z"}]}}
{"rx_ns": 42944361573500, "frame": {"channel":"book","type":"update","data":[{"symbol":"BTC/USD","bids":[],"asks":[{"price":62791.3,"qty":4.14963328}],"checksum":1345564600,"timestamp":"2026-08-16T23:37:58.986083Z"}]}}
{"rx_ns": 42944361593500, "frame": {"channel":"book","type":"update","data":[{"symbol":"BTC/USD","bids":[{"price":62791.2,"qty":0.01534221}],"asks":[],"checksum":2324436219,"timestamp":"2026-08-16T23:37:58.986350Z"}]}}
{"rx_ns": 42944363187800, "frame": {"channel":"heartbeat"}}
{"rx_ns": 42944516040100, "frame": {"channel":"book","type":"update","data":[{"symbol":"BTC/USD","bids":[],"asks":[{"price":62791.3,"qty":3.99035120}],"checksum":2025312224,"timestamp":"2026-08-16T23:37:59.137994Z"}]}}
{"rx_ns": 42944516104700, "frame": {"channel":"book","type":"update","data":[{"symbol":"BTC/USD","bids":[],"asks":[{"price":62794.1,"qty":0.00000000},{"price":62795.4,"qty":0.50933300}],"checksum":1916296984,"timestamp":"2026-08-16T23:37:59.138271Z"}]}}
{"rx_ns": 42944518426600, "frame": {"channel":"book","type":"update","data":[{"symbol":"BTC/USD","bids":[],"asks":[{"price":62791.3,"qty":4.06835120}],"checksum":1984973282,"timestamp":"2026-08-16T23:37:59.140834Z"}]}}
{"rx_ns": 42944534402000, "frame": {"channel":"book","type":"update","data":[{"symbol":"BTC/USD","bids":[],"asks":[{"price":62795.4,"qty":0.00000000},{"price":62796.1,"qty":0.40200000}],"checksum":818920400,"timestamp":"2026-08-16T23:37:59.159814Z"}]}}
{"rx_ns": 42944535656300, "frame": {"channel":"book","type":"update","data":[{"symbol":"BTC/USD","bids":[],"asks":[{"price":62794.0,"qty":0.00000000},{"price":62797.4,"qty":0.00005100}],"checksum":893320615,"timestamp":"2026-08-16T23:37:59.161502Z"}]}}
{"rx_ns": 42944543220600, "frame": {"channel":"book","type":"update","data":[{"symbol":"BTC/USD","bids":[],"asks":[{"price":62794.7,"qty":0.35767591}],"checksum":898131639,"timestamp":"2026-08-16T23:37:59.163348Z"}]}}
{"rx_ns": 42944543277700, "frame": {"channel":"book","type":"update","data":[{"symbol":"BTC/USD","bids":[{"price":62791.2,"qty":0.16822674}],"asks":[],"checksum":803645041,"timestamp":"2026-08-16T23:37:59.163385Z"}]}}
{"rx_ns": 42944543288600, "frame": {"channel":"book","type":"update","data":[{"symbol":"BTC/USD","bids":[],"asks":[{"price":62791.3,"qty":4.05649820}],"checksum":1371655920,"timestamp":"2026-08-16T23:37:59.163674Z"}]}}
{"rx_ns": 42944543314800, "frame": {"channel":"book","type":"update","data":[{"symbol":"BTC/USD","bids":[{"price":62791.2,"qty":0.01534221}],"asks":[],"checksum":2744933050,"timestamp":"2026-08-16T23:37:59.166784Z"}]}}
{"rx_ns": 42944543324500, "frame": {"channel":"book","type":"update","data":[{"symbol":"BTC/USD","bids":[],"asks":[{"price":62791.3,"qty":4.06835120}],"checksum":898131639,"timestamp":"2026-08-16T23:37:59.167287Z"}]}}
{"rx_ns": 42944588798900, "frame": {"channel":"book","type":"update","data":[{"symbol":"BTC/USD","bids":[],"asks":[{"price":62791.3,"qty":4.22763328}],"checksum":382030878,"timestamp":"2026-08-16T23:37:59.215111Z"}]}}
{"rx_ns": 42944595071300, "frame": {"channel":"book","type":"update","data":[{"symbol":"BTC/USD","bids":[],"asks":[{"price":62796.0,"qty":0.18489680}],"checksum":3171989201,"timestamp":"2026-08-16T23:37:59.216226Z"}]}}
{"rx_ns": 42945362924300, "frame": {"channel":"heartbeat"}}
{"rx_ns": 42945749070700, "frame": {"channel":"book","type":"update","data":[{"symbol":"BTC/USD","bids":[],"asks":[{"price":62794.7,"qty":0.86700591}],"checksum":428792094,"timestamp":"2026-08-16T23:38:00.371023Z"}]}}
{"rx_ns": 42945750974900, "frame": {"channel":"book","type":"update","data":[{"symbol":"BTC/USD","bids":[],"asks":[{"price":62794.7,"qty":0.50933000}],"checksum":1292753551,"timestamp":"2026-08-16T23:38:00.372165Z"}]}}
{"rx_ns": 42945751020900, "frame": {"channel":"book","type":"update","data":[{"symbol":"BTC/USD","bids":[],"asks":[{"price":62796.0,"qty":0.00000000},{"price":62796.1,"qty":0.40200000}],"checksum":3872929856,"timestamp":"2026-08-16T23:38:00.372309Z"}]}}
{"rx_ns": 42945751038600, "frame": {"channel":"book","type":"update","data":[{"symbol":"BTC/USD","bids":[],"asks":[{"price":62794.6,"qty":0.56490261}],"checksum":3974163983,"timestamp":"2026-08-16T23:38:00.373369Z"}]}}
{"rx_ns": 42946249043000, "frame": {"channel":"book","type":"update","data":[{"symbol":"BTC/USD","bids":[],"asks":[{"price":62792.3,"qty":0.00000000},{"price":62796.1,"qty":0.40200000}],"checksum":475638106,"timestamp":"2026-08-16T23:38:00.864877Z"}]}}
{"rx_ns": 42946249134700, "frame": {"channel":"book","type":"update","data":[{"symbol":"BTC/USD","bids":[{"price":62788.1,"qty":0.00000000},{"price":62780.5,"qty":0.06101297},{"price":62791.2,"qty":0.07132693}],"asks":[],"checksum":4218590375,"timestamp":"2026-08-16T23:38:00.866106Z"}]}}
{"rx_ns": 42946249156000, "frame": {"channel":"book","type":"update","data":[{"symbol":"BTC/USD","bids":[],"asks":[{"price":62794.5,"qty":0.05598472}],"checksum":1184025778,"timestamp":"2026-08-16T23:38:00.866246Z"}]}}
{"rx_ns": 42946249169800, "frame": {"channel":"book","type":"update","data":[{"symbol":"BTC/USD","bids":[],"asks":[{"price":62794.4,"qty":0.18489680}],"checksum":368929866,"timestamp":"2026-08-16T23:38:00.867378Z"}]}}
{"rx_ns": 42946252098200, "frame": {"channel":"book","type":"update","data":[{"symbol":"BTC/USD","bids":[],"asks":[{"price":62791.3,"qty":4.14963328}],"checksum":3236139778,"timestamp":"2026-08-16T23:38:00.877944Z"}]}}
{"rx_ns": 42946364409800, "frame": {"channel":"heartbeat"}}
{"rx_ns": 42946609738700, "frame": {"channel":"book","type":"update","data":[{"symbol":"BTC/USD","bids":[],"asks":[{"price":62794.5,"qty":0.00000000},{"price":62794.8,"qty":0.79624427},{"price":62794.3,"qty":0.05598472}],"checksum":4184523727,"timestamp":"2026-08-16T23:38:01.217742Z"}]}}
{"rx_ns": 42946615986200, "frame": {"channel":"book","type":"update","data":[{"symbol":"BTC/USD","bids":[],"asks":[{"price":62794.4,"qty":0.00000000},{"price":62794.8,"qty":0.79624427}],"checksum":1888054188,"timestamp":"2026-08-16T23:38:01.219094Z"}]}}
{"rx_ns": 42946616071100, "frame": {"channel":"book","type":"update","data":[{"symbol":"BTC/USD","bids":[],"asks":[{"price":62794.3,"qty":0.00000000},{"price":62796.1,"qty":0.40200000},{"price":62794.5,"qty":0.05598472}],"checksum":2475439098,"timestamp":"2026-08-16T23:38:01.220351Z"}]}}
{"rx_ns": 42946640226900, "frame": {"channel":"book","type":"update","data":[{"symbol":"BTC/USD","bids":[],"asks":[{"price":62794.4,"qty":0.18489680}],"checksum":3236139778,"timestamp":"2026-08-16T23:38:01.266302Z"}]}}
{"rx_ns": 42946667727000, "frame": {"channel":"book","type":"update","data":[{"symbol":"BTC/USD","bids":[],"asks":[{"price":62791.5,"qty":0.00000000},{"price":62794.8,"qty":0.79624427}],"checksum":2870577217,"timestamp":"2026-08-16T23:38:01.289997Z"}]}}
{"rx_ns": 42946668084700, "frame": {"channel":"book","type":"update","data":[{"symbol":"BTC/USD","bids":[],"asks":[{"price":62794.6,"qty":0.00000000},{"price":62796.1,"qty":0.40200000}],"checksum":2703318542,"timestamp":"2026-08-16T23:38:01.291350Z"}]}}
{"rx_ns": 42946668115300, "frame": {"channel":"book","type":"update","data":[{"symbol":"BTC/USD","bids":[],"asks":[{"price":62791.3,"qty":3.99035120}],"checksum":1394246933,"timestamp":"2026-08-16T23:38:01.291370Z"}]}}
{"rx_ns": 42946668125400, "frame": {"channel":"book","type":"update","data":[{"symbol":"BTC/USD","bids":[],"asks":[{"price":62795.6,"qty":0.46828931}],"checksum":871322194,"timestamp":"2026-08-16T23:38:01.291398Z"}]}}
{"rx_ns": 42946668133900, "frame": {"channel":"book","type":"update","data":[{"symbol":"BTC/USD","bids":[{"price":62782.2,"qty":0.00000000},{"price":62780.3,"qty":0.00023884}],"asks":[],"checksum":689505975,"timestamp":"2026-08-16T23:38:01.291524Z"}]}}
{"rx_ns": 42946668209300, "frame": {"channel":"book","type":"update","data":[{"symbol":"BTC/USD","bids":[],"asks":[{"price":62791.7,"qty":0.00000000},{"price":62796.1,"qty":0.40200000}],"checksum":1670636267,"timestamp":"2026-08-16T23:38:01.292162Z"}]}}
{"rx_ns": 42946680035200, "frame": {"channel":"book","type":"update","data":[{"symbol":"BTC/USD","bids":[{"price":62782.5,"qty":0.15928208}],"asks":[],"checksum":4220277771,"timestamp":"2026-08-16T23:38:01.292628Z"}]}}
{"rx_ns": 42946680067200, "frame": {"channel":"book","type":"update","data":[{"symbol":"BTC/USD","bids":[{"price":62791.2,"qty":0.09263985}],"asks":[],"checksum":2961876508,"timestamp":"2026-08-16T23:38:01.292747Z"}]}}
{"rx_ns": 42946680075900, "frame": {"channel":"book","type":"update","data":[{"symbol":"BTC/USD","bids":[],"asks":[{"price":62792.4,"qty":0.00000000},{"price":62797.4,"qty":0.00005100}],"checksum":1091779999,"timestamp":"2026-08-16T23:38:01.292799Z"}]}}
{"rx_ns": 42946680084800, "frame": {"channel":"book","type":"update","data":[{"symbol":"BTC/USD","bids":[],"asks":[{"price":62794.4,"qty":0.00000000},{"price":62799.4,"qty":0.06000000}],"checksum":2980483900,"timestamp":"2026-08-16T23:38:01.293486Z"}]}}
{"rx_ns": 42946680092300, "frame": {"channel":"book","type":"update","data":[{"symbol":"BTC/USD","bids":[],"asks":[{"price":62794.8,"qty":0.00000000},{"price":62800.5,"qty":0.00005100}],"checksum":2520603607,"timestamp":"2026-08-16T23:38:01.293560Z"}]}}
{"rx_ns": 42946680099400, "frame": {"channel":"book","type":"update","data":[{"symbol":"BTC/USD","bids":[],"asks":[{"price":62791.6,"qty":0.00000000},{"price":62800.6,"qty":0.18489680}],"checksum":2661133330,"timestamp":"2026-08-16T23:38:01.293959Z"}]}}
{"rx_ns": 42946695511500, "frame": {"channel":"book","type":"update","data":[{"symbol":"BTC/USD","bids":[],"asks":[{"price":62797.6,"qty":0.79620930}],"checksum":708478009,"timestamp":"2026-08-16T23:38:01.297767Z"}]}}
{"rx_ns": 42946695573600, "frame": {"channel":"book","type":"update","data":[{"symbol":"BTC/USD","bids":[],"asks":[{"price":62799.6,"qty":0.79618411}],"checksum":2132157746,"timestamp":"2026-08-16T23:38:01.297960Z"}]}}
{"rx_ns": 42946695587800, "frame": {"channel":"book","type":"update","data":[{"symbol":"BTC/USD","bids":[{"price":62786.1,"qty":0.79635444}],"asks":[],"checksum":4111564792,"timestamp":"2026-08-16T23:38:01.298586Z"}]}}
{"rx_ns": 42946695598900, "frame": {"channel":"book","type":"update","data":[{"symbol":"BTC/USD","bids":[{"price":62791.2,"qty":0.16223985}],"asks":[],"checksum":49408415,"timestamp":"2026-08-16T23:38:01.298704Z"}]}}
{"rx_ns": 42946695609700, "frame": {"channel":"book","type":"update","data":[{"symbol":"BTC/USD","bids":[{"price":62786.1,"qty":0.00000000},{"price":62780.5,"qty":0.06101297}],"asks":[],"checksum":4258733990,"timestamp":"2026-08-16T23:38:01.299147Z"}]}}
{"rx_ns": 42946695622000, "frame": {"channel":"book","type":"update","data":[{"symbol":"BTC/USD","bids":[],"asks":[{"price":62797.6,"qty":0.00000000},{"price":62800.5,"qty":0.00005100}],"checksum":270957255,"timestamp":"2026-08-16T23:38:01.299872Z"}]}}
{"rx_ns": 42946695634800, "frame": {"channel":"book","type":"update","data":[{"symbol":"BTC/USD","bids":[{"price":62782.5,"qty":0.00000000},{"price":62780.4,"qty":0.79642633}],"asks":[],"checksum":2368727334,"timestamp":"2026-08-16T23:38:01.300272Z"}]}}
{"rx_ns": 42946695646500, "frame": {"channel":"book","type":"update","data":[{"symbol":"BTC/USD","bids":[],"asks":[{"price":62799.6,"qty":0.00000000},{"price":62800.6,"qty":0.18489680}],"checksum":1532045062,"timestamp":"2026-08-16T23:38:01.300360Z"}]}}
{"rx_ns": 42946695657800, "frame": {"channel":"book","type":"update","data":[{"symbol":"BTC/USD","bids":[],"asks":[{"price":62794.7,"qty":0.00000000},{"price":62800.7,"qty":0.19620257}],"checksum":3147494362,"timestamp":"2026-08-16T23:38:01.300382Z"}]}}
{"rx_ns": 42946695669900, "frame": {"channel":"book","type":"update","data":[{"symbol":"BTC/USD","bids":[{"price":62780.4,"qty":0.00000000},{"price":62780.3,"qty":0.00023884}],"asks":[],"checksum":2093402930,"timestamp":"2026-08-16T23:38:01.301848Z"}]}}
{"rx_ns": 42946695681700, "frame": {"channel":"book","type":"update","data":[{"symbol":"BTC/USD","bids":[{"price":62790.3,"qty":0.00000000},{"price":62779.1,"qty":0.08000431}],"asks":[],"checksum":3037536373,"timestamp":"2026-08-16T23:38:01.302062Z"}]}}
{"rx_ns": 42946695693100, "frame": {"channel":"book","type":"update","data":[{"symbol":"BTC/USD","bids":[],"asks":[{"price":62791.3,"qty":0.19944872}],"checksum":4056512674,"timestamp":"2026-08-16T23:38:01.303977Z"}]}}
{"rx_ns": 42946723500300, "frame": {"channel":"book","type":"update","data":[{"symbol":"BTC/USD","bids":[{"price":62782.3,"qty":0.46828931}],"asks":[],"checksum":649679329,"timestamp":"2026-08-16T23:38:01.306370Z"}]}}
{"rx_ns": 42946723545300, "frame": {"channel":"book","type":"update","data":[{"symbol":"BTC/USD","bids":[{"price":62782.6,"qty":0.04851164}],"asks":[],"checksum":1286896507,"timestamp":"2026-08-16T23:38:01.307070Z"}]}}
{"rx_ns": 42946723554600, "frame": {"channel":"book","type":"update","data":[{"symbol":"BTC/USD","bids":[{"price":62782.3,"qty":0.00000000},{"price":62780.3,"qty":0.00023884}],"asks":[],"checksum":1053413852,"timestamp":"2026-08-16T23:38:01.308098Z"}]}}
{"rx_ns": 42946723563200, "frame": {"channel":"book","type":"update","data":[{"symbol":"BTC/USD","bids":[],"asks":[{"price":62791.3,"qty":0.18031524}],"checksum":1836424615,"timestamp":"2026-08-16T23:38:01.308425Z"}]}}
{"rx_ns": 42946723570800, "frame": {"channel":"book","type":"update","data":[{"symbol":"BTC/USD","bids":[],"asks":[{"price":62794.8,"qty":0.15928208}],"checksum":229245831,"timestamp":"2026-08-16T23:38:01.310298Z"}]}}
{"rx_ns": 42946723577400, "frame": {"channel":"book","type":"update","data":[{"symbol":"BTC/USD","bids":[],"asks":[{"price":62799.3,"qty":0.01791000}],"checksum":3057330669,"timestamp":"2026-08-16T23:38:01.310738Z"}]}}
{"rx_ns": 42946723584200, "frame": {"channel":"book","type":"update","data":[{"symbol":"BTC/USD","bids":[],"asks":[{"price":62795.6,"qty":0.00000000},{"price":62800.6,"qty":0.18489680}],"checksum":3759523045,"timestamp":"2026-08-16T23:38:01.311585Z"}]}}
{"rx_ns": 42946723591200, "frame": {"channel":"book","type":"update","data":[{"symbol":"BTC/USD","bids":[{"price":62780.5,"qty":0.07234750}],"asks":[],"checksum":739450336,"timestamp":"2026-08-16T23:38:01.312302Z"}]}}
{"rx_ns": 42946723597600, "frame": {"channel":"book","type":"update","data":[{"symbol":"BTC/USD","bids":[{"price":62782.6,"qty":0.00000000},{"price":62779.1,"qty":0.06960000}],"asks":[],"checksum":3662340389,"timestamp":"2026-08-16T23:38:01.315139Z"}]}}
{"rx_ns": 42946730864400, "frame": {"channel":"book","type":"update","data":[{"symbol":"BTC/USD","bids":[{"price":62780.6,"qty":0.06848480}],"asks":[],"checksum":1474485455,"timestamp":"2026-08-16T23:38:01.316742Z"}]}}
{"rx_ns": 42946730911600, "frame": {"channel":"book","type":"update","data":[{"symbol":"BTC/USD","bids":[],"asks":[{"price":62794.8,"qty":0.00000000},{"price":62800.7,"qty":0.19620257}],"checksum":3365392916,"timestamp":"2026-08-16T23:38:01.317192Z"}]}}
{"rx_ns": 42946730921500, "frame": {"channel":"book","type":"update","data":[{"symbol":"BTC/USD","bids":[],"asks":[{"price":62799.9,"qty":0.79618083}],"checksum":1560795841,"timestamp":"2026-08-16T23:38:01.317721Z"}]}}
{"rx_ns": 42946730928200, "frame": {"channel":"book","type":"update","data":[{"symbol":"BTC/USD","bids":[],"asks":[{"price":62799.9,"qty":0.00000000},{"price":62800.7,"qty":0.19620257}],"checksum":3365392916,"timestamp":"2026-08-16T23:38:01.319003Z"}]}}
{"rx_ns": 42946730936400, "frame": {"channel":"book","type":"update","data":[{"symbol":"BTC/USD","bids":[],"asks":[{"price":62800.5,"qty":0.12400653}],"checksum":3787501510,"timestamp":"2026-08-16T23:38:01.320079Z"}]}}
{"rx_ns": 42946730942600, "frame": {"channel":"book","type":"update","data":[{"symbol":"BTC/USD","bids":[],"asks":[{"price":62800.6,"qty":0.00000000},{"price":62801.3,"qty":0.00318497}],"checksum":2574780886,"timestamp":"2026-08-16T23:38:01.320100Z"}]}}
{"rx_ns": 42946731007000, "frame": {"channel":"book","type":"update","data":[{"symbol":"BTC/USD","bids":[],"asks":[{"price":62800.7,"qty":0.00000000},{"price":62801.9,"qty":0.03097706}],"checksum":1273973075,"timestamp":"2026-08-16T23:38:01.323612Z"}]}}
{"rx_ns": 42946731015300, "frame": {"channel":"book","type":"update","data":[{"symbol":"BTC/USD","bids":[],"asks":[{"price":62799.3,"qty":0.00000000},{"price":62803.2,"qty":0.18489680}],"checksum":1005810463,"timestamp":"2026-08-16T23:38:01.325271Z"}]}}
{"rx_ns": 42946731022400, "frame": {"channel":"book","type":"update","data":[{"symbol":"BTC/USD","bids":[],"asks":[{"price":62800.5,"qty":0.00005100}],"checksum":485387837,"timestamp":"2026-08-16T23:38:01.325338Z"}]}}
{"rx_ns": 42946798935200, "frame": {"channel":"book","type":"update","data":[{"symbol":"BTC/USD","bids":[{"price":62784.0,"qty":0.00318553}],"asks":[],"checksum":557502852,"timestamp":"2026-08-16T23:38:01.327190Z"}]}}
{"rx_ns": 42946798985300, "frame": {"channel":"book","type":"update","data":[{"symbol":"BTC/USD","bids":[],"asks":[{"price":62799.8,"qty":0.36163073}],"checksum":300246037,"timestamp":"2026-08-16T23:38:01.327208Z"}]}}
{"rx_ns": 42946798998900, "frame": {"channel":"book","type":"update","data":[{"symbol":"BTC/USD","bids":[],"asks":[{"price":62799.8,"qty":0.00000000},{"price":62803.2,"qty":0.18489680}],"checksum":557502852,"timestamp":"2026-08-16T23:38:01.327228Z"}]}}
{"rx_ns": 42946799012400, "frame": {"channel":"book","type":"update","data":[{"symbol":"BTC/USD","bids":[],"asks":[{"price":62794.5,"qty":0.00000000},{"price":62803.3,"qty":0.01100000}],"checksum":3533723450,"timestamp":"2026-08-16T23:38:01.327642Z"}]}}
{"rx_ns": 42946799028000, "frame": {"channel":"book","type":"update","data":[{"symbol":"BTC/USD","bids":[{"price":62791.2,"qty":0.09263985}],"asks":[],"checksum":4224961254,"timestamp":"2026-08-16T23:38:01.327917Z"}]}}
{"rx_ns": 42946799041200, "frame": {"channel":"book","type":"update","data":[{"symbol":"BTC/USD","bids":[],"asks":[{"price":62791.3,"qty":0.25991524}],"checksum":1140291382,"timestamp":"2026-08-16T23:38:01.328326Z"}]}}
{"rx_ns": 42946799054700, "frame": {"channel":"book","type":"update","data":[{"symbol":"BTC/USD","bids":[],"asks":[{"price":62791.8,"qty":0.00000000},{"price":62803.4,"qty":0.06960000}],"checksum":2004382442,"timestamp":"2026-08-16T23:38:01.332349Z"}]}}
{"rx_ns": 42946799069800, "frame": {"channel":"book","type":"update","data":[{"symbol":"BTC/USD","bids":[],"asks":[{"price":62791.3,"qty":0.33791524}],"checksum":3085037868,"timestamp":"2026-08-16T23:38:01.332493Z"}]}}
{"rx_ns": 42946799082100, "frame": {"channel":"book","type":"update","data":[{"symbol":"BTC/USD","bids":[],"asks":[{"price":62803.3,"qty":3.80107593}],"checksum":689102351,"timestamp":"2026-08-16T23:38:01.333382Z"}]}}
{"rx_ns": 42946799095600, "frame": {"channel":"book","type":"update","data":[{"symbol":"BTC/USD","bids":[],"asks":[{"price":62791.3,"qty":0.25846517}],"checksum":2683164719,"timestamp":"2026-08-16T23:38:01.334122Z"}]}}
{"rx_ns": 42946799133500, "frame": {"channel":"book","type":"update","data":[{"symbol":"BTC/USD","bids":[],"asks":[{"price":62803.2,"qty":1.63214579}],"checksum":3125685034,"timestamp":"2026-08-16T23:38:01.335930Z"}]}}
{"rx_ns": 42946799149500, "frame": {"channel":"book","type":"update","data":[{"symbol":"BTC/USD","bids":[{"price":62791.2,"qty":0.25192193}],"asks":[],"checksum":2664822469,"timestamp":"2026-08-16T23:38:01.337133Z"}]}}
{"rx_ns": 42946799161500, "frame": {"channel":"book","type":"update","data":[{"symbol":"BTC/USD","bids":[{"price":62791.2,"qty":0.33152193}],"asks":[],"checksum":2305038319,"timestamp":"2026-08-16T23:38:01.341635Z"}]}}
{"rx_ns": 42946799172600, "frame": {"channel":"book","type":"update","data":[{"symbol":"BTC/USD","bids":[{"price":62791.2,"qty":0.25192193}],"asks":[],"checksum":2664822469,"timestamp":"2026-08-16T23:38:01.343577Z"}]}}
{"rx_ns": 42946799184500, "frame": {"channel":"book","type":"update","data":[{"symbol":"BTC/USD","bids":[],"asks":[{"price":62791.3,"qty":0.17886517}],"checksum":4148880007,"timestamp":"2026-08-16T23:38:01.344185Z"}]}}
{"rx_ns": 42946799197200, "frame": {"channel":"book","type":"update","data":[{"symbol":"BTC/USD","bids":[],"asks":[{"price":62791.3,"qty":0.39786514}],"checksum":1224939851,"timestamp":"2026-08-16T23:38:01.344930Z"}]}}
{"rx_ns": 42946799226300, "frame": {"channel":"book","type":"update","data":[{"symbol":"BTC/USD","bids":[],"asks":[{"price":62791.3,"qty":0.47746514}],"checksum":2103821309,"timestamp":"2026-08-16T23:38:01.346358Z"}]}}
{"rx_ns": 42946799242400, "frame": {"channel":"book","type":"update","data":[{"symbol":"BTC/USD","bids":[{"price":62791.2,"qty":0.33152193}],"asks":[],"checksum":1792287447,"timestamp":"2026-08-16T23:38:01.346785Z"}]}}
{"rx_ns": 42946799312300, "frame": {"channel":"book","type":"update","data":[{"symbol":"BTC/USD","bids":[],"asks":[{"price":62791.3,"qty":0.39786514}],"checksum":1588787297,"timestamp":"2026-08-16T23:38:01.346966Z"}]}}
{"rx_ns": 42946799325700, "frame": {"channel":"book","type":"update","data":[{"symbol":"BTC/USD","bids":[{"price":62791.2,"qty":0.25192193}],"asks":[],"checksum":1224939851,"timestamp":"2026-08-16T23:38:01.347147Z"}]}}
{"rx_ns": 42946799361200, "frame": {"channel":"book","type":"update","data":[{"symbol":"BTC/USD","bids":[],"asks":[{"price":62791.3,"qty":0.47746514}],"checksum":2103821309,"timestamp":"2026-08-16T23:38:01.347180Z"}]}}
{"rx_ns": 42946799405400, "frame": {"channel":"book","type":"update","data":[{"symbol":"BTC/USD","bids":[],"asks":[{"price":62803.1,"qty":0.00222509}],"checksum":3870000262,"timestamp":"2026-08-16T23:38:01.354200Z"}]}}
{"rx_ns": 42946799421800, "frame": {"channel":"book","type":"update","data":[{"symbol":"BTC/USD","bids":[],"asks":[{"price":62803.1,"qty":0.00000000},{"price":62803.4,"qty":0.06960000}],"checksum":2103821309,"timestamp":"2026-08-16T23:38:01.359716Z"}]}}
{"rx_ns": 42946799436000, "frame": {"channel":"book","type":"update","data":[{"symbol":"BTC/USD","bids":[],"asks":[{"price":62794.2,"qty":0.00005100}],"checksum":1846346802,"timestamp":"2026-08-16T23:38:01.362358Z"}]}}
{"rx_ns": 42946799463100, "frame": {"channel":"book","type":"update","data":[{"symbol":"BTC/USD","bids":[],"asks":[{"price":62799.4,"qty":0.00000000},{"price":62803.4,"qty":0.06960000}],"checksum":1436342704,"timestamp":"2026-08-16T23:38:01.362888Z"}]}}
{"rx_ns": 42946799479700, "frame": {"channel":"book","type":"update","data":[{"symbol":"BTC/USD","bids":[{"price":62780.6,"qty":0.30523348}],"asks":[],"checksum":1180419952,"timestamp":"2026-08-16T23:38:01.364522Z"}]}}
{"rx_ns": 42946799493700, "frame": {"channel":"book","type":"update","data":[{"symbol":"BTC/USD","bids":[],"asks":[{"price":62803.1,"qty":0.00222509}],"checksum":2712371193,"timestamp":"2026-08-16T23:38:01.365427Z"}]}}
{"rx_ns": 42946799506700, "frame": {"channel":"book","type":"update","data":[{"symbol":"BTC/USD","bids":[{"price":62791.2,"qty":0.33152193}],"asks":[],"checksum":2047281102,"timestamp":"2026-08-16T23:38:01.365847Z"}]}}
{"rx_ns": 42946799519500, "frame": {"channel":"book","type":"update","data":[{"symbol":"BTC/USD","bids":[{"price":62789.7,"qty":0.79630822}],"asks":[],"checksum":4019963876,"timestamp":"2026-08-16T23:38:01.366121Z"}]}}
{"rx_ns": 42946799529300, "frame": {"channel":"book","type":"update","data":[{"symbol":"BTC/USD","bids":[{"price":62791.2,"qty":0.25192193}],"asks":[],"checksum":1476251283,"timestamp":"2026-08-16T23:38:01.367614Z"}]}}
{"rx_ns": 42946799538200, "frame": {"channel":"book","type":"update","data":[{"symbol":"BTC/USD","bids":[{"price":62791.2,"qty":0.33152193}],"asks":[],"checksum":4019963876,"timestamp":"2026-08-16T23:38:01.368102Z"}]}}
{"rx_ns": 42946799547000, "frame": {"channel":"book","type":"update","data":[{"symbol":"BTC/USD","bids":[],"asks":[{"price":62796.1,"qty":0.00000000},{"price":62803.4,"qty":0.06960000}],"checksum":202930260,"timestamp":"2026-08-16T23:38:01.370298Z"}]}}
{"rx_ns": 42946799594600, "frame": {"channel":"book","type":"update","data":[{"symbol":"BTC/USD","bids":[],"asks":[{"price":62803.2,"qty":1.44724899}],"checksum":748753257,"timestamp":"2026-08-16T23:38:01.370680Z"}]}}
{"rx_ns": 42946799627500, "frame": {"channel":"book","type":"update","data":[{"symbol":"BTC/USD","bids":[{"price":62780.7,"qty":0.03185211}],"asks":[],"checksum":1456095657,"timestamp":"2026-08-16T23:38:01.372911Z"}]}}
{"rx_ns": 42946799643100, "frame": {"channel":"book","type":"update","data":[{"symbol":"BTC/USD","bids":[],"asks":[{"price":62791.3,"qty":0.39786514}],"checksum":2013377784,"timestamp":"2026-08-16T23:38:01.377286Z"}]}}
{"rx_ns": 42946799657000, "frame": {"channel":"book","type":"update","data":[{"symbol":"BTC/USD","bids":[],"asks":[{"price":62803.1,"qty":0.00000000},{"price":62803.7,"qty":0.00005100}],"checksum":2942002923,"timestamp":"2026-08-16T23:38:01.377312Z"}]}}
{"rx_ns": 42946799671800, "frame": {"channel":"book","type":"update","data":[{"symbol":"BTC/USD","bids":[],"asks":[{"price":62792.6,"qty":0.32999995}],"checksum":2745058805,"timestamp":"2026-08-16T23:38:01.377909Z"}]}}
{"rx_ns": 42946799685200, "frame": {"channel":"book","type":"update","data":[{"symbol":"BTC/USD","bids":[],"asks":[{"price":62803.2,"qty":1.50323371}],"checksum":620378616,"timestamp":"2026-08-16T23:38:01.379888Z"}]}}
{"rx_ns": 42946799718300, "frame": {"channel":"book","type":"update","data":[{"symbol":"BTC/USD","bids":[{"price":62781.7,"qty":0.01050463}],"asks":[],"checksum":2311275496,"timestamp":"2026-08-16T23:38:01.382769Z"}]}}
{"rx_ns": 42946799730200, "frame": {"channel":"book","type":"update","data":[{"symbol":"BTC/USD","bids":[{"price":62791.2,"qty":0.40796420}],"asks":[],"checksum":1748223774,"timestamp":"2026-08-16T23:38:01.387898Z"}]}}
{"rx_ns": 42946799746300, "frame": {"channel":"book","type":"update","data":[{"symbol":"BTC/USD","bids":[],"asks":[{"price":62791.3,"qty":0.38601214}],"checksum":4243915096,"timestamp":"2026-08-16T23:38:01.388130Z"}]}}
{"rx_ns": 42946799783500, "frame": {"channel":"book","type":"update","data":[{"symbol":"BTC/USD","bids":[],"asks":[{"price":62791.3,"qty":0.39193864}],"checksum":300863609,"timestamp":"2026-08-16T23:38:01.395214Z"}]}}
{"rx_ns": 42946799799000, "frame": {"channel":"book","type":"update","data":[{"symbol":"BTC/USD","bids":[{"price":62791.2,"qty":0.33152193}],"asks":[],"checksum":4028519567,"timestamp":"2026-08-16T23:38:01.395515Z"}]}}
{"rx_ns": 42946804947400, "frame": {"channel":"book","type":"update","data":[{"symbol":"BTC/USD","bids":[{"price":62780.7,"qty":0.00000000},{"price":62780.6,"qty":0.30523348},{"price":62782.2,"qty":0.07962767}],"asks":[],"checksum":3698360267,"timestamp":"2026-08-16T23:38:01.402328Z"}]}}
{"rx_ns": 42946806330400, "frame": {"channel":"book","type":"update","data":[{"symbol":"BTC/USD","bids":[{"price":62782.3,"qty":0.02785521}],"asks":[],"checksum":36566971,"timestamp":"2026-08-16T23:38:01.404864Z"}]}}
{"rx_ns": 42946806366500, "frame": {"channel":"book","type":"update","data":[{"symbol":"BTC/USD","bids":[{"price":62791.2,"qty":0.40112193}],"asks":[],"checksum":1427311536,"timestamp":"2026-08-16T23:38:01.405989Z"}]}}
{"rx_ns": 42946806376500, "frame": {"channel":"book","type":"update","data":[{"symbol":"BTC/USD","bids":[{"price":62782.8,"qty":0.03185106}],"asks":[],"checksum":520131817,"timestamp":"2026-08-16T23:38:01.406242Z"}]}}
{"rx_ns": 42946813380000, "frame": {"channel":"book","type":"update","data":[{"symbol":"BTC/USD","bids":[{"price":62790.0,"qty":0.00318523}],"asks":[],"checksum":3664566073,"timestamp":"2026-08-16T23:38:01.417007Z"}]}}
{"rx_ns": 42946836200500, "frame": {"channel":"book","type":"update","data":[{"symbol":"BTC/USD","bids":[],"asks":[{"price":62791.3,"qty":0.17293867}],"checksum":2146273835,"timestamp":"2026-08-16T23:38:01.420254Z"}]}}
{"rx_ns": 42946836250700, "frame": {"channel":"book","type":"update","data":[{"symbol":"BTC/USD","bids":[],"asks":[{"price":62801.3,"qty":0.79934706}],"checksum":4026838791,"timestamp":"2026-08-16T23:38:01.420518Z"}]}}
{"rx_ns": 42946836259400, "frame": {"channel":"book","type":"update","data":[{"symbol":"BTC/USD","bids":[{"price":62790.9,"qty":0.79629279}],"asks":[],"checksum":1494215353,"timestamp":"2026-08-16T23:38:01.420755Z"}]}}
{"rx_ns": 42946836288200, "frame": {"channel":"book","type":"update","data":[{"symbol":"BTC/USD","bids":[],"asks":[{"price":62801.2,"qty":0.24785175}],"checksum":1335722306,"timestamp":"2026-08-16T23:38:01.422842Z"}]}}
{"rx_ns": 42946836304700, "frame": {"channel":"book","type":"update","data":[{"symbol":"BTC/USD","bids":[{"price":62791.2,"qty":0.47756420}],"asks":[],"checksum":1624915639,"timestamp":"2026-08-16T23:38:01.425221Z"}]}}
{"rx_ns": 42946836312200, "frame": {"channel":"book","type":"update","data":[{"symbol":"BTC/USD","bids":[],"asks":[{"price":62791.3,"qty":0.16701217}],"checksum":2129717806,"timestamp":"2026-08-16T23:38:01.425584Z"}]}}
{"rx_ns": 42946836318400, "frame": {"channel":"book","type":"update","data":[{"symbol":"BTC/USD","bids":[{"price":62791.2,"qty":0.51299470}],"asks":[],"checksum":3436849565,"timestamp":"2026-08-16T23:38:01.426130Z"}]}}
{"rx_ns": 42946836334500, "frame": {"channel":"book","type":"update","data":[{"symbol":"BTC/USD","bids":[],"asks":[{"price":62791.3,"qty":0.17293867}],"checksum":3539008772,"timestamp":"2026-08-16T23:38:01.430362Z"}]}}
{"rx_ns": 42946836341600, "frame": {"channel":"book","type":"update","data":[{"symbol":"BTC/USD","bids":[{"price":62791.2,"qty":0.43655243}],"asks":[],"checksum":663456826,"timestamp":"2026-08-16T23:38:01.430384Z"}]}}
{"rx_ns": 42946836347900, "frame": {"channel":"book","type":"update","data":[{"symbol":"BTC/USD","bids":[],"asks":[{"price":62803.3,"qty":0.01100000}],"checksum":1651018148,"timestamp":"2026-08-16T23:38:01.430522Z"}]}}
{"rx_ns": 42946836361900, "frame": {"channel":"book","type":"update","data":[{"symbol":"BTC/USD","bids":[],"asks":[{"price":62792.6,"qty":0.00000000},{"price":62803.4,"qty":0.06960000}],"checksum":4065363213,"timestamp":"2026-08-16T23:38:01.431411Z"}]}}
{"rx_ns": 42946836711900, "frame": {"channel":"book","type":"update","data":[{"symbol":"BTC/USD","bids":[],"asks":[{"price":62801.3,"qty":0.00318497}],"checksum":3341713082,"timestamp":"2026-08-16T23:38:01.438830Z"}]}}
{"rx_ns": 42946841083800, "frame": {"channel":"book","type":"update","data":[{"symbol":"BTC/USD","bids":[],"asks":[{"price":62801.2,"qty":0.00000000},{"price":62803.7,"qty":0.00005100}],"checksum":2411606937,"timestamp":"2026-08-16T23:38:01.440435Z"}]}}
{"rx_ns": 42946843017200, "frame": {"channel":"book","type":"update","data":[{"symbol":"BTC/USD","bids":[],"asks":[{"price":62803.1,"qty":0.18489680}],"checksum":1576967647,"timestamp":"2026-08-16T23:38:01.450030Z"}]}}
{"rx_ns": 42946843087600, "frame": {"channel":"book","type":"update","data":[{"symbol":"BTC/USD","bids":[{"price":62782.8,"qty":0.07962549}],"asks":[],"checksum":2497695024,"timestamp":"2026-08-16T23:38:01.454728Z"}]}}
{"rx_ns": 42946843101800, "frame": {"channel":"book","type":"update","data":[{"symbol":"BTC/USD","bids":[{"price":62782.9,"qty":0.02473415}],"asks":[],"checksum":1175219547,"timestamp":"2026-08-16T23:38:01.456292Z"}]}}
{"rx_ns": 42946843122500, "frame": {"channel":"book","type":"update","data":[{"symbol":"BTC/USD","bids":[{"price":62784.6,"qty":0.03194519}],"asks":[],"checksum":1495402573,"timestamp":"2026-08-16T23:38:01.458182Z"}]}}
{"rx_ns": 42946847493200, "frame": {"channel":"book","type":"update","data":[{"symbol":"BTC/USD","bids":[{"price":62791.2,"qty":0.51299470}],"asks":[],"checksum":2250514465,"timestamp":"2026-08-16T23:38:01.473079Z"}]}}
{"rx_ns": 42946850439200, "frame": {"channel":"book","type":"update","data":[{"symbol":"BTC/USD","bids":[],"asks":[{"price":62791.3,"qty":0.16701217}],"checksum":344924315,"timestamp":"2026-08-16T23:38:01.473325Z"}]}}
{"rx_ns": 42946873265000, "frame": {"channel":"book","type":"update","data":[{"symbol":"BTC/USD","bids":[],"asks":[{"price":62800.7,"qty":3.79023544}],"checksum":419626156,"timestamp":"2026-08-16T23:38:01.490106Z"}]}}
{"rx_ns": 42946880293500, "frame": {"channel":"book","type":"update","data":[{"symbol":"BTC/USD","bids":[],"asks":[{"price":62803.1,"qty":0.00000000},{"price":62803.4,"qty":0.06960000}],"checksum":1199063658,"timestamp":"2026-08-16T23:38:01.491630Z"}]}}
{"rx_ns": 42946880350200, "frame": {"channel":"book","type":"update","data":[{"symbol":"BTC/USD","bids":[],"asks":[{"price":62803.2,"qty":0.05598472}],"checksum":946213074,"timestamp":"2026-08-16T23:38:01.491768Z"}]}}
{"rx_ns": 42946880361700, "frame": {"channel":"book","type":"update","data":[{"symbol":"BTC/USD","bids":[],"asks":[{"price":62803.0,"qty":0.14418735}],"checksum":1826028569,"timestamp":"2026-08-16T23:38:01.492214Z"}]}}
{"rx_ns": 42946880371700, "frame": {"channel":"book","type":"update","data":[{"symbol":"BTC/USD","bids":[],"asks":[{"price":62800.6,"qty":1.14158264}],"checksum":1717098453,"timestamp":"2026-08-16T23:38:01.492281Z"}]}}
{"rx_ns": 42946880380100, "frame": {"channel":"book","type":"update","data":[{"symbol":"BTC/USD","bids":[],"asks":[{"price":62803.0,"qty":0.23318300}],"checksum":1397514330,"timestamp":"2026-08-16T23:38:01.493504Z"}]}}
{"rx_ns": 42946880388800, "frame": {"channel":"book","type":"update","data":[{"symbol":"BTC/USD","bids":[],"asks":[{"price":62803.0,"qty":0.08899565}],"checksum":3043819628,"timestamp":"2026-08-16T23:38:01.493691Z"}]}}
{"rx_ns": 42946880397000, "frame": {"channel":"book","type":"update","data":[{"symbol":"BTC/USD","bids":[],"asks":[{"price":62803.0,"qty":0.00000000},{"price":62803.3,"qty":0.01100000}],"checksum":3061168335,"timestamp":"2026-08-16T23:38:01.493772Z"}]}}
{"rx_ns": 42946886093200, "frame": {"channel":"book","type":"update","data":[{"symbol":"BTC/USD","bids":[],"asks":[{"price":62803.1,"qty":0.04078576}],"checksum":2575515575,"timestamp":"2026-08-16T23:38:01.495495Z"}]}}
{"rx_ns": 42946886144900, "frame": {"channel":"book","type":"update","data":[{"symbol":"BTC/USD","bids":[],"asks":[{"price":62803.1,"qty":0.06840638}],"checksum":1021186483,"timestamp":"2026-08-16T23:38:01.496145Z"}]}}
{"rx_ns": 42946893839600, "frame": {"channel":"book","type":"update","data":[{"symbol":"BTC/USD","bids":[],"asks":[{"price":62800.7,"qty":0.00000000},{"price":62803.3,"qty":0.01100000},{"price":62803.3,"qty":3.80117314}],"checksum":185101305,"timestamp":"2026-08-16T23:38:01.506831Z"}]}}
{"rx_ns": 42946893892300, "frame": {"channel":"book","type":"update","data":[{"symbol":"BTC/USD","bids":[],"asks":[{"price":62800.6,"qty":0.00000000},{"price":62803.4,"qty":0.06960000}],"checksum":4201044545,"timestamp":"2026-08-16T23:38:01.508174Z"}]}}
{"rx_ns": 42946893921700, "frame": {"channel":"book","type":"update","data":[{"symbol":"BTC/USD","bids":[],"asks":[{"price":62803.1,"qty":0.04078576}],"checksum":2342090726,"timestamp":"2026-08-16T23:38:01.510058Z"}]}}
{"rx_ns": 42946893932200, "frame": {"channel":"book","type":"update","data":[{"symbol":"BTC/USD","bids":[],"asks":[{"price":62803.1,"qty":0.00000000},{"price":62803.7,"qty":0.00005100}],"checksum":627270606,"timestamp":"2026-08-16T23:38:01.510068Z"}]}}
{"rx_ns": 42946893950000, "frame": {"channel":"book","type":"update","data":[{"symbol":"BTC/USD","bids":[],"asks":[{"price":62803.2,"qty":1.24426073}],"checksum":3440525999,"timestamp":"2026-08-16T23:38:01.512772Z"}]}}
{"rx_ns": 42946912668700, "frame": {"channel":"book","type":"update","data":[{"symbol":"BTC/USD","bids":[{"price":62791.2,"qty":0.49815064}],"asks":[],"checksum":1037109929,"timestamp":"2026-08-16T23:38:01.526113Z"}]}}
{"rx_ns": 42946914704600, "frame": {"channel":"book","type":"update","data":[{"symbol":"BTC/USD","bids":[],"asks":[{"price":62803.3,"qty":0.01100000}],"checksum":1806738532,"timestamp":"2026-08-16T23:38:01.531194Z"}]}}
{"rx_ns": 42946918342400, "frame": {"channel":"book","type":"update","data":[{"symbol":"BTC/USD","bids":[],"asks":[{"price":62803.2,"qty":0.05598472}],"checksum":2462213399,"timestamp":"2026-08-16T23:38:01.534540Z"}]}}
{"rx_ns": 42946918385800, "frame": {"channel":"book","type":"update","data":[{"symbol":"BTC/USD","bids":[],"asks":[{"price":62803.2,"qty":0.11289404}],"checksum":3921496087,"timestamp":"2026-08-16T23:38:01.534865Z"}]}}
{"rx_ns": 42946939651500, "frame": {"channel":"book","type":"update","data":[{"symbol":"BTC/USD","bids":[],"asks":[{"price":62803.2,"qty":0.05690932},{"price":62803.1,"qty":0.05598472}],"checksum":1616801797,"timestamp":"2026-08-16T23:38:01.563709Z"}]}}
{"rx_ns": 42946963868900, "frame": {"channel":"book","type":"update","data":[{"symbol":"BTC/USD","bids":[{"price":62785.1,"qty":0.06142600}],"asks":[],"checksum":1095941684,"timestamp":"2026-08-16T23:38:01.586981Z"}]}}
{"rx_ns": 42946969232800, "frame": {"channel":"book","type":"update","data":[{"symbol":"BTC/USD","bids":[{"price":62785.2,"qty":0.02788652}],"asks":[],"checksum":1560325775,"timestamp":"2026-08-16T23:38:01.590703Z"}]}}
{"rx_ns": 42946976361500, "frame": {"channel":"book","type":"update","data":[{"symbol":"BTC/USD","bids":[{"price":62790.9,"qty":0.80575127}],"asks":[],"checksum":2889111423,"timestamp":"2026-08-16T23:38:01.593612Z"}]}}
{"rx_ns": 42946990093000, "frame": {"channel":"book","type":"update","data":[{"symbol":"BTC/USD","bids":[{"price":62784.6,"qty":0.00009500},{"price":62785.9,"qty":0.07962319}],"asks":[],"checksum":3761237606,"timestamp":"2026-08-16T23:38:01.611190Z"}]}}
{"rx_ns": 42946994158500, "frame": {"channel":"book","type":"update","data":[{"symbol":"BTC/USD","bids":[{"price":62786.0,"qty":0.04214676}],"asks":[],"checksum":3678940694,"timestamp":"2026-08-16T23:38:01.612998Z"}]}}
{"rx_ns": 42946994211500, "frame": {"channel":"book","type":"update","data":[{"symbol":"BTC/USD","bids":[{"price":62785.2,"qty":0.00000000},{"price":62784.6,"qty":0.00009500}],"asks":[],"checksum":3724522284,"timestamp":"2026-08-16T23:38:01.613103Z"}]}}
{"rx_ns": 42946995775300, "frame": {"channel":"book","type":"update","data":[{"symbol":"BTC/USD","bids":[{"price":62786.5,"qty":0.03184927}],"asks":[],"checksum":1394507087,"timestamp":"2026-08-16T23:38:01.614788Z"}]}}
{"rx_ns": 42947013656200, "frame": {"channel":"book","type":"update","data":[{"symbol":"BTC/USD","bids":[{"price":62790.9,"qty":0.79629279}],"asks":[],"checksum":3998399402,"timestamp":"2026-08-16T23:38:01.626926Z"}]}}
{"rx_ns": 42947013707400, "frame": {"channel":"book","type":"update","data":[{"symbol":"BTC/USD","bids":[{"price":62791.2,"qty":0.50761108}],"asks":[],"checksum":1112264871,"timestamp":"2026-08-16T23:38:01.627057Z"}]}}
{"rx_ns": 42947013740100, "frame": {"channel":"book","type":"update","data":[{"symbol":"BTC/USD","bids":[],"asks":[{"price":62791.3,"qty":0.08901217}],"checksum":2078237671,"timestamp":"2026-08-16T23:38:01.629975Z"}]}}
{"rx_ns": 42947030744000, "frame": {"channel":"book","type":"update","data":[{"symbol":"BTC/USD","bids":[],"asks":[{"price":62803.2,"qty":1.18098705}],"checksum":937304535,"timestamp":"2026-08-16T23:38:01.646064Z"}]}}
{"rx_ns": 42947037165500, "frame": {"channel":"book","type":"update","data":[{"symbol":"BTC/USD","bids":[{"price":62791.2,"qty":0.43801108}],"asks":[],"checksum":2664679184,"timestamp":"2026-08-16T23:38:01.651306Z"}]}}
{"rx_ns": 42947037241900, "frame": {"channel":"book","type":"update","data":[{"symbol":"BTC/USD","bids":[],"asks":[{"price":62791.3,"qty":0.16701217}],"checksum":1019368375,"timestamp":"2026-08-16T23:38:01.654290Z"}]}}
{"rx_ns": 42947069042800, "frame": {"channel":"book","type":"update","data":[{"symbol":"BTC/USD","bids":[],"asks":[{"price":62803.0,"qty":0.18489680}],"checksum":3719964212,"timestamp":"2026-08-16T23:38:01.682160Z"}]}}
{"rx_ns": 42947069096600, "frame": {"channel":"book","type":"update","data":[{"symbol":"BTC/USD","bids":[{"price":62789.6,"qty":0.46828931}],"asks":[],"checksum":1684759509,"timestamp":"2026-08-16T23:38:01.691752Z"}]}}
{"rx_ns": 42947092896900, "frame": {"channel":"book","type":"update","data":[{"symbol":"BTC/USD","bids":[{"price":62791.2,"qty":0.53801108}],"asks":[],"checksum":275618112,"timestamp":"2026-08-16T23:38:01.718733Z"}]}}
{"rx_ns": 42947110283700, "frame": {"channel":"book","type":"update","data":[{"symbol":"BTC/USD","bids":[],"asks":[{"price":62803.1,"qty":0.00000000},{"price":62803.4,"qty":0.06960000},{"price":62801.8,"qty":0.05598472}],"checksum":1583429609,"timestamp":"2026-08-16T23:38:01.733468Z"}]}}
{"rx_ns": 42947114972200, "frame": {"channel":"book","type":"update","data":[{"symbol":"BTC/USD","bids":[],"asks":[{"price":62801.7,"qty":0.02595809}],"checksum":2579754582,"timestamp":"2026-08-16T23:38:01.737902Z"}]}}
{"rx_ns": 42947157973900, "frame": {"channel":"book","type":"update","data":[{"symbol":"BTC/USD","bids":[],"asks":[{"price":62803.0,"qty":0.00000000},{"price":62803.3,"qty":0.01100000}],"checksum":365274667,"timestamp":"2026-08-16T23:38:01.783930Z"}]}}
{"rx_ns": 42947161177000, "frame": {"channel":"book","type":"update","data":[{"symbol":"BTC/USD","bids":[],"asks":[{"price":62803.2,"qty":0.05690932}],"checksum":935383986,"timestamp":"2026-08-16T23:38:01.784114Z"}]}}
{"rx_ns": 42947161219000, "frame": {"channel":"book","type":"update","data":[{"symbol":"BTC/USD","bids":[],"asks":[{"price":62803.2,"qty":0.00000000},{"price":62803.4,"qty":0.06960000}],"checksum":1257083400,"timestamp":"2026-08-16T23:38:01.784185Z"}]}}
{"rx_ns": 42947161232000, "frame": {"channel":"book","type":"update","data":[{"symbol":"BTC/USD","bids":[],"asks":[{"price":62802.9,"qty":0.15964672}],"checksum":2703775025,"timestamp":"2026-08-16T23:38:01.784356Z"}]}}
{"rx_ns": 42947161240900, "frame": {"channel":"book","type":"update","data":[{"symbol":"BTC/USD","bids":[],"asks":[{"price":62802.9,"qty":0.00000000},{"price":62803.4,"qty":0.06960000}],"checksum":1257083400,"timestamp":"2026-08-16T23:38:01.785264Z"}]}}
{"rx_ns": 42947161612400, "frame": {"channel":"book","type":"update","data":[{"symbol":"BTC/USD","bids":[],"asks":[{"price":62803.3,"qty":0.11217152}],"checksum":3354329682,"timestamp":"2026-08-16T23:38:01.785485Z"}]}}
{"rx_ns": 42947182470900, "frame": {"channel":"book","type":"update","data":[{"symbol":"BTC/USD","bids":[],"asks":[{"price":62803.0,"qty":3.79014773}],"checksum":2193339348,"timestamp":"2026-08-16T23:38:01.805420Z"}]}}
{"rx_ns": 42947182535100, "frame": {"channel":"book","type":"update","data":[{"symbol":"BTC/USD","bids":[],"asks":[{"price":62803.3,"qty":0.01100000}],"checksum":912214613,"timestamp":"2026-08-16T23:38:01.806716Z"}]}}
{"rx_ns": 42947182546300, "frame": {"channel":"book","type":"update","data":[{"symbol":"BTC/USD","bids":[],"asks":[{"price":62802.9,"qty":1.23581412}],"checksum":212343242,"timestamp":"2026-08-16T23:38:01.806876Z"}]}}
{"rx_ns": 42947249015800, "frame": {"channel":"book","type":"update","data":[{"symbol":"BTC/USD","bids":[],"asks":[{"price":62803.0,"qty":0.00000000},{"price":62803.3,"qty":0.01100000}],"checksum":1409775982,"timestamp":"2026-08-16T23:38:01.873526Z"}]}}
{"rx_ns": 42947287562600, "frame": {"channel":"book","type":"update","data":[{"symbol":"BTC/USD","bids":[],"asks":[{"price":62801.8,"qty":0.00000000},{"price":62803.4,"qty":0.06960000},{"price":62801.6,"qty":0.05598472}],"checksum":3336317953,"timestamp":"2026-08-16T23:38:01.914008Z"}]}}
{"rx_ns": 42947290464200, "frame": {"channel":"book","type":"update","data":[{"symbol":"BTC/USD","bids":[],"asks":[{"price":62801.7,"qty":0.00000000},{"price":62803.4,"qty":0.06960000}],"checksum":2721529374,"timestamp":"2026-08-16T23:38:01.915243Z"}]}}
{"rx_ns": 42947292901700, "frame": {"channel":"book","type":"update","data":[{"symbol":"BTC/USD","bids":[],"asks":[{"price":62801.6,"qty":0.00000000},{"price":62803.7,"qty":0.00005100},{"price":62801.8,"qty":0.05598472}],"checksum":148534162,"timestamp":"2026-08-16T23:38:01.916306Z"}]}}
{"rx_ns": 42947292974200, "frame": {"channel":"book","type":"update","data":[{"symbol":"BTC/USD","bids":[],"asks":[{"price":62801.5,"qty":0.02595809}],"checksum":3873333868,"timestamp":"2026-08-16T23:38:01.916582Z"}]}}
{"rx_ns": 42947326531800, "frame": {"channel":"book","type":"update","data":[{"symbol":"BTC/USD","bids":[],"asks":[{"price":62798.5,"qty":0.79619769}],"checksum":3994432474,"timestamp":"2026-08-16T23:38:01.951290Z"}]}}
{"rx_ns": 42947329901200, "frame": {"channel":"book","type":"update","data":[{"symbol":"BTC/USD","bids":[{"price":62785.3,"qty":0.79636458}],"asks":[],"checksum":1200474295,"timestamp":"2026-08-16T23:38:01.952195Z"}]}}
{"rx_ns": 42947367261300, "frame": {"channel":"heartbeat"}}
{"rx_ns": 42947394352000, "frame": {"channel":"book","type":"update","data":[{"symbol":"BTC/USD","bids":[{"price":62790.9,"qty":0.00000000},{"price":62785.1,"qty":0.06142600}],"asks":[],"checksum":611048089,"timestamp":"2026-08-16T23:38:02.015099Z"}]}}
{"rx_ns": 42947394427600, "frame": {"channel":"book","type":"update","data":[{"symbol":"BTC/USD","bids":[],"asks":[{"price":62802.8,"qty":0.18489680}],"checksum":3772208152,"timestamp":"2026-08-16T23:38:02.016303Z"}]}}
{"rx_ns": 42947394443500, "frame": {"channel":"book","type":"update","data":[{"symbol":"BTC/USD","bids":[{"price":62787.7,"qty":0.79633307}],"asks":[],"checksum":891024067,"timestamp":"2026-08-16T23:38:02.016504Z"}]}}
{"rx_ns": 42947427847400, "frame": {"channel":"book","type":"update","data":[{"symbol":"BTC/USD","bids":[],"asks":[{"price":62791.3,"qty":0.32629915}],"checksum":229335932,"timestamp":"2026-08-16T23:38:02.051685Z"}]}}
{"rx_ns": 42947429954800, "frame": {"channel":"book","type":"update","data":[{"symbol":"BTC/USD","bids":[],"asks":[{"price":62792.6,"qty":0.23893047}],"checksum":4222463003,"timestamp":"2026-08-16T23:38:02.051887Z"}]}}
{"rx_ns": 42947490169900, "frame": {"channel":"book","type":"update","data":[{"symbol":"BTC/USD","bids":[],"asks":[{"price":62801.8,"qty":0.00000000},{"price":62802.8,"qty":0.18489680},{"price":62801.4,"qty":0.05598472}],"checksum":2044321105,"timestamp":"2026-08-16T23:38:02.097799Z"}]}}
{"rx_ns": 42947548334400, "frame": {"channel":"book","type":"update","data":[{"symbol":"BTC/USD","bids":[],"asks":[{"price":62800.5,"qty":0.79622378}],"checksum":1300289455,"timestamp":"2026-08-16T23:38:02.174830Z"}]}}
{"rx_ns": 42947549875500, "frame": {"channel":"book","type":"update","data":[{"symbol":"BTC/USD","bids":[],"asks":[{"price":62801.5,"qty":0.00000000},{"price":62802.8,"qty":0.18489680}],"checksum":3235744262,"timestamp":"2026-08-16T23:38:02.176527Z"}]}}
{"rx_ns": 42947552570800, "frame": {"channel":"book","type":"update","data":[{"symbol":"BTC/USD","bids":[],"asks":[{"price":62801.4,"qty":0.00000000},{"price":62802.9,"qty":1.23581412},{"price":62801.8,"qty":0.05598472}],"checksum":3718659307,"timestamp":"2026-08-16T23:38:02.177553Z"}]}}
{"rx_ns": 42947552636400, "frame": {"channel":"book","type":"update","data":[{"symbol":"BTC/USD","bids":[],"asks":[{"price":62800.4,"qty":0.31977330}],"checksum":1196011240,"timestamp":"2026-08-16T23:38:02.178032Z"}]}}
{"rx_ns": 42947578333500, "frame": {"channel":"book","type":"update","data":[{"symbol":"BTC/USD","bids":[],"asks":[{"price":62800.4,"qty":1.41024762}],"checksum":128466214,"timestamp":"2026-08-16T23:38:02.202897Z"}]}}
{"rx_ns": 42947612310900, "frame": {"channel":"book","type":"update","data":[{"symbol":"BTC/USD","bids":[],"asks":[{"price":62791.3,"qty":0.16701217}],"checksum":928540820,"timestamp":"2026-08-16T23:38:02.239204Z"}]}}
{"rx_ns": 42947634973700, "frame": {"channel":"book","type":"update","data":[{"symbol":"BTC/USD","bids":[],"asks":[{"price":62792.6,"qty":0.00000000},{"price":62802.7,"qty":3.79013973}],"checksum":3606142446,"timestamp":"2026-08-16T23:38:02.259228Z"}]}}
{"rx_ns": 42947680435200, "frame": {"channel":"book","type":"update","data":[{"symbol":"BTC/USD","bids":[{"price":62789.6,"qty":0.00000000},{"price":62784.9,"qty":0.00005100}],"asks":[],"checksum":2821419149,"timestamp":"2026-08-16T23:38:02.301332Z"}]}}
{"rx_ns": 42947680505000, "frame": {"channel":"book","type":"update","data":[{"symbol":"BTC/USD","bids":[{"price":62791.2,"qty":0.37872900}],"asks":[],"checksum":2070382073,"timestamp":"2026-08-16T23:38:02.301656Z"}]}}
{"rx_ns": 42947680517000, "frame": {"channel":"book","type":"update","data":[{"symbol":"BTC/USD","bids":[{"price":62787.7,"qty":0.00000000},{"price":62784.6,"qty":0.00009500}],"asks":[],"checksum":3106539854,"timestamp":"2026-08-16T23:38:02.302758Z"}]}}
{"rx_ns": 42947680532800, "frame": {"channel":"book","type":"update","data":[{"symbol":"BTC/USD","bids":[{"price":62789.7,"qty":0.00000000},{"price":62784.0,"qty":0.00318553}],"asks":[],"checksum":1758851182,"timestamp":"2026-08-16T23:38:02.303852Z"}]}}
{"rx_ns": 42947680541300, "frame": {"channel":"book","type":"update","data":[{"symbol":"BTC/USD","bids":[],"asks":[{"price":62800.3,"qty":0.18489680}],"checksum":281573904,"timestamp":"2026-08-16T23:38:02.304861Z"}]}}
{"rx_ns": 42947682417100, "frame": {"channel":"book","type":"update","data":[{"symbol":"BTC/USD","bids":[{"price":62790.3,"qty":0.79630010}],"asks":[],"checksum":3189950789,"timestamp":"2026-08-16T23:38:02.305204Z"}]}}
{"rx_ns": 42947682434100, "frame": {"channel":"book","type":"update","data":[{"symbol":"BTC/USD","bids":[],"asks":[{"price":62801.8,"qty":0.00000000},{"price":62802.7,"qty":3.79013973},{"price":62797.3,"qty":0.05598472}],"checksum":998545642,"timestamp":"2026-08-16T23:38:02.306628Z"}]}}
{"rx_ns": 42947697922100, "frame": {"channel":"book","type":"update","data":[{"symbol":"BTC/USD","bids":[],"asks":[{"price":62798.5,"qty":0.00000000},{"price":62802.7,"qty":3.79013973}],"checksum":3086434746,"timestamp":"2026-08-16T23:38:02.323408Z"}]}}
{"rx_ns": 42947700635100, "frame": {"channel":"book","type":"update","data":[{"symbol":"BTC/USD","bids":[],"asks":[{"price":62797.6,"qty":0.79620942}],"checksum":2051201836,"timestamp":"2026-08-16T23:38:02.325565Z"}]}}
{"rx_ns": 42947700699300, "frame": {"channel":"book","type":"update","data":[{"symbol":"BTC/USD","bids":[{"price":62788.1,"qty":0.79632832}],"asks":[],"checksum":3135450395,"timestamp":"2026-08-16T23:38:02.326051Z"}]}}
{"rx_ns": 42947737757600, "frame": {"channel":"book","type":"update","data":[{"symbol":"BTC/USD","bids":[{"price":62791.2,"qty":0.53801108}],"asks":[],"checksum":1773131887,"timestamp":"2026-08-16T23:38:02.363802Z"}]}}
{"rx_ns": 42947765026800, "frame": {"channel":"book","type":"update","data":[{"symbol":"BTC/USD","bids":[],"asks":[{"price":62800.4,"qty":0.31977330}],"checksum":3591996418,"timestamp":"2026-08-16T23:38:02.391244Z"}]}}
{"rx_ns": 42947766767700, "frame": {"channel":"book","type":"update","data":[{"symbol":"BTC/USD","bids":[],"asks":[{"price":62800.3,"qty":0.00000000},{"price":62803.3,"qty":0.01100000}],"checksum":3431303827,"timestamp":"2026-08-16T23:38:02.392167Z"}]}}
{"rx_ns": 42947808707100, "frame": {"channel":"book","type":"update","data":[{"symbol":"BTC/USD","bids":[{"price":62788.2,"qty":0.09538420}],"asks":[],"checksum":1852948902,"timestamp":"2026-08-16T23:38:02.431141Z"}]}}
{"rx_ns": 42947826257700, "frame": {"channel":"book","type":"update","data":[{"symbol":"BTC/USD","bids":[],"asks":[{"price":62801.7,"qty":3.79017557}],"checksum":954533511,"timestamp":"2026-08-16T23:38:02.449845Z"}]}}
{"rx_ns": 42947827485400, "frame": {"channel":"book","type":"update","data":[{"symbol":"BTC/USD","bids":[],"asks":[{"price":62800.4,"qty":1.33835519}],"checksum":2770451842,"timestamp":"2026-08-16T23:38:02.452884Z"}]}}
{"rx_ns": 42947835177900, "frame": {"channel":"book","type":"update","data":[{"symbol":"BTC/USD","bids":[],"asks":[{"price":62801.7,"qty":0.00000000},{"price":62803.3,"qty":0.01100000},{"price":62803.3,"qty":3.80117556}],"checksum":1664539394,"timestamp":"2026-08-16T23:38:02.457258Z"}]}}
{"rx_ns": 42947835251200, "frame": {"channel":"book","type":"update","data":[{"symbol":"BTC/USD","bids":[],"asks":[{"price":62800.4,"qty":0.31977330}],"checksum":4277297159,"timestamp":"2026-08-16T23:38:02.458306Z"}]}}
{"rx_ns": 42947855884900, "frame": {"channel":"book","type":"update","data":[{"symbol":"BTC/USD","bids":[],"asks":[{"price":62803.2,"qty":1.58092341}],"checksum":929163324,"timestamp":"2026-08-16T23:38:02.479125Z"}]}}
{"rx_ns": 42947855952600, "frame": {"channel":"book","type":"update","data":[{"symbol":"BTC/USD","bids":[],"asks":[{"price":62803.1,"qty":0.18489680}],"checksum":1022581689,"timestamp":"2026-08-16T23:38:02.480284Z"}]}}
{"rx_ns": 42947888902100, "frame": {"channel":"book","type":"update","data":[{"symbol":"BTC/USD","bids":[{"price":62790.3,"qty":0.00000000},{"price":62784.9,"qty":0.00005100}],"asks":[],"checksum":2968216295,"timestamp":"2026-08-16T23:38:02.513380Z"}]}}
{"rx_ns": 42947888964500, "frame": {"channel":"book","type":"update","data":[{"symbol":"BTC/USD","bids":[{"price":62791.2,"qty":1.33430100}],"asks":[],"checksum":3015141924,"timestamp":"2026-08-16T23:38:02.514741Z"}]}}
{"rx_ns": 42947896591700, "frame": {"channel":"book","type":"update","data":[{"symbol":"BTC/USD","bids":[{"price":62791.2,"qty":1.31298808}],"asks":[],"checksum":3012899845,"timestamp":"2026-08-16T23:38:02.515729Z"}]}}
{"rx_ns": 42947896633700, "frame": {"channel":"book","type":"update","data":[{"symbol":"BTC/USD","bids":[{"price":62790.1,"qty":0.02131292}],"asks":[],"checksum":1406743130,"timestamp":"2026-08-16T23:38:02.516967Z"}]}}
{"rx_ns": 42947978276000, "frame": {"channel":"book","type":"update","data":[{"symbol":"BTC/USD","bids":[],"asks":[{"price":62797.6,"qty":0.00000000},{"price":62803.2,"qty":1.58092341}],"checksum":224948055,"timestamp":"2026-08-16T23:38:02.599550Z"}]}}
{"rx_ns": 42947979115500, "frame": {"channel":"book","type":"update","data":[{"symbol":"BTC/USD","bids":[{"price":62788.1,"qty":0.00000000},{"price":62784.9,"qty":0.00005100}],"asks":[],"checksum":2213627627,"timestamp":"2026-08-16T23:38:02.600078Z"}]}}
{"rx_ns": 42947979151200, "frame": {"channel":"book","type":"update","data":[{"symbol":"BTC/USD","bids":[],"asks":[{"price":62798.9,"qty":0.79619324}],"checksum":2344649299,"timestamp":"2026-08-16T23:38:02.601679Z"}]}}
{"rx_ns": 42948041752600, "frame": {"channel":"book","type":"update","data":[{"symbol":"BTC/USD","bids":[],"asks":[{"price":62803.1,"qty":0.00000000},{"price":62803.2,"qty":1.58092341}],"checksum":709001415,"timestamp":"2026-08-16T23:38:02.666078Z"}]}}
{"rx_ns": 42948042621900, "frame": {"channel":"book","type":"update","data":[{"symbol":"BTC/USD","bids":[],"asks":[{"price":62803.2,"qty":0.00000000},{"price":62803.3,"qty":0.01100000}],"checksum":4096236737,"timestamp":"2026-08-16T23:38:02.666114Z"}]}}
{"rx_ns": 42948321105600, "frame": {"channel":"book","type":"update","data":[{"symbol":"BTC/USD","bids":[{"price":62790.1,"qty":0.00000000},{"price":62784.6,"qty":0.00009500}],"asks":[],"checksum":3637943102,"timestamp":"2026-08-16T23:38:02.945809Z"}]}}
{"rx_ns": 42948322968600, "frame": {"channel":"book","type":"update","data":[{"symbol":"BTC/USD","bids":[{"price":62791.0,"qty":0.02131292}],"asks":[],"checksum":3263878484,"timestamp":"2026-08-16T23:38:02.946098Z"}]}}
{"rx_ns": 42948327882000, "frame": {"channel":"book","type":"update","data":[{"symbol":"BTC/USD","bids":[{"price":62791.2,"qty":1.38258808}],"asks":[],"checksum":2996446060,"timestamp":"2026-08-16T23:38:02.953201Z"}]}}
{"rx_ns": 42948363451900, "frame": {"channel":"heartbeat"}}
