{"rx_ns": 42916836766600, "frame": {"channel":"book","type":"update","data":[{"symbol":"BTC/USD","bids":[{"price":62773.8,"qty":0.00000000},{"price":62772.6,"qty":0.06960000}],"asks":[],"checksum":2438003544,"timestamp":"2026-08-16T23:37:31.461571Z"}]}}
{"rx_ns": 42916862789000, "frame": {"channel":"book","type":"update","data":[{"symbol":"BTC/USD","bids":[],"asks":[{"price":62805.1,"qty":0.00000000},{"price":62809.9,"qty":0.00318421}],"checksum":2438003544,"timestamp":"2026-08-16T23:37:31.486089Z"}]}}
{"rx_ns": 42916894806800, "frame": {"channel":"book","type":"update","data":[{"symbol":"BTC/USD","bids":[{"price":62792.0,"qty":0.00000000},{"price":62772.2,"qty":0.07963741}],"asks":[],"checksum":1579795993,"timestamp":"2026-08-16T23:37:31.517946Z"}]}}
{"rx_ns": 42916894895700, "frame": {"channel":"book","type":"update","data":[{"symbol":"BTC/USD","bids":[{"price":62789.8,"qty":0.02131292}],"asks":[],"checksum":2234111488,"timestamp":"2026-08-16T23:37:31.519441Z"}]}}
{"rx_ns": 42916897322000, "frame": {"channel":"book","type":"update","data":[{"symbol":"BTC/USD","bids":[{"price":62778.1,"qty":0.00000000},{"price":62772.2,"qty":0.07963741}],"asks":[],"checksum":2234111488,"timestamp":"2026-08-16T23:37:31.522877Z"}]}}
{"rx_ns": 42916897363300, "frame": {"channel":"book","type":"update","data":[{"symbol":"BTC/USD","bids":[{"price":62777.4,"qty":0.00000000},{"price":62772.0,"qty":0.00318614}],"asks":[],"checksum":2234111488,"timestamp":"2026-08-16T23:37:31.522997Z"}]}}
{"rx_ns": 42916902971900, "frame": {"channel":"book","type":"update","data":[{"symbol":"BTC/USD","bids":[{"price":62780.4,"qty":0.79642650}],"asks":[],"checksum":2234111488,"timestamp":"2026-08-16T23:37:31.528145Z"}]}}
{"rx_ns": 42916921207200, "frame": {"channel":"book","type":"update","data":[{"symbol":"BTC/USD","bids":[{"price":62777.3,"qty":0.15927762}],"asks":[],"checksum":2234111488,"timestamp":"2026-08-16T23:37:31.547000Z"}]}}
{"rx_ns": 42917018731900, "frame": {"channel":"book","type":"update","data":[{"symbol":"BTC/USD","bids":[{"price":62789.8,"qty":0.00000000},{"price":62772.2,"qty":0.07963741}],"asks":[],"checksum":3318361441,"timestamp":"2026-08-16T23:37:31.640783Z"}]}}
{"rx_ns": 42917018809200, "frame": {"channel":"book","type":"update","data":[{"symbol":"BTC/USD","bids":[{"price":62790.7,"qty":0.02131292}],"asks":[],"checksum":2833757300,"timestamp":"2026-08-16T23:37:31.640984Z"}]}}
{"rx_ns": 42917125637700, "frame": {"channel":"book","type":"update","data":[{"symbol":"BTC/USD","bids":[{"price":62777.3,"qty":0.00000000},{"price":62772.2,"qty":0.07963741}],"asks":[],"checksum":2833757300,"timestamp":"2026-08-16T23:37:31.747976Z"}]}}
{"rx_ns": 42917150949200, "frame": {"channel":"book","type":"update","data":[{"symbol":"BTC/USD","bids":[{"price":62790.7,"qty":0.00000000},{"price":62772.0,"qty":0.00318614}],"asks":[],"checksum":3318361441,"timestamp":"2026-08-16T23:37:31.775513Z"}]}}
{"rx_ns": 42917152258000, "frame": {"channel":"book","type":"update","data":[{"symbol":"BTC/USD","bids":[{"price":62791.7,"qty":0.02131292}],"asks":[],"checksum":2131541990,"timestamp":"2026-08-16T23:37:31.775860Z"}]}}
{"rx_ns": 42917172086300, "frame": {"channel":"book","type":"update","data":[{"symbol":"BTC/USD","bids":[{"price":62777.4,"qty":0.15927762}],"asks":[],"checksum":2131541990,"timestamp":"2026-08-16T23:37:31.796164Z"}]}}
{"rx_ns": 42917176389900, "frame": {"channel":"book","type":"update","data":[{"symbol":"BTC/USD","bids":[{"price":62774.1,"qty":0.65558669}],"asks":[],"checksum":2131541990,"timestamp":"2026-08-16T23:37:31.800119Z"}]}}
{"rx_ns": 42917381667500, "frame": {"channel":"book","type":"update","data":[{"symbol":"BTC/USD","bids":[],"asks":[{"price":62805.2,"qty":0.00000000},{"price":62810.4,"qty":0.13109402},{"price":62805.5,"qty":1.59575715}],"checksum":2131541990,"timestamp":"2026-08-16T23:37:32.006215Z"}]}}
{"rx_ns": 42917551087200, "frame": {"channel":"book","type":"update","data":[{"symbol":"BTC/USD","bids":[{"price":62778.3,"qty":0.79645294}],"asks":[],"checksum":2131541990,"timestamp":"2026-08-16T23:37:32.175965Z"}]}}
{"rx_ns": 42917627914800, "frame": {"channel":"book","type":"update","data":[{"symbol":"BTC/USD","bids":[],"asks":[{"price":62793.6,"qty":5.17992472},{"price":62793.6,"qty":5.17809965}],"checksum":3025085744,"timestamp":"2026-08-16T23:37:32.249350Z"}]}}
{"rx_ns": 42917627954500, "frame": {"channel":"book","type":"update","data":[{"symbol":"BTC/USD","bids":[],"asks":[{"price":62793.6,"qty":5.10009965}],"checksum":4240877949,"timestamp":"2026-08-16T23:37:32.251395Z"}]}}
{"rx_ns": 42917709211000, "frame": {"channel":"book","type":"update","data":[{"symbol":"BTC/USD","bids":[{"price":62777.4,"qty":0.00000000},{"price":62772.7,"qty":0.00796524}],"asks":[],"checksum":4240877949,"timestamp":"2026-08-16T23:37:32.335022Z"}]}}
{"rx_ns": 42917720458200, "frame": {"channel":"book","type":"update","data":[{"symbol":"BTC/USD","bids":[{"price":62777.5,"qty":0.15927762}],"asks":[],"checksum":4240877949,"timestamp":"2026-08-16T23:37:32.346237Z"}]}}
{"rx_ns": 42917748652900, "frame": {"channel":"heartbeat"}}
{"rx_ns": 42917822855400, "frame": {"channel":"book","type":"update","data":[{"symbol":"BTC/USD","bids":[{"price":62777.5,"qty":0.00000000},{"price":62772.7,"qty":0.00796524}],"asks":[],"checksum":4240877949,"timestamp":"2026-08-16T23:37:32.446641Z"}]}}
{"rx_ns": 42917870316900, "frame": {"channel":"book","type":"update","data":[{"symbol":"BTC/USD","bids":[{"price":62778.1,"qty":0.15927762}],"asks":[],"checksum":4240877949,"timestamp":"2026-08-16T23:37:32.496261Z"}]}}
{"rx_ns": 42918362167000, "frame": {"channel":"book","type":"update","data":[{"symbol":"BTC/USD","bids":[],"asks":[{"price":62802.4,"qty":0.00000000},{"price":62810.4,"qty":0.13109402},{"price":62802.7,"qty":0.00318497}],"checksum":4240877949,"timestamp":"2026-08-16T23:37:32.987293Z"}]}}
{"rx_ns": 42918363726100, "frame": {"channel":"book","type":"update","data":[{"symbol":"BTC/USD","bids":[{"price":62783.0,"qty":0.00000000},{"price":62772.7,"qty":0.00796524},{"price":62783.3,"qty":0.00318497}],"asks":[],"checksum":2942104313,"timestamp":"2026-08-16T23:37:32.987579Z"}]}}
{"rx_ns": 42918748961500, "frame": {"channel":"heartbeat"}}
{"rx_ns": 42918821548300, "frame": {"channel":"book","type":"update","data":[{"symbol":"BTC/USD","bids":[{"price":62778.1,"qty":0.00000000},{"price":62772.7,"qty":0.00796524}],"asks":[],"checksum":2942104313,"timestamp":"2026-08-16T23:37:33.446844Z"}]}}
{"rx_ns": 42918870804200, "frame": {"channel":"book","type":"update","data":[{"symbol":"BTC/USD","bids":[{"price":62778.2,"qty":0.15927762}],"asks":[],"checksum":2942104313,"timestamp":"2026-08-16T23:37:33.496205Z"}]}}
{"rx_ns": 42919749677200, "frame": {"channel":"heartbeat"}}
{"rx_ns": 42920215551800, "frame": {"channel":"book","type":"update","data":[{"symbol":"BTC/USD","bids":[{"price":62778.2,"qty":0.00000000},{"price":62772.7,"qty":0.00796524}],"asks":[],"checksum":2942104313,"timestamp":"2026-08-16T23:37:34.841538Z"}]}}
{"rx_ns": 42920220542000, "frame": {"channel":"book","type":"update","data":[{"symbol":"BTC/USD","bids":[{"price":62778.3,"qty":0.95573056}],"asks":[],"checksum":2942104313,"timestamp":"2026-08-16T23:37:34.846358Z"}]}}
{"rx_ns": 42920385004200, "frame": {"channel":"book","type":"update","data":[{"symbol":"BTC/USD","bids":[],"asks":[{"price":62808.9,"qty":0.00000000},{"price":62810.4,"qty":0.13109402}],"checksum":2942104313,"timestamp":"2026-08-16T23:37:35.010370Z"}]}}
{"rx_ns": 42920385101500, "frame": {"channel":"book","type":"update","data":[{"symbol":"BTC/USD","bids":[],"asks":[{"price":62807.2,"qty":0.02865913}],"checksum":2942104313,"timestamp":"2026-08-16T23:37:35.010442Z"}]}}
{"rx_ns": 42920716106800, "frame": {"channel":"book","type":"update","data":[{"symbol":"BTC/USD","bids":[],"asks":[{"price":62809.9,"qty":0.00000000},{"price":62810.4,"qty":0.13109402}],"checksum":2942104313,"timestamp":"2026-08-16T23:37:35.340816Z"}]}}
{"rx_ns": 42920716179000, "frame": {"channel":"book","type":"update","data":[{"symbol":"BTC/USD","bids":[],"asks":[{"price":62808.0,"qty":0.00318430}],"checksum":2942104313,"timestamp":"2026-08-16T23:37:35.341098Z"}]}}
{"rx_ns": 42920748088200, "frame": {"channel":"heartbeat"}}
{"rx_ns": 42921751005700, "frame": {"channel":"heartbeat"}}
{"rx_ns": 42922182495700, "frame": {"channel":"book","type":"update","data":[{"symbol":"BTC/USD","bids":[],"asks":[{"price":62793.6,"qty":5.09877786}],"checksum":1980689788,"timestamp":"2026-08-16T23:37:36.798277Z"}]}}
{"rx_ns": 42922182541100, "frame": {"channel":"book","type":"update","data":[{"symbol":"BTC/USD","bids":[],"asks":[{"price":62793.6,"qty":5.17677786}],"checksum":528254587,"timestamp":"2026-08-16T23:37:36.800332Z"}]}}
{"rx_ns": 42922202553900, "frame": {"channel":"book","type":"update","data":[{"symbol":"BTC/USD","bids":[{"price":62775.1,"qty":0.00000000},{"price":62772.6,"qty":0.06960000}],"asks":[],"checksum":528254587,"timestamp":"2026-08-16T23:37:36.827998Z"}]}}
{"rx_ns": 42922204602000, "frame": {"channel":"book","type":"update","data":[{"symbol":"BTC/USD","bids":[{"price":62780.4,"qty":0.00000000},{"price":62772.2,"qty":0.07963741}],"asks":[],"checksum":528254587,"timestamp":"2026-08-16T23:37:36.829815Z"}]}}
{"rx_ns": 42922204626600, "frame": {"channel":"book","type":"update","data":[{"symbol":"BTC/USD","bids":[{"price":62778.3,"qty":0.15927762}],"asks":[],"checksum":528254587,"timestamp":"2026-08-16T23:37:36.829942Z"}]}}
{"rx_ns": 42922207259500, "frame": {"channel":"book","type":"update","data":[{"symbol":"BTC/USD","bids":[{"price":62772.8,"qty":0.79652267}],"asks":[],"checksum":528254587,"timestamp":"2026-08-16T23:37:36.832610Z"}]}}
{"rx_ns": 42922208963400, "frame": {"channel":"book","type":"update","data":[{"symbol":"BTC/USD","bids":[{"price":62775.0,"qty":0.01017606}],"asks":[],"checksum":528254587,"timestamp":"2026-08-16T23:37:36.833821Z"}]}}
{"rx_ns": 42922212184900, "frame": {"channel":"book","type":"update","data":[{"symbol":"BTC/USD","bids":[{"price":62772.8,"qty":0.00000000},{"price":62772.6,"qty":0.06960000}],"asks":[],"checksum":528254587,"timestamp":"2026-08-16T23:37:36.834736Z"}]}}
{"rx_ns": 42922318244100, "frame": {"channel":"book","type":"update","data":[{"symbol":"BTC/USD","bids":[{"price":62778.3,"qty":0.00000000},{"price":62772.2,"qty":0.07963741}],"asks":[],"checksum":528254587,"timestamp":"2026-08-16T23:37:36.944785Z"}]}}
{"rx_ns": 42922321760700, "frame": {"channel":"book","type":"update","data":[{"symbol":"BTC/USD","bids":[{"price":62778.4,"qty":0.15927762}],"asks":[],"checksum":528254587,"timestamp":"2026-08-16T23:37:36.946337Z"}]}}
{"rx_ns": 42922380324200, "frame": {"channel":"book","type":"update","data":[{"symbol":"BTC/USD","bids":[{"price":62779.2,"qty":0.79644107}],"asks":[],"checksum":528254587,"timestamp":"2026-08-16T23:37:37.006141Z"}]}}
{"rx_ns": 42922548821200, "frame": {"channel":"book","type":"update","data":[{"symbol":"BTC/USD","bids":[{"price":62777.0,"qty":0.79647000}],"asks":[],"checksum":528254587,"timestamp":"2026-08-16T23:37:37.174177Z"}]}}
{"rx_ns": 42922551612000, "frame": {"channel":"book","type":"update","data":[{"symbol":"BTC/USD","bids":[{"price":62775.0,"qty":0.00000000},{"price":62773.1,"qty":0.79651925}],"asks":[],"checksum":528254587,"timestamp":"2026-08-16T23:37:37.177001Z"}]}}
{"rx_ns": 42922732636100, "frame": {"channel":"book","type":"update","data":[{"symbol":"BTC/USD","bids":[{"price":62779.2,"qty":0.00000000},{"price":62772.7,"qty":0.00796524}],"asks":[],"checksum":528254587,"timestamp":"2026-08-16T23:37:37.358118Z"}]}}
{"rx_ns": 42922734040000, "frame": {"channel":"book","type":"update","data":[{"symbol":"BTC/USD","bids":[{"price":62779.8,"qty":0.79643358}],"asks":[],"checksum":528254587,"timestamp":"2026-08-16T23:37:37.359600Z"}]}}
{"rx_ns": 42922735553900, "frame": {"channel":"book","type":"update","data":[{"symbol":"BTC/USD","bids":[{"price":62774.8,"qty":0.01015299}],"asks":[],"checksum":528254587,"timestamp":"2026-08-16T23:37:37.361149Z"}]}}
{"rx_ns": 42922736979700, "frame": {"channel":"book","type":"update","data":[{"symbol":"BTC/USD","bids":[{"price":62774.8,"qty":0.00000000},{"price":62773.1,"qty":0.79651925}],"asks":[],"checksum":528254587,"timestamp":"2026-08-16T23:37:37.362197Z"}]}}
{"rx_ns": 42922749979300, "frame": {"channel":"heartbeat"}}
{"rx_ns": 42923221313000, "frame": {"channel":"book","type":"update","data":[{"symbol":"BTC/USD","bids":[{"price":62778.4,"qty":0.00000000},{"price":62772.7,"qty":0.00796524}],"asks":[],"checksum":528254587,"timestamp":"2026-08-16T23:37:37.846234Z"}]}}
{"rx_ns": 42923273971700, "frame": {"channel":"book","type":"update","data":[{"symbol":"BTC/USD","bids":[{"price":62778.3,"qty":0.15927762}],"asks":[],"checksum":528254587,"timestamp":"2026-08-16T23:37:37.896400Z"}]}}
{"rx_ns": 42923748432400, "frame": {"channel":"heartbeat"}}
{"rx_ns": 42923755667600, "frame": {"channel":"book","type":"update","data":[{"symbol":"BTC/USD","bids":[],"asks":[{"price":62805.5,"qty":0.00000000},{"price":62810.4,"qty":0.13109402}],"checksum":528254587,"timestamp":"2026-08-16T23:37:38.371757Z"}]}}
{"rx_ns": 42923856422400, "frame": {"channel":"book","type":"update","data":[{"symbol":"BTC/USD","bids":[],"asks":[{"price":62805.5,"qty":1.59575715}],"checksum":528254587,"timestamp":"2026-08-16T23:37:38.481381Z"}]}}
{"rx_ns": 42923947364400, "frame": {"channel":"book","type":"update","data":[{"symbol":"BTC/USD","bids":[],"asks":[{"price":62805.5,"qty":0.00000000},{"price":62810.4,"qty":0.13109402}],"checksum":528254587,"timestamp":"2026-08-16T23:37:38.572705Z"}]}}
{"rx_ns": 42923954082800, "frame": {"channel":"book","type":"update","data":[{"symbol":"BTC/USD","bids":[{"price":62777.0,"qty":0.00000000},{"price":62772.7,"qty":0.00796524}],"asks":[],"checksum":528254587,"timestamp":"2026-08-16T23:37:38.578207Z"}]}}
{"rx_ns": 42923954139700, "frame": {"channel":"book","type":"update","data":[{"symbol":"BTC/USD","bids":[{"price":62779.8,"qty":0.00000000},{"price":62772.6,"qty":0.06960000}],"asks":[],"checksum":528254587,"timestamp":"2026-08-16T23:37:38.578417Z"}]}}
{"rx_ns": 42923955837800, "frame": {"channel":"book","type":"update","data":[{"symbol":"BTC/USD","bids":[{"price":62780.4,"qty":0.79642601}],"asks":[],"checksum":528254587,"timestamp":"2026-08-16T23:37:38.580133Z"}]}}
{"rx_ns": 42923955865200, "frame": {"channel":"book","type":"update","data":[{"symbol":"BTC/USD","bids":[{"price":62778.3,"qty":0.95573092}],"asks":[],"checksum":528254587,"timestamp":"2026-08-16T23:37:38.580383Z"}]}}
{"rx_ns": 42923956360400, "frame": {"channel":"book","type":"update","data":[{"symbol":"BTC/USD","bids":[{"price":62775.1,"qty":0.01018783}],"asks":[],"checksum":528254587,"timestamp":"2026-08-16T23:37:38.582173Z"}]}}
{"rx_ns": 42923957927600, "frame": {"channel":"book","type":"update","data":[{"symbol":"BTC/USD","bids":[{"price":62775.1,"qty":0.00000000},{"price":62772.7,"qty":0.00796524}],"asks":[],"checksum":528254587,"timestamp":"2026-08-16T23:37:38.583906Z"}]}}
{"rx_ns": 42924134652100, "frame": {"channel":"book","type":"update","data":[{"symbol":"BTC/USD","bids":[{"price":62780.4,"qty":0.00000000},{"price":62772.6,"qty":0.06960000}],"asks":[],"checksum":528254587,"timestamp":"2026-08-16T23:37:38.757125Z"}]}}
{"rx_ns": 42924134815600, "frame": {"channel":"book","type":"update","data":[{"symbol":"BTC/USD","bids":[{"price":62785.0,"qty":0.00000000},{"price":62772.2,"qty":0.07963741},{"price":62788.1,"qty":0.05598472}],"asks":[],"checksum":366735595,"timestamp":"2026-08-16T23:37:38.758685Z"}]}}
{"rx_ns": 42924134852600, "frame": {"channel":"book","type":"update","data":[{"symbol":"BTC/USD","bids":[{"price":62781.1,"qty":0.79641687}],"asks":[],"checksum":366735595,"timestamp":"2026-08-16T23:37:38.759138Z"}]}}
{"rx_ns": 42924138399400, "frame": {"channel":"book","type":"update","data":[{"symbol":"BTC/USD","bids":[{"price":62775.3,"qty":0.01021271}],"asks":[],"checksum":366735595,"timestamp":"2026-08-16T23:37:38.760804Z"}]}}
{"rx_ns": 42924139880900, "frame": {"channel":"book","type":"update","data":[{"symbol":"BTC/USD","bids":[{"price":62775.3,"qty":0.00000000},{"price":62772.7,"qty":0.00796524}],"asks":[],"checksum":366735595,"timestamp":"2026-08-16T23:37:38.762954Z"}]}}
{"rx_ns": 42924139922100, "frame": {"channel":"book","type":"update","data":[{"symbol":"BTC/USD","bids":[{"price":62780.9,"qty":0.06960000}],"asks":[],"checksum":366735595,"timestamp":"2026-08-16T23:37:38.764305Z"}]}}
{"rx_ns": 42924153076000, "frame": {"channel":"book","type":"update","data":[{"symbol":"BTC/USD","bids":[{"price":62778.3,"qty":0.79645330}],"asks":[],"checksum":366735595,"timestamp":"2026-08-16T23:37:38.778713Z"}]}}
{"rx_ns": 42924171003500, "frame": {"channel":"book","type":"update","data":[{"symbol":"BTC/USD","bids":[{"price":62779.0,"qty":0.15927762}],"asks":[],"checksum":366735595,"timestamp":"2026-08-16T23:37:38.796422Z"}]}}
{"rx_ns": 42924497684600, "frame": {"channel":"book","type":"update","data":[{"symbol":"BTC/USD","bids":[{"price":62793.5,"qty":0.00033098}],"asks":[],"checksum":751092168,"timestamp":"2026-08-16T23:37:39.121185Z"}]}}
{"rx_ns": 42924593880200, "frame": {"channel":"book","type":"update","data":[{"symbol":"BTC/USD","bids":[{"price":62784.6,"qty":0.00000000},{"price":62773.6,"qty":0.03185600},{"price":62784.0,"qty":0.00009500}],"asks":[],"checksum":3071590662,"timestamp":"2026-08-16T23:37:39.220089Z"}]}}
{"rx_ns": 42924752925200, "frame": {"channel":"heartbeat"}}
{"rx_ns": 42925071501500, "frame": {"channel":"book","type":"update","data":[{"symbol":"BTC/USD","bids":[{"price":62793.5,"qty":0.00010000},{"price":62793.5,"qty":0.00000098}],"asks":[],"checksum":640876754,"timestamp":"2026-08-16T23:37:39.696630Z"}]}}
{"rx_ns": 42925078329600, "frame": {"channel":"book","type":"update","data":[{"symbol":"BTC/USD","bids":[],"asks":[{"price":62793.6,"qty":5.10717786}],"checksum":3053448393,"timestamp":"2026-08-16T23:37:39.698369Z"}]}}
{"rx_ns": 42925078394100, "frame": {"channel":"book","type":"update","data":[{"symbol":"BTC/USD","bids":[],"asks":[{"price":62793.6,"qty":5.02917786}],"checksum":470850293,"timestamp":"2026-08-16T23:37:39.698536Z"}]}}
{"rx_ns": 42925078407500, "frame": {"channel":"book","type":"update","data":[{"symbol":"BTC/USD","bids":[{"price":62783.3,"qty":0.00000000},{"price":62773.6,"qty":0.03185600},{"price":62783.2,"qty":0.00318497}],"asks":[],"checksum":2612416950,"timestamp":"2026-08-16T23:37:39.698879Z"}]}}
{"rx_ns": 42925078422200, "frame": {"channel":"book","type":"update","data":[{"symbol":"BTC/USD","bids":[{"price":62793.5,"qty":0.00000000},{"price":62773.6,"qty":0.03185600}],"asks":[{"price":62791.8,"qty":0.00019902}],"checksum":1847579405,"timestamp":"2026-08-16T23:37:39.700974Z"}]}}
{"rx_ns": 42925081568000, "frame": {"channel":"book","type":"update","data":[{"symbol":"BTC/USD","bids":[],"asks":[{"price":62791.8,"qty":0.01185194}],"checksum":4024195837,"timestamp":"2026-08-16T23:37:39.701453Z"}]}}
{"rx_ns": 42925081603200, "frame": {"channel":"book","type":"update","data":[{"symbol":"BTC/USD","bids":[],"asks":[{"price":62793.6,"qty":5.02067207}],"checksum":2396385677,"timestamp":"2026-08-16T23:37:39.701570Z"}]}}
{"rx_ns": 42925081613300, "frame": {"channel":"book","type":"update","data":[{"symbol":"BTC/USD","bids":[],"asks":[{"price":62793.5,"qty":0.11000000}],"checksum":2550666438,"timestamp":"2026-08-16T23:37:39.702085Z"}]}}
{"rx_ns": 42925081623900, "frame": {"channel":"book","type":"update","data":[{"symbol":"BTC/USD","bids":[],"asks":[{"price":62793.6,"qty":4.96468735},{"price":62793.5,"qty":0.16598472}],"checksum":1925322800,"timestamp":"2026-08-16T23:37:39.702512Z"}]}}
{"rx_ns": 42925081634300, "frame": {"channel":"book","type":"update","data":[{"symbol":"BTC/USD","bids":[],"asks":[{"price":62796.9,"qty":0.00000000},{"price":62808.0,"qty":0.00318430}],"checksum":3215782809,"timestamp":"2026-08-16T23:37:39.702547Z"}]}}
{"rx_ns": 42925081643600, "frame": {"channel":"book","type":"update","data":[{"symbol":"BTC/USD","bids":[],"asks":[{"price":62793.6,"qty":4.80540973}],"checksum":1002541753,"timestamp":"2026-08-16T23:37:39.702581Z"}]}}
{"rx_ns": 42925081653000, "frame": {"channel":"book","type":"update","data":[{"symbol":"BTC/USD","bids":[],"asks":[{"price":62793.6,"qty":4.78609981}],"checksum":659995938,"timestamp":"2026-08-16T23:37:39.702595Z"}]}}
{"rx_ns": 42925081661600, "frame": {"channel":"book","type":"update","data":[{"symbol":"BTC/USD","bids":[],"asks":[{"price":62791.8,"qty":0.08145194}],"checksum":2242350871,"timestamp":"2026-08-16T23:37:39.702751Z"}]}}
{"rx_ns": 42925081669900, "frame": {"channel":"book","type":"update","data":[{"symbol":"BTC/USD","bids":[],"asks":[{"price":62791.8,"qty":0.16105194}],"checksum":3504772867,"timestamp":"2026-08-16T23:37:39.702910Z"}]}}
{"rx_ns": 42925081679600, "frame": {"channel":"book","type":"update","data":[{"symbol":"BTC/USD","bids":[],"asks":[{"price":62796.6,"qty":0.00000000},{"price":62810.4,"qty":0.13109402},{"price":62793.4,"qty":0.18489680}],"checksum":4088771495,"timestamp":"2026-08-16T23:37:39.703274Z"}]}}
{"rx_ns": 42925081690100, "frame": {"channel":"book","type":"update","data":[{"symbol":"BTC/USD","bids":[],"asks":[{"price":62791.8,"qty":0.95733425}],"checksum":410721376,"timestamp":"2026-08-16T23:37:39.704214Z"}]}}
{"rx_ns": 42925081698900, "frame": {"channel":"book","type":"update","data":[{"symbol":"BTC/USD","bids":[],"asks":[{"price":62802.7,"qty":0.00000000},{"price":62810.4,"qty":0.13109402},{"price":62801.8,"qty":0.00318497}],"checksum":410721376,"timestamp":"2026-08-16T23:37:39.704648Z"}]}}
{"rx_ns": 42925081708900, "frame": {"channel":"book","type":"update","data":[{"symbol":"BTC/USD","bids":[{"price":62791.7,"qty":0.03646524}],"asks":[],"checksum":1415153699,"timestamp":"2026-08-16T23:37:39.704846Z"}]}}
{"rx_ns": 42925085975400, "frame": {"channel":"book","type":"update","data":[{"symbol":"BTC/USD","bids":[],"asks":[{"price":62793.6,"qty":4.70649981}],"checksum":1468185855,"timestamp":"2026-08-16T23:37:39.711171Z"}]}}
{"rx_ns": 42925113037900, "frame": {"channel":"book","type":"update","data":[{"symbol":"BTC/USD","bids":[{"price":62780.5,"qty":0.06101297}],"asks":[],"checksum":1468185855,"timestamp":"2026-08-16T23:37:39.738789Z"}]}}
{"rx_ns": 42925117402800, "frame": {"channel":"book","type":"update","data":[{"symbol":"BTC/USD","bids":[],"asks":[{"price":62793.4,"qty":0.00000000},{"price":62810.4,"qty":0.13109402},{"price":62796.6,"qty":0.18489680}],"checksum":2324392335,"timestamp":"2026-08-16T23:37:39.740178Z"}]}}
{"rx_ns": 42925121663600, "frame": {"channel":"book","type":"update","data":[{"symbol":"BTC/USD","bids":[],"asks":[{"price":62791.8,"qty":1.11661187}],"checksum":3340241787,"timestamp":"2026-08-16T23:37:39.746370Z"}]}}
{"rx_ns": 42925177283400, "frame": {"channel":"book","type":"update","data":[{"symbol":"BTC/USD","bids":[],"asks":[{"price":62793.6,"qty":4.59649981}],"checksum":2073847771,"timestamp":"2026-08-16T23:37:39.802690Z"}]}}
{"rx_ns": 42925178686800, "frame": {"channel":"book","type":"update","data":[{"symbol":"BTC/USD","bids":[],"asks":[{"price":62791.8,"qty":1.22661187}],"checksum":1647664858,"timestamp":"2026-08-16T23:37:39.803386Z"}]}}
{"rx_ns": 42925178742500, "frame": {"channel":"book","type":"update","data":[{"symbol":"BTC/USD","bids":[],"asks":[{"price":62791.8,"qty":1.30461187}],"checksum":2108117186,"timestamp":"2026-08-16T23:37:39.805104Z"}]}}
{"rx_ns": 42925205204300, "frame": {"channel":"book","type":"update","data":[{"symbol":"BTC/USD","bids":[],"asks":[{"price":62794.2,"qty":0.00005100}],"checksum":3847940669,"timestamp":"2026-08-16T23:37:39.830167Z"}]}}
{"rx_ns": 42925215663600, "frame": {"channel":"book","type":"update","data":[{"symbol":"BTC/USD","bids":[{"price":62791.7,"qty":0.03686339}],"asks":[],"checksum":2967582984,"timestamp":"2026-08-16T23:37:39.842035Z"}]}}
{"rx_ns": 42925225650100, "frame": {"channel":"book","type":"update","data":[{"symbol":"BTC/USD","bids":[],"asks":[{"price":62793.6,"qty":0.80565762},{"price":62797.6,"qty":3.79087127}],"checksum":2496475101,"timestamp":"2026-08-16T23:37:39.850717Z"}]}}
{"rx_ns": 42925232839700, "frame": {"channel":"book","type":"update","data":[{"symbol":"BTC/USD","bids":[],"asks":[{"price":62797.6,"qty":0.00000000},{"price":62807.2,"qty":0.02865913},{"price":62791.8,"qty":5.09548326}],"checksum":1271504441,"timestamp":"2026-08-16T23:37:39.857866Z"}]}}
{"rx_ns": 42925241646400, "frame": {"channel":"book","type":"update","data":[{"symbol":"BTC/USD","bids":[{"price":62774.1,"qty":0.00000000},{"price":62773.6,"qty":0.03185600}],"asks":[],"checksum":1271504441,"timestamp":"2026-08-16T23:37:39.864874Z"}]}}
{"rx_ns": 42925246215300, "frame": {"channel":"book","type":"update","data":[{"symbol":"BTC/USD","bids":[{"price":62779.0,"qty":0.00000000},{"price":62773.1,"qty":0.79651925}],"asks":[],"checksum":1271504441,"timestamp":"2026-08-16T23:37:39.865345Z"}]}}
{"rx_ns": 42925246250800, "frame": {"channel":"book","type":"update","data":[{"symbol":"BTC/USD","bids":[],"asks":[{"price":62793.5,"qty":0.11000000},{"price":62793.4,"qty":0.05598472}],"checksum":2664721418,"timestamp":"2026-08-16T23:37:39.867085Z"}]}}
{"rx_ns": 42925246262000, "frame": {"channel":"book","type":"update","data":[{"symbol":"BTC/USD","bids":[{"price":62780.9,"qty":0.00000000},{"price":62772.7,"qty":0.00796524}],"asks":[],"checksum":2664721418,"timestamp":"2026-08-16T23:37:39.870421Z"}]}}
{"rx_ns": 42925259449000, "frame": {"channel":"book","type":"update","data":[{"symbol":"BTC/USD","bids":[{"price":62781.1,"qty":0.00000000},{"price":62772.6,"qty":0.06960000}],"asks":[],"checksum":3413766371,"timestamp":"2026-08-16T23:37:39.876467Z"}]}}
{"rx_ns": 42925271831600, "frame": {"channel":"book","type":"update","data":[{"symbol":"BTC/USD","bids":[{"price":62778.3,"qty":0.00000000},{"price":62772.2,"qty":0.07963741}],"asks":[],"checksum":3413766371,"timestamp":"2026-08-16T23:37:39.882011Z"}]}}
{"rx_ns": 42925271885300, "frame": {"channel":"book","type":"update","data":[{"symbol":"BTC/USD","bids":[{"price":62780.2,"qty":0.79642904}],"asks":[],"checksum":3413766371,"timestamp":"2026-08-16T23:37:39.884548Z"}]}}
{"rx_ns": 42925271897600, "frame": {"channel":"book","type":"update","data":[{"symbol":"BTC/USD","bids":[{"price":62788.1,"qty":0.00000000},{"price":62772.2,"qty":0.07963741}],"asks":[],"checksum":318673332,"timestamp":"2026-08-16T23:37:39.885241Z"}]}}
{"rx_ns": 42925271907700, "frame": {"channel":"book","type":"update","data":[{"symbol":"BTC/USD","bids":[{"price":62780.2,"qty":0.00000000},{"price":62772.0,"qty":0.00318614}],"asks":[],"checksum":318673332,"timestamp":"2026-08-16T23:37:39.885377Z"}]}}
{"rx_ns": 42925271917800, "frame": {"channel":"book","type":"update","data":[{"symbol":"BTC/USD","bids":[],"asks":[{"price":62805.5,"qty":1.59575715}],"checksum":318673332,"timestamp":"2026-08-16T23:37:39.887535Z"}]}}
{"rx_ns": 42925279090500, "frame": {"channel":"book","type":"update","data":[{"symbol":"BTC/USD","bids":[{"price":62777.1,"qty":0.79646752}],"asks":[],"checksum":318673332,"timestamp":"2026-08-16T23:37:39.890512Z"}]}}
{"rx_ns": 42925279138400, "frame": {"channel":"book","type":"update","data":[{"symbol":"BTC/USD","bids":[{"price":62785.0,"qty":0.05598472}],"asks":[],"checksum":3674695736,"timestamp":"2026-08-16T23:37:39.891600Z"}]}}
{"rx_ns": 42925279149500, "frame": {"channel":"book","type":"update","data":[{"symbol":"BTC/USD","bids":[{"price":62776.7,"qty":0.01037554}],"asks":[],"checksum":3674695736,"timestamp":"2026-08-16T23:37:39.892386Z"}]}}
{"rx_ns": 42925279158200, "frame": {"channel":"book","type":"update","data":[{"symbol":"BTC/USD","bids":[{"price":62791.7,"qty":0.03726154}],"asks":[],"checksum":3546013139,"timestamp":"2026-08-16T23:37:39.899575Z"}]}}
{"rx_ns": 42925283886100, "frame": {"channel":"book","type":"update","data":[{"symbol":"BTC/USD","bids":[],"asks":[{"price":62793.5,"qty":0.00000000},{"price":62806.8,"qty":0.00005100}],"checksum":2149974504,"timestamp":"2026-08-16T23:37:39.904141Z"}]}}
{"rx_ns": 42925290246100, "frame": {"channel":"book","type":"update","data":[{"symbol":"BTC/USD","bids":[{"price":62777.1,"qty":0.00000000},{"price":62772.6,"qty":0.06960000}],"asks":[],"checksum":2149974504,"timestamp":"2026-08-16T23:37:39.909802Z"}]}}
{"rx_ns": 42925290295600, "frame": {"channel":"book","type":"update","data":[{"symbol":"BTC/USD","bids":[],"asks":[{"price":62805.5,"qty":0.00000000},{"price":62807.2,"qty":0.02865913}],"checksum":2149974504,"timestamp":"2026-08-16T23:37:39.911565Z"}]}}
{"rx_ns": 42925290309100, "frame": {"channel":"book","type":"update","data":[{"symbol":"BTC/USD","bids":[],"asks":[{"price":62791.8,"qty":5.11625024}],"checksum":2399616079,"timestamp":"2026-08-16T23:37:39.912576Z"}]}}
{"rx_ns": 42925297775000, "frame": {"channel":"book","type":"update","data":[{"symbol":"BTC/USD","bids":[{"price":62791.7,"qty":0.01594862}],"asks":[],"checksum":3773226174,"timestamp":"2026-08-16T23:37:39.921447Z"}]}}
{"rx_ns": 42925299977200, "frame": {"channel":"book","type":"update","data":[{"symbol":"BTC/USD","bids":[{"price":62790.4,"qty":0.02131292}],"asks":[],"checksum":1757913779,"timestamp":"2026-08-16T23:37:39.923416Z"}]}}
{"rx_ns": 42925317691600, "frame": {"channel":"book","type":"update","data":[{"symbol":"BTC/USD","bids":[],"asks":[{"price":62805.5,"qty":1.59575715}],"checksum":1757913779,"timestamp":"2026-08-16T23:37:39.942302Z"}]}}
{"rx_ns": 42925323504300, "frame": {"channel":"book","type":"update","data":[{"symbol":"BTC/USD","bids":[{"price":62778.2,"qty":0.15927762}],"asks":[],"checksum":1757913779,"timestamp":"2026-08-16T23:37:39.944655Z"}]}}
{"rx_ns": 42925334507900, "frame": {"channel":"book","type":"update","data":[{"symbol":"BTC/USD","bids":[{"price":62791.7,"qty":0.01634677}],"asks":[],"checksum":917966638,"timestamp":"2026-08-16T23:37:39.957029Z"}]}}
{"rx_ns": 42925343443200, "frame": {"channel":"book","type":"update","data":[{"symbol":"BTC/USD","bids":[],"asks":[{"price":62797.1,"qty":0.00000000},{"price":62807.2,"qty":0.02865913}],"checksum":103604441,"timestamp":"2026-08-16T23:37:39.965056Z"}]}}
{"rx_ns": 42925360331300, "frame": {"channel":"book","type":"update","data":[{"symbol":"BTC/USD","bids":[{"price":62773.6,"qty":0.00000000},{"price":62772.7,"qty":0.00796524}],"asks":[],"checksum":103604441,"timestamp":"2026-08-16T23:37:39.983431Z"}]}}
{"rx_ns": 42925389783000, "frame": {"channel":"book","type":"update","data":[{"symbol":"BTC/USD","bids":[{"price":62791.7,"qty":0.01674492}],"asks":[],"checksum":1915702950,"timestamp":"2026-08-16T23:37:40.013405Z"}]}}
{"rx_ns": 42925402071600, "frame": {"channel":"book","type":"update","data":[{"symbol":"BTC/USD","bids":[{"price":62779.7,"qty":0.79643526}],"asks":[],"checksum":1915702950,"timestamp":"2026-08-16T23:37:40.018601Z"}]}}
{"rx_ns": 42925402199600, "frame": {"channel":"book","type":"update","data":[{"symbol":"BTC/USD","bids":[{"price":62779.1,"qty":0.06960000}],"asks":[],"checksum":1915702950,"timestamp":"2026-08-16T23:37:40.024698Z"}]}}
{"rx_ns": 42925449003900, "frame": {"channel":"book","type":"update","data":[{"symbol":"BTC/USD","bids":[{"price":62791.7,"qty":0.01714307}],"asks":[],"checksum":2770044821,"timestamp":"2026-08-16T23:37:40.072281Z"}]}}
{"rx_ns": 42925449071200, "frame": {"channel":"book","type":"update","data":[{"symbol":"BTC/USD","bids":[{"price":62774.9,"qty":0.65558669}],"asks":[],"checksum":2770044821,"timestamp":"2026-08-16T23:37:40.073146Z"}]}}
{"rx_ns": 42925449084300, "frame": {"channel":"book","type":"update","data":[{"symbol":"BTC/USD","bids":[],"asks":[{"price":62793.4,"qty":0.00000000},{"price":62808.0,"qty":0.00318430},{"price":62791.8,"qty":5.17223496}],"checksum":3886578281,"timestamp":"2026-08-16T23:37:40.073489Z"}]}}
{"rx_ns": 42925451731200, "frame": {"channel":"book","type":"update","data":[{"symbol":"BTC/USD","bids":[{"price":62778.2,"qty":0.00000000},{"price":62774.0,"qty":0.74369300}],"asks":[],"checksum":3886578281,"timestamp":"2026-08-16T23:37:40.074338Z"}]}}
{"rx_ns": 42925451780700, "frame": {"channel":"book","type":"update","data":[{"symbol":"BTC/USD","bids":[],"asks":[{"price":62796.6,"qty":0.00000000},{"price":62810.4,"qty":0.13109402},{"price":62799.0,"qty":0.18489680}],"checksum":2438922597,"timestamp":"2026-08-16T23:37:40.074785Z"}]}}
{"rx_ns": 42925454004200, "frame": {"channel":"book","type":"update","data":[{"symbol":"BTC/USD","bids":[],"asks":[{"price":62793.6,"qty":0.80525949},{"price":62791.8,"qty":5.17263311}],"checksum":2963904680,"timestamp":"2026-08-16T23:37:40.079635Z"}]}}
{"rx_ns": 42925472466400, "frame": {"channel":"book","type":"update","data":[{"symbol":"BTC/USD","bids":[{"price":62791.7,"qty":0.01674492}],"asks":[],"checksum":1738363291,"timestamp":"2026-08-16T23:37:40.096347Z"}]}}
{"rx_ns": 42925472527100, "frame": {"channel":"book","type":"update","data":[{"symbol":"BTC/USD","bids":[{"price":62778.0,"qty":0.16350086}],"asks":[],"checksum":1738363291,"timestamp":"2026-08-16T23:37:40.096799Z"}]}}
{"rx_ns": 42925474097200, "frame": {"channel":"book","type":"update","data":[{"symbol":"BTC/USD","bids":[{"price":62791.7,"qty":0.00159260},{"price":62791.7,"qty":0.00119445},{"price":62791.7,"qty":0.00079630},{"price":62791.7,"qty":0.00039815},{"price":62791.7,"qty":0.00000092}],"asks":[],"checksum":2063019841,"timestamp":"2026-08-16T23:37:40.098682Z"}]}}
{"rx_ns": 42925482305900, "frame": {"channel":"book","type":"update","data":[{"symbol":"BTC/USD","bids":[],"asks":[{"price":62801.3,"qty":0.00000000},{"price":62810.4,"qty":0.13109402}],"checksum":2063019841,"timestamp":"2026-08-16T23:37:40.105581Z"}]}}
{"rx_ns": 42925482343400, "frame": {"channel":"book","type":"update","data":[{"symbol":"BTC/USD","bids":[],"asks":[{"price":62805.5,"qty":0.00000000},{"price":62810.8,"qty":0.00222509}],"checksum":2063019841,"timestamp":"2026-08-16T23:37:40.106337Z"}]}}
{"rx_ns": 42925482355100, "frame": {"channel":"book","type":"update","data":[{"symbol":"BTC/USD","bids":[],"asks":[{"price":62799.0,"qty":0.00000000},{"price":62810.9,"qty":7.96040350},{"price":62810.3,"qty":0.18489680}],"checksum":232506524,"timestamp":"2026-08-16T23:37:40.107048Z"}]}}
{"rx_ns": 42925486349500, "frame": {"channel":"book","type":"update","data":[{"symbol":"BTC/USD","bids":[],"asks":[{"price":62791.8,"qty":1.38176172}],"checksum":2374695972,"timestamp":"2026-08-16T23:37:40.109986Z"}]}}
{"rx_ns": 42925590582900, "frame": {"channel":"book","type":"update","data":[{"symbol":"BTC/USD","bids":[],"asks":[{"price":62805.5,"qty":1.59575715}],"checksum":2374695972,"timestamp":"2026-08-16T23:37:40.216001Z"}]}}
{"rx_ns": 42925593141500, "frame": {"channel":"book","type":"update","data":[{"symbol":"BTC/USD","bids":[],"asks":[{"price":62810.3,"qty":0.00000000},{"price":62810.8,"qty":0.00222509},{"price":62805.4,"qty":0.18489680}],"checksum":2374695972,"timestamp":"2026-08-16T23:37:40.217374Z"}]}}
{"rx_ns": 42925595165500, "frame": {"channel":"book","type":"update","data":[{"symbol":"BTC/USD","bids":[],"asks":[{"price":62800.8,"qty":0.19620257}],"checksum":2374695972,"timestamp":"2026-08-16T23:37:40.219571Z"}]}}
{"rx_ns": 42925597234900, "frame": {"channel":"book","type":"update","data":[{"symbol":"BTC/USD","bids":[],"asks":[{"price":62800.8,"qty":0.19842766}],"checksum":2374695972,"timestamp":"2026-08-16T23:37:40.220915Z"}]}}
{"rx_ns": 42925604676700, "frame": {"channel":"book","type":"update","data":[{"symbol":"BTC/USD","bids":[],"asks":[{"price":62791.8,"qty":5.17264463}],"checksum":3391432564,"timestamp":"2026-08-16T23:37:40.230040Z"}]}}
{"rx_ns": 42925654132600, "frame": {"channel":"book","type":"update","data":[{"symbol":"BTC/USD","bids":[],"asks":[{"price":62805.6,"qty":0.00000000},{"price":62810.4,"qty":0.13109402}],"checksum":3391432564,"timestamp":"2026-08-16T23:37:40.274992Z"}]}}
{"rx_ns": 42925654174300, "frame": {"channel":"book","type":"update","data":[{"symbol":"BTC/USD","bids":[],"asks":[{"price":62794.8,"qty":0.79624427}],"checksum":2870120382,"timestamp":"2026-08-16T23:37:40.275203Z"}]}}
{"rx_ns": 42925654185400, "frame": {"channel":"book","type":"update","data":[{"symbol":"BTC/USD","bids":[{"price":62774.9,"qty":0.00000000},{"price":62773.1,"qty":0.79651925}],"asks":[],"checksum":2870120382,"timestamp":"2026-08-16T23:37:40.275330Z"}]}}
{"rx_ns": 42925656258900, "frame": {"channel":"book","type":"update","data":[{"symbol":"BTC/USD","bids":[],"asks":[{"price":62805.4,"qty":0.00000000},{"price":62810.9,"qty":7.96040350},{"price":62810.4,"qty":0.31599082}],"checksum":2870120382,"timestamp":"2026-08-16T23:37:40.276525Z"}]}}
{"rx_ns": 42925656301100, "frame": {"channel":"book","type":"update","data":[{"symbol":"BTC/USD","bids":[],"asks":[{"price":62791.8,"qty":5.44164463}],"checksum":690156824,"timestamp":"2026-08-16T23:37:40.278905Z"}]}}
{"rx_ns": 42925656329700, "frame": {"channel":"book","type":"update","data":[{"symbol":"BTC/USD","bids":[{"price":62779.7,"qty":0.00000000},{"price":62772.7,"qty":0.00796524}],"asks":[],"checksum":690156824,"timestamp":"2026-08-16T23:37:40.280995Z"}]}}
{"rx_ns": 42925662670600, "frame": {"channel":"book","type":"update","data":[{"symbol":"BTC/USD","bids":[{"price":62778.8,"qty":0.79644624}],"asks":[],"checksum":690156824,"timestamp":"2026-08-16T23:37:40.282591Z"}]}}
{"rx_ns": 42925662722200, "frame": {"channel":"book","type":"update","data":[{"symbol":"BTC/USD","bids":[],"asks":[{"price":62800.8,"qty":0.19620257},{"price":62810.3,"qty":0.00222509}],"checksum":690156824,"timestamp":"2026-08-16T23:37:40.282698Z"}]}}
{"rx_ns": 42925662734600, "frame": {"channel":"book","type":"update","data":[{"symbol":"BTC/USD","bids":[{"price":62776.8,"qty":0.89978347}],"asks":[],"checksum":690156824,"timestamp":"2026-08-16T23:37:40.282896Z"}]}}
{"rx_ns": 42925662760700, "frame": {"channel":"book","type":"update","data":[{"symbol":"BTC/USD","bids":[{"price":62776.7,"qty":0.00000000},{"price":62772.7,"qty":0.00796524}],"asks":[],"checksum":690156824,"timestamp":"2026-08-16T23:37:40.285786Z"}]}}
{"rx_ns": 42925716173200, "frame": {"channel":"book","type":"update","data":[{"symbol":"BTC/USD","bids":[{"price":62791.7,"qty":0.00000000},{"price":62772.6,"qty":0.06960000}],"asks":[],"checksum":320454299,"timestamp":"2026-08-16T23:37:40.337287Z"}]}}
{"rx_ns": 42925716251000, "frame": {"channel":"book","type":"update","data":[{"symbol":"BTC/USD","bids":[],"asks":[{"price":62791.7,"qty":0.11000000}],"checksum":3908996609,"timestamp":"2026-08-16T23:37:40.338082Z"}]}}
{"rx_ns": 42925716278500, "frame": {"channel":"book","type":"update","data":[{"symbol":"BTC/USD","bids":[],"asks":[{"price":62793.6,"qty":0.00900000}],"checksum":3676949702,"timestamp":"2026-08-16T23:37:40.338420Z"}]}}
{"rx_ns": 42925716289500, "frame": {"channel":"book","type":"update","data":[{"symbol":"BTC/USD","bids":[{"price":62791.2,"qty":0.00159200}],"asks":[],"checksum":2514593829,"timestamp":"2026-08-16T23:37:40.338449Z"}]}}
{"rx_ns": 42925716300700, "frame": {"channel":"book","type":"update","data":[{"symbol":"BTC/USD","bids":[],"asks":[{"price":62800.7,"qty":0.18489680}],"checksum":2514593829,"timestamp":"2026-08-16T23:37:40.338483Z"}]}}
{"rx_ns": 42925716309400, "frame": {"channel":"book","type":"update","data":[{"symbol":"BTC/USD","bids":[],"asks":[{"price":62791.8,"qty":5.38565991},{"price":62791.7,"qty":0.16598472}],"checksum":1363035562,"timestamp":"2026-08-16T23:37:40.338497Z"}]}}
{"rx_ns": 42925716329300, "frame": {"channel":"book","type":"update","data":[{"symbol":"BTC/USD","bids":[],"asks":[{"price":62791.3,"qty":0.06960000}],"checksum":2760898864,"timestamp":"2026-08-16T23:37:40.338510Z"}]}}
{"rx_ns": 42925716337900, "frame": {"channel":"book","type":"update","data":[{"symbol":"BTC/USD","bids":[],"asks":[{"price":62791.8,"qty":5.22638229}],"checksum":307271300,"timestamp":"2026-08-16T23:37:40.338580Z"}]}}
{"rx_ns": 42925716348200, "frame": {"channel":"book","type":"update","data":[{"symbol":"BTC/USD","bids":[],"asks":[{"price":62791.8,"qty":5.15678229}],"checksum":407443951,"timestamp":"2026-08-16T23:37:40.339116Z"}]}}
{"rx_ns": 42925716356300, "frame": {"channel":"book","type":"update","data":[{"symbol":"BTC/USD","bids":[],"asks":[{"price":62791.8,"qty":4.36049998}],"checksum":3955429569,"timestamp":"2026-08-16T23:37:40.339375Z"}]}}
{"rx_ns": 42925716364900, "frame": {"channel":"book","type":"update","data":[{"symbol":"BTC/USD","bids":[],"asks":[{"price":62791.8,"qty":4.33973300}],"checksum":1895754000,"timestamp":"2026-08-16T23:37:40.339499Z"}]}}
{"rx_ns": 42925716375200, "frame": {"channel":"book","type":"update","data":[{"symbol":"BTC/USD","bids":[],"asks":[{"price":62792.3,"qty":0.46828931}],"checksum":758658748,"timestamp":"2026-08-16T23:37:40.339512Z"}]}}
{"rx_ns": 42925716386100, "frame": {"channel":"book","type":"update","data":[{"symbol":"BTC/USD","bids":[{"price":62774.8,"qty":0.46828931}],"asks":[],"checksum":758658748,"timestamp":"2026-08-16T23:37:40.339567Z"}]}}
{"rx_ns": 42925716395300, "frame": {"channel":"book","type":"update","data":[{"symbol":"BTC/USD","bids":[],"asks":[{"price":62805.6,"qty":0.46828931}],"checksum":758658748,"timestamp":"2026-08-16T23:37:40.339637Z"}]}}
{"rx_ns": 42925716403800, "frame": {"channel":"book","type":"update","data":[{"symbol":"BTC/USD","bids":[],"asks":[{"price":62791.7,"qty":0.24558472}],"checksum":81208305,"timestamp":"2026-08-16T23:37:40.339811Z"}]}}
{"rx_ns": 42925718386900, "frame": {"channel":"book","type":"update","data":[{"symbol":"BTC/USD","bids":[],"asks":[{"price":62791.7,"qty":0.32358472}],"checksum":3540620598,"timestamp":"2026-08-16T23:37:40.339882Z"}]}}
{"rx_ns": 42925718429600, "frame": {"channel":"book","type":"update","data":[{"symbol":"BTC/USD","bids":[],"asks":[{"price":62791.8,"qty":4.26173300}],"checksum":1676821098,"timestamp":"2026-08-16T23:37:40.339952Z"}]}}
{"rx_ns": 42925718443400, "frame": {"channel":"book","type":"update","data":[{"symbol":"BTC/USD","bids":[],"asks":[{"price":62791.3,"qty":0.14760000}],"checksum":261477611,"timestamp":"2026-08-16T23:37:40.340052Z"}]}}
{"rx_ns": 42925718456400, "frame": {"channel":"book","type":"update","data":[{"symbol":"BTC/USD","bids":[],"asks":[{"price":62791.7,"qty":0.24398472}],"checksum":3521529220,"timestamp":"2026-08-16T23:37:40.340148Z"}]}}
{"rx_ns": 42925718467600, "frame": {"channel":"book","type":"update","data":[{"symbol":"BTC/USD","bids":[],"asks":[{"price":62791.8,"qty":4.18213300}],"checksum":514637132,"timestamp":"2026-08-16T23:37:40.340220Z"}]}}
{"rx_ns": 42925718477000, "frame": {"channel":"book","type":"update","data":[{"symbol":"BTC/USD","bids":[],"asks":[{"price":62791.3,"qty":0.22720000}],"checksum":2081597679,"timestamp":"2026-08-16T23:37:40.340235Z"}]}}
{"rx_ns": 42925718487400, "frame": {"channel":"book","type":"update","data":[{"symbol":"BTC/USD","bids":[],"asks":[{"price":62791.7,"qty":0.16598472}],"checksum":1548786186,"timestamp":"2026-08-16T23:37:40.340556Z"}]}}
{"rx_ns": 42925718495500, "frame": {"channel":"book","type":"update","data":[{"symbol":"BTC/USD","bids":[],"asks":[{"price":62791.8,"qty":4.17048008}],"checksum":2175776341,"timestamp":"2026-08-16T23:37:40.340824Z"}]}}
{"rx_ns": 42925718503900, "frame": {"channel":"book","type":"update","data":[{"symbol":"BTC/USD","bids":[],"asks":[{"price":62791.6,"qty":0.79628485}],"checksum":1960831144,"timestamp":"2026-08-16T23:37:40.340983Z"}]}}
{"rx_ns": 42925718512900, "frame": {"channel":"book","type":"update","data":[{"symbol":"BTC/USD","bids":[{"price":62791.2,"qty":0.01674406}],"asks":[],"checksum":1610156619,"timestamp":"2026-08-16T23:37:40.341008Z"}]}}
{"rx_ns": 42925718520900, "frame": {"channel":"book","type":"update","data":[{"symbol":"BTC/USD","bids":[],"asks":[{"price":62791.8,"qty":4.17028106}],"checksum":900183268,"timestamp":"2026-08-16T23:37:40.341170Z"}]}}
{"rx_ns": 42925718529100, "frame": {"channel":"book","type":"update","data":[{"symbol":"BTC/USD","bids":[],"asks":[{"price":62792.4,"qty":0.79627492}],"checksum":1124412163,"timestamp":"2026-08-16T23:37:40.341278Z"}]}}
{"rx_ns": 42925720520700, "frame": {"channel":"book","type":"update","data":[{"symbol":"BTC/USD","bids":[],"asks":[{"price":62791.3,"qty":0.29664450}],"checksum":2030218429,"timestamp":"2026-08-16T23:37:40.341867Z"}]}}
{"rx_ns": 42925724204900, "frame": {"channel":"book","type":"update","data":[{"symbol":"BTC/USD","bids":[],"asks":[{"price":62791.3,"qty":0.30849750}],"checksum":3185453586,"timestamp":"2026-08-16T23:37:40.345695Z"}]}}
{"rx_ns": 42925724226800, "frame": {"channel":"book","type":"update","data":[{"symbol":"BTC/USD","bids":[],"asks":[{"price":62791.3,"qty":0.46777958}],"checksum":1131500464,"timestamp":"2026-08-16T23:37:40.346222Z"}]}}
{"rx_ns": 42925751672700, "frame": {"channel":"heartbeat"}}
{"rx_ns": 42925770854900, "frame": {"channel":"book","type":"update","data":[{"symbol":"BTC/USD","bids":[{"price":62778.8,"qty":0.00000000},{"price":62772.6,"qty":0.06960000}],"asks":[],"checksum":1131500464,"timestamp":"2026-08-16T23:37:40.367538Z"}]}}
{"rx_ns": 42925770914300, "frame": {"channel":"book","type":"update","data":[{"symbol":"BTC/USD","bids":[],"asks":[{"price":62800.7,"qty":0.00000000},{"price":62805.5,"qty":1.59575715},{"price":62796.6,"qty":0.18489680}],"checksum":1131500464,"timestamp":"2026-08-16T23:37:40.370108Z"}]}}
{"rx_ns": 42925770927000, "frame": {"channel":"book","type":"update","data":[{"symbol":"BTC/USD","bids":[],"asks":[{"price":62793.6,"qty":0.00800000}],"checksum":1950458168,"timestamp":"2026-08-16T23:37:40.371352Z"}]}}
{"rx_ns": 42925772584900, "frame": {"channel":"book","type":"update","data":[{"symbol":"BTC/USD","bids":[{"price":62776.8,"qty":0.10331161}],"asks":[],"checksum":1950458168,"timestamp":"2026-08-16T23:37:40.398036Z"}]}}
{"rx_ns": 42925777016700, "frame": {"channel":"book","type":"update","data":[{"symbol":"BTC/USD","bids":[{"price":62780.1,"qty":0.79642992}],"asks":[],"checksum":1950458168,"timestamp":"2026-08-16T23:37:40.399417Z"}]}}
{"rx_ns": 42925777078800, "frame": {"channel":"book","type":"update","data":[{"symbol":"BTC/USD","bids":[{"price":62785.0,"qty":0.00000000},{"price":62772.6,"qty":0.06960000},{"price":62788.1,"qty":0.05598472}],"asks":[],"checksum":1681865187,"timestamp":"2026-08-16T23:37:40.399697Z"}]}}
{"rx_ns": 42925777094900, "frame": {"channel":"book","type":"update","data":[{"symbol":"BTC/USD","bids":[],"asks":[{"price":62791.7,"qty":0.11000000},{"price":62792.2,"qty":0.05598472}],"checksum":2238506126,"timestamp":"2026-08-16T23:37:40.399746Z"}]}}
{"rx_ns": 42925784415400, "frame": {"channel":"book","type":"update","data":[{"symbol":"BTC/USD","bids":[{"price":62775.0,"qty":0.01020752}],"asks":[],"checksum":2238506126,"timestamp":"2026-08-16T23:37:40.404043Z"}]}}
{"rx_ns": 42925812620200, "frame": {"channel":"book","type":"update","data":[{"symbol":"BTC/USD","bids":[],"asks":[{"price":62791.8,"qty":4.06028106}],"checksum":3749819463,"timestamp":"2026-08-16T23:37:40.438553Z"}]}}
{"rx_ns": 42925826011100, "frame": {"channel":"book","type":"update","data":[{"symbol":"BTC/USD","bids":[{"price":62791.2,"qty":0.01714221}],"asks":[],"checksum":3753061460,"timestamp":"2026-08-16T23:37:40.450122Z"}]}}
{"rx_ns": 42925873970300, "frame": {"channel":"book","type":"update","data":[{"symbol":"BTC/USD","bids":[],"asks":[{"price":62791.8,"qty":0.26939815},{"price":62791.3,"qty":4.25868206}],"checksum":4138607178,"timestamp":"2026-08-16T23:37:40.491040Z"}]}}
{"rx_ns": 42925884137800, "frame": {"channel":"book","type":"update","data":[{"symbol":"BTC/USD","bids":[{"price":62791.2,"qty":0.01754036}],"asks":[],"checksum":1696178996,"timestamp":"2026-08-16T23:37:40.505906Z"}]}}
{"rx_ns": 42925930218200, "frame": {"channel":"book","type":"update","data":[{"symbol":"BTC/USD","bids":[],"asks":[{"price":62791.3,"qty":4.27781554}],"checksum":3458916970,"timestamp":"2026-08-16T23:37:40.556316Z"}]}}
{"rx_ns": 42925943709500, "frame": {"channel":"book","type":"update","data":[{"symbol":"BTC/USD","bids":[{"price":62791.2,"qty":0.01793851}],"asks":[],"checksum":2324819886,"timestamp":"2026-08-16T23:37:40.563664Z"}]}}
{"rx_ns": 42925952842500, "frame": {"channel":"book","type":"update","data":[{"symbol":"BTC/USD","bids":[],"asks":[{"price":62791.8,"qty":0.26900000},{"price":62791.3,"qty":4.27821369}],"checksum":483201873,"timestamp":"2026-08-16T23:37:40.573800Z"}]}}
{"rx_ns": 42925973008300, "frame": {"channel":"book","type":"update","data":[{"symbol":"BTC/USD","bids":[{"price":62791.2,"qty":0.01754036}],"asks":[],"checksum":1484136085,"timestamp":"2026-08-16T23:37:40.587931Z"}]}}
{"rx_ns": 42926044782600, "frame": {"channel":"book","type":"update","data":[{"symbol":"BTC/USD","bids":[{"price":62791.2,"qty":0.01714221}],"asks":[],"checksum":3418464235,"timestamp":"2026-08-16T23:37:40.649890Z"}]}}
{"rx_ns": 42926323548900, "frame": {"channel":"book","type":"update","data":[{"symbol":"BTC/USD","bids":[{"price":62778.0,"qty":0.00422324}],"asks":[],"checksum":3418464235,"timestamp":"2026-08-16T23:37:40.944414Z"}]}}
{"rx_ns": 42926326842000, "frame": {"channel":"book","type":"update","data":[{"symbol":"BTC/USD","bids":[{"price":62777.9,"qty":0.15928208}],"asks":[],"checksum":3418464235,"timestamp":"2026-08-16T23:37:40.946574Z"}]}}
{"rx_ns": 42926392436200, "frame": {"channel":"book","type":"update","data":[{"symbol":"BTC/USD","bids":[],"asks":[{"price":62794.2,"qty":0.00000000},{"price":62803.7,"qty":0.00005100}],"checksum":3667834091,"timestamp":"2026-08-16T23:37:40.986079Z"}]}}
{"rx_ns": 42926409093700, "frame": {"channel":"book","type":"update","data":[{"symbol":"BTC/USD","bids":[{"price":62791.2,"qty":0.01724221}],"asks":[],"checksum":280341157,"timestamp":"2026-08-16T23:37:41.018446Z"}]}}
{"rx_ns": 42926466760900, "frame": {"channel":"book","type":"update","data":[{"symbol":"BTC/USD","bids":[{"price":62791.2,"qty":0.01565021},{"price":62791.2,"qty":0.01534221}],"asks":[],"checksum":21505966,"timestamp":"2026-08-16T23:37:41.083592Z"}]}}
{"rx_ns": 42926564312400, "frame": {"channel":"book","type":"update","data":[{"symbol":"BTC/USD","bids":[{"price":62777.9,"qty":0.95573946}],"asks":[],"checksum":21505966,"timestamp":"2026-08-16T23:37:41.174196Z"}]}}
{"rx_ns": 42926570675100, "frame": {"channel":"book","type":"update","data":[{"symbol":"BTC/USD","bids":[{"price":62775.0,"qty":0.00000000},{"price":62773.1,"qty":0.79651925}],"asks":[],"checksum":21505966,"timestamp":"2026-08-16T23:37:41.177071Z"}]}}
{"rx_ns": 42926755501000, "frame": {"channel":"heartbeat"}}
{"rx_ns": 42926816934900, "frame": {"channel":"book","type":"update","data":[{"symbol":"BTC/USD","bids":[],"asks":[{"price":62791.3,"qty":4.27921369}],"checksum":647521170,"timestamp":"2026-08-16T23:37:41.438542Z"}]}}
{"rx_ns": 42926817013300, "frame": {"channel":"book","type":"update","data":[{"symbol":"BTC/USD","bids":[],"asks":[{"price":62791.3,"qty":4.20121369}],"checksum":261096058,"timestamp":"2026-08-16T23:37:41.440266Z"}]}}
{"rx_ns": 42926817039700, "frame": {"channel":"book","type":"update","data":[{"symbol":"BTC/USD","bids":[{"price":62783.2,"qty":0.00000000},{"price":62772.7,"qty":0.00796524},{"price":62781.8,"qty":0.00318497}],"asks":[],"checksum":1390939081,"timestamp":"2026-08-16T23:37:41.441568Z"}]}}
{"rx_ns": 42926817053600, "frame": {"channel":"book","type":"update","data":[{"symbol":"BTC/USD","bids":[],"asks":[{"price":62801.8,"qty":0.00000000},{"price":62805.5,"qty":1.59575715},{"price":62801.3,"qty":0.00318497}],"checksum":1390939081,"timestamp":"2026-08-16T23:37:41.441883Z"}]}}
{"rx_ns": 42926912953300, "frame": {"channel":"book","type":"update","data":[{"symbol":"BTC/USD","bids":[{"price":62788.1,"qty":0.00000000},{"price":62772.7,"qty":0.00796524}],"asks":[],"checksum":497105662,"timestamp":"2026-08-16T23:37:41.534207Z"}]}}
{"rx_ns": 42926913037300, "frame": {"channel":"book","type":"update","data":[{"symbol":"BTC/USD","bids":[{"price":62785.0,"qty":0.05598472}],"asks":[],"checksum":1117164306,"timestamp":"2026-08-16T23:37:41.535486Z"}]}}
{"rx_ns": 42926913102400, "frame": {"channel":"book","type":"update","data":[{"symbol":"BTC/USD","bids":[],"asks":[{"price":62792.2,"qty":0.00000000},{"price":62805.5,"qty":1.59575715},{"price":62791.3,"qty":4.25719841}],"checksum":2174995255,"timestamp":"2026-08-16T23:37:41.535585Z"}]}}
{"rx_ns": 42926913336200, "frame": {"channel":"book","type":"update","data":[{"symbol":"BTC/USD","bids":[],"asks":[{"price":62791.3,"qty":4.33519841}],"checksum":3976925027,"timestamp":"2026-08-16T23:37:41.537605Z"}]}}
{"rx_ns": 42927557249500, "frame": {"channel":"book","type":"update","data":[{"symbol":"BTC/USD","bids":[{"price":62780.1,"qty":0.00000000},{"price":62772.7,"qty":0.00796524}],"asks":[],"checksum":3976925027,"timestamp":"2026-08-16T23:37:42.183097Z"}]}}
{"rx_ns": 42927559732300, "frame": {"channel":"book","type":"update","data":[{"symbol":"BTC/USD","bids":[{"price":62780.7,"qty":0.79642261}],"asks":[],"checksum":2379088104,"timestamp":"2026-08-16T23:37:42.185445Z"}]}}
{"rx_ns": 42927565226900, "frame": {"channel":"book","type":"update","data":[{"symbol":"BTC/USD","bids":[{"price":62775.6,"qty":0.01031774}],"asks":[],"checksum":2379088104,"timestamp":"2026-08-16T23:37:42.186099Z"}]}}
{"rx_ns": 42927565292900, "frame": {"channel":"book","type":"update","data":[{"symbol":"BTC/USD","bids":[{"price":62775.6,"qty":0.00000000},{"price":62773.1,"qty":0.79651925}],"asks":[],"checksum":2379088104,"timestamp":"2026-08-16T23:37:42.188696Z"}]}}
{"rx_ns": 42927566642400, "frame": {"channel":"book","type":"update","data":[{"symbol":"BTC/USD","bids":[{"price":62785.0,"qty":0.00000000},{"price":62772.7,"qty":0.00796524},{"price":62788.1,"qty":0.05598472}],"asks":[],"checksum":2631890220,"timestamp":"2026-08-16T23:37:42.190838Z"}]}}
{"rx_ns": 42927566699400, "frame": {"channel":"book","type":"update","data":[{"symbol":"BTC/USD","bids":[],"asks":[{"price":62791.3,"qty":4.27921369},{"price":62792.2,"qty":0.05598472}],"checksum":361417521,"timestamp":"2026-08-16T23:37:42.190910Z"}]}}
{"rx_ns": 42927570074400, "frame": {"channel":"book","type":"update","data":[{"symbol":"BTC/USD","bids":[],"asks":[{"price":62791.3,"qty":4.20121369}],"checksum":3144853786,"timestamp":"2026-08-16T23:37:42.193696Z"}]}}
{"rx_ns": 42927575491700, "frame": {"channel":"book","type":"update","data":[{"symbol":"BTC/USD","bids":[],"asks":[{"price":62791.3,"qty":4.13176919}],"checksum":3836476284,"timestamp":"2026-08-16T23:37:42.196444Z"}]}}
{"rx_ns": 42927577152400, "frame": {"channel":"book","type":"update","data":[{"symbol":"BTC/USD","bids":[],"asks":[{"price":62796.6,"qty":0.00000000},{"price":62805.5,"qty":1.59575715},{"price":62799.0,"qty":0.18489680}],"checksum":3836476284,"timestamp":"2026-08-16T23:37:42.197709Z"}]}}
{"rx_ns": 42927753950100, "frame": {"channel":"heartbeat"}}
{"rx_ns": 42928013618300, "frame": {"channel":"book","type":"update","data":[{"symbol":"BTC/USD","bids":[],"asks":[{"price":62801.9,"qty":0.03097706}],"checksum":3836476284,"timestamp":"2026-08-16T23:37:42.638089Z"}]}}
{"rx_ns": 42928159345600, "frame": {"channel":"book","type":"update","data":[{"symbol":"BTC/USD","bids":[{"price":62777.9,"qty":0.79645738}],"asks":[],"checksum":3836476284,"timestamp":"2026-08-16T23:37:42.778430Z"}]}}
{"rx_ns": 42928176682200, "frame": {"channel":"book","type":"update","data":[{"symbol":"BTC/USD","bids":[{"price":62778.6,"qty":0.24745577}],"asks":[],"checksum":3836476284,"timestamp":"2026-08-16T23:37:42.796330Z"}]}}
{"rx_ns": 42928249418200, "frame": {"channel":"book","type":"update","data":[{"symbol":"BTC/USD","bids":[{"price":62777.9,"qty":0.00000000},{"price":62772.7,"qty":0.00796524}],"asks":[],"checksum":3836476284,"timestamp":"2026-08-16T23:37:42.866418Z"}]}}
{"rx_ns": 42928253323600, "frame": {"channel":"book","type":"update","data":[{"symbol":"BTC/USD","bids":[],"asks":[{"price":62791.3,"qty":4.06216919}],"checksum":1902995337,"timestamp":"2026-08-16T23:37:42.866484Z"}]}}
{"rx_ns": 42928253399600, "frame": {"channel":"book","type":"update","data":[{"symbol":"BTC/USD","bids":[{"price":62779.0,"qty":0.79644427}],"asks":[],"checksum":1902995337,"timestamp":"2026-08-16T23:37:42.867916Z"}]}}
{"rx_ns": 42928253414300, "frame": {"channel":"book","type":"update","data":[{"symbol":"BTC/USD","bids":[{"price":62778.6,"qty":0.08817369}],"asks":[],"checksum":1902995337,"timestamp":"2026-08-16T23:37:42.867990Z"}]}}
{"rx_ns": 42928253435000, "frame": {"channel":"book","type":"update","data":[{"symbol":"BTC/USD","bids":[{"price":62778.0,"qty":0.01462836}],"asks":[],"checksum":1902995337,"timestamp":"2026-08-16T23:37:42.870270Z"}]}}
{"rx_ns": 42928255228200, "frame": {"channel":"book","type":"update","data":[{"symbol":"BTC/USD","bids":[{"price":62778.0,"qty":0.00422324}],"asks":[],"checksum":1902995337,"timestamp":"2026-08-16T23:37:42.871255Z"}]}}
{"rx_ns": 42928265631800, "frame": {"channel":"book","type":"update","data":[{"symbol":"BTC/USD","bids":[{"price":62780.7,"qty":0.00000000},{"price":62772.7,"qty":0.00796524}],"asks":[],"checksum":4158919224,"timestamp":"2026-08-16T23:37:42.880556Z"}]}}
{"rx_ns": 42928268334000, "frame": {"channel":"book","type":"update","data":[{"symbol":"BTC/USD","bids":[{"price":62773.1,"qty":0.00000000},{"price":62772.6,"qty":0.06960000}],"asks":[],"checksum":4158919224,"timestamp":"2026-08-16T23:37:42.880955Z"}]}}
{"rx_ns": 42928269666700, "frame": {"channel":"book","type":"update","data":[{"symbol":"BTC/USD","bids":[{"price":62781.6,"qty":0.79641162}],"asks":[],"checksum":3037433,"timestamp":"2026-08-16T23:37:42.883016Z"}]}}
{"rx_ns": 42928269710200, "frame": {"channel":"book","type":"update","data":[{"symbol":"BTC/USD","bids":[{"price":62775.6,"qty":0.79648738}],"asks":[],"checksum":3037433,"timestamp":"2026-08-16T23:37:42.883301Z"}]}}
{"rx_ns": 42928269723000, "frame": {"channel":"book","type":"update","data":[{"symbol":"BTC/USD","bids":[{"price":62778.0,"qty":0.01462836}],"asks":[],"checksum":3037433,"timestamp":"2026-08-16T23:37:42.883344Z"}]}}
{"rx_ns": 42928276149800, "frame": {"channel":"book","type":"update","data":[{"symbol":"BTC/USD","bids":[{"price":62778.0,"qty":0.00422324}],"asks":[],"checksum":3037433,"timestamp":"2026-08-16T23:37:42.886733Z"}]}}
{"rx_ns": 42928283220100, "frame": {"channel":"book","type":"update","data":[{"symbol":"BTC/USD","bids":[{"price":62779.0,"qty":0.95572635}],"asks":[],"checksum":3037433,"timestamp":"2026-08-16T23:37:42.896527Z"}]}}
{"rx_ns": 42928354477700, "frame": {"channel":"book","type":"update","data":[{"symbol":"BTC/USD","bids":[{"price":62778.0,"qty":0.00740907}],"asks":[],"checksum":3037433,"timestamp":"2026-08-16T23:37:42.979509Z"}]}}
{"rx_ns": 42928402518600, "frame": {"channel":"book","type":"update","data":[{"symbol":"BTC/USD","bids":[],"asks":[{"price":62800.8,"qty":0.00000000},{"price":62803.7,"qty":0.00005100}],"checksum":3037433,"timestamp":"2026-08-16T23:37:43.025629Z"}]}}
{"rx_ns": 42928486706100, "frame": {"channel":"book","type":"update","data":[{"symbol":"BTC/USD","bids":[{"price":62779.1,"qty":0.08000431}],"asks":[],"checksum":3037433,"timestamp":"2026-08-16T23:37:43.110660Z"}]}}
{"rx_ns": 42928515953400, "frame": {"channel":"book","type":"update","data":[{"symbol":"BTC/USD","bids":[],"asks":[{"price":62801.3,"qty":0.19938754}],"checksum":3037433,"timestamp":"2026-08-16T23:37:43.141309Z"}]}}
{"rx_ns": 42928751489900, "frame": {"channel":"heartbeat"}}
{"rx_ns": 42928759754700, "frame": {"channel":"book","type":"update","data":[{"symbol":"BTC/USD","bids":[],"asks":[{"price":62799.1,"qty":0.00000000},{"price":62805.6,"qty":0.46828931}],"checksum":3037433,"timestamp":"2026-08-16T23:37:43.371769Z"}]}}
{"rx_ns": 42928759809800, "frame": {"channel":"book","type":"update","data":[{"symbol":"BTC/USD","bids":[],"asks":[{"price":62802.4,"qty":0.06000000}],"checksum":3037433,"timestamp":"2026-08-16T23:37:43.371976Z"}]}}
{"rx_ns": 42928759827800, "frame": {"channel":"book","type":"update","data":[{"symbol":"BTC/USD","bids":[],"asks":[{"price":62799.0,"qty":0.00000000},{"price":62805.6,"qty":0.46828931},{"price":62800.8,"qty":0.18489680}],"checksum":3037433,"timestamp":"2026-08-16T23:37:43.372955Z"}]}}
{"rx_ns": 42929751472400, "frame": {"channel":"heartbeat"}}
{"rx_ns": 42930527251700, "frame": {"channel":"book","type":"update","data":[{"symbol":"BTC/USD","bids":[],"asks":[{"price":62791.3,"qty":4.06201926}],"checksum":4116625613,"timestamp":"2026-08-16T23:37:45.146951Z"}]}}
{"rx_ns": 42930529307800, "frame": {"channel":"book","type":"update","data":[{"symbol":"BTC/USD","bids":[],"asks":[{"price":62791.3,"qty":4.14001926}],"checksum":2432504321,"timestamp":"2026-08-16T23:37:45.150387Z"}]}}
{"rx_ns": 42930755580000, "frame": {"channel":"heartbeat"}}
{"rx_ns": 42931751188800, "frame": {"channel":"heartbeat"}}
{"rx_ns": 42932138443100, "frame": {"channel":"book","type":"update","data":[{"symbol":"BTC/USD","bids":[{"price":62781.6,"qty":0.00000000},{"price":62773.7,"qty":0.03185598}],"asks":[],"checksum":2612230967,"timestamp":"2026-08-16T23:37:46.763838Z"}]}}
{"rx_ns": 42932139126100, "frame": {"channel":"book","type":"update","data":[{"symbol":"BTC/USD","bids":[{"price":62779.0,"qty":0.15928208}],"asks":[],"checksum":2612230967,"timestamp":"2026-08-16T23:37:46.763931Z"}]}}
{"rx_ns": 42932140772900, "frame": {"channel":"book","type":"update","data":[{"symbol":"BTC/USD","bids":[{"price":62782.3,"qty":0.79640177}],"asks":[],"checksum":665890636,"timestamp":"2026-08-16T23:37:46.765548Z"}]}}
{"rx_ns": 42932140807400, "frame": {"channel":"book","type":"update","data":[{"symbol":"BTC/USD","bids":[{"price":62780.2,"qty":0.79642925}],"asks":[],"checksum":665890636,"timestamp":"2026-08-16T23:37:46.765886Z"}]}}
{"rx_ns": 42932445265400, "frame": {"channel":"book","type":"update","data":[{"symbol":"BTC/USD","bids":[],"asks":[{"price":62792.3,"qty":0.00000000},{"price":62804.0,"qty":0.13109402}],"checksum":3071886888,"timestamp":"2026-08-16T23:37:47.066992Z"}]}}
{"rx_ns": 42932445308200, "frame": {"channel":"book","type":"update","data":[{"symbol":"BTC/USD","bids":[],"asks":[{"price":62791.3,"qty":3.98073718}],"checksum":2794503,"timestamp":"2026-08-16T23:37:47.067184Z"}]}}
{"rx_ns": 42932447897500, "frame": {"channel":"book","type":"update","data":[{"symbol":"BTC/USD","bids":[],"asks":[{"price":62791.3,"qty":3.90273718}],"checksum":1286414513,"timestamp":"2026-08-16T23:37:47.070032Z"}]}}
{"rx_ns": 42932447935300, "frame": {"channel":"book","type":"update","data":[{"symbol":"BTC/USD","bids":[],"asks":[{"price":62792.2,"qty":0.00000000},{"price":62805.6,"qty":0.46828931},{"price":62792.3,"qty":0.05598472}],"checksum":365014320,"timestamp":"2026-08-16T23:37:47.070176Z"}]}}
{"rx_ns": 42932497721700, "frame": {"channel":"book","type":"update","data":[{"symbol":"BTC/USD","bids":[],"asks":[{"price":62791.3,"qty":4.06201926}],"checksum":2346082661,"timestamp":"2026-08-16T23:37:47.123472Z"}]}}
{"rx_ns": 42932501695500, "frame": {"channel":"book","type":"update","data":[{"symbol":"BTC/USD","bids":[],"asks":[{"price":62791.3,"qty":4.14001926}],"checksum":4000697257,"timestamp":"2026-08-16T23:37:47.127333Z"}]}}
{"rx_ns": 42932761514700, "frame": {"channel":"heartbeat"}}
{"rx_ns": 42932852265300, "frame": {"channel":"book","type":"update","data":[{"symbol":"BTC/USD","bids":[],"asks":[{"price":62796.7,"qty":0.00000000},{"price":62805.6,"qty":0.46828931}],"checksum":1818694345,"timestamp":"2026-08-16T23:37:47.477347Z"}]}}
{"rx_ns": 42932860303200, "frame": {"channel":"book","type":"update","data":[{"symbol":"BTC/USD","bids":[],"asks":[{"price":62799.1,"qty":0.50933400}],"checksum":1818694345,"timestamp":"2026-08-16T23:37:47.479508Z"}]}}
{"rx_ns": 42932860359700, "frame": {"channel":"book","type":"update","data":[{"symbol":"BTC/USD","bids":[{"price":62782.3,"qty":0.00000000},{"price":62774.0,"qty":0.74369300}],"asks":[],"checksum":1222293778,"timestamp":"2026-08-16T23:37:47.481592Z"}]}}
{"rx_ns": 42932868280000, "frame": {"channel":"book","type":"update","data":[{"symbol":"BTC/USD","bids":[{"price":62783.1,"qty":0.79639225}],"asks":[],"checksum":3503003054,"timestamp":"2026-08-16T23:37:47.483113Z"}]}}
{"rx_ns": 42932946687300, "frame": {"channel":"book","type":"update","data":[{"symbol":"BTC/USD","bids":[{"price":62775.4,"qty":0.03185507}],"asks":[],"checksum":3503003054,"timestamp":"2026-08-16T23:37:47.572863Z"}]}}
{"rx_ns": 42932988354200, "frame": {"channel":"book","type":"update","data":[{"symbol":"BTC/USD","bids":[],"asks":[{"price":62801.3,"qty":0.00318497}],"checksum":3503003054,"timestamp":"2026-08-16T23:37:47.614400Z"}]}}
{"rx_ns": 42933035159300, "frame": {"channel":"book","type":"update","data":[{"symbol":"BTC/USD","bids":[],"asks":[{"price":62799.1,"qty":0.00000000},{"price":62805.5,"qty":0.19620257}],"checksum":3503003054,"timestamp":"2026-08-16T23:37:47.659480Z"}]}}
{"rx_ns": 42933035236100, "frame": {"channel":"book","type":"update","data":[{"symbol":"BTC/USD","bids":[],"asks":[{"price":62795.4,"qty":0.50933300}],"checksum":2417761487,"timestamp":"2026-08-16T23:37:47.660358Z"}]}}
{"rx_ns": 42933755558200, "frame": {"channel":"heartbeat"}}
{"rx_ns": 42933760215100, "frame": {"channel":"book","type":"update","data":[{"symbol":"BTC/USD","bids":[],"asks":[{"price":62801.3,"qty":0.19938754}],"checksum":2417761487,"timestamp":"2026-08-16T23:37:48.385458Z"}]}}
{"rx_ns": 42933760269600, "frame": {"channel":"book","type":"update","data":[{"symbol":"BTC/USD","bids":[{"price":62783.1,"qty":0.00000000},{"price":62774.2,"qty":0.02867420}],"asks":[],"checksum":1079557880,"timestamp":"2026-08-16T23:37:48.385734Z"}]}}
{"rx_ns": 42933766933300, "frame": {"channel":"book","type":"update","data":[{"symbol":"BTC/USD","bids":[{"price":62781.6,"qty":0.79641163}],"asks":[],"checksum":3975812723,"timestamp":"2026-08-16T23:37:48.387190Z"}]}}
{"rx_ns": 42934383714300, "frame": {"channel":"book","type":"update","data":[{"symbol":"BTC/USD","bids":[{"price":62775.4,"qty":0.00000000},{"price":62774.2,"qty":0.02867420}],"asks":[],"checksum":3975812723,"timestamp":"2026-08-16T23:37:49.008425Z"}]}}
{"rx_ns": 42934758333800, "frame": {"channel":"heartbeat"}}
{"rx_ns": 42935288101500, "frame": {"channel":"book","type":"update","data":[{"symbol":"BTC/USD","bids":[],"asks":[{"price":62794.1,"qty":0.46828931}],"checksum":347180296,"timestamp":"2026-08-16T23:37:49.911196Z"}]}}
{"rx_ns": 42935448934600, "frame": {"channel":"book","type":"update","data":[{"symbol":"BTC/USD","bids":[{"price":62781.6,"qty":0.00000000},{"price":62774.0,"qty":0.74369300}],"asks":[],"checksum":1768795173,"timestamp":"2026-08-16T23:37:50.072055Z"}]}}
{"rx_ns": 42935449009700, "frame": {"channel":"book","type":"update","data":[{"symbol":"BTC/USD","bids":[{"price":62782.3,"qty":0.79640231}],"asks":[],"checksum":1708808869,"timestamp":"2026-08-16T23:37:50.074516Z"}]}}
{"rx_ns": 42935529180500, "frame": {"channel":"book","type":"update","data":[{"symbol":"BTC/USD","bids":[],"asks":[{"price":62793.6,"qty":0.00000000},{"price":62804.0,"qty":0.13109402},{"price":62791.3,"qty":4.14801926}],"checksum":177492051,"timestamp":"2026-08-16T23:37:50.110773Z"}]}}
{"rx_ns": 42935625857800, "frame": {"channel":"book","type":"update","data":[{"symbol":"BTC/USD","bids":[{"price":62779.0,"qty":0.00000000},{"price":62774.0,"qty":0.74369300}],"asks":[],"checksum":177492051,"timestamp":"2026-08-16T23:37:50.236721Z"}]}}
{"rx_ns": 42935625924400, "frame": {"channel":"book","type":"update","data":[{"symbol":"BTC/USD","bids":[{"price":62774.8,"qty":0.00000000},{"price":62773.7,"qty":0.07963767}],"asks":[],"checksum":177492051,"timestamp":"2026-08-16T23:37:50.236944Z"}]}}
{"rx_ns": 42935718820300, "frame": {"channel":"book","type":"update","data":[{"symbol":"BTC/USD","bids":[{"price":62779.0,"qty":0.15928208}],"asks":[],"checksum":177492051,"timestamp":"2026-08-16T23:37:50.334876Z"}]}}
{"rx_ns": 42935768643800, "frame": {"channel":"heartbeat"}}
{"rx_ns": 42936049975700, "frame": {"channel":"book","type":"update","data":[{"symbol":"BTC/USD","bids":[],"asks":[{"price":62794.0,"qty":0.64949617}],"checksum":449672467,"timestamp":"2026-08-16T23:37:50.672432Z"}]}}
{"rx_ns": 42936050036600, "frame": {"channel":"book","type":"update","data":[{"symbol":"BTC/USD","bids":[{"price":62774.1,"qty":0.41082131}],"asks":[],"checksum":449672467,"timestamp":"2026-08-16T23:37:50.672522Z"}]}}
{"rx_ns": 42936050085900, "frame": {"channel":"book","type":"update","data":[{"symbol":"BTC/USD","bids":[],"asks":[{"price":62791.5,"qty":0.60522203}],"checksum":2215648505,"timestamp":"2026-08-16T23:37:50.672706Z"}]}}
{"rx_ns": 42936050208700, "frame": {"channel":"book","type":"update","data":[{"symbol":"BTC/USD","bids":[],"asks":[{"price":62800.8,"qty":1.09420926}],"checksum":2215648505,"timestamp":"2026-08-16T23:37:50.673375Z"}]}}
{"rx_ns": 42936769919100, "frame": {"channel":"heartbeat"}}
{"rx_ns": 42937757453200, "frame": {"channel":"heartbeat"}}
{"rx_ns": 42937779728300, "frame": {"channel":"book","type":"update","data":[{"symbol":"BTC/USD","bids":[],"asks":[{"price":62791.3,"qty":4.22763328}],"checksum":3875586520,"timestamp":"2026-08-16T23:37:52.405728Z"}]}}
{"rx_ns": 42938302660300, "frame": {"channel":"book","type":"update","data":[{"symbol":"BTC/USD","bids":[{"price":62776.1,"qty":0.46828931}],"asks":[],"checksum":3875586520,"timestamp":"2026-08-16T23:37:52.919808Z"}]}}
{"rx_ns": 42938755392000, "frame": {"channel":"heartbeat"}}
{"rx_ns": 42939753012800, "frame": {"channel":"heartbeat"}}
{"rx_ns": 42940753658400, "frame": {"channel":"heartbeat"}}
{"rx_ns": 42941754167600, "frame": {"channel":"heartbeat"}}
{"rx_ns": 42942754594300, "frame": {"channel":"heartbeat"}}
{"rx_ns": 42942837304800, "frame": {"channel":"book","type":"update","data":[{"symbol":"BTC/USD","bids":[{"price":62782.3,"qty":0.00000000},{"price":62774.1,"qty":0.41082131}],"asks":[],"checksum":3137474675,"timestamp":"2026-08-16T23:37:57.462017Z"}]}}
{"rx_ns": 42942837368400, "frame": {"channel":"book","type":"update","data":[{"symbol":"BTC/USD","bids":[{"price":62780.2,"qty":0.00000000},{"price":62774.0,"qty":0.74369300}],"asks":[],"checksum":3137474675,"timestamp":"2026-08-16T23:37:57.462300Z"}]}}
{"rx_ns": 42942838888100, "frame": {"channel":"book","type":"update","data":[{"symbol":"BTC/USD","bids":[{"price":62781.2,"qty":0.79641642}],"asks":[],"checksum":2348352488,"timestamp":"2026-08-16T23:37:57.463743Z"}]}}
{"rx_ns": 42942838924800, "frame": {"channel":"book","type":"update","data":[{"symbol":"BTC/USD","bids":[{"price":62779.0,"qty":0.95572575}],"asks":[],"checksum":2348352488,"timestamp":"2026-08-16T23:37:57.463893Z"}]}}
{"rx_ns": 42942840460100, "frame": {"channel":"book","type":"update","data":[{"symbol":"BTC/USD","bids":[{"price":62778.0,"qty":0.00422324}],"asks":[],"checksum":2348352488,"timestamp":"2026-08-16T23:37:57.464869Z"}]}}
{"rx_ns": 42943070176600, "frame": {"channel":"book","type":"update","data":[{"symbol":"BTC/USD","bids":[{"price":62774.1,"qty":0.00000000},{"price":62774.0,"qty":0.74369300}],"asks":[],"checksum":2348352488,"timestamp":"2026-08-16T23:37:57.694475Z"}]}}
{"rx_ns": 42943070256000, "frame": {"channel":"book","type":"update","data":[{"symbol":"BTC/USD","bids":[{"price":62774.1,"qty":0.29364066}],"asks":[],"checksum":2348352488,"timestamp":"2026-08-16T23:37:57.695644Z"}]}}
{"rx_ns": 42943176646300, "frame": {"channel":"book","type":"update","data":[{"symbol":"BTC/USD","bids":[{"price":62784.0,"qty":0.00000000},{"price":62774.0,"qty":0.74369300},{"price":62784.6,"qty":0.00009500}],"asks":[],"checksum":606211463,"timestamp":"2026-08-16T23:37:57.792094Z"}]}}
{"rx_ns": 42943187431800, "frame": {"channel":"book","type":"update","data":[{"symbol":"BTC/USD","bids":[{"price":62790.4,"qty":0.00000000},{"price":62774.0,"qty":0.74369300}],"asks":[],"checksum":2525654230,"timestamp":"2026-08-16T23:37:57.796850Z"}]}}
{"rx_ns": 42943187500600, "frame": {"channel":"book","type":"update","data":[{"symbol":"BTC/USD","bids":[{"price":62789.4,"qty":0.02131292}],"asks":[],"checksum":1647631820,"timestamp":"2026-08-16T23:37:57.798280Z"}]}}
{"rx_ns": 42943187531100, "frame": {"channel":"book","type":"update","data":[{"symbol":"BTC/USD","bids":[{"price":62788.1,"qty":0.00000000},{"price":62774.0,"qty":0.74369300},{"price":62789.4,"qty":0.07729764}],"asks":[],"checksum":2990073840,"timestamp":"2026-08-16T23:37:57.799340Z"}]}}
{"rx_ns": 42943344860000, "frame": {"channel":"book","type":"update","data":[{"symbol":"BTC/USD","bids":[{"price":62789.4,"qty":0.05598472}],"asks":[],"checksum":2035133278,"timestamp":"2026-08-16T23:37:57.965246Z"}]}}
{"rx_ns": 42943344928000, "frame": {"channel":"book","type":"update","data":[{"symbol":"BTC/USD","bids":[{"price":62790.3,"qty":0.02131292}],"asks":[],"checksum":1413053836,"timestamp":"2026-08-16T23:37:57.965451Z"}]}}
{"rx_ns": 42943344948500, "frame": {"channel":"book","type":"update","data":[{"symbol":"BTC/USD","bids":[{"price":62789.4,"qty":0.00000000},{"price":62774.0,"qty":0.74369300},{"price":62788.1,"qty":0.05598472}],"asks":[],"checksum":3943424355,"timestamp":"2026-08-16T23:37:57.966568Z"}]}}
{"rx_ns": 42943699793600, "frame": {"channel":"book","type":"update","data":[{"symbol":"BTC/USD","bids":[{"price":62781.2,"qty":0.00000000},{"price":62774.0,"qty":0.74369300}],"asks":[],"checksum":4184755948,"timestamp":"2026-08-16T23:37:58.324198Z"}]}}
{"rx_ns": 42943699853200, "frame": {"channel":"book","type":"update","data":[{"symbol":"BTC/USD","bids":[{"price":62779.0,"qty":0.15928208}],"asks":[],"checksum":4184755948,"timestamp":"2026-08-16T23:37:58.324456Z"}]}}
{"rx_ns": 42943701240400, "frame": {"channel":"book","type":"update","data":[{"symbol":"BTC/USD","bids":[{"price":62782.2,"qty":0.79640364}],"asks":[],"checksum":1603464115,"timestamp":"2026-08-16T23:37:58.325751Z"}]}}
{"rx_ns": 42943701285700, "frame": {"channel":"book","type":"update","data":[{"symbol":"BTC/USD","bids":[{"price":62780.0,"qty":0.79643093}],"asks":[],"checksum":1603464115,"timestamp":"2026-08-16T23:37:58.326027Z"}]}}
{"rx_ns": 42943757796300, "frame": {"channel":"heartbeat"}}
{"rx_ns": 42944355220900, "frame": {"channel":"book","type":"update","data":[{"symbol":"BTC/USD","bids":[{"price":62791.2,"qty":0.16822674}],"asks":[],"checksum":685865189,"timestamp":"2026-08-16T23:37:58.979902Z"}]}}
{"rx_ns": 42944355282700, "frame": {"channel":"book","type":"update","data":[{"symbol":"BTC/USD","bids":[],"asks":[{"price":62791.3,"qty":4.21578028}],"checksum":329939991,"timestamp":"2026-08-16T23:37:58.980162Z"}]}}
{"rx_ns": 42944356760100, "frame": {"channel":"book","type":"update","data":[{"symbol":"BTC/USD","bids":[],"asks":[{"price":62791.3,"qty":4.13778028}],"checksum":3227652704,"timestamp":"2026-08-16T23:37:58.982804Z"}]}}
{"rx_ns": 42944361500400, "frame": {"channel":"book","type":"update","data":[{"symbol":"BTC/USD","bids":[],"asks":[{"price":62791.3,"qty":4.14963328}],"checksum":1345564600,"timestamp":"2026-08-16T23:37:58.986083Z"}]}}
{"rx_ns": 42944361551900, "frame": {"channel":"book","type":"update","data":[{"symbol":"BTC/USD","bids":[{"price":62791.2,"qty":0.01534221}],"asks":[],"checksum":2324436219,"timestamp":"2026-08-16T23:37:58.986350Z"}]}}
{"rx_ns": 42944372339600, "frame": {"channel":"book","type":"update","data":[{"symbol":"BTC/USD","bids":[],"asks":[{"price":62799.4,"qty":0.06000000}],"checksum":2324436219,"timestamp":"2026-08-16T23:37:58.998615Z"}]}}
{"rx_ns": 42944373755000, "frame": {"channel":"book","type":"update","data":[{"symbol":"BTC/USD","bids":[],"asks":[{"price":62802.4,"qty":0.00000000},{"price":62803.4,"qty":0.06960000}],"checksum":2324436219,"timestamp":"2026-08-16T23:37:58.998656Z"}]}}
{"rx_ns": 42944516041500, "frame": {"channel":"book","type":"update","data":[{"symbol":"BTC/USD","bids":[],"asks":[{"price":62791.3,"qty":3.99035120}],"checksum":2025312224,"timestamp":"2026-08-16T23:37:59.137994Z"}]}}
{"rx_ns": 42944516101000, "frame": {"channel":"book","type":"update","data":[{"symbol":"BTC/USD","bids":[],"asks":[{"price":62794.1,"qty":0.00000000},{"price":62803.7,"qty":0.00005100}],"checksum":1916296984,"timestamp":"2026-08-16T23:37:59.138271Z"}]}}
{"rx_ns": 42944518278600, "frame": {"channel":"book","type":"update","data":[{"symbol":"BTC/USD","bids":[],"asks":[{"price":62791.3,"qty":4.06835120}],"checksum":1984973282,"timestamp":"2026-08-16T23:37:59.140834Z"}]}}
{"rx_ns": 42944538648700, "frame": {"channel":"book","type":"update","data":[{"symbol":"BTC/USD","bids":[],"asks":[{"price":62795.4,"qty":0.00000000},{"price":62803.9,"qty":0.17891592}],"checksum":818920400,"timestamp":"2026-08-16T23:37:59.159814Z"}]}}
{"rx_ns": 42944543223800, "frame": {"channel":"book","type":"update","data":[{"symbol":"BTC/USD","bids":[],"asks":[{"price":62798.3,"qty":0.50933000}],"checksum":818920400,"timestamp":"2026-08-16T23:37:59.161222Z"}]}}
{"rx_ns": 42944543279100, "frame": {"channel":"book","type":"update","data":[{"symbol":"BTC/USD","bids":[],"asks":[{"price":62800.8,"qty":0.90931246},{"price":62803.3,"qty":0.19589680}],"checksum":818920400,"timestamp":"2026-08-16T23:37:59.161452Z"}]}}
{"rx_ns": 42944543295600, "frame": {"channel":"book","type":"update","data":[{"symbol":"BTC/USD","bids":[],"asks":[{"price":62794.0,"qty":0.00000000},{"price":62803.9,"qty":0.17891592}],"checksum":893320615,"timestamp":"2026-08-16T23:37:59.161502Z"}]}}
{"rx_ns": 42944543308000, "frame": {"channel":"book","type":"update","data":[{"symbol":"BTC/USD","bids":[],"asks":[{"price":62794.7,"qty":0.35767591}],"checksum":898131639,"timestamp":"2026-08-16T23:37:59.163348Z"}]}}
{"rx_ns": 42944543318300, "frame": {"channel":"book","type":"update","data":[{"symbol":"BTC/USD","bids":[{"price":62791.2,"qty":0.16822674}],"asks":[],"checksum":803645041,"timestamp":"2026-08-16T23:37:59.163385Z"}]}}
{"rx_ns": 42944543328600, "frame": {"channel":"book","type":"update","data":[{"symbol":"BTC/USD","bids":[],"asks":[{"price":62791.3,"qty":4.05649820}],"checksum":1371655920,"timestamp":"2026-08-16T23:37:59.163674Z"}]}}
{"rx_ns": 42944543359700, "frame": {"channel":"book","type":"update","data":[{"symbol":"BTC/USD","bids":[{"price":62791.2,"qty":0.01534221}],"asks":[],"checksum":2744933050,"timestamp":"2026-08-16T23:37:59.166784Z"}]}}
{"rx_ns": 42944543371900, "frame": {"channel":"book","type":"update","data":[{"symbol":"BTC/USD","bids":[],"asks":[{"price":62791.3,"qty":4.06835120}],"checksum":898131639,"timestamp":"2026-08-16T23:37:59.167287Z"}]}}
{"rx_ns": 42944588805900, "frame": {"channel":"book","type":"update","data":[{"symbol":"BTC/USD","bids":[],"asks":[{"price":62791.3,"qty":4.22763328}],"checksum":382030878,"timestamp":"2026-08-16T23:37:59.215111Z"}]}}
{"rx_ns": 42944595081200, "frame": {"channel":"book","type":"update","data":[{"symbol":"BTC/USD","bids":[],"asks":[{"price":62803.3,"qty":0.01100000},{"price":62796.0,"qty":0.18489680}],"checksum":3171989201,"timestamp":"2026-08-16T23:37:59.216226Z"}]}}
{"rx_ns": 42944678195400, "frame": {"channel":"book","type":"update","data":[{"symbol":"BTC/USD","bids":[],"asks":[{"price":62801.3,"qty":0.00318497}],"checksum":3171989201,"timestamp":"2026-08-16T23:37:59.303524Z"}]}}
{"rx_ns": 42944757214600, "frame": {"channel":"heartbeat"}}
{"rx_ns": 42944817929600, "frame": {"channel":"book","type":"update","data":[{"symbol":"BTC/USD","bids":[],"asks":[{"price":62800.7,"qty":0.19620257}],"checksum":3171989201,"timestamp":"2026-08-16T23:37:59.444049Z"}]}}
{"rx_ns": 42945760607900, "frame": {"channel":"heartbeat"}}
{"rx_ns": 42945770576500, "frame": {"channel":"book","type":"update","data":[{"symbol":"BTC/USD","bids":[],"asks":[{"price":62798.3,"qty":0.00000000},{"price":62803.4,"qty":0.06960000}],"checksum":3171989201,"timestamp":"2026-08-16T23:38:00.369803Z"}]}}
{"rx_ns": 42945770627800, "frame": {"channel":"book","type":"update","data":[{"symbol":"BTC/USD","bids":[],"asks":[{"price":62794.7,"qty":0.86700591}],"checksum":428792094,"timestamp":"2026-08-16T23:38:00.371023Z"}]}}
{"rx_ns": 42945770642800, "frame": {"channel":"book","type":"update","data":[{"symbol":"BTC/USD","bids":[],"asks":[{"price":62794.7,"qty":0.50933000}],"checksum":1292753551,"timestamp":"2026-08-16T23:38:00.372165Z"}]}}
{"rx_ns": 42945770653400, "frame": {"channel":"book","type":"update","data":[{"symbol":"BTC/USD","bids":[],"asks":[{"price":62796.0,"qty":0.00000000},{"price":62803.7,"qty":0.00005100},{"price":62800.6,"qty":0.18489680}],"checksum":3872929856,"timestamp":"2026-08-16T23:38:00.372309Z"}]}}
{"rx_ns": 42945770665700, "frame": {"channel":"book","type":"update","data":[{"symbol":"BTC/USD","bids":[],"asks":[{"price":62794.6,"qty":0.56490261}],"checksum":3974163983,"timestamp":"2026-08-16T23:38:00.373369Z"}]}}
{"rx_ns": 42946249042900, "frame": {"channel":"book","type":"update","data":[{"symbol":"BTC/USD","bids":[],"asks":[{"price":62792.3,"qty":0.00000000},{"price":62803.4,"qty":0.06960000}],"checksum":475638106,"timestamp":"2026-08-16T23:38:00.864877Z"}]}}
{"rx_ns": 42946249134700, "frame": {"channel":"book","type":"update","data":[{"symbol":"BTC/USD","bids":[{"price":62788.1,"qty":0.00000000},{"price":62774.1,"qty":0.29364066},{"price":62791.2,"qty":0.07132693}],"asks":[],"checksum":4218590375,"timestamp":"2026-08-16T23:38:00.866106Z"}]}}
{"rx_ns": 42946249155800, "frame": {"channel":"book","type":"update","data":[{"symbol":"BTC/USD","bids":[],"asks":[{"price":62794.5,"qty":0.05598472}],"checksum":1184025778,"timestamp":"2026-08-16T23:38:00.866246Z"}]}}
{"rx_ns": 42946249184700, "frame": {"channel":"book","type":"update","data":[{"symbol":"BTC/USD","bids":[],"asks":[{"price":62800.6,"qty":0.00000000},{"price":62803.4,"qty":0.06960000},{"price":62794.4,"qty":0.18489680}],"checksum":368929866,"timestamp":"2026-08-16T23:38:00.867378Z"}]}}
{"rx_ns": 42946251433900, "frame": {"channel":"book","type":"update","data":[{"symbol":"BTC/USD","bids":[],"asks":[{"price":62791.3,"qty":4.14963328}],"checksum":3236139778,"timestamp":"2026-08-16T23:38:00.877944Z"}]}}
{"rx_ns": 42946609710400, "frame": {"channel":"book","type":"update","data":[{"symbol":"BTC/USD","bids":[],"asks":[{"price":62794.5,"qty":0.00000000},{"price":62803.4,"qty":0.06960000},{"price":62794.3,"qty":0.05598472}],"checksum":4184523727,"timestamp":"2026-08-16T23:38:01.217742Z"}]}}
{"rx_ns": 42946616029400, "frame": {"channel":"book","type":"update","data":[{"symbol":"BTC/USD","bids":[],"asks":[{"price":62794.4,"qty":0.00000000},{"price":62803.4,"qty":0.06960000},{"price":62800.6,"qty":0.18489680}],"checksum":1888054188,"timestamp":"2026-08-16T23:38:01.219094Z"}]}}
{"rx_ns": 42946616142100, "frame": {"channel":"book","type":"update","data":[{"symbol":"BTC/USD","bids":[],"asks":[{"price":62794.3,"qty":0.00000000},{"price":62803.4,"qty":0.06960000},{"price":62794.5,"qty":0.05598472}],"checksum":2475439098,"timestamp":"2026-08-16T23:38:01.220351Z"}]}}
{"rx_ns": 42946639732100, "frame": {"channel":"book","type":"update","data":[{"symbol":"BTC/USD","bids":[],"asks":[{"price":62798.0,"qty":0.00000000},{"price":62803.4,"qty":0.06960000}],"checksum":2475439098,"timestamp":"2026-08-16T23:38:01.264969Z"}]}}
{"rx_ns": 42946640207000, "frame": {"channel":"book","type":"update","data":[{"symbol":"BTC/USD","bids":[],"asks":[{"price":62800.6,"qty":0.00000000},{"price":62803.7,"qty":0.00005100},{"price":62794.4,"qty":0.18489680}],"checksum":3236139778,"timestamp":"2026-08-16T23:38:01.266302Z"}]}}
{"rx_ns": 42946662873000, "frame": {"channel":"book","type":"update","data":[{"symbol":"BTC/USD","bids":[{"price":62778.0,"qty":0.00740907}],"asks":[],"checksum":3236139778,"timestamp":"2026-08-16T23:38:01.287196Z"}]}}
{"rx_ns": 42946667728600, "frame": {"channel":"book","type":"update","data":[{"symbol":"BTC/USD","bids":[],"asks":[{"price":62791.5,"qty":0.00000000},{"price":62803.7,"qty":0.00005100}],"checksum":2870577217,"timestamp":"2026-08-16T23:38:01.289997Z"}]}}
{"rx_ns": 42946667771200, "frame": {"channel":"book","type":"update","data":[{"symbol":"BTC/USD","bids":[{"price":62779.0,"qty":0.00000000},{"price":62774.0,"qty":0.74369300}],"asks":[],"checksum":2870577217,"timestamp":"2026-08-16T23:38:01.290351Z"}]}}
{"rx_ns": 42946668051400, "frame": {"channel":"book","type":"update","data":[{"symbol":"BTC/USD","bids":[],"asks":[{"price":62794.6,"qty":0.00000000},{"price":62803.9,"qty":0.17891592}],"checksum":2703318542,"timestamp":"2026-08-16T23:38:01.291350Z"}]}}
{"rx_ns": 42946668065800, "frame": {"channel":"book","type":"update","data":[{"symbol":"BTC/USD","bids":[],"asks":[{"price":62791.3,"qty":3.99035120}],"checksum":1394246933,"timestamp":"2026-08-16T23:38:01.291370Z"}]}}
{"rx_ns": 42946668073200, "frame": {"channel":"book","type":"update","data":[{"symbol":"BTC/USD","bids":[],"asks":[{"price":62795.6,"qty":0.46828931}],"checksum":871322194,"timestamp":"2026-08-16T23:38:01.291398Z"}]}}
{"rx_ns": 42946668079700, "frame": {"channel":"book","type":"update","data":[{"symbol":"BTC/USD","bids":[{"price":62782.2,"qty":0.00000000},{"price":62773.7,"qty":0.07963767}],"asks":[],"checksum":689505975,"timestamp":"2026-08-16T23:38:01.291524Z"}]}}
{"rx_ns": 42946676125200, "frame": {"channel":"book","type":"update","data":[{"symbol":"BTC/USD","bids":[],"asks":[{"price":62800.0,"qty":0.00000000},{"price":62803.9,"qty":0.17891592}],"checksum":689505975,"timestamp":"2026-08-16T23:38:01.292055Z"}]}}
{"rx_ns": 42946676161700, "frame": {"channel":"book","type":"update","data":[{"symbol":"BTC/USD","bids":[],"asks":[{"price":62791.7,"qty":0.00000000},{"price":62804.0,"qty":0.13109402}],"checksum":1670636267,"timestamp":"2026-08-16T23:38:01.292162Z"}]}}
{"rx_ns": 42946676171200, "frame": {"channel":"book","type":"update","data":[{"symbol":"BTC/USD","bids":[{"price":62780.0,"qty":0.00000000},{"price":62773.1,"qty":0.07963874}],"asks":[],"checksum":1670636267,"timestamp":"2026-08-16T23:38:01.292220Z"}]}}
{"rx_ns": 42946676179200, "frame": {"channel":"book","type":"update","data":[{"symbol":"BTC/USD","bids":[{"price":62780.1,"qty":0.28793577}],"asks":[],"checksum":1670636267,"timestamp":"2026-08-16T23:38:01.292297Z"}]}}
{"rx_ns": 42946676186000, "frame": {"channel":"book","type":"update","data":[{"symbol":"BTC/USD","bids":[],"asks":[{"price":62802.0,"qty":0.00422162}],"checksum":1670636267,"timestamp":"2026-08-16T23:38:01.292318Z"}]}}
{"rx_ns": 42946676192400, "frame": {"channel":"book","type":"update","data":[{"symbol":"BTC/USD","bids":[{"price":62782.5,"qty":0.15928208}],"asks":[],"checksum":4220277771,"timestamp":"2026-08-16T23:38:01.292628Z"}]}}
{"rx_ns": 42946676199400, "frame": {"channel":"book","type":"update","data":[{"symbol":"BTC/USD","bids":[{"price":62791.2,"qty":0.09263985}],"asks":[],"checksum":2961876508,"timestamp":"2026-08-16T23:38:01.292747Z"}]}}
{"rx_ns": 42946676205400, "frame": {"channel":"book","type":"update","data":[{"symbol":"BTC/USD","bids":[],"asks":[{"price":62792.4,"qty":0.00000000},{"price":62805.6,"qty":0.46828931}],"checksum":1091779999,"timestamp":"2026-08-16T23:38:01.292799Z"}]}}
{"rx_ns": 42946676212500, "frame": {"channel":"book","type":"update","data":[{"symbol":"BTC/USD","bids":[],"asks":[{"price":62794.4,"qty":0.00000000},{"price":62806.8,"qty":0.00005100},{"price":62800.6,"qty":0.18489680}],"checksum":2980483900,"timestamp":"2026-08-16T23:38:01.293486Z"}]}}
{"rx_ns": 42946676221900, "frame": {"channel":"book","type":"update","data":[{"symbol":"BTC/USD","bids":[],"asks":[{"price":62794.8,"qty":0.00000000},{"price":62806.8,"qty":0.00005100}],"checksum":2520603607,"timestamp":"2026-08-16T23:38:01.293560Z"}]}}
{"rx_ns": 42946676232900, "frame": {"channel":"book","type":"update","data":[{"symbol":"BTC/USD","bids":[{"price":62776.1,"qty":0.00000000},{"price":62773.7,"qty":0.07963767}],"asks":[],"checksum":2520603607,"timestamp":"2026-08-16T23:38:01.293570Z"}]}}
{"rx_ns": 42946676239900, "frame": {"channel":"book","type":"update","data":[{"symbol":"BTC/USD","bids":[{"price":62775.6,"qty":0.00000000},{"price":62773.1,"qty":0.07963874}],"asks":[],"checksum":2520603607,"timestamp":"2026-08-16T23:38:01.293659Z"}]}}
{"rx_ns": 42946676246700, "frame": {"channel":"book","type":"update","data":[{"symbol":"BTC/USD","bids":[],"asks":[{"price":62791.6,"qty":0.00000000},{"price":62807.2,"qty":0.02905654}],"checksum":2661133330,"timestamp":"2026-08-16T23:38:01.293959Z"}]}}
{"rx_ns": 42946684383600, "frame": {"channel":"book","type":"update","data":[{"symbol":"BTC/USD","bids":[],"asks":[{"price":62800.9,"qty":0.00000000},{"price":62808.0,"qty":0.00636861}],"checksum":2661133330,"timestamp":"2026-08-16T23:38:01.294650Z"}]}}
{"rx_ns": 42946684423100, "frame": {"channel":"book","type":"update","data":[{"symbol":"BTC/USD","bids":[{"price":62776.2,"qty":0.38096420}],"asks":[],"checksum":2661133330,"timestamp":"2026-08-16T23:38:01.295846Z"}]}}
{"rx_ns": 42946684432500, "frame": {"channel":"book","type":"update","data":[{"symbol":"BTC/USD","bids":[],"asks":[{"price":62802.0,"qty":0.00000000},{"price":62808.1,"qty":0.00159200}],"checksum":2661133330,"timestamp":"2026-08-16T23:38:01.296621Z"}]}}
{"rx_ns": 42946684440000, "frame": {"channel":"book","type":"update","data":[{"symbol":"BTC/USD","bids":[],"asks":[{"price":62808.0,"qty":0.00318430}],"checksum":2661133330,"timestamp":"2026-08-16T23:38:01.297320Z"}]}}
{"rx_ns": 42946684446000, "frame": {"channel":"book","type":"update","data":[{"symbol":"BTC/USD","bids":[],"asks":[{"price":62797.6,"qty":0.79620930}],"checksum":708478009,"timestamp":"2026-08-16T23:38:01.297767Z"}]}}
{"rx_ns": 42946684452500, "frame": {"channel":"book","type":"update","data":[{"symbol":"BTC/USD","bids":[],"asks":[{"price":62799.6,"qty":0.79618411}],"checksum":2132157746,"timestamp":"2026-08-16T23:38:01.297960Z"}]}}
{"rx_ns": 42946710318500, "frame": {"channel":"book","type":"update","data":[{"symbol":"BTC/USD","bids":[{"price":62786.1,"qty":0.79635444}],"asks":[],"checksum":4111564792,"timestamp":"2026-08-16T23:38:01.298586Z"}]}}
{"rx_ns": 42946710378000, "frame": {"channel":"book","type":"update","data":[{"symbol":"BTC/USD","bids":[{"price":62791.2,"qty":0.16223985}],"asks":[],"checksum":49408415,"timestamp":"2026-08-16T23:38:01.298704Z"}]}}
{"rx_ns": 42946710388000, "frame": {"channel":"book","type":"update","data":[{"symbol":"BTC/USD","bids":[{"price":62780.4,"qty":0.79642633}],"asks":[],"checksum":49408415,"timestamp":"2026-08-16T23:38:01.298804Z"}]}}
{"rx_ns": 42946710396600, "frame": {"channel":"book","type":"update","data":[{"symbol":"BTC/USD","bids":[{"price":62786.1,"qty":0.00000000},{"price":62774.0,"qty":0.74369300}],"asks":[],"checksum":4258733990,"timestamp":"2026-08-16T23:38:01.299147Z"}]}}
{"rx_ns": 42946710407500, "frame": {"channel":"book","type":"update","data":[{"symbol":"BTC/USD","bids":[{"price":62780.1,"qty":0.00000000},{"price":62773.7,"qty":0.07963767}],"asks":[],"checksum":4258733990,"timestamp":"2026-08-16T23:38:01.299659Z"}]}}
{"rx_ns": 42946710416900, "frame": {"channel":"book","type":"update","data":[{"symbol":"BTC/USD","bids":[],"asks":[{"price":62797.6,"qty":0.00000000},{"price":62808.0,"qty":0.00318430}],"checksum":270957255,"timestamp":"2026-08-16T23:38:01.299872Z"}]}}
{"rx_ns": 42946710428000, "frame": {"channel":"book","type":"update","data":[{"symbol":"BTC/USD","bids":[{"price":62782.5,"qty":0.00000000},{"price":62773.1,"qty":0.07963874}],"asks":[],"checksum":2368727334,"timestamp":"2026-08-16T23:38:01.300272Z"}]}}
{"rx_ns": 42946710436900, "frame": {"channel":"book","type":"update","data":[{"symbol":"BTC/USD","bids":[],"asks":[{"price":62799.6,"qty":0.00000000},{"price":62808.1,"qty":0.00159200}],"checksum":1532045062,"timestamp":"2026-08-16T23:38:01.300360Z"}]}}
{"rx_ns": 42946710445000, "frame": {"channel":"book","type":"update","data":[{"symbol":"BTC/USD","bids":[],"asks":[{"price":62794.7,"qty":0.00000000},{"price":62809.8,"qty":0.00222509}],"checksum":3147494362,"timestamp":"2026-08-16T23:38:01.300382Z"}]}}
{"rx_ns": 42946710454900, "frame": {"channel":"book","type":"update","data":[{"symbol":"BTC/USD","bids":[{"price":62780.4,"qty":0.00000000},{"price":62772.6,"qty":0.06960000}],"asks":[],"checksum":2093402930,"timestamp":"2026-08-16T23:38:01.301848Z"}]}}
{"rx_ns": 42946710463500, "frame": {"channel":"book","type":"update","data":[{"symbol":"BTC/USD","bids":[{"price":62790.3,"qty":0.00000000},{"price":62772.0,"qty":0.24087933}],"asks":[],"checksum":3037536373,"timestamp":"2026-08-16T23:38:01.302062Z"}]}}
{"rx_ns": 42946710472300, "frame": {"channel":"book","type":"update","data":[{"symbol":"BTC/USD","bids":[],"asks":[{"price":62791.3,"qty":0.19944872},{"price":62803.3,"qty":3.80113501}],"checksum":4056512674,"timestamp":"2026-08-16T23:38:01.303977Z"}]}}
{"rx_ns": 42946777153200, "frame": {"channel":"book","type":"update","data":[{"symbol":"BTC/USD","bids":[],"asks":[{"price":62807.2,"qty":0.02865913}],"checksum":4056512674,"timestamp":"2026-08-16T23:38:01.305196Z"}]}}
{"rx_ns": 42946777201000, "frame": {"channel":"book","type":"update","data":[{"symbol":"BTC/USD","bids":[],"asks":[{"price":62801.4,"qty":0.00000000},{"price":62809.9,"qty":2.52543044}],"checksum":4056512674,"timestamp":"2026-08-16T23:38:01.305753Z"}]}}
{"rx_ns": 42946777213300, "frame": {"channel":"book","type":"update","data":[{"symbol":"BTC/USD","bids":[{"price":62782.3,"qty":0.46828931}],"asks":[],"checksum":649679329,"timestamp":"2026-08-16T23:38:01.306370Z"}]}}
{"rx_ns": 42946777222200, "frame": {"channel":"book","type":"update","data":[{"symbol":"BTC/USD","bids":[{"price":62782.6,"qty":0.04851164}],"asks":[],"checksum":1286896507,"timestamp":"2026-08-16T23:38:01.307070Z"}]}}
{"rx_ns": 42946777230600, "frame": {"channel":"book","type":"update","data":[{"symbol":"BTC/USD","bids":[],"asks":[{"price":62804.6,"qty":0.50933000}],"checksum":1286896507,"timestamp":"2026-08-16T23:38:01.307223Z"}]}}
{"rx_ns": 42946777239000, "frame": {"channel":"book","type":"update","data":[{"symbol":"BTC/USD","bids":[{"price":62782.3,"qty":0.00000000},{"price":62772.6,"qty":0.06960000}],"asks":[],"checksum":1053413852,"timestamp":"2026-08-16T23:38:01.308098Z"}]}}
{"rx_ns": 42946777247800, "frame": {"channel":"book","type":"update","data":[{"symbol":"BTC/USD","bids":[],"asks":[{"price":62791.3,"qty":0.18031524}],"checksum":1836424615,"timestamp":"2026-08-16T23:38:01.308425Z"}]}}
{"rx_ns": 42946777255900, "frame": {"channel":"book","type":"update","data":[{"symbol":"BTC/USD","bids":[{"price":62776.2,"qty":0.00000000},{"price":62772.0,"qty":0.23769319}],"asks":[],"checksum":1836424615,"timestamp":"2026-08-16T23:38:01.308767Z"}]}}
{"rx_ns": 42946777265800, "frame": {"channel":"book","type":"update","data":[{"symbol":"BTC/USD","bids":[],"asks":[{"price":62804.0,"qty":0.00000000},{"price":62809.9,"qty":2.52543044}],"checksum":1836424615,"timestamp":"2026-08-16T23:38:01.310128Z"}]}}
{"rx_ns": 42946777274600, "frame": {"channel":"book","type":"update","data":[{"symbol":"BTC/USD","bids":[],"asks":[{"price":62794.8,"qty":0.15928208}],"checksum":229245831,"timestamp":"2026-08-16T23:38:01.310298Z"}]}}
{"rx_ns": 42946777282400, "frame": {"channel":"book","type":"update","data":[{"symbol":"BTC/USD","bids":[],"asks":[{"price":62799.3,"qty":0.01791000}],"checksum":3057330669,"timestamp":"2026-08-16T23:38:01.310738Z"}]}}
{"rx_ns": 42946777290400, "frame": {"channel":"book","type":"update","data":[{"symbol":"BTC/USD","bids":[],"asks":[{"price":62795.6,"qty":0.00000000},{"price":62809.8,"qty":0.00222509}],"checksum":3759523045,"timestamp":"2026-08-16T23:38:01.311585Z"}]}}
{"rx_ns": 42946777299200, "frame": {"channel":"book","type":"update","data":[{"symbol":"BTC/USD","bids":[{"price":62779.1,"qty":0.06960000}],"asks":[],"checksum":3759523045,"timestamp":"2026-08-16T23:38:01.311915Z"}]}}
{"rx_ns": 42946777371100, "frame": {"channel":"book","type":"update","data":[{"symbol":"BTC/USD","bids":[{"price":62780.2,"qty":0.01145513}],"asks":[],"checksum":3759523045,"timestamp":"2026-08-16T23:38:01.312162Z"}]}}
{"rx_ns": 42946777382100, "frame": {"channel":"book","type":"update","data":[{"symbol":"BTC/USD","bids":[{"price":62780.2,"qty":0.00000000},{"price":62772.0,"qty":0.23769319}],"asks":[],"checksum":3759523045,"timestamp":"2026-08-16T23:38:01.312192Z"}]}}
{"rx_ns": 42946777392100, "frame": {"channel":"book","type":"update","data":[{"symbol":"BTC/USD","bids":[{"price":62780.5,"qty":0.07234750}],"asks":[],"checksum":739450336,"timestamp":"2026-08-16T23:38:01.312302Z"}]}}
{"rx_ns": 42946777401900, "frame": {"channel":"book","type":"update","data":[{"symbol":"BTC/USD","bids":[{"price":62782.6,"qty":0.00000000},{"price":62771.6,"qty":0.04193000}],"asks":[],"checksum":3662340389,"timestamp":"2026-08-16T23:38:01.315139Z"}]}}
{"rx_ns": 42946798967700, "frame": {"channel":"book","type":"update","data":[{"symbol":"BTC/USD","bids":[{"price":62780.6,"qty":0.06848480}],"asks":[],"checksum":1474485455,"timestamp":"2026-08-16T23:38:01.316742Z"}]}}
{"rx_ns": 42946799009900, "frame": {"channel":"book","type":"update","data":[{"symbol":"BTC/USD","bids":[],"asks":[{"price":62800.8,"qty":0.00000000},{"price":62809.9,"qty":2.52543044}],"checksum":1474485455,"timestamp":"2026-08-16T23:38:01.317073Z"}]}}
{"rx_ns": 42946799027400, "frame": {"channel":"book","type":"update","data":[{"symbol":"BTC/USD","bids":[],"asks":[{"price":62794.8,"qty":0.00000000},{"price":62810.0,"qty":0.50000000}],"checksum":3365392916,"timestamp":"2026-08-16T23:38:01.317192Z"}]}}
{"rx_ns": 42946799042100, "frame": {"channel":"book","type":"update","data":[{"symbol":"BTC/USD","bids":[],"asks":[{"price":62799.9,"qty":0.79618083}],"checksum":1560795841,"timestamp":"2026-08-16T23:38:01.317721Z"}]}}
{"rx_ns": 42946799054700, "frame": {"channel":"book","type":"update","data":[{"symbol":"BTC/USD","bids":[],"asks":[{"price":62809.9,"qty":0.00000000},{"price":62810.0,"qty":0.50000000}],"checksum":1560795841,"timestamp":"2026-08-16T23:38:01.318857Z"}]}}
{"rx_ns": 42946799069900, "frame": {"channel":"book","type":"update","data":[{"symbol":"BTC/USD","bids":[],"asks":[{"price":62799.9,"qty":0.00000000},{"price":62811.1,"qty":2.38811661}],"checksum":3365392916,"timestamp":"2026-08-16T23:38:01.319003Z"}]}}
{"rx_ns": 42946799084500, "frame": {"channel":"book","type":"update","data":[{"symbol":"BTC/USD","bids":[{"price":62774.2,"qty":0.13159865}],"asks":[],"checksum":3365392916,"timestamp":"2026-08-16T23:38:01.319197Z"}]}}
{"rx_ns": 42946799097500, "frame": {"channel":"book","type":"update","data":[{"symbol":"BTC/USD","bids":[],"asks":[{"price":62800.5,"qty":0.12400653}],"checksum":3787501510,"timestamp":"2026-08-16T23:38:01.320079Z"}]}}
{"rx_ns": 42946799110300, "frame": {"channel":"book","type":"update","data":[{"symbol":"BTC/USD","bids":[],"asks":[{"price":62800.6,"qty":0.00000000},{"price":62812.6,"qty":0.00080000},{"price":62803.2,"qty":0.18489680}],"checksum":2574780886,"timestamp":"2026-08-16T23:38:01.320100Z"}]}}
{"rx_ns": 42946799122300, "frame": {"channel":"book","type":"update","data":[{"symbol":"BTC/USD","bids":[],"asks":[{"price":62800.7,"qty":0.00000000},{"price":62812.6,"qty":0.00080000},{"price":62805.5,"qty":0.19620257}],"checksum":1273973075,"timestamp":"2026-08-16T23:38:01.323612Z"}]}}
{"rx_ns": 42946799136100, "frame": {"channel":"book","type":"update","data":[{"symbol":"BTC/USD","bids":[{"price":62774.2,"qty":0.02867420},{"price":62775.7,"qty":0.10292200}],"asks":[],"checksum":1273973075,"timestamp":"2026-08-16T23:38:01.324011Z"}]}}
{"rx_ns": 42946799179400, "frame": {"channel":"book","type":"update","data":[{"symbol":"BTC/USD","bids":[],"asks":[{"price":62803.3,"qty":0.01100000},{"price":62805.5,"qty":3.98616031}],"checksum":1273973075,"timestamp":"2026-08-16T23:38:01.324907Z"}]}}
{"rx_ns": 42946799196500, "frame": {"channel":"book","type":"update","data":[{"symbol":"BTC/USD","bids":[],"asks":[{"price":62799.3,"qty":0.00000000},{"price":62812.6,"qty":0.00080000}],"checksum":1005810463,"timestamp":"2026-08-16T23:38:01.325271Z"}]}}
{"rx_ns": 42946799210900, "frame": {"channel":"book","type":"update","data":[{"symbol":"BTC/USD","bids":[],"asks":[{"price":62800.5,"qty":0.00005100}],"checksum":485387837,"timestamp":"2026-08-16T23:38:01.325338Z"}]}}
{"rx_ns": 42946799222800, "frame": {"channel":"book","type":"update","data":[{"symbol":"BTC/USD","bids":[],"asks":[{"price":62805.6,"qty":0.00000000},{"price":62813.2,"qty":0.02077560}],"checksum":485387837,"timestamp":"2026-08-16T23:38:01.325382Z"}]}}
{"rx_ns": 42946799235800, "frame": {"channel":"book","type":"update","data":[{"symbol":"BTC/USD","bids":[{"price":62784.0,"qty":0.00318553}],"asks":[],"checksum":557502852,"timestamp":"2026-08-16T23:38:01.327190Z"}]}}
{"rx_ns": 42946799248400, "frame": {"channel":"book","type":"update","data":[{"symbol":"BTC/USD","bids":[],"asks":[{"price":62799.8,"qty":0.36163073}],"checksum":300246037,"timestamp":"2026-08-16T23:38:01.327208Z"}]}}
{"rx_ns": 42946799302700, "frame": {"channel":"book","type":"update","data":[{"symbol":"BTC/USD","bids":[],"asks":[{"price":62799.8,"qty":0.00000000},{"price":62813.2,"qty":0.02077560}],"checksum":557502852,"timestamp":"2026-08-16T23:38:01.327228Z"}]}}
{"rx_ns": 42946799368100, "frame": {"channel":"book","type":"update","data":[{"symbol":"BTC/USD","bids":[],"asks":[{"price":62794.5,"qty":0.00000000},{"price":62813.3,"qty":0.06960000}],"checksum":3533723450,"timestamp":"2026-08-16T23:38:01.327642Z"}]}}
{"rx_ns": 42946799387200, "frame": {"channel":"book","type":"update","data":[{"symbol":"BTC/USD","bids":[{"price":62791.2,"qty":0.09263985}],"asks":[],"checksum":4224961254,"timestamp":"2026-08-16T23:38:01.327917Z"}]}}
{"rx_ns": 42946799400300, "frame": {"channel":"book","type":"update","data":[{"symbol":"BTC/USD","bids":[],"asks":[{"price":62791.3,"qty":0.25991524}],"checksum":1140291382,"timestamp":"2026-08-16T23:38:01.328326Z"}]}}
{"rx_ns": 42946799411800, "frame": {"channel":"book","type":"update","data":[{"symbol":"BTC/USD","bids":[{"price":62775.7,"qty":0.00000000},{"price":62772.6,"qty":0.06960000},{"price":62774.2,"qty":0.13159865}],"asks":[],"checksum":1140291382,"timestamp":"2026-08-16T23:38:01.330877Z"}]}}
{"rx_ns": 42946799426100, "frame": {"channel":"book","type":"update","data":[{"symbol":"BTC/USD","bids":[{"price":62774.2,"qty":0.10292445}],"asks":[],"checksum":1140291382,"timestamp":"2026-08-16T23:38:01.330896Z"}]}}
{"rx_ns": 42946799438500, "frame": {"channel":"book","type":"update","data":[{"symbol":"BTC/USD","bids":[],"asks":[{"price":62804.6,"qty":0.00000000},{"price":62815.6,"qty":0.29690768}],"checksum":1140291382,"timestamp":"2026-08-16T23:38:01.332065Z"}]}}
{"rx_ns": 42946799452900, "frame": {"channel":"book","type":"update","data":[{"symbol":"BTC/USD","bids":[],"asks":[{"price":62791.8,"qty":0.00000000},{"price":62815.7,"qty":0.10331161}],"checksum":2004382442,"timestamp":"2026-08-16T23:38:01.332349Z"}]}}
{"rx_ns": 42946799465400, "frame": {"channel":"book","type":"update","data":[{"symbol":"BTC/USD","bids":[],"asks":[{"price":62791.3,"qty":0.33791524}],"checksum":3085037868,"timestamp":"2026-08-16T23:38:01.332493Z"}]}}
{"rx_ns": 42946799477000, "frame": {"channel":"book","type":"update","data":[{"symbol":"BTC/USD","bids":[],"asks":[{"price":62805.5,"qty":0.19620257},{"price":62803.3,"qty":3.80107593}],"checksum":689102351,"timestamp":"2026-08-16T23:38:01.333382Z"}]}}
{"rx_ns": 42946799490500, "frame": {"channel":"book","type":"update","data":[{"symbol":"BTC/USD","bids":[],"asks":[{"price":62791.3,"qty":0.25846517}],"checksum":2683164719,"timestamp":"2026-08-16T23:38:01.334122Z"}]}}
{"rx_ns": 42946799503900, "frame": {"channel":"book","type":"update","data":[{"symbol":"BTC/USD","bids":[],"asks":[{"price":62815.6,"qty":0.00000000},{"price":62818.9,"qty":2.68320903}],"checksum":2683164719,"timestamp":"2026-08-16T23:38:01.334402Z"}]}}
{"rx_ns": 42946799604000, "frame": {"channel":"book","type":"update","data":[{"symbol":"BTC/USD","bids":[],"asks":[{"price":62803.2,"qty":1.63214579}],"checksum":3125685034,"timestamp":"2026-08-16T23:38:01.335930Z"}]}}
{"rx_ns": 42946799620800, "frame": {"channel":"book","type":"update","data":[{"symbol":"BTC/USD","bids":[{"price":62773.1,"qty":0.00000000},{"price":62772.0,"qty":0.23769319},{"price":62775.4,"qty":0.03185508}],"asks":[],"checksum":3125685034,"timestamp":"2026-08-16T23:38:01.336530Z"}]}}
{"rx_ns": 42946799635700, "frame": {"channel":"book","type":"update","data":[{"symbol":"BTC/USD","bids":[{"price":62791.2,"qty":0.25192193}],"asks":[],"checksum":2664822469,"timestamp":"2026-08-16T23:38:01.337133Z"}]}}
{"rx_ns": 42946799649300, "frame": {"channel":"book","type":"update","data":[{"symbol":"BTC/USD","bids":[{"price":62773.7,"qty":0.04778169}],"asks":[],"checksum":2664822469,"timestamp":"2026-08-16T23:38:01.340190Z"}]}}
{"rx_ns": 42946799662400, "frame": {"channel":"book","type":"update","data":[{"symbol":"BTC/USD","bids":[{"price":62773.7,"qty":0.00000000},{"price":62772.0,"qty":0.23769319}],"asks":[],"checksum":2664822469,"timestamp":"2026-08-16T23:38:01.340235Z"}]}}
{"rx_ns": 42946799676100, "frame": {"channel":"book","type":"update","data":[{"symbol":"BTC/USD","bids":[],"asks":[{"price":62809.8,"qty":0.00000000},{"price":62819.0,"qty":7.95938166},{"price":62805.4,"qty":0.00222509}],"checksum":2664822469,"timestamp":"2026-08-16T23:38:01.340716Z"}]}}
{"rx_ns": 42946799778900, "frame": {"channel":"book","type":"update","data":[{"symbol":"BTC/USD","bids":[{"price":62791.2,"qty":0.33152193}],"asks":[],"checksum":2305038319,"timestamp":"2026-08-16T23:38:01.341635Z"}]}}
{"rx_ns": 42946799797200, "frame": {"channel":"book","type":"update","data":[{"symbol":"BTC/USD","bids":[{"price":62791.2,"qty":0.25192193}],"asks":[],"checksum":2664822469,"timestamp":"2026-08-16T23:38:01.343577Z"}]}}
{"rx_ns": 42946799810600, "frame": {"channel":"book","type":"update","data":[{"symbol":"BTC/USD","bids":[{"price":62775.4,"qty":0.00000000},{"price":62771.6,"qty":0.04193000},{"price":62778.2,"qty":0.07963274}],"asks":[],"checksum":2664822469,"timestamp":"2026-08-16T23:38:01.344059Z"}]}}
{"rx_ns": 42946799823800, "frame": {"channel":"book","type":"update","data":[{"symbol":"BTC/USD","bids":[],"asks":[{"price":62791.3,"qty":0.17886517}],"checksum":4148880007,"timestamp":"2026-08-16T23:38:01.344185Z"}]}}
{"rx_ns": 42946799833900, "frame": {"channel":"book","type":"update","data":[{"symbol":"BTC/USD","bids":[],"asks":[{"price":62803.9,"qty":0.00000000},{"price":62819.0,"qty":7.95938166}],"checksum":4148880007,"timestamp":"2026-08-16T23:38:01.344827Z"}]}}
{"rx_ns": 42946799842700, "frame": {"channel":"book","type":"update","data":[{"symbol":"BTC/USD","bids":[],"asks":[{"price":62791.3,"qty":0.39786514}],"checksum":1224939851,"timestamp":"2026-08-16T23:38:01.344930Z"}]}}
{"rx_ns": 42946799850400, "frame": {"channel":"book","type":"update","data":[{"symbol":"BTC/USD","bids":[],"asks":[{"price":62791.3,"qty":0.47746514}],"checksum":2103821309,"timestamp":"2026-08-16T23:38:01.346358Z"}]}}
{"rx_ns": 42946799859100, "frame": {"channel":"book","type":"update","data":[{"symbol":"BTC/USD","bids":[{"price":62791.2,"qty":0.33152193}],"asks":[],"checksum":1792287447,"timestamp":"2026-08-16T23:38:01.346785Z"}]}}
{"rx_ns": 42946799866700, "frame": {"channel":"book","type":"update","data":[{"symbol":"BTC/USD","bids":[],"asks":[{"price":62791.3,"qty":0.39786514}],"checksum":1588787297,"timestamp":"2026-08-16T23:38:01.346966Z"}]}}
{"rx_ns": 42946799874100, "frame": {"channel":"book","type":"update","data":[{"symbol":"BTC/USD","bids":[{"price":62778.0,"qty":0.00318583}],"asks":[],"checksum":1588787297,"timestamp":"2026-08-16T23:38:01.347039Z"}]}}
{"rx_ns": 42946799882000, "frame": {"channel":"book","type":"update","data":[{"symbol":"BTC/USD","bids":[{"price":62791.2,"qty":0.25192193}],"asks":[],"checksum":1224939851,"timestamp":"2026-08-16T23:38:01.347147Z"}]}}
{"rx_ns": 42946799891200, "frame": {"channel":"book","type":"update","data":[{"symbol":"BTC/USD","bids":[],"asks":[{"price":62791.3,"qty":0.47746514}],"checksum":2103821309,"timestamp":"2026-08-16T23:38:01.347180Z"}]}}
{"rx_ns": 42946799899200, "frame": {"channel":"book","type":"update","data":[{"symbol":"BTC/USD","bids":[{"price":62777.9,"qty":0.07187345}],"asks":[],"checksum":2103821309,"timestamp":"2026-08-16T23:38:01.347759Z"}]}}
{"rx_ns": 42946799906800, "frame": {"channel":"book","type":"update","data":[{"symbol":"BTC/USD","bids":[{"price":62778.8,"qty":0.03185309}],"asks":[],"checksum":2103821309,"timestamp":"2026-08-16T23:38:01.348111Z"}]}}
{"rx_ns": 42946799914600, "frame": {"channel":"book","type":"update","data":[{"symbol":"BTC/USD","bids":[{"price":62774.9,"qty":0.02867388}],"asks":[],"checksum":2103821309,"timestamp":"2026-08-16T23:38:01.350907Z"}]}}
{"rx_ns": 42946799946200, "frame": {"channel":"book","type":"update","data":[{"symbol":"BTC/USD","bids":[],"asks":[{"price":62815.5,"qty":1.59575715}],"checksum":2103821309,"timestamp":"2026-08-16T23:38:01.353537Z"}]}}
{"rx_ns": 42946799955800, "frame": {"channel":"book","type":"update","data":[{"symbol":"BTC/USD","bids":[],"asks":[{"price":62805.4,"qty":0.00000000},{"price":62819.0,"qty":7.95938166},{"price":62803.1,"qty":0.00222509}],"checksum":3870000262,"timestamp":"2026-08-16T23:38:01.354200Z"}]}}
{"rx_ns": 42946799965300, "frame": {"channel":"book","type":"update","data":[{"symbol":"BTC/USD","bids":[],"asks":[{"price":62811.0,"qty":0.71285281}],"checksum":3870000262,"timestamp":"2026-08-16T23:38:01.354452Z"}]}}
{"rx_ns": 42946799973900, "frame": {"channel":"book","type":"update","data":[{"symbol":"BTC/USD","bids":[{"price":62779.5,"qty":0.71004400}],"asks":[],"checksum":3870000262,"timestamp":"2026-08-16T23:38:01.357109Z"}]}}
{"rx_ns": 42946799981600, "frame": {"channel":"book","type":"update","data":[{"symbol":"BTC/USD","bids":[{"price":62778.0,"qty":0.00000000},{"price":62774.1,"qty":0.29364066}],"asks":[],"checksum":3870000262,"timestamp":"2026-08-16T23:38:01.358542Z"}]}}
{"rx_ns": 42946800003600, "frame": {"channel":"book","type":"update","data":[{"symbol":"BTC/USD","bids":[],"asks":[{"price":62803.1,"qty":0.00000000},{"price":62818.9,"qty":2.68320903}],"checksum":2103821309,"timestamp":"2026-08-16T23:38:01.359716Z"}]}}
{"rx_ns": 42946806369300, "frame": {"channel":"book","type":"update","data":[{"symbol":"BTC/USD","bids":[],"asks":[{"price":62794.2,"qty":0.00005100}],"checksum":1846346802,"timestamp":"2026-08-16T23:38:01.362358Z"}]}}
{"rx_ns": 42946806413700, "frame": {"channel":"book","type":"update","data":[{"symbol":"BTC/USD","bids":[],"asks":[{"price":62799.4,"qty":0.00000000},{"price":62818.9,"qty":2.68320903}],"checksum":1436342704,"timestamp":"2026-08-16T23:38:01.362888Z"}]}}
{"rx_ns": 42946806429900, "frame": {"channel":"book","type":"update","data":[{"symbol":"BTC/USD","bids":[{"price":62780.6,"qty":0.30523348}],"asks":[],"checksum":1180419952,"timestamp":"2026-08-16T23:38:01.364522Z"}]}}
{"rx_ns": 42946806442200, "frame": {"channel":"book","type":"update","data":[{"symbol":"BTC/USD","bids":[{"price":62778.2,"qty":0.00000000},{"price":62774.0,"qty":0.74369300}],"asks":[],"checksum":1180419952,"timestamp":"2026-08-16T23:38:01.364602Z"}]}}
{"rx_ns": 42946806455100, "frame": {"channel":"book","type":"update","data":[{"symbol":"BTC/USD","bids":[],"asks":[{"price":62803.1,"qty":0.00222509}],"checksum":2712371193,"timestamp":"2026-08-16T23:38:01.365427Z"}]}}
{"rx_ns": 42946806466700, "frame": {"channel":"book","type":"update","data":[{"symbol":"BTC/USD","bids":[{"price":62791.2,"qty":0.33152193}],"asks":[],"checksum":2047281102,"timestamp":"2026-08-16T23:38:01.365847Z"}]}}
{"rx_ns": 42946806479300, "frame": {"channel":"book","type":"update","data":[{"symbol":"BTC/USD","bids":[{"price":62789.7,"qty":0.79630822}],"asks":[],"checksum":4019963876,"timestamp":"2026-08-16T23:38:01.366121Z"}]}}
{"rx_ns": 42946806490900, "frame": {"channel":"book","type":"update","data":[{"symbol":"BTC/USD","bids":[{"price":62778.8,"qty":0.00000000},{"price":62774.0,"qty":0.74369300},{"price":62780.1,"qty":0.07963030}],"asks":[],"checksum":4019963876,"timestamp":"2026-08-16T23:38:01.366425Z"}]}}
{"rx_ns": 42946806574100, "frame": {"channel":"book","type":"update","data":[{"symbol":"BTC/USD","bids":[{"price":62791.2,"qty":0.25192193}],"asks":[],"checksum":1476251283,"timestamp":"2026-08-16T23:38:01.367614Z"}]}}
{"rx_ns": 42946806590900, "frame": {"channel":"heartbeat"}}
{"rx_ns": 42946806601000, "frame": {"channel":"book","type":"update","data":[{"symbol":"BTC/USD","bids":[{"price":62791.2,"qty":0.33152193}],"asks":[],"checksum":4019963876,"timestamp":"2026-08-16T23:38:01.368102Z"}]}}
{"rx_ns": 42946806613500, "frame": {"channel":"book","type":"update","data":[{"symbol":"BTC/USD","bids":[],"asks":[{"price":62796.1,"qty":0.00000000},{"price":62818.9,"qty":2.68320903}],"checksum":202930260,"timestamp":"2026-08-16T23:38:01.370298Z"}]}}
{"rx_ns": 42946806626100, "frame": {"channel":"book","type":"update","data":[{"symbol":"BTC/USD","bids":[],"asks":[{"price":62812.6,"qty":0.00000000},{"price":62819.0,"qty":7.95938166}],"checksum":202930260,"timestamp":"2026-08-16T23:38:01.370615Z"}]}}
{"rx_ns": 42946806638100, "frame": {"channel":"book","type":"update","data":[{"symbol":"BTC/USD","bids":[],"asks":[{"price":62803.2,"qty":1.44724899},{"price":62810.9,"qty":0.18489680}],"checksum":748753257,"timestamp":"2026-08-16T23:38:01.370680Z"}]}}
{"rx_ns": 42946822944800, "frame": {"channel":"book","type":"update","data":[{"symbol":"BTC/USD","bids":[{"price":62780.7,"qty":0.03185211}],"asks":[],"checksum":1456095657,"timestamp":"2026-08-16T23:38:01.372911Z"}]}}
{"rx_ns": 42946823014700, "frame": {"channel":"book","type":"update","data":[{"symbol":"BTC/USD","bids":[],"asks":[{"price":62791.3,"qty":0.39786514}],"checksum":2013377784,"timestamp":"2026-08-16T23:38:01.377286Z"}]}}
{"rx_ns": 42946823029500, "frame": {"channel":"book","type":"update","data":[{"symbol":"BTC/USD","bids":[],"asks":[{"price":62803.1,"qty":0.00000000},{"price":62819.0,"qty":7.95938166}],"checksum":2942002923,"timestamp":"2026-08-16T23:38:01.377312Z"}]}}
{"rx_ns": 42946823043100, "frame": {"channel":"book","type":"update","data":[{"symbol":"BTC/USD","bids":[],"asks":[{"price":62815.5,"qty":0.00000000},{"price":62820.0,"qty":0.00318370},{"price":62816.2,"qty":1.59575715}],"checksum":2942002923,"timestamp":"2026-08-16T23:38:01.377709Z"}]}}
{"rx_ns": 42946823059200, "frame": {"channel":"book","type":"update","data":[{"symbol":"BTC/USD","bids":[{"price":62774.2,"qty":0.00000000},{"price":62774.1,"qty":0.29364066},{"price":62776.2,"qty":0.10292118}],"asks":[],"checksum":2942002923,"timestamp":"2026-08-16T23:38:01.377830Z"}]}}
{"rx_ns": 42946823070900, "frame": {"channel":"book","type":"update","data":[{"symbol":"BTC/USD","bids":[],"asks":[{"price":62792.6,"qty":0.32999995}],"checksum":2745058805,"timestamp":"2026-08-16T23:38:01.377909Z"}]}}
{"rx_ns": 42946823079700, "frame": {"channel":"book","type":"update","data":[{"symbol":"BTC/USD","bids":[],"asks":[{"price":62810.3,"qty":0.13109402}],"checksum":2745058805,"timestamp":"2026-08-16T23:38:01.377940Z"}]}}
{"rx_ns": 42946823088200, "frame": {"channel":"book","type":"update","data":[{"symbol":"BTC/USD","bids":[],"asks":[{"price":62803.2,"qty":1.50323371}],"checksum":620378616,"timestamp":"2026-08-16T23:38:01.379888Z"}]}}
{"rx_ns": 42946823096800, "frame": {"channel":"book","type":"update","data":[{"symbol":"BTC/USD","bids":[{"price":62780.5,"qty":0.06101297}],"asks":[],"checksum":620378616,"timestamp":"2026-08-16T23:38:01.382498Z"}]}}
{"rx_ns": 42946823105300, "frame": {"channel":"book","type":"update","data":[{"symbol":"BTC/USD","bids":[{"price":62781.7,"qty":0.01050463}],"asks":[],"checksum":2311275496,"timestamp":"2026-08-16T23:38:01.382769Z"}]}}
{"rx_ns": 42946823116500, "frame": {"channel":"book","type":"update","data":[{"symbol":"BTC/USD","bids":[],"asks":[{"price":62816.2,"qty":0.00000000},{"price":62818.8,"qty":0.46828931},{"price":62818.7,"qty":1.59575715}],"checksum":2311275496,"timestamp":"2026-08-16T23:38:01.383877Z"}]}}
{"rx_ns": 42946823128100, "frame": {"channel":"book","type":"update","data":[{"symbol":"BTC/USD","bids":[{"price":62791.2,"qty":0.40796420}],"asks":[],"checksum":1748223774,"timestamp":"2026-08-16T23:38:01.387898Z"}]}}
{"rx_ns": 42946823137600, "frame": {"channel":"book","type":"update","data":[{"symbol":"BTC/USD","bids":[],"asks":[{"price":62791.3,"qty":0.38601214}],"checksum":4243915096,"timestamp":"2026-08-16T23:38:01.388130Z"}]}}
{"rx_ns": 42946823146900, "frame": {"channel":"book","type":"update","data":[{"symbol":"BTC/USD","bids":[],"asks":[{"price":62791.3,"qty":0.39193864}],"checksum":300863609,"timestamp":"2026-08-16T23:38:01.395214Z"}]}}
{"rx_ns": 42946823156200, "frame": {"channel":"book","type":"update","data":[{"symbol":"BTC/USD","bids":[{"price":62791.2,"qty":0.33152193}],"asks":[],"checksum":4028519567,"timestamp":"2026-08-16T23:38:01.395515Z"}]}}
{"rx_ns": 42946823167200, "frame": {"channel":"book","type":"update","data":[{"symbol":"BTC/USD","bids":[],"asks":[{"price":62818.7,"qty":0.00000000},{"price":62818.8,"qty":0.46828931},{"price":62816.2,"qty":1.59575715}],"checksum":4028519567,"timestamp":"2026-08-16T23:38:01.395838Z"}]}}
{"rx_ns": 42946823178400, "frame": {"channel":"book","type":"update","data":[{"symbol":"BTC/USD","bids":[{"price":62780.1,"qty":0.00000000},{"price":62774.1,"qty":0.29364066}],"asks":[],"checksum":4028519567,"timestamp":"2026-08-16T23:38:01.399023Z"}]}}
{"rx_ns": 42946823189400, "frame": {"channel":"book","type":"update","data":[{"symbol":"BTC/USD","bids":[],"asks":[{"price":62816.2,"qty":0.00000000},{"price":62818.8,"qty":0.46828931},{"price":62818.7,"qty":1.59575715}],"checksum":4028519567,"timestamp":"2026-08-16T23:38:01.401980Z"}]}}
{"rx_ns": 42946823199900, "frame": {"channel":"book","type":"update","data":[{"symbol":"BTC/USD","bids":[{"price":62780.7,"qty":0.00000000},{"price":62774.0,"qty":0.74369300},{"price":62782.2,"qty":0.07962767}],"asks":[],"checksum":3698360267,"timestamp":"2026-08-16T23:38:01.402328Z"}]}}
{"rx_ns": 42946823211300, "frame": {"channel":"book","type":"update","data":[{"symbol":"BTC/USD","bids":[],"asks":[{"price":62809.9,"qty":0.00222509}],"checksum":3698360267,"timestamp":"2026-08-16T23:38:01.402374Z"}]}}
{"rx_ns": 42946863097500, "frame": {"channel":"book","type":"update","data":[{"symbol":"BTC/USD","bids":[{"price":62782.3,"qty":0.02785521}],"asks":[],"checksum":36566971,"timestamp":"2026-08-16T23:38:01.404864Z"}]}}
{"rx_ns": 42946863150100, "frame": {"channel":"book","type":"update","data":[{"symbol":"BTC/USD","bids":[],"asks":[{"price":62815.6,"qty":0.03083852}],"checksum":36566971,"timestamp":"2026-08-16T23:38:01.405425Z"}]}}
{"rx_ns": 42946863162300, "frame": {"channel":"book","type":"update","data":[{"symbol":"BTC/USD","bids":[{"price":62779.2,"qty":0.46828931}],"asks":[],"checksum":36566971,"timestamp":"2026-08-16T23:38:01.405517Z"}]}}
{"rx_ns": 42946863172100, "frame": {"channel":"book","type":"update","data":[{"symbol":"BTC/USD","bids":[{"price":62791.2,"qty":0.40112193}],"asks":[],"checksum":1427311536,"timestamp":"2026-08-16T23:38:01.405989Z"}]}}
{"rx_ns": 42946863181300, "frame": {"channel":"book","type":"update","data":[{"symbol":"BTC/USD","bids":[{"price":62782.8,"qty":0.03185106}],"asks":[],"checksum":520131817,"timestamp":"2026-08-16T23:38:01.406242Z"}]}}
{"rx_ns": 42946863191100, "frame": {"channel":"book","type":"update","data":[{"symbol":"BTC/USD","bids":[{"price":62790.0,"qty":0.00318523}],"asks":[],"checksum":3664566073,"timestamp":"2026-08-16T23:38:01.417007Z"}]}}
{"rx_ns": 42946863202300, "frame": {"channel":"book","type":"update","data":[{"symbol":"BTC/USD","bids":[],"asks":[{"price":62791.3,"qty":0.17293867}],"checksum":2146273835,"timestamp":"2026-08-16T23:38:01.420254Z"}]}}
{"rx_ns": 42946863212400, "frame": {"channel":"book","type":"update","data":[{"symbol":"BTC/USD","bids":[],"asks":[{"price":62801.3,"qty":0.79934706}],"checksum":4026838791,"timestamp":"2026-08-16T23:38:01.420518Z"}]}}
{"rx_ns": 42946863221400, "frame": {"channel":"book","type":"update","data":[{"symbol":"BTC/USD","bids":[{"price":62790.9,"qty":0.79629279}],"asks":[],"checksum":1494215353,"timestamp":"2026-08-16T23:38:01.420755Z"}]}}
{"rx_ns": 42946863291900, "frame": {"channel":"book","type":"update","data":[{"symbol":"BTC/USD","bids":[],"asks":[{"price":62811.1,"qty":0.00000000},{"price":62815.7,"qty":0.10331161}],"checksum":1494215353,"timestamp":"2026-08-16T23:38:01.420871Z"}]}}
{"rx_ns": 42946863310100, "frame": {"channel":"book","type":"update","data":[{"symbol":"BTC/USD","bids":[],"asks":[{"price":62805.5,"qty":0.00000000},{"price":62818.7,"qty":1.59575715},{"price":62809.7,"qty":0.19620257}],"checksum":1494215353,"timestamp":"2026-08-16T23:38:01.421941Z"}]}}
{"rx_ns": 42946863323900, "frame": {"channel":"book","type":"update","data":[{"symbol":"BTC/USD","bids":[],"asks":[{"price":62801.2,"qty":0.24785175}],"checksum":1335722306,"timestamp":"2026-08-16T23:38:01.422842Z"}]}}
{"rx_ns": 42946863334100, "frame": {"channel":"book","type":"update","data":[{"symbol":"BTC/USD","bids":[],"asks":[{"price":62809.9,"qty":0.24579835}],"checksum":1335722306,"timestamp":"2026-08-16T23:38:01.423160Z"}]}}
{"rx_ns": 42946863343700, "frame": {"channel":"book","type":"update","data":[{"symbol":"BTC/USD","bids":[],"asks":[{"price":62811.0,"qty":0.00000000},{"price":62815.7,"qty":0.10331161}],"checksum":1335722306,"timestamp":"2026-08-16T23:38:01.424422Z"}]}}
{"rx_ns": 42946863354600, "frame": {"channel":"book","type":"update","data":[{"symbol":"BTC/USD","bids":[{"price":62791.2,"qty":0.47756420}],"asks":[],"checksum":1624915639,"timestamp":"2026-08-16T23:38:01.425221Z"}]}}
{"rx_ns": 42946863366200, "frame": {"channel":"book","type":"update","data":[{"symbol":"BTC/USD","bids":[],"asks":[{"price":62791.3,"qty":0.16701217}],"checksum":2129717806,"timestamp":"2026-08-16T23:38:01.425584Z"}]}}
{"rx_ns": 42946863376900, "frame": {"channel":"book","type":"update","data":[{"symbol":"BTC/USD","bids":[],"asks":[{"price":62810.9,"qty":0.00000000},{"price":62818.7,"qty":1.59575715},{"price":62813.2,"qty":0.20567240}],"checksum":2129717806,"timestamp":"2026-08-16T23:38:01.425724Z"}]}}
{"rx_ns": 42946863388600, "frame": {"channel":"book","type":"update","data":[{"symbol":"BTC/USD","bids":[{"price":62791.2,"qty":0.51299470}],"asks":[],"checksum":3436849565,"timestamp":"2026-08-16T23:38:01.426130Z"}]}}
{"rx_ns": 42946863398900, "frame": {"channel":"book","type":"update","data":[{"symbol":"BTC/USD","bids":[],"asks":[{"price":62813.1,"qty":0.07596729}],"checksum":3436849565,"timestamp":"2026-08-16T23:38:01.427944Z"}]}}
{"rx_ns": 42946863409000, "frame": {"channel":"book","type":"update","data":[{"symbol":"BTC/USD","bids":[],"asks":[{"price":62813.2,"qty":0.18489680}],"checksum":3436849565,"timestamp":"2026-08-16T23:38:01.428277Z"}]}}
{"rx_ns": 42946863442700, "frame": {"channel":"book","type":"update","data":[{"symbol":"BTC/USD","bids":[{"price":62781.7,"qty":0.00005100}],"asks":[],"checksum":3436849565,"timestamp":"2026-08-16T23:38:01.430000Z"}]}}
{"rx_ns": 42946863455800, "frame": {"channel":"book","type":"update","data":[{"symbol":"BTC/USD","bids":[],"asks":[{"price":62808.5,"qty":0.50933000}],"checksum":3436849565,"timestamp":"2026-08-16T23:38:01.430215Z"}]}}
{"rx_ns": 42946863465800, "frame": {"channel":"book","type":"update","data":[{"symbol":"BTC/USD","bids":[],"asks":[{"price":62791.3,"qty":0.17293867}],"checksum":3539008772,"timestamp":"2026-08-16T23:38:01.430362Z"}]}}
{"rx_ns": 42946863476000, "frame": {"channel":"book","type":"update","data":[{"symbol":"BTC/USD","bids":[{"price":62791.2,"qty":0.43655243}],"asks":[],"checksum":663456826,"timestamp":"2026-08-16T23:38:01.430384Z"}]}}
{"rx_ns": 42946863488200, "frame": {"channel":"book","type":"update","data":[{"symbol":"BTC/USD","bids":[],"asks":[{"price":62803.3,"qty":0.01100000},{"price":62805.5,"qty":3.79000002}],"checksum":1651018148,"timestamp":"2026-08-16T23:38:01.430522Z"}]}}
{"rx_ns": 42946863499200, "frame": {"channel":"book","type":"update","data":[{"symbol":"BTC/USD","bids":[],"asks":[{"price":62792.6,"qty":0.00000000},{"price":62815.6,"qty":0.03083852}],"checksum":4065363213,"timestamp":"2026-08-16T23:38:01.431411Z"}]}}
{"rx_ns": 42946863510900, "frame": {"channel":"book","type":"update","data":[{"symbol":"BTC/USD","bids":[],"asks":[{"price":62805.2,"qty":0.15928208}],"checksum":4065363213,"timestamp":"2026-08-16T23:38:01.432225Z"}]}}
{"rx_ns": 42946863521100, "frame": {"channel":"book","type":"update","data":[{"symbol":"BTC/USD","bids":[],"asks":[{"price":62808.4,"qty":0.15203501}],"checksum":4065363213,"timestamp":"2026-08-16T23:38:01.432317Z"}]}}
{"rx_ns": 42946863531300, "frame": {"channel":"book","type":"update","data":[{"symbol":"BTC/USD","bids":[],"asks":[{"price":62801.3,"qty":0.00318497}],"checksum":3341713082,"timestamp":"2026-08-16T23:38:01.438830Z"}]}}
{"rx_ns": 42946863557400, "frame": {"channel":"book","type":"update","data":[{"symbol":"BTC/USD","bids":[],"asks":[{"price":62805.5,"qty":0.00000000},{"price":62813.3,"qty":0.06960000},{"price":62803.8,"qty":3.79004932}],"checksum":3341713082,"timestamp":"2026-08-16T23:38:01.440038Z"}]}}
{"rx_ns": 42946863570100, "frame": {"channel":"book","type":"update","data":[{"symbol":"BTC/USD","bids":[],"asks":[{"price":62801.2,"qty":0.00000000},{"price":62813.3,"qty":0.06960000}],"checksum":2411606937,"timestamp":"2026-08-16T23:38:01.440435Z"}]}}
{"rx_ns": 42946863581900, "frame": {"channel":"book","type":"update","data":[{"symbol":"BTC/USD","bids":[],"asks":[{"price":62809.9,"qty":0.24357326},{"price":62805.1,"qty":0.00222509}],"checksum":2411606937,"timestamp":"2026-08-16T23:38:01.446240Z"}]}}
{"rx_ns": 42946863606900, "frame": {"channel":"book","type":"update","data":[{"symbol":"BTC/USD","bids":[],"asks":[{"price":62813.2,"qty":0.00000000},{"price":62813.3,"qty":0.06960000},{"price":62803.1,"qty":0.18489680}],"checksum":1576967647,"timestamp":"2026-08-16T23:38:01.450030Z"}]}}
{"rx_ns": 42946863620800, "frame": {"channel":"book","type":"update","data":[{"symbol":"BTC/USD","bids":[],"asks":[{"price":62813.1,"qty":0.00000000},{"price":62813.3,"qty":0.06960000}],"checksum":1576967647,"timestamp":"2026-08-16T23:38:01.451977Z"}]}}
{"rx_ns": 42946863630400, "frame": {"channel":"book","type":"update","data":[{"symbol":"BTC/USD","bids":[],"asks":[{"price":62813.1,"qty":0.02077560}],"checksum":1576967647,"timestamp":"2026-08-16T23:38:01.452271Z"}]}}
{"rx_ns": 42946863639500, "frame": {"channel":"book","type":"update","data":[{"symbol":"BTC/USD","bids":[{"price":62782.2,"qty":0.00000000},{"price":62776.2,"qty":0.10292118},{"price":62782.8,"qty":0.07962549}],"asks":[],"checksum":2497695024,"timestamp":"2026-08-16T23:38:01.454728Z"}]}}
{"rx_ns": 42946863649000, "frame": {"channel":"book","type":"update","data":[{"symbol":"BTC/USD","bids":[{"price":62782.3,"qty":0.00000000},{"price":62775.8,"qty":0.00318594}],"asks":[],"checksum":2497695024,"timestamp":"2026-08-16T23:38:01.455962Z"}]}}
{"rx_ns": 42946864004900, "frame": {"channel":"book","type":"update","data":[{"symbol":"BTC/USD","bids":[{"price":62782.9,"qty":0.02473415}],"asks":[],"checksum":1175219547,"timestamp":"2026-08-16T23:38:01.456292Z"}]}}
{"rx_ns": 42946864020500, "frame": {"channel":"book","type":"update","data":[{"symbol":"BTC/USD","bids":[{"price":62784.6,"qty":0.03194519}],"asks":[],"checksum":1495402573,"timestamp":"2026-08-16T23:38:01.458182Z"}]}}
{"rx_ns": 42946864057900, "frame": {"channel":"book","type":"update","data":[{"symbol":"BTC/USD","bids":[{"price":62791.2,"qty":0.51299470}],"asks":[],"checksum":2250514465,"timestamp":"2026-08-16T23:38:01.473079Z"}]}}
{"rx_ns": 42946864076000, "frame": {"channel":"book","type":"update","data":[{"symbol":"BTC/USD","bids":[],"asks":[{"price":62791.3,"qty":0.16701217}],"checksum":344924315,"timestamp":"2026-08-16T23:38:01.473325Z"}]}}
{"rx_ns": 42946873322000, "frame": {"channel":"book","type":"update","data":[{"symbol":"BTC/USD","bids":[],"asks":[{"price":62803.8,"qty":0.00000000},{"price":62813.3,"qty":0.06960000},{"price":62800.7,"qty":3.79023544}],"checksum":419626156,"timestamp":"2026-08-16T23:38:01.490106Z"}]}}
{"rx_ns": 42946880304400, "frame": {"channel":"book","type":"update","data":[{"symbol":"BTC/USD","bids":[],"asks":[{"price":62803.1,"qty":0.00000000},{"price":62813.3,"qty":0.06960000},{"price":62810.0,"qty":0.68489680}],"checksum":1199063658,"timestamp":"2026-08-16T23:38:01.491630Z"}]}}
{"rx_ns": 42946880350200, "frame": {"channel":"book","type":"update","data":[{"symbol":"BTC/USD","bids":[],"asks":[{"price":62803.2,"qty":0.05598472}],"checksum":946213074,"timestamp":"2026-08-16T23:38:01.491768Z"}]}}
{"rx_ns": 42946880361700, "frame": {"channel":"book","type":"update","data":[{"symbol":"BTC/USD","bids":[],"asks":[{"price":62805.2,"qty":0.00000000},{"price":62815.6,"qty":0.03083852}],"checksum":946213074,"timestamp":"2026-08-16T23:38:01.492105Z"}]}}
{"rx_ns": 42946880371400, "frame": {"channel":"book","type":"update","data":[{"symbol":"BTC/USD","bids":[],"asks":[{"price":62803.0,"qty":0.14418735}],"checksum":1826028569,"timestamp":"2026-08-16T23:38:01.492214Z"}]}}
{"rx_ns": 42946880379700, "frame": {"channel":"book","type":"update","data":[{"symbol":"BTC/USD","bids":[],"asks":[{"price":62800.6,"qty":1.14158264}],"checksum":1717098453,"timestamp":"2026-08-16T23:38:01.492281Z"}]}}
{"rx_ns": 42946880389000, "frame": {"channel":"book","type":"update","data":[{"symbol":"BTC/USD","bids":[],"asks":[{"price":62803.0,"qty":0.23318300}],"checksum":1397514330,"timestamp":"2026-08-16T23:38:01.493504Z"}]}}
{"rx_ns": 42946880397000, "frame": {"channel":"book","type":"update","data":[{"symbol":"BTC/USD","bids":[],"asks":[{"price":62805.1,"qty":0.00000000},{"price":62813.3,"qty":0.06960000}],"checksum":1397514330,"timestamp":"2026-08-16T23:38:01.493518Z"}]}}
{"rx_ns": 42946880405600, "frame": {"channel":"book","type":"update","data":[{"symbol":"BTC/USD","bids":[],"asks":[{"price":62803.0,"qty":0.08899565}],"checksum":3043819628,"timestamp":"2026-08-16T23:38:01.493691Z"}]}}
{"rx_ns": 42946880413400, "frame": {"channel":"book","type":"update","data":[{"symbol":"BTC/USD","bids":[],"asks":[{"price":62803.0,"qty":0.00000000},{"price":62815.6,"qty":0.03083852}],"checksum":3061168335,"timestamp":"2026-08-16T23:38:01.493772Z"}]}}
{"rx_ns": 42946880422000, "frame": {"channel":"book","type":"update","data":[{"symbol":"BTC/USD","bids":[],"asks":[{"price":62806.0,"qty":0.11000000}],"checksum":3061168335,"timestamp":"2026-08-16T23:38:01.494324Z"}]}}
{"rx_ns": 42946880429700, "frame": {"channel":"book","type":"update","data":[{"symbol":"BTC/USD","bids":[],"asks":[{"price":62803.1,"qty":0.04078576}],"checksum":2575515575,"timestamp":"2026-08-16T23:38:01.495495Z"}]}}
{"rx_ns": 42946887435500, "frame": {"channel":"book","type":"update","data":[{"symbol":"BTC/USD","bids":[],"asks":[{"price":62803.1,"qty":0.06840638}],"checksum":1021186483,"timestamp":"2026-08-16T23:38:01.496145Z"}]}}
{"rx_ns": 42946893839600, "frame": {"channel":"book","type":"update","data":[{"symbol":"BTC/USD","bids":[],"asks":[{"price":62800.7,"qty":0.00000000},{"price":62813.3,"qty":0.06960000},{"price":62803.3,"qty":3.80117314}],"checksum":185101305,"timestamp":"2026-08-16T23:38:01.506831Z"}]}}
{"rx_ns": 42946893892700, "frame": {"channel":"book","type":"update","data":[{"symbol":"BTC/USD","bids":[],"asks":[{"price":62800.6,"qty":0.00000000},{"price":62815.6,"qty":0.03083852}],"checksum":4201044545,"timestamp":"2026-08-16T23:38:01.508174Z"}]}}
{"rx_ns": 42946893929600, "frame": {"channel":"book","type":"update","data":[{"symbol":"BTC/USD","bids":[],"asks":[{"price":62803.1,"qty":0.04078576}],"checksum":2342090726,"timestamp":"2026-08-16T23:38:01.510058Z"}]}}
{"rx_ns": 42946893943100, "frame": {"channel":"book","type":"update","data":[{"symbol":"BTC/USD","bids":[],"asks":[{"price":62803.1,"qty":0.00000000},{"price":62815.7,"qty":0.10331161}],"checksum":627270606,"timestamp":"2026-08-16T23:38:01.510068Z"}]}}
{"rx_ns": 42946893967500, "frame": {"channel":"book","type":"update","data":[{"symbol":"BTC/USD","bids":[],"asks":[{"price":62803.2,"qty":1.24426073}],"checksum":3440525999,"timestamp":"2026-08-16T23:38:01.512772Z"}]}}
{"rx_ns": 42946893979400, "frame": {"channel":"book","type":"update","data":[{"symbol":"BTC/USD","bids":[],"asks":[{"price":62810.0,"qty":0.50000000},{"price":62813.3,"qty":0.25449680}],"checksum":3440525999,"timestamp":"2026-08-16T23:38:01.514153Z"}]}}
{"rx_ns": 42946903762100, "frame": {"channel":"book","type":"update","data":[{"symbol":"BTC/USD","bids":[],"asks":[{"price":62813.1,"qty":0.07331118}],"checksum":3440525999,"timestamp":"2026-08-16T23:38:01.517272Z"}]}}
{"rx_ns": 42946909069600, "frame": {"channel":"book","type":"update","data":[{"symbol":"BTC/USD","bids":[{"price":62791.2,"qty":0.49815064}],"asks":[],"checksum":1037109929,"timestamp":"2026-08-16T23:38:01.526113Z"}]}}
{"rx_ns": 42946909125300, "frame": {"channel":"book","type":"update","data":[{"symbol":"BTC/USD","bids":[],"asks":[{"price":62809.7,"qty":0.00000000},{"price":62818.6,"qty":0.00222509}],"checksum":1037109929,"timestamp":"2026-08-16T23:38:01.526874Z"}]}}
{"rx_ns": 42946917800500, "frame": {"channel":"book","type":"update","data":[{"symbol":"BTC/USD","bids":[{"price":62776.2,"qty":0.00000000},{"price":62775.8,"qty":0.00318594}],"asks":[],"checksum":1037109929,"timestamp":"2026-08-16T23:38:01.530606Z"}]}}
{"rx_ns": 42946917853900, "frame": {"channel":"book","type":"update","data":[{"symbol":"BTC/USD","bids":[],"asks":[{"price":62803.3,"qty":0.01100000}],"checksum":1806738532,"timestamp":"2026-08-16T23:38:01.531194Z"}]}}
{"rx_ns": 42946917865100, "frame": {"channel":"book","type":"update","data":[{"symbol":"BTC/USD","bids":[],"asks":[{"price":62813.3,"qty":0.06960000},{"price":62815.6,"qty":0.21573532}],"checksum":1806738532,"timestamp":"2026-08-16T23:38:01.534312Z"}]}}
{"rx_ns": 42946917874900, "frame": {"channel":"book","type":"update","data":[{"symbol":"BTC/USD","bids":[],"asks":[{"price":62803.2,"qty":0.05598472}],"checksum":2462213399,"timestamp":"2026-08-16T23:38:01.534540Z"}]}}
{"rx_ns": 42946918299700, "frame": {"channel":"book","type":"update","data":[{"symbol":"BTC/USD","bids":[],"asks":[{"price":62803.2,"qty":0.11289404}],"checksum":3921496087,"timestamp":"2026-08-16T23:38:01.534865Z"}]}}
{"rx_ns": 42946918312400, "frame": {"channel":"book","type":"update","data":[{"symbol":"BTC/USD","bids":[],"asks":[{"price":62813.1,"qty":0.02077560}],"checksum":3921496087,"timestamp":"2026-08-16T23:38:01.536479Z"}]}}
{"rx_ns": 42946941403200, "frame": {"channel":"book","type":"update","data":[{"symbol":"BTC/USD","bids":[],"asks":[{"price":62803.2,"qty":0.05690932},{"price":62803.1,"qty":0.05598472}],"checksum":1616801797,"timestamp":"2026-08-16T23:38:01.563709Z"}]}}
{"rx_ns": 42946941468000, "frame": {"channel":"book","type":"update","data":[{"symbol":"BTC/USD","bids":[],"asks":[{"price":62815.6,"qty":0.03083852},{"price":62813.2,"qty":0.18489680}],"checksum":1616801797,"timestamp":"2026-08-16T23:38:01.565338Z"}]}}
{"rx_ns": 42946943598900, "frame": {"channel":"book","type":"update","data":[{"symbol":"BTC/USD","bids":[],"asks":[{"price":62813.1,"qty":0.07331118}],"checksum":1616801797,"timestamp":"2026-08-16T23:38:01.567340Z"}]}}
{"rx_ns": 42946969232800, "frame": {"channel":"book","type":"update","data":[{"symbol":"BTC/USD","bids":[{"price":62780.5,"qty":0.00000000},{"price":62775.5,"qty":0.00829935}],"asks":[],"checksum":1616801797,"timestamp":"2026-08-16T23:38:01.586891Z"}]}}
{"rx_ns": 42946969283600, "frame": {"channel":"book","type":"update","data":[{"symbol":"BTC/USD","bids":[{"price":62785.1,"qty":0.06142600}],"asks":[],"checksum":1095941684,"timestamp":"2026-08-16T23:38:01.586981Z"}]}}
{"rx_ns": 42946969294900, "frame": {"channel":"book","type":"update","data":[{"symbol":"BTC/USD","bids":[],"asks":[{"price":62813.2,"qty":0.00000000},{"price":62815.7,"qty":0.10331161},{"price":62813.0,"qty":0.18489680}],"checksum":1095941684,"timestamp":"2026-08-16T23:38:01.588218Z"}]}}
{"rx_ns": 42946976361500, "frame": {"channel":"book","type":"update","data":[{"symbol":"BTC/USD","bids":[],"asks":[{"price":62813.1,"qty":0.02077560}],"checksum":1095941684,"timestamp":"2026-08-16T23:38:01.590667Z"}]}}
{"rx_ns": 42946976422500, "frame": {"channel":"book","type":"update","data":[{"symbol":"BTC/USD","bids":[{"price":62785.2,"qty":0.02788652}],"asks":[],"checksum":1560325775,"timestamp":"2026-08-16T23:38:01.590703Z"}]}}
{"rx_ns": 42946976434900, "frame": {"channel":"book","type":"update","data":[{"symbol":"BTC/USD","bids":[],"asks":[{"price":62813.1,"qty":0.00000000},{"price":62815.7,"qty":0.10331161}],"checksum":1560325775,"timestamp":"2026-08-16T23:38:01.590795Z"}]}}
{"rx_ns": 42946976446400, "frame": {"channel":"book","type":"update","data":[{"symbol":"BTC/USD","bids":[],"asks":[{"price":62812.9,"qty":0.07596729}],"checksum":1560325775,"timestamp":"2026-08-16T23:38:01.592235Z"}]}}
{"rx_ns": 42946976473700, "frame": {"channel":"book","type":"update","data":[{"symbol":"BTC/USD","bids":[{"price":62790.9,"qty":0.80575127}],"asks":[],"checksum":2889111423,"timestamp":"2026-08-16T23:38:01.593612Z"}]}}
{"rx_ns": 42946984575000, "frame": {"channel":"book","type":"update","data":[{"symbol":"BTC/USD","bids":[{"price":62782.8,"qty":0.04777443}],"asks":[],"checksum":2889111423,"timestamp":"2026-08-16T23:38:01.607964Z"}]}}
{"rx_ns": 42946990092400, "frame": {"channel":"book","type":"update","data":[{"symbol":"BTC/USD","bids":[],"asks":[{"price":62813.0,"qty":0.00000000},{"price":62815.7,"qty":0.10331161},{"price":62812.8,"qty":0.18489680}],"checksum":2889111423,"timestamp":"2026-08-16T23:38:01.609869Z"}]}}
{"rx_ns": 42946994130700, "frame": {"channel":"book","type":"update","data":[{"symbol":"BTC/USD","bids":[{"price":62782.9,"qty":0.00000000},{"price":62775.8,"qty":0.00318594}],"asks":[],"checksum":2889111423,"timestamp":"2026-08-16T23:38:01.610421Z"}]}}
{"rx_ns": 42946994191500, "frame": {"channel":"book","type":"update","data":[{"symbol":"BTC/USD","bids":[],"asks":[{"price":62812.9,"qty":0.00000000},{"price":62815.7,"qty":0.10331161}],"checksum":2889111423,"timestamp":"2026-08-16T23:38:01.611002Z"}]}}
{"rx_ns": 42946994231600, "frame": {"channel":"book","type":"update","data":[{"symbol":"BTC/USD","bids":[{"price":62782.8,"qty":0.00000000},{"price":62775.5,"qty":0.00829935}],"asks":[],"checksum":2889111423,"timestamp":"2026-08-16T23:38:01.611083Z"}]}}
{"rx_ns": 42946994246600, "frame": {"channel":"book","type":"update","data":[{"symbol":"BTC/USD","bids":[{"price":62784.6,"qty":0.00009500},{"price":62785.9,"qty":0.07962319}],"asks":[],"checksum":3761237606,"timestamp":"2026-08-16T23:38:01.611190Z"}]}}
{"rx_ns": 42946994258600, "frame": {"channel":"book","type":"update","data":[{"symbol":"BTC/USD","bids":[],"asks":[{"price":62812.7,"qty":0.07596729}],"checksum":3761237606,"timestamp":"2026-08-16T23:38:01.611399Z"}]}}
{"rx_ns": 42946994268900, "frame": {"channel":"book","type":"update","data":[{"symbol":"BTC/USD","bids":[{"price":62786.0,"qty":0.04214676}],"asks":[],"checksum":3678940694,"timestamp":"2026-08-16T23:38:01.612998Z"}]}}
{"rx_ns": 42946994279300, "frame": {"channel":"book","type":"update","data":[{"symbol":"BTC/USD","bids":[{"price":62785.2,"qty":0.00000000},{"price":62775.8,"qty":0.00318594}],"asks":[],"checksum":3724522284,"timestamp":"2026-08-16T23:38:01.613103Z"}]}}
{"rx_ns": 42946995792300, "frame": {"channel":"book","type":"update","data":[{"symbol":"BTC/USD","bids":[{"price":62786.5,"qty":0.03184927}],"asks":[],"checksum":1394507087,"timestamp":"2026-08-16T23:38:01.614788Z"}]}}
{"rx_ns": 42947006540500, "frame": {"channel":"book","type":"update","data":[{"symbol":"BTC/USD","bids":[],"asks":[{"price":62814.6,"qty":0.19072285}],"checksum":1394507087,"timestamp":"2026-08-16T23:38:01.623524Z"}]}}
{"rx_ns": 42947012582300, "frame": {"channel":"book","type":"update","data":[{"symbol":"BTC/USD","bids":[],"asks":[{"price":62812.7,"qty":0.12318580}],"checksum":1394507087,"timestamp":"2026-08-16T23:38:01.624852Z"}]}}
{"rx_ns": 42947013656400, "frame": {"channel":"book","type":"update","data":[{"symbol":"BTC/USD","bids":[{"price":62790.9,"qty":0.79629279}],"asks":[],"checksum":3998399402,"timestamp":"2026-08-16T23:38:01.626926Z"}]}}
{"rx_ns": 42947013707600, "frame": {"channel":"book","type":"update","data":[{"symbol":"BTC/USD","bids":[{"price":62791.2,"qty":0.50761108}],"asks":[],"checksum":1112264871,"timestamp":"2026-08-16T23:38:01.627057Z"}]}}
{"rx_ns": 42947013736700, "frame": {"channel":"book","type":"update","data":[{"symbol":"BTC/USD","bids":[],"asks":[{"price":62791.3,"qty":0.08901217}],"checksum":2078237671,"timestamp":"2026-08-16T23:38:01.629975Z"}]}}
{"rx_ns": 42947015459900, "frame": {"channel":"book","type":"update","data":[{"symbol":"BTC/USD","bids":[],"asks":[{"price":62812.8,"qty":0.00000000},{"price":62815.6,"qty":0.03083852},{"price":62809.8,"qty":0.18489680}],"checksum":2078237671,"timestamp":"2026-08-16T23:38:01.631274Z"}]}}
{"rx_ns": 42947018017400, "frame": {"channel":"book","type":"update","data":[{"symbol":"BTC/USD","bids":[],"asks":[{"price":62808.5,"qty":0.00000000},{"price":62815.6,"qty":0.03083852}],"checksum":2078237671,"timestamp":"2026-08-16T23:38:01.632064Z"}]}}
{"rx_ns": 42947018082000, "frame": {"channel":"book","type":"update","data":[{"symbol":"BTC/USD","bids":[],"asks":[{"price":62815.0,"qty":0.50830200}],"checksum":2078237671,"timestamp":"2026-08-16T23:38:01.633537Z"}]}}
{"rx_ns": 42947018116100, "frame": {"channel":"book","type":"update","data":[{"symbol":"BTC/USD","bids":[],"asks":[{"price":62812.7,"qty":0.07596729}],"checksum":2078237671,"timestamp":"2026-08-16T23:38:01.635667Z"}]}}
{"rx_ns": 42947018128300, "frame": {"channel":"book","type":"update","data":[{"symbol":"BTC/USD","bids":[],"asks":[{"price":62808.4,"qty":0.00000000},{"price":62815.6,"qty":0.03083852}],"checksum":2078237671,"timestamp":"2026-08-16T23:38:01.635837Z"}]}}
{"rx_ns": 42947018139100, "frame": {"channel":"book","type":"update","data":[{"symbol":"BTC/USD","bids":[],"asks":[{"price":62812.7,"qty":0.21972225}],"checksum":2078237671,"timestamp":"2026-08-16T23:38:01.635937Z"}]}}
{"rx_ns": 42947018148700, "frame": {"channel":"book","type":"update","data":[{"symbol":"BTC/USD","bids":[],"asks":[{"price":62815.0,"qty":0.00000000},{"price":62815.7,"qty":0.10331161}],"checksum":2078237671,"timestamp":"2026-08-16T23:38:01.636419Z"}]}}
{"rx_ns": 42947021050100, "frame": {"channel":"book","type":"update","data":[{"symbol":"BTC/USD","bids":[],"asks":[{"price":62812.7,"qty":0.07596729}],"checksum":2078237671,"timestamp":"2026-08-16T23:38:01.637761Z"}]}}
{"rx_ns": 42947030745000, "frame": {"channel":"book","type":"update","data":[{"symbol":"BTC/USD","bids":[],"asks":[{"price":62804.2,"qty":3.79012888}],"checksum":2078237671,"timestamp":"2026-08-16T23:38:01.644736Z"}]}}
{"rx_ns": 42947030807300, "frame": {"channel":"book","type":"update","data":[{"symbol":"BTC/USD","bids":[],"asks":[{"price":62803.2,"qty":1.18098705}],"checksum":937304535,"timestamp":"2026-08-16T23:38:01.646064Z"}]}}
{"rx_ns": 42947037165500, "frame": {"channel":"book","type":"update","data":[{"symbol":"BTC/USD","bids":[{"price":62791.2,"qty":0.43801108}],"asks":[],"checksum":2664679184,"timestamp":"2026-08-16T23:38:01.651306Z"}]}}
{"rx_ns": 42947042358100, "frame": {"channel":"book","type":"update","data":[{"symbol":"BTC/USD","bids":[],"asks":[{"price":62809.8,"qty":0.00000000},{"price":62815.7,"qty":0.10331161},{"price":62813.3,"qty":0.25449680}],"checksum":2664679184,"timestamp":"2026-08-16T23:38:01.652727Z"}]}}
{"rx_ns": 42947042444100, "frame": {"channel":"book","type":"update","data":[{"symbol":"BTC/USD","bids":[],"asks":[{"price":62791.3,"qty":0.16701217}],"checksum":1019368375,"timestamp":"2026-08-16T23:38:01.654290Z"}]}}
{"rx_ns": 42947042461100, "frame": {"channel":"book","type":"update","data":[{"symbol":"BTC/USD","bids":[],"asks":[{"price":62812.7,"qty":0.12318580}],"checksum":1019368375,"timestamp":"2026-08-16T23:38:01.655181Z"}]}}
{"rx_ns": 42947049742200, "frame": {"channel":"book","type":"update","data":[{"symbol":"BTC/USD","bids":[],"asks":[{"price":62807.6,"qty":0.46828931}],"checksum":1019368375,"timestamp":"2026-08-16T23:38:01.661891Z"}]}}
{"rx_ns": 42947049813500, "frame": {"channel":"book","type":"update","data":[{"symbol":"BTC/USD","bids":[],"asks":[{"price":62804.5,"qty":0.15928208}],"checksum":1019368375,"timestamp":"2026-08-16T23:38:01.662027Z"}]}}
{"rx_ns": 42947049826600, "frame": {"channel":"book","type":"update","data":[{"symbol":"BTC/USD","bids":[],"asks":[{"price":62813.2,"qty":0.19620257}],"checksum":1019368375,"timestamp":"2026-08-16T23:38:01.662240Z"}]}}
{"rx_ns": 42947049837300, "frame": {"channel":"book","type":"update","data":[{"symbol":"BTC/USD","bids":[],"asks":[{"price":62812.7,"qty":0.04721851}],"checksum":1019368375,"timestamp":"2026-08-16T23:38:01.663915Z"}]}}
{"rx_ns": 42947049846500, "frame": {"channel":"book","type":"update","data":[{"symbol":"BTC/USD","bids":[],"asks":[{"price":62807.5,"qty":0.14121008}],"checksum":1019368375,"timestamp":"2026-08-16T23:38:01.663934Z"}]}}
{"rx_ns": 42947049856500, "frame": {"channel":"book","type":"update","data":[{"symbol":"BTC/USD","bids":[],"asks":[{"price":62812.7,"qty":0.00000000},{"price":62813.3,"qty":0.25449680}],"checksum":1019368375,"timestamp":"2026-08-16T23:38:01.664188Z"}]}}
{"rx_ns": 42947049940100, "frame": {"channel":"book","type":"update","data":[{"symbol":"BTC/USD","bids":[],"asks":[{"price":62813.1,"qty":0.19146453}],"checksum":1019368375,"timestamp":"2026-08-16T23:38:01.666335Z"}]}}
{"rx_ns": 42947055281300, "frame": {"channel":"book","type":"update","data":[{"symbol":"BTC/USD","bids":[],"asks":[{"price":62813.2,"qty":0.00000000},{"price":62813.3,"qty":0.25449680}],"checksum":1019368375,"timestamp":"2026-08-16T23:38:01.680960Z"}]}}
{"rx_ns": 42947068831000, "frame": {"channel":"book","type":"update","data":[{"symbol":"BTC/USD","bids":[],"asks":[{"price":62813.1,"qty":0.32436260}],"checksum":1019368375,"timestamp":"2026-08-16T23:38:01.682116Z"}]}}
{"rx_ns": 42947068887300, "frame": {"channel":"book","type":"update","data":[{"symbol":"BTC/USD","bids":[],"asks":[{"price":62813.1,"qty":0.13289807}],"checksum":1019368375,"timestamp":"2026-08-16T23:38:01.682132Z"}]}}
{"rx_ns": 42947068901600, "frame": {"channel":"book","type":"update","data":[{"symbol":"BTC/USD","bids":[],"asks":[{"price":62813.3,"qty":0.06960000},{"price":62803.0,"qty":0.18489680}],"checksum":3719964212,"timestamp":"2026-08-16T23:38:01.682160Z"}]}}
{"rx_ns": 42947068938200, "frame": {"channel":"book","type":"update","data":[{"symbol":"BTC/USD","bids":[],"asks":[{"price":62813.1,"qty":0.00000000},{"price":62813.3,"qty":0.06960000}],"checksum":3719964212,"timestamp":"2026-08-16T23:38:01.683622Z"}]}}
{"rx_ns": 42947068953900, "frame": {"channel":"book","type":"update","data":[{"symbol":"BTC/USD","bids":[],"asks":[{"price":62813.1,"qty":0.07770637}],"checksum":3719964212,"timestamp":"2026-08-16T23:38:01.683935Z"}]}}
{"rx_ns": 42947077565700, "frame": {"channel":"book","type":"update","data":[{"symbol":"BTC/USD","bids":[],"asks":[{"price":62804.5,"qty":0.00000000},{"price":62813.3,"qty":0.06960000}],"checksum":3719964212,"timestamp":"2026-08-16T23:38:01.691650Z"}]}}
{"rx_ns": 42947077622200, "frame": {"channel":"book","type":"update","data":[{"symbol":"BTC/USD","bids":[{"price":62789.6,"qty":0.46828931}],"asks":[],"checksum":1684759509,"timestamp":"2026-08-16T23:38:01.691752Z"}]}}
{"rx_ns": 42947077662800, "frame": {"channel":"book","type":"update","data":[{"symbol":"BTC/USD","bids":[],"asks":[{"price":62803.8,"qty":0.15928208}],"checksum":1684759509,"timestamp":"2026-08-16T23:38:01.698945Z"}]}}
{"rx_ns": 42947092926000, "frame": {"channel":"book","type":"update","data":[{"symbol":"BTC/USD","bids":[{"price":62791.2,"qty":0.53801108}],"asks":[],"checksum":275618112,"timestamp":"2026-08-16T23:38:01.718733Z"}]}}
{"rx_ns": 42947110324900, "frame": {"channel":"book","type":"update","data":[{"symbol":"BTC/USD","bids":[],"asks":[{"price":62803.1,"qty":0.00000000},{"price":62813.3,"qty":0.06960000},{"price":62801.8,"qty":0.05598472}],"checksum":1583429609,"timestamp":"2026-08-16T23:38:01.733468Z"}]}}
{"rx_ns": 42947113456400, "frame": {"channel":"book","type":"update","data":[{"symbol":"BTC/USD","bids":[],"asks":[{"price":62801.7,"qty":0.02595809}],"checksum":2579754582,"timestamp":"2026-08-16T23:38:01.737902Z"}]}}
{"rx_ns": 42947157968200, "frame": {"channel":"book","type":"update","data":[{"symbol":"BTC/USD","bids":[],"asks":[{"price":62804.2,"qty":0.00000000},{"price":62813.1,"qty":0.07770637},{"price":62810.2,"qty":3.79014856}],"checksum":2579754582,"timestamp":"2026-08-16T23:38:01.782901Z"}]}}
{"rx_ns": 42947158041500, "frame": {"channel":"book","type":"update","data":[{"symbol":"BTC/USD","bids":[],"asks":[{"price":62803.0,"qty":0.00000000},{"price":62813.1,"qty":0.07770637},{"price":62809.8,"qty":0.18489680}],"checksum":365274667,"timestamp":"2026-08-16T23:38:01.783930Z"}]}}
{"rx_ns": 42947161043100, "frame": {"channel":"book","type":"update","data":[{"symbol":"BTC/USD","bids":[],"asks":[{"price":62803.2,"qty":0.05690932}],"checksum":935383986,"timestamp":"2026-08-16T23:38:01.784114Z"}]}}
{"rx_ns": 42947161106200, "frame": {"channel":"book","type":"update","data":[{"symbol":"BTC/USD","bids":[],"asks":[{"price":62803.2,"qty":0.00000000},{"price":62813.1,"qty":0.07770637}],"checksum":1257083400,"timestamp":"2026-08-16T23:38:01.784185Z"}]}}
{"rx_ns": 42947161120500, "frame": {"channel":"book","type":"update","data":[{"symbol":"BTC/USD","bids":[],"asks":[{"price":62802.9,"qty":0.15964672}],"checksum":2703775025,"timestamp":"2026-08-16T23:38:01.784356Z"}]}}
{"rx_ns": 42947161156900, "frame": {"channel":"book","type":"update","data":[{"symbol":"BTC/USD","bids":[],"asks":[{"price":62802.9,"qty":0.00000000},{"price":62813.1,"qty":0.07770637}],"checksum":1257083400,"timestamp":"2026-08-16T23:38:01.785264Z"}]}}
{"rx_ns": 42947161171400, "frame": {"channel":"book","type":"update","data":[{"symbol":"BTC/USD","bids":[],"asks":[{"price":62803.3,"qty":0.11217152}],"checksum":3354329682,"timestamp":"2026-08-16T23:38:01.785485Z"}]}}
{"rx_ns": 42947161602800, "frame": {"channel":"book","type":"update","data":[{"symbol":"BTC/USD","bids":[],"asks":[{"price":62809.8,"qty":0.18712189}],"checksum":3354329682,"timestamp":"2026-08-16T23:38:01.786527Z"}]}}
{"rx_ns": 42947167766800, "frame": {"channel":"book","type":"update","data":[{"symbol":"BTC/USD","bids":[],"asks":[{"price":62809.9,"qty":1.28860055}],"checksum":3354329682,"timestamp":"2026-08-16T23:38:01.788164Z"}]}}
{"rx_ns": 42947182454200, "frame": {"channel":"book","type":"update","data":[{"symbol":"BTC/USD","bids":[{"price":62780.6,"qty":0.78625848}],"asks":[],"checksum":3354329682,"timestamp":"2026-08-16T23:38:01.798593Z"}]}}
{"rx_ns": 42947182535300, "frame": {"channel":"book","type":"update","data":[{"symbol":"BTC/USD","bids":[{"price":62780.6,"qty":0.54950980}],"asks":[],"checksum":3354329682,"timestamp":"2026-08-16T23:38:01.799767Z"}]}}
{"rx_ns": 42947182551700, "frame": {"channel":"book","type":"update","data":[{"symbol":"BTC/USD","bids":[{"price":62780.6,"qty":0.48102500}],"asks":[],"checksum":3354329682,"timestamp":"2026-08-16T23:38:01.799778Z"}]}}
{"rx_ns": 42947182563600, "frame": {"channel":"book","type":"update","data":[{"symbol":"BTC/USD","bids":[{"price":62780.7,"qty":0.54248520}],"asks":[],"checksum":3354329682,"timestamp":"2026-08-16T23:38:01.800013Z"}]}}
{"rx_ns": 42947182651700, "frame": {"channel":"book","type":"update","data":[{"symbol":"BTC/USD","bids":[],"asks":[{"price":62810.2,"qty":0.00000000},{"price":62813.3,"qty":0.06960000},{"price":62803.0,"qty":3.79014773}],"checksum":2193339348,"timestamp":"2026-08-16T23:38:01.805420Z"}]}}
{"rx_ns": 42947182684100, "frame": {"channel":"book","type":"update","data":[{"symbol":"BTC/USD","bids":[],"asks":[{"price":62803.3,"qty":0.01100000}],"checksum":912214613,"timestamp":"2026-08-16T23:38:01.806716Z"}]}}
{"rx_ns": 42947182720200, "frame": {"channel":"book","type":"update","data":[{"symbol":"BTC/USD","bids":[],"asks":[{"price":62809.9,"qty":0.24357326}],"checksum":912214613,"timestamp":"2026-08-16T23:38:01.806867Z"}]}}
{"rx_ns": 42947182732500, "frame": {"channel":"book","type":"update","data":[{"symbol":"BTC/USD","bids":[],"asks":[{"price":62802.9,"qty":1.23581412}],"checksum":212343242,"timestamp":"2026-08-16T23:38:01.806876Z"}]}}
{"rx_ns": 42947250411100, "frame": {"channel":"book","type":"update","data":[{"symbol":"BTC/USD","bids":[],"asks":[{"price":62803.0,"qty":0.00000000},{"price":62813.1,"qty":0.07770637},{"price":62804.7,"qty":3.79014221}],"checksum":1409775982,"timestamp":"2026-08-16T23:38:01.873526Z"}]}}
{"rx_ns": 42947288972300, "frame": {"channel":"book","type":"update","data":[{"symbol":"BTC/USD","bids":[],"asks":[{"price":62801.8,"qty":0.00000000},{"price":62813.1,"qty":0.07770637},{"price":62801.6,"qty":0.05598472}],"checksum":3336317953,"timestamp":"2026-08-16T23:38:01.914008Z"}]}}
{"rx_ns": 42947290468000, "frame": {"channel":"book","type":"update","data":[{"symbol":"BTC/USD","bids":[],"asks":[{"price":62801.7,"qty":0.00000000},{"price":62813.1,"qty":0.07770637}],"checksum":2721529374,"timestamp":"2026-08-16T23:38:01.915243Z"}]}}
{"rx_ns": 42947290499200, "frame": {"channel":"book","type":"update","data":[{"symbol":"BTC/USD","bids":[],"asks":[{"price":62801.6,"qty":0.00000000},{"price":62813.3,"qty":0.06960000},{"price":62801.8,"qty":0.05598472}],"checksum":148534162,"timestamp":"2026-08-16T23:38:01.916306Z"}]}}
{"rx_ns": 42947292851700, "frame": {"channel":"book","type":"update","data":[{"symbol":"BTC/USD","bids":[],"asks":[{"price":62801.5,"qty":0.02595809}],"checksum":3873333868,"timestamp":"2026-08-16T23:38:01.916582Z"}]}}
{"rx_ns": 42947298543600, "frame": {"channel":"book","type":"update","data":[{"symbol":"BTC/USD","bids":[{"price":62778.6,"qty":0.00000000},{"price":62776.8,"qty":0.10331161}],"asks":[],"checksum":3873333868,"timestamp":"2026-08-16T23:38:01.921180Z"}]}}
{"rx_ns": 42947298628900, "frame": {"channel":"book","type":"update","data":[{"symbol":"BTC/USD","bids":[],"asks":[{"price":62804.8,"qty":0.36000000}],"checksum":3873333868,"timestamp":"2026-08-16T23:38:01.922125Z"}]}}
{"rx_ns": 42947326531300, "frame": {"channel":"book","type":"update","data":[{"symbol":"BTC/USD","bids":[],"asks":[{"price":62798.5,"qty":0.79619769}],"checksum":3994432474,"timestamp":"2026-08-16T23:38:01.951290Z"}]}}
{"rx_ns": 42947329724700, "frame": {"channel":"book","type":"update","data":[{"symbol":"BTC/USD","bids":[],"asks":[{"price":62804.9,"qty":0.79611719}],"checksum":3994432474,"timestamp":"2026-08-16T23:38:01.951523Z"}]}}
{"rx_ns": 42947329779700, "frame": {"channel":"book","type":"update","data":[{"symbol":"BTC/USD","bids":[{"price":62785.3,"qty":0.79636458}],"asks":[],"checksum":1200474295,"timestamp":"2026-08-16T23:38:01.952195Z"}]}}
{"rx_ns": 42947329811500, "frame": {"channel":"book","type":"update","data":[{"symbol":"BTC/USD","bids":[],"asks":[{"price":62809.8,"qty":0.00222509},{"price":62808.1,"qty":0.18648880}],"checksum":1200474295,"timestamp":"2026-08-16T23:38:01.952490Z"}]}}
{"rx_ns": 42947329826100, "frame": {"channel":"book","type":"update","data":[{"symbol":"BTC/USD","bids":[{"price":62779.3,"qty":2.38932015}],"asks":[],"checksum":1200474295,"timestamp":"2026-08-16T23:38:01.952594Z"}]}}
{"rx_ns": 42947394352000, "frame": {"channel":"book","type":"update","data":[{"symbol":"BTC/USD","bids":[{"price":62790.9,"qty":0.00000000},{"price":62777.8,"qty":0.11000000}],"asks":[],"checksum":611048089,"timestamp":"2026-08-16T23:38:02.015099Z"}]}}
{"rx_ns": 42947394424200, "frame": {"channel":"book","type":"update","data":[{"symbol":"BTC/USD","bids":[],"asks":[{"price":62808.1,"qty":0.00159200},{"price":62802.8,"qty":0.18489680}],"checksum":3772208152,"timestamp":"2026-08-16T23:38:02.016303Z"}]}}
{"rx_ns": 42947394437900, "frame": {"channel":"book","type":"update","data":[{"symbol":"BTC/USD","bids":[{"price":62787.7,"qty":0.79633307}],"asks":[],"checksum":891024067,"timestamp":"2026-08-16T23:38:02.016504Z"}]}}
{"rx_ns": 42947428624100, "frame": {"channel":"book","type":"update","data":[{"symbol":"BTC/USD","bids":[],"asks":[{"price":62791.3,"qty":0.32629915}],"checksum":229335932,"timestamp":"2026-08-16T23:38:02.051685Z"}]}}
{"rx_ns": 42947428666600, "frame": {"channel":"book","type":"update","data":[{"symbol":"BTC/USD","bids":[],"asks":[{"price":62792.6,"qty":0.23893047}],"checksum":4222463003,"timestamp":"2026-08-16T23:38:02.051887Z"}]}}
{"rx_ns": 42947490171600, "frame": {"channel":"book","type":"update","data":[{"symbol":"BTC/USD","bids":[],"asks":[{"price":62801.8,"qty":0.00000000},{"price":62808.1,"qty":0.00159200},{"price":62801.4,"qty":0.05598472}],"checksum":2044321105,"timestamp":"2026-08-16T23:38:02.097799Z"}]}}
{"rx_ns": 42947552177100, "frame": {"channel":"book","type":"update","data":[{"symbol":"BTC/USD","bids":[],"asks":[{"price":62800.5,"qty":0.79622378}],"checksum":1300289455,"timestamp":"2026-08-16T23:38:02.174830Z"}]}}
{"rx_ns": 42947554717600, "frame": {"channel":"book","type":"update","data":[{"symbol":"BTC/USD","bids":[],"asks":[{"price":62801.5,"qty":0.00000000},{"price":62808.1,"qty":0.00159200}],"checksum":3235744262,"timestamp":"2026-08-16T23:38:02.176527Z"}]}}
{"rx_ns": 42947554766300, "frame": {"channel":"book","type":"update","data":[{"symbol":"BTC/USD","bids":[],"asks":[{"price":62801.4,"qty":0.00000000},{"price":62809.8,"qty":0.00222509},{"price":62801.8,"qty":0.05598472}],"checksum":3718659307,"timestamp":"2026-08-16T23:38:02.177553Z"}]}}
{"rx_ns": 42947554779800, "frame": {"channel":"book","type":"update","data":[{"symbol":"BTC/USD","bids":[],"asks":[{"price":62800.4,"qty":0.31977330}],"checksum":1196011240,"timestamp":"2026-08-16T23:38:02.178032Z"}]}}
{"rx_ns": 42947576203400, "frame": {"channel":"book","type":"update","data":[{"symbol":"BTC/USD","bids":[],"asks":[{"price":62804.7,"qty":0.00000000},{"price":62808.1,"qty":0.00159200},{"price":62802.7,"qty":3.79013973}],"checksum":1196011240,"timestamp":"2026-08-16T23:38:02.200254Z"}]}}
{"rx_ns": 42947578314600, "frame": {"channel":"book","type":"update","data":[{"symbol":"BTC/USD","bids":[],"asks":[{"price":62802.8,"qty":0.00000000},{"price":62808.1,"qty":0.00159200},{"price":62802.6,"qty":0.18489680}],"checksum":1196011240,"timestamp":"2026-08-16T23:38:02.201466Z"}]}}
{"rx_ns": 42947578390000, "frame": {"channel":"book","type":"update","data":[{"symbol":"BTC/USD","bids":[],"asks":[{"price":62802.9,"qty":0.00000000},{"price":62808.1,"qty":0.00159200}],"checksum":1196011240,"timestamp":"2026-08-16T23:38:02.201490Z"}]}}
{"rx_ns": 42947578423600, "frame": {"channel":"book","type":"update","data":[{"symbol":"BTC/USD","bids":[],"asks":[{"price":62800.4,"qty":1.41024762}],"checksum":128466214,"timestamp":"2026-08-16T23:38:02.202897Z"}]}}
{"rx_ns": 42947611103500, "frame": {"channel":"book","type":"update","data":[{"symbol":"BTC/USD","bids":[],"asks":[{"price":62803.8,"qty":0.00000000},{"price":62809.8,"qty":0.00222509}],"checksum":128466214,"timestamp":"2026-08-16T23:38:02.233239Z"}]}}
{"rx_ns": 42947611150900, "frame": {"channel":"book","type":"update","data":[{"symbol":"BTC/USD","bids":[],"asks":[{"price":62802.6,"qty":0.00000000},{"price":62809.9,"qty":0.24357326},{"price":62804.7,"qty":0.18489680}],"checksum":128466214,"timestamp":"2026-08-16T23:38:02.233348Z"}]}}
{"rx_ns": 42947613843300, "frame": {"channel":"book","type":"update","data":[{"symbol":"BTC/USD","bids":[],"asks":[{"price":62791.3,"qty":0.16701217}],"checksum":928540820,"timestamp":"2026-08-16T23:38:02.239204Z"}]}}
{"rx_ns": 42947617854200, "frame": {"channel":"book","type":"update","data":[{"symbol":"BTC/USD","bids":[{"price":62785.1,"qty":0.00000000},{"price":62777.8,"qty":0.11000000}],"asks":[],"checksum":928540820,"timestamp":"2026-08-16T23:38:02.242671Z"}]}}
{"rx_ns": 42947622746500, "frame": {"channel":"book","type":"update","data":[{"symbol":"BTC/USD","bids":[],"asks":[{"price":62803.7,"qty":0.15933308}],"checksum":928540820,"timestamp":"2026-08-16T23:38:02.246659Z"}]}}
{"rx_ns": 42947634996400, "frame": {"channel":"book","type":"update","data":[{"symbol":"BTC/USD","bids":[],"asks":[{"price":62792.6,"qty":0.00000000},{"price":62809.9,"qty":0.24357326}],"checksum":3606142446,"timestamp":"2026-08-16T23:38:02.259228Z"}]}}
{"rx_ns": 42947680486500, "frame": {"channel":"book","type":"update","data":[{"symbol":"BTC/USD","bids":[{"price":62789.6,"qty":0.00000000},{"price":62776.8,"qty":0.10331161}],"asks":[],"checksum":2821419149,"timestamp":"2026-08-16T23:38:02.301332Z"}]}}
{"rx_ns": 42947680540300, "frame": {"channel":"book","type":"update","data":[{"symbol":"BTC/USD","bids":[{"price":62791.2,"qty":0.37872900}],"asks":[],"checksum":2070382073,"timestamp":"2026-08-16T23:38:02.301656Z"}]}}
{"rx_ns": 42947680570200, "frame": {"channel":"book","type":"update","data":[{"symbol":"BTC/USD","bids":[{"price":62787.7,"qty":0.00000000},{"price":62776.4,"qty":0.01598519}],"asks":[],"checksum":3106539854,"timestamp":"2026-08-16T23:38:02.302758Z"}]}}
{"rx_ns": 42947680580900, "frame": {"channel":"book","type":"update","data":[{"symbol":"BTC/USD","bids":[{"price":62789.7,"qty":0.00000000},{"price":62775.8,"qty":0.00318594}],"asks":[],"checksum":1758851182,"timestamp":"2026-08-16T23:38:02.303852Z"}]}}
{"rx_ns": 42947683362900, "frame": {"channel":"book","type":"update","data":[{"symbol":"BTC/USD","bids":[],"asks":[{"price":62804.7,"qty":0.00000000},{"price":62810.0,"qty":0.50000000},{"price":62800.3,"qty":0.18489680}],"checksum":281573904,"timestamp":"2026-08-16T23:38:02.304861Z"}]}}
{"rx_ns": 42947683404200, "frame": {"channel":"book","type":"update","data":[{"symbol":"BTC/USD","bids":[{"price":62790.3,"qty":0.79630010}],"asks":[],"checksum":3189950789,"timestamp":"2026-08-16T23:38:02.305204Z"}]}}
{"rx_ns": 42947683415600, "frame": {"channel":"book","type":"update","data":[{"symbol":"BTC/USD","bids":[],"asks":[{"price":62801.8,"qty":0.00000000},{"price":62810.0,"qty":0.50000000},{"price":62797.3,"qty":0.05598472}],"checksum":998545642,"timestamp":"2026-08-16T23:38:02.306628Z"}]}}
{"rx_ns": 42947697913800, "frame": {"channel":"book","type":"update","data":[{"symbol":"BTC/USD","bids":[],"asks":[{"price":62798.5,"qty":0.00000000},{"price":62810.0,"qty":0.50000000}],"checksum":3086434746,"timestamp":"2026-08-16T23:38:02.323408Z"}]}}
{"rx_ns": 42947702270700, "frame": {"channel":"book","type":"update","data":[{"symbol":"BTC/USD","bids":[],"asks":[{"price":62797.6,"qty":0.79620942}],"checksum":2051201836,"timestamp":"2026-08-16T23:38:02.325565Z"}]}}
{"rx_ns": 42947702307900, "frame": {"channel":"book","type":"update","data":[{"symbol":"BTC/USD","bids":[{"price":62788.1,"qty":0.79632832}],"asks":[],"checksum":3135450395,"timestamp":"2026-08-16T23:38:02.326051Z"}]}}
{"rx_ns": 42947709569000, "frame": {"channel":"book","type":"update","data":[{"symbol":"BTC/USD","bids":[],"asks":[{"price":62803.7,"qty":0.00005100}],"checksum":3135450395,"timestamp":"2026-08-16T23:38:02.334959Z"}]}}
{"rx_ns": 42947720375100, "frame": {"channel":"book","type":"update","data":[{"symbol":"BTC/USD","bids":[],"asks":[{"price":62803.5,"qty":0.15928208}],"checksum":3135450395,"timestamp":"2026-08-16T23:38:02.346588Z"}]}}
{"rx_ns": 42947737807100, "frame": {"channel":"book","type":"update","data":[{"symbol":"BTC/USD","bids":[{"price":62791.2,"qty":0.53801108}],"asks":[],"checksum":1773131887,"timestamp":"2026-08-16T23:38:02.363802Z"}]}}
{"rx_ns": 42947762571100, "frame": {"channel":"heartbeat"}}
{"rx_ns": 42947770828700, "frame": {"channel":"book","type":"update","data":[{"symbol":"BTC/USD","bids":[],"asks":[{"price":62802.7,"qty":0.00000000},{"price":62809.9,"qty":0.24357326},{"price":62804.7,"qty":3.79013059}],"checksum":1773131887,"timestamp":"2026-08-16T23:38:02.389815Z"}]}}
{"rx_ns": 42947770866900, "frame": {"channel":"book","type":"update","data":[{"symbol":"BTC/USD","bids":[],"asks":[{"price":62800.4,"qty":0.31977330}],"checksum":3591996418,"timestamp":"2026-08-16T23:38:02.391244Z"}]}}
{"rx_ns": 42947770879300, "frame": {"channel":"book","type":"update","data":[{"symbol":"BTC/USD","bids":[],"asks":[{"price":62800.3,"qty":0.00000000},{"price":62809.9,"qty":0.24357326},{"price":62804.6,"qty":0.18489680}],"checksum":3431303827,"timestamp":"2026-08-16T23:38:02.392167Z"}]}}
{"rx_ns": 42947770889500, "frame": {"channel":"book","type":"update","data":[{"symbol":"BTC/USD","bids":[],"asks":[{"price":62804.6,"qty":1.69418676}],"checksum":3431303827,"timestamp":"2026-08-16T23:38:02.393564Z"}]}}
{"rx_ns": 42947805890200, "frame": {"channel":"book","type":"update","data":[{"symbol":"BTC/USD","bids":[{"price":62788.2,"qty":0.09538420}],"asks":[],"checksum":1852948902,"timestamp":"2026-08-16T23:38:02.431141Z"}]}}
{"rx_ns": 42947826047100, "frame": {"channel":"book","type":"update","data":[{"symbol":"BTC/USD","bids":[],"asks":[{"price":62804.7,"qty":0.00000000},{"price":62809.9,"qty":0.24357326},{"price":62801.7,"qty":3.79017557}],"checksum":954533511,"timestamp":"2026-08-16T23:38:02.449845Z"}]}}
{"rx_ns": 42947826135800, "frame": {"channel":"book","type":"update","data":[{"symbol":"BTC/USD","bids":[],"asks":[{"price":62804.6,"qty":0.18489680}],"checksum":954533511,"timestamp":"2026-08-16T23:38:02.451363Z"}]}}
{"rx_ns": 42947829114000, "frame": {"channel":"book","type":"update","data":[{"symbol":"BTC/USD","bids":[],"asks":[{"price":62804.6,"qty":0.00000000},{"price":62809.9,"qty":0.24357326},{"price":62807.5,"qty":0.32610688}],"checksum":954533511,"timestamp":"2026-08-16T23:38:02.452639Z"}]}}
{"rx_ns": 42947829144600, "frame": {"channel":"book","type":"update","data":[{"symbol":"BTC/USD","bids":[],"asks":[{"price":62800.4,"qty":1.33835519}],"checksum":2770451842,"timestamp":"2026-08-16T23:38:02.452884Z"}]}}
{"rx_ns": 42947830668800, "frame": {"channel":"book","type":"update","data":[{"symbol":"BTC/USD","bids":[],"asks":[{"price":62801.7,"qty":0.00000000},{"price":62810.0,"qty":0.50000000},{"price":62803.3,"qty":3.80117556}],"checksum":1664539394,"timestamp":"2026-08-16T23:38:02.457258Z"}]}}
{"rx_ns": 42947835201600, "frame": {"channel":"book","type":"update","data":[{"symbol":"BTC/USD","bids":[],"asks":[{"price":62800.4,"qty":0.31977330}],"checksum":4277297159,"timestamp":"2026-08-16T23:38:02.458306Z"}]}}
{"rx_ns": 42947852823900, "frame": {"channel":"book","type":"update","data":[{"symbol":"BTC/USD","bids":[],"asks":[{"price":62803.2,"qty":1.58092341}],"checksum":929163324,"timestamp":"2026-08-16T23:38:02.479125Z"}]}}
{"rx_ns": 42947855886800, "frame": {"channel":"book","type":"update","data":[{"symbol":"BTC/USD","bids":[],"asks":[{"price":62807.5,"qty":0.14121008},{"price":62803.1,"qty":0.18489680}],"checksum":1022581689,"timestamp":"2026-08-16T23:38:02.480284Z"}]}}
{"rx_ns": 42947888888400, "frame": {"channel":"book","type":"update","data":[{"symbol":"BTC/USD","bids":[{"price":62790.3,"qty":0.00000000},{"price":62776.8,"qty":0.10331161}],"asks":[],"checksum":2968216295,"timestamp":"2026-08-16T23:38:02.513380Z"}]}}
{"rx_ns": 42947888951600, "frame": {"channel":"book","type":"update","data":[{"symbol":"BTC/USD","bids":[{"price":62791.2,"qty":1.33430100}],"asks":[],"checksum":3015141924,"timestamp":"2026-08-16T23:38:02.514741Z"}]}}
{"rx_ns": 42947896491600, "frame": {"channel":"book","type":"update","data":[{"symbol":"BTC/USD","bids":[{"price":62791.2,"qty":1.31298808}],"asks":[],"checksum":3012899845,"timestamp":"2026-08-16T23:38:02.515729Z"}]}}
{"rx_ns": 42947896567100, "frame": {"channel":"book","type":"update","data":[{"symbol":"BTC/USD","bids":[{"price":62790.1,"qty":0.02131292}],"asks":[],"checksum":1406743130,"timestamp":"2026-08-16T23:38:02.516967Z"}]}}
{"rx_ns": 42947896656400, "frame": {"channel":"book","type":"update","data":[{"symbol":"BTC/USD","bids":[],"asks":[{"price":62803.3,"qty":0.01100000},{"price":62804.7,"qty":3.79017042}],"checksum":1406743130,"timestamp":"2026-08-16T23:38:02.517251Z"}]}}
{"rx_ns": 42947978273400, "frame": {"channel":"book","type":"update","data":[{"symbol":"BTC/USD","bids":[],"asks":[{"price":62797.6,"qty":0.00000000},{"price":62809.8,"qty":0.00222509}],"checksum":224948055,"timestamp":"2026-08-16T23:38:02.599550Z"}]}}
{"rx_ns": 42947979114300, "frame": {"channel":"book","type":"update","data":[{"symbol":"BTC/USD","bids":[{"price":62788.1,"qty":0.00000000},{"price":62776.8,"qty":0.10331161}],"asks":[],"checksum":2213627627,"timestamp":"2026-08-16T23:38:02.600078Z"}]}}
{"rx_ns": 42947979161600, "frame": {"channel":"book","type":"update","data":[{"symbol":"BTC/USD","bids":[],"asks":[{"price":62798.9,"qty":0.79619324}],"checksum":2344649299,"timestamp":"2026-08-16T23:38:02.601679Z"}]}}
{"rx_ns": 42948039600000, "frame": {"channel":"book","type":"update","data":[{"symbol":"BTC/USD","bids":[],"asks":[{"price":62804.7,"qty":0.00000000},{"price":62809.8,"qty":0.00222509}],"checksum":2344649299,"timestamp":"2026-08-16T23:38:02.664679Z"}]}}
{"rx_ns": 42948039677700, "frame": {"channel":"book","type":"update","data":[{"symbol":"BTC/USD","bids":[],"asks":[{"price":62803.1,"qty":0.00000000},{"price":62809.9,"qty":0.24357326},{"price":62807.5,"qty":0.32610688}],"checksum":709001415,"timestamp":"2026-08-16T23:38:02.666078Z"}]}}
{"rx_ns": 42948041757000, "frame": {"channel":"book","type":"update","data":[{"symbol":"BTC/USD","bids":[],"asks":[{"price":62803.2,"qty":0.00000000},{"price":62810.0,"qty":0.50000000}],"checksum":4096236737,"timestamp":"2026-08-16T23:38:02.666114Z"}]}}
{"rx_ns": 42948042590200, "frame": {"channel":"book","type":"update","data":[{"symbol":"BTC/USD","bids":[],"asks":[{"price":62804.7,"qty":0.37793598}],"checksum":4096236737,"timestamp":"2026-08-16T23:38:02.667587Z"}]}}
{"rx_ns": 42948042611400, "frame": {"channel":"book","type":"update","data":[{"symbol":"BTC/USD","bids":[],"asks":[{"price":62809.9,"qty":0.36755940}],"checksum":4096236737,"timestamp":"2026-08-16T23:38:02.667729Z"}]}}
{"rx_ns": 42948072661900, "frame": {"channel":"book","type":"update","data":[{"symbol":"BTC/USD","bids":[],"asks":[{"price":62809.9,"qty":0.24357326}],"checksum":4096236737,"timestamp":"2026-08-16T23:38:02.699057Z"}]}}
{"rx_ns": 42948321117300, "frame": {"channel":"book","type":"update","data":[{"symbol":"BTC/USD","bids":[{"price":62790.1,"qty":0.00000000},{"price":62776.4,"qty":0.01598519}],"asks":[],"checksum":3637943102,"timestamp":"2026-08-16T23:38:02.945809Z"}]}}
{"rx_ns": 42948325070700, "frame": {"channel":"book","type":"update","data":[{"symbol":"BTC/USD","bids":[{"price":62791.0,"qty":0.02131292}],"asks":[],"checksum":3263878484,"timestamp":"2026-08-16T23:38:02.946098Z"}]}}
{"rx_ns": 42948325125100, "frame": {"channel":"book","type":"update","data":[{"symbol":"BTC/USD","bids":[],"asks":[{"price":62809.9,"qty":0.36756776}],"checksum":3263878484,"timestamp":"2026-08-16T23:38:02.949979Z"}]}}
{"rx_ns": 42948327874500, "frame": {"channel":"book","type":"update","data":[{"symbol":"BTC/USD","bids":[{"price":62791.2,"qty":1.38258808}],"asks":[],"checksum":2996446060,"timestamp":"2026-08-16T23:38:02.953201Z"}]}}
{"rx_ns": 42948372810200, "frame": {"channel":"book","type":"update","data":[{"symbol":"BTC/USD","bids":[],"asks":[{"price":62809.9,"qty":0.24357326}],"checksum":2996446060,"timestamp":"2026-08-16T23:38:02.999046Z"}]}}
{"rx_ns": 42948430721300, "frame": {"channel":"book","type":"update","data":[{"symbol":"BTC/USD","bids":[],"asks":[{"price":62797.3,"qty":0.00000000},{"price":62810.0,"qty":0.50000000}],"checksum":1376800992,"timestamp":"2026-08-16T23:38:03.054422Z"}]}}
{"rx_ns": 42948430779000, "frame": {"channel":"book","type":"update","data":[{"symbol":"BTC/USD","bids":[],"asks":[{"price":62800.4,"qty":0.00000000},{"price":62810.3,"qty":0.13109402}],"checksum":2523327288,"timestamp":"2026-08-16T23:38:03.056420Z"}]}}
{"rx_ns": 42948432413500, "frame": {"channel":"book","type":"update","data":[{"symbol":"BTC/USD","bids":[],"asks":[{"price":62798.8,"qty":0.05598472}],"checksum":3020957121,"timestamp":"2026-08-16T23:38:03.057290Z"}]}}
{"rx_ns": 42948433870000, "frame": {"channel":"book","type":"update","data":[{"symbol":"BTC/USD","bids":[],"asks":[{"price":62807.5,"qty":0.14121008},{"price":62809.8,"qty":0.18712189}],"checksum":3020957121,"timestamp":"2026-08-16T23:38:03.057930Z"}]}}
{"rx_ns": 42948471891400, "frame": {"channel":"book","type":"update","data":[{"symbol":"BTC/USD","bids":[],"asks":[{"price":62809.3,"qty":0.50843600}],"checksum":3020957121,"timestamp":"2026-08-16T23:38:03.097288Z"}]}}
{"rx_ns": 42948472006500, "frame": {"channel":"book","type":"update","data":[{"symbol":"BTC/USD","bids":[],"asks":[{"price":62809.8,"qty":0.00222509},{"price":62808.1,"qty":0.18648880}],"checksum":3020957121,"timestamp":"2026-08-16T23:38:03.098394Z"}]}}
{"rx_ns": 42948473430700, "frame": {"channel":"book","type":"update","data":[{"symbol":"BTC/USD","bids":[],"asks":[{"price":62809.9,"qty":0.00000000},{"price":62810.0,"qty":0.50000000}],"checksum":3020957121,"timestamp":"2026-08-16T23:38:03.098447Z"}]}}
{"rx_ns": 42948473448800, "frame": {"channel":"book","type":"update","data":[{"symbol":"BTC/USD","bids":[],"asks":[{"price":62809.2,"qty":0.45457206}],"checksum":3020957121,"timestamp":"2026-08-16T23:38:03.098605Z"}]}}
{"rx_ns": 42948506123100, "frame": {"channel":"book","type":"update","data":[{"symbol":"BTC/USD","bids":[{"price":62786.0,"qty":0.25613755}],"asks":[],"checksum":251579807,"timestamp":"2026-08-16T23:38:03.131269Z"}]}}
{"rx_ns": 42948506192900, "frame": {"channel":"book","type":"update","data":[{"symbol":"BTC/USD","bids":[{"price":62780.7,"qty":1.16002175}],"asks":[],"checksum":251579807,"timestamp":"2026-08-16T23:38:03.131291Z"}]}}
{"rx_ns": 42948551967600, "frame": {"channel":"book","type":"update","data":[{"symbol":"BTC/USD","bids":[{"price":62789.3,"qty":0.79631398}],"asks":[],"checksum":79891852,"timestamp":"2026-08-16T23:38:03.174339Z"}]}}
{"rx_ns": 42948618003600, "frame": {"channel":"book","type":"update","data":[{"symbol":"BTC/USD","bids":[{"price":62788.5,"qty":0.06164822}],"asks":[],"checksum":832162561,"timestamp":"2026-08-16T23:38:03.243681Z"}]}}
