{"captured_at": "2026-08-16T23:37:01.904975+00:00", "url": "wss://ws.kraken.com/v2", "venue": "kraken", "symbol": "BTC/USD", "depth": 25, "subscribe": "{\"method\":\"subscribe\",\"params\":{\"channel\":\"book\",\"symbol\":[\"BTC/USD\"],\"depth\":25,\"snapshot\":true}}", "tool_version": "0.1.0", "clock": "perf_counter_ns", "capture_mode": "baseline", "cycles": 1, "origin_sent": null, "handshake_status": "HTTP/1.1 101 Switching Protocols"}
{"rx_ns": 42888730702400, "dir": "tx", "frame": {"method":"subscribe","params":{"channel":"book","symbol":["BTC/USD"],"depth":25,"snapshot":true}}}
{"rx_ns": 42888731021100, "frame": {"channel":"status","type":"update","data":[{"version":"2.0.10","system":"online","api_version":"v2","connection_id":15113583034416118705}]}}
{"rx_ns": 42888748949900, "frame": {"method":"subscribe","result":{"channel":"book","depth":25,"snapshot":true,"symbol":"BTC/USD"},"success":true,"time_in":"2026-08-16T23:37:03.374788Z","time_out":"2026-08-16T23:37:03.374824Z"}}
{"rx_ns": 42889068994200, "frame": {"channel":"book","type":"snapshot","data":[{"symbol":"BTC/USD","bids":[{"price":62802.5,"qty":0.02987767},{"price":62800.7,"qty":0.05598472},{"price":62800.6,"qty":0.00005100},{"price":62797.5,"qty":0.00005100},{"price":62796.2,"qty":0.00019900},{"price":62795.7,"qty":0.00012700},{"price":62794.3,"qty":0.00005100},{"price":62794.0,"qty":0.00532806},{"price":62793.9,"qty":0.79625467},{"price":62792.9,"qty":0.00334543},{"price":62792.3,"qty":0.15923399},{"price":62792.1,"qty":0.00318511},{"price":62792.0,"qty":0.00532823},{"price":62791.9,"qty":0.79628063},{"price":62791.4,"qty":0.06083209},{"price":62791.2,"qty":0.00164300},{"price":62790.6,"qty":0.02866671},{"price":62790.0,"qty":0.00596958},{"price":62789.9,"qty":0.09703642},{"price":62789.7,"qty":0.06960000},{"price":62789.4,"qty":0.12052463},{"price":62788.0,"qty":0.01313953},{"price":62787.5,"qty":0.01540085},{"price":62787.3,"qty":0.79633936},{"price":62786.3,"qty":0.00829459}],"asks":[{"price":62802.6,"qty":1.09074394},{"price":62803.7,"qty":0.05598472},{"price":62803.8,"qty":0.79613017},{"price":62803.9,"qty":1.16228981},{"price":62804.5,"qty":0.15923399},{"price":62806.8,"qty":0.00005100},{"price":62806.9,"qty":0.18489680},{"price":62807.0,"qty":3.79000790},{"price":62807.1,"qty":0.36000000},{"price":62807.2,"qty":0.65540712},{"price":62807.4,"qty":0.50920200},{"price":62808.0,"qty":0.79607759},{"price":62809.9,"qty":0.00005100},{"price":62810.0,"qty":0.00756724},{"price":62810.1,"qty":0.13109402},{"price":62810.2,"qty":0.06000000},{"price":62812.0,"qty":0.00756700},{"price":62812.4,"qty":0.00318620},{"price":62812.7,"qty":0.01100000},{"price":62813.3,"qty":0.06960000},{"price":62813.8,"qty":0.19620257},{"price":62813.9,"qty":2.38800788},{"price":62814.0,"qty":0.00909439},{"price":62816.2,"qty":0.00005100},{"price":62818.7,"qty":0.00222509}],"checksum":267719021,"timestamp":"2026-08-16T23:37:03.693545Z"}]}}
{"rx_ns": 42889122359100, "frame": {"channel":"book","type":"update","data":[{"symbol":"BTC/USD","bids":[],"asks":[{"price":62807.0,"qty":0.00000000},{"price":62818.8,"qty":0.65540712},{"price":62803.8,"qty":4.58618079}],"checksum":4249465476,"timestamp":"2026-08-16T23:37:03.745044Z"}]}}
{"rx_ns": 42889122421900, "frame": {"channel":"book","type":"update","data":[{"symbol":"BTC/USD","bids":[{"price":62792.3,"qty":0.00000000},{"price":62786.0,"qty":0.01313995}],"asks":[],"checksum":4249465476,"timestamp":"2026-08-16T23:37:03.747489Z"}]}}
{"rx_ns": 42889122670500, "frame": {"channel":"book","type":"update","data":[{"symbol":"BTC/USD","bids":[],"asks":[{"price":62804.5,"qty":0.00000000},{"price":62818.9,"qty":1.59575715}],"checksum":3839258924,"timestamp":"2026-08-16T23:37:03.747520Z"}]}}
{"rx_ns": 42889141787300, "frame": {"channel":"book","type":"update","data":[{"symbol":"BTC/USD","bids":[{"price":62791.6,"qty":0.15923399}],"asks":[],"checksum":3839258924,"timestamp":"2026-08-16T23:37:03.766178Z"}]}}
{"rx_ns": 42889141837700, "frame": {"channel":"book","type":"update","data":[{"symbol":"BTC/USD","bids":[],"asks":[{"price":62803.8,"qty":4.74541478}],"checksum":2007317691,"timestamp":"2026-08-16T23:37:03.766340Z"}]}}
{"rx_ns": 42889143279500, "frame": {"channel":"book","type":"update","data":[{"symbol":"BTC/USD","bids":[],"asks":[{"price":62803.8,"qty":0.95536416},{"price":62806.8,"qty":3.79009491}],"checksum":2659657542,"timestamp":"2026-08-16T23:37:03.767619Z"}]}}
{"rx_ns": 42889146080000, "frame": {"channel":"book","type":"update","data":[{"symbol":"BTC/USD","bids":[],"asks":[{"price":62806.9,"qty":0.00000000},{"price":62819.0,"qty":7.95938166},{"price":62806.7,"qty":0.18489680}],"checksum":1457650434,"timestamp":"2026-08-16T23:37:03.770064Z"}]}}
{"rx_ns": 42889364103700, "frame": {"channel":"book","type":"update","data":[{"symbol":"BTC/USD","bids":[],"asks":[{"price":62812.4,"qty":0.00000000},{"price":62819.0,"qty":7.95938166},{"price":62812.6,"qty":0.00318620}],"checksum":1457650434,"timestamp":"2026-08-16T23:37:03.987275Z"}]}}
{"rx_ns": 42889364164900, "frame": {"channel":"book","type":"update","data":[{"symbol":"BTC/USD","bids":[{"price":62792.9,"qty":0.00015923},{"price":62793.1,"qty":0.00318620}],"asks":[],"checksum":1420235078,"timestamp":"2026-08-16T23:37:03.987959Z"}]}}
{"rx_ns": 42889375791500, "frame": {"channel":"book","type":"update","data":[{"symbol":"BTC/USD","bids":[],"asks":[{"price":62813.1,"qty":0.00005100}],"checksum":1420235078,"timestamp":"2026-08-16T23:37:03.999652Z"}]}}
{"rx_ns": 42889606886100, "frame": {"channel":"book","type":"update","data":[{"symbol":"BTC/USD","bids":[],"asks":[{"price":62806.8,"qty":0.00005100},{"price":62803.8,"qty":4.74541097}],"checksum":2133845198,"timestamp":"2026-08-16T23:37:04.231265Z"}]}}
{"rx_ns": 42889607203200, "frame": {"channel":"book","type":"update","data":[{"symbol":"BTC/USD","bids":[],"asks":[{"price":62806.7,"qty":0.00000000},{"price":62818.9,"qty":1.59575715},{"price":62807.0,"qty":0.18489680}],"checksum":2424274018,"timestamp":"2026-08-16T23:37:04.232749Z"}]}}
{"rx_ns": 42889613706800, "frame": {"channel":"book","type":"update","data":[{"symbol":"BTC/USD","bids":[],"asks":[{"price":62803.8,"qty":0.95536416},{"price":62806.6,"qty":3.79004471}],"checksum":4143655417,"timestamp":"2026-08-16T23:37:04.238772Z"}]}}
{"rx_ns": 42889691610600, "frame": {"channel":"book","type":"update","data":[{"symbol":"BTC/USD","bids":[{"price":62795.7,"qty":0.00000000},{"price":62786.3,"qty":0.00829459},{"price":62797.0,"qty":0.00012700}],"asks":[],"checksum":3689417502,"timestamp":"2026-08-16T23:37:04.315146Z"}]}}
{"rx_ns": 42889693297500, "frame": {"channel":"book","type":"update","data":[{"symbol":"BTC/USD","bids":[],"asks":[{"price":62807.0,"qty":0.00000000},{"price":62818.8,"qty":0.65540712},{"price":62806.5,"qty":0.18489680}],"checksum":975661613,"timestamp":"2026-08-16T23:37:04.316445Z"}]}}
{"rx_ns": 42889744399600, "frame": {"channel":"heartbeat"}}
{"rx_ns": 42889941786900, "frame": {"channel":"book","type":"update","data":[{"symbol":"BTC/USD","bids":[{"price":62788.8,"qty":0.65540712}],"asks":[],"checksum":975661613,"timestamp":"2026-08-16T23:37:04.563561Z"}]}}
{"rx_ns": 42889941837400, "frame": {"channel":"book","type":"update","data":[{"symbol":"BTC/USD","bids":[{"price":62787.5,"qty":0.00000000},{"price":62787.3,"qty":0.79633936}],"asks":[],"checksum":975661613,"timestamp":"2026-08-16T23:37:04.566479Z"}]}}
{"rx_ns": 42889941851900, "frame": {"channel":"book","type":"update","data":[{"symbol":"BTC/USD","bids":[{"price":62790.2,"qty":0.01557581}],"asks":[],"checksum":975661613,"timestamp":"2026-08-16T23:37:04.566662Z"}]}}
{"rx_ns": 42890744500200, "frame": {"channel":"heartbeat"}}
{"rx_ns": 42890757802200, "frame": {"channel":"book","type":"update","data":[{"symbol":"BTC/USD","bids":[],"asks":[{"price":62806.6,"qty":0.00000000},{"price":62818.8,"qty":0.65540712},{"price":62803.8,"qty":4.74541363}],"checksum":265834348,"timestamp":"2026-08-16T23:37:05.376419Z"}]}}
{"rx_ns": 42890757871100, "frame": {"channel":"book","type":"update","data":[{"symbol":"BTC/USD","bids":[],"asks":[{"price":62810.1,"qty":0.00000000},{"price":62818.9,"qty":1.59575715}],"checksum":265834348,"timestamp":"2026-08-16T23:37:05.377162Z"}]}}
{"rx_ns": 42890757891100, "frame": {"channel":"book","type":"update","data":[{"symbol":"BTC/USD","bids":[],"asks":[{"price":62817.1,"qty":0.13109402}],"checksum":265834348,"timestamp":"2026-08-16T23:37:05.377368Z"}]}}
{"rx_ns": 42890757905200, "frame": {"channel":"book","type":"update","data":[{"symbol":"BTC/USD","bids":[],"asks":[{"price":62802.6,"qty":0.98074394}],"checksum":1348273380,"timestamp":"2026-08-16T23:37:05.377468Z"}]}}
{"rx_ns": 42890757918300, "frame": {"channel":"book","type":"update","data":[{"symbol":"BTC/USD","bids":[],"asks":[{"price":62810.8,"qty":0.11000000}],"checksum":1348273380,"timestamp":"2026-08-16T23:37:05.377609Z"}]}}
{"rx_ns": 42890757937700, "frame": {"channel":"book","type":"update","data":[{"symbol":"BTC/USD","bids":[],"asks":[{"price":62806.5,"qty":0.00000000},{"price":62818.8,"qty":0.65540712},{"price":62807.0,"qty":0.18489680}],"checksum":3676157681,"timestamp":"2026-08-16T23:37:05.377919Z"}]}}
{"rx_ns": 42890757973000, "frame": {"channel":"book","type":"update","data":[{"symbol":"BTC/USD","bids":[],"asks":[{"price":62802.6,"qty":0.90274394}],"checksum":2543465031,"timestamp":"2026-08-16T23:37:05.380457Z"}]}}
{"rx_ns": 42890775054300, "frame": {"channel":"book","type":"update","data":[{"symbol":"BTC/USD","bids":[],"asks":[{"price":62803.8,"qty":0.95536416},{"price":62806.4,"qty":3.79004364}],"checksum":441069893,"timestamp":"2026-08-16T23:37:05.399046Z"}]}}
{"rx_ns": 42891191058700, "frame": {"channel":"book","type":"update","data":[{"symbol":"BTC/USD","bids":[],"asks":[{"price":62806.4,"qty":0.00000000},{"price":62818.7,"qty":0.00222509},{"price":62803.7,"qty":3.84603600}],"checksum":3303084279,"timestamp":"2026-08-16T23:37:05.815233Z"}]}}
{"rx_ns": 42891213514500, "frame": {"channel":"book","type":"update","data":[{"symbol":"BTC/USD","bids":[],"asks":[{"price":62803.7,"qty":0.05598472},{"price":62806.9,"qty":3.79000109}],"checksum":2474031404,"timestamp":"2026-08-16T23:37:05.837728Z"}]}}
{"rx_ns": 42891213588600, "frame": {"channel":"book","type":"update","data":[{"symbol":"BTC/USD","bids":[],"asks":[{"price":62807.0,"qty":0.00000000},{"price":62818.7,"qty":0.00222509},{"price":62806.8,"qty":0.18494780}],"checksum":3569469293,"timestamp":"2026-08-16T23:37:05.839103Z"}]}}
{"rx_ns": 42891247139500, "frame": {"channel":"book","type":"update","data":[{"symbol":"BTC/USD","bids":[{"price":62802.5,"qty":0.00849808}],"asks":[],"checksum":1879693603,"timestamp":"2026-08-16T23:37:05.871705Z"}]}}
{"rx_ns": 42891251070900, "frame": {"channel":"book","type":"update","data":[{"symbol":"BTC/USD","bids":[{"price":62801.4,"qty":0.02137959}],"asks":[],"checksum":50978620,"timestamp":"2026-08-16T23:37:05.872920Z"}]}}
{"rx_ns": 42891251135500, "frame": {"channel":"book","type":"update","data":[{"symbol":"BTC/USD","bids":[{"price":62800.7,"qty":0.00000000},{"price":62788.0,"qty":0.01313953},{"price":62801.5,"qty":0.05598472}],"asks":[],"checksum":1604503902,"timestamp":"2026-08-16T23:37:05.873993Z"}]}}
{"rx_ns": 42891251154500, "frame": {"channel":"book","type":"update","data":[{"symbol":"BTC/USD","bids":[{"price":62793.1,"qty":0.00000000},{"price":62788.0,"qty":0.01313953},{"price":62793.0,"qty":0.00318620}],"asks":[],"checksum":1604503902,"timestamp":"2026-08-16T23:37:05.874090Z"}]}}
{"rx_ns": 42891251182200, "frame": {"channel":"book","type":"update","data":[{"symbol":"BTC/USD","bids":[],"asks":[{"price":62812.6,"qty":0.00000000},{"price":62818.8,"qty":0.65540712},{"price":62812.4,"qty":0.00318620}],"checksum":1604503902,"timestamp":"2026-08-16T23:37:05.874388Z"}]}}
{"rx_ns": 42891650736800, "frame": {"channel":"book","type":"update","data":[{"symbol":"BTC/USD","bids":[{"price":62801.5,"qty":0.00000000},{"price":62788.0,"qty":0.01313953}],"asks":[],"checksum":3719378320,"timestamp":"2026-08-16T23:37:06.275708Z"}]}}
{"rx_ns": 42891652450400, "frame": {"channel":"book","type":"update","data":[{"symbol":"BTC/USD","bids":[{"price":62797.6,"qty":0.05598472}],"asks":[],"checksum":2564800303,"timestamp":"2026-08-16T23:37:06.276752Z"}]}}
{"rx_ns": 42891661587300, "frame": {"channel":"book","type":"update","data":[{"symbol":"BTC/USD","bids":[{"price":62793.9,"qty":0.00000000},{"price":62788.0,"qty":0.01313953}],"asks":[],"checksum":110749926,"timestamp":"2026-08-16T23:37:06.285045Z"}]}}
{"rx_ns": 42891666027000, "frame": {"channel":"book","type":"update","data":[{"symbol":"BTC/USD","bids":[{"price":62793.2,"qty":0.79626397}],"asks":[],"checksum":2330494038,"timestamp":"2026-08-16T23:37:06.286874Z"}]}}
{"rx_ns": 42891671872500, "frame": {"channel":"book","type":"update","data":[{"symbol":"BTC/USD","bids":[],"asks":[{"price":62803.8,"qty":0.79613017}],"checksum":371959854,"timestamp":"2026-08-16T23:37:06.297387Z"}]}}
{"rx_ns": 42891673223100, "frame": {"channel":"book","type":"update","data":[{"symbol":"BTC/USD","bids":[{"price":62791.6,"qty":0.00000000},{"price":62788.0,"qty":0.01313953}],"asks":[],"checksum":371959854,"timestamp":"2026-08-16T23:37:06.297399Z"}]}}
{"rx_ns": 42891699166200, "frame": {"channel":"book","type":"update","data":[{"symbol":"BTC/USD","bids":[{"price":62794.0,"qty":0.00000000},{"price":62787.3,"qty":0.79633936}],"asks":[],"checksum":2630192712,"timestamp":"2026-08-16T23:37:06.324556Z"}]}}
{"rx_ns": 42891718169800, "frame": {"channel":"book","type":"update","data":[{"symbol":"BTC/USD","bids":[],"asks":[{"price":62802.6,"qty":1.06197793}],"checksum":2871320315,"timestamp":"2026-08-16T23:37:06.334835Z"}]}}
{"rx_ns": 42891718224000, "frame": {"channel":"book","type":"update","data":[{"symbol":"BTC/USD","bids":[{"price":62790.3,"qty":0.15923399}],"asks":[],"checksum":2871320315,"timestamp":"2026-08-16T23:37:06.335007Z"}]}}
{"rx_ns": 42891718251600, "frame": {"channel":"book","type":"update","data":[{"symbol":"BTC/USD","bids":[],"asks":[{"price":62802.6,"qty":1.13997793}],"checksum":1696580693,"timestamp":"2026-08-16T23:37:06.336631Z"}]}}
{"rx_ns": 42891745775400, "frame": {"channel":"heartbeat"}}
{"rx_ns": 42891754797200, "frame": {"channel":"book","type":"update","data":[{"symbol":"BTC/USD","bids":[],"asks":[{"price":62806.9,"qty":0.00000000},{"price":62818.8,"qty":0.65540712},{"price":62803.8,"qty":4.58617734}],"checksum":54414482,"timestamp":"2026-08-16T23:37:06.361885Z"}]}}
{"rx_ns": 42892127935200, "frame": {"channel":"book","type":"update","data":[{"symbol":"BTC/USD","bids":[],"asks":[{"price":62803.8,"qty":0.79613017},{"price":62806.7,"qty":3.79004495}],"checksum":1900210029,"timestamp":"2026-08-16T23:37:06.750448Z"}]}}
{"rx_ns": 42892129728900, "frame": {"channel":"book","type":"update","data":[{"symbol":"BTC/USD","bids":[],"asks":[{"price":62806.8,"qty":0.00005100},{"price":62806.6,"qty":0.18489680}],"checksum":1899318310,"timestamp":"2026-08-16T23:37:06.751983Z"}]}}
{"rx_ns": 42892147506700, "frame": {"channel":"book","type":"update","data":[{"symbol":"BTC/USD","bids":[{"price":62790.3,"qty":0.00000000},{"price":62787.3,"qty":0.79633936}],"asks":[],"checksum":1899318310,"timestamp":"2026-08-16T23:37:06.770399Z"}]}}
{"rx_ns": 42892171179700, "frame": {"channel":"book","type":"update","data":[{"symbol":"BTC/USD","bids":[{"price":62790.2,"qty":0.17480980}],"asks":[],"checksum":1899318310,"timestamp":"2026-08-16T23:37:06.796085Z"}]}}
{"rx_ns": 42892314819400, "frame": {"channel":"book","type":"update","data":[{"symbol":"BTC/USD","bids":[],"asks":[{"price":62807.1,"qty":0.00000000},{"price":62818.7,"qty":0.00222509}],"checksum":4083933284,"timestamp":"2026-08-16T23:37:06.938737Z"}]}}
{"rx_ns": 42892640478700, "frame": {"channel":"book","type":"update","data":[{"symbol":"BTC/USD","bids":[],"asks":[{"price":62815.6,"qty":0.18701894}],"checksum":4083933284,"timestamp":"2026-08-16T23:37:07.265426Z"}]}}
{"rx_ns": 42892680617200, "frame": {"channel":"book","type":"update","data":[{"symbol":"BTC/USD","bids":[],"asks":[{"price":62806.7,"qty":0.00000000},{"price":62818.7,"qty":0.00222509},{"price":62803.8,"qty":4.58618091}],"checksum":2043980972,"timestamp":"2026-08-16T23:37:07.300795Z"}]}}
{"rx_ns": 42892680678200, "frame": {"channel":"book","type":"update","data":[{"symbol":"BTC/USD","bids":[],"asks":[{"price":62806.6,"qty":0.00000000},{"price":62818.8,"qty":0.65540712},{"price":62807.9,"qty":0.18489680}],"checksum":235672643,"timestamp":"2026-08-16T23:37:07.302093Z"}]}}
{"rx_ns": 42892743290200, "frame": {"channel":"heartbeat"}}
{"rx_ns": 42892896875300, "frame": {"channel":"book","type":"update","data":[{"symbol":"BTC/USD","bids":[],"asks":[{"price":62807.1,"qty":0.36000000}],"checksum":3521650448,"timestamp":"2026-08-16T23:37:07.520640Z"}]}}
{"rx_ns": 42892898502000, "frame": {"channel":"book","type":"update","data":[{"symbol":"BTC/USD","bids":[],"asks":[{"price":62807.9,"qty":0.00000000},{"price":62818.7,"qty":0.00222509},{"price":62807.0,"qty":0.18489680}],"checksum":4056636036,"timestamp":"2026-08-16T23:37:07.521946Z"}]}}
{"rx_ns": 42892898705500, "frame": {"channel":"book","type":"update","data":[{"symbol":"BTC/USD","bids":[],"asks":[{"price":62812.4,"qty":0.00000000},{"price":62818.7,"qty":0.00222509},{"price":62812.5,"qty":0.00318620}],"checksum":4056636036,"timestamp":"2026-08-16T23:37:07.523244Z"}]}}
{"rx_ns": 42892949204000, "frame": {"channel":"book","type":"update","data":[{"symbol":"BTC/USD","bids":[],"asks":[{"price":62807.2,"qty":0.00000000},{"price":62818.7,"qty":0.00222509}],"checksum":4219639166,"timestamp":"2026-08-16T23:37:07.574122Z"}]}}
{"rx_ns": 42892957389100, "frame": {"channel":"book","type":"update","data":[{"symbol":"BTC/USD","bids":[{"price":62790.2,"qty":0.01557581}],"asks":[],"checksum":4219639166,"timestamp":"2026-08-16T23:37:07.581989Z"}]}}
{"rx_ns": 42892971290400, "frame": {"channel":"book","type":"update","data":[{"symbol":"BTC/USD","bids":[{"price":62790.1,"qty":0.15923399}],"asks":[],"checksum":4219639166,"timestamp":"2026-08-16T23:37:07.596190Z"}]}}
{"rx_ns": 42893439057200, "frame": {"channel":"book","type":"update","data":[{"symbol":"BTC/USD","bids":[],"asks":[{"price":62803.8,"qty":0.79613017},{"price":62806.9,"qty":3.79000581}],"checksum":2688985755,"timestamp":"2026-08-16T23:37:08.064059Z"}]}}
{"rx_ns": 42893440863000, "frame": {"channel":"book","type":"update","data":[{"symbol":"BTC/USD","bids":[],"asks":[{"price":62807.0,"qty":0.00000000},{"price":62818.7,"qty":0.00222509},{"price":62806.8,"qty":0.18494780}],"checksum":4088415580,"timestamp":"2026-08-16T23:37:08.065495Z"}]}}
{"rx_ns": 42893462233300, "frame": {"channel":"book","type":"update","data":[{"symbol":"BTC/USD","bids":[],"asks":[{"price":62806.9,"qty":0.00000000},{"price":62818.8,"qty":0.65540712},{"price":62803.7,"qty":3.84603605}],"checksum":1080158762,"timestamp":"2026-08-16T23:37:08.087504Z"}]}}
{"rx_ns": 42893462709400, "frame": {"channel":"book","type":"update","data":[{"symbol":"BTC/USD","bids":[],"asks":[{"price":62803.7,"qty":3.79005133},{"price":62803.6,"qty":0.05598472}],"checksum":1312528143,"timestamp":"2026-08-16T23:37:08.088677Z"}]}}
{"rx_ns": 42893464742400, "frame": {"channel":"book","type":"update","data":[{"symbol":"BTC/USD","bids":[],"asks":[{"price":62806.8,"qty":0.00005100},{"price":62807.9,"qty":0.18489680}],"checksum":1201675115,"timestamp":"2026-08-16T23:37:08.088784Z"}]}}
{"rx_ns": 42893494030700, "frame": {"channel":"book","type":"update","data":[{"symbol":"BTC/USD","bids":[],"asks":[{"price":62803.7,"qty":0.00000000},{"price":62818.7,"qty":0.00222509},{"price":62806.9,"qty":3.79004418}],"checksum":440535564,"timestamp":"2026-08-16T23:37:08.117588Z"}]}}
{"rx_ns": 42893494118900, "frame": {"channel":"book","type":"update","data":[{"symbol":"BTC/USD","bids":[],"asks":[{"price":62807.9,"qty":0.00000000},{"price":62818.7,"qty":0.00222509},{"price":62806.8,"qty":0.18494780}],"checksum":2494929030,"timestamp":"2026-08-16T23:37:08.118838Z"}]}}
{"rx_ns": 42893494682700, "frame": {"channel":"book","type":"update","data":[{"symbol":"BTC/USD","bids":[],"asks":[{"price":62803.6,"qty":0.00000000},{"price":62818.8,"qty":0.65540712},{"price":62803.7,"qty":0.05598472}],"checksum":2465943611,"timestamp":"2026-08-16T23:37:08.118853Z"}]}}
{"rx_ns": 42893744228700, "frame": {"channel":"heartbeat"}}
{"rx_ns": 42894065782400, "frame": {"channel":"book","type":"update","data":[{"symbol":"BTC/USD","bids":[{"price":62790.1,"qty":0.00000000},{"price":62787.3,"qty":0.79633936}],"asks":[],"checksum":2465943611,"timestamp":"2026-08-16T23:37:08.686693Z"}]}}
{"rx_ns": 42894070683400, "frame": {"channel":"book","type":"update","data":[{"symbol":"BTC/USD","bids":[{"price":62790.0,"qty":0.16520357}],"asks":[],"checksum":2465943611,"timestamp":"2026-08-16T23:37:08.695984Z"}]}}
{"rx_ns": 42894096236100, "frame": {"channel":"book","type":"update","data":[{"symbol":"BTC/USD","bids":[],"asks":[{"price":62806.9,"qty":0.00000000},{"price":62818.8,"qty":0.65540712},{"price":62803.6,"qty":3.79008032}],"checksum":485000038,"timestamp":"2026-08-16T23:37:08.719864Z"}]}}
{"rx_ns": 42894096315200, "frame": {"channel":"book","type":"update","data":[{"symbol":"BTC/USD","bids":[],"asks":[{"price":62806.8,"qty":0.00005100},{"price":62807.9,"qty":0.18489680}],"checksum":359862018,"timestamp":"2026-08-16T23:37:08.721198Z"}]}}
{"rx_ns": 42894098045200, "frame": {"channel":"book","type":"update","data":[{"symbol":"BTC/USD","bids":[],"asks":[{"price":62803.7,"qty":0.00000000},{"price":62818.7,"qty":0.00222509},{"price":62803.5,"qty":0.05598472}],"checksum":2947842144,"timestamp":"2026-08-16T23:37:08.721219Z"}]}}
{"rx_ns": 42894128333300, "frame": {"channel":"book","type":"update","data":[{"symbol":"BTC/USD","bids":[],"asks":[{"price":62803.6,"qty":0.00000000},{"price":62818.7,"qty":0.00222509},{"price":62806.7,"qty":3.79001496}],"checksum":1565111361,"timestamp":"2026-08-16T23:37:08.751537Z"}]}}
{"rx_ns": 42894129802500, "frame": {"channel":"book","type":"update","data":[{"symbol":"BTC/USD","bids":[],"asks":[{"price":62803.5,"qty":0.00000000},{"price":62818.7,"qty":0.00222509},{"price":62803.7,"qty":0.05598472}],"checksum":1372857659,"timestamp":"2026-08-16T23:37:08.753024Z"}]}}
{"rx_ns": 42894391083100, "frame": {"channel":"book","type":"update","data":[{"symbol":"BTC/USD","bids":[],"asks":[{"price":62806.7,"qty":0.00000000},{"price":62818.7,"qty":1.59798224},{"price":62803.8,"qty":4.58618103}],"checksum":1864190754,"timestamp":"2026-08-16T23:37:09.015116Z"}]}}
{"rx_ns": 42894421297300, "frame": {"channel":"book","type":"update","data":[{"symbol":"BTC/USD","bids":[],"asks":[{"price":62803.8,"qty":0.79613017},{"price":62807.0,"qty":3.78999969}],"checksum":3292457266,"timestamp":"2026-08-16T23:37:09.045279Z"}]}}
{"rx_ns": 42894424857900, "frame": {"channel":"book","type":"update","data":[{"symbol":"BTC/USD","bids":[],"asks":[{"price":62807.9,"qty":0.00000000},{"price":62818.7,"qty":1.59798224},{"price":62806.9,"qty":0.18489680}],"checksum":3897311709,"timestamp":"2026-08-16T23:37:09.047337Z"}]}}
{"rx_ns": 42894438724600, "frame": {"channel":"book","type":"update","data":[{"symbol":"BTC/USD","bids":[{"price":62793.2,"qty":0.00000000},{"price":62786.3,"qty":0.00829459}],"asks":[],"checksum":3560232215,"timestamp":"2026-08-16T23:37:09.053796Z"}]}}
{"rx_ns": 42894443059600, "frame": {"channel":"book","type":"update","data":[{"symbol":"BTC/USD","bids":[{"price":62793.8,"qty":0.79625623}],"asks":[],"checksum":3165917908,"timestamp":"2026-08-16T23:37:09.062522Z"}]}}
{"rx_ns": 42894515537300, "frame": {"channel":"book","type":"update","data":[{"symbol":"BTC/USD","bids":[],"asks":[{"price":62803.7,"qty":0.00000000},{"price":62818.7,"qty":0.00222509}],"checksum":2451645330,"timestamp":"2026-08-16T23:37:09.140594Z"}]}}
{"rx_ns": 42894518966000, "frame": {"channel":"book","type":"update","data":[{"symbol":"BTC/USD","bids":[{"price":62797.6,"qty":0.00000000},{"price":62786.3,"qty":0.00829459},{"price":62802.5,"qty":0.06448280}],"asks":[],"checksum":1825135173,"timestamp":"2026-08-16T23:37:09.141793Z"}]}}
{"rx_ns": 42894519016800, "frame": {"channel":"book","type":"update","data":[{"symbol":"BTC/USD","bids":[],"asks":[{"price":62803.9,"qty":1.21827453}],"checksum":336881173,"timestamp":"2026-08-16T23:37:09.141970Z"}]}}
{"rx_ns": 42894521184900, "frame": {"channel":"book","type":"update","data":[{"symbol":"BTC/USD","bids":[],"asks":[{"price":62812.5,"qty":0.00000000},{"price":62818.8,"qty":0.65540712},{"price":62812.6,"qty":0.00318620}],"checksum":336881173,"timestamp":"2026-08-16T23:37:09.144273Z"}]}}
{"rx_ns": 42894521219300, "frame": {"channel":"book","type":"update","data":[{"symbol":"BTC/USD","bids":[{"price":62793.0,"qty":0.00000000},{"price":62786.0,"qty":0.01313995},{"price":62793.1,"qty":0.00318620}],"asks":[],"checksum":4215722228,"timestamp":"2026-08-16T23:37:09.144533Z"}]}}
{"rx_ns": 42894589387800, "frame": {"channel":"book","type":"update","data":[{"symbol":"BTC/USD","bids":[{"price":62790.0,"qty":0.00596958}],"asks":[],"checksum":4215722228,"timestamp":"2026-08-16T23:37:09.214645Z"}]}}
{"rx_ns": 42894622949300, "frame": {"channel":"book","type":"update","data":[{"symbol":"BTC/USD","bids":[{"price":62790.3,"qty":0.15923399}],"asks":[],"checksum":4215722228,"timestamp":"2026-08-16T23:37:09.246165Z"}]}}
{"rx_ns": 42894743864000, "frame": {"channel":"heartbeat"}}
{"rx_ns": 42894777431600, "frame": {"channel":"book","type":"update","data":[{"symbol":"BTC/USD","bids":[{"price":62794.0,"qty":0.00552708}],"asks":[],"checksum":197040151,"timestamp":"2026-08-16T23:37:09.399268Z"}]}}
{"rx_ns": 42895382062000, "frame": {"channel":"book","type":"update","data":[{"symbol":"BTC/USD","bids":[],"asks":[{"price":62818.7,"qty":1.59798224}],"checksum":197040151,"timestamp":"2026-08-16T23:37:10.006349Z"}]}}
{"rx_ns": 42895594892400, "frame": {"channel":"book","type":"update","data":[{"symbol":"BTC/USD","bids":[{"price":62802.5,"qty":0.00849808}],"asks":[],"checksum":979958136,"timestamp":"2026-08-16T23:37:10.213367Z"}]}}
{"rx_ns": 42895594981500, "frame": {"channel":"book","type":"update","data":[{"symbol":"BTC/USD","bids":[{"price":62797.6,"qty":0.05598472}],"asks":[],"checksum":4106223823,"timestamp":"2026-08-16T23:37:10.214795Z"}]}}
{"rx_ns": 42895594998300, "frame": {"channel":"book","type":"update","data":[{"symbol":"BTC/USD","bids":[],"asks":[{"price":62803.9,"qty":1.16228981},{"price":62803.7,"qty":0.05598472}],"checksum":2974203201,"timestamp":"2026-08-16T23:37:10.215095Z"}]}}
{"rx_ns": 42895595013100, "frame": {"channel":"book","type":"update","data":[{"symbol":"BTC/USD","bids":[],"asks":[{"price":62802.6,"qty":1.06197793}],"checksum":613166112,"timestamp":"2026-08-16T23:37:10.215138Z"}]}}
{"rx_ns": 42895662717900, "frame": {"channel":"book","type":"update","data":[{"symbol":"BTC/USD","bids":[{"price":62793.8,"qty":0.00000000},{"price":62788.0,"qty":0.01313953}],"asks":[],"checksum":1294649062,"timestamp":"2026-08-16T23:37:10.285432Z"}]}}
{"rx_ns": 42895665381000, "frame": {"channel":"book","type":"update","data":[{"symbol":"BTC/USD","bids":[{"price":62793.0,"qty":0.79626632}],"asks":[],"checksum":1294649062,"timestamp":"2026-08-16T23:37:10.287058Z"}]}}
{"rx_ns": 42895744859300, "frame": {"channel":"heartbeat"}}
{"rx_ns": 42895774581700, "frame": {"channel":"book","type":"update","data":[{"symbol":"BTC/USD","bids":[{"price":62791.9,"qty":0.00000000},{"price":62788.0,"qty":0.01313953}],"asks":[],"checksum":1294649062,"timestamp":"2026-08-16T23:37:10.395397Z"}]}}
{"rx_ns": 42895774661000, "frame": {"channel":"book","type":"update","data":[{"symbol":"BTC/USD","bids":[{"price":62790.8,"qty":0.79629454}],"asks":[],"checksum":1294649062,"timestamp":"2026-08-16T23:37:10.396686Z"}]}}
{"rx_ns": 42895851172900, "frame": {"channel":"book","type":"update","data":[{"symbol":"BTC/USD","bids":[{"price":62794.0,"qty":0.00000000},{"price":62788.0,"qty":0.01313953}],"asks":[],"checksum":2847926976,"timestamp":"2026-08-16T23:37:10.474842Z"}]}}
{"rx_ns": 42895864494700, "frame": {"channel":"book","type":"update","data":[{"symbol":"BTC/USD","bids":[],"asks":[{"price":62807.0,"qty":0.00000000},{"price":62818.7,"qty":1.59798224},{"price":62803.8,"qty":4.58617735}],"checksum":1988537768,"timestamp":"2026-08-16T23:37:10.484052Z"}]}}
{"rx_ns": 42895864564500, "frame": {"channel":"book","type":"update","data":[{"symbol":"BTC/USD","bids":[],"asks":[{"price":62806.9,"qty":0.00000000},{"price":62818.8,"qty":0.65540712},{"price":62807.9,"qty":0.18489680}],"checksum":2074920805,"timestamp":"2026-08-16T23:37:10.485180Z"}]}}
{"rx_ns": 42895891557100, "frame": {"channel":"book","type":"update","data":[{"symbol":"BTC/USD","bids":[],"asks":[{"price":62802.6,"qty":1.13157793}],"checksum":2207559158,"timestamp":"2026-08-16T23:37:10.513171Z"}]}}
{"rx_ns": 42895891636800, "frame": {"channel":"book","type":"update","data":[{"symbol":"BTC/USD","bids":[],"asks":[{"price":62802.6,"qty":1.20957793}],"checksum":1974850468,"timestamp":"2026-08-16T23:37:10.515555Z"}]}}
{"rx_ns": 42895949092000, "frame": {"channel":"book","type":"update","data":[{"symbol":"BTC/USD","bids":[{"price":62790.3,"qty":0.00000000},{"price":62787.3,"qty":0.79633936}],"asks":[],"checksum":1974850468,"timestamp":"2026-08-16T23:37:10.573849Z"}]}}
{"rx_ns": 42895970209400, "frame": {"channel":"book","type":"update","data":[{"symbol":"BTC/USD","bids":[{"price":62789.6,"qty":0.15923399}],"asks":[],"checksum":1974850468,"timestamp":"2026-08-16T23:37:10.596086Z"}]}}
{"rx_ns": 42895998404600, "frame": {"channel":"book","type":"update","data":[{"symbol":"BTC/USD","bids":[],"asks":[{"price":62803.9,"qty":1.81769693}],"checksum":2820170745,"timestamp":"2026-08-16T23:37:10.622759Z"}]}}
{"rx_ns": 42895999200300, "frame": {"channel":"book","type":"update","data":[{"symbol":"BTC/USD","bids":[],"asks":[{"price":62807.9,"qty":0.00000000},{"price":62818.8,"qty":0.65540712},{"price":62807.0,"qty":0.18489680}],"checksum":3636937355,"timestamp":"2026-08-16T23:37:10.623835Z"}]}}
{"rx_ns": 42896037944400, "frame": {"channel":"book","type":"update","data":[{"symbol":"BTC/USD","bids":[],"asks":[{"price":62803.8,"qty":0.79613017},{"price":62802.6,"qty":4.99970683}],"checksum":3663539781,"timestamp":"2026-08-16T23:37:10.662581Z"}]}}
{"rx_ns": 42896039230800, "frame": {"channel":"book","type":"update","data":[{"symbol":"BTC/USD","bids":[{"price":62793.1,"qty":0.00000000},{"price":62787.3,"qty":0.79633936},{"price":62793.0,"qty":0.79945252}],"asks":[],"checksum":120787881,"timestamp":"2026-08-16T23:37:10.665069Z"}]}}
{"rx_ns": 42896041020200, "frame": {"channel":"book","type":"update","data":[{"symbol":"BTC/USD","bids":[],"asks":[{"price":62812.6,"qty":0.00000000},{"price":62818.8,"qty":0.65540712},{"price":62812.5,"qty":0.00318620}],"checksum":120787881,"timestamp":"2026-08-16T23:37:10.665334Z"}]}}
{"rx_ns": 42896105365300, "frame": {"channel":"book","type":"update","data":[{"symbol":"BTC/USD","bids":[],"asks":[{"price":62808.0,"qty":0.80163538}],"checksum":966893802,"timestamp":"2026-08-16T23:37:10.731196Z"}]}}
{"rx_ns": 42896108408400, "frame": {"channel":"book","type":"update","data":[{"symbol":"BTC/USD","bids":[{"price":62789.6,"qty":0.00000000},{"price":62786.3,"qty":0.00829459}],"asks":[],"checksum":966893802,"timestamp":"2026-08-16T23:37:10.734087Z"}]}}
{"rx_ns": 42896121450000, "frame": {"channel":"book","type":"update","data":[{"symbol":"BTC/USD","bids":[{"price":62788.4,"qty":0.15923399}],"asks":[],"checksum":966893802,"timestamp":"2026-08-16T23:37:10.746132Z"}]}}
{"rx_ns": 42896144717700, "frame": {"channel":"book","type":"update","data":[{"symbol":"BTC/USD","bids":[{"price":62788.4,"qty":0.00000000},{"price":62786.3,"qty":0.00829459}],"asks":[],"checksum":966893802,"timestamp":"2026-08-16T23:37:10.769669Z"}]}}
{"rx_ns": 42896147976600, "frame": {"channel":"book","type":"update","data":[{"symbol":"BTC/USD","bids":[{"price":62793.0,"qty":0.00318620}],"asks":[],"checksum":4115027398,"timestamp":"2026-08-16T23:37:10.771692Z"}]}}
{"rx_ns": 42896149509500, "frame": {"channel":"book","type":"update","data":[{"symbol":"BTC/USD","bids":[{"price":62792.0,"qty":0.80160690}],"asks":[],"checksum":4115027398,"timestamp":"2026-08-16T23:37:10.773529Z"}]}}
{"rx_ns": 42896173428400, "frame": {"channel":"book","type":"update","data":[{"symbol":"BTC/USD","bids":[{"price":62788.3,"qty":0.15923399}],"asks":[],"checksum":4115027398,"timestamp":"2026-08-16T23:37:10.796168Z"}]}}
{"rx_ns": 42896451862300, "frame": {"channel":"book","type":"update","data":[{"symbol":"BTC/USD","bids":[{"price":62792.0,"qty":0.00532823}],"asks":[],"checksum":4115027398,"timestamp":"2026-08-16T23:37:11.076509Z"}]}}
{"rx_ns": 42896453439100, "frame": {"channel":"book","type":"update","data":[{"symbol":"BTC/USD","bids":[{"price":62792.7,"qty":0.79627054}],"asks":[],"checksum":4115027398,"timestamp":"2026-08-16T23:37:11.078334Z"}]}}
{"rx_ns": 42896552177500, "frame": {"channel":"book","type":"update","data":[{"symbol":"BTC/USD","bids":[],"asks":[{"price":62802.6,"qty":1.20957793},{"price":62803.6,"qty":3.79008208}],"checksum":3334117364,"timestamp":"2026-08-16T23:37:11.177506Z"}]}}
{"rx_ns": 42896553776800, "frame": {"channel":"book","type":"update","data":[{"symbol":"BTC/USD","bids":[],"asks":[{"price":62803.7,"qty":0.00000000},{"price":62818.7,"qty":1.59798224},{"price":62803.5,"qty":0.05598472}],"checksum":533271318,"timestamp":"2026-08-16T23:37:11.178829Z"}]}}
{"rx_ns": 42896585086500, "frame": {"channel":"book","type":"update","data":[{"symbol":"BTC/USD","bids":[],"asks":[{"price":62803.6,"qty":0.00000000},{"price":62818.7,"qty":1.59798224},{"price":62802.6,"qty":4.99971332}],"checksum":3762211511,"timestamp":"2026-08-16T23:37:11.210125Z"}]}}
{"rx_ns": 42896586849200, "frame": {"channel":"book","type":"update","data":[{"symbol":"BTC/USD","bids":[],"asks":[{"price":62803.5,"qty":0.00000000},{"price":62818.8,"qty":0.65540712},{"price":62803.7,"qty":0.05598472}],"checksum":1027078409,"timestamp":"2026-08-16T23:37:11.211864Z"}]}}
{"rx_ns": 42896638792700, "frame": {"channel":"book","type":"update","data":[{"symbol":"BTC/USD","bids":[],"asks":[{"price":62802.6,"qty":1.20957793},{"price":62803.6,"qty":3.79012046}],"checksum":3780872311,"timestamp":"2026-08-16T23:37:11.263989Z"}]}}
{"rx_ns": 42896685754800, "frame": {"channel":"book","type":"update","data":[{"symbol":"BTC/USD","bids":[],"asks":[{"price":62803.6,"qty":0.00000000},{"price":62818.7,"qty":1.59798224},{"price":62802.6,"qty":4.99971268}],"checksum":1382623541,"timestamp":"2026-08-16T23:37:11.311297Z"}]}}
{"rx_ns": 42896709458300, "frame": {"channel":"book","type":"update","data":[{"symbol":"BTC/USD","bids":[{"price":62788.3,"qty":0.00000000},{"price":62787.3,"qty":0.79633936}],"asks":[],"checksum":1382623541,"timestamp":"2026-08-16T23:37:11.334989Z"}]}}
{"rx_ns": 42896720385500, "frame": {"channel":"book","type":"update","data":[{"symbol":"BTC/USD","bids":[{"price":62788.4,"qty":0.15923399}],"asks":[],"checksum":1382623541,"timestamp":"2026-08-16T23:37:11.346079Z"}]}}
{"rx_ns": 42896743661200, "frame": {"channel":"heartbeat"}}
{"rx_ns": 42896840034000, "frame": {"channel":"book","type":"update","data":[{"symbol":"BTC/USD","bids":[{"price":62788.4,"qty":0.00000000},{"price":62787.3,"qty":0.79633936}],"asks":[],"checksum":1382623541,"timestamp":"2026-08-16T23:37:11.464763Z"}]}}
{"rx_ns": 42896841708400, "frame": {"channel":"book","type":"update","data":[{"symbol":"BTC/USD","bids":[],"asks":[{"price":62803.9,"qty":1.16228981}],"checksum":682064655,"timestamp":"2026-08-16T23:37:11.464974Z"}]}}
{"rx_ns": 42896849107800, "frame": {"channel":"book","type":"update","data":[{"symbol":"BTC/USD","bids":[],"asks":[{"price":62802.6,"qty":4.93011268}],"checksum":4071950562,"timestamp":"2026-08-16T23:37:11.470378Z"}]}}
{"rx_ns": 42896851396300, "frame": {"channel":"book","type":"update","data":[{"symbol":"BTC/USD","bids":[{"price":62792.7,"qty":0.00000000},{"price":62786.3,"qty":0.00829459}],"asks":[],"checksum":4071950562,"timestamp":"2026-08-16T23:37:11.472225Z"}]}}
{"rx_ns": 42896851455600, "frame": {"channel":"book","type":"update","data":[{"symbol":"BTC/USD","bids":[{"price":62793.4,"qty":0.79626152}],"asks":[],"checksum":2617994829,"timestamp":"2026-08-16T23:37:11.473715Z"}]}}
{"rx_ns": 42896855132500, "frame": {"channel":"book","type":"update","data":[{"symbol":"BTC/USD","bids":[],"asks":[{"price":62802.6,"qty":1.13997793},{"price":62803.6,"qty":3.79008208}],"checksum":4104263212,"timestamp":"2026-08-16T23:37:11.474505Z"}]}}
{"rx_ns": 42896855192200, "frame": {"channel":"book","type":"update","data":[{"symbol":"BTC/USD","bids":[],"asks":[{"price":62803.7,"qty":0.00000000},{"price":62818.7,"qty":1.59798224},{"price":62803.5,"qty":0.05598472}],"checksum":3358027762,"timestamp":"2026-08-16T23:37:11.475874Z"}]}}
{"rx_ns": 42896870135800, "frame": {"channel":"book","type":"update","data":[{"symbol":"BTC/USD","bids":[{"price":62793.4,"qty":0.00000000},{"price":62786.3,"qty":0.00829459}],"asks":[],"checksum":181708683,"timestamp":"2026-08-16T23:37:11.495336Z"}]}}
{"rx_ns": 42896871675400, "frame": {"channel":"book","type":"update","data":[{"symbol":"BTC/USD","bids":[{"price":62790.8,"qty":0.00000000},{"price":62786.0,"qty":0.01313995}],"asks":[],"checksum":181708683,"timestamp":"2026-08-16T23:37:11.495442Z"}]}}
{"rx_ns": 42896871711100, "frame": {"channel":"book","type":"update","data":[{"symbol":"BTC/USD","bids":[{"price":62789.0,"qty":0.15923399}],"asks":[],"checksum":181708683,"timestamp":"2026-08-16T23:37:11.496074Z"}]}}
{"rx_ns": 42896871735500, "frame": {"channel":"book","type":"update","data":[{"symbol":"BTC/USD","bids":[{"price":62791.9,"qty":0.79628006}],"asks":[],"checksum":181708683,"timestamp":"2026-08-16T23:37:11.496932Z"}]}}
{"rx_ns": 42896893720500, "frame": {"channel":"book","type":"update","data":[{"symbol":"BTC/USD","bids":[],"asks":[{"price":62808.0,"qty":0.79607759}],"checksum":2964866042,"timestamp":"2026-08-16T23:37:11.518945Z"}]}}
{"rx_ns": 42896948972000, "frame": {"channel":"book","type":"update","data":[{"symbol":"BTC/USD","bids":[{"price":62791.9,"qty":0.00000000},{"price":62786.3,"qty":0.00829459}],"asks":[],"checksum":2964866042,"timestamp":"2026-08-16T23:37:11.572358Z"}]}}
{"rx_ns": 42896949021200, "frame": {"channel":"book","type":"update","data":[{"symbol":"BTC/USD","bids":[{"price":62793.1,"qty":0.79626564}],"asks":[],"checksum":953773812,"timestamp":"2026-08-16T23:37:11.573970Z"}]}}
{"rx_ns": 42897015112900, "frame": {"channel":"book","type":"update","data":[{"symbol":"BTC/USD","bids":[],"asks":[{"price":62803.6,"qty":0.00000000},{"price":62818.7,"qty":1.59798224},{"price":62806.9,"qty":3.79004492}],"checksum":1717844585,"timestamp":"2026-08-16T23:37:11.640118Z"}]}}
{"rx_ns": 42897016565100, "frame": {"channel":"book","type":"update","data":[{"symbol":"BTC/USD","bids":[],"asks":[{"price":62803.5,"qty":0.00000000},{"price":62818.7,"qty":1.59798224},{"price":62803.7,"qty":0.05598472}],"checksum":1794747155,"timestamp":"2026-08-16T23:37:11.641389Z"}]}}
{"rx_ns": 42897016623100, "frame": {"channel":"book","type":"update","data":[{"symbol":"BTC/USD","bids":[],"asks":[{"price":62807.0,"qty":0.00000000},{"price":62818.7,"qty":1.59798224},{"price":62806.8,"qty":0.18494780}],"checksum":3992508294,"timestamp":"2026-08-16T23:37:11.641459Z"}]}}
{"rx_ns": 42897073439200, "frame": {"channel":"book","type":"update","data":[{"symbol":"BTC/USD","bids":[{"price":62793.1,"qty":0.00000000},{"price":62786.3,"qty":0.00829459}],"asks":[],"checksum":3849491617,"timestamp":"2026-08-16T23:37:11.698183Z"}]}}
{"rx_ns": 42897076546100, "frame": {"channel":"book","type":"update","data":[{"symbol":"BTC/USD","bids":[],"asks":[{"price":62802.6,"qty":1.20957793}],"checksum":1117952424,"timestamp":"2026-08-16T23:37:11.698610Z"}]}}
{"rx_ns": 42897076902000, "frame": {"channel":"book","type":"update","data":[{"symbol":"BTC/USD","bids":[{"price":62789.0,"qty":0.00000000},{"price":62786.0,"qty":0.01313995}],"asks":[],"checksum":1117952424,"timestamp":"2026-08-16T23:37:11.699401Z"}]}}
{"rx_ns": 42897076934800, "frame": {"channel":"book","type":"update","data":[{"symbol":"BTC/USD","bids":[{"price":62792.0,"qty":0.00000000},{"price":62785.6,"qty":0.10331161}],"asks":[],"checksum":1117952424,"timestamp":"2026-08-16T23:37:11.699444Z"}]}}
{"rx_ns": 42897078641800, "frame": {"channel":"book","type":"update","data":[{"symbol":"BTC/USD","bids":[{"price":62790.0,"qty":0.00000000},{"price":62785.0,"qty":0.76851700}],"asks":[],"checksum":1117952424,"timestamp":"2026-08-16T23:37:11.701867Z"}]}}
{"rx_ns": 42897083949300, "frame": {"channel":"book","type":"update","data":[{"symbol":"BTC/USD","bids":[],"asks":[{"price":62808.0,"qty":0.80146697}],"checksum":2471279502,"timestamp":"2026-08-16T23:37:11.704540Z"}]}}
{"rx_ns": 42897083995000, "frame": {"channel":"book","type":"update","data":[{"symbol":"BTC/USD","bids":[{"price":62787.3,"qty":0.00000000},{"price":62784.0,"qty":0.00857697}],"asks":[],"checksum":2471279502,"timestamp":"2026-08-16T23:37:11.704679Z"}]}}
{"rx_ns": 42897084010900, "frame": {"channel":"book","type":"update","data":[{"symbol":"BTC/USD","bids":[{"price":62801.4,"qty":0.00000000},{"price":62783.7,"qty":0.03185093}],"asks":[],"checksum":2080124398,"timestamp":"2026-08-16T23:37:11.705438Z"}]}}
{"rx_ns": 42897084091700, "frame": {"channel":"book","type":"update","data":[{"symbol":"BTC/USD","bids":[{"price":62788.8,"qty":0.00000000},{"price":62783.3,"qty":0.06960000}],"asks":[],"checksum":2080124398,"timestamp":"2026-08-16T23:37:11.705521Z"}]}}
{"rx_ns": 42897084149100, "frame": {"channel":"book","type":"update","data":[{"symbol":"BTC/USD","bids":[{"price":62784.7,"qty":0.79637232}],"asks":[],"checksum":2080124398,"timestamp":"2026-08-16T23:37:11.707009Z"}]}}
{"rx_ns": 42897090225600, "frame": {"channel":"book","type":"update","data":[{"symbol":"BTC/USD","bids":[{"price":62798.8,"qty":0.02137959}],"asks":[],"checksum":934498548,"timestamp":"2026-08-16T23:37:11.712240Z"}]}}
{"rx_ns": 42897090280900, "frame": {"channel":"book","type":"update","data":[{"symbol":"BTC/USD","bids":[],"asks":[{"price":62806.9,"qty":0.00000000},{"price":62818.8,"qty":0.65540712},{"price":62802.6,"qty":4.99984308}],"checksum":3465157871,"timestamp":"2026-08-16T23:37:11.712472Z"}]}}
{"rx_ns": 42897097073400, "frame": {"channel":"book","type":"update","data":[{"symbol":"BTC/USD","bids":[],"asks":[{"price":62802.6,"qty":5.65525020}],"checksum":2187582356,"timestamp":"2026-08-16T23:37:11.714679Z"}]}}
{"rx_ns": 42897097127900, "frame": {"channel":"book","type":"update","data":[{"symbol":"BTC/USD","bids":[{"price":62789.7,"qty":0.00000000},{"price":62783.7,"qty":0.03185093}],"asks":[],"checksum":2187582356,"timestamp":"2026-08-16T23:37:11.716817Z"}]}}
{"rx_ns": 42897098623500, "frame": {"channel":"book","type":"update","data":[{"symbol":"BTC/USD","bids":[],"asks":[{"price":62803.7,"qty":0.00000000},{"price":62819.0,"qty":7.95938166},{"price":62802.6,"qty":5.71123492}],"checksum":3085279688,"timestamp":"2026-08-16T23:37:11.721981Z"}]}}
{"rx_ns": 42897125105200, "frame": {"channel":"book","type":"update","data":[{"symbol":"BTC/USD","bids":[{"price":62789.9,"qty":0.16663642}],"asks":[],"checksum":3085279688,"timestamp":"2026-08-16T23:37:11.746622Z"}]}}
{"rx_ns": 42897137101100, "frame": {"channel":"book","type":"update","data":[{"symbol":"BTC/USD","bids":[{"price":62798.8,"qty":0.00000000},{"price":62783.3,"qty":0.06960000}],"asks":[],"checksum":1214962299,"timestamp":"2026-08-16T23:37:11.756737Z"}]}}
{"rx_ns": 42897138481600, "frame": {"channel":"book","type":"update","data":[{"symbol":"BTC/USD","bids":[{"price":62797.5,"qty":0.02143059}],"asks":[],"checksum":1032397851,"timestamp":"2026-08-16T23:37:11.758379Z"}]}}
{"rx_ns": 42897145247000, "frame": {"channel":"book","type":"update","data":[{"symbol":"BTC/USD","bids":[{"price":62786.1,"qty":0.15923399}],"asks":[],"checksum":1032397851,"timestamp":"2026-08-16T23:37:11.770044Z"}]}}
{"rx_ns": 42897181826400, "frame": {"channel":"book","type":"update","data":[{"symbol":"BTC/USD","bids":[],"asks":[{"price":62806.0,"qty":0.00537797}],"checksum":3704904613,"timestamp":"2026-08-16T23:37:11.805822Z"}]}}
{"rx_ns": 42897192549500, "frame": {"channel":"book","type":"update","data":[{"symbol":"BTC/USD","bids":[{"price":62790.5,"qty":0.79629802}],"asks":[],"checksum":3704904613,"timestamp":"2026-08-16T23:37:11.817609Z"}]}}
{"rx_ns": 42897192650900, "frame": {"channel":"book","type":"update","data":[{"symbol":"BTC/USD","bids":[{"price":62787.6,"qty":0.79633552}],"asks":[],"checksum":3704904613,"timestamp":"2026-08-16T23:37:11.817819Z"}]}}
{"rx_ns": 42897298223400, "frame": {"channel":"book","type":"update","data":[{"symbol":"BTC/USD","bids":[],"asks":[{"price":62814.0,"qty":0.00318401}],"checksum":3704904613,"timestamp":"2026-08-16T23:37:11.921827Z"}]}}
{"rx_ns": 42897300207000, "frame": {"channel":"book","type":"update","data":[{"symbol":"BTC/USD","bids":[],"asks":[{"price":62802.6,"qty":5.65525020},{"price":62803.7,"qty":0.05598472}],"checksum":1389439018,"timestamp":"2026-08-16T23:37:11.922993Z"}]}}
{"rx_ns": 42897300244300, "frame": {"channel":"book","type":"update","data":[{"symbol":"BTC/USD","bids":[{"price":62797.5,"qty":0.00005100}],"asks":[],"checksum":1073822854,"timestamp":"2026-08-16T23:37:11.924319Z"}]}}
{"rx_ns": 42897300256600, "frame": {"channel":"book","type":"update","data":[{"symbol":"BTC/USD","bids":[{"price":62798.8,"qty":0.02137959}],"asks":[],"checksum":1960920207,"timestamp":"2026-08-16T23:37:11.924378Z"}]}}
{"rx_ns": 42897350881100, "frame": {"channel":"book","type":"update","data":[{"symbol":"BTC/USD","bids":[{"price":62798.8,"qty":0.00000000},{"price":62784.7,"qty":0.79637232}],"asks":[],"checksum":1073822854,"timestamp":"2026-08-16T23:37:11.976558Z"}]}}
{"rx_ns": 42897351448400, "frame": {"channel":"book","type":"update","data":[{"symbol":"BTC/USD","bids":[{"price":62799.8,"qty":0.02137959}],"asks":[],"checksum":3642521851,"timestamp":"2026-08-16T23:37:11.976799Z"}]}}
{"rx_ns": 42897385649800, "frame": {"channel":"book","type":"update","data":[{"symbol":"BTC/USD","bids":[{"price":62787.6,"qty":0.00000000},{"price":62784.7,"qty":0.79637232}],"asks":[],"checksum":3642521851,"timestamp":"2026-08-16T23:37:12.010388Z"}]}}
{"rx_ns": 42897404615000, "frame": {"channel":"book","type":"update","data":[{"symbol":"BTC/USD","bids":[{"price":62786.1,"qty":0.00000000},{"price":62784.0,"qty":0.00857697}],"asks":[],"checksum":3642521851,"timestamp":"2026-08-16T23:37:12.016630Z"}]}}
{"rx_ns": 42897421481100, "frame": {"channel":"book","type":"update","data":[{"symbol":"BTC/USD","bids":[{"price":62786.6,"qty":0.15923399}],"asks":[],"checksum":3642521851,"timestamp":"2026-08-16T23:37:12.046268Z"}]}}
{"rx_ns": 42897497985800, "frame": {"channel":"book","type":"update","data":[{"symbol":"BTC/USD","bids":[{"price":62786.6,"qty":0.00000000},{"price":62784.0,"qty":0.00857697}],"asks":[],"checksum":3642521851,"timestamp":"2026-08-16T23:37:12.123470Z"}]}}
{"rx_ns": 42897520714000, "frame": {"channel":"book","type":"update","data":[{"symbol":"BTC/USD","bids":[{"price":62786.7,"qty":0.15923399}],"asks":[],"checksum":3642521851,"timestamp":"2026-08-16T23:37:12.145970Z"}]}}
{"rx_ns": 42897548640500, "frame": {"channel":"book","type":"update","data":[{"symbol":"BTC/USD","bids":[{"price":62788.8,"qty":0.79631955}],"asks":[],"checksum":3642521851,"timestamp":"2026-08-16T23:37:12.174037Z"}]}}
{"rx_ns": 42897551629200, "frame": {"channel":"book","type":"update","data":[{"symbol":"BTC/USD","bids":[{"price":62793.0,"qty":0.00000000},{"price":62784.7,"qty":0.79637232},{"price":62792.9,"qty":0.00334543}],"asks":[],"checksum":826747392,"timestamp":"2026-08-16T23:37:12.176483Z"}]}}
{"rx_ns": 42897551672600, "frame": {"channel":"book","type":"update","data":[{"symbol":"BTC/USD","bids":[],"asks":[{"price":62812.5,"qty":0.00000000},{"price":62818.8,"qty":0.65540712},{"price":62812.4,"qty":0.00318620}],"checksum":826747392,"timestamp":"2026-08-16T23:37:12.176806Z"}]}}
{"rx_ns": 42897557089700, "frame": {"channel":"book","type":"update","data":[{"symbol":"BTC/USD","bids":[{"price":62790.5,"qty":0.00000000},{"price":62784.0,"qty":0.00857697}],"asks":[],"checksum":826747392,"timestamp":"2026-08-16T23:37:12.182647Z"}]}}
{"rx_ns": 42897558680800, "frame": {"channel":"book","type":"update","data":[{"symbol":"BTC/USD","bids":[{"price":62791.2,"qty":0.79793185}],"asks":[],"checksum":826747392,"timestamp":"2026-08-16T23:37:12.183882Z"}]}}
{"rx_ns": 42897577325300, "frame": {"channel":"book","type":"update","data":[{"symbol":"BTC/USD","bids":[{"price":62799.8,"qty":0.00000000},{"price":62783.7,"qty":0.03185093}],"asks":[],"checksum":3187817973,"timestamp":"2026-08-16T23:37:12.194533Z"}]}}
{"rx_ns": 42897577391300, "frame": {"channel":"book","type":"update","data":[{"symbol":"BTC/USD","bids":[{"price":62800.7,"qty":0.02137959}],"asks":[],"checksum":585990068,"timestamp":"2026-08-16T23:37:12.194725Z"}]}}
{"rx_ns": 42897744215200, "frame": {"channel":"heartbeat"}}
{"rx_ns": 42897846770200, "frame": {"channel":"book","type":"update","data":[{"symbol":"BTC/USD","bids":[{"price":62791.2,"qty":0.00164300}],"asks":[],"checksum":585990068,"timestamp":"2026-08-16T23:37:12.470751Z"}]}}
{"rx_ns": 42897846821700, "frame": {"channel":"book","type":"update","data":[{"symbol":"BTC/USD","bids":[{"price":62788.8,"qty":0.00000000},{"price":62783.7,"qty":0.03185093}],"asks":[],"checksum":585990068,"timestamp":"2026-08-16T23:37:12.470872Z"}]}}
{"rx_ns": 42897847990300, "frame": {"channel":"book","type":"update","data":[{"symbol":"BTC/USD","bids":[{"price":62792.0,"qty":0.79627932}],"asks":[],"checksum":585990068,"timestamp":"2026-08-16T23:37:12.472427Z"}]}}
{"rx_ns": 42897848823700, "frame": {"channel":"book","type":"update","data":[{"symbol":"BTC/USD","bids":[{"price":62789.8,"qty":0.79630690}],"asks":[],"checksum":585990068,"timestamp":"2026-08-16T23:37:12.474101Z"}]}}
{"rx_ns": 42898040979000, "frame": {"channel":"book","type":"update","data":[{"symbol":"BTC/USD","bids":[{"price":62786.7,"qty":0.00000000},{"price":62784.0,"qty":0.00857697}],"asks":[],"checksum":585990068,"timestamp":"2026-08-16T23:37:12.664881Z"}]}}
{"rx_ns": 42898063455800, "frame": {"channel":"book","type":"update","data":[{"symbol":"BTC/USD","bids":[{"price":62784.0,"qty":0.00539144}],"asks":[],"checksum":585990068,"timestamp":"2026-08-16T23:37:12.688293Z"}]}}
{"rx_ns": 42898080398900, "frame": {"channel":"book","type":"update","data":[{"symbol":"BTC/USD","bids":[{"price":62792.0,"qty":0.00000000},{"price":62783.3,"qty":0.06960000}],"asks":[],"checksum":585990068,"timestamp":"2026-08-16T23:37:12.705991Z"}]}}
{"rx_ns": 42898140450100, "frame": {"channel":"book","type":"update","data":[{"symbol":"BTC/USD","bids":[{"price":62789.8,"qty":0.00000000},{"price":62782.4,"qty":0.00796401}],"asks":[],"checksum":585990068,"timestamp":"2026-08-16T23:37:12.763207Z"}]}}
{"rx_ns": 42898141653200, "frame": {"channel":"book","type":"update","data":[{"symbol":"BTC/USD","bids":[{"price":62789.1,"qty":0.79631559}],"asks":[],"checksum":585990068,"timestamp":"2026-08-16T23:37:12.765986Z"}]}}
{"rx_ns": 42898151824200, "frame": {"channel":"book","type":"update","data":[{"symbol":"BTC/USD","bids":[{"price":62789.9,"qty":0.09703642}],"asks":[],"checksum":585990068,"timestamp":"2026-08-16T23:37:12.770387Z"}]}}
{"rx_ns": 42898151873200, "frame": {"channel":"book","type":"update","data":[{"symbol":"BTC/USD","bids":[{"price":62785.9,"qty":0.15923399}],"asks":[],"checksum":585990068,"timestamp":"2026-08-16T23:37:12.770496Z"}]}}
{"rx_ns": 42898151904400, "frame": {"channel":"book","type":"update","data":[{"symbol":"BTC/USD","bids":[{"price":62785.9,"qty":0.00000000},{"price":62783.3,"qty":0.06960000}],"asks":[],"checksum":585990068,"timestamp":"2026-08-16T23:37:12.770757Z"}]}}
{"rx_ns": 42898151920100, "frame": {"channel":"book","type":"update","data":[{"symbol":"BTC/USD","bids":[{"price":62789.1,"qty":0.00000000},{"price":62782.4,"qty":0.00796401}],"asks":[],"checksum":585990068,"timestamp":"2026-08-16T23:37:12.771098Z"}]}}
{"rx_ns": 42898151931100, "frame": {"channel":"book","type":"update","data":[{"symbol":"BTC/USD","bids":[{"price":62784.7,"qty":0.00000000},{"price":62781.9,"qty":0.03185137}],"asks":[],"checksum":585990068,"timestamp":"2026-08-16T23:37:12.771107Z"}]}}
{"rx_ns": 42898162376800, "frame": {"channel":"book","type":"update","data":[{"symbol":"BTC/USD","bids":[{"price":62788.0,"qty":0.00000000},{"price":62781.3,"qty":0.07962845}],"asks":[],"checksum":585990068,"timestamp":"2026-08-16T23:37:12.772529Z"}]}}
{"rx_ns": 42898162433000, "frame": {"channel":"book","type":"update","data":[{"symbol":"BTC/USD","bids":[{"price":62782.0,"qty":0.00518958}],"asks":[],"checksum":585990068,"timestamp":"2026-08-16T23:37:12.772625Z"}]}}
{"rx_ns": 42898162445300, "frame": {"channel":"book","type":"update","data":[{"symbol":"BTC/USD","bids":[],"asks":[{"price":62813.9,"qty":0.00000000},{"price":62818.8,"qty":0.65540712}],"checksum":585990068,"timestamp":"2026-08-16T23:37:12.772859Z"}]}}
{"rx_ns": 42898162456400, "frame": {"channel":"book","type":"update","data":[{"symbol":"BTC/USD","bids":[{"price":62790.2,"qty":0.00000000},{"price":62781.3,"qty":0.07962845}],"asks":[],"checksum":585990068,"timestamp":"2026-08-16T23:37:12.772971Z"}]}}
{"rx_ns": 42898162466800, "frame": {"channel":"book","type":"update","data":[{"symbol":"BTC/USD","bids":[{"price":62800.7,"qty":0.00000000},{"price":62780.3,"qty":0.00023884}],"asks":[],"checksum":3187817973,"timestamp":"2026-08-16T23:37:12.775009Z"}]}}
{"rx_ns": 42898162477000, "frame": {"channel":"book","type":"update","data":[{"symbol":"BTC/USD","bids":[],"asks":[{"price":62818.7,"qty":0.00222509},{"price":62813.8,"qty":1.79195972}],"checksum":3187817973,"timestamp":"2026-08-16T23:37:12.776724Z"}]}}
{"rx_ns": 42898162488100, "frame": {"channel":"book","type":"update","data":[{"symbol":"BTC/USD","bids":[{"price":62798.4,"qty":0.02137959}],"asks":[],"checksum":3545983341,"timestamp":"2026-08-16T23:37:12.776831Z"}]}}
{"rx_ns": 42898162497300, "frame": {"channel":"book","type":"update","data":[{"symbol":"BTC/USD","bids":[{"price":62789.4,"qty":0.00000000},{"price":62780.3,"qty":0.00023884}],"asks":[],"checksum":3545983341,"timestamp":"2026-08-16T23:37:12.777515Z"}]}}
{"rx_ns": 42898162507200, "frame": {"channel":"book","type":"update","data":[{"symbol":"BTC/USD","bids":[],"asks":[{"price":62802.6,"qty":5.76525020}],"checksum":1486616732,"timestamp":"2026-08-16T23:37:12.778064Z"}]}}
{"rx_ns": 42898162516400, "frame": {"channel":"book","type":"update","data":[{"symbol":"BTC/USD","bids":[{"price":62786.0,"qty":0.00000000},{"price":62780.1,"qty":0.11000000}],"asks":[],"checksum":1486616732,"timestamp":"2026-08-16T23:37:12.778639Z"}]}}
{"rx_ns": 42898162527200, "frame": {"channel":"book","type":"update","data":[{"symbol":"BTC/USD","bids":[],"asks":[{"price":62818.8,"qty":0.00000000},{"price":62819.0,"qty":7.95938166}],"checksum":1486616732,"timestamp":"2026-08-16T23:37:12.778809Z"}]}}
{"rx_ns": 42898162537500, "frame": {"channel":"book","type":"update","data":[{"symbol":"BTC/USD","bids":[],"asks":[{"price":62803.7,"qty":0.00000000},{"price":62820.9,"qty":0.02865288},{"price":62802.6,"qty":5.82123492}],"checksum":2303946671,"timestamp":"2026-08-16T23:37:12.779302Z"}]}}
{"rx_ns": 42898162548900, "frame": {"channel":"book","type":"update","data":[{"symbol":"BTC/USD","bids":[{"price":62797.6,"qty":0.00000000},{"price":62780.0,"qty":0.00518974}],"asks":[],"checksum":110839787,"timestamp":"2026-08-16T23:37:12.779406Z"}]}}
{"rx_ns": 42898174016700, "frame": {"channel":"book","type":"update","data":[{"symbol":"BTC/USD","bids":[{"price":62781.2,"qty":0.01311942}],"asks":[],"checksum":110839787,"timestamp":"2026-08-16T23:37:12.781432Z"}]}}
{"rx_ns": 42898174059200, "frame": {"channel":"book","type":"update","data":[{"symbol":"BTC/USD","bids":[],"asks":[{"price":62805.6,"qty":0.65540712}],"checksum":1758381660,"timestamp":"2026-08-16T23:37:12.784945Z"}]}}
{"rx_ns": 42898174071100, "frame": {"channel":"book","type":"update","data":[{"symbol":"BTC/USD","bids":[{"price":62784.0,"qty":0.00000000},{"price":62780.0,"qty":0.00518974}],"asks":[],"checksum":1758381660,"timestamp":"2026-08-16T23:37:12.785205Z"}]}}
{"rx_ns": 42898174081700, "frame": {"channel":"book","type":"update","data":[{"symbol":"BTC/USD","bids":[],"asks":[{"price":62813.8,"qty":0.19620257},{"price":62818.7,"qty":1.59798224}],"checksum":1758381660,"timestamp":"2026-08-16T23:37:12.786180Z"}]}}
{"rx_ns": 42898174092300, "frame": {"channel":"book","type":"update","data":[{"symbol":"BTC/USD","bids":[],"asks":[{"price":62808.0,"qty":0.80465128}],"checksum":629431951,"timestamp":"2026-08-16T23:37:12.788738Z"}]}}
{"rx_ns": 42898181971600, "frame": {"channel":"book","type":"update","data":[{"symbol":"BTC/USD","bids":[],"asks":[{"price":62806.8,"qty":0.00005100},{"price":62805.5,"qty":0.18489680}],"checksum":3971036504,"timestamp":"2026-08-16T23:37:12.792748Z"}]}}
{"rx_ns": 42898182022800, "frame": {"channel":"book","type":"update","data":[{"symbol":"BTC/USD","bids":[],"asks":[{"price":62818.7,"qty":0.00222509},{"price":62813.8,"qty":1.79195972}],"checksum":3971036504,"timestamp":"2026-08-16T23:37:12.797075Z"}]}}
{"rx_ns": 42898182036300, "frame": {"channel":"book","type":"update","data":[{"symbol":"BTC/USD","bids":[],"asks":[{"price":62804.0,"qty":0.00518776}],"checksum":3551524133,"timestamp":"2026-08-16T23:37:12.797171Z"}]}}
{"rx_ns": 42898196062400, "frame": {"channel":"book","type":"update","data":[{"symbol":"BTC/USD","bids":[],"asks":[{"price":62809.5,"qty":2.38817573}],"checksum":3551524133,"timestamp":"2026-08-16T23:37:12.803193Z"}]}}
{"rx_ns": 42898196117600, "frame": {"channel":"book","type":"update","data":[{"symbol":"BTC/USD","bids":[{"price":62794.4,"qty":0.05598472}],"asks":[],"checksum":824940461,"timestamp":"2026-08-16T23:37:12.804659Z"}]}}
{"rx_ns": 42898196127700, "frame": {"channel":"book","type":"update","data":[{"symbol":"BTC/USD","bids":[{"price":62782.0,"qty":0.80159566}],"asks":[],"checksum":824940461,"timestamp":"2026-08-16T23:37:12.804746Z"}]}}
{"rx_ns": 42898196137400, "frame": {"channel":"book","type":"update","data":[{"symbol":"BTC/USD","bids":[{"price":62796.2,"qty":0.00000000},{"price":62780.0,"qty":0.00518974}],"asks":[],"checksum":23065628,"timestamp":"2026-08-16T23:37:12.805182Z"}]}}
{"rx_ns": 42898196148600, "frame": {"channel":"book","type":"update","data":[{"symbol":"BTC/USD","bids":[{"price":62782.0,"qty":0.00518958}],"asks":[],"checksum":23065628,"timestamp":"2026-08-16T23:37:12.805192Z"}]}}
{"rx_ns": 42898196158500, "frame": {"channel":"book","type":"update","data":[{"symbol":"BTC/USD","bids":[{"price":62794.4,"qty":0.00000000},{"price":62779.5,"qty":0.84467700}],"asks":[],"checksum":2546430391,"timestamp":"2026-08-16T23:37:12.805732Z"}]}}
{"rx_ns": 42898205857000, "frame": {"channel":"book","type":"update","data":[{"symbol":"BTC/USD","bids":[{"price":62781.9,"qty":0.00000000},{"price":62779.4,"qty":0.79643879},{"price":62779.7,"qty":0.07963050}],"asks":[],"checksum":2546430391,"timestamp":"2026-08-16T23:37:12.814155Z"}]}}
{"rx_ns": 42898205916000, "frame": {"channel":"book","type":"update","data":[{"symbol":"BTC/USD","bids":[{"price":62785.0,"qty":0.00000000},{"price":62779.4,"qty":0.79643879}],"asks":[],"checksum":2546430391,"timestamp":"2026-08-16T23:37:12.816406Z"}]}}
{"rx_ns": 42898205930500, "frame": {"channel":"book","type":"update","data":[{"symbol":"BTC/USD","bids":[{"price":62781.3,"qty":0.00000000},{"price":62778.2,"qty":0.00080000},{"price":62778.6,"qty":0.03185313}],"asks":[],"checksum":2546430391,"timestamp":"2026-08-16T23:37:12.817441Z"}]}}
{"rx_ns": 42898205941600, "frame": {"channel":"book","type":"update","data":[{"symbol":"BTC/USD","bids":[{"price":62779.7,"qty":0.00000000},{"price":62778.2,"qty":0.00080000}],"asks":[],"checksum":2546430391,"timestamp":"2026-08-16T23:37:12.821082Z"}]}}
{"rx_ns": 42898221009400, "frame": {"channel":"book","type":"update","data":[{"symbol":"BTC/USD","bids":[{"price":62779.4,"qty":0.00000000},{"price":62778.0,"qty":0.08800859}],"asks":[],"checksum":2546430391,"timestamp":"2026-08-16T23:37:12.826660Z"}]}}
{"rx_ns": 42898221066400, "frame": {"channel":"book","type":"update","data":[{"symbol":"BTC/USD","bids":[{"price":62778.2,"qty":0.00000000},{"price":62777.4,"qty":0.00039823}],"asks":[],"checksum":2546430391,"timestamp":"2026-08-16T23:37:12.834906Z"}]}}
{"rx_ns": 42898222473500, "frame": {"channel":"book","type":"update","data":[{"symbol":"BTC/USD","bids":[{"price":62792.1,"qty":0.00000000},{"price":62776.4,"qty":0.01598519}],"asks":[],"checksum":1553735971,"timestamp":"2026-08-16T23:37:12.843222Z"}]}}
{"rx_ns": 42898236153100, "frame": {"channel":"book","type":"update","data":[{"symbol":"BTC/USD","bids":[{"price":62782.0,"qty":0.00000000},{"price":62775.8,"qty":0.00318594}],"asks":[],"checksum":1553735971,"timestamp":"2026-08-16T23:37:12.854835Z"}]}}
{"rx_ns": 42898250924700, "frame": {"channel":"book","type":"update","data":[{"symbol":"BTC/USD","bids":[{"price":62781.0,"qty":0.79641831}],"asks":[],"checksum":1553735971,"timestamp":"2026-08-16T23:37:12.874029Z"}]}}
{"rx_ns": 42898253181600, "frame": {"channel":"book","type":"update","data":[{"symbol":"BTC/USD","bids":[{"price":62781.0,"qty":0.00000000},{"price":62775.8,"qty":0.00318594}],"asks":[],"checksum":1553735971,"timestamp":"2026-08-16T23:37:12.874675Z"}]}}
{"rx_ns": 42898256899300, "frame": {"channel":"book","type":"update","data":[{"symbol":"BTC/USD","bids":[],"asks":[{"price":62810.8,"qty":0.00000000},{"price":62817.1,"qty":0.13109402}],"checksum":1553735971,"timestamp":"2026-08-16T23:37:12.879049Z"}]}}
{"rx_ns": 42898256953000, "frame": {"channel":"book","type":"update","data":[{"symbol":"BTC/USD","bids":[],"asks":[{"price":62813.8,"qty":0.19620257},{"price":62807.0,"qty":1.59575715}],"checksum":2819771186,"timestamp":"2026-08-16T23:37:12.879101Z"}]}}
{"rx_ns": 42898262064000, "frame": {"channel":"book","type":"update","data":[{"symbol":"BTC/USD","bids":[],"asks":[{"price":62807.0,"qty":0.00000000},{"price":62817.1,"qty":0.13109402},{"price":62813.8,"qty":1.79195972}],"checksum":1553735971,"timestamp":"2026-08-16T23:37:12.885342Z"}]}}
{"rx_ns": 42898294447200, "frame": {"channel":"book","type":"update","data":[{"symbol":"BTC/USD","bids":[],"asks":[{"price":62813.8,"qty":1.59575715},{"price":62807.9,"qty":0.19620257}],"checksum":1553735971,"timestamp":"2026-08-16T23:37:12.910495Z"}]}}
{"rx_ns": 42898298268100, "frame": {"channel":"book","type":"update","data":[{"symbol":"BTC/USD","bids":[{"price":62792.9,"qty":0.00318620}],"asks":[],"checksum":1476275024,"timestamp":"2026-08-16T23:37:12.916965Z"}]}}
{"rx_ns": 42898307961500, "frame": {"channel":"book","type":"update","data":[{"symbol":"BTC/USD","bids":[],"asks":[{"price":62813.8,"qty":0.00000000},{"price":62817.1,"qty":0.13109402},{"price":62807.0,"qty":1.59575715}],"checksum":2742042945,"timestamp":"2026-08-16T23:37:12.926022Z"}]}}
{"rx_ns": 42898318465900, "frame": {"channel":"book","type":"update","data":[{"symbol":"BTC/USD","bids":[{"price":62785.6,"qty":0.00000000},{"price":62774.0,"qty":0.74369300}],"asks":[],"checksum":2742042945,"timestamp":"2026-08-16T23:37:12.935297Z"}]}}
{"rx_ns": 42898318516500, "frame": {"channel":"book","type":"update","data":[{"symbol":"BTC/USD","bids":[{"price":62790.6,"qty":0.00000000},{"price":62773.8,"qty":0.13109402}],"asks":[],"checksum":3235540812,"timestamp":"2026-08-16T23:37:12.940256Z"}]}}
{"rx_ns": 42898318528800, "frame": {"channel":"book","type":"update","data":[{"symbol":"BTC/USD","bids":[{"price":62774.2,"qty":0.02867420}],"asks":[],"checksum":3235540812,"timestamp":"2026-08-16T23:37:12.940480Z"}]}}
{"rx_ns": 42898333961300, "frame": {"channel":"book","type":"update","data":[{"symbol":"BTC/USD","bids":[{"price":62786.4,"qty":0.05598472}],"asks":[],"checksum":3235540812,"timestamp":"2026-08-16T23:37:12.942249Z"}]}}
{"rx_ns": 42898334016800, "frame": {"channel":"book","type":"update","data":[{"symbol":"BTC/USD","bids":[{"price":62778.6,"qty":0.00000000},{"price":62774.0,"qty":0.74369300}],"asks":[],"checksum":3235540812,"timestamp":"2026-08-16T23:37:12.947892Z"}]}}
{"rx_ns": 42898335715000, "frame": {"channel":"book","type":"update","data":[{"symbol":"BTC/USD","bids":[{"price":62778.0,"qty":0.00837574},{"price":62776.5,"qty":0.03185420}],"asks":[],"checksum":3235540812,"timestamp":"2026-08-16T23:37:12.951215Z"}]}}
{"rx_ns": 42898335763600, "frame": {"channel":"book","type":"update","data":[{"symbol":"BTC/USD","bids":[{"price":62780.1,"qty":0.00000000},{"price":62774.0,"qty":0.74369300}],"asks":[],"checksum":3235540812,"timestamp":"2026-08-16T23:37:12.953611Z"}]}}
{"rx_ns": 42898335778400, "frame": {"channel":"book","type":"update","data":[{"symbol":"BTC/USD","bids":[{"price":62775.9,"qty":0.07963552}],"asks":[],"checksum":3235540812,"timestamp":"2026-08-16T23:37:12.954832Z"}]}}
{"rx_ns": 42898343337400, "frame": {"channel":"book","type":"update","data":[{"symbol":"BTC/USD","bids":[{"price":62798.4,"qty":0.00000000},{"price":62774.0,"qty":0.74369300}],"asks":[],"checksum":3404109272,"timestamp":"2026-08-16T23:37:12.957714Z"}]}}
{"rx_ns": 42898343705700, "frame": {"channel":"book","type":"update","data":[{"symbol":"BTC/USD","bids":[{"price":62797.0,"qty":0.02150659}],"asks":[],"checksum":4025759346,"timestamp":"2026-08-16T23:37:12.959954Z"}]}}
{"rx_ns": 42898343719400, "frame": {"channel":"book","type":"update","data":[{"symbol":"BTC/USD","bids":[{"price":62782.4,"qty":0.00000000},{"price":62773.4,"qty":0.89108800}],"asks":[],"checksum":4025759346,"timestamp":"2026-08-16T23:37:12.959970Z"}]}}
{"rx_ns": 42898343729900, "frame": {"channel":"book","type":"update","data":[{"symbol":"BTC/USD","bids":[],"asks":[{"price":62810.4,"qty":0.13109402}],"checksum":4025759346,"timestamp":"2026-08-16T23:37:12.961023Z"}]}}
{"rx_ns": 42898348544100, "frame": {"channel":"book","type":"update","data":[{"symbol":"BTC/USD","bids":[{"price":62777.4,"qty":0.00000000},{"price":62772.6,"qty":0.06960000}],"asks":[],"checksum":4025759346,"timestamp":"2026-08-16T23:37:12.965620Z"}]}}
{"rx_ns": 42898364093200, "frame": {"channel":"book","type":"update","data":[{"symbol":"BTC/USD","bids":[{"price":62779.5,"qty":1.00391099}],"asks":[],"checksum":4025759346,"timestamp":"2026-08-16T23:37:12.982112Z"}]}}
{"rx_ns": 42898364147300, "frame": {"channel":"book","type":"update","data":[{"symbol":"BTC/USD","bids":[],"asks":[{"price":62803.9,"qty":0.57289635}],"checksum":2791712775,"timestamp":"2026-08-16T23:37:12.982804Z"}]}}
{"rx_ns": 42898364161200, "frame": {"channel":"book","type":"update","data":[{"symbol":"BTC/USD","bids":[],"asks":[{"price":62805.5,"qty":0.00000000},{"price":62815.7,"qty":0.10331161},{"price":62806.9,"qty":0.18489680}],"checksum":1905968279,"timestamp":"2026-08-16T23:37:12.985101Z"}]}}
{"rx_ns": 42898378660300, "frame": {"channel":"book","type":"update","data":[{"symbol":"BTC/USD","bids":[{"price":62797.0,"qty":0.00012700}],"asks":[],"checksum":2903422294,"timestamp":"2026-08-16T23:37:13.001862Z"}]}}
{"rx_ns": 42898378705200, "frame": {"channel":"book","type":"update","data":[{"symbol":"BTC/USD","bids":[{"price":62775.9,"qty":0.00000000},{"price":62771.8,"qty":0.00080000}],"asks":[],"checksum":2903422294,"timestamp":"2026-08-16T23:37:13.002959Z"}]}}
{"rx_ns": 42898378718500, "frame": {"channel":"book","type":"update","data":[{"symbol":"BTC/USD","bids":[{"price":62796.0,"qty":0.02137959}],"asks":[],"checksum":3183349564,"timestamp":"2026-08-16T23:37:13.003110Z"}]}}
{"rx_ns": 42898380886400, "frame": {"channel":"book","type":"update","data":[{"symbol":"BTC/USD","bids":[{"price":62776.5,"qty":0.00000000},{"price":62771.8,"qty":0.00080000}],"asks":[],"checksum":3183349564,"timestamp":"2026-08-16T23:37:13.006001Z"}]}}
{"rx_ns": 42898384417200, "frame": {"channel":"book","type":"update","data":[{"symbol":"BTC/USD","bids":[{"price":62779.5,"qty":0.84467700}],"asks":[],"checksum":3183349564,"timestamp":"2026-08-16T23:37:13.007531Z"}]}}
{"rx_ns": 42898390990400, "frame": {"channel":"book","type":"update","data":[{"symbol":"BTC/USD","bids":[{"price":62802.5,"qty":0.00049808}],"asks":[],"checksum":1327756067,"timestamp":"2026-08-16T23:37:13.011009Z"}]}}
{"rx_ns": 42898392658600, "frame": {"channel":"book","type":"update","data":[{"symbol":"BTC/USD","bids":[],"asks":[{"price":62807.0,"qty":0.00000000},{"price":62815.7,"qty":0.10331161}],"checksum":4286353542,"timestamp":"2026-08-16T23:37:13.013789Z"}]}}
{"rx_ns": 42898396522400, "frame": {"channel":"book","type":"update","data":[{"symbol":"BTC/USD","bids":[{"price":62802.5,"qty":0.00010000},{"price":62802.5,"qty":0.00000000},{"price":62771.4,"qty":0.00039827}],"asks":[{"price":62800.7,"qty":0.07084096}],"checksum":403221632,"timestamp":"2026-08-16T23:37:13.016972Z"}]}}
{"rx_ns": 42898396561400, "frame": {"channel":"book","type":"update","data":[{"symbol":"BTC/USD","bids":[{"price":62780.3,"qty":0.15947283}],"asks":[],"checksum":403221632,"timestamp":"2026-08-16T23:37:13.017168Z"}]}}
{"rx_ns": 42898396571600, "frame": {"channel":"book","type":"update","data":[{"symbol":"BTC/USD","bids":[{"price":62785.0,"qty":0.79636797}],"asks":[],"checksum":403221632,"timestamp":"2026-08-16T23:37:13.017223Z"}]}}
{"rx_ns": 42898396578700, "frame": {"channel":"book","type":"update","data":[{"symbol":"BTC/USD","bids":[],"asks":[{"price":62800.7,"qty":0.18084096}],"checksum":3091587529,"timestamp":"2026-08-16T23:37:13.018112Z"}]}}
{"rx_ns": 42898396585800, "frame": {"channel":"book","type":"update","data":[{"symbol":"BTC/USD","bids":[{"price":62800.6,"qty":0.00000000},{"price":62771.4,"qty":0.00039827}],"asks":[],"checksum":2907335323,"timestamp":"2026-08-16T23:37:13.018420Z"}]}}
{"rx_ns": 42898396593800, "frame": {"channel":"book","type":"update","data":[{"symbol":"BTC/USD","bids":[],"asks":[{"price":62802.6,"qty":5.76525020},{"price":62800.7,"qty":0.23682568}],"checksum":2873051894,"timestamp":"2026-08-16T23:37:13.018702Z"}]}}
{"rx_ns": 42898396602100, "frame": {"channel":"book","type":"update","data":[{"symbol":"BTC/USD","bids":[],"asks":[{"price":62802.6,"qty":5.74557538}],"checksum":3003994414,"timestamp":"2026-08-16T23:37:13.018736Z"}]}}
{"rx_ns": 42898396608600, "frame": {"channel":"book","type":"update","data":[{"symbol":"BTC/USD","bids":[],"asks":[{"price":62802.6,"qty":5.58634139}],"checksum":2382578928,"timestamp":"2026-08-16T23:37:13.018826Z"}]}}
{"rx_ns": 42898396614700, "frame": {"channel":"book","type":"update","data":[{"symbol":"BTC/USD","bids":[],"asks":[{"price":62800.7,"qty":0.31642568}],"checksum":180174683,"timestamp":"2026-08-16T23:37:13.018853Z"}]}}
{"rx_ns": 42898396621100, "frame": {"channel":"book","type":"update","data":[{"symbol":"BTC/USD","bids":[],"asks":[{"price":62800.7,"qty":0.38602568}],"checksum":2050336391,"timestamp":"2026-08-16T23:37:13.018873Z"}]}}
{"rx_ns": 42898396627700, "frame": {"channel":"book","type":"update","data":[{"symbol":"BTC/USD","bids":[],"asks":[{"price":62806.9,"qty":0.00000000},{"price":62815.7,"qty":0.10331161},{"price":62802.5,"qty":0.18489680}],"checksum":2142917193,"timestamp":"2026-08-16T23:37:13.019048Z"}]}}
{"rx_ns": 42898396635300, "frame": {"channel":"book","type":"update","data":[{"symbol":"BTC/USD","bids":[{"price":62777.2,"qty":0.65540712}],"asks":[],"checksum":2142917193,"timestamp":"2026-08-16T23:37:13.019161Z"}]}}
{"rx_ns": 42898396641700, "frame": {"channel":"book","type":"update","data":[{"symbol":"BTC/USD","bids":[],"asks":[{"price":62808.0,"qty":0.00857369}],"checksum":2142917193,"timestamp":"2026-08-16T23:37:13.019259Z"}]}}
{"rx_ns": 42898408409000, "frame": {"channel":"book","type":"update","data":[{"symbol":"BTC/USD","bids":[],"asks":[{"price":62802.6,"qty":5.51674139}],"checksum":2400985091,"timestamp":"2026-08-16T23:37:13.019602Z"}]}}
{"rx_ns": 42898408453400, "frame": {"channel":"book","type":"update","data":[{"symbol":"BTC/USD","bids":[{"price":62797.5,"qty":0.00000000},{"price":62771.4,"qty":0.00039827}],"asks":[],"checksum":2913601983,"timestamp":"2026-08-16T23:37:13.020845Z"}]}}
{"rx_ns": 42898408465300, "frame": {"channel":"book","type":"update","data":[{"symbol":"BTC/USD","bids":[],"asks":[{"price":62802.6,"qty":4.86133427}],"checksum":944096166,"timestamp":"2026-08-16T23:37:13.020917Z"}]}}
{"rx_ns": 42898408474100, "frame": {"channel":"book","type":"update","data":[{"symbol":"BTC/USD","bids":[],"asks":[{"price":62800.7,"qty":0.83629385}],"checksum":212590745,"timestamp":"2026-08-16T23:37:13.020976Z"}]}}
{"rx_ns": 42898408482600, "frame": {"channel":"book","type":"update","data":[{"symbol":"BTC/USD","bids":[],"asks":[{"price":62800.7,"qty":1.63246331}],"checksum":3135709292,"timestamp":"2026-08-16T23:37:13.021167Z"}]}}
{"rx_ns": 42898408491000, "frame": {"channel":"book","type":"update","data":[{"symbol":"BTC/USD","bids":[],"asks":[{"price":62802.6,"qty":4.06518889}],"checksum":3002962644,"timestamp":"2026-08-16T23:37:13.021327Z"}]}}
{"rx_ns": 42898408499500, "frame": {"channel":"book","type":"update","data":[{"symbol":"BTC/USD","bids":[],"asks":[{"price":62803.8,"qty":0.00000000},{"price":62815.7,"qty":0.10331161}],"checksum":2734298107,"timestamp":"2026-08-16T23:37:13.021351Z"}]}}
{"rx_ns": 42898408508400, "frame": {"channel":"book","type":"update","data":[{"symbol":"BTC/USD","bids":[],"asks":[{"price":62797.6,"qty":0.06960000}],"checksum":3405185678,"timestamp":"2026-08-16T23:37:13.021394Z"}]}}
{"rx_ns": 42898408516600, "frame": {"channel":"book","type":"update","data":[{"symbol":"BTC/USD","bids":[],"asks":[{"price":62800.7,"qty":1.56286331}],"checksum":2866389728,"timestamp":"2026-08-16T23:37:13.022022Z"}]}}
{"rx_ns": 42898408524600, "frame": {"channel":"book","type":"update","data":[{"symbol":"BTC/USD","bids":[],"asks":[{"price":62800.7,"qty":1.11259514}],"checksum":881858089,"timestamp":"2026-08-16T23:37:13.022090Z"}]}}
{"rx_ns": 42898408532600, "frame": {"channel":"book","type":"update","data":[{"symbol":"BTC/USD","bids":[],"asks":[{"price":62800.7,"qty":1.19059514}],"checksum":2532219740,"timestamp":"2026-08-16T23:37:13.023106Z"}]}}
{"rx_ns": 42898408541600, "frame": {"channel":"book","type":"update","data":[{"symbol":"BTC/USD","bids":[],"asks":[{"price":62800.7,"qty":0.39442568}],"checksum":3381156956,"timestamp":"2026-08-16T23:37:13.023127Z"}]}}
{"rx_ns": 42898408550200, "frame": {"channel":"book","type":"update","data":[{"symbol":"BTC/USD","bids":[],"asks":[{"price":62802.6,"qty":3.98558889}],"checksum":666767927,"timestamp":"2026-08-16T23:37:13.023552Z"}]}}
{"rx_ns": 42898408558000, "frame": {"channel":"book","type":"update","data":[{"symbol":"BTC/USD","bids":[],"asks":[{"price":62800.7,"qty":0.31482568}],"checksum":1885372546,"timestamp":"2026-08-16T23:37:13.023719Z"}]}}
{"rx_ns": 42898408566000, "frame": {"channel":"book","type":"update","data":[{"symbol":"BTC/USD","bids":[],"asks":[{"price":62797.6,"qty":0.14920000}],"checksum":3396078074,"timestamp":"2026-08-16T23:37:13.024133Z"}]}}
{"rx_ns": 42898408685200, "frame": {"channel":"book","type":"update","data":[{"symbol":"BTC/USD","bids":[{"price":62791.4,"qty":0.00000000},{"price":62770.7,"qty":0.00455372}],"asks":[],"checksum":3873733962,"timestamp":"2026-08-16T23:37:13.025420Z"}]}}
{"rx_ns": 42898408697000, "frame": {"channel":"book","type":"update","data":[{"symbol":"BTC/USD","bids":[],"asks":[{"price":62802.5,"qty":0.19566797}],"checksum":110438741,"timestamp":"2026-08-16T23:37:13.025555Z"}]}}
{"rx_ns": 42898408707000, "frame": {"channel":"book","type":"update","data":[{"symbol":"BTC/USD","bids":[],"asks":[{"price":62812.0,"qty":0.00000000},{"price":62815.7,"qty":0.10331161}],"checksum":110438741,"timestamp":"2026-08-16T23:37:13.025673Z"}]}}
{"rx_ns": 42898408716100, "frame": {"channel":"book","type":"update","data":[{"symbol":"BTC/USD","bids":[],"asks":[{"price":62814.0,"qty":0.00000000},{"price":62816.2,"qty":0.00005100}],"checksum":110438741,"timestamp":"2026-08-16T23:37:13.025778Z"}]}}
{"rx_ns": 42898408725100, "frame": {"channel":"book","type":"update","data":[{"symbol":"BTC/USD","bids":[],"asks":[{"price":62797.6,"qty":0.07960000}],"checksum":2607988117,"timestamp":"2026-08-16T23:37:13.026041Z"}]}}
{"rx_ns": 42898408733500, "frame": {"channel":"book","type":"update","data":[{"symbol":"BTC/USD","bids":[],"asks":[{"price":62797.1,"qty":0.06960000}],"checksum":3298962471,"timestamp":"2026-08-16T23:37:13.026178Z"}]}}
{"rx_ns": 42898408742100, "frame": {"channel":"book","type":"update","data":[{"symbol":"BTC/USD","bids":[{"price":62792.9,"qty":0.00000000},{"price":62770.0,"qty":0.39276310},{"price":62787.4,"qty":0.00318620}],"asks":[],"checksum":2182572719,"timestamp":"2026-08-16T23:37:13.026947Z"}]}}
{"rx_ns": 42898411877700, "frame": {"channel":"book","type":"update","data":[{"symbol":"BTC/USD","bids":[],"asks":[{"price":62809.5,"qty":0.00000000},{"price":62816.2,"qty":0.00005100}],"checksum":2182572719,"timestamp":"2026-08-16T23:37:13.027169Z"}]}}
{"rx_ns": 42898411911500, "frame": {"channel":"book","type":"update","data":[{"symbol":"BTC/USD","bids":[],"asks":[{"price":62812.4,"qty":0.00000000},{"price":62817.1,"qty":0.13109402},{"price":62806.8,"qty":0.00323720}],"checksum":2498127341,"timestamp":"2026-08-16T23:37:13.027202Z"}]}}
{"rx_ns": 42898411922800, "frame": {"channel":"book","type":"update","data":[{"symbol":"BTC/USD","bids":[],"asks":[{"price":62797.6,"qty":0.15760000}],"checksum":3089088190,"timestamp":"2026-08-16T23:37:13.027734Z"}]}}
{"rx_ns": 42898411930300, "frame": {"channel":"book","type":"update","data":[{"symbol":"BTC/USD","bids":[],"asks":[{"price":62800.7,"qty":0.23682568}],"checksum":870085212,"timestamp":"2026-08-16T23:37:13.027841Z"}]}}
{"rx_ns": 42898411937200, "frame": {"channel":"book","type":"update","data":[{"symbol":"BTC/USD","bids":[],"asks":[{"price":62797.6,"qty":0.07800000}],"checksum":3521396130,"timestamp":"2026-08-16T23:37:13.027854Z"}]}}
{"rx_ns": 42898411943700, "frame": {"channel":"book","type":"update","data":[{"symbol":"BTC/USD","bids":[],"asks":[{"price":62797.1,"qty":0.14920000}],"checksum":2992318915,"timestamp":"2026-08-16T23:37:13.027952Z"}]}}
{"rx_ns": 42898411950000, "frame": {"channel":"book","type":"update","data":[{"symbol":"BTC/USD","bids":[],"asks":[{"price":62802.6,"qty":3.90758889}],"checksum":3493395947,"timestamp":"2026-08-16T23:37:13.028083Z"}]}}
{"rx_ns": 42898411956900, "frame": {"channel":"book","type":"update","data":[{"symbol":"BTC/USD","bids":[],"asks":[{"price":62797.6,"qty":0.00000000},{"price":62818.7,"qty":0.00222509}],"checksum":3067110439,"timestamp":"2026-08-16T23:37:13.028718Z"}]}}
{"rx_ns": 42898411964000, "frame": {"channel":"book","type":"update","data":[{"symbol":"BTC/USD","bids":[],"asks":[{"price":62797.1,"qty":0.19750000}],"checksum":2525488707,"timestamp":"2026-08-16T23:37:13.028793Z"}]}}
{"rx_ns": 42898411970400, "frame": {"channel":"book","type":"update","data":[{"symbol":"BTC/USD","bids":[],"asks":[{"price":62798.7,"qty":0.79619496}],"checksum":870418109,"timestamp":"2026-08-16T23:37:13.028824Z"}]}}
{"rx_ns": 42898411976700, "frame": {"channel":"book","type":"update","data":[{"symbol":"BTC/USD","bids":[],"asks":[{"price":62797.6,"qty":0.07084444}],"checksum":3370121935,"timestamp":"2026-08-16T23:37:13.030510Z"}]}}
{"rx_ns": 42898411983500, "frame": {"channel":"book","type":"update","data":[{"symbol":"BTC/USD","bids":[],"asks":[{"price":62797.1,"qty":0.26834500}],"checksum":3431873363,"timestamp":"2026-08-16T23:37:13.030552Z"}]}}
{"rx_ns": 42898411989600, "frame": {"channel":"book","type":"update","data":[{"symbol":"BTC/USD","bids":[],"asks":[{"price":62810.0,"qty":0.00000000},{"price":62817.1,"qty":0.13109402}],"checksum":3431873363,"timestamp":"2026-08-16T23:37:13.030593Z"}]}}
{"rx_ns": 42898411996500, "frame": {"channel":"book","type":"update","data":[{"symbol":"BTC/USD","bids":[],"asks":[{"price":62808.0,"qty":0.00318431}],"checksum":3431873363,"timestamp":"2026-08-16T23:37:13.030618Z"}]}}
{"rx_ns": 42898412002900, "frame": {"channel":"book","type":"update","data":[{"symbol":"BTC/USD","bids":[],"asks":[{"price":62803.4,"qty":0.06960000}],"checksum":2503302653,"timestamp":"2026-08-16T23:37:13.030906Z"}]}}
{"rx_ns": 42898425083100, "frame": {"channel":"book","type":"update","data":[{"symbol":"BTC/USD","bids":[],"asks":[{"price":62797.1,"qty":0.42757899}],"checksum":1654766325,"timestamp":"2026-08-16T23:37:13.046260Z"}]}}
{"rx_ns": 42898425155900, "frame": {"channel":"book","type":"update","data":[{"symbol":"BTC/USD","bids":[{"price":62780.3,"qty":0.00023884}],"asks":[],"checksum":1654766325,"timestamp":"2026-08-16T23:37:13.047156Z"}]}}
{"rx_ns": 42898427069400, "frame": {"channel":"book","type":"update","data":[{"symbol":"BTC/USD","bids":[],"asks":[{"price":62802.5,"qty":0.01077117},{"price":62813.2,"qty":0.18489680}],"checksum":2381632431,"timestamp":"2026-08-16T23:37:13.047373Z"}]}}
{"rx_ns": 42898427125900, "frame": {"channel":"book","type":"update","data":[{"symbol":"BTC/USD","bids":[],"asks":[{"price":62812.7,"qty":0.00000000},{"price":62816.2,"qty":0.00005100},{"price":62803.3,"qty":0.01100000}],"checksum":4090389357,"timestamp":"2026-08-16T23:37:13.047579Z"}]}}
{"rx_ns": 42898427143400, "frame": {"channel":"book","type":"update","data":[{"symbol":"BTC/USD","bids":[{"price":62776.8,"qty":0.10331161}],"asks":[],"checksum":4090389357,"timestamp":"2026-08-16T23:37:13.047937Z"}]}}
{"rx_ns": 42898427180000, "frame": {"channel":"book","type":"update","data":[{"symbol":"BTC/USD","bids":[],"asks":[{"price":62797.1,"qty":0.76953847}],"checksum":840042318,"timestamp":"2026-08-16T23:37:13.050885Z"}]}}
{"rx_ns": 42898427216400, "frame": {"channel":"book","type":"update","data":[{"symbol":"BTC/USD","bids":[{"price":62796.0,"qty":0.00000000},{"price":62770.7,"qty":0.00455372}],"asks":[],"checksum":3655306591,"timestamp":"2026-08-16T23:37:13.051716Z"}]}}
{"rx_ns": 42898430277100, "frame": {"channel":"book","type":"update","data":[{"symbol":"BTC/USD","bids":[],"asks":[{"price":62797.1,"qty":1.42494559}],"checksum":723689792,"timestamp":"2026-08-16T23:37:13.052821Z"}]}}
{"rx_ns": 42898430314900, "frame": {"channel":"book","type":"update","data":[{"symbol":"BTC/USD","bids":[{"price":62782.2,"qty":0.15923399}],"asks":[],"checksum":1373789466,"timestamp":"2026-08-16T23:37:13.052885Z"}]}}
{"rx_ns": 42898430326700, "frame": {"channel":"book","type":"update","data":[{"symbol":"BTC/USD","bids":[{"price":62777.8,"qty":0.11000000}],"asks":[],"checksum":1373789466,"timestamp":"2026-08-16T23:37:13.053809Z"}]}}
{"rx_ns": 42898437804500, "frame": {"channel":"book","type":"update","data":[{"symbol":"BTC/USD","bids":[{"price":62796.9,"qty":0.02137959}],"asks":[],"checksum":3685579384,"timestamp":"2026-08-16T23:37:13.057297Z"}]}}
{"rx_ns": 42898437841200, "frame": {"channel":"book","type":"update","data":[{"symbol":"BTC/USD","bids":[],"asks":[{"price":62802.5,"qty":0.00000000},{"price":62816.2,"qty":0.00005100}],"checksum":2338405213,"timestamp":"2026-08-16T23:37:13.058201Z"}]}}
{"rx_ns": 42898437854800, "frame": {"channel":"book","type":"update","data":[{"symbol":"BTC/USD","bids":[{"price":62785.0,"qty":0.00000000},{"price":62771.8,"qty":0.00080000}],"asks":[],"checksum":1847904079,"timestamp":"2026-08-16T23:37:13.058212Z"}]}}
{"rx_ns": 42898437916600, "frame": {"channel":"book","type":"update","data":[{"symbol":"BTC/USD","bids":[{"price":62777.2,"qty":0.00000000},{"price":62771.5,"qty":0.13109402}],"asks":[],"checksum":1847904079,"timestamp":"2026-08-16T23:37:13.058289Z"}]}}
{"rx_ns": 42898437927800, "frame": {"channel":"book","type":"update","data":[{"symbol":"BTC/USD","bids":[],"asks":[{"price":62800.7,"qty":0.24275148}],"checksum":2704872004,"timestamp":"2026-08-16T23:37:13.059838Z"}]}}
{"rx_ns": 42898437936800, "frame": {"channel":"book","type":"update","data":[{"symbol":"BTC/USD","bids":[],"asks":[{"price":62802.6,"qty":3.90166323}],"checksum":2650887292,"timestamp":"2026-08-16T23:37:13.060091Z"}]}}
{"rx_ns": 42898441585700, "frame": {"channel":"book","type":"update","data":[{"symbol":"BTC/USD","bids":[{"price":62782.2,"qty":0.00000000},{"price":62771.4,"qty":0.00039827}],"asks":[],"checksum":1925078646,"timestamp":"2026-08-16T23:37:13.062743Z"}]}}
{"rx_ns": 42898445195800, "frame": {"channel":"book","type":"update","data":[{"symbol":"BTC/USD","bids":[],"asks":[{"price":62797.6,"qty":0.07677047}],"checksum":4156579959,"timestamp":"2026-08-16T23:37:13.064062Z"}]}}
{"rx_ns": 42898445241400, "frame": {"channel":"book","type":"update","data":[{"symbol":"BTC/USD","bids":[],"asks":[{"price":62800.7,"qty":0.23682568}],"checksum":1350627905,"timestamp":"2026-08-16T23:37:13.064370Z"}]}}
{"rx_ns": 42898451234200, "frame": {"channel":"book","type":"update","data":[{"symbol":"BTC/USD","bids":[],"asks":[{"price":62813.2,"qty":0.00000000},{"price":62818.7,"qty":0.00222509},{"price":62807.0,"qty":0.18489680}],"checksum":1350627905,"timestamp":"2026-08-16T23:37:13.068816Z"}]}}
{"rx_ns": 42898451291700, "frame": {"channel":"book","type":"update","data":[{"symbol":"BTC/USD","bids":[],"asks":[{"price":62797.1,"qty":1.43087166}],"checksum":3986990149,"timestamp":"2026-08-16T23:37:13.071265Z"}]}}
{"rx_ns": 42898451303600, "frame": {"channel":"book","type":"update","data":[{"symbol":"BTC/USD","bids":[],"asks":[{"price":62797.6,"qty":0.07084444}],"checksum":1759156804,"timestamp":"2026-08-16T23:37:13.071305Z"}]}}
{"rx_ns": 42898460039500, "frame": {"channel":"book","type":"update","data":[{"symbol":"BTC/USD","bids":[{"price":62783.9,"qty":0.15923399}],"asks":[],"checksum":2464825369,"timestamp":"2026-08-16T23:37:13.084050Z"}]}}
{"rx_ns": 42898462363800, "frame": {"channel":"book","type":"update","data":[{"symbol":"BTC/USD","bids":[],"asks":[{"price":62802.6,"qty":3.90126515},{"price":62800.7,"qty":0.23722376}],"checksum":2396577722,"timestamp":"2026-08-16T23:37:13.088127Z"}]}}
{"rx_ns": 42898479992000, "frame": {"channel":"book","type":"update","data":[{"symbol":"BTC/USD","bids":[{"price":62786.4,"qty":0.00000000},{"price":62771.4,"qty":0.00039827},{"price":62791.3,"qty":0.05598472}],"asks":[],"checksum":1269445095,"timestamp":"2026-08-16T23:37:13.104176Z"}]}}
{"rx_ns": 42898481643900, "frame": {"channel":"book","type":"update","data":[{"symbol":"BTC/USD","bids":[{"price":62797.0,"qty":0.00000000},{"price":62771.4,"qty":0.00039827}],"asks":[{"price":62797.0,"qty":0.00007300}],"checksum":2115243580,"timestamp":"2026-08-16T23:37:13.106889Z"}]}}
{"rx_ns": 42898486586100, "frame": {"channel":"book","type":"update","data":[{"symbol":"BTC/USD","bids":[],"asks":[{"price":62797.0,"qty":0.01172515}],"checksum":2465731891,"timestamp":"2026-08-16T23:37:13.107492Z"}]}}
{"rx_ns": 42898486636100, "frame": {"channel":"book","type":"update","data":[{"symbol":"BTC/USD","bids":[],"asks":[{"price":62797.1,"qty":1.42494559}],"checksum":6578741,"timestamp":"2026-08-16T23:37:13.107630Z"}]}}
{"rx_ns": 42898486650700, "frame": {"channel":"book","type":"update","data":[{"symbol":"BTC/USD","bids":[],"asks":[{"price":62797.0,"qty":0.08132515}],"checksum":1338619859,"timestamp":"2026-08-16T23:37:13.108117Z"}]}}
{"rx_ns": 42898486669400, "frame": {"channel":"book","type":"update","data":[{"symbol":"BTC/USD","bids":[],"asks":[{"price":62797.1,"qty":1.35534559}],"checksum":2050678557,"timestamp":"2026-08-16T23:37:13.108151Z"}]}}
{"rx_ns": 42898486680400, "frame": {"channel":"book","type":"update","data":[{"symbol":"BTC/USD","bids":[{"price":62780.7,"qty":0.65540712}],"asks":[],"checksum":2050678557,"timestamp":"2026-08-16T23:37:13.109969Z"}]}}
{"rx_ns": 42898486691200, "frame": {"channel":"book","type":"update","data":[{"symbol":"BTC/USD","bids":[],"asks":[{"price":62797.1,"qty":1.19611160}],"checksum":1192618340,"timestamp":"2026-08-16T23:37:13.110007Z"}]}}
{"rx_ns": 42898486700900, "frame": {"channel":"book","type":"update","data":[{"symbol":"BTC/USD","bids":[{"price":62772.7,"qty":0.00796524}],"asks":[],"checksum":1192618340,"timestamp":"2026-08-16T23:37:13.110040Z"}]}}
{"rx_ns": 42898486707200, "frame": {"channel":"book","type":"update","data":[{"symbol":"BTC/USD","bids":[],"asks":[{"price":62797.0,"qty":0.15932515}],"checksum":2238747027,"timestamp":"2026-08-16T23:37:13.110069Z"}]}}
{"rx_ns": 42898486713900, "frame": {"channel":"book","type":"update","data":[{"symbol":"BTC/USD","bids":[],"asks":[{"price":62797.1,"qty":1.14781160}],"checksum":3548517327,"timestamp":"2026-08-16T23:37:13.110097Z"}]}}
{"rx_ns": 42898486720400, "frame": {"channel":"book","type":"update","data":[{"symbol":"BTC/USD","bids":[],"asks":[{"price":62797.1,"qty":1.06821160}],"checksum":3644668436,"timestamp":"2026-08-16T23:37:13.110233Z"}]}}
{"rx_ns": 42898486727000, "frame": {"channel":"book","type":"update","data":[{"symbol":"BTC/USD","bids":[],"asks":[{"price":62797.0,"qty":0.23892515}],"checksum":4174566184,"timestamp":"2026-08-16T23:37:13.110241Z"}]}}
{"rx_ns": 42898495396400, "frame": {"channel":"book","type":"update","data":[{"symbol":"BTC/USD","bids":[],"asks":[{"price":62797.0,"qty":0.30933848}],"checksum":3662060326,"timestamp":"2026-08-16T23:37:13.116174Z"}]}}
{"rx_ns": 42898495446900, "frame": {"channel":"book","type":"update","data":[{"symbol":"BTC/USD","bids":[],"asks":[{"price":62807.9,"qty":1.79195972}],"checksum":3662060326,"timestamp":"2026-08-16T23:37:13.117028Z"}]}}
{"rx_ns": 42898495478400, "frame": {"channel":"book","type":"update","data":[{"symbol":"BTC/USD","bids":[],"asks":[{"price":62802.6,"qty":0.11100000}],"checksum":3946368491,"timestamp":"2026-08-16T23:37:13.118066Z"}]}}
{"rx_ns": 42898498689100, "frame": {"channel":"book","type":"update","data":[{"symbol":"BTC/USD","bids":[],"asks":[{"price":62807.0,"qty":0.00000000},{"price":62816.2,"qty":0.00005100},{"price":62810.1,"qty":0.18489680}],"checksum":3946368491,"timestamp":"2026-08-16T23:37:13.119791Z"}]}}
{"rx_ns": 42898498729200, "frame": {"channel":"book","type":"update","data":[{"symbol":"BTC/USD","bids":[],"asks":[{"price":62802.6,"qty":0.00100000}],"checksum":2071172721,"timestamp":"2026-08-16T23:37:13.119912Z"}]}}
{"rx_ns": 42898498740500, "frame": {"channel":"book","type":"update","data":[{"symbol":"BTC/USD","bids":[],"asks":[{"price":62802.6,"qty":3.79160819}],"checksum":504708799,"timestamp":"2026-08-16T23:37:13.122343Z"}]}}
{"rx_ns": 42898521063300, "frame": {"channel":"book","type":"update","data":[{"symbol":"BTC/USD","bids":[],"asks":[{"price":62797.0,"qty":0.46857247}],"checksum":3515650208,"timestamp":"2026-08-16T23:37:13.146148Z"}]}}
{"rx_ns": 42898527014900, "frame": {"channel":"book","type":"update","data":[{"symbol":"BTC/USD","bids":[],"asks":[{"price":62810.1,"qty":0.00000000},{"price":62816.2,"qty":0.00005100},{"price":62807.0,"qty":0.18489680}],"checksum":3515650208,"timestamp":"2026-08-16T23:37:13.147272Z"}]}}
{"rx_ns": 42898527203300, "frame": {"channel":"book","type":"update","data":[{"symbol":"BTC/USD","bids":[],"asks":[{"price":62797.0,"qty":0.57857247}],"checksum":1294644508,"timestamp":"2026-08-16T23:37:13.148288Z"}]}}
{"rx_ns": 42898529961100, "frame": {"channel":"book","type":"update","data":[{"symbol":"BTC/USD","bids":[],"asks":[{"price":62802.6,"qty":3.79060819}],"checksum":2791466827,"timestamp":"2026-08-16T23:37:13.154832Z"}]}}
{"rx_ns": 42898551635900, "frame": {"channel":"book","type":"update","data":[{"symbol":"BTC/USD","bids":[],"asks":[{"price":62797.6,"qty":0.86705321}],"checksum":3480597428,"timestamp":"2026-08-16T23:37:13.174371Z"}]}}
{"rx_ns": 42898553513900, "frame": {"channel":"book","type":"update","data":[{"symbol":"BTC/USD","bids":[],"asks":[{"price":62805.3,"qty":2.38833658}],"checksum":3480597428,"timestamp":"2026-08-16T23:37:13.174702Z"}]}}
{"rx_ns": 42898553546300, "frame": {"channel":"book","type":"update","data":[{"symbol":"BTC/USD","bids":[{"price":62786.0,"qty":0.79635491}],"asks":[],"checksum":100781553,"timestamp":"2026-08-16T23:37:13.174985Z"}]}}
{"rx_ns": 42898553556400, "frame": {"channel":"book","type":"update","data":[{"symbol":"BTC/USD","bids":[{"price":62783.8,"qty":0.79638273}],"asks":[],"checksum":658555657,"timestamp":"2026-08-16T23:37:13.175392Z"}]}}
{"rx_ns": 42898553563400, "frame": {"channel":"book","type":"update","data":[{"symbol":"BTC/USD","bids":[{"price":62778.0,"qty":0.80483233}],"asks":[],"checksum":658555657,"timestamp":"2026-08-16T23:37:13.175594Z"}]}}
{"rx_ns": 42898553570900, "frame": {"channel":"book","type":"update","data":[{"symbol":"BTC/USD","bids":[],"asks":[{"price":62807.0,"qty":0.00000000},{"price":62815.7,"qty":0.10331161},{"price":62805.5,"qty":0.18489680}],"checksum":658555657,"timestamp":"2026-08-16T23:37:13.175695Z"}]}}
{"rx_ns": 42898569093000, "frame": {"channel":"book","type":"update","data":[{"symbol":"BTC/USD","bids":[],"asks":[{"price":62807.9,"qty":0.19620257}],"checksum":658555657,"timestamp":"2026-08-16T23:37:13.190083Z"}]}}
{"rx_ns": 42898569172000, "frame": {"channel":"book","type":"update","data":[{"symbol":"BTC/USD","bids":[],"asks":[{"price":62800.7,"qty":0.18123904},{"price":62797.0,"qty":0.63455719}],"checksum":1149516300,"timestamp":"2026-08-16T23:37:13.191332Z"}]}}
{"rx_ns": 42898569201600, "frame": {"channel":"book","type":"update","data":[{"symbol":"BTC/USD","bids":[],"asks":[{"price":62802.6,"qty":0.00000000},{"price":62815.7,"qty":0.10331161},{"price":62797.1,"qty":4.85884670}],"checksum":758797259,"timestamp":"2026-08-16T23:37:13.193019Z"}]}}
{"rx_ns": 42898571254200, "frame": {"channel":"book","type":"update","data":[{"symbol":"BTC/USD","bids":[{"price":62778.0,"qty":0.83668569}],"asks":[],"checksum":758797259,"timestamp":"2026-08-16T23:37:13.195664Z"}]}}
{"rx_ns": 42898571309400, "frame": {"channel":"book","type":"update","data":[{"symbol":"BTC/USD","bids":[],"asks":[{"price":62805.5,"qty":0.00000000},{"price":62816.2,"qty":0.00005100},{"price":62805.2,"qty":0.18489680}],"checksum":2774269819,"timestamp":"2026-08-16T23:37:13.196822Z"}]}}
{"rx_ns": 42898589151200, "frame": {"channel":"book","type":"update","data":[{"symbol":"BTC/USD","bids":[{"price":62783.9,"qty":0.00000000},{"price":62772.6,"qty":0.06960000}],"asks":[],"checksum":2944484608,"timestamp":"2026-08-16T23:37:13.214943Z"}]}}
{"rx_ns": 42898592008900, "frame": {"channel":"book","type":"update","data":[{"symbol":"BTC/USD","bids":[],"asks":[{"price":62800.7,"qty":0.11039808}],"checksum":450625269,"timestamp":"2026-08-16T23:37:13.217429Z"}]}}
{"rx_ns": 42898608227800, "frame": {"channel":"book","type":"update","data":[{"symbol":"BTC/USD","bids":[],"asks":[{"price":62797.6,"qty":0.79620877}],"checksum":2106818657,"timestamp":"2026-08-16T23:37:13.232920Z"}]}}
{"rx_ns": 42898608274900, "frame": {"channel":"book","type":"update","data":[{"symbol":"BTC/USD","bids":[],"asks":[{"price":62797.1,"qty":4.78800170}],"checksum":1046123224,"timestamp":"2026-08-16T23:37:13.233010Z"}]}}
{"rx_ns": 42898622182100, "frame": {"channel":"book","type":"update","data":[{"symbol":"BTC/USD","bids":[{"price":62783.2,"qty":0.15923399}],"asks":[],"checksum":1046123224,"timestamp":"2026-08-16T23:37:13.246225Z"}]}}
{"rx_ns": 42898623870300, "frame": {"channel":"book","type":"update","data":[{"symbol":"BTC/USD","bids":[],"asks":[{"price":62813.1,"qty":0.00000000},{"price":62818.7,"qty":1.59798224}],"checksum":1046123224,"timestamp":"2026-08-16T23:37:13.247280Z"}]}}
{"rx_ns": 42898623892600, "frame": {"channel":"book","type":"update","data":[{"symbol":"BTC/USD","bids":[{"price":62788.0,"qty":0.00005100}],"asks":[],"checksum":143167616,"timestamp":"2026-08-16T23:37:13.247452Z"}]}}
{"rx_ns": 42898625603600, "frame": {"channel":"book","type":"update","data":[{"symbol":"BTC/USD","bids":[],"asks":[{"price":62800.7,"qty":0.00039808}],"checksum":1755017823,"timestamp":"2026-08-16T23:37:13.250355Z"}]}}
{"rx_ns": 42898633065700, "frame": {"channel":"book","type":"update","data":[{"symbol":"BTC/USD","bids":[],"asks":[{"price":62797.1,"qty":0.99736660},{"price":62797.0,"qty":4.42520746}],"checksum":1894782819,"timestamp":"2026-08-16T23:37:13.257115Z"}]}}
{"rx_ns": 42898643445400, "frame": {"channel":"book","type":"update","data":[{"symbol":"BTC/USD","bids":[{"price":62786.0,"qty":0.00000000},{"price":62772.7,"qty":0.00796524}],"asks":[],"checksum":2973694444,"timestamp":"2026-08-16T23:37:13.266070Z"}]}}
{"rx_ns": 42898646132000, "frame": {"channel":"book","type":"update","data":[{"symbol":"BTC/USD","bids":[],"asks":[{"price":62803.9,"qty":0.63289635}],"checksum":2336368610,"timestamp":"2026-08-16T23:37:13.268214Z"}]}}
{"rx_ns": 42898646169900, "frame": {"channel":"book","type":"update","data":[{"symbol":"BTC/USD","bids":[],"asks":[{"price":62810.2,"qty":0.00000000},{"price":62818.8,"qty":1.96622134}],"checksum":2336368610,"timestamp":"2026-08-16T23:37:13.268359Z"}]}}
{"rx_ns": 42898648022900, "frame": {"channel":"book","type":"update","data":[{"symbol":"BTC/USD","bids":[{"price":62775.0,"qty":0.23769319}],"asks":[],"checksum":2336368610,"timestamp":"2026-08-16T23:37:13.272859Z"}]}}
{"rx_ns": 42898654649200, "frame": {"channel":"book","type":"update","data":[{"symbol":"BTC/USD","bids":[{"price":62786.3,"qty":0.00000000},{"price":62772.7,"qty":0.00796524}],"asks":[],"checksum":2020945883,"timestamp":"2026-08-16T23:37:13.279379Z"}]}}
{"rx_ns": 42898685788400, "frame": {"channel":"book","type":"update","data":[{"symbol":"BTC/USD","bids":[{"price":62796.9,"qty":0.02177770}],"asks":[],"checksum":892994901,"timestamp":"2026-08-16T23:37:13.310230Z"}]}}
{"rx_ns": 42898709768300, "frame": {"channel":"book","type":"update","data":[{"symbol":"BTC/USD","bids":[{"price":62783.2,"qty":0.00000000},{"price":62772.6,"qty":0.06960000}],"asks":[],"checksum":2410232346,"timestamp":"2026-08-16T23:37:13.334929Z"}]}}
{"rx_ns": 42898721159100, "frame": {"channel":"book","type":"update","data":[{"symbol":"BTC/USD","bids":[{"price":62782.3,"qty":0.15923399}],"asks":[],"checksum":3447945768,"timestamp":"2026-08-16T23:37:13.346482Z"}]}}
{"rx_ns": 42898724454900, "frame": {"channel":"book","type":"update","data":[{"symbol":"BTC/USD","bids":[],"asks":[{"price":62807.9,"qty":0.00000000},{"price":62819.0,"qty":7.95938166}],"checksum":3447945768,"timestamp":"2026-08-16T23:37:13.346613Z"}]}}
{"rx_ns": 42898725903800, "frame": {"channel":"book","type":"update","data":[{"symbol":"BTC/USD","bids":[],"asks":[{"price":62818.7,"qty":0.00222509}],"checksum":3447945768,"timestamp":"2026-08-16T23:37:13.347776Z"}]}}
{"rx_ns": 42898731862100, "frame": {"channel":"book","type":"update","data":[{"symbol":"BTC/USD","bids":[],"asks":[{"price":62807.4,"qty":0.00000000},{"price":62820.9,"qty":0.02865288}],"checksum":3447945768,"timestamp":"2026-08-16T23:37:13.356843Z"}]}}
{"rx_ns": 42898745331700, "frame": {"channel":"heartbeat"}}
{"rx_ns": 42898745389600, "frame": {"channel":"book","type":"update","data":[{"symbol":"BTC/USD","bids":[],"asks":[{"price":62800.8,"qty":0.50922800}],"checksum":3890578034,"timestamp":"2026-08-16T23:37:13.357957Z"}]}}
{"rx_ns": 42898754053600, "frame": {"channel":"book","type":"update","data":[{"symbol":"BTC/USD","bids":[],"asks":[{"price":62814.6,"qty":0.01598519}],"checksum":3890578034,"timestamp":"2026-08-16T23:37:13.365520Z"}]}}
{"rx_ns": 42898757141100, "frame": {"channel":"book","type":"update","data":[{"symbol":"BTC/USD","bids":[{"price":62783.8,"qty":0.00000000},{"price":62772.6,"qty":0.06960000}],"asks":[],"checksum":2647680867,"timestamp":"2026-08-16T23:37:13.379660Z"}]}}
{"rx_ns": 42898757182900, "frame": {"channel":"book","type":"update","data":[{"symbol":"BTC/USD","bids":[],"asks":[{"price":62800.6,"qty":0.79617073}],"checksum":2684872005,"timestamp":"2026-08-16T23:37:13.381024Z"}]}}
{"rx_ns": 42898757197000, "frame": {"channel":"book","type":"update","data":[{"symbol":"BTC/USD","bids":[{"price":62785.2,"qty":0.79636550}],"asks":[],"checksum":549165233,"timestamp":"2026-08-16T23:37:13.381265Z"}]}}
{"rx_ns": 42898760395400, "frame": {"channel":"book","type":"update","data":[{"symbol":"BTC/USD","bids":[],"asks":[{"price":62805.2,"qty":0.00000000},{"price":62818.8,"qty":1.96622134},{"price":62803.2,"qty":0.18489680}],"checksum":941186462,"timestamp":"2026-08-16T23:37:13.382255Z"}]}}
{"rx_ns": 42898768920200, "frame": {"channel":"book","type":"update","data":[{"symbol":"BTC/USD","bids":[{"price":62796.9,"qty":0.00039811}],"asks":[],"checksum":2766704233,"timestamp":"2026-08-16T23:37:13.394510Z"}]}}
{"rx_ns": 42898773058100, "frame": {"channel":"book","type":"update","data":[{"symbol":"BTC/USD","bids":[{"price":62796.0,"qty":0.02137959}],"asks":[],"checksum":2736933280,"timestamp":"2026-08-16T23:37:13.395771Z"}]}}
{"rx_ns": 42898773125000, "frame": {"channel":"book","type":"update","data":[{"symbol":"BTC/USD","bids":[{"price":62775.0,"qty":0.00000000},{"price":62772.7,"qty":0.00796524}],"asks":[],"checksum":2736933280,"timestamp":"2026-08-16T23:37:13.396500Z"}]}}
{"rx_ns": 42898773146300, "frame": {"channel":"book","type":"update","data":[{"symbol":"BTC/USD","bids":[],"asks":[{"price":62797.0,"qty":4.44784873}],"checksum":57790229,"timestamp":"2026-08-16T23:37:13.397118Z"}]}}
{"rx_ns": 42898814478500, "frame": {"channel":"book","type":"update","data":[{"symbol":"BTC/USD","bids":[{"price":62789.9,"qty":0.00000000},{"price":62772.6,"qty":0.06960000}],"asks":[],"checksum":3863301526,"timestamp":"2026-08-16T23:37:13.438431Z"}]}}
{"rx_ns": 42898825192400, "frame": {"channel":"book","type":"update","data":[{"symbol":"BTC/USD","bids":[{"price":62785.2,"qty":0.00000000},{"price":62771.8,"qty":0.00080000}],"asks":[],"checksum":1376481407,"timestamp":"2026-08-16T23:37:13.450539Z"}]}}
{"rx_ns": 42898828915700, "frame": {"channel":"book","type":"update","data":[{"symbol":"BTC/USD","bids":[],"asks":[{"price":62818.7,"qty":1.59798224}],"checksum":1376481407,"timestamp":"2026-08-16T23:37:13.451642Z"}]}}
{"rx_ns": 42898828953300, "frame": {"channel":"book","type":"update","data":[{"symbol":"BTC/USD","bids":[{"price":62782.3,"qty":0.00000000},{"price":62771.5,"qty":0.13109402}],"asks":[],"checksum":431058180,"timestamp":"2026-08-16T23:37:13.451659Z"}]}}
{"rx_ns": 42898828971800, "frame": {"channel":"book","type":"update","data":[{"symbol":"BTC/USD","bids":[{"price":62780.7,"qty":0.00000000},{"price":62771.4,"qty":0.00039827}],"asks":[],"checksum":235013936,"timestamp":"2026-08-16T23:37:13.451834Z"}]}}
{"rx_ns": 42898830540400, "frame": {"channel":"book","type":"update","data":[{"symbol":"BTC/USD","bids":[{"price":62783.3,"qty":0.00000000},{"price":62771.3,"qty":2.38962605}],"asks":[],"checksum":1524074089,"timestamp":"2026-08-16T23:37:13.453382Z"}]}}
{"rx_ns": 42898830579900, "frame": {"channel":"book","type":"update","data":[{"symbol":"BTC/USD","bids":[],"asks":[{"price":62803.2,"qty":0.00000000},{"price":62818.8,"qty":1.96622134},{"price":62800.5,"qty":0.18489680}],"checksum":739533287,"timestamp":"2026-08-16T23:37:13.453655Z"}]}}
{"rx_ns": 42898834093300, "frame": {"channel":"book","type":"update","data":[{"symbol":"BTC/USD","bids":[],"asks":[{"price":62818.7,"qty":0.00222509},{"price":62807.3,"qty":1.59575715}],"checksum":739533287,"timestamp":"2026-08-16T23:37:13.457311Z"}]}}
{"rx_ns": 42898834125000, "frame": {"channel":"book","type":"update","data":[{"symbol":"BTC/USD","bids":[],"asks":[{"price":62805.1,"qty":0.19620257}],"checksum":739533287,"timestamp":"2026-08-16T23:37:13.457872Z"}]}}
{"rx_ns": 42898834237600, "frame": {"channel":"book","type":"update","data":[{"symbol":"BTC/USD","bids":[{"price":62796.9,"qty":0.00000000},{"price":62770.7,"qty":0.00455372}],"asks":[],"checksum":1042280290,"timestamp":"2026-08-16T23:37:13.458991Z"}]}}
{"rx_ns": 42898837883900, "frame": {"channel":"book","type":"update","data":[{"symbol":"BTC/USD","bids":[],"asks":[{"price":62796.9,"qty":0.11000000}],"checksum":684315505,"timestamp":"2026-08-16T23:37:13.459906Z"}]}}
{"rx_ns": 42898837922500, "frame": {"channel":"book","type":"update","data":[{"symbol":"BTC/USD","bids":[],"asks":[{"price":62796.1,"qty":0.06960000}],"checksum":2315581737,"timestamp":"2026-08-16T23:37:13.460980Z"}]}}
{"rx_ns": 42898837935700, "frame": {"channel":"book","type":"update","data":[{"symbol":"BTC/USD","bids":[],"asks":[{"price":62797.0,"qty":4.39186401},{"price":62796.9,"qty":0.16598472}],"checksum":1036017090,"timestamp":"2026-08-16T23:37:13.461395Z"}]}}
{"rx_ns": 42898837947900, "frame": {"channel":"book","type":"update","data":[{"symbol":"BTC/USD","bids":[],"asks":[{"price":62797.6,"qty":0.00000000},{"price":62814.6,"qty":0.01598519}],"checksum":1862507838,"timestamp":"2026-08-16T23:37:13.461460Z"}]}}
{"rx_ns": 42898840825300, "frame": {"channel":"book","type":"update","data":[{"symbol":"BTC/USD","bids":[],"asks":[{"price":62797.0,"qty":4.36922274}],"checksum":2302058582,"timestamp":"2026-08-16T23:37:13.461492Z"}]}}
{"rx_ns": 42898840852900, "frame": {"channel":"book","type":"update","data":[{"symbol":"BTC/USD","bids":[{"price":62776.8,"qty":0.75871873}],"asks":[],"checksum":2302058582,"timestamp":"2026-08-16T23:37:13.461616Z"}]}}
{"rx_ns": 42898840865100, "frame": {"channel":"book","type":"update","data":[{"symbol":"BTC/USD","bids":[],"asks":[{"price":62800.6,"qty":0.00000000},{"price":62815.6,"qty":0.18701894}],"checksum":4111384582,"timestamp":"2026-08-16T23:37:13.461698Z"}]}}
{"rx_ns": 42898840877600, "frame": {"channel":"book","type":"update","data":[{"symbol":"BTC/USD","bids":[],"asks":[{"price":62797.0,"qty":4.28962274}],"checksum":1667611176,"timestamp":"2026-08-16T23:37:13.461816Z"}]}}
{"rx_ns": 42898840887700, "frame": {"channel":"book","type":"update","data":[{"symbol":"BTC/USD","bids":[],"asks":[{"price":62796.9,"qty":0.24558472}],"checksum":3163067179,"timestamp":"2026-08-16T23:37:13.462033Z"}]}}
{"rx_ns": 42898840897900, "frame": {"channel":"book","type":"update","data":[{"symbol":"BTC/USD","bids":[],"asks":[{"price":62797.0,"qty":4.27797059}],"checksum":2675249811,"timestamp":"2026-08-16T23:37:13.462354Z"}]}}
{"rx_ns": 42898840908400, "frame": {"channel":"book","type":"update","data":[{"symbol":"BTC/USD","bids":[],"asks":[{"price":62797.0,"qty":4.27789759}],"checksum":1022966283,"timestamp":"2026-08-16T23:37:13.462365Z"}]}}
{"rx_ns": 42898840918600, "frame": {"channel":"book","type":"update","data":[{"symbol":"BTC/USD","bids":[],"asks":[{"price":62796.9,"qty":0.32358472}],"checksum":3885899048,"timestamp":"2026-08-16T23:37:13.462445Z"}]}}
{"rx_ns": 42898840928500, "frame": {"channel":"book","type":"update","data":[{"symbol":"BTC/USD","bids":[],"asks":[{"price":62797.0,"qty":4.19989759}],"checksum":898682576,"timestamp":"2026-08-16T23:37:13.462469Z"}]}}
{"rx_ns": 42898840945700, "frame": {"channel":"book","type":"update","data":[{"symbol":"BTC/USD","bids":[{"price":62796.0,"qty":0.00000000},{"price":62770.0,"qty":0.39276310}],"asks":[],"checksum":4073369100,"timestamp":"2026-08-16T23:37:13.462645Z"}]}}
{"rx_ns": 42898840957000, "frame": {"channel":"book","type":"update","data":[{"symbol":"BTC/USD","bids":[],"asks":[{"price":62796.9,"qty":0.24398472}],"checksum":1898895313,"timestamp":"2026-08-16T23:37:13.462677Z"}]}}
{"rx_ns": 42898840966400, "frame": {"channel":"book","type":"update","data":[{"symbol":"BTC/USD","bids":[],"asks":[{"price":62796.1,"qty":0.14920000}],"checksum":3318805193,"timestamp":"2026-08-16T23:37:13.462794Z"}]}}
{"rx_ns": 42898840975600, "frame": {"channel":"book","type":"update","data":[{"symbol":"BTC/USD","bids":[],"asks":[{"price":62797.0,"qty":4.13029759}],"checksum":1121346064,"timestamp":"2026-08-16T23:37:13.462820Z"}]}}
{"rx_ns": 42898840984900, "frame": {"channel":"book","type":"update","data":[{"symbol":"BTC/USD","bids":[],"asks":[{"price":62798.0,"qty":0.00513547}],"checksum":878264134,"timestamp":"2026-08-16T23:37:13.463345Z"}]}}
{"rx_ns": 42898840996100, "frame": {"channel":"book","type":"update","data":[{"symbol":"BTC/USD","bids":[],"asks":[{"price":62797.0,"qty":4.05988426}],"checksum":2356068417,"timestamp":"2026-08-16T23:37:13.463475Z"}]}}
{"rx_ns": 42898841005300, "frame": {"channel":"book","type":"update","data":[{"symbol":"BTC/USD","bids":[],"asks":[{"price":62796.1,"qty":0.94542779}],"checksum":1759713999,"timestamp":"2026-08-16T23:37:13.463545Z"}]}}
{"rx_ns": 42898841014200, "frame": {"channel":"book","type":"update","data":[{"symbol":"BTC/USD","bids":[],"asks":[{"price":62796.9,"qty":0.16598472}],"checksum":1536495352,"timestamp":"2026-08-16T23:37:13.463625Z"}]}}
{"rx_ns": 42898841023500, "frame": {"channel":"book","type":"update","data":[{"symbol":"BTC/USD","bids":[{"price":62794.7,"qty":0.02137959}],"asks":[],"checksum":3350735210,"timestamp":"2026-08-16T23:37:13.463765Z"}]}}
{"rx_ns": 42898841033000, "frame": {"channel":"book","type":"update","data":[{"symbol":"BTC/USD","bids":[],"asks":[{"price":62796.1,"qty":1.02342779}],"checksum":3674350646,"timestamp":"2026-08-16T23:37:13.463788Z"}]}}
{"rx_ns": 42898842889700, "frame": {"channel":"book","type":"update","data":[{"symbol":"BTC/USD","bids":[],"asks":[{"price":62798.7,"qty":0.00000000},{"price":62815.6,"qty":0.18701894}],"checksum":1855476045,"timestamp":"2026-08-16T23:37:13.464269Z"}]}}
{"rx_ns": 42898842936400, "frame": {"channel":"book","type":"update","data":[{"symbol":"BTC/USD","bids":[],"asks":[{"price":62797.1,"qty":0.34195948}],"checksum":106192259,"timestamp":"2026-08-16T23:37:13.464423Z"}]}}
{"rx_ns": 42898842949200, "frame": {"channel":"book","type":"update","data":[{"symbol":"BTC/USD","bids":[{"price":62794.3,"qty":0.00000000},{"price":62770.0,"qty":0.39276310}],"asks":[],"checksum":511134499,"timestamp":"2026-08-16T23:37:13.465188Z"}]}}
{"rx_ns": 42898842960400, "frame": {"channel":"book","type":"update","data":[{"symbol":"BTC/USD","bids":[],"asks":[{"price":62796.1,"qty":1.09399949}],"checksum":3766052222,"timestamp":"2026-08-16T23:37:13.466088Z"}]}}
{"rx_ns": 42898842970300, "frame": {"channel":"book","type":"update","data":[{"symbol":"BTC/USD","bids":[],"asks":[{"price":62796.1,"qty":0.29777170}],"checksum":2386186471,"timestamp":"2026-08-16T23:37:13.466273Z"}]}}
{"rx_ns": 42898847530000, "frame": {"channel":"book","type":"update","data":[{"symbol":"BTC/USD","bids":[{"price":62794.7,"qty":0.02117959}],"asks":[],"checksum":2366283063,"timestamp":"2026-08-16T23:37:13.467505Z"}]}}
{"rx_ns": 42898847573700, "frame": {"channel":"book","type":"update","data":[{"symbol":"BTC/USD","bids":[],"asks":[{"price":62796.1,"qty":0.22817170}],"checksum":906474757,"timestamp":"2026-08-16T23:37:13.467746Z"}]}}
{"rx_ns": 42898851349700, "frame": {"channel":"book","type":"update","data":[{"symbol":"BTC/USD","bids":[],"asks":[{"price":62807.3,"qty":0.00000000},{"price":62815.7,"qty":0.10331161}],"checksum":906474757,"timestamp":"2026-08-16T23:37:13.470208Z"}]}}
{"rx_ns": 42898851439500, "frame": {"channel":"book","type":"update","data":[{"symbol":"BTC/USD","bids":[],"asks":[{"price":62794.8,"qty":0.01185247}],"checksum":3404885841,"timestamp":"2026-08-16T23:37:13.471768Z"}]}}
{"rx_ns": 42898851476600, "frame": {"channel":"book","type":"update","data":[{"symbol":"BTC/USD","bids":[],"asks":[{"price":62794.8,"qty":0.08145247}],"checksum":3960111225,"timestamp":"2026-08-16T23:37:13.472960Z"}]}}
{"rx_ns": 42898851490100, "frame": {"channel":"book","type":"update","data":[{"symbol":"BTC/USD","bids":[],"asks":[{"price":62794.8,"qty":0.16105247}],"checksum":167885924,"timestamp":"2026-08-16T23:37:13.473268Z"}]}}
{"rx_ns": 42898851503200, "frame": {"channel":"book","type":"update","data":[{"symbol":"BTC/USD","bids":[],"asks":[{"price":62796.1,"qty":0.14857170}],"checksum":1757391303,"timestamp":"2026-08-16T23:37:13.473281Z"}]}}
{"rx_ns": 42898851514200, "frame": {"channel":"book","type":"update","data":[{"symbol":"BTC/USD","bids":[],"asks":[{"price":62794.8,"qty":0.23905247}],"checksum":3612973972,"timestamp":"2026-08-16T23:37:13.473401Z"}]}}
{"rx_ns": 42898851525000, "frame": {"channel":"book","type":"update","data":[{"symbol":"BTC/USD","bids":[],"asks":[{"price":62796.1,"qty":0.07057170}],"checksum":1714635624,"timestamp":"2026-08-16T23:37:13.473488Z"}]}}
{"rx_ns": 42898851536300, "frame": {"channel":"book","type":"update","data":[{"symbol":"BTC/USD","bids":[],"asks":[{"price":62800.5,"qty":0.00000000},{"price":62815.7,"qty":0.10331161},{"price":62805.0,"qty":0.18489680}],"checksum":1729045999,"timestamp":"2026-08-16T23:37:13.474135Z"}]}}
{"rx_ns": 42898853388500, "frame": {"channel":"book","type":"update","data":[{"symbol":"BTC/USD","bids":[],"asks":[{"price":62802.0,"qty":0.00318462}],"checksum":1856495559,"timestamp":"2026-08-16T23:37:13.474914Z"}]}}
{"rx_ns": 42898871376600, "frame": {"channel":"book","type":"update","data":[{"symbol":"BTC/USD","bids":[{"price":62780.0,"qty":0.16442373}],"asks":[],"checksum":3114252206,"timestamp":"2026-08-16T23:37:13.496220Z"}]}}
{"rx_ns": 42898871422500, "frame": {"channel":"book","type":"update","data":[{"symbol":"BTC/USD","bids":[],"asks":[{"price":62797.0,"qty":3.90065027}],"checksum":4202515596,"timestamp":"2026-08-16T23:37:13.496353Z"}]}}
{"rx_ns": 42898876690800, "frame": {"channel":"book","type":"update","data":[{"symbol":"BTC/USD","bids":[{"price":62775.5,"qty":0.00829935}],"asks":[],"checksum":4202515596,"timestamp":"2026-08-16T23:37:13.502322Z"}]}}
{"rx_ns": 42898910706200, "frame": {"channel":"book","type":"update","data":[{"symbol":"BTC/USD","bids":[],"asks":[{"price":62794.8,"qty":0.39828646}],"checksum":4106524555,"timestamp":"2026-08-16T23:37:13.535184Z"}]}}
{"rx_ns": 42898919578500, "frame": {"channel":"book","type":"update","data":[{"symbol":"BTC/USD","bids":[{"price":62778.0,"qty":0.80483233}],"asks":[],"checksum":2016943779,"timestamp":"2026-08-16T23:37:13.543280Z"}]}}
{"rx_ns": 42898933246600, "frame": {"channel":"book","type":"update","data":[{"symbol":"BTC/USD","bids":[{"price":62784.0,"qty":0.79638050}],"asks":[],"checksum":3931539391,"timestamp":"2026-08-16T23:37:13.559234Z"}]}}
{"rx_ns": 42898936711200, "frame": {"channel":"book","type":"update","data":[{"symbol":"BTC/USD","bids":[{"price":62781.3,"qty":0.79641481}],"asks":[],"checksum":4139273683,"timestamp":"2026-08-16T23:37:13.559433Z"}]}}
{"rx_ns": 42898936761300, "frame": {"channel":"book","type":"update","data":[{"symbol":"BTC/USD","bids":[],"asks":[{"price":62797.0,"qty":3.79065027}],"checksum":2113754527,"timestamp":"2026-08-16T23:37:13.560453Z"}]}}
{"rx_ns": 42898938417300, "frame": {"channel":"book","type":"update","data":[{"symbol":"BTC/USD","bids":[{"price":62782.1,"qty":0.06960000}],"asks":[],"checksum":789392036,"timestamp":"2026-08-16T23:37:13.562257Z"}]}}
{"rx_ns": 42898941680800, "frame": {"channel":"book","type":"update","data":[{"symbol":"BTC/USD","bids":[{"price":62794.7,"qty":0.02157772}],"asks":[],"checksum":2459854834,"timestamp":"2026-08-16T23:37:13.565470Z"}]}}
{"rx_ns": 42898948748500, "frame": {"channel":"book","type":"update","data":[{"symbol":"BTC/USD","bids":[],"asks":[{"price":62803.9,"qty":0.06000000}],"checksum":2459854834,"timestamp":"2026-08-16T23:37:13.571232Z"}]}}
{"rx_ns": 42898959320400, "frame": {"channel":"book","type":"update","data":[{"symbol":"BTC/USD","bids":[],"asks":[{"price":62814.6,"qty":0.00000000},{"price":62815.6,"qty":0.18701894}],"checksum":2459854834,"timestamp":"2026-08-16T23:37:13.583591Z"}]}}
{"rx_ns": 42898996663500, "frame": {"channel":"book","type":"update","data":[{"symbol":"BTC/USD","bids":[{"price":62794.7,"qty":0.02197585}],"asks":[],"checksum":3863698846,"timestamp":"2026-08-16T23:37:13.620716Z"}]}}
{"rx_ns": 42898996719600, "frame": {"channel":"book","type":"update","data":[{"symbol":"BTC/USD","bids":[],"asks":[{"price":62796.9,"qty":0.11000000},{"price":62796.0,"qty":0.05598472}],"checksum":1583906534,"timestamp":"2026-08-16T23:37:13.621890Z"}]}}
{"rx_ns": 42899002044800, "frame": {"channel":"book","type":"update","data":[{"symbol":"BTC/USD","bids":[],"asks":[{"price":62797.0,"qty":0.00000000},{"price":62815.6,"qty":0.18701894},{"price":62794.8,"qty":4.18901796}],"checksum":111484047,"timestamp":"2026-08-16T23:37:13.626585Z"}]}}
{"rx_ns": 42899018137400, "frame": {"channel":"book","type":"update","data":[{"symbol":"BTC/USD","bids":[{"price":62794.7,"qty":0.00079626}],"asks":[],"checksum":495752823,"timestamp":"2026-08-16T23:37:13.641453Z"}]}}
{"rx_ns": 42899019635700, "frame": {"channel":"book","type":"update","data":[{"symbol":"BTC/USD","bids":[{"price":62793.1,"qty":0.02131292}],"asks":[],"checksum":2435127186,"timestamp":"2026-08-16T23:37:13.644602Z"}]}}
{"rx_ns": 42899026733200, "frame": {"channel":"book","type":"update","data":[{"symbol":"BTC/USD","bids":[],"asks":[{"price":62794.8,"qty":4.84442508}],"checksum":854277363,"timestamp":"2026-08-16T23:37:13.650393Z"}]}}
{"rx_ns": 42899052201000, "frame": {"channel":"book","type":"update","data":[{"symbol":"BTC/USD","bids":[{"price":62794.7,"qty":0.00119439}],"asks":[],"checksum":2813080452,"timestamp":"2026-08-16T23:37:13.676685Z"}]}}
{"rx_ns": 42899052253700, "frame": {"channel":"book","type":"update","data":[{"symbol":"BTC/USD","bids":[],"asks":[{"price":62807.1,"qty":0.00000000},{"price":62815.7,"qty":0.10331161}],"checksum":2813080452,"timestamp":"2026-08-16T23:37:13.676744Z"}]}}
{"rx_ns": 42899054171300, "frame": {"channel":"book","type":"update","data":[{"symbol":"BTC/USD","bids":[],"asks":[{"price":62796.1,"qty":0.00000000},{"price":62818.7,"qty":1.59798224}],"checksum":3712950378,"timestamp":"2026-08-16T23:37:13.679942Z"}]}}
{"rx_ns": 42899055607800, "frame": {"channel":"book","type":"update","data":[{"symbol":"BTC/USD","bids":[],"asks":[{"price":62796.0,"qty":0.00000000},{"price":62818.8,"qty":1.96622134},{"price":62796.8,"qty":0.05598472}],"checksum":1322700297,"timestamp":"2026-08-16T23:37:13.681212Z"}]}}
{"rx_ns": 42899059501200, "frame": {"channel":"book","type":"update","data":[{"symbol":"BTC/USD","bids":[],"asks":[{"price":62806.0,"qty":0.00000000},{"price":62818.8,"qty":1.96622134}],"checksum":1322700297,"timestamp":"2026-08-16T23:37:13.684001Z"}]}}
{"rx_ns": 42899061123300, "frame": {"channel":"book","type":"update","data":[{"symbol":"BTC/USD","bids":[{"price":62780.0,"qty":0.00518974}],"asks":[],"checksum":1322700297,"timestamp":"2026-08-16T23:37:13.686504Z"}]}}
{"rx_ns": 42899089090700, "frame": {"channel":"book","type":"update","data":[{"symbol":"BTC/USD","bids":[{"price":62780.8,"qty":0.15923399}],"asks":[],"checksum":1322700297,"timestamp":"2026-08-16T23:37:13.696028Z"}]}}
{"rx_ns": 42899090619600, "frame": {"channel":"book","type":"update","data":[{"symbol":"BTC/USD","bids":[{"price":62780.8,"qty":0.00000000},{"price":62771.8,"qty":0.00080000}],"asks":[],"checksum":1322700297,"timestamp":"2026-08-16T23:37:13.710681Z"}]}}
{"rx_ns": 42899109378800, "frame": {"channel":"book","type":"update","data":[{"symbol":"BTC/USD","bids":[{"price":62794.7,"qty":0.00159252}],"asks":[],"checksum":3672878434,"timestamp":"2026-08-16T23:37:13.731911Z"}]}}
{"rx_ns": 42899114684100, "frame": {"channel":"book","type":"update","data":[{"symbol":"BTC/USD","bids":[],"asks":[{"price":62800.7,"qty":0.00000000},{"price":62819.0,"qty":7.95938166},{"price":62794.8,"qty":4.84482321}],"checksum":3278123104,"timestamp":"2026-08-16T23:37:13.739975Z"}]}}
{"rx_ns": 42899120494700, "frame": {"channel":"book","type":"update","data":[{"symbol":"BTC/USD","bids":[{"price":62779.7,"qty":0.15923399}],"asks":[],"checksum":3278123104,"timestamp":"2026-08-16T23:37:13.746031Z"}]}}
{"rx_ns": 42899132159100, "frame": {"channel":"book","type":"update","data":[{"symbol":"BTC/USD","bids":[{"price":62794.7,"qty":0.00119439}],"asks":[],"checksum":1465471755,"timestamp":"2026-08-16T23:37:13.756589Z"}]}}
{"rx_ns": 42899133906400, "frame": {"channel":"book","type":"update","data":[{"symbol":"BTC/USD","bids":[{"price":62794.7,"qty":0.01634490}],"asks":[],"checksum":405992136,"timestamp":"2026-08-16T23:37:13.757603Z"}]}}
{"rx_ns": 42899190945900, "frame": {"channel":"book","type":"update","data":[{"symbol":"BTC/USD","bids":[{"price":62794.7,"qty":0.01594677}],"asks":[],"checksum":3673217803,"timestamp":"2026-08-16T23:37:13.816573Z"}]}}
{"rx_ns": 42899210903100, "frame": {"channel":"book","type":"update","data":[{"symbol":"BTC/USD","bids":[{"price":62784.0,"qty":0.00000000},{"price":62771.8,"qty":0.00080000}],"asks":[],"checksum":30612623,"timestamp":"2026-08-16T23:37:13.834817Z"}]}}
{"rx_ns": 42899211781100, "frame": {"channel":"book","type":"update","data":[{"symbol":"BTC/USD","bids":[],"asks":[{"price":62794.8,"qty":5.64106748}],"checksum":1746669247,"timestamp":"2026-08-16T23:37:13.836517Z"}]}}
{"rx_ns": 42899213330600, "frame": {"channel":"book","type":"update","data":[{"symbol":"BTC/USD","bids":[],"asks":[{"price":62796.0,"qty":0.79622905}],"checksum":10078239,"timestamp":"2026-08-16T23:37:13.836833Z"}]}}
{"rx_ns": 42899213358600, "frame": {"channel":"book","type":"update","data":[{"symbol":"BTC/USD","bids":[{"price":62783.2,"qty":0.79639015}],"asks":[],"checksum":2264673763,"timestamp":"2026-08-16T23:37:13.837088Z"}]}}
{"rx_ns": 42899214900000, "frame": {"channel":"book","type":"update","data":[{"symbol":"BTC/USD","bids":[],"asks":[{"price":62794.8,"qty":5.66123042}],"checksum":2717124202,"timestamp":"2026-08-16T23:37:13.838243Z"}]}}
{"rx_ns": 42899214935900, "frame": {"channel":"book","type":"update","data":[{"symbol":"BTC/USD","bids":[],"asks":[{"price":62796.8,"qty":0.00000000},{"price":62819.0,"qty":7.95938166},{"price":62795.9,"qty":0.05598472}],"checksum":2863317049,"timestamp":"2026-08-16T23:37:13.838291Z"}]}}
{"rx_ns": 42899216368700, "frame": {"channel":"book","type":"update","data":[{"symbol":"BTC/USD","bids":[{"price":62794.3,"qty":0.00005100}],"asks":[],"checksum":3447956584,"timestamp":"2026-08-16T23:37:13.841308Z"}]}}
{"rx_ns": 42899250152800, "frame": {"channel":"book","type":"update","data":[{"symbol":"BTC/USD","bids":[{"price":62794.7,"qty":0.01554864}],"asks":[],"checksum":3133548343,"timestamp":"2026-08-16T23:37:13.875446Z"}]}}
{"rx_ns": 42899290109900, "frame": {"channel":"book","type":"update","data":[{"symbol":"BTC/USD","bids":[],"asks":[{"price":62796.1,"qty":0.46044544}],"checksum":1992868612,"timestamp":"2026-08-16T23:37:13.914384Z"}]}}
{"rx_ns": 42899410161300, "frame": {"channel":"book","type":"update","data":[{"symbol":"BTC/USD","bids":[{"price":62782.1,"qty":0.00000000},{"price":62772.6,"qty":0.06960000}],"asks":[],"checksum":2224799627,"timestamp":"2026-08-16T23:37:14.030312Z"}]}}
{"rx_ns": 42899440125000, "frame": {"channel":"book","type":"update","data":[{"symbol":"BTC/USD","bids":[{"price":62783.5,"qty":0.00015926}],"asks":[],"checksum":2565865318,"timestamp":"2026-08-16T23:37:14.065529Z"}]}}
{"rx_ns": 42899552597300, "frame": {"channel":"book","type":"update","data":[{"symbol":"BTC/USD","bids":[],"asks":[{"price":62796.9,"qty":0.90621764}],"checksum":2340148065,"timestamp":"2026-08-16T23:37:14.174120Z"}]}}
{"rx_ns": 42899552887500, "frame": {"channel":"book","type":"update","data":[{"symbol":"BTC/USD","bids":[],"asks":[{"price":62805.0,"qty":0.00000000},{"price":62818.8,"qty":1.96622134},{"price":62800.7,"qty":0.18489680}],"checksum":1790700499,"timestamp":"2026-08-16T23:37:14.175497Z"}]}}
{"rx_ns": 42899562584200, "frame": {"channel":"book","type":"update","data":[{"symbol":"BTC/USD","bids":[],"asks":[{"price":62801.4,"qty":0.36000000}],"checksum":369341209,"timestamp":"2026-08-16T23:37:14.185798Z"}]}}
{"rx_ns": 42899562653800, "frame": {"channel":"book","type":"update","data":[{"symbol":"BTC/USD","bids":[{"price":62780.2,"qty":0.10252886}],"asks":[],"checksum":369341209,"timestamp":"2026-08-16T23:37:14.187940Z"}]}}
{"rx_ns": 42899589176200, "frame": {"channel":"book","type":"update","data":[{"symbol":"BTC/USD","bids":[{"price":62779.7,"qty":0.00000000},{"price":62772.7,"qty":0.00796524}],"asks":[],"checksum":369341209,"timestamp":"2026-08-16T23:37:14.214692Z"}]}}
{"rx_ns": 42899601733900, "frame": {"channel":"book","type":"update","data":[{"symbol":"BTC/USD","bids":[],"asks":[{"price":62794.8,"qty":5.66223042}],"checksum":3341616031,"timestamp":"2026-08-16T23:37:14.227458Z"}]}}
{"rx_ns": 42899622534900, "frame": {"channel":"book","type":"update","data":[{"symbol":"BTC/USD","bids":[{"price":62779.8,"qty":0.15923399}],"asks":[],"checksum":3341616031,"timestamp":"2026-08-16T23:37:14.246469Z"}]}}
{"rx_ns": 42899722334200, "frame": {"channel":"book","type":"update","data":[{"symbol":"BTC/USD","bids":[],"asks":[{"price":62813.5,"qty":0.50000000}],"checksum":3341616031,"timestamp":"2026-08-16T23:37:14.345602Z"}]}}
{"rx_ns": 42899744448000, "frame": {"channel":"heartbeat"}}
{"rx_ns": 42899811672200, "frame": {"channel":"book","type":"update","data":[{"symbol":"BTC/USD","bids":[{"price":62784.9,"qty":0.00005100}],"asks":[],"checksum":1941947137,"timestamp":"2026-08-16T23:37:14.437357Z"}]}}
{"rx_ns": 42899837705700, "frame": {"channel":"book","type":"update","data":[{"symbol":"BTC/USD","bids":[{"price":62780.0,"qty":0.00000000},{"price":62772.7,"qty":0.00796524}],"asks":[],"checksum":1941947137,"timestamp":"2026-08-16T23:37:14.457621Z"}]}}
{"rx_ns": 42899837751600, "frame": {"channel":"book","type":"update","data":[{"symbol":"BTC/USD","bids":[{"price":62778.0,"qty":0.80164650}],"asks":[],"checksum":1941947137,"timestamp":"2026-08-16T23:37:14.457762Z"}]}}
{"rx_ns": 42899840852000, "frame": {"channel":"book","type":"update","data":[{"symbol":"BTC/USD","bids":[{"price":62791.3,"qty":0.00000000},{"price":62772.6,"qty":0.06960000}],"asks":[],"checksum":2533704444,"timestamp":"2026-08-16T23:37:14.464865Z"}]}}
{"rx_ns": 42899840874400, "frame": {"channel":"book","type":"update","data":[{"symbol":"BTC/USD","bids":[],"asks":[{"price":62810.9,"qty":7.96040350}],"checksum":2533704444,"timestamp":"2026-08-16T23:37:14.465171Z"}]}}
{"rx_ns": 42899842389600, "frame": {"channel":"book","type":"update","data":[{"symbol":"BTC/USD","bids":[{"price":62781.3,"qty":0.00000000},{"price":62772.0,"qty":0.00318614}],"asks":[],"checksum":3173549658,"timestamp":"2026-08-16T23:37:14.465592Z"}]}}
{"rx_ns": 42899842415300, "frame": {"channel":"book","type":"update","data":[{"symbol":"BTC/USD","bids":[{"price":62783.2,"qty":0.00000000},{"price":62771.8,"qty":0.00080000}],"asks":[],"checksum":1602837373,"timestamp":"2026-08-16T23:37:14.465732Z"}]}}
{"rx_ns": 42899842429800, "frame": {"channel":"book","type":"update","data":[{"symbol":"BTC/USD","bids":[{"price":62788.1,"qty":0.05598472}],"asks":[],"checksum":3032084499,"timestamp":"2026-08-16T23:37:14.465999Z"}]}}
{"rx_ns": 42899842440400, "frame": {"channel":"book","type":"update","data":[{"symbol":"BTC/USD","bids":[],"asks":[{"price":62795.9,"qty":0.00000000},{"price":62815.6,"qty":0.18701894},{"price":62794.8,"qty":5.71821514}],"checksum":1018442104,"timestamp":"2026-08-16T23:37:14.466073Z"}]}}
{"rx_ns": 42899842453200, "frame": {"channel":"book","type":"update","data":[{"symbol":"BTC/USD","bids":[{"price":62778.0,"qty":0.00518991}],"asks":[],"checksum":1018442104,"timestamp":"2026-08-16T23:37:14.466413Z"}]}}
{"rx_ns": 42899852195200, "frame": {"channel":"book","type":"update","data":[{"symbol":"BTC/USD","bids":[{"price":62781.6,"qty":0.79641109}],"asks":[],"checksum":3367639601,"timestamp":"2026-08-16T23:37:14.474890Z"}]}}
{"rx_ns": 42899852253500, "frame": {"channel":"book","type":"update","data":[{"symbol":"BTC/USD","bids":[{"price":62780.1,"qty":0.79642987}],"asks":[],"checksum":3367639601,"timestamp":"2026-08-16T23:37:14.475105Z"}]}}
{"rx_ns": 42899852266100, "frame": {"channel":"book","type":"update","data":[{"symbol":"BTC/USD","bids":[{"price":62775.3,"qty":0.79649059}],"asks":[],"checksum":3367639601,"timestamp":"2026-08-16T23:37:14.475127Z"}]}}
{"rx_ns": 42899865277000, "frame": {"channel":"book","type":"update","data":[{"symbol":"BTC/USD","bids":[{"price":62779.8,"qty":0.00000000},{"price":62772.7,"qty":0.00796524}],"asks":[],"checksum":3367639601,"timestamp":"2026-08-16T23:37:14.487480Z"}]}}
{"rx_ns": 42899871080800, "frame": {"channel":"book","type":"update","data":[{"symbol":"BTC/USD","bids":[{"price":62781.6,"qty":0.00000000},{"price":62772.6,"qty":0.06960000}],"asks":[],"checksum":1018442104,"timestamp":"2026-08-16T23:37:14.491767Z"}]}}
{"rx_ns": 42899874309800, "frame": {"channel":"book","type":"update","data":[{"symbol":"BTC/USD","bids":[{"price":62779.2,"qty":0.15927785}],"asks":[],"checksum":1018442104,"timestamp":"2026-08-16T23:37:14.495971Z"}]}}
{"rx_ns": 42899887335600, "frame": {"channel":"book","type":"update","data":[{"symbol":"BTC/USD","bids":[{"price":62780.1,"qty":0.00000000},{"price":62772.6,"qty":0.06960000}],"asks":[],"checksum":1018442104,"timestamp":"2026-08-16T23:37:14.511302Z"}]}}
{"rx_ns": 42899891679200, "frame": {"channel":"book","type":"update","data":[{"symbol":"BTC/USD","bids":[{"price":62779.5,"qty":0.00000000},{"price":62772.0,"qty":0.00318614}],"asks":[],"checksum":1018442104,"timestamp":"2026-08-16T23:37:14.513724Z"}]}}
{"rx_ns": 42899902676600, "frame": {"channel":"book","type":"update","data":[{"symbol":"BTC/USD","bids":[{"price":62794.7,"qty":0.02354864}],"asks":[],"checksum":1509198837,"timestamp":"2026-08-16T23:37:14.527268Z"}]}}
{"rx_ns": 42899940418700, "frame": {"channel":"book","type":"update","data":[{"symbol":"BTC/USD","bids":[{"price":62774.0,"qty":0.98138619}],"asks":[],"checksum":1509198837,"timestamp":"2026-08-16T23:37:14.565745Z"}]}}
{"rx_ns": 42899964762100, "frame": {"channel":"book","type":"update","data":[{"symbol":"BTC/USD","bids":[{"price":62779.2,"qty":0.00000000},{"price":62771.5,"qty":0.13109402}],"asks":[],"checksum":1509198837,"timestamp":"2026-08-16T23:37:14.583904Z"}]}}
{"rx_ns": 42899964840200, "frame": {"channel":"book","type":"update","data":[{"symbol":"BTC/USD","bids":[],"asks":[{"price":62794.8,"qty":5.82821514}],"checksum":3355188604,"timestamp":"2026-08-16T23:37:14.584606Z"}]}}
{"rx_ns": 42899964867400, "frame": {"channel":"book","type":"update","data":[{"symbol":"BTC/USD","bids":[{"price":62781.6,"qty":0.79641120}],"asks":[],"checksum":2227588130,"timestamp":"2026-08-16T23:37:14.586742Z"}]}}
{"rx_ns": 42899964881200, "frame": {"channel":"book","type":"update","data":[{"symbol":"BTC/USD","bids":[{"price":62787.4,"qty":0.00000000},{"price":62771.5,"qty":0.13109402},{"price":62785.3,"qty":0.00318620}],"asks":[],"checksum":3685692380,"timestamp":"2026-08-16T23:37:14.586887Z"}]}}
{"rx_ns": 42899964894900, "frame": {"channel":"book","type":"update","data":[{"symbol":"BTC/USD","bids":[],"asks":[{"price":62806.8,"qty":0.00005100},{"price":62804.8,"qty":0.00318620}],"checksum":3685692380,"timestamp":"2026-08-16T23:37:14.587188Z"}]}}
{"rx_ns": 42899966417200, "frame": {"channel":"book","type":"update","data":[{"symbol":"BTC/USD","bids":[],"asks":[{"price":62805.5,"qty":1.59575715}],"checksum":3685692380,"timestamp":"2026-08-16T23:37:14.590484Z"}]}}
{"rx_ns": 42899968305400, "frame": {"channel":"book","type":"update","data":[{"symbol":"BTC/USD","bids":[{"price":62785.9,"qty":0.00009500}],"asks":[],"checksum":2271829500,"timestamp":"2026-08-16T23:37:14.592494Z"}]}}
{"rx_ns": 42899973457700, "frame": {"channel":"book","type":"update","data":[{"symbol":"BTC/USD","bids":[],"asks":[{"price":62805.5,"qty":0.00000000},{"price":62813.5,"qty":0.50000000},{"price":62813.4,"qty":1.59575715}],"checksum":2271829500,"timestamp":"2026-08-16T23:37:14.595220Z"}]}}
{"rx_ns": 42899973524800, "frame": {"channel":"book","type":"update","data":[{"symbol":"BTC/USD","bids":[{"price":62778.6,"qty":0.15927785}],"asks":[],"checksum":2271829500,"timestamp":"2026-08-16T23:37:14.596240Z"}]}}
{"rx_ns": 42899974949600, "frame": {"channel":"book","type":"update","data":[{"symbol":"BTC/USD","bids":[{"price":62778.6,"qty":0.00000000},{"price":62772.6,"qty":0.06960000}],"asks":[],"checksum":2271829500,"timestamp":"2026-08-16T23:37:14.599194Z"}]}}
{"rx_ns": 42899990887300, "frame": {"channel":"book","type":"update","data":[{"symbol":"BTC/USD","bids":[{"price":62781.6,"qty":0.00000000},{"price":62772.0,"qty":0.00318614}],"asks":[],"checksum":2271829500,"timestamp":"2026-08-16T23:37:14.616567Z"}]}}
{"rx_ns": 42899991152300, "frame": {"channel":"book","type":"update","data":[{"symbol":"BTC/USD","bids":[{"price":62777.9,"qty":0.15927785}],"asks":[],"checksum":2271829500,"timestamp":"2026-08-16T23:37:14.617307Z"}]}}
{"rx_ns": 42900006256500, "frame": {"channel":"book","type":"update","data":[{"symbol":"BTC/USD","bids":[{"price":62781.2,"qty":0.00000000},{"price":62772.0,"qty":0.00318614}],"asks":[],"checksum":2271829500,"timestamp":"2026-08-16T23:37:14.630044Z"}]}}
{"rx_ns": 42900012696000, "frame": {"channel":"book","type":"update","data":[{"symbol":"BTC/USD","bids":[{"price":62793.1,"qty":0.00000000},{"price":62771.5,"qty":0.13109402}],"asks":[],"checksum":2258769787,"timestamp":"2026-08-16T23:37:14.633646Z"}]}}
{"rx_ns": 42900012758200, "frame": {"channel":"book","type":"update","data":[{"symbol":"BTC/USD","bids":[{"price":62774.0,"qty":0.74369300}],"asks":[],"checksum":2258769787,"timestamp":"2026-08-16T23:37:14.635225Z"}]}}
{"rx_ns": 42900019001800, "frame": {"channel":"book","type":"update","data":[{"symbol":"BTC/USD","bids":[{"price":62791.7,"qty":0.02131292}],"asks":[],"checksum":4005069483,"timestamp":"2026-08-16T23:37:14.636339Z"}]}}
{"rx_ns": 42900019081200, "frame": {"channel":"book","type":"update","data":[{"symbol":"BTC/USD","bids":[{"price":62774.0,"qty":0.98138619}],"asks":[],"checksum":4005069483,"timestamp":"2026-08-16T23:37:14.637742Z"}]}}
{"rx_ns": 42900026311400, "frame": {"channel":"book","type":"update","data":[{"symbol":"BTC/USD","bids":[],"asks":[{"price":62813.4,"qty":0.00000000},{"price":62813.5,"qty":0.50000000},{"price":62805.5,"qty":1.59575715}],"checksum":4005069483,"timestamp":"2026-08-16T23:37:14.651441Z"}]}}
{"rx_ns": 42900063443800, "frame": {"channel":"book","type":"update","data":[{"symbol":"BTC/USD","bids":[],"asks":[{"price":62796.9,"qty":0.79621764}],"checksum":1516177984,"timestamp":"2026-08-16T23:37:14.685621Z"}]}}
{"rx_ns": 42900075110200, "frame": {"channel":"book","type":"update","data":[{"symbol":"BTC/USD","bids":[{"price":62780.2,"qty":0.00000000},{"price":62771.5,"qty":0.13109402}],"asks":[],"checksum":1516177984,"timestamp":"2026-08-16T23:37:14.695525Z"}]}}
{"rx_ns": 42900077778900, "frame": {"channel":"book","type":"update","data":[{"symbol":"BTC/USD","bids":[],"asks":[{"price":62805.5,"qty":0.00000000},{"price":62813.5,"qty":0.50000000},{"price":62810.8,"qty":1.59575715}],"checksum":1516177984,"timestamp":"2026-08-16T23:37:14.698645Z"}]}}
{"rx_ns": 42900124530600, "frame": {"channel":"book","type":"update","data":[{"symbol":"BTC/USD","bids":[],"asks":[{"price":62808.0,"qty":0.00000000},{"price":62813.5,"qty":0.50000000}],"checksum":1516177984,"timestamp":"2026-08-16T23:37:14.749783Z"}]}}
{"rx_ns": 42900195263000, "frame": {"channel":"book","type":"update","data":[{"symbol":"BTC/USD","bids":[{"price":62779.8,"qty":0.79643385}],"asks":[],"checksum":1516177984,"timestamp":"2026-08-16T23:37:14.818407Z"}]}}
{"rx_ns": 42900290822100, "frame": {"channel":"book","type":"update","data":[{"symbol":"BTC/USD","bids":[{"price":62779.8,"qty":0.00000000},{"price":62771.5,"qty":0.13109402}],"asks":[],"checksum":1516177984,"timestamp":"2026-08-16T23:37:14.915753Z"}]}}
{"rx_ns": 42900292889700, "frame": {"channel":"book","type":"update","data":[{"symbol":"BTC/USD","bids":[{"price":62781.0,"qty":0.79641900}],"asks":[],"checksum":1516177984,"timestamp":"2026-08-16T23:37:14.917261Z"}]}}
{"rx_ns": 42900302505800, "frame": {"channel":"book","type":"update","data":[{"symbol":"BTC/USD","bids":[],"asks":[{"price":62805.1,"qty":0.00000000},{"price":62815.6,"qty":0.18701894},{"price":62800.6,"qty":0.19620257}],"checksum":2299750211,"timestamp":"2026-08-16T23:37:14.927024Z"}]}}
{"rx_ns": 42900303631000, "frame": {"channel":"book","type":"update","data":[{"symbol":"BTC/USD","bids":[],"asks":[{"price":62800.7,"qty":0.00000000},{"price":62815.6,"qty":0.18701894},{"price":62800.5,"qty":0.18489680}],"checksum":1064814256,"timestamp":"2026-08-16T23:37:14.928208Z"}]}}
{"rx_ns": 42900312631600, "frame": {"channel":"book","type":"update","data":[{"symbol":"BTC/USD","bids":[],"asks":[{"price":62800.5,"qty":0.18494780}],"checksum":120429725,"timestamp":"2026-08-16T23:37:14.937667Z"}]}}
{"rx_ns": 42900383210300, "frame": {"channel":"book","type":"update","data":[{"symbol":"BTC/USD","bids":[],"asks":[{"price":62809.7,"qty":0.02865799}],"checksum":120429725,"timestamp":"2026-08-16T23:37:15.006962Z"}]}}
{"rx_ns": 42900388507900, "frame": {"channel":"book","type":"update","data":[{"symbol":"BTC/USD","bids":[{"price":62777.9,"qty":0.00000000},{"price":62771.5,"qty":0.13109402}],"asks":[],"checksum":120429725,"timestamp":"2026-08-16T23:37:15.010744Z"}]}}
{"rx_ns": 42900392213600, "frame": {"channel":"book","type":"update","data":[{"symbol":"BTC/USD","bids":[{"price":62777.8,"qty":0.26927785}],"asks":[],"checksum":120429725,"timestamp":"2026-08-16T23:37:15.016908Z"}]}}
{"rx_ns": 42900393097300, "frame": {"channel":"book","type":"update","data":[{"symbol":"BTC/USD","bids":[{"price":62794.7,"qty":0.02364864}],"asks":[],"checksum":2532399212,"timestamp":"2026-08-16T23:37:15.017770Z"}]}}
{"rx_ns": 42900448255500, "frame": {"channel":"book","type":"update","data":[{"symbol":"BTC/USD","bids":[{"price":62791.7,"qty":0.00000000},{"price":62771.4,"qty":0.00039827}],"asks":[],"checksum":3206063212,"timestamp":"2026-08-16T23:37:15.074258Z"}]}}
{"rx_ns": 42900458024900, "frame": {"channel":"book","type":"update","data":[{"symbol":"BTC/USD","bids":[{"price":62792.6,"qty":0.02131292}],"asks":[],"checksum":557000923,"timestamp":"2026-08-16T23:37:15.074420Z"}]}}
{"rx_ns": 42900458078100, "frame": {"channel":"book","type":"update","data":[{"symbol":"BTC/USD","bids":[{"price":62774.0,"qty":0.74369300}],"asks":[],"checksum":557000923,"timestamp":"2026-08-16T23:37:15.074931Z"}]}}
{"rx_ns": 42900538122400, "frame": {"channel":"book","type":"update","data":[{"symbol":"BTC/USD","bids":[{"price":62771.7,"qty":0.07963975}],"asks":[],"checksum":557000923,"timestamp":"2026-08-16T23:37:15.162912Z"}]}}
{"rx_ns": 42900542423300, "frame": {"channel":"book","type":"update","data":[{"symbol":"BTC/USD","bids":[{"price":62772.3,"qty":0.03185589}],"asks":[],"checksum":557000923,"timestamp":"2026-08-16T23:37:15.166228Z"}]}}
{"rx_ns": 42900549868200, "frame": {"channel":"book","type":"update","data":[{"symbol":"BTC/USD","bids":[{"price":62781.0,"qty":0.00000000},{"price":62771.7,"qty":0.07963975}],"asks":[],"checksum":557000923,"timestamp":"2026-08-16T23:37:15.173645Z"}]}}
{"rx_ns": 42900551975600, "frame": {"channel":"book","type":"update","data":[{"symbol":"BTC/USD","bids":[{"price":62781.7,"qty":0.79640946}],"asks":[],"checksum":557000923,"timestamp":"2026-08-16T23:37:15.175631Z"}]}}
{"rx_ns": 42900552026300, "frame": {"channel":"book","type":"update","data":[{"symbol":"BTC/USD","bids":[{"price":62779.5,"qty":0.79643772}],"asks":[],"checksum":557000923,"timestamp":"2026-08-16T23:37:15.175742Z"}]}}
{"rx_ns": 42900599027300, "frame": {"channel":"book","type":"update","data":[{"symbol":"BTC/USD","bids":[],"asks":[{"price":62810.7,"qty":0.00222509}],"checksum":557000923,"timestamp":"2026-08-16T23:37:15.221225Z"}]}}
{"rx_ns": 42900712681300, "frame": {"channel":"book","type":"update","data":[{"symbol":"BTC/USD","bids":[],"asks":[{"price":62810.3,"qty":0.00318419}],"checksum":557000923,"timestamp":"2026-08-16T23:37:15.337357Z"}]}}
{"rx_ns": 42900749759200, "frame": {"channel":"heartbeat"}}
{"rx_ns": 42900792500100, "frame": {"channel":"book","type":"update","data":[{"symbol":"BTC/USD","bids":[{"price":62775.3,"qty":0.00000000},{"price":62772.0,"qty":0.00318614}],"asks":[],"checksum":557000923,"timestamp":"2026-08-16T23:37:15.413155Z"}]}}
{"rx_ns": 42900799992400, "frame": {"channel":"book","type":"update","data":[{"symbol":"BTC/USD","bids":[{"price":62781.7,"qty":0.00000000},{"price":62771.7,"qty":0.07963975}],"asks":[],"checksum":557000923,"timestamp":"2026-08-16T23:37:15.415798Z"}]}}
{"rx_ns": 42900800074000, "frame": {"channel":"book","type":"update","data":[{"symbol":"BTC/USD","bids":[{"price":62779.5,"qty":0.00000000},{"price":62771.5,"qty":0.13109402}],"asks":[],"checksum":557000923,"timestamp":"2026-08-16T23:37:15.417439Z"}]}}
{"rx_ns": 42900801540200, "frame": {"channel":"book","type":"update","data":[{"symbol":"BTC/USD","bids":[{"price":62777.5,"qty":0.79646257}],"asks":[],"checksum":557000923,"timestamp":"2026-08-16T23:37:15.420641Z"}]}}
{"rx_ns": 42900801594400, "frame": {"channel":"book","type":"update","data":[{"symbol":"BTC/USD","bids":[{"price":62772.7,"qty":0.80448897}],"asks":[],"checksum":557000923,"timestamp":"2026-08-16T23:37:15.420787Z"}]}}
{"rx_ns": 42900801608100, "frame": {"channel":"book","type":"update","data":[{"symbol":"BTC/USD","bids":[{"price":62777.5,"qty":0.00000000},{"price":62771.5,"qty":0.13109402}],"asks":[],"checksum":557000923,"timestamp":"2026-08-16T23:37:15.423575Z"}]}}
{"rx_ns": 42900807534600, "frame": {"channel":"book","type":"update","data":[{"symbol":"BTC/USD","bids":[{"price":62778.0,"qty":0.00000000},{"price":62771.4,"qty":0.00039827}],"asks":[],"checksum":557000923,"timestamp":"2026-08-16T23:37:15.426592Z"}]}}
{"rx_ns": 42900859101000, "frame": {"channel":"book","type":"update","data":[{"symbol":"BTC/USD","bids":[{"price":62773.6,"qty":0.23769319}],"asks":[],"checksum":557000923,"timestamp":"2026-08-16T23:37:15.483877Z"}]}}
{"rx_ns": 42900882425500, "frame": {"channel":"book","type":"update","data":[{"symbol":"BTC/USD","bids":[{"price":62776.0,"qty":0.79648231}],"asks":[],"checksum":557000923,"timestamp":"2026-08-16T23:37:15.504359Z"}]}}
{"rx_ns": 42900893825500, "frame": {"channel":"book","type":"update","data":[{"symbol":"BTC/USD","bids":[],"asks":[{"price":62803.7,"qty":0.00005100}],"checksum":557000923,"timestamp":"2026-08-16T23:37:15.516031Z"}]}}
{"rx_ns": 42900893867700, "frame": {"channel":"book","type":"update","data":[{"symbol":"BTC/USD","bids":[{"price":62777.8,"qty":0.11000000}],"asks":[],"checksum":557000923,"timestamp":"2026-08-16T23:37:15.516578Z"}]}}
{"rx_ns": 42900910630500, "frame": {"channel":"book","type":"update","data":[{"symbol":"BTC/USD","bids":[{"price":62775.4,"qty":0.15927785}],"asks":[],"checksum":557000923,"timestamp":"2026-08-16T23:37:15.532132Z"}]}}
{"rx_ns": 42900910695000, "frame": {"channel":"book","type":"update","data":[{"symbol":"BTC/USD","bids":[{"price":62776.8,"qty":0.10331161}],"asks":[],"checksum":557000923,"timestamp":"2026-08-16T23:37:15.532171Z"}]}}
{"rx_ns": 42900915662200, "frame": {"channel":"book","type":"update","data":[{"symbol":"BTC/USD","bids":[{"price":62776.0,"qty":0.00000000},{"price":62771.7,"qty":0.07963975}],"asks":[],"checksum":557000923,"timestamp":"2026-08-16T23:37:15.536756Z"}]}}
{"rx_ns": 42900917402800, "frame": {"channel":"book","type":"update","data":[{"symbol":"BTC/USD","bids":[{"price":62779.3,"qty":0.79644014}],"asks":[],"checksum":557000923,"timestamp":"2026-08-16T23:37:15.539469Z"}]}}
{"rx_ns": 42900933308800, "frame": {"channel":"book","type":"update","data":[{"symbol":"BTC/USD","bids":[{"price":62772.3,"qty":0.00000000},{"price":62771.5,"qty":0.13109402}],"asks":[],"checksum":557000923,"timestamp":"2026-08-16T23:37:15.556512Z"}]}}
{"rx_ns": 42900938379400, "frame": {"channel":"book","type":"update","data":[{"symbol":"BTC/USD","bids":[{"price":62775.4,"qty":0.00000000},{"price":62771.4,"qty":0.00039827}],"asks":[],"checksum":557000923,"timestamp":"2026-08-16T23:37:15.561843Z"}]}}
{"rx_ns": 42900952758100, "frame": {"channel":"book","type":"update","data":[{"symbol":"BTC/USD","bids":[{"price":62788.1,"qty":0.00000000},{"price":62770.9,"qty":0.00023889}],"asks":[],"checksum":3176470186,"timestamp":"2026-08-16T23:37:15.570473Z"}]}}
{"rx_ns": 42900952825000, "frame": {"channel":"book","type":"update","data":[{"symbol":"BTC/USD","bids":[{"price":62780.4,"qty":0.05598472}],"asks":[],"checksum":2641248790,"timestamp":"2026-08-16T23:37:15.572362Z"}]}}
{"rx_ns": 42900961471300, "frame": {"channel":"book","type":"update","data":[{"symbol":"BTC/USD","bids":[{"price":62779.3,"qty":0.00000000},{"price":62770.9,"qty":0.00023889}],"asks":[],"checksum":2641248790,"timestamp":"2026-08-16T23:37:15.582316Z"}]}}
{"rx_ns": 42900969956500, "frame": {"channel":"book","type":"update","data":[{"symbol":"BTC/USD","bids":[{"price":62794.7,"qty":0.00849813}],"asks":[],"checksum":2615511242,"timestamp":"2026-08-16T23:37:15.590050Z"}]}}
{"rx_ns": 42900971810900, "frame": {"channel":"book","type":"update","data":[{"symbol":"BTC/USD","bids":[{"price":62773.6,"qty":0.00000000},{"price":62770.7,"qty":0.00455372}],"asks":[],"checksum":2615511242,"timestamp":"2026-08-16T23:37:15.594127Z"}]}}
{"rx_ns": 42900976101200, "frame": {"channel":"book","type":"update","data":[{"symbol":"BTC/USD","bids":[{"price":62776.2,"qty":0.15927785}],"asks":[],"checksum":2615511242,"timestamp":"2026-08-16T23:37:15.596249Z"}]}}
{"rx_ns": 42900987790900, "frame": {"channel":"book","type":"update","data":[{"symbol":"BTC/USD","bids":[],"asks":[{"price":62803.9,"qty":0.00000000},{"price":62810.8,"qty":1.59575715}],"checksum":2615511242,"timestamp":"2026-08-16T23:37:15.608241Z"}]}}
{"rx_ns": 42900987847900, "frame": {"channel":"book","type":"update","data":[{"symbol":"BTC/USD","bids":[],"asks":[{"price":62799.1,"qty":0.06000000}],"checksum":3466112437,"timestamp":"2026-08-16T23:37:15.608264Z"}]}}
{"rx_ns": 42901087603700, "frame": {"channel":"book","type":"update","data":[{"symbol":"BTC/USD","bids":[],"asks":[{"price":62796.1,"qty":0.00000000},{"price":62810.8,"qty":1.59575715}],"checksum":516116918,"timestamp":"2026-08-16T23:37:15.710466Z"}]}}
{"rx_ns": 42901094863100, "frame": {"channel":"book","type":"update","data":[{"symbol":"BTC/USD","bids":[{"price":62777.8,"qty":0.15522003}],"asks":[],"checksum":516116918,"timestamp":"2026-08-16T23:37:15.719311Z"}]}}
{"rx_ns": 42901123021600, "frame": {"channel":"book","type":"update","data":[{"symbol":"BTC/USD","bids":[{"price":62776.2,"qty":0.00000000},{"price":62770.7,"qty":0.00455372}],"asks":[],"checksum":516116918,"timestamp":"2026-08-16T23:37:15.747737Z"}]}}
{"rx_ns": 42901157306300, "frame": {"channel":"book","type":"update","data":[{"symbol":"BTC/USD","bids":[{"price":62775.7,"qty":0.15927785}],"asks":[],"checksum":516116918,"timestamp":"2026-08-16T23:37:15.778599Z"}]}}
{"rx_ns": 42901161907200, "frame": {"channel":"book","type":"update","data":[{"symbol":"BTC/USD","bids":[{"price":62779.9,"qty":0.79643245}],"asks":[],"checksum":516116918,"timestamp":"2026-08-16T23:37:15.782428Z"}]}}
{"rx_ns": 42901319746500, "frame": {"channel":"book","type":"update","data":[{"symbol":"BTC/USD","bids":[{"price":62775.7,"qty":0.00000000},{"price":62770.9,"qty":0.00023889}],"asks":[],"checksum":516116918,"timestamp":"2026-08-16T23:37:15.944540Z"}]}}
{"rx_ns": 42901319808200, "frame": {"channel":"book","type":"update","data":[{"symbol":"BTC/USD","bids":[{"price":62775.8,"qty":0.16246379}],"asks":[],"checksum":516116918,"timestamp":"2026-08-16T23:37:15.946107Z"}]}}
{"rx_ns": 42901407310000, "frame": {"channel":"book","type":"update","data":[{"symbol":"BTC/USD","bids":[{"price":62775.8,"qty":0.00318594}],"asks":[],"checksum":516116918,"timestamp":"2026-08-16T23:37:16.016558Z"}]}}
{"rx_ns": 42901414626800, "frame": {"channel":"book","type":"update","data":[{"symbol":"BTC/USD","bids":[{"price":62776.4,"qty":0.17526304}],"asks":[],"checksum":516116918,"timestamp":"2026-08-16T23:37:16.039697Z"}]}}
{"rx_ns": 42901533154100, "frame": {"channel":"book","type":"update","data":[{"symbol":"BTC/USD","bids":[],"asks":[{"price":62810.8,"qty":0.00000000},{"price":62810.9,"qty":7.96040350},{"price":62805.2,"qty":1.59575715}],"checksum":516116918,"timestamp":"2026-08-16T23:37:16.159053Z"}]}}
{"rx_ns": 42901535471400, "frame": {"channel":"book","type":"update","data":[{"symbol":"BTC/USD","bids":[{"price":62785.3,"qty":0.00000000},{"price":62770.7,"qty":0.00455372},{"price":62785.2,"qty":0.00318620}],"asks":[],"checksum":4141138199,"timestamp":"2026-08-16T23:37:16.161334Z"}]}}
{"rx_ns": 42901538738200, "frame": {"channel":"book","type":"update","data":[{"symbol":"BTC/USD","bids":[],"asks":[{"price":62804.8,"qty":0.00000000},{"price":62810.9,"qty":7.96040350},{"price":62804.6,"qty":0.00318620}],"checksum":4141138199,"timestamp":"2026-08-16T23:37:16.161720Z"}]}}
{"rx_ns": 42901555955400, "frame": {"channel":"book","type":"update","data":[{"symbol":"BTC/USD","bids":[{"price":62776.9,"qty":0.79647111}],"asks":[],"checksum":4141138199,"timestamp":"2026-08-16T23:37:16.174427Z"}]}}
{"rx_ns": 42901581052400, "frame": {"channel":"book","type":"update","data":[{"symbol":"BTC/USD","bids":[{"price":62779.9,"qty":0.00000000},{"price":62770.9,"qty":0.00023889}],"asks":[],"checksum":4141138199,"timestamp":"2026-08-16T23:37:16.193503Z"}]}}
{"rx_ns": 42901581138500, "frame": {"channel":"book","type":"update","data":[{"symbol":"BTC/USD","bids":[{"price":62779.2,"qty":0.79644162}],"asks":[],"checksum":4141138199,"timestamp":"2026-08-16T23:37:16.194866Z"}]}}
{"rx_ns": 42901710024000, "frame": {"channel":"book","type":"update","data":[{"symbol":"BTC/USD","bids":[{"price":62776.4,"qty":0.01598519}],"asks":[],"checksum":4141138199,"timestamp":"2026-08-16T23:37:16.335011Z"}]}}
{"rx_ns": 42901723558000, "frame": {"channel":"book","type":"update","data":[{"symbol":"BTC/USD","bids":[{"price":62776.5,"qty":0.15927785}],"asks":[],"checksum":4141138199,"timestamp":"2026-08-16T23:37:16.346588Z"}]}}
{"rx_ns": 42901744640500, "frame": {"channel":"heartbeat"}}
{"rx_ns": 42901757621600, "frame": {"channel":"book","type":"update","data":[{"symbol":"BTC/USD","bids":[{"price":62779.2,"qty":0.00000000},{"price":62771.4,"qty":0.00039827}],"asks":[],"checksum":4141138199,"timestamp":"2026-08-16T23:37:16.382165Z"}]}}
{"rx_ns": 42901757677800, "frame": {"channel":"book","type":"update","data":[{"symbol":"BTC/USD","bids":[{"price":62776.9,"qty":0.00000000},{"price":62770.9,"qty":0.00023889}],"asks":[],"checksum":4141138199,"timestamp":"2026-08-16T23:37:16.382432Z"}]}}
{"rx_ns": 42901757975500, "frame": {"channel":"book","type":"update","data":[{"symbol":"BTC/USD","bids":[{"price":62780.2,"qty":0.79642883}],"asks":[],"checksum":4141138199,"timestamp":"2026-08-16T23:37:16.383897Z"}]}}
{"rx_ns": 42902030019700, "frame": {"channel":"book","type":"update","data":[{"symbol":"BTC/USD","bids":[{"price":62785.9,"qty":0.00000000},{"price":62770.9,"qty":0.00023889},{"price":62784.5,"qty":0.00009500}],"asks":[],"checksum":1439235734,"timestamp":"2026-08-16T23:37:16.643557Z"}]}}
{"rx_ns": 42902061314000, "frame": {"channel":"book","type":"update","data":[{"symbol":"BTC/USD","bids":[{"price":62773.2,"qty":0.65558762}],"asks":[],"checksum":1439235734,"timestamp":"2026-08-16T23:37:16.679654Z"}]}}
{"rx_ns": 42902071263700, "frame": {"channel":"book","type":"update","data":[{"symbol":"BTC/USD","bids":[{"price":62776.5,"qty":0.00000000},{"price":62771.4,"qty":0.00039827}],"asks":[],"checksum":1439235734,"timestamp":"2026-08-16T23:37:16.693969Z"}]}}
{"rx_ns": 42902071335800, "frame": {"channel":"book","type":"update","data":[{"symbol":"BTC/USD","bids":[],"asks":[{"price":62800.8,"qty":0.00000000},{"price":62810.9,"qty":7.96040350}],"checksum":619817487,"timestamp":"2026-08-16T23:37:16.695067Z"}]}}
{"rx_ns": 42902071424300, "frame": {"channel":"book","type":"update","data":[{"symbol":"BTC/USD","bids":[{"price":62776.6,"qty":0.15927785}],"asks":[],"checksum":619817487,"timestamp":"2026-08-16T23:37:16.696004Z"}]}}
{"rx_ns": 42902071439500, "frame": {"channel":"book","type":"update","data":[{"symbol":"BTC/USD","bids":[],"asks":[{"price":62796.7,"qty":0.50925300}],"checksum":3087092893,"timestamp":"2026-08-16T23:37:16.696084Z"}]}}
{"rx_ns": 42902073058800, "frame": {"channel":"book","type":"update","data":[{"symbol":"BTC/USD","bids":[],"asks":[{"price":62800.5,"qty":0.00005100},{"price":62799.0,"qty":0.18489680}],"checksum":4103853375,"timestamp":"2026-08-16T23:37:16.697294Z"}]}}
{"rx_ns": 42902321755500, "frame": {"channel":"book","type":"update","data":[{"symbol":"BTC/USD","bids":[{"price":62776.6,"qty":0.00000000},{"price":62771.4,"qty":0.00039827}],"asks":[],"checksum":4103853375,"timestamp":"2026-08-16T23:37:16.944495Z"}]}}
{"rx_ns": 42902321819200, "frame": {"channel":"book","type":"update","data":[{"symbol":"BTC/USD","bids":[{"price":62776.7,"qty":0.15927785}],"asks":[],"checksum":4103853375,"timestamp":"2026-08-16T23:37:16.946161Z"}]}}
{"rx_ns": 42902384777100, "frame": {"channel":"book","type":"update","data":[{"symbol":"BTC/USD","bids":[],"asks":[{"price":62805.1,"qty":0.00222509}],"checksum":4103853375,"timestamp":"2026-08-16T23:37:17.006791Z"}]}}
{"rx_ns": 42902553101500, "frame": {"channel":"book","type":"update","data":[{"symbol":"BTC/USD","bids":[{"price":62778.0,"qty":0.79645716}],"asks":[],"checksum":4103853375,"timestamp":"2026-08-16T23:37:17.174991Z"}]}}
{"rx_ns": 42902598720500, "frame": {"channel":"book","type":"update","data":[{"symbol":"BTC/USD","bids":[],"asks":[{"price":62796.1,"qty":0.40200000}],"checksum":251141378,"timestamp":"2026-08-16T23:37:17.224347Z"}]}}
{"rx_ns": 42902599191000, "frame": {"channel":"book","type":"update","data":[{"symbol":"BTC/USD","bids":[],"asks":[{"price":62799.0,"qty":0.00000000},{"price":62810.3,"qty":0.00318419},{"price":62795.9,"qty":0.18489680}],"checksum":3282933231,"timestamp":"2026-08-16T23:37:17.225632Z"}]}}
{"rx_ns": 42902748148900, "frame": {"channel":"heartbeat"}}
{"rx_ns": 42902752528600, "frame": {"channel":"book","type":"update","data":[{"symbol":"BTC/USD","bids":[{"price":62776.7,"qty":0.00000000},{"price":62771.5,"qty":0.13109402}],"asks":[],"checksum":3282933231,"timestamp":"2026-08-16T23:37:17.363642Z"}]}}
{"rx_ns": 42902772319600, "frame": {"channel":"book","type":"update","data":[{"symbol":"BTC/USD","bids":[{"price":62776.8,"qty":0.26258946}],"asks":[],"checksum":3282933231,"timestamp":"2026-08-16T23:37:17.396279Z"}]}}
{"rx_ns": 42902780388600, "frame": {"channel":"book","type":"update","data":[{"symbol":"BTC/USD","bids":[{"price":62776.8,"qty":0.10331161}],"asks":[],"checksum":3282933231,"timestamp":"2026-08-16T23:37:17.406066Z"}]}}
{"rx_ns": 42902822047700, "frame": {"channel":"book","type":"update","data":[{"symbol":"BTC/USD","bids":[{"price":62776.0,"qty":0.15927785}],"asks":[],"checksum":3282933231,"timestamp":"2026-08-16T23:37:17.446170Z"}]}}
{"rx_ns": 42903134890700, "frame": {"channel":"book","type":"update","data":[{"symbol":"BTC/USD","bids":[{"price":62785.2,"qty":0.00318497}],"asks":[],"checksum":95103724,"timestamp":"2026-08-16T23:37:17.756276Z"}]}}
{"rx_ns": 42903134946000, "frame": {"channel":"book","type":"update","data":[{"symbol":"BTC/USD","bids":[],"asks":[{"price":62804.6,"qty":0.00318497}],"checksum":95103724,"timestamp":"2026-08-16T23:37:17.756519Z"}]}}
{"rx_ns": 42903146474000, "frame": {"channel":"book","type":"update","data":[{"symbol":"BTC/USD","bids":[{"price":62776.0,"qty":0.00000000},{"price":62771.5,"qty":0.13109402}],"asks":[],"checksum":95103724,"timestamp":"2026-08-16T23:37:17.770103Z"}]}}
{"rx_ns": 42903170679800, "frame": {"channel":"book","type":"update","data":[{"symbol":"BTC/USD","bids":[{"price":62776.7,"qty":0.15927785}],"asks":[],"checksum":95103724,"timestamp":"2026-08-16T23:37:17.796245Z"}]}}
{"rx_ns": 42903321062000, "frame": {"channel":"book","type":"update","data":[{"symbol":"BTC/USD","bids":[{"price":62776.7,"qty":0.00000000},{"price":62771.5,"qty":0.13109402}],"asks":[],"checksum":95103724,"timestamp":"2026-08-16T23:37:17.944337Z"}]}}
{"rx_ns": 42903321109900, "frame": {"channel":"book","type":"update","data":[{"symbol":"BTC/USD","bids":[{"price":62776.8,"qty":0.26258946}],"asks":[],"checksum":95103724,"timestamp":"2026-08-16T23:37:17.946079Z"}]}}
{"rx_ns": 42903745949600, "frame": {"channel":"heartbeat"}}
{"rx_ns": 42903980701700, "frame": {"channel":"book","type":"update","data":[{"symbol":"BTC/USD","bids":[{"price":62776.8,"qty":0.10331161}],"asks":[],"checksum":95103724,"timestamp":"2026-08-16T23:37:18.605750Z"}]}}
{"rx_ns": 42904023026400, "frame": {"channel":"book","type":"update","data":[{"symbol":"BTC/USD","bids":[{"price":62776.9,"qty":0.15927785}],"asks":[],"checksum":95103724,"timestamp":"2026-08-16T23:37:18.646348Z"}]}}
{"rx_ns": 42904027847800, "frame": {"channel":"book","type":"update","data":[{"symbol":"BTC/USD","bids":[{"price":62776.9,"qty":0.00000000},{"price":62771.5,"qty":0.13109402}],"asks":[],"checksum":95103724,"timestamp":"2026-08-16T23:37:18.652250Z"}]}}
{"rx_ns": 42904070500000, "frame": {"channel":"book","type":"update","data":[{"symbol":"BTC/USD","bids":[{"price":62777.5,"qty":0.15927785}],"asks":[],"checksum":95103724,"timestamp":"2026-08-16T23:37:18.696301Z"}]}}
{"rx_ns": 42904072585200, "frame": {"channel":"book","type":"update","data":[{"symbol":"BTC/USD","bids":[{"price":62784.5,"qty":0.00000000},{"price":62771.5,"qty":0.13109402},{"price":62784.6,"qty":0.00009500}],"asks":[],"checksum":2695053696,"timestamp":"2026-08-16T23:37:18.696875Z"}]}}
{"rx_ns": 42904319582400, "frame": {"channel":"book","type":"update","data":[{"symbol":"BTC/USD","bids":[{"price":62777.5,"qty":0.00000000},{"price":62771.5,"qty":0.13109402}],"asks":[],"checksum":2695053696,"timestamp":"2026-08-16T23:37:18.944545Z"}]}}
{"rx_ns": 42904321093700, "frame": {"channel":"book","type":"update","data":[{"symbol":"BTC/USD","bids":[{"price":62777.6,"qty":0.15927785}],"asks":[],"checksum":2695053696,"timestamp":"2026-08-16T23:37:18.946033Z"}]}}
{"rx_ns": 42904383857100, "frame": {"channel":"book","type":"update","data":[{"symbol":"BTC/USD","bids":[{"price":62780.2,"qty":0.00000000},{"price":62771.5,"qty":0.13109402}],"asks":[],"checksum":2695053696,"timestamp":"2026-08-16T23:37:18.995943Z"}]}}
{"rx_ns": 42904383922400, "frame": {"channel":"book","type":"update","data":[{"symbol":"BTC/USD","bids":[{"price":62777.6,"qty":0.00000000},{"price":62771.4,"qty":0.00039827}],"asks":[],"checksum":2695053696,"timestamp":"2026-08-16T23:37:18.997391Z"}]}}
{"rx_ns": 42904383939200, "frame": {"channel":"book","type":"update","data":[{"symbol":"BTC/USD","bids":[{"price":62780.8,"qty":0.79642089}],"asks":[],"checksum":3988989950,"timestamp":"2026-08-16T23:37:18.997686Z"}]}}
{"rx_ns": 42904383991300, "frame": {"channel":"book","type":"update","data":[{"symbol":"BTC/USD","bids":[{"price":62778.0,"qty":0.00000000},{"price":62771.4,"qty":0.00039827}],"asks":[],"checksum":3988989950,"timestamp":"2026-08-16T23:37:18.999861Z"}]}}
{"rx_ns": 42904384008200, "frame": {"channel":"book","type":"update","data":[{"symbol":"BTC/USD","bids":[{"price":62780.4,"qty":0.00000000},{"price":62770.9,"qty":0.00023889},{"price":62788.1,"qty":0.05598472}],"asks":[],"checksum":3101889628,"timestamp":"2026-08-16T23:37:19.000345Z"}]}}
{"rx_ns": 42904384036600, "frame": {"channel":"book","type":"update","data":[{"symbol":"BTC/USD","bids":[{"price":62780.8,"qty":0.00000000},{"price":62770.9,"qty":0.00023889}],"asks":[],"checksum":3101889628,"timestamp":"2026-08-16T23:37:19.001500Z"}]}}
{"rx_ns": 42904384051600, "frame": {"channel":"book","type":"update","data":[{"symbol":"BTC/USD","bids":[{"price":62772.7,"qty":0.00796524}],"asks":[],"checksum":3101889628,"timestamp":"2026-08-16T23:37:19.001764Z"}]}}
{"rx_ns": 42904384062600, "frame": {"channel":"book","type":"update","data":[{"symbol":"BTC/USD","bids":[{"price":62779.1,"qty":0.79644281}],"asks":[],"checksum":3101889628,"timestamp":"2026-08-16T23:37:19.003216Z"}]}}
{"rx_ns": 42904384073300, "frame": {"channel":"book","type":"update","data":[{"symbol":"BTC/USD","bids":[{"price":62775.1,"qty":0.79649335}],"asks":[],"checksum":3101889628,"timestamp":"2026-08-16T23:37:19.003617Z"}]}}
{"rx_ns": 42904392217700, "frame": {"channel":"book","type":"update","data":[{"symbol":"BTC/USD","bids":[{"price":62779.0,"qty":0.15927785}],"asks":[],"checksum":3101889628,"timestamp":"2026-08-16T23:37:19.016947Z"}]}}
{"rx_ns": 42904494147300, "frame": {"channel":"book","type":"update","data":[{"symbol":"BTC/USD","bids":[{"price":62775.9,"qty":0.00966536}],"asks":[],"checksum":3101889628,"timestamp":"2026-08-16T23:37:19.118998Z"}]}}
{"rx_ns": 42904550632100, "frame": {"channel":"book","type":"update","data":[{"symbol":"BTC/USD","bids":[{"price":62781.5,"qty":0.79641282}],"asks":[],"checksum":3101889628,"timestamp":"2026-08-16T23:37:19.173891Z"}]}}
{"rx_ns": 42904553942600, "frame": {"channel":"book","type":"update","data":[{"symbol":"BTC/USD","bids":[{"price":62775.9,"qty":0.00000000},{"price":62772.6,"qty":0.06960000}],"asks":[],"checksum":3101889628,"timestamp":"2026-08-16T23:37:19.177097Z"}]}}
{"rx_ns": 42904745688500, "frame": {"channel":"heartbeat"}}
{"rx_ns": 42904754386600, "frame": {"channel":"book","type":"update","data":[{"symbol":"BTC/USD","bids":[{"price":62773.2,"qty":0.00000000},{"price":62772.0,"qty":0.00318614}],"asks":[],"checksum":3101889628,"timestamp":"2026-08-16T23:37:19.363789Z"}]}}
{"rx_ns": 42904754433200, "frame": {"channel":"book","type":"update","data":[{"symbol":"BTC/USD","bids":[{"price":62779.0,"qty":0.00000000},{"price":62771.5,"qty":0.13109402}],"asks":[],"checksum":3101889628,"timestamp":"2026-08-16T23:37:19.363878Z"}]}}
{"rx_ns": 42904773081300, "frame": {"channel":"book","type":"update","data":[{"symbol":"BTC/USD","bids":[{"price":62779.7,"qty":0.15927785}],"asks":[],"checksum":3101889628,"timestamp":"2026-08-16T23:37:19.396214Z"}]}}
{"rx_ns": 42904845481400, "frame": {"channel":"book","type":"update","data":[{"symbol":"BTC/USD","bids":[{"price":62779.7,"qty":0.00000000},{"price":62771.5,"qty":0.13109402}],"asks":[],"checksum":3101889628,"timestamp":"2026-08-16T23:37:19.470344Z"}]}}
{"rx_ns": 42904871333300, "frame": {"channel":"book","type":"update","data":[{"symbol":"BTC/USD","bids":[{"price":62779.6,"qty":0.15927785}],"asks":[],"checksum":3101889628,"timestamp":"2026-08-16T23:37:19.496011Z"}]}}
{"rx_ns": 42904887697600, "frame": {"channel":"book","type":"update","data":[{"symbol":"BTC/USD","bids":[],"asks":[{"price":62798.0,"qty":0.00000000},{"price":62810.3,"qty":0.00318419}],"checksum":1265967782,"timestamp":"2026-08-16T23:37:19.510016Z"}]}}
{"rx_ns": 42904889065500, "frame": {"channel":"book","type":"update","data":[{"symbol":"BTC/USD","bids":[{"price":62781.5,"qty":0.00000000},{"price":62771.5,"qty":0.13109402}],"asks":[],"checksum":1265967782,"timestamp":"2026-08-16T23:37:19.510131Z"}]}}
{"rx_ns": 42904889106100, "frame": {"channel":"book","type":"update","data":[{"symbol":"BTC/USD","bids":[{"price":62779.6,"qty":0.00000000},{"price":62771.4,"qty":0.00039827}],"asks":[],"checksum":1265967782,"timestamp":"2026-08-16T23:37:19.510426Z"}]}}
{"rx_ns": 42904889140800, "frame": {"channel":"book","type":"update","data":[{"symbol":"BTC/USD","bids":[{"price":62779.1,"qty":0.00000000},{"price":62770.9,"qty":0.00023889}],"asks":[],"checksum":1265967782,"timestamp":"2026-08-16T23:37:19.510978Z"}]}}
{"rx_ns": 42904889152900, "frame": {"channel":"book","type":"update","data":[{"symbol":"BTC/USD","bids":[{"price":62788.1,"qty":0.00000000},{"price":62770.7,"qty":0.00455372},{"price":62791.3,"qty":0.05598472}],"asks":[],"checksum":1870932767,"timestamp":"2026-08-16T23:37:19.511362Z"}]}}
{"rx_ns": 42904890930600, "frame": {"channel":"book","type":"update","data":[{"symbol":"BTC/USD","bids":[],"asks":[{"price":62805.2,"qty":0.00000000},{"price":62810.4,"qty":0.13109402}],"checksum":1870932767,"timestamp":"2026-08-16T23:37:19.512530Z"}]}}
{"rx_ns": 42904890961000, "frame": {"channel":"book","type":"update","data":[{"symbol":"BTC/USD","bids":[{"price":62783.0,"qty":0.79639330}],"asks":[],"checksum":1870932767,"timestamp":"2026-08-16T23:37:19.513371Z"}]}}
{"rx_ns": 42904890973700, "frame": {"channel":"book","type":"update","data":[{"symbol":"BTC/USD","bids":[{"price":62780.8,"qty":0.79642153}],"asks":[],"checksum":1870932767,"timestamp":"2026-08-16T23:37:19.513620Z"}]}}
{"rx_ns": 42904893336300, "frame": {"channel":"book","type":"update","data":[{"symbol":"BTC/USD","bids":[],"asks":[{"price":62795.9,"qty":0.00000000},{"price":62810.8,"qty":1.59575715},{"price":62810.3,"qty":0.18808099}],"checksum":1630239249,"timestamp":"2026-08-16T23:37:19.514959Z"}]}}
{"rx_ns": 42904893387500, "frame": {"channel":"book","type":"update","data":[{"symbol":"BTC/USD","bids":[{"price":62782.1,"qty":0.06960000}],"asks":[],"checksum":1630239249,"timestamp":"2026-08-16T23:37:19.516187Z"}]}}
{"rx_ns": 42904896168000, "frame": {"channel":"book","type":"update","data":[{"symbol":"BTC/USD","bids":[{"price":62777.5,"qty":0.00953744}],"asks":[],"checksum":1630239249,"timestamp":"2026-08-16T23:37:19.519395Z"}]}}
{"rx_ns": 42904899034600, "frame": {"channel":"book","type":"update","data":[{"symbol":"BTC/USD","bids":[{"price":62777.5,"qty":0.00000000},{"price":62772.0,"qty":0.00318614}],"asks":[],"checksum":1630239249,"timestamp":"2026-08-16T23:37:19.519855Z"}]}}
{"rx_ns": 42904899118800, "frame": {"channel":"book","type":"update","data":[{"symbol":"BTC/USD","bids":[{"price":62792.6,"qty":0.00000000},{"price":62771.5,"qty":0.13109402}],"asks":[],"checksum":2712969851,"timestamp":"2026-08-16T23:37:19.523057Z"}]}}
{"rx_ns": 42904899135600, "frame": {"channel":"book","type":"update","data":[{"symbol":"BTC/USD","bids":[{"price":62793.5,"qty":0.02131292}],"asks":[],"checksum":3095074458,"timestamp":"2026-08-16T23:37:19.523640Z"}]}}
{"rx_ns": 42904920650600, "frame": {"channel":"book","type":"update","data":[{"symbol":"BTC/USD","bids":[{"price":62780.9,"qty":0.15927785}],"asks":[],"checksum":3095074458,"timestamp":"2026-08-16T23:37:19.546261Z"}]}}
{"rx_ns": 42904930939900, "frame": {"channel":"book","type":"update","data":[{"symbol":"BTC/USD","bids":[{"price":62778.0,"qty":0.00318583}],"asks":[],"checksum":3095074458,"timestamp":"2026-08-16T23:37:19.556862Z"}]}}
{"rx_ns": 42904938897300, "frame": {"channel":"book","type":"update","data":[{"symbol":"BTC/USD","bids":[],"asks":[{"price":62805.1,"qty":0.00000000},{"price":62810.9,"qty":7.96040350},{"price":62810.7,"qty":0.00222509}],"checksum":3095074458,"timestamp":"2026-08-16T23:37:19.562652Z"}]}}
{"rx_ns": 42904955970800, "frame": {"channel":"book","type":"update","data":[{"symbol":"BTC/USD","bids":[{"price":62785.2,"qty":0.00000000},{"price":62772.6,"qty":0.06960000},{"price":62785.1,"qty":0.00318497}],"asks":[],"checksum":4120057597,"timestamp":"2026-08-16T23:37:19.581084Z"}]}}
{"rx_ns": 42904956023300, "frame": {"channel":"book","type":"update","data":[{"symbol":"BTC/USD","bids":[],"asks":[{"price":62804.6,"qty":0.00000000},{"price":62810.9,"qty":7.96040350},{"price":62804.5,"qty":0.00318497}],"checksum":4120057597,"timestamp":"2026-08-16T23:37:19.581392Z"}]}}
{"rx_ns": 42904993667700, "frame": {"channel":"book","type":"update","data":[{"symbol":"BTC/USD","bids":[{"price":62783.0,"qty":0.00000000},{"price":62772.6,"qty":0.06960000}],"asks":[],"checksum":4120057597,"timestamp":"2026-08-16T23:37:19.619079Z"}]}}
{"rx_ns": 42904996695500, "frame": {"channel":"book","type":"update","data":[{"symbol":"BTC/USD","bids":[{"price":62782.1,"qty":0.86600506}],"asks":[],"checksum":4120057597,"timestamp":"2026-08-16T23:37:19.620601Z"}]}}
{"rx_ns": 42904999440800, "frame": {"channel":"book","type":"update","data":[{"symbol":"BTC/USD","bids":[{"price":62778.4,"qty":0.00951371}],"asks":[],"checksum":4120057597,"timestamp":"2026-08-16T23:37:19.622725Z"}]}}
{"rx_ns": 42904999514900, "frame": {"channel":"book","type":"update","data":[{"symbol":"BTC/USD","bids":[{"price":62778.4,"qty":0.00000000},{"price":62772.6,"qty":0.06960000}],"asks":[],"checksum":4120057597,"timestamp":"2026-08-16T23:37:19.623442Z"}]}}
{"rx_ns": 42905031819600, "frame": {"channel":"book","type":"update","data":[{"symbol":"BTC/USD","bids":[],"asks":[{"price":62800.6,"qty":0.00000000},{"price":62810.9,"qty":7.96040350},{"price":62805.1,"qty":0.19620257}],"checksum":4094946014,"timestamp":"2026-08-16T23:37:19.657336Z"}]}}
{"rx_ns": 42905061091700, "frame": {"channel":"book","type":"update","data":[{"symbol":"BTC/USD","bids":[{"price":62780.9,"qty":0.00000000},{"price":62772.0,"qty":0.00318614}],"asks":[],"checksum":4094946014,"timestamp":"2026-08-16T23:37:19.686509Z"}]}}
{"rx_ns": 42905072232400, "frame": {"channel":"book","type":"update","data":[{"symbol":"BTC/USD","bids":[{"price":62780.8,"qty":0.95569938}],"asks":[],"checksum":4094946014,"timestamp":"2026-08-16T23:37:19.696666Z"}]}}
{"rx_ns": 42905082507700, "frame": {"channel":"book","type":"update","data":[{"symbol":"BTC/USD","bids":[{"price":62777.4,"qty":0.65558762}],"asks":[],"checksum":4094946014,"timestamp":"2026-08-16T23:37:19.702535Z"}]}}
{"rx_ns": 42905084729200, "frame": {"channel":"book","type":"update","data":[{"symbol":"BTC/USD","bids":[{"price":62780.8,"qty":0.79642153}],"asks":[],"checksum":4094946014,"timestamp":"2026-08-16T23:37:19.710251Z"}]}}
{"rx_ns": 42905121030900, "frame": {"channel":"book","type":"update","data":[{"symbol":"BTC/USD","bids":[{"price":62780.9,"qty":0.15927785}],"asks":[],"checksum":4094946014,"timestamp":"2026-08-16T23:37:19.746313Z"}]}}
{"rx_ns": 42905320716300, "frame": {"channel":"book","type":"update","data":[{"symbol":"BTC/USD","bids":[{"price":62780.9,"qty":0.00000000},{"price":62772.6,"qty":0.06960000}],"asks":[],"checksum":4094946014,"timestamp":"2026-08-16T23:37:19.944377Z"}]}}
{"rx_ns": 42905321927200, "frame": {"channel":"book","type":"update","data":[{"symbol":"BTC/USD","bids":[{"price":62780.8,"qty":0.95569938}],"asks":[],"checksum":4094946014,"timestamp":"2026-08-16T23:37:19.946183Z"}]}}
{"rx_ns": 42905409416800, "frame": {"channel":"book","type":"update","data":[{"symbol":"BTC/USD","bids":[{"price":62780.8,"qty":0.79642153}],"asks":[],"checksum":4094946014,"timestamp":"2026-08-16T23:37:20.016688Z"}]}}
{"rx_ns": 42905421128200, "frame": {"channel":"book","type":"update","data":[{"symbol":"BTC/USD","bids":[{"price":62780.3,"qty":0.15951669}],"asks":[],"checksum":4094946014,"timestamp":"2026-08-16T23:37:20.046251Z"}]}}
{"rx_ns": 42905592344500, "frame": {"channel":"book","type":"update","data":[{"symbol":"BTC/USD","bids":[{"price":62780.3,"qty":0.00023884}],"asks":[],"checksum":4094946014,"timestamp":"2026-08-16T23:37:20.214867Z"}]}}
{"rx_ns": 42905620897200, "frame": {"channel":"book","type":"update","data":[{"symbol":"BTC/USD","bids":[{"price":62780.2,"qty":0.15927785}],"asks":[],"checksum":4094946014,"timestamp":"2026-08-16T23:37:20.246387Z"}]}}
{"rx_ns": 42905680551100, "frame": {"channel":"book","type":"update","data":[{"symbol":"BTC/USD","bids":[],"asks":[{"price":62805.1,"qty":0.00000000},{"price":62810.9,"qty":7.96040350},{"price":62801.3,"qty":0.19620257}],"checksum":2268677733,"timestamp":"2026-08-16T23:37:20.303710Z"}]}}
{"rx_ns": 42905745754900, "frame": {"channel":"heartbeat"}}
{"rx_ns": 42906129650000, "frame": {"channel":"book","type":"update","data":[{"symbol":"BTC/USD","bids":[{"price":62784.6,"qty":0.00000000},{"price":62772.6,"qty":0.06960000},{"price":62785.8,"qty":0.00009500}],"asks":[],"checksum":43290064,"timestamp":"2026-08-16T23:37:20.749720Z"}]}}
{"rx_ns": 42906325638600, "frame": {"channel":"book","type":"update","data":[{"symbol":"BTC/USD","bids":[{"price":62780.2,"qty":0.00000000},{"price":62772.6,"qty":0.06960000}],"asks":[],"checksum":43290064,"timestamp":"2026-08-16T23:37:20.944748Z"}]}}
{"rx_ns": 42906325733900, "frame": {"channel":"book","type":"update","data":[{"symbol":"BTC/USD","bids":[{"price":62780.1,"qty":0.15927785}],"asks":[],"checksum":43290064,"timestamp":"2026-08-16T23:37:20.946304Z"}]}}
{"rx_ns": 42906745761100, "frame": {"channel":"heartbeat"}}
{"rx_ns": 42906861628700, "frame": {"channel":"book","type":"update","data":[{"symbol":"BTC/USD","bids":[],"asks":[{"price":62804.5,"qty":0.00000000},{"price":62810.9,"qty":7.96040350},{"price":62804.7,"qty":0.00318497}],"checksum":43290064,"timestamp":"2026-08-16T23:37:21.487323Z"}]}}
{"rx_ns": 42906863069500, "frame": {"channel":"book","type":"update","data":[{"symbol":"BTC/USD","bids":[{"price":62785.1,"qty":0.00000000},{"price":62772.6,"qty":0.06960000},{"price":62785.2,"qty":0.00318497}],"asks":[],"checksum":4885239,"timestamp":"2026-08-16T23:37:21.487557Z"}]}}
{"rx_ns": 42907063976000, "frame": {"channel":"book","type":"update","data":[{"symbol":"BTC/USD","bids":[{"price":62780.1,"qty":0.00000000},{"price":62772.6,"qty":0.06960000}],"asks":[],"checksum":4885239,"timestamp":"2026-08-16T23:37:21.686388Z"}]}}
{"rx_ns": 42907070699000, "frame": {"channel":"book","type":"update","data":[{"symbol":"BTC/USD","bids":[{"price":62780.0,"qty":0.15927785}],"asks":[],"checksum":4885239,"timestamp":"2026-08-16T23:37:21.696148Z"}]}}
{"rx_ns": 42907746668700, "frame": {"channel":"heartbeat"}}
{"rx_ns": 42908119681500, "frame": {"channel":"book","type":"update","data":[{"symbol":"BTC/USD","bids":[{"price":62780.0,"qty":0.00000000},{"price":62772.6,"qty":0.06960000}],"asks":[],"checksum":4885239,"timestamp":"2026-08-16T23:37:22.739029Z"}]}}
{"rx_ns": 42908121307300, "frame": {"channel":"book","type":"update","data":[{"symbol":"BTC/USD","bids":[{"price":62779.9,"qty":0.15927762}],"asks":[],"checksum":4885239,"timestamp":"2026-08-16T23:37:22.746103Z"}]}}
{"rx_ns": 42908141181500, "frame": {"channel":"book","type":"update","data":[{"symbol":"BTC/USD","bids":[{"price":62777.8,"qty":0.11000000}],"asks":[],"checksum":4885239,"timestamp":"2026-08-16T23:37:22.765979Z"}]}}
{"rx_ns": 42908287984500, "frame": {"channel":"book","type":"update","data":[{"symbol":"BTC/USD","bids":[{"price":62773.8,"qty":0.03185496}],"asks":[],"checksum":4885239,"timestamp":"2026-08-16T23:37:22.913100Z"}]}}
{"rx_ns": 42908373216800, "frame": {"channel":"book","type":"update","data":[{"symbol":"BTC/USD","bids":[{"price":62791.3,"qty":0.00000000},{"price":62772.7,"qty":0.00796524},{"price":62791.2,"qty":0.05762772}],"asks":[],"checksum":2245812262,"timestamp":"2026-08-16T23:37:22.998072Z"}]}}
{"rx_ns": 42908750004300, "frame": {"channel":"heartbeat"}}
{"rx_ns": 42908841334600, "frame": {"channel":"book","type":"update","data":[{"symbol":"BTC/USD","bids":[{"price":62778.6,"qty":0.08817369}],"asks":[],"checksum":2245812262,"timestamp":"2026-08-16T23:37:23.465919Z"}]}}
{"rx_ns": 42908973000300, "frame": {"channel":"book","type":"update","data":[{"symbol":"BTC/USD","bids":[{"price":62779.9,"qty":0.00000000},{"price":62772.7,"qty":0.00796524}],"asks":[],"checksum":2245812262,"timestamp":"2026-08-16T23:37:23.596119Z"}]}}
{"rx_ns": 42909020346900, "frame": {"channel":"book","type":"update","data":[{"symbol":"BTC/USD","bids":[{"price":62779.8,"qty":0.15927762}],"asks":[],"checksum":2245812262,"timestamp":"2026-08-16T23:37:23.646306Z"}]}}
{"rx_ns": 42909752044200, "frame": {"channel":"heartbeat"}}
{"rx_ns": 42910061090100, "frame": {"channel":"book","type":"update","data":[{"symbol":"BTC/USD","bids":[{"price":62779.8,"qty":0.00000000},{"price":62772.7,"qty":0.00796524}],"asks":[],"checksum":2245812262,"timestamp":"2026-08-16T23:37:24.686614Z"}]}}
{"rx_ns": 42910070435700, "frame": {"channel":"book","type":"update","data":[{"symbol":"BTC/USD","bids":[{"price":62779.7,"qty":0.15927762}],"asks":[],"checksum":2245812262,"timestamp":"2026-08-16T23:37:24.696326Z"}]}}
{"rx_ns": 42910232345300, "frame": {"channel":"book","type":"update","data":[{"symbol":"BTC/USD","bids":[{"price":62785.8,"qty":0.00000000},{"price":62772.7,"qty":0.00796524},{"price":62784.6,"qty":0.00009500}],"asks":[],"checksum":2977238349,"timestamp":"2026-08-16T23:37:24.854528Z"}]}}
{"rx_ns": 42910384122900, "frame": {"channel":"book","type":"update","data":[{"symbol":"BTC/USD","bids":[],"asks":[{"price":62809.7,"qty":0.00000000},{"price":62810.9,"qty":7.96040350}],"checksum":2977238349,"timestamp":"2026-08-16T23:37:25.008283Z"}]}}
{"rx_ns": 42910384183900, "frame": {"channel":"book","type":"update","data":[{"symbol":"BTC/USD","bids":[],"asks":[{"price":62808.9,"qty":0.02865835}],"checksum":2977238349,"timestamp":"2026-08-16T23:37:25.008318Z"}]}}
{"rx_ns": 42910715024500, "frame": {"channel":"book","type":"update","data":[{"symbol":"BTC/USD","bids":[],"asks":[{"price":62810.3,"qty":0.18489680}],"checksum":2977238349,"timestamp":"2026-08-16T23:37:25.338879Z"}]}}
{"rx_ns": 42910715103100, "frame": {"channel":"book","type":"update","data":[{"symbol":"BTC/USD","bids":[],"asks":[{"price":62809.9,"qty":0.00323521}],"checksum":2977238349,"timestamp":"2026-08-16T23:37:25.339166Z"}]}}
{"rx_ns": 42910750900300, "frame": {"channel":"heartbeat"}}
{"rx_ns": 42910963849700, "frame": {"channel":"book","type":"update","data":[{"symbol":"BTC/USD","bids":[{"price":62794.7,"qty":0.00810000},{"price":62794.7,"qty":0.00010000},{"price":62794.7,"qty":0.00000013}],"asks":[],"checksum":4023025237,"timestamp":"2026-08-16T23:37:25.588038Z"}]}}
{"rx_ns": 42910971978700, "frame": {"channel":"book","type":"update","data":[{"symbol":"BTC/USD","bids":[],"asks":[{"price":62794.8,"qty":5.75861514}],"checksum":3588718414,"timestamp":"2026-08-16T23:37:25.590596Z"}]}}
{"rx_ns": 42910972023400, "frame": {"channel":"book","type":"update","data":[{"symbol":"BTC/USD","bids":[{"price":62785.2,"qty":0.00000000},{"price":62772.7,"qty":0.00796524},{"price":62784.7,"qty":0.00318497}],"asks":[],"checksum":2402876717,"timestamp":"2026-08-16T23:37:25.591031Z"}]}}
{"rx_ns": 42910972039100, "frame": {"channel":"book","type":"update","data":[{"symbol":"BTC/USD","bids":[],"asks":[{"price":62804.7,"qty":0.00000000},{"price":62810.9,"qty":7.96040350},{"price":62804.2,"qty":0.00318497}],"checksum":2402876717,"timestamp":"2026-08-16T23:37:25.591329Z"}]}}
{"rx_ns": 42910972051400, "frame": {"channel":"book","type":"update","data":[{"symbol":"BTC/USD","bids":[{"price":62794.7,"qty":0.00000000},{"price":62772.7,"qty":0.00796524},{"price":62794.3,"qty":0.00000000},{"price":62772.6,"qty":0.06960000}],"asks":[{"price":62793.6,"qty":0.00014887}],"checksum":2848284173,"timestamp":"2026-08-16T23:37:25.592135Z"}]}}
{"rx_ns": 42910972140000, "frame": {"channel":"book","type":"update","data":[{"symbol":"BTC/USD","bids":[],"asks":[{"price":62793.6,"qty":0.01180152}],"checksum":1914264378,"timestamp":"2026-08-16T23:37:25.592450Z"}]}}
{"rx_ns": 42910972150500, "frame": {"channel":"book","type":"update","data":[{"symbol":"BTC/USD","bids":[],"asks":[{"price":62794.8,"qty":5.74676267}],"checksum":1285553076,"timestamp":"2026-08-16T23:37:25.592670Z"}]}}
{"rx_ns": 42910972159600, "frame": {"channel":"book","type":"update","data":[{"symbol":"BTC/USD","bids":[],"asks":[{"price":62794.7,"qty":0.11000000}],"checksum":3043339451,"timestamp":"2026-08-16T23:37:25.593295Z"}]}}
{"rx_ns": 42910972167800, "frame": {"channel":"book","type":"update","data":[{"symbol":"BTC/USD","bids":[],"asks":[{"price":62794.8,"qty":5.72659973}],"checksum":2264016189,"timestamp":"2026-08-16T23:37:25.593662Z"}]}}
{"rx_ns": 42910972176200, "frame": {"channel":"book","type":"update","data":[{"symbol":"BTC/USD","bids":[],"asks":[{"price":62794.8,"qty":5.67061501},{"price":62794.7,"qty":0.16598472}],"checksum":4271627307,"timestamp":"2026-08-16T23:37:25.593718Z"}]}}
{"rx_ns": 42910975321400, "frame": {"channel":"book","type":"update","data":[{"symbol":"BTC/USD","bids":[],"asks":[{"price":62810.3,"qty":0.00000000},{"price":62810.7,"qty":0.00222509},{"price":62794.7,"qty":0.35088152}],"checksum":429499939,"timestamp":"2026-08-16T23:37:25.593747Z"}]}}
{"rx_ns": 42910975354500, "frame": {"channel":"book","type":"update","data":[{"symbol":"BTC/USD","bids":[],"asks":[{"price":62794.8,"qty":5.59261501}],"checksum":3916550877,"timestamp":"2026-08-16T23:37:25.593774Z"}]}}
{"rx_ns": 42910975367000, "frame": {"channel":"book","type":"update","data":[{"symbol":"BTC/USD","bids":[],"asks":[{"price":62794.8,"qty":5.43338102}],"checksum":39271468,"timestamp":"2026-08-16T23:37:25.593801Z"}]}}
{"rx_ns": 42910975377300, "frame": {"channel":"book","type":"update","data":[{"symbol":"BTC/USD","bids":[],"asks":[{"price":62796.0,"qty":0.00000000},{"price":62810.8,"qty":1.59575715}],"checksum":1926668286,"timestamp":"2026-08-16T23:37:25.593997Z"}]}}
{"rx_ns": 42910975388000, "frame": {"channel":"book","type":"update","data":[{"symbol":"BTC/USD","bids":[],"asks":[{"price":62793.6,"qty":0.08140152}],"checksum":2008821468,"timestamp":"2026-08-16T23:37:25.594134Z"}]}}
{"rx_ns": 42910975396500, "frame": {"channel":"book","type":"update","data":[{"symbol":"BTC/USD","bids":[],"asks":[{"price":62793.6,"qty":0.16100152}],"checksum":4192410485,"timestamp":"2026-08-16T23:37:25.594750Z"}]}}
{"rx_ns": 42910975406600, "frame": {"channel":"book","type":"update","data":[{"symbol":"BTC/USD","bids":[],"asks":[{"price":62793.6,"qty":0.95726101}],"checksum":3060720704,"timestamp":"2026-08-16T23:37:25.595756Z"}]}}
{"rx_ns": 42910975416500, "frame": {"channel":"book","type":"update","data":[{"symbol":"BTC/USD","bids":[{"price":62779.7,"qty":0.00000000},{"price":62772.2,"qty":0.07963741}],"asks":[],"checksum":3060720704,"timestamp":"2026-08-16T23:37:25.595956Z"}]}}
{"rx_ns": 42910975426600, "frame": {"channel":"book","type":"update","data":[{"symbol":"BTC/USD","bids":[],"asks":[{"price":62793.6,"qty":1.11653863}],"checksum":3151525005,"timestamp":"2026-08-16T23:37:25.596229Z"}]}}
{"rx_ns": 42910975437200, "frame": {"channel":"book","type":"update","data":[{"symbol":"BTC/USD","bids":[{"price":62793.5,"qty":0.03646524}],"asks":[],"checksum":155797922,"timestamp":"2026-08-16T23:37:25.596279Z"}]}}
{"rx_ns": 42910975500700, "frame": {"channel":"book","type":"update","data":[{"symbol":"BTC/USD","bids":[],"asks":[{"price":62798.0,"qty":0.00422189}],"checksum":3717398103,"timestamp":"2026-08-16T23:37:25.598790Z"}]}}
{"rx_ns": 42910975515600, "frame": {"channel":"book","type":"update","data":[{"symbol":"BTC/USD","bids":[],"asks":[{"price":62800.0,"qty":0.00422176}],"checksum":81595150,"timestamp":"2026-08-16T23:37:25.598975Z"}]}}
{"rx_ns": 42910975525300, "frame": {"channel":"book","type":"update","data":[{"symbol":"BTC/USD","bids":[],"asks":[{"price":62802.0,"qty":0.00740624}],"checksum":81595150,"timestamp":"2026-08-16T23:37:25.599093Z"}]}}
{"rx_ns": 42910978849000, "frame": {"channel":"book","type":"update","data":[{"symbol":"BTC/USD","bids":[],"asks":[{"price":62794.8,"qty":5.35378102}],"checksum":1645088991,"timestamp":"2026-08-16T23:37:25.604095Z"}]}}
{"rx_ns": 42910986351300, "frame": {"channel":"book","type":"update","data":[{"symbol":"BTC/USD","bids":[],"asks":[{"price":62809.9,"qty":0.00318421}],"checksum":1645088991,"timestamp":"2026-08-16T23:37:25.610708Z"}]}}
{"rx_ns": 42910986427400, "frame": {"channel":"book","type":"update","data":[{"symbol":"BTC/USD","bids":[{"price":62781.7,"qty":0.00005100}],"asks":[],"checksum":3490493081,"timestamp":"2026-08-16T23:37:25.610754Z"}]}}
{"rx_ns": 42911010756400, "frame": {"channel":"book","type":"update","data":[{"symbol":"BTC/USD","bids":[{"price":62782.0,"qty":0.00422297}],"asks":[],"checksum":2028456910,"timestamp":"2026-08-16T23:37:25.635416Z"}]}}
{"rx_ns": 42911011689700, "frame": {"channel":"book","type":"update","data":[{"symbol":"BTC/USD","bids":[{"price":62780.0,"qty":0.00422310}],"asks":[],"checksum":2028456910,"timestamp":"2026-08-16T23:37:25.635555Z"}]}}
{"rx_ns": 42911011722400, "frame": {"channel":"book","type":"update","data":[{"symbol":"BTC/USD","bids":[{"price":62778.0,"qty":0.00740907}],"asks":[],"checksum":2028456910,"timestamp":"2026-08-16T23:37:25.635640Z"}]}}
{"rx_ns": 42911011745700, "frame": {"channel":"book","type":"update","data":[{"symbol":"BTC/USD","bids":[],"asks":[{"price":62794.7,"qty":0.16598472},{"price":62794.6,"qty":0.18489680}],"checksum":2936487497,"timestamp":"2026-08-16T23:37:25.636612Z"}]}}
{"rx_ns": 42911022672000, "frame": {"channel":"book","type":"update","data":[{"symbol":"BTC/USD","bids":[{"price":62779.9,"qty":0.15927762}],"asks":[],"checksum":2936487497,"timestamp":"2026-08-16T23:37:25.646247Z"}]}}
{"rx_ns": 42911061296000, "frame": {"channel":"book","type":"update","data":[{"symbol":"BTC/USD","bids":[{"price":62779.9,"qty":0.00000000},{"price":62773.8,"qty":0.03185496}],"asks":[],"checksum":2936487497,"timestamp":"2026-08-16T23:37:25.686564Z"}]}}
{"rx_ns": 42911077498500, "frame": {"channel":"book","type":"update","data":[{"symbol":"BTC/USD","bids":[],"asks":[{"price":62794.8,"qty":5.24378102}],"checksum":2828043326,"timestamp":"2026-08-16T23:37:25.693952Z"}]}}
{"rx_ns": 42911077547600, "frame": {"channel":"book","type":"update","data":[{"symbol":"BTC/USD","bids":[],"asks":[{"price":62793.6,"qty":1.22653863}],"checksum":4002292958,"timestamp":"2026-08-16T23:37:25.694724Z"}]}}
{"rx_ns": 42911077559100, "frame": {"channel":"book","type":"update","data":[{"symbol":"BTC/USD","bids":[],"asks":[{"price":62793.6,"qty":1.24584855}],"checksum":517189455,"timestamp":"2026-08-16T23:37:25.695944Z"}]}}
{"rx_ns": 42911077567900, "frame": {"channel":"book","type":"update","data":[{"symbol":"BTC/USD","bids":[{"price":62779.8,"qty":0.15927762}],"asks":[],"checksum":517189455,"timestamp":"2026-08-16T23:37:25.696259Z"}]}}
{"rx_ns": 42911077576800, "frame": {"channel":"book","type":"update","data":[{"symbol":"BTC/USD","bids":[],"asks":[{"price":62793.6,"qty":1.32384855}],"checksum":3478771735,"timestamp":"2026-08-16T23:37:25.696482Z"}]}}
{"rx_ns": 42911107304100, "frame": {"channel":"book","type":"update","data":[{"symbol":"BTC/USD","bids":[{"price":62793.5,"qty":0.03686337}],"asks":[],"checksum":4007975360,"timestamp":"2026-08-16T23:37:25.730121Z"}]}}
{"rx_ns": 42911124899300, "frame": {"channel":"book","type":"update","data":[{"symbol":"BTC/USD","bids":[],"asks":[{"price":62794.8,"qty":1.45304952},{"price":62793.6,"qty":5.11469074}],"checksum":1352614562,"timestamp":"2026-08-16T23:37:25.747207Z"}]}}
{"rx_ns": 42911124990400, "frame": {"channel":"book","type":"update","data":[{"symbol":"BTC/USD","bids":[],"asks":[{"price":62794.6,"qty":0.00000000},{"price":62810.4,"qty":0.13109402},{"price":62796.6,"qty":0.18489680}],"checksum":2032201701,"timestamp":"2026-08-16T23:37:25.749991Z"}]}}
{"rx_ns": 42911165224500, "frame": {"channel":"book","type":"update","data":[{"symbol":"BTC/USD","bids":[{"price":62793.5,"qty":0.03726150}],"asks":[],"checksum":429493614,"timestamp":"2026-08-16T23:37:25.785284Z"}]}}
{"rx_ns": 42911165288000, "frame": {"channel":"book","type":"update","data":[{"symbol":"BTC/USD","bids":[],"asks":[{"price":62794.7,"qty":0.11000000},{"price":62793.6,"qty":5.17067546}],"checksum":4161908341,"timestamp":"2026-08-16T23:37:25.786608Z"}]}}
{"rx_ns": 42911170195700, "frame": {"channel":"book","type":"update","data":[{"symbol":"BTC/USD","bids":[],"asks":[{"price":62794.7,"qty":0.00000000},{"price":62810.4,"qty":0.13109402}],"checksum":4002293099,"timestamp":"2026-08-16T23:37:25.795179Z"}]}}
{"rx_ns": 42911171105800, "frame": {"channel":"book","type":"update","data":[{"symbol":"BTC/USD","bids":[],"asks":[{"price":62796.6,"qty":0.00000000},{"price":62810.7,"qty":0.00222509},{"price":62808.9,"qty":0.21355515}],"checksum":2833370573,"timestamp":"2026-08-16T23:37:25.796418Z"}]}}
{"rx_ns": 42911229769400, "frame": {"channel":"book","type":"update","data":[{"symbol":"BTC/USD","bids":[{"price":62793.5,"qty":0.03765963}],"asks":[],"checksum":3045787538,"timestamp":"2026-08-16T23:37:25.840329Z"}]}}
{"rx_ns": 42911299806000, "frame": {"channel":"book","type":"update","data":[{"symbol":"BTC/USD","bids":[{"price":62793.5,"qty":0.03805776}],"asks":[],"checksum":2383411611,"timestamp":"2026-08-16T23:37:25.896149Z"}]}}
{"rx_ns": 42911344341600, "frame": {"channel":"book","type":"update","data":[{"symbol":"BTC/USD","bids":[{"price":62793.5,"qty":0.03845589}],"asks":[],"checksum":353784763,"timestamp":"2026-08-16T23:37:25.952216Z"}]}}
{"rx_ns": 42911347488800, "frame": {"channel":"book","type":"update","data":[{"symbol":"BTC/USD","bids":[],"asks":[{"price":62794.8,"qty":1.45265139},{"price":62793.6,"qty":5.17107359}],"checksum":1812003054,"timestamp":"2026-08-16T23:37:25.959958Z"}]}}
{"rx_ns": 42911347555700, "frame": {"channel":"book","type":"update","data":[{"symbol":"BTC/USD","bids":[{"price":62793.5,"qty":0.01714297}],"asks":[],"checksum":2124107990,"timestamp":"2026-08-16T23:37:25.965743Z"}]}}
{"rx_ns": 42911347585900, "frame": {"channel":"book","type":"update","data":[{"symbol":"BTC/USD","bids":[{"price":62792.3,"qty":0.02131292}],"asks":[],"checksum":1277878187,"timestamp":"2026-08-16T23:37:25.966882Z"}]}}
{"rx_ns": 42911352964200, "frame": {"channel":"book","type":"update","data":[{"symbol":"BTC/USD","bids":[{"price":62793.5,"qty":0.01674484}],"asks":[],"checksum":4035872163,"timestamp":"2026-08-16T23:37:25.976331Z"}]}}
{"rx_ns": 42911420476900, "frame": {"channel":"book","type":"update","data":[{"symbol":"BTC/USD","bids":[{"price":62793.5,"qty":0.01634671}],"asks":[],"checksum":711502303,"timestamp":"2026-08-16T23:37:26.036421Z"}]}}
{"rx_ns": 42911472400400, "frame": {"channel":"book","type":"update","data":[{"symbol":"BTC/USD","bids":[{"price":62793.5,"qty":0.01594858}],"asks":[],"checksum":4156906713,"timestamp":"2026-08-16T23:37:26.097856Z"}]}}
{"rx_ns": 42911537564100, "frame": {"channel":"book","type":"update","data":[{"symbol":"BTC/USD","bids":[{"price":62793.5,"qty":0.01555045}],"asks":[],"checksum":2717056460,"timestamp":"2026-08-16T23:37:26.163306Z"}]}}
{"rx_ns": 42911561981600, "frame": {"channel":"book","type":"update","data":[{"symbol":"BTC/USD","bids":[],"asks":[{"price":62797.4,"qty":0.00005100}],"checksum":1942515925,"timestamp":"2026-08-16T23:37:26.187901Z"}]}}
{"rx_ns": 42911613994000, "frame": {"channel":"book","type":"update","data":[{"symbol":"BTC/USD","bids":[],"asks":[{"price":62794.8,"qty":1.45165139}],"checksum":1238281393,"timestamp":"2026-08-16T23:37:26.239707Z"}]}}
{"rx_ns": 42911747977500, "frame": {"channel":"heartbeat"}}
{"rx_ns": 42912289961800, "frame": {"channel":"book","type":"update","data":[{"symbol":"BTC/USD","bids":[{"price":62784.6,"qty":0.00000000},{"price":62774.0,"qty":0.74369300},{"price":62785.2,"qty":0.00009500}],"asks":[],"checksum":3188426293,"timestamp":"2026-08-16T23:37:26.913423Z"}]}}
{"rx_ns": 42912394235200, "frame": {"channel":"book","type":"update","data":[{"symbol":"BTC/USD","bids":[{"price":62793.5,"qty":0.01565045}],"asks":[],"checksum":3170033834,"timestamp":"2026-08-16T23:37:27.018565Z"}]}}
{"rx_ns": 42912529958300, "frame": {"channel":"book","type":"update","data":[{"symbol":"BTC/USD","bids":[{"price":62779.8,"qty":0.00000000},{"price":62774.0,"qty":0.74369300}],"asks":[],"checksum":3170033834,"timestamp":"2026-08-16T23:37:27.155973Z"}]}}
{"rx_ns": 42912533099800, "frame": {"channel":"book","type":"update","data":[{"symbol":"BTC/USD","bids":[{"price":62784.7,"qty":0.00000000},{"price":62773.8,"qty":0.03185496},{"price":62784.1,"qty":0.00318497}],"asks":[],"checksum":1073902054,"timestamp":"2026-08-16T23:37:27.158354Z"}]}}
{"rx_ns": 42912534745900, "frame": {"channel":"book","type":"update","data":[{"symbol":"BTC/USD","bids":[],"asks":[{"price":62804.2,"qty":0.00000000},{"price":62810.7,"qty":0.00222509},{"price":62803.6,"qty":0.00318497}],"checksum":1073902054,"timestamp":"2026-08-16T23:37:27.158597Z"}]}}
{"rx_ns": 42912571028800, "frame": {"channel":"book","type":"update","data":[{"symbol":"BTC/USD","bids":[{"price":62779.7,"qty":0.15927762}],"asks":[],"checksum":1073902054,"timestamp":"2026-08-16T23:37:27.196330Z"}]}}
{"rx_ns": 42912682152400, "frame": {"channel":"book","type":"update","data":[{"symbol":"BTC/USD","bids":[],"asks":[{"price":62793.6,"qty":5.17207359}],"checksum":1479992716,"timestamp":"2026-08-16T23:37:27.305061Z"}]}}
{"rx_ns": 42912747287300, "frame": {"channel":"heartbeat"}}
{"rx_ns": 42912830335900, "frame": {"channel":"book","type":"update","data":[{"symbol":"BTC/USD","bids":[],"asks":[{"price":62793.6,"qty":5.18007359}],"checksum":1023654041,"timestamp":"2026-08-16T23:37:27.456429Z"}]}}
{"rx_ns": 42913068051700, "frame": {"channel":"book","type":"update","data":[{"symbol":"BTC/USD","bids":[{"price":62780.8,"qty":0.00000000},{"price":62774.0,"qty":0.74369300}],"asks":[],"checksum":1023654041,"timestamp":"2026-08-16T23:37:27.693381Z"}]}}
{"rx_ns": 42913069680300, "frame": {"channel":"book","type":"update","data":[{"symbol":"BTC/USD","bids":[{"price":62779.6,"qty":0.79643604}],"asks":[],"checksum":1023654041,"timestamp":"2026-08-16T23:37:27.694854Z"}]}}
{"rx_ns": 42913070973800, "frame": {"channel":"book","type":"update","data":[{"symbol":"BTC/USD","bids":[{"price":62778.6,"qty":0.09784428}],"asks":[],"checksum":1023654041,"timestamp":"2026-08-16T23:37:27.696264Z"}]}}
{"rx_ns": 42913071026200, "frame": {"channel":"book","type":"update","data":[{"symbol":"BTC/USD","bids":[{"price":62778.6,"qty":0.08817369}],"asks":[],"checksum":1023654041,"timestamp":"2026-08-16T23:37:27.697244Z"}]}}
{"rx_ns": 42913746698700, "frame": {"channel":"heartbeat"}}
{"rx_ns": 42914338679700, "frame": {"channel":"book","type":"update","data":[{"symbol":"BTC/USD","bids":[{"price":62785.2,"qty":0.00000000},{"price":62774.0,"qty":0.74369300},{"price":62784.6,"qty":0.00009500}],"asks":[],"checksum":2216900534,"timestamp":"2026-08-16T23:37:28.964640Z"}]}}
{"rx_ns": 42914747188600, "frame": {"channel":"heartbeat"}}
{"rx_ns": 42915747913900, "frame": {"channel":"heartbeat"}}
{"rx_ns": 42916459421700, "frame": {"channel":"book","type":"update","data":[{"symbol":"BTC/USD","bids":[{"price":62782.1,"qty":0.79640506}],"asks":[],"checksum":3358324374,"timestamp":"2026-08-16T23:37:31.082701Z"}]}}
{"rx_ns": 42916459488500, "frame": {"channel":"book","type":"update","data":[{"symbol":"BTC/USD","bids":[{"price":62780.9,"qty":0.06960000}],"asks":[],"checksum":3358324374,"timestamp":"2026-08-16T23:37:31.083984Z"}]}}
{"rx_ns": 42916498920400, "frame": {"channel":"book","type":"update","data":[{"symbol":"BTC/USD","bids":[{"price":62782.0,"qty":0.00000000},{"price":62774.2,"qty":0.02867420}],"asks":[],"checksum":688615201,"timestamp":"2026-08-16T23:37:31.124655Z"}]}}
{"rx_ns": 42916569036400, "frame": {"channel":"book","type":"update","data":[{"symbol":"BTC/USD","bids":[{"price":62780.9,"qty":0.00000000},{"price":62774.0,"qty":0.74369300}],"asks":[],"checksum":688615201,"timestamp":"2026-08-16T23:37:31.194906Z"}]}}
{"rx_ns": 42916581161200, "frame": {"channel":"book","type":"update","data":[{"symbol":"BTC/USD","bids":[{"price":62791.2,"qty":0.00164300}],"asks":[],"checksum":416759365,"timestamp":"2026-08-16T23:37:31.206414Z"}]}}
{"rx_ns": 42916583038700, "frame": {"channel":"book","type":"update","data":[{"symbol":"BTC/USD","bids":[{"price":62785.0,"qty":0.05598472}],"asks":[],"checksum":1400058470,"timestamp":"2026-08-16T23:37:31.207772Z"}]}}
{"rx_ns": 42916590391500, "frame": {"channel":"book","type":"update","data":[{"symbol":"BTC/USD","bids":[{"price":62779.7,"qty":0.00000000},{"price":62774.0,"qty":0.74369300}],"asks":[],"checksum":1400058470,"timestamp":"2026-08-16T23:37:31.214769Z"}]}}
{"rx_ns": 42916590456000, "frame": {"channel":"book","type":"update","data":[{"symbol":"BTC/USD","bids":[],"asks":[{"price":62805.2,"qty":1.59575715}],"checksum":1400058470,"timestamp":"2026-08-16T23:37:31.215075Z"}]}}
{"rx_ns": 42916594711600, "frame": {"channel":"book","type":"update","data":[{"symbol":"BTC/USD","bids":[],"asks":[{"price":62805.1,"qty":0.00222509}],"checksum":1400058470,"timestamp":"2026-08-16T23:37:31.219200Z"}]}}
{"rx_ns": 42916595122300, "frame": {"channel":"book","type":"update","data":[{"symbol":"BTC/USD","bids":[],"asks":[{"price":62808.9,"qty":0.02865835},{"price":62796.6,"qty":0.18489680}],"checksum":2789801949,"timestamp":"2026-08-16T23:37:31.220461Z"}]}}
{"rx_ns": 42916598236500, "frame": {"channel":"book","type":"update","data":[{"symbol":"BTC/USD","bids":[{"price":62782.1,"qty":0.00000000},{"price":62773.8,"qty":0.03185496}],"asks":[],"checksum":1782937448,"timestamp":"2026-08-16T23:37:31.220769Z"}]}}
{"rx_ns": 42916598258000, "frame": {"channel":"book","type":"update","data":[{"symbol":"BTC/USD","bids":[{"price":62781.4,"qty":0.79641314}],"asks":[],"checksum":1782937448,"timestamp":"2026-08-16T23:37:31.222402Z"}]}}
{"rx_ns": 42916621067300, "frame": {"channel":"book","type":"update","data":[{"symbol":"BTC/USD","bids":[{"price":62779.2,"qty":0.15927762}],"asks":[],"checksum":1782937448,"timestamp":"2026-08-16T23:37:31.246426Z"}]}}
{"rx_ns": 42916664686200, "frame": {"channel":"book","type":"update","data":[{"symbol":"BTC/USD","bids":[{"price":62779.2,"qty":0.00000000},{"price":62774.0,"qty":0.74369300}],"asks":[],"checksum":1782937448,"timestamp":"2026-08-16T23:37:31.287828Z"}]}}
{"rx_ns": 42916671172600, "frame": {"channel":"book","type":"update","data":[{"symbol":"BTC/USD","bids":[{"price":62778.1,"qty":0.15927762}],"asks":[],"checksum":1782937448,"timestamp":"2026-08-16T23:37:31.296402Z"}]}}
{"rx_ns": 42916677594400, "frame": {"channel":"book","type":"update","data":[{"symbol":"BTC/USD","bids":[{"price":62778.0,"qty":0.00422324}],"asks":[],"checksum":1782937448,"timestamp":"2026-08-16T23:37:31.302588Z"}]}}
{"rx_ns": 42916699558800, "frame": {"channel":"book","type":"update","data":[{"symbol":"BTC/USD","bids":[{"price":62792.3,"qty":0.00000000},{"price":62774.0,"qty":0.74369300}],"asks":[],"checksum":3752802498,"timestamp":"2026-08-16T23:37:31.324194Z"}]}}
{"rx_ns": 42916700818600, "frame": {"channel":"book","type":"update","data":[{"symbol":"BTC/USD","bids":[{"price":62791.0,"qty":0.02131292}],"asks":[],"checksum":3211923694,"timestamp":"2026-08-16T23:37:31.325700Z"}]}}
{"rx_ns": 42916703977000, "frame": {"channel":"book","type":"update","data":[{"symbol":"BTC/USD","bids":[{"price":62780.0,"qty":0.00000000},{"price":62774.0,"qty":0.74369300}],"asks":[],"checksum":3211923694,"timestamp":"2026-08-16T23:37:31.329785Z"}]}}
{"rx_ns": 42916762748400, "frame": {"channel":"heartbeat"}}
{"rx_ns": 42916768739600, "frame": {"channel":"book","type":"update","data":[{"symbol":"BTC/USD","bids":[],"asks":[{"price":62804.0,"qty":0.00000000},{"price":62808.9,"qty":0.02865835}],"checksum":3211923694,"timestamp":"2026-08-16T23:37:31.374495Z"}]}}
{"rx_ns": 42916768795900, "frame": {"channel":"book","type":"update","data":[{"symbol":"BTC/USD","bids":[{"price":62793.5,"qty":0.00049813}],"asks":[],"checksum":1313096917,"timestamp":"2026-08-16T23:37:31.379798Z"}]}}
{"rx_ns": 42916768810300, "frame": {"channel":"book","type":"update","data":[{"symbol":"BTC/USD","bids":[{"price":62784.1,"qty":0.00000000},{"price":62773.8,"qty":0.03185496},{"price":62783.0,"qty":0.00318497}],"asks":[],"checksum":4263316697,"timestamp":"2026-08-16T23:37:31.382176Z"}]}}
{"rx_ns": 42916768823200, "frame": {"channel":"book","type":"update","data":[{"symbol":"BTC/USD","bids":[],"asks":[{"price":62803.6,"qty":0.00000000},{"price":62809.9,"qty":0.00318421},{"price":62802.4,"qty":0.00318497}],"checksum":4263316697,"timestamp":"2026-08-16T23:37:31.382425Z"}]}}
{"rx_ns": 42916802732000, "frame": {"channel":"book","type":"update","data":[{"symbol":"BTC/USD","bids":[{"price":62781.4,"qty":0.00000000},{"price":62773.8,"qty":0.03185496}],"asks":[],"checksum":4263316697,"timestamp":"2026-08-16T23:37:31.423248Z"}]}}
{"rx_ns": 42916802837400, "frame": {"channel":"book","type":"update","data":[{"symbol":"BTC/USD","bids":[{"price":62791.0,"qty":0.00000000},{"price":62772.7,"qty":0.00796524}],"asks":[],"checksum":1579795993,"timestamp":"2026-08-16T23:37:31.424241Z"}]}}
{"rx_ns": 42916802857400, "frame": {"channel":"book","type":"update","data":[{"symbol":"BTC/USD","bids":[{"price":62792.0,"qty":0.02131292}],"asks":[],"checksum":2438003544,"timestamp":"2026-08-16T23:37:31.424431Z"}]}}
{"rx_ns": 42916802879100, "frame": {"channel":"book","type":"update","data":[{"symbol":"BTC/USD","bids":[{"price":62780.7,"qty":0.79642200}],"asks":[],"checksum":2438003544,"timestamp":"2026-08-16T23:37:31.424860Z"}]}}
{"rx_ns": 42916804068700, "frame": {"channel":"book","type":"update","data":[{"symbol":"BTC/USD","bids":[{"price":62779.6,"qty":0.00000000},{"price":62773.8,"qty":0.03185496}],"asks":[],"checksum":2438003544,"timestamp":"2026-08-16T23:37:31.429927Z"}]}}
{"rx_ns": 42916805910000, "frame": {"channel":"book","type":"update","data":[{"symbol":"BTC/USD","bids":[{"price":62778.4,"qty":0.79645161}],"asks":[],"checksum":2438003544,"timestamp":"2026-08-16T23:37:31.431470Z"}]}}
{"rx_ns": 42916812416000, "frame": {"channel":"book","type":"update","data":[{"symbol":"BTC/USD","bids":[],"asks":[{"price":62805.3,"qty":0.00000000},{"price":62809.9,"qty":0.00318421}],"checksum":2438003544,"timestamp":"2026-08-16T23:37:31.433890Z"}]}}
{"rx_ns": 42916812477400, "frame": {"channel":"book","type":"update","data":[{"symbol":"BTC/USD","bids":[{"price":62780.7,"qty":0.00000000},{"price":62773.8,"qty":0.03185496}],"asks":[],"checksum":2438003544,"timestamp":"2026-08-16T23:37:31.434515Z"}]}}
{"rx_ns": 42916812528000, "frame": {"channel":"book","type":"update","data":[{"symbol":"BTC/USD","bids":[],"asks":[{"price":62800.9,"qty":2.38850205}],"checksum":2438003544,"timestamp":"2026-08-16T23:37:31.435905Z"}]}}
{"rx_ns": 42916812545300, "frame": {"channel":"book","type":"update","data":[{"symbol":"BTC/USD","bids":[{"price":62778.4,"qty":0.00000000},{"price":62772.7,"qty":0.00796524}],"asks":[],"checksum":2438003544,"timestamp":"2026-08-16T23:37:31.436780Z"}]}}
