{"captured_at": "2026-08-16T23:37:03.402652+00:00", "url": "wss://ws.kraken.com/v2", "venue": "kraken", "symbol": "MINA/GBP", "depth": 25, "subscribe": "{\"method\":\"subscribe\",\"params\":{\"channel\":\"book\",\"symbol\":[\"MINA/GBP\"],\"depth\":25,\"snapshot\":true}}", "tool_version": "0.1.0", "clock": "perf_counter_ns", "capture_mode": "baseline", "cycles": 1, "origin_sent": null, "handshake_status": "HTTP/1.1 101 Switching Protocols"}
{"rx_ns": 42890204228400, "dir": "tx", "frame": {"method":"subscribe","params":{"channel":"book","symbol":["MINA/GBP"],"depth":25,"snapshot":true}}}
{"rx_ns": 42890204502000, "frame": {"channel":"status","type":"update","data":[{"version":"2.0.10","system":"online","api_version":"v2","connection_id":3007355780899554854}]}}
{"rx_ns": 42890222687400, "frame": {"method":"subscribe","result":{"channel":"book","depth":25,"snapshot":true,"symbol":"MINA/GBP"},"success":true,"time_in":"2026-08-16T23:37:04.849274Z","time_out":"2026-08-16T23:37:04.849309Z"}}
{"rx_ns": 42890613745900, "frame": {"channel":"book","type":"snapshot","data":[{"symbol":"MINA/GBP","bids":[{"price":0.0286,"qty":74198.19125726},{"price":0.0285,"qty":18831.49589194},{"price":0.0280,"qty":12925.63811394},{"price":0.0279,"qty":1475.94222688},{"price":0.0276,"qty":4207.74770000},{"price":0.0273,"qty":1846.46965000},{"price":0.0271,"qty":525.46740467},{"price":0.0270,"qty":370.37037037},{"price":0.0266,"qty":535.34461152},{"price":0.0260,"qty":547.69871794},{"price":0.0256,"qty":1000.00000000},{"price":0.0253,"qty":23363.09766166},{"price":0.0240,"qty":90.00000000},{"price":0.0225,"qty":2222.22222223},{"price":0.0210,"qty":2000.00000000},{"price":0.0182,"qty":3000.00000000},{"price":0.0124,"qty":90.00000000},{"price":0.0100,"qty":50.00000000},{"price":0.0086,"qty":50.00000000},{"price":0.0080,"qty":90.00000000},{"price":0.0070,"qty":120.00000000},{"price":0.0057,"qty":877.19298245},{"price":0.0050,"qty":120.00000000},{"price":0.0040,"qty":200.00000000},{"price":0.0030,"qty":143.33333334}],"asks":[{"price":0.0288,"qty":32416.38964164},{"price":0.0289,"qty":18831.49589194},{"price":0.0290,"qty":1740.00000000},{"price":0.0294,"qty":1740.00000000},{"price":0.0296,"qty":1740.00000000},{"price":0.0299,"qty":1847.77578386},{"price":0.0301,"qty":1740.00000000},{"price":0.0303,"qty":1740.00000000},{"price":0.0304,"qty":1847.77578386},{"price":0.0309,"qty":1847.77578386},{"price":0.0489,"qty":1986.15467694},{"price":0.0600,"qty":1752.82392026},{"price":0.0800,"qty":3373.43721760},{"price":0.1150,"qty":67.55460411},{"price":0.1780,"qty":1814.14472703},{"price":0.2000,"qty":1814.14472703},{"price":0.2300,"qty":161.78901632},{"price":0.2600,"qty":510.62544699},{"price":0.2800,"qty":100.00000000},{"price":0.4790,"qty":2336.44859813},{"price":0.5300,"qty":90.00000000},{"price":0.5580,"qty":1792.11469534},{"price":0.5900,"qty":1209.42981802},{"price":0.6000,"qty":3017.83667372},{"price":0.6900,"qty":217.39130434}],"checksum":2570005138,"timestamp":"2026-08-16T23:37:04.190019Z"}]}}
{"rx_ns": 42890781516500, "frame": {"channel":"heartbeat"}}
{"rx_ns": 42891099229100, "frame": {"channel":"book","type":"update","data":[{"symbol":"MINA/GBP","bids":[{"price":0.0279,"qty":0.00000000},{"price":0.0020,"qty":5220.00000000},{"price":0.0277,"qty":1486.59884909}],"asks":[],"checksum":222201382,"timestamp":"2026-08-16T23:37:05.723653Z"}]}}
{"rx_ns": 42891109363800, "frame": {"channel":"book","type":"update","data":[{"symbol":"MINA/GBP","bids":[{"price":0.0280,"qty":0.00000000},{"price":0.0020,"qty":5220.00000000}],"asks":[],"checksum":2818891544,"timestamp":"2026-08-16T23:37:05.734968Z"}]}}
{"rx_ns": 42891120804100, "frame": {"channel":"book","type":"update","data":[{"symbol":"MINA/GBP","bids":[{"price":0.0278,"qty":13018.62844188}],"asks":[],"checksum":3531183883,"timestamp":"2026-08-16T23:37:05.746733Z"}]}}
{"rx_ns": 42891782966400, "frame": {"channel":"heartbeat"}}
{"rx_ns": 42892782954300, "frame": {"channel":"heartbeat"}}
{"rx_ns": 42893783455000, "frame": {"channel":"heartbeat"}}
{"rx_ns": 42894659250000, "frame": {"channel":"book","type":"update","data":[{"symbol":"MINA/GBP","bids":[{"price":0.0277,"qty":0.00000000},{"price":0.0020,"qty":5220.00000000},{"price":0.0279,"qty":1475.94222616}],"asks":[],"checksum":1283410063,"timestamp":"2026-08-16T23:37:09.285552Z"}]}}
{"rx_ns": 42894716028300, "frame": {"channel":"book","type":"update","data":[{"symbol":"MINA/GBP","bids":[{"price":0.0280,"qty":173.54195958}],"asks":[],"checksum":2854269840,"timestamp":"2026-08-16T23:37:09.342672Z"}]}}
{"rx_ns": 42894785402400, "frame": {"channel":"heartbeat"}}
{"rx_ns": 42895789146600, "frame": {"channel":"heartbeat"}}
{"rx_ns": 42896786052500, "frame": {"channel":"heartbeat"}}
{"rx_ns": 42897783944400, "frame": {"channel":"heartbeat"}}
{"rx_ns": 42898789218300, "frame": {"channel":"heartbeat"}}
{"rx_ns": 42899785036400, "frame": {"channel":"heartbeat"}}
{"rx_ns": 42900784212300, "frame": {"channel":"heartbeat"}}
{"rx_ns": 42901788014700, "frame": {"channel":"heartbeat"}}
{"rx_ns": 42902784796000, "frame": {"channel":"heartbeat"}}
{"rx_ns": 42903298518400, "frame": {"channel":"book","type":"update","data":[{"symbol":"MINA/GBP","bids":[{"price":0.0278,"qty":0.00000000},{"price":0.0030,"qty":143.33333334}],"asks":[],"checksum":3204759855,"timestamp":"2026-08-16T23:37:17.925764Z"}]}}
{"rx_ns": 42903316639900, "frame": {"channel":"book","type":"update","data":[{"symbol":"MINA/GBP","bids":[{"price":0.0280,"qty":13099.18007352}],"asks":[],"checksum":1054683491,"timestamp":"2026-08-16T23:37:17.943092Z"}]}}
{"rx_ns": 42903329999600, "frame": {"channel":"book","type":"update","data":[{"symbol":"MINA/GBP","bids":[{"price":0.0280,"qty":12925.63811394},{"price":0.0281,"qty":173.01796684}],"asks":[],"checksum":134748938,"timestamp":"2026-08-16T23:37:17.954451Z"}]}}
{"rx_ns": 42903789048300, "frame": {"channel":"heartbeat"}}
{"rx_ns": 42904787743800, "frame": {"channel":"heartbeat"}}
{"rx_ns": 42905361698300, "frame": {"channel":"book","type":"update","data":[{"symbol":"MINA/GBP","bids":[{"price":0.0279,"qty":0.00000000},{"price":0.0030,"qty":143.33333334},{"price":0.0277,"qty":1486.59884837}],"asks":[],"checksum":4067960158,"timestamp":"2026-08-16T23:37:19.988831Z"}]}}
{"rx_ns": 42905376792200, "frame": {"channel":"book","type":"update","data":[{"symbol":"MINA/GBP","bids":[{"price":0.0280,"qty":0.00000000},{"price":0.0030,"qty":143.33333334}],"asks":[],"checksum":1403715174,"timestamp":"2026-08-16T23:37:20.003142Z"}]}}
{"rx_ns": 42905407939900, "frame": {"channel":"book","type":"update","data":[{"symbol":"MINA/GBP","bids":[{"price":0.0278,"qty":13018.62844188}],"asks":[],"checksum":2309643305,"timestamp":"2026-08-16T23:37:20.034528Z"}]}}
{"rx_ns": 42905792104900, "frame": {"channel":"heartbeat"}}
{"rx_ns": 42906787775400, "frame": {"channel":"heartbeat"}}
{"rx_ns": 42907787690900, "frame": {"channel":"heartbeat"}}
{"rx_ns": 42908788405100, "frame": {"channel":"heartbeat"}}
{"rx_ns": 42908951930200, "frame": {"channel":"book","type":"update","data":[{"symbol":"MINA/GBP","bids":[{"price":0.0277,"qty":0.00000000},{"price":0.0030,"qty":143.33333334},{"price":0.0279,"qty":1475.94222544}],"asks":[],"checksum":1089777670,"timestamp":"2026-08-16T23:37:23.578512Z"}]}}
{"rx_ns": 42909790779400, "frame": {"channel":"heartbeat"}}
{"rx_ns": 42910788348400, "frame": {"channel":"heartbeat"}}
{"rx_ns": 42911787296100, "frame": {"channel":"heartbeat"}}
{"rx_ns": 42912789868400, "frame": {"channel":"heartbeat"}}
{"rx_ns": 42913793484100, "frame": {"channel":"heartbeat"}}
{"rx_ns": 42914787476700, "frame": {"channel":"heartbeat"}}
{"rx_ns": 42915787481900, "frame": {"channel":"heartbeat"}}
{"rx_ns": 42916789418200, "frame": {"channel":"heartbeat"}}
{"rx_ns": 42917440502100, "frame": {"channel":"book","type":"update","data":[{"symbol":"MINA/GBP","bids":[{"price":0.0278,"qty":0.00000000},{"price":0.0030,"qty":143.33333334}],"asks":[],"checksum":551175022,"timestamp":"2026-08-16T23:37:32.067001Z"}]}}
{"rx_ns": 42917452292800, "frame": {"channel":"book","type":"update","data":[{"symbol":"MINA/GBP","bids":[{"price":0.0280,"qty":12925.63811394}],"asks":[],"checksum":803308292,"timestamp":"2026-08-16T23:37:32.079744Z"}]}}
{"rx_ns": 42917791211800, "frame": {"channel":"heartbeat"}}
{"rx_ns": 42918788113800, "frame": {"channel":"heartbeat"}}
{"rx_ns": 42919503993600, "frame": {"channel":"book","type":"update","data":[{"symbol":"MINA/GBP","bids":[{"price":0.0279,"qty":0.00000000},{"price":0.0030,"qty":143.33333334},{"price":0.0277,"qty":1486.59884765}],"asks":[],"checksum":490375754,"timestamp":"2026-08-16T23:37:34.129941Z"}]}}
{"rx_ns": 42919512408200, "frame": {"channel":"book","type":"update","data":[{"symbol":"MINA/GBP","bids":[{"price":0.0280,"qty":0.00000000},{"price":0.0030,"qty":143.33333334}],"asks":[],"checksum":1883605192,"timestamp":"2026-08-16T23:37:34.139534Z"}]}}
{"rx_ns": 42919526034400, "frame": {"channel":"book","type":"update","data":[{"symbol":"MINA/GBP","bids":[{"price":0.0278,"qty":13018.62844188}],"asks":[],"checksum":1726542653,"timestamp":"2026-08-16T23:37:34.153267Z"}]}}
{"rx_ns": 42919788160200, "frame": {"channel":"heartbeat"}}
{"rx_ns": 42920788622400, "frame": {"channel":"heartbeat"}}
{"rx_ns": 42921788933100, "frame": {"channel":"heartbeat"}}
{"rx_ns": 42922795502200, "frame": {"channel":"heartbeat"}}
{"rx_ns": 42923056986500, "frame": {"channel":"book","type":"update","data":[{"symbol":"MINA/GBP","bids":[{"price":0.0277,"qty":0.00000000},{"price":0.0030,"qty":143.33333334},{"price":0.0279,"qty":1475.94222473}],"asks":[],"checksum":2568061605,"timestamp":"2026-08-16T23:37:37.680099Z"}]}}
{"rx_ns": 42923788747500, "frame": {"channel":"heartbeat"}}
{"rx_ns": 42924789374400, "frame": {"channel":"heartbeat"}}
{"rx_ns": 42925791214700, "frame": {"channel":"heartbeat"}}
{"rx_ns": 42926794092000, "frame": {"channel":"heartbeat"}}
{"rx_ns": 42927789697000, "frame": {"channel":"heartbeat"}}
{"rx_ns": 42928812291700, "frame": {"channel":"heartbeat"}}
{"rx_ns": 42929790243300, "frame": {"channel":"heartbeat"}}
{"rx_ns": 42930791605900, "frame": {"channel":"heartbeat"}}
{"rx_ns": 42931796761300, "frame": {"channel":"heartbeat"}}
{"rx_ns": 42932063747400, "frame": {"channel":"book","type":"update","data":[{"symbol":"MINA/GBP","bids":[{"price":0.0278,"qty":0.00000000},{"price":0.0030,"qty":143.33333334}],"asks":[],"checksum":1270370051,"timestamp":"2026-08-16T23:37:46.691308Z"}]}}
{"rx_ns": 42932080399000, "frame": {"channel":"book","type":"update","data":[{"symbol":"MINA/GBP","bids":[{"price":0.0280,"qty":12925.63811394}],"asks":[],"checksum":2347302876,"timestamp":"2026-08-16T23:37:46.707266Z"}]}}
{"rx_ns": 42932792188200, "frame": {"channel":"heartbeat"}}
{"rx_ns": 42933697643800, "frame": {"channel":"book","type":"update","data":[{"symbol":"MINA/GBP","bids":[{"price":0.0279,"qty":0.00000000},{"price":0.0030,"qty":143.33333334},{"price":0.0277,"qty":1486.59884693}],"asks":[],"checksum":848900270,"timestamp":"2026-08-16T23:37:48.321082Z"}]}}
{"rx_ns": 42933707747100, "frame": {"channel":"book","type":"update","data":[{"symbol":"MINA/GBP","bids":[{"price":0.0280,"qty":0.00000000},{"price":0.0030,"qty":143.33333334}],"asks":[],"checksum":3775386879,"timestamp":"2026-08-16T23:37:48.333198Z"}]}}
{"rx_ns": 42933721111000, "frame": {"channel":"book","type":"update","data":[{"symbol":"MINA/GBP","bids":[{"price":0.0278,"qty":13018.62844188}],"asks":[],"checksum":1229670873,"timestamp":"2026-08-16T23:37:48.347883Z"}]}}
{"rx_ns": 42933793076500, "frame": {"channel":"heartbeat"}}
{"rx_ns": 42934792653100, "frame": {"channel":"heartbeat"}}
{"rx_ns": 42935793555500, "frame": {"channel":"heartbeat"}}
{"rx_ns": 42936819779500, "frame": {"channel":"heartbeat"}}
{"rx_ns": 42937239302500, "frame": {"channel":"book","type":"update","data":[{"symbol":"MINA/GBP","bids":[{"price":0.0277,"qty":0.00000000},{"price":0.0030,"qty":143.33333334},{"price":0.0279,"qty":1475.94222401}],"asks":[],"checksum":2515523339,"timestamp":"2026-08-16T23:37:51.866621Z"}]}}
{"rx_ns": 42937794338800, "frame": {"channel":"heartbeat"}}
{"rx_ns": 42938795445000, "frame": {"channel":"heartbeat"}}
{"rx_ns": 42939793812700, "frame": {"channel":"heartbeat"}}
{"rx_ns": 42940795906000, "frame": {"channel":"heartbeat"}}
{"rx_ns": 42941793251400, "frame": {"channel":"heartbeat"}}
{"rx_ns": 42942795312900, "frame": {"channel":"heartbeat"}}
{"rx_ns": 42943795093200, "frame": {"channel":"heartbeat"}}
{"rx_ns": 42944793383500, "frame": {"channel":"heartbeat"}}
{"rx_ns": 42945797026300, "frame": {"channel":"heartbeat"}}
{"rx_ns": 42945911397300, "frame": {"channel":"book","type":"update","data":[{"symbol":"MINA/GBP","bids":[{"price":0.0278,"qty":0.00000000},{"price":0.0030,"qty":143.33333334}],"asks":[],"checksum":3071856548,"timestamp":"2026-08-16T23:38:00.534918Z"}]}}
{"rx_ns": 42945929947800, "frame": {"channel":"book","type":"update","data":[{"symbol":"MINA/GBP","bids":[{"price":0.0280,"qty":12925.63811394}],"asks":[],"checksum":1719528899,"timestamp":"2026-08-16T23:38:00.553247Z"}]}}
{"rx_ns": 42946822014500, "frame": {"channel":"heartbeat"}}
{"rx_ns": 42947795694200, "frame": {"channel":"heartbeat"}}
{"rx_ns": 42947844644900, "frame": {"channel":"book","type":"update","data":[{"symbol":"MINA/GBP","bids":[{"price":0.0279,"qty":0.00000000},{"price":0.0030,"qty":143.33333334},{"price":0.0277,"qty":1486.59884620}],"asks":[],"checksum":1420223629,"timestamp":"2026-08-16T23:38:02.471817Z"}]}}
{"rx_ns": 42947857844000, "frame": {"channel":"book","type":"update","data":[{"symbol":"MINA/GBP","bids":[{"price":0.0280,"qty":0.00000000},{"price":0.0030,"qty":143.33333334}],"asks":[],"checksum":3884385282,"timestamp":"2026-08-16T23:38:02.484796Z"}]}}
{"rx_ns": 42947871650800, "frame": {"channel":"book","type":"update","data":[{"symbol":"MINA/GBP","bids":[{"price":0.0278,"qty":13018.62844188}],"asks":[],"checksum":796171770,"timestamp":"2026-08-16T23:38:02.495712Z"}]}}
{"rx_ns": 42948798344900, "frame": {"channel":"heartbeat"}}
{"rx_ns": 42949799638700, "frame": {"channel":"heartbeat"}}
