{"rx_ns": 42948368457600, "frame": {"channel":"book","type":"update","data":[{"symbol":"BTC/USD","bids":[],"asks":[{"price":62810.8,"qty":0.00000000},{"price":62862.7,"qty":0.00600000}],"checksum":2996446060,"timestamp":"2026-08-16T23:38:02.997278Z"}]}}
{"rx_ns": 42948370744300, "frame": {"channel":"book","type":"update","data":[{"symbol":"BTC/USD","bids":[],"asks":[{"price":62809.9,"qty":0.24357326}],"checksum":2996446060,"timestamp":"2026-08-16T23:38:02.999046Z"}]}}
{"rx_ns": 42948386955900, "frame": {"channel":"book","type":"update","data":[{"symbol":"BTC/USD","bids":[],"asks":[{"price":62823.3,"qty":0.00000000},{"price":62864.1,"qty":1.66191821}],"checksum":2996446060,"timestamp":"2026-08-16T23:38:03.015841Z"}]}}
{"rx_ns": 42948425405900, "frame": {"channel":"book","type":"update","data":[{"symbol":"BTC/USD","bids":[],"asks":[{"price":62797.3,"qty":0.00000000},{"price":62864.2,"qty":5.56756520}],"checksum":1376800992,"timestamp":"2026-08-16T23:38:03.054422Z"}]}}
{"rx_ns": 42948427277100, "frame": {"channel":"book","type":"update","data":[{"symbol":"BTC/USD","bids":[],"asks":[{"price":62800.4,"qty":0.00000000},{"price":62865.4,"qty":0.05498517}],"checksum":2523327288,"timestamp":"2026-08-16T23:38:03.056420Z"}]}}
{"rx_ns": 42948430759600, "frame": {"channel":"book","type":"update","data":[{"symbol":"BTC/USD","bids":[],"asks":[{"price":62798.8,"qty":0.05598472}],"checksum":3020957121,"timestamp":"2026-08-16T23:38:03.057290Z"}]}}
{"rx_ns": 42948430801900, "frame": {"channel":"book","type":"update","data":[{"symbol":"BTC/USD","bids":[],"asks":[{"price":62807.5,"qty":0.14121008},{"price":62809.8,"qty":0.18712189}],"checksum":3020957121,"timestamp":"2026-08-16T23:38:03.057930Z"}]}}
{"rx_ns": 42948468390800, "frame": {"channel":"book","type":"update","data":[{"symbol":"BTC/USD","bids":[],"asks":[{"price":62809.3,"qty":0.50843600}],"checksum":3020957121,"timestamp":"2026-08-16T23:38:03.097288Z"}]}}
{"rx_ns": 42948470296200, "frame": {"channel":"book","type":"update","data":[{"symbol":"BTC/USD","bids":[],"asks":[{"price":62809.8,"qty":0.00222509},{"price":62808.1,"qty":0.18648880}],"checksum":3020957121,"timestamp":"2026-08-16T23:38:03.098394Z"}]}}
{"rx_ns": 42948470353100, "frame": {"channel":"book","type":"update","data":[{"symbol":"BTC/USD","bids":[],"asks":[{"price":62809.9,"qty":0.00000000},{"price":62864.2,"qty":5.56756520}],"checksum":3020957121,"timestamp":"2026-08-16T23:38:03.098447Z"}]}}
{"rx_ns": 42948471890400, "frame": {"channel":"book","type":"update","data":[{"symbol":"BTC/USD","bids":[],"asks":[{"price":62809.2,"qty":0.45457206}],"checksum":3020957121,"timestamp":"2026-08-16T23:38:03.098605Z"}]}}
{"rx_ns": 42948501453300, "frame": {"channel":"book","type":"update","data":[{"symbol":"BTC/USD","bids":[{"price":62775.8,"qty":0.00000000},{"price":62726.2,"qty":0.35581000}],"asks":[],"checksum":3020957121,"timestamp":"2026-08-16T23:38:03.129819Z"}]}}
{"rx_ns": 42948501521500, "frame": {"channel":"book","type":"update","data":[{"symbol":"BTC/USD","bids":[{"price":62776.1,"qty":0.00318592}],"asks":[],"checksum":3020957121,"timestamp":"2026-08-16T23:38:03.129851Z"}]}}
{"rx_ns": 42948501807900, "frame": {"channel":"book","type":"update","data":[{"symbol":"BTC/USD","bids":[{"price":62786.0,"qty":0.25613755}],"asks":[],"checksum":251579807,"timestamp":"2026-08-16T23:38:03.131269Z"}]}}
{"rx_ns": 42948506073700, "frame": {"channel":"book","type":"update","data":[{"symbol":"BTC/USD","bids":[{"price":62780.7,"qty":1.16002175}],"asks":[],"checksum":251579807,"timestamp":"2026-08-16T23:38:03.131291Z"}]}}
{"rx_ns": 42948547340900, "frame": {"channel":"book","type":"update","data":[{"symbol":"BTC/USD","bids":[{"price":62789.3,"qty":0.79631398}],"asks":[],"checksum":79891852,"timestamp":"2026-08-16T23:38:03.174339Z"}]}}
{"rx_ns": 42948618003600, "frame": {"channel":"book","type":"update","data":[{"symbol":"BTC/USD","bids":[{"price":62788.5,"qty":0.06164822}],"asks":[],"checksum":832162561,"timestamp":"2026-08-16T23:38:03.243681Z"}]}}
{"rx_ns": 42948648148600, "frame": {"channel":"book","type":"update","data":[{"symbol":"BTC/USD","bids":[],"asks":[{"price":62823.3,"qty":0.00094656}],"checksum":832162561,"timestamp":"2026-08-16T23:38:03.276646Z"}]}}
{"rx_ns": 42948686444600, "frame": {"channel":"heartbeat"}}
{"rx_ns": 42948897723600, "frame": {"channel":"book","type":"update","data":[{"symbol":"BTC/USD","bids":[],"asks":[{"price":62809.3,"qty":0.00000000},{"price":62864.1,"qty":1.66191821}],"checksum":832162561,"timestamp":"2026-08-16T23:38:03.525782Z"}]}}
{"rx_ns": 42948898185500, "frame": {"channel":"book","type":"update","data":[{"symbol":"BTC/USD","bids":[],"asks":[{"price":62809.2,"qty":0.00000000},{"price":62864.2,"qty":5.56756520}],"checksum":832162561,"timestamp":"2026-08-16T23:38:03.526903Z"}]}}
{"rx_ns": 42948898212600, "frame": {"channel":"book","type":"update","data":[{"symbol":"BTC/USD","bids":[],"asks":[{"price":62809.2,"qty":0.24761222}],"checksum":832162561,"timestamp":"2026-08-16T23:38:03.527126Z"}]}}
{"rx_ns": 42948998409000, "frame": {"channel":"book","type":"update","data":[{"symbol":"BTC/USD","bids":[],"asks":[{"price":62808.5,"qty":0.50849600}],"checksum":832162561,"timestamp":"2026-08-16T23:38:03.626072Z"}]}}
{"rx_ns": 42949004082800, "frame": {"channel":"book","type":"update","data":[{"symbol":"BTC/USD","bids":[{"price":62750.7,"qty":0.00000000},{"price":62728.5,"qty":0.00011160}],"asks":[],"checksum":832162561,"timestamp":"2026-08-16T23:38:03.627335Z"}]}}
{"rx_ns": 42949004142000, "frame": {"channel":"book","type":"update","data":[{"symbol":"BTC/USD","bids":[],"asks":[{"price":62807.5,"qty":0.33013440}],"checksum":832162561,"timestamp":"2026-08-16T23:38:03.627509Z"}]}}
{"rx_ns": 42949004171000, "frame": {"channel":"book","type":"update","data":[{"symbol":"BTC/USD","bids":[{"price":62764.2,"qty":0.00050000}],"asks":[],"checksum":832162561,"timestamp":"2026-08-16T23:38:03.629877Z"}]}}
{"rx_ns": 42949017172500, "frame": {"channel":"book","type":"update","data":[{"symbol":"BTC/USD","bids":[],"asks":[{"price":62793.0,"qty":0.15928698}],"checksum":3677478602,"timestamp":"2026-08-16T23:38:03.645075Z"}]}}
{"rx_ns": 42949017284000, "frame": {"channel":"book","type":"update","data":[{"symbol":"BTC/USD","bids":[],"asks":[{"price":62794.3,"qty":0.23893047}],"checksum":502623758,"timestamp":"2026-08-16T23:38:03.645214Z"}]}}
{"rx_ns": 42949017563000, "frame": {"channel":"book","type":"update","data":[{"symbol":"BTC/USD","bids":[],"asks":[{"price":62808.1,"qty":0.00159200},{"price":62808.0,"qty":0.18808110}],"checksum":502623758,"timestamp":"2026-08-16T23:38:03.646319Z"}]}}
{"rx_ns": 42949119166700, "frame": {"channel":"book","type":"update","data":[{"symbol":"BTC/USD","bids":[],"asks":[{"price":62798.9,"qty":0.00000000},{"price":62862.0,"qty":0.15142628}],"checksum":2928285168,"timestamp":"2026-08-16T23:38:03.747519Z"}]}}
{"rx_ns": 42949123710800, "frame": {"channel":"book","type":"update","data":[{"symbol":"BTC/USD","bids":[],"asks":[{"price":62798.8,"qty":0.00000000},{"price":62862.7,"qty":0.00600000},{"price":62800.4,"qty":0.05488265}],"checksum":1147329776,"timestamp":"2026-08-16T23:38:03.750065Z"}]}}
{"rx_ns": 42949123745500, "frame": {"channel":"book","type":"update","data":[{"symbol":"BTC/USD","bids":[],"asks":[{"price":62798.2,"qty":0.79620200}],"checksum":1896861654,"timestamp":"2026-08-16T23:38:03.750087Z"}]}}
{"rx_ns": 42949125974300, "frame": {"channel":"book","type":"update","data":[{"symbol":"BTC/USD","bids":[],"asks":[{"price":62800.4,"qty":0.00000000},{"price":62862.0,"qty":0.15142628},{"price":62798.1,"qty":0.05488265}],"checksum":157154957,"timestamp":"2026-08-16T23:38:03.751529Z"}]}}
{"rx_ns": 42949126031500, "frame": {"channel":"book","type":"update","data":[{"symbol":"BTC/USD","bids":[],"asks":[{"price":62808.0,"qty":0.00318430},{"price":62807.5,"qty":0.51503120}],"checksum":157154957,"timestamp":"2026-08-16T23:38:03.752166Z"}]}}
