{"captured_at": "2026-08-16T23:37:02.367538+00:00", "url": "wss://ws.kraken.com/v2", "venue": "kraken", "symbol": "BTC/USD", "depth": 100, "subscribe": "{\"method\":\"subscribe\",\"params\":{\"channel\":\"book\",\"symbol\":[\"BTC/USD\"],\"depth\":100,\"snapshot\":true}}", "tool_version": "0.1.0", "clock": "perf_counter_ns", "capture_mode": "baseline", "cycles": 1, "origin_sent": null, "handshake_status": "HTTP/1.1 101 Switching Protocols"}
{"rx_ns": 42889166115300, "dir": "tx", "frame": {"method":"subscribe","params":{"channel":"book","symbol":["BTC/USD"],"depth":100,"snapshot":true}}}
{"rx_ns": 42889166484200, "frame": {"channel":"status","type":"update","data":[{"version":"2.0.10","system":"online","api_version":"v2","connection_id":17001309753738053924}]}}
{"rx_ns": 42889179282100, "frame": {"method":"subscribe","result":{"channel":"book","depth":100,"snapshot":true,"symbol":"BTC/USD"},"success":true,"time_in":"2026-08-16T23:37:03.806372Z","time_out":"2026-08-16T23:37:03.806411Z"}}
{"rx_ns": 42889528297400, "frame": {"channel":"book","type":"snapshot","data":[{"symbol":"BTC/USD","bids":[{"price":62802.5,"qty":0.02987767},{"price":62800.7,"qty":0.05598472},{"price":62800.6,"qty":0.00005100},{"price":62797.5,"qty":0.00005100},{"price":62796.2,"qty":0.00019900},{"price":62795.7,"qty":0.00012700},{"price":62794.3,"qty":0.00005100},{"price":62794.0,"qty":0.00532806},{"price":62793.9,"qty":0.79625467},{"price":62793.1,"qty":0.00318620},{"price":62792.9,"qty":0.00015923},{"price":62792.1,"qty":0.00318511},{"price":62792.0,"qty":0.00532823},{"price":62791.9,"qty":0.79628063},{"price":62791.6,"qty":0.15923399},{"price":62791.4,"qty":0.06083209},{"price":62791.2,"qty":0.00164300},{"price":62790.6,"qty":0.02866671},{"price":62790.0,"qty":0.00596958},{"price":62789.9,"qty":0.09703642},{"price":62789.7,"qty":0.06960000},{"price":62789.4,"qty":0.12052463},{"price":62788.0,"qty":0.01313953},{"price":62787.5,"qty":0.01540085},{"price":62787.3,"qty":0.79633936},{"price":62786.3,"qty":0.00829459},{"price":62786.0,"qty":0.01313995},{"price":62785.6,"qty":0.10331161},{"price":62785.0,"qty":0.76851700},{"price":62784.0,"qty":0.00318553},{"price":62783.3,"qty":0.06960000},{"price":62782.4,"qty":0.00796401},{"price":62781.8,"qty":0.03185163},{"price":62780.3,"qty":0.00023884},{"price":62780.1,"qty":0.11000000},{"price":62779.7,"qty":2.38930372},{"price":62779.5,"qty":0.84467700},{"price":62778.4,"qty":0.18713170},{"price":62778.2,"qty":0.00080000},{"price":62777.6,"qty":0.12667900},{"price":62777.4,"qty":0.00039823},{"price":62776.4,"qty":0.01598519},{"price":62775.5,"qty":0.10292232},{"price":62774.1,"qty":0.79650684},{"price":62774.0,"qty":0.74369300},{"price":62773.8,"qty":0.13109402},{"price":62773.4,"qty":0.89108800},{"price":62772.6,"qty":0.06960000},{"price":62772.2,"qty":0.03427340},{"price":62770.7,"qty":7.97004904},{"price":62770.1,"qty":0.00050000},{"price":62770.0,"qty":0.00418410},{"price":62768.7,"qty":0.15390298},{"price":62767.9,"qty":0.01598519},{"price":62766.0,"qty":0.00005100},{"price":62765.2,"qty":0.00162380},{"price":62765.1,"qty":0.00303427},{"price":62765.0,"qty":0.03186489},{"price":62764.7,"qty":0.00318620},{"price":62764.4,"qty":0.06960000},{"price":62764.1,"qty":0.03911694},{"price":62763.6,"qty":0.23900000},{"price":62762.5,"qty":0.15985195},{"price":62762.2,"qty":7.96657665},{"price":62761.8,"qty":0.01300000},{"price":62761.2,"qty":0.00830438},{"price":62761.1,"qty":0.15920000},{"price":62760.3,"qty":7.96681948},{"price":62757.7,"qty":0.10643220},{"price":62757.6,"qty":2.12501460},{"price":62755.4,"qty":0.62650800},{"price":62755.0,"qty":0.01046131},{"price":62754.8,"qty":7.96751252},{"price":62753.6,"qty":0.00005000},{"price":62753.4,"qty":0.00005100},{"price":62750.9,"qty":0.01598519},{"price":62750.0,"qty":0.00331711},{"price":62749.1,"qty":0.22754396},{"price":62748.3,"qty":0.00159300},{"price":62747.5,"qty":0.03224409},{"price":62746.5,"qty":7.96856958},{"price":62742.8,"qty":0.06960000},{"price":62742.3,"qty":3.08434813},{"price":62741.4,"qty":0.00200000},{"price":62740.9,"qty":0.00005100},{"price":62740.8,"qty":2.05366319},{"price":62740.6,"qty":0.05490827},{"price":62737.4,"qty":15.00000000},{"price":62736.6,"qty":0.70609000},{"price":62736.5,"qty":5.64848720},{"price":62733.6,"qty":0.35581000},{"price":62730.2,"qty":0.06960000},{"price":62729.2,"qty":5.58112495},{"price":62728.5,"qty":0.00011160},{"price":62727.3,"qty":0.00711918},{"price":62725.9,"qty":5.57982866},{"price":62723.9,"qty":0.06960000},{"price":62723.7,"qty":5.64716200},{"price":62719.9,"qty":2.12501460},{"price":62718.0,"qty":0.00015944}],"asks":[{"price":62802.6,"qty":1.09074394},{"price":62803.7,"qty":0.05598472},{"price":62803.8,"qty":0.95536416},{"price":62803.9,"qty":1.16228981},{"price":62806.7,"qty":0.18489680},{"price":62806.8,"qty":3.79009491},{"price":62807.1,"qty":0.36000000},{"price":62807.2,"qty":0.65540712},{"price":62807.4,"qty":0.50920200},{"price":62808.0,"qty":0.79607759},{"price":62809.9,"qty":0.00005100},{"price":62810.0,"qty":0.00756724},{"price":62810.1,"qty":0.13109402},{"price":62810.2,"qty":0.06000000},{"price":62812.0,"qty":0.00756700},{"price":62812.6,"qty":0.00318620},{"price":62812.7,"qty":0.01100000},{"price":62813.1,"qty":0.00005100},{"price":62813.3,"qty":0.06960000},{"price":62813.8,"qty":0.19620257},{"price":62813.9,"qty":2.38800788},{"price":62814.0,"qty":0.00909439},{"price":62816.2,"qty":0.00005100},{"price":62818.7,"qty":0.00222509},{"price":62818.8,"qty":0.65540712},{"price":62818.9,"qty":1.59575715},{"price":62819.0,"qty":7.95938166},{"price":62820.6,"qty":0.00039741},{"price":62821.3,"qty":0.50000000},{"price":62824.2,"qty":0.18883319},{"price":62824.3,"qty":0.02865133},{"price":62824.6,"qty":0.06960000},{"price":62824.9,"qty":0.00318345},{"price":62825.1,"qty":0.00159100},{"price":62828.8,"qty":7.95813579},{"price":62829.0,"qty":0.10331161},{"price":62830.9,"qty":0.03553497},{"price":62831.2,"qty":0.00794680},{"price":62832.0,"qty":1.96622134},{"price":62832.4,"qty":0.01598519},{"price":62833.4,"qty":0.28000000},{"price":62835.0,"qty":0.00080000},{"price":62835.2,"qty":0.00050000},{"price":62835.3,"qty":0.06960000},{"price":62835.6,"qty":0.00094656},{"price":62835.7,"qty":0.01598519},{"price":62836.6,"qty":0.89107300},{"price":62837.3,"qty":0.69770863},{"price":62837.5,"qty":7.95704118},{"price":62838.0,"qty":0.00319703},{"price":62839.8,"qty":0.23769319},{"price":62839.9,"qty":0.71540000},{"price":62840.6,"qty":0.00318620},{"price":62840.7,"qty":0.00198855},{"price":62841.4,"qty":0.00005100},{"price":62841.6,"qty":0.06960000},{"price":62842.0,"qty":0.00159100},{"price":62842.1,"qty":0.11123578},{"price":62845.2,"qty":1.00871835},{"price":62845.4,"qty":7.95604285},{"price":62847.2,"qty":15.00000000},{"price":62847.9,"qty":0.06960000},{"price":62850.8,"qty":0.02057681},{"price":62851.3,"qty":0.01598519},{"price":62851.9,"qty":0.00830438},{"price":62852.1,"qty":2.73683427},{"price":62853.8,"qty":7.95498086},{"price":62854.0,"qty":0.00005100},{"price":62854.2,"qty":0.06960000},{"price":62857.0,"qty":0.03178721},{"price":62858.7,"qty":0.00660000},{"price":62858.8,"qty":0.03187000},{"price":62858.9,"qty":0.00159000},{"price":62860.5,"qty":0.06960000},{"price":62860.7,"qty":0.15930000},{"price":62860.9,"qty":0.03198619},{"price":62862.0,"qty":0.15142628},{"price":62862.7,"qty":0.00600000},{"price":62863.8,"qty":0.00385951},{"price":62866.0,"qty":0.55689900},{"price":62866.5,"qty":0.01172408},{"price":62866.8,"qty":0.06960000},{"price":62871.7,"qty":5.56689713},{"price":62872.2,"qty":0.05497612},{"price":62873.1,"qty":0.06960000},{"price":62873.9,"qty":0.00198855},{"price":62874.0,"qty":0.60000000},{"price":62875.0,"qty":0.00025448},{"price":62875.2,"qty":5.56658959},{"price":62875.3,"qty":0.01000000},{"price":62875.9,"qty":0.00159000},{"price":62876.4,"qty":0.23890000},{"price":62878.8,"qty":0.11123578},{"price":62879.4,"qty":0.06960000},{"price":62879.7,"qty":0.00200000},{"price":62881.0,"qty":0.00829460},{"price":62881.2,"qty":0.16061732},{"price":62883.3,"qty":0.02184000},{"price":62883.7,"qty":1.31257213},{"price":62885.7,"qty":0.06960000}],"checksum":1420235078,"timestamp":"2026-08-16T23:37:04.137657Z"}]}}
{"rx_ns": 42889603537500, "frame": {"channel":"book","type":"update","data":[{"symbol":"BTC/USD","bids":[],"asks":[{"price":62806.8,"qty":0.00005100},{"price":62803.8,"qty":4.74541097}],"checksum":2133845198,"timestamp":"2026-08-16T23:37:04.231265Z"}]}}
{"rx_ns": 42889606850600, "frame": {"channel":"book","type":"update","data":[{"symbol":"BTC/USD","bids":[],"asks":[{"price":62806.7,"qty":0.00000000},{"price":62889.0,"qty":0.04690699},{"price":62807.0,"qty":0.18489680}],"checksum":2424274018,"timestamp":"2026-08-16T23:37:04.232749Z"}]}}
{"rx_ns": 42889606921500, "frame": {"channel":"book","type":"update","data":[{"symbol":"BTC/USD","bids":[],"asks":[{"price":62840.6,"qty":0.00000000},{"price":62889.0,"qty":0.04690699},{"price":62840.8,"qty":0.00318620}],"checksum":2424274018,"timestamp":"2026-08-16T23:37:04.233345Z"}]}}
{"rx_ns": 42889606941300, "frame": {"channel":"book","type":"update","data":[{"symbol":"BTC/USD","bids":[{"price":62764.7,"qty":0.00000000},{"price":62717.0,"qty":0.01531514},{"price":62764.9,"qty":0.00318620}],"asks":[],"checksum":2424274018,"timestamp":"2026-08-16T23:37:04.233678Z"}]}}
{"rx_ns": 42889611191400, "frame": {"channel":"book","type":"update","data":[{"symbol":"BTC/USD","bids":[],"asks":[{"price":62803.8,"qty":0.95536416},{"price":62806.6,"qty":3.79004471}],"checksum":4143655417,"timestamp":"2026-08-16T23:37:04.238772Z"}]}}
{"rx_ns": 42889660660800, "frame": {"channel":"heartbeat"}}
{"rx_ns": 42889691606900, "frame": {"channel":"book","type":"update","data":[{"symbol":"BTC/USD","bids":[{"price":62795.7,"qty":0.00000000},{"price":62717.0,"qty":0.01531514},{"price":62797.0,"qty":0.00012700}],"asks":[],"checksum":3689417502,"timestamp":"2026-08-16T23:37:04.315146Z"}]}}
{"rx_ns": 42889691689100, "frame": {"channel":"book","type":"update","data":[{"symbol":"BTC/USD","bids":[],"asks":[{"price":62807.0,"qty":0.00000000},{"price":62889.0,"qty":0.04690699},{"price":62806.5,"qty":0.18489680}],"checksum":975661613,"timestamp":"2026-08-16T23:37:04.316445Z"}]}}
{"rx_ns": 42889767566700, "frame": {"channel":"book","type":"update","data":[{"symbol":"BTC/USD","bids":[{"price":62765.1,"qty":0.00000000},{"price":62717.0,"qty":0.01531514},{"price":62765.2,"qty":0.00465807}],"asks":[],"checksum":975661613,"timestamp":"2026-08-16T23:37:04.395678Z"}]}}
{"rx_ns": 42889767650500, "frame": {"channel":"book","type":"update","data":[{"symbol":"BTC/USD","bids":[],"asks":[{"price":62835.6,"qty":0.00000000},{"price":62889.0,"qty":0.04690699},{"price":62834.9,"qty":0.00094656}],"checksum":975661613,"timestamp":"2026-08-16T23:37:04.395763Z"}]}}
{"rx_ns": 42889771686400, "frame": {"channel":"book","type":"update","data":[{"symbol":"BTC/USD","bids":[{"price":62717.6,"qty":0.06960000}],"asks":[],"checksum":975661613,"timestamp":"2026-08-16T23:37:04.399453Z"}]}}
{"rx_ns": 42889937178000, "frame": {"channel":"book","type":"update","data":[{"symbol":"BTC/USD","bids":[{"price":62779.2,"qty":0.65540712}],"asks":[],"checksum":975661613,"timestamp":"2026-08-16T23:37:04.563418Z"}]}}
{"rx_ns": 42889937230200, "frame": {"channel":"book","type":"update","data":[{"symbol":"BTC/USD","bids":[{"price":62788.8,"qty":0.65540712}],"asks":[],"checksum":975661613,"timestamp":"2026-08-16T23:37:04.563561Z"}]}}
{"rx_ns": 42889938468600, "frame": {"channel":"book","type":"update","data":[{"symbol":"BTC/USD","bids":[{"price":62766.0,"qty":1.96627234}],"asks":[],"checksum":975661613,"timestamp":"2026-08-16T23:37:04.563717Z"}]}}
{"rx_ns": 42889939863100, "frame": {"channel":"book","type":"update","data":[{"symbol":"BTC/USD","bids":[{"price":62787.5,"qty":0.00000000},{"price":62718.0,"qty":0.00015944}],"asks":[],"checksum":975661613,"timestamp":"2026-08-16T23:37:04.566479Z"}]}}
{"rx_ns": 42889939881100, "frame": {"channel":"book","type":"update","data":[{"symbol":"BTC/USD","bids":[{"price":62790.2,"qty":0.01557581}],"asks":[],"checksum":975661613,"timestamp":"2026-08-16T23:37:04.566662Z"}]}}
{"rx_ns": 42890103517500, "frame": {"channel":"book","type":"update","data":[{"symbol":"BTC/USD","bids":[{"price":62774.1,"qty":0.00000000},{"price":62718.0,"qty":0.00015944}],"asks":[],"checksum":975661613,"timestamp":"2026-08-16T23:37:04.731142Z"}]}}
{"rx_ns": 42890378969500, "frame": {"channel":"book","type":"update","data":[{"symbol":"BTC/USD","bids":[],"asks":[{"price":62820.9,"qty":0.02865288}],"checksum":975661613,"timestamp":"2026-08-16T23:37:05.005203Z"}]}}
{"rx_ns": 42890379072100, "frame": {"channel":"book","type":"update","data":[{"symbol":"BTC/USD","bids":[],"asks":[{"price":62824.3,"qty":0.00000000},{"price":62883.7,"qty":1.31257213}],"checksum":975661613,"timestamp":"2026-08-16T23:37:05.005361Z"}]}}
{"rx_ns": 42890400031500, "frame": {"channel":"book","type":"update","data":[{"symbol":"BTC/USD","bids":[{"price":62772.2,"qty":0.00000000},{"price":62717.0,"qty":0.01531514}],"asks":[],"checksum":975661613,"timestamp":"2026-08-16T23:37:05.027367Z"}]}}
{"rx_ns": 42890403929500, "frame": {"channel":"book","type":"update","data":[{"symbol":"BTC/USD","bids":[{"price":62717.6,"qty":0.06960000}],"asks":[],"checksum":975661613,"timestamp":"2026-08-16T23:37:05.030960Z"}]}}
{"rx_ns": 42890431748300, "frame": {"channel":"book","type":"update","data":[{"symbol":"BTC/USD","bids":[],"asks":[{"price":62830.9,"qty":0.00000000},{"price":62889.0,"qty":0.04690699}],"checksum":975661613,"timestamp":"2026-08-16T23:37:05.056424Z"}]}}
{"rx_ns": 42890433058900, "frame": {"channel":"book","type":"update","data":[{"symbol":"BTC/USD","bids":[],"asks":[{"price":62885.7,"qty":0.06960000}],"checksum":975661613,"timestamp":"2026-08-16T23:37:05.059870Z"}]}}
{"rx_ns": 42890443567800, "frame": {"channel":"book","type":"update","data":[{"symbol":"BTC/USD","bids":[],"asks":[{"price":62849.7,"qty":0.16478084}],"checksum":975661613,"timestamp":"2026-08-16T23:37:05.070903Z"}]}}
{"rx_ns": 42890506791600, "frame": {"channel":"book","type":"update","data":[{"symbol":"BTC/USD","bids":[],"asks":[{"price":62858.7,"qty":0.00000000},{"price":62889.0,"qty":0.04690699},{"price":62856.9,"qty":0.00660000}],"checksum":975661613,"timestamp":"2026-08-16T23:37:05.132991Z"}]}}
{"rx_ns": 42890534246800, "frame": {"channel":"book","type":"update","data":[{"symbol":"BTC/USD","bids":[{"price":62781.8,"qty":0.07962538}],"asks":[],"checksum":975661613,"timestamp":"2026-08-16T23:37:05.155438Z"}]}}
{"rx_ns": 42890534306000, "frame": {"channel":"book","type":"update","data":[{"symbol":"BTC/USD","bids":[{"price":62783.6,"qty":0.03185015}],"asks":[],"checksum":975661613,"timestamp":"2026-08-16T23:37:05.158755Z"}]}}
{"rx_ns": 42890661446400, "frame": {"channel":"heartbeat"}}
{"rx_ns": 42890707826900, "frame": {"channel":"book","type":"update","data":[{"symbol":"BTC/USD","bids":[],"asks":[{"price":62824.9,"qty":0.00000000},{"price":62889.0,"qty":0.04690699}],"checksum":975661613,"timestamp":"2026-08-16T23:37:05.335273Z"}]}}
{"rx_ns": 42890708251100, "frame": {"channel":"book","type":"update","data":[{"symbol":"BTC/USD","bids":[],"asks":[{"price":62821.7,"qty":0.00318361}],"checksum":975661613,"timestamp":"2026-08-16T23:37:05.335650Z"}]}}
{"rx_ns": 42890748557500, "frame": {"channel":"book","type":"update","data":[{"symbol":"BTC/USD","bids":[],"asks":[{"price":62806.6,"qty":0.00000000},{"price":62889.0,"qty":0.04690699},{"price":62803.8,"qty":4.74541363}],"checksum":265834348,"timestamp":"2026-08-16T23:37:05.376419Z"}]}}
{"rx_ns": 42890749320000, "frame": {"channel":"book","type":"update","data":[{"symbol":"BTC/USD","bids":[],"asks":[{"price":62810.1,"qty":0.00000000},{"price":62890.7,"qty":0.53296102}],"checksum":265834348,"timestamp":"2026-08-16T23:37:05.377162Z"}]}}
{"rx_ns": 42890749377900, "frame": {"channel":"book","type":"update","data":[{"symbol":"BTC/USD","bids":[],"asks":[{"price":62817.1,"qty":0.13109402}],"checksum":265834348,"timestamp":"2026-08-16T23:37:05.377368Z"}]}}
{"rx_ns": 42890749389800, "frame": {"channel":"book","type":"update","data":[{"symbol":"BTC/USD","bids":[],"asks":[{"price":62802.6,"qty":0.98074394}],"checksum":1348273380,"timestamp":"2026-08-16T23:37:05.377468Z"}]}}
{"rx_ns": 42890751165000, "frame": {"channel":"book","type":"update","data":[{"symbol":"BTC/USD","bids":[],"asks":[{"price":62810.8,"qty":0.11000000}],"checksum":1348273380,"timestamp":"2026-08-16T23:37:05.377609Z"}]}}
{"rx_ns": 42890751203300, "frame": {"channel":"book","type":"update","data":[{"symbol":"BTC/USD","bids":[],"asks":[{"price":62806.5,"qty":0.00000000},{"price":62889.0,"qty":0.04690699},{"price":62807.0,"qty":0.18489680}],"checksum":3676157681,"timestamp":"2026-08-16T23:37:05.377919Z"}]}}
{"rx_ns": 42890752747200, "frame": {"channel":"book","type":"update","data":[{"symbol":"BTC/USD","bids":[],"asks":[{"price":62802.6,"qty":0.90274394}],"checksum":2543465031,"timestamp":"2026-08-16T23:37:05.380457Z"}]}}
{"rx_ns": 42890771818500, "frame": {"channel":"book","type":"update","data":[{"symbol":"BTC/USD","bids":[],"asks":[{"price":62803.8,"qty":0.95536416},{"price":62806.4,"qty":3.79004364}],"checksum":441069893,"timestamp":"2026-08-16T23:37:05.399046Z"}]}}
{"rx_ns": 42891187365200, "frame": {"channel":"book","type":"update","data":[{"symbol":"BTC/USD","bids":[],"asks":[{"price":62806.4,"qty":0.00000000},{"price":62883.7,"qty":1.31257213},{"price":62803.7,"qty":3.84603600}],"checksum":3303084279,"timestamp":"2026-08-16T23:37:05.815233Z"}]}}
{"rx_ns": 42891210297700, "frame": {"channel":"book","type":"update","data":[{"symbol":"BTC/USD","bids":[],"asks":[{"price":62803.7,"qty":0.05598472},{"price":62806.9,"qty":3.79000109}],"checksum":2474031404,"timestamp":"2026-08-16T23:37:05.837728Z"}]}}
{"rx_ns": 42891212091700, "frame": {"channel":"book","type":"update","data":[{"symbol":"BTC/USD","bids":[],"asks":[{"price":62807.0,"qty":0.00000000},{"price":62883.7,"qty":1.31257213},{"price":62806.8,"qty":0.18494780}],"checksum":3569469293,"timestamp":"2026-08-16T23:37:05.839103Z"}]}}
{"rx_ns": 42891244114100, "frame": {"channel":"book","type":"update","data":[{"symbol":"BTC/USD","bids":[{"price":62802.5,"qty":0.00849808}],"asks":[],"checksum":1879693603,"timestamp":"2026-08-16T23:37:05.871705Z"}]}}
{"rx_ns": 42891245400900, "frame": {"channel":"book","type":"update","data":[{"symbol":"BTC/USD","bids":[{"price":62801.4,"qty":0.02137959}],"asks":[],"checksum":50978620,"timestamp":"2026-08-16T23:37:05.872920Z"}]}}
{"rx_ns": 42891247091300, "frame": {"channel":"book","type":"update","data":[{"symbol":"BTC/USD","bids":[{"price":62764.9,"qty":0.00000000},{"price":62718.0,"qty":0.00015944},{"price":62764.7,"qty":0.00318620}],"asks":[],"checksum":50978620,"timestamp":"2026-08-16T23:37:05.873850Z"}]}}
{"rx_ns": 42891247116300, "frame": {"channel":"book","type":"update","data":[{"symbol":"BTC/USD","bids":[{"price":62800.7,"qty":0.00000000},{"price":62718.0,"qty":0.00015944},{"price":62801.5,"qty":0.05598472}],"asks":[],"checksum":1604503902,"timestamp":"2026-08-16T23:37:05.873993Z"}]}}
{"rx_ns": 42891247128900, "frame": {"channel":"book","type":"update","data":[{"symbol":"BTC/USD","bids":[{"price":62793.1,"qty":0.00000000},{"price":62718.0,"qty":0.00015944},{"price":62793.0,"qty":0.00318620}],"asks":[],"checksum":1604503902,"timestamp":"2026-08-16T23:37:05.874090Z"}]}}
{"rx_ns": 42891247152100, "frame": {"channel":"book","type":"update","data":[{"symbol":"BTC/USD","bids":[],"asks":[{"price":62812.6,"qty":0.00000000},{"price":62889.0,"qty":0.04690699},{"price":62812.4,"qty":0.00318620}],"checksum":1604503902,"timestamp":"2026-08-16T23:37:05.874388Z"}]}}
{"rx_ns": 42891247163500, "frame": {"channel":"book","type":"update","data":[{"symbol":"BTC/USD","bids":[],"asks":[{"price":62840.8,"qty":0.00000000},{"price":62889.0,"qty":0.04690699},{"price":62840.7,"qty":0.00517475}],"checksum":1604503902,"timestamp":"2026-08-16T23:37:05.874859Z"}]}}
{"rx_ns": 42891252780300, "frame": {"channel":"book","type":"update","data":[{"symbol":"BTC/USD","bids":[],"asks":[{"price":62885.7,"qty":0.06960000}],"checksum":1604503902,"timestamp":"2026-08-16T23:37:05.880644Z"}]}}
{"rx_ns": 42891338664500, "frame": {"channel":"book","type":"update","data":[{"symbol":"BTC/USD","bids":[{"price":62740.8,"qty":0.00000000},{"price":62718.0,"qty":0.00015944}],"asks":[],"checksum":1604503902,"timestamp":"2026-08-16T23:37:05.964560Z"}]}}
{"rx_ns": 42891338723100, "frame": {"channel":"book","type":"update","data":[{"symbol":"BTC/USD","bids":[{"price":62742.3,"qty":0.00000000},{"price":62717.0,"qty":0.01531514}],"asks":[],"checksum":1604503902,"timestamp":"2026-08-16T23:37:05.964578Z"}]}}
{"rx_ns": 42891339880700, "frame": {"channel":"book","type":"update","data":[{"symbol":"BTC/USD","bids":[{"price":62717.6,"qty":0.06960000}],"asks":[],"checksum":1604503902,"timestamp":"2026-08-16T23:37:05.966577Z"}]}}
{"rx_ns": 42891342979200, "frame": {"channel":"book","type":"update","data":[{"symbol":"BTC/USD","bids":[{"price":62740.9,"qty":2.87568114}],"asks":[],"checksum":1604503902,"timestamp":"2026-08-16T23:37:05.968757Z"}]}}
{"rx_ns": 42891343083200, "frame": {"channel":"book","type":"update","data":[{"symbol":"BTC/USD","bids":[{"price":62737.5,"qty":2.51205548}],"asks":[],"checksum":1604503902,"timestamp":"2026-08-16T23:37:05.968966Z"}]}}
{"rx_ns": 42891350132300, "frame": {"channel":"book","type":"update","data":[{"symbol":"BTC/USD","bids":[{"price":62736.6,"qty":0.00000000},{"price":62717.0,"qty":0.01531514},{"price":62733.2,"qty":0.70609000}],"asks":[],"checksum":1604503902,"timestamp":"2026-08-16T23:37:05.978332Z"}]}}
{"rx_ns": 42891351687100, "frame": {"channel":"book","type":"update","data":[{"symbol":"BTC/USD","bids":[{"price":62733.6,"qty":0.00000000},{"price":62717.0,"qty":0.01531514},{"price":62730.1,"qty":0.35581000}],"asks":[],"checksum":1604503902,"timestamp":"2026-08-16T23:37:05.978573Z"}]}}
{"rx_ns": 42891380656800, "frame": {"channel":"book","type":"update","data":[{"symbol":"BTC/USD","bids":[{"price":62775.5,"qty":0.00000000},{"price":62717.0,"qty":0.01531514},{"price":62774.1,"qty":0.10292462}],"asks":[],"checksum":1604503902,"timestamp":"2026-08-16T23:37:06.007525Z"}]}}
{"rx_ns": 42891488788900, "frame": {"channel":"book","type":"update","data":[{"symbol":"BTC/USD","bids":[],"asks":[{"price":62863.8,"qty":0.00000000},{"price":62889.0,"qty":0.04690699},{"price":62861.9,"qty":0.00385951}],"checksum":1604503902,"timestamp":"2026-08-16T23:37:06.117116Z"}]}}
{"rx_ns": 42891564078100, "frame": {"channel":"book","type":"update","data":[{"symbol":"BTC/USD","bids":[{"price":62755.4,"qty":0.06960000}],"asks":[],"checksum":1604503902,"timestamp":"2026-08-16T23:37:06.190072Z"}]}}
{"rx_ns": 42891570419900, "frame": {"channel":"book","type":"update","data":[{"symbol":"BTC/USD","bids":[{"price":62745.1,"qty":0.55695300}],"asks":[],"checksum":1604503902,"timestamp":"2026-08-16T23:37:06.191262Z"}]}}
{"rx_ns": 42891649137500, "frame": {"channel":"book","type":"update","data":[{"symbol":"BTC/USD","bids":[{"price":62801.5,"qty":0.00000000},{"price":62718.0,"qty":0.00015944}],"asks":[],"checksum":3719378320,"timestamp":"2026-08-16T23:37:06.275708Z"}]}}
{"rx_ns": 42891650736900, "frame": {"channel":"book","type":"update","data":[{"symbol":"BTC/USD","bids":[{"price":62797.6,"qty":0.05598472}],"asks":[],"checksum":2564800303,"timestamp":"2026-08-16T23:37:06.276752Z"}]}}
{"rx_ns": 42891661280700, "frame": {"channel":"heartbeat"}}
{"rx_ns": 42891677925600, "frame": {"channel":"book","type":"update","data":[{"symbol":"BTC/USD","bids":[{"price":62793.9,"qty":0.00000000},{"price":62718.0,"qty":0.00015944}],"asks":[],"checksum":110749926,"timestamp":"2026-08-16T23:37:06.285045Z"}]}}
{"rx_ns": 42891677986300, "frame": {"channel":"book","type":"update","data":[{"symbol":"BTC/USD","bids":[{"price":62793.2,"qty":0.79626397}],"asks":[],"checksum":2330494038,"timestamp":"2026-08-16T23:37:06.286874Z"}]}}
{"rx_ns": 42891678001800, "frame": {"channel":"book","type":"update","data":[{"symbol":"BTC/USD","bids":[],"asks":[{"price":62803.8,"qty":0.79613017}],"checksum":371959854,"timestamp":"2026-08-16T23:37:06.297387Z"}]}}
{"rx_ns": 42891678012500, "frame": {"channel":"book","type":"update","data":[{"symbol":"BTC/USD","bids":[{"price":62791.6,"qty":0.00000000},{"price":62718.0,"qty":0.00015944}],"asks":[],"checksum":371959854,"timestamp":"2026-08-16T23:37:06.297399Z"}]}}
{"rx_ns": 42891697062600, "frame": {"channel":"book","type":"update","data":[{"symbol":"BTC/USD","bids":[{"price":62794.0,"qty":0.00000000},{"price":62717.0,"qty":0.01531514}],"asks":[],"checksum":2630192712,"timestamp":"2026-08-16T23:37:06.324556Z"}]}}
{"rx_ns": 42891706297300, "frame": {"channel":"book","type":"update","data":[{"symbol":"BTC/USD","bids":[{"price":62717.6,"qty":0.06960000}],"asks":[],"checksum":2630192712,"timestamp":"2026-08-16T23:37:06.326916Z"}]}}
{"rx_ns": 42891707962400, "frame": {"channel":"book","type":"update","data":[{"symbol":"BTC/USD","bids":[],"asks":[{"price":62802.6,"qty":1.06197793}],"checksum":2871320315,"timestamp":"2026-08-16T23:37:06.334835Z"}]}}
{"rx_ns": 42891708184300, "frame": {"channel":"book","type":"update","data":[{"symbol":"BTC/USD","bids":[{"price":62790.3,"qty":0.15923399}],"asks":[],"checksum":2871320315,"timestamp":"2026-08-16T23:37:06.335007Z"}]}}
{"rx_ns": 42891718195000, "frame": {"channel":"book","type":"update","data":[{"symbol":"BTC/USD","bids":[],"asks":[{"price":62802.6,"qty":1.13997793}],"checksum":1696580693,"timestamp":"2026-08-16T23:37:06.336631Z"}]}}
{"rx_ns": 42891718249200, "frame": {"channel":"book","type":"update","data":[{"symbol":"BTC/USD","bids":[{"price":62765.2,"qty":0.00162380}],"asks":[],"checksum":1696580693,"timestamp":"2026-08-16T23:37:06.337353Z"}]}}
{"rx_ns": 42891735361100, "frame": {"channel":"book","type":"update","data":[{"symbol":"BTC/USD","bids":[],"asks":[{"price":62806.9,"qty":0.00000000},{"price":62889.0,"qty":0.04690699},{"price":62803.8,"qty":4.58617734}],"checksum":54414482,"timestamp":"2026-08-16T23:37:06.361885Z"}]}}
{"rx_ns": 42891771540300, "frame": {"channel":"book","type":"update","data":[{"symbol":"BTC/USD","bids":[],"asks":[{"price":62845.2,"qty":0.01649028}],"checksum":54414482,"timestamp":"2026-08-16T23:37:06.398089Z"}]}}
{"rx_ns": 42891780721800, "frame": {"channel":"book","type":"update","data":[{"symbol":"BTC/USD","bids":[],"asks":[{"price":62845.1,"qty":0.97705714}],"checksum":54414482,"timestamp":"2026-08-16T23:37:06.400950Z"}]}}
{"rx_ns": 42891822396200, "frame": {"channel":"book","type":"update","data":[{"symbol":"BTC/USD","bids":[],"asks":[{"price":62845.2,"qty":0.00000000},{"price":62889.0,"qty":0.04690699},{"price":62834.8,"qty":0.01661157}],"checksum":54414482,"timestamp":"2026-08-16T23:37:06.450097Z"}]}}
{"rx_ns": 42891970091200, "frame": {"channel":"book","type":"update","data":[{"symbol":"BTC/USD","bids":[{"price":62765.1,"qty":0.00303429}],"asks":[],"checksum":54414482,"timestamp":"2026-08-16T23:37:06.597830Z"}]}}
{"rx_ns": 42892123350700, "frame": {"channel":"book","type":"update","data":[{"symbol":"BTC/USD","bids":[],"asks":[{"price":62803.8,"qty":0.79613017},{"price":62806.7,"qty":3.79004495}],"checksum":1900210029,"timestamp":"2026-08-16T23:37:06.750448Z"}]}}
{"rx_ns": 42892124593900, "frame": {"channel":"book","type":"update","data":[{"symbol":"BTC/USD","bids":[],"asks":[{"price":62806.8,"qty":0.00005100},{"price":62806.6,"qty":0.18489680}],"checksum":1899318310,"timestamp":"2026-08-16T23:37:06.751983Z"}]}}
{"rx_ns": 42892144824500, "frame": {"channel":"book","type":"update","data":[{"symbol":"BTC/USD","bids":[{"price":62790.3,"qty":0.00000000},{"price":62718.0,"qty":0.00015944}],"asks":[],"checksum":1899318310,"timestamp":"2026-08-16T23:37:06.770399Z"}]}}
{"rx_ns": 42892168886100, "frame": {"channel":"book","type":"update","data":[{"symbol":"BTC/USD","bids":[{"price":62790.2,"qty":0.17480980}],"asks":[],"checksum":1899318310,"timestamp":"2026-08-16T23:37:06.796085Z"}]}}
{"rx_ns": 42892311303300, "frame": {"channel":"book","type":"update","data":[{"symbol":"BTC/USD","bids":[],"asks":[{"price":62807.1,"qty":0.00000000},{"price":62883.7,"qty":1.31257213}],"checksum":4083933284,"timestamp":"2026-08-16T23:37:06.938737Z"}]}}
{"rx_ns": 42892311352700, "frame": {"channel":"book","type":"update","data":[{"symbol":"BTC/USD","bids":[],"asks":[{"price":62824.2,"qty":0.00000000},{"price":62889.0,"qty":0.04690699}],"checksum":4083933284,"timestamp":"2026-08-16T23:37:06.938869Z"}]}}
{"rx_ns": 42892316889300, "frame": {"channel":"book","type":"update","data":[{"symbol":"BTC/USD","bids":[],"asks":[{"price":62885.7,"qty":0.06960000}],"checksum":4083933284,"timestamp":"2026-08-16T23:37:06.944801Z"}]}}
{"rx_ns": 42892637566200, "frame": {"channel":"book","type":"update","data":[{"symbol":"BTC/USD","bids":[],"asks":[{"price":62815.6,"qty":0.18701894}],"checksum":4083933284,"timestamp":"2026-08-16T23:37:07.265426Z"}]}}
{"rx_ns": 42892662026500, "frame": {"channel":"heartbeat"}}
{"rx_ns": 42892680616100, "frame": {"channel":"book","type":"update","data":[{"symbol":"BTC/USD","bids":[],"asks":[{"price":62806.7,"qty":0.00000000},{"price":62889.0,"qty":0.04690699},{"price":62803.8,"qty":4.58618091}],"checksum":2043980972,"timestamp":"2026-08-16T23:37:07.300795Z"}]}}
{"rx_ns": 42892680679600, "frame": {"channel":"book","type":"update","data":[{"symbol":"BTC/USD","bids":[],"asks":[{"price":62806.6,"qty":0.00000000},{"price":62891.0,"qty":0.47691231},{"price":62807.9,"qty":0.18489680}],"checksum":235672643,"timestamp":"2026-08-16T23:37:07.302093Z"}]}}
{"rx_ns": 42892680698200, "frame": {"channel":"book","type":"update","data":[{"symbol":"BTC/USD","bids":[],"asks":[{"price":62885.7,"qty":0.06960000}],"checksum":235672643,"timestamp":"2026-08-16T23:37:07.303150Z"}]}}
{"rx_ns": 42892895022400, "frame": {"channel":"book","type":"update","data":[{"symbol":"BTC/USD","bids":[],"asks":[{"price":62807.1,"qty":0.36000000}],"checksum":3521650448,"timestamp":"2026-08-16T23:37:07.520640Z"}]}}
{"rx_ns": 42892896829300, "frame": {"channel":"book","type":"update","data":[{"symbol":"BTC/USD","bids":[],"asks":[{"price":62807.9,"qty":0.00000000},{"price":62885.7,"qty":0.06960000},{"price":62807.0,"qty":0.18489680}],"checksum":4056636036,"timestamp":"2026-08-16T23:37:07.521946Z"}]}}
{"rx_ns": 42892896902600, "frame": {"channel":"book","type":"update","data":[{"symbol":"BTC/USD","bids":[],"asks":[{"price":62840.7,"qty":0.00198855},{"price":62840.8,"qty":0.00318620}],"checksum":4056636036,"timestamp":"2026-08-16T23:37:07.522906Z"}]}}
{"rx_ns": 42892896923800, "frame": {"channel":"book","type":"update","data":[{"symbol":"BTC/USD","bids":[],"asks":[{"price":62812.4,"qty":0.00000000},{"price":62883.7,"qty":1.31257213},{"price":62812.5,"qty":0.00318620}],"checksum":4056636036,"timestamp":"2026-08-16T23:37:07.523244Z"}]}}
{"rx_ns": 42892898475200, "frame": {"channel":"book","type":"update","data":[{"symbol":"BTC/USD","bids":[{"price":62764.7,"qty":0.00000000},{"price":62717.0,"qty":0.01531514},{"price":62764.8,"qty":0.00318620}],"asks":[],"checksum":4056636036,"timestamp":"2026-08-16T23:37:07.523606Z"}]}}
{"rx_ns": 42892946600500, "frame": {"channel":"book","type":"update","data":[{"symbol":"BTC/USD","bids":[],"asks":[{"price":62807.2,"qty":0.00000000},{"price":62883.7,"qty":1.31257213}],"checksum":4219639166,"timestamp":"2026-08-16T23:37:07.574122Z"}]}}
{"rx_ns": 42892954114400, "frame": {"channel":"book","type":"update","data":[{"symbol":"BTC/USD","bids":[{"price":62790.2,"qty":0.01557581}],"asks":[],"checksum":4219639166,"timestamp":"2026-08-16T23:37:07.581989Z"}]}}
{"rx_ns": 42892971290400, "frame": {"channel":"book","type":"update","data":[{"symbol":"BTC/USD","bids":[{"price":62790.1,"qty":0.15923399}],"asks":[],"checksum":4219639166,"timestamp":"2026-08-16T23:37:07.596190Z"}]}}
{"rx_ns": 42893436985000, "frame": {"channel":"book","type":"update","data":[{"symbol":"BTC/USD","bids":[],"asks":[{"price":62803.8,"qty":0.79613017},{"price":62806.9,"qty":3.79000581}],"checksum":2688985755,"timestamp":"2026-08-16T23:37:08.064059Z"}]}}
{"rx_ns": 42893438300000, "frame": {"channel":"book","type":"update","data":[{"symbol":"BTC/USD","bids":[],"asks":[{"price":62807.0,"qty":0.00000000},{"price":62883.7,"qty":1.31257213},{"price":62806.8,"qty":0.18494780}],"checksum":4088415580,"timestamp":"2026-08-16T23:37:08.065495Z"}]}}
{"rx_ns": 42893462233200, "frame": {"channel":"book","type":"update","data":[{"symbol":"BTC/USD","bids":[],"asks":[{"price":62806.9,"qty":0.00000000},{"price":62889.0,"qty":0.04690699},{"price":62803.7,"qty":3.84603605}],"checksum":1080158762,"timestamp":"2026-08-16T23:37:08.087504Z"}]}}
{"rx_ns": 42893462315900, "frame": {"channel":"book","type":"update","data":[{"symbol":"BTC/USD","bids":[],"asks":[{"price":62803.7,"qty":3.79005133},{"price":62803.6,"qty":0.05598472}],"checksum":1312528143,"timestamp":"2026-08-16T23:37:08.088677Z"}]}}
{"rx_ns": 42893462344200, "frame": {"channel":"book","type":"update","data":[{"symbol":"BTC/USD","bids":[],"asks":[{"price":62806.8,"qty":0.00005100},{"price":62807.9,"qty":0.18489680}],"checksum":1201675115,"timestamp":"2026-08-16T23:37:08.088784Z"}]}}
{"rx_ns": 42893489150300, "frame": {"channel":"book","type":"update","data":[{"symbol":"BTC/USD","bids":[],"asks":[{"price":62803.7,"qty":0.00000000},{"price":62883.7,"qty":1.31257213},{"price":62806.9,"qty":3.79004418}],"checksum":440535564,"timestamp":"2026-08-16T23:37:08.117588Z"}]}}
{"rx_ns": 42893491686700, "frame": {"channel":"book","type":"update","data":[{"symbol":"BTC/USD","bids":[],"asks":[{"price":62807.9,"qty":0.00000000},{"price":62883.7,"qty":1.31257213},{"price":62806.8,"qty":0.18494780}],"checksum":2494929030,"timestamp":"2026-08-16T23:37:08.118838Z"}]}}
{"rx_ns": 42893491766600, "frame": {"channel":"book","type":"update","data":[{"symbol":"BTC/USD","bids":[],"asks":[{"price":62803.6,"qty":0.00000000},{"price":62889.0,"qty":0.04690699},{"price":62803.7,"qty":0.05598472}],"checksum":2465943611,"timestamp":"2026-08-16T23:37:08.118853Z"}]}}
{"rx_ns": 42893661712000, "frame": {"channel":"heartbeat"}}
{"rx_ns": 42893677854600, "frame": {"channel":"book","type":"update","data":[{"symbol":"BTC/USD","bids":[{"price":62740.9,"qty":0.00005100}],"asks":[],"checksum":2465943611,"timestamp":"2026-08-16T23:37:08.304950Z"}]}}
{"rx_ns": 42893680877300, "frame": {"channel":"book","type":"update","data":[{"symbol":"BTC/USD","bids":[{"price":62737.5,"qty":0.00000000},{"price":62718.0,"qty":0.00015944}],"asks":[],"checksum":2465943611,"timestamp":"2026-08-16T23:37:08.305215Z"}]}}
{"rx_ns": 42893682359000, "frame": {"channel":"book","type":"update","data":[{"symbol":"BTC/USD","bids":[{"price":62741.0,"qty":3.26327906}],"asks":[],"checksum":2465943611,"timestamp":"2026-08-16T23:37:08.309614Z"}]}}
{"rx_ns": 42893682394000, "frame": {"channel":"book","type":"update","data":[{"symbol":"BTC/USD","bids":[{"price":62737.6,"qty":2.44525628}],"asks":[],"checksum":2465943611,"timestamp":"2026-08-16T23:37:08.309657Z"}]}}
{"rx_ns": 42894065759600, "frame": {"channel":"book","type":"update","data":[{"symbol":"BTC/USD","bids":[{"price":62790.1,"qty":0.00000000},{"price":62719.9,"qty":2.12501460}],"asks":[],"checksum":2465943611,"timestamp":"2026-08-16T23:37:08.686693Z"}]}}
{"rx_ns": 42894067988400, "frame": {"channel":"book","type":"update","data":[{"symbol":"BTC/USD","bids":[{"price":62790.0,"qty":0.16520357}],"asks":[],"checksum":2465943611,"timestamp":"2026-08-16T23:37:08.695984Z"}]}}
{"rx_ns": 42894090720100, "frame": {"channel":"book","type":"update","data":[{"symbol":"BTC/USD","bids":[],"asks":[{"price":62820.6,"qty":0.00000000},{"price":62889.0,"qty":0.04690699},{"price":62825.4,"qty":0.00039741}],"checksum":2465943611,"timestamp":"2026-08-16T23:37:08.717504Z"}]}}
{"rx_ns": 42894092985200, "frame": {"channel":"book","type":"update","data":[{"symbol":"BTC/USD","bids":[],"asks":[{"price":62806.9,"qty":0.00000000},{"price":62889.0,"qty":0.04690699},{"price":62803.6,"qty":3.79008032}],"checksum":485000038,"timestamp":"2026-08-16T23:37:08.719864Z"}]}}
{"rx_ns": 42894096274900, "frame": {"channel":"book","type":"update","data":[{"symbol":"BTC/USD","bids":[],"asks":[{"price":62806.8,"qty":0.00005100},{"price":62807.9,"qty":0.18489680}],"checksum":359862018,"timestamp":"2026-08-16T23:37:08.721198Z"}]}}
{"rx_ns": 42894096330800, "frame": {"channel":"book","type":"update","data":[{"symbol":"BTC/USD","bids":[],"asks":[{"price":62803.7,"qty":0.00000000},{"price":62883.7,"qty":1.31257213},{"price":62803.5,"qty":0.05598472}],"checksum":2947842144,"timestamp":"2026-08-16T23:37:08.721219Z"}]}}
{"rx_ns": 42894108878200, "frame": {"channel":"book","type":"update","data":[{"symbol":"BTC/USD","bids":[],"asks":[{"price":62845.1,"qty":0.00000000},{"price":62883.7,"qty":1.31257213}],"checksum":2947842144,"timestamp":"2026-08-16T23:37:08.736669Z"}]}}
{"rx_ns": 42894118796300, "frame": {"channel":"book","type":"update","data":[{"symbol":"BTC/USD","bids":[],"asks":[{"price":62845.0,"qty":0.77607268}],"checksum":2947842144,"timestamp":"2026-08-16T23:37:08.746645Z"}]}}
{"rx_ns": 42894123571500, "frame": {"channel":"book","type":"update","data":[{"symbol":"BTC/USD","bids":[],"asks":[{"price":62803.6,"qty":0.00000000},{"price":62883.7,"qty":1.31257213},{"price":62806.7,"qty":3.79001496}],"checksum":1565111361,"timestamp":"2026-08-16T23:37:08.751537Z"}]}}
{"rx_ns": 42894128326100, "frame": {"channel":"book","type":"update","data":[{"symbol":"BTC/USD","bids":[],"asks":[{"price":62803.5,"qty":0.00000000},{"price":62883.7,"qty":1.31257213},{"price":62803.7,"qty":0.05598472}],"checksum":1372857659,"timestamp":"2026-08-16T23:37:08.753024Z"}]}}
{"rx_ns": 42894349524700, "frame": {"channel":"book","type":"update","data":[{"symbol":"BTC/USD","bids":[],"asks":[{"price":62830.9,"qty":0.03429038}],"checksum":1372857659,"timestamp":"2026-08-16T23:37:08.977242Z"}]}}
{"rx_ns": 42894351261600, "frame": {"channel":"book","type":"update","data":[{"symbol":"BTC/USD","bids":[{"price":62772.1,"qty":0.03476338}],"asks":[],"checksum":1372857659,"timestamp":"2026-08-16T23:37:08.978308Z"}]}}
{"rx_ns": 42894380695300, "frame": {"channel":"book","type":"update","data":[{"symbol":"BTC/USD","bids":[],"asks":[{"price":62818.9,"qty":0.00000000},{"price":62883.3,"qty":0.02184000},{"price":62818.7,"qty":1.59798224}],"checksum":1372857659,"timestamp":"2026-08-16T23:37:09.008232Z"}]}}
{"rx_ns": 42894387678400, "frame": {"channel":"book","type":"update","data":[{"symbol":"BTC/USD","bids":[],"asks":[{"price":62806.7,"qty":0.00000000},{"price":62883.7,"qty":1.31257213},{"price":62803.8,"qty":4.58618103}],"checksum":1864190754,"timestamp":"2026-08-16T23:37:09.015116Z"}]}}
{"rx_ns": 42894417570800, "frame": {"channel":"book","type":"update","data":[{"symbol":"BTC/USD","bids":[],"asks":[{"price":62803.8,"qty":0.79613017},{"price":62807.0,"qty":3.78999969}],"checksum":3292457266,"timestamp":"2026-08-16T23:37:09.045279Z"}]}}
{"rx_ns": 42894424889600, "frame": {"channel":"book","type":"update","data":[{"symbol":"BTC/USD","bids":[],"asks":[{"price":62807.9,"qty":0.00000000},{"price":62883.7,"qty":1.31257213},{"price":62806.9,"qty":0.18489680}],"checksum":3897311709,"timestamp":"2026-08-16T23:37:09.047337Z"}]}}
{"rx_ns": 42894434705300, "frame": {"channel":"book","type":"update","data":[{"symbol":"BTC/USD","bids":[{"price":62793.2,"qty":0.00000000},{"price":62719.9,"qty":2.12501460}],"asks":[],"checksum":3560232215,"timestamp":"2026-08-16T23:37:09.053796Z"}]}}
{"rx_ns": 42894443062100, "frame": {"channel":"book","type":"update","data":[{"symbol":"BTC/USD","bids":[],"asks":[{"price":62818.7,"qty":0.00222509},{"price":62818.9,"qty":1.59575715}],"checksum":3560232215,"timestamp":"2026-08-16T23:37:09.058896Z"}]}}
{"rx_ns": 42894443179000, "frame": {"channel":"book","type":"update","data":[{"symbol":"BTC/USD","bids":[{"price":62793.8,"qty":0.79625623}],"asks":[],"checksum":3165917908,"timestamp":"2026-08-16T23:37:09.062522Z"}]}}
{"rx_ns": 42894444698400, "frame": {"channel":"book","type":"update","data":[{"symbol":"BTC/USD","bids":[],"asks":[{"price":62818.9,"qty":0.00000000},{"price":62883.3,"qty":0.02184000},{"price":62821.2,"qty":1.59575715}],"checksum":3165917908,"timestamp":"2026-08-16T23:37:09.070001Z"}]}}
{"rx_ns": 42894452920100, "frame": {"channel":"book","type":"update","data":[{"symbol":"BTC/USD","bids":[],"asks":[{"price":62821.2,"qty":0.00000000},{"price":62883.3,"qty":0.02184000},{"price":62818.9,"qty":1.59575715}],"checksum":3165917908,"timestamp":"2026-08-16T23:37:09.078892Z"}]}}
{"rx_ns": 42894463528900, "frame": {"channel":"book","type":"update","data":[{"symbol":"BTC/USD","bids":[],"asks":[{"price":62860.9,"qty":0.00000000},{"price":62883.3,"qty":0.02184000}],"checksum":3165917908,"timestamp":"2026-08-16T23:37:09.090383Z"}]}}
{"rx_ns": 42894513367300, "frame": {"channel":"book","type":"update","data":[{"symbol":"BTC/USD","bids":[],"asks":[{"price":62803.7,"qty":0.00000000},{"price":62883.7,"qty":1.31257213}],"checksum":2451645330,"timestamp":"2026-08-16T23:37:09.140594Z"}]}}
{"rx_ns": 42894515492700, "frame": {"channel":"book","type":"update","data":[{"symbol":"BTC/USD","bids":[{"price":62797.6,"qty":0.00000000},{"price":62719.9,"qty":2.12501460},{"price":62802.5,"qty":0.06448280}],"asks":[],"checksum":1825135173,"timestamp":"2026-08-16T23:37:09.141793Z"}]}}
{"rx_ns": 42894515646300, "frame": {"channel":"book","type":"update","data":[{"symbol":"BTC/USD","bids":[],"asks":[{"price":62803.9,"qty":1.21827453}],"checksum":336881173,"timestamp":"2026-08-16T23:37:09.141970Z"}]}}
{"rx_ns": 42894518965800, "frame": {"channel":"book","type":"update","data":[{"symbol":"BTC/USD","bids":[],"asks":[{"price":62812.5,"qty":0.00000000},{"price":62889.0,"qty":0.04690699},{"price":62812.6,"qty":0.00318620}],"checksum":336881173,"timestamp":"2026-08-16T23:37:09.144273Z"}]}}
{"rx_ns": 42894519015900, "frame": {"channel":"book","type":"update","data":[{"symbol":"BTC/USD","bids":[{"price":62793.0,"qty":0.00000000},{"price":62718.0,"qty":0.00015944},{"price":62793.1,"qty":0.00318620}],"asks":[],"checksum":4215722228,"timestamp":"2026-08-16T23:37:09.144533Z"}]}}
{"rx_ns": 42894521159500, "frame": {"channel":"book","type":"update","data":[{"symbol":"BTC/USD","bids":[{"price":62764.8,"qty":0.00000000},{"price":62718.0,"qty":0.00015944},{"price":62764.9,"qty":0.00318620}],"asks":[],"checksum":4215722228,"timestamp":"2026-08-16T23:37:09.144842Z"}]}}
{"rx_ns": 42894587043400, "frame": {"channel":"book","type":"update","data":[{"symbol":"BTC/USD","bids":[{"price":62790.0,"qty":0.00596958}],"asks":[],"checksum":4215722228,"timestamp":"2026-08-16T23:37:09.214645Z"}]}}
{"rx_ns": 42894618783400, "frame": {"channel":"book","type":"update","data":[{"symbol":"BTC/USD","bids":[{"price":62790.3,"qty":0.15923399}],"asks":[],"checksum":4215722228,"timestamp":"2026-08-16T23:37:09.246165Z"}]}}
{"rx_ns": 42894664290600, "frame": {"channel":"heartbeat"}}
{"rx_ns": 42894772617500, "frame": {"channel":"book","type":"update","data":[{"symbol":"BTC/USD","bids":[{"price":62794.0,"qty":0.00552708}],"asks":[],"checksum":197040151,"timestamp":"2026-08-16T23:37:09.399268Z"}]}}
{"rx_ns": 42894865026000, "frame": {"channel":"book","type":"update","data":[{"symbol":"BTC/USD","bids":[],"asks":[{"price":62872.2,"qty":0.00000000},{"price":62889.0,"qty":0.04690699}],"checksum":197040151,"timestamp":"2026-08-16T23:37:09.492054Z"}]}}
{"rx_ns": 42894868743900, "frame": {"channel":"book","type":"update","data":[{"symbol":"BTC/USD","bids":[],"asks":[{"price":62885.7,"qty":0.06960000}],"checksum":197040151,"timestamp":"2026-08-16T23:37:09.496481Z"}]}}
{"rx_ns": 42895147906800, "frame": {"channel":"book","type":"update","data":[{"symbol":"BTC/USD","bids":[],"asks":[{"price":62862.0,"qty":0.18271916}],"checksum":197040151,"timestamp":"2026-08-16T23:37:09.775062Z"}]}}
{"rx_ns": 42895353477100, "frame": {"channel":"book","type":"update","data":[{"symbol":"BTC/USD","bids":[],"asks":[{"price":62861.3,"qty":0.15888884}],"checksum":197040151,"timestamp":"2026-08-16T23:37:09.977864Z"}]}}
{"rx_ns": 42895353544700, "frame": {"channel":"book","type":"update","data":[{"symbol":"BTC/USD","bids":[],"asks":[{"price":62829.8,"qty":0.15286432}],"checksum":197040151,"timestamp":"2026-08-16T23:37:09.978463Z"}]}}
{"rx_ns": 42895364984700, "frame": {"channel":"book","type":"update","data":[{"symbol":"BTC/USD","bids":[],"asks":[{"price":62869.0,"qty":0.05419295}],"checksum":197040151,"timestamp":"2026-08-16T23:37:09.992258Z"}]}}
{"rx_ns": 42895378789500, "frame": {"channel":"book","type":"update","data":[{"symbol":"BTC/USD","bids":[],"asks":[{"price":62818.9,"qty":0.00000000},{"price":62883.3,"qty":0.02184000},{"price":62818.7,"qty":1.59798224}],"checksum":197040151,"timestamp":"2026-08-16T23:37:10.006349Z"}]}}
{"rx_ns": 42895509258900, "frame": {"channel":"book","type":"update","data":[{"symbol":"BTC/USD","bids":[],"asks":[{"price":62834.9,"qty":0.00000000},{"price":62883.7,"qty":1.31257213},{"price":62834.7,"qty":0.00094656}],"checksum":197040151,"timestamp":"2026-08-16T23:37:10.135669Z"}]}}
{"rx_ns": 42895588881600, "frame": {"channel":"book","type":"update","data":[{"symbol":"BTC/USD","bids":[{"price":62802.5,"qty":0.00849808}],"asks":[],"checksum":979958136,"timestamp":"2026-08-16T23:37:10.213367Z"}]}}
{"rx_ns": 42895594960700, "frame": {"channel":"book","type":"update","data":[{"symbol":"BTC/USD","bids":[{"price":62797.6,"qty":0.05598472}],"asks":[],"checksum":4106223823,"timestamp":"2026-08-16T23:37:10.214795Z"}]}}
{"rx_ns": 42895595007400, "frame": {"channel":"book","type":"update","data":[{"symbol":"BTC/USD","bids":[],"asks":[{"price":62803.9,"qty":1.16228981},{"price":62803.7,"qty":0.05598472}],"checksum":2974203201,"timestamp":"2026-08-16T23:37:10.215095Z"}]}}
{"rx_ns": 42895595024800, "frame": {"channel":"book","type":"update","data":[{"symbol":"BTC/USD","bids":[],"asks":[{"price":62802.6,"qty":1.06197793}],"checksum":613166112,"timestamp":"2026-08-16T23:37:10.215138Z"}]}}
{"rx_ns": 42895642972500, "frame": {"channel":"book","type":"update","data":[{"symbol":"BTC/USD","bids":[],"asks":[{"price":62834.8,"qty":0.00000000},{"price":62883.3,"qty":0.02184000},{"price":62834.6,"qty":0.01671227}],"checksum":613166112,"timestamp":"2026-08-16T23:37:10.270441Z"}]}}
{"rx_ns": 42895662715300, "frame": {"channel":"heartbeat"}}
{"rx_ns": 42895662764300, "frame": {"channel":"book","type":"update","data":[{"symbol":"BTC/USD","bids":[{"price":62793.8,"qty":0.00000000},{"price":62723.7,"qty":5.64716200}],"asks":[],"checksum":1294649062,"timestamp":"2026-08-16T23:37:10.285432Z"}]}}
{"rx_ns": 42895677424300, "frame": {"channel":"book","type":"update","data":[{"symbol":"BTC/USD","bids":[{"price":62723.9,"qty":0.06960000}],"asks":[],"checksum":1294649062,"timestamp":"2026-08-16T23:37:10.286896Z"}]}}
{"rx_ns": 42895677485800, "frame": {"channel":"book","type":"update","data":[{"symbol":"BTC/USD","bids":[{"price":62793.0,"qty":0.79626632}],"asks":[],"checksum":1294649062,"timestamp":"2026-08-16T23:37:10.287058Z"}]}}
{"rx_ns": 42895774581600, "frame": {"channel":"book","type":"update","data":[{"symbol":"BTC/USD","bids":[{"price":62791.9,"qty":0.00000000},{"price":62723.7,"qty":5.64716200}],"asks":[],"checksum":1294649062,"timestamp":"2026-08-16T23:37:10.395397Z"}]}}
{"rx_ns": 42895774661500, "frame": {"channel":"book","type":"update","data":[{"symbol":"BTC/USD","bids":[{"price":62723.9,"qty":0.06960000}],"asks":[],"checksum":1294649062,"timestamp":"2026-08-16T23:37:10.396642Z"}]}}
{"rx_ns": 42895774678300, "frame": {"channel":"book","type":"update","data":[{"symbol":"BTC/USD","bids":[{"price":62790.8,"qty":0.79629454}],"asks":[],"checksum":1294649062,"timestamp":"2026-08-16T23:37:10.396686Z"}]}}
{"rx_ns": 42895849054400, "frame": {"channel":"book","type":"update","data":[{"symbol":"BTC/USD","bids":[{"price":62794.0,"qty":0.00000000},{"price":62723.7,"qty":5.64716200}],"asks":[],"checksum":2847926976,"timestamp":"2026-08-16T23:37:10.474842Z"}]}}
{"rx_ns": 42895851305300, "frame": {"channel":"book","type":"update","data":[{"symbol":"BTC/USD","bids":[{"price":62723.9,"qty":0.06960000}],"asks":[],"checksum":2847926976,"timestamp":"2026-08-16T23:37:10.477307Z"}]}}
{"rx_ns": 42895856915400, "frame": {"channel":"book","type":"update","data":[{"symbol":"BTC/USD","bids":[],"asks":[{"price":62807.0,"qty":0.00000000},{"price":62883.3,"qty":0.02184000},{"price":62803.8,"qty":4.58617735}],"checksum":1988537768,"timestamp":"2026-08-16T23:37:10.484052Z"}]}}
{"rx_ns": 42895859576800, "frame": {"channel":"book","type":"update","data":[{"symbol":"BTC/USD","bids":[],"asks":[{"price":62806.9,"qty":0.00000000},{"price":62883.7,"qty":1.31257213},{"price":62807.9,"qty":0.18489680}],"checksum":2074920805,"timestamp":"2026-08-16T23:37:10.485180Z"}]}}
{"rx_ns": 42895886676900, "frame": {"channel":"book","type":"update","data":[{"symbol":"BTC/USD","bids":[],"asks":[{"price":62802.6,"qty":1.13157793}],"checksum":2207559158,"timestamp":"2026-08-16T23:37:10.513171Z"}]}}
{"rx_ns": 42895891555900, "frame": {"channel":"book","type":"update","data":[{"symbol":"BTC/USD","bids":[],"asks":[{"price":62802.6,"qty":1.20957793}],"checksum":1974850468,"timestamp":"2026-08-16T23:37:10.515555Z"}]}}
{"rx_ns": 42895946363200, "frame": {"channel":"book","type":"update","data":[{"symbol":"BTC/USD","bids":[{"price":62790.3,"qty":0.00000000},{"price":62723.7,"qty":5.64716200}],"asks":[],"checksum":1974850468,"timestamp":"2026-08-16T23:37:10.573849Z"}]}}
{"rx_ns": 42895968538500, "frame": {"channel":"book","type":"update","data":[{"symbol":"BTC/USD","bids":[{"price":62789.6,"qty":0.15923399}],"asks":[],"checksum":1974850468,"timestamp":"2026-08-16T23:37:10.596086Z"}]}}
{"rx_ns": 42895970132200, "frame": {"channel":"book","type":"update","data":[{"symbol":"BTC/USD","bids":[{"price":62741.0,"qty":0.00000000},{"price":62723.7,"qty":5.64716200}],"asks":[],"checksum":1974850468,"timestamp":"2026-08-16T23:37:10.598027Z"}]}}
{"rx_ns": 42895970302700, "frame": {"channel":"book","type":"update","data":[{"symbol":"BTC/USD","bids":[{"price":62737.6,"qty":0.00000000},{"price":62719.9,"qty":2.12501460}],"asks":[],"checksum":1974850468,"timestamp":"2026-08-16T23:37:10.598314Z"}]}}
{"rx_ns": 42895974281500, "frame": {"channel":"book","type":"update","data":[{"symbol":"BTC/USD","bids":[{"price":62737.7,"qty":2.19074954}],"asks":[],"checksum":1974850468,"timestamp":"2026-08-16T23:37:10.601782Z"}]}}
{"rx_ns": 42895974319100, "frame": {"channel":"book","type":"update","data":[{"symbol":"BTC/USD","bids":[{"price":62741.1,"qty":3.39074600}],"asks":[],"checksum":1974850468,"timestamp":"2026-08-16T23:37:10.601933Z"}]}}
{"rx_ns": 42895995826300, "frame": {"channel":"book","type":"update","data":[{"symbol":"BTC/USD","bids":[],"asks":[{"price":62803.9,"qty":1.81769693}],"checksum":2820170745,"timestamp":"2026-08-16T23:37:10.622759Z"}]}}
{"rx_ns": 42895997689300, "frame": {"channel":"book","type":"update","data":[{"symbol":"BTC/USD","bids":[],"asks":[{"price":62807.9,"qty":0.00000000},{"price":62883.7,"qty":1.31257213},{"price":62807.0,"qty":0.18489680}],"checksum":3636937355,"timestamp":"2026-08-16T23:37:10.623835Z"}]}}
{"rx_ns": 42896022601200, "frame": {"channel":"book","type":"update","data":[{"symbol":"BTC/USD","bids":[{"price":62783.6,"qty":0.00000000},{"price":62723.7,"qty":5.64716200},{"price":62781.3,"qty":0.07962747}],"asks":[],"checksum":3636937355,"timestamp":"2026-08-16T23:37:10.649713Z"}]}}
{"rx_ns": 42896037939300, "frame": {"channel":"book","type":"update","data":[{"symbol":"BTC/USD","bids":[],"asks":[{"price":62803.8,"qty":0.79613017},{"price":62802.6,"qty":4.99970683}],"checksum":3663539781,"timestamp":"2026-08-16T23:37:10.662581Z"}]}}
{"rx_ns": 42896038023900, "frame": {"channel":"book","type":"update","data":[{"symbol":"BTC/USD","bids":[{"price":62764.9,"qty":0.00000000},{"price":62723.7,"qty":5.64716200},{"price":62764.8,"qty":0.00318620}],"asks":[],"checksum":3663539781,"timestamp":"2026-08-16T23:37:10.664728Z"}]}}
{"rx_ns": 42896038049000, "frame": {"channel":"book","type":"update","data":[{"symbol":"BTC/USD","bids":[{"price":62793.1,"qty":0.00000000},{"price":62723.7,"qty":5.64716200},{"price":62793.0,"qty":0.79945252}],"asks":[],"checksum":120787881,"timestamp":"2026-08-16T23:37:10.665069Z"}]}}
{"rx_ns": 42896039196700, "frame": {"channel":"book","type":"update","data":[{"symbol":"BTC/USD","bids":[],"asks":[{"price":62812.6,"qty":0.00000000},{"price":62883.7,"qty":1.31257213},{"price":62812.5,"qty":0.00318620}],"checksum":120787881,"timestamp":"2026-08-16T23:37:10.665334Z"}]}}
{"rx_ns": 42896104341500, "frame": {"channel":"book","type":"update","data":[{"symbol":"BTC/USD","bids":[],"asks":[{"price":62808.0,"qty":0.80163538}],"checksum":966893802,"timestamp":"2026-08-16T23:37:10.731196Z"}]}}
{"rx_ns": 42896105397300, "frame": {"channel":"book","type":"update","data":[{"symbol":"BTC/USD","bids":[{"price":62789.6,"qty":0.00000000},{"price":62719.9,"qty":2.12501460}],"asks":[],"checksum":966893802,"timestamp":"2026-08-16T23:37:10.734087Z"}]}}
{"rx_ns": 42896119257400, "frame": {"channel":"book","type":"update","data":[{"symbol":"BTC/USD","bids":[{"price":62788.4,"qty":0.15923399}],"asks":[],"checksum":966893802,"timestamp":"2026-08-16T23:37:10.746132Z"}]}}
{"rx_ns": 42896141790200, "frame": {"channel":"book","type":"update","data":[{"symbol":"BTC/USD","bids":[{"price":62788.4,"qty":0.00000000},{"price":62719.9,"qty":2.12501460}],"asks":[],"checksum":966893802,"timestamp":"2026-08-16T23:37:10.769669Z"}]}}
{"rx_ns": 42896144709500, "frame": {"channel":"book","type":"update","data":[{"symbol":"BTC/USD","bids":[{"price":62793.0,"qty":0.00318620}],"asks":[],"checksum":4115027398,"timestamp":"2026-08-16T23:37:10.771692Z"}]}}
{"rx_ns": 42896147912300, "frame": {"channel":"book","type":"update","data":[{"symbol":"BTC/USD","bids":[{"price":62792.0,"qty":0.80160690}],"asks":[],"checksum":4115027398,"timestamp":"2026-08-16T23:37:10.773529Z"}]}}
{"rx_ns": 42896171530500, "frame": {"channel":"book","type":"update","data":[{"symbol":"BTC/USD","bids":[{"price":62788.3,"qty":0.15923399}],"asks":[],"checksum":4115027398,"timestamp":"2026-08-16T23:37:10.796168Z"}]}}
{"rx_ns": 42896362169900, "frame": {"channel":"book","type":"update","data":[{"symbol":"BTC/USD","bids":[],"asks":[{"price":62836.6,"qty":0.00000000},{"price":62883.7,"qty":1.31257213}],"checksum":4115027398,"timestamp":"2026-08-16T23:37:10.990082Z"}]}}
{"rx_ns": 42896364201100, "frame": {"channel":"book","type":"update","data":[{"symbol":"BTC/USD","bids":[],"asks":[{"price":62827.1,"qty":0.89114400}],"checksum":4115027398,"timestamp":"2026-08-16T23:37:10.991168Z"}]}}
{"rx_ns": 42896436393100, "frame": {"channel":"book","type":"update","data":[{"symbol":"BTC/USD","bids":[],"asks":[{"price":62845.0,"qty":0.00000000},{"price":62883.7,"qty":1.31257213}],"checksum":4115027398,"timestamp":"2026-08-16T23:37:11.063172Z"}]}}
{"rx_ns": 42896438076000, "frame": {"channel":"book","type":"update","data":[{"symbol":"BTC/USD","bids":[],"asks":[{"price":62844.9,"qty":0.99307764}],"checksum":4115027398,"timestamp":"2026-08-16T23:37:11.065589Z"}]}}
{"rx_ns": 42896448509400, "frame": {"channel":"book","type":"update","data":[{"symbol":"BTC/USD","bids":[{"price":62792.0,"qty":0.00532823}],"asks":[],"checksum":4115027398,"timestamp":"2026-08-16T23:37:11.076509Z"}]}}
{"rx_ns": 42896450656800, "frame": {"channel":"book","type":"update","data":[{"symbol":"BTC/USD","bids":[{"price":62792.7,"qty":0.79627054}],"asks":[],"checksum":4115027398,"timestamp":"2026-08-16T23:37:11.078334Z"}]}}
{"rx_ns": 42896508190500, "frame": {"channel":"book","type":"update","data":[{"symbol":"BTC/USD","bids":[{"price":62765.1,"qty":0.00000000},{"price":62723.7,"qty":5.64716200},{"price":62765.3,"qty":0.00303435}],"asks":[],"checksum":4115027398,"timestamp":"2026-08-16T23:37:11.135853Z"}]}}
{"rx_ns": 42896508271900, "frame": {"channel":"book","type":"update","data":[{"symbol":"BTC/USD","bids":[],"asks":[{"price":62834.7,"qty":0.00000000},{"price":62883.7,"qty":1.31257213},{"price":62834.5,"qty":0.00094656}],"checksum":4115027398,"timestamp":"2026-08-16T23:37:11.135951Z"}]}}
{"rx_ns": 42896550602400, "frame": {"channel":"book","type":"update","data":[{"symbol":"BTC/USD","bids":[],"asks":[{"price":62802.6,"qty":1.20957793},{"price":62803.6,"qty":3.79008208}],"checksum":3334117364,"timestamp":"2026-08-16T23:37:11.177506Z"}]}}
{"rx_ns": 42896550686900, "frame": {"channel":"book","type":"update","data":[{"symbol":"BTC/USD","bids":[],"asks":[{"price":62803.7,"qty":0.00000000},{"price":62883.3,"qty":0.02184000},{"price":62803.5,"qty":0.05598472}],"checksum":533271318,"timestamp":"2026-08-16T23:37:11.178829Z"}]}}
{"rx_ns": 42896583471800, "frame": {"channel":"book","type":"update","data":[{"symbol":"BTC/USD","bids":[],"asks":[{"price":62803.6,"qty":0.00000000},{"price":62883.3,"qty":0.02184000},{"price":62802.6,"qty":4.99971332}],"checksum":3762211511,"timestamp":"2026-08-16T23:37:11.210125Z"}]}}
{"rx_ns": 42896583548400, "frame": {"channel":"book","type":"update","data":[{"symbol":"BTC/USD","bids":[],"asks":[{"price":62803.5,"qty":0.00000000},{"price":62883.7,"qty":1.31257213},{"price":62803.7,"qty":0.05598472}],"checksum":1027078409,"timestamp":"2026-08-16T23:37:11.211864Z"}]}}
{"rx_ns": 42896636025100, "frame": {"channel":"book","type":"update","data":[{"symbol":"BTC/USD","bids":[],"asks":[{"price":62802.6,"qty":1.20957793},{"price":62803.6,"qty":3.79012046}],"checksum":3780872311,"timestamp":"2026-08-16T23:37:11.263989Z"}]}}
{"rx_ns": 42896663712500, "frame": {"channel":"heartbeat"}}
{"rx_ns": 42896684010900, "frame": {"channel":"book","type":"update","data":[{"symbol":"BTC/USD","bids":[],"asks":[{"price":62803.6,"qty":0.00000000},{"price":62883.3,"qty":0.02184000},{"price":62802.6,"qty":4.99971268}],"checksum":1382623541,"timestamp":"2026-08-16T23:37:11.311297Z"}]}}
{"rx_ns": 42896707486900, "frame": {"channel":"book","type":"update","data":[{"symbol":"BTC/USD","bids":[{"price":62788.3,"qty":0.00000000},{"price":62723.7,"qty":5.64716200}],"asks":[],"checksum":1382623541,"timestamp":"2026-08-16T23:37:11.334989Z"}]}}
{"rx_ns": 42896719097300, "frame": {"channel":"book","type":"update","data":[{"symbol":"BTC/USD","bids":[{"price":62788.4,"qty":0.15923399}],"asks":[],"checksum":1382623541,"timestamp":"2026-08-16T23:37:11.346079Z"}]}}
{"rx_ns": 42896838524900, "frame": {"channel":"book","type":"update","data":[{"symbol":"BTC/USD","bids":[{"price":62788.4,"qty":0.00000000},{"price":62723.7,"qty":5.64716200}],"asks":[],"checksum":1382623541,"timestamp":"2026-08-16T23:37:11.464763Z"}]}}
{"rx_ns": 42896838575700, "frame": {"channel":"book","type":"update","data":[{"symbol":"BTC/USD","bids":[],"asks":[{"price":62803.9,"qty":1.16228981}],"checksum":682064655,"timestamp":"2026-08-16T23:37:11.464974Z"}]}}
{"rx_ns": 42896843930900, "frame": {"channel":"book","type":"update","data":[{"symbol":"BTC/USD","bids":[],"asks":[{"price":62802.6,"qty":4.93011268}],"checksum":4071950562,"timestamp":"2026-08-16T23:37:11.470378Z"}]}}
{"rx_ns": 42896849081800, "frame": {"channel":"book","type":"update","data":[{"symbol":"BTC/USD","bids":[{"price":62792.7,"qty":0.00000000},{"price":62719.9,"qty":2.12501460}],"asks":[],"checksum":4071950562,"timestamp":"2026-08-16T23:37:11.472225Z"}]}}
{"rx_ns": 42896849122100, "frame": {"channel":"book","type":"update","data":[{"symbol":"BTC/USD","bids":[{"price":62793.4,"qty":0.79626152}],"asks":[],"checksum":2617994829,"timestamp":"2026-08-16T23:37:11.473715Z"}]}}
{"rx_ns": 42896851305400, "frame": {"channel":"book","type":"update","data":[{"symbol":"BTC/USD","bids":[],"asks":[{"price":62802.6,"qty":1.13997793},{"price":62803.6,"qty":3.79008208}],"checksum":4104263212,"timestamp":"2026-08-16T23:37:11.474505Z"}]}}
{"rx_ns": 42896851364800, "frame": {"channel":"book","type":"update","data":[{"symbol":"BTC/USD","bids":[],"asks":[{"price":62803.7,"qty":0.00000000},{"price":62883.3,"qty":0.02184000},{"price":62803.5,"qty":0.05598472}],"checksum":3358027762,"timestamp":"2026-08-16T23:37:11.475874Z"}]}}
{"rx_ns": 42896867385500, "frame": {"channel":"book","type":"update","data":[{"symbol":"BTC/USD","bids":[{"price":62793.4,"qty":0.00000000},{"price":62719.9,"qty":2.12501460}],"asks":[],"checksum":181708683,"timestamp":"2026-08-16T23:37:11.495336Z"}]}}
{"rx_ns": 42896870078100, "frame": {"channel":"book","type":"update","data":[{"symbol":"BTC/USD","bids":[{"price":62790.8,"qty":0.00000000},{"price":62718.0,"qty":0.00015944}],"asks":[],"checksum":181708683,"timestamp":"2026-08-16T23:37:11.495442Z"}]}}
{"rx_ns": 42896870130300, "frame": {"channel":"book","type":"update","data":[{"symbol":"BTC/USD","bids":[{"price":62789.0,"qty":0.15923399}],"asks":[],"checksum":181708683,"timestamp":"2026-08-16T23:37:11.496074Z"}]}}
{"rx_ns": 42896870158800, "frame": {"channel":"book","type":"update","data":[{"symbol":"BTC/USD","bids":[{"price":62791.9,"qty":0.79628006}],"asks":[],"checksum":181708683,"timestamp":"2026-08-16T23:37:11.496932Z"}]}}
{"rx_ns": 42896891362800, "frame": {"channel":"book","type":"update","data":[{"symbol":"BTC/USD","bids":[],"asks":[{"price":62808.0,"qty":0.79607759}],"checksum":2964866042,"timestamp":"2026-08-16T23:37:11.518945Z"}]}}
{"rx_ns": 42896905193900, "frame": {"channel":"book","type":"update","data":[{"symbol":"BTC/USD","bids":[],"asks":[{"price":62834.5,"qty":0.00000000},{"price":62883.3,"qty":0.02184000}],"checksum":2964866042,"timestamp":"2026-08-16T23:37:11.531525Z"}]}}
{"rx_ns": 42896944332400, "frame": {"channel":"book","type":"update","data":[{"symbol":"BTC/USD","bids":[{"price":62791.9,"qty":0.00000000},{"price":62719.9,"qty":2.12501460}],"asks":[],"checksum":2964866042,"timestamp":"2026-08-16T23:37:11.572358Z"}]}}
{"rx_ns": 42896946817700, "frame": {"channel":"book","type":"update","data":[{"symbol":"BTC/USD","bids":[{"price":62793.1,"qty":0.79626564}],"asks":[],"checksum":953773812,"timestamp":"2026-08-16T23:37:11.573970Z"}]}}
{"rx_ns": 42896948953300, "frame": {"channel":"book","type":"update","data":[{"symbol":"BTC/USD","bids":[{"price":62781.8,"qty":0.03185163}],"asks":[],"checksum":953773812,"timestamp":"2026-08-16T23:37:11.574423Z"}]}}
{"rx_ns": 42896950958000, "frame": {"channel":"book","type":"update","data":[{"symbol":"BTC/USD","bids":[{"price":62781.3,"qty":0.00000000},{"price":62719.9,"qty":2.12501460},{"price":62783.1,"qty":0.07962735}],"asks":[],"checksum":953773812,"timestamp":"2026-08-16T23:37:11.577591Z"}]}}
{"rx_ns": 42896950983300, "frame": {"channel":"book","type":"update","data":[{"symbol":"BTC/USD","bids":[{"price":62781.8,"qty":0.00000000},{"price":62719.9,"qty":2.12501460}],"asks":[],"checksum":953773812,"timestamp":"2026-08-16T23:37:11.577865Z"}]}}
{"rx_ns": 42896953267700, "frame": {"channel":"book","type":"update","data":[{"symbol":"BTC/USD","bids":[{"price":62783.7,"qty":0.03185093}],"asks":[],"checksum":953773812,"timestamp":"2026-08-16T23:37:11.581429Z"}]}}
{"rx_ns": 42897011982700, "frame": {"channel":"book","type":"update","data":[{"symbol":"BTC/USD","bids":[],"asks":[{"price":62803.6,"qty":0.00000000},{"price":62883.7,"qty":1.31257213},{"price":62806.9,"qty":3.79004492}],"checksum":1717844585,"timestamp":"2026-08-16T23:37:11.640118Z"}]}}
{"rx_ns": 42897013499600, "frame": {"channel":"book","type":"update","data":[{"symbol":"BTC/USD","bids":[],"asks":[{"price":62803.5,"qty":0.00000000},{"price":62883.7,"qty":1.31257213},{"price":62803.7,"qty":0.05598472}],"checksum":1794747155,"timestamp":"2026-08-16T23:37:11.641389Z"}]}}
{"rx_ns": 42897015095700, "frame": {"channel":"book","type":"update","data":[{"symbol":"BTC/USD","bids":[],"asks":[{"price":62807.0,"qty":0.00000000},{"price":62883.7,"qty":1.31257213},{"price":62806.8,"qty":0.18494780}],"checksum":3992508294,"timestamp":"2026-08-16T23:37:11.641459Z"}]}}
{"rx_ns": 42897138460900, "frame": {"channel":"book","type":"update","data":[{"symbol":"BTC/USD","bids":[{"price":62793.1,"qty":0.00000000},{"price":62719.9,"qty":2.12501460}],"asks":[],"checksum":3849491617,"timestamp":"2026-08-16T23:37:11.698183Z"}]}}
{"rx_ns": 42897138512900, "frame": {"channel":"book","type":"update","data":[{"symbol":"BTC/USD","bids":[],"asks":[{"price":62802.6,"qty":1.20957793}],"checksum":1117952424,"timestamp":"2026-08-16T23:37:11.698610Z"}]}}
{"rx_ns": 42897138525200, "frame": {"channel":"book","type":"update","data":[{"symbol":"BTC/USD","bids":[{"price":62789.0,"qty":0.00000000},{"price":62718.0,"qty":0.00015944}],"asks":[],"checksum":1117952424,"timestamp":"2026-08-16T23:37:11.699401Z"}]}}
{"rx_ns": 42897138542500, "frame": {"channel":"book","type":"update","data":[{"symbol":"BTC/USD","bids":[{"price":62792.0,"qty":0.00000000},{"price":62717.0,"qty":0.01531514}],"asks":[],"checksum":1117952424,"timestamp":"2026-08-16T23:37:11.699444Z"}]}}
{"rx_ns": 42897138552000, "frame": {"channel":"book","type":"update","data":[{"symbol":"BTC/USD","bids":[{"price":62790.0,"qty":0.00000000},{"price":62715.2,"qty":0.55690900}],"asks":[],"checksum":1117952424,"timestamp":"2026-08-16T23:37:11.701867Z"}]}}
{"rx_ns": 42897138560900, "frame": {"channel":"book","type":"update","data":[{"symbol":"BTC/USD","bids":[{"price":62784.0,"qty":0.00857697}],"asks":[],"checksum":1117952424,"timestamp":"2026-08-16T23:37:11.702029Z"}]}}
{"rx_ns": 42897138569300, "frame": {"channel":"book","type":"update","data":[{"symbol":"BTC/USD","bids":[{"price":62772.1,"qty":0.00000000},{"price":62713.3,"qty":0.10643220}],"asks":[],"checksum":1117952424,"timestamp":"2026-08-16T23:37:11.702302Z"}]}}
{"rx_ns": 42897138577900, "frame": {"channel":"book","type":"update","data":[{"symbol":"BTC/USD","bids":[{"price":62740.6,"qty":0.00000000},{"price":62712.7,"qty":0.15985195}],"asks":[],"checksum":1117952424,"timestamp":"2026-08-16T23:37:11.702592Z"}]}}
{"rx_ns": 42897138586800, "frame": {"channel":"book","type":"update","data":[{"symbol":"BTC/USD","bids":[{"price":62717.6,"qty":0.06960000}],"asks":[],"checksum":1117952424,"timestamp":"2026-08-16T23:37:11.702992Z"}]}}
{"rx_ns": 42897138594600, "frame": {"channel":"book","type":"update","data":[{"symbol":"BTC/USD","bids":[],"asks":[{"price":62808.0,"qty":0.80146697}],"checksum":2471279502,"timestamp":"2026-08-16T23:37:11.704540Z"}]}}
{"rx_ns": 42897138602600, "frame": {"channel":"book","type":"update","data":[{"symbol":"BTC/USD","bids":[{"price":62787.3,"qty":0.00000000},{"price":62712.7,"qty":0.15985195}],"asks":[],"checksum":2471279502,"timestamp":"2026-08-16T23:37:11.704679Z"}]}}
{"rx_ns": 42897138611500, "frame": {"channel":"book","type":"update","data":[{"symbol":"BTC/USD","bids":[{"price":62747.5,"qty":0.00000000},{"price":62712.6,"qty":1.50000000}],"asks":[],"checksum":2471279502,"timestamp":"2026-08-16T23:37:11.705205Z"}]}}
{"rx_ns": 42897138620400, "frame": {"channel":"book","type":"update","data":[{"symbol":"BTC/USD","bids":[{"price":62801.4,"qty":0.00000000},{"price":62712.1,"qty":5.65674500}],"asks":[],"checksum":2080124398,"timestamp":"2026-08-16T23:37:11.705438Z"}]}}
{"rx_ns": 42897138630500, "frame": {"channel":"book","type":"update","data":[{"symbol":"BTC/USD","bids":[{"price":62788.8,"qty":0.00000000},{"price":62710.2,"qty":0.00159400}],"asks":[],"checksum":2080124398,"timestamp":"2026-08-16T23:37:11.705521Z"}]}}
{"rx_ns": 42897138639300, "frame": {"channel":"book","type":"update","data":[{"symbol":"BTC/USD","bids":[{"price":62784.7,"qty":0.79637232}],"asks":[],"checksum":2080124398,"timestamp":"2026-08-16T23:37:11.707009Z"}]}}
{"rx_ns": 42897138647200, "frame": {"channel":"book","type":"update","data":[{"symbol":"BTC/USD","bids":[],"asks":[{"price":62840.8,"qty":0.00000000},{"price":62889.0,"qty":0.04690699},{"price":62840.5,"qty":0.00318620}],"checksum":2080124398,"timestamp":"2026-08-16T23:37:11.711008Z"}]}}
{"rx_ns": 42897138657900, "frame": {"channel":"book","type":"update","data":[{"symbol":"BTC/USD","bids":[{"price":62766.0,"qty":0.00005100}],"asks":[],"checksum":2080124398,"timestamp":"2026-08-16T23:37:11.711051Z"}]}}
{"rx_ns": 42897138666900, "frame": {"channel":"book","type":"update","data":[{"symbol":"BTC/USD","bids":[{"price":62779.2,"qty":0.00000000},{"price":62710.2,"qty":0.00159400}],"asks":[],"checksum":2080124398,"timestamp":"2026-08-16T23:37:11.712001Z"}]}}
{"rx_ns": 42897138675400, "frame": {"channel":"book","type":"update","data":[{"symbol":"BTC/USD","bids":[{"price":62798.8,"qty":0.02137959}],"asks":[],"checksum":934498548,"timestamp":"2026-08-16T23:37:11.712240Z"}]}}
{"rx_ns": 42897138683000, "frame": {"channel":"book","type":"update","data":[{"symbol":"BTC/USD","bids":[],"asks":[{"price":62806.9,"qty":0.00000000},{"price":62889.0,"qty":0.04690699},{"price":62802.6,"qty":4.99984308}],"checksum":3465157871,"timestamp":"2026-08-16T23:37:11.712472Z"}]}}
{"rx_ns": 42897138693900, "frame": {"channel":"book","type":"update","data":[{"symbol":"BTC/USD","bids":[],"asks":[{"price":62802.6,"qty":5.65525020}],"checksum":2187582356,"timestamp":"2026-08-16T23:37:11.714679Z"}]}}
{"rx_ns": 42897138701600, "frame": {"channel":"book","type":"update","data":[{"symbol":"BTC/USD","bids":[{"price":62789.7,"qty":0.00000000},{"price":62710.2,"qty":0.00159400}],"asks":[],"checksum":2187582356,"timestamp":"2026-08-16T23:37:11.716817Z"}]}}
{"rx_ns": 42897138710200, "frame": {"channel":"book","type":"update","data":[{"symbol":"BTC/USD","bids":[],"asks":[{"price":62885.7,"qty":0.06960000}],"checksum":2187582356,"timestamp":"2026-08-16T23:37:11.719430Z"}]}}
{"rx_ns": 42897138718200, "frame": {"channel":"book","type":"update","data":[{"symbol":"BTC/USD","bids":[{"price":62711.3,"qty":0.06960000}],"asks":[],"checksum":2187582356,"timestamp":"2026-08-16T23:37:11.720157Z"}]}}
{"rx_ns": 42897138726900, "frame": {"channel":"book","type":"update","data":[{"symbol":"BTC/USD","bids":[],"asks":[{"price":62803.7,"qty":0.00000000},{"price":62889.0,"qty":0.04690699},{"price":62802.6,"qty":5.71123492}],"checksum":3085279688,"timestamp":"2026-08-16T23:37:11.721981Z"}]}}
{"rx_ns": 42897138736000, "frame": {"channel":"book","type":"update","data":[{"symbol":"BTC/USD","bids":[{"price":62789.9,"qty":0.16663642}],"asks":[],"checksum":3085279688,"timestamp":"2026-08-16T23:37:11.746622Z"}]}}
{"rx_ns": 42897138744600, "frame": {"channel":"book","type":"update","data":[{"symbol":"BTC/USD","bids":[{"price":62798.8,"qty":0.00000000},{"price":62710.2,"qty":0.00159400}],"asks":[],"checksum":1214962299,"timestamp":"2026-08-16T23:37:11.756737Z"}]}}
{"rx_ns": 42897138753700, "frame": {"channel":"book","type":"update","data":[{"symbol":"BTC/USD","bids":[{"price":62797.5,"qty":0.02143059}],"asks":[],"checksum":1032397851,"timestamp":"2026-08-16T23:37:11.758379Z"}]}}
{"rx_ns": 42897142204700, "frame": {"channel":"book","type":"update","data":[{"symbol":"BTC/USD","bids":[{"price":62786.1,"qty":0.15923399}],"asks":[],"checksum":1032397851,"timestamp":"2026-08-16T23:37:11.770044Z"}]}}
{"rx_ns": 42897164133600, "frame": {"channel":"book","type":"update","data":[{"symbol":"BTC/USD","bids":[],"asks":[{"price":62834.5,"qty":0.00094656}],"checksum":1032397851,"timestamp":"2026-08-16T23:37:11.791981Z"}]}}
{"rx_ns": 42897180888600, "frame": {"channel":"book","type":"update","data":[{"symbol":"BTC/USD","bids":[],"asks":[{"price":62806.0,"qty":0.00537797}],"checksum":3704904613,"timestamp":"2026-08-16T23:37:11.805822Z"}]}}
{"rx_ns": 42897189525700, "frame": {"channel":"book","type":"update","data":[{"symbol":"BTC/USD","bids":[{"price":62790.5,"qty":0.79629802}],"asks":[],"checksum":3704904613,"timestamp":"2026-08-16T23:37:11.817609Z"}]}}
{"rx_ns": 42897190897700, "frame": {"channel":"book","type":"update","data":[{"symbol":"BTC/USD","bids":[{"price":62787.6,"qty":0.79633552}],"asks":[],"checksum":3704904613,"timestamp":"2026-08-16T23:37:11.817819Z"}]}}
{"rx_ns": 42897294854900, "frame": {"channel":"book","type":"update","data":[{"symbol":"BTC/USD","bids":[],"asks":[{"price":62814.0,"qty":0.00318401}],"checksum":3704904613,"timestamp":"2026-08-16T23:37:11.921827Z"}]}}
{"rx_ns": 42897298196600, "frame": {"channel":"book","type":"update","data":[{"symbol":"BTC/USD","bids":[],"asks":[{"price":62802.6,"qty":5.65525020},{"price":62803.7,"qty":0.05598472}],"checksum":1389439018,"timestamp":"2026-08-16T23:37:11.922993Z"}]}}
{"rx_ns": 42897300221900, "frame": {"channel":"book","type":"update","data":[{"symbol":"BTC/USD","bids":[{"price":62797.5,"qty":0.00005100}],"asks":[],"checksum":1073822854,"timestamp":"2026-08-16T23:37:11.924319Z"}]}}
{"rx_ns": 42897300245900, "frame": {"channel":"book","type":"update","data":[{"symbol":"BTC/USD","bids":[{"price":62798.8,"qty":0.02137959}],"asks":[],"checksum":1960920207,"timestamp":"2026-08-16T23:37:11.924378Z"}]}}
{"rx_ns": 42897348612200, "frame": {"channel":"book","type":"update","data":[{"symbol":"BTC/USD","bids":[{"price":62798.8,"qty":0.00000000},{"price":62712.6,"qty":1.50000000}],"asks":[],"checksum":1073822854,"timestamp":"2026-08-16T23:37:11.976558Z"}]}}
{"rx_ns": 42897349067900, "frame": {"channel":"book","type":"update","data":[{"symbol":"BTC/USD","bids":[{"price":62799.8,"qty":0.02137959}],"asks":[],"checksum":3642521851,"timestamp":"2026-08-16T23:37:11.976799Z"}]}}
{"rx_ns": 42897382545300, "frame": {"channel":"book","type":"update","data":[{"symbol":"BTC/USD","bids":[{"price":62787.6,"qty":0.00000000},{"price":62712.6,"qty":1.50000000}],"asks":[],"checksum":3642521851,"timestamp":"2026-08-16T23:37:12.010388Z"}]}}
{"rx_ns": 42897387381500, "frame": {"channel":"book","type":"update","data":[{"symbol":"BTC/USD","bids":[{"price":62747.0,"qty":0.03205704}],"asks":[],"checksum":3642521851,"timestamp":"2026-08-16T23:37:12.014777Z"}]}}
{"rx_ns": 42897388711900, "frame": {"channel":"book","type":"update","data":[{"symbol":"BTC/USD","bids":[{"price":62786.1,"qty":0.00000000},{"price":62712.6,"qty":1.50000000}],"asks":[],"checksum":3642521851,"timestamp":"2026-08-16T23:37:12.016630Z"}]}}
{"rx_ns": 42897419103700, "frame": {"channel":"book","type":"update","data":[{"symbol":"BTC/USD","bids":[{"price":62786.6,"qty":0.15923399}],"asks":[],"checksum":3642521851,"timestamp":"2026-08-16T23:37:12.046268Z"}]}}
{"rx_ns": 42897496250600, "frame": {"channel":"book","type":"update","data":[{"symbol":"BTC/USD","bids":[{"price":62786.6,"qty":0.00000000},{"price":62712.6,"qty":1.50000000}],"asks":[],"checksum":3642521851,"timestamp":"2026-08-16T23:37:12.123470Z"}]}}
{"rx_ns": 42897518948100, "frame": {"channel":"book","type":"update","data":[{"symbol":"BTC/USD","bids":[{"price":62786.7,"qty":0.15923399}],"asks":[],"checksum":3642521851,"timestamp":"2026-08-16T23:37:12.145970Z"}]}}
{"rx_ns": 42897546050700, "frame": {"channel":"book","type":"update","data":[{"symbol":"BTC/USD","bids":[{"price":62788.8,"qty":0.79631955}],"asks":[],"checksum":3642521851,"timestamp":"2026-08-16T23:37:12.174037Z"}]}}
{"rx_ns": 42897550031400, "frame": {"channel":"book","type":"update","data":[{"symbol":"BTC/USD","bids":[{"price":62764.8,"qty":0.00000000},{"price":62712.7,"qty":0.15985195},{"price":62764.7,"qty":0.00318620}],"asks":[],"checksum":3642521851,"timestamp":"2026-08-16T23:37:12.176240Z"}]}}
{"rx_ns": 42897550074400, "frame": {"channel":"book","type":"update","data":[{"symbol":"BTC/USD","bids":[{"price":62793.0,"qty":0.00000000},{"price":62712.7,"qty":0.15985195},{"price":62792.9,"qty":0.00334543}],"asks":[],"checksum":826747392,"timestamp":"2026-08-16T23:37:12.176483Z"}]}}
{"rx_ns": 42897553264500, "frame": {"channel":"book","type":"update","data":[{"symbol":"BTC/USD","bids":[],"asks":[{"price":62812.5,"qty":0.00000000},{"price":62883.7,"qty":1.31257213},{"price":62812.4,"qty":0.00318620}],"checksum":826747392,"timestamp":"2026-08-16T23:37:12.176806Z"}]}}
{"rx_ns": 42897554868800, "frame": {"channel":"book","type":"update","data":[{"symbol":"BTC/USD","bids":[{"price":62790.5,"qty":0.00000000},{"price":62712.6,"qty":1.50000000}],"asks":[],"checksum":826747392,"timestamp":"2026-08-16T23:37:12.182647Z"}]}}
{"rx_ns": 42897557074300, "frame": {"channel":"book","type":"update","data":[{"symbol":"BTC/USD","bids":[{"price":62791.2,"qty":0.79793185}],"asks":[],"checksum":826747392,"timestamp":"2026-08-16T23:37:12.183882Z"}]}}
{"rx_ns": 42897566289500, "frame": {"channel":"book","type":"update","data":[{"symbol":"BTC/USD","bids":[{"price":62799.8,"qty":0.00000000},{"price":62712.1,"qty":5.65674500}],"asks":[],"checksum":3187817973,"timestamp":"2026-08-16T23:37:12.194533Z"}]}}
{"rx_ns": 42897568412400, "frame": {"channel":"book","type":"update","data":[{"symbol":"BTC/USD","bids":[{"price":62800.7,"qty":0.02137959}],"asks":[],"checksum":585990068,"timestamp":"2026-08-16T23:37:12.194725Z"}]}}
{"rx_ns": 42897585166600, "frame": {"channel":"book","type":"update","data":[{"symbol":"BTC/USD","bids":[{"price":62740.3,"qty":0.05430412}],"asks":[],"checksum":585990068,"timestamp":"2026-08-16T23:37:12.213070Z"}]}}
{"rx_ns": 42897668392800, "frame": {"channel":"heartbeat"}}
{"rx_ns": 42897843184600, "frame": {"channel":"book","type":"update","data":[{"symbol":"BTC/USD","bids":[{"price":62791.2,"qty":0.00164300}],"asks":[],"checksum":585990068,"timestamp":"2026-08-16T23:37:12.470751Z"}]}}
{"rx_ns": 42897843630900, "frame": {"channel":"book","type":"update","data":[{"symbol":"BTC/USD","bids":[{"price":62788.8,"qty":0.00000000},{"price":62712.6,"qty":1.50000000}],"asks":[],"checksum":585990068,"timestamp":"2026-08-16T23:37:12.470872Z"}]}}
{"rx_ns": 42897846778900, "frame": {"channel":"book","type":"update","data":[{"symbol":"BTC/USD","bids":[{"price":62792.0,"qty":0.79627932}],"asks":[],"checksum":585990068,"timestamp":"2026-08-16T23:37:12.472427Z"}]}}
{"rx_ns": 42897848006300, "frame": {"channel":"book","type":"update","data":[{"symbol":"BTC/USD","bids":[{"price":62789.8,"qty":0.79630690}],"asks":[],"checksum":585990068,"timestamp":"2026-08-16T23:37:12.474101Z"}]}}
{"rx_ns": 42898038593600, "frame": {"channel":"book","type":"update","data":[{"symbol":"BTC/USD","bids":[{"price":62786.7,"qty":0.00000000},{"price":62712.7,"qty":0.15985195}],"asks":[],"checksum":585990068,"timestamp":"2026-08-16T23:37:12.664881Z"}]}}
{"rx_ns": 42898040972700, "frame": {"channel":"book","type":"update","data":[{"symbol":"BTC/USD","bids":[],"asks":[{"price":62837.3,"qty":0.00000000},{"price":62883.7,"qty":1.31257213}],"checksum":585990068,"timestamp":"2026-08-16T23:37:12.667570Z"}]}}
{"rx_ns": 42898043491500, "frame": {"channel":"book","type":"update","data":[{"symbol":"BTC/USD","bids":[],"asks":[{"price":62833.1,"qty":0.23769319}],"checksum":585990068,"timestamp":"2026-08-16T23:37:12.669778Z"}]}}
{"rx_ns": 42898043538900, "frame": {"channel":"book","type":"update","data":[{"symbol":"BTC/USD","bids":[],"asks":[{"price":62822.3,"qty":0.10331161}],"checksum":585990068,"timestamp":"2026-08-16T23:37:12.669815Z"}]}}
{"rx_ns": 42898043552200, "frame": {"channel":"book","type":"update","data":[{"symbol":"BTC/USD","bids":[],"asks":[{"price":62832.7,"qty":1.02945016}],"checksum":585990068,"timestamp":"2026-08-16T23:37:12.669845Z"}]}}
{"rx_ns": 42898045392900, "frame": {"channel":"book","type":"update","data":[{"symbol":"BTC/USD","bids":[{"price":62740.3,"qty":0.00000000},{"price":62712.6,"qty":1.50000000}],"asks":[],"checksum":585990068,"timestamp":"2026-08-16T23:37:12.670360Z"}]}}
{"rx_ns": 42898060835800, "frame": {"channel":"book","type":"update","data":[{"symbol":"BTC/USD","bids":[{"price":62784.0,"qty":0.00539144}],"asks":[],"checksum":585990068,"timestamp":"2026-08-16T23:37:12.688293Z"}]}}
{"rx_ns": 42898061816800, "frame": {"channel":"book","type":"update","data":[{"symbol":"BTC/USD","bids":[{"price":62778.0,"qty":0.00318583}],"asks":[],"checksum":585990068,"timestamp":"2026-08-16T23:37:12.690011Z"}]}}
{"rx_ns": 42898078688100, "frame": {"channel":"book","type":"update","data":[{"symbol":"BTC/USD","bids":[{"price":62783.7,"qty":0.00000000},{"price":62712.6,"qty":1.50000000},{"price":62781.3,"qty":0.07962845}],"asks":[],"checksum":585990068,"timestamp":"2026-08-16T23:37:12.704942Z"}]}}
{"rx_ns": 42898078801700, "frame": {"channel":"book","type":"update","data":[{"symbol":"BTC/USD","bids":[{"price":62792.0,"qty":0.00000000},{"price":62712.6,"qty":1.50000000}],"asks":[],"checksum":585990068,"timestamp":"2026-08-16T23:37:12.705991Z"}]}}
{"rx_ns": 42898083866500, "frame": {"channel":"book","type":"update","data":[{"symbol":"BTC/USD","bids":[{"price":62783.1,"qty":0.00000000},{"price":62712.1,"qty":5.65674500},{"price":62781.9,"qty":0.03185137}],"asks":[],"checksum":585990068,"timestamp":"2026-08-16T23:37:12.709966Z"}]}}
{"rx_ns": 42898137201900, "frame": {"channel":"book","type":"update","data":[{"symbol":"BTC/USD","bids":[{"price":62789.8,"qty":0.00000000},{"price":62712.1,"qty":5.65674500}],"asks":[],"checksum":585990068,"timestamp":"2026-08-16T23:37:12.763207Z"}]}}
{"rx_ns": 42898140449700, "frame": {"channel":"book","type":"update","data":[{"symbol":"BTC/USD","bids":[{"price":62779.7,"qty":0.00000000},{"price":62710.2,"qty":0.00159400}],"asks":[],"checksum":585990068,"timestamp":"2026-08-16T23:37:12.764257Z"}]}}
{"rx_ns": 42898140516000, "frame": {"channel":"book","type":"update","data":[{"symbol":"BTC/USD","bids":[],"asks":[{"price":62835.2,"qty":0.00000000},{"price":62881.2,"qty":0.16061732}],"checksum":585990068,"timestamp":"2026-08-16T23:37:12.764494Z"}]}}
{"rx_ns": 42898143293100, "frame": {"channel":"book","type":"update","data":[{"symbol":"BTC/USD","bids":[{"price":62789.1,"qty":0.79631559}],"asks":[],"checksum":585990068,"timestamp":"2026-08-16T23:37:12.765986Z"}]}}
{"rx_ns": 42898143346500, "frame": {"channel":"book","type":"update","data":[{"symbol":"BTC/USD","bids":[{"price":62775.4,"qty":2.38946781}],"asks":[],"checksum":585990068,"timestamp":"2026-08-16T23:37:12.766249Z"}]}}
{"rx_ns": 42898143364900, "frame": {"channel":"book","type":"update","data":[{"symbol":"BTC/USD","bids":[],"asks":[{"price":62823.4,"qty":0.00050000}],"checksum":585990068,"timestamp":"2026-08-16T23:37:12.767520Z"}]}}
{"rx_ns": 42898150624200, "frame": {"channel":"book","type":"update","data":[{"symbol":"BTC/USD","bids":[],"asks":[{"price":62839.8,"qty":0.00000000},{"price":62881.2,"qty":0.16061732}],"checksum":585990068,"timestamp":"2026-08-16T23:37:12.770266Z"}]}}
{"rx_ns": 42898150737100, "frame": {"channel":"book","type":"update","data":[{"symbol":"BTC/USD","bids":[],"asks":[{"price":62829.0,"qty":0.00000000},{"price":62883.3,"qty":0.02184000}],"checksum":585990068,"timestamp":"2026-08-16T23:37:12.770323Z"}]}}
{"rx_ns": 42898150765300, "frame": {"channel":"book","type":"update","data":[{"symbol":"BTC/USD","bids":[{"price":62789.9,"qty":0.09703642}],"asks":[],"checksum":585990068,"timestamp":"2026-08-16T23:37:12.770387Z"}]}}
{"rx_ns": 42898150781700, "frame": {"channel":"book","type":"update","data":[{"symbol":"BTC/USD","bids":[{"price":62785.9,"qty":0.15923399}],"asks":[],"checksum":585990068,"timestamp":"2026-08-16T23:37:12.770496Z"}]}}
{"rx_ns": 42898150796100, "frame": {"channel":"book","type":"update","data":[{"symbol":"BTC/USD","bids":[{"price":62785.9,"qty":0.00000000},{"price":62712.6,"qty":1.50000000}],"asks":[],"checksum":585990068,"timestamp":"2026-08-16T23:37:12.770757Z"}]}}
{"rx_ns": 42898150806900, "frame": {"channel":"book","type":"update","data":[{"symbol":"BTC/USD","bids":[{"price":62789.1,"qty":0.00000000},{"price":62712.1,"qty":5.65674500}],"asks":[],"checksum":585990068,"timestamp":"2026-08-16T23:37:12.771098Z"}]}}
{"rx_ns": 42898150817700, "frame": {"channel":"book","type":"update","data":[{"symbol":"BTC/USD","bids":[{"price":62784.7,"qty":0.00000000},{"price":62711.3,"qty":0.06960000}],"asks":[],"checksum":585990068,"timestamp":"2026-08-16T23:37:12.771107Z"}]}}
{"rx_ns": 42898150828700, "frame": {"channel":"book","type":"update","data":[{"symbol":"BTC/USD","bids":[{"price":62711.3,"qty":0.00000000},{"price":62710.2,"qty":0.00159400}],"asks":[],"checksum":585990068,"timestamp":"2026-08-16T23:37:12.771239Z"}]}}
{"rx_ns": 42898150839200, "frame": {"channel":"book","type":"update","data":[{"symbol":"BTC/USD","bids":[{"price":62775.4,"qty":0.00000000},{"price":62709.6,"qty":0.10195271}],"asks":[],"checksum":585990068,"timestamp":"2026-08-16T23:37:12.771672Z"}]}}
{"rx_ns": 42898159085700, "frame": {"channel":"book","type":"update","data":[{"symbol":"BTC/USD","bids":[{"price":62733.2,"qty":0.00000000},{"price":62709.2,"qty":0.43000000},{"price":62732.8,"qty":0.70609000}],"asks":[],"checksum":585990068,"timestamp":"2026-08-16T23:37:12.771824Z"}]}}
{"rx_ns": 42898159154000, "frame": {"channel":"book","type":"update","data":[{"symbol":"BTC/USD","bids":[{"price":62730.1,"qty":0.00000000},{"price":62709.2,"qty":0.43000000},{"price":62729.7,"qty":0.35581000}],"asks":[],"checksum":585990068,"timestamp":"2026-08-16T23:37:12.771936Z"}]}}
{"rx_ns": 42898159169600, "frame": {"channel":"book","type":"update","data":[{"symbol":"BTC/USD","bids":[{"price":62762.2,"qty":0.00000000},{"price":62709.2,"qty":0.43000000}],"asks":[],"checksum":585990068,"timestamp":"2026-08-16T23:37:12.772076Z"}]}}
{"rx_ns": 42898159180700, "frame": {"channel":"book","type":"update","data":[{"symbol":"BTC/USD","bids":[{"price":62763.6,"qty":0.00000000},{"price":62707.9,"qty":0.00079734}],"asks":[],"checksum":585990068,"timestamp":"2026-08-16T23:37:12.772194Z"}]}}
{"rx_ns": 42898159190700, "frame": {"channel":"book","type":"update","data":[{"symbol":"BTC/USD","bids":[{"price":62761.1,"qty":0.00000000},{"price":62707.2,"qty":0.02137959}],"asks":[],"checksum":585990068,"timestamp":"2026-08-16T23:37:12.772220Z"}]}}
{"rx_ns": 42898159200200, "frame": {"channel":"book","type":"update","data":[{"symbol":"BTC/USD","bids":[{"price":62788.0,"qty":0.00000000},{"price":62706.6,"qty":0.00410211}],"asks":[],"checksum":585990068,"timestamp":"2026-08-16T23:37:12.772529Z"}]}}
{"rx_ns": 42898159210100, "frame": {"channel":"book","type":"update","data":[{"symbol":"BTC/USD","bids":[{"price":62782.0,"qty":0.00518958}],"asks":[],"checksum":585990068,"timestamp":"2026-08-16T23:37:12.772625Z"}]}}
{"rx_ns": 42898159219900, "frame": {"channel":"book","type":"update","data":[{"symbol":"BTC/USD","bids":[],"asks":[{"price":62813.9,"qty":0.00000000},{"price":62883.7,"qty":1.31257213}],"checksum":585990068,"timestamp":"2026-08-16T23:37:12.772859Z"}]}}
{"rx_ns": 42898159229700, "frame": {"channel":"book","type":"update","data":[{"symbol":"BTC/USD","bids":[{"price":62790.2,"qty":0.00000000},{"price":62706.6,"qty":0.00410211}],"asks":[],"checksum":585990068,"timestamp":"2026-08-16T23:37:12.772971Z"}]}}
{"rx_ns": 42898159239200, "frame": {"channel":"book","type":"update","data":[{"symbol":"BTC/USD","bids":[{"price":62770.7,"qty":0.00455372}],"asks":[],"checksum":585990068,"timestamp":"2026-08-16T23:37:12.773388Z"}]}}
{"rx_ns": 42898159247900, "frame": {"channel":"book","type":"update","data":[{"symbol":"BTC/USD","bids":[{"price":62771.5,"qty":0.03462373}],"asks":[],"checksum":585990068,"timestamp":"2026-08-16T23:37:12.773793Z"}]}}
{"rx_ns": 42898159255800, "frame": {"channel":"book","type":"update","data":[{"symbol":"BTC/USD","bids":[{"price":62736.5,"qty":0.06960000}],"asks":[],"checksum":585990068,"timestamp":"2026-08-16T23:37:12.774607Z"}]}}
{"rx_ns": 42898159266300, "frame": {"channel":"book","type":"update","data":[{"symbol":"BTC/USD","bids":[{"price":62732.8,"qty":0.00000000},{"price":62706.6,"qty":0.00410211},{"price":62731.6,"qty":0.70609000}],"asks":[],"checksum":585990068,"timestamp":"2026-08-16T23:37:12.774647Z"}]}}
{"rx_ns": 42898159276900, "frame": {"channel":"book","type":"update","data":[{"symbol":"BTC/USD","bids":[{"price":62760.8,"qty":0.23900000}],"asks":[],"checksum":585990068,"timestamp":"2026-08-16T23:37:12.774715Z"}]}}
{"rx_ns": 42898159285300, "frame": {"channel":"book","type":"update","data":[{"symbol":"BTC/USD","bids":[{"price":62729.7,"qty":0.00000000},{"price":62707.2,"qty":0.02137959},{"price":62728.5,"qty":0.35592160}],"asks":[],"checksum":585990068,"timestamp":"2026-08-16T23:37:12.774807Z"}]}}
{"rx_ns": 42898159295200, "frame": {"channel":"book","type":"update","data":[{"symbol":"BTC/USD","bids":[{"price":62800.7,"qty":0.00000000},{"price":62706.6,"qty":0.00410211}],"asks":[],"checksum":3187817973,"timestamp":"2026-08-16T23:37:12.775009Z"}]}}
{"rx_ns": 42898159304700, "frame": {"channel":"book","type":"update","data":[{"symbol":"BTC/USD","bids":[{"price":62747.0,"qty":0.00000000},{"price":62706.5,"qty":0.00162380}],"asks":[],"checksum":3187817973,"timestamp":"2026-08-16T23:37:12.775348Z"}]}}
{"rx_ns": 42898159314300, "frame": {"channel":"book","type":"update","data":[{"symbol":"BTC/USD","bids":[{"price":62774.1,"qty":0.00000000},{"price":62699.8,"qty":0.00136206},{"price":62773.5,"qty":0.10292560}],"asks":[],"checksum":3187817973,"timestamp":"2026-08-16T23:37:12.776133Z"}]}}
{"rx_ns": 42898159326600, "frame": {"channel":"book","type":"update","data":[{"symbol":"BTC/USD","bids":[],"asks":[{"price":62818.7,"qty":0.00222509},{"price":62813.8,"qty":1.79195972}],"checksum":3187817973,"timestamp":"2026-08-16T23:37:12.776724Z"}]}}
{"rx_ns": 42898159399600, "frame": {"channel":"book","type":"update","data":[{"symbol":"BTC/USD","bids":[{"price":62798.4,"qty":0.02137959}],"asks":[],"checksum":3545983341,"timestamp":"2026-08-16T23:37:12.776831Z"}]}}
{"rx_ns": 42898159412900, "frame": {"channel":"book","type":"update","data":[{"symbol":"BTC/USD","bids":[],"asks":[{"price":62832.0,"qty":0.00000000},{"price":62889.0,"qty":0.04690699}],"checksum":3545983341,"timestamp":"2026-08-16T23:37:12.777400Z"}]}}
{"rx_ns": 42898159423800, "frame": {"channel":"book","type":"update","data":[{"symbol":"BTC/USD","bids":[{"price":62778.4,"qty":0.00000000},{"price":62706.5,"qty":0.00162380}],"asks":[],"checksum":3545983341,"timestamp":"2026-08-16T23:37:12.777496Z"}]}}
{"rx_ns": 42898159432900, "frame": {"channel":"book","type":"update","data":[{"symbol":"BTC/USD","bids":[{"price":62789.4,"qty":0.00000000},{"price":62699.8,"qty":0.00136206}],"asks":[],"checksum":3545983341,"timestamp":"2026-08-16T23:37:12.777515Z"}]}}
{"rx_ns": 42898159442300, "frame": {"channel":"book","type":"update","data":[{"symbol":"BTC/USD","bids":[{"price":62766.0,"qty":0.65545812}],"asks":[],"checksum":3545983341,"timestamp":"2026-08-16T23:37:12.777733Z"}]}}
{"rx_ns": 42898170667400, "frame": {"channel":"book","type":"update","data":[{"symbol":"BTC/USD","bids":[],"asks":[{"price":62802.6,"qty":5.76525020}],"checksum":1486616732,"timestamp":"2026-08-16T23:37:12.778064Z"}]}}
{"rx_ns": 42898170718100, "frame": {"channel":"book","type":"update","data":[{"symbol":"BTC/USD","bids":[{"price":62711.3,"qty":0.06960000}],"asks":[],"checksum":1486616732,"timestamp":"2026-08-16T23:37:12.778334Z"}]}}
{"rx_ns": 42898170728200, "frame": {"channel":"book","type":"update","data":[{"symbol":"BTC/USD","bids":[{"price":62786.0,"qty":0.00000000},{"price":62699.8,"qty":0.00136206}],"asks":[],"checksum":1486616732,"timestamp":"2026-08-16T23:37:12.778639Z"}]}}
{"rx_ns": 42898170738500, "frame": {"channel":"book","type":"update","data":[{"symbol":"BTC/USD","bids":[],"asks":[{"price":62818.8,"qty":0.00000000},{"price":62890.4,"qty":1.50000000}],"checksum":1486616732,"timestamp":"2026-08-16T23:37:12.778809Z"}]}}
{"rx_ns": 42898170747100, "frame": {"channel":"book","type":"update","data":[{"symbol":"BTC/USD","bids":[{"price":62780.0,"qty":0.00518974}],"asks":[],"checksum":1486616732,"timestamp":"2026-08-16T23:37:12.778823Z"}]}}
{"rx_ns": 42898170754500, "frame": {"channel":"book","type":"update","data":[{"symbol":"BTC/USD","bids":[{"price":62771.5,"qty":0.00000000},{"price":62699.8,"qty":0.00136206}],"asks":[],"checksum":1486616732,"timestamp":"2026-08-16T23:37:12.778981Z"}]}}
{"rx_ns": 42898170762700, "frame": {"channel":"book","type":"update","data":[{"symbol":"BTC/USD","bids":[],"asks":[{"price":62803.7,"qty":0.00000000},{"price":62891.1,"qty":0.47681308},{"price":62802.6,"qty":5.82123492}],"checksum":2303946671,"timestamp":"2026-08-16T23:37:12.779302Z"}]}}
{"rx_ns": 42898170772200, "frame": {"channel":"book","type":"update","data":[{"symbol":"BTC/USD","bids":[{"price":62797.6,"qty":0.00000000},{"price":62699.7,"qty":5.58216167}],"asks":[],"checksum":110839787,"timestamp":"2026-08-16T23:37:12.779406Z"}]}}
{"rx_ns": 42898170779900, "frame": {"channel":"book","type":"update","data":[{"symbol":"BTC/USD","bids":[{"price":62777.6,"qty":0.00000000},{"price":62698.3,"qty":0.04150088}],"asks":[],"checksum":110839787,"timestamp":"2026-08-16T23:37:12.780205Z"}]}}
{"rx_ns": 42898170789100, "frame": {"channel":"book","type":"update","data":[{"symbol":"BTC/USD","bids":[{"price":62709.6,"qty":0.04678000},{"price":62703.8,"qty":0.05517271}],"asks":[],"checksum":110839787,"timestamp":"2026-08-16T23:37:12.780395Z"}]}}
{"rx_ns": 42898170796900, "frame": {"channel":"book","type":"update","data":[{"symbol":"BTC/USD","bids":[{"price":62781.2,"qty":0.01311942}],"asks":[],"checksum":110839787,"timestamp":"2026-08-16T23:37:12.781432Z"}]}}
{"rx_ns": 42898170804300, "frame": {"channel":"book","type":"update","data":[{"symbol":"BTC/USD","bids":[{"price":62774.0,"qty":1.13227200}],"asks":[],"checksum":110839787,"timestamp":"2026-08-16T23:37:12.782337Z"}]}}
{"rx_ns": 42898170811300, "frame": {"channel":"book","type":"update","data":[{"symbol":"BTC/USD","bids":[{"price":62758.5,"qty":0.15920000}],"asks":[],"checksum":110839787,"timestamp":"2026-08-16T23:37:12.782651Z"}]}}
{"rx_ns": 42898170818600, "frame": {"channel":"book","type":"update","data":[{"symbol":"BTC/USD","bids":[{"price":62774.0,"qty":0.74369300}],"asks":[],"checksum":110839787,"timestamp":"2026-08-16T23:37:12.783274Z"}]}}
{"rx_ns": 42898170825500, "frame": {"channel":"book","type":"update","data":[{"symbol":"BTC/USD","bids":[],"asks":[{"price":62805.6,"qty":0.65540712}],"checksum":1758381660,"timestamp":"2026-08-16T23:37:12.784945Z"}]}}
{"rx_ns": 42898170834100, "frame": {"channel":"book","type":"update","data":[{"symbol":"BTC/USD","bids":[{"price":62752.8,"qty":1.96622134}],"asks":[],"checksum":1758381660,"timestamp":"2026-08-16T23:37:12.785007Z"}]}}
{"rx_ns": 42898170841200, "frame": {"channel":"book","type":"update","data":[{"symbol":"BTC/USD","bids":[{"price":62784.0,"qty":0.00000000},{"price":62703.8,"qty":0.05517271}],"asks":[],"checksum":1758381660,"timestamp":"2026-08-16T23:37:12.785205Z"}]}}
{"rx_ns": 42898170849600, "frame": {"channel":"book","type":"update","data":[{"symbol":"BTC/USD","bids":[{"price":62778.0,"qty":0.00837574}],"asks":[],"checksum":1758381660,"timestamp":"2026-08-16T23:37:12.785348Z"}]}}
{"rx_ns": 42898170856600, "frame": {"channel":"book","type":"update","data":[{"symbol":"BTC/USD","bids":[{"price":62705.0,"qty":0.06960000}],"asks":[],"checksum":1758381660,"timestamp":"2026-08-16T23:37:12.785469Z"}]}}
{"rx_ns": 42898170863700, "frame": {"channel":"book","type":"update","data":[{"symbol":"BTC/USD","bids":[],"asks":[{"price":62844.4,"qty":0.02057681}],"checksum":1758381660,"timestamp":"2026-08-16T23:37:12.785751Z"}]}}
{"rx_ns": 42898177021700, "frame": {"channel":"book","type":"update","data":[{"symbol":"BTC/USD","bids":[],"asks":[{"price":62813.8,"qty":0.19620257},{"price":62818.7,"qty":1.59798224}],"checksum":1758381660,"timestamp":"2026-08-16T23:37:12.786180Z"}]}}
{"rx_ns": 42898177092100, "frame": {"channel":"book","type":"update","data":[{"symbol":"BTC/USD","bids":[{"price":62770.0,"qty":0.39276310}],"asks":[],"checksum":1758381660,"timestamp":"2026-08-16T23:37:12.786340Z"}]}}
{"rx_ns": 42898177108000, "frame": {"channel":"book","type":"update","data":[{"symbol":"BTC/USD","bids":[],"asks":[{"price":62885.7,"qty":0.06960000}],"checksum":1758381660,"timestamp":"2026-08-16T23:37:12.787062Z"}]}}
{"rx_ns": 42898177119500, "frame": {"channel":"book","type":"update","data":[{"symbol":"BTC/USD","bids":[{"price":62765.2,"qty":0.00000000},{"price":62703.8,"qty":0.05517271},{"price":62758.8,"qty":0.00162380}],"asks":[],"checksum":1758381660,"timestamp":"2026-08-16T23:37:12.788439Z"}]}}
{"rx_ns": 42898177137100, "frame": {"channel":"book","type":"update","data":[{"symbol":"BTC/USD","bids":[],"asks":[{"price":62808.0,"qty":0.80465128}],"checksum":629431951,"timestamp":"2026-08-16T23:37:12.788738Z"}]}}
{"rx_ns": 42898177155100, "frame": {"channel":"book","type":"update","data":[{"symbol":"BTC/USD","bids":[{"price":62773.5,"qty":0.00000000},{"price":62703.8,"qty":0.05517271},{"price":62763.7,"qty":0.10294167}],"asks":[],"checksum":629431951,"timestamp":"2026-08-16T23:37:12.790815Z"}]}}
{"rx_ns": 42898177166700, "frame": {"channel":"book","type":"update","data":[{"symbol":"BTC/USD","bids":[{"price":62717.0,"qty":0.00000000},{"price":62703.8,"qty":0.05517271}],"asks":[],"checksum":629431951,"timestamp":"2026-08-16T23:37:12.791244Z"}]}}
{"rx_ns": 42898177177600, "frame": {"channel":"book","type":"update","data":[{"symbol":"BTC/USD","bids":[],"asks":[{"price":62806.8,"qty":0.00005100},{"price":62805.5,"qty":0.18489680}],"checksum":3971036504,"timestamp":"2026-08-16T23:37:12.792748Z"}]}}
{"rx_ns": 42898177188700, "frame": {"channel":"book","type":"update","data":[{"symbol":"BTC/USD","bids":[],"asks":[{"price":62818.7,"qty":0.00222509},{"price":62813.8,"qty":1.79195972}],"checksum":3971036504,"timestamp":"2026-08-16T23:37:12.797075Z"}]}}
{"rx_ns": 42898177253300, "frame": {"channel":"book","type":"update","data":[{"symbol":"BTC/USD","bids":[],"asks":[{"price":62833.4,"qty":0.00000000},{"price":62889.0,"qty":0.04690699},{"price":62830.4,"qty":0.28000000}],"checksum":3971036504,"timestamp":"2026-08-16T23:37:12.797106Z"}]}}
{"rx_ns": 42898177266500, "frame": {"channel":"book","type":"update","data":[{"symbol":"BTC/USD","bids":[],"asks":[{"price":62804.0,"qty":0.00518776}],"checksum":3551524133,"timestamp":"2026-08-16T23:37:12.797171Z"}]}}
{"rx_ns": 42898189124000, "frame": {"channel":"book","type":"update","data":[{"symbol":"BTC/USD","bids":[],"asks":[{"price":62818.8,"qty":1.96622134}],"checksum":3551524133,"timestamp":"2026-08-16T23:37:12.797679Z"}]}}
{"rx_ns": 42898189187200, "frame": {"channel":"book","type":"update","data":[{"symbol":"BTC/USD","bids":[],"asks":[{"price":62809.5,"qty":2.38817573}],"checksum":3551524133,"timestamp":"2026-08-16T23:37:12.803193Z"}]}}
{"rx_ns": 42898189198800, "frame": {"channel":"book","type":"update","data":[{"symbol":"BTC/USD","bids":[],"asks":[{"price":62862.0,"qty":0.15142628}],"checksum":3551524133,"timestamp":"2026-08-16T23:37:12.804461Z"}]}}
{"rx_ns": 42898189208400, "frame": {"channel":"book","type":"update","data":[{"symbol":"BTC/USD","bids":[],"asks":[{"price":62864.2,"qty":5.56756520}],"checksum":3551524133,"timestamp":"2026-08-16T23:37:12.804623Z"}]}}
{"rx_ns": 42898189217000, "frame": {"channel":"book","type":"update","data":[{"symbol":"BTC/USD","bids":[{"price":62794.4,"qty":0.05598472}],"asks":[],"checksum":824940461,"timestamp":"2026-08-16T23:37:12.804659Z"}]}}
{"rx_ns": 42898189229800, "frame": {"channel":"book","type":"update","data":[{"symbol":"BTC/USD","bids":[{"price":62763.7,"qty":0.00000000},{"price":62703.8,"qty":0.05517271},{"price":62774.1,"qty":0.10292462}],"asks":[],"checksum":824940461,"timestamp":"2026-08-16T23:37:12.804725Z"}]}}
{"rx_ns": 42898189242200, "frame": {"channel":"book","type":"update","data":[{"symbol":"BTC/USD","bids":[{"price":62782.0,"qty":0.80159566}],"asks":[],"checksum":824940461,"timestamp":"2026-08-16T23:37:12.804746Z"}]}}
{"rx_ns": 42898189251400, "frame": {"channel":"book","type":"update","data":[{"symbol":"BTC/USD","bids":[{"price":62739.6,"qty":7.96943819}],"asks":[],"checksum":824940461,"timestamp":"2026-08-16T23:37:12.804897Z"}]}}
{"rx_ns": 42898189259900, "frame": {"channel":"book","type":"update","data":[{"symbol":"BTC/USD","bids":[{"price":62796.2,"qty":0.00000000},{"price":62705.0,"qty":0.06960000}],"asks":[],"checksum":23065628,"timestamp":"2026-08-16T23:37:12.805182Z"}]}}
{"rx_ns": 42898189270400, "frame": {"channel":"book","type":"update","data":[{"symbol":"BTC/USD","bids":[{"price":62782.0,"qty":0.00518958}],"asks":[],"checksum":23065628,"timestamp":"2026-08-16T23:37:12.805192Z"}]}}
{"rx_ns": 42898192214000, "frame": {"channel":"book","type":"update","data":[{"symbol":"BTC/USD","bids":[{"price":62794.4,"qty":0.00000000},{"price":62703.8,"qty":0.05517271}],"asks":[],"checksum":2546430391,"timestamp":"2026-08-16T23:37:12.805732Z"}]}}
{"rx_ns": 42898192255000, "frame": {"channel":"book","type":"update","data":[{"symbol":"BTC/USD","bids":[{"price":62712.6,"qty":0.00000000},{"price":62703.0,"qty":0.01531807}],"asks":[],"checksum":2546430391,"timestamp":"2026-08-16T23:37:12.805895Z"}]}}
{"rx_ns": 42898192267400, "frame": {"channel":"book","type":"update","data":[{"symbol":"BTC/USD","bids":[{"price":62760.8,"qty":0.00000000},{"price":62699.8,"qty":0.00136206}],"asks":[],"checksum":2546430391,"timestamp":"2026-08-16T23:37:12.806519Z"}]}}
{"rx_ns": 42898192280300, "frame": {"channel":"book","type":"update","data":[{"symbol":"BTC/USD","bids":[{"price":62758.5,"qty":0.00000000},{"price":62699.7,"qty":5.58216167}],"asks":[],"checksum":2546430391,"timestamp":"2026-08-16T23:37:12.806796Z"}]}}
{"rx_ns": 42898192291200, "frame": {"channel":"book","type":"update","data":[{"symbol":"BTC/USD","bids":[],"asks":[{"price":62840.7,"qty":0.00000000},{"price":62881.0,"qty":0.00829460},{"price":62834.3,"qty":0.00198855}],"checksum":2546430391,"timestamp":"2026-08-16T23:37:12.807468Z"}]}}
{"rx_ns": 42898192303600, "frame": {"channel":"book","type":"update","data":[{"symbol":"BTC/USD","bids":[{"price":62774.1,"qty":0.00000000},{"price":62698.3,"qty":0.04150088},{"price":62763.7,"qty":0.10294167}],"asks":[],"checksum":2546430391,"timestamp":"2026-08-16T23:37:12.807708Z"}]}}
{"rx_ns": 42898197869500, "frame": {"channel":"book","type":"update","data":[{"symbol":"BTC/USD","bids":[{"price":62779.4,"qty":0.79643879}],"asks":[],"checksum":2546430391,"timestamp":"2026-08-16T23:37:12.812487Z"}]}}
{"rx_ns": 42898197912800, "frame": {"channel":"book","type":"update","data":[{"symbol":"BTC/USD","bids":[{"price":62770.1,"qty":0.00000000},{"price":62699.7,"qty":5.58216167}],"asks":[],"checksum":2546430391,"timestamp":"2026-08-16T23:37:12.812543Z"}]}}
{"rx_ns": 42898197923400, "frame": {"channel":"book","type":"update","data":[{"symbol":"BTC/USD","bids":[{"price":62781.9,"qty":0.00000000},{"price":62698.3,"qty":0.04150088},{"price":62779.7,"qty":0.07963050}],"asks":[],"checksum":2546430391,"timestamp":"2026-08-16T23:37:12.814155Z"}]}}
{"rx_ns": 42898197934700, "frame": {"channel":"book","type":"update","data":[{"symbol":"BTC/USD","bids":[{"price":62785.0,"qty":0.00000000},{"price":62696.2,"qty":0.07974964}],"asks":[],"checksum":2546430391,"timestamp":"2026-08-16T23:37:12.816406Z"}]}}
{"rx_ns": 42898197941800, "frame": {"channel":"book","type":"update","data":[{"symbol":"BTC/USD","bids":[{"price":62768.5,"qty":0.76302000}],"asks":[],"checksum":2546430391,"timestamp":"2026-08-16T23:37:12.816771Z"}]}}
{"rx_ns": 42898197948200, "frame": {"channel":"book","type":"update","data":[{"symbol":"BTC/USD","bids":[{"price":62781.3,"qty":0.00000000},{"price":62696.2,"qty":0.07974964},{"price":62778.6,"qty":0.03185313}],"asks":[],"checksum":2546430391,"timestamp":"2026-08-16T23:37:12.817441Z"}]}}
{"rx_ns": 42898197955700, "frame": {"channel":"book","type":"update","data":[{"symbol":"BTC/USD","bids":[],"asks":[{"price":62830.4,"qty":0.00000000},{"price":62881.0,"qty":0.00829460},{"price":62829.3,"qty":0.28000000}],"checksum":2546430391,"timestamp":"2026-08-16T23:37:12.817758Z"}]}}
{"rx_ns": 42898199440200, "frame": {"channel":"book","type":"update","data":[{"symbol":"BTC/USD","bids":[{"price":62779.7,"qty":0.00000000},{"price":62696.2,"qty":0.07974964},{"price":62778.0,"qty":0.08800859}],"asks":[],"checksum":2546430391,"timestamp":"2026-08-16T23:37:12.821082Z"}]}}
{"rx_ns": 42898199468800, "frame": {"channel":"book","type":"update","data":[{"symbol":"BTC/USD","bids":[{"price":62698.7,"qty":0.06960000}],"asks":[],"checksum":2546430391,"timestamp":"2026-08-16T23:37:12.824810Z"}]}}
{"rx_ns": 42898204491300, "frame": {"channel":"book","type":"update","data":[{"symbol":"BTC/USD","bids":[{"price":62707.2,"qty":0.00000000},{"price":62696.2,"qty":0.07974964}],"asks":[],"checksum":2546430391,"timestamp":"2026-08-16T23:37:12.825273Z"}]}}
{"rx_ns": 42898204549400, "frame": {"channel":"book","type":"update","data":[{"symbol":"BTC/USD","bids":[{"price":62779.4,"qty":0.00000000},{"price":62692.1,"qty":0.00119632}],"asks":[],"checksum":2546430391,"timestamp":"2026-08-16T23:37:12.826660Z"}]}}
{"rx_ns": 42898205816500, "frame": {"channel":"book","type":"update","data":[{"symbol":"BTC/USD","bids":[{"price":62760.0,"qty":0.00050000}],"asks":[],"checksum":2546430391,"timestamp":"2026-08-16T23:37:12.830892Z"}]}}
{"rx_ns": 42898211354800, "frame": {"channel":"book","type":"update","data":[{"symbol":"BTC/USD","bids":[{"price":62765.3,"qty":0.00000000},{"price":62692.1,"qty":0.00119632}],"asks":[],"checksum":2546430391,"timestamp":"2026-08-16T23:37:12.834075Z"}]}}
{"rx_ns": 42898212872000, "frame": {"channel":"book","type":"update","data":[{"symbol":"BTC/USD","bids":[{"price":62778.2,"qty":0.00000000},{"price":62691.1,"qty":0.00159500}],"asks":[],"checksum":2546430391,"timestamp":"2026-08-16T23:37:12.834906Z"}]}}
{"rx_ns": 42898212925300, "frame": {"channel":"book","type":"update","data":[{"symbol":"BTC/USD","bids":[],"asks":[{"price":62835.0,"qty":0.00000000},{"price":62881.0,"qty":0.00829460}],"checksum":2546430391,"timestamp":"2026-08-16T23:37:12.836642Z"}]}}
{"rx_ns": 42898212939800, "frame": {"channel":"book","type":"update","data":[{"symbol":"BTC/USD","bids":[{"price":62771.8,"qty":0.00080000}],"asks":[],"checksum":2546430391,"timestamp":"2026-08-16T23:37:12.836981Z"}]}}
{"rx_ns": 42898212950800, "frame": {"channel":"book","type":"update","data":[{"symbol":"BTC/USD","bids":[],"asks":[{"price":62822.2,"qty":0.00080000}],"checksum":2546430391,"timestamp":"2026-08-16T23:37:12.837112Z"}]}}
{"rx_ns": 42898214157100, "frame": {"channel":"book","type":"update","data":[{"symbol":"BTC/USD","bids":[{"price":62737.1,"qty":0.05587296}],"asks":[],"checksum":2546430391,"timestamp":"2026-08-16T23:37:12.839797Z"}]}}
{"rx_ns": 42898220996000, "frame": {"channel":"book","type":"update","data":[{"symbol":"BTC/USD","bids":[{"price":62792.1,"qty":0.00000000},{"price":62692.1,"qty":0.00119632}],"asks":[],"checksum":1553735971,"timestamp":"2026-08-16T23:37:12.843222Z"}]}}
{"rx_ns": 42898221060500, "frame": {"channel":"book","type":"update","data":[{"symbol":"BTC/USD","bids":[{"price":62775.8,"qty":0.00318594}],"asks":[],"checksum":1553735971,"timestamp":"2026-08-16T23:37:12.843234Z"}]}}
{"rx_ns": 42898221092200, "frame": {"channel":"book","type":"update","data":[{"symbol":"BTC/USD","bids":[{"price":62737.1,"qty":0.00000000},{"price":62692.1,"qty":0.00119632}],"asks":[],"checksum":1553735971,"timestamp":"2026-08-16T23:37:12.845669Z"}]}}
{"rx_ns": 42898231379300, "frame": {"channel":"book","type":"update","data":[{"symbol":"BTC/USD","bids":[{"price":62782.0,"qty":0.00000000},{"price":62691.1,"qty":0.00159500}],"asks":[],"checksum":1553735971,"timestamp":"2026-08-16T23:37:12.854835Z"}]}}
{"rx_ns": 42898234406700, "frame": {"channel":"book","type":"update","data":[{"symbol":"BTC/USD","bids":[{"price":62699.9,"qty":1.50000000}],"asks":[],"checksum":1553735971,"timestamp":"2026-08-16T23:37:12.860047Z"}]}}
{"rx_ns": 42898250911600, "frame": {"channel":"book","type":"update","data":[{"symbol":"BTC/USD","bids":[{"price":62781.0,"qty":0.79641831}],"asks":[],"checksum":1553735971,"timestamp":"2026-08-16T23:37:12.874029Z"}]}}
{"rx_ns": 42898250987000, "frame": {"channel":"book","type":"update","data":[{"symbol":"BTC/USD","bids":[{"price":62781.0,"qty":0.00000000},{"price":62692.1,"qty":0.00119632}],"asks":[],"checksum":1553735971,"timestamp":"2026-08-16T23:37:12.874675Z"}]}}
{"rx_ns": 42898253180800, "frame": {"channel":"book","type":"update","data":[{"symbol":"BTC/USD","bids":[],"asks":[{"price":62810.8,"qty":0.00000000},{"price":62881.0,"qty":0.00829460}],"checksum":1553735971,"timestamp":"2026-08-16T23:37:12.879049Z"}]}}
{"rx_ns": 42898253237700, "frame": {"channel":"book","type":"update","data":[{"symbol":"BTC/USD","bids":[],"asks":[{"price":62813.8,"qty":0.19620257},{"price":62807.0,"qty":1.59575715}],"checksum":2819771186,"timestamp":"2026-08-16T23:37:12.879101Z"}]}}
{"rx_ns": 42898256948600, "frame": {"channel":"book","type":"update","data":[{"symbol":"BTC/USD","bids":[],"asks":[{"price":62807.0,"qty":0.00000000},{"price":62881.0,"qty":0.00829460},{"price":62813.8,"qty":1.79195972}],"checksum":1553735971,"timestamp":"2026-08-16T23:37:12.885342Z"}]}}
{"rx_ns": 42898266486400, "frame": {"channel":"book","type":"update","data":[{"symbol":"BTC/USD","bids":[],"asks":[{"price":62850.8,"qty":0.00000000},{"price":62881.2,"qty":0.16061732}],"checksum":1553735971,"timestamp":"2026-08-16T23:37:12.892870Z"}]}}
{"rx_ns": 42898283385700, "frame": {"channel":"book","type":"update","data":[{"symbol":"BTC/USD","bids":[],"asks":[{"price":62813.8,"qty":1.59575715},{"price":62807.9,"qty":0.19620257}],"checksum":1553735971,"timestamp":"2026-08-16T23:37:12.910495Z"}]}}
{"rx_ns": 42898294459500, "frame": {"channel":"book","type":"update","data":[{"symbol":"BTC/USD","bids":[{"price":62792.9,"qty":0.00318620}],"asks":[],"checksum":1476275024,"timestamp":"2026-08-16T23:37:12.916965Z"}]}}
{"rx_ns": 42898301166400, "frame": {"channel":"book","type":"update","data":[{"symbol":"BTC/USD","bids":[],"asks":[{"price":62869.0,"qty":0.00000000},{"price":62881.2,"qty":0.16061732}],"checksum":1476275024,"timestamp":"2026-08-16T23:37:12.920678Z"}]}}
{"rx_ns": 42898301227900, "frame": {"channel":"book","type":"update","data":[{"symbol":"BTC/USD","bids":[{"price":62749.1,"qty":0.06960000}],"asks":[],"checksum":1476275024,"timestamp":"2026-08-16T23:37:12.921094Z"}]}}
{"rx_ns": 42898301240200, "frame": {"channel":"book","type":"update","data":[{"symbol":"BTC/USD","bids":[{"price":62768.7,"qty":0.00000000},{"price":62691.1,"qty":0.00159500}],"asks":[],"checksum":1476275024,"timestamp":"2026-08-16T23:37:12.921377Z"}]}}
{"rx_ns": 42898305536200, "frame": {"channel":"book","type":"update","data":[{"symbol":"BTC/USD","bids":[],"asks":[{"price":62813.8,"qty":0.00000000},{"price":62883.3,"qty":0.02184000},{"price":62807.0,"qty":1.59575715}],"checksum":2742042945,"timestamp":"2026-08-16T23:37:12.926022Z"}]}}
{"rx_ns": 42898305594800, "frame": {"channel":"book","type":"update","data":[{"symbol":"BTC/USD","bids":[{"price":62763.7,"qty":0.00000000},{"price":62691.0,"qty":5.58293320},{"price":62760.4,"qty":0.10294709}],"asks":[],"checksum":2742042945,"timestamp":"2026-08-16T23:37:12.926119Z"}]}}
{"rx_ns": 42898313787000, "frame": {"channel":"book","type":"update","data":[{"symbol":"BTC/USD","bids":[],"asks":[{"price":62829.3,"qty":0.00000000},{"price":62883.3,"qty":0.02184000},{"price":62829.0,"qty":0.28000000}],"checksum":2742042945,"timestamp":"2026-08-16T23:37:12.930731Z"}]}}
{"rx_ns": 42898313846200, "frame": {"channel":"book","type":"update","data":[{"symbol":"BTC/USD","bids":[{"price":62760.4,"qty":0.00000000},{"price":62691.0,"qty":5.58293320},{"price":62766.1,"qty":0.10293774}],"asks":[],"checksum":2742042945,"timestamp":"2026-08-16T23:37:12.934038Z"}]}}
{"rx_ns": 42898313859500, "frame": {"channel":"book","type":"update","data":[{"symbol":"BTC/USD","bids":[{"price":62785.6,"qty":0.00000000},{"price":62691.0,"qty":5.58293320}],"asks":[],"checksum":2742042945,"timestamp":"2026-08-16T23:37:12.935297Z"}]}}
{"rx_ns": 42898315953000, "frame": {"channel":"book","type":"update","data":[{"symbol":"BTC/USD","bids":[{"price":62790.6,"qty":0.00000000},{"price":62690.0,"qty":0.00319030}],"asks":[],"checksum":3235540812,"timestamp":"2026-08-16T23:37:12.940256Z"}]}}
{"rx_ns": 42898315993500, "frame": {"channel":"book","type":"update","data":[{"symbol":"BTC/USD","bids":[{"price":62774.2,"qty":0.02867420}],"asks":[],"checksum":3235540812,"timestamp":"2026-08-16T23:37:12.940480Z"}]}}
{"rx_ns": 42898322126500, "frame": {"channel":"book","type":"update","data":[{"symbol":"BTC/USD","bids":[{"price":62786.4,"qty":0.05598472}],"asks":[],"checksum":3235540812,"timestamp":"2026-08-16T23:37:12.942249Z"}]}}
{"rx_ns": 42898324031900, "frame": {"channel":"book","type":"update","data":[{"symbol":"BTC/USD","bids":[{"price":62778.6,"qty":0.00000000},{"price":62691.0,"qty":5.58293320}],"asks":[],"checksum":3235540812,"timestamp":"2026-08-16T23:37:12.947892Z"}]}}
{"rx_ns": 42898328327700, "frame": {"channel":"book","type":"update","data":[{"symbol":"BTC/USD","bids":[],"asks":[{"price":62829.0,"qty":0.00000000},{"price":62883.3,"qty":0.02184000},{"price":62828.5,"qty":0.28000000}],"checksum":3235540812,"timestamp":"2026-08-16T23:37:12.951185Z"}]}}
{"rx_ns": 42898328383700, "frame": {"channel":"book","type":"update","data":[{"symbol":"BTC/USD","bids":[{"price":62778.0,"qty":0.00837574},{"price":62776.5,"qty":0.03185420}],"asks":[],"checksum":3235540812,"timestamp":"2026-08-16T23:37:12.951215Z"}]}}
{"rx_ns": 42898335532900, "frame": {"channel":"book","type":"update","data":[{"symbol":"BTC/USD","bids":[{"price":62780.1,"qty":0.00000000},{"price":62691.0,"qty":5.58293320}],"asks":[],"checksum":3235540812,"timestamp":"2026-08-16T23:37:12.953611Z"}]}}
{"rx_ns": 42898335618800, "frame": {"channel":"book","type":"update","data":[{"symbol":"BTC/USD","bids":[{"price":62773.8,"qty":0.00000000},{"price":62690.0,"qty":0.00319030}],"asks":[],"checksum":3235540812,"timestamp":"2026-08-16T23:37:12.953694Z"}]}}
{"rx_ns": 42898335635400, "frame": {"channel":"book","type":"update","data":[{"symbol":"BTC/USD","bids":[{"price":62775.9,"qty":0.07963552}],"asks":[],"checksum":3235540812,"timestamp":"2026-08-16T23:37:12.954832Z"}]}}
{"rx_ns": 42898338719400, "frame": {"channel":"book","type":"update","data":[{"symbol":"BTC/USD","bids":[{"price":62798.4,"qty":0.00000000},{"price":62690.0,"qty":0.00319030}],"asks":[],"checksum":3404109272,"timestamp":"2026-08-16T23:37:12.957714Z"}]}}
{"rx_ns": 42898338776400, "frame": {"channel":"book","type":"update","data":[{"symbol":"BTC/USD","bids":[{"price":62731.6,"qty":0.00000000},{"price":62688.0,"qty":0.00015952},{"price":62727.2,"qty":0.70609000}],"asks":[],"checksum":3404109272,"timestamp":"2026-08-16T23:37:12.957899Z"}]}}
{"rx_ns": 42898338794300, "frame": {"channel":"book","type":"update","data":[{"symbol":"BTC/USD","bids":[{"price":62728.5,"qty":0.00011160},{"price":62724.1,"qty":0.35581000}],"asks":[],"checksum":3404109272,"timestamp":"2026-08-16T23:37:12.958311Z"}]}}
{"rx_ns": 42898338805300, "frame": {"channel":"book","type":"update","data":[{"symbol":"BTC/USD","bids":[{"price":62797.0,"qty":0.02150659}],"asks":[],"checksum":4025759346,"timestamp":"2026-08-16T23:37:12.959954Z"}]}}
{"rx_ns": 42898338816400, "frame": {"channel":"book","type":"update","data":[{"symbol":"BTC/USD","bids":[{"price":62782.4,"qty":0.00000000},{"price":62690.0,"qty":0.00319030}],"asks":[],"checksum":4025759346,"timestamp":"2026-08-16T23:37:12.959970Z"}]}}
{"rx_ns": 42898338824100, "frame": {"channel":"book","type":"update","data":[{"symbol":"BTC/USD","bids":[],"asks":[{"price":62810.4,"qty":0.13109402}],"checksum":4025759346,"timestamp":"2026-08-16T23:37:12.961023Z"}]}}
{"rx_ns": 42898338850900, "frame": {"channel":"book","type":"update","data":[{"symbol":"BTC/USD","bids":[{"price":62765.0,"qty":0.00000000},{"price":62688.0,"qty":0.00015952},{"price":62752.3,"qty":0.03187134}],"asks":[],"checksum":4025759346,"timestamp":"2026-08-16T23:37:12.963683Z"}]}}
{"rx_ns": 42898344778500, "frame": {"channel":"book","type":"update","data":[{"symbol":"BTC/USD","bids":[{"price":62777.4,"qty":0.00000000},{"price":62688.0,"qty":0.00015952},{"price":62771.4,"qty":0.00039827}],"asks":[],"checksum":4025759346,"timestamp":"2026-08-16T23:37:12.965620Z"}]}}
{"rx_ns": 42898344841900, "frame": {"channel":"book","type":"update","data":[{"symbol":"BTC/USD","bids":[{"price":62727.2,"qty":0.00000000},{"price":62688.0,"qty":0.00015952},{"price":62725.3,"qty":0.70609000}],"asks":[],"checksum":4025759346,"timestamp":"2026-08-16T23:37:12.966079Z"}]}}
{"rx_ns": 42898344866500, "frame": {"channel":"book","type":"update","data":[{"symbol":"BTC/USD","bids":[{"price":62724.1,"qty":0.00000000},{"price":62688.0,"qty":0.00015952},{"price":62722.2,"qty":0.35581000}],"asks":[],"checksum":4025759346,"timestamp":"2026-08-16T23:37:12.966168Z"}]}}
{"rx_ns": 42898344881200, "frame": {"channel":"book","type":"update","data":[{"symbol":"BTC/USD","bids":[],"asks":[{"price":62815.7,"qty":0.10331161}],"checksum":4025759346,"timestamp":"2026-08-16T23:37:12.966531Z"}]}}
{"rx_ns": 42898344891800, "frame": {"channel":"book","type":"update","data":[{"symbol":"BTC/USD","bids":[{"price":62766.1,"qty":0.00000000},{"price":62688.0,"qty":0.00015952},{"price":62760.9,"qty":0.10294627}],"asks":[],"checksum":4025759346,"timestamp":"2026-08-16T23:37:12.968024Z"}]}}
{"rx_ns": 42898352084200, "frame": {"channel":"book","type":"update","data":[{"symbol":"BTC/USD","bids":[{"price":62760.9,"qty":0.00000000},{"price":62688.0,"qty":0.00015952},{"price":62766.1,"qty":0.10293774}],"asks":[],"checksum":4025759346,"timestamp":"2026-08-16T23:37:12.973435Z"}]}}
{"rx_ns": 42898352134900, "frame": {"channel":"book","type":"update","data":[{"symbol":"BTC/USD","bids":[],"asks":[{"price":62825.7,"qty":0.23769319}],"checksum":4025759346,"timestamp":"2026-08-16T23:37:12.973450Z"}]}}
{"rx_ns": 42898352147400, "frame": {"channel":"book","type":"update","data":[{"symbol":"BTC/USD","bids":[{"price":62764.5,"qty":0.03430911}],"asks":[],"checksum":4025759346,"timestamp":"2026-08-16T23:37:12.975069Z"}]}}
{"rx_ns": 42898353352700, "frame": {"channel":"book","type":"update","data":[{"symbol":"BTC/USD","bids":[{"price":62727.3,"qty":0.00000000},{"price":62690.0,"qty":0.00319030},{"price":62720.2,"qty":0.00711998}],"asks":[],"checksum":4025759346,"timestamp":"2026-08-16T23:37:12.977751Z"}]}}
{"rx_ns": 42898355615200, "frame": {"channel":"book","type":"update","data":[{"symbol":"BTC/USD","bids":[],"asks":[{"price":62828.5,"qty":0.00000000},{"price":62879.7,"qty":0.00200000},{"price":62828.1,"qty":0.28000000}],"checksum":4025759346,"timestamp":"2026-08-16T23:37:12.980365Z"}]}}
{"rx_ns": 42898355676600, "frame": {"channel":"book","type":"update","data":[{"symbol":"BTC/USD","bids":[{"price":62779.5,"qty":1.00391099}],"asks":[],"checksum":4025759346,"timestamp":"2026-08-16T23:37:12.982112Z"}]}}
{"rx_ns": 42898358970300, "frame": {"channel":"book","type":"update","data":[{"symbol":"BTC/USD","bids":[],"asks":[{"price":62803.9,"qty":0.57289635}],"checksum":2791712775,"timestamp":"2026-08-16T23:37:12.982804Z"}]}}
{"rx_ns": 42898361698400, "frame": {"channel":"book","type":"update","data":[{"symbol":"BTC/USD","bids":[],"asks":[{"price":62805.5,"qty":0.00000000},{"price":62879.7,"qty":0.00200000},{"price":62806.9,"qty":0.18489680}],"checksum":1905968279,"timestamp":"2026-08-16T23:37:12.985101Z"}]}}
{"rx_ns": 42898364085500, "frame": {"channel":"book","type":"update","data":[{"symbol":"BTC/USD","bids":[],"asks":[{"price":62866.5,"qty":0.00005100},{"price":62859.4,"qty":0.01167440}],"checksum":1905968279,"timestamp":"2026-08-16T23:37:12.990621Z"}]}}
{"rx_ns": 42898373119800, "frame": {"channel":"book","type":"update","data":[{"symbol":"BTC/USD","bids":[{"price":62733.8,"qty":0.05462847}],"asks":[],"checksum":1905968279,"timestamp":"2026-08-16T23:37:12.999030Z"}]}}
{"rx_ns": 42898376430400, "frame": {"channel":"book","type":"update","data":[{"symbol":"BTC/USD","bids":[{"price":62797.0,"qty":0.00012700}],"asks":[],"checksum":2903422294,"timestamp":"2026-08-16T23:37:13.001862Z"}]}}
{"rx_ns": 42898376490700, "frame": {"channel":"book","type":"update","data":[{"symbol":"BTC/USD","bids":[{"price":62775.9,"qty":0.00000000},{"price":62691.0,"qty":5.58293320}],"asks":[],"checksum":2903422294,"timestamp":"2026-08-16T23:37:13.002959Z"}]}}
{"rx_ns": 42898376505400, "frame": {"channel":"book","type":"update","data":[{"symbol":"BTC/USD","bids":[{"price":62796.0,"qty":0.02137959}],"asks":[],"checksum":3183349564,"timestamp":"2026-08-16T23:37:13.003110Z"}]}}
{"rx_ns": 42898378626600, "frame": {"channel":"book","type":"update","data":[{"symbol":"BTC/USD","bids":[{"price":62776.5,"qty":0.00000000},{"price":62691.0,"qty":5.58293320}],"asks":[],"checksum":3183349564,"timestamp":"2026-08-16T23:37:13.006001Z"}]}}
{"rx_ns": 42898381558800, "frame": {"channel":"book","type":"update","data":[{"symbol":"BTC/USD","bids":[{"price":62779.5,"qty":0.84467700}],"asks":[],"checksum":3183349564,"timestamp":"2026-08-16T23:37:13.007531Z"}]}}
{"rx_ns": 42898384396200, "frame": {"channel":"book","type":"update","data":[{"symbol":"BTC/USD","bids":[{"price":62802.5,"qty":0.00049808}],"asks":[],"checksum":1327756067,"timestamp":"2026-08-16T23:37:13.011009Z"}]}}
{"rx_ns": 42898387164100, "frame": {"channel":"book","type":"update","data":[{"symbol":"BTC/USD","bids":[],"asks":[{"price":62807.0,"qty":0.00000000},{"price":62879.7,"qty":0.00200000}],"checksum":4286353542,"timestamp":"2026-08-16T23:37:13.013789Z"}]}}
{"rx_ns": 42898387207500, "frame": {"channel":"book","type":"update","data":[{"symbol":"BTC/USD","bids":[{"price":62766.1,"qty":0.00000000},{"price":62690.0,"qty":0.00319030}],"asks":[],"checksum":4286353542,"timestamp":"2026-08-16T23:37:13.013895Z"}]}}
{"rx_ns": 42898391040500, "frame": {"channel":"book","type":"update","data":[{"symbol":"BTC/USD","bids":[],"asks":[{"price":62879.4,"qty":0.06960000}],"checksum":4286353542,"timestamp":"2026-08-16T23:37:13.016542Z"}]}}
{"rx_ns": 42898394965200, "frame": {"channel":"book","type":"update","data":[{"symbol":"BTC/USD","bids":[{"price":62802.5,"qty":0.00010000},{"price":62802.5,"qty":0.00000000},{"price":62688.0,"qty":0.00015952}],"asks":[{"price":62800.7,"qty":0.07084096}],"checksum":403221632,"timestamp":"2026-08-16T23:37:13.016972Z"}]}}
{"rx_ns": 42898395022300, "frame": {"channel":"book","type":"update","data":[{"symbol":"BTC/USD","bids":[{"price":62780.3,"qty":0.15947283}],"asks":[],"checksum":403221632,"timestamp":"2026-08-16T23:37:13.017168Z"}]}}
{"rx_ns": 42898395035700, "frame": {"channel":"book","type":"update","data":[{"symbol":"BTC/USD","bids":[{"price":62785.0,"qty":0.79636797}],"asks":[],"checksum":403221632,"timestamp":"2026-08-16T23:37:13.017223Z"}]}}
{"rx_ns": 42898395044900, "frame": {"channel":"book","type":"update","data":[{"symbol":"BTC/USD","bids":[],"asks":[{"price":62800.7,"qty":0.18084096}],"checksum":3091587529,"timestamp":"2026-08-16T23:37:13.018112Z"}]}}
{"rx_ns": 42898395054600, "frame": {"channel":"book","type":"update","data":[{"symbol":"BTC/USD","bids":[{"price":62800.6,"qty":0.00000000},{"price":62688.0,"qty":0.00015952}],"asks":[],"checksum":2907335323,"timestamp":"2026-08-16T23:37:13.018420Z"}]}}
{"rx_ns": 42898395067100, "frame": {"channel":"book","type":"update","data":[{"symbol":"BTC/USD","bids":[],"asks":[{"price":62802.6,"qty":5.76525020},{"price":62800.7,"qty":0.23682568}],"checksum":2873051894,"timestamp":"2026-08-16T23:37:13.018702Z"}]}}
{"rx_ns": 42898395079900, "frame": {"channel":"book","type":"update","data":[{"symbol":"BTC/USD","bids":[],"asks":[{"price":62802.6,"qty":5.74557538}],"checksum":3003994414,"timestamp":"2026-08-16T23:37:13.018736Z"}]}}
{"rx_ns": 42898395090400, "frame": {"channel":"book","type":"update","data":[{"symbol":"BTC/USD","bids":[],"asks":[{"price":62802.6,"qty":5.58634139}],"checksum":2382578928,"timestamp":"2026-08-16T23:37:13.018826Z"}]}}
{"rx_ns": 42898395099300, "frame": {"channel":"book","type":"update","data":[{"symbol":"BTC/USD","bids":[],"asks":[{"price":62800.7,"qty":0.31642568}],"checksum":180174683,"timestamp":"2026-08-16T23:37:13.018853Z"}]}}
{"rx_ns": 42898395108000, "frame": {"channel":"book","type":"update","data":[{"symbol":"BTC/USD","bids":[],"asks":[{"price":62800.7,"qty":0.38602568}],"checksum":2050336391,"timestamp":"2026-08-16T23:37:13.018873Z"}]}}
{"rx_ns": 42898395117400, "frame": {"channel":"book","type":"update","data":[{"symbol":"BTC/USD","bids":[],"asks":[{"price":62806.9,"qty":0.00000000},{"price":62879.4,"qty":0.06960000},{"price":62802.5,"qty":0.18489680}],"checksum":2142917193,"timestamp":"2026-08-16T23:37:13.019048Z"}]}}
{"rx_ns": 42898395128500, "frame": {"channel":"book","type":"update","data":[{"symbol":"BTC/USD","bids":[{"price":62777.2,"qty":0.65540712}],"asks":[],"checksum":2142917193,"timestamp":"2026-08-16T23:37:13.019161Z"}]}}
{"rx_ns": 42898395137100, "frame": {"channel":"book","type":"update","data":[{"symbol":"BTC/USD","bids":[],"asks":[{"price":62808.0,"qty":0.00857369}],"checksum":2142917193,"timestamp":"2026-08-16T23:37:13.019259Z"}]}}
{"rx_ns": 42898395145900, "frame": {"channel":"book","type":"update","data":[{"symbol":"BTC/USD","bids":[],"asks":[{"price":62802.6,"qty":5.51674139}],"checksum":2400985091,"timestamp":"2026-08-16T23:37:13.019602Z"}]}}
{"rx_ns": 42898403185400, "frame": {"channel":"book","type":"update","data":[{"symbol":"BTC/USD","bids":[{"price":62764.7,"qty":0.00000000},{"price":62688.0,"qty":0.00015952},{"price":62760.7,"qty":0.00318620}],"asks":[],"checksum":2400985091,"timestamp":"2026-08-16T23:37:13.019620Z"}]}}
{"rx_ns": 42898403238500, "frame": {"channel":"book","type":"update","data":[{"symbol":"BTC/USD","bids":[],"asks":[{"price":62840.5,"qty":0.00000000},{"price":62879.4,"qty":0.06960000},{"price":62836.7,"qty":0.00318620}],"checksum":2400985091,"timestamp":"2026-08-16T23:37:13.019949Z"}]}}
{"rx_ns": 42898403252800, "frame": {"channel":"book","type":"update","data":[{"symbol":"BTC/USD","bids":[{"price":62797.5,"qty":0.00000000},{"price":62688.0,"qty":0.00015952}],"asks":[],"checksum":2913601983,"timestamp":"2026-08-16T23:37:13.020845Z"}]}}
{"rx_ns": 42898403264300, "frame": {"channel":"book","type":"update","data":[{"symbol":"BTC/USD","bids":[],"asks":[{"price":62802.6,"qty":4.86133427}],"checksum":944096166,"timestamp":"2026-08-16T23:37:13.020917Z"}]}}
{"rx_ns": 42898403274600, "frame": {"channel":"book","type":"update","data":[{"symbol":"BTC/USD","bids":[],"asks":[{"price":62800.7,"qty":0.83629385}],"checksum":212590745,"timestamp":"2026-08-16T23:37:13.020976Z"}]}}
{"rx_ns": 42898403284100, "frame": {"channel":"book","type":"update","data":[{"symbol":"BTC/USD","bids":[],"asks":[{"price":62800.7,"qty":1.63246331}],"checksum":3135709292,"timestamp":"2026-08-16T23:37:13.021167Z"}]}}
{"rx_ns": 42898403292900, "frame": {"channel":"book","type":"update","data":[{"symbol":"BTC/USD","bids":[],"asks":[{"price":62802.6,"qty":4.06518889}],"checksum":3002962644,"timestamp":"2026-08-16T23:37:13.021327Z"}]}}
{"rx_ns": 42898403302300, "frame": {"channel":"book","type":"update","data":[{"symbol":"BTC/USD","bids":[],"asks":[{"price":62803.8,"qty":0.00000000},{"price":62879.4,"qty":0.06960000}],"checksum":2734298107,"timestamp":"2026-08-16T23:37:13.021351Z"}]}}
{"rx_ns": 42898403312900, "frame": {"channel":"book","type":"update","data":[{"symbol":"BTC/USD","bids":[],"asks":[{"price":62797.6,"qty":0.06960000}],"checksum":3405185678,"timestamp":"2026-08-16T23:37:13.021394Z"}]}}
{"rx_ns": 42898403322600, "frame": {"channel":"book","type":"update","data":[{"symbol":"BTC/USD","bids":[],"asks":[{"price":62800.7,"qty":1.56286331}],"checksum":2866389728,"timestamp":"2026-08-16T23:37:13.022022Z"}]}}
{"rx_ns": 42898403332400, "frame": {"channel":"book","type":"update","data":[{"symbol":"BTC/USD","bids":[],"asks":[{"price":62800.7,"qty":1.11259514}],"checksum":881858089,"timestamp":"2026-08-16T23:37:13.022090Z"}]}}
{"rx_ns": 42898403342900, "frame": {"channel":"book","type":"update","data":[{"symbol":"BTC/USD","bids":[],"asks":[{"price":62800.7,"qty":1.19059514}],"checksum":2532219740,"timestamp":"2026-08-16T23:37:13.023106Z"}]}}
{"rx_ns": 42898403351900, "frame": {"channel":"book","type":"update","data":[{"symbol":"BTC/USD","bids":[],"asks":[{"price":62800.7,"qty":0.39442568}],"checksum":3381156956,"timestamp":"2026-08-16T23:37:13.023127Z"}]}}
{"rx_ns": 42898403361200, "frame": {"channel":"book","type":"update","data":[{"symbol":"BTC/USD","bids":[{"price":62762.5,"qty":0.00000000},{"price":62686.1,"qty":0.00031904}],"asks":[],"checksum":3381156956,"timestamp":"2026-08-16T23:37:13.023520Z"}]}}
{"rx_ns": 42898403371500, "frame": {"channel":"book","type":"update","data":[{"symbol":"BTC/USD","bids":[],"asks":[{"price":62802.6,"qty":3.98558889}],"checksum":666767927,"timestamp":"2026-08-16T23:37:13.023552Z"}]}}
{"rx_ns": 42898403381100, "frame": {"channel":"book","type":"update","data":[{"symbol":"BTC/USD","bids":[],"asks":[{"price":62800.7,"qty":0.31482568}],"checksum":1885372546,"timestamp":"2026-08-16T23:37:13.023719Z"}]}}
{"rx_ns": 42898403390800, "frame": {"channel":"book","type":"update","data":[{"symbol":"BTC/USD","bids":[],"asks":[{"price":62797.6,"qty":0.14920000}],"checksum":3396078074,"timestamp":"2026-08-16T23:37:13.024133Z"}]}}
{"rx_ns": 42898403401900, "frame": {"channel":"book","type":"update","data":[{"symbol":"BTC/USD","bids":[{"price":62686.1,"qty":0.06991904}],"asks":[],"checksum":3396078074,"timestamp":"2026-08-16T23:37:13.025393Z"}]}}
{"rx_ns": 42898403411100, "frame": {"channel":"book","type":"update","data":[{"symbol":"BTC/USD","bids":[{"price":62791.4,"qty":0.00000000},{"price":62684.9,"qty":0.02491872}],"asks":[],"checksum":3873733962,"timestamp":"2026-08-16T23:37:13.025420Z"}]}}
{"rx_ns": 42898403501100, "frame": {"channel":"book","type":"update","data":[{"symbol":"BTC/USD","bids":[],"asks":[{"price":62802.5,"qty":0.19566797}],"checksum":110438741,"timestamp":"2026-08-16T23:37:13.025555Z"}]}}
{"rx_ns": 42898403518000, "frame": {"channel":"book","type":"update","data":[{"symbol":"BTC/USD","bids":[],"asks":[{"price":62812.0,"qty":0.00000000},{"price":62879.7,"qty":0.00200000}],"checksum":110438741,"timestamp":"2026-08-16T23:37:13.025673Z"}]}}
{"rx_ns": 42898403531300, "frame": {"channel":"book","type":"update","data":[{"symbol":"BTC/USD","bids":[],"asks":[{"price":62814.0,"qty":0.00000000},{"price":62881.0,"qty":0.00829460}],"checksum":110438741,"timestamp":"2026-08-16T23:37:13.025778Z"}]}}
{"rx_ns": 42898403544500, "frame": {"channel":"book","type":"update","data":[{"symbol":"BTC/USD","bids":[],"asks":[{"price":62797.6,"qty":0.07960000}],"checksum":2607988117,"timestamp":"2026-08-16T23:37:13.026041Z"}]}}
{"rx_ns": 42898408331100, "frame": {"channel":"book","type":"update","data":[{"symbol":"BTC/USD","bids":[],"asks":[{"price":62797.1,"qty":0.06960000}],"checksum":3298962471,"timestamp":"2026-08-16T23:37:13.026178Z"}]}}
{"rx_ns": 42898408355700, "frame": {"channel":"book","type":"update","data":[{"symbol":"BTC/USD","bids":[{"price":62792.9,"qty":0.00000000},{"price":62684.3,"qty":5.59894519},{"price":62787.4,"qty":0.00318620}],"asks":[],"checksum":2182572719,"timestamp":"2026-08-16T23:37:13.026947Z"}]}}
{"rx_ns": 42898408366300, "frame": {"channel":"book","type":"update","data":[{"symbol":"BTC/USD","bids":[],"asks":[{"price":62809.5,"qty":0.00000000},{"price":62881.0,"qty":0.00829460}],"checksum":2182572719,"timestamp":"2026-08-16T23:37:13.027169Z"}]}}
{"rx_ns": 42898408374400, "frame": {"channel":"book","type":"update","data":[{"symbol":"BTC/USD","bids":[],"asks":[{"price":62812.4,"qty":0.00000000},{"price":62881.2,"qty":0.16061732},{"price":62806.8,"qty":0.00323720}],"checksum":2498127341,"timestamp":"2026-08-16T23:37:13.027202Z"}]}}
{"rx_ns": 42898408382200, "frame": {"channel":"book","type":"update","data":[{"symbol":"BTC/USD","bids":[],"asks":[{"price":62797.6,"qty":0.15760000}],"checksum":3089088190,"timestamp":"2026-08-16T23:37:13.027734Z"}]}}
{"rx_ns": 42898408388600, "frame": {"channel":"book","type":"update","data":[{"symbol":"BTC/USD","bids":[],"asks":[{"price":62800.7,"qty":0.23682568}],"checksum":870085212,"timestamp":"2026-08-16T23:37:13.027841Z"}]}}
{"rx_ns": 42898408394800, "frame": {"channel":"book","type":"update","data":[{"symbol":"BTC/USD","bids":[],"asks":[{"price":62797.6,"qty":0.07800000}],"checksum":3521396130,"timestamp":"2026-08-16T23:37:13.027854Z"}]}}
{"rx_ns": 42898408400700, "frame": {"channel":"book","type":"update","data":[{"symbol":"BTC/USD","bids":[],"asks":[{"price":62797.1,"qty":0.14920000}],"checksum":2992318915,"timestamp":"2026-08-16T23:37:13.027952Z"}]}}
{"rx_ns": 42898408407800, "frame": {"channel":"book","type":"update","data":[{"symbol":"BTC/USD","bids":[],"asks":[{"price":62802.6,"qty":3.90758889}],"checksum":3493395947,"timestamp":"2026-08-16T23:37:13.028083Z"}]}}
{"rx_ns": 42898408413600, "frame": {"channel":"book","type":"update","data":[{"symbol":"BTC/USD","bids":[],"asks":[{"price":62797.6,"qty":0.00000000},{"price":62883.3,"qty":0.02184000}],"checksum":3067110439,"timestamp":"2026-08-16T23:37:13.028718Z"}]}}
{"rx_ns": 42898408420100, "frame": {"channel":"book","type":"update","data":[{"symbol":"BTC/USD","bids":[],"asks":[{"price":62797.1,"qty":0.19750000}],"checksum":2525488707,"timestamp":"2026-08-16T23:37:13.028793Z"}]}}
{"rx_ns": 42898408426000, "frame": {"channel":"book","type":"update","data":[{"symbol":"BTC/USD","bids":[],"asks":[{"price":62798.7,"qty":0.79619496}],"checksum":870418109,"timestamp":"2026-08-16T23:37:13.028824Z"}]}}
{"rx_ns": 42898408432300, "frame": {"channel":"book","type":"update","data":[{"symbol":"BTC/USD","bids":[],"asks":[{"price":62797.6,"qty":0.07084444}],"checksum":3370121935,"timestamp":"2026-08-16T23:37:13.030510Z"}]}}
{"rx_ns": 42898408438600, "frame": {"channel":"book","type":"update","data":[{"symbol":"BTC/USD","bids":[],"asks":[{"price":62797.1,"qty":0.26834500}],"checksum":3431873363,"timestamp":"2026-08-16T23:37:13.030552Z"}]}}
{"rx_ns": 42898408444600, "frame": {"channel":"book","type":"update","data":[{"symbol":"BTC/USD","bids":[],"asks":[{"price":62810.0,"qty":0.00000000},{"price":62881.2,"qty":0.16061732}],"checksum":3431873363,"timestamp":"2026-08-16T23:37:13.030593Z"}]}}
{"rx_ns": 42898408451500, "frame": {"channel":"book","type":"update","data":[{"symbol":"BTC/USD","bids":[],"asks":[{"price":62808.0,"qty":0.00318431}],"checksum":3431873363,"timestamp":"2026-08-16T23:37:13.030618Z"}]}}
{"rx_ns": 42898408457400, "frame": {"channel":"book","type":"update","data":[{"symbol":"BTC/USD","bids":[],"asks":[{"price":62879.4,"qty":0.06960000}],"checksum":3431873363,"timestamp":"2026-08-16T23:37:13.030724Z"}]}}
{"rx_ns": 42898408463400, "frame": {"channel":"book","type":"update","data":[{"symbol":"BTC/USD","bids":[],"asks":[{"price":62803.4,"qty":0.06960000}],"checksum":2503302653,"timestamp":"2026-08-16T23:37:13.030906Z"}]}}
{"rx_ns": 42898419312800, "frame": {"channel":"book","type":"update","data":[{"symbol":"BTC/USD","bids":[],"asks":[{"price":62797.1,"qty":0.42757899}],"checksum":1654766325,"timestamp":"2026-08-16T23:37:13.046260Z"}]}}
{"rx_ns": 42898425083200, "frame": {"channel":"book","type":"update","data":[{"symbol":"BTC/USD","bids":[{"price":62780.3,"qty":0.00023884}],"asks":[],"checksum":1654766325,"timestamp":"2026-08-16T23:37:13.047156Z"}]}}
{"rx_ns": 42898425135300, "frame": {"channel":"book","type":"update","data":[{"symbol":"BTC/USD","bids":[],"asks":[{"price":62802.5,"qty":0.01077117},{"price":62813.2,"qty":0.18489680}],"checksum":2381632431,"timestamp":"2026-08-16T23:37:13.047373Z"}]}}
{"rx_ns": 42898425151900, "frame": {"channel":"book","type":"update","data":[{"symbol":"BTC/USD","bids":[],"asks":[{"price":62812.7,"qty":0.00000000},{"price":62879.7,"qty":0.00200000},{"price":62803.3,"qty":0.01100000}],"checksum":4090389357,"timestamp":"2026-08-16T23:37:13.047579Z"}]}}
{"rx_ns": 42898425167200, "frame": {"channel":"book","type":"update","data":[{"symbol":"BTC/USD","bids":[{"price":62776.8,"qty":0.10331161}],"asks":[],"checksum":4090389357,"timestamp":"2026-08-16T23:37:13.047937Z"}]}}
{"rx_ns": 42898427082500, "frame": {"channel":"book","type":"update","data":[{"symbol":"BTC/USD","bids":[{"price":62699.8,"qty":0.02274165}],"asks":[],"checksum":4090389357,"timestamp":"2026-08-16T23:37:13.050868Z"}]}}
{"rx_ns": 42898427112900, "frame": {"channel":"book","type":"update","data":[{"symbol":"BTC/USD","bids":[],"asks":[{"price":62797.1,"qty":0.76953847}],"checksum":840042318,"timestamp":"2026-08-16T23:37:13.050885Z"}]}}
{"rx_ns": 42898427155100, "frame": {"channel":"book","type":"update","data":[{"symbol":"BTC/USD","bids":[{"price":62796.0,"qty":0.00000000},{"price":62684.9,"qty":0.02491872}],"asks":[],"checksum":3655306591,"timestamp":"2026-08-16T23:37:13.051716Z"}]}}
{"rx_ns": 42898427170100, "frame": {"channel":"book","type":"update","data":[{"symbol":"BTC/USD","bids":[],"asks":[{"price":62797.1,"qty":1.42494559}],"checksum":723689792,"timestamp":"2026-08-16T23:37:13.052821Z"}]}}
{"rx_ns": 42898427179800, "frame": {"channel":"book","type":"update","data":[{"symbol":"BTC/USD","bids":[{"price":62782.2,"qty":0.15923399}],"asks":[],"checksum":1373789466,"timestamp":"2026-08-16T23:37:13.052885Z"}]}}
{"rx_ns": 42898430768000, "frame": {"channel":"book","type":"update","data":[{"symbol":"BTC/USD","bids":[{"price":62777.8,"qty":0.11000000}],"asks":[],"checksum":1373789466,"timestamp":"2026-08-16T23:37:13.053809Z"}]}}
{"rx_ns": 42898430804800, "frame": {"channel":"book","type":"update","data":[{"symbol":"BTC/USD","bids":[{"price":62771.5,"qty":0.13109402}],"asks":[],"checksum":1373789466,"timestamp":"2026-08-16T23:37:13.054010Z"}]}}
{"rx_ns": 42898430817400, "frame": {"channel":"book","type":"update","data":[{"symbol":"BTC/USD","bids":[{"price":62760.7,"qty":0.00000000},{"price":62688.0,"qty":0.00015952},{"price":62756.0,"qty":0.00318620}],"asks":[],"checksum":1373789466,"timestamp":"2026-08-16T23:37:13.054976Z"}]}}
{"rx_ns": 42898430895300, "frame": {"channel":"book","type":"update","data":[{"symbol":"BTC/USD","bids":[],"asks":[{"price":62836.7,"qty":0.00000000},{"price":62879.7,"qty":0.00200000},{"price":62831.9,"qty":0.00318620}],"checksum":1373789466,"timestamp":"2026-08-16T23:37:13.055200Z"}]}}
{"rx_ns": 42898430907900, "frame": {"channel":"book","type":"update","data":[{"symbol":"BTC/USD","bids":[{"price":62737.4,"qty":0.00000000},{"price":62688.0,"qty":0.00015952}],"asks":[],"checksum":1373789466,"timestamp":"2026-08-16T23:37:13.055797Z"}]}}
{"rx_ns": 42898436393700, "frame": {"channel":"book","type":"update","data":[{"symbol":"BTC/USD","bids":[{"price":62796.9,"qty":0.02137959}],"asks":[],"checksum":3685579384,"timestamp":"2026-08-16T23:37:13.057297Z"}]}}
{"rx_ns": 42898436449200, "frame": {"channel":"book","type":"update","data":[{"symbol":"BTC/USD","bids":[],"asks":[{"price":62802.5,"qty":0.00000000},{"price":62879.7,"qty":0.00200000}],"checksum":2338405213,"timestamp":"2026-08-16T23:37:13.058201Z"}]}}
{"rx_ns": 42898436466200, "frame": {"channel":"book","type":"update","data":[{"symbol":"BTC/USD","bids":[{"price":62785.0,"qty":0.00000000},{"price":62688.0,"qty":0.00015952}],"asks":[],"checksum":1847904079,"timestamp":"2026-08-16T23:37:13.058212Z"}]}}
{"rx_ns": 42898436474500, "frame": {"channel":"book","type":"update","data":[{"symbol":"BTC/USD","bids":[{"price":62777.2,"qty":0.00000000},{"price":62686.1,"qty":0.00031904}],"asks":[],"checksum":1847904079,"timestamp":"2026-08-16T23:37:13.058289Z"}]}}
{"rx_ns": 42898436481900, "frame": {"channel":"book","type":"update","data":[{"symbol":"BTC/USD","bids":[],"asks":[{"price":62800.7,"qty":0.24275148}],"checksum":2704872004,"timestamp":"2026-08-16T23:37:13.059838Z"}]}}
{"rx_ns": 42898437834700, "frame": {"channel":"book","type":"update","data":[{"symbol":"BTC/USD","bids":[],"asks":[{"price":62802.6,"qty":3.90166323}],"checksum":2650887292,"timestamp":"2026-08-16T23:37:13.060091Z"}]}}
{"rx_ns": 42898437854600, "frame": {"channel":"book","type":"update","data":[{"symbol":"BTC/USD","bids":[{"price":62724.1,"qty":15.00000000}],"asks":[],"checksum":2650887292,"timestamp":"2026-08-16T23:37:13.060454Z"}]}}
{"rx_ns": 42898437865300, "frame": {"channel":"book","type":"update","data":[{"symbol":"BTC/USD","bids":[{"price":62742.5,"qty":0.03182142}],"asks":[],"checksum":2650887292,"timestamp":"2026-08-16T23:37:13.060517Z"}]}}
{"rx_ns": 42898437874000, "frame": {"channel":"book","type":"update","data":[{"symbol":"BTC/USD","bids":[],"asks":[{"price":62851.4,"qty":0.03136929}],"checksum":2650887292,"timestamp":"2026-08-16T23:37:13.061354Z"}]}}
{"rx_ns": 42898437883700, "frame": {"channel":"book","type":"update","data":[{"symbol":"BTC/USD","bids":[],"asks":[{"price":62831.9,"qty":0.00000000},{"price":62879.7,"qty":0.00200000},{"price":62835.3,"qty":0.07278620}],"checksum":2650887292,"timestamp":"2026-08-16T23:37:13.061554Z"}]}}
{"rx_ns": 42898437894400, "frame": {"channel":"book","type":"update","data":[{"symbol":"BTC/USD","bids":[],"asks":[{"price":62817.1,"qty":0.00000000},{"price":62881.0,"qty":0.00829460}],"checksum":2650887292,"timestamp":"2026-08-16T23:37:13.061948Z"}]}}
{"rx_ns": 42898437903800, "frame": {"channel":"book","type":"update","data":[{"symbol":"BTC/USD","bids":[{"price":62756.0,"qty":0.00000000},{"price":62688.0,"qty":0.00015952},{"price":62759.3,"qty":0.00318620}],"asks":[],"checksum":2650887292,"timestamp":"2026-08-16T23:37:13.062054Z"}]}}
{"rx_ns": 42898437913900, "frame": {"channel":"book","type":"update","data":[{"symbol":"BTC/USD","bids":[{"price":62782.2,"qty":0.00000000},{"price":62688.0,"qty":0.00015952}],"asks":[],"checksum":1925078646,"timestamp":"2026-08-16T23:37:13.062743Z"}]}}
{"rx_ns": 42898441590000, "frame": {"channel":"book","type":"update","data":[{"symbol":"BTC/USD","bids":[],"asks":[{"price":62797.6,"qty":0.07677047}],"checksum":4156579959,"timestamp":"2026-08-16T23:37:13.064062Z"}]}}
{"rx_ns": 42898441609600, "frame": {"channel":"book","type":"update","data":[{"symbol":"BTC/USD","bids":[],"asks":[{"price":62800.7,"qty":0.23682568}],"checksum":1350627905,"timestamp":"2026-08-16T23:37:13.064370Z"}]}}
{"rx_ns": 42898441619400, "frame": {"channel":"book","type":"update","data":[{"symbol":"BTC/USD","bids":[],"asks":[{"price":62822.3,"qty":0.00000000},{"price":62881.2,"qty":0.16061732}],"checksum":1350627905,"timestamp":"2026-08-16T23:37:13.067215Z"}]}}
{"rx_ns": 42898444044700, "frame": {"channel":"book","type":"update","data":[{"symbol":"BTC/USD","bids":[],"asks":[{"price":62813.2,"qty":0.00000000},{"price":62883.3,"qty":0.02184000},{"price":62807.0,"qty":0.18489680}],"checksum":1350627905,"timestamp":"2026-08-16T23:37:13.068816Z"}]}}
{"rx_ns": 42898445137800, "frame": {"channel":"book","type":"update","data":[{"symbol":"BTC/USD","bids":[],"asks":[{"price":62797.1,"qty":1.43087166}],"checksum":3986990149,"timestamp":"2026-08-16T23:37:13.071265Z"}]}}
{"rx_ns": 42898445159400, "frame": {"channel":"book","type":"update","data":[{"symbol":"BTC/USD","bids":[],"asks":[{"price":62797.6,"qty":0.07084444}],"checksum":1759156804,"timestamp":"2026-08-16T23:37:13.071305Z"}]}}
{"rx_ns": 42898451253600, "frame": {"channel":"book","type":"update","data":[{"symbol":"BTC/USD","bids":[],"asks":[{"price":62833.1,"qty":0.00000000},{"price":62883.3,"qty":0.02184000}],"checksum":1759156804,"timestamp":"2026-08-16T23:37:13.077113Z"}]}}
{"rx_ns": 42898456543100, "frame": {"channel":"book","type":"update","data":[{"symbol":"BTC/USD","bids":[{"price":62783.9,"qty":0.15923399}],"asks":[],"checksum":2464825369,"timestamp":"2026-08-16T23:37:13.084050Z"}]}}
{"rx_ns": 42898460005900, "frame": {"channel":"book","type":"update","data":[{"symbol":"BTC/USD","bids":[],"asks":[{"price":62802.6,"qty":3.90126515},{"price":62800.7,"qty":0.23722376}],"checksum":2396577722,"timestamp":"2026-08-16T23:37:13.088127Z"}]}}
{"rx_ns": 42898470728400, "frame": {"channel":"book","type":"update","data":[{"symbol":"BTC/USD","bids":[{"price":62765.1,"qty":0.00303485}],"asks":[],"checksum":2396577722,"timestamp":"2026-08-16T23:37:13.098052Z"}]}}
{"rx_ns": 42898475211500, "frame": {"channel":"book","type":"update","data":[{"symbol":"BTC/USD","bids":[],"asks":[{"price":62873.9,"qty":0.00000000},{"price":62883.7,"qty":1.31257213},{"price":62860.9,"qty":0.00198855}],"checksum":2396577722,"timestamp":"2026-08-16T23:37:13.102717Z"}]}}
{"rx_ns": 42898477899600, "frame": {"channel":"book","type":"update","data":[{"symbol":"BTC/USD","bids":[{"price":62758.8,"qty":0.00000000},{"price":62690.0,"qty":0.00319030},{"price":62752.0,"qty":0.00162380}],"asks":[],"checksum":2396577722,"timestamp":"2026-08-16T23:37:13.103896Z"}]}}
{"rx_ns": 42898477981700, "frame": {"channel":"book","type":"update","data":[{"symbol":"BTC/USD","bids":[],"asks":[{"price":62834.3,"qty":0.00000000},{"price":62883.7,"qty":1.31257213},{"price":62827.5,"qty":0.00198855}],"checksum":2396577722,"timestamp":"2026-08-16T23:37:13.104029Z"}]}}
{"rx_ns": 42898477996000, "frame": {"channel":"book","type":"update","data":[{"symbol":"BTC/USD","bids":[{"price":62786.4,"qty":0.00000000},{"price":62690.0,"qty":0.00319030},{"price":62791.3,"qty":0.05598472}],"asks":[],"checksum":1269445095,"timestamp":"2026-08-16T23:37:13.104176Z"}]}}
{"rx_ns": 42898484158500, "frame": {"channel":"book","type":"update","data":[{"symbol":"BTC/USD","bids":[{"price":62797.0,"qty":0.00000000},{"price":62690.0,"qty":0.00319030}],"asks":[{"price":62797.0,"qty":0.00007300}],"checksum":2115243580,"timestamp":"2026-08-16T23:37:13.106889Z"}]}}
{"rx_ns": 42898484216000, "frame": {"channel":"book","type":"update","data":[{"symbol":"BTC/USD","bids":[],"asks":[{"price":62797.0,"qty":0.01172515}],"checksum":2465731891,"timestamp":"2026-08-16T23:37:13.107492Z"}]}}
{"rx_ns": 42898484228100, "frame": {"channel":"book","type":"update","data":[{"symbol":"BTC/USD","bids":[],"asks":[{"price":62797.1,"qty":1.42494559}],"checksum":6578741,"timestamp":"2026-08-16T23:37:13.107630Z"}]}}
{"rx_ns": 42898484337200, "frame": {"channel":"book","type":"update","data":[{"symbol":"BTC/USD","bids":[],"asks":[{"price":62797.0,"qty":0.08132515}],"checksum":1338619859,"timestamp":"2026-08-16T23:37:13.108117Z"}]}}
{"rx_ns": 42898484358300, "frame": {"channel":"book","type":"update","data":[{"symbol":"BTC/USD","bids":[],"asks":[{"price":62797.1,"qty":1.35534559}],"checksum":2050678557,"timestamp":"2026-08-16T23:37:13.108151Z"}]}}
{"rx_ns": 42898484367900, "frame": {"channel":"book","type":"update","data":[{"symbol":"BTC/USD","bids":[{"price":62780.7,"qty":0.65540712}],"asks":[],"checksum":2050678557,"timestamp":"2026-08-16T23:37:13.109969Z"}]}}
{"rx_ns": 42898484376200, "frame": {"channel":"book","type":"update","data":[{"symbol":"BTC/USD","bids":[],"asks":[{"price":62797.1,"qty":1.19611160}],"checksum":1192618340,"timestamp":"2026-08-16T23:37:13.110007Z"}]}}
{"rx_ns": 42898484384700, "frame": {"channel":"book","type":"update","data":[{"symbol":"BTC/USD","bids":[{"price":62772.7,"qty":0.00796524}],"asks":[],"checksum":1192618340,"timestamp":"2026-08-16T23:37:13.110040Z"}]}}
{"rx_ns": 42898484392500, "frame": {"channel":"book","type":"update","data":[{"symbol":"BTC/USD","bids":[],"asks":[{"price":62797.0,"qty":0.15932515}],"checksum":2238747027,"timestamp":"2026-08-16T23:37:13.110069Z"}]}}
{"rx_ns": 42898484400400, "frame": {"channel":"book","type":"update","data":[{"symbol":"BTC/USD","bids":[],"asks":[{"price":62797.1,"qty":1.14781160}],"checksum":3548517327,"timestamp":"2026-08-16T23:37:13.110097Z"}]}}
{"rx_ns": 42898486582700, "frame": {"channel":"book","type":"update","data":[{"symbol":"BTC/USD","bids":[],"asks":[{"price":62797.1,"qty":1.06821160}],"checksum":3644668436,"timestamp":"2026-08-16T23:37:13.110233Z"}]}}
{"rx_ns": 42898486625400, "frame": {"channel":"book","type":"update","data":[{"symbol":"BTC/USD","bids":[],"asks":[{"price":62797.0,"qty":0.23892515}],"checksum":4174566184,"timestamp":"2026-08-16T23:37:13.110241Z"}]}}
{"rx_ns": 42898494056500, "frame": {"channel":"book","type":"update","data":[{"symbol":"BTC/USD","bids":[],"asks":[{"price":62797.0,"qty":0.30933848}],"checksum":3662060326,"timestamp":"2026-08-16T23:37:13.116174Z"}]}}
{"rx_ns": 42898494101900, "frame": {"channel":"book","type":"update","data":[{"symbol":"BTC/USD","bids":[{"price":62766.1,"qty":0.10293774}],"asks":[],"checksum":3662060326,"timestamp":"2026-08-16T23:37:13.116912Z"}]}}
{"rx_ns": 42898494111800, "frame": {"channel":"book","type":"update","data":[{"symbol":"BTC/USD","bids":[],"asks":[{"price":62807.9,"qty":1.79195972}],"checksum":3662060326,"timestamp":"2026-08-16T23:37:13.117028Z"}]}}
{"rx_ns": 42898494120700, "frame": {"channel":"book","type":"update","data":[{"symbol":"BTC/USD","bids":[],"asks":[{"price":62802.6,"qty":0.11100000}],"checksum":3946368491,"timestamp":"2026-08-16T23:37:13.118066Z"}]}}
{"rx_ns": 42898495346300, "frame": {"channel":"book","type":"update","data":[{"symbol":"BTC/USD","bids":[],"asks":[{"price":62807.0,"qty":0.00000000},{"price":62883.3,"qty":0.02184000},{"price":62810.1,"qty":0.18489680}],"checksum":3946368491,"timestamp":"2026-08-16T23:37:13.119791Z"}]}}
{"rx_ns": 42898495369900, "frame": {"channel":"book","type":"update","data":[{"symbol":"BTC/USD","bids":[],"asks":[{"price":62802.6,"qty":0.00100000}],"checksum":2071172721,"timestamp":"2026-08-16T23:37:13.119912Z"}]}}
{"rx_ns": 42898495380100, "frame": {"channel":"book","type":"update","data":[{"symbol":"BTC/USD","bids":[{"price":62699.8,"qty":0.02137959},{"price":62700.0,"qty":0.00136290}],"asks":[],"checksum":2071172721,"timestamp":"2026-08-16T23:37:13.121358Z"}]}}
{"rx_ns": 42898498675100, "frame": {"channel":"book","type":"update","data":[{"symbol":"BTC/USD","bids":[],"asks":[{"price":62802.6,"qty":3.79160819}],"checksum":504708799,"timestamp":"2026-08-16T23:37:13.122343Z"}]}}
{"rx_ns": 42898518361600, "frame": {"channel":"book","type":"update","data":[{"symbol":"BTC/USD","bids":[],"asks":[{"price":62797.0,"qty":0.46857247}],"checksum":3515650208,"timestamp":"2026-08-16T23:37:13.146148Z"}]}}
{"rx_ns": 42898521014400, "frame": {"channel":"book","type":"update","data":[{"symbol":"BTC/USD","bids":[],"asks":[{"price":62810.1,"qty":0.00000000},{"price":62883.3,"qty":0.02184000},{"price":62807.0,"qty":0.18489680}],"checksum":3515650208,"timestamp":"2026-08-16T23:37:13.147272Z"}]}}
{"rx_ns": 42898527213100, "frame": {"channel":"book","type":"update","data":[{"symbol":"BTC/USD","bids":[],"asks":[{"price":62797.0,"qty":0.57857247}],"checksum":1294644508,"timestamp":"2026-08-16T23:37:13.148288Z"}]}}
{"rx_ns": 42898527313100, "frame": {"channel":"book","type":"update","data":[{"symbol":"BTC/USD","bids":[{"price":62760.4,"qty":0.79668071}],"asks":[],"checksum":1294644508,"timestamp":"2026-08-16T23:37:13.149983Z"}]}}
{"rx_ns": 42898527646700, "frame": {"channel":"book","type":"update","data":[{"symbol":"BTC/USD","bids":[],"asks":[{"price":62802.6,"qty":3.79060819}],"checksum":2791466827,"timestamp":"2026-08-16T23:37:13.154832Z"}]}}
{"rx_ns": 42898547126400, "frame": {"channel":"book","type":"update","data":[{"symbol":"BTC/USD","bids":[],"asks":[{"price":62797.6,"qty":0.86705321}],"checksum":3480597428,"timestamp":"2026-08-16T23:37:13.174371Z"}]}}
{"rx_ns": 42898551788800, "frame": {"channel":"book","type":"update","data":[{"symbol":"BTC/USD","bids":[],"asks":[{"price":62805.3,"qty":2.38833658}],"checksum":3480597428,"timestamp":"2026-08-16T23:37:13.174702Z"}]}}
{"rx_ns": 42898551837000, "frame": {"channel":"book","type":"update","data":[{"symbol":"BTC/USD","bids":[{"price":62786.0,"qty":0.79635491}],"asks":[],"checksum":100781553,"timestamp":"2026-08-16T23:37:13.174985Z"}]}}
{"rx_ns": 42898551850900, "frame": {"channel":"book","type":"update","data":[{"symbol":"BTC/USD","bids":[{"price":62783.8,"qty":0.79638273}],"asks":[],"checksum":658555657,"timestamp":"2026-08-16T23:37:13.175392Z"}]}}
{"rx_ns": 42898551862300, "frame": {"channel":"book","type":"update","data":[{"symbol":"BTC/USD","bids":[{"price":62778.0,"qty":0.80483233}],"asks":[],"checksum":658555657,"timestamp":"2026-08-16T23:37:13.175594Z"}]}}
{"rx_ns": 42898551873200, "frame": {"channel":"book","type":"update","data":[{"symbol":"BTC/USD","bids":[],"asks":[{"price":62807.0,"qty":0.00000000},{"price":62881.2,"qty":0.16061732},{"price":62805.5,"qty":0.18489680}],"checksum":658555657,"timestamp":"2026-08-16T23:37:13.175695Z"}]}}
{"rx_ns": 42898551887100, "frame": {"channel":"book","type":"update","data":[{"symbol":"BTC/USD","bids":[{"price":62771.3,"qty":2.38962605}],"asks":[],"checksum":658555657,"timestamp":"2026-08-16T23:37:13.175715Z"}]}}
{"rx_ns": 42898563870400, "frame": {"channel":"book","type":"update","data":[{"symbol":"BTC/USD","bids":[],"asks":[{"price":62807.9,"qty":0.19620257},{"price":62818.7,"qty":1.59798224}],"checksum":658555657,"timestamp":"2026-08-16T23:37:13.190083Z"}]}}
{"rx_ns": 42898565583700, "frame": {"channel":"book","type":"update","data":[{"symbol":"BTC/USD","bids":[],"asks":[{"price":62800.7,"qty":0.18123904},{"price":62797.0,"qty":0.63455719}],"checksum":1149516300,"timestamp":"2026-08-16T23:37:13.191332Z"}]}}
{"rx_ns": 42898569158500, "frame": {"channel":"book","type":"update","data":[{"symbol":"BTC/USD","bids":[],"asks":[{"price":62802.6,"qty":0.00000000},{"price":62881.2,"qty":0.16061732},{"price":62797.1,"qty":4.85884670}],"checksum":758797259,"timestamp":"2026-08-16T23:37:13.193019Z"}]}}
{"rx_ns": 42898569221100, "frame": {"channel":"book","type":"update","data":[{"symbol":"BTC/USD","bids":[{"price":62760.4,"qty":0.00000000},{"price":62699.8,"qty":0.02137959}],"asks":[],"checksum":758797259,"timestamp":"2026-08-16T23:37:13.194598Z"}]}}
{"rx_ns": 42898569236800, "frame": {"channel":"book","type":"update","data":[{"symbol":"BTC/USD","bids":[{"price":62778.0,"qty":0.83668569}],"asks":[],"checksum":758797259,"timestamp":"2026-08-16T23:37:13.195664Z"}]}}
{"rx_ns": 42898570429000, "frame": {"channel":"book","type":"update","data":[{"symbol":"BTC/USD","bids":[],"asks":[{"price":62805.5,"qty":0.00000000},{"price":62883.3,"qty":0.02184000},{"price":62805.2,"qty":0.18489680}],"checksum":2774269819,"timestamp":"2026-08-16T23:37:13.196822Z"}]}}
{"rx_ns": 42898587253800, "frame": {"channel":"book","type":"update","data":[{"symbol":"BTC/USD","bids":[{"price":62783.9,"qty":0.00000000},{"price":62699.7,"qty":5.58216167}],"asks":[],"checksum":2944484608,"timestamp":"2026-08-16T23:37:13.214943Z"}]}}
{"rx_ns": 42898589137800, "frame": {"channel":"book","type":"update","data":[{"symbol":"BTC/USD","bids":[],"asks":[{"price":62800.7,"qty":0.11039808}],"checksum":450625269,"timestamp":"2026-08-16T23:37:13.217429Z"}]}}
{"rx_ns": 42898606756100, "frame": {"channel":"book","type":"update","data":[{"symbol":"BTC/USD","bids":[],"asks":[{"price":62797.6,"qty":0.79620877}],"checksum":2106818657,"timestamp":"2026-08-16T23:37:13.232920Z"}]}}
{"rx_ns": 42898606807500, "frame": {"channel":"book","type":"update","data":[{"symbol":"BTC/USD","bids":[],"asks":[{"price":62797.1,"qty":4.78800170}],"checksum":1046123224,"timestamp":"2026-08-16T23:37:13.233010Z"}]}}
{"rx_ns": 42898618517300, "frame": {"channel":"book","type":"update","data":[{"symbol":"BTC/USD","bids":[{"price":62783.2,"qty":0.15923399}],"asks":[],"checksum":1046123224,"timestamp":"2026-08-16T23:37:13.246225Z"}]}}
{"rx_ns": 42898622142100, "frame": {"channel":"book","type":"update","data":[{"symbol":"BTC/USD","bids":[{"price":62766.0,"qty":0.65540712}],"asks":[],"checksum":1046123224,"timestamp":"2026-08-16T23:37:13.246736Z"}]}}
{"rx_ns": 42898622183700, "frame": {"channel":"book","type":"update","data":[{"symbol":"BTC/USD","bids":[],"asks":[{"price":62828.8,"qty":7.95818679}],"checksum":1046123224,"timestamp":"2026-08-16T23:37:13.246806Z"}]}}
{"rx_ns": 42898622195100, "frame": {"channel":"book","type":"update","data":[{"symbol":"BTC/USD","bids":[],"asks":[{"price":62816.2,"qty":0.00000000},{"price":62883.3,"qty":0.02184000}],"checksum":1046123224,"timestamp":"2026-08-16T23:37:13.247152Z"}]}}
{"rx_ns": 42898622205600, "frame": {"channel":"book","type":"update","data":[{"symbol":"BTC/USD","bids":[],"asks":[{"price":62813.1,"qty":0.00000000},{"price":62883.7,"qty":1.31257213}],"checksum":1046123224,"timestamp":"2026-08-16T23:37:13.247280Z"}]}}
{"rx_ns": 42898622215300, "frame": {"channel":"book","type":"update","data":[{"symbol":"BTC/USD","bids":[{"price":62788.0,"qty":0.00005100}],"asks":[],"checksum":143167616,"timestamp":"2026-08-16T23:37:13.247452Z"}]}}
{"rx_ns": 42898623895500, "frame": {"channel":"book","type":"update","data":[{"symbol":"BTC/USD","bids":[],"asks":[{"price":62800.7,"qty":0.00039808}],"checksum":1755017823,"timestamp":"2026-08-16T23:37:13.250355Z"}]}}
{"rx_ns": 42898631501200, "frame": {"channel":"book","type":"update","data":[{"symbol":"BTC/USD","bids":[],"asks":[{"price":62797.1,"qty":0.99736660},{"price":62797.0,"qty":4.42520746}],"checksum":1894782819,"timestamp":"2026-08-16T23:37:13.257115Z"}]}}
{"rx_ns": 42898631561400, "frame": {"channel":"book","type":"update","data":[{"symbol":"BTC/USD","bids":[],"asks":[{"price":62861.9,"qty":0.00000000},{"price":62884.4,"qty":0.47672669},{"price":62858.7,"qty":0.00385951}],"checksum":1894782819,"timestamp":"2026-08-16T23:37:13.258322Z"}]}}
{"rx_ns": 42898631575000, "frame": {"channel":"book","type":"update","data":[{"symbol":"BTC/USD","bids":[{"price":62706.6,"qty":0.00000000},{"price":62699.8,"qty":0.02137959},{"price":62703.1,"qty":0.00410313}],"asks":[],"checksum":1894782819,"timestamp":"2026-08-16T23:37:13.258392Z"}]}}
{"rx_ns": 42898643390200, "frame": {"channel":"book","type":"update","data":[{"symbol":"BTC/USD","bids":[{"price":62703.1,"qty":0.00000000},{"price":62699.8,"qty":0.02137959},{"price":62700.0,"qty":0.00546603}],"asks":[],"checksum":1894782819,"timestamp":"2026-08-16T23:37:13.263237Z"}]}}
{"rx_ns": 42898643468000, "frame": {"channel":"book","type":"update","data":[{"symbol":"BTC/USD","bids":[{"price":62786.0,"qty":0.00000000},{"price":62699.7,"qty":5.58216167}],"asks":[],"checksum":2973694444,"timestamp":"2026-08-16T23:37:13.266070Z"}]}}
{"rx_ns": 42898643490200, "frame": {"channel":"book","type":"update","data":[{"symbol":"BTC/USD","bids":[{"price":62699.8,"qty":0.00000000},{"price":62696.2,"qty":0.07974964}],"asks":[],"checksum":2973694444,"timestamp":"2026-08-16T23:37:13.267803Z"}]}}
{"rx_ns": 42898643501800, "frame": {"channel":"book","type":"update","data":[{"symbol":"BTC/USD","bids":[],"asks":[{"price":62803.9,"qty":0.63289635}],"checksum":2336368610,"timestamp":"2026-08-16T23:37:13.268214Z"}]}}
{"rx_ns": 42898643511400, "frame": {"channel":"book","type":"update","data":[{"symbol":"BTC/USD","bids":[],"asks":[{"price":62810.2,"qty":0.00000000},{"price":62884.4,"qty":0.47672669}],"checksum":2336368610,"timestamp":"2026-08-16T23:37:13.268359Z"}]}}
{"rx_ns": 42898643528800, "frame": {"channel":"book","type":"update","data":[{"symbol":"BTC/USD","bids":[{"price":62698.7,"qty":0.06960000}],"asks":[],"checksum":2336368610,"timestamp":"2026-08-16T23:37:13.271027Z"}]}}
{"rx_ns": 42898646169300, "frame": {"channel":"book","type":"update","data":[{"symbol":"BTC/USD","bids":[{"price":62775.0,"qty":0.23769319}],"asks":[],"checksum":2336368610,"timestamp":"2026-08-16T23:37:13.272859Z"}]}}
{"rx_ns": 42898647989500, "frame": {"channel":"book","type":"update","data":[{"symbol":"BTC/USD","bids":[{"price":62765.1,"qty":0.00000000},{"price":62698.7,"qty":0.06960000},{"price":62758.9,"qty":0.00303481}],"asks":[],"checksum":2336368610,"timestamp":"2026-08-16T23:37:13.275630Z"}]}}
{"rx_ns": 42898650481000, "frame": {"channel":"book","type":"update","data":[{"symbol":"BTC/USD","bids":[],"asks":[{"price":62834.5,"qty":0.00000000},{"price":62886.5,"qty":0.02137959},{"price":62829.7,"qty":0.00094656}],"checksum":2336368610,"timestamp":"2026-08-16T23:37:13.277925Z"}]}}
{"rx_ns": 42898650994100, "frame": {"channel":"book","type":"update","data":[{"symbol":"BTC/USD","bids":[{"price":62700.0,"qty":0.00410313}],"asks":[],"checksum":2336368610,"timestamp":"2026-08-16T23:37:13.278887Z"}]}}
{"rx_ns": 42898651027600, "frame": {"channel":"book","type":"update","data":[{"symbol":"BTC/USD","bids":[],"asks":[{"price":62856.9,"qty":0.00000000},{"price":62886.5,"qty":0.02137959},{"price":62853.7,"qty":0.00660000}],"checksum":2336368610,"timestamp":"2026-08-16T23:37:13.278909Z"}]}}
{"rx_ns": 42898652255500, "frame": {"channel":"book","type":"update","data":[{"symbol":"BTC/USD","bids":[{"price":62786.3,"qty":0.00000000},{"price":62696.3,"qty":0.00136326}],"asks":[],"checksum":2020945883,"timestamp":"2026-08-16T23:37:13.279379Z"}]}}
{"rx_ns": 42898656610400, "frame": {"channel":"book","type":"update","data":[{"symbol":"BTC/USD","bids":[{"price":62696.3,"qty":0.00000000},{"price":62696.2,"qty":0.07974964}],"asks":[],"checksum":2020945883,"timestamp":"2026-08-16T23:37:13.285056Z"}]}}
{"rx_ns": 42898658191200, "frame": {"channel":"book","type":"update","data":[{"symbol":"BTC/USD","bids":[{"price":62698.7,"qty":0.06960000}],"asks":[],"checksum":2020945883,"timestamp":"2026-08-16T23:37:13.285708Z"}]}}
{"rx_ns": 42898665659800, "frame": {"channel":"heartbeat"}}
{"rx_ns": 42898692141600, "frame": {"channel":"book","type":"update","data":[{"symbol":"BTC/USD","bids":[{"price":62796.9,"qty":0.02177770}],"asks":[],"checksum":892994901,"timestamp":"2026-08-16T23:37:13.310230Z"}]}}
{"rx_ns": 42898707529800, "frame": {"channel":"book","type":"update","data":[{"symbol":"BTC/USD","bids":[{"price":62783.2,"qty":0.00000000},{"price":62696.2,"qty":0.07974964}],"asks":[],"checksum":2410232346,"timestamp":"2026-08-16T23:37:13.334929Z"}]}}
{"rx_ns": 42898715418400, "frame": {"channel":"book","type":"update","data":[{"symbol":"BTC/USD","bids":[],"asks":[{"price":62821.3,"qty":0.00000000},{"price":62886.5,"qty":0.02137959}],"checksum":2410232346,"timestamp":"2026-08-16T23:37:13.343291Z"}]}}
{"rx_ns": 42898718449600, "frame": {"channel":"book","type":"update","data":[{"symbol":"BTC/USD","bids":[],"asks":[{"price":62885.7,"qty":0.06960000}],"checksum":2410232346,"timestamp":"2026-08-16T23:37:13.346298Z"}]}}
{"rx_ns": 42898721147000, "frame": {"channel":"book","type":"update","data":[{"symbol":"BTC/USD","bids":[{"price":62782.3,"qty":0.15923399}],"asks":[],"checksum":3447945768,"timestamp":"2026-08-16T23:37:13.346482Z"}]}}
{"rx_ns": 42898721203200, "frame": {"channel":"book","type":"update","data":[{"symbol":"BTC/USD","bids":[],"asks":[{"price":62807.9,"qty":0.00000000},{"price":62886.5,"qty":0.02137959}],"checksum":3447945768,"timestamp":"2026-08-16T23:37:13.346613Z"}]}}
{"rx_ns": 42898721240300, "frame": {"channel":"book","type":"update","data":[{"symbol":"BTC/USD","bids":[{"price":62766.1,"qty":0.00000000},{"price":62696.2,"qty":0.07974964}],"asks":[],"checksum":3447945768,"timestamp":"2026-08-16T23:37:13.347686Z"}]}}
{"rx_ns": 42898721255800, "frame": {"channel":"book","type":"update","data":[{"symbol":"BTC/USD","bids":[],"asks":[{"price":62818.7,"qty":0.00222509}],"checksum":3447945768,"timestamp":"2026-08-16T23:37:13.347776Z"}]}}
{"rx_ns": 42898731744900, "frame": {"channel":"book","type":"update","data":[{"symbol":"BTC/USD","bids":[],"asks":[{"price":62807.4,"qty":0.00000000},{"price":62889.0,"qty":0.04690699}],"checksum":3447945768,"timestamp":"2026-08-16T23:37:13.356843Z"}]}}
{"rx_ns": 42898731814900, "frame": {"channel":"book","type":"update","data":[{"symbol":"BTC/USD","bids":[],"asks":[{"price":62800.8,"qty":0.50922800}],"checksum":3890578034,"timestamp":"2026-08-16T23:37:13.357957Z"}]}}
{"rx_ns": 42898735891100, "frame": {"channel":"book","type":"update","data":[{"symbol":"BTC/USD","bids":[],"asks":[{"price":62851.3,"qty":0.00000000},{"price":62889.0,"qty":0.04690699}],"checksum":3890578034,"timestamp":"2026-08-16T23:37:13.364289Z"}]}}
{"rx_ns": 42898736593900, "frame": {"channel":"book","type":"update","data":[{"symbol":"BTC/USD","bids":[],"asks":[{"price":62838.0,"qty":0.00000000},{"price":62890.4,"qty":1.50000000}],"checksum":3890578034,"timestamp":"2026-08-16T23:37:13.364567Z"}]}}
{"rx_ns": 42898736652300, "frame": {"channel":"book","type":"update","data":[{"symbol":"BTC/USD","bids":[],"asks":[{"price":62814.6,"qty":0.01598519}],"checksum":3890578034,"timestamp":"2026-08-16T23:37:13.365520Z"}]}}
{"rx_ns": 42898739494100, "frame": {"channel":"book","type":"update","data":[{"symbol":"BTC/USD","bids":[],"asks":[{"price":62823.9,"qty":0.00319703}],"checksum":3890578034,"timestamp":"2026-08-16T23:37:13.365833Z"}]}}
{"rx_ns": 42898745505800, "frame": {"channel":"book","type":"update","data":[{"symbol":"BTC/USD","bids":[{"price":62765.9,"qty":0.19762201}],"asks":[],"checksum":3890578034,"timestamp":"2026-08-16T23:37:13.371259Z"}]}}
{"rx_ns": 42898747903400, "frame": {"channel":"book","type":"update","data":[{"symbol":"BTC/USD","bids":[],"asks":[{"price":62853.7,"qty":0.00000000},{"price":62889.0,"qty":0.04690699},{"price":62851.2,"qty":0.00660000}],"checksum":3890578034,"timestamp":"2026-08-16T23:37:13.374111Z"}]}}
{"rx_ns": 42898755426500, "frame": {"channel":"book","type":"update","data":[{"symbol":"BTC/USD","bids":[{"price":62783.8,"qty":0.00000000},{"price":62696.2,"qty":0.07974964}],"asks":[],"checksum":2647680867,"timestamp":"2026-08-16T23:37:13.379660Z"}]}}
{"rx_ns": 42898755485900, "frame": {"channel":"book","type":"update","data":[{"symbol":"BTC/USD","bids":[],"asks":[{"price":62800.6,"qty":0.79617073}],"checksum":2684872005,"timestamp":"2026-08-16T23:37:13.381024Z"}]}}
{"rx_ns": 42898755499400, "frame": {"channel":"book","type":"update","data":[{"symbol":"BTC/USD","bids":[{"price":62785.2,"qty":0.79636550}],"asks":[],"checksum":549165233,"timestamp":"2026-08-16T23:37:13.381265Z"}]}}
{"rx_ns": 42898758960200, "frame": {"channel":"book","type":"update","data":[{"symbol":"BTC/USD","bids":[],"asks":[{"price":62805.2,"qty":0.00000000},{"price":62886.5,"qty":0.02137959},{"price":62803.2,"qty":0.18489680}],"checksum":941186462,"timestamp":"2026-08-16T23:37:13.382255Z"}]}}
{"rx_ns": 42898763405900, "frame": {"channel":"book","type":"update","data":[{"symbol":"BTC/USD","bids":[{"price":62742.5,"qty":0.00000000},{"price":62696.2,"qty":0.07974964}],"asks":[],"checksum":941186462,"timestamp":"2026-08-16T23:37:13.390045Z"}]}}
{"rx_ns": 42898767603200, "frame": {"channel":"book","type":"update","data":[{"symbol":"BTC/USD","bids":[{"price":62796.9,"qty":0.00039811}],"asks":[],"checksum":2766704233,"timestamp":"2026-08-16T23:37:13.394510Z"}]}}
{"rx_ns": 42898768915100, "frame": {"channel":"book","type":"update","data":[{"symbol":"BTC/USD","bids":[{"price":62796.0,"qty":0.02137959}],"asks":[],"checksum":2736933280,"timestamp":"2026-08-16T23:37:13.395771Z"}]}}
{"rx_ns": 42898768978500, "frame": {"channel":"book","type":"update","data":[{"symbol":"BTC/USD","bids":[{"price":62775.0,"qty":0.00000000},{"price":62696.2,"qty":0.07974964}],"asks":[],"checksum":2736933280,"timestamp":"2026-08-16T23:37:13.396500Z"}]}}
{"rx_ns": 42898773024900, "frame": {"channel":"book","type":"update","data":[{"symbol":"BTC/USD","bids":[],"asks":[{"price":62797.0,"qty":4.44784873}],"checksum":57790229,"timestamp":"2026-08-16T23:37:13.397118Z"}]}}
{"rx_ns": 42898812789400, "frame": {"channel":"book","type":"update","data":[{"symbol":"BTC/USD","bids":[{"price":62789.9,"qty":0.00000000},{"price":62692.2,"qty":0.00136326},{"price":62733.9,"qty":0.01972397}],"asks":[],"checksum":3863301526,"timestamp":"2026-08-16T23:37:13.438431Z"}]}}
{"rx_ns": 42898823269000, "frame": {"channel":"book","type":"update","data":[{"symbol":"BTC/USD","bids":[{"price":62785.2,"qty":0.00000000},{"price":62692.2,"qty":0.00136326}],"asks":[],"checksum":1376481407,"timestamp":"2026-08-16T23:37:13.450539Z"}]}}
{"rx_ns": 42898826922600, "frame": {"channel":"book","type":"update","data":[{"symbol":"BTC/USD","bids":[{"price":62766.1,"qty":0.10293774}],"asks":[],"checksum":1376481407,"timestamp":"2026-08-16T23:37:13.451152Z"}]}}
{"rx_ns": 42898826955600, "frame": {"channel":"book","type":"update","data":[{"symbol":"BTC/USD","bids":[],"asks":[{"price":62818.7,"qty":1.59798224}],"checksum":1376481407,"timestamp":"2026-08-16T23:37:13.451642Z"}]}}
{"rx_ns": 42898826968000, "frame": {"channel":"book","type":"update","data":[{"symbol":"BTC/USD","bids":[{"price":62782.3,"qty":0.00000000},{"price":62692.2,"qty":0.00136326}],"asks":[],"checksum":431058180,"timestamp":"2026-08-16T23:37:13.451659Z"}]}}
{"rx_ns": 42898826979000, "frame": {"channel":"book","type":"update","data":[{"symbol":"BTC/USD","bids":[{"price":62780.7,"qty":0.00000000},{"price":62692.1,"qty":0.00119632}],"asks":[],"checksum":235013936,"timestamp":"2026-08-16T23:37:13.451834Z"}]}}
{"rx_ns": 42898830542800, "frame": {"channel":"book","type":"update","data":[{"symbol":"BTC/USD","bids":[{"price":62783.3,"qty":0.00000000},{"price":62691.1,"qty":0.00159500}],"asks":[],"checksum":1524074089,"timestamp":"2026-08-16T23:37:13.453382Z"}]}}
{"rx_ns": 42898830587200, "frame": {"channel":"book","type":"update","data":[{"symbol":"BTC/USD","bids":[],"asks":[{"price":62803.2,"qty":0.00000000},{"price":62886.5,"qty":0.02137959},{"price":62800.5,"qty":0.18489680}],"checksum":739533287,"timestamp":"2026-08-16T23:37:13.453655Z"}]}}
{"rx_ns": 42898836302000, "frame": {"channel":"book","type":"update","data":[{"symbol":"BTC/USD","bids":[],"asks":[{"price":62818.7,"qty":0.00222509},{"price":62807.3,"qty":1.59575715}],"checksum":739533287,"timestamp":"2026-08-16T23:37:13.457311Z"}]}}
{"rx_ns": 42898836350900, "frame": {"channel":"book","type":"update","data":[{"symbol":"BTC/USD","bids":[],"asks":[{"price":62805.1,"qty":0.19620257}],"checksum":739533287,"timestamp":"2026-08-16T23:37:13.457872Z"}]}}
{"rx_ns": 42898836361900, "frame": {"channel":"book","type":"update","data":[{"symbol":"BTC/USD","bids":[{"price":62796.9,"qty":0.00000000},{"price":62691.0,"qty":5.58293320}],"asks":[],"checksum":1042280290,"timestamp":"2026-08-16T23:37:13.458991Z"}]}}
{"rx_ns": 42898836372000, "frame": {"channel":"book","type":"update","data":[{"symbol":"BTC/USD","bids":[],"asks":[{"price":62796.9,"qty":0.11000000}],"checksum":684315505,"timestamp":"2026-08-16T23:37:13.459906Z"}]}}
{"rx_ns": 42898840160400, "frame": {"channel":"book","type":"update","data":[{"symbol":"BTC/USD","bids":[],"asks":[{"price":62796.1,"qty":0.06960000}],"checksum":2315581737,"timestamp":"2026-08-16T23:37:13.460980Z"}]}}
{"rx_ns": 42898840279900, "frame": {"channel":"book","type":"update","data":[{"symbol":"BTC/USD","bids":[],"asks":[{"price":62797.0,"qty":4.39186401},{"price":62796.9,"qty":0.16598472}],"checksum":1036017090,"timestamp":"2026-08-16T23:37:13.461395Z"}]}}
{"rx_ns": 42898840297800, "frame": {"channel":"book","type":"update","data":[{"symbol":"BTC/USD","bids":[],"asks":[{"price":62797.6,"qty":0.00000000},{"price":62883.3,"qty":0.02184000}],"checksum":1862507838,"timestamp":"2026-08-16T23:37:13.461460Z"}]}}
{"rx_ns": 42898840309600, "frame": {"channel":"book","type":"update","data":[{"symbol":"BTC/USD","bids":[],"asks":[{"price":62797.0,"qty":4.36922274}],"checksum":2302058582,"timestamp":"2026-08-16T23:37:13.461492Z"}]}}
{"rx_ns": 42898840318800, "frame": {"channel":"book","type":"update","data":[{"symbol":"BTC/USD","bids":[{"price":62776.8,"qty":0.75871873}],"asks":[],"checksum":2302058582,"timestamp":"2026-08-16T23:37:13.461616Z"}]}}
{"rx_ns": 42898840328100, "frame": {"channel":"book","type":"update","data":[{"symbol":"BTC/USD","bids":[],"asks":[{"price":62800.6,"qty":0.00000000},{"price":62883.7,"qty":1.31257213}],"checksum":4111384582,"timestamp":"2026-08-16T23:37:13.461698Z"}]}}
{"rx_ns": 42898840338200, "frame": {"channel":"book","type":"update","data":[{"symbol":"BTC/USD","bids":[],"asks":[{"price":62797.0,"qty":4.28962274}],"checksum":1667611176,"timestamp":"2026-08-16T23:37:13.461816Z"}]}}
{"rx_ns": 42898840347500, "frame": {"channel":"book","type":"update","data":[{"symbol":"BTC/USD","bids":[],"asks":[{"price":62796.9,"qty":0.24558472}],"checksum":3163067179,"timestamp":"2026-08-16T23:37:13.462033Z"}]}}
{"rx_ns": 42898840354400, "frame": {"channel":"book","type":"update","data":[{"symbol":"BTC/USD","bids":[],"asks":[{"price":62797.0,"qty":4.27797059}],"checksum":2675249811,"timestamp":"2026-08-16T23:37:13.462354Z"}]}}
{"rx_ns": 42898840361700, "frame": {"channel":"book","type":"update","data":[{"symbol":"BTC/USD","bids":[],"asks":[{"price":62797.0,"qty":4.27789759}],"checksum":1022966283,"timestamp":"2026-08-16T23:37:13.462365Z"}]}}
{"rx_ns": 42898840370200, "frame": {"channel":"book","type":"update","data":[{"symbol":"BTC/USD","bids":[],"asks":[{"price":62796.9,"qty":0.32358472}],"checksum":3885899048,"timestamp":"2026-08-16T23:37:13.462445Z"}]}}
{"rx_ns": 42898840380600, "frame": {"channel":"book","type":"update","data":[{"symbol":"BTC/USD","bids":[],"asks":[{"price":62797.0,"qty":4.19989759}],"checksum":898682576,"timestamp":"2026-08-16T23:37:13.462469Z"}]}}
{"rx_ns": 42898840389400, "frame": {"channel":"book","type":"update","data":[{"symbol":"BTC/USD","bids":[{"price":62796.0,"qty":0.00000000},{"price":62690.0,"qty":0.00319030}],"asks":[],"checksum":4073369100,"timestamp":"2026-08-16T23:37:13.462645Z"}]}}
{"rx_ns": 42898840396900, "frame": {"channel":"book","type":"update","data":[{"symbol":"BTC/USD","bids":[],"asks":[{"price":62796.9,"qty":0.24398472}],"checksum":1898895313,"timestamp":"2026-08-16T23:37:13.462677Z"}]}}
{"rx_ns": 42898840402900, "frame": {"channel":"book","type":"update","data":[{"symbol":"BTC/USD","bids":[],"asks":[{"price":62796.1,"qty":0.14920000}],"checksum":3318805193,"timestamp":"2026-08-16T23:37:13.462794Z"}]}}
{"rx_ns": 42898840408800, "frame": {"channel":"book","type":"update","data":[{"symbol":"BTC/USD","bids":[],"asks":[{"price":62797.0,"qty":4.13029759}],"checksum":1121346064,"timestamp":"2026-08-16T23:37:13.462820Z"}]}}
{"rx_ns": 42898840414500, "frame": {"channel":"book","type":"update","data":[{"symbol":"BTC/USD","bids":[],"asks":[{"price":62798.0,"qty":0.00513547}],"checksum":878264134,"timestamp":"2026-08-16T23:37:13.463345Z"}]}}
{"rx_ns": 42898840420300, "frame": {"channel":"book","type":"update","data":[{"symbol":"BTC/USD","bids":[],"asks":[{"price":62797.0,"qty":4.05988426}],"checksum":2356068417,"timestamp":"2026-08-16T23:37:13.463475Z"}]}}
{"rx_ns": 42898840427200, "frame": {"channel":"book","type":"update","data":[{"symbol":"BTC/USD","bids":[],"asks":[{"price":62796.1,"qty":0.94542779}],"checksum":1759713999,"timestamp":"2026-08-16T23:37:13.463545Z"}]}}
{"rx_ns": 42898840433100, "frame": {"channel":"book","type":"update","data":[{"symbol":"BTC/USD","bids":[],"asks":[{"price":62796.9,"qty":0.16598472}],"checksum":1536495352,"timestamp":"2026-08-16T23:37:13.463625Z"}]}}
{"rx_ns": 42898840438800, "frame": {"channel":"book","type":"update","data":[{"symbol":"BTC/USD","bids":[{"price":62794.7,"qty":0.02137959}],"asks":[],"checksum":3350735210,"timestamp":"2026-08-16T23:37:13.463765Z"}]}}
{"rx_ns": 42898840444900, "frame": {"channel":"book","type":"update","data":[{"symbol":"BTC/USD","bids":[],"asks":[{"price":62796.1,"qty":1.02342779}],"checksum":3674350646,"timestamp":"2026-08-16T23:37:13.463788Z"}]}}
{"rx_ns": 42898840450700, "frame": {"channel":"book","type":"update","data":[{"symbol":"BTC/USD","bids":[],"asks":[{"price":62798.7,"qty":0.00000000},{"price":62883.7,"qty":1.31257213}],"checksum":1855476045,"timestamp":"2026-08-16T23:37:13.464269Z"}]}}
{"rx_ns": 42898840457200, "frame": {"channel":"book","type":"update","data":[{"symbol":"BTC/USD","bids":[],"asks":[{"price":62797.1,"qty":0.34195948}],"checksum":106192259,"timestamp":"2026-08-16T23:37:13.464423Z"}]}}
{"rx_ns": 42898847979800, "frame": {"channel":"book","type":"update","data":[{"symbol":"BTC/USD","bids":[{"price":62794.3,"qty":0.00000000},{"price":62690.0,"qty":0.00319030}],"asks":[],"checksum":511134499,"timestamp":"2026-08-16T23:37:13.465188Z"}]}}
{"rx_ns": 42898848018500, "frame": {"channel":"book","type":"update","data":[{"symbol":"BTC/USD","bids":[],"asks":[{"price":62796.1,"qty":1.09399949}],"checksum":3766052222,"timestamp":"2026-08-16T23:37:13.466088Z"}]}}
{"rx_ns": 42898848029300, "frame": {"channel":"book","type":"update","data":[{"symbol":"BTC/USD","bids":[],"asks":[{"price":62796.1,"qty":0.29777170}],"checksum":2386186471,"timestamp":"2026-08-16T23:37:13.466273Z"}]}}
{"rx_ns": 42898848037800, "frame": {"channel":"book","type":"update","data":[{"symbol":"BTC/USD","bids":[{"price":62794.7,"qty":0.02117959}],"asks":[],"checksum":2366283063,"timestamp":"2026-08-16T23:37:13.467505Z"}]}}
{"rx_ns": 42898848046300, "frame": {"channel":"book","type":"update","data":[{"symbol":"BTC/USD","bids":[],"asks":[{"price":62796.1,"qty":0.22817170}],"checksum":906474757,"timestamp":"2026-08-16T23:37:13.467746Z"}]}}
{"rx_ns": 42898851396100, "frame": {"channel":"book","type":"update","data":[{"symbol":"BTC/USD","bids":[],"asks":[{"price":62807.3,"qty":0.00000000},{"price":62884.4,"qty":0.47672669},{"price":62818.7,"qty":1.59798224}],"checksum":906474757,"timestamp":"2026-08-16T23:37:13.470208Z"}]}}
{"rx_ns": 42898851432800, "frame": {"channel":"book","type":"update","data":[{"symbol":"BTC/USD","bids":[],"asks":[{"price":62794.8,"qty":0.01185247}],"checksum":3404885841,"timestamp":"2026-08-16T23:37:13.471768Z"}]}}
{"rx_ns": 42898851444500, "frame": {"channel":"book","type":"update","data":[{"symbol":"BTC/USD","bids":[],"asks":[{"price":62794.8,"qty":0.08145247}],"checksum":3960111225,"timestamp":"2026-08-16T23:37:13.472960Z"}]}}
{"rx_ns": 42898851453100, "frame": {"channel":"book","type":"update","data":[{"symbol":"BTC/USD","bids":[],"asks":[{"price":62794.8,"qty":0.16105247}],"checksum":167885924,"timestamp":"2026-08-16T23:37:13.473268Z"}]}}
{"rx_ns": 42898851463900, "frame": {"channel":"book","type":"update","data":[{"symbol":"BTC/USD","bids":[],"asks":[{"price":62796.1,"qty":0.14857170}],"checksum":1757391303,"timestamp":"2026-08-16T23:37:13.473281Z"}]}}
{"rx_ns": 42898851472300, "frame": {"channel":"book","type":"update","data":[{"symbol":"BTC/USD","bids":[],"asks":[{"price":62794.8,"qty":0.23905247}],"checksum":3612973972,"timestamp":"2026-08-16T23:37:13.473401Z"}]}}
{"rx_ns": 42898851480300, "frame": {"channel":"book","type":"update","data":[{"symbol":"BTC/USD","bids":[],"asks":[{"price":62796.1,"qty":0.07057170}],"checksum":1714635624,"timestamp":"2026-08-16T23:37:13.473488Z"}]}}
{"rx_ns": 42898851488800, "frame": {"channel":"book","type":"update","data":[{"symbol":"BTC/USD","bids":[],"asks":[{"price":62800.5,"qty":0.00000000},{"price":62884.4,"qty":0.47672669},{"price":62805.0,"qty":0.18489680}],"checksum":1729045999,"timestamp":"2026-08-16T23:37:13.474135Z"}]}}
{"rx_ns": 42898851579900, "frame": {"channel":"book","type":"update","data":[{"symbol":"BTC/USD","bids":[],"asks":[{"price":62802.0,"qty":0.00318462}],"checksum":1856495559,"timestamp":"2026-08-16T23:37:13.474914Z"}]}}
{"rx_ns": 42898869613300, "frame": {"channel":"book","type":"update","data":[{"symbol":"BTC/USD","bids":[{"price":62780.0,"qty":0.16442373}],"asks":[],"checksum":3114252206,"timestamp":"2026-08-16T23:37:13.496220Z"}]}}
{"rx_ns": 42898869665700, "frame": {"channel":"book","type":"update","data":[{"symbol":"BTC/USD","bids":[],"asks":[{"price":62797.0,"qty":3.90065027}],"checksum":4202515596,"timestamp":"2026-08-16T23:37:13.496353Z"}]}}
{"rx_ns": 42898871512700, "frame": {"channel":"book","type":"update","data":[{"symbol":"BTC/USD","bids":[],"asks":[{"price":62863.8,"qty":0.05371082}],"checksum":4202515596,"timestamp":"2026-08-16T23:37:13.499823Z"}]}}
{"rx_ns": 42898874809500, "frame": {"channel":"book","type":"update","data":[{"symbol":"BTC/USD","bids":[{"price":62775.5,"qty":0.00829935}],"asks":[],"checksum":4202515596,"timestamp":"2026-08-16T23:37:13.502322Z"}]}}
{"rx_ns": 42898907571200, "frame": {"channel":"book","type":"update","data":[{"symbol":"BTC/USD","bids":[],"asks":[{"price":62794.8,"qty":0.39828646}],"checksum":4106524555,"timestamp":"2026-08-16T23:37:13.535184Z"}]}}
{"rx_ns": 42898910706300, "frame": {"channel":"book","type":"update","data":[{"symbol":"BTC/USD","bids":[],"asks":[{"price":62829.7,"qty":0.00000000},{"price":62883.3,"qty":0.02184000},{"price":62828.7,"qty":0.00094656}],"checksum":4106524555,"timestamp":"2026-08-16T23:37:13.536544Z"}]}}
{"rx_ns": 42898915787800, "frame": {"channel":"book","type":"update","data":[{"symbol":"BTC/USD","bids":[{"price":62778.0,"qty":0.80483233}],"asks":[],"checksum":2016943779,"timestamp":"2026-08-16T23:37:13.543280Z"}]}}
{"rx_ns": 42898932795000, "frame": {"channel":"book","type":"update","data":[{"symbol":"BTC/USD","bids":[{"price":62784.0,"qty":0.79638050}],"asks":[],"checksum":3931539391,"timestamp":"2026-08-16T23:37:13.559234Z"}]}}
{"rx_ns": 42898932850900, "frame": {"channel":"book","type":"update","data":[{"symbol":"BTC/USD","bids":[{"price":62781.3,"qty":0.79641481}],"asks":[],"checksum":4139273683,"timestamp":"2026-08-16T23:37:13.559433Z"}]}}
{"rx_ns": 42898936555400, "frame": {"channel":"book","type":"update","data":[{"symbol":"BTC/USD","bids":[],"asks":[{"price":62797.0,"qty":3.79065027}],"checksum":2113754527,"timestamp":"2026-08-16T23:37:13.560453Z"}]}}
{"rx_ns": 42898936605000, "frame": {"channel":"book","type":"update","data":[{"symbol":"BTC/USD","bids":[{"price":62733.8,"qty":0.00000000},{"price":62691.1,"qty":0.00159500}],"asks":[],"checksum":2113754527,"timestamp":"2026-08-16T23:37:13.560983Z"}]}}
{"rx_ns": 42898936633500, "frame": {"channel":"book","type":"update","data":[{"symbol":"BTC/USD","bids":[{"price":62782.1,"qty":0.06960000}],"asks":[],"checksum":789392036,"timestamp":"2026-08-16T23:37:13.562257Z"}]}}
{"rx_ns": 42898939856400, "frame": {"channel":"book","type":"update","data":[{"symbol":"BTC/USD","bids":[{"price":62794.7,"qty":0.02157772}],"asks":[],"checksum":2459854834,"timestamp":"2026-08-16T23:37:13.565470Z"}]}}
{"rx_ns": 42898966140700, "frame": {"channel":"book","type":"update","data":[{"symbol":"BTC/USD","bids":[{"price":62699.4,"qty":0.05598472}],"asks":[],"checksum":2459854834,"timestamp":"2026-08-16T23:37:13.568153Z"}]}}
{"rx_ns": 42898966187300, "frame": {"channel":"book","type":"update","data":[{"symbol":"BTC/USD","bids":[],"asks":[{"price":62803.9,"qty":0.06000000}],"checksum":2459854834,"timestamp":"2026-08-16T23:37:13.571232Z"}]}}
{"rx_ns": 42898966199700, "frame": {"channel":"book","type":"update","data":[{"symbol":"BTC/USD","bids":[],"asks":[{"price":62814.6,"qty":0.00000000},{"price":62883.3,"qty":0.02184000}],"checksum":2459854834,"timestamp":"2026-08-16T23:37:13.583591Z"}]}}
{"rx_ns": 42898966210900, "frame": {"channel":"book","type":"update","data":[{"symbol":"BTC/USD","bids":[],"asks":[{"price":62847.0,"qty":0.01598519}],"checksum":2459854834,"timestamp":"2026-08-16T23:37:13.585048Z"}]}}
{"rx_ns": 42898993685900, "frame": {"channel":"book","type":"update","data":[{"symbol":"BTC/USD","bids":[{"price":62794.7,"qty":0.02197585}],"asks":[],"checksum":3863698846,"timestamp":"2026-08-16T23:37:13.620716Z"}]}}
{"rx_ns": 42898995081800, "frame": {"channel":"book","type":"update","data":[{"symbol":"BTC/USD","bids":[],"asks":[{"price":62796.9,"qty":0.11000000},{"price":62796.0,"qty":0.05598472}],"checksum":1583906534,"timestamp":"2026-08-16T23:37:13.621890Z"}]}}
{"rx_ns": 42898999656500, "frame": {"channel":"book","type":"update","data":[{"symbol":"BTC/USD","bids":[],"asks":[{"price":62797.0,"qty":0.00000000},{"price":62881.2,"qty":0.16061732},{"price":62794.8,"qty":4.18901796}],"checksum":111484047,"timestamp":"2026-08-16T23:37:13.626585Z"}]}}
{"rx_ns": 42899013716100, "frame": {"channel":"book","type":"update","data":[{"symbol":"BTC/USD","bids":[{"price":62794.7,"qty":0.00079626}],"asks":[],"checksum":495752823,"timestamp":"2026-08-16T23:37:13.641453Z"}]}}
{"rx_ns": 42899015169100, "frame": {"channel":"book","type":"update","data":[{"symbol":"BTC/USD","bids":[{"price":62759.3,"qty":0.00000000},{"price":62692.1,"qty":0.00119632},{"price":62755.5,"qty":0.00318620}],"asks":[],"checksum":495752823,"timestamp":"2026-08-16T23:37:13.643489Z"}]}}
{"rx_ns": 42899018136600, "frame": {"channel":"book","type":"update","data":[{"symbol":"BTC/USD","bids":[],"asks":[{"price":62835.3,"qty":0.06960000},{"price":62831.5,"qty":0.00318620}],"checksum":495752823,"timestamp":"2026-08-16T23:37:13.643814Z"}]}}
{"rx_ns": 42899018215200, "frame": {"channel":"book","type":"update","data":[{"symbol":"BTC/USD","bids":[{"price":62793.1,"qty":0.02131292}],"asks":[],"checksum":2435127186,"timestamp":"2026-08-16T23:37:13.644602Z"}]}}
{"rx_ns": 42899024682500, "frame": {"channel":"book","type":"update","data":[{"symbol":"BTC/USD","bids":[],"asks":[{"price":62794.8,"qty":4.84442508}],"checksum":854277363,"timestamp":"2026-08-16T23:37:13.650393Z"}]}}
{"rx_ns": 42899050825600, "frame": {"channel":"book","type":"update","data":[{"symbol":"BTC/USD","bids":[{"price":62794.7,"qty":0.00119439}],"asks":[],"checksum":2813080452,"timestamp":"2026-08-16T23:37:13.676685Z"}]}}
{"rx_ns": 42899050892500, "frame": {"channel":"book","type":"update","data":[{"symbol":"BTC/USD","bids":[],"asks":[{"price":62807.1,"qty":0.00000000},{"price":62881.2,"qty":0.16061732}],"checksum":2813080452,"timestamp":"2026-08-16T23:37:13.676744Z"}]}}
{"rx_ns": 42899052115800, "frame": {"channel":"book","type":"update","data":[{"symbol":"BTC/USD","bids":[],"asks":[{"price":62796.1,"qty":0.00000000},{"price":62883.3,"qty":0.02184000}],"checksum":3712950378,"timestamp":"2026-08-16T23:37:13.679942Z"}]}}
{"rx_ns": 42899053696600, "frame": {"channel":"book","type":"update","data":[{"symbol":"BTC/USD","bids":[],"asks":[{"price":62796.0,"qty":0.00000000},{"price":62883.7,"qty":1.31257213},{"price":62796.8,"qty":0.05598472}],"checksum":1322700297,"timestamp":"2026-08-16T23:37:13.681212Z"}]}}
{"rx_ns": 42899068427500, "frame": {"channel":"book","type":"update","data":[{"symbol":"BTC/USD","bids":[],"asks":[{"price":62806.0,"qty":0.00000000},{"price":62883.7,"qty":1.31257213}],"checksum":1322700297,"timestamp":"2026-08-16T23:37:13.684001Z"}]}}
{"rx_ns": 42899068490400, "frame": {"channel":"book","type":"update","data":[{"symbol":"BTC/USD","bids":[{"price":62780.0,"qty":0.00518974}],"asks":[],"checksum":1322700297,"timestamp":"2026-08-16T23:37:13.686504Z"}]}}
{"rx_ns": 42899068502500, "frame": {"channel":"book","type":"update","data":[{"symbol":"BTC/USD","bids":[{"price":62780.8,"qty":0.15923399}],"asks":[],"checksum":1322700297,"timestamp":"2026-08-16T23:37:13.696028Z"}]}}
{"rx_ns": 42899073202900, "frame": {"channel":"book","type":"update","data":[{"symbol":"BTC/USD","bids":[],"asks":[{"price":62858.7,"qty":0.00000000},{"price":62884.4,"qty":0.47672669},{"price":62854.1,"qty":0.00385951}],"checksum":1322700297,"timestamp":"2026-08-16T23:37:13.701107Z"}]}}
{"rx_ns": 42899083079300, "frame": {"channel":"book","type":"update","data":[{"symbol":"BTC/USD","bids":[{"price":62780.8,"qty":0.00000000},{"price":62696.2,"qty":0.07974964}],"asks":[],"checksum":1322700297,"timestamp":"2026-08-16T23:37:13.710681Z"}]}}
{"rx_ns": 42899085241000, "frame": {"channel":"book","type":"update","data":[{"symbol":"BTC/USD","bids":[{"price":62765.0,"qty":0.15554013}],"asks":[],"checksum":1322700297,"timestamp":"2026-08-16T23:37:13.711740Z"}]}}
{"rx_ns": 42899085307600, "frame": {"channel":"book","type":"update","data":[{"symbol":"BTC/USD","bids":[{"price":62764.5,"qty":0.00000000},{"price":62696.2,"qty":0.07974964}],"asks":[],"checksum":1322700297,"timestamp":"2026-08-16T23:37:13.711880Z"}]}}
{"rx_ns": 42899085323200, "frame": {"channel":"book","type":"update","data":[{"symbol":"BTC/USD","bids":[{"price":62733.1,"qty":0.05429936}],"asks":[],"checksum":1322700297,"timestamp":"2026-08-16T23:37:13.712018Z"}]}}
{"rx_ns": 42899085440700, "frame": {"channel":"book","type":"update","data":[{"symbol":"BTC/USD","bids":[{"price":62733.6,"qty":0.15757628}],"asks":[],"checksum":1322700297,"timestamp":"2026-08-16T23:37:13.712314Z"}]}}
{"rx_ns": 42899087184200, "frame": {"channel":"book","type":"update","data":[{"symbol":"BTC/USD","bids":[{"price":62758.9,"qty":0.00000000},{"price":62698.7,"qty":0.06960000},{"price":62757.8,"qty":0.00303484}],"asks":[],"checksum":1322700297,"timestamp":"2026-08-16T23:37:13.714710Z"}]}}
{"rx_ns": 42899103337900, "frame": {"channel":"book","type":"update","data":[{"symbol":"BTC/USD","bids":[{"price":62757.8,"qty":0.00000000},{"price":62696.2,"qty":0.07974964},{"price":62755.5,"qty":0.00622104}],"asks":[],"checksum":1322700297,"timestamp":"2026-08-16T23:37:13.730313Z"}]}}
{"rx_ns": 42899104936700, "frame": {"channel":"book","type":"update","data":[{"symbol":"BTC/USD","bids":[{"price":62794.7,"qty":0.00159252}],"asks":[],"checksum":3672878434,"timestamp":"2026-08-16T23:37:13.731911Z"}]}}
{"rx_ns": 42899109378700, "frame": {"channel":"book","type":"update","data":[{"symbol":"BTC/USD","bids":[{"price":62698.7,"qty":0.06960000}],"asks":[],"checksum":3672878434,"timestamp":"2026-08-16T23:37:13.733263Z"}]}}
{"rx_ns": 42899112471800, "frame": {"channel":"book","type":"update","data":[{"symbol":"BTC/USD","bids":[],"asks":[{"price":62800.7,"qty":0.00000000},{"price":62884.4,"qty":0.47672669},{"price":62794.8,"qty":4.84482321}],"checksum":3278123104,"timestamp":"2026-08-16T23:37:13.739975Z"}]}}
{"rx_ns": 42899114692700, "frame": {"channel":"book","type":"update","data":[{"symbol":"BTC/USD","bids":[],"asks":[{"price":62828.1,"qty":0.00000000},{"price":62886.5,"qty":0.02137959},{"price":62826.7,"qty":0.28000000}],"checksum":3278123104,"timestamp":"2026-08-16T23:37:13.743156Z"}]}}
{"rx_ns": 42899118115500, "frame": {"channel":"book","type":"update","data":[{"symbol":"BTC/USD","bids":[{"price":62779.7,"qty":0.15923399}],"asks":[],"checksum":3278123104,"timestamp":"2026-08-16T23:37:13.746031Z"}]}}
{"rx_ns": 42899130047600, "frame": {"channel":"book","type":"update","data":[{"symbol":"BTC/USD","bids":[{"price":62794.7,"qty":0.00119439}],"asks":[],"checksum":1465471755,"timestamp":"2026-08-16T23:37:13.756589Z"}]}}
{"rx_ns": 42899133941000, "frame": {"channel":"book","type":"update","data":[{"symbol":"BTC/USD","bids":[],"asks":[{"price":62875.0,"qty":0.04717193}],"checksum":1465471755,"timestamp":"2026-08-16T23:37:13.757483Z"}]}}
{"rx_ns": 42899133991800, "frame": {"channel":"book","type":"update","data":[{"symbol":"BTC/USD","bids":[{"price":62794.7,"qty":0.01634490}],"asks":[],"checksum":405992136,"timestamp":"2026-08-16T23:37:13.757603Z"}]}}
{"rx_ns": 42899143002200, "frame": {"channel":"book","type":"update","data":[{"symbol":"BTC/USD","bids":[],"asks":[{"price":62826.7,"qty":0.00000000},{"price":62886.5,"qty":0.02137959},{"price":62824.3,"qty":0.28000000}],"checksum":405992136,"timestamp":"2026-08-16T23:37:13.770055Z"}]}}
{"rx_ns": 42899188837800, "frame": {"channel":"book","type":"update","data":[{"symbol":"BTC/USD","bids":[{"price":62794.7,"qty":0.01594677}],"asks":[],"checksum":3673217803,"timestamp":"2026-08-16T23:37:13.816573Z"}]}}
{"rx_ns": 42899191313800, "frame": {"channel":"book","type":"update","data":[{"symbol":"BTC/USD","bids":[{"price":62753.2,"qty":0.15920000}],"asks":[],"checksum":3673217803,"timestamp":"2026-08-16T23:37:13.818005Z"}]}}
{"rx_ns": 42899191347000, "frame": {"channel":"book","type":"update","data":[{"symbol":"BTC/USD","bids":[{"price":62755.7,"qty":0.23900000}],"asks":[],"checksum":3673217803,"timestamp":"2026-08-16T23:37:13.818209Z"}]}}
{"rx_ns": 42899196651200, "frame": {"channel":"book","type":"update","data":[{"symbol":"BTC/USD","bids":[{"price":62741.5,"qty":0.03262062}],"asks":[],"checksum":3673217803,"timestamp":"2026-08-16T23:37:13.822242Z"}]}}
{"rx_ns": 42899206977700, "frame": {"channel":"book","type":"update","data":[{"symbol":"BTC/USD","bids":[{"price":62784.0,"qty":0.00000000},{"price":62699.9,"qty":1.50000000}],"asks":[],"checksum":30612623,"timestamp":"2026-08-16T23:37:13.834817Z"}]}}
{"rx_ns": 42899210873500, "frame": {"channel":"book","type":"update","data":[{"symbol":"BTC/USD","bids":[],"asks":[{"price":62794.8,"qty":5.64106748}],"checksum":1746669247,"timestamp":"2026-08-16T23:37:13.836517Z"}]}}
{"rx_ns": 42899213334200, "frame": {"channel":"book","type":"update","data":[{"symbol":"BTC/USD","bids":[],"asks":[{"price":62796.0,"qty":0.79622905}],"checksum":10078239,"timestamp":"2026-08-16T23:37:13.836833Z"}]}}
{"rx_ns": 42899213368300, "frame": {"channel":"book","type":"update","data":[{"symbol":"BTC/USD","bids":[{"price":62783.2,"qty":0.79639015}],"asks":[],"checksum":2264673763,"timestamp":"2026-08-16T23:37:13.837088Z"}]}}
{"rx_ns": 42899213382800, "frame": {"channel":"book","type":"update","data":[{"symbol":"BTC/USD","bids":[],"asks":[{"price":62794.8,"qty":5.66123042}],"checksum":2717124202,"timestamp":"2026-08-16T23:37:13.838243Z"}]}}
{"rx_ns": 42899213394300, "frame": {"channel":"book","type":"update","data":[{"symbol":"BTC/USD","bids":[],"asks":[{"price":62796.8,"qty":0.00000000},{"price":62884.4,"qty":0.47672669},{"price":62795.9,"qty":0.05598472}],"checksum":2863317049,"timestamp":"2026-08-16T23:37:13.838291Z"}]}}
{"rx_ns": 42899214887000, "frame": {"channel":"book","type":"update","data":[{"symbol":"BTC/USD","bids":[{"price":62794.3,"qty":0.00005100}],"asks":[],"checksum":3447956584,"timestamp":"2026-08-16T23:37:13.841308Z"}]}}
{"rx_ns": 42899248310100, "frame": {"channel":"book","type":"update","data":[{"symbol":"BTC/USD","bids":[{"price":62794.7,"qty":0.01554864}],"asks":[],"checksum":3133548343,"timestamp":"2026-08-16T23:37:13.875446Z"}]}}
{"rx_ns": 42899286676500, "frame": {"channel":"book","type":"update","data":[{"symbol":"BTC/USD","bids":[],"asks":[{"price":62796.1,"qty":0.46044544}],"checksum":1992868612,"timestamp":"2026-08-16T23:37:13.914384Z"}]}}
{"rx_ns": 42899349265600, "frame": {"channel":"book","type":"update","data":[{"symbol":"BTC/USD","bids":[{"price":62755.5,"qty":0.00318620},{"price":62755.6,"qty":0.00303491}],"asks":[],"checksum":1992868612,"timestamp":"2026-08-16T23:37:13.974949Z"}]}}
{"rx_ns": 42899403738900, "frame": {"channel":"book","type":"update","data":[{"symbol":"BTC/USD","bids":[{"price":62782.1,"qty":0.00000000},{"price":62703.0,"qty":0.01531807}],"asks":[],"checksum":2224799627,"timestamp":"2026-08-16T23:37:14.030312Z"}]}}
{"rx_ns": 42899438053200, "frame": {"channel":"book","type":"update","data":[{"symbol":"BTC/USD","bids":[{"price":62783.5,"qty":0.00015926}],"asks":[],"checksum":2565865318,"timestamp":"2026-08-16T23:37:14.065529Z"}]}}
{"rx_ns": 42899547508000, "frame": {"channel":"book","type":"update","data":[{"symbol":"BTC/USD","bids":[],"asks":[{"price":62796.9,"qty":0.90621764}],"checksum":2340148065,"timestamp":"2026-08-16T23:37:14.174120Z"}]}}
{"rx_ns": 42899547630800, "frame": {"channel":"book","type":"update","data":[{"symbol":"BTC/USD","bids":[],"asks":[{"price":62805.0,"qty":0.00000000},{"price":62883.7,"qty":1.31257213},{"price":62800.7,"qty":0.18489680}],"checksum":1790700499,"timestamp":"2026-08-16T23:37:14.175497Z"}]}}
{"rx_ns": 42899558260400, "frame": {"channel":"book","type":"update","data":[{"symbol":"BTC/USD","bids":[],"asks":[{"price":62801.4,"qty":0.36000000}],"checksum":369341209,"timestamp":"2026-08-16T23:37:14.185798Z"}]}}
{"rx_ns": 42899562584300, "frame": {"channel":"book","type":"update","data":[{"symbol":"BTC/USD","bids":[{"price":62780.2,"qty":0.10252886}],"asks":[],"checksum":369341209,"timestamp":"2026-08-16T23:37:14.187940Z"}]}}
{"rx_ns": 42899585830800, "frame": {"channel":"book","type":"update","data":[{"symbol":"BTC/USD","bids":[{"price":62779.7,"qty":0.00000000},{"price":62703.8,"qty":0.05517271}],"asks":[],"checksum":369341209,"timestamp":"2026-08-16T23:37:14.214692Z"}]}}
{"rx_ns": 42899599171800, "frame": {"channel":"book","type":"update","data":[{"symbol":"BTC/USD","bids":[],"asks":[{"price":62794.8,"qty":5.66223042}],"checksum":3341616031,"timestamp":"2026-08-16T23:37:14.227458Z"}]}}
{"rx_ns": 42899620555900, "frame": {"channel":"book","type":"update","data":[{"symbol":"BTC/USD","bids":[{"price":62779.8,"qty":0.15923399}],"asks":[],"checksum":3341616031,"timestamp":"2026-08-16T23:37:14.246469Z"}]}}
{"rx_ns": 42899667164500, "frame": {"channel":"heartbeat"}}
{"rx_ns": 42899717430300, "frame": {"channel":"book","type":"update","data":[{"symbol":"BTC/USD","bids":[],"asks":[{"price":62813.5,"qty":0.50000000}],"checksum":3341616031,"timestamp":"2026-08-16T23:37:14.345602Z"}]}}
{"rx_ns": 42899809330800, "frame": {"channel":"book","type":"update","data":[{"symbol":"BTC/USD","bids":[{"price":62784.9,"qty":0.00005100}],"asks":[],"checksum":1941947137,"timestamp":"2026-08-16T23:37:14.437357Z"}]}}
{"rx_ns": 42899822076200, "frame": {"channel":"book","type":"update","data":[{"symbol":"BTC/USD","bids":[{"price":62773.4,"qty":0.00000000},{"price":62703.8,"qty":0.05517271}],"asks":[],"checksum":1941947137,"timestamp":"2026-08-16T23:37:14.446955Z"}]}}
{"rx_ns": 42899822131800, "frame": {"channel":"book","type":"update","data":[{"symbol":"BTC/USD","bids":[{"price":62770.0,"qty":0.00418410}],"asks":[],"checksum":1941947137,"timestamp":"2026-08-16T23:37:14.447198Z"}]}}
{"rx_ns": 42899824968400, "frame": {"channel":"book","type":"update","data":[{"symbol":"BTC/USD","bids":[{"price":62763.0,"qty":0.89116200}],"asks":[],"checksum":1941947137,"timestamp":"2026-08-16T23:37:14.449843Z"}]}}
{"rx_ns": 42899825018500, "frame": {"channel":"book","type":"update","data":[{"symbol":"BTC/USD","bids":[{"price":62766.1,"qty":0.49279374}],"asks":[],"checksum":1941947137,"timestamp":"2026-08-16T23:37:14.450060Z"}]}}
{"rx_ns": 42899826877000, "frame": {"channel":"book","type":"update","data":[{"symbol":"BTC/USD","bids":[{"price":62766.1,"qty":0.10293774}],"asks":[],"checksum":1941947137,"timestamp":"2026-08-16T23:37:14.450327Z"}]}}
{"rx_ns": 42899830073500, "frame": {"channel":"book","type":"update","data":[{"symbol":"BTC/USD","bids":[{"price":62741.5,"qty":0.00000000},{"price":62703.8,"qty":0.05517271}],"asks":[],"checksum":1941947137,"timestamp":"2026-08-16T23:37:14.454185Z"}]}}
{"rx_ns": 42899831998900, "frame": {"channel":"book","type":"update","data":[{"symbol":"BTC/USD","bids":[{"price":62761.5,"qty":0.38985600}],"asks":[],"checksum":1941947137,"timestamp":"2026-08-16T23:37:14.456430Z"}]}}
{"rx_ns": 42899832055000, "frame": {"channel":"book","type":"update","data":[{"symbol":"BTC/USD","bids":[{"price":62780.0,"qty":0.00000000},{"price":62703.8,"qty":0.05517271}],"asks":[],"checksum":1941947137,"timestamp":"2026-08-16T23:37:14.457621Z"}]}}
{"rx_ns": 42899832069100, "frame": {"channel":"book","type":"update","data":[{"symbol":"BTC/USD","bids":[{"price":62778.0,"qty":0.80164650}],"asks":[],"checksum":1941947137,"timestamp":"2026-08-16T23:37:14.457762Z"}]}}
{"rx_ns": 42899832078100, "frame": {"channel":"book","type":"update","data":[{"symbol":"BTC/USD","bids":[{"price":62772.0,"qty":0.00318614}],"asks":[],"checksum":1941947137,"timestamp":"2026-08-16T23:37:14.457981Z"}]}}
{"rx_ns": 42899834481000, "frame": {"channel":"book","type":"update","data":[{"symbol":"BTC/USD","bids":[{"price":62765.0,"qty":0.00000000},{"price":62705.0,"qty":0.06960000}],"asks":[],"checksum":1941947137,"timestamp":"2026-08-16T23:37:14.461788Z"}]}}
{"rx_ns": 42899834537000, "frame": {"channel":"book","type":"update","data":[{"symbol":"BTC/USD","bids":[{"price":62733.1,"qty":0.00000000},{"price":62703.8,"qty":0.05517271}],"asks":[],"checksum":1941947137,"timestamp":"2026-08-16T23:37:14.461861Z"}]}}
{"rx_ns": 42899834578800, "frame": {"channel":"book","type":"update","data":[{"symbol":"BTC/USD","bids":[{"price":62705.0,"qty":0.00000000},{"price":62703.0,"qty":0.01531807}],"asks":[],"checksum":1941947137,"timestamp":"2026-08-16T23:37:14.461872Z"}]}}
{"rx_ns": 42899836087300, "frame": {"channel":"book","type":"update","data":[{"symbol":"BTC/USD","bids":[],"asks":[{"price":62853.8,"qty":0.00000000},{"price":62881.2,"qty":0.16061732}],"checksum":1941947137,"timestamp":"2026-08-16T23:37:14.463548Z"}]}}
{"rx_ns": 42899837690700, "frame": {"channel":"book","type":"update","data":[{"symbol":"BTC/USD","bids":[{"price":62705.0,"qty":0.06960000}],"asks":[],"checksum":1941947137,"timestamp":"2026-08-16T23:37:14.464816Z"}]}}
{"rx_ns": 42899837717200, "frame": {"channel":"book","type":"update","data":[{"symbol":"BTC/USD","bids":[{"price":62791.3,"qty":0.00000000},{"price":62703.0,"qty":0.01531807}],"asks":[],"checksum":2533704444,"timestamp":"2026-08-16T23:37:14.464865Z"}]}}
{"rx_ns": 42899840860800, "frame": {"channel":"book","type":"update","data":[{"symbol":"BTC/USD","bids":[],"asks":[{"price":62810.9,"qty":7.96040350}],"checksum":2533704444,"timestamp":"2026-08-16T23:37:14.465171Z"}]}}
{"rx_ns": 42899840898300, "frame": {"channel":"book","type":"update","data":[{"symbol":"BTC/USD","bids":[{"price":62781.3,"qty":0.00000000},{"price":62699.9,"qty":1.50000000}],"asks":[],"checksum":3173549658,"timestamp":"2026-08-16T23:37:14.465592Z"}]}}
{"rx_ns": 42899840912100, "frame": {"channel":"book","type":"update","data":[{"symbol":"BTC/USD","bids":[{"price":62783.2,"qty":0.00000000},{"price":62699.7,"qty":5.58216167}],"asks":[],"checksum":1602837373,"timestamp":"2026-08-16T23:37:14.465732Z"}]}}
{"rx_ns": 42899840923500, "frame": {"channel":"book","type":"update","data":[{"symbol":"BTC/USD","bids":[{"price":62788.1,"qty":0.05598472}],"asks":[],"checksum":3032084499,"timestamp":"2026-08-16T23:37:14.465999Z"}]}}
